File: data/XRD/XG-Luft/XG-600/W6824-1D_XG_Luft_600.xrdml
<xrdMeasurements xmlns="http://www.xrdml.com/XRDMeasurement/2.1" xmlns:xsi="http://www.w3.org/2001/XMLSchema-instance" xsi:schemaLocation="http://www.xrdml.com/XRDMeasurement/2.1 http://www.xrdml.com/XRDMeasurement/2.1/XRDMeasurement.xsd" status="Completed">
	<comment>
		<entry>Configuration=Factory configuration, Owner=User-1, Creation date=7/8/2013 4:01:53 PM</entry>
		<entry>Goniometer=PW3050/65 (Theta/2Theta); Minimum step size 2Theta:0.0001; Minimum step size Omega:0.0001</entry>
		<entry>Sample stage=MRD Cradle; Minimum step size Phi:0.01; Minimum step size Chi:0.01; Minimum step size X:0.01; Minimum step size Y:0.01; Minimum step size Z:0.001</entry>
		<entry>Diffractometer system=XPERT-PRO</entry>
		<entry>Measurement program=C:\PANalytical\Data Collector\Programs\Jorrit\2thom\_absolute_2th-om_10-130deg_PIXscan_56min.xrdmp, Identifier={15BCCF57-2807-42BD-B5B9-ECC0B3DC9284}</entry>
		<entry>Batch program=C:\PANalytical\Data Collector\Programs\SimonL\batch4x_2thom_10-130°_z9.1_x0,10,20,30_y0_57min.xrdmp, Identifier={EED9823A-2BEB-424C-9252-345C4EF2834A}</entry>
	</comment>
	<sample type="To be analyzed">
		<id></id>
		<name></name>
		<preparedBy></preparedBy>
	</sample>
	<xrdMeasurement measurementType="Scan" status="Completed" sampleMode="Reflection">
		<comment>
			<entry>_absolute_2th-om_10-130deg_PIXscan_56min</entry>
			<entry>PHD Lower Level = 4.83 (keV), PHD Upper Level = 11.27 (keV)</entry>
		</comment>
		<usedWavelength intended="K-Alpha 1">
			<kAlpha1 unit="Angstrom">1.5405980</kAlpha1>
			<kAlpha2 unit="Angstrom">1.5444260</kAlpha2>
			<kBeta unit="Angstrom">1.3922500</kBeta>
			<ratioKAlpha2KAlpha1>0.5000</ratioKAlpha2KAlpha1>
		</usedWavelength>
		<incidentBeamPath>
			<radius unit="mm">320.00</radius>
			<xRayTube id="1010048" name="Empyrean Cu LFF HR (9430 033 7310x) DK442154">
				<tension unit="kV">40.0</tension>
				<current unit="mA">40.0</current>
				<anodeMaterial>Cu</anodeMaterial>
				<focus type="Line">
					<length unit="mm">12.0</length>
					<width unit="mm">0.4</width>
					<takeOffAngle unit="deg">4.2</takeOffAngle>
				</focus>
			</xRayTube>
			<xRayMirror id="27010001" name="Inc. Beam Cu W/Si (parabolic MRD)" hybrid="false">
				<crystal type="Graded" shape="Parabolic">W/Si</crystal>
				<acceptanceAngle unit="deg">0.800</acceptanceAngle>
				<length unit="mm">60.0</length>
			</xRayMirror>
			<sollerSlit id="21010002" name="Soller slits 0.04 rad.">
				<opening unit="rad">0.0400</opening>
			</sollerSlit>
			<mask id="22030008" name="Fixed mask 4 mm">
				<distanceToSample unit="mm">220.00</distanceToSample>
				<width unit="mm">4.00</width>
			</mask>
			<divergenceSlit id="22010007" name="Fixed slit 1/8°" xsi:type="fixedDivergenceSlitType">
				<distanceToSample unit="mm">220.00</distanceToSample>
				<height unit="mm">0.19</height>
			</divergenceSlit>
		</incidentBeamPath>
		<diffractedBeamPath>
			<radius unit="mm">320.00</radius>
			<sollerSlit id="21010002" name="Soller slits 0.04 rad.">
				<opening unit="rad">0.0400</opening>
			</sollerSlit>
			<receivingSlit id="22010001" name="Fixed slit 4°">
				<height unit="mm">5.88</height>
			</receivingSlit>
			<detector id="7010017" name="PIXcel3D 1x1 detector" xsi:type="areaDetectorType">
				<phd unit="%">
					<lowerLevel>30.0</lowerLevel>
					<upperLevel>70.0</upperLevel>
				</phd>
				<mode>Scanning</mode>
				<activeChannelsEquatorial>255</activeChannelsEquatorial>
				<activeChannelsAxial>255</activeChannelsAxial>
				<pitchEquatorial unit="mm">0.05500</pitchEquatorial>
				<pitchAxial unit="mm">0.05500</pitchAxial>
				<readOutPeriod unit="seconds">0.135</readOutPeriod>
			</detector>
		</diffractedBeamPath>
		<scan appendNumber="0" mode="Continuous" scanAxis="2Theta-Omega" status="Completed">
			<header>
				<startTimeStamp>2024-10-22T20:37:45+02:00</startTimeStamp>
				<endTimeStamp>2024-10-22T21:33:51+02:00</endTimeStamp>
				<author>
					<name>PRO-MRD</name>
				</author>
				<source>
					<applicationSoftware version="6.1b">Data Collector</applicationSoftware>
					<instrumentControlSoftware version="7.0E 20130304">XPERT-PRO</instrumentControlSoftware>
					<instrumentID>0000000011142674</instrumentID>
				</source>
			</header>
			<dataPoints>
				<positions axis="2Theta" unit="deg">
					<startPosition>9.99826193</startPosition>
					<endPosition>129.99755682</endPosition>
				</positions>
				<positions axis="Omega" unit="deg">
					<startPosition>4.99913096</startPosition>
					<endPosition>64.99877841</endPosition>
				</positions>
				<positions axis="Phi" unit="deg">
					<commonPosition>0.00</commonPosition>
				</positions>
				<positions axis="Chi" unit="deg">
					<commonPosition>0.00</commonPosition>
				</positions>
				<positions axis="X" unit="mm">
					<commonPosition>30.00</commonPosition>
				</positions>
				<positions axis="Y" unit="mm">
					<commonPosition>0.00</commonPosition>
				</positions>
				<positions axis="Z" unit="mm">
					<commonPosition>9.100</commonPosition>
				</positions>
				<commonCountingTime unit="seconds">32.895</commonCountingTime>
				<counts 432 388 384 414 401 419 414 438 347 445 376 398 420 447 377 392 396 432 390 400 393 427 442 391 417 402 425 404 408 377 409 413 407 413 376 437 397 432 466 423 405 443 427 402 409 428 447 430 401 415 422 413 397 411 369 415 399 410 428 428 400 408 411 396 434 425 433 405 413 405 403 377 398 402 402 410 370 414 413 393 383 402 421 387 413 447 394 405 400 376 397 385 394 391 407 370 398 418 425 412 407 384 396 423 358 356 369 416 433 369 401 377 398 401 401 381 387 390 420 343 363 415 398 393 382 370 378 357 397 371 373 392 393 360 388 414 345 355 362 366 375 390 422 385 402 349 379 395 409 423 400 364 378 376 386 366 406 391 397 391 348 390 383 382 400 401 406 380 384 356 393 404 399 411 394 392 409 362 382 362 399 384 437 317 388 370 390 393 438 374 370 393 368 352 368 361 367 419 400 368 390 369 417 385 373 386 365 375 394 379 403 377 355 381 373 409 401 347 371 349 364 396 384 346 345 354 412 391 371 373 393 349 362 361 388 384 386 345 344 351 356 387 368 362 363 391 395 363 351 358 377 369 367 369 363 362 367 358 390 366 362 382 391 366 383 340 368 359 389 375 353 348 362 340 377 360 340 372 383 354 356 368 383 392 401 357 363 368 338 375 361 363 372 363 375 369 376 352 355 379 364 354 336 371 362 360 352 346 368 330 366 357 382 347 391 328 361 376 331 350 361 369 316 359 342 346 370 373 342 386 396 359 350 343 318 313 352 341 333 326 315 350 338 328 330 370 337 351 351 342 353 354 311 337 342 337 337 354 338 347 359 340 351 323 374 356 333 370 311 368 366 315 356 368 323 373 354 343 323 324 345 369 342 360 352 336 330 364 311 332 355 339 316 315 325 353 327 337 350 367 339 340 344 364 329 364 342 329 347 306 346 322 314 360 330 342 371 321 314 314 325 328 347 350 350 325 342 311 336 319 357 358 331 353 324 320 309 332 357 341 336 314 355 333 333 368 335 326 317 308 340 322 327 290 304 323 342 333 299 307 352 345 319 309 330 284 314 320 326 336 330 293 320 340 325 331 345 309 347 337 321 338 345 343 350 340 313 329 325 334 310 348 308 366 344 337 322 342 297 303 321 319 286 321 307 294 319 318 324 338 337 305 308 303 300 335 330 306 325 331 341 348 329 337 309 302 313 331 352 352 304 327 317 303 315 346 316 323 323 297 326 295 318 325 309 314 330 327 320 320 317 308 303 306 322 286 302 282 338 294 296 316 296 322 301 287 321 299 306 276 288 272 303 326 305 293 328 283 292 300 274 308 289 311 306 318 297 301 320 320 296 295 308 283 277 346 301 266 335 286 295 326 320 303 355 335 264 317 317 303 327 311 302 324 300 284 284 303 297 333 296 311 263 311 304 279 332 303 281 321 303 306 321 326 300 277 318 310 336 301 296 302 309 286 317 309 294 332 275 316 303 269 282 300 301 284 301 316 318 308 324 305 303 338 279 297 299 316 301 291 328 316 277 307 298 272 309 286 281 281 314 287 269 292 281 286 292 297 331 276 299 303 310 307 299 288 308 287 315 285 290 336 294 306 283 316 291 288 322 275 265 271 300 279 288 296 270 294 326 282 281 296 317 286 242 290 296 276 277 292 285 313 268 308 276 298 305 260 288 271 270 298 307 307 311 285 333 264 294 284 311 290 284 293 286 314 305 274 279 304 262 289 322 280 286 299 282 289 322 304 291 312 302 289 292 321 303 280 248 294 270 289 270 307 270 270 294 279 272 297 336 266 277 294 301 296 258 329 318 281 281 288 304 295 284 248 261 284 291 315 339 303 305 298 320 311 299 296 282 293 311 293 281 257 269 258 327 285 309 293 290 286 283 271 295 265 296 332 296 294 283 302 276 314 306 284 279 320 320 276 259 283 248 282 286 280 286 293 325 300 278 283 302 292 298 315 275 281 285 307 303 281 282 301 326 298 270 325 296 310 302 303 293 308 267 300 267 312 288 271 290 302 325 293 296 298 277 305 290 287 296 302 281 301 275 331 319 331 324 296 292 284 309 261 272 261 287 316 293 302 269 312 341 288 291 316 319 282 314 275 270 309 298 303 293 313 285 314 307 295 276 307 294 292 307 320 294 296 286 288 272 277 270 298 288 279 290 316 313 275 302 273 287 308 289 303 310 311 304 290 287 293 296 271 311 304 261 286 297 280 305 288 260 305 300 321 298 311 282 267 310 289 304 281 277 320 241 285 300 294 257 288 274 297 277 316 309 330 281 288 302 274 299 276 267 295 298 293 309 313 318 310 276 299 296 321 262 297 300 288 295 290 258 340 301 296 301 345 298 312 276 309 306 307 297 308 308 321 290 286 317 300 289 311 325 289 293 308 319 293 298 321 302 306 299 278 296 266 304 284 293 304 304 285 281 325 307 313 295 296 283 288 310 311 292 301 312 314 312 312 304 297 304 293 318 312 278 290 297 285 308 317 322 308 289 322 298 314 295 296 348 289 291 279 308 282 321 318 278 304 302 320 260 299 300 315 295 331 319 344 307 296 305 268 330 331 327 284 330 341 303 325 290 303 310 306 290 304 302 307 319 308 319 319 305 303 322 301 321 296 307 297 299 306 303 309 315 272 294 309 305 280 308 294 311 304 323 294 312 308 324 327 308 279 315 309 279 311 305 299 287 312 308 291 311 310 335 318 310 291 287 308 308 287 303 311 314 294 319 315 290 311 291 291 329 300 311 300 300 296 297 301 314 310 288 312 295 323 306 316 301 294 282 310 305 320 314 317 272 264 287 318 310 303 309 307 316 299 325 294 310 319 303 285 289 302 288 298 302 306 318 276 307 289 313 305 328 305 330 314 288 285 295 316 334 291 292 279 307 300 295 288 306 302 298 308 304 269 290 297 315 316 306 300 291 272 291 270 297 303 333 286 324 281 330 309 315 277 288 280 285 305 292 289 278 316 313 309 281 271 311 323 312 309 305 336 332 326 305 306 307 301 322 293 295 316 314 304 295 311 298 286 297 299 302 279 277 315 318 337 285 322 308 332 309 284 329 322 321 300 317 329 303 323 294 312 321 291 299 298 299 333 308 283 308 321 322 292 296 281 285 318 295 280 297 300 311 283 317 301 292 302 288 293 290 311 322 326 287 272 306 298 246 277 299 291 295 329 320 301 310 310 279 295 298 294 319 284 263 265 304 288 306 274 300 281 316 309 280 296 285 312 298 284 295 301 308 300 326 301 317 295 308 314 293 328 292 315 283 329 271 287 328 304 309 312 290 287 304 279 311 290 277 296 285 283 308 304 266 291 313 260 284 282 322 281 271 323 297 281 304 257 288 293 302 259 272 289 288 293 302 296 296 278 320 294 286 270 284 271 282 299 263 307 280 271 264 317 277 291 303 249 292 291 300 283 264 310 277 295 286 262 287 298 295 331 285 293 275 267 261 263 285 306 276 282 321 306 279 287 277 284 273 232 304 268 287 297 281 294 299 295 284 267 270 297 288 293 292 248 301 274 311 276 311 263 285 309 267 271 275 281 284 280 268 282 291 282 277 290 256 287 291 304 294 299 298 287 279 310 261 269 247 288 236 267 273 294 299 270 279 286 316 310 278 280 320 289 277 308 294 274 291 294 294 273 288 246 271 219 304 278 272 286 306 290 259 283 284 264 261 277 267 264 302 267 269 281 277 307 297 257 255 285 309 270 277 266 290 323 238 289 296 276 285 282 291 285 267 281 292 239 273 263 284 263 274 291 242 245 268 291 280 275 271 269 257 268 226 280 259 271 264 249 270 263 284 265 289 256 288 282 242 227 272 275 276 268 247 297 274 286 266 238 247 255 295 260 249 267 278 277 278 255 274 270 299 277 297 235 238 285 275 276 284 257 265 283 238 246 279 275 265 315 258 278 256 266 281 232 240 271 250 278 240 290 275 275 286 249 265 241 271 246 269 242 273 241 282 270 276 301 268 298 284 293 258 256 272 241 271 249 287 269 270 279 245 245 269 247 261 278 264 286 240 287 235 273 242 223 256 246 265 283 240 276 286 263 267 287 283 272 290 247 263 231 265 262 238 241 272 243 260 237 255 278 244 238 228 250 270 255 263 285 280 262 272 260 249 269 262 265 260 255 232 259 257 240 266 256 246 242 246 273 255 280 266 248 246 259 280 237 238 239 246 214 248 234 262 241 247 263 224 255 275 255 273 275 247 244 245 274 257 245 250 237 278 262 225 259 245 290 247 274 257 276 247 259 232 258 246 228 287 281 281 246 278 241 262 279 292 249 227 258 217 268 223 236 268 264 247 233 199 243 272 245 245 277 261 221 264 258 231 255 245 250 257 241 276 263 235 272 264 272 250 239 273 247 235 246 248 247 262 249 244 226 256 276 245 272 240 262 244 258 234 241 232 262 257 238 244 262 260 245 242 265 234 230 216 272 247 245 236 274 258 232 259 235 238 224 249 257 266 241 239 258 238 258 227 272 257 228 243 260 262 211 245 237 256 235 235 230 229 245 259 235 283 223 226 255 217 255 248 248 212 211 260 260 236 265 263 242 235 216 237 239 241 237 239 255 247 239 215 250 236 260 242 268 244 224 235 256 247 243 231 247 264 242 223 215 244 229 255 237 230 244 243 258 241 224 244 235 235 260 242 228 224 255 245 233 209 262 233 272 267 228 234 233 237 239 215 284 239 224 262 220 262 260 248 257 239 257 257 265 211 259 236 238 213 223 240 236 263 249 240 230 257 222 240 204 233 241 244 264 230 246 256 242 246 239 234 259 255 291 247 236 259 249 257 230 242 241 226 256 231 224 237 227 231 244 258 222 269 261 236 272 214 228 249 247 265 231 256 265 233 237 236 242 246 256 246 266 263 283 247 229 241 244 243 278 231 243 279 260 264 237 231 267 228 228 234 233 240 270 239 239 239 231 259 232 234 245 244 275 227 244 239 258 221 239 231 212 244 245 248 266 227 256 247 234 226 235 204 233 255 213 242 238 233 218 256 259 245 229 236 284 208 238 261 274 234 236 233 213 241 230 230 243 221 256 255 266 219 231 241 245 263 248 280 237 234 240 238 246 225 236 222 245 211 242 227 216 194 239 208 258 215 234 240 285 265 242 230 232 230 238 270 215 262 230 248 285 246 234 226 227 250 225 237 259 249 248 247 215 229 216 248 233 223 232 217 244 257 243 242 259 224 228 248 257 240 215 222 221 250 240 220 229 234 222 229 239 230 240 265 214 259 249 222 207 245 246 232 219 271 204 204 231 236 263 244 210 190 241 220 237 273 256 237 245 227 237 229 233 266 239 258 241 238 235 234 229 220 222 236 246 228 238 220 247 248 235 230 258 258 246 256 241 216 219 243 206 264 249 261 235 244 235 238 192 249 234 243 225 234 218 236 233 221 233 230 230 239 224 242 227 223 229 241 232 207 211 231 244 236 236 240 224 249 213 202 234 218 185 226 235 243 227 224 220 243 218 222 219 219 234 260 239 216 238 230 256 218 241 220 222 226 220 236 246 229 224 244 229 216 204 198 244 239 225 203 215 227 223 241 233 240 233 228 236 229 215 231 223 232 260 239 228 229 207 232 235 239 241 260 248 225 211 219 225 203 229 242 231 237 229 243 242 245 208 198 210 218 206 231 243 228 258 233 249 201 241 221 221 225 237 234 210 235 242 230 230 220 188 201 233 239 221 214 223 233 258 241 224 216 212 243 240 225 196 217 203 239 249 229 220 206 217 245 240 230 245 231 230 222 221 241 203 223 231 206 237 244 208 215 225 217 270 261 220 207 203 229 211 209 239 247 217 204 229 249 243 207 231 228 219 229 239 215 213 212 179 249 222 211 226 224 257 264 219 228 242 230 240 228 234 242 247 216 243 227 237 205 222 212 237 222 233 232 223 203 233 206 230 238 231 267 244 236 238 239 216 232 239 227 228 229 224 223 240 250 210 211 210 228 233 216 213 235 230 200 220 197 197 237 239 194 207 218 195 227 232 229 191 230 208 231 222 237 238 216 214 225 223 224 227 199 214 243 219 239 220 225 213 207 225 222 227 227 227 204 225 202 209 196 244 218 216 203 226 231 206 231 239 220 219 228 231 205 195 246 236 226 219 217 237 262 228 227 234 261 235 222 219 234 217 259 281 264 273 233 267 244 242 245 241 218 233 211 263 243 240 212 233 231 242 230 236 246 241 228 232 233 263 220 256 258 240 229 228 214 229 260 245 237 242 233 208 213 249 192 212 244 218 211 184 196 211 234 226 209 228 235 231 235 224 257 235 228 220 209 238 226 202 201 216 226 217 232 235 243 220 200 226 222 197 197 211 215 209 224 204 234 218 244 249 198 213 195 237 237 209 193 238 225 196 232 207 232 216 215 225 223 209 241 210 196 219 218 199 217 234 192 205 230 230 225 208 204 234 198 260 245 241 194 190 206 213 206 208 232 215 230 212 223 219 207 227 244 212 222 220 196 203 217 233 217 206 215 196 231 232 210 223 231 208 245 205 225 212 224 238 221 240 240 218 217 208 225 242 216 220 221 233 183 228 204 224 233 238 213 212 225 214 207 213 224 205 232 216 215 249 194 200 246 239 246 216 216 226 208 224 233 221 184 211 263 202 234 208 234 201 228 239 188 213 232 225 218 224 197 235 214 191 207 232 229 222 212 210 220 244 202 202 197 217 222 225 209 227 220 218 207 195 219 216 206 221 244 249 220 215 232 212 221 228 208 219 232 232 255 210 215 191 246 220 231 238 213 212 216 237 236 222 206 221 215 228 233 230 219 233 246 231 198 215 223 212 230 231 218 232 221 223 210 225 232 216 240 217 230 206 229 260 224 209 212 217 198 240 226 217 225 220 189 218 227 224 194 237 208 221 238 258 220 241 208 190 190 220 215 208 229 237 205 214 223 247 216 225 220 225 201 218 219 226 222 193 205 223 236 231 235 224 256 241 212 215 225 229 211 217 222 249 249 205 244 206 213 247 226 234 206 236 234 224 230 229 222 229 219 226 215 208 208 222 201 219 193 209 230 232 221 239 204 216 219 222 226 203 198 227 229 229 220 216 232 179 229 248 227 224 186 225 227 214 231 236 241 211 232 228 222 186 224 191 231 239 208 225 213 224 230 238 259 209 232 237 229 201 213 221 222 235 231 239 274 218 213 223 225 257 197 242 218 220 224 225 247 208 249 234 225 235 213 209 232 224 243 225 223 237 233 272 216 238 268 238 214 213 224 240 230 241 225 227 231 239 194 215 234 205 247 217 231 238 229 214 245 258 265 248 216 197 206 237 215 233 233 228 241 201 210 255 222 221 246 208 245 243 207 243 202 229 218 215 245 248 226 240 234 215 245 221 232 228 206 226 196 242 202 257 241 235 206 213 256 227 245 226 266 230 221 212 194 231 209 220 281 215 225 241 214 234 259 233 227 230 221 243 213 236 224 211 232 230 205 220 258 229 219 214 238 236 222 247 228 211 213 237 229 246 214 239 215 228 231 236 213 212 246 263 266 217 224 224 245 217 265 230 238 211 236 257 230 212 232 238 231 219 235 258 237 234 238 237 216 223 264 232 234 257 219 257 213 247 237 241 244 219 225 211 242 246 220 246 231 246 235 211 276 265 215 222 234 239 270 264 220 232 215 232 265 260 261 227 259 246 229 209 240 247 241 237 281 249 250 205 245 244 239 223 229 263 212 225 264 228 246 237 248 255 238 240 261 245 277 272 259 275 265 267 269 255 217 264 278 261 241 230 267 271 246 277 232 249 276 255 266 281 288 287 273 248 292 286 297 298 289 294 264 297 281 310 326 311 329 324 311 328 349 356 359 361 369 410 354 383 406 353 391 375 425 440 416 433 420 399 389 439 457 412 382 380 398 402 396 366 351 372 351 337 382 333 326 323 318 291 289 297 306 297 261 278 323 287 314 289 315 266 270 269 267 257 270 260 244 238 279 282 229 273 245 267 291 241 232 280 217 268 278 239 247 219 221 225 246 222 227 270 235 228 255 221 241 246 237 270 256 255 257 230 218 216 249 236 227 237 263 231 241 255 206 233 243 229 231 232 206 225 232 233 235 239 245 232 223 238 201 256 235 227 200 240 211 230 227 242 216 227 256 217 227 232 236 244 245 231 227 230 217 243 247 239 264 240 238 220 235 236 208 218 258 227 220 239 235 229 224 219 258 240 215 193 216 232 221 229 232 236 209 246 224 216 231 217 215 235 232 234 236 241 240 234 190 234 228 257 240 262 234 212 225 221 244 224 238 223 214 221 212 221 238 217 257 223 239 236 227 248 233 235 240 227 235 234 237 242 268 232 223 261 231 233 232 236 240 243 245 218 239 223 247 255 202 247 218 215 244 227 259 241 231 228 206 218 215 224 223 257 241 241 218 217 257 247 233 231 208 233 231 243 217 230 245 227 233 225 227 238 241 219 199 223 240 230 217 233 230 220 235 207 240 229 228 220 240 222 224 227 257 206 228 233 219 219 230 237 249 258 246 229 255 242 244 271 198 219 259 219 195 229 207 233 201 218 227 223 232 216 237 235 229 221 244 264 206 222 199 224 206 239 229 238 238 237 243 217 233 236 265 237 235 218 231 249 236 215 246 233 214 237 212 195 222 220 213 229 238 243 237 213 229 243 225 228 230 238 229 219 223 223 229 211 226 233 208 234 245 240 246 214 223 256 220 256 234 227 211 224 214 224 226 243 234 220 218 217 233 240 210 225 257 237 245 224 237 244 228 235 230 260 262 203 210 240 255 244 198 220 219 247 246 227 260 233 239 221 231 200 265 211 242 203 229 226 208 239 232 228 231 228 233 223 240 243 238 222 246 224 189 231 231 229 209 228 205 216 210 217 215 234 263 238 214 276 217 227 233 228 213 262 234 228 235 221 211 218 220 217 222 205 243 227 242 244 207 223 218 226 207 231 237 249 238 210 234 260 232 224 208 207 230 223 242 228 210 247 216 235 211 264 237 219 229 247 216 229 249 188 228 206 215 224 232 255 245 229 207 243 236 216 183 212 224 216 227 233 225 232 255 216 208 257 259 242 233 242 222 201 227 232 202 243 233 237 245 220 233 225 224 224 208 221 217 203 268 228 236 242 235 218 220 227 239 221 224 225 225 250 215 224 248 209 250 235 219 226 264 246 218 271 224 234 224 246 234 217 245 236 233 212 207 236 208 237 225 232 203 230 248 210 231 238 222 241 259 223 241 237 234 198 234 212 223 229 206 230 257 242 248 237 217 221 205 237 247 249 226 243 241 214 215 206 231 271 237 183 231 243 228 235 196 212 215 232 210 196 290 216 230 236 223 214 225 228 222 229 243 219 231 236 234 227 207 202 246 268 218 232 217 221 234 257 233 231 228 241 214 222 216 240 227 232 226 229 217 231 215 236 234 236 237 229 241 223 220 242 192 216 237 220 220 210 226 212 257 207 256 211 240 232 229 238 238 240 218 211 213 240 243 226 232 213 221 235 248 206 212 228 206 198 241 238 207 221 197 248 231 236 224 226 208 203 207 227 219 228 217 244 216 196 231 222 220 230 212 211 231 210 242 231 211 218 246 196 222 220 218 228 249 233 212 218 214 219 223 235 225 242 229 231 230 216 214 257 241 220 242 233 230 234 216 206 223 233 231 196 205 229 224 210 197 227 227 224 229 222 218 210 225 235 271 225 215 233 247 220 211 229 225 239 223 228 234 223 203 225 218 211 240 205 221 232 217 227 227 235 223 226 236 236 219 237 214 218 206 206 257 214 209 259 209 242 245 224 234 210 231 234 241 209 204 237 181 216 232 232 221 273 227 228 235 237 242 225 208 227 232 226 229 244 241 206 216 212 227 216 212 243 213 219 223 224 230 236 208 231 197 202 255 227 220 232 199 218 201 228 192 258 224 205 216 230 227 213 217 223 244 214 199 221 209 210 236 221 247 237 226 214 233 230 255 219 241 243 209 239 203 227 263 215 234 241 232 238 203 225 200 235 222 222 227 231 220 219 230 226 226 221 226 236 234 212 219 255 216 250 217 238 230 207 210 214 256 235 213 227 240 220 219 216 222 249 228 217 213 233 235 234 205 214 217 201 242 226 233 211 190 208 232 209 225 216 222 219 223 263 208 208 244 239 205 236 222 231 218 216 219 229 217 229 238 234 216 228 233 232 235 222 208 232 218 204 229 241 214 222 229 221 228 239 214 228 228 206 209 224 213 237 225 197 231 231 203 218 222 245 242 222 223 206 223 212 215 200 218 221 231 215 232 223 220 232 214 209 272 246 211 222 248 216 226 218 193 218 230 224 247 207 213 230 215 225 225 216 205 225 227 218 219 231 230 226 249 201 242 230 211 217 228 230 239 221 221 193 213 221 218 220 243 230 217 204 217 215 246 222 217 240 206 224 213 204 238 206 225 232 238 242 212 202 263 229 234 218 236 215 243 218 224 216 243 222 259 260 233 241 222 228 238 217 228 235 220 245 210 224 229 232 237 240 223 223 228 240 220 243 242 225 222 231 208 213 218 232 239 190 230 256 219 228 213 244 222 217 212 228 222 229 231 238 216 235 262 209 230 227 227 234 242 247 202 230 223 233 209 224 237 208 219 222 238 224 258 192 217 219 208 204 224 233 233 222 232 240 226 244 191 221 191 202 215 225 212 245 222 224 221 243 202 238 220 226 212 223 241 241 222 239 257 230 239 228 222 237 267 193 218 209 211 228 255 227 260 241 226 243 220 245 209 226 221 208 232 206 215 235 219 224 241 228 231 226 217 218 242 234 211 245 220 232 224 247 223 223 224 262 202 228 218 228 221 229 243 266 236 211 240 224 222 221 226 276 221 212 230 234 242 247 233 221 245 230 222 233 272 228 258 230 234 214 215 228 241 245 239 244 222 221 215 201 240 227 249 218 194 215 226 227 223 260 239 248 207 208 233 224 225 232 230 258 235 245 212 221 213 245 226 210 223 205 218 204 232 223 204 240 203 224 227 185 223 232 242 208 245 213 235 231 230 246 233 205 210 216 234 226 226 215 273 227 225 244 247 243 247 214 197 218 210 214 244 203 234 223 226 225 235 200 198 236 217 229 228 240 232 215 214 195 232 200 233 248 240 213 264 212 220 243 211 259 255 218 224 215 233 214 228 245 240 233 228 211 210 188 218 212 244 255 219 271 220 217 205 219 234 212 217 237 222 225 209 223 238 225 229 240 211 261 229 233 221 204 216 222 258 244 225 221 248 249 256 231 260 225 222 215 237 229 225 233 268 260 238 219 255 212 255 217 215 227 264 195 241 229 200 217 214 231 240 232 239 227 226 226 214 243 237 215 227 218 203 237 209 220 236 261 218 221 237 248 232 220 248 211 270 233 269 231 226 199 211 203 275 227 213 229 221 221 227 237 241 237 225 230 241 239 241 223 278 247 227 258 229 244 221 208 241 210 219 241 233 217 223 196 207 230 219 237 237 217 218 227 229 237 242 237 211 224 224 226 233 250 218 206 229 237 218 236 244 229 224 246 220 211 246 243 249 205 220 269 260 246 229 205 220 231 243 237 214 249 224 259 213 238 216 233 229 240 256 237 229 220 246 215 246 214 201 215 249 189 214 255 240 234 217 230 257 234 222 202 230 229 218 212 222 203 200 232 223 225 226 222 235 230 224 248 236 202 223 202 246 223 220 237 234 213 249 236 228 245 238 205 256 222 238 229 228 242 245 237 216 226 196 215 231 233 222 234 212 219 211 212 232 259 244 221 287 221 217 211 222 259 258 224 247 241 240 225 210 238 215 236 218 227 236 259 227 234 235 235 234 217 217 241 230 256 255 235 256 229 239 248 225 240 238 229 224 215 204 245 218 213 224 238 246 237 211 255 207 216 243 246 244 217 261 240 238 225 222 202 216 224 230 219 249 231 216 222 224 238 255 240 216 209 244 226 232 220 224 231 264 213 249 205 260 260 258 238 220 228 240 238 255 246 262 206 222 214 258 241 242 249 228 232 213 220 226 243 235 245 225 215 226 231 222 256 209 247 232 249 241 230 207 264 275 238 234 235 276 260 241 239 220 236 238 231 221 270 232 257 223 217 224 219 228 219 250 222 204 241 256 250 278 219 214 224 245 290 236 222 231 231 237 229 235 274 214 233 235 244 288 219 213 235 208 267 196 249 221 195 209 234 261 234 236 228 244 266 217 228 235 264 227 211 237 235 209 243 235 224 229 240 250 241 239 223 248 264 268 221 255 226 224 248 240 245 220 241 247 237 217 240 246 221 215 256 237 235 213 232 273 231 219 247 213 256 249 225 215 232 256 243 243 225 236 242 226 236 277 236 230 208 210 244 226 263 244 208 240 229 225 243 231 274 232 244 238 256 238 234 237 239 232 243 221 223 232 223 243 238 243 214 271 230 241 220 235 257 266 247 264 245 229 229 243 208 257 270 262 216 241 291 228 245 236 255 282 269 239 236 226 260 230 242 247 259 235 237 235 229 263 217 241 222 250 255 246 261 265 228 248 235 240 215 263 232 271 246 272 241 221 267 228 244 256 245 269 264 269 262 266 240 256 255 242 224 231 275 215 243 243 256 262 269 257 237 266 255 236 263 255 260 227 214 259 242 244 248 238 245 241 241 248 256 231 229 287 236 261 260 260 245 260 226 264 240 265 229 220 243 233 225 247 273 242 273 246 247 229 235 275 274 217 249 230 225 232 233 244 264 250 242 232 256 245 247 241 260 209 267 219 233 266 238 235 249 243 257 267 241 264 235 238 235 266 241 227 269 249 257 224 243 263 266 229 259 235 241 235 226 246 249 243 241 210 255 235 232 268 264 236 241 258 243 245 248 231 233 209 243 219 227 248 224 257 231 276 213 238 224 239 247 229 240 242 246 257 260 205 235 258 243 243 236 233 242 226 241 230 223 244 230 236 234 221 219 225 239 227 263 214 230 231 235 269 230 233 238 275 248 243 236 240 255 242 218 225 246 264 215 232 216 230 255 228 271 276 210 267 216 266 258 250 225 224 241 262 211 248 235 222 243 233 234 233 247 230 255 248 243 217 277 223 233 243 242 241 239 232 237 229 243 262 243 217 245 220 260 226 214 245 237 212 258 232 228 214 222 266 241 191 245 235 244 273 241 263 244 224 248 257 264 246 261 257 222 207 258 227 244 269 273 263 223 223 258 261 243 207 246 240 224 240 259 220 239 244 249 236 214 196 211 209 224 249 217 256 237 277 260 214 264 218 219 234 213 212 220 214 222 235 247 244 237 215 261 246 228 276 255 200 229 215 227 237 243 193 224 246 237 261 222 248 223 243 222 223 242 239 226 221 264 227 262 236 256 219 224 219 216 260 271 234 238 218 198 247 248 231 223 242 227 240 228 228 214 267 237 208 255 225 225 231 226 199 240 221 226 260 217 213 230 233 237 259 226 267 234 255 216 239 236 226 224 260 235 234 236 227 247 273 234 238 234 215 234 256 262 239 257 216 233 230 223 222 224 230 256 234 235 232 271 274 266 248 260 248 229 261 221 234 222 234 219 204 234 204 225 219 209 219 237 232 227 222 222 248 277 256 234 245 250 211 231 261 248 218 257 237 229 220 245 232 269 234 240 242 236 227 221 241 236 210 263 218 220 224 240 259 261 229 223 213 231 226 223 262 255 266 227 260 247 216 244 248 228 255 265 227 229 231 257 225 232 269 236 218 240 224 234 224 217 233 267 241 236 243 222 248 244 235 269 245 232 238 235 243 225 276 213 212 264 278 262 224 238 257 268 243 232 275 242 237 244 215 234 219 210 219 229 257 203 226 224 233 234 235 264 248 265 238 230 244 216 236 220 242 231 239 284 228 246 229 232 263 259 211 217 204 257 241 228 235 259 221 268 255 232 222 246 231 211 240 261 225 244 223 247 214 235 239 239 241 230 234 223 235 245 248 215 206 262 232 234 206 258 222 230 230 225 240 245 256 255 232 255 228 213 250 246 243 276 225 246 256 245 218 232 255 260 236 229 259 237 199 262 197 256 248 228 232 263 233 263 234 255 241 234 222 250 219 231 235 274 222 243 244 232 201 246 241 237 214 239 229 234 242 227 229 213 211 244 238 232 240 220 278 192 230 263 246 231 233 233 262 211 234 213 236 245 255 214 236 228 242 240 227 247 244 195 222 231 229 267 240 230 229 238 256 222 258 241 229 208 257 241 258 259 270 217 246 225 230 259 246 231 242 210 237 246 241 226 258 272 232 217 236 241 230 233 245 230 205 231 257 264 221 263 247 236 246 230 202 204 225 240 224 226 230 262 240 227 244 256 220 226 230 247 263 225 231 235 222 247 239 249 247 233 238 246 214 249 263 220 258 258 212 263 233 227 249 245 233 230 229 257 256 244 231 258 247 189 261 267 218 219 269 225 245 235 244 231 222 235 242 204 233 224 226 211 240 237 221 250 221 238 266 227 219 258 244 228 241 221 226 257 234 224 239 228 226 234 245 239 249 255 244 232 227 236 227 214 214 233 229 232 264 216 227 250 255 228 232 262 237 225 237 210 222 243 241 236 246 237 249 196 203 240 233 235 259 214 248 227 244 234 259 234 220 241 233 258 256 233 230 238 217 238 246 231 219 247 220 258 259 248 205 260 255 249 263 232 245 229 246 192 218 260 221 239 215 233 216 236 245 255 243 265 265 244 227 236 235 230 237 230 224 247 266 257 248 247 212 222 257 234 257 219 242 247 218 211 235 246 247 244 261 269 222 230 255 207 258 244 266 210 224 243 256 225 229 238 236 243 235 259 225 239 244 257 236 264 246 243 210 219 236 232 265 224 228 232 242 206 255 236 239 211 225 224 261 228 240 239 235 233 224 234 222 239 238 245 244 248 260 223 219 240 222 257 231 223 225 258 256 243 255 262 234 247 248 229 272 241 247 247 233 264 266 238 250 235 277 234 238 238 264 243 237 259 226 250 245 244 226 256 235 230 241 249 232 256 243 266 210 211 241 224 239 245 288 226 238 236 209 259 266 267 255 244 225 229 227 209 238 247 235 222 231 245 227 227 225 222 228 244 237 257 259 263 245 220 238 240 259 247 235 237 236 263 238 228 233 227 240 236 246 210 218 219 247 240 228 232 272 232 226 218 236 218 223 221 273 234 243 226 264 224 242 235 195 228 241 246 234 206 234 203 228 221 219 224 216 245 262 238 272 247 214 235 245 263 268 244 231 269 224 226 255 239 237 263 227 240 234 260 234 250 234 256 242 225 241 249 218 243 238 195 238 226 241 240 220 230 216 262 227 237 239 248 269 212 256 235 239 220 235 255 249 280 234 240 236 235 249 247 226 234 243 212 228 244 264 241 220 232 238 236 247 257 242 210 287 263 233 237 230 250 245 231 270 221 221 232 222 245 244 235 218 229 199 284 225 233 231 256 234 270 256 261 207 248 232 270 232 231 209 227 233 236 250 211 292 240 221 216 260 232 261 228 236 237 222 243 239 249 242 246 226 258 242 214 208 261 234 229 236 241 214 255 249 231 227 230 257 237 235 216 215 210 236 223 243 228 261 238 238 250 235 272 269 212 215 257 245 229 260 235 229 232 259 244 234 225 247 243 246 259 257 240 237 210 206 218 233 255 234 259 223 234 263 287 233 246 230 223 224 244 261 250 240 276 243 244 255 269 268 235 246 249 227 258 226 206 240 235 210 234 210 256 256 239 230 243 215 247 236 223 223 241 221 246 241 231 243 241 227 243 240 228 222 239 229 264 243 256 266 217 239 206 240 237 235 215 238 243 239 247 218 241 213 231 239 255 228 265 239 219 208 221 237 257 261 232 239 228 230 224 258 269 215 229 285 245 234 245 220 230 223 237 231 243 211 244 279 259 267 270 239 266 235 244 238 223 214 268 244 223 255 210 236 236 216 238 221 246 238 245 218 232 268 235 260 255 259 235 226 233 249 221 243 240 230 284 237 269 242 229 222 247 232 207 242 257 237 237 242 232 229 229 238 242 223 238 229 248 235 230 227 265 266 240 248 263 239 233 233 220 248 244 269 230 244 232 233 230 210 236 243 215 262 236 262 243 264 230 250 235 228 263 245 241 203 242 262 232 208 255 230 235 271 255 228 234 275 224 246 225 236 232 249 245 228 216 280 260 231 244 230 241 216 227 258 245 225 237 267 255 227 237 220 240 248 227 230 256 222 261 229 271 239 233 209 237 242 255 261 209 225 242 241 240 216 218 266 233 238 259 265 208 237 220 265 243 239 248 257 276 228 244 224 242 243 232 215 268 243 268 225 257 210 278 267 240 233 243 244 256 222 218 260 204 240 256 249 204 259 244 272 236 261 256 243 245 214 272 248 238 249 246 260 248 239 250 259 275 235 228 257 229 257 243 282 246 237 276 262 258 232 257 241 279 244 255 284 242 240 259 265 255 235 233 264 236 266 243 229 274 255 248 267 280 235 277 274 270 261 235 242 247 218 232 265 249 270 274 244 277 307 266 289 273 286 259 277 282 279 259 280 268 291 235 275 262 278 297 238 294 272 275 274 271 283 285 282 255 279 274 286 288 290 269 287 282 283 283 274 290 288 249 270 280 264 278 280 266 260 257 245 267 270 233 278 270 256 281 248 246 242 287 244 246 223 223 243 242 264 262 270 257 265 267 242 235 257 255 249 264 260 245 230 229 206 244 239 259 246 220 229 237 267 263 240 256 231 240 231 240 234 265 247 280 227 232 232 242 262 258 244 256 230 257 232 238 222 280 247 230 229 269 228 246 225 248 242 267 238 270 265 239 242 260 265 239 241 229 231 201 260 202 262 255 258 291 245 281 237 236 245 239 242 232 247 273 229 262 239 246 257 235 225 260 259 234 236 223 231 290 234 249 269 248 257 224 261 238 266 280 194 272 260 263 244 240 230 232 255 244 273 222 225 246 238 244 234 250 248 259 244 219 263 271 271 234 270 261 279 274 226 227 225 247 240 238 243 232 227 243 244 231 216 244 223 249 258 235 235 260 268 246 229 267 219 261 214 232 262 223 263 261 248 228 243 231 259 248 260 223 242 246 236 221 239 224 218 224 228 216 238 244 222 225 260 217 256 262 220 230 242 211 230 238 227 256 242 216 261 262 214 238 239 225 225 281 268 256 241 278 269 237 255 205 248 229 225 248 268 224 229 206 232 245 255 205 249 227 242 248 249 212 223 270 240 242 260 243 245 240 229 263 249 249 224 228 255 244 260 232 256 232 242 225 235 240 236 245 261 270 235 226 229 228 239 235 225 237 213 232 250 241 239 229 232 242 246 225 258 249 187 255 229 236 244 231 262 200 236 260 245 260 261 233 246 276 239 240 233 230 242 222 232 264 236 235 265 240 261 247 245 233 256 227 260 262 269 216 239 226 246 225 245 260 230 248 243 213 265 231 240 230 248 239 246 218 246 232 231 241 215 218 258 245 238 270 210 223 225 263 237 234 215 240 243 240 240 230 247 257 222 259 255 235 235 246 210 244 198 268 247 275 277 260 271 262 223 245 269 240 209 263 256 258 273 226 275 211 217 224 232 220 214 255 267 246 231 225 225 230 276 268 240 234 242 242 245 265 246 260 236 215 230 225 258 236 237 239 248 239 246 286 229 236 244 259 237 269 213 257 262 211 237 258 231 227 221 243 226 236 263 258 263 222 262 243 271 265 237 256 267 228 270 221 241 225 224 261 275 229 235 236 264 244 250 214 258 260 226 260 241 220 239 230 273 249 246 226 238 228 229 246 244 259 262 262 234 269 222 218 229 225 241 235 268 225 238 282 243 242 234 248 255 256 249 258 246 280 200 265 240 238 248 243 222 244 230 235 241 240 231 263 242 216 234 239 229 233 242 258 258 245 245 259 244 247 242 234 262 239 232 237 206 246 224 264 234 250 242 246 235 212 228 256 265 249 268 261 233 269 272 258 247 242 249 248 220 241 246 259 218 275 255 231 256 235 213 265 225 238 235 215 237 262 237 234 237 238 246 220 260 255 239 257 220 261 255 269 248 240 256 245 204 227 238 228 279 259 242 269 228 241 285 216 235 249 241 207 228 262 257 233 256 262 224 264 203 220 289 238 244 262 240 258 281 241 216 244 240 233 213 241 232 228 258 233 235 226 282 229 231 231 240 276 237 268 242 225 255 255 245 265 243 224 240 258 229 256 242 233 225 228 259 238 237 268 264 236 243 235 240 229 234 246 219 246 227 229 239 270 206 267 229 239 233 256 241 242 236 240 226 217 258 238 219 272 234 246 238 247 240 256 226 229 257 248 237 260 243 240 247 238 228 255 231 224 237 221 228 256 229 229 244 287 234 224 227 277 238 240 268 244 258 210 245 271 272 267 249 235 245 265 257 261 236 248 223 242 228 235 241 256 242 248 285 232 249 240 241 240 230 213 247 225 237 281 236 223 239 233 250 239 266 257 227 210 264 260 243 241 241 274 232 243 213 245 239 265 264 229 201 246 238 258 249 242 228 233 231 246 272 247 255 261 246 245 233 221 228 223 235 258 245 242 260 201 245 210 213 241 268 239 249 244 237 226 247 220 264 218 256 234 260 205 230 202 236 232 272 203 220 228 244 258 232 244 249 240 215 232 238 226 267 259 245 248 235 245 248 242 209 240 233 238 235 224 223 231 211 269 255 256 271 238 212 227 273 227 236 238 234 225 236 222 219 237 233 239 222 224 242 241 241 204 241 213 226 221 256 229 230 272 226 214 216 257 243 193 222 266 227 250 266 264 219 276 283 234 227 249 268 221 218 231 236 239 242 228 238 208 236 221 256 280 212 247 244 210 228 246 198 229 229 240 237 234 235 238 243 235 233 240 245 224 226 234 267 231 237 256 215 255 237 247 262 234 263 268 238 226 242 262 224 274 226 257 222 272 241 234 239 255 231 229 218 218 239 239 278 242 240 260 256 242 239 237 214 235 223 245 222 233 269 240 241 240 268 245 260 229 215 256 240 237 218 247 246 246 230 238 219 256 237 228 246 246 236 245 265 246 257 214 247 223 250 233 258 235 219 262 227 239 217 250 215 257 240 229 256 246 273 260 245 268 228 257 241 229 235 216 225 240 238 244 244 237 230 202 227 235 241 205 272 234 263 230 242 244 241 235 242 258 238 256 257 240 266 213 233 257 236 260 231 242 268 237 261 234 247 263 265 238 237 227 227 234 240 229 260 239 255 267 236 222 204 243 221 218 237 249 235 236 230 244 246 257 270 261 222 286 261 234 204 230 236 237 236 281 232 230 247 265 201 243 246 282 200 242 268 270 264 233 238 246 207 237 224 232 233 222 261 242 247 250 240 227 227 274 266 241 210 242 235 241 276 219 255 243 243 243 264 239 245 240 222 242 237 243 277 272 262 264 250 244 222 228 270 242 273 229 242 244 228 246 255 246 246 237 246 220 268 232 242 233 262 258 232 272 238 248 271 236 232 245 259 232 249 242 256 281 267 255 267 227 258 222 233 248 271 221 215 221 246 258 243 221 242 261 255 225 231 240 240 244 211 211 227 267 271 231 232 245 246 233 240 243 273 231 245 243 240 232 256 259 237 246 264 238 205 239 260 285 226 266 260 244 239 246 255 250 255 224 223 235 262 243 268 246 286 211 219 249 238 237 272 239 250 255 230 256 247 248 249 224 255 241 234 236 259 205 227 246 257 218 267 237 234 235 279 237 267 247 249 249 241 217 226 236 267 241 210 243 245 232 237 277 224 232 242 236 232 229 231 234 248 248 272 268 255 219 241 257 239 259 241 241 246 273 233 242 244 208 248 264 232 256 212 225 265 247 237 230 245 262 259 259 258 279 292 286 249 226 237 245 239 232 242 268 228 234 220 259 270 270 256 256 250 245 215 226 255 238 260 265 231 242 285 222 275 260 240 249 244 230 237 224 239 233 232 229 240 223 247 247 233 243 235 243 224 250 240 270 227 242 249 223 236 256 258 216 232 235 235 225 230 248 225 218 232 233 233 225 216 256 239 228 247 233 264 242 245 246 233 228 235 212 245 261 237 231 224 258 233 229 264 222 248 249 235 234 212 242 230 242 223 246 227 242 220 273 236 255 213 261 243 258 235 222 220 265 223 225 213 225 218 241 248 239 231 243 227 232 273 224 274 209 273 215 246 222 255 247 273 262 240 258 235 235 236 240 261 272 243 225 275 229 257 239 226 243 266 255 225 240 263 256 266 241 243 223 241 256 228 233 235 241 237 240 246 238 196 221 257 261 248 260 221 241 211 249 224 218 256 220 219 245 225 219 234 231 249 248 234 236 262 212 246 221 257 226 258 238 229 247 237 280 237 228 250 268 236 249 262 235 249 240 256 232 239 229 259 244 236 227 272 228 244 294 265 232 216 273 278 231 256 262 259 279 227 260 269 235 232 247 255 248 263 233 249 226 232 273 244 241 244 211 211 244 230 236 230 237 271 265 286 241 270 219 247 255 227 244 272 228 227 220 236 228 235 256 243 273 245 228 258 227 241 263 246 212 223 242 220 260 217 242 230 241 244 262 220 241 223 213 222 258 233 258 248 257 233 221 210 255 234 236 219 266 234 247 245 231 238 249 257 239 244 239 230 233 224 245 239 221 230 256 228 234 245 219 244 265 218 257 250 262 258 232 232 240 218 228 221 206 257 262 231 264 220 237 245 233 270 267 239 274 235 259 220 240 257 242 225 231 265 222 231 246 255 250 222 237 211 258 242 258 248 225 237 193 226 266 227 238 256 233 224 231 278 231 238 246 226 244 241 243 230 233 248 239 259 248 241 236 246 237 234 237 238 229 255 208 234 217 215 224 275 271 234 228 247 249 246 234 237 220 239 244 238 237 243 249 232 236 258 247 229 246 249 231 221 259 233 276 241 237 264 246 269 232 238 240 226 239 230 244 227 214 229 237 213 271 256 247 235 243 221 211 247 239 259 233 265 232 255 221 225 266 228 257 247 248 225 211 238 236 224 231 261 229 241 221 264 225 235 256 218 273 243 212 234 231 256 214 246 229 226 255 230 236 255 241 232 229 241 242 227 268 227 234 263 237 224 239 248 243 237 216 245 229 234 263 266 221 210 248 247 259 272 218 219 201 258 270 257 232 249 232 249 239 266 232 222 239 256 258 256 259 218 227 227 212 218 232 249 233 248 247 240 237 248 227 245 249 247 235 247 235 250 246 257 248 232 235 224 242 220 236 240 259 230 243 228 264 255 240 241 230 210 242 261 260 225 211 242 217 247 230 245 231 230 262 221 228 236 260 235 261 215 222 257 237 235 222 264 233 212 229 238 212 256 270 233 236 243 248 246 258 282 255 241 211 241 273 237 222 243 231 223 255 233 222 220 260 249 234 226 256 212 248 235 236 238 257 232 224 227 244 231 231 249 234 250 219 265 240 241 241 215 205 237 221 243 250 220 255 234 261 187 258 230 220 256 226 267 224 228 273 258 239 233 260 245 240 230 228 258 242 249 234 240 240 234 233 247 211 248 223 247 221 258 277 257 258 263 232 246 221 219 228 226 234 242 209 256 259 246 238 206 239 269 265 227 236 218 227 257 263 240 269 242 208 235 220 245 226 248 219 239 227 233 221 264 230 220 238 229 240 242 230 218 238 233 255 228 242 212 206 233 248 261 239 239 248 245 229 242 244 247 228 246 221 242 231 241 228 228 261 222 235 237 236 247 224 258 256 229 234 255 256 258 232 277 208 264 220 286 225 255 236 250 219 222 249 249 235 223 269 244 234 233 239 232 247 225 235 212 232 227 256 235 274 221 259 232 240 272 247 286 228 262 225 245 244 261 227 229 228 223 220 237 238 229 236 257 266 221 249 258 238 222 278 256 265 256 231 261 230 272 242 277 230 255 244 245 249 249 270 245 240 240 217 236 243 214 248 263 220 266 233 236 256 237 256 265 243 268 273 255 269 228 238 241 237 238 248 244 235 239 241 248 264 250 275 215 261 268 244 234 227 229 246 262 230 257 224 269 269 223 242 208 255 278 236 273 243 263 232 214 239 247 235 241 245 263 232 231 241 264 265 256 247 269 265 211 261 244 247 232 266 258 236 233 264 240 235 223 229 241 244 202 242 223 258 228 228 233 211 228 244 259 214 261 242 233 236 205 212 234 241 223 237 235 237 240 240 272 257 281 234 228 265 216 239 237 228 268 242 236 233 237 257 236 241 221 238 214 218 261 242 243 242 273 217 215 256 259 230 245 266 239 231 235 271 219 234 257 265 256 243 224 216 247 267 255 277 233 238 226 224 232 243 243 219 239 260 214 244 233 258 247 230 244 231 220 242 231 231 245 230 240 242 240 227 239 263 242 256 229 240 238 220 257 257 208 240 227 222 256 209 232 237 248 212 246 226 255 236 227 242 266 246 241 235 245 243 250 231 236 244 249 232 236 245 237 242 248 231 250 202 233 230 222 239 225 239 240 270 226 260 229 215 223 244 231 232 228 235 271 235 237 192 242 259 236 231 263 240 244 245 244 207 245 268 226 235 241 258 240 238 226 235 235 232 272 216 241 218 243 226 258 227 273 239 231 227 229 230 234 228 258 230 226 220 230 221 270 246 220 232 257 233 229 255 243 244 200 257 250 226 221 262 266 232 244 245 226 231 256 267 242 256 225 257 248 225 227 267 244 226 241 230 292 245 261 262 234 229 265 260 248 214 258 229 218 229 243 256 225 246 269 249 215 247 237 233 222 256 258 248 236 257 272 212 224 240 232 226 227 264 217 240 232 234 229 250 237 239 250 240 193 282 240 249 216 263 228 218 236 225 262 249 242 269 263 262 233 234 230 200 209 246 226 258 269 247 236 246 204 232 242 245 235 235 221 233 229 241 262 247 226 274 257 221 242 231 231 246 223 230 247 247 258 260 234 215 261 241 223 259 228 204 218 274 248 236 232 219 225 239 242 235 219 256 230 221 232 231 259 267 239 242 223 255 250 218 277 227 227 269 239 247 224 227 225 228 230 257 237 250 234 230 250 237 263 236 294 228 228 231 227 236 219 267 223 246 270 268 238 238 217 255 237 218 239 247 270 278 275 265 263 274 240 241 235 258 266 259 261 248 228 231 265 233 245 223 243 258 255 242 240 233 243 234 249 285 274 207 259 255 243 233 223 242 239 250 245 257 213 228 266 261 209 201 269 224 224 240 240 242 276 243 246 267 229 248 239 255 218 233 249 279 259 239 236 212 211 223 222 236 262 194 216 232 242 236 234 235 220 222 256 260 222 231 237 239 250 240 239 267 220 265 226 236 217 213 219 260 231 240 246 230 227 238 265 241 242 273 259 225 207 239 238 238 231 256 244 260 232 261 233 231 250 261 258 238 242 239 230 220 244 205 259 217 219 231 228 244 262 249 221 236 214 243 263 214 248 258 257 226 238 255 256 240 229 223 257 259 228 247 231 256 229 256 233 249 242 206 242 246 255 243 235 257 266 202 249 259 250 237 242 213 232 241 227 243 231 271 222 227 242 233 236 263 274 238 255 244 233 244 258 226 244 270 255 243 239 246 210 206 230 226 229 249 240 240 200 244 259 263 270 256 202 272 228 272 235 259 240 233 249 229 265 248 231 211 230 220 225 256 230 249 234 241 230 238 232 244 278 225 255 262 223 234 235 228 240 226 242 242 234 234 234 216 243 223 272 223 255 248 247 259 256 237 240 241 268 273 279 216 246 213 246 245 240 257 242 243 273 277 216 225 247 255 221 258 245 240 216 222 245 236 229 223 257 245 258 281 225 219 250 244 205 283 269 248 221 246 215 257 236 265 240 257 255 230 248 246 229 239 224 236 257 247 236 224 226 258 236 236 239 243 266 215 255 245 223 264 215 249 238 229 224 262 258 255 226 230 236 264 223 255 223 248 278 242 231 243 239 231 231 250 246 260 243 211 232 256 256 238 257 225 236 240 269 223 264 262 236 278 242 255 250 232 248 242 233 272 194 249 246 266 228 235 259 233 244 233 279 241 223 236 245 270 268 234 245 244 221 259 236 238 236 248 247 265 226 255 276 268 274 241 259 243 222 237 222 244 246 230 266 240 262 243 239 235 212 223 268 240 262 235 245 271 261 234 248 268 243 259 245 259 272 287 241 258 224 259 246 272 264 221 276 243 260 273 230 246 271 247 245 247 250 257 244 248 237 239 273 249 228 262 245 286 240 267 266 245 227 229 234 249 239 233 272 229 244 221 269 268 215 248 271 259 255 280 282 277 217 280 229 266 247 280 235 309 257 230 258 280 238 237 275 264 291 255 259 262 261 235 282 256 247 274 289 281 301 249 240 264 306 283 263 224 278 246 274 267 281 249 261 245 293 240 277 235 271 241 286 277 235 260 308 288 268 263 282 282 248 267 236 260 249 264 244 258 244 265 260 274 240 281 256 258 259 241 230 266 239 261 255 265 268 263 265 258 280 237 283 265 238 268 240 247 260 264 235 250 243 276 243 236 275 261 231 285 239 273 286 261 258 262 258 299 226 244 246 273 244 256 269 212 246 246 255 293 257 222 262 248 265 249 232 226 241 242 250 224 262 242 258 239 266 232 249 246 257 277 256 239 246 255 249 260 273 225 261 243 257 271 237 246 231 261 234 249 238 268 243 236 235 244 249 226 269 260 262 247 236 298 265 219 257 248 245 266 256 257 249 261 238 279 244 223 261 220 277 240 247 246 264 261 218 233 278 281 256 224 241 214 239 256 239 278 260 257 263 256 246 258 245 234 256 242 291 248 264 203 241 257 235 220 249 250 256 224 259 231 266 269 259 272 229 260 265 237 229 266 250 273 244 299 248 232 228 300 239 245 262 247 223 240 245 257 224 241 265 236 271 262 248 227 269 242 293 242 268 256 248 267 242 241 242 278 248 264 261 247 256 256 232 237 264 265 270 208 214 269 240 238 225 227 255 256 277 248 270 249 228 286 255 226 227 227 242 227 241 237 261 265 223 265 241 273 257 233 221 245 271 274 263 228 246 259 229 256 260 235 249 245 261 258 259 237 274 246 271 235 259 230 241 227 258 248 263 243 265 245 208 236 225 262 284 245 282 247 246 233 245 201 250 233 241 240 243 221 234 245 256 261 235 273 239 300 255 237 240 227 219 268 248 255 230 230 247 262 268 243 247 217 248 230 243 259 230 271 248 245 267 271 261 264 264 266 221 249 255 243 231 237 242 267 244 246 265 249 261 238 248 249 244 264 262 265 256 260 275 237 236 235 248 248 230 242 224 267 240 248 274 246 244 284 265 257 238 240 236 226 235 234 273 240 248 248 240 241 237 224 270 267 229 242 231 235 237 264 256 267 265 255 245 243 280 239 242 240 226 232 223 265 242 237 239 240 236 260 246 263 240 241 259 266 221 248 237 241 230 232 246 240 206 237 266 247 212 242 225 247 259 244 234 257 246 265 220 232 226 221 264 261 237 210 221 233 239 248 229 237 235 264 232 229 250 223 262 264 261 233 219 242 235 262 257 240 218 243 240 236 266 245 271 230 248 225 256 232 248 250 229 218 239 256 281 290 212 257 230 270 220 218 228 239 245 222 246 248 231 247 235 220 256 212 227 257 259 264 244 232 235 271 243 242 265 227 216 243 224 246 238 267 268 247 245 265 244 249 259 238 248 242 270 239 261 226 271 235 245 235 220 229 233 239 255 248 229 263 246 235 263 233 214 248 238 227 259 242 248 230 225 247 277 205 229 213 237 227 241 231 240 268 266 266 230 242 246 230 246 246 219 233 241 234 231 235 274 276 207 236 258 228 212 258 228 225 227 232 265 237 247 238 259 264 244 239 242 231 249 273 263 260 237 224 230 240 235 222 225 236 260 262 197 223 241 288 237 243 245 228 242 237 239 259 244 237 236 222 257 235 243 227 241 239 243 228 262 246 274 208 234 257 264 243 230 258 235 268 247 267 234 234 229 247 250 235 267 259 229 223 215 226 226 258 220 214 237 256 230 268 237 220 248 272 204 233 222 234 217 260 221 233 226 258 239 230 256 243 265 225 239 268 239 239 226 222 235 235 239 246 219 226 231 209 260 232 224 217 234 239 246 257 239 233 263 235 266 275 213 231 238 221 234 230 228 260 259 230 232 243 237 228 265 237 257 256 220 230 232 223 225 258 232 237 223 226 235 239 231 221 235 260 227 242 263 249 233 202 245 244 222 215 239 221 209 238 248 261 206 217 247 233 243 244 234 216 271 237 235 221 247 221 207 233 246 244 235 225 273 270 222 238 260 234 259 213 229 244 256 232 240 259 249 243 270 224 244 222 244 259 240 244 226 220 261 240 269 215 248 241 236 244 296 235 258 266 223 229 221 228 257 234 264 243 250 258 248 230 262 277 238 260 224 218 236 223 256 212 215 275 244 235 266 239 233 227 241 216 224 240 244 267 258 233 236 270 248 233 222 224 233 231 245 229 237 267 235 258 260 248 227 240 230 245 272 257 230 255 235 225 236 217 230 235 232 236 255 231 245 229 240 240 226 241 235 227 276 248 214 240 225 230 232 237 225 249 269 277 240 238 239 230 194 242 244 242 267 224 221 220 268 233 277 224 235 215 226 258 257 246 224 259 235 239 217 210 243 247 242 258 220 240 230 229 240 258 205 247 230 273 209 261 246 215 245 220 261 217 259 240 282 247 259 270 234 265 274 256 213 222 217 234 233 264 259 275 277 219 268 226 235 229 229 238 233 245 227 255 236 213 243 221 264 215 239 277 207 232 261 230 233 235 241 232 248 247 258 256 266 260 228 233 234 228 236 261 243 233 220 221 235 230 241 238 259 219 222 231 239 243 246 227 273 273 261 257 237 227 247 202 197 248 243 231 263 238 232 261 265 222 256 298 236 245 241 247 214 227 220 248 237 242 255 232 265 231 223 281 226 239 257 236 272 267 230 244 249 215 229 257 214 237 257 212 237 225 243 236 224 235 231 235 243 244 215 247 236 255 278 250 209 244 222 226 262 225 273 244 231 232 258 261 226 271 249 216 220 243 238 243 245 240 229 264 283 214 215 224 241 235 265 237 242 232 249 242 241 247 235 238 240 255 229 237 210 224 224 222 220 259 223 220 265 247 224 229 240 235 230 232 242 233 246 237 269 234 248 222 284 236 235 229 210 255 257 241 233 232 224 216 242 245 234 260 240 228 258 256 217 248 241 227 229 267 231 229 203 225 244 280 249 224 246 248 241 256 265 257 262 237 231 231 236 256 234 231 215 248 265 229 258 235 266 239 224 215 249 244 234 237 277 248 229 230 228 242 245 248 261 266 229 242 264 303 259 226 264 233 230 248 260 249 279 240 216 239 262 239 260 245 235 239 256 238 227 263 225 230 236 251 219 273 211 244 233 242 296 245 248 235 223 220 259 250 244 218 264 211 219 276 219 236 257 269 218 241 259 260 231 265 261 230 245 231 227 244 280 234 236 234 224 257 260 248 260 288 219 241 257 244 234 259 216 248 241 229 237 243 228 255 240 238 248 268 227 267 243 236 247 248 257 259 262 260 212 237 248 249</counts>
			</dataPoints>
		</scan>
	</xrdMeasurement>
</xrdMeasurements>