File: data/XRD/XG-Luft/XG-600/W6822-1D_XG_Luft_600.xrdml
<xrdMeasurements xmlns="http://www.xrdml.com/XRDMeasurement/2.1" xmlns:xsi="http://www.w3.org/2001/XMLSchema-instance" xsi:schemaLocation="http://www.xrdml.com/XRDMeasurement/2.1 http://www.xrdml.com/XRDMeasurement/2.1/XRDMeasurement.xsd" status="Completed">
	<comment>
		<entry>Configuration=Factory configuration, Owner=User-1, Creation date=7/8/2013 4:01:53 PM</entry>
		<entry>Goniometer=PW3050/65 (Theta/2Theta); Minimum step size 2Theta:0.0001; Minimum step size Omega:0.0001</entry>
		<entry>Sample stage=MRD Cradle; Minimum step size Phi:0.01; Minimum step size Chi:0.01; Minimum step size X:0.01; Minimum step size Y:0.01; Minimum step size Z:0.001</entry>
		<entry>Diffractometer system=XPERT-PRO</entry>
		<entry>Measurement program=C:\PANalytical\Data Collector\Programs\Jorrit\2thom\_absolute_2th-om_10-130deg_PIXscan_56min.xrdmp, Identifier={15BCCF57-2807-42BD-B5B9-ECC0B3DC9284}</entry>
		<entry>Batch program=C:\PANalytical\Data Collector\Programs\SimonL\batch4x_2thom_10-130°_z9.1_x0,10,20,30_y0_57min.xrdmp, Identifier={EED9823A-2BEB-424C-9252-345C4EF2834A}</entry>
	</comment>
	<sample type="To be analyzed">
		<id></id>
		<name></name>
		<preparedBy></preparedBy>
	</sample>
	<xrdMeasurement measurementType="Scan" status="Completed" sampleMode="Reflection">
		<comment>
			<entry>_absolute_2th-om_10-130deg_PIXscan_56min</entry>
			<entry>PHD Lower Level = 4.83 (keV), PHD Upper Level = 11.27 (keV)</entry>
		</comment>
		<usedWavelength intended="K-Alpha 1">
			<kAlpha1 unit="Angstrom">1.5405980</kAlpha1>
			<kAlpha2 unit="Angstrom">1.5444260</kAlpha2>
			<kBeta unit="Angstrom">1.3922500</kBeta>
			<ratioKAlpha2KAlpha1>0.5000</ratioKAlpha2KAlpha1>
		</usedWavelength>
		<incidentBeamPath>
			<radius unit="mm">320.00</radius>
			<xRayTube id="1010048" name="Empyrean Cu LFF HR (9430 033 7310x) DK442154">
				<tension unit="kV">40.0</tension>
				<current unit="mA">40.0</current>
				<anodeMaterial>Cu</anodeMaterial>
				<focus type="Line">
					<length unit="mm">12.0</length>
					<width unit="mm">0.4</width>
					<takeOffAngle unit="deg">4.2</takeOffAngle>
				</focus>
			</xRayTube>
			<xRayMirror id="27010001" name="Inc. Beam Cu W/Si (parabolic MRD)" hybrid="false">
				<crystal type="Graded" shape="Parabolic">W/Si</crystal>
				<acceptanceAngle unit="deg">0.800</acceptanceAngle>
				<length unit="mm">60.0</length>
			</xRayMirror>
			<sollerSlit id="21010002" name="Soller slits 0.04 rad.">
				<opening unit="rad">0.0400</opening>
			</sollerSlit>
			<mask id="22030008" name="Fixed mask 4 mm">
				<distanceToSample unit="mm">220.00</distanceToSample>
				<width unit="mm">4.00</width>
			</mask>
			<divergenceSlit id="22010007" name="Fixed slit 1/8°" xsi:type="fixedDivergenceSlitType">
				<distanceToSample unit="mm">220.00</distanceToSample>
				<height unit="mm">0.19</height>
			</divergenceSlit>
		</incidentBeamPath>
		<diffractedBeamPath>
			<radius unit="mm">320.00</radius>
			<sollerSlit id="21010002" name="Soller slits 0.04 rad.">
				<opening unit="rad">0.0400</opening>
			</sollerSlit>
			<receivingSlit id="22010001" name="Fixed slit 4°">
				<height unit="mm">5.88</height>
			</receivingSlit>
			<detector id="7010017" name="PIXcel3D 1x1 detector" xsi:type="areaDetectorType">
				<phd unit="%">
					<lowerLevel>30.0</lowerLevel>
					<upperLevel>70.0</upperLevel>
				</phd>
				<mode>Scanning</mode>
				<activeChannelsEquatorial>255</activeChannelsEquatorial>
				<activeChannelsAxial>255</activeChannelsAxial>
				<pitchEquatorial unit="mm">0.05500</pitchEquatorial>
				<pitchAxial unit="mm">0.05500</pitchAxial>
				<readOutPeriod unit="seconds">0.135</readOutPeriod>
			</detector>
		</diffractedBeamPath>
		<scan appendNumber="0" mode="Continuous" scanAxis="2Theta-Omega" status="Completed">
			<header>
				<startTimeStamp>2024-10-22T18:44:31+02:00</startTimeStamp>
				<endTimeStamp>2024-10-22T19:40:37+02:00</endTimeStamp>
				<author>
					<name>PRO-MRD</name>
				</author>
				<source>
					<applicationSoftware version="6.1b">Data Collector</applicationSoftware>
					<instrumentControlSoftware version="7.0E 20130304">XPERT-PRO</instrumentControlSoftware>
					<instrumentID>0000000011142674</instrumentID>
				</source>
			</header>
			<dataPoints>
				<positions axis="2Theta" unit="deg">
					<startPosition>9.99826193</startPosition>
					<endPosition>129.99755682</endPosition>
				</positions>
				<positions axis="Omega" unit="deg">
					<startPosition>4.99913096</startPosition>
					<endPosition>64.99877841</endPosition>
				</positions>
				<positions axis="Phi" unit="deg">
					<commonPosition>0.00</commonPosition>
				</positions>
				<positions axis="Chi" unit="deg">
					<commonPosition>0.00</commonPosition>
				</positions>
				<positions axis="X" unit="mm">
					<commonPosition>10.00</commonPosition>
				</positions>
				<positions axis="Y" unit="mm">
					<commonPosition>0.00</commonPosition>
				</positions>
				<positions axis="Z" unit="mm">
					<commonPosition>9.100</commonPosition>
				</positions>
				<commonCountingTime unit="seconds">32.895</commonCountingTime>
				<counts 444 475 433 391 429 425 405 427 421 418 430 396 443 420 412 373 446 427 423 416 436 420 424 385 471 428 414 454 393 409 451 418 420 415 412 446 421 419 447 412 423 406 418 386 399 434 417 394 423 401 430 415 410 427 426 394 403 409 441 470 444 421 429 406 399 410 406 386 431 391 384 396 407 386 417 433 394 407 384 419 394 434 415 441 400 407 419 418 397 393 385 428 401 408 458 358 389 394 437 413 425 413 441 392 414 432 423 411 403 424 402 410 368 448 423 366 390 400 376 422 395 396 362 380 410 396 403 417 424 372 394 413 425 412 364 388 403 412 415 388 377 385 363 410 442 435 417 362 387 396 388 407 406 422 396 382 406 365 373 390 396 399 371 382 410 404 420 373 406 387 390 407 407 363 398 397 377 402 394 399 407 398 360 385 445 415 377 428 390 404 391 429 410 379 382 387 417 389 389 382 377 378 382 388 366 411 363 373 396 335 391 383 363 386 335 368 378 388 328 362 342 364 408 391 372 368 379 417 370 390 366 379 386 379 335 381 390 393 393 394 389 354 359 368 372 397 397 376 387 400 385 386 336 374 365 333 346 353 353 365 358 361 374 344 379 379 346 338 353 362 363 376 328 375 376 393 382 400 350 360 349 348 405 383 367 350 395 363 366 375 388 360 365 360 372 358 357 366 364 358 341 374 371 339 336 375 340 350 380 364 335 377 326 342 367 341 360 373 388 349 353 375 308 383 361 335 337 359 371 344 335 354 355 367 367 339 370 361 349 376 343 352 366 338 378 359 336 359 328 333 327 367 362 342 340 375 340 316 343 354 373 354 336 361 317 374 331 365 365 412 357 329 339 356 309 348 328 371 346 318 339 357 381 357 371 366 371 347 325 346 332 339 329 316 357 332 350 318 367 359 350 350 330 350 349 336 329 346 307 324 373 322 316 322 332 329 326 323 356 363 356 345 345 348 330 342 334 311 299 328 296 360 348 333 325 335 337 325 325 340 335 357 306 354 329 328 322 320 313 330 329 302 314 313 321 319 296 317 316 319 308 330 307 300 355 303 323 318 328 327 333 314 350 331 331 354 330 347 318 339 340 344 306 331 328 313 310 352 318 307 362 348 298 316 325 335 334 338 344 266 288 315 327 288 314 313 343 344 331 319 314 318 327 296 346 320 350 304 320 318 301 316 319 328 341 332 322 338 320 335 346 324 308 337 327 318 344 314 316 305 347 284 329 343 333 301 311 308 317 301 332 318 330 313 282 335 328 310 343 330 296 318 312 335 312 315 318 297 326 332 338 337 313 337 316 330 327 341 314 307 269 323 329 320 317 288 285 294 311 333 330 312 303 321 298 312 325 313 325 330 305 278 324 298 309 321 351 313 328 303 316 291 296 262 311 317 317 320 319 310 298 329 316 325 317 327 330 306 319 295 310 283 301 332 321 314 291 314 323 291 298 312 326 309 278 308 313 294 336 321 300 280 339 289 350 280 318 297 314 300 336 327 325 304 326 319 306 293 342 323 293 287 297 273 290 303 321 318 323 322 274 312 315 308 264 309 301 299 308 298 292 322 298 290 329 301 307 296 321 274 296 297 292 305 332 333 292 324 306 328 286 296 297 271 330 285 325 321 287 356 320 329 292 335 329 304 315 348 284 285 308 292 277 320 321 313 316 298 357 327 292 306 272 291 327 282 284 310 289 312 301 299 286 278 324 277 304 300 261 294 315 298 297 321 339 284 284 321 336 291 286 292 326 303 318 291 316 301 286 351 301 302 286 347 311 293 319 322 309 293 283 337 318 316 271 298 308 306 309 274 324 321 291 291 323 314 299 303 302 294 275 293 284 323 289 296 308 301 318 291 295 354 291 287 326 296 291 293 314 332 301 289 332 348 291 297 302 328 310 305 327 311 303 295 294 306 307 320 281 315 282 284 296 292 315 309 313 340 308 290 320 312 306 284 310 295 316 333 325 302 293 299 305 332 298 315 285 274 286 306 329 323 332 290 284 326 309 327 294 317 344 316 281 295 310 277 351 275 280 284 307 321 337 310 281 286 345 302 313 318 312 290 319 320 296 320 303 296 296 339 297 340 316 325 328 304 331 288 358 303 300 310 318 325 314 305 343 321 321 294 334 326 322 322 313 328 307 335 327 298 309 322 335 320 336 332 296 330 295 320 312 318 342 316 286 307 274 362 308 285 299 325 315 324 292 305 346 295 326 353 338 319 341 345 313 320 307 316 304 293 295 290 312 289 354 331 334 334 351 310 306 307 310 318 311 309 312 299 339 340 334 317 328 301 311 303 318 319 285 347 343 305 319 355 307 310 323 322 312 318 324 297 314 304 320 284 326 319 318 349 301 316 330 316 303 296 316 324 306 287 352 334 345 313 311 308 320 320 355 305 311 338 312 311 325 354 314 330 315 323 340 314 339 321 326 328 301 323 311 311 311 358 294 346 347 341 322 296 300 353 337 360 330 308 355 318 332 318 352 309 310 357 301 293 330 329 310 316 324 344 321 311 285 312 325 306 341 317 327 366 323 331 332 336 324 329 301 360 298 321 344 313 325 345 334 313 305 319 313 338 298 345 302 314 323 315 344 331 316 343 331 294 294 316 328 344 359 308 310 316 313 331 331 314 354 320 340 322 322 317 332 330 334 358 328 351 340 340 317 308 350 306 294 327 359 334 361 309 327 317 331 340 342 354 318 297 343 322 316 340 324 305 347 301 307 305 327 310 338 329 361 328 308 343 305 320 279 322 358 340 298 322 337 316 328 323 313 314 303 369 318 321 350 335 364 344 327 329 323 355 341 347 353 355 312 339 313 351 300 321 318 325 348 350 324 347 348 369 320 336 331 299 363 341 323 340 309 340 340 338 340 317 319 298 330 342 338 372 303 340 335 359 325 327 303 320 299 344 330 330 298 306 319 342 356 321 314 308 327 320 331 317 282 307 331 344 338 312 321 332 362 339 330 344 329 314 368 290 351 362 336 317 320 317 349 326 313 313 325 332 325 316 328 306 330 341 357 297 304 335 329 320 353 351 321 337 325 348 352 332 317 325 323 322 324 318 311 296 339 334 369 284 293 307 325 325 355 347 303 300 358 382 309 330 300 368 316 307 376 353 319 314 334 330 316 319 328 312 315 297 347 299 310 303 322 296 320 331 313 334 308 314 315 366 331 321 306 327 318 318 331 306 320 316 306 279 336 343 328 330 314 322 323 343 340 305 363 353 350 325 332 317 347 316 329 314 319 343 308 318 325 303 314 343 367 314 324 311 311 318 312 320 304 323 311 296 313 323 328 290 304 314 316 307 308 347 352 316 326 339 313 306 293 347 329 330 321 311 320 299 329 309 308 337 295 312 290 301 304 302 313 338 322 301 308 298 293 327 333 313 307 319 295 303 293 301 300 306 297 312 321 302 299 308 308 302 332 278 305 329 305 338 319 344 348 303 338 298 335 298 306 324 315 293 345 301 309 330 321 342 321 335 313 306 297 283 303 332 280 345 316 287 312 293 336 334 300 302 275 286 315 303 308 300 300 308 306 307 307 304 305 317 323 315 289 303 280 289 311 321 333 307 315 319 285 331 337 294 296 297 322 308 267 289 354 279 326 294 310 327 331 314 316 301 289 280 317 284 310 290 298 284 308 320 285 299 282 267 287 309 294 292 321 288 312 286 299 311 301 315 293 311 269 294 277 299 268 303 283 312 293 303 307 296 307 301 275 291 277 306 303 300 272 292 282 287 240 294 313 283 299 324 317 306 283 309 297 294 278 316 309 295 287 291 300 292 292 288 286 292 284 297 281 287 286 317 322 288 296 297 296 265 295 271 288 303 308 302 300 266 308 289 302 302 316 315 269 275 308 288 267 265 317 241 286 294 309 273 277 286 310 316 282 283 294 272 287 278 312 264 294 298 283 294 291 313 299 318 298 302 300 289 270 282 318 289 311 267 284 290 274 296 269 278 327 260 307 249 272 290 276 291 281 280 303 308 286 278 305 275 290 300 278 292 265 258 296 274 281 327 273 280 275 284 280 309 271 269 296 270 266 290 269 308 284 237 268 261 290 289 275 256 264 278 274 248 265 281 290 291 296 278 273 286 298 276 282 289 305 268 278 274 290 305 299 296 264 289 298 300 265 262 290 290 291 268 295 275 302 316 311 267 286 246 282 263 308 283 273 322 284 228 275 295 312 266 257 279 306 274 278 297 320 267 281 281 264 271 245 274 266 274 266 260 263 290 272 278 280 301 298 256 271 271 281 288 301 235 246 255 290 291 267 272 265 277 272 283 289 280 279 263 267 256 274 247 279 300 263 258 215 273 260 294 282 259 310 266 266 302 264 272 227 296 255 247 256 265 278 255 262 256 271 233 263 264 289 267 276 240 273 283 275 249 261 282 299 261 261 241 301 264 277 273 276 320 284 263 268 243 245 268 291 270 274 211 272 286 218 270 282 249 262 241 294 272 245 308 268 256 291 273 264 275 289 290 303 258 292 278 249 246 243 263 290 257 260 282 278 293 269 271 278 256 230 280 268 295 258 264 281 285 293 269 274 292 280 266 263 293 271 224 273 276 265 219 275 291 273 282 250 235 249 223 258 246 262 273 236 306 279 258 240 284 263 280 268 267 263 262 245 279 267 275 283 271 278 298 249 260 268 267 258 270 256 256 270 241 256 278 260 221 275 285 240 257 257 270 244 261 275 260 274 274 269 256 279 274 246 263 250 239 262 271 270 268 255 258 271 265 270 245 246 244 271 272 246 225 287 262 267 258 267 271 304 310 239 278 250 269 259 274 282 276 283 230 272 255 258 257 243 274 280 269 236 302 228 273 285 288 260 277 240 274 272 234 271 265 266 250 298 283 301 286 261 273 283 235 262 278 282 268 296 280 243 273 236 277 262 248 295 256 272 282 238 265 283 280 267 230 245 263 236 239 285 242 291 266 285 265 294 266 268 274 263 273 264 294 275 289 246 249 258 266 245 239 257 271 249 225 242 238 249 249 247 245 262 269 259 232 263 245 282 237 266 242 243 266 247 274 290 277 255 225 221 271 269 249 274 261 231 239 233 262 280 286 234 262 233 263 266 264 267 248 255 235 272 278 227 265 248 233 255 258 243 265 238 259 260 238 233 270 265 255 265 259 246 238 246 228 240 258 288 292 260 282 270 276 271 211 262 258 241 284 232 248 249 227 285 283 229 235 237 236 269 242 238 237 275 266 243 256 258 236 246 271 247 276 263 239 225 227 223 224 287 245 280 264 237 238 241 231 269 266 229 237 269 220 258 237 244 236 258 273 273 235 259 237 256 234 223 243 263 255 243 265 261 273 268 255 260 258 215 229 255 276 241 240 265 259 243 271 230 261 262 277 234 259 234 232 259 260 267 256 248 239 258 255 256 265 225 259 256 229 233 261 217 247 238 245 245 232 244 255 280 236 246 218 240 234 267 212 266 239 234 256 216 233 234 267 239 270 225 263 267 234 224 272 233 262 263 256 277 249 245 249 231 241 237 224 221 248 275 255 261 264 258 239 265 244 267 256 227 248 255 248 237 231 215 239 235 246 228 291 244 227 229 219 232 243 234 235 268 229 237 236 234 257 238 267 297 239 263 258 275 229 213 257 233 261 255 224 231 255 240 244 243 257 248 238 234 242 225 283 234 243 225 255 248 229 264 230 217 295 213 231 250 241 273 221 248 239 246 264 217 257 240 240 245 255 240 242 216 236 257 259 244 242 239 218 215 248 260 228 237 240 246 216 274 243 228 230 244 247 243 226 232 238 235 236 265 226 227 220 240 247 241 261 207 244 249 240 255 235 259 283 240 273 245 242 219 226 239 227 229 268 246 235 235 238 286 257 255 264 224 266 234 261 242 256 244 256 263 246 264 238 231 243 260 230 235 235 239 217 222 231 268 256 259 224 223 257 237 230 238 222 234 247 239 236 266 269 241 234 294 249 246 243 256 271 225 227 235 256 267 261 248 242 232 247 240 228 231 291 244 256 267 226 227 236 222 241 228 230 248 263 259 277 245 275 249 259 258 248 247 265 233 246 235 239 235 248 248 227 236 226 250 260 263 224 267 222 249 232 285 241 229 247 257 244 247 265 259 256 219 237 257 264 246 250 235 245 249 239 246 263 273 299 270 263 267 267 255 247 273 259 245 264 236 257 274 232 285 259 255 255 277 242 291 314 248 259 275 263 231 262 276 283 237 259 266 243 255 263 258 279 234 270 240 228 242 266 256 259 243 279 280 242 271 249 230 264 218 233 264 261 269 236 256 222 215 248 240 245 223 229 240 262 255 221 279 248 231 233 236 237 244 238 238 255 257 264 236 239 216 260 224 255 244 255 266 237 239 244 257 281 217 218 255 263 229 222 210 242 240 273 269 238 218 216 256 265 247 245 212 227 260 245 247 260 276 265 257 238 262 257 247 241 259 237 272 236 260 266 233 264 242 249 274 227 241 249 238 270 230 215 246 258 238 261 235 241 243 259 237 202 249 221 275 239 258 273 223 241 236 258 231 214 255 239 258 264 239 232 260 234 239 224 249 259 240 273 226 220 225 261 209 245 250 257 225 287 236 255 242 232 242 226 239 231 234 258 237 232 245 258 225 249 236 223 239 272 272 240 238 220 265 232 256 237 240 259 219 258 229 264 235 198 275 261 203 245 231 234 231 259 245 269 235 222 236 264 245 258 267 256 245 243 218 217 224 236 255 241 232 233 231 243 220 213 231 221 244 287 242 242 217 245 259 249 233 249 248 248 211 259 267 247 241 238 205 255 273 249 234 249 234 228 217 249 240 264 259 240 263 241 229 230 234 268 233 246 242 245 233 277 259 247 237 234 200 245 279 245 240 222 242 222 281 264 268 225 241 280 271 222 259 222 242 245 238 250 262 241 230 255 235 228 249 241 241 237 262 234 255 261 247 268 259 238 225 236 218 236 237 268 238 257 248 247 229 275 230 229 255 222 265 249 273 264 242 249 258 244 276 231 263 250 241 256 196 236 231 255 225 258 233 225 249 255 247 268 282 248 229 234 228 237 225 262 270 236 255 220 220 223 231 257 242 235 243 274 259 237 227 258 242 271 247 230 287 264 219 218 229 246 246 271 242 249 275 261 261 278 266 240 258 250 234 228 248 259 258 220 235 246 241 249 247 265 256 260 268 247 231 258 245 231 249 261 235 228 237 261 262 225 223 263 247 235 275 262 255 227 259 228 238 240 260 280 248 274 245 265 292 261 242 242 240 241 258 223 232 230 261 238 259 229 257 228 247 277 261 276 242 224 256 227 226 255 223 255 258 245 274 257 249 229 230 267 234 231 270 269 217 229 245 235 224 265 230 234 232 236 275 239 266 241 259 260 244 260 241 245 286 205 240 268 261 243 233 229 228 280 255 263 230 235 219 247 244 233 232 274 245 255 282 232 242 260 220 226 239 280 247 246 275 276 263 281 260 279 244 261 255 246 220 261 257 234 238 245 230 260 248 255 225 249 273 272 245 285 276 223 241 270 233 266 231 224 239 241 290 260 227 262 257 286 248 267 241 280 286 266 269 276 263 263 266 256 281 226 260 214 264 260 270 248 262 246 281 270 258 276 268 243 245 272 241 275 274 262 264 262 304 226 245 266 242 309 232 222 246 269 242 280 257 264 279 221 275 280 274 270 262 274 265 288 293 249 267 218 281 240 278 276 247 298 264 285 275 262 280 245 282 281 289 266 282 296 279 271 300 273 272 275 265 288 282 287 263 265 269 273 306 264 276 297 268 273 304 292 301 292 287 325 304 282 364 329 256 312 326 297 273 333 310 314 303 335 360 315 341 345 332 337 348 327 379 399 381 397 367 409 407 422 388 429 461 433 459 468 428 473 472 484 447 450 448 457 456 438 433 437 398 382 396 407 385 378 396 358 404 416 359 360 324 352 324 317 321 323 300 306 333 296 308 308 325 280 304 309 286 301 278 317 244 285 296 281 269 278 302 282 276 304 306 303 276 264 282 292 294 262 295 296 271 278 242 279 247 255 275 282 234 256 249 264 255 273 244 273 255 245 224 263 283 277 272 277 240 264 271 258 262 269 257 258 277 295 270 264 267 261 248 257 286 245 305 279 241 248 260 263 231 224 248 270 283 270 278 275 265 231 255 285 265 287 255 272 240 271 272 258 265 261 270 260 242 276 263 266 287 257 255 288 214 255 244 256 274 279 279 271 244 247 281 277 257 291 237 243 260 244 246 267 262 269 230 231 240 249 281 270 248 260 246 269 247 280 272 243 274 238 265 266 278 246 239 230 260 259 239 277 257 278 232 248 259 270 238 286 240 284 273 224 244 246 223 257 273 237 277 261 246 267 261 275 261 262 246 239 234 260 273 240 270 255 281 258 271 240 269 289 271 243 272 275 265 227 270 246 285 256 271 264 278 240 221 277 236 261 234 290 268 287 263 270 227 257 292 232 259 250 243 247 229 245 264 256 250 235 256 256 256 261 258 266 282 264 286 235 268 248 233 273 257 243 247 289 287 256 276 250 230 282 256 260 263 264 287 258 255 233 273 266 224 257 267 277 231 272 245 278 248 290 273 221 279 239 236 268 272 266 244 278 246 268 239 223 241 255 220 236 255 244 264 216 279 267 258 269 262 240 235 271 286 266 271 275 250 258 269 235 246 275 242 240 266 245 230 237 239 276 263 245 278 247 257 227 231 234 260 248 271 275 257 258 240 270 235 259 242 217 245 240 261 268 231 279 280 283 228 227 269 236 280 261 255 250 245 270 244 269 226 279 239 269 261 230 220 244 284 258 261 260 278 286 271 234 281 268 272 249 237 250 234 231 263 261 238 256 244 230 269 293 244 256 241 240 275 239 228 264 275 263 268 223 261 285 267 261 265 263 249 244 241 235 242 235 224 272 246 232 271 245 246 242 257 273 267 259 250 231 267 274 262 245 282 246 235 240 291 261 237 275 242 272 263 255 236 247 240 262 297 286 266 284 256 255 286 258 256 232 273 284 244 281 233 244 265 272 261 242 258 272 278 242 261 249 287 221 259 242 285 262 258 249 270 257 259 237 256 239 242 265 278 257 263 270 263 271 280 274 272 222 276 278 236 272 265 240 277 232 267 233 233 245 258 244 248 276 258 303 247 260 238 267 233 256 247 274 263 313 298 236 269 248 276 270 264 247 263 273 264 265 242 248 232 266 259 245 260 277 279 260 265 275 279 276 289 285 273 280 260 248 240 240 242 270 266 241 276 248 260 207 263 244 229 247 259 277 265 278 250 265 263 225 263 244 234 265 270 246 262 266 293 249 260 246 224 279 267 235 246 255 278 234 264 261 274 268 222 288 260 258 278 242 282 279 256 275 233 264 246 268 246 269 275 223 278 261 256 273 242 228 226 277 267 282 240 280 256 277 295 269 283 242 268 233 278 256 240 275 257 258 263 267 256 291 258 281 267 311 256 255 258 274 239 247 240 262 260 282 273 255 296 273 246 270 257 278 248 275 264 228 239 224 258 258 267 277 243 280 244 291 273 256 257 244 261 285 225 266 261 282 268 265 260 242 238 286 271 258 257 269 261 245 260 259 238 274 260 261 289 269 265 270 269 262 272 264 242 243 259 276 250 256 272 259 244 296 273 268 233 245 267 246 272 295 261 223 296 272 231 294 269 272 233 218 282 271 300 231 265 231 255 248 249 288 268 237 264 239 246 250 245 280 268 261 289 281 257 270 267 261 267 262 284 219 276 256 243 263 234 234 265 268 267 223 282 268 265 284 243 258 238 231 259 300 287 233 256 242 260 279 263 270 244 271 275 244 239 249 248 243 273 264 280 278 263 235 262 226 272 274 262 302 257 284 267 266 234 233 245 283 237 239 277 281 262 265 265 281 270 249 268 272 255 271 250 279 260 262 271 249 276 279 259 246 245 257 272 247 278 265 276 275 266 239 247 277 267 295 272 260 263 282 278 273 269 268 291 274 270 255 263 276 286 257 278 278 267 281 257 264 264 245 246 292 232 259 271 280 276 290 269 234 268 238 246 265 265 266 248 262 241 264 268 303 261 255 237 258 285 250 266 262 249 269 285 260 232 258 243 234 284 249 307 249 266 312 232 241 282 266 267 259 280 259 246 255 286 283 263 230 231 263 268 244 261 270 259 249 268 245 278 245 237 238 244 263 225 293 245 281 281 268 221 277 243 267 274 255 238 281 255 223 242 283 281 258 293 260 267 288 243 233 239 244 246 258 244 261 237 237 230 276 267 243 214 240 257 293 244 283 260 249 247 276 234 273 268 268 264 255 291 280 248 221 267 238 282 276 233 297 234 263 262 256 269 238 273 266 292 262 272 246 266 269 236 248 265 285 241 289 267 304 286 277 234 286 249 255 278 270 288 239 275 249 279 264 235 246 273 271 286 322 284 285 261 244 226 283 260 288 249 271 272 269 259 275 306 262 269 241 265 278 263 237 271 281 281 241 262 268 226 237 247 257 274 262 237 270 266 276 267 249 250 247 247 242 249 268 283 275 245 290 281 256 257 266 239 275 238 265 255 269 256 239 255 241 248 227 265 316 244 278 230 286 231 278 245 243 267 267 258 229 249 243 241 256 248 248 279 264 287 283 264 250 266 275 265 268 267 262 272 266 267 239 283 245 247 237 241 258 262 249 258 242 243 258 268 237 244 261 249 236 288 267 261 263 243 241 224 265 255 244 246 258 266 237 249 265 245 258 269 244 238 235 242 229 262 242 261 238 226 295 263 237 234 258 247 233 284 266 265 255 237 265 240 259 258 283 255 262 259 274 271 280 233 261 266 282 266 239 266 257 241 234 228 245 264 228 222 242 263 264 233 245 237 258 257 265 237 275 236 236 241 259 245 241 242 218 278 277 268 304 266 244 261 243 268 240 247 245 205 249 235 229 267 261 275 272 290 267 247 270 283 257 263 244 256 287 247 255 205 249 245 244 242 222 247 275 244 258 237 261 262 264 259 237 245 228 248 274 241 280 272 277 287 265 266 246 266 282 219 244 237 213 247 246 246 264 247 247 264 264 235 242 268 285 242 248 245 274 246 259 247 243 270 241 261 249 255 227 259 258 263 230 255 263 225 247 257 228 266 286 266 265 244 275 243 232 268 248 282 242 261 229 230 274 247 262 239 236 242 245 266 270 242 244 268 262 241 232 230 238 246 245 265 282 227 288 255 272 279 247 265 274 289 281 228 237 259 233 242 281 264 268 234 231 268 247 243 264 264 267 255 240 295 269 242 265 244 285 243 285 296 232 237 270 249 270 242 234 274 241 277 258 259 257 230 225 258 249 270 288 276 260 277 287 242 226 272 240 241 259 231 259 238 229 232 261 269 263 259 240 240 275 249 227 274 250 242 242 265 240 267 248 245 249 260 264 262 241 238 297 274 240 233 273 268 266 288 255 272 273 234 274 262 265 244 278 262 281 265 218 255 279 258 258 280 258 236 265 241 279 259 265 240 275 256 278 263 262 234 240 262 273 256 281 243 273 279 263 270 241 249 264 264 257 283 248 230 275 249 275 247 256 264 237 235 269 239 258 232 275 239 283 276 249 256 269 241 285 222 240 238 262 262 265 273 232 261 277 248 241 217 281 234 245 306 276 255 273 266 242 272 270 266 268 267 244 228 267 265 241 280 282 262 297 272 257 286 249 218 234 250 256 257 241 270 256 262 229 263 288 243 261 247 258 243 264 259 267 272 271 290 270 247 259 224 242 296 257 274 248 267 245 247 264 279 274 242 263 244 297 276 295 237 239 274 240 250 233 247 263 264 260 240 281 257 263 269 260 257 225 270 255 245 242 242 289 270 256 277 266 265 231 237 285 238 266 285 264 226 269 247 279 262 236 271 268 278 265 280 236 255 244 238 293 267 263 285 296 249 256 247 246 247 249 276 240 278 248 229 255 261 244 273 279 262 243 269 237 265 244 277 290 291 264 262 284 272 232 243 238 237 245 275 273 271 273 278 234 290 283 233 270 274 232 259 261 246 263 274 269 266 261 232 250 267 268 264 267 273 282 247 267 281 262 267 257 237 272 298 245 302 261 229 247 270 242 265 288 222 239 266 304 291 302 255 257 241 269 243 220 239 246 241 287 257 242 263 237 272 286 247 232 239 268 292 259 245 268 284 288 224 239 262 242 267 238 274 249 267 288 280 272 244 266 255 248 263 283 229 247 236 285 270 226 256 270 241 271 238 271 260 300 247 242 281 268 257 267 224 268 249 257 267 302 258 248 290 269 262 263 243 229 272 282 260 256 255 258 274 229 247 260 249 285 286 245 279 236 267 243 272 266 266 275 258 244 264 211 240 256 258 255 261 248 270 240 255 261 237 243 273 274 245 213 235 257 245 238 245 247 263 260 259 278 281 260 286 247 290 274 240 234 281 307 276 281 233 231 264 287 257 240 244 271 274 276 256 273 266 280 266 293 268 281 318 282 258 270 279 268 246 248 261 259 288 269 296 277 287 261 257 284 274 246 298 295 262 282 255 278 290 279 256 289 296 300 247 294 290 286 294 279 283 262 270 229 293 264 294 255 259 260 260 270 280 260 295 261 271 259 278 240 295 285 285 234 271 271 291 257 301 267 280 262 271 295 263 272 274 242 258 283 243 295 271 277 276 259 286 244 265 247 262 285 275 299 267 267 275 276 271 266 291 242 235 270 268 257 263 248 260 281 250 277 279 263 273 265 266 245 261 238 242 266 256 260 266 273 310 258 282 290 244 246 291 264 248 264 246 285 274 269 265 285 246 257 259 281 263 266 261 221 294 267 270 271 260 267 273 225 265 260 261 264 240 277 270 262 240 257 266 229 268 282 267 263 287 256 270 274 261 248 274 292 256 268 214 267 242 274 228 243 271 295 275 258 281 244 306 289 274 262 245 279 262 261 281 272 247 235 264 248 244 279 290 281 271 231 234 263 241 275 281 268 267 273 247 262 268 272 297 255 279 245 261 262 285 275 279 268 264 275 279 296 268 243 265 290 267 270 237 274 260 295 266 267 267 282 273 293 287 249 278 246 263 305 276 274 285 230 257 264 261 270 245 306 277 266 304 267 255 275 268 247 255 291 300 269 234 241 289 257 247 303 258 280 307 282 204 243 257 275 275 246 241 282 259 264 241 271 279 274 258 263 293 260 246 275 267 248 258 246 244 201 237 223 265 295 286 285 247 277 280 257 262 240 262 279 262 238 276 245 266 245 242 271 238 256 268 257 288 292 287 275 273 287 272 279 244 274 240 272 244 259 260 244 281 243 274 290 268 267 255 267 266 244 225 232 269 285 262 263 308 281 281 256 278 284 258 255 262 248 241 248 286 311 306 248 272 267 259 250 216 218 268 265 259 238 291 264 283 258 257 233 226 273 269 241 258 282 270 278 280 275 273 242 302 288 257 265 269 259 264 226 258 273 264 249 271 243 270 250 265 264 270 276 267 248 246 228 233 273 276 227 281 261 264 237 274 292 225 249 256 268 249 247 268 289 283 266 239 261 287 256 259 217 274 257 277 249 263 239 241 267 236 246 267 293 259 275 232 241 249 266 276 266 243 244 270 262 268 247 255 260 275 261 280 255 266 276 243 268 289 241 248 289 270 272 280 242 313 277 278 271 317 243 264 247 249 256 269 270 319 268 256 244 261 262 261 283 288 275 264 246 258 249 237 271 264 276 275 278 247 243 265 266 260 256 246 260 268 268 258 240 269 277 270 263 268 243 259 288 277 271 238 236 243 268 276 282 284 239 258 265 292 263 267 257 260 269 262 259 232 263 242 308 239 295 256 249 289 268 272 261 249 271 268 233 276 286 280 292 261 260 259 263 231 280 269 235 291 241 235 241 272 289 279 248 257 245 239 288 265 273 275 231 261 307 240 256 293 241 240 272 244 248 276 268 259 261 257 261 278 297 276 233 238 292 281 290 256 282 284 259 265 243 247 240 272 292 267 266 238 243 271 273 286 258 280 275 275 270 287 272 234 264 290 263 285 267 258 262 280 263 242 292 277 265 257 283 235 263 248 276 262 269 237 270 270 263 293 284 271 226 263 258 259 243 241 261 266 274 261 256 260 244 262 273 275 231 266 264 301 248 290 261 261 297 274 269 272 242 286 256 268 261 287 268 271 263 255 263 263 228 260 279 288 264 270 290 247 323 270 294 261 280 261 275 247 281 249 274 265 242 265 259 240 263 242 271 282 241 273 262 259 249 224 263 249 265 260 294 267 296 240 257 304 229 263 278 255 292 272 279 237 244 257 291 258 272 269 239 257 277 269 290 248 263 276 279 273 261 244 275 230 263 275 275 286 262 295 286 260 275 265 262 282 272 263 265 257 264 276 273 276 271 268 272 260 260 228 238 272 247 258 259 284 263 273 261 274 286 282 231 277 290 239 243 238 244 264 238 285 264 261 283 260 275 262 279 262 274 284 261 256 259 259 255 235 293 238 256 263 282 261 281 236 226 274 274 231 283 257 287 287 260 258 266 250 272 246 258 286 249 229 263 241 241 246 275 298 290 265 273 259 276 268 288 268 219 242 259 288 238 268 257 232 269 236 281 263 255 232 285 240 269 244 276 279 268 264 241 241 241 273 279 255 245 293 272 284 249 246 245 267 247 256 257 249 281 259 275 271 265 262 231 292 272 244 256 242 224 270 268 270 262 266 276 248 244 235 239 258 288 258 275 261 262 241 278 265 257 269 248 268 229 286 258 273 264 230 275 269 259 260 255 272 275 224 260 271 277 301 243 274 267 260 262 247 235 261 240 239 261 256 250 233 259 284 261 221 266 272 276 255 271 278 248 239 265 286 241 304 256 282 280 279 285 303 257 266 240 285 276 272 298 288 240 261 247 236 269 271 249 260 269 259 248 232 236 266 269 291 277 238 222 220 278 241 239 243 258 236 280 269 281 278 249 264 267 271 256 289 267 243 275 237 285 247 246 289 243 278 260 236 255 290 258 236 264 264 241 275 268 244 277 263 257 247 268 276 284 268 230 263 245 267 228 276 280 257 274 244 283 258 265 223 259 261 273 232 276 264 259 273 264 241 246 257 267 244 238 240 246 268 270 266 221 245 237 269 249 237 242 245 266 247 236 257 236 228 238 273 247 262 281 271 259 266 267 260 255 224 245 269 245 273 240 228 246 228 245 226 237 270 242 240 279 265 247 256 228 267 257 235 266 288 278 247 260 280 279 269 273 243 277 246 238 249 268 272 268 259 261 246 239 270 256 238 242 248 293 247 284 269 264 237 289 269 289 222 291 260 273 245 205 247 280 239 246 273 233 266 247 269 265 269 237 239 259 266 296 256 246 238 259 264 278 228 257 243 260 265 259 240 245 233 234 246 272 269 235 262 244 264 299 243 275 266 274 282 271 249 291 243 234 244 239 271 264 282 261 265 248 271 241 267 245 225 240 289 232 236 240 276 259 257 218 256 259 235 237 270 237 244 248 257 233 246 258 259 221 248 240 262 274 266 261 267 231 242 243 275 234 287 245 240 262 256 260 264 277 258 287 241 274 261 239 293 259 257 248 236 240 256 243 277 271 238 238 246 229 234 249 225 240 264 247 216 264 245 263 233 260 257 258 261 271 266 263 287 264 234 263 262 236 262 265 263 237 236 234 249 264 284 266 275 275 256 262 282 236 247 250 242 244 228 258 230 245 242 258 242 259 234 279 258 265 261 241 238 260 271 276 276 248 246 259 269 242 217 229 299 233 266 283 261 239 236 279 259 259 235 245 260 248 279 242 239 255 270 263 240 257 258 239 285 220 278 267 236 264 240 238 286 258 274 267 264 284 236 258 222 221 287 263 298 231 263 273 288 248 249 243 283 238 275 223 230 241 237 245 261 256 260 262 266 298 244 237 267 244 246 272 270 245 244 257 279 277 233 271 280 289 275 248 282 272 240 267 249 240 261 246 233 227 242 239 258 230 248 258 275 262 260 266 278 263 273 242 239 248 240 244 240 233 245 240 261 266 255 278 267 268 255 235 233 261 243 245 272 278 265 246 275 285 218 242 272 284 293 237 265 271 257 242 237 274 258 257 261 279 261 237 258 257 266 294 239 297 278 291 263 226 236 256 220 255 246 255 236 257 240 243 266 247 288 240 269 269 259 235 246 258 237 269 293 242 258 268 238 276 237 266 249 218 255 242 260 240 279 263 267 288 264 265 246 249 240 261 283 265 242 265 270 262 261 236 257 244 261 264 240 292 274 248 259 255 242 222 247 231 271 242 271 243 235 277 271 224 268 234 231 272 243 264 237 229 257 238 235 284 269 236 264 223 262 248 244 247 235 255 255 265 269 266 264 226 255 242 270 258 272 290 270 294 248 263 257 241 264 257 226 267 278 262 259 267 282 246 249 275 285 297 297 261 245 228 300 265 264 290 268 290 269 243 266 243 276 265 296 273 260 291 231 268 287 289 294 270 266 243 280 258 289 287 257 279 244 294 281 270 284 291 300 263 265 286 265 313 258 276 280 270 289 283 286 305 308 296 318 299 270 286 277 310 296 300 293 308 307 300 286 311 295 279 311 276 282 269 278 297 293 294 294 288 281 283 278 272 300 302 289 289 307 242 281 293 297 265 258 316 258 261 279 259 256 250 264 247 283 293 256 291 275 284 269 265 239 246 267 299 272 264 245 286 289 243 297 270 261 228 268 277 244 271 267 243 247 260 232 255 241 265 255 244 280 291 260 255 242 255 262 262 249 221 249 264 278 229 270 240 222 239 209 210 237 256 259 257 281 283 269 246 271 247 232 243 238 255 237 229 243 255 264 259 266 257 261 269 260 221 256 257 238 293 267 261 260 237 281 285 223 231 242 243 241 248 243 237 250 276 274 262 279 249 243 225 224 240 238 265 237 238 270 232 243 258 242 261 243 222 270 272 263 263 234 260 275 264 226 239 256 296 233 271 290 261 255 231 246 283 227 226 217 229 263 272 289 260 261 232 237 218 263 269 243 231 256 233 235 256 243 280 240 280 237 236 267 210 242 244 291 282 231 260 276 241 261 234 240 262 210 246 228 246 235 233 248 249 262 236 237 234 229 262 244 230 233 246 237 275 240 226 256 245 272 241 269 266 220 243 237 246 246 280 248 221 257 238 255 257 243 227 243 259 235 235 243 218 279 245 242 266 267 266 238 218 256 256 244 228 225 273 238 241 245 231 235 244 236 297 230 237 236 261 230 245 225 228 234 267 268 261 222 245 244 205 243 263 248 246 270 249 233 243 231 268 244 239 234 230 266 234 274 243 270 245 233 274 235 260 233 258 233 259 262 257 216 241 226 231 261 263 232 259 248 232 244 241 244 262 255 263 232 228 242 270 278 223 267 264 225 260 240 229 283 239 236 238 225 226 277 232 232 268 240 275 256 206 212 234 259 240 235 246 245 266 264 242 241 230 236 260 245 274 245 256 246 258 260 271 257 241 289 262 232 270 257 229 256 239 193 230 228 257 223 275 249 225 263 247 234 220 242 261 239 240 261 269 249 268 237 235 214 263 221 232 230 258 226 245 260 216 264 236 264 258 274 231 258 260 240 255 255 225 231 238 230 269 257 221 226 227 249 259 263 241 258 235 225 235 242 266 245 231 213 245 244 243 233 262 269 260 264 267 237 258 232 245 272 263 239 248 236 225 236 229 230 210 274 235 243 234 226 238 209 207 227 241 277 228 229 232 233 245 208 246 225 239 210 245 233 244 230 219 284 235 260 231 240 236 231 220 260 256 240 271 274 240 226 248 220 263 221 255 259 262 241 232 249 277 236 243 246 275 286 255 262 262 236 262 239 236 230 275 270 285 241 266 239 272 230 235 234 245 255 224 249 263 266 230 245 244 239 266 290 248 257 234 242 265 265 247 259 228 240 244 260 258 243 246 221 242 232 242 261 232 226 263 256 273 269 246 241 239 277 278 242 262 233 265 239 288 236 259 268 247 256 225 260 273 239 230 271 264 261 262 247 270 258 246 281 239 244 255 277 248 225 266 246 281 236 242 229 276 243 233 238 227 247 271 242 243 227 249 268 263 255 255 248 285 243 246 234 241 222 214 277 256 239 258 288 261 228 260 241 257 277 263 228 257 263 256 267 245 235 240 243 238 228 246 218 233 240 265 237 226 272 261 272 248 233 240 237 256 242 242 261 276 226 271 234 246 259 258 286 256 296 233 239 228 249 239 273 256 265 237 249 249 259 259 276 273 261 221 272 220 266 256 247 264 228 245 223 270 243 259 255 225 275 233 247 277 241 268 213 281 262 258 256 268 223 256 263 273 245 243 240 247 236 227 234 250 226 255 244 278 247 249 234 247 247 244 237 260 240 258 256 229 236 248 258 273 250 258 264 261 258 260 256 245 236 240 242 265 259 259 259 268 249 261 217 244 265 248 277 265 223 284 236 261 256 230 245 229 234 214 264 227 249 272 238 247 248 232 283 267 259 238 249 269 268 273 265 230 274 276 217 237 259 244 214 246 276 264 250 263 248 223 239 249 222 266 242 240 231 265 266 236 247 235 266 256 235 244 242 236 262 247 242 290 236 228 234 257 273 270 248 264 233 232 278 247 281 259 237 257 249 248 244 227 286 234 273 283 265 257 247 234 249 237 217 246 224 268 266 224 240 246 259 216 235 269 237 258 258 256 240 241 238 262 219 267 243 292 237 237 249 261 256 267 256 247 247 288 232 258 274 265 238 243 248 228 248 275 261 250 224 234 271 222 262 246 244 244 246 269 242 257 271 232 256 261 262 260 224 258 316 238 226 245 209 246 225 243 249 277 241 275 264 264 260 257 271 243 247 268 249 232 264 245 261 266 244 274 258 257 244 227 271 262 266 236 237 265 258 245 263 258 255 245 270 224 230 234 245 258 269 260 271 261 247 265 239 245 258 239 271 269 268 242 267 243 259 250 272 237 234 275 236 264 267 286 248 242 265 272 263 245 247 233 287 257 246 282 244 234 249 229 226 226 242 226 246 243 262 250 260 257 257 276 240 248 225 247 268 263 270 209 244 255 256 245 236 262 279 240 248 248 232 275 259 281 256 270 270 246 239 259 235 258 255 211 270 297 262 243 287 270 248 244 224 249 255 257 273 273 277 261 257 257 259 244 235 242 282 225 262 250 221 242 267 259 246 242 263 249 223 255 242 234 241 281 281 262 249 245 274 263 258 247 257 246 263 241 261 262 245 233 239 236 266 217 236 266 247 273 265 218 234 266 233 223 263 256 272 226 248 241 271 213 292 220 248 267 269 246 229 248 258 244 264 246 268 234 246 248 255 231 235 243 288 231 241 248 248 263 255 230 226 226 224 242 243 266 257 217 218 275 247 248 273 232 229 244 258 262 248 227 236 228 244 221 228 261 275 261 268 242 260 272 264 228 279 274 276 269 235 219 286 259 266 249 274 244 257 240 266 237 242 255 257 276 262 247 243 244 255 240 249 259 257 258 274 236 227 231 241 228 266 272 276 260 248 234 266 289 221 264 231 239 259 248 228 245 228 256 240 247 272 227 259 263 278 220 241 249 269 272 249 250 264 239 268 245 227 249 273 277 249 272 255 217 258 256 222 256 259 226 248 226 212 235 215 217 257 240 271 257 237 261 255 244 257 250 221 276 220 298 246 243 270 235 264 255 238 284 230 242 243 274 214 261 236 263 256 231 246 222 278 294 258 273 275 217 241 274 261 269 271 248 267 241 245 243 276 264 257 230 244 284 247 258 275 259 267 277 275 280 231 262 243 241 255 233 219 262 244 201 232 247 249 259 268 274 232 243 264 268 273 225 237 261 268 267 243 261 246 255 258 231 282 243 230 261 273 248 246 266 264 262 233 234 274 288 257 262 224 235 246 245 280 235 256 269 274 264 240 247 248 244 277 257 238 258 270 241 225 240 239 215 220 272 216 212 238 260 269 243 250 246 238 245 246 242 255 234 270 265 266 251 236 243 232 264 237 269 238 230 238 238 261 279 235 225 245 248 284 264 263 242 262 235 282 257 268 272 264 262 272 243 259 276 247 276 234 260 268 220 261 273 283 246 271 268 263 280 258 245 238 269 271 227 242 242 281 266 247 261 270 273 246 246 270 258 249 269 240 209 257 273 278 294 255 226 243 227 221 237 273 266 258 262 245 241 263 267 296 234 263 267 240 273 241 271 281 269 226 271 279 224 256 264 261 270 259 264 257 269 243 267 235 235 260 238 241 241 255 243 267 249 264 256 257 272 267 228 275 268 266 273 247 276 280 268 269 239 283 235 264 272 281 226 281 275 272 257 266 268 236 266 247 278 294 279 244 277 281 273 226 267 238 281 265 279 262 269 270 280 275 276 245 266 275 279 262 238 271 262 262 259 246 271 274 273 264 266 262 265 298 273 243 284 234 272 277 248 229 262 284 272 248 248 280 242 272 303 255 243 296 238 278 268 280 258 223 259 249 255 265 233 249 249 263 260 272 256 255 241 263 265 258 259 262 230 258 279 262 278 248 281 264 302 248 249 276 240 234 235 239 246 273 230 239 234 259 257 235 277 271 258 263 233 264 292 264 258 256 234 256 259 239 243 262 242 237 270 222 244 238 273 244 275 225 269 239 233 228 265 267 240 236 273 259 264 270 232 257 236 267 262 228 259 243 275 274 246 235 228 272 234 235 262 277 262 239 255 226 230 268 242 267 270 261 236 219 245 279 262 239 233 246 233 275 262 261 270 233 266 259 244 246 268 285 221 265 306 281 257 257 259 228 263 267 267 244 283 272 241 269 255 227 239 264 243 237 256 246 270 241 290 223 289 276 268 261 264 255 257 242 255 221 262 258 268 248 284 275 249 242 269 215 266 242 278 220 238 256 258 249 245 274 238 262 275 248 229 267 271 246 271 259 270 272 244 245 267 266 270 262 290 264 248 265 246 286 264 247 231 235 265 270 257 266 245 268 265 256 270 271 262 280 219 295 268 282 274 247 284 256 273 261 249 238 288 265 285 259 224 257 239 246 248 237 236 255 241 246 265 265 237 228 255 230 246 257 281 286 278 268 222 258 271 270 223 281 243 246 248 247 240 247 300 228 221 238 258 237 208 249 244 257 229 289 264 263 225 257 281 255 246 240 279 277 259 245 250 268 285 293 261 250 247 289 266 227 246 239 257 259 209 255 243 269 258 265 262 249 238 263 261 240 258 265 288 243 265 266 242 269 263 225 244 246 246 241 239 267 265 246 269 265 244 277 297 248 259 265 242 272 264 239 282 258 270 280 264 279 223 245 268 242 284 241 272 263 227 262 240 244 223 278 246 269 271 282 250 269 267 264 207 241 239 261 289 239 269 245 274 231 267 270 268 261 256 243 244 234 259 256 256 264 277 263 255 260 245 265 256 244 224 266 271 276 257 247 264 227 245 294 225 275 265 278 249 247 224 284 268 242 286 233 266 236 241 257 215 274 259 234 264 298 249 272 233 222 265 261 263 270 295 272 292 286 277 277 280 231 270 240 267 232 247 248 238 268 277 248 273 258 269 275 270 221 266 271 240 275 248 248 217 239 230 264 246 216 295 248 285 273 276 261 263 244 281 267 230 258 280 248 273 250 256 235 260 243 264 243 247 241 224 271 286 273 274 259 228 273 237 261 309 303 274 271 270 241 219 299 270 240 259 276 235 255 247 258 243 246 271 223 266 286 258 293 259 297 249 266 259 275 266 262 262 262 256 246 273 258 235 264 259 246 283 262 243 260 264 274 281 257 236 277 243 238 275 285 228 228 239 241 275 264 274 273 259 239 298 267 275 262 276 259 238 262 255 243 264 257 275 292 262 281 273 277 234 235 248 257 279 245 227 285 266 286 237 229 243 238 279 223 267 301 275 275 246 232 274 276 282 249 258 278 248 234 267 279 258 282 233 282 244 261 295 256 256 231 259 250 230 257 286 235 255 280 244 261 256 225 280 247 264 222 241 283 274 258 292 275 262 237 258 261 287 288 274 266 278 262 214 258 246 235 290 261 260 278 274 244 235 256 242 246 245 246 262 248 250 289 267 299 287 228 256 290 258 291 238 263 272 263 238 309 281 279 286 247 229 259 270 267 223 267 255 269 219 260 246 276 279 237 247 255 282 228 296 265 248 249 263 306 267 260 274 265 264 228 266 280 255 259 277 277 239 247 273 239 291 275 319 270 263 259 279 242 232 260 273 249 240 243 272 281 279 259 255 260 262 237 263 261 238 256 246 280 282 246 264 249 267 298 219 264 261 260 259 285 243 260 261 246 269 287 278 243 241 267 255 264 241 274 259 263 242 261 290 242 243 235 265 266 245 283 258 231 268 222 279 243 262 275 279 265 228 276 261 258 276 259 273 278 249 266 274 256 259 255 259 280 246 264 244 259 266 282 257 255 277 267 277 256 267 260 265 260 274 282 266 263 283 289 261 255 235 265 258 256 266 279 259 276 276 212 290 291 257 265 279 237 243 260 244 265 257 247 236 258 269 247 243 245 242 245 291 245 295 262 248 255 245 271 256 256 263 262 280 271 264 241 264 265 257 284 261 232 291 221 259 256 265 264 274 272 256 225 244 278 272 273 258 248 243 246 255 244 228 277 258 287 265 250 238 264 257 289 238 255 237 247 284 271 264 259 276 241 244 270 271 259 265 246 266 244 258 258 264 271 271 243 228 261 237 277 249 247 267 227 279 255 257 223 265 241 234 256 244 242 263 237 266 283 265 242 302 256 264 242 293 258 269 262 217 246 264 260 274 266 258 247 248 288 258 246 280 286 277 269 288 274 266 245 284 268 289 255 231 219 238 240 255 249 259 269 242 255 244 241 221 244 287 267 243 265 271 248 230 234 296 292 242 244 249 262 260 231 236 279 246 256 282 270 228 273 255 244 267 269 240 262 269 237 262 268 284 258 280 261 262 255 248 276 241 249 268 248 259 284 259 259 273 237 284 263 228 257 286 244 256 283 243 269 281 271 256 266 269 230 272 245 279 263 260 243 279 222 260 257 269 279 271 262 260 257 266 241 242 263 236 255 257 288 264 249 263 272 285 276 283 286 246 262 282 257 272 285 244 318 261 260 265 266 281 256 241 256 272 268 257 284 258 280 235 247 255 279 259 271 237 259 263 274 270 255 283 243 272 263 245 282 232 247 272 240 265 265 228 273 227 275 281 271 299 268 275 244 244 255 257 264 271 269 293 276 255 241 283 275 239 256 260 259 258 261 275 255 286 248 259 247 266 272 250 249 246 236 292 286 255 271 258 261 227 279 247 314 257 237 258 232 263 284 257 279 267 290 263 275 279 270 297 262 273 259 267 263 286 270 272 288 240 269 324 258 274 290 224 295 267 247 265 299 287 226 243 299 248 290 313 279 272 276 268 266 258 289 262 278 241 278 255 241 278 238 280 258 269 266 262 264 300 298 271 259 263 303 279 282 261 260 259 293 266 276 264 287 302 228 286 281 249 247 267 245 245 237 258 231 264 243 263 272 257 255 275 268 295 272 286 267 280 275 285 264 267 301 273 267 265 281 259 289 244 262 246 243 281 287 255 268 281 292 283 275 293 264 270 279 286 226 268 257 272 302 285 274 261 245 237 283 277 247 265 296 276 268 237 304 263 260 278 287 249 271 286 232 248 304 275 298 274 277 267 271 285 295 293 280 258 273 281 283 271 299 258 263 289 280 233 277 265 266 272 275 266 261 270 244 271 278 291 273 238 274 238 288 242 265 248 276 258 286 265 243 263 260 241 276 280 269 263 257 269 262 242 300 260 274 246 272 299 242 267 236 271 259 266 244 260 271 294 281 263 285 271 250 274 258 275 258 243 281 263 256 285 245 258 264 258 248 260 247 269 279 239 268 236 243 247 246 228 265 267 285 274 264 277 274 260 256 268 289 266 237 274 246 274 275 256 270 275 299 262 303 287 290 255 281 258 267 248 272 259 265 269 260 258 250 238 236 272 308 268 273 235 261 311 245 269 248 301 242 282 287 276 247 273 232 294 241 282 259 249 281 264 271 222 260 280 245 272 270 264 233 299 292 246 279 232 250 324 264 298 235 279 246 244 236 282 285 242 237 269 299 268 288 262 263 265 283 273 278 230 260 280 268 270 238 265 282 258 291 270 272 258 259 313 269 257 277 265 256 274 276 302 264 256 244 278 266 299 274 262 314 245 285 258 277 250 288 259 302 263 249 285 275 241 277 273 259 257 292 279 257 263 265 274 289 265 246 300 266 270 257 245 297 265 298 289 274 320 293 309 275 313 283 271 275 273 283 257 281 275 293 279 266 272 318 241 276 292 260 289 290 282 274 269 261 282 293 288 292 299 302 282 265 286 255 281 272 259 244 261 279 277 283 279 303 283 307 283 276 304 258 282 269 311 282 277 259 272 279 282 301 286 295 291 286 284 282 263 301 292 285 277 261 279 260 262 265 288 307 273 295 281 309 261 285 289 245 282 295 291 270 290 281 300 279 301 275 282 300 269 267 290 300 280 284 272 258 280 271 304 275 264 292 279 282 301 261 282 281 245 292 282 270 223 245 280 278 265 285 280 300 286 269 272 295 266 308 232 289 291 298 256 283 242 294 272 264 255 257 283 249 270 262 271 278 222 256 274 269 282 281 280 274 285 284 293 274 261 237 244 278 264 308 260 278 259 262 265 285 243 266 269 274 269 260 298 265 231 266 278 279 285 274 272 249 299 274 288 285 285 293 283 279 274 255 302 299 270 258 231 274 325 223 262 227 273 225 258 266 248 250 259 275 259 255 256 262 245 249 292 283 258 290 249 235 282 282 259 281 261 285 281 270 245 292 279 291 279 240 280 265 265 289 257 258 266 288 265 287 240 286 284 263 259 231 296 283 239 270 263 282 272 249 258 272 238 277 255 255 265 284 268 273 258 274 269 257 283 264 267 238 258 299 250 239 269 279 267 240 275 239 244 289 265 245 256 257 276 295 274 278 249 248 274 282 265 256 263 289 231 239 284 222 274 268 268 293 266 263 292 295 275 274 255 240 294 272 261 257 290 259 266 276 255 230 270 266 287 279 271 270 261 266 242 292 268 238 279 244 268 272 268 281 275 266 238 265 263 274 282 287 237 264 236 261 250 250 257 292 278 268 303 273 259 243 285 286 288 263 277 268 256 294 241 218 279 291 285 285 265 307 259 271 245 285 277 279 289 267 285 222 302 283 265 299 275 246 244 282 281 283 264 298 229 270 231 261 243 266 277 245 244 262 275 250 241 216 243 259 298 266 246 257 272 268 262 246 293 256 255 255 261 312 264 281 240 258 234 230 260 286 236 250 316 279 297 293 255 265 246 264 292 266 274 257 236 223 258 258 287 284 242 288 272 289 250 247 264 300 276 277 258 237 270 289 267 240 239 262 255 230 257 257 269 281 257 233 243 267 245 275 278 263 265 245 274 274 264 257 258 270 235 248 277 269 291 250 261 271 270 258 238 267 276 272 275 284 242 271 266 256 277 304 272 257 258 276 292 247 277 262 236 248 265 244 281 266 256 256 251 266 257 233 281 248 238 261 259 235 275 239 286 281 244 284 284 260 272 289 270 222 288 268 240 257 270 257 282 257 262 265 284 248 296 266 235 269 297 270 272 256 299 265 263 270 234 248 256 274 306 232 268 269 266 264 259 285 279 248 241 267 256 247 281 230 246 271 248 255 271 266 263 260 267 269 275 255 249 238 248 261 291 244 259 270 266 240 243 282 268 259 245 207 274 286 281 230 235 283 229 235 251 259 242 213 283 247 258 271 268 280 302 241 276 244 266 264 256 302 286 259 303 248 270 286 240 275 237 260 255 279 294 256 271 263 280 268 289 285 285 269 273 271 229 269 264 244 267 224 310 257 285 249 256 276 284 246 272 259 257 271 256 230 274 267 255 261 272 279 263 255 289 278 259 275 248 270 250 264 278 271 275 282 278 272 296 248 306 269 226 274 274 290 280 264 261 267 272 266 257 285 246 283 285 256 268 271 264 246 238 262 280 282 270 281 242 286 274 288 288 266 264 242 258 261 222 263 290 289 299 257 262 259 266 258 270 290 265 298 241 257 270 236 273 276 306 279 260 237 270 239 278 241 273 287 246 262 276 257 269 242 257 264 293 246 265 255 278 247 248 271 269 261 287 304 288 242 287 276 271 282 263 271 298 239 270 271 262 259 265 248 243 227 290 256 291 245 266 240 300 289 270 242 273 285 282 291 279 278 273 256 230 249 264 270 261 304 276 266 296 269 293 290 261 291 273 291 247 264 269 256 230 287 255 291 261 266 263 263 260 296 257 276 244 277 280 247 275 242 279 275 275 242 256 269 269 260 240 276 259 248 246 258 283 269 269 290 284 277 304 282 271 279 270 243 237 263 269 266 269 266 267 258 242 282 245 250 259 291 263 263 304 245 273 259 270 259 261 284 230 275 296 281 227 262 273 235 243 231 271 300 265 268 262 269 248 261 245 303 268 259 246 262 283 270 268 235 250 268 266 261 222 267 287 259 239 294 291 244 258 275 279 280 263 256 264 269 237 290 276 245 240 237 263 257 280 257 238 276 292 244 296 259 284 219 266 256 265 292 283 261 276 278 285 244 246 278 286 258 240 242 239 239 247 265 234 259 283 249 241 270 268 261 285 297 288 281 259 283 269 279 268 274 277 230 270 282 282 244 224 272 246 275 238 267 235 285 239 273 276 238 246 268 235 275 273 240 268 264 270 261 228 284 260 275 309 263 268 246 267 273 274 273 276 271 304 290 246 277 270 262 269 263 283 263 246 245 285 296 240 287 264 305 231 246 257 270 265 265 269 239 242 236 274 276 272 258 249 262 259 267 260 268 300 291 277 272 271 306 275 274 295 297 287 275 265 280 263 241 292 282 299 297 268 272 288 289 299 298 276 267 276 275 296 238 274 263 256 266 308 250 329 260 269 263 273 270 241 266 292 278 243 276 281 296 296 249 265 258 291 283 279 277 276 268 264 267 273 303 278 259 249 299 268 286 281 285 292 271 272 272 271 262 276 273 244 280 289 272 256 288 243 299 257 272 303 292 234 292 272 281 261 258 276 287 289 291 282 279 260 242 271 265 279 289 246 245 284 293 298 280 286 273 277 269 259 256 283 260 281 289 262 290 273 272 293 307 304 262 286 272 315 275 285 281 249 273 283 262 270 257 278 290 280 278 308 290 289 262 277 267 260 277 265 273 268 244 243 283 273 303 262 275 275 249 273 274 287 261 276 277 263 257 256 262 264 273 256 291 262 265 273 288 274 292 262 249 240 270 286 270 274 277 274 280 296 263 277 307 264 261 263 240 261 283 276 287 279 262 256 283 265 248 287 303 283 290 275 274 299 273 262 271 233 262 262 285 287 285 277 257 263 302 276 296 273 279 267 301 233 298 301 302 278 289 280 247 301 247 286 272 287 276 241 305 265 282 240 225 238 236 293 272 278 279 275 244 297 270 281 284 275 290 261 286 258 265 264 265 262 294 292 270 286 293 273 273 257 266 292 266 269 291 257 257 286 267 264 299 290 245 279 299 265 268 286</counts>
			</dataPoints>
		</scan>
	</xrdMeasurement>
</xrdMeasurements>