File: data/XRD/XG-Luft/XG-600/W6823-1D_XG_Luft_600.xrdml
<xrdMeasurements xmlns="http://www.xrdml.com/XRDMeasurement/2.1" xmlns:xsi="http://www.w3.org/2001/XMLSchema-instance" xsi:schemaLocation="http://www.xrdml.com/XRDMeasurement/2.1 http://www.xrdml.com/XRDMeasurement/2.1/XRDMeasurement.xsd" status="Completed">
	<comment>
		<entry>Configuration=Factory configuration, Owner=User-1, Creation date=7/8/2013 4:01:53 PM</entry>
		<entry>Goniometer=PW3050/65 (Theta/2Theta); Minimum step size 2Theta:0.0001; Minimum step size Omega:0.0001</entry>
		<entry>Sample stage=MRD Cradle; Minimum step size Phi:0.01; Minimum step size Chi:0.01; Minimum step size X:0.01; Minimum step size Y:0.01; Minimum step size Z:0.001</entry>
		<entry>Diffractometer system=XPERT-PRO</entry>
		<entry>Measurement program=C:\PANalytical\Data Collector\Programs\Jorrit\2thom\_absolute_2th-om_10-130deg_PIXscan_56min.xrdmp, Identifier={15BCCF57-2807-42BD-B5B9-ECC0B3DC9284}</entry>
		<entry>Batch program=C:\PANalytical\Data Collector\Programs\SimonL\batch4x_2thom_10-130°_z9.1_x0,10,20,30_y0_57min.xrdmp, Identifier={EED9823A-2BEB-424C-9252-345C4EF2834A}</entry>
	</comment>
	<sample type="To be analyzed">
		<id></id>
		<name></name>
		<preparedBy></preparedBy>
	</sample>
	<xrdMeasurement measurementType="Scan" status="Completed" sampleMode="Reflection">
		<comment>
			<entry>_absolute_2th-om_10-130deg_PIXscan_56min</entry>
			<entry>PHD Lower Level = 4.83 (keV), PHD Upper Level = 11.27 (keV)</entry>
		</comment>
		<usedWavelength intended="K-Alpha 1">
			<kAlpha1 unit="Angstrom">1.5405980</kAlpha1>
			<kAlpha2 unit="Angstrom">1.5444260</kAlpha2>
			<kBeta unit="Angstrom">1.3922500</kBeta>
			<ratioKAlpha2KAlpha1>0.5000</ratioKAlpha2KAlpha1>
		</usedWavelength>
		<incidentBeamPath>
			<radius unit="mm">320.00</radius>
			<xRayTube id="1010048" name="Empyrean Cu LFF HR (9430 033 7310x) DK442154">
				<tension unit="kV">40.0</tension>
				<current unit="mA">40.0</current>
				<anodeMaterial>Cu</anodeMaterial>
				<focus type="Line">
					<length unit="mm">12.0</length>
					<width unit="mm">0.4</width>
					<takeOffAngle unit="deg">4.2</takeOffAngle>
				</focus>
			</xRayTube>
			<xRayMirror id="27010001" name="Inc. Beam Cu W/Si (parabolic MRD)" hybrid="false">
				<crystal type="Graded" shape="Parabolic">W/Si</crystal>
				<acceptanceAngle unit="deg">0.800</acceptanceAngle>
				<length unit="mm">60.0</length>
			</xRayMirror>
			<sollerSlit id="21010002" name="Soller slits 0.04 rad.">
				<opening unit="rad">0.0400</opening>
			</sollerSlit>
			<mask id="22030008" name="Fixed mask 4 mm">
				<distanceToSample unit="mm">220.00</distanceToSample>
				<width unit="mm">4.00</width>
			</mask>
			<divergenceSlit id="22010007" name="Fixed slit 1/8°" xsi:type="fixedDivergenceSlitType">
				<distanceToSample unit="mm">220.00</distanceToSample>
				<height unit="mm">0.19</height>
			</divergenceSlit>
		</incidentBeamPath>
		<diffractedBeamPath>
			<radius unit="mm">320.00</radius>
			<sollerSlit id="21010002" name="Soller slits 0.04 rad.">
				<opening unit="rad">0.0400</opening>
			</sollerSlit>
			<receivingSlit id="22010001" name="Fixed slit 4°">
				<height unit="mm">5.88</height>
			</receivingSlit>
			<detector id="7010017" name="PIXcel3D 1x1 detector" xsi:type="areaDetectorType">
				<phd unit="%">
					<lowerLevel>30.0</lowerLevel>
					<upperLevel>70.0</upperLevel>
				</phd>
				<mode>Scanning</mode>
				<activeChannelsEquatorial>255</activeChannelsEquatorial>
				<activeChannelsAxial>255</activeChannelsAxial>
				<pitchEquatorial unit="mm">0.05500</pitchEquatorial>
				<pitchAxial unit="mm">0.05500</pitchAxial>
				<readOutPeriod unit="seconds">0.135</readOutPeriod>
			</detector>
		</diffractedBeamPath>
		<scan appendNumber="0" mode="Continuous" scanAxis="2Theta-Omega" status="Completed">
			<header>
				<startTimeStamp>2024-10-22T19:41:08+02:00</startTimeStamp>
				<endTimeStamp>2024-10-22T20:37:14+02:00</endTimeStamp>
				<author>
					<name>PRO-MRD</name>
				</author>
				<source>
					<applicationSoftware version="6.1b">Data Collector</applicationSoftware>
					<instrumentControlSoftware version="7.0E 20130304">XPERT-PRO</instrumentControlSoftware>
					<instrumentID>0000000011142674</instrumentID>
				</source>
			</header>
			<dataPoints>
				<positions axis="2Theta" unit="deg">
					<startPosition>9.99826193</startPosition>
					<endPosition>129.99755682</endPosition>
				</positions>
				<positions axis="Omega" unit="deg">
					<startPosition>4.99913096</startPosition>
					<endPosition>64.99877841</endPosition>
				</positions>
				<positions axis="Phi" unit="deg">
					<commonPosition>0.00</commonPosition>
				</positions>
				<positions axis="Chi" unit="deg">
					<commonPosition>0.00</commonPosition>
				</positions>
				<positions axis="X" unit="mm">
					<commonPosition>20.00</commonPosition>
				</positions>
				<positions axis="Y" unit="mm">
					<commonPosition>0.00</commonPosition>
				</positions>
				<positions axis="Z" unit="mm">
					<commonPosition>9.100</commonPosition>
				</positions>
				<commonCountingTime unit="seconds">32.895</commonCountingTime>
				<counts 410 399 359 369 392 375 375 371 404 367 407 372 397 418 364 383 374 364 410 419 393 402 416 404 391 392 362 371 431 397 393 370 407 387 375 402 394 385 380 370 361 357 417 359 396 382 382 394 383 380 375 398 381 402 380 398 367 372 362 378 374 369 356 368 391 388 381 377 374 387 371 365 392 362 378 395 376 355 399 375 362 363 332 407 371 358 376 440 389 363 372 379 371 351 386 392 397 391 375 371 371 375 352 346 408 355 393 385 342 374 386 368 340 373 357 376 372 381 388 351 402 349 362 383 362 380 323 356 373 347 382 341 365 401 378 393 397 368 334 385 351 385 334 388 368 355 366 357 365 346 353 397 384 371 322 366 351 340 351 310 364 332 346 374 378 368 352 357 367 379 379 357 395 365 365 366 372 335 356 345 363 362 339 367 380 358 377 322 344 359 346 365 336 342 335 338 359 380 359 356 348 363 345 326 351 317 351 377 371 363 370 355 337 342 344 328 370 329 361 334 364 376 336 341 339 312 312 320 361 334 348 365 387 355 339 352 331 329 347 346 339 366 342 334 385 358 340 319 338 397 348 382 360 372 351 347 342 334 301 318 297 349 335 365 338 319 348 367 315 330 347 330 375 354 343 339 299 358 328 330 339 356 313 353 335 308 304 322 326 329 328 333 342 297 326 340 341 317 364 312 314 307 350 324 308 315 340 315 310 294 332 335 317 308 299 352 318 320 286 322 344 352 341 306 357 335 344 331 324 326 306 315 345 316 320 310 310 338 307 309 341 321 332 328 330 331 280 334 322 332 306 290 322 355 335 333 300 307 304 313 332 334 312 316 340 293 351 315 320 298 337 301 338 298 303 312 324 282 301 317 312 333 323 327 304 359 288 303 320 305 310 337 315 262 271 312 307 302 317 327 323 307 312 316 313 319 300 323 321 284 299 291 310 337 326 322 298 309 291 288 324 295 313 281 299 334 301 309 321 312 308 279 247 329 298 293 282 293 305 314 283 300 306 303 305 317 333 286 324 309 311 317 295 322 313 334 299 276 281 289 317 284 310 296 313 296 318 301 294 294 297 301 300 300 291 276 292 302 320 327 314 307 295 283 284 310 263 266 318 261 307 291 300 288 319 310 270 296 309 298 288 312 285 322 298 292 301 283 313 299 297 291 305 278 272 310 321 321 297 312 304 305 293 284 249 308 289 307 291 272 291 313 280 305 283 309 292 302 258 310 304 290 285 261 278 287 293 290 300 266 275 320 269 296 294 276 273 295 268 271 282 296 280 284 279 271 306 290 270 299 276 275 296 275 303 289 313 244 267 308 274 282 288 286 263 289 295 289 346 317 281 281 300 299 264 257 264 262 273 322 295 307 256 288 232 286 305 291 276 292 288 277 293 270 291 281 305 298 320 295 291 287 301 279 302 261 292 282 295 293 291 250 305 282 265 265 282 250 288 270 278 303 286 285 258 280 266 293 290 272 313 291 288 285 280 282 273 280 273 300 288 260 310 270 264 261 304 266 267 266 279 265 284 267 278 306 273 274 269 281 289 293 264 261 292 294 284 277 259 279 287 297 282 301 247 287 298 303 306 306 293 271 275 247 272 286 282 299 277 298 308 279 281 261 282 292 267 292 264 236 277 259 305 243 295 274 268 245 308 267 267 294 281 287 282 281 283 289 300 300 280 281 298 305 305 263 297 271 286 262 259 297 290 276 289 276 274 249 260 285 271 279 268 266 265 293 260 283 259 261 268 290 241 271 233 300 256 288 277 250 285 294 265 320 262 258 258 286 292 276 276 255 257 258 308 278 248 312 280 298 305 272 273 288 274 270 274 297 312 272 290 298 285 265 279 290 293 263 270 309 295 282 292 281 262 267 306 262 271 306 276 294 288 288 263 273 298 265 264 278 278 313 299 258 293 269 311 296 263 283 272 310 326 267 288 297 283 240 283 282 291 271 284 273 270 273 265 284 292 264 282 271 271 293 285 247 285 272 275 260 288 258 302 281 267 281 302 269 300 281 291 271 288 269 275 298 255 273 288 287 278 270 281 276 286 287 282 295 290 287 292 272 306 298 284 300 271 276 316 279 293 307 272 310 271 294 305 326 278 262 280 291 246 302 299 294 298 310 310 290 274 291 270 301 288 320 255 292 279 275 293 264 316 288 264 301 296 284 284 263 283 294 295 301 290 297 315 293 288 261 271 289 298 272 309 285 323 308 273 301 292 289 315 293 288 294 304 270 270 282 308 283 304 290 323 295 319 307 301 296 284 277 309 295 296 280 279 290 298 277 301 313 283 297 274 265 282 310 299 308 318 277 315 290 292 287 295 292 320 300 302 333 312 310 281 268 290 297 267 300 301 269 266 279 271 324 264 258 265 288 302 287 306 313 313 307 294 313 310 305 273 292 304 297 293 268 291 311 328 297 277 304 294 306 305 298 286 297 287 301 294 330 259 289 248 313 285 256 303 265 267 306 296 269 346 301 302 300 285 314 264 296 293 328 323 297 300 289 308 315 248 306 305 302 245 330 308 303 303 296 283 320 288 280 291 330 292 304 313 306 275 307 289 312 310 286 317 325 322 297 279 297 323 300 320 320 323 280 311 300 283 303 293 304 310 306 322 311 289 306 317 292 301 302 297 266 312 293 308 328 343 288 304 277 356 289 293 313 324 335 278 330 315 304 321 281 307 315 330 267 314 293 304 287 293 295 296 311 318 303 279 276 299 288 289 292 289 324 326 312 286 339 306 319 301 255 310 295 278 346 320 313 307 297 297 292 325 282 319 304 304 302 306 335 301 288 293 293 310 333 306 283 271 304 300 309 276 294 287 332 274 309 309 288 317 277 308 289 293 272 282 289 341 269 320 285 300 295 287 333 289 311 332 299 318 290 286 324 311 315 311 332 277 309 289 296 304 318 329 328 317 310 329 309 312 296 345 320 323 291 312 329 273 317 322 309 296 310 293 288 321 311 318 283 313 320 300 281 307 319 323 290 319 304 320 313 314 316 279 300 321 299 315 334 301 316 279 329 299 310 278 305 284 283 346 291 300 272 309 268 310 310 324 312 323 298 308 286 301 329 314 298 275 326 304 292 284 306 304 277 319 292 315 311 333 328 286 291 283 297 270 278 270 329 308 286 287 303 304 291 288 311 304 298 325 298 333 292 331 302 301 314 301 299 315 310 309 299 294 303 296 299 288 338 299 293 301 324 299 281 293 325 298 245 289 313 290 321 335 275 331 297 290 304 301 287 291 323 289 324 302 297 315 272 322 289 306 299 294 283 313 284 309 294 301 283 314 281 278 286 280 275 291 307 292 265 260 275 275 294 275 295 330 309 302 301 260 263 292 299 268 304 282 310 292 293 294 274 328 288 281 272 302 269 286 282 275 277 311 241 286 278 307 302 243 259 312 271 283 315 294 289 297 282 307 312 280 304 285 327 309 274 267 323 277 300 302 287 283 275 289 301 335 312 285 272 249 295 297 264 288 289 292 274 289 276 327 300 312 264 318 306 304 261 316 286 298 317 260 257 289 304 290 304 265 268 316 289 265 266 296 279 261 292 297 314 316 274 288 279 282 259 287 276 273 295 278 312 298 290 274 289 268 290 272 264 247 297 281 262 292 260 244 258 275 304 236 257 274 272 268 308 294 285 276 282 301 277 284 290 262 294 281 232 286 289 291 267 271 269 292 295 277 283 304 279 299 276 287 262 290 311 290 290 292 240 267 243 299 277 291 249 260 260 290 243 246 312 270 270 265 288 264 236 276 274 283 283 300 263 263 275 262 263 258 237 272 271 256 255 280 269 283 239 283 281 262 288 263 276 295 269 236 246 236 271 244 245 276 248 283 249 269 275 270 263 266 234 264 293 231 282 298 265 262 276 274 269 259 283 264 277 228 259 262 228 286 270 285 266 262 267 256 261 255 234 284 226 259 248 245 259 247 273 235 291 261 273 270 288 278 289 220 292 256 265 235 279 221 265 287 255 229 246 223 280 265 296 263 243 256 263 245 256 294 271 242 273 278 229 264 260 256 270 235 262 226 230 244 236 260 231 238 232 258 234 265 260 271 309 263 274 255 266 230 236 255 237 247 234 289 238 258 214 260 255 238 239 242 222 235 259 240 227 249 233 268 233 221 215 276 246 247 273 233 240 231 249 255 255 279 225 235 228 244 255 263 263 229 256 261 271 266 257 257 238 260 272 234 211 261 246 224 243 269 239 266 231 249 214 224 259 223 278 237 233 255 242 206 216 241 230 242 265 239 221 236 260 262 240 236 242 255 258 211 241 264 269 222 240 231 245 224 256 250 264 235 219 227 240 221 239 235 240 217 264 220 244 261 237 238 217 260 231 219 250 227 239 237 224 247 235 230 222 222 240 264 245 234 229 232 242 231 230 277 237 220 225 231 268 225 224 230 267 239 228 217 219 273 201 257 229 232 245 220 247 231 259 226 228 214 248 248 236 216 228 221 241 243 223 275 222 240 227 258 238 217 223 249 238 249 230 205 207 229 234 255 247 205 213 207 232 206 235 205 239 236 239 246 222 222 237 257 232 249 242 227 260 279 224 265 218 227 238 255 210 213 257 222 207 195 234 185 205 229 234 216 221 234 220 222 234 218 236 219 264 223 228 227 213 218 220 227 211 235 238 200 224 217 230 227 231 224 234 227 216 237 211 223 242 265 234 231 200 241 240 196 239 238 219 218 212 228 206 215 222 223 184 226 221 232 229 228 224 241 228 242 205 224 220 234 242 237 202 220 204 221 231 243 205 224 293 205 225 222 240 227 241 240 213 228 219 218 213 242 178 235 226 222 221 246 218 213 229 225 218 208 245 213 219 227 255 234 200 223 212 244 235 227 219 239 208 207 222 256 227 246 232 221 213 216 218 237 211 210 216 240 192 212 226 219 234 212 215 222 207 195 235 214 187 194 220 220 215 244 204 210 208 205 216 209 222 197 219 188 214 228 212 222 236 231 213 228 221 206 214 235 234 203 212 209 217 201 223 208 225 202 219 201 225 238 210 206 200 218 209 243 209 228 216 217 212 201 217 231 232 203 211 223 204 243 222 199 202 215 239 223 212 221 191 219 203 222 217 209 228 195 203 212 203 213 227 194 208 211 232 197 228 238 231 210 235 221 203 229 217 215 192 205 202 210 207 221 230 199 229 226 215 208 226 217 219 199 223 211 198 201 218 231 212 216 206 213 214 186 213 211 218 220 204 225 211 214 221 220 183 230 203 213 227 210 207 243 184 229 208 241 205 225 249 193 222 221 201 198 220 192 207 202 246 214 193 223 222 217 197 196 189 220 224 206 204 244 209 230 220 228 202 205 227 227 202 219 193 193 201 206 200 205 208 231 182 233 213 190 255 211 208 202 215 211 228 196 222 219 212 193 211 223 200 222 207 193 212 206 205 181 203 206 209 212 220 218 228 207 218 213 219 230 216 196 179 223 210 190 225 195 194 216 238 234 198 218 214 226 211 223 218 209 214 214 206 220 212 210 220 239 228 207 215 221 220 227 216 224 225 203 210 237 187 217 208 207 225 195 193 199 206 233 214 221 220 199 192 196 223 205 217 214 196 210 191 222 205 225 228 192 203 196 186 233 206 199 190 214 213 218 214 223 202 196 206 174 228 203 219 210 200 224 212 211 207 220 226 235 203 193 205 209 202 220 220 243 217 222 201 205 243 223 227 230 229 195 189 198 193 193 190 214 216 215 221 210 219 203 212 188 173 226 214 207 218 216 224 201 199 214 192 219 201 219 211 193 206 228 213 193 213 211 199 207 188 223 204 224 207 239 225 216 208 221 205 225 210 214 210 204 210 219 210 227 218 220 182 229 214 204 218 205 202 208 214 216 212 217 192 204 216 233 188 211 198 198 232 207 197 199 217 207 217 182 197 184 201 210 200 209 230 209 238 195 200 214 193 196 200 202 221 228 196 198 181 186 208 223 203 224 210 206 198 191 234 200 194 191 228 205 198 203 217 210 210 212 216 227 205 230 203 191 234 200 221 224 227 224 203 205 216 204 190 224 215 205 183 185 212 194 198 194 205 236 207 213 194 227 214 215 199 207 215 249 204 236 229 226 255 222 196 210 210 205 193 212 201 210 194 221 206 215 205 197 203 228 237 216 215 235 232 207 205 233 215 206 229 209 199 212 203 238 215 213 198 228 221 231 227 210 227 192 195 191 216 215 222 211 205 216 218 215 221 219 219 207 215 206 195 227 225 202 195 223 202 198 193 209 199 226 205 204 218 212 175 222 205 196 211 199 219 196 192 194 213 210 200 225 206 181 218 211 223 211 205 191 211 223 211 186 239 203 190 202 188 197 200 209 208 236 220 225 199 230 178 198 201 219 197 218 226 227 190 220 185 218 218 191 226 211 214 218 209 195 215 215 202 211 219 209 217 210 219 238 225 185 208 180 197 189 240 222 190 218 204 170 215 221 228 202 214 212 208 218 206 247 215 206 200 214 185 226 183 187 223 205 216 224 199 218 224 206 168 226 205 202 216 212 200 190 206 213 213 208 214 197 221 221 216 208 202 209 232 224 235 211 236 234 189 233 207 215 198 216 233 209 205 231 203 218 210 211 189 201 224 227 218 215 219 225 205 213 193 231 233 183 212 207 204 213 188 198 212 228 220 212 219 208 206 193 234 237 176 204 196 191 187 196 200 204 220 216 211 206 199 206 178 208 211 186 238 201 221 212 229 226 207 184 215 220 222 204 217 226 194 223 229 224 215 232 224 229 213 193 223 231 205 192 217 195 209 226 194 225 194 221 208 204 221 210 202 194 222 242 210 215 208 224 217 199 220 187 240 214 204 225 212 200 230 225 216 206 178 247 195 196 217 242 188 207 237 227 208 224 196 230 216 192 190 197 225 210 206 210 211 197 202 201 186 210 208 220 209 223 198 225 259 212 195 200 215 226 219 216 221 233 217 220 210 206 199 208 220 236 218 216 230 206 187 228 215 228 258 194 223 226 235 207 220 189 216 235 218 196 230 220 235 216 186 222 213 227 211 231 225 207 229 212 227 203 220 201 194 230 216 232 225 206 222 204 193 226 214 222 255 214 199 185 212 219 222 231 210 206 207 201 213 225 210 207 211 205 196 211 228 181 222 205 194 204 221 223 201 237 236 208 214 228 207 230 231 265 204 215 230 206 207 209 207 203 183 208 223 201 209 201 212 220 212 210 226 214 231 191 220 227 197 201 220 195 205 206 204 206 229 229 217 221 218 216 232 212 230 231 219 249 196 226 246 217 259 228 226 219 221 208 205 213 248 201 233 212 217 200 191 216 211 226 210 230 227 232 267 198 233 229 201 207 192 233 205 225 211 236 245 231 192 209 218 247 209 220 217 211 203 223 230 219 211 210 210 214 217 218 199 198 229 223 221 179 201 207 219 213 235 237 224 236 227 231 216 222 204 206 232 217 219 200 217 234 230 226 243 226 223 225 258 245 209 241 207 241 210 244 239 196 238 221 223 236 212 208 225 214 228 231 216 259 255 243 209 211 217 246 246 247 218 225 239 204 240 231 220 227 234 265 247 243 216 245 241 245 242 224 232 245 216 260 227 232 232 263 239 236 222 246 221 226 262 212 231 259 246 214 208 247 200 245 259 242 247 220 231 238 261 212 192 243 235 225 241 262 264 235 226 215 263 223 233 236 236 205 212 215 232 248 233 237 223 266 229 224 206 218 255 230 227 213 250 236 239 239 231 233 233 235 245 243 238 248 216 284 259 272 219 267 265 256 257 239 264 261 264 234 262 257 225 277 271 236 245 236 259 278 258 246 276 281 280 284 290 274 272 306 290 306 317 296 306 328 307 334 343 358 348 339 362 345 357 368 393 374 377 342 385 392 351 430 393 393 389 453 381 373 394 390 350 393 378 341 347 360 333 333 295 347 318 316 331 288 317 289 286 304 276 324 291 266 279 273 326 268 249 272 273 288 263 220 236 241 268 257 248 262 273 235 234 259 231 221 229 245 282 236 228 229 236 242 204 278 213 237 226 227 236 222 247 234 235 233 248 182 247 219 218 248 188 224 222 228 255 235 191 228 225 255 226 233 246 219 250 235 232 193 227 208 213 213 232 233 233 233 225 230 238 210 215 209 218 195 224 203 216 212 228 222 236 236 217 218 237 226 235 213 224 227 210 231 215 217 244 217 256 228 229 204 226 234 235 241 232 227 201 217 227 212 200 196 196 221 205 215 209 232 218 234 201 218 257 203 225 194 232 243 224 246 235 225 205 219 206 209 234 225 225 223 188 207 229 215 204 230 219 218 227 217 215 218 193 224 197 234 205 243 243 219 183 222 211 235 222 238 209 216 205 203 222 211 199 235 196 196 221 215 224 227 230 205 206 233 221 242 199 207 249 203 217 225 258 230 221 193 212 221 219 227 227 203 230 226 229 220 231 220 199 206 238 210 248 224 226 214 226 223 198 220 222 228 204 198 221 243 210 228 207 222 191 210 218 208 213 217 232 205 217 228 227 219 213 172 221 255 200 210 234 239 221 224 237 244 223 222 243 230 229 232 240 210 208 225 222 233 230 241 222 220 205 204 212 211 212 214 231 239 208 193 245 206 218 218 225 219 225 232 245 240 220 215 235 184 205 226 217 207 208 222 232 241 211 197 198 238 234 235 231 229 226 202 208 226 228 205 216 209 219 212 196 232 224 231 224 237 221 227 234 243 203 233 229 258 223 229 238 233 230 222 220 227 208 225 187 199 248 214 235 244 237 213 214 198 223 211 216 232 243 262 222 229 235 225 189 247 212 232 234 232 244 237 248 195 243 215 233 236 202 233 237 233 224 217 236 199 223 208 230 213 209 208 216 210 211 205 206 265 225 223 261 268 229 199 212 248 203 221 218 232 227 193 239 211 232 231 211 226 218 256 219 234 210 218 235 217 216 231 210 214 216 216 207 210 229 237 202 233 209 233 209 201 222 227 212 199 222 220 223 240 237 217 226 216 229 210 243 240 218 200 230 180 260 210 248 229 224 227 219 225 263 231 227 239 238 236 209 233 219 256 223 238 217 234 219 221 216 210 218 229 214 213 231 218 240 244 230 225 221 233 207 221 240 232 226 219 204 228 232 234 222 228 212 255 226 229 234 226 238 205 228 231 236 214 227 211 217 223 233 246 217 223 255 239 209 220 247 219 228 231 213 223 215 214 224 205 197 217 228 222 195 205 198 204 221 209 229 213 222 228 224 242 190 219 223 238 237 222 237 207 220 224 206 221 217 249 221 229 243 224 213 196 232 236 179 249 257 240 225 233 235 219 225 216 218 227 202 240 204 216 218 218 219 233 215 219 196 225 209 237 209 234 224 223 216 220 239 197 241 234 230 213 214 216 222 230 224 265 237 228 218 257 241 233 229 213 217 222 220 218 243 201 213 206 206 231 217 236 229 247 211 210 262 229 230 203 206 220 237 214 227 247 256 225 260 242 213 213 225 227 212 238 217 216 230 225 250 194 220 262 222 191 196 227 225 218 243 209 233 224 220 228 220 239 226 222 207 203 206 233 238 215 232 233 221 244 229 215 206 214 225 233 229 245 204 207 204 244 231 193 218 222 195 215 204 231 216 239 214 239 221 231 256 261 232 231 237 247 248 231 244 217 232 237 224 203 226 270 233 245 228 234 244 245 208 195 217 240 243 214 228 233 239 215 204 192 192 214 245 217 216 222 260 198 237 241 227 226 203 225 219 228 227 222 223 243 224 229 214 206 236 227 232 217 262 216 267 208 217 246 232 249 212 219 233 231 216 236 206 236 221 217 220 241 207 217 244 225 218 257 233 240 225 230 218 234 227 212 215 236 220 186 225 218 232 227 235 222 217 239 247 224 234 237 245 225 206 235 241 209 215 219 211 241 228 232 256 247 188 238 230 224 241 226 269 225 214 234 250 206 222 240 217 213 217 219 239 207 249 242 207 235 230 219 211 213 235 242 225 242 214 225 206 233 237 240 227 217 211 206 224 196 247 218 214 223 243 228 219 225 245 242 227 209 246 202 201 221 243 260 233 201 218 210 226 263 242 257 221 265 255 228 238 228 222 219 225 219 244 230 211 217 220 235 216 239 220 241 239 227 220 235 232 231 209 249 218 229 208 233 237 219 228 223 196 209 231 216 206 206 214 212 221 223 218 259 239 207 217 224 230 220 210 222 228 210 216 208 224 201 209 241 231 242 218 239 223 232 231 240 212 233 246 223 198 225 219 208 217 221 214 230 217 249 262 260 219 198 226 234 222 225 219 203 238 221 215 235 220 226 223 265 209 249 235 239 225 230 189 233 240 238 230 226 226 224 210 226 219 225 248 242 214 203 240 212 238 227 233 222 243 223 234 208 236 228 213 238 232 225 210 230 219 230 231 213 231 207 216 196 223 224 212 221 223 235 210 234 223 210 258 233 247 218 241 270 266 225 217 240 215 200 202 233 259 260 248 197 228 211 212 227 218 221 213 234 224 202 240 225 240 224 265 216 200 213 231 204 207 216 217 223 221 235 233 235 242 237 233 217 207 237 221 245 228 225 246 238 244 214 222 230 243 226 246 219 194 233 239 239 209 238 225 212 244 237 246 218 221 234 239 238 227 222 231 213 220 229 229 235 217 210 234 243 224 235 223 230 262 228 241 217 247 265 231 228 236 223 218 210 230 233 232 236 225 228 207 220 257 257 242 237 242 249 238 223 230 232 236 216 235 209 263 237 207 258 260 219 239 238 211 236 223 242 234 239 205 227 229 247 222 209 219 212 223 246 218 227 235 220 242 225 228 244 219 218 222 226 221 237 232 218 248 217 232 219 200 220 234 260 249 240 204 228 260 246 264 255 220 216 228 218 215 217 219 258 205 247 256 218 238 226 244 193 244 218 242 222 214 256 220 224 225 202 238 219 213 216 246 247 215 215 230 215 271 206 224 234 214 230 195 234 217 241 234 212 214 226 219 237 246 223 234 240 217 224 219 226 232 206 263 202 219 228 217 233 259 226 235 216 228 239 215 242 245 203 230 212 233 232 234 238 241 240 264 221 234 237 212 224 224 225 211 208 245 218 240 226 239 237 210 270 208 219 223 263 224 232 244 240 265 239 229 216 218 221 222 221 276 204 238 242 259 245 215 230 195 243 239 257 257 225 224 236 216 210 226 226 267 222 248 200 236 222 218 223 219 230 246 224 202 219 223 233 223 217 223 215 245 233 224 211 221 207 216 208 263 227 222 227 261 232 246 236 235 203 242 240 229 258 211 226 241 244 219 224 256 222 227 229 218 249 218 225 211 244 243 282 265 217 257 210 246 214 265 271 233 220 230 216 247 217 241 246 218 205 205 204 241 266 237 248 232 220 221 246 255 202 207 229 216 216 263 241 220 206 231 248 240 226 237 244 227 248 234 224 226 231 289 238 209 238 221 260 209 237 232 256 233 256 219 212 223 218 229 227 199 231 215 206 244 206 224 243 245 225 197 222 243 237 238 242 216 226 241 255 213 259 229 238 235 224 223 250 257 211 231 225 226 218 241 257 264 244 248 215 240 239 236 227 237 237 237 235 238 239 227 217 240 208 236 256 232 235 222 240 217 233 232 215 209 229 220 245 209 212 234 233 244 221 220 227 207 247 240 223 230 209 236 260 220 264 237 224 194 247 245 238 230 239 241 218 205 247 265 226 258 241 265 204 246 239 225 232 234 213 238 225 248 217 221 233 241 237 244 228 234 235 232 185 239 244 223 246 243 246 233 232 216 246 256 242 222 222 210 223 195 230 230 233 216 220 239 265 218 223 216 245 240 217 241 226 235 218 226 256 244 256 216 209 259 222 211 249 256 197 230 217 224 257 221 233 240 212 225 238 265 258 212 246 243 217 256 239 242 213 205 220 220 240 248 229 235 223 245 231 235 233 225 228 224 244 244 259 220 236 224 229 227 212 232 218 234 270 248 230 279 232 228 236 223 224 224 232 266 268 219 245 241 229 229 239 215 267 224 208 211 261 234 243 229 217 226 235 225 223 246 221 240 223 231 219 240 209 247 240 235 233 223 234 245 232 203 239 226 228 263 228 221 219 234 230 233 230 237 240 243 220 238 247 227 236 234 234 225 255 227 292 216 219 261 223 233 237 259 216 234 229 249 239 232 199 260 250 212 229 229 218 224 234 228 213 233 216 224 222 236 243 225 240 249 216 225 255 231 255 234 274 234 243 230 216 222 248 231 230 230 240 226 227 243 247 261 216 233 246 239 248 208 218 235 217 241 227 231 228 226 222 216 212 261 238 218 233 242 221 235 250 230 218 262 243 227 216 218 243 249 268 214 237 260 211 226 240 231 222 229 260 238 221 240 212 229 226 236 215 235 239 249 206 224 237 250 268 236 230 219 230 259 236 270 234 239 237 263 241 263 258 241 241 227 236 241 239 258 261 246 243 228 258 275 248 276 227 242 268 215 237 223 222 265 235 239 270 226 246 260 255 243 239 270 264 281 223 232 268 240 227 239 264 264 257 265 270 241 233 289 241 226 245 244 242 266 245 233 245 257 242 233 260 277 279 237 256 235 244 283 270 272 228 240 293 262 259 247 245 234 241 223 267 239 240 219 258 266 255 244 225 221 230 248 248 236 258 263 222 212 229 257 241 272 232 270 216 233 235 239 264 237 230 236 223 235 220 248 236 246 223 268 259 236 224 263 212 209 226 240 246 231 235 234 242 236 247 239 247 256 236 229 257 288 224 238 231 229 247 227 216 228 216 225 213 238 230 220 256 229 222 233 242 244 248 239 223 245 234 219 258 237 239 216 228 228 225 238 238 245 230 240 235 225 225 241 225 228 235 258 234 234 221 213 211 227 214 236 238 241 249 244 190 232 257 281 223 215 248 224 240 232 221 239 228 223 227 217 242 231 265 232 235 229 208 230 259 232 224 205 224 222 244 234 225 234 234 232 220 232 284 244 219 223 225 205 220 215 226 226 216 216 242 234 242 218 249 214 259 232 276 228 201 241 236 203 249 228 246 242 233 242 244 207 241 265 213 258 236 207 206 211 227 236 255 261 244 235 236 227 206 247 229 270 215 218 261 261 222 263 244 247 220 239 233 217 235 200 235 238 246 227 234 269 234 222 249 232 242 222 239 215 222 236 241 219 226 238 190 259 225 274 242 215 207 228 213 231 224 242 237 238 225 262 259 255 211 257 256 220 246 242 231 215 222 231 262 233 210 262 233 242 237 250 231 219 206 250 263 210 222 238 246 223 211 217 227 229 234 255 209 242 222 241 224 234 263 202 241 218 222 232 229 258 219 247 200 212 234 203 227 224 230 232 258 238 219 214 204 246 223 228 238 223 263 238 229 220 242 256 237 243 245 256 259 228 234 261 269 239 233 262 237 220 227 233 223 208 218 243 243 235 239 226 230 218 228 212 203 242 238 223 235 234 245 212 269 227 240 226 227 238 225 226 264 209 230 238 204 233 212 243 226 215 225 193 227 255 219 237 249 237 225 238 229 216 219 215 219 244 216 224 238 241 224 214 237 248 218 223 216 226 237 221 207 217 262 234 231 228 223 221 234 238 216 226 210 222 212 247 261 228 240 230 243 248 225 267 235 226 220 257 216 228 245 239 239 215 237 228 275 225 248 217 216 231 238 204 258 235 265 234 270 259 239 243 224 228 234 226 214 245 228 236 224 221 235 241 245 230 240 238 206 262 223 241 241 258 237 246 226 230 227 258 227 224 219 239 203 224 225 199 238 216 227 265 226 198 232 255 225 247 247 247 260 273 256 239 222 228 233 263 216 230 248 204 229 240 235 230 235 201 217 199 241 237 235 235 221 238 228 228 237 221 235 216 242 231 233 284 222 226 222 208 247 241 261 226 219 232 218 202 245 271 242 209 212 240 244 249 230 238 233 227 255 229 226 229 228 261 209 258 243 232 223 213 216 239 212 200 249 230 210 242 225 236 225 218 230 233 255 213 233 214 220 225 223 258 223 223 227 215 243 244 223 211 216 223 240 229 226 259 260 261 245 221 243 221 260 244 232 217 229 260 217 224 213 240 242 230 215 212 246 248 231 234 217 225 257 233 235 231 261 230 246 236 255 234 236 227 246 250 218 243 228 248 224 234 228 248 269 219 246 239 260 224 241 265 228 221 206 264 234 259 191 218 228 219 221 261 213 216 225 225 229 231 196 239 249 243 228 233 257 226 256 255 220 236 236 219 207 225 218 229 229 236 248 250 241 259 263 214 228 241 226 206 241 226 242 219 236 233 225 233 247 215 238 223 226 240 247 218 211 223 220 230 223 224 238 214 225 224 212 240 201 237 227 259 250 257 242 232 223 232 209 237 234 214 249 229 211 240 234 212 271 226 223 232 224 240 255 262 219 225 225 245 214 256 220 231 242 212 222 262 236 239 265 211 245 269 214 228 232 249 219 264 228 214 186 210 218 217 211 224 243 262 244 266 231 223 245 229 209 223 231 231 264 269 240 243 224 258 232 225 261 216 241 227 233 256 235 236 207 234 224 229 206 216 225 219 250 232 218 241 234 216 249 262 233 236 219 213 245 245 211 261 223 224 238 232 237 272 200 225 245 235 224 216 246 217 218 213 217 238 239 203 225 224 224 208 214 236 231 226 223 218 264 250 241 264 231 242 233 243 218 221 260 230 235 224 232 241 225 233 237 238 237 261 259 242 246 261 225 227 243 220 206 230 231 219 232 260 256 230 255 241 228 260 224 233 263 241 226 255 243 227 246 235 214 236 261 236 218 236 262 239 234 230 231 221 228 234 226 215 245 227 244 231 230 258 243 219 240 211 258 239 228 236 236 227 229 244 213 263 221 257 238 211 222 250 243 261 270 230 244 216 221 240 235 219 203 201 201 201 244 234 236 255 272 204 218 246 245 210 237 242 213 217 216 249 246 227 212 245 250 234 236 270 206 232 243 224 267 225 225 218 242 246 258 236 209 229 249 214 227 229 219 223 238 223 232 240 211 209 224 248 230 237 228 228 246 246 221 214 224 205 236 230 225 225 233 225 222 256 228 232 227 249 247 259 243 229 223 208 247 224 213 259 232 238 209 220 220 227 250 231 237 247 268 225 223 226 226 247 219 225 191 224 235 232 238 227 217 226 259 236 256 237 226 239 265 212 263 220 227 209 235 240 229 237 273 219 200 255 245 231 199 239 258 238 280 245 226 215 214 266 259 246 237 238 260 242 239 232 235 221 231 217 221 238 250 280 258 227 233 230 261 242 240 236 238 237 232 225 240 247 242 247 231 258 266 258 204 215 199 193 243 236 201 218 249 218 231 224 218 237 241 244 218 243 231 265 230 234 238 229 228 263 249 225 232 234 241 239 257 235 237 231 269 272 206 230 223 222 235 223 239 236 232 231 218 228 227 240 231 238 224 236 224 231 217 250 228 243 277 239 228 264 242 232 241 209 232 233 223 255 216 224 210 232 234 236 244 232 211 242 266 204 265 237 227 247 245 216 231 228 219 241 225 257 239 256 224 222 244 204 255 232 237 232 200 248 245 227 236 212 246 244 258 237 243 238 225 274 210 258 218 246 247 257 263 241 256 222 221 248 256 241 222 234 204 278 225 268 200 226 221 241 241 233 257 223 241 237 218 203 244 249 238 214 219 204 223 220 227 260 228 239 227 231 233 255 235 216 231 211 219 238 243 225 244 228 240 221 255 241 233 235 237 240 240 233 244 232 244 235 255 199 269 257 288 216 224 239 235 264 239 226 227 231 228 238 232 242 204 249 256 229 233 242 228 256 228 234 217 261 224 222 256 235 262 224 234 242 250 247 202 223 246 225 235 240 259 261 264 262 263 226 227 236 227 244 262 239 266 257 218 255 259 216 235 229 237 240 225 239 243 229 259 237 227 239 239 221 246 241 215 231 225 227 244 224 241 273 224 221 236 205 239 257 216 227 258 215 258 230 232 236 259 227 230 263 234 235 235 243 238 215 255 279 196 227 204 255 241 235 228 199 222 263 191 239 221 234 230 239 208 209 204 223 240 225 203 232 243 244 216 245 256 240 244 218 225 225 269 243 231 246 231 240 231 221 221 218 226 247 219 267 233 245 248 258 244 276 231 239 227 236 233 239 243 234 238 244 232 229 243 220 259 218 225 230 257 244 260 213 211 225 256 223 237 233 210 242 266 234 216 246 235 226 255 239 209 268 248 225 230 240 245 229 221 231 259 265 245 210 264 220 223 207 236 247 235 244 217 220 256 236 255 246 231 243 200 225 248 240 234 245 260 249 235 214 201 225 231 242 212 259 258 237 240 263 243 218 198 233 230 255 275 233 258 249 239 241 258 219 232 236 224 231 243 256 221 235 259 238 226 221 223 257 236 244 219 232 237 235 230 240 260 259 217 225 234 209 218 229 231 241 226 236 221 248 258 226 234 241 237 242 261 262 240 262 218 231 273 228 242 227 271 224 235 239 262 227 271 241 269 226 274 240 244 247 235 246 245 277 247 236 283 229 268 231 273 270 230 234 310 277 259 266 249 287 282 262 258 278 248 268 268 255 274 265 282 265 273 268 275 243 255 286 274 245 272 268 265 236 268 268 272 258 259 261 273 249 258 271 248 256 273 235 233 239 248 275 231 217 229 228 272 244 236 211 213 249 257 237 221 228 243 268 219 247 270 212 241 233 236 225 232 248 244 240 223 247 239 242 247 262 217 255 259 238 216 222 228 230 234 240 239 236 281 228 230 241 255 258 230 238 218 212 234 229 211 288 230 215 230 244 214 258 219 229 255 235 242 234 259 248 235 197 219 225 234 247 209 231 233 215 255 226 240 250 222 211 234 216 255 233 219 248 221 230 237 215 207 213 217 223 206 246 214 236 240 226 245 236 226 266 222 230 257 221 226 237 228 248 220 225 256 225 213 243 244 249 234 244 231 228 228 223 225 226 214 226 207 224 248 232 234 210 244 216 240 238 204 196 230 263 231 238 263 233 232 226 200 187 238 248 238 216 238 226 214 213 224 230 219 209 209 248 226 209 214 249 225 265 218 217 248 231 249 237 235 236 236 241 235 238 226 217 201 224 247 220 214 204 237 225 221 223 276 228 228 268 274 220 228 246 229 217 230 226 233 203 255 238 217 247 234 228 215 229 255 243 236 209 231 224 213 241 217 284 235 215 196 229 206 218 215 236 230 247 258 216 225 206 260 229 242 213 223 235 232 237 227 261 218 259 201 225 237 187 236 208 243 258 229 231 237 231 242 217 219 226 236 210 236 267 205 215 255 215 240 233 219 245 241 245 228 203 238 234 214 232 210 247 235 229 259 243 224 238 231 212 266 230 211 230 238 212 208 235 204 203 224 244 217 194 226 266 259 239 240 220 226 215 232 240 227 263 228 224 213 228 268 216 228 219 206 233 221 258 226 202 234 228 239 211 234 246 257 239 255 240 220 255 224 239 230 220 235 208 201 255 265 248 216 219 248 229 219 226 249 232 225 234 237 233 239 209 206 197 209 247 223 265 234 222 211 215 261 235 257 201 236 247 189 219 205 234 224 236 210 240 222 248 232 214 216 216 248 189 246 221 220 205 241 219 231 255 205 236 261 222 237 207 219 229 243 249 242 236 241 221 236 246 219 229 212 200 236 233 196 242 224 246 229 207 260 219 228 211 267 271 230 243 218 204 218 205 247 206 221 213 221 207 227 224 226 201 214 214 225 203 244 232 240 234 209 243 236 227 261 245 215 213 239 236 229 246 226 235 245 241 269 230 231 240 218 203 200 198 235 216 249 233 249 242 207 215 206 201 228 263 238 235 225 228 218 233 260 234 234 209 239 216 229 249 236 230 246 235 235 239 235 214 233 235 233 234 247 201 209 226 241 221 217 205 216 216 232 224 226 223 232 236 237 215 204 213 196 238 235 263 225 239 218 245 210 245 241 243 228 230 229 249 231 223 223 238 226 238 226 213 243 222 219 199 226 218 229 215 234 231 213 235 235 247 274 240 224 230 184 227 241 240 207 234 261 239 230 266 210 245 225 244 212 214 243 218 224 221 238 223 209 228 203 224 234 227 223 214 229 197 229 226 228 236 214 235 242 232 236 237 234 237 229 232 224 208 227 223 231 218 217 246 259 234 223 238 236 215 211 215 263 217 237 214 209 228 235 214 226 243 234 222 234 240 239 211 244 259 201 247 204 221 227 225 203 222 227 222 242 233 244 240 230 238 227 198 223 264 215 237 243 197 240 243 235 229 218 223 232 230 249 212 194 236 239 230 222 220 246 214 220 203 203 224 229 236 223 229 220 235 200 246 230 220 220 232 218 208 212 221 225 218 216 276 222 210 212 216 228 245 266 232 232 235 228 239 236 221 218 255 256 233 239 223 210 235 237 224 232 246 225 231 257 231 227 264 248 222 228 236 220 213 236 224 255 231 232 235 242 245 215 238 214 238 206 224 219 238 228 220 243 229 235 225 236 214 222 209 230 230 225 195 230 276 226 217 229 216 231 202 261 200 263 231 255 242 231 232 207 242 234 211 209 212 257 229 249 216 216 229 208 202 259 230 220 224 250 241 218 217 225 223 222 220 202 232 220 235 228 212 257 249 204 237 247 240 266 232 215 213 234 234 230 236 238 219 262 219 208 200 242 229 213 203 229 247 220 222 210 231 193 190 240 244 232 216 209 214 218 224 219 206 234 220 259 233 221 218 208 237 220 221 251 210 234 237 228 219 232 231 229 258 227 204 240 221 210 240 255 227 232 235 258 236 227 235 221 225 204 243 217 226 189 244 217 214 241 223 236 221 200 229 218 231 234 219 227 229 256 240 242 237 239 249 238 236 265 213 215 214 221 227 241 215 186 221 231 220 229 212 223 208 227 217 231 210 230 232 229 260 232 232 233 224 209 216 255 236 233 217 249 212 241 226 239 220 235 221 248 237 226 264 232 222 258 229 221 227 206 220 243 236 227 228 224 224 267 259 231 213 223 235 244 218 246 226 241 221 226 245 257 230 229 213 228 190 227 199 211 224 228 237 228 231 207 203 222 202 244 260 230 227 265 221 223 257 227 235 255 223 234 242 240 265 219 242 228 246 247 230 222 224 228 193 241 207 222 210 212 232 225 211 226 237 227 226 242 246 237 217 225 219 228 294 226 224 245 247 213 248 244 208 235 221 247 193 244 219 234 236 237 214 233 265 199 231 208 226 220 226 205 249 237 211 259 214 222 206 228 226 259 228 220 227 236 243 232 257 201 240 222 239 236 279 246 220 229 263 241 233 215 249 235 203 218 235 209 223 230 235 201 208 215 245 198 269 211 229 237 216 256 216 238 196 242 211 224 212 263 231 227 242 259 219 222 238 264 226 265 246 219 241 243 233 250 238 241 218 198 214 221 223 219 244 217 210 224 232 224 237 256 236 228 245 211 233 257 234 229 232 238 230 257 242 235 230 223 240 243 226 230 245 262 208 231 219 202 232 230 227 213 229 231 216 237 250 261 234 206 202 241 257 248 229 259 225 258 249 239 231 225 247 234 222 269 260 213 247 229 206 222 218 218 255 257 231 231 207 231 240 237 247 226 241 234 237 232 234 206 238 232 226 222 228 249 230 244 213 265 248 224 228 234 273 232 211 259 238 215 274 223 207 234 234 233 224 220 200 257 263 229 257 230 237 228 230 248 235 202 246 241 236 245 281 230 248 236 239 248 236 237 236 220 203 239 268 266 202 238 209 264 260 226 223 215 226 224 232 240 230 233 230 213 239 236 240 218 232 203 228 237 245 232 222 241 210 208 271 232 226 218 224 246 227 239 231 231 259 261 233 231 255 233 216 219 208 228 266 212 230 220 243 260 231 246 286 259 237 239 246 255 233 273 210 224 258 247 236 230 237 245 260 231 244 242 213 257 261 262 266 231 234 229 222 231 239 229 229 275 227 206 236 230 247 226 205 216 231 229 248 226 237 210 229 258 235 209 247 232 230 223 240 257 239 239 264 225 228 225 227 245 222 223 240 231 210 243 238 235 216 217 205 261 216 222 228 219 258 243 232 219 234 217 230 217 225 236 266 238 216 225 225 231 231 218 233 240 216 227 222 242 233 243 247 237 230 264 223 225 260 265 239 244 228 223 228 241 210 257 215 227 250 205 227 210 269 280 238 263 191 232 237 201 235 238 198 227 266 230 206 264 227 291 226 244 235 272 239 233 205 230 257 246 229 231 261 240 217 247 259 255 222 215 219 236 221 233 255 238 237 245 268 234 238 244 217 213 236 257 225 269 238 242 229 245 241 262 239 232 280 212 248 244 235 238 228 226 244 240 257 225 244 271 235 245 222 227 211 255 244 231 222 231 241 236 247 258 223 256 226 207 230 256 230 230 243 276 225 219 269 248 217 247 222 258 217 271 274 266 242 280 211 232 244 227 249 247 230 239 267 235 246 282 215 246 264 297 242 235 240 267 218 263 241 239 247 244 223 248 235 232 241 233 279 219 236 238 211 229 258 230 224 239 266 260 233 230 242 209 226 245 239 212 267 237 212 237 222 214 223 231 243 232 275 241 219 243 210 240 240 231 233 221 229 214 219 206 233 218 230 217 233 219 239 230 259 191 271 225 217 220 211 247 235 229 220 255 216 200 234 235 244 244 216 246 225 235 242 214 292 196 247 266 236 220 231 215 221 259 243 263 232 223 246 210 247 238 240 259 219 227 222 224 204 226 259 231 239 243 225 237 225 238 235 239 229 229 225 209 262 234 229 237 232 259 257 221 219 194 210 232 264 244 231 235 236 242 223 234 196 239 213 227 230 249 220 240 237 257 241 241 212 279 235 213 230 234 248 264 287 244 236 275 229 228 227 223 220 230 221 229 267 258 266 224 250 230 235 266 258 224 287 228 230 221 211 234 229 231 223 250 255 224 231 225 222 248 222 258 268 242 234 219 215 213 230 255 214 239 267 218 222 265 198 230 258 214 242 234 210 238 231 235 231 217 214 220 228 240 247 240 263 242 234 256 235 243 245 225 240 210 215 217 214 227 220 257 236 203 248 244 211 269 244 224 242 242 208 221 229 243 211 279 264 222 220 236 239 255 225 202 247 238 204 235 238 226 235 228 194 233 241 216 248 244 200 232 242 230 215 241 190 245 249 228 264 228 209 241 231 235 228 224 215 241 212 213 211 223 228 258 213 232 262 229 222 248 223 227 227 205 212 232 231 221 246 238 230 202 204 246 209 240 205 228 227 242 250 230 240 200 227 224 237 248 209 237 222 240 230 218 234 232 239 259 227 223 220 232 290 241 222 208 219 207 224 241 233 247 255 214 232 229 215 223 227 240 230 212 219 207 239 243 231 214 237 218 264 226 209 229 232 195 242 214 232 239 242 236 211 220 222 208 200 261 224 234 218 227 231 262 233 232 234 235 216 230 273 237 257 217 233 215 259 228 224 242 218 221 235 226 233 243 228 242 258 235 212 260 226 212 228 247 239 242 221 219 258 236 237 271 197 226 231 210 237 248 236 238 212 216 235 187 243 222 243 209 242 217 225 207 240 229 255 217 239 244 219 235 233 207 260 221 240 188 264 230 224 213 229 210 233 238 236 204 238 233 225 216 200 218 247 242 195 199 211 241 217 221 243 256 238 242 212 197 233 228 230 239 238 234 272 245 225 234 256 228 208 210 239 206 203 217 221 225 245 246 191 243 217 260 240 214 227 242 227 229 215 221 265 230 236 247 237 247 244 264 246 222 236 228 255 267 210 258 225 233 230 226 235 211 255 239 227 222 218 231 227 245 258 221 229 222 235 232 222 202 234 238 210 224 216 231 234 218 222 231 212 213 234 257 215 235 233 234 238 214 241 231 256 273 247 233 228 241 208 223 233 236 234 229 209 229 237 200 243 231 212 228 234 228 225 219 234 207 257 231 236 245 242 243 246 221 257 217 204 214 245 227 203 223 237 244 204 258 240 228 233 224 209 241 216 241 208 229 245 228 274 232 236 221 220 255 209 206 219 233 216 246 210 214 229 204 204 257 220 256 201 272 242 246 261 269 243 194 215 232 256 262 223 261 220 264 218 207 219 230 235 239 228 227 211 225 240 233 226 238 222 218 248 238 238 208 242 248 241 225 228 226 214 208 216 209 224 223 229 226 220 218 261 256 229 244 208 221 206 231 268 232 188 238 233 243 264 237 228 208 241 218 234 210 256 216 197 229 227 246 215 205 245 239 249 236 239 242 247 236 215 209 202 233 228 200 227 210 234 188 219 263 220 220 223 245 205 205 207 217 214 219 196 219 244 255 222 207 230 215 214 239 242 215 235 226 245 234 231 219 225 239 237 224 224 234 235 211 220 246 208 219 272 231 207 233 244 207 218 227 238 280 226 189 230 223 219 247 233 207 217 209 232 215 212 244 231 231 196 222 246 218 222 247 220 243 222 233 214 216 215 230 234 219 212 241 216 231 248 206 239 229 239 206 228 236 191 217 230 217 238 234 217 235 219 244 226 217 234 235 211 219 222 214 224 232 213 239 220 218 209 225 231 223 239 234 231 246 208 219 224 216 232 220 242 200 228 214 216 239 222 229 235 232 207 233 208 231 213 221 231 245 244 235 225 220 193 231 199 229 225 238 205 208 231 237 240 261 200 237 225 239 241 242 237 233 222 223 241 239 237 268 201 241 222 224 242 212 264 237 212 247 257 231 177 210 217 234 262 213 205 226 220 220 217 248 233 221 229 221 249 232 214 209 227 225 227 222 227 226 249 219 213 236 230 235 247 223 214 238 214 217 206 208 221 217 232 245 211 221 228 207 229 266 230 190 222 240 194 224 209 225 223 227 256 196 242 225 229 211 236 236 224 226 247 240 230 233 223 237 206 225 211 213 236 244 245 210 236 229 233 230 222 231 218 218 223 224 218 255 246 229 200 207 222 246 225 222 232 217 216 211 228 227 222 209 219 210 227 224 243 221 206 240 262 239 221 230 225 255 230 246 229 226 239 238 256 256 234 236 222 227 245 202 228 215 227 240 220 209 211 199 225 244 230 229 214 257 244 219 229 236 231 225 255 258 223 240 230 236 237 232 215 243 231 233 243 222 246 226 210 205 232 223 231 240 229 246 213 198 200 221 233 236 233 209 197 234 245 247 207 221 234 218 228 270 257 235 247 242 249 233 210 256 239 217 215 216 235 238 229 266 222 216 233 203 230 230 241 205 229 241 249 238 222 226 226 229 227 202 235 219 218 231 233 224 263 244 266 201 212 218 227 206 242 242 256 277 219 236 247 225 239 200 241 220 240 227 206 236 249 224 213 233 211 235 228 222 223 241 220 221 220 198 204 239 234 219 212 249 267 229 234 268 256 230 236 228 206 231 217 234 223 230 238 246 213 230 210 214 203 246 218 232 241 250 209 237 220 229 214 257 233 231 204 238 277 235 234 257 232 207 256 245 241 230 238 239 244 232 259 222 232 213 227 229 231 233 226 214 215 237 242 219 233 219 213 209 226 224 231 256 236 234 227 203 231 244 227 197 230 227 244 227 223 265 224 213 260 219 242 230 228 218 243 222 247 230 235 261 208 244 234 204 224 227 230 217 223 233 223 257 229 224 231 209 232 221 202 249 226 236 278 224 232 230 216 233 202 263 232 214 219 238 247 192 228 225 217 234 244 236 244 220 212 222 210 214 193 206 225 226 207 207 214 243 231 210 224 231 231 219 259 207 239 233 219 230 209 232 224 232 279 234 244 239 225 224 223 230 222 220 215 230 267 233 234 226 256 205 219 231 220 277 216 221 232 257 230 215 235 237 242 268 218 244 249 233 222 241 242 234 217 231 221 228 244 207 230 249 247 228 220 236 233 221 226 246 270 241 207 239 256 237 229 246 229 214 240 259 219 219 226 221 219 228 256 236 223 248 229 205 232 237 227 205 255 230 242 232 242 242 233 232 215 224 222 228 211 223 226 216 190 206 216 202 235 243 259 225 227 219 217 238 258 228 241 240 220 243 206 232 235 236 222 240 243 223 240 242 219 235 265 227 224 224 238 231 248 229 264 194 212 239 229 222 223 207 239 245 201 198 231 233 227 234 245 261 220 198 239 243 247 229 258 230 235 241 199 216 247 228 222 261 263 262 229 240 269 231 236 227 211 229 240 235 239 268 247 241 229 236 220 260 214 228 219 245 198 232 237 244 236 267 209 244 219 204 245 281 258 236 234 249 259 264 225 242 244 242 274 235 248 274 213 263 271 229 220 239 248 258 228 267 229 222 227 247 236 244 221 256 229 256 228 216 233 257 233 260 257 228 235 234 225 234 236 243 237 268 229 260 263 226 234 263 232 244 225 240 236 255 240 200 232 255 242 279 231 246 243 260 244 247 221 240 233 268 220 248 276 236 236 235 240 242 246 232 259 206 239 243 245 232 255 242 278 199 276 243 243 275 243 257 235 240 231 250 258 259 238 218 233 221 234 246 206 236 235 262 263 235 232 205 255 215 267 222 256 218 225 221 257 229 270 261 241 229 248 246 223 239 234 247 248 230 215 256 209 261 229 225 257 231 260 264 225 246 222 212 262 219 232 218 246 233 258 237 228 263 210 229 222 262 223 204 216 246 232 231 233 240 234 229 245 274 234 260 240 242 242 231 233 226 238 229 244 262 212 246 226 247 220 227 236 220 242 257 244 230 207 215 246 233 217 242 217 255 201 196 242 230 231 237 242 213 237 218 223 202 227 238 205 239 233 214 240 212 244 203 247 222 223 221 224 234 216 261 214 233 225 225 223 232 208 237 259 232 256 220 246 234 213 204 210 201 227 226 210 236 257 216 271 239 278 222 261 239 262 234 245 231 215 295 256 255 245 238 231 221 236 247 236 205 208 236 234 222 241 237 229 206 225 236 238 224 237 245 237 218 240 233 207 236 200 219 226 261 249 246 209 243 219 231 211 256 215 214 214 230 228 214 225 209 214 215 227 238 225 233 206 223 240 232 223 233 231 210 235 238 222 218 201 230 213 239 204 218 246 255 239 206 220 227 211 222 215 239 227 224 221 219 219 234 212 231 233 199 205 222 243 261 227 238 227 243 232 231 217 229 272 192 230 244 230 234 225 221 217 234 241 193 227 205 214 266 233 225 215 233 219 218 223 225 235 211 204 236 259 222 230 224 207 230 197 203 203 211 197 248 244 231 234 241 241 214 251 215 192 221 248 219 232 232 209 206 217 228 219 204 198 260 237 220 222 221 216 197 248 230 221 213 218 238 238 235 239 229 215 234 207 233 226 248 225 257 225 229 217 241 233 231 209 218 236 223 214 229 223 228 234 225 232 234 196 230 211 225 228 217 223 255 260 236 245 261 220 238 270 225 236 233 211 243 225 226 210 208 241 248 223 216 240 200 230 228 232 216 224 206 226 232 207 206 242 219 218 228 218 248 209 233 219 238 226 248 231 239 246 207 226 199 228 229 194 222 224 263 240 206 265 228 224 196 228 225 202 237 226 206 258 219 216 235 246 257 240 209 244 201 228 214 247 233 222 209 213 224 240 227 228 222 230 224 225 228 222 226 231 217 218 231 219 241 231 231 231 236 215 209 230 207 246 232 223 235 221 236 233 271 214 244 216 204 238 226 227 229 226 222 219 276 222 256 192 233 221 245 227 233 243 240 245 235 270 219 224 202 207 227 222 246 229 212 224 236 240 216 214 216 193 249 242 220 224 219 210 223 214 221 249 200 206 235 215 219 218 242 230 234 219 215 233 222 208 237 231 230 235 218 215 236 205 217 213 241 229 229 206 232 230 203 207 268 228 235 236 246 218 224 236 264 232 230 232 213 245 219 215 203 219 238 223 220 212 234 262 233 246 197 227 235 228 249 233 244 218 232 265 218 220 228 246 231 234 258 230 234 245 213 232 240 222 214 233 226 232 237 258 227 265 282 212 270 210 210 262 231 227 239 249 225 229 223 195 265 227 256 231 195 272 248 228 215 240 227 243 192 240 248 218 275 217 243 243 230 235 213 225 210 233 255 223 240 238 220 247 231 237 220 238 256 234 227 249 262 264 225 232 223 282 232 255 238 230 201 220 235 240 205 248 222 247 246 260 211 258 245 227 218 249 230 207 214 234 223 225 208 225 217 265 232 228 223 248 229 216 231 221 241 257 209 228 227 220 247 203 221 262 231 219 259 237 247 241 237 211 229 209 268 239 216 248 233 245 223 205 243 239 257 237 243 203 240 229 211 217 244 240 217 220 205 231 230 221 225 232 232 237 233 257 223 218 215 248 227 227 237 239 257 206 243 233 214 246 243 230 217 220 240 243 239 229 221 240 265 244 230 229 227 215 222 235 218 241 256 230 249 236 217 242 228 262 237 214 228 256 214 185 234 229 220 248 223 219 235 245 248 208 229 244 228 226 230 206 230 247 236 244 235 229 213 255 237 228 243 235 212 229 247 216 214 247 244 238 240 224 233 231 263 256 225 224 232 238 187 230 233 225 238 240 224 224 234 224 238 236 219 247 247 241 249 249 228 224 223 238 244 226 238 227 207 244 227 235 255 224 241 204 257 271 200 223 237 230 237 218 202 228 273 208 234 233 217 211 222 250 236 226 220 213 245 226 267 243 255 225 206 195 265 219 248 230 240 230 232 238 231 222 234 250 239 228 214 231 230 222 222 242 242 232 198 198 223 232 217 241 236 207 225 259 233 217 205 235 222 269 261 204 211 205 243 212 208 242 227 247 227 244 223 237 225 232 226 249 233 231 225 246 225 210 224 208 215 240 263 206 228 221 237 228 234 220 249 216 233 244 217 223 231 220 206 239 236 228 213 227 196 232 198 240 214 230 237 215 212 213 238 211 270 214 221 198 233 199 222 236 219 228 237 242 230 268 216 232 228 224 230 237 219 214 235 179 220 237 196 218 242 267 249 210 218 246 228 233 242 235 230 250 242 208 235 241 226 240 227 225 234 230 227 218 219 256 221 249 235 247 231 248 231 257 240 229 244 235 230 246 226 226 223 221 201 232 264 231 232 213 256 224 229 223 243 265 219 237 232 235 244 268 258 241 231 248 199 242 264 226 264 261 228 256 250 247 242 238 235 226 217 195 232 235 219 222 243 276 231 231 235 265 233 246 229 269 234 212 235 242 198 212 214 232 248 243 239 240 237 256 243 278 195 246 231 214 232 236 228 245 244 228 236 224 231 209 260 244 239 237 247 214 249 273 244 225 189 266 226 247 257 219 265 234 255 248 238 232 204 233 226 233 236 237 247 228 227 238 227 272 202 256 214 250 212 257 270 246 230 196 247 225 237 232 222 226 237 204 231 237 250 219 240 235 247 225 246 246 258 239 190 239 235 237 210 241 227 272 211 236 277 237 255 218 240 232 226 238 236 219 214 221 245 263 268 220 229 231 249 238 234 238 231 231 244 235 259 231 224 247 236 256 241 265 210 240 194 262 233 239 236 226 197 236 290 223 259 225 239 249 220 264 233 243 244 216 231 218 223 273 214 218 209 230 235 213 258 239 232 243 234 238 257 207 219 245 258 266 233 235 260 245 230 235 245 248 230 262</counts>
			</dataPoints>
		</scan>
	</xrdMeasurement>
</xrdMeasurements>