File: data/XRD/XG-Luft/XG-600/W6821-1D_XG_Luft_600.xrdml
<xrdMeasurements xmlns="http://www.xrdml.com/XRDMeasurement/2.1" xmlns:xsi="http://www.w3.org/2001/XMLSchema-instance" xsi:schemaLocation="http://www.xrdml.com/XRDMeasurement/2.1 http://www.xrdml.com/XRDMeasurement/2.1/XRDMeasurement.xsd" status="Completed">
	<comment>
		<entry>Configuration=Factory configuration, Owner=User-1, Creation date=7/8/2013 4:01:53 PM</entry>
		<entry>Goniometer=PW3050/65 (Theta/2Theta); Minimum step size 2Theta:0.0001; Minimum step size Omega:0.0001</entry>
		<entry>Sample stage=MRD Cradle; Minimum step size Phi:0.01; Minimum step size Chi:0.01; Minimum step size X:0.01; Minimum step size Y:0.01; Minimum step size Z:0.001</entry>
		<entry>Diffractometer system=XPERT-PRO</entry>
		<entry>Measurement program=C:\PANalytical\Data Collector\Programs\Jorrit\2thom\_absolute_2th-om_10-130deg_PIXscan_56min.xrdmp, Identifier={15BCCF57-2807-42BD-B5B9-ECC0B3DC9284}</entry>
		<entry>Batch program=C:\PANalytical\Data Collector\Programs\SimonL\batch4x_2thom_10-130°_z9.1_x0,10,20,30_y0_57min.xrdmp, Identifier={EED9823A-2BEB-424C-9252-345C4EF2834A}</entry>
	</comment>
	<sample type="To be analyzed">
		<id></id>
		<name></name>
		<preparedBy></preparedBy>
	</sample>
	<xrdMeasurement measurementType="Scan" status="Completed" sampleMode="Reflection">
		<comment>
			<entry>_absolute_2th-om_10-130deg_PIXscan_56min</entry>
			<entry>PHD Lower Level = 4.83 (keV), PHD Upper Level = 11.27 (keV)</entry>
		</comment>
		<usedWavelength intended="K-Alpha 1">
			<kAlpha1 unit="Angstrom">1.5405980</kAlpha1>
			<kAlpha2 unit="Angstrom">1.5444260</kAlpha2>
			<kBeta unit="Angstrom">1.3922500</kBeta>
			<ratioKAlpha2KAlpha1>0.5000</ratioKAlpha2KAlpha1>
		</usedWavelength>
		<incidentBeamPath>
			<radius unit="mm">320.00</radius>
			<xRayTube id="1010048" name="Empyrean Cu LFF HR (9430 033 7310x) DK442154">
				<tension unit="kV">40.0</tension>
				<current unit="mA">40.0</current>
				<anodeMaterial>Cu</anodeMaterial>
				<focus type="Line">
					<length unit="mm">12.0</length>
					<width unit="mm">0.4</width>
					<takeOffAngle unit="deg">4.2</takeOffAngle>
				</focus>
			</xRayTube>
			<xRayMirror id="27010001" name="Inc. Beam Cu W/Si (parabolic MRD)" hybrid="false">
				<crystal type="Graded" shape="Parabolic">W/Si</crystal>
				<acceptanceAngle unit="deg">0.800</acceptanceAngle>
				<length unit="mm">60.0</length>
			</xRayMirror>
			<sollerSlit id="21010002" name="Soller slits 0.04 rad.">
				<opening unit="rad">0.0400</opening>
			</sollerSlit>
			<mask id="22030008" name="Fixed mask 4 mm">
				<distanceToSample unit="mm">220.00</distanceToSample>
				<width unit="mm">4.00</width>
			</mask>
			<divergenceSlit id="22010007" name="Fixed slit 1/8°" xsi:type="fixedDivergenceSlitType">
				<distanceToSample unit="mm">220.00</distanceToSample>
				<height unit="mm">0.19</height>
			</divergenceSlit>
		</incidentBeamPath>
		<diffractedBeamPath>
			<radius unit="mm">320.00</radius>
			<sollerSlit id="21010002" name="Soller slits 0.04 rad.">
				<opening unit="rad">0.0400</opening>
			</sollerSlit>
			<receivingSlit id="22010001" name="Fixed slit 4°">
				<height unit="mm">5.88</height>
			</receivingSlit>
			<detector id="7010017" name="PIXcel3D 1x1 detector" xsi:type="areaDetectorType">
				<phd unit="%">
					<lowerLevel>30.0</lowerLevel>
					<upperLevel>70.0</upperLevel>
				</phd>
				<mode>Scanning</mode>
				<activeChannelsEquatorial>255</activeChannelsEquatorial>
				<activeChannelsAxial>255</activeChannelsAxial>
				<pitchEquatorial unit="mm">0.05500</pitchEquatorial>
				<pitchAxial unit="mm">0.05500</pitchAxial>
				<readOutPeriod unit="seconds">0.135</readOutPeriod>
			</detector>
		</diffractedBeamPath>
		<scan appendNumber="0" mode="Continuous" scanAxis="2Theta-Omega" status="Completed">
			<header>
				<startTimeStamp>2024-10-22T17:47:55+02:00</startTimeStamp>
				<endTimeStamp>2024-10-22T18:44:00+02:00</endTimeStamp>
				<author>
					<name>PRO-MRD</name>
				</author>
				<source>
					<applicationSoftware version="6.1b">Data Collector</applicationSoftware>
					<instrumentControlSoftware version="7.0E 20130304">XPERT-PRO</instrumentControlSoftware>
					<instrumentID>0000000011142674</instrumentID>
				</source>
			</header>
			<dataPoints>
				<positions axis="2Theta" unit="deg">
					<startPosition>9.99826193</startPosition>
					<endPosition>129.99755682</endPosition>
				</positions>
				<positions axis="Omega" unit="deg">
					<startPosition>4.99913096</startPosition>
					<endPosition>64.99877841</endPosition>
				</positions>
				<positions axis="Phi" unit="deg">
					<commonPosition>0.00</commonPosition>
				</positions>
				<positions axis="Chi" unit="deg">
					<commonPosition>0.00</commonPosition>
				</positions>
				<positions axis="X" unit="mm">
					<commonPosition>0.00</commonPosition>
				</positions>
				<positions axis="Y" unit="mm">
					<commonPosition>0.00</commonPosition>
				</positions>
				<positions axis="Z" unit="mm">
					<commonPosition>9.100</commonPosition>
				</positions>
				<commonCountingTime unit="seconds">32.895</commonCountingTime>
				<counts 473 478 467 458 439 454 465 439 423 425 466 487 425 449 471 423 455 481 427 440 443 437 422 445 417 475 439 426 451 398 444 418 450 451 456 447 444 443 398 426 420 419 424 427 450 452 448 461 423 442 440 440 434 426 438 459 431 446 410 422 482 420 446 429 416 417 432 431 455 474 418 435 434 426 409 462 396 410 444 402 516 403 442 428 447 444 476 410 435 421 474 394 404 404 441 418 462 427 454 400 404 441 414 413 435 408 446 439 424 398 462 413 407 447 462 424 457 394 437 421 429 409 394 408 413 446 403 429 409 361 428 458 442 408 406 427 409 403 435 437 427 431 394 430 385 390 373 394 388 420 415 433 421 396 400 400 421 393 401 424 386 369 385 425 414 402 424 404 405 418 407 402 410 398 394 429 412 428 371 409 397 386 378 424 434 367 445 410 397 419 397 414 396 423 369 400 388 440 411 388 422 421 380 388 342 426 391 415 391 399 386 393 400 381 408 378 382 360 405 382 399 394 377 423 404 427 385 363 404 397 427 381 389 416 400 385 399 390 385 356 402 408 389 362 390 358 430 364 368 373 381 389 383 402 374 376 396 398 379 401 354 369 401 391 390 408 385 365 408 389 400 353 411 365 388 392 385 391 378 375 383 389 367 401 386 379 388 381 356 352 379 380 350 375 346 360 379 386 375 374 336 398 354 398 396 382 400 364 380 309 354 393 402 375 317 379 350 388 375 365 355 389 375 349 353 375 403 364 349 351 378 334 374 374 367 373 359 345 361 378 392 331 362 397 362 363 351 335 388 360 329 348 344 362 345 311 375 320 352 328 342 335 349 340 316 361 357 345 341 353 367 352 339 316 353 331 331 367 360 312 356 345 333 347 352 310 353 366 356 361 389 369 326 363 361 323 350 349 342 310 348 345 339 323 376 318 327 345 350 356 342 348 325 357 382 350 355 321 335 328 340 315 363 332 360 370 337 337 365 339 361 360 363 343 315 358 352 370 330 338 322 347 342 326 349 361 359 323 312 346 351 320 330 339 333 355 359 320 329 338 344 303 308 327 338 336 325 315 306 323 338 350 329 352 317 316 320 355 328 313 312 316 334 336 327 344 321 311 347 359 337 351 322 361 320 324 350 354 333 345 332 322 342 353 319 361 345 345 325 340 333 339 331 309 334 307 278 301 335 337 314 294 310 327 312 302 308 329 326 375 331 304 358 319 316 357 353 304 346 322 288 321 294 296 344 331 299 319 332 299 328 303 331 319 324 312 316 329 296 304 309 326 336 330 330 324 317 313 350 319 294 301 321 311 307 321 324 313 297 310 339 339 325 323 303 328 309 333 327 335 303 297 313 309 304 304 285 325 299 283 314 292 295 318 297 322 315 314 313 306 295 293 327 339 342 323 318 315 326 277 260 297 294 306 314 314 344 330 311 313 320 310 338 327 329 317 316 295 341 313 326 302 306 322 321 307 303 330 339 316 313 265 298 299 293 301 328 325 315 291 330 307 316 299 318 329 315 283 342 294 328 316 300 276 273 293 322 338 285 309 326 272 310 317 308 303 289 274 305 290 322 308 301 278 303 292 316 343 298 312 299 302 327 288 291 308 290 315 299 300 317 325 310 306 307 305 309 328 354 283 326 320 314 298 289 310 327 311 282 298 280 314 323 315 297 284 326 296 259 298 301 299 283 293 320 299 326 333 282 295 344 275 337 347 309 330 298 299 303 306 330 315 312 293 342 319 304 316 311 305 325 287 323 305 328 306 322 284 315 328 312 309 298 263 295 297 321 316 323 303 311 317 333 344 302 280 310 307 338 306 315 299 332 294 304 301 310 275 326 294 290 307 327 268 311 313 302 319 268 316 306 289 310 324 334 320 309 311 318 322 332 308 309 292 267 293 309 301 297 319 354 312 303 348 295 278 305 319 295 305 320 291 297 298 307 279 307 300 322 283 305 324 338 287 290 316 326 304 294 320 325 317 287 339 328 330 292 317 338 327 311 308 301 327 335 350 280 326 308 334 312 315 302 339 300 317 316 314 303 320 313 313 327 325 285 322 353 312 287 325 333 337 293 318 272 323 299 323 329 335 321 329 330 324 319 316 304 326 318 326 319 326 312 262 296 308 296 302 321 316 313 327 308 282 305 308 287 307 304 304 280 348 340 317 322 329 336 300 321 310 308 324 290 318 329 308 360 325 326 282 306 339 309 324 342 337 275 338 286 323 307 313 322 303 328 321 306 321 360 335 320 331 324 320 334 315 304 313 322 346 321 296 346 305 308 312 283 329 306 323 318 309 303 319 312 326 318 323 309 312 328 298 314 305 313 290 318 312 305 332 330 333 331 313 303 285 319 311 277 326 302 321 348 298 327 306 304 319 313 340 321 321 332 313 330 353 330 301 348 314 319 352 332 345 336 303 292 337 312 329 308 360 295 316 336 298 317 310 335 339 327 319 340 286 310 354 337 332 340 360 326 345 303 336 326 306 314 327 317 310 330 355 299 316 328 334 326 326 298 347 315 309 324 297 354 339 327 338 303 329 289 325 326 320 324 369 300 329 327 341 299 352 315 299 323 349 330 359 322 347 312 330 340 329 319 324 351 331 341 329 321 352 320 329 332 356 333 287 357 353 340 338 319 309 334 338 346 317 333 350 334 320 356 351 341 329 335 333 310 350 358 343 310 348 350 311 315 333 340 344 334 341 324 341 300 334 366 342 357 359 326 355 344 324 340 340 340 326 334 359 328 335 374 330 348 342 319 344 341 355 354 339 324 309 337 325 309 341 336 349 286 324 360 333 332 361 328 307 352 364 323 349 344 354 352 320 341 377 374 330 317 370 341 318 332 327 369 317 352 333 335 345 346 325 331 314 294 322 363 327 341 363 342 319 320 322 329 324 315 295 337 328 321 336 349 328 362 373 337 325 326 316 357 332 298 317 363 315 338 302 338 337 338 317 315 308 356 331 314 337 321 332 312 358 338 325 352 336 311 335 318 329 338 349 336 349 332 325 338 307 329 379 326 310 365 328 319 320 353 376 344 307 332 359 313 337 299 324 334 345 356 318 348 343 383 345 332 302 314 334 317 287 352 331 323 314 339 320 307 330 342 321 319 325 332 329 346 303 326 320 342 337 347 336 347 342 312 321 309 336 341 335 314 351 328 333 311 350 373 304 345 378 296 301 335 321 344 338 357 332 365 334 351 366 347 322 314 341 315 364 343 337 339 301 336 390 308 341 337 343 332 310 346 360 349 340 312 286 327 353 292 327 365 292 325 330 364 328 283 313 341 344 319 293 357 338 317 323 297 320 286 305 328 344 307 328 312 351 300 317 287 355 314 326 349 320 347 333 300 304 329 309 336 313 333 325 338 299 289 316 293 303 312 329 342 332 352 337 326 305 344 332 313 321 302 315 333 327 312 329 290 347 333 308 301 307 323 312 312 314 332 311 302 341 322 320 296 324 346 301 316 302 320 312 327 284 324 309 311 319 313 339 331 312 301 312 344 350 323 296 315 310 332 330 295 330 325 313 338 324 315 306 310 287 305 301 313 311 295 321 302 325 312 319 326 320 316 324 317 317 318 326 317 320 369 310 310 308 285 310 310 286 296 324 334 318 284 303 297 316 317 357 316 279 328 318 291 318 314 307 307 323 321 314 314 296 309 307 310 321 317 329 298 294 335 281 319 313 317 282 345 306 279 314 322 304 297 302 317 328 372 315 290 329 294 328 279 311 318 296 301 326 276 320 324 292 305 317 286 336 321 289 298 311 285 328 280 322 303 312 310 283 323 296 288 310 298 331 306 297 300 318 311 295 315 313 295 294 293 314 273 303 268 335 281 301 291 305 325 310 320 301 317 268 319 296 323 281 306 327 301 271 304 292 320 297 304 300 273 304 313 275 292 310 276 312 308 294 306 314 265 303 296 271 307 306 281 274 305 296 293 307 297 301 299 305 289 308 280 275 318 269 265 289 272 290 272 295 298 309 280 286 321 283 284 296 311 281 313 274 264 303 321 305 303 281 329 298 266 281 308 301 284 336 325 296 298 288 292 311 308 316 263 314 275 276 322 304 312 313 316 289 359 310 293 297 322 291 277 292 292 282 305 255 296 295 286 299 289 324 278 297 299 303 298 293 306 303 289 331 286 307 276 338 289 283 275 296 280 292 293 284 286 279 273 305 308 289 293 290 303 278 267 295 289 289 293 300 317 287 284 288 249 296 304 308 291 280 285 282 297 271 313 283 273 300 278 292 293 306 308 285 276 272 319 286 310 305 224 294 258 282 277 280 310 316 286 277 301 296 294 280 301 256 262 292 271 239 296 244 268 285 248 272 271 301 276 287 287 288 291 260 305 266 289 257 301 284 287 298 307 286 274 296 264 257 305 283 291 307 310 307 284 288 281 297 242 284 283 267 275 309 272 297 284 260 274 295 260 297 279 299 273 274 294 268 281 293 268 312 264 296 276 280 262 307 329 307 309 277 280 232 247 283 277 261 267 310 288 272 296 301 277 278 257 257 284 298 299 319 295 267 261 284 292 292 265 266 283 248 268 273 268 260 279 278 292 283 278 266 261 274 275 307 270 261 277 286 268 292 274 294 265 293 259 275 288 242 283 296 313 277 259 292 313 270 268 271 275 257 317 261 286 299 275 298 270 296 278 302 276 286 268 279 295 263 283 298 278 270 297 309 284 283 297 273 289 278 270 255 301 284 271 255 280 276 271 260 242 259 281 273 262 310 280 271 283 278 279 285 285 286 288 260 238 299 268 276 265 275 259 289 256 270 291 274 309 315 273 258 246 288 279 278 261 283 307 314 281 260 270 284 282 257 248 279 269 296 282 289 247 260 265 269 291 298 266 287 287 293 283 280 277 318 267 243 280 280 246 282 240 291 318 316 265 294 270 309 270 286 246 248 290 294 280 267 261 301 277 275 294 267 263 255 292 240 308 291 280 255 298 270 296 282 266 247 281 278 303 271 285 237 273 245 286 238 275 271 274 264 275 279 294 285 260 276 290 260 285 281 268 264 264 282 269 265 246 284 273 270 248 268 269 285 263 248 273 292 280 269 262 292 268 303 294 273 272 286 264 246 250 272 255 289 271 287 236 281 300 261 303 266 244 286 261 289 263 287 298 264 266 287 278 277 309 266 273 258 233 284 246 269 293 273 300 276 239 292 287 240 277 243 268 249 239 269 308 235 260 272 295 243 285 271 258 260 264 243 291 263 226 264 281 272 238 269 269 277 274 277 238 224 264 272 256 292 295 249 255 260 234 265 300 281 257 263 268 287 249 317 287 270 265 264 276 271 284 302 285 261 281 268 283 287 279 270 262 290 275 272 285 302 264 281 266 295 268 258 238 245 274 268 284 256 281 269 285 288 259 250 274 276 268 278 240 248 281 283 260 258 258 281 267 265 261 250 294 290 274 261 275 278 268 259 261 260 244 260 285 255 239 277 243 277 264 235 269 264 237 229 256 290 279 255 285 245 259 260 269 293 255 289 259 272 282 236 261 274 269 261 263 245 307 229 295 265 259 265 257 240 292 269 305 248 264 256 270 281 258 255 278 290 268 241 270 283 279 228 240 234 256 274 280 282 276 261 289 274 223 295 294 256 285 281 263 281 283 265 264 279 279 236 280 273 259 241 283 262 233 243 282 273 275 267 308 268 276 278 262 245 247 273 292 238 268 232 265 260 301 276 290 232 250 242 275 259 219 285 248 268 265 265 268 268 260 301 270 260 295 255 226 249 303 249 285 259 259 257 229 273 290 248 246 287 250 249 287 283 249 246 285 247 266 266 293 258 273 278 280 257 261 257 269 267 265 260 300 246 248 263 278 255 264 330 243 223 257 257 231 281 241 278 266 280 264 239 244 267 284 269 266 276 276 259 244 276 268 266 274 280 261 311 269 256 262 255 255 234 272 244 246 268 249 292 278 260 236 270 259 276 259 292 240 262 235 287 257 291 282 237 242 246 239 264 237 296 230 268 263 267 267 273 280 247 244 263 259 263 247 273 283 282 280 258 280 259 280 264 261 256 242 240 272 286 242 265 262 239 295 247 278 298 273 284 241 256 269 256 280 270 290 265 260 287 275 294 255 260 258 313 271 292 243 279 263 244 237 286 286 303 262 248 259 242 276 259 266 267 271 248 256 235 265 288 248 288 268 272 277 308 286 281 266 286 239 286 291 267 304 295 258 268 260 241 276 291 285 260 267 227 274 286 286 274 267 261 258 266 262 260 276 265 277 248 282 245 300 276 267 269 245 262 285 266 262 262 279 242 279 261 259 279 299 280 259 269 250 266 255 308 287 271 288 286 245 268 249 255 239 246 269 260 296 270 270 268 232 243 256 290 239 237 274 300 255 227 274 285 240 272 275 259 293 275 272 282 247 290 246 279 248 256 256 286 265 278 243 269 315 235 290 247 244 259 259 268 262 269 262 247 235 286 258 267 274 287 276 269 272 249 263 275 275 268 227 259 270 263 260 267 240 279 258 262 278 241 282 264 274 275 275 286 273 255 281 210 248 272 267 244 265 302 279 259 267 243 297 274 256 261 272 257 285 256 263 265 247 270 270 261 266 264 242 225 274 275 259 249 264 265 240 275 291 260 243 227 275 273 287 238 271 240 259 262 268 257 286 244 240 242 257 259 276 259 280 275 246 277 264 261 227 246 247 256 257 260 263 248 244 247 226 275 247 294 267 272 264 250 222 257 246 265 241 265 237 262 266 261 248 261 275 271 263 259 267 239 293 264 221 270 272 256 248 265 270 278 263 268 276 226 243 256 238 238 261 238 246 259 265 271 287 262 240 271 257 261 246 273 260 262 244 264 244 258 250 276 235 242 289 239 296 248 289 273 269 255 294 281 248 231 240 258 278 299 279 243 246 260 274 278 259 282 271 246 281 288 269 275 248 248 234 259 244 265 266 231 246 235 271 282 269 243 261 264 266 275 273 250 270 244 242 248 268 245 255 270 240 243 259 271 255 301 232 260 272 259 269 232 281 275 282 237 272 276 283 260 289 268 287 264 255 263 257 268 268 291 275 290 267 282 273 288 268 240 233 285 244 261 282 260 256 250 247 257 259 267 271 268 282 258 250 255 269 261 283 246 265 263 261 261 246 289 283 264 299 268 247 279 278 266 276 287 268 284 282 232 241 255 274 248 255 273 274 276 278 260 222 256 238 269 243 281 279 225 236 297 236 278 291 263 290 232 267 275 269 301 272 265 255 258 275 282 272 241 256 248 273 257 243 245 289 275 249 287 250 246 288 263 260 258 264 272 272 268 259 268 265 279 260 272 274 288 271 238 264 259 278 270 237 277 259 256 260 272 291 261 235 237 262 272 265 242 268 280 277 270 278 279 245 263 261 262 282 262 243 279 276 267 265 268 234 279 281 273 255 301 258 261 273 294 263 256 266 263 300 267 287 262 263 266 272 273 302 269 276 275 263 298 273 290 306 282 299 268 261 300 292 222 289 308 284 257 279 269 222 266 244 267 291 265 277 289 286 273 278 288 296 260 271 277 269 250 293 260 261 244 286 294 271 237 292 289 284 273 248 243 276 275 286 249 263 289 279 321 296 303 282 265 302 284 319 275 255 282 263 302 284 269 300 244 314 282 277 290 258 276 273 298 271 286 275 286 269 303 286 271 294 260 264 285 317 282 299 299 291 239 281 275 271 276 311 318 302 271 292 307 257 294 282 300 268 269 278 308 273 329 302 291 282 313 300 295 280 299 317 292 301 312 287 283 287 292 274 308 319 276 317 311 291 333 330 333 296 297 299 307 309 313 319 341 333 292 340 355 360 322 355 366 362 378 334 338 380 352 400 375 410 420 422 418 392 395 409 441 458 471 455 502 491 493 472 485 566 549 546 535 541 500 486 514 505 514 489 487 492 493 463 458 469 420 413 419 402 397 373 403 364 362 348 365 373 371 329 378 345 333 342 333 315 333 314 332 339 319 289 287 296 302 256 282 283 306 288 307 323 315 304 271 313 280 287 283 302 307 287 273 294 287 297 290 309 281 269 290 269 276 273 315 266 303 273 326 301 322 288 282 289 321 279 291 292 260 295 240 287 303 262 238 267 283 278 289 327 303 298 282 278 276 276 273 297 292 291 275 279 281 283 262 294 274 294 278 278 298 289 269 279 275 312 258 291 298 302 295 265 275 246 279 286 279 299 298 256 285 284 282 241 262 284 290 317 261 279 301 268 259 289 265 304 268 285 272 270 284 277 276 274 288 282 301 248 274 279 287 287 300 278 274 268 283 289 274 289 276 259 270 279 296 291 286 275 268 272 295 296 315 284 279 296 289 278 266 290 279 284 276 263 246 282 256 312 277 237 241 290 283 268 270 285 302 295 285 281 293 291 268 297 269 267 264 282 255 292 283 269 231 277 266 263 279 287 286 281 272 302 259 292 290 247 275 257 272 292 281 260 281 266 294 265 246 274 289 270 284 292 305 260 246 275 267 282 275 245 290 249 272 292 282 248 303 279 269 297 276 292 288 242 287 267 264 274 294 261 297 290 285 291 278 247 277 275 239 269 265 288 281 268 264 290 287 257 320 250 326 256 262 297 276 266 281 268 264 288 275 257 290 244 283 264 265 270 294 280 289 279 278 270 291 313 270 258 276 303 319 282 246 246 292 262 246 289 308 286 280 278 273 282 288 259 270 276 305 244 282 272 284 250 248 249 309 284 284 248 284 290 278 296 296 245 255 303 312 288 265 272 294 286 265 257 312 274 269 279 259 284 259 307 273 271 255 247 279 293 270 298 266 255 298 276 282 298 308 281 285 272 266 293 265 270 274 262 269 304 317 274 265 255 260 272 288 276 289 266 240 264 315 311 278 297 273 296 279 277 296 293 282 271 288 284 287 273 282 282 297 298 262 238 271 262 268 288 246 287 273 263 271 257 263 330 237 273 277 286 248 261 273 272 270 296 246 248 260 294 274 265 294 298 245 286 292 296 267 278 282 290 294 266 263 246 277 279 258 297 271 247 280 265 297 263 314 288 281 267 268 272 259 271 257 271 279 284 265 302 298 297 276 275 255 266 249 250 298 264 303 273 271 279 267 272 281 280 246 261 267 302 302 260 293 271 241 302 300 286 268 283 277 279 278 274 264 262 275 284 273 288 281 275 292 244 282 258 260 265 272 266 269 258 278 279 265 277 287 313 277 263 271 266 276 291 282 310 311 288 279 243 255 280 264 277 261 292 265 274 271 272 294 276 288 234 265 298 284 287 276 246 274 290 304 288 266 284 280 242 278 285 281 313 276 266 282 306 266 277 257 284 268 273 261 281 272 296 271 265 282 284 282 266 256 269 328 267 290 281 280 279 233 274 245 293 310 272 272 237 264 258 244 273 248 275 277 249 269 283 265 290 280 270 288 256 299 283 264 284 277 305 210 276 277 290 262 274 267 282 283 270 276 304 259 262 298 287 267 258 285 292 299 258 271 279 241 270 278 285 279 278 276 269 295 274 266 255 285 264 249 265 297 282 287 299 283 288 294 297 238 277 269 234 280 298 277 271 285 264 282 271 248 222 277 282 268 233 268 249 291 287 248 238 259 283 243 292 261 271 272 280 259 280 282 259 288 265 275 272 241 271 266 270 243 239 310 297 285 267 265 284 273 306 288 276 278 274 281 236 273 272 266 267 259 239 270 297 264 278 265 298 294 284 269 280 304 276 244 304 268 261 283 275 267 286 297 287 290 278 298 265 281 278 302 271 282 281 264 241 278 284 259 255 293 292 301 282 278 285 263 276 279 272 278 277 264 276 260 268 263 264 272 265 285 280 229 267 262 300 260 268 292 280 275 287 266 275 288 296 290 247 244 275 272 286 263 257 277 293 298 301 276 282 243 278 298 287 244 273 295 264 229 267 287 295 279 277 257 281 272 300 259 280 266 282 256 267 270 263 278 294 304 300 293 269 308 259 273 287 295 273 246 291 271 262 244 256 267 259 255 293 264 264 294 313 289 289 268 281 306 296 301 273 262 260 285 281 258 290 279 276 283 317 278 257 286 247 275 235 270 264 268 284 270 304 257 292 274 269 272 282 286 258 262 293 271 265 275 281 269 227 268 278 281 311 280 279 250 289 297 272 259 285 275 286 275 256 296 308 290 290 285 290 282 248 247 248 294 244 268 279 277 265 286 280 290 250 274 283 266 266 301 292 294 293 280 299 270 264 282 287 273 288 250 280 287 259 264 311 266 275 268 284 276 301 288 274 274 260 244 220 291 277 288 278 247 288 278 285 295 296 273 273 269 277 297 274 282 266 267 295 275 247 306 285 276 268 292 279 301 281 279 250 262 294 294 307 256 269 285 264 250 267 277 255 285 263 277 284 280 287 290 263 295 292 272 264 272 266 268 294 274 289 247 243 298 283 287 284 294 280 287 264 277 288 279 275 262 287 269 273 297 292 297 275 291 294 281 266 259 298 271 259 305 272 314 288 277 286 288 280 239 280 289 308 271 260 276 273 288 263 268 285 278 233 292 302 270 271 292 239 281 274 311 275 273 291 289 268 273 281 281 287 280 267 287 293 293 282 256 270 286 307 273 281 277 328 286 292 268 270 313 298 282 273 268 275 261 256 272 277 290 286 280 286 281 295 256 270 269 268 318 275 274 270 301 257 265 312 245 255 268 291 267 293 263 309 279 269 264 305 297 283 274 301 273 260 288 285 273 309 280 281 269 273 294 293 231 292 284 275 289 307 267 300 281 292 283 265 271 286 276 255 309 277 270 278 316 316 295 275 272 273 268 319 273 272 288 286 298 299 281 285 270 308 267 311 297 283 220 258 292 277 316 306 301 273 286 260 268 287 257 327 249 285 292 288 290 293 258 263 255 272 287 270 273 268 285 275 278 302 328 273 286 292 278 258 258 265 287 315 267 281 261 312 271 245 292 273 274 270 292 283 287 248 274 266 266 288 283 295 264 298 311 269 311 271 296 282 283 283 266 263 283 285 278 269 302 263 283 274 291 256 263 312 264 281 244 290 285 264 274 303 260 249 276 292 307 220 300 290 290 291 315 302 289 285 283 275 297 306 276 299 269 266 247 255 271 296 281 262 274 282 286 275 261 255 273 294 289 258 265 258 255 294 270 260 297 282 262 276 284 222 290 293 281 270 277 302 269 287 296 293 282 298 262 265 286 300 293 276 289 297 258 256 306 282 287 302 308 247 282 247 312 310 279 264 279 304 291 275 265 257 288 261 294 271 270 281 289 307 271 299 270 265 294 277 284 290 278 285 263 266 284 245 280 283 264 282 263 285 296 256 264 257 323 286 301 274 291 289 268 273 286 289 261 280 287 284 277 294 278 281 267 278 257 283 290 292 303 300 297 289 265 312 278 287 256 293 270 301 288 325 257 288 277 271 291 309 281 314 267 274 297 287 273 266 280 282 285 287 245 300 289 242 285 288 256 290 287 269 266 301 268 294 246 270 289 287 286 248 281 258 278 260 282 307 247 265 289 296 298 290 277 256 293 246 301 267 284 262 261 260 281 268 260 296 284 299 299 284 286 274 265 271 303 274 272 269 293 313 256 283 277 291 238 281 288 275 279 269 290 275 269 284 272 278 288 274 290 270 307 288 283 256 280 243 275 291 281 263 269 271 276 237 301 277 297 279 285 291 283 313 268 282 274 293 294 273 262 287 269 261 282 279 280 296 278 276 275 279 271 280 301 288 316 284 261 237 270 325 274 291 299 294 290 283 281 256 262 306 315 272 293 298 266 298 289 306 284 308 302 273 286 304 263 283 290 302 297 319 281 276 269 303 283 271 289 268 295 271 284 266 272 259 281 264 283 300 289 303 300 272 273 287 247 288 294 275 282 287 269 255 295 294 305 274 237 277 261 288 272 275 259 295 293 261 300 303 299 262 280 282 324 294 294 274 262 299 281 311 277 296 290 272 288 275 271 276 293 273 305 279 281 264 276 297 284 294 295 273 315 285 291 263 305 288 289 286 275 264 285 295 286 310 270 267 301 259 311 304 291 282 244 277 319 281 245 283 290 279 288 259 281 281 286 316 285 276 286 304 305 286 294 262 292 247 291 313 272 267 264 299 272 268 270 304 290 296 307 264 307 292 276 279 269 311 302 305 308 265 282 260 312 303 279 299 300 256 261 289 266 281 300 261 274 279 281 300 289 298 289 276 309 274 259 284 270 277 294 260 274 296 292 259 274 286 309 246 273 283 290 281 277 292 283 291 297 269 275 248 272 291 297 281 286 242 288 289 261 289 309 293 274 258 291 244 297 277 295 282 294 315 290 289 286 266 270 298 319 313 296 287 270 278 286 278 270 286 299 286 283 282 264 298 259 278 283 306 287 289 249 308 310 303 315 285 280 308 287 236 281 280 293 298 300 279 284 272 280 295 306 314 278 304 282 313 302 278 297 306 324 307 322 294 297 289 300 311 314 321 296 318 285 308 310 327 294 246 325 312 304 260 313 286 269 281 288 275 267 275 302 282 290 303 296 277 309 318 316 298 289 307 327 309 302 326 294 278 275 322 308 321 309 324 307 331 295 286 315 338 292 327 324 291 302 340 316 308 322 304 276 319 297 312 271 301 310 312 295 309 293 277 301 286 302 306 300 312 347 291 291 293 289 289 295 281 291 299 309 259 257 296 273 290 289 300 322 277 283 273 296 285 288 291 297 296 240 317 314 294 262 297 305 284 309 280 292 276 317 301 315 268 283 284 321 317 296 319 273 292 266 284 319 290 281 289 274 292 314 299 270 303 295 302 305 280 294 279 259 304 312 266 282 276 325 290 314 262 296 261 273 264 270 294 283 277 277 294 305 266 305 265 292 299 262 283 290 302 280 319 275 269 313 288 290 297 297 288 284 305 282 263 275 290 289 295 285 288 294 273 278 299 258 291 309 305 298 272 304 285 307 308 285 274 323 303 278 300 246 259 270 299 275 280 284 309 285 299 273 289 301 279 285 259 271 310 272 271 277 291 293 275 268 285 282 288 229 303 313 291 276 292 292 268 277 271 288 311 287 284 261 259 286 294 248 320 273 287 306 283 258 297 267 295 276 287 269 265 287 304 284 280 256 276 255 301 249 293 257 282 313 274 298 271 264 328 299 307 281 275 284 291 278 287 308 265 296 289 292 290 298 277 295 297 307 298 249 269 285 334 272 271 290 268 294 270 267 287 275 277 285 300 290 299 266 270 305 272 304 328 248 289 259 281 287 301 291 282 324 290 311 257 269 297 284 291 263 278 300 272 250 310 284 298 239 291 289 299 282 296 259 300 261 270 295 281 312 274 256 280 313 264 284 268 283 278 276 285 305 312 291 281 284 277 273 280 284 281 301 292 256 280 284 256 268 325 271 266 283 286 311 279 266 313 290 265 293 282 297 309 293 281 264 245 309 259 293 300 293 320 282 240 311 265 248 274 291 292 313 286 265 269 260 302 258 270 299 286 292 280 274 256 269 241 273 279 270 308 300 293 291 279 262 286 301 267 288 279 300 298 269 295 269 281 272 284 273 273 297 246 278 274 272 275 263 275 292 274 284 283 319 275 267 279 296 266 299 308 270 298 298 299 303 301 281 279 269 290 318 296 277 276 319 269 282 247 292 291 248 293 280 266 285 276 290 306 273 293 267 290 281 257 269 277 277 296 292 260 304 280 294 313 293 287 276 266 274 267 287 278 297 247 285 262 260 292 299 300 263 285 279 279 249 281 317 285 288 272 288 287 281 275 285 302 289 293 279 276 269 309 288 275 276 297 278 311 274 279 298 290 278 280 292 310 303 291 278 293 281 303 242 283 268 289 287 288 298 315 284 288 283 297 321 277 297 281 293 286 324 291 284 274 279 283 304 288 270 309 292 300 294 249 288 290 303 319 295 280 282 260 284 257 317 293 274 288 292 237 284 284 280 307 291 298 270 297 287 284 304 276 298 273 296 284 293 279 300 267 264 277 312 313 279 266 271 288 322 293 282 276 285 284 306 271 266 301 287 279 260 291 288 307 305 265 314 296 261 293 239 292 270 284 299 281 306 295 293 287 287 314 339 289 289 296 294 280 298 238 260 280 282 277 275 296 295 293 294 303 279 274 309 283 242 293 296 272 301 293 299 275 302 292 294 262 307 234 291 279 264 296 297 278 281 289 303 300 272 291 296 265 301 256 245 294 299 263 270 277 320 307 280 283 273 292 273 274 260 307 296 283 274 303 292 293 297 289 297 288 262 280 284 289 266 283 313 295 292 285 282 298 312 277 275 299 270 221 289 319 310 297 311 286 261 295 310 318 268 240 300 260 303 285 272 276 279 272 282 281 263 325 290 285 288 269 263 267 284 305 268 282 329 268 265 259 287 272 289 302 283 291 292 283 239 265 271 264 285 274 247 287 287 288 290 289 261 299 280 309 300 279 276 280 268 285 270 300 272 294 281 281 271 295 294 294 298 257 272 279 284 262 288 274 275 297 299 270 285 287 286 292 285 294 295 284 313 266 292 277 289 283 294 268 296 258 313 281 295 303 269 300 273 301 299 292 281 305 242 288 283 304 291 296 287 302 267 301 311 293 255 271 306 305 297 277 283 293 278 299 312 289 289 290 277 273 303 289 266 310 261 294 273 279 283 296 271 259 312 290 281 278 306 291 311 277 296 265 281 262 289 287 289 276 267 301 303 287 315 267 288 288 249 301 273 287 297 303 282 290 269 275 286 229 291 317 299 259 277 281 306 313 317 278 283 245 317 256 300 295 294 303 296 296 296 324 297 266 288 283 299 289 304 238 261 290 268 296 277 284 316 308 288 326 278 245 290 269 293 320 296 296 273 302 285 285 258 256 282 284 282 301 302 305 312 280 314 274 300 302 346 289 279 305 317 288 282 285 340 294 269 280 280 302 271 302 314 281 277 294 288 288 309 298 289 282 291 309 316 268 279 297 328 272 299 297 290 296 313 328 297 320 293 281 273 310 298 289 276 297 270 290 283 309 302 307 313 301 320 267 268 284 296 277 309 260 306 298 276 314 276 306 283 272 323 264 304 317 264 296 261 269 299 313 324 280 279 297 280 291 272 272 281 268 285 280 289 290 295 289 306 319 263 307 271 273 294 299 276 293 295 276 276 278 307 267 288 283 275 281 299 312 310 319 267 289 292 294 260 291 295 287 313 279 313 297 271 299 278 286 291 291 282 271 261 265 306 300 295 300 288 284 284 272 325 282 299 291 336 276 287 296 288 243 305 286 303 322 315 327 307 302 307 305 299 295 301 269 311 297 296 278 270 294 299 283 306 324 304 297 255 311 311 319 309 272 309 293 279 245 268 285 284 310 267 288 275 273 329 255 294 261 286 321 295 280 307 287 304 257 295 293 256 280 257 272 279 309 272 288 275 294 295 288 285 315 310 310 286 304 331 285 278 258 280 291 297 304 275 295 283 279 291 294 314 297 279 302 318 244 275 299 288 299 270 297 271 295 288 285 279 292 291 288 275 264 265 285 298 311 297 289 287 280 302 278 313 306 290 296 249 264 286 260 277 290 312 272 282 288 307 288 287 273 280 265 309 274 311 268 316 287 311 291 304 284 272 284 278 304 305 279 261 272 298 272 286 305 300 282 266 315 299 290 293 301 308 271 273 278 299 294 294 280 276 282 260 283 274 299 277 321 271 306 273 256 299 305 280 286 293 298 279 313 297 298 284 256 324 261 270 283 309 304 310 280 294 264 284 280 294 302 291 298 280 330 277 270 269 300 285 243 243 290 297 282 275 315 305 301 298 291 274 249 281 274 267 292 319 258 298 283 273 305 265 296 287 274 276 276 301 282 328 286 292 278 310 302 298 280 308 299 290 265 308 296 316 317 276 299 291 302 279 306 285 262 282 296 304 301 297 290 274 308 305 275 291 298 289 261 305 305 292 288 289 309 287 293 294 300 275 285 302 306 270 293 300 283 306 281 293 280 295 275 281 316 270 277 286 315 284 312 274 307 278 248 283 328 308 276 311 294 265 297 280 271 286 277 271 293 307 298 294 281 297 280 283 280 286 277 294 294 283 271 288 264 305 315 284 325 272 262 307 305 293 287 246 270 290 270 315 305 260 284 296 305 293 304 294 255 296 288 272 311 308 287 283 278 284 270 278 244 260 312 294 276 276 307 262 258 288 305 297 265 320 313 280 328 285 273 328 283 249 281 308 238 295 311 249 312 307 290 259 244 300 274 262 293 279 290 282 303 274 256 269 297 297 314 281 313 285 285 298 275 294 286 315 278 268 260 274 297 247 257 297 314 295 293 279 316 281 308 293 295 287 305 278 305 277 288 293 269 281 292 303 282 295 276 294 276 272 267 281 267 283 256 307 313 310 301 299 277 304 294 259 267 296 300 321 314 314 305 298 326 279 305 310 270 282 315 318 293 310 301 320 287 278 307 340 310 279 279 306 287 319 318 303 290 305 283 277 284 303 293 324 298 289 282 325 314 327 300 307 334 326 302 355 321 343 353 321 330 323 351 311 323 354 322 315 350 343 316 332 311 351 330 341 336 327 351 352 344 377 355 345 310 309 327 361 305 311 303 332 288 310 312 336 314 340 307 326 337 334 332 304 295 341 322 324 324 330 294 343 309 318 302 305 276 331 341 293 291 332 322 290 318 297 263 288 283 306 311 308 281 292 306 309 293 276 297 242 318 292 279 290 299 321 258 308 314 319 306 298 309 295 283 311 293 279 330 287 315 307 309 300 273 313 271 273 295 317 264 277 283 323 292 287 291 289 328 273 278 300 293 289 298 297 296 282 299 315 302 294 293 279 264 282 297 283 316 309 300 299 311 302 284 297 290 282 285 286 312 302 279 278 284 278 300 285 274 269 313 305 285 279 285 293 275 310 263 278 277 310 306 282 307 275 305 291 282 301 313 267 268 279 301 299 268 296 276 288 305 289 292 324 269 274 285 276 279 296 291 292 267 307 284 267 307 340 292 294 289 273 287 239 283 283 281 261 277 282 291 281 260 260 258 275 285 299 295 288 262 301 246 314 286 268 269 291 280 286 288 289 306 299 292 288 294 291 264 279 273 285 277 293 269 283 303 266 290 302 305 280 291 273 296 292 291 281 274 280 312 283 267 286 259 262 323 289 262 269 286 322 275 290 281 314 322 287 304 289 293 273 263 302 281 299 278 313 271 272 281 273 284 275 276 262 289 269 290 263 275 289 274 290 289 299 284 282 296 280 275 257 287 282 287 291 319 268 289 295 271 263 260 290 265 255 309 293 248 260 263 275 305 307 268 282 302 289 266 291 266 303 293 298 226 285 316 273 275 269 270 261 284 264 276 282 277 280 258 260 291 296 272 326 295 296 298 285 287 293 289 293 271 279 273 294 299 260 261 278 266 276 293 271 274 274 273 278 283 270 292 286 272 285 271 281 306 308 288 298 292 266 272 289 271 280 257 300 291 267 256 267 287 300 278 271 307 303 292 278 286 259 243 287 281 301 274 301 285 297 292 303 262 293 297 293 276 266 285 299 299 280 265 257 278 268 224 262 277 281 275 246 272 268 279 296 283 291 294 311 257 271 284 273 287 309 269 280 266 317 294 285 286 272 285 265 271 272 298 293 314 270 277 304 295 265 278 248 301 274 288 290 295 313 266 285 259 278 278 286 288 276 274 274 275 275 293 312 270 242 262 302 278 280 300 275 267 285 270 283 296 301 242 262 276 282 271 272 268 255 245 276 268 278 268 266 242 318 244 272 278 291 300 285 289 279 317 261 265 266 283 289 303 266 263 270 285 277 275 277 270 264 297 302 269 301 289 275 276 280 298 262 283 275 275 278 285 261 269 285 294 261 277 297 246 277 258 311 267 294 319 267 283 281 263 289 278 287 277 279 258 273 278 262 334 312 280 309 321 257 285 295 248 292 302 265 288 289 268 283 289 235 270 275 304 285 280 292 276 299 246 309 245 305 311 284 296 273 293 319 303 278 272 288 245 300 273 304 274 258 287 287 270 276 271 271 283 270 264 263 277 282 298 285 283 285 289 291 268 317 265 267 289 282 266 306 289 314 274 257 296 294 277 261 290 277 265 265 279 271 286 279 294 288 289 276 295 269 288 278 282 267 289 271 287 285 301 279 299 318 276 256 290 264 276 280 238 304 247 294 304 237 298 281 257 303 241 285 273 271 279 304 333 286 275 232 314 272 247 270 287 289 271 290 239 306 268 261 277 278 281 282 309 299 298 293 281 285 275 292 271 258 265 273 278 247 275 266 285 287 275 266 293 263 286 271 261 255 290 270 262 293 271 279 275 233 285 301 296 284 279 306 305 286 273 297 278 265 305 269 307 295 260 302 309 259 271 299 285 274 272 267 264 289 248 272 273 261 305 279 309 275 270 303 274 267 296 269 299 256 267 293 296 256 264 274 258 294 288 283 294 285 260 262 264 245 214 270 239 264 255 301 283 294 266 270 285 282 286 297 267 258 256 256 265 274 278 278 268 297 260 284 316 276 293 259 266 278 269 295 271 241 293 280 281 248 283 283 297 262 243 288 264 268 263 267 281 281 286 275 247 265 267 299 307 307 284 276 238 277 256 277 270 289 292 226 282 288 306 265 292 243 274 303 262 259 328 278 292 278 291 249 291 261 244 262 304 292 272 301 296 241 310 295 279 277 281 303 270 265 246 282 304 280 274 290 267 249 263 304 281 273 289 234 285 286 259 283 272 262 279 296 269 256 285 285 264 262 238 236 278 288 255 263 324 294 296 288 291 270 286 294 278 288 258 274 246 273 281 276 293 290 255 259 266 282 287 292 302 269 230 277 292 284 281 274 248 249 263 291 269 299 257 294 247 272 275 249 222 263 266 295 267 273 273 271 287 273 240 269 255 292 282 264 245 245 276 255 269 266 266 304 302 276 288 285 275 275 280 272 275 285 283 299 270 282 261 278 271 284 290 281 277 297 300 269 286 290 284 275 297 286 291 288 262 267 302 282 262 259 263 274 263 261 285 258 325 276 271 264 263 290 267 314 281 276 305 266 270 281 294 286 287 272 265 262 294 301 297 286 269 258 248 275 273 249 275 264 270 275 277 296 271 278 292 289 263 263 265 274 258 297 281 247 265 266 270 292 323 267 276 258 287 302 289 255 290 260 275 274 314 274 287 263 285 269 280 271 276 295 272 300 274 275 301 262 289 289 241 255 246 265 290 264 267 292 233 306 268 264 255 267 261 271 269 272 312 256 275 293 271 275 268 290 285 284 263 306 273 303 308 266 244 313 264 294 283 268 284 301 270 257 266 279 280 261 324 292 304 261 274 294 264 265 255 266 258 294 276 247 246 312 290 289 282 279 268 266 290 280 268 302 267 294 303 266 294 260 272 294 292 294 279 232 294 292 264 296 319 280 282 268 281 273 264 316 302 268 258 284 291 257 279 236 298 300 275 274 300 313 249 246 261 283 299 289 277 268 269 263 276 286 257 272 273 281 270 288 260 304 313 262 300 273 266 261 281 290 268 307 263 308 285 247 262 284 282 263 301 296 283 259 286 289 272 261 283 243 278 299 270 287 301 233 297 265 290 286 289 289 267 286 277 284 230 269 284 258 299 260 312 248 284 309 297 297 267 275 291 268 286 294 282 268 258 298 264 293 272 276 248 282 277 274 287 268 284 275 270 245 249 311 293 261 292 295 260 282 285 295 244 281 284 293 279 292 291 276 260 314 249 276 310 262 304 266 268 269 262 248 258 290 273 242 312 239 289 285 284 280 272 275 275 304 239 285 271 281 267 307 243 266 268 275 294 282 277 291 271 290 280 282 293 271 287 309 281 282 290 239 274 244 281 288 320 248 292 300 247 290 291 259 283 282 303 288 305 309 281 283 264 268 283 281 288 258 315 283 293 278 277 285 274 271 274 282 310 260 291 300 261 270 297 317 270 278 314 271 318 268 267 269 277 247 296 291 281 282 279 236 301 256 287 242 260 264 300 268 307 298 268 280 249 248 294 279 248 322 256 284 276 271 276 286 276 303 289 297 279 267 280 268 293 273 272 286 280 285 297 288 274 311 304 272 279 276 292 281 274 304 275 265 281 303 264 290 292 282 239 294 239 288 260 260 300 283 282 288 264 217 272 268 265 263 304 248 278 300 290 319 287 272 285 267 284 292 287 280 310 275 306 294 298 283 266 287 285 258 266 283 287 298 289 299 289 264 302 282 266 311 293 266 299 275 297 280 289 281 282 281 264 284 277 282 258 289 262 255 281 304 269 304 290 266 304 299 278 290 285 306 290 286 275 269 257 306 320 255 272 262 317 303 263 339 292 287 297 301 276 333 284 268 292 285 310 313 305 308 324 285 275 282 308 314 314 310 297 308 299 274 293 309 309 288 294 282 268 298 305 306 307 289 307 312 306 308 280 278 288 281 310 272 315 306 297 299 305 272 285 291 325 275 290 263 283 291 286 285 287 297 299 286 271 316 311 295 284 292 312 293 268 332 278 291 299 291 300 265 259 275 300 267 288 306 292 295 274 315 282 272 279 310 277 248 266 292 292 276 278 263 299 278 290 248 285 274 278 313 294 294 285 296 268 271 309 280 255 268 290 270 269 274 265 270 280 292 286 262 293 296 269 277 283 263 304 249 277 241 296 301 297 280 255 263 309 265 307 276 291 271 279 275 243 274 256 264 305 272 291 270 263 290 292 298 323 291 255 243 269 285 264 258 337 264 259 299 257 235 249 278 298 289 260 289 299 301 270 268 276 257 232 268 224 304 265 259 277 247 287 269 270 296 260 281 298 297 283 292 273 291 308 287 302 272 261 295 284 248 295 283 248 273 275 249 271 289 263 286 292 302 267 286 277 273 262 249 286 247 288 274 248 288 286 268 269 281 284 294 243 275 299 247 263 267 275 272 270 278 287 278 272 286 256 272 311 276 279 292 279 259 308 297 247 266 262 292 275 260 285 297 296 265 281 290 283 261 286 266 268 261 272 288 237 272 271 289 312 273 275 288 274 275 279 262 281 276 290 260 274 249 250 273 291 319 279 287 273 293 299 295 288 272 290 276 291 246 276 289 276 265 317 289 276 271 257 273 267 325 268 284 288 302 269 237 278 286 270 304 298 273 294 289 272 309 267 247 278 274 274 275 298 298 300 273 276 280 250 269 258 273 290 272 277 287 288 273 287 276 301 296 303 283 224 277 250 280 277 258 266 262 291 262 250 268 284 268 275 278 271 244 272 288 302 278 270 261 264 301 279 275 266 292 269 269 274 244 229 274 319 267 255 296 287 265 288 261 268 273 271 306 303 285 267 277 262 283 283 259 283 311 243 280 238 292 260 242 245 277 279 279 263 270 288 293 272 283 273 296 286 271 260 274 285 281 284 290 269 310 291 300 287 291 259 293 286 285 292 272 296 290 272 287 257 276 298 240 245 282 294 266 260 275 303 276 290 266 291 289 297 266 293 314 294 284 282 291 276 308 279 260 315 311 289 307 264 260 281 268 241 274 283 258 307 278 284 278 245 267 246 267 279 305 247 285 296 264 243 287 244 297 261 308 295 268 277 265 265 245 301 271 285 287 246 282 288 262 268 282 301 255 256 298 267 274 284 280 279 259 297 267 283 286 276 262 289 261 290 268 260 291 249 277 303 284 257 261 303 282 273 297 269 289 255 277 266 266 279 296 265 268 277 244 292 305 263 272 301 315 275 286 301 274 303 244 245 280 281 288 283 293 293 275 307 283 286 277 280 297 255 270 289 273 286 249 336 300 245 288 270 282 317 277 277 278 265 303 270 276 272 294 276 296 269 294 270 288 279 279 307 293 267 277 312 280 273 286 286 307 262 299 261 264 308 272 307 312 299 269 274 240 296 314 272 271 262 245 280 243 319 284 297 289 288 277 270 289 320 267 263 283 280 314 293 274 240 293 276 280 287 271 271 293 298 276 286 298 274 302 275 283 314 299 292 279 274 273 286 248 277 285 299 282 264 259 270 288 292 285 264 246 297 275 265 275 285 283 267 288 295 295 292 274 274 265 305 258 310 296 270 277 279 289 243 302 307 268 290 264 291 293 290 304 281 271 279 276 299 283 269 309 244 280 278 260 288 271 262 277 294 291 288 259 278 278 273 282 298 322 285 300 311 294 282 288 305 263 288 284 274 270 271 289 311 303 279 269 287 292 274 269 292 260 301 275 291 300 279 309 260 256 273 320 265 285 298 285 282 288 270 282 246 315 314 277 267 285 294 266 301 267 284 257 284 289 273 301 249 287 262 292 286 297 267 289 302 312 269 281 277 323 275 275 285 262 295 290 284 302 279 297 300 270 299 267 284 297 272 272 309 281 305 281 287 279 273 307 298 283 306 283 290 281 260 280 298 267 280 307 317 298 299 303 261 292 281 280 269 294 249 301 264 294 284 302 316 313 299 248 275 289 283 259 256 283 274 277 222 296 317 262 271 247 292 285 289 300 283 289 297 298 274 248 284 315 281 299 282 310 317 288 261 295 262 268 292 265 291 269 282 300 283 263 288 298 284 304 264 265 303 295 283 293 270 281 283 304 274 272 260 258 282 281 260 272 293 313 274 294 293 295 289 291 276 278 317 295 288 276 275 297 275 294 280 295 260 294 300 296 285 303 296 282 268 285 308 287 264 288 267 259 260 276 281 275 268 294 236 292 242 286 282 247 277 293 286 294 305 303 307 255 310 282 283 279 276 287 280 286 281 291 276 300 281 275 306 256 320 273 267 287 293 296 296 284 288 269 307 318 292 305 256 263 261 295 309 291 304 286 303 275 296 262 278 304 250 288 286 250 268 264 284 277 277 275 299 274 311 263 262 283 320 286 268 285 310 264 294 285 291 300 291 269 286 299 303 280 296 276 274 256 279 284 276 284 267 295 291 307 281 258 286 299 297 292 266 290 263 292 294 259 260 296 264 260 301 265 300 292 287 243 269 277 284 280 273 276 275 266 287 284 283 264 291 289 266 247 308 279 282 267 275 350 281 271 263 323 304 291 299 292 303 287 273 274 277 287 294 276 280 269 262 284 263 263 286 285 289 269 284 326 272 313 282 268 295 275 301 279 281 286 302 284 269 274 313 308 286 316 302 292 299 310 261 267 269 296 265 276 268 288 298 285 314 267 280 277 285 283 269 301 294 279 269 268 297 280 248 291 286 271 291 296 275 277 287 268 257 289 310 290 295 300 295 273 288 291 240 272 282 292 278 324 273 298 284 280 291 278 274 274 269 309 275 306 263 281 283 285 284 283 240 265 301 285 276 271 285 289 261 246 258 289 288 273 265 265 290 293 302 280 289 275 285 287 273 288 287 280 294 258 259 285 302 310 280 314 277 283 301 255 295 275 279 237 287 271 262 260 295 313 258 265 280 298 274 294 294 293 288 260 273 277 273 284 272 262 296 302 261 287 309 259 273 258 295 249 281 301 297 275 264 274 279 265 277 271 263 301 294 297 266 276 287 283 287 288 249 308 272 268 241 267 256 260 276 290 297 286 273 289 270 262 291 266 298 262 267 266 302 284 286 266 309 293 291 274 284 284 297 276 285 279 269 297 281 305 305 291 272 292 269 299 288 294 271 279 296 304 272 284 300 274 260 250 277 291 277 270 281 273 277 291 289 288 265 270 283 282 281 262 284 301 270 272 280 298 270 282 300 297 298 312 277 305 283 304 278 271 312 267 290 308 286 266 294 287 291 287 277 310 289 296 283 280 304 289 294 291 307 296 283 278 289 299 267 296 288 296 306 297 261 293 276 282 282 282 276 304 302 306 294 291 297 279 308 298 277 262 286 303 298 275 297 298 304 276 271 295 288 285 285 267 275 316 282 291 285 268 292 301 289 280 290 304 283 276 268 289 278 235 289 288 319 311 281 264 314 293 280 274 248 293 308 296 292 281 283 278 287 314 283 299 283 308 270 287 290 264 284 270 279 312 310 261 289 267 287 273 294 329 270 288 271 279 296 275 300 304 291 301 290 286 305 271 287 313 290 288 315 276 242 267 280 275 295 303 296 286 279 302 289 288 288 280 300 291 273 301 306 296 285 281 275 299 284 276 280 304 271 298 301 302 272 286 276 281 297 309 283 286 287 283 288 329 294 306 284 311 311 287 281 314 313 305 294 302 288 290 304 292 279 309 257 280 271 300 318 300 283 295 284 299 283 302 299 288 302 277 321 282 306 272 280 289 313 306 290 301 303 310 323 317 276 279 312 293 290 293 321 281 305 307 316 307 301 306 290 324 316 309 295 290 291 345 350 308 272 307 324 304 298 302 316 311 306 306 306 261 281 298 323 311 305 313 291 347 301 294 267 327 293 289 297 276 307 321 331 319 329 320 296 318 337 278 309 291 311 291 271 286 308 298 312 294 304 289 275 278 309 311 268 313 301 340 287 311 289 288 298 332 289 313 307 326 307 298 333 292 298 299 304 293 287 313 266 267 326 289 314 326 296 286 280 308 295 318 277 266 273 292 274 328 296 288 296 297 299 298 313 300 280 266 295 303 287 311 280 281 300 310 292 310 284 246 316 292 307 264 302 312 275 311 299 282 281 300 287 288 280 284 310 303 286 302 276 288 289 297 288 272 315 285 268 289 306 280 278 259 309 275 316 299 310 287 284 295 313 284 275 265 306 287 309 297 290 313 288 283 292 279 323 307 287 273 287 282 248 295 298 272 303 278 295 283 283 307 289 301 282 284 320 264 268 281 281 264 308 278 280 284 280 298 304 285 278 285 288 289 280 249 274 286 294 262 295 301 279 279 268 310 289 328 288 257 271 283 300 280 282 285 296 300 300 285 287 290 279 293 320 286 292 295 264 305 248 285 315 274 312 286 290 310 281 308 272 287 296 289 255 301 286 291 309 270 275 300 259 281 263 302 306 297 277 311 337 265 258 292 282 300 333 280 283 283 282 313 284 307 288 284 294 289 311 275 330 281 264 277 268 287 304 298 305 282 269 308 272 311 282 293 286 270 270 269 287 263 290 284 289 287 262 299 287 284 281 286 284 279 279 286 272 265 291 292 293 296 294 245 292 299 283 305 291 280 294 301 293 274 327 285 303 283 279 266 289 285 263 276 276 261 261 325 302 284 282 286 285 293 290 299 274 278 287 299 300 299 294 281 280 293 305 230 285 273 280 281 273 282 311 244 268 284 260 263 257 294 323 267 267 233 299 297 298 304 266 306 291 308 286 269 274 292 280 280 295 281 300 248 283 294 285 289 276 270 277 283 308 296 288 292 304 308 278 284 264 275 296 300 238 262 290 290 275 301 304 311 296 286 284 299 303 288 249 309 297 282 293 296 299 285 262 259 280 282 280 273 289 283 316 304 275 275 324 319 293 310 298 245 301 269 265 276 236 279 304 291 299 301 274 294 246 278 261 290 304 294 271 309 310 303 304 301 281 285 308 301 273 287 289 315 283 281 265 318 296 288 265 272 288 293 292 287 275 288 293 326 258 306 328 292 278 272 281 302 294 299 313 275 295 267 268 297 262 310 289 307 290 297 302 302 305 277 297 246 285 291 294 275 264 311 290 303 287 285 243 307 301 274 267 292 267 273 295 278 277 263 299 274 287 302 311 318 277 282 317 280 289 287 264 303 290 301 284 293 288 291 283 282 316 319 291 304 278 292 282 257 281 276 328 282 283 307 296 295 291 282 266 296 263 290 296 281 289 266 292 264 299 261 292 292 279 287 296 293 293 302 315 264 274 255 269 290 300 299 300 305 271 298 300 293 273 293 286 292 288 299 279 268 272 259 283 304 289 297 291 279 305 278 272 276 288 290 333 295 269 259 285 306 247 295 233 297 276 282 276 284 279 297 297 296 285 275 301 259 283 285 294 266 317 313 264 303 278 274 313 287 286 283 318 296 307 289 259 289 299 293 298 271 277 283 266 305 291 295 288 288 298 269 278 276 266 278 300 257 274 264 282 281 267 322 287 298 328 294 311 324 295 273 308 276 284 281 285 297 270 296 289 278 290 294 279 308 287 270 261 298 273 291 270 274 273 298 296 276 315 272 306 278 277 297 299 312 292 305 277 306 324 314 279 282 261 299 322 295 273 313 281 298 301 270 323 250 282 289 283 302 288 298 274 257 263 273 285 298 276 303 282 276 281 296 264 271 246 304 299 259 273 276 283 243 314 304 269 289 291 302 293 301 269 286 331 299 283 289 274 268 284 283 293 261 329 241 310 330 264 272 267 301 237 310 299 302 308 296 290 309 263 298 292 285 281 278 275 260 277 288 298 299 319 269 261 290 301 269 281 318 295 300 281 304 308 307 262 290 305 300 279 312 300 284 264 292 269 266 292 269 309 314 278 287 321 282 287 281 245 281 286 275 304 248 295 312 272 308 266 317 295 298 256 250 281 241 284 292 260 288 296 300 290 263 310 301 283 276 259 274 287 260 277 299 269 291 283 306 273 272 289 284 332 320 278 285 274 273 264 293 277 278 279 284 280 267 299 285 262 287 260 234 281 291 264 262 290 265 275 277 292 291 285 277 289 286 294 272 307 285 298 303 261 294 306 275 276 268 283 321 258 299 260 266 285 329 299 309 277 276 280 290 267 291 293 261 287 258 255 295 275 279 296 294 276 311 296 312 304 292 289 298 299 286 293 287 305 291 247 286 330 301 346 272 307 283 283 292 304 292 273 292 300 295 275 285 306 291 296 293 292 297 289 321 289 312 299 293 297 279 294 288 286 278 267 307 282 288 279 290 272 298 321 296 266 293 304 270 288 307 272 288 280 286 283 323 325 293 285 327 242 283 294 273 287 314 292 243 298 269 287 292 286 283 299 247 269 311 292 290 312 315 284 295 282 291 249 285 279 282 314 248 300 305 295 285 300 293 335 282 310 274 264 268 264 259 286 291 301 263 242 289 289 267 301 305 308 289 285 269 290 280 293 274 260 286 300 312 295 325 268 292 280 299 313 245 257 289 280 294 291 286 271 322 298 294 260 280 304 303 272 287 272 264 287 295 266 267 278 322 320 279 277 311 310 293 295 290 261 294 303 304 294 290 295 278 285 305 293 281 289 246 280 304 289 269 284 298 294 311 297 282 292 293 287 272 273 288 281 309 291 294 317 295 282 283 309 298 276 277 282 301 297 295 246 268 272 301 305 304 304 297 300 279 312 280 299 301 263 282 262 309 317 293 291 265 283 298 317 301 248 292 341 303 266 291 285 284 282 284 325 263 269 311 299 289 321 257 304 275 270 296 305 280 310 282 301 263 276 289 260 299 268 260 284 249 300 272 329 288 296 261 282 280 260 287 305 293 305 276 299 280 300 282 286 311 303 300 283 303 308 278 281 284 294 304 286 296 313 314 259 294 280 323 296 282 283 309 272 306 287 289 303 293 275 269 313 285 285 270 286 299 305 275 294 318 308 279 274 284 291 277 284 289 280 291 291 292 276 307 293 274 258 270 284 298 280 296 305 275 274 294 290 275 285 296 307 290 258 284 302 305 298 317 297 319 299 298 286 258 295 287 309 274 274 286 337 289 279 301 291 297 256 270 243 279 267 292 280 297 292 309 315 298 307 320</counts>
			</dataPoints>
		</scan>
	</xrdMeasurement>
</xrdMeasurements>