File: data/XRD/_misc/old/XG-650C/W6822-1A_absolute_2th-om_10-130deg_PIXscan_56min_2.xrdml
<xrdMeasurements xmlns="http://www.xrdml.com/XRDMeasurement/2.1" xmlns:xsi="http://www.w3.org/2001/XMLSchema-instance" xsi:schemaLocation="http://www.xrdml.com/XRDMeasurement/2.1 http://www.xrdml.com/XRDMeasurement/2.1/XRDMeasurement.xsd" status="Completed">
	<comment>
		<entry>Configuration=Factory configuration, Owner=User-1, Creation date=7/8/2013 4:01:53 PM</entry>
		<entry>Goniometer=PW3050/65 (Theta/2Theta); Minimum step size 2Theta:0.0001; Minimum step size Omega:0.0001</entry>
		<entry>Sample stage=MRD Cradle; Minimum step size Phi:0.01; Minimum step size Chi:0.01; Minimum step size X:0.01; Minimum step size Y:0.01; Minimum step size Z:0.001</entry>
		<entry>Diffractometer system=XPERT-PRO</entry>
		<entry>Measurement program=C:\PANalytical\Data Collector\Programs\Jorrit\2thom\_absolute_2th-om_10-130deg_PIXscan_56min.xrdmp, Identifier={15BCCF57-2807-42BD-B5B9-ECC0B3DC9284}</entry>
		<entry>Batch program=C:\PANalytical\Data Collector\Programs\SimonL\batch4x_2thom_10-130°_z9.1_x0,10,20,30_y0_57min.xrdmp, Identifier={EED9823A-2BEB-424C-9252-345C4EF2834A}</entry>
	</comment>
	<sample type="To be analyzed">
		<id></id>
		<name></name>
		<preparedBy></preparedBy>
	</sample>
	<xrdMeasurement measurementType="Scan" status="Completed" sampleMode="Reflection">
		<comment>
			<entry>_absolute_2th-om_10-130deg_PIXscan_56min</entry>
			<entry>PHD Lower Level = 4.83 (keV), PHD Upper Level = 11.27 (keV)</entry>
		</comment>
		<usedWavelength intended="K-Alpha 1">
			<kAlpha1 unit="Angstrom">1.5405980</kAlpha1>
			<kAlpha2 unit="Angstrom">1.5444260</kAlpha2>
			<kBeta unit="Angstrom">1.3922500</kBeta>
			<ratioKAlpha2KAlpha1>0.5000</ratioKAlpha2KAlpha1>
		</usedWavelength>
		<incidentBeamPath>
			<radius unit="mm">320.00</radius>
			<xRayTube id="1010048" name="Empyrean Cu LFF HR (9430 033 7310x) DK442154">
				<tension unit="kV">40.0</tension>
				<current unit="mA">40.0</current>
				<anodeMaterial>Cu</anodeMaterial>
				<focus type="Line">
					<length unit="mm">12.0</length>
					<width unit="mm">0.4</width>
					<takeOffAngle unit="deg">4.2</takeOffAngle>
				</focus>
			</xRayTube>
			<xRayMirror id="27010001" name="Inc. Beam Cu W/Si (parabolic MRD)" hybrid="false">
				<crystal type="Graded" shape="Parabolic">W/Si</crystal>
				<acceptanceAngle unit="deg">0.800</acceptanceAngle>
				<length unit="mm">60.0</length>
			</xRayMirror>
			<sollerSlit id="21010002" name="Soller slits 0.04 rad.">
				<opening unit="rad">0.0400</opening>
			</sollerSlit>
			<mask id="22030007" name="Fixed mask 2 mm">
				<distanceToSample unit="mm">220.00</distanceToSample>
				<width unit="mm">2.00</width>
			</mask>
			<divergenceSlit id="22010007" name="Fixed slit 1/8°" xsi:type="fixedDivergenceSlitType">
				<distanceToSample unit="mm">220.00</distanceToSample>
				<height unit="mm">0.19</height>
			</divergenceSlit>
		</incidentBeamPath>
		<diffractedBeamPath>
			<radius unit="mm">320.00</radius>
			<sollerSlit id="21010002" name="Soller slits 0.04 rad.">
				<opening unit="rad">0.0400</opening>
			</sollerSlit>
			<receivingSlit id="22010001" name="Fixed slit 4°">
				<height unit="mm">5.88</height>
			</receivingSlit>
			<detector id="7010017" name="PIXcel3D 1x1 detector" xsi:type="areaDetectorType">
				<phd unit="%">
					<lowerLevel>30.0</lowerLevel>
					<upperLevel>70.0</upperLevel>
				</phd>
				<mode>Scanning</mode>
				<activeChannelsEquatorial>255</activeChannelsEquatorial>
				<activeChannelsAxial>255</activeChannelsAxial>
				<pitchEquatorial unit="mm">0.05500</pitchEquatorial>
				<pitchAxial unit="mm">0.05500</pitchAxial>
				<readOutPeriod unit="seconds">0.135</readOutPeriod>
			</detector>
		</diffractedBeamPath>
		<scan appendNumber="0" mode="Continuous" scanAxis="2Theta-Omega" status="Completed">
			<header>
				<startTimeStamp>2024-08-29T19:13:52+02:00</startTimeStamp>
				<endTimeStamp>2024-08-29T20:09:57+02:00</endTimeStamp>
				<author>
					<name>PRO-MRD</name>
				</author>
				<source>
					<applicationSoftware version="6.1b">Data Collector</applicationSoftware>
					<instrumentControlSoftware version="7.0E 20130304">XPERT-PRO</instrumentControlSoftware>
					<instrumentID>0000000011142674</instrumentID>
				</source>
			</header>
			<dataPoints>
				<positions axis="2Theta" unit="deg">
					<startPosition>9.99826193</startPosition>
					<endPosition>129.99755682</endPosition>
				</positions>
				<positions axis="Omega" unit="deg">
					<startPosition>4.99913096</startPosition>
					<endPosition>64.99877841</endPosition>
				</positions>
				<positions axis="Phi" unit="deg">
					<commonPosition>0.00</commonPosition>
				</positions>
				<positions axis="Chi" unit="deg">
					<commonPosition>0.00</commonPosition>
				</positions>
				<positions axis="X" unit="mm">
					<commonPosition>10.00</commonPosition>
				</positions>
				<positions axis="Y" unit="mm">
					<commonPosition>0.00</commonPosition>
				</positions>
				<positions axis="Z" unit="mm">
					<commonPosition>9.100</commonPosition>
				</positions>
				<commonCountingTime unit="seconds">32.895</commonCountingTime>
				<counts 232 221 196 243 241 232 231 223 222 210 220 225 201 241 219 216 204 220 220 222 231 221 229 206 223 215 217 232 255 232 223 199 218 233 215 201 218 227 226 226 220 250 208 227 224 208 213 196 224 220 240 237 225 212 203 206 202 220 210 201 221 238 208 229 239 219 206 224 227 215 219 211 232 228 228 219 229 210 184 213 220 223 187 222 225 203 235 189 223 200 200 208 219 213 199 193 205 221 211 205 235 206 243 213 193 239 205 222 190 206 202 218 212 224 223 213 245 213 209 212 240 209 192 210 191 202 198 225 184 207 255 236 206 192 204 192 224 224 240 178 206 217 203 221 226 229 189 213 238 203 192 205 199 210 198 203 198 208 206 215 216 217 196 211 209 212 208 201 218 203 185 203 210 192 197 203 204 205 203 225 227 196 189 226 186 185 174 202 185 202 157 212 204 188 194 202 208 205 224 227 205 230 204 220 214 202 195 200 206 178 194 206 203 196 231 200 196 189 176 212 187 192 190 214 189 180 191 186 222 211 177 182 193 197 216 202 188 206 193 173 184 198 179 191 183 202 189 171 189 190 206 194 207 187 239 212 190 181 177 199 194 203 188 200 181 192 183 176 190 170 194 207 164 196 200 208 209 185 179 180 189 190 194 176 186 184 194 192 187 202 207 195 205 196 208 183 181 182 173 177 208 198 172 149 189 186 180 187 179 186 189 195 216 183 188 183 193 172 169 209 220 195 192 191 186 191 181 151 171 186 190 178 175 196 188 208 155 173 185 181 182 182 189 218 179 179 188 182 185 161 163 186 175 190 187 190 198 176 163 181 161 200 183 179 188 182 186 177 150 170 177 177 197 182 176 196 177 175 189 171 199 169 163 183 190 194 168 200 164 181 183 163 171 161 162 196 158 193 176 178 160 175 134 169 175 180 156 164 163 201 157 172 149 154 193 179 186 161 178 192 174 175 180 202 182 172 169 159 188 184 170 186 178 169 174 178 183 163 189 183 190 178 166 175 168 169 185 183 183 172 182 183 179 169 171 195 162 163 186 150 166 181 143 134 162 186 146 175 158 151 173 174 177 171 162 162 183 160 177 192 161 139 163 192 140 152 151 183 162 170 154 160 149 180 188 163 167 158 155 176 149 177 186 168 171 166 182 160 187 172 169 173 164 165 154 167 149 182 183 152 173 172 179 165 173 162 158 175 157 156 167 155 137 181 152 170 172 184 166 179 175 162 167 151 159 163 161 155 157 173 178 157 169 178 189 145 173 149 169 171 147 145 154 179 166 167 146 181 175 168 154 169 162 146 170 150 192 177 161 175 165 164 179 154 177 177 176 168 176 134 198 170 152 188 160 186 157 165 152 156 166 177 161 154 139 167 157 162 165 158 156 169 163 172 151 161 154 186 158 186 172 182 159 145 162 173 172 152 148 159 157 161 159 168 161 150 195 159 151 152 160 160 150 159 174 157 145 158 161 157 141 143 162 179 152 158 166 162 155 155 173 191 160 172 145 149 148 193 144 158 141 150 156 150 165 174 140 165 160 149 164 175 159 153 160 154 151 156 168 197 173 156 142 167 162 152 170 165 172 165 160 172 154 160 150 165 154 179 194 151 136 168 166 146 154 152 125 166 133 137 156 159 158 151 145 161 144 159 136 154 151 156 157 157 150 156 160 163 126 169 170 138 143 155 181 168 168 153 167 158 167 154 170 160 182 172 155 151 135 181 163 160 172 148 177 151 170 139 153 160 160 159 150 151 172 166 192 155 149 146 170 160 175 165 174 150 155 160 171 168 154 139 162 152 158 128 135 167 148 165 178 159 167 141 144 149 161 150 162 147 174 158 166 147 153 155 136 147 147 141 167 155 182 171 171 171 150 162 156 144 155 164 161 156 156 148 165 177 168 138 156 137 150 157 161 162 158 149 172 177 155 168 162 171 171 146 166 151 167 158 163 188 147 171 148 144 169 162 155 165 161 167 142 145 165 164 165 169 151 174 175 180 152 177 160 166 141 157 149 175 161 164 154 153 159 139 161 154 162 145 174 172 160 175 138 158 167 196 159 166 143 147 152 166 170 157 163 162 152 152 160 178 154 175 154 177 159 171 158 160 153 189 165 185 146 174 158 167 165 152 163 157 150 163 165 185 172 186 170 168 177 173 156 153 162 182 166 172 159 138 170 184 178 148 165 167 160 164 179 163 163 169 175 153 162 158 172 173 162 164 153 177 186 169 157 171 160 179 152 169 151 158 164 171 172 142 161 158 133 164 179 184 174 172 171 148 166 153 158 150 161 161 148 182 185 150 155 159 171 144 193 178 178 182 169 152 161 151 174 148 143 145 188 176 172 173 177 169 186 166 180 184 173 168 194 177 183 174 167 165 160 161 183 175 161 176 162 181 152 189 173 161 177 171 186 174 190 178 146 185 171 174 145 176 176 168 177 154 170 155 157 170 166 170 190 161 179 180 166 158 168 170 163 166 163 172 177 176 175 163 172 156 153 170 157 149 207 167 179 162 155 208 179 180 181 171 174 180 146 158 167 169 188 186 162 188 178 193 180 199 179 183 159 171 170 164 178 159 169 156 192 171 168 176 163 168 185 172 166 185 180 172 172 191 176 208 163 166 162 181 150 191 207 181 163 175 159 191 156 169 158 157 180 155 163 137 194 167 155 157 202 170 201 173 187 168 160 166 171 178 159 161 179 181 179 194 154 183 152 161 175 150 177 188 140 160 150 177 174 175 152 156 144 152 174 184 190 174 166 169 159 179 179 169 170 169 173 187 162 162 164 176 184 171 162 168 174 161 173 161 195 158 160 188 184 149 170 153 154 199 199 157 160 175 162 175 175 182 159 194 146 187 162 175 199 191 195 173 151 153 168 166 175 156 143 155 175 177 179 193 190 173 171 142 171 165 184 164 173 175 162 158 163 158 181 164 159 166 176 156 180 160 159 187 188 170 183 179 178 167 161 181 163 163 151 169 167 158 191 158 176 156 197 181 158 175 178 162 167 188 177 156 185 144 155 154 159 169 161 180 161 164 155 184 174 181 157 168 167 159 153 168 171 162 180 154 164 205 147 170 156 166 173 159 146 167 169 175 160 154 172 177 156 171 168 175 146 173 176 154 148 165 177 174 168 160 172 144 142 171 174 161 169 170 147 174 168 179 155 135 178 181 164 144 174 170 177 168 164 156 167 173 167 175 163 176 172 163 157 177 170 151 149 149 178 159 124 159 158 155 154 169 145 155 127 149 162 152 166 180 153 174 150 142 174 169 163 151 154 156 166 152 161 158 131 165 164 156 163 149 169 146 142 163 174 176 166 135 155 141 167 151 162 194 180 178 174 154 174 166 166 153 172 147 178 161 165 154 191 148 140 182 160 159 161 165 136 145 149 151 157 161 143 149 176 162 163 146 155 142 165 144 169 149 162 167 162 157 147 134 162 179 168 162 138 167 153 155 165 170 156 163 136 160 157 171 139 193 145 150 137 180 142 169 160 154 181 165 146 166 155 143 149 146 160 125 162 147 168 143 145 175 150 167 173 142 149 160 135 162 164 150 163 140 170 174 160 157 140 164 141 130 148 126 168 169 147 146 156 168 155 144 146 169 139 163 147 157 153 174 147 154 145 176 143 151 138 142 159 156 171 171 179 152 157 157 154 117 155 164 149 139 152 144 155 144 176 133 169 151 143 157 151 165 153 121 154 130 146 146 143 141 152 164 151 129 160 186 176 158 160 175 168 141 143 141 180 159 150 152 138 147 150 163 167 147 142 162 149 145 120 156 150 154 163 142 148 135 158 154 170 136 162 166 145 142 150 175 163 177 142 159 155 147 175 165 153 134 146 160 160 156 134 130 143 163 137 155 171 167 143 158 141 144 143 169 148 144 141 153 131 161 158 152 116 154 152 140 145 146 148 124 142 144 132 136 135 127 140 133 130 154 154 170 127 148 148 127 148 141 137 146 127 138 139 144 142 158 137 126 133 136 141 147 148 161 146 138 139 142 119 151 125 140 142 141 141 151 150 148 151 148 154 147 146 163 152 133 149 156 141 143 159 158 145 127 140 124 154 136 158 157 133 147 146 152 158 154 148 122 144 145 124 117 141 152 143 128 149 137 133 118 122 129 131 163 156 139 126 130 137 153 141 141 128 140 145 128 137 158 152 125 132 142 127 131 166 150 138 127 149 139 133 115 143 132 130 139 150 127 127 112 144 121 134 118 144 126 127 123 137 143 160 129 132 139 146 154 133 137 138 148 147 134 125 143 136 134 132 147 137 143 137 132 119 118 129 130 132 169 150 146 143 179 139 121 126 151 150 129 127 141 120 139 122 137 136 145 135 125 136 142 134 138 155 140 142 142 158 140 139 140 123 121 132 138 137 140 146 168 132 140 149 152 132 155 146 130 132 136 138 138 128 149 134 152 126 139 144 123 120 147 122 145 147 130 123 137 137 128 139 142 109 127 133 152 120 133 118 115 143 139 147 135 128 131 120 136 144 122 147 137 147 131 150 117 136 113 165 133 129 134 128 122 119 120 167 153 131 125 119 127 115 131 136 162 153 141 114 114 125 111 144 124 142 119 133 122 111 132 131 126 140 139 134 127 143 131 147 151 125 128 121 120 106 124 118 122 130 143 127 125 156 135 143 137 118 116 120 146 133 109 118 154 130 142 140 133 118 133 135 122 141 128 149 124 134 124 137 128 115 147 141 149 113 121 120 117 133 126 121 119 124 120 131 129 141 127 147 133 131 121 136 120 123 122 130 112 130 136 144 116 126 122 140 142 141 148 139 132 121 139 113 127 148 117 137 147 138 129 132 121 122 122 125 126 137 123 130 128 128 130 133 122 136 134 113 130 122 119 140 130 141 128 117 112 117 132 115 127 134 133 134 145 131 126 106 132 139 119 145 128 127 126 118 138 130 153 134 124 143 124 150 114 133 135 125 127 122 116 110 133 124 114 114 129 145 123 115 131 132 136 131 128 135 129 123 114 136 119 130 127 127 106 127 135 97 133 114 113 123 132 128 120 131 117 122 114 128 131 122 117 122 121 102 124 140 163 136 122 122 111 111 134 129 115 116 137 124 120 106 122 118 122 129 133 121 129 123 143 128 105 141 125 114 132 129 131 132 126 122 142 125 129 116 124 133 120 131 118 123 138 123 112 115 113 118 111 117 118 140 138 130 134 120 118 131 115 120 126 125 123 126 119 118 134 114 135 118 116 121 117 118 134 122 107 144 124 100 135 107 104 128 122 120 105 138 127 114 131 130 118 127 130 105 119 130 113 129 129 120 132 118 110 124 116 108 122 111 131 119 118 131 141 114 115 144 123 113 106 128 128 124 116 102 109 124 126 107 119 119 129 119 127 123 105 124 105 108 110 101 121 125 126 123 127 116 134 111 131 107 122 104 121 128 102 120 129 131 120 127 123 129 131 113 126 105 129 135 118 107 137 125 118 117 129 118 119 119 119 145 145 109 124 102 129 129 123 125 129 123 132 123 127 117 131 117 138 123 136 118 97 129 108 136 107 117 133 123 131 110 116 124 97 116 115 119 103 113 98 122 122 135 115 117 122 124 135 131 111 111 117 116 124 130 100 100 131 130 113 115 111 127 117 116 133 114 114 131 127 137 132 114 125 100 117 127 117 123 109 120 123 112 113 117 105 137 122 119 120 124 130 130 116 120 122 99 102 116 134 119 118 114 144 120 135 119 102 122 114 119 102 135 110 136 121 116 135 123 120 117 138 123 113 133 105 129 114 118 134 109 114 116 120 104 103 114 113 120 119 135 132 119 123 124 109 124 133 127 116 133 117 134 136 112 128 114 122 126 122 115 129 110 115 91 107 127 128 135 121 114 120 106 147 108 121 144 94 124 136 121 112 133 133 120 119 114 128 113 114 111 113 112 124 111 121 116 132 128 114 119 133 118 117 122 148 133 118 124 115 122 121 131 119 113 118 110 127 127 136 136 115 129 130 95 123 136 112 131 138 128 106 142 135 122 110 129 107 132 132 123 98 136 103 142 111 123 114 127 132 124 101 120 114 130 112 108 124 124 138 131 128 108 143 114 128 114 124 116 102 131 119 126 123 142 119 108 154 122 101 109 115 133 110 131 127 109 121 140 111 136 119 105 125 142 136 110 112 107 122 121 120 101 110 117 117 110 108 109 122 129 116 121 110 126 125 125 128 107 110 109 119 113 106 108 127 109 119 114 128 124 114 128 136 111 128 120 116 117 119 123 111 110 121 108 104 123 121 126 112 133 126 118 112 109 97 129 118 143 114 120 113 121 136 121 107 126 117 104 107 110 106 110 109 121 105 127 126 112 116 139 116 139 119 135 128 129 122 91 113 120 122 112 111 101 108 120 131 128 123 100 123 121 129 130 120 109 116 122 104 120 125 126 92 111 117 100 116 110 116 130 113 121 125 121 138 124 112 102 109 105 121 105 137 127 118 113 114 126 117 120 115 124 94 115 124 123 121 132 116 119 121 119 120 131 115 117 104 121 102 126 116 102 119 97 121 130 118 130 110 128 126 129 131 119 126 123 103 125 117 113 126 109 129 106 132 117 110 119 120 108 119 109 127 104 108 132 123 128 113 99 115 100 107 114 108 133 118 110 136 132 124 103 113 117 113 123 120 132 109 103 100 112 134 131 115 110 108 119 123 117 120 107 120 119 114 112 115 131 116 133 111 121 122 110 117 125 136 117 108 136 137 110 115 103 117 117 135 127 127 133 129 109 129 131 120 121 133 126 112 117 119 113 111 123 108 131 128 122 115 109 124 133 117 117 124 137 109 118 125 116 115 126 116 108 136 94 123 121 89 95 114 122 138 125 109 134 110 125 120 118 104 106 109 130 125 132 122 142 131 143 117 127 125 134 113 104 131 112 113 100 112 143 108 114 102 104 113 114 127 93 136 120 102 122 108 105 113 118 123 108 112 121 128 125 135 120 110 114 118 110 127 133 110 121 118 115 103 136 123 105 130 120 143 110 105 113 125 109 134 123 114 97 105 98 101 132 108 112 105 99 112 131 136 152 113 112 122 120 111 118 110 118 111 114 131 92 111 117 126 114 117 110 138 127 124 105 121 111 122 113 108 97 107 129 124 112 112 124 104 106 103 108 105 131 112 129 122 125 126 131 105 119 136 122 121 135 130 122 101 110 104 126 126 132 110 128 123 123 125 102 116 112 126 120 141 125 109 113 122 114 112 120 109 123 128 135 130 92 127 127 124 115 113 95 103 119 110 122 120 101 122 119 104 116 120 112 114 116 127 98 107 129 131 94 135 101 124 120 106 124 111 99 117 116 124 117 95 104 103 115 132 121 140 129 124 115 127 117 131 127 107 119 130 138 112 122 130 118 114 125 113 133 105 139 114 120 128 115 119 101 119 144 107 121 112 143 130 132 131 115 122 152 122 102 112 146 120 118 142 135 110 108 128 147 117 129 130 130 113 120 114 109 120 121 116 116 118 124 114 112 129 133 124 115 129 112 122 117 110 127 122 114 124 136 134 124 121 129 118 119 123 112 115 120 114 125 114 149 108 127 106 118 108 117 127 132 124 131 117 122 127 131 111 132 94 127 139 119 127 99 136 129 108 109 113 122 110 124 124 122 121 111 103 112 93 109 117 130 137 135 143 105 139 115 135 121 116 127 130 123 121 131 127 107 110 131 130 123 121 129 111 130 106 120 141 120 120 125 135 136 121 131 134 113 129 142 133 124 135 123 140 114 138 135 135 97 117 143 114 133 111 130 124 139 134 127 132 150 132 159 120 120 151 114 137 138 154 121 146 156 149 141 152 134 147 144 149 157 171 139 163 169 170 151 182 144 181 171 153 169 174 180 195 159 181 203 203 184 190 200 218 178 198 212 192 214 228 211 215 230 200 192 192 203 186 186 195 214 199 199 162 164 173 171 145 161 169 143 162 141 146 167 146 150 142 149 138 140 158 120 155 148 125 128 118 152 142 147 127 150 127 128 129 115 130 126 136 136 152 130 127 133 125 141 130 120 130 142 129 117 111 118 132 125 116 136 136 125 123 126 99 117 129 131 120 132 123 126 148 103 117 116 126 117 114 152 140 141 124 130 125 110 103 109 109 111 106 117 124 121 126 133 121 130 141 124 125 132 115 126 135 120 127 120 121 142 127 121 135 129 95 119 114 116 131 105 138 124 109 144 128 124 112 121 111 125 121 112 111 132 137 137 141 134 110 134 116 120 133 125 104 148 126 87 122 136 116 119 109 133 109 135 127 134 126 128 112 126 109 116 117 119 129 103 118 117 107 114 136 107 125 126 118 127 138 126 123 135 133 113 132 143 137 123 153 137 127 121 126 117 130 123 116 110 131 125 122 129 112 113 131 128 103 115 107 117 99 126 129 151 121 129 122 149 127 123 125 116 114 115 123 133 121 124 127 120 119 116 118 114 114 102 111 126 104 104 119 122 109 124 107 123 132 111 83 111 141 117 115 123 113 130 127 112 110 125 144 115 136 134 133 122 118 104 131 127 151 132 142 131 137 140 121 131 127 112 128 136 123 101 131 115 112 111 116 117 113 119 143 105 154 113 122 124 144 130 120 113 142 117 116 104 121 116 93 109 138 123 119 127 109 127 147 123 124 118 120 132 123 114 142 125 115 127 134 133 130 135 96 114 115 118 108 109 113 116 108 129 121 124 104 116 115 132 121 137 111 125 145 111 126 143 130 108 149 126 123 104 133 124 117 112 127 101 108 130 99 115 124 112 121 115 119 131 131 130 105 113 128 137 102 99 105 108 129 138 102 125 114 111 114 109 108 119 124 124 142 135 133 138 132 123 126 118 124 124 121 114 125 119 142 115 110 119 116 115 119 115 123 123 124 123 108 115 139 130 138 133 121 113 124 126 128 115 113 106 110 121 112 119 127 148 116 123 124 129 130 106 140 114 114 134 128 108 111 122 122 126 119 129 120 118 119 107 137 115 118 114 127 98 118 111 134 136 117 135 122 120 110 123 130 115 125 123 113 121 132 128 135 101 115 114 123 121 99 120 128 117 122 124 134 123 102 111 135 118 129 123 111 105 116 137 125 135 134 130 127 113 125 117 129 126 122 120 115 122 126 103 117 125 124 125 133 107 109 105 119 111 123 123 123 136 131 110 120 117 107 118 92 110 107 122 108 105 115 121 125 123 111 110 109 118 110 119 109 116 112 111 123 106 106 113 124 105 117 111 124 128 122 129 106 109 128 125 127 136 117 113 110 108 123 100 129 125 115 109 138 114 135 102 134 118 114 102 118 112 118 114 117 112 116 117 130 124 118 137 110 136 150 140 92 140 141 115 125 115 136 110 108 113 104 114 116 119 123 99 130 113 119 121 132 128 107 118 123 97 106 110 120 113 128 118 113 126 116 127 123 109 117 134 108 113 114 113 124 138 126 114 128 118 111 118 121 103 125 136 98 109 115 125 126 127 110 126 108 133 134 136 106 118 112 137 129 124 121 122 136 125 109 131 112 127 110 109 126 121 122 118 121 125 120 123 123 112 116 126 117 109 135 124 128 117 93 135 115 112 99 114 120 132 126 109 131 129 112 126 108 127 112 122 117 115 95 120 120 130 125 98 133 106 90 130 118 136 107 108 124 100 112 129 111 113 111 114 113 114 113 107 101 125 123 109 123 132 130 134 112 126 119 105 117 120 105 101 111 137 117 115 115 82 126 115 125 116 116 117 114 115 105 139 123 107 103 130 124 117 111 133 113 135 125 136 108 124 109 112 120 115 136 109 136 115 144 113 112 133 128 115 133 127 118 98 117 112 116 118 112 109 140 122 124 141 102 106 109 112 98 90 115 146 109 127 128 136 139 115 118 104 134 118 118 113 135 120 114 111 125 112 111 116 128 87 127 126 114 122 120 124 121 109 133 119 135 115 135 115 113 107 124 112 120 121 125 122 112 150 112 119 109 124 132 126 105 115 118 123 116 113 118 114 113 121 91 106 121 110 118 110 116 115 108 119 125 113 135 98 112 113 111 127 119 136 120 101 133 117 118 111 107 116 116 122 103 116 121 121 107 98 124 135 121 107 110 125 117 120 121 111 124 134 125 133 121 141 132 124 128 117 141 123 115 120 114 112 142 108 120 133 115 121 121 135 128 101 133 119 96 123 99 102 126 125 108 132 96 99 131 126 116 115 129 103 118 113 114 147 104 124 111 113 136 121 116 126 109 127 125 138 115 131 122 109 124 116 123 130 113 126 125 124 138 104 128 120 109 110 124 108 114 113 132 117 128 130 115 122 118 135 139 112 127 110 115 118 120 116 124 145 106 123 117 135 114 127 116 132 112 122 115 114 130 130 110 112 142 122 123 119 129 129 104 135 122 122 132 115 122 110 123 105 111 109 119 120 101 131 112 132 139 121 108 135 125 110 117 119 125 108 118 118 115 135 129 109 118 127 113 112 136 108 108 124 138 132 107 114 136 118 117 119 110 112 118 115 124 114 124 106 108 144 121 115 142 128 115 121 117 103 117 103 122 143 109 111 113 122 128 122 125 118 127 104 119 133 128 123 145 130 123 124 115 117 119 121 110 116 123 126 125 121 116 117 105 125 140 121 137 130 151 133 129 119 114 115 121 116 118 106 121 126 114 102 127 92 115 129 100 111 116 116 120 120 121 127 123 121 117 116 124 115 115 125 141 119 125 113 100 110 106 137 116 120 104 138 112 123 123 133 112 131 111 101 100 120 144 90 131 132 127 131 119 121 127 131 134 109 105 105 139 121 104 109 123 119 121 111 115 115 117 125 118 119 119 133 126 118 130 116 114 105 141 107 143 129 111 106 118 121 130 97 110 109 118 128 111 122 118 136 123 111 117 117 120 111 106 116 122 110 138 134 105 110 112 123 125 127 91 120 124 132 100 150 111 106 120 114 120 132 109 94 115 112 117 115 112 122 124 124 117 122 125 143 114 135 121 119 120 132 121 122 130 129 113 130 141 101 106 125 134 94 111 102 143 117 130 128 119 105 124 112 103 121 136 106 131 126 113 113 106 116 136 134 137 135 140 120 116 94 115 128 106 102 149 109 131 110 115 110 126 125 95 123 125 101 125 115 124 108 116 135 123 112 148 133 124 126 121 117 118 124 101 131 114 125 125 111 121 128 137 117 115 138 98 124 103 125 124 120 131 141 108 108 102 127 120 117 127 125 130 118 115 119 105 107 118 137 142 136 124 135 117 134 141 122 149 127 106 123 126 125 104 116 120 130 112 126 132 94 121 127 137 123 119 112 126 128 127 111 121 112 114 136 129 134 114 127 120 108 123 116 103 112 123 119 138 105 112 126 144 106 108 115 121 122 114 111 128 126 148 135 130 131 129 132 118 122 135 117 130 120 107 107 96 120 118 126 118 134 124 114 126 133 123 108 125 132 146 134 134 153 116 122 131 114 124 124 128 128 127 124 129 139 146 109 124 143 126 110 121 129 103 130 126 135 140 132 104 127 98 132 125 129 135 118 125 110 124 123 134 108 122 121 102 113 144 100 125 120 129 134 111 116 121 127 128 119 124 120 106 119 132 107 105 132 121 112 121 123 145 108 134 111 128 118 128 98 106 102 131 143 129 116 115 139 132 142 112 128 114 120 118 113 110 145 123 121 130 117 114 112 122 108 122 125 111 130 120 122 132 116 150 110 133 153 132 125 122 128 130 116 136 110 122 100 136 135 97 120 136 116 129 115 101 111 129 122 114 136 124 126 113 137 135 112 131 123 113 120 130 104 119 118 111 114 149 130 139 113 122 126 119 118 110 122 125 125 114 96 120 131 122 98 114 105 112 123 130 138 109 139 115 110 123 127 116 120 116 116 117 146 129 118 117 117 120 128 103 143 119 115 108 115 102 138 129 133 117 125 111 100 124 114 139 135 115 140 120 108 124 153 124 115 129 115 91 126 115 120 118 127 115 110 112 125 122 118 131 126 135 124 111 109 134 107 104 114 122 113 127 104 134 133 137 126 133 129 115 138 110 115 110 115 117 118 118 114 112 136 127 110 126 129 136 146 95 125 127 116 115 117 115 121 112 118 124 128 118 102 118 128 135 142 130 118 113 114 121 118 113 114 125 115 130 125 135 114 118 142 116 121 128 120 106 134 119 109 127 116 109 125 128 144 104 119 121 136 121 150 121 113 121 129 130 109 117 116 102 120 140 126 121 109 117 145 122 132 126 130 104 125 139 139 117 144 136 122 127 131 106 147 116 105 123 115 121 120 133 139 125 118 120 112 130 118 119 112 134 130 129 123 127 120 123 123 119 123 120 123 130 131 107 113 125 133 117 138 135 115 126 128 96 100 122 116 133 102 139 109 124 115 132 123 110 113 128 115 126 133 143 155 137 125 133 114 124 124 115 134 139 122 116 121 117 124 117 108 127 122 133 127 132 123 123 121 129 118 139 146 122 115 102 116 118 115 122 142 130 111 140 115 121 140 134 127 122 108 128 132 129 129 129 132 143 118 120 131 133 137 118 114 120 123 121 135 114 128 132 115 123 147 140 130 140 135 126 134 129 146 117 122 138 126 114 130 121 131 120 117 90 129 105 109 153 120 127 133 100 114 127 145 116 139 111 128 132 140 116 105 112 113 129 120 133 120 126 133 136 126 139 131 132 132 125 140 133 132 134 123 140 128 125 109 108 137 133 109 118 141 140 119 115 116 108 129 117 137 118 114 134 136 109 112 109 125 131 106 114 124 123 116 119 120 121 110 134 115 140 118 119 111 104 142 137 124 116 116 100 118 127 119 124 118 122 132 116 118 100 100 120 132 119 129 122 125 114 131 118 142 132 128 117 130 121 113 118 121 121 120 117 120 123 117 127 113 120 129 153 126 121 113 111 115 120 144 116 106 113 125 141 121 119 114 116 126 131 129 92 110 134 131 130 121 133 99 108 122 127 108 124 124 114 132 105 114 120 136 129 114 134 110 120 107 133 141 115 118 144 135 131 136 117 109 119 118 133 109 119 107 120 105 119 135 128 117 105 116 130 123 106 117 128 114 116 126 129 122 122 121 90 124 121 106 102 112 114 120 136 119 133 148 121 104 112 122 132 105 113 126 117 111 102 95 133 123 130 118 141 131 133 117 130 112 127 144 114 102 122 116 122 121 123 128 132 122 119 121 135 128 125 130 100 120 123 110 118 122 123 126 148 116 113 119 133 113 131 134 123 114 120 122 130 113 130 133 127 122 125 128 133 132 126 125 130 120 115 123 138 117 116 143 123 113 103 120 124 149 120 116 114 119 114 136 97 115 103 115 137 142 129 120 124 121 124 156 108 109 138 126 110 116 127 127 119 105 125 128 114 106 107 104 137 117 122 118 126 121 125 112 123 134 131 111 114 132 125 130 128 118 105 111 136 115 121 119 123 133 112 116 128 103 129 107 133 130 142 133 121 128 109 96 128 112 126 128 129 119 121 125 120 116 137 136 125 130 121 121 119 130 125 137 110 117 123 138 134 114 131 117 143 119 109 119 111 124 127 109 125 123 119 127 123 107 137 109 126 114 136 122 102 134 128 135 112 120 135 130 119 107 124 108 134 106 112 126 146 119 107 112 106 131 126 113 122 121 136 116 161 128 121 102 107 124 115 132 106 129 112 124 110 104 121 124 113 118 120 109 123 129 125 120 112 113 129 127 124 120 132 127 108 112 124 126 114 129 122 109 111 144 120 122 139 114 132 119 130 126 133 124 118 133 114 88 117 104 119 110 102 114 111 104 145 115 124 121 109 122 124 135 123 108 137 126 119 107 141 117 122 131 116 126 147 116 129 113 124 109 138 126 117 120 131 125 123 149 134 123 128 129 133 109 117 123 111 103 117 112 121 122 107 114 96 126 117 111 119 136 134 128 127 121 126 127 115 114 131 136 122 138 129 119 124 147 98 143 126 110 118 124 128 120 108 132 128 134 115 106 104 123 125 105 117 120 115 133 138 122 119 112 116 114 127 130 112 134 95 129 103 118 121 149 128 116 149 110 118 127 136 121 116 99 141 115 115 115 127 119 133 100 130 128 113 124 111 133 107 105 123 129 120 122 115 108 138 100 118 116 113 123 133 125 121 131 129 119 128 129 113 127 117 121 125 135 128 145 114 131 127 106 110 116 108 115 143 139 118 121 121 123 117 107 118 118 115 129 101 110 113 127 138 127 123 127 130 105 128 123 123 123 114 131 129 115 152 124 113 107 112 115 108 124 110 118 125 134 109 134 124 114 118 127 111 120 122 97 114 122 118 114 111 130 125 115 110 118 122 120 107 120 138 113 109 122 110 133 130 107 104 115 120 139 108 130 114 105 116 121 141 121 113 122 112 120 117 122 124 106 116 113 112 118 120 136 121 125 129 112 119 130 145 112 125 131 131 143 108 131 121 129 113 107 131 127 106 113 113 129 125 118 122 126 136 105 138 125 110 97 122 110 137 128 101 118 120 141 118 128 112 125 122 116 140 129 108 91 115 118 140 132 102 114 106 127 111 115 130 131 116 114 128 114 136 124 110 121 101 121 124 115 125 120 132 122 125 134 132 120 109 106 120 145 113 119 142 115 132 136 136 113 119 115 120 106 113 130 109 110 101 117 121 134 128 101 117 130 109 141 129 126 132 132 123 135 125 123 103 124 148 126 120 117 129 125 129 125 136 127 125 139 123 110 129 103 109 125 121 121 135 129 122 125 105 153 138 116 168 132 136 101 94 132 120 124 111 128 113 111 107 122 133 130 113 125 125 107 123 116 117 130 108 103 111 135 120 118 109 124 118 112 124 125 145 131 126 113 112 138 133 108 129 133 116 142 112 117 114 107 123 113 114 138 136 119 127 124 121 126 123 121 120 128 110 142 123 121 115 117 113 125 133 127 126 109 114 109 127 114 113 110 120 136 132 131 112 103 116 119 123 136 122 133 121 120 114 104 115 135 108 135 139 120 122 138 121 112 124 127 119 103 131 124 130 121 124 115 118 126 138 111 133 133 117 119 117 137 106 140 121 126 138 124 135 127 138 141 115 110 112 100 120 129 121 125 100 104 115 115 125 118 126 125 126 115 124 127 129 122 110 112 127 116 115 114 122 138 109 131 105 112 112 121 129 124 114 145 120 140 136 119 113 122 123 116 116 126 113 122 132 130 116 127 107 131 128 98 109 119 136 125 130 101 125 120 120 134 133 130 120 124 131 112 126 131 129 99 119 128 120 133 138 120 126 126 122 129 114 119 109 111 119 104 131 115 113 134 116 122 107 111 128 134 118 110 113 122 118 130 128 129 114 142 138 127 124 112 133 134 131 122 143 106 141 127 125 96 106 124 129 105 105 121 107 113 114 126 120 129 132 132 130 119 116 114 131 110 117 129 110 107 128 131 122 136 127 98 119 115 124 144 110 114 105 111 116 121 128 146 115 134 123 128 126 108 132 113 109 131 114 114 107 130 107 111 112 116 116 102 110 117 117 144 108 123 139 140 110 129 133 119 126 131 122 119 139 100 120 125 103 123 119 130 137 127 129 123 125 138 135 141 135 125 117 118 117 114 114 125 130 121 121 105 120 131 132 121 113 120 110 121 103 121 116 126 117 117 144 123 107 118 118 123 118 121 113 153 134 131 131 116 141 122 113 111 122 120 117 123 157 117 119 126 132 112 134 126 124 122 98 120 127 129 125 121 127 117 115 133 104 121 115 112 107 122 124 131 120 115 118 133 127 135 153 128 123 111 126 120 106 138 118 123 126 107 137 132 115 131 125 119 114 107 118 138 120 113 120 132 100 166 130 112 113 118 153 131 117 115 120 114 115 111 116 122 129 122 123 131 114 127 140 122 129 110 136 118 117 121 108 111 119 123 109 114 129 118 105 121 108 112 114 128 110 120 130 119 116 129 114 113 119 125 120 107 116 115 134 121 130 134 111 107 95 120 129 118 103 128 144 140 115 117 144 125 140 120 122 106 121 122 106 129 122 116 104 122 114 132 114 107 137 118 132 118 112 132 130 125 114 125 121 111 107 129 107 116 120 126 123 120 126 127 121 103 139 120 104 111 132 137 115 126 118 116 135 126 107 134 117 98 141 116 97 122 136 109 98 106 115 118 130 125 130 125 114 139 114 134 134 131 124 138 124 124 139 143 109 117 106 131 118 122 118 133 132 112 104 108 126 138 116 124 130 127 125 112 104 105 127 122 119 120 98 132 128 131 113 140 126 127 117 111 130 107 112 120 123 151 125 113 112 122 122 135 129 123 112 128 108 113 127 116 111 123 114 125 106 128 122 107 133 134 118 111 127 123 119 128 130 115 117 142 110 122 116 115 119 124 106 128 115 120 126 129 107 120 128 119 121 115 107 130 114 109 114 118 131 120 116 127 136 124 106 114 119 125 104 121 117 137 134 129 127 123 131 140 138 116 122 126 124 126 140 123 135 137 142 121 129 136 116 135 125 120 134 123 130 128 128 138 130 142 118 142 131 125 149 112 132 113 123 152 140 131 155 140 142 150 123 141 119 122 125 128 120 156 167 140 137 148 142 127 143 122 129 139 165 131 140 155 133 148 139 159 138 142 138 150 140 142 129 127 141 134 139 146 163 148 135 138 138 136 130 139 127 114 127 113 147 141 138 143 118 121 151 131 114 126 132 117 113 136 129 127 124 137 128 130 131 133 139 142 126 113 126 128 127 129 137 112 122 119 133 138 129 125 139 124 114 115 140 134 124 144 125 124 118 138 119 101 140 135 117 117 116 123 129 126 134 123 128 138 115 113 124 103 123 124 110 113 119 127 126 103 118 132 135 121 136 117 133 116 120 119 120 140 134 122 117 140 124 139 123 117 111 121 118 135 103 125 97 114 119 109 106 126 110 116 121 120 121 118 115 100 113 131 140 123 117 117 99 109 99 109 128 113 120 128 113 120 101 138 144 147 113 116 120 108 126 107 121 152 127 129 124 129 133 124 126 123 107 120 122 127 116 115 120 140 108 114 125 126 127 116 116 108 133 128 148 126 141 123 94 117 102 117 118 107 114 121 115 115 120 109 126 121 107 109 126 127 117 128 99 139 101 135 120 109 114 116 111 118 123 128 119 124 113 114 121 151 121 114 135 122 146 112 132 123 109 142 123 138 103 123 129 116 129 115 120 128 125 131 136 114 124 125 108 105 119 121 118 121 107 117 128 128 119 123 139 114 105 104 131 129 105 124 122 135 130 113 117 131 107 119 116 109 128 126 115 127 128 118 102 100 138 139 111 105 102 122 141 129 111 117 128 127 133 115 127 115 118 143 113 125 118 112 118 131 120 129 115 117 108 123 122 139 119 135 124 125 114 120 128 114 112 96 122 111 141 128 127 119 129 127 109 108 116 103 134 105 111 125 96 118 142 121 107 111 125 110 126 113 138 122 117 124 119 118 107 104 113 108 111 119 130 97 130 122 114 121 143 116 105 123 130 120 130 117 123 119 111 108 127 118 106 105 105 138 102 119 112 102 114 120 112 117 104 141 111 115 120 126 118 131 125 123 115 121 119 130 114 103 102 129 113 118 117 135 110 132 113 132 118 113 116 129 116 125 115 115 132 135 135 108 137 101 132 128 116 133 116 111 103 134 137 90 128 107 119 119 133 111 142 107 135 112 116 111 100 140 123 110 114 127 119 105 135 107 118 109 145 113 91 117 121 126 140 120 99 102 141 115 135 116 110 100 126 121 120 111 119 117 122 124 104 137 123 103 120 132 121 122 118 111 102 122 117 125 112 115 111 124 129 127 124 110 133 126 133 123 116 110 130 94 124 115 124 107 106 111 123 137 130 119 114 124 105 129 126 112 119 114 140 127 104 115 118 142 109 118 106 117 140 126 116 104 125 132 107 125 120 130 111 131 114 125 115 116 111 106 126 115 134 119 123 124 110 118 123 102 116 128 114 126 114 124 97 122 130 125 99 122 106 112 133 116 119 123 117 120 118 129 138 118 117 127 133 123 128 119 134 131 115 87 134 122 115 128 120 130 128 109 111 141 109 134 111 119 115 117 106 100 100 113 102 102 106 128 139 114 112 117 123 107 119 112 130 113 110 124 125 102 108 142 131 115 105 113 111 123 128 128 109 113 114 114 123 128 138 127 122 117 107 118 134 105 109 127 123 122 116 121 104 120 117 133 130 122 141 141 109 112 104 115 131 128 113 130 121 121 126 137 111 107 128 96 114 111 116 114 112 98 118 123 122 127 137 137 124 111 116 142 135 113 120 119 135 112 124 134 122 115 113 97 123 124 115 145 127 117 114 126 116 137 112 127 115 133 113 117 124 137 106 109 110 118 138 113 110 117 121 131 100 99 132 138 110 106 116 109 133 112 127 120 111 131 118 121 107 119 120 114 109 111 135 114 99 103 119 126 99 128 109 130 120 125 112 99 126 136 119 118 127 109 111 120 137 114 120 132 122 113 127 112 105 105 107 125 106 114 99 145 105 122 122 101 116 122 133 124 126 128 109 121 120 112 130 122 133 104 114 113 120 121 106 129 121 124 127 110 112 118 120 112 101 107 126 114 114 105 130 131 127 116 118 120 109 122 133 97 131 116 138 105 123 140 128 118 110 114 128 110 121 119 99 138 121 108 126 119 124 109 141 116 124 122 128 131 115 125 107 108 129 127 122 116 132 132 118 119 102 110 110 136 123 116 124 104 111 132 122 128 117 114 128 113 125 103 101 127 124 123 115 129 115 116 109 111 130 123 112 122 110 112 126 121 116 106 118 112 124 105 138 117 120 123 116 117 132 114 127 130 141 121 104 124 114 120 117 117 146 136 134 125 112 105 100 115 110 132 118 139 115 123 97 105 115 114 147 104 123 92 107 132 115 133 114 106 110 117 117 103 124 110 121 127 131 125 113 125 128 112 107 134 121 102 116 137 118 122 104 113 98 127 140 114 106 137 111 131 129 102 121 130 118 116 115 97 118 108 135 122 118 134 113 118 118 110 105 124 136 110 141 108 119 108 128 120 118 116 124 103 119 121 95 101 112 127 110 124 122 127 110 120 124 124 121 118 134 127 129 115 89 106 131 124 102 132 121 118 117 111 131 121 118 121 121 113 108 106 105 121 114 134 117 109 115 108 119 140 118 121 110 123 106 136 108 107 150 126 111 110 117 111 130 109 128 150 91 116 134 117 96 133 100 122 118 113 128 103 116 122 112 105 115 94 139 119 120 121 120 121 112 109 112 118 124 120 121 101 116 114 143 127 114 115 105 121 105 106 128 106 121 99 107 112 130 119 110 126 113 121 111 117 120 113 118 110 115 115 118 107 112 93 111 134 118 121 108 104 123 151 108 130 100 116 120 130 107 102 108 117 133 134 125 118 132 102 114 107 103 112 133 109 110 102 120 120 110 108 127 113 123 138 131 111 105 120 99 111 109 129 114 116 117 135 94 132 110 127 114 107 116 128 126 115 105 115 125 117 132 133 113 130 137 109 107 101 106 123 137 106 122 103 116 111 132 119 114 145 127 123 99 107 128 151 123 114 121 133 117 114 119 110 113 123 104 104 130 106 107 112 143 104 109 131 112 132 101 119 132 108 119 121 110 108 121 124 117 109 117 125 131 124 122 124 151 141 110 119 103 120 117 112 140 113 135 136 139 115 113 119 123 140 125 106 114 122 124 117 124 117 130 119 132 122 131 141 128 121 101 121 122 135 125 98 103 126 108 139 133 132 113 125 99 117 121 123 115 113 135 115 116 115 109 117 111 116 90 137 122 130 147 95 100 122 108 119 117 110 103 121 115 128 112 105 120 124 127 96 114 105 97 101 102 122 122 115 114 120 116 112 132 107 108 121 113 106 114 119 112 105 122 118 111 142 111 119 107 101 98 114 119 124 112 117 129 107 126 124 124 101 112 109 114 107 114 125 96 118 129 121 113 106 109 108 132 120 108 107 97 126 116 106 102 114 125 126 117 117 118 134 114 137 116 112 122 133 120 105 126 113 107 124 127 140 118 119 108 118 116 117 107 105 129 139 135 120 113 122 111 124 108 122 113 119 103 109 121 109 113 127 104 125 110 124 110 124 124 98 124 108 119 99 123 118 123 110 131 131 116 120 117 105 131 121 113 118 113 127 120 109 118 126 104 123 140 125 138 95 106 100 124 125 124 107 112 131 127 100 111 125 108 108 111 112 126 104 105 116 105 114 104 100 127 113 101 113 127 129 128 106 125 113 116 100 122 119 117 116 105 110 119 127 102 103 124 133 117 142 122 119 103 114 111 128 103 111 112 106 131 118 121 131 143 126 115 113 128 123 130 132 118 100 120 97 120 150 124 107 110 116 113 121 139 125 109 103 129 115 125 139 124 130 137 109 149 121 144 130 131 107 121 129 100 125 116 118 106 124 116 112 136 134 116 113 123 121 124 106 127 115 123 108 125 124 114 116 119 121 122 125 116 93 107 112 109 133 108 119 110 110 119 120 113 131 104 135 123 121 123 108 98 124 113 121 120 105 120 135 123 106 104 114 95 123 115 99 129 121 108 133 111 119 122 111 113 135 105 141 106 121 120 127 117 118 109 116 96 92 134 121 107 133 112 130 111 127 129 120 109 111 117 127 138 118 128 106 123 128 105 117 131 104 101 115 125 118 116 109 109 121 98 107 110 111 105 122 131 108 132 103 105 121 99 124 124 116 109 136 121 100 124 107 121 100 116 121 107 118 102 120 114 128 118 123 124 118 114 131 119 114 113 141 114 116 94 133 122 138 124 119 114 106 111 114 107 133 120 113 117 121 108 124 108 127 125 106 115 132 139 136 120 97 114 125 103 132 119 116 142 105 127 109 114 99 136 122 118 93 110 97 103 120 99 120 110 118 116 101 101 115 110 120 102 106 120 116 128 115 120 124 131 105 102 113 102 142 103 102 109 112 111 117 128 122 115 115 117 102 118 133 115 115 120 135 121 112 100 125 128 110 112 130 115 118 115 115 109 102 131 116 114 118 102 122 119 112 103 117 115 123 106 118 124 124 109 124 125 117 122 130 105 104 101 122 149 143 117 105 129 132 114 109 123 101 118 117 123 110 110 128 118 115 124 112 88 121 134 98 112 93 132 104 111 127 129 126 110 99 122 115 104 101 113 119 111 113 106 106 118 125 105 113 125 102 116 145 122 141 112 98 110 119 114 119 113 138 117 136 121 114 135 121 111 94 116 126 119 119 103 126 114 104 127 104 128 121 120 106 135 110 116 119 109 104 126 122 116 107 128 116 117 119 119 131 120 120 110 125 125 117 117 123 120 117 104 108 137 95 107 120 129 111 101 122 112 87 113 127 128 127 113 107 117 132 105 106 123 104 116 115 116 120 127 112 124 103 99 124 132 121 135 114 123 114 117 124 117 127 122 130 108 109 106 115 102 127 100 112 103 105 99 109 116 116 114 102 120 100 114 129 105 105 114 120 116 107 126 111 109 121 133 120 122 116 123 125 121 141 115 121 110 131 130 107 130 133 126 112 118 140 114 134 112 119 110 118 117 127 128 107 112 123 114 117 134 116 132 125 97 106 126 102 122 112 125 121 121 103 116 117 121 121 114 98 102 101 124 123 118 98 110 117 121 120 119 135 133 146 121 139 126 119 131 110 105 119 120 105 120 114 120 122 123 115 125 109 129 137 119 104 101 125 128 110 102 93 100 91 129 117 113 119 141 133 113 116 103 111 115 150 125 112 103 129 120 124 105 116 116 119 111 124 128 97 106 113 95 116 103 107 116 107 111 101 116 127 112 101 126 121 110 129 118 113 125 121 121 132 125 114 108 112 111 116 98 112 105 126 123 114 124 115 118 122 117 115 109 134 105 103 121 125 100 117 134 119 101 132 118 108 96 126 105 130 109 115 114 119 121 114 113 127 115 119 124 122 105 107 91 121 105 109 105 123 107 129 104 108 106 124 114 109 113 118 132 112 114 115 113 109 115 102 115 113 106 108 116 106 92 116 116 121 103 134 109 120 120 119 128 120 116 114 130 130 97 115 125 116 139 110 128 97 112 112 102 100 114 110 125 106 118 130 137 125 123 119 104 119 123 109 142 107 130 125 129 117 119 118 119 130 106 128 117 109 136 102 117 111 115 120 108 122 97 119 114 112 117 113 119 114 148 115 125 124 111 104 126 106 120 98 131 98 133 140 131 88 118 129 102 102 131 113 130 115 116 120 99 106 110 148 112 120 118 99 82 110 104 105 124 106 134 130 104 119 101 114 129 117 118 105 112 121 111 114 126 116 103 120 127 139 112 126 116 120 112 122 111 121 115 113 114 117 140 127 115 115 131 123 111 121 106 106 125 109 121 98 112 100 105 109 114 112 113 122 104 114 124 124 123 111 117 108 121 141 126 115 110 112 105 124 124 115 107 93 125 102 109 138 118 118 100 128 126 104 113 114 121 115 121 118 102 106 115 126 121 117 115 100 123 126 100 123 123 121 111 113 106 111 112 99 120 114 110 114 130 98 113 116 116 123 118 122 117 100 114 112 111 94 98 129 128 110 114 109 118 113 125 130 134 116 109 121 129 93 139 108 114 116 125 116 121 121 111 122 114 129 118 107 108 96 94 117 112 140 113 115 115 126 108 133 103 124 112 105 108 122 103 129 111 135 104 119 114 132 110 121 116 110 113 112 122 117 138 126 116 119 122 121 135 104 99 109 89 111 127 120 127 126 119 112 112 113 109 115 97 126 121 87 103 125 127 118 113 122 96 123 111 117 102 129 111 124 105 128 126 130 118 98 131 119 116 104 124 136 125 107 89 133 102 120 108 115 125 124 124 127 103 107 118 105 108 135 122 115 98 124 122 109 131 128 109 124 122 134 128 115 109 121 110 97 111 117 101 124 115 125 158 120 127 115 118 103 116 101 122 115 120 111 128 130 120 126 132 129 116 113 118 113 129 112 107 122 121 110 110 117 112 129 128 113 114 102 130 121 100 117 116 106 98 116 104 120 113 152 126 106 136 117 126 112 115 121 132 112 114 107 127 126 119 115 111 115 137 95 117 123 114 119 106 128 117 115 106 119 105 106 112 126 125 123 129 108 135 109 133 142 100 125 110 118 100 122 135 116 133 120 120 111 107 114 118 118 99 115 112 131 121 102 137 131 117 102 133 112 133 103 128 106 127 115 126 122 114 126 116 108 101 144 111 117 122 119 126 113 126 124 127 125 142 124 123 129 125 86 117 122 102 113 115 127 120 137 121 121 121 119 133 126 108 109 124 121 117 135 113 116 113 144 113 107 126 102 118 122 124 118 124 110 126 122 113 121 118 116 119 98 105 110 118 124 125 113 118 111 130 128 106 103 119 102 140 118 115 125 137 122 130 111 112 111 108 124 111 131 111 112 110 109 118 130 101 130 107 111 106 108 136 110 120 105 106 124 126 127 126 105 163 114 125 128 111 130 109 141 127 118 114 133 136 97 110 120 100 133 138 108 122 117 130 107 126 137 112 108 124 117 115 130 117 121 112 106 110 133 140 126 128 130 111 113 111 128 119 116 131 135 117 112 116 95 120 125 118 130 97 122 110 119 127 116 132 114 126 120 134 103 135 110 106 117 109 93 123 91 122 108 112 119 112 130 123 111 113 114 116 111 124 112 108 117 117 110 112 137 108 133 127 107 112 124 133 125 116 93 125 119 125 127 99 120 119 133 128 122 135 110 127 120 140 123 116 118 122 127 103 117 133 105 103 120 112 114 117 101 123 96 125 102 125 122 133 141 113 125 135 117 120 140 130 115 131 108 113 120 115 116 115 132 105 115 104 100 112 118 114 105 110 121 119 122 122 125 110 124 126 122 113 123 106 110 111 116 118 117 137 116 115 126 122 135 115 123 92 112 124 128 117 113 116 125 127 121 121 103 113 131 121 105 124 111 128 116 97 120 128 111 96 133 116 109 113 101 119 110 123 97 127 96 114 127 119 118 114 126 124 126 118 112 111 128 93 122 119 118 131 124 116 104 118 121 107 120 104 134 105 116 134 135 105 105 102 98 126 128 112 120 105 108 110 112 113 125 137 118 106 118 126 112 111 120 109 126 122 147 128 120 119 118 122 127 116 126 147 105 125 116 130 122 113 121 117 123 129 123 108 113 113 118 117 122 128 111 144 121 117 123 119 130 124 109 139 111 116 130 126 117 110 103 123 103 123 132 121 109 113 118 128 102 130 125 124 137 126 123 129 136 116 109 119 122 115 136 113 118 115 139 119 119 127 101 135 128 128 114 110 138 111 146 124 126 137 142 147 124 131 133 132 112 107 137 123 137 127 148 131 121 122 131 119 111 130 125 127 120 126 131 105 125 120 151 132 126 111 129 130 111 135 120 121 114 125 123 116 129 125 130 138 139 127 115 138 137 128 112 130 145 119 104 126 149 127 129 109 120 128 102 116 111 114 136 113 132 125 116 112 108 144 132 127 128 129 138 121 139 120 119 115 139 140 134 119 112 118 131 119 117 136 126 132 92 120 119 112 132 114 117 118 119 118 125 129 125 126 123 121 121 121 101 105 119 119 121 115 151 129 118 146 113 115 111 115 113 121 118 122 129 107 121 115 132 130 112 144 133 140 134 133 111 131 121 123 116 114 104 104 140 133 137 126 119 127 123 138 127 129 115 135 133 115 120 130 111 107 125 123 105 107 129 113 84 120 101 136 110 121 111 120 122 100 132 120 127 120 109 108 128 116 113 122 129 110 125 107 115 131 115 114 120 117 114 122 118 96 119 115 108 119 107 115 129 105 119 109 106 109 108 116 147 121 122 107 105 111 103 112 114 126 122 111 120 130 112 115 125 123 140 108 113 126 128 131 126 121 131 128 125 107 110 102 122 113 117 120 128 111 134 116 112 121 100 98 96 108 128 116 142 125 111 135 140 102 124 118 125 128 126 125 127 124 107 126 125 104 117 117 115 109 115 123 106 123 107 103 112 122 96 126 108 134 112 116 139 123 123 123 112 94 105 115 106 145 117 122 127 115 119 114 141 124 107 125 139 94 131 103 105 133 119 123 116 115 109 101 119 116 132 116 116 128 109 102 123 135 119 105 123 146 116 115 125 131 137 133 110 122 128 111 131 116 120 109 118 119 106 116 112 132 109 117 128 120 119 125 133 127 113 119 111 127 121 125 114 116 112 120 134 131 134 120 125 103 131 133 112 121 88 106 123 111 108 137 116 134 136 116 126 117 121 139 106 115 116 131 118 111 118 101 131 126 109 121 123 130 117 139 110 127 121 106 109 126 128 136 96 126 121 92 119 119 114 116 125 125 132 121 131 103 118 113 118 136 140 103 102 118 123 127 127 126 121 120 126 114 127 120 130 95 122 125 140 114 125 136 130 110 112 109 112 119 110 113 95 114 117 132 117 115 115 120 117 118 108 123 123 122 115 116 103 124 118 106 127 99 119 110 116 119 113 105 124 112 123 109 112 113 122 132 130 114 135 104 133 91 133 101 113 105 114 117 110 127 102 115 124 115 129 115 115 116 110 108 118 117 114 132 129 122 137 151 119 113 114 121 112 114 122 129 149 126 107 115 127 117 142 112 94 128 130 121 116 124 131 142 101 119 104 122 124 130 100 135 128 121 121 126 130 107 125 117 126 136 126 115 123 124 124 138 118 117 100 125 115 131 125 127 127 108 147 126 121 101 117 108 113 119 116 137 118 125 128 110 139 99 91 118 111 114 123 133 118 126 120 112 111 105 118 122 109 112 100 133 127 121 123 115 122 124 128 106 126 128 120 112 86 124 123 114 110 116 110 125 119 114 107 118 130 103 128 125 126 136 116 127 106 111 128 95 121 130 108 113 130 128 116 107 126 113 123 131 135 114 114 121 114 134 113 130 110 126 122 118 106 138 123 141 149 122 130 109 142 96 126 130 112 132 128 120 152 106 104 139 117 141 109 118 118 117 124 107 107 108 132 124 117 106 112 127 130 123 119 112 142 128 117 111 124 154 107 113 136 107 118 136 123 118 106 130 121 142 112 132 128 98 130 125 129 111 108 107 117 121 106 125 120 116 118 115 129 127 118 117 104 103 108 130 130 135 113 142 116 108 128 126 110 113 108 113 112 100 130 126 110 126 127 109 135 117 112 112 109 113 109 122 130 116 120 149 112 121 107 123 121 119 116 125 123 112 110 112 148 102 115 107 105 117 122 140 118 121 121 132 133 132 129 112 126 127 121 116 115 114 129 121 122 123 114 117 113 104 144 99 124 124 117 101 118 135 145 117 149 143 126 128 124 107 113 123 104 120 110 113 113 125 130 133 134 116 100 112 120 132 116 115 103 128 120 119 118 110 127 106 120 122 122 126 121 118 116 113 113 125 107 118 123 104 113 124 119 129 126 116 120 129 117 104 131 116 129 123 133 115 117 116 103 109 141 105 113 112 121 124 130 113 122 113 122 120 107 128 114 121 128 109 128 109 117 120 110 130 147 110 109 116 122 135 114 136 92 137 125 117 111 124 123 127 129 115 146 126 112 127 111 129 129 127 120 109 115 130 115 109 119 125 120 133 112 114 120 112 119 94 110 101 110 134 141 117 102 119 117 122 125 117 117 119 122 126 122 117 112 92 109 108 117 135 109 130 128 131 126 132 122 117 114 108 125 113 125 120 138 130 128 143 133 132 95 99 115 128 97 127 120 126 124 136 119 128 92 104 91 127 137 120 107 113 99 117 131 108 113 119 118 113 118 108 124 124 134 102 122 124 137 138 138 123 133 121 110 98 123 108 134 103 112 130 137 101 116 112 107 120 132 109 123 124 144 140 120 101 111 117 136 121 100 123 122 116 133 126 108 124 128 115 126 126 134 118 104 120 129 107 128 115 123 115 102 117 136 127 133 143 124 118 118 123 104 116 114 126 121 112 136 118 101 118 109 115 122 121 114 152 136 122 120 102 102 115 100 132 105 119 105 144 104 113 112 104 129 112 121 117 117 124 127 113 129 133 103 118 126 129 129 117 130 122 112 109 145 129 110 122 118 120 113 102 134 117 128 109 143 114 137 113 102 120 112 127 115 129 106 126 130 128 126 124 122 118 108 124 116 122 119 139 105 126 127 114 139 117 139 114 113 114 135 112 118 127 127 113 128 129 108 99 130 105 119 113 106 126 125 133 120 127 114 118 115 123 124 125 118 111 117 118 116 125 110 125 108 116 136 122 104 111 109 128 95 133 118 136 140 111 117 119 124 134 124 137 121 129 133 123 132 141 120 118 131 117 131 112 136 121 120 118 143 126 135 113 127 112 83 129 115 110 126 128 116 118 113 130 126 108 132 137 123 125 129 112 132 133 129 127 115 123 133 127 123 113 133 115 140 145 117 131 112 124 145 115 122 135 115 125 107 107 136 138 106 113 120 107 125 128 110 118 125 126 136 118 108 140 111 130 139 139 138 127 109 126 116 122 112 131 124 127 127 141 126 112 131 99 126 122 104 111 136 129 120 119 140 147 120 149 143 133 109 107 126 125 123 136 104 135 101 119 124 139 121 132 138 136 113 113 131 125 103 137 122 99 119 133 132 141 131 136 146 125 102 120 142 123 129 123 133 120 128 115</counts>
			</dataPoints>
		</scan>
	</xrdMeasurement>
</xrdMeasurements>