File: data/XRD/_misc/old/XG-650C/W6824-1A_absolute_2th-om_10-130deg_PIXscan_56min_4.xrdml
<xrdMeasurements xmlns="http://www.xrdml.com/XRDMeasurement/2.1" xmlns:xsi="http://www.w3.org/2001/XMLSchema-instance" xsi:schemaLocation="http://www.xrdml.com/XRDMeasurement/2.1 http://www.xrdml.com/XRDMeasurement/2.1/XRDMeasurement.xsd" status="Completed">
	<comment>
		<entry>Configuration=Factory configuration, Owner=User-1, Creation date=7/8/2013 4:01:53 PM</entry>
		<entry>Goniometer=PW3050/65 (Theta/2Theta); Minimum step size 2Theta:0.0001; Minimum step size Omega:0.0001</entry>
		<entry>Sample stage=MRD Cradle; Minimum step size Phi:0.01; Minimum step size Chi:0.01; Minimum step size X:0.01; Minimum step size Y:0.01; Minimum step size Z:0.001</entry>
		<entry>Diffractometer system=XPERT-PRO</entry>
		<entry>Measurement program=C:\PANalytical\Data Collector\Programs\Jorrit\2thom\_absolute_2th-om_10-130deg_PIXscan_56min.xrdmp, Identifier={15BCCF57-2807-42BD-B5B9-ECC0B3DC9284}</entry>
		<entry>Batch program=C:\PANalytical\Data Collector\Programs\SimonL\batch4x_2thom_10-130°_z9.1_x0,10,20,30_y0_57min.xrdmp, Identifier={EED9823A-2BEB-424C-9252-345C4EF2834A}</entry>
	</comment>
	<sample type="To be analyzed">
		<id></id>
		<name></name>
		<preparedBy></preparedBy>
	</sample>
	<xrdMeasurement measurementType="Scan" status="Completed" sampleMode="Reflection">
		<comment>
			<entry>_absolute_2th-om_10-130deg_PIXscan_56min</entry>
			<entry>PHD Lower Level = 4.83 (keV), PHD Upper Level = 11.27 (keV)</entry>
		</comment>
		<usedWavelength intended="K-Alpha 1">
			<kAlpha1 unit="Angstrom">1.5405980</kAlpha1>
			<kAlpha2 unit="Angstrom">1.5444260</kAlpha2>
			<kBeta unit="Angstrom">1.3922500</kBeta>
			<ratioKAlpha2KAlpha1>0.5000</ratioKAlpha2KAlpha1>
		</usedWavelength>
		<incidentBeamPath>
			<radius unit="mm">320.00</radius>
			<xRayTube id="1010048" name="Empyrean Cu LFF HR (9430 033 7310x) DK442154">
				<tension unit="kV">40.0</tension>
				<current unit="mA">40.0</current>
				<anodeMaterial>Cu</anodeMaterial>
				<focus type="Line">
					<length unit="mm">12.0</length>
					<width unit="mm">0.4</width>
					<takeOffAngle unit="deg">4.2</takeOffAngle>
				</focus>
			</xRayTube>
			<xRayMirror id="27010001" name="Inc. Beam Cu W/Si (parabolic MRD)" hybrid="false">
				<crystal type="Graded" shape="Parabolic">W/Si</crystal>
				<acceptanceAngle unit="deg">0.800</acceptanceAngle>
				<length unit="mm">60.0</length>
			</xRayMirror>
			<sollerSlit id="21010002" name="Soller slits 0.04 rad.">
				<opening unit="rad">0.0400</opening>
			</sollerSlit>
			<mask id="22030007" name="Fixed mask 2 mm">
				<distanceToSample unit="mm">220.00</distanceToSample>
				<width unit="mm">2.00</width>
			</mask>
			<divergenceSlit id="22010007" name="Fixed slit 1/8°" xsi:type="fixedDivergenceSlitType">
				<distanceToSample unit="mm">220.00</distanceToSample>
				<height unit="mm">0.19</height>
			</divergenceSlit>
		</incidentBeamPath>
		<diffractedBeamPath>
			<radius unit="mm">320.00</radius>
			<sollerSlit id="21010002" name="Soller slits 0.04 rad.">
				<opening unit="rad">0.0400</opening>
			</sollerSlit>
			<receivingSlit id="22010001" name="Fixed slit 4°">
				<height unit="mm">5.88</height>
			</receivingSlit>
			<detector id="7010017" name="PIXcel3D 1x1 detector" xsi:type="areaDetectorType">
				<phd unit="%">
					<lowerLevel>30.0</lowerLevel>
					<upperLevel>70.0</upperLevel>
				</phd>
				<mode>Scanning</mode>
				<activeChannelsEquatorial>255</activeChannelsEquatorial>
				<activeChannelsAxial>255</activeChannelsAxial>
				<pitchEquatorial unit="mm">0.05500</pitchEquatorial>
				<pitchAxial unit="mm">0.05500</pitchAxial>
				<readOutPeriod unit="seconds">0.135</readOutPeriod>
			</detector>
		</diffractedBeamPath>
		<scan appendNumber="0" mode="Continuous" scanAxis="2Theta-Omega" status="Completed">
			<header>
				<startTimeStamp>2024-08-29T21:07:05+02:00</startTimeStamp>
				<endTimeStamp>2024-08-29T22:03:11+02:00</endTimeStamp>
				<author>
					<name>PRO-MRD</name>
				</author>
				<source>
					<applicationSoftware version="6.1b">Data Collector</applicationSoftware>
					<instrumentControlSoftware version="7.0E 20130304">XPERT-PRO</instrumentControlSoftware>
					<instrumentID>0000000011142674</instrumentID>
				</source>
			</header>
			<dataPoints>
				<positions axis="2Theta" unit="deg">
					<startPosition>9.99826193</startPosition>
					<endPosition>129.99755682</endPosition>
				</positions>
				<positions axis="Omega" unit="deg">
					<startPosition>4.99913096</startPosition>
					<endPosition>64.99877841</endPosition>
				</positions>
				<positions axis="Phi" unit="deg">
					<commonPosition>0.00</commonPosition>
				</positions>
				<positions axis="Chi" unit="deg">
					<commonPosition>0.00</commonPosition>
				</positions>
				<positions axis="X" unit="mm">
					<commonPosition>30.00</commonPosition>
				</positions>
				<positions axis="Y" unit="mm">
					<commonPosition>0.00</commonPosition>
				</positions>
				<positions axis="Z" unit="mm">
					<commonPosition>9.100</commonPosition>
				</positions>
				<commonCountingTime unit="seconds">32.895</commonCountingTime>
				<counts 201 207 193 202 192 220 191 197 180 168 186 166 198 187 204 183 183 173 193 183 182 199 181 214 167 194 177 184 198 180 172 187 197 172 197 187 191 178 197 209 167 188 191 172 199 186 183 171 185 184 177 176 201 199 199 190 171 179 164 185 201 161 187 167 168 186 201 165 204 171 175 174 188 190 171 187 185 201 196 202 197 179 179 159 198 203 193 160 199 185 194 197 187 186 177 172 182 174 182 218 182 186 168 192 178 168 171 168 170 184 171 173 177 173 162 187 160 185 167 198 178 174 173 151 163 194 155 178 165 196 193 177 188 169 145 181 157 187 157 174 185 198 177 191 171 179 159 181 155 181 156 183 175 168 194 169 162 186 183 193 154 149 170 185 199 154 169 166 165 182 194 145 185 197 175 152 190 182 179 177 163 170 171 173 180 182 178 181 177 165 173 163 172 176 182 138 180 167 166 152 165 171 183 166 196 188 172 166 145 169 160 183 176 152 182 155 173 170 154 169 189 186 169 147 171 167 190 142 130 160 174 178 180 191 152 177 152 182 149 166 133 160 164 176 164 167 152 159 180 153 154 167 168 158 166 164 162 151 180 167 162 148 148 154 178 156 154 160 174 153 157 153 178 162 162 162 150 169 170 176 159 154 154 195 153 172 147 172 166 173 154 181 168 168 158 176 152 171 162 157 172 146 163 150 168 169 168 170 158 166 154 169 151 150 134 156 166 159 175 162 165 140 160 136 161 135 166 157 158 143 148 164 156 156 164 153 158 175 136 160 161 160 142 151 168 153 159 154 127 163 145 139 139 165 162 167 150 179 180 143 169 146 171 169 139 141 145 163 161 150 141 150 157 144 143 147 167 170 148 157 131 157 142 153 160 152 163 138 130 151 148 164 143 172 147 158 150 165 161 161 137 167 167 130 140 156 166 145 171 160 143 151 157 159 147 153 146 140 144 141 144 145 172 151 161 184 165 155 156 168 153 150 142 142 142 158 143 156 174 164 141 151 150 135 132 154 157 159 145 151 143 160 124 149 135 154 139 144 150 152 164 144 149 146 157 147 119 163 136 133 159 130 156 133 162 131 153 130 145 142 155 158 143 141 145 132 170 136 142 140 147 141 141 135 146 152 139 130 138 138 141 151 149 162 171 157 125 143 142 135 131 152 155 139 143 140 147 153 135 152 151 143 124 136 160 141 140 151 135 153 130 146 130 131 121 132 135 149 137 126 157 132 145 136 147 132 140 144 142 153 138 136 124 132 148 153 131 155 156 153 148 132 130 129 154 137 153 164 137 128 133 133 144 155 134 145 135 145 128 134 143 135 145 161 141 136 148 136 162 134 136 135 125 126 125 151 129 141 120 125 147 145 147 130 121 136 129 150 154 142 123 148 130 117 130 138 145 134 136 143 146 150 159 134 128 126 132 116 146 128 127 153 121 135 129 148 120 137 111 122 137 146 130 149 147 124 152 113 146 152 129 128 140 143 141 127 132 130 160 138 143 147 149 147 148 129 136 121 135 125 129 127 144 141 118 133 121 134 120 123 137 150 150 138 153 109 133 115 152 121 127 153 129 119 123 139 147 138 135 146 127 142 161 121 133 120 157 147 140 175 147 147 146 145 108 140 142 122 128 122 147 143 135 139 119 127 151 137 129 157 143 142 126 113 134 127 133 149 134 159 143 148 146 124 134 150 118 149 133 159 125 141 144 142 160 137 143 147 131 147 153 129 137 128 125 128 152 140 126 152 135 114 140 125 138 146 113 137 147 155 142 134 144 145 136 126 113 132 146 146 134 128 133 135 127 130 163 126 118 152 141 146 148 125 149 132 121 144 141 146 146 133 145 146 171 145 143 129 146 130 130 133 129 123 140 126 126 146 115 142 157 160 145 142 137 125 126 119 150 121 131 127 143 146 138 137 143 140 110 109 136 130 154 135 141 135 151 124 150 151 140 132 167 135 145 118 129 145 106 143 143 146 154 145 142 126 130 157 144 155 137 137 139 162 137 134 133 140 149 155 171 140 144 145 139 153 114 123 128 126 135 159 163 145 140 159 125 146 144 128 121 142 120 136 140 133 145 145 139 146 134 135 124 139 141 153 127 146 101 135 137 145 133 126 146 160 136 140 121 147 149 145 143 150 140 147 138 140 138 142 142 152 149 152 130 164 147 147 156 144 128 161 140 152 142 149 154 139 149 126 148 146 131 164 152 148 125 146 142 138 130 149 156 153 158 142 156 125 139 135 142 139 137 150 128 145 164 163 145 142 137 113 169 145 151 130 163 146 159 139 134 143 160 154 163 135 141 150 149 133 132 128 128 148 149 142 146 153 152 140 132 165 136 106 153 145 136 151 128 140 145 126 136 147 155 165 157 151 163 123 137 151 166 134 146 144 147 154 138 159 146 139 142 153 138 123 151 123 158 158 149 155 154 152 145 144 131 166 149 124 150 157 129 150 132 121 167 149 156 153 177 159 123 141 159 153 135 144 149 151 142 135 152 155 154 143 137 139 158 154 164 143 145 161 151 141 128 134 137 154 152 151 135 157 151 143 150 143 152 149 146 135 161 149 135 162 172 147 150 157 135 155 164 178 156 161 141 146 146 157 154 152 171 169 144 139 146 149 144 139 153 142 163 143 167 156 157 155 143 153 162 170 147 163 148 160 166 139 148 127 163 153 146 166 156 161 142 149 155 139 129 164 133 154 172 160 142 156 140 145 157 130 168 151 150 145 157 145 136 167 171 148 140 168 160 189 167 131 169 156 159 136 157 172 167 156 149 149 149 144 167 153 176 152 159 157 160 153 151 139 154 134 138 165 138 148 144 142 165 149 149 160 148 137 156 147 158 141 166 147 149 186 161 147 166 151 141 175 150 163 151 151 162 139 181 159 140 139 146 155 157 148 165 155 147 167 144 153 132 154 155 148 148 157 183 148 156 180 168 143 134 155 138 165 146 143 138 138 158 158 128 132 169 153 143 142 149 152 140 143 143 156 144 164 148 136 141 160 175 142 129 161 142 145 153 134 164 148 132 156 169 132 140 163 141 159 129 159 146 138 138 144 153 145 146 147 147 169 149 146 159 146 171 169 157 165 144 140 158 146 141 174 143 161 154 152 165 158 141 162 180 175 183 160 141 146 146 141 156 162 165 157 152 139 134 140 166 136 168 156 165 148 145 150 155 144 160 155 153 154 147 157 146 184 180 170 171 143 171 115 155 141 157 160 147 137 155 154 140 122 142 140 154 152 153 145 127 148 135 149 137 170 149 151 136 149 161 151 116 161 145 134 171 153 143 149 146 159 139 130 142 135 154 153 148 154 154 132 125 149 149 162 145 133 130 153 176 161 147 128 144 173 133 152 137 153 158 120 147 171 140 140 143 155 134 133 156 128 136 158 160 147 145 144 145 150 151 178 130 145 132 155 148 151 145 157 147 115 119 163 143 146 134 120 162 158 154 163 149 153 172 142 150 126 147 143 156 142 161 122 154 120 160 148 159 142 124 136 130 132 141 149 146 127 134 141 152 114 134 136 145 154 133 123 132 126 131 151 126 134 155 135 119 131 141 132 131 149 134 154 136 127 149 133 133 163 154 140 152 142 155 145 146 131 134 124 137 117 105 129 134 143 142 129 124 137 120 153 141 141 150 136 150 147 144 147 141 114 139 136 122 152 142 139 123 150 155 128 116 142 142 142 136 118 173 153 131 152 135 142 134 135 124 109 132 117 137 120 143 144 145 121 136 142 121 123 103 138 134 139 164 149 132 145 133 139 120 134 140 134 131 133 128 105 149 129 125 147 161 117 140 129 119 138 128 132 134 134 117 123 151 141 140 131 118 114 149 134 112 120 139 121 113 118 135 132 122 132 139 114 132 112 145 122 129 124 141 125 123 129 105 130 119 131 130 136 116 125 137 125 134 139 152 117 142 107 128 140 122 133 119 126 121 104 146 125 132 117 158 133 132 117 153 111 124 122 126 117 123 116 124 127 122 120 123 111 127 105 142 142 124 127 110 115 119 107 116 123 123 121 120 111 111 128 125 133 122 138 117 145 119 127 129 127 118 129 120 142 128 119 134 109 108 139 114 133 132 124 137 137 101 117 109 121 124 117 143 130 134 129 135 125 127 112 129 116 129 129 128 107 139 118 118 130 122 117 125 132 127 141 99 125 133 117 130 136 125 116 121 129 125 136 122 143 138 140 124 117 118 120 130 126 115 108 100 123 125 124 111 124 128 155 110 119 119 108 112 123 123 131 121 122 104 130 108 129 139 108 115 119 111 134 118 112 108 102 115 98 117 102 125 117 131 97 119 111 133 123 140 121 119 111 136 124 122 107 118 129 113 108 105 115 107 125 134 104 104 128 125 112 104 132 109 133 129 127 115 125 118 113 120 125 107 105 120 124 133 138 122 145 99 133 115 132 122 123 103 116 115 116 132 127 121 116 118 127 112 127 94 118 130 135 115 136 113 111 109 140 127 108 115 115 116 124 132 111 124 105 110 106 116 107 110 110 106 135 129 138 116 131 120 105 112 111 107 106 100 115 128 113 109 99 107 122 136 111 104 117 114 125 122 111 110 101 107 107 92 117 133 110 121 120 112 104 127 112 124 131 104 117 121 143 106 140 100 116 99 125 109 102 118 129 126 113 110 151 95 134 119 118 113 114 111 126 88 117 112 92 111 104 127 109 113 119 112 130 99 114 119 109 107 122 136 112 116 109 112 107 107 100 121 98 128 92 119 111 110 100 125 98 106 115 101 128 111 124 129 129 122 111 109 104 121 116 139 123 108 115 118 110 96 135 116 107 98 112 121 109 130 102 111 125 119 115 117 118 113 116 104 111 113 119 113 105 116 111 107 106 98 120 113 113 108 91 120 110 115 84 104 104 92 124 121 124 114 104 112 108 111 110 97 119 138 115 120 97 94 115 109 127 117 93 130 119 112 102 109 120 124 94 97 112 99 109 85 112 117 117 114 110 118 115 102 114 105 98 113 113 127 115 106 128 101 118 100 114 105 104 105 92 110 107 99 114 114 87 93 107 114 118 104 121 113 110 125 122 130 109 105 102 106 109 108 124 121 116 112 114 101 101 97 97 93 107 94 101 106 109 109 85 124 109 122 107 111 107 107 95 104 133 113 100 131 113 103 119 107 107 107 104 113 109 96 92 110 126 104 112 108 108 98 129 106 122 94 101 104 102 105 126 111 112 99 98 107 118 109 108 97 106 136 94 114 112 114 104 124 112 119 99 114 109 107 90 106 100 106 111 94 117 108 119 108 95 103 114 116 112 115 108 123 102 108 108 117 120 98 118 99 98 102 109 104 102 110 90 107 104 111 100 100 107 99 87 109 120 120 105 117 112 136 101 88 110 124 99 106 114 110 108 100 101 117 88 122 125 112 107 107 96 96 118 110 111 109 130 104 100 108 109 115 102 118 97 102 104 104 108 105 105 122 114 89 107 119 111 86 114 119 106 101 112 100 99 105 100 109 112 108 114 111 114 121 114 99 127 106 102 105 88 113 110 87 113 94 107 117 127 110 104 106 93 104 113 104 89 102 110 113 108 104 102 116 112 111 110 124 108 97 111 103 92 92 115 89 101 86 109 108 100 116 110 111 115 113 104 100 105 96 102 102 84 92 98 118 113 106 97 102 99 120 104 100 116 94 101 96 106 115 108 105 114 111 114 93 94 114 113 100 93 95 121 96 132 87 110 101 127 99 108 103 104 120 112 78 96 117 92 102 124 105 100 101 94 99 100 104 99 107 96 104 91 123 104 112 122 135 103 124 99 127 114 94 92 113 106 108 108 105 104 102 123 105 110 102 114 113 115 131 122 105 107 108 102 98 119 87 103 107 110 94 106 115 99 119 109 114 103 109 120 106 102 97 95 121 110 108 122 112 85 124 110 88 82 97 115 109 103 104 110 104 83 101 113 103 105 89 113 106 119 90 120 101 110 106 96 108 105 115 111 102 98 110 96 92 101 111 105 130 111 112 126 95 99 112 99 124 95 105 94 103 111 95 104 107 117 109 87 107 87 106 96 100 107 103 104 96 99 102 114 115 108 95 118 108 113 110 88 116 104 91 107 97 91 91 111 88 91 97 117 98 104 98 120 107 114 92 105 101 110 101 108 106 99 115 118 92 98 111 100 119 117 105 86 90 98 98 100 92 110 95 91 97 116 89 113 105 92 99 122 99 103 97 111 111 110 114 91 107 92 108 112 115 94 121 117 104 106 110 97 98 116 85 102 131 114 116 112 109 113 80 97 105 93 127 102 107 110 101 113 101 87 103 106 116 117 117 103 99 108 114 104 98 99 107 118 102 80 101 85 95 102 117 108 88 106 104 93 90 111 102 97 105 86 117 93 98 94 116 104 98 102 103 99 106 124 108 119 106 112 94 133 85 86 116 97 99 89 111 106 107 99 102 107 104 107 99 114 96 118 118 102 102 89 100 122 108 109 90 132 98 92 104 103 98 115 110 102 111 88 105 84 98 95 119 90 99 110 97 104 101 95 92 120 103 96 93 102 116 105 89 110 100 105 99 89 95 101 91 109 100 93 98 106 91 102 88 97 97 93 94 116 97 100 96 108 107 100 107 105 108 95 109 111 117 108 96 123 100 99 116 103 118 119 100 95 101 95 101 98 117 89 112 117 103 115 114 105 108 101 108 99 106 90 101 113 94 96 107 103 100 93 86 112 88 86 100 106 111 106 89 79 103 87 83 103 96 105 115 98 98 89 106 108 101 111 110 101 110 94 97 110 95 111 118 96 108 102 102 111 112 95 126 115 114 109 100 112 114 97 110 95 99 94 106 109 99 105 113 118 113 111 103 98 106 128 112 118 92 91 104 119 117 101 87 108 99 94 102 98 108 92 102 91 124 93 109 102 102 88 103 99 92 94 95 107 102 112 103 102 82 90 100 111 110 103 91 99 103 110 87 110 100 102 125 108 92 77 85 92 95 117 122 111 95 111 97 110 98 118 102 109 117 93 126 110 103 107 100 114 86 99 85 107 120 87 105 103 112 115 100 113 111 110 104 105 102 100 95 108 118 95 109 106 117 105 108 109 109 99 92 122 92 109 94 110 89 108 92 105 102 118 92 102 104 95 109 103 109 111 104 110 98 112 95 101 91 104 104 102 81 101 124 90 116 113 92 89 89 107 89 109 115 93 95 101 102 90 120 125 94 112 92 127 118 91 100 88 96 96 101 121 123 111 95 100 105 104 118 74 113 105 93 105 107 119 88 81 98 104 110 103 123 101 91 96 104 103 117 107 97 109 102 96 110 101 94 96 109 92 105 83 107 108 109 110 106 106 94 89 90 102 106 112 117 106 95 94 94 94 87 96 115 100 105 98 100 96 111 104 104 109 79 92 106 96 101 89 103 110 100 102 93 91 105 113 96 114 95 105 107 122 120 95 102 105 119 98 96 96 103 102 103 108 101 105 115 112 82 100 114 105 101 107 100 116 95 113 111 87 103 103 103 102 107 103 90 104 101 112 105 102 101 111 109 110 99 109 99 118 110 97 109 117 101 104 109 98 109 116 104 95 100 97 96 95 106 109 104 113 107 123 100 117 99 99 115 92 86 104 122 93 113 102 98 91 103 119 96 96 109 103 96 90 98 117 116 113 115 105 83 113 113 107 115 115 100 105 112 111 103 100 95 90 114 107 119 110 123 111 110 99 121 116 133 99 112 110 106 124 118 124 104 113 119 105 107 87 114 107 118 125 108 114 100 106 122 130 114 111 110 120 130 133 126 118 133 116 116 119 116 106 119 109 111 135 113 115 129 122 142 135 128 146 143 120 137 133 130 136 123 149 140 117 137 146 133 154 116 161 155 158 177 171 173 177 199 196 192 181 185 199 170 182 199 174 200 201 188 207 205 179 184 187 196 177 188 186 179 164 183 157 178 160 129 160 169 130 145 157 129 154 132 135 115 131 117 136 113 129 123 127 123 126 113 115 115 118 122 150 98 104 126 121 127 120 116 117 112 117 113 110 120 121 112 116 103 120 123 114 120 111 99 111 108 94 119 99 121 124 99 111 102 100 139 103 102 105 107 93 117 125 105 127 106 95 87 115 118 97 98 106 117 117 116 108 109 97 100 92 113 105 110 106 116 106 117 127 103 108 106 106 84 116 107 101 113 110 124 108 105 97 90 107 103 106 122 108 100 100 99 99 83 110 102 112 109 103 104 103 132 113 112 129 121 104 104 107 122 98 112 103 120 112 110 100 99 110 114 96 99 113 115 115 100 97 98 128 92 94 109 114 88 100 103 113 112 101 113 127 98 103 104 113 91 119 98 114 107 106 95 105 131 103 98 102 102 103 101 105 110 103 113 99 102 75 118 126 112 110 102 95 96 116 120 83 86 125 113 102 97 95 93 107 122 114 105 98 105 116 114 90 97 110 107 85 96 111 86 94 98 116 123 93 113 101 100 88 105 132 107 116 109 113 108 102 99 87 118 102 117 92 101 91 96 101 104 114 104 97 115 110 110 100 108 94 105 102 130 91 116 98 102 108 93 100 135 98 108 110 95 106 119 93 108 97 107 106 116 123 111 93 112 113 93 119 120 99 109 111 98 102 114 87 107 94 113 105 107 104 96 103 108 135 112 92 115 122 114 85 102 115 113 96 105 100 92 106 100 114 121 108 99 111 103 100 104 101 97 106 101 99 89 114 113 106 114 102 106 104 107 113 100 107 113 105 110 114 89 109 115 116 114 110 124 102 112 98 125 114 106 93 88 109 115 117 108 89 87 96 104 106 106 94 96 111 108 119 96 130 93 104 105 110 120 103 108 100 112 106 97 98 111 100 102 98 109 99 107 108 116 100 125 105 97 98 102 93 97 100 112 96 101 114 103 126 123 107 123 126 114 94 89 85 97 85 101 84 104 112 109 105 95 106 115 100 116 111 117 99 101 117 114 89 108 119 104 114 113 111 108 105 106 96 112 128 108 121 125 119 124 105 113 95 87 112 104 96 103 105 117 122 106 103 108 108 100 122 103 102 103 109 96 113 111 106 121 123 105 84 116 101 108 93 110 127 94 98 104 112 87 130 95 108 100 112 115 115 98 110 99 126 92 95 82 117 107 101 106 88 85 98 124 105 87 119 111 102 92 135 110 127 122 95 123 89 116 107 88 128 111 110 110 83 97 115 109 123 99 96 106 116 117 122 123 98 95 113 125 114 92 102 98 100 91 98 103 102 123 115 121 116 103 98 98 112 107 100 107 116 120 96 112 109 120 102 90 101 109 117 107 119 118 120 95 97 81 103 97 109 111 109 114 105 98 105 103 96 117 88 111 101 99 103 92 94 101 90 111 100 99 87 115 84 113 120 90 105 116 103 111 113 109 128 111 123 120 93 107 107 104 116 115 110 93 90 98 130 108 102 104 104 117 109 105 105 101 108 104 84 88 106 103 109 111 112 124 97 117 107 107 111 107 94 115 98 94 116 87 95 107 102 106 108 83 98 119 128 96 94 90 117 90 115 110 97 110 97 112 105 100 105 93 89 93 97 103 110 121 115 94 109 92 116 87 105 83 126 115 110 109 111 111 98 99 111 111 109 115 109 115 87 114 91 102 101 103 112 93 109 97 115 114 135 93 108 115 96 89 119 104 94 119 101 100 111 101 117 113 108 104 126 106 120 119 114 106 103 98 118 72 111 107 100 106 109 103 112 111 105 115 114 105 101 90 99 105 109 107 108 117 113 116 112 93 111 85 110 114 112 98 94 116 104 92 125 110 83 97 102 124 101 100 134 110 106 120 104 75 101 94 99 108 97 103 88 107 94 104 95 109 117 92 115 103 108 109 122 108 113 99 102 75 96 117 96 116 90 101 109 120 99 100 95 85 113 91 96 99 107 104 104 105 104 105 110 97 107 104 117 112 114 95 104 89 122 117 100 94 102 101 114 112 96 96 117 108 96 108 99 95 107 128 100 99 114 105 88 105 95 115 108 99 114 106 110 85 105 103 90 101 124 86 100 92 109 108 102 84 109 102 95 97 102 127 106 95 93 108 100 112 128 109 103 95 124 94 112 109 98 123 102 105 93 104 118 110 114 120 111 96 91 108 104 100 102 103 108 108 121 104 107 104 102 108 105 95 101 111 91 102 112 104 114 122 100 110 84 108 103 99 103 108 93 97 111 109 114 112 108 127 93 103 90 116 94 116 109 96 103 101 136 110 115 113 109 112 92 108 98 100 115 103 124 125 117 111 88 99 108 90 108 101 102 110 97 120 101 122 107 114 115 109 113 130 106 116 109 104 113 100 106 120 114 123 115 104 105 92 88 102 92 106 93 116 94 96 102 112 93 97 126 114 127 87 109 93 100 112 116 89 105 103 129 96 95 120 97 102 100 99 100 111 106 107 109 118 107 106 115 104 90 101 104 110 114 122 125 109 122 109 111 104 102 113 103 99 107 115 104 130 107 95 109 105 100 105 100 110 113 100 117 119 115 106 111 129 114 100 110 108 124 114 123 95 103 119 103 98 109 92 103 111 105 90 124 90 114 108 88 122 107 113 119 102 107 118 103 108 102 106 100 108 117 112 103 120 109 115 129 121 106 111 89 118 107 99 99 107 111 103 114 96 95 118 123 115 115 99 96 106 97 134 107 121 116 89 100 120 99 99 93 104 99 107 104 96 99 91 114 108 104 116 95 103 105 106 124 109 99 101 107 91 112 116 132 107 101 90 97 109 105 120 114 106 100 86 100 105 112 99 113 118 107 110 111 99 121 107 127 111 115 114 108 95 92 112 118 140 115 98 103 98 109 111 111 107 112 106 97 117 105 129 90 136 117 93 112 98 102 103 107 101 106 101 108 110 103 103 127 137 83 117 110 112 124 129 96 102 111 99 110 112 103 104 113 99 90 124 110 106 123 112 98 128 103 124 106 113 95 111 101 99 105 116 120 121 115 105 105 122 117 108 122 119 104 114 121 109 100 109 114 92 110 127 115 118 113 102 106 129 127 112 87 111 121 99 122 104 101 95 99 124 103 95 96 126 98 84 102 107 115 96 113 94 111 118 102 104 115 101 99 107 115 134 113 122 106 114 98 96 95 130 110 107 114 111 114 118 108 91 109 111 97 109 110 109 96 104 109 95 102 102 110 113 115 111 113 108 105 106 113 108 119 113 98 126 118 105 111 106 119 115 120 122 102 111 116 98 80 100 105 116 115 115 114 117 100 112 114 117 113 89 89 124 121 100 101 98 120 111 99 118 108 136 123 110 82 96 104 125 106 123 101 111 99 108 107 90 112 107 95 94 98 101 100 84 117 102 91 96 85 101 117 94 109 104 91 107 88 116 122 111 128 105 120 106 103 115 113 100 115 102 124 126 100 101 106 110 118 102 105 143 112 112 114 107 107 128 95 117 105 129 100 82 108 94 110 98 99 108 101 107 97 112 99 108 124 104 101 111 121 99 105 105 130 119 111 111 115 106 90 108 111 102 123 111 117 110 105 110 102 121 109 111 107 105 94 88 104 104 110 96 107 107 96 107 115 99 116 114 109 118 113 133 96 104 104 106 109 103 116 106 95 92 118 111 100 112 109 116 101 104 104 125 109 102 102 114 112 124 103 106 104 98 96 120 111 102 126 118 105 115 103 98 100 103 111 99 116 101 122 113 112 108 123 103 119 92 106 119 114 98 108 110 99 113 119 108 116 96 116 97 112 122 118 112 118 104 121 115 124 109 98 104 88 135 104 87 122 124 115 111 108 104 109 100 99 114 97 134 117 102 111 113 126 93 114 110 97 104 110 106 112 99 109 106 105 107 110 106 110 110 106 128 120 121 109 94 130 95 104 90 118 119 104 114 94 110 121 121 101 117 117 126 112 119 98 108 120 110 127 119 107 114 119 98 132 109 107 113 113 106 98 115 93 89 109 92 104 109 113 108 105 109 138 105 120 106 106 112 103 117 101 90 109 97 93 106 111 116 115 111 101 104 92 108 109 104 107 101 123 128 107 117 100 124 116 109 104 114 111 131 99 107 97 87 98 102 82 101 114 108 117 100 100 109 111 137 116 123 104 101 112 117 91 132 103 103 114 114 103 117 113 106 118 98 108 117 124 107 112 104 99 104 112 119 112 105 114 108 107 128 106 113 115 108 96 108 124 107 112 120 97 110 120 99 118 112 101 122 117 130 109 92 106 117 105 104 109 112 96 103 97 128 124 100 124 105 133 131 137 101 129 101 101 118 114 102 121 116 113 99 107 119 113 117 129 109 116 123 119 120 115 127 105 81 117 109 110 127 113 124 100 83 106 108 120 118 87 108 108 116 123 100 122 100 117 114 101 113 101 117 111 131 106 114 97 109 131 107 112 130 113 114 91 100 129 96 104 115 118 126 104 115 102 118 116 129 101 105 129 107 116 113 104 103 116 100 119 110 130 113 107 108 110 110 110 107 100 130 122 111 117 115 121 122 125 117 119 114 105 100 139 127 109 103 128 104 127 107 102 99 109 100 125 99 100 116 91 108 114 111 112 139 115 125 112 112 118 112 124 112 108 105 118 113 103 118 129 111 138 96 106 128 121 99 106 130 107 124 117 109 139 123 120 116 125 128 123 112 106 140 150 111 109 130 100 101 111 116 113 114 133 111 95 111 116 123 110 105 123 113 133 124 111 116 111 111 104 107 99 118 100 131 110 119 133 124 130 113 116 122 111 128 116 107 109 116 130 123 140 89 111 104 113 123 101 97 107 115 129 112 118 118 115 106 124 107 109 122 107 105 129 99 145 106 101 127 118 113 121 101 136 115 98 132 112 114 113 126 95 94 116 139 110 121 131 97 115 107 110 122 118 113 115 109 112 113 105 113 117 112 119 106 101 94 125 120 137 107 98 106 97 127 121 130 125 111 124 102 115 122 95 110 120 105 114 122 106 96 108 118 126 115 118 101 111 102 125 109 114 134 125 108 110 100 111 110 111 129 123 124 111 122 128 112 125 108 104 131 116 102 101 104 126 105 104 130 116 125 110 119 125 108 118 106 114 114 113 117 102 106 116 109 116 100 103 121 117 123 99 127 113 114 136 109 98 129 107 105 125 109 108 120 119 118 88 111 103 115 112 113 126 118 128 113 127 114 121 99 128 110 116 123 123 102 140 120 109 110 117 102 105 126 85 100 121 125 126 113 122 89 112 130 97 110 121 116 123 117 112 114 111 121 116 109 125 114 108 96 112 96 121 121 118 107 103 116 109 104 113 109 117 102 117 119 121 120 108 105 92 124 109 98 97 110 106 112 132 129 117 108 118 117 111 118 112 123 110 107 107 133 111 107 120 139 110 121 112 111 109 117 108 109 122 115 117 103 109 107 92 112 114 99 127 121 113 112 113 107 125 114 126 114 103 125 114 110 105 124 112 114 103 127 121 116 117 118 129 108 126 103 102 110 121 117 104 117 108 105 113 101 105 114 112 128 112 119 123 116 128 129 122 128 125 125 121 113 117 107 127 126 118 111 110 105 98 130 122 93 120 113 120 101 110 140 124 105 108 111 111 123 119 117 119 113 111 130 104 115 118 99 116 107 114 112 118 100 121 119 120 110 123 112 109 101 111 122 126 118 103 111 108 112 107 110 95 120 107 114 115 111 112 99 90 99 111 109 119 121 119 115 116 114 136 94 115 122 121 130 99 113 117 92 112 111 121 112 100 122 114 116 118 107 137 105 116 122 106 99 98 127 113 112 111 110 117 107 119 113 112 118 98 127 104 121 113 102 106 117 121 115 110 123 118 118 110 106 105 104 107 115 133 106 111 113 113 123 110 115 139 111 134 102 127 132 130 116 114 111 111 112 128 109 121 125 106 118 135 114 121 101 115 116 114 119 115 137 132 106 108 107 104 115 118 111 139 123 117 115 113 106 116 118 111 121 117 136 111 111 108 109 111 122 117 115 126 112 120 111 105 142 127 124 119 104 109 108 123 120 113 127 136 112 101 134 116 120 106 112 114 113 121 112 122 100 117 116 113 124 120 110 111 113 110 96 93 139 97 121 133 113 121 117 134 120 92 125 127 115 100 110 83 111 123 132 110 122 111 117 116 141 116 95 129 119 127 109 105 124 91 127 137 108 113 109 134 109 123 119 117 103 134 109 117 103 113 108 110 119 129 100 119 124 103 107 111 104 122 106 115 115 112 108 116 117 102 120 118 120 123 114 105 120 120 117 118 127 107 114 118 103 91 111 107 111 110 119 111 114 117 105 118 136 110 108 124 118 118 94 110 98 101 113 119 125 129 115 109 119 122 107 106 108 120 113 95 120 123 96 105 107 122 107 106 112 121 121 117 117 122 114 123 113 137 114 114 116 104 114 104 118 96 111 122 125 97 137 138 118 102 100 107 97 108 113 94 121 99 101 98 98 101 113 123 123 102 117 115 110 112 106 106 129 119 98 108 105 107 120 126 104 107 123 106 101 113 107 115 125 114 114 109 139 117 130 114 110 118 115 116 107 108 105 112 97 116 108 126 112 116 121 109 102 120 112 107 108 107 109 106 114 127 114 129 113 109 89 105 107 92 128 113 111 108 115 111 107 116 112 109 124 111 125 133 128 107 137 102 116 104 115 118 126 95 122 109 111 111 119 115 111 124 112 107 126 122 97 114 114 106 99 97 101 100 122 128 116 118 129 136 124 108 123 104 107 126 102 119 117 105 120 130 108 124 142 124 98 116 107 125 113 82 129 117 99 128 99 115 112 116 92 103 114 103 127 103 114 112 103 108 121 106 95 139 133 118 143 110 105 124 117 99 117 109 103 114 117 111 125 102 126 114 108 119 113 123 109 115 110 125 116 132 94 133 87 118 119 123 113 134 107 123 116 117 93 120 116 123 115 121 106 116 106 130 99 104 107 132 121 129 122 106 123 96 111 112 133 122 133 97 118 114 111 98 107 117 120 137 111 111 121 126 107 121 101 99 97 101 111 113 125 144 108 92 123 107 114 119 99 110 115 120 122 130 124 116 119 130 113 138 130 107 103 127 129 118 118 110 100 109 128 122 111 105 117 118 103 114 121 91 135 115 110 102 115 114 108 97 109 118 124 121 123 120 107 135 121 112 105 110 113 114 98 122 117 118 118 131 113 113 135 117 118 104 109 100 119 101 113 134 110 130 114 131 149 120 119 139 113 104 125 126 130 118 117 115 109 119 100 107 121 130 110 124 92 110 137 113 123 127 117 106 118 93 109 111 97 123 135 98 111 125 102 113 120 108 115 117 107 135 109 138 106 123 132 107 118 109 109 112 114 108 132 116 110 113 121 127 111 127 112 107 119 114 98 95 114 133 110 124 105 108 115 101 119 99 124 118 111 119 120 126 107 110 127 120 139 106 121 114 116 120 124 122 105 115 108 135 95 117 104 98 122 109 119 130 97 100 128 104 118 127 96 123 118 119 104 127 107 116 112 119 120 140 102 115 110 94 122 119 131 130 113 116 106 130 121 116 117 122 114 122 95 123 124 93 116 126 106 132 113 115 116 116 111 123 95 129 117 106 99 101 113 108 105 108 136 128 104 137 108 111 111 107 120 106 108 122 125 133 106 102 113 118 115 118 107 119 137 108 104 129 103 115 98 108 120 113 114 112 108 112 133 127 95 123 119 108 107 121 105 125 94 114 97 101 107 107 130 138 109 130 100 113 97 119 119 116 116 129 112 112 112 104 119 112 106 126 121 112 122 92 110 105 116 116 102 124 109 127 128 125 109 114 117 120 103 122 124 124 136 119 100 103 124 112 126 120 125 108 114 113 114 131 107 109 129 106 106 125 97 129 86 115 114 119 126 126 114 104 107 128 110 125 136 101 106 106 134 114 119 144 92 104 106 115 121 123 129 105 126 152 112 136 112 101 116 101 108 113 106 130 106 135 118 114 106 108 110 112 104 100 118 112 116 116 109 91 115 121 132 110 113 139 111 112 115 123 120 99 93 134 115 119 118 123 114 109 118 108 103 119 110 129 117 124 138 95 119 129 123 112 108 110 120 119 118 133 128 127 97 105 123 117 118 118 119 113 106 132 113 96 115 117 113 123 114 91 138 128 115 117 113 106 112 112 106 124 99 112 98 135 115 115 130 149 112 110 108 102 121 102 120 110 123 126 110 89 105 129 117 116 113 109 124 97 126 111 119 137 114 104 114 105 113 125 114 128 123 114 120 122 135 114 115 133 136 113 125 125 130 112 108 110 117 136 120 118 100 122 113 127 110 125 113 123 93 115 109 96 99 119 110 110 115 130 109 111 119 132 124 120 101 122 103 128 112 136 102 94 123 118 133 112 118 119 112 116 132 108 113 120 118 113 111 115 125 120 106 124 118 121 114 104 126 109 132 111 123 106 128 148 125 110 127 127 139 119 114 112 101 116 104 123 139 120 96 117 123 101 129 114 108 105 115 132 122 118 117 114 127 101 115 112 133 110 118 124 129 116 122 136 114 128 125 105 128 100 138 142 115 109 126 117 141 132 117 122 128 144 144 114 112 121 145 113 146 123 136 125 119 132 144 135 145 155 126 144 128 131 126 126 147 122 138 124 130 146 129 156 135 111 122 124 148 134 134 131 141 130 123 135 126 112 128 140 148 112 129 122 150 135 124 130 122 134 137 121 140 117 142 133 133 133 118 130 122 122 103 124 105 113 104 115 108 118 126 130 125 107 131 101 117 100 117 107 98 121 133 103 94 108 103 124 126 131 124 117 112 131 136 123 119 120 115 116 116 131 110 113 110 122 127 101 100 113 111 114 123 117 122 118 127 104 108 118 130 117 143 127 128 120 120 108 121 113 130 110 98 114 117 115 128 106 113 117 109 108 115 115 128 126 132 112 90 109 113 118 98 97 101 100 121 109 110 118 109 116 108 107 119 121 115 112 98 120 130 115 122 105 127 114 118 111 120 102 108 110 112 121 117 102 113 103 109 102 110 112 101 103 97 106 116 92 99 106 124 121 127 115 129 101 125 96 113 122 114 98 111 114 107 116 120 121 120 102 123 103 116 119 112 113 105 104 107 120 142 117 129 119 122 111 110 107 115 111 104 98 106 109 112 110 108 139 113 100 115 115 106 97 125 121 118 103 119 108 105 99 110 100 107 129 113 100 113 125 106 112 128 100 110 115 119 96 123 117 115 108 102 95 120 139 115 111 96 146 118 125 119 110 132 108 122 110 107 119 107 120 129 102 115 115 112 119 112 92 114 117 120 102 101 98 109 124 119 118 107 103 106 117 114 100 119 118 113 103 105 118 106 115 111 109 110 109 119 87 106 100 98 120 112 114 103 123 109 140 116 114 123 116 121 102 124 123 102 114 89 104 112 116 138 116 116 94 99 107 104 106 108 105 125 127 116 121 118 118 119 115 108 115 114 109 127 108 105 108 93 128 119 105 105 107 107 102 97 103 102 114 109 117 106 92 104 118 106 115 98 96 129 119 113 96 103 122 108 128 104 111 110 106 113 110 103 110 109 117 107 109 108 93 110 103 120 114 120 96 102 143 98 139 121 110 100 115 128 105 109 124 102 108 109 105 116 106 120 137 98 102 125 111 109 115 115 111 111 118 108 112 118 119 114 100 114 112 119 112 111 117 128 111 115 115 111 114 109 107 106 108 110 93 123 85 133 108 105 120 101 93 120 111 90 132 120 113 113 98 124 114 119 118 117 118 92 111 107 108 104 102 111 106 110 97 99 119 110 104 123 112 109 102 110 107 88 133 87 116 112 102 105 111 109 129 120 126 109 114 97 127 109 110 109 114 118 94 107 100 142 109 108 103 90 98 122 97 116 98 125 124 104 95 104 109 98 125 114 129 114 99 108 119 105 113 100 100 102 109 108 108 107 103 123 110 111 112 141 122 83 123 106 119 127 110 106 103 110 99 115 121 109 108 96 116 104 107 117 102 109 119 113 106 111 117 120 103 123 118 115 108 102 115 104 113 114 124 104 122 89 107 122 107 88 123 102 100 116 124 108 116 122 127 120 126 107 135 118 125 106 105 109 116 117 124 118 121 94 111 114 96 93 99 110 114 110 111 128 133 125 118 88 103 125 120 120 115 132 119 115 114 100 110 105 116 96 121 106 120 98 109 116 127 104 115 118 118 103 118 122 111 111 115 108 105 119 110 112 98 111 102 126 132 105 114 111 113 123 115 131 113 112 113 123 100 104 111 107 111 107 112 114 102 125 117 116 120 117 110 110 109 107 117 86 107 95 109 122 123 102 112 110 110 110 125 109 133 126 113 112 109 112 110 110 112 98 101 119 110 108 105 105 111 109 120 114 118 117 114 113 110 132 122 100 122 102 113 116 112 122 98 113 96 98 112 115 106 116 112 92 103 108 116 119 121 105 102 108 106 108 103 122 119 100 110 110 103 111 104 102 112 107 108 102 105 127 108 128 117 96 122 119 123 114 99 104 102 122 125 110 100 110 109 117 108 120 98 114 95 95 103 96 99 120 98 110 113 104 98 104 89 114 101 106 107 114 103 100 99 112 110 107 121 84 112 112 111 101 122 91 120 99 134 113 87 117 110 106 107 115 90 120 98 112 109 109 108 99 110 128 102 121 118 134 107 121 110 105 108 111 114 125 113 105 88 127 118 124 103 116 115 124 108 105 135 126 121 133 116 101 116 107 97 92 118 104 112 131 118 129 125 93 127 88 113 99 104 113 82 125 117 108 114 102 115 127 110 112 106 105 109 122 116 99 116 120 125 106 117 115 106 107 112 114 104 111 131 112 105 99 138 120 103 97 105 95 123 107 113 119 108 108 126 91 111 105 110 99 101 140 112 100 87 107 129 109 111 107 100 123 91 115 113 101 95 117 122 114 127 112 98 125 116 109 113 103 112 104 101 111 112 120 108 104 114 127 117 100 112 116 106 118 111 115 98 123 100 110 130 125 100 117 96 103 115 119 110 113 95 108 120 105 112 94 125 112 118 128 111 104 107 132 117 124 87 108 122 103 98 116 120 115 108 111 115 119 87 110 79 92 109 108 109 115 131 119 124 111 117 96 106 128 97 104 119 87 94 98 115 125 126 106 108 102 107 102 126 115 113 118 103 131 79 105 90 110 93 119 100 104 113 114 102 121 127 123 122 114 127 103 123 115 129 124 124 120 114 110 126 103 116 119 86 116 101 99 107 128 134 112 114 125 103 107 105 108 119 112 114 108 121 98 108 104 126 106 108 91 109 107 108 97 143 118 113 100 108 123 122 106 121 112 104 105 101 103 113 123 105 115 116 101 100 109 100 118 115 97 133 98 95 99 116 109 106 126 127 113 112 102 103 128 124 115 116 113 129 116 124 118 110 89 115 115 104 101 127 127 118 108 111 104 120 112 111 116 130 104 106 125 120 123 116 101 102 108 113 103 109 130 114 101 100 117 107 118 122 110 128 96 97 123 124 107 108 102 118 125 114 117 106 113 95 117 105 135 124 103 96 103 111 119 90 97 112 113 124 116 118 109 104 119 85 124 118 123 108 115 113 110 116 122 130 116 104 103 118 101 114 126 104 101 120 111 111 117 107 101 118 105 114 120 129 117 103 116 100 109 102 120 115 124 110 117 110 102 103 107 128 109 108 106 111 104 127 126 121 121 120 124 106 109 114 115 136 121 97 94 103 111 108 104 111 152 114 101 86 113 107 110 108 111 104 125 105 115 110 109 98 108 108 110 111 106 104 116 94 113 116 109 101 108 105 99 104 104 88 103 120 105 115 104 115 116 119 102 115 100 121 119 118 107 108 95 113 109 128 124 112 120 101 125 113 111 127 106 109 130 130 115 119 113 128 121 113 107 110 115 92 108 119 114 104 120 120 113 113 118 131 106 108 127 113 111 107 94 105 102 92 125 109 125 99 110 119 102 109 118 114 114 106 113 115 116 107 133 90 117 113 115 117 118 106 113 95 121 121 94 109 107 125 126 123 100 125 109 108 123 98 134 118 97 92 125 107 112 96 113 104 114 108 119 114 81 95 106 119 111 99 111 118 108 116 117 122 119 117 93 112 101 102 108 127 109 131 101 100 111 143 106 116 114 108 110 115 105 104 112 119 129 128 112 116 116 117 122 125 104 102 106 120 100 110 97 111 115 111 133 112 118 118 103 136 114 113 96 100 123 113 96 128 110 106 106 117 117 125 131 114 105 105 102 135 117 88 104 105 96 124 101 120 110 115 101 106 118 110 103 110 113 142 118 103 121 123 111 101 101 103 116 119 96 140 119 104 112 127 113 111 101 107 116 123 112 122 121 113 113 112 117 121 112 132 118 121 132 125 110 124 114 115 131 101 108 125 125 113 130 92 126 100 138 102 110 100 94 108 129 133 129 128 97 121 108 116 132 107 126 117 116 112 119 129 107 121 127 134 129 128 106 111 127 107 133 123 117 124 114 113 120 132 108 116 103 113 140 114 134 122 110 101 122 133 135 114 120 122 121 117 122 118 115 104 115 143 113 122 109 113 100 91 127 107 113 132 126 122 99 123 107 116 112 120 107 95 107 123 108 118 110 117 124 114 106 114 100 108 127 100 114 123 126 104 122 114 108 131 116 118 104 116 125 109 112 110 142 111 100 103 125 130 111 113 118 112 109 99 113 93 109 112 107 102 123 103 128 112 118 127 107 95 127 121 123 98 110 115 116 110 127 104 98 105 107 122 95 115 110 113 112 116 108 110 116 130 110 113 120 112 122 116 99 110 128 104 130 125 105 107 108 117 121 120 132 117 107 101 110 105 88 125 112 111 95 132 108 114 111 129 124 126 101 107 112 110 123 126 127 112 113 123 130 126 132 109 114 116 111 116 116 113 100 114 113 109 124 115 120 98 107 127 104 142 126 115 128 110 113 113 118 113 119 94 105 115 99 120 113 112 111 113 86 118 97 125 108 123 114 121 97 129 102 113 125 101 106 93 96 115 105 118 112 126 100 105 104 126 115 112 116 127 120 101 120 119 120 110 123 93 105 107 102 122 108 107 112 112 97 114 104 118 108 105 133 110 110 108 111 107 97 109 106 122 116 89 93 110 111 122 111 127 109 119 111 115 136 93 109 123 130 127 115 110 125 127 116 114 127 116 102 116 109 113 119 123 111 101 115 102 117 115 98 110 107 98 115 99 112 99 98 123 96 118 112 111 128 104 110 118 99 113 114 121 91 119 111 79 124 113 114 112 107 121 100 110 103 124 116 104 131 100 120 115 102 120 101 100 114 108 119 114 105 109 103 100 119 102 108 123 118 122 115 116 104 136 130 123 101 105 117 104 115 113 113 95 138 109 93 104 106 104 112 97 127 106 114 114 111 118 101 112 125 111 106 115 119 122 99 106 118 93 114 133 98 103 107 112 125 129 119 126 107 124 119 116 102 100 103 120 103 126 117 104 105 80 113 96 106 112 119 114 128 114 115 113 128 103 107 109 101 137 102 97 108 94 103 102 120 103 103 90 128 102 121 120 117 116 118 115 107 119 118 98 113 103 110 116 106 114 116 117 110 122 122 125 109 139 103 109 107 88 118 121 108 120 111 113 104 74 94 121 96 107 134 94 108 116 121 98 116 117 111 96 116 119 113 108 111 114 115 104 110 103 120 121 101 125 111 117 121 102 110 109 121 113 105 102 110 106 123 118 118 89 111 118 103 112 114 111 113 101 118 97 113 100 112 121 112 120 117 125 122 123 127 112 111 110 121 108 104 107 116 108 121 111 108 104 93 105 129 124 91 111 109 128 121 115 129 116 112 119 125 125 120 93 127 101 114 111 113 117 123 104 108 100 108 119 111 113 119 111 100 109 101 113 121 118 118 102 110 109 106 99 105 113 115 124 110 104 123 108 108 93 100 126 102 108 105 104 132 91 126 105 109 129 99 94 121 103 110 132 102 109 123 127 130 116 99 102 109 118 97 90 129 112 117 113 125 116 98 119 118 84 126 96 122 115 95 122 103 111 110 107 118 120 130 106 101 109 102 124 103 122 103 105 100 120 110 96 104 112 121 122 131 96 108 101 91 118 90 106 112 111 101 118 105 109 114 102 125 112 121 104 114 109 104 106 127 102 125 105 107 105 104 105 115 91 106 118 111 111 85 125 108 116 113 106 111 124 116 102 105 96 99 136 113 118 129 109 98 122 118 115 127 95 107 100 113 107 124 101 106 107 106 118 130 91 81 117 109 128 121 114 108 125 114 129 114 99 106 125 131 104 116 103 126 123 129 90 115 123 106 104 100 115 102 112 102 110 115 123 106 114 113 124 126 127 112 120 134 106 110 119 109 102 120 113 111 110 123 110 108 115 120 117 121 109 106 97 109 109 105 104 117 107 131 112 112 110 102 117 110 123 108 95 107 107 107 119 95 97 126 101 103 110 113 115 104 115 123 121 114 93 101 114 100 104 122 114 111 117 106 104 101 111 102 115 105 120 105 123 111 117 97 130 108 115 112 100 97 109 147 100 125 125 129 105 120 110 129 115 124 107 112 118 116 116 114 109 105 117 120 96 121 103 88 126 123 116 99 104 125 104 87 108 115 109 108 110 115 114 131 113 115 110 114 116 105 103 109 116 119 119 117 100 113 118 121 110 114 119 113 126 132 111 99 114 117 103 113 128 115 115 145 110 113 108 112 125 97 113 98 119 108 96 113 115 117 113 113 118 110 99 126 95 108 109 116 119 113 121 103 132 125 111 107 110 123 118 140 119 110 99 107 124 117 95 129 114 91 110 105 105 123 116 118 124 114 98 115 115 126 132 111 109 103 127 119 120 124 110 119 111 122 108 101 133 113 119 117 125 102 119 118 143 119 106 120 118 113 124 121 122 114 122 116 128 120 120 121 121 123 107 103 111 90 120 108 120 106 111 115 105 95 137 120 121 108 140 118 131 102 113 121 130 111 117 116 118 104 125 107 109 115 118 111 103 102 107 122 116 126 137 106 134 121 123 125 110 109 124 101 109 124 116 113 115 110 118 104 107 102 109 118 113 111 103 101 116 95 107 100 120 113 121 112 129 107 113 103 119 113 121 120 128 134 114 93 118 127 99 128 121 116 120 99 124 122 126 102 99 131 116 122 121 114 102 122 108 105 120 100 117 116 114 105 115 103 119 118 108 123 88 110 129 124 123 111 97 111 135 123 122 120 100 114 113 126 107 110 127 117 99 105 119 117 110 122 115 117 113 127 121 124 118 111 110 115 141 110 125 122 101 132 124 114 100 121 116 125 128 111 136 107 127 124 113 104 118 123 110 116 86 119 101 107 105 112 122 120 113 111 106 132 111 137 105 108 118 116 111 132 114 118 127 124 121 127 102 146 102 105 110 128 98 122 128 100 117 110 111 112 117 109 102 118 127 116 139 116 112 114 121 117 132 87 122 141 123 108 103 102 104 129 125 104 122 131 115 142 123 93 136 132 112 107 116 106 117 127 102 106 99 109 127 121 112 114 139 120 120 111 128 132 113 124 108 114 131 107 118 115 109 121 121 108 136 114 133 120 115 95 128 115 124 97 103 111 92 113 109 108 146 116 112 121 115 106 121 124 111 112 121 124 121 125 113 121 119 116 108 140 121 120 134 112 109 134 92 106 133 104 129 126 121 118 108 102 128 125 129 117 107 95 99 120 112 135 104 116 121 128 110 112 110 113 121 110 111 110 112 96 122 122 116 118 117 127 118 121 116 101 118 114 115 117 116 96 119 118 129 106 99 123 114 110 104 121 115 97 125 116 112 108 108 128 129 112 123 129 129 107 119 113 107 120 122 132 120 114 99 113 100 111 96 112 112 124 125 113 97 100 120 108 123 114 110 93 124 107 126 124 127 131 110 107 114 124 126 130 111 108 128 111 110 120 114 105 113 102 118 120 123 128 119 97 129 116 115 119 91 117 142 98 126 100 92 102 128 112 113 98 104 129 119 125 138 110 102 139 113 113 111 99 136 114 137 89 101 107 132 103 111 132 93 119 122 119 134 115 119 116 112 127 112 101 100 118 133 102 138 106 109 110 104 119 100 108 107 107 124 126 139 127 97 119 97 136 122 129 109 125 103 137 125 103 138 115 127 117 115 96 115 105 118 118 113 113 114 121 116 102 109 101 106 118 123 119 158 119 125 121 128 108 111 97 117 102 111 105 107 115 102 105 152 105 124 121 117 121 107 131 114 123 114 106 124 115 140 119 123 121 139 124 111 133 98 113 115 129 115 128 118 113 119 121 117 99 120 119 109 113 116 114 112 111 114 128 110 118 117 120 117 114 111 116 121 118 148 114 116 139 140 147 125 107 126 123 115 117 108 106 105 118 114 124 102 120 132 97 119 99 114 116 126 111 113 139 112 122 126 129 100 124 124 97 126 142 113 120 132 127 123 111 119 115 128 120 98 111 114 119 132 128 121 117 140 123 122 118 113 126 112 127 108 115 112 135 106 122 128 102 110 102 107 124 116 137 130 104 115 118 136 107 108 108 130 111 137 121 109 103 112 123 102 137 110 101 122 115 125 117 133 142 146 116 135 123 128 121 122 111 121 129 115 116 127 142 118 114 127 117 138 115 118 121 91 112 103 115 117 127 105 131 135 122 107 119 116 118 115 126 125 122 102 138 123 120 109 114 111 121 140 121 111 117 116 113 123 120 122 127 112 115 134 120 114 114 123 118 112 114 109 124 119 133 102 104 121 116 112 110 122 111 119 117 110 96 123 105 105 125 103 127 132 131 109 105 117 118 104 131 102 105 114 126 101 107 113 106 121 123 137 94 121 128 100 111 116 111 108 128 91 121 110 116 120 131 122 129 137 119 91 133 116 139 111 124 122 120 112 109 119 123 110 100 100 107 126 111 122 119 148 93 99 116 120 116 122 119 124 108 110 119 105 118 117 117 100 89 123 105 107 118 120 125 106 119 123 126 97 115 125 107 118 116 117 119 109 98 129 119 108 140 105 113 120 111 123 121 91 105 114 102 113 110 111 97 131 98 120 106 98 105 114 100 105 119 119 112 113 127 119 112 107 97 130 112 103 120 129 133 108 119 112 116 140 123 100 112 122 118 110 136 118 122 124 111 111 104 127 120 107 89 107 122 123 105 126 119 107 112 123 111 131 117 106 109 127 125 121 113 107 116 113 106 124 110 111 105 98 116 127 104 101 118 123 117 109 115 93 112 116 102 125 116 97 101 120 129 114 114 124 110 119 107 114 120 108 111 120 128 108 114 121 121 120 94 137 103 102 116 120 137 120 125 106 113 115 120 113 125 97 135 117 137 117 115 117 98 110 119 117 127 123 107 110 119 119 120 109 109 118 118 129 112 122 111 104 109 118 117 101 133 111 121 112 97 113 102 99 104 117 103 122 114 110 97 124 123 94 113 128 105 134 116 113 110 119 117 121 125 100 104 126 127 106 100 121 110 114 107 114 108 114 111 96 111 122 110 124 113 129 121 123 122 115 94 114 117 130 109 105 122 105 88 107 105 119 106 121 106 103 119 116 99 108 93 134 117 128 114 115 103 98 121 111 139 115 115 129 101 112 108 116 124 102 112 118 113 113 129 123 133 138 115 106 102 85 115 129 113 109 101 126 118 102 120 133 110 104 109 112 138 127 114 94 123 121 124 117 130 117 117 107 117 137 117 127 109 131 116 133 114 89 114 144 118 119 90 128 107 109 124 106 104 115 109 97 135 103 95 112 106 117 122 115 129 121 102 108 108 107 112 98 113 111 125 121 108 99 108 144 112 110 110 123 102 110 131 111 100 102 118 122 113 125 103 96 106 111 107 125 108 97 116 111 103 98 116 130 103 107 118 110 108 129 100 129 91 106 121 112 112 105 114 105 113 107 115 94 103 100 112 105 115 123 113 111 101 111 108 128 110 131 127 126 107 97 126 111 109 126 108 124 105 111 95 127 106 121 100 112 113 116 97 129 128 129 90 128 115 111 117 136 110 128 118 102 109 128 108 117 109 122 112 96 119 120 112 107 128 121 112 118 109 114 114 135 119 122 132 108 117 110 109 103 116 121 107 119 103 101 115 131 126 111 103 122 103 125 110 119 124 84 109 128 108 114 115 99 121 100 100 110 127 98 98 117 103 113 101 125 102 93 122 120 105 129 112 96 101 117 100 106 113 123 118 103 117 102 108 101 111 135 106 123 106 119 125 111 120 136 110 107 131 117 110 106 119 110 122 117 123 121 121 95 113 118 99 131 109 107 109 121 110 102 121 112 114 134 115 118 94 121 109 98 114 105 114 112 119 84 113 102 119 118 117 107 120 104 133 112 82 110 103 93 107 108 89 101 111 109 120 127 107 124 117 101 132 105 126 112 101 106 101 114 109 110 110 124 130 115 109 121 115 118 118 97 119 114 103 112 112 93 128 119 118 108 97 106 100 116 120 105 120 116 108 99 115 121 111 111 105 128 107 103 111 124 126 120 77 102 108 97 102 103 108 116 99 101 124 119 99 101 108 112 94 119 105 105 104 114 107 94 96 102 128 97 118 110 107 122 112 110 124 101 111 105 116 125 109 122 96 128 98 105 119 106 112 114 113 104 108 122 108 118 129 112 113 87 127 106 127 93 103 104 118 124 117 91 101 105 114 104 109 129 112 129 106 113 85 119 112 111 99 117 127 104 88 128 109 97 113 114 120 113 97 118 104 119 117 114 107 112 114 111 113 108 104 106 100 97 108 113 106 103 113 98 108 123 106 120 119 113 96 101 128 104 100 109 99 102 110 90 108 119 111 133 115 108 96 109 113 110 103 107 114 113 105 118 121 113 95 108 111 118 114 94 114 115 125 114 104 110 106 108 111 93 123 100 111 114 112 113 93 115 126 120 94 106 102 114 104 109 97 109 115 109 120 120 101 114 105 108 118 108 114 129 109 125 95 112 126 116 117 123 107 108 111 123 125 88 135 105 95 103 124 121 111 95 116 118 90 105 109 126 104 103 116 108 91 116 112 113 114 111 106 120 124 131 111 111 123 120 114 94 134 101 105 102 110 120 112 90 90 113 93 97 85 110 110 88 91 111 119 107 98 102 114 127 85 111 120 103 108 116 112 102 120 107 106 107 106 105 112 108 113 110 111 106 109 119 123 101 119 112 120 104 104 111 103 104 105 111 91 119 112 94 101 103 104 125 105 102 95 106 105 130 85 129 125 101 130 105 107 121 104 128 121 90 122 121 122 109 96 104 111 127 110 122 121 127 104 99 99 108 110 115 99 113 100 101 116 120 99 125 103 79 114 117 109 115 135 109 84 97 103 108 130 108 111 124 115 125 94 104 106 119 121 112 89 94 121 117 91 129 100 116 107 98 110 104 104 108 102 113 119 99 114 95 105 102 108 110 115 113 118 114 95 104 104 112 127 112 112 135 101 113 103 108 101 93 126 113 107 109 109 114 115 104 104 126 106 87 107 134 104 98 96 120 103 97 102 105 104 109 112 104 114 109 103 113 113 125 106 102 116 130 129 107 105 120 92 111 112 106 113 110 114 102 108 109 99 92 107 98 109 122 95 90 100 105 99 105 110 116 101 93 104 97 108 110 97 111 126 106 98 102 129 117 108 94 104 117 111 118 90 102 95 105 95 111 107 94 89 92</counts>
			</dataPoints>
		</scan>
	</xrdMeasurement>
</xrdMeasurements>