File: data/XRD/_misc/old/XG-650C/W6823-1A_absolute_2th-om_10-130deg_PIXscan_56min_3.xrdml
<xrdMeasurements xmlns="http://www.xrdml.com/XRDMeasurement/2.1" xmlns:xsi="http://www.w3.org/2001/XMLSchema-instance" xsi:schemaLocation="http://www.xrdml.com/XRDMeasurement/2.1 http://www.xrdml.com/XRDMeasurement/2.1/XRDMeasurement.xsd" status="Completed">
	<comment>
		<entry>Configuration=Factory configuration, Owner=User-1, Creation date=7/8/2013 4:01:53 PM</entry>
		<entry>Goniometer=PW3050/65 (Theta/2Theta); Minimum step size 2Theta:0.0001; Minimum step size Omega:0.0001</entry>
		<entry>Sample stage=MRD Cradle; Minimum step size Phi:0.01; Minimum step size Chi:0.01; Minimum step size X:0.01; Minimum step size Y:0.01; Minimum step size Z:0.001</entry>
		<entry>Diffractometer system=XPERT-PRO</entry>
		<entry>Measurement program=C:\PANalytical\Data Collector\Programs\Jorrit\2thom\_absolute_2th-om_10-130deg_PIXscan_56min.xrdmp, Identifier={15BCCF57-2807-42BD-B5B9-ECC0B3DC9284}</entry>
		<entry>Batch program=C:\PANalytical\Data Collector\Programs\SimonL\batch4x_2thom_10-130°_z9.1_x0,10,20,30_y0_57min.xrdmp, Identifier={EED9823A-2BEB-424C-9252-345C4EF2834A}</entry>
	</comment>
	<sample type="To be analyzed">
		<id></id>
		<name></name>
		<preparedBy></preparedBy>
	</sample>
	<xrdMeasurement measurementType="Scan" status="Completed" sampleMode="Reflection">
		<comment>
			<entry>_absolute_2th-om_10-130deg_PIXscan_56min</entry>
			<entry>PHD Lower Level = 4.83 (keV), PHD Upper Level = 11.27 (keV)</entry>
		</comment>
		<usedWavelength intended="K-Alpha 1">
			<kAlpha1 unit="Angstrom">1.5405980</kAlpha1>
			<kAlpha2 unit="Angstrom">1.5444260</kAlpha2>
			<kBeta unit="Angstrom">1.3922500</kBeta>
			<ratioKAlpha2KAlpha1>0.5000</ratioKAlpha2KAlpha1>
		</usedWavelength>
		<incidentBeamPath>
			<radius unit="mm">320.00</radius>
			<xRayTube id="1010048" name="Empyrean Cu LFF HR (9430 033 7310x) DK442154">
				<tension unit="kV">40.0</tension>
				<current unit="mA">40.0</current>
				<anodeMaterial>Cu</anodeMaterial>
				<focus type="Line">
					<length unit="mm">12.0</length>
					<width unit="mm">0.4</width>
					<takeOffAngle unit="deg">4.2</takeOffAngle>
				</focus>
			</xRayTube>
			<xRayMirror id="27010001" name="Inc. Beam Cu W/Si (parabolic MRD)" hybrid="false">
				<crystal type="Graded" shape="Parabolic">W/Si</crystal>
				<acceptanceAngle unit="deg">0.800</acceptanceAngle>
				<length unit="mm">60.0</length>
			</xRayMirror>
			<sollerSlit id="21010002" name="Soller slits 0.04 rad.">
				<opening unit="rad">0.0400</opening>
			</sollerSlit>
			<mask id="22030007" name="Fixed mask 2 mm">
				<distanceToSample unit="mm">220.00</distanceToSample>
				<width unit="mm">2.00</width>
			</mask>
			<divergenceSlit id="22010007" name="Fixed slit 1/8°" xsi:type="fixedDivergenceSlitType">
				<distanceToSample unit="mm">220.00</distanceToSample>
				<height unit="mm">0.19</height>
			</divergenceSlit>
		</incidentBeamPath>
		<diffractedBeamPath>
			<radius unit="mm">320.00</radius>
			<sollerSlit id="21010002" name="Soller slits 0.04 rad.">
				<opening unit="rad">0.0400</opening>
			</sollerSlit>
			<receivingSlit id="22010001" name="Fixed slit 4°">
				<height unit="mm">5.88</height>
			</receivingSlit>
			<detector id="7010017" name="PIXcel3D 1x1 detector" xsi:type="areaDetectorType">
				<phd unit="%">
					<lowerLevel>30.0</lowerLevel>
					<upperLevel>70.0</upperLevel>
				</phd>
				<mode>Scanning</mode>
				<activeChannelsEquatorial>255</activeChannelsEquatorial>
				<activeChannelsAxial>255</activeChannelsAxial>
				<pitchEquatorial unit="mm">0.05500</pitchEquatorial>
				<pitchAxial unit="mm">0.05500</pitchAxial>
				<readOutPeriod unit="seconds">0.135</readOutPeriod>
			</detector>
		</diffractedBeamPath>
		<scan appendNumber="0" mode="Continuous" scanAxis="2Theta-Omega" status="Completed">
			<header>
				<startTimeStamp>2024-08-29T20:10:28+02:00</startTimeStamp>
				<endTimeStamp>2024-08-29T21:06:34+02:00</endTimeStamp>
				<author>
					<name>PRO-MRD</name>
				</author>
				<source>
					<applicationSoftware version="6.1b">Data Collector</applicationSoftware>
					<instrumentControlSoftware version="7.0E 20130304">XPERT-PRO</instrumentControlSoftware>
					<instrumentID>0000000011142674</instrumentID>
				</source>
			</header>
			<dataPoints>
				<positions axis="2Theta" unit="deg">
					<startPosition>9.99826193</startPosition>
					<endPosition>129.99755682</endPosition>
				</positions>
				<positions axis="Omega" unit="deg">
					<startPosition>4.99913096</startPosition>
					<endPosition>64.99877841</endPosition>
				</positions>
				<positions axis="Phi" unit="deg">
					<commonPosition>0.00</commonPosition>
				</positions>
				<positions axis="Chi" unit="deg">
					<commonPosition>0.00</commonPosition>
				</positions>
				<positions axis="X" unit="mm">
					<commonPosition>20.00</commonPosition>
				</positions>
				<positions axis="Y" unit="mm">
					<commonPosition>0.00</commonPosition>
				</positions>
				<positions axis="Z" unit="mm">
					<commonPosition>9.100</commonPosition>
				</positions>
				<commonCountingTime unit="seconds">32.895</commonCountingTime>
				<counts 221 188 203 174 181 227 204 194 186 223 215 191 219 204 174 204 204 184 196 192 230 209 175 184 182 207 210 228 182 184 217 206 216 188 197 210 198 225 191 208 213 193 214 207 205 192 226 179 203 201 205 183 219 209 203 213 207 229 193 213 207 215 213 187 182 209 184 186 195 188 211 183 192 204 209 185 190 202 208 211 204 182 196 182 187 180 184 201 195 188 178 191 167 195 195 193 180 178 193 215 209 195 176 212 185 198 212 195 215 183 181 190 154 224 192 184 193 220 197 162 188 214 186 202 206 195 205 205 167 171 193 178 185 172 190 200 208 175 193 202 175 181 179 176 193 208 187 180 154 165 184 197 171 181 162 172 188 197 188 187 179 191 209 203 182 177 194 181 201 202 187 170 178 202 204 188 187 220 190 186 183 177 181 167 185 187 195 190 179 191 183 174 192 179 185 202 205 167 192 210 186 172 166 198 178 178 167 195 185 191 208 208 176 175 167 154 175 183 196 181 193 171 171 172 141 175 199 177 153 150 177 176 184 194 181 194 191 192 185 177 170 186 161 191 172 164 160 176 178 184 193 168 192 179 176 165 184 167 167 182 173 174 171 171 199 164 170 173 173 195 178 189 177 175 179 175 186 156 170 188 171 170 178 175 159 175 186 156 162 167 181 183 164 157 186 186 164 178 156 182 165 182 158 163 168 164 180 151 173 173 178 159 178 166 169 175 189 171 160 167 134 165 175 181 178 164 173 171 166 168 163 188 174 160 153 172 155 153 173 174 168 174 177 163 173 180 152 145 190 187 176 181 163 173 142 160 170 165 178 184 141 141 155 154 154 168 163 171 184 164 166 154 150 169 141 179 164 162 151 171 169 150 162 158 178 169 194 149 156 170 175 172 166 174 171 165 175 154 161 152 149 149 172 143 176 161 158 145 162 165 147 191 161 166 174 156 165 180 168 155 157 168 146 172 153 161 172 176 153 164 176 164 167 150 175 170 167 149 160 155 162 167 176 151 175 137 165 148 193 182 149 134 137 181 177 153 152 151 169 158 168 171 171 154 148 170 174 150 166 166 152 160 169 153 132 155 159 164 162 158 154 154 157 171 147 152 158 171 174 159 161 163 134 142 169 153 181 167 145 140 146 173 161 167 150 164 143 150 164 156 156 181 185 118 167 177 178 136 157 150 180 136 153 157 151 133 141 141 143 154 160 156 161 171 156 160 140 151 170 181 146 145 147 149 184 147 158 166 152 162 168 144 180 147 148 155 168 167 152 147 150 160 129 154 179 153 141 168 190 157 153 159 180 138 145 155 149 153 157 156 135 164 177 158 155 167 157 172 155 157 170 148 155 156 168 163 163 148 154 154 130 158 127 143 144 165 136 157 131 153 148 165 160 165 142 141 152 159 125 134 155 142 155 155 141 165 176 142 158 144 151 152 157 154 154 160 136 127 139 168 157 173 137 168 155 153 132 150 154 149 138 131 172 162 133 137 180 157 159 163 154 138 139 168 147 143 153 174 161 134 159 148 143 156 168 157 146 153 158 161 142 168 149 152 140 150 166 146 139 168 170 134 132 138 137 159 154 160 151 153 152 143 159 154 149 149 158 132 164 137 149 135 149 141 144 160 156 165 158 146 171 149 141 150 153 145 152 153 142 158 150 145 158 126 152 149 137 147 136 149 142 169 148 141 150 162 159 137 162 144 165 149 136 152 150 136 136 129 134 157 138 159 144 136 142 138 165 148 139 162 131 148 163 158 150 165 149 161 147 143 174 151 161 152 160 150 163 145 133 167 144 146 135 135 143 133 150 129 153 149 178 162 147 169 138 145 146 147 133 152 139 130 145 158 143 136 164 127 178 141 139 159 139 150 126 126 135 144 156 123 160 157 145 163 152 151 162 130 136 137 174 138 144 157 143 169 153 137 164 126 163 168 133 152 126 141 141 156 151 149 148 134 152 131 152 146 152 152 143 143 151 155 144 150 142 174 164 142 161 154 156 150 160 158 153 136 162 147 164 172 170 156 156 164 153 126 170 167 136 136 133 150 165 150 154 138 145 157 134 134 143 151 140 159 148 138 139 145 155 137 154 166 145 149 163 145 141 153 160 156 170 152 149 169 155 155 141 148 154 151 155 134 151 149 125 169 157 141 143 149 149 155 171 134 152 139 177 158 138 148 154 137 156 162 158 131 172 153 154 148 163 167 155 144 158 156 140 174 139 156 151 148 154 148 144 133 153 145 152 141 175 153 145 157 136 145 156 134 159 159 162 169 173 164 158 133 145 147 154 185 129 156 157 145 169 159 166 148 139 165 153 176 142 156 134 148 132 144 149 150 150 168 152 166 156 171 176 149 140 160 147 150 181 160 157 171 136 165 151 143 170 163 153 168 172 161 167 131 163 161 183 147 166 149 169 162 137 167 139 139 161 157 158 162 146 149 146 166 161 171 166 168 145 168 186 161 144 153 163 163 149 141 147 181 169 137 163 164 163 172 146 186 162 162 179 163 165 162 151 149 177 161 186 167 180 158 189 176 166 156 153 152 163 165 156 147 167 142 168 169 164 156 156 151 157 167 169 172 141 161 161 159 159 138 157 165 171 159 171 172 139 156 157 172 160 150 146 161 163 155 147 166 149 149 154 185 163 172 173 155 149 139 158 177 161 152 138 181 147 157 149 176 165 150 144 175 190 156 169 153 165 149 170 161 164 180 157 147 154 167 154 171 152 166 156 158 162 151 160 157 168 148 144 165 146 165 152 162 166 172 182 155 180 148 178 187 170 185 161 138 182 174 169 159 178 157 163 176 138 142 148 152 156 170 168 177 162 173 180 154 166 143 174 178 155 164 183 160 169 180 173 139 161 144 167 178 152 157 164 168 178 191 156 177 156 174 184 171 150 153 173 134 185 172 180 161 159 169 150 158 175 171 167 166 148 159 185 146 165 139 172 145 152 172 158 166 167 200 151 154 162 182 153 152 143 166 156 174 158 142 156 155 189 169 165 154 158 163 153 170 158 147 170 161 170 161 159 156 184 167 164 164 163 165 139 143 163 180 159 173 180 168 180 172 159 164 153 166 157 187 168 152 150 166 146 168 159 155 159 159 188 147 176 149 153 147 148 152 168 137 168 151 157 164 153 166 147 154 146 152 161 162 153 157 146 162 148 151 163 157 156 161 145 144 163 190 156 145 141 167 160 185 172 162 169 153 162 121 146 159 178 154 156 162 153 170 161 135 161 164 147 163 149 181 156 153 171 170 144 157 150 166 155 122 141 174 157 141 165 151 161 144 143 157 135 130 156 166 159 169 147 150 142 148 161 147 178 164 156 142 149 148 146 153 162 147 164 136 147 161 146 147 158 170 147 167 153 149 174 147 161 159 169 144 169 175 158 138 136 165 137 159 165 140 160 125 146 155 147 132 163 162 160 145 173 149 135 158 156 160 143 151 151 152 188 153 148 171 133 146 154 138 150 142 155 130 138 146 174 145 147 158 124 154 139 145 156 150 142 138 149 163 155 147 150 134 138 153 160 140 147 150 135 161 176 144 155 132 125 156 141 145 159 155 138 159 150 157 168 143 137 121 113 152 148 138 119 153 140 115 152 149 146 162 136 142 174 151 145 140 144 154 117 144 131 133 144 157 150 124 149 142 168 152 141 161 135 160 134 179 140 172 153 129 145 153 133 160 152 139 139 137 136 149 142 144 152 166 156 151 136 139 123 122 135 185 157 152 145 134 130 129 150 161 146 157 160 150 135 167 139 139 152 158 154 160 145 146 138 153 132 131 123 147 160 137 147 145 149 142 150 134 128 126 132 124 149 114 137 129 117 161 136 132 145 138 155 135 159 136 136 159 150 143 133 137 136 146 132 140 136 152 150 150 144 139 141 125 140 133 156 135 157 145 156 142 144 139 137 133 120 116 145 128 141 157 149 120 160 132 148 128 109 144 148 116 135 133 145 117 156 151 141 132 134 127 141 132 149 144 154 140 137 123 135 119 136 135 136 106 121 162 145 144 116 136 144 129 139 135 116 133 134 141 147 128 151 110 134 123 159 138 124 141 137 130 131 137 131 126 136 124 125 131 156 137 152 128 130 115 135 137 142 137 151 143 142 150 137 133 144 139 143 152 120 136 132 122 120 122 138 131 148 137 134 127 125 131 144 139 135 126 114 135 139 138 125 132 149 139 142 140 140 114 137 129 140 123 115 140 156 147 128 126 127 149 149 129 146 146 125 143 140 139 122 141 124 153 115 118 127 127 120 122 128 135 152 138 144 143 115 129 127 133 134 129 133 116 115 118 117 136 115 145 129 110 132 142 133 124 132 114 115 137 143 147 128 122 111 110 136 131 124 135 141 133 100 107 143 142 134 120 138 139 124 139 123 131 113 104 128 122 120 122 127 131 131 125 124 119 143 145 128 125 126 115 131 126 131 139 139 127 123 133 141 117 126 148 139 128 130 128 129 136 119 136 116 137 132 136 138 114 121 123 126 116 134 138 154 152 127 142 108 130 121 118 143 109 124 123 136 130 113 133 106 118 111 137 126 112 120 108 121 109 120 118 125 152 118 135 115 143 120 112 123 129 128 123 112 127 122 111 115 119 106 116 115 140 100 125 121 132 109 116 137 113 116 130 107 130 113 119 132 116 152 123 137 124 134 114 126 135 133 103 123 131 136 120 116 126 121 117 120 124 128 120 123 118 111 91 121 129 131 145 123 104 109 140 129 111 119 116 93 115 121 131 118 122 138 111 121 115 141 128 123 118 120 142 130 110 138 116 123 128 131 131 145 109 118 124 107 112 124 120 110 124 111 125 122 120 111 110 105 123 103 127 128 110 123 129 130 124 124 102 105 110 114 122 128 109 99 126 123 132 113 104 108 108 107 103 122 123 112 114 108 111 126 104 115 126 115 121 115 109 93 110 108 113 119 132 118 115 103 115 114 129 125 104 109 130 110 106 110 121 99 101 134 127 122 106 146 141 119 119 126 137 117 109 115 102 121 128 122 125 116 97 129 113 124 129 112 105 104 97 125 101 112 95 113 117 111 130 111 105 122 105 122 130 119 110 116 119 100 114 112 117 109 102 116 89 112 107 96 101 118 134 126 126 112 121 123 115 100 143 118 112 93 120 120 106 107 130 122 131 116 108 108 107 117 123 107 107 114 119 116 116 112 87 119 118 105 94 123 114 106 105 112 120 98 108 115 115 113 125 105 129 108 124 97 106 111 112 112 107 110 120 115 123 98 118 127 124 112 114 126 117 124 113 117 128 118 100 124 105 109 115 112 109 104 111 122 100 128 131 113 116 129 97 114 114 130 122 101 138 140 110 123 112 110 115 95 121 104 105 108 97 122 119 115 99 122 142 118 114 116 98 112 130 104 96 117 121 113 117 102 91 118 120 115 101 115 95 122 129 118 118 108 93 105 108 121 108 112 118 113 111 107 121 100 113 109 96 110 122 118 114 113 115 112 90 130 120 119 114 126 112 116 105 107 114 100 95 110 107 104 84 110 107 99 114 89 110 118 127 104 126 126 120 106 126 112 127 106 123 114 105 108 107 105 110 112 110 116 92 102 108 99 85 120 102 112 122 121 116 126 102 112 105 116 91 118 105 101 107 104 118 99 110 97 100 102 111 85 121 87 108 123 107 106 112 100 130 100 111 125 96 101 109 107 102 97 117 127 103 113 111 118 116 98 125 126 125 104 111 85 101 147 98 113 112 106 116 104 110 106 105 97 96 121 108 112 105 112 102 98 126 100 117 122 110 115 102 110 92 118 109 108 96 120 103 95 120 125 118 119 115 103 95 105 110 127 114 131 101 98 106 103 95 112 107 114 123 106 130 120 104 118 116 100 120 105 93 117 94 112 110 108 111 102 103 100 114 93 104 105 106 123 118 101 99 94 121 114 113 94 106 110 106 95 116 112 117 104 94 112 109 103 98 119 107 112 102 116 121 95 103 91 90 116 109 106 96 96 108 114 89 107 118 122 104 111 99 99 118 97 112 106 108 116 111 104 108 100 114 115 104 128 117 101 108 124 105 101 109 103 131 118 98 89 120 95 123 116 115 105 83 108 119 104 92 104 117 90 98 108 103 86 86 106 100 105 113 97 97 104 103 121 107 95 121 116 116 96 97 126 114 107 110 102 90 104 123 98 109 100 108 100 114 105 105 104 132 103 101 112 104 102 106 101 104 96 114 104 105 103 93 112 105 106 121 94 107 104 87 104 117 111 129 112 107 108 125 114 109 108 94 112 94 112 92 98 110 87 99 97 102 91 106 94 97 99 110 122 123 109 111 134 108 118 98 106 103 98 97 112 121 92 103 95 121 119 112 113 117 92 97 88 115 111 116 117 123 110 91 98 106 118 111 97 123 100 98 128 117 96 105 79 123 110 116 122 93 115 104 95 109 110 112 119 115 88 116 107 102 87 92 99 104 120 113 100 83 102 109 113 91 96 117 98 106 112 115 125 109 103 114 100 104 112 119 99 107 101 120 114 113 104 99 106 89 110 107 96 84 112 100 102 103 105 115 87 117 116 106 101 107 114 111 104 103 117 116 113 110 114 105 100 114 130 107 129 112 103 110 122 117 104 93 104 101 103 106 108 105 109 103 113 123 118 101 116 93 113 108 107 103 94 117 122 100 111 96 104 76 107 101 121 100 110 104 98 96 114 99 107 100 107 101 107 100 109 115 121 107 109 90 118 103 116 122 93 118 103 102 130 103 118 114 112 125 96 85 106 108 117 120 103 98 104 115 100 113 89 116 97 101 110 86 129 119 106 105 87 91 101 118 111 86 128 108 124 105 96 117 126 133 117 103 95 104 112 115 103 86 127 108 112 111 138 91 125 104 89 100 121 99 99 107 113 121 113 110 122 115 102 109 107 114 107 107 105 92 99 110 110 99 105 112 117 113 106 110 100 108 122 119 110 116 83 120 116 103 103 109 94 99 108 89 118 117 86 119 103 101 120 108 115 97 109 113 101 143 118 93 109 107 133 114 99 99 108 124 90 100 113 112 106 106 104 118 97 101 119 98 109 95 117 99 103 121 125 135 107 95 113 100 101 101 119 109 119 98 119 111 111 100 100 118 111 100 112 113 90 121 107 125 114 122 103 120 110 91 109 105 103 114 98 118 112 106 120 118 115 97 113 115 94 115 104 107 115 109 114 110 119 113 107 109 112 115 106 109 99 117 112 125 119 131 121 101 118 115 110 108 116 107 118 105 121 117 120 120 102 121 122 98 101 118 109 114 99 123 122 118 116 123 107 107 123 92 101 119 111 114 126 129 120 127 98 101 109 109 98 103 112 122 119 96 116 92 112 87 114 116 103 128 116 111 117 109 111 110 113 104 134 112 95 110 116 130 109 108 116 115 121 113 110 134 116 91 123 118 124 100 121 120 128 117 100 103 127 125 124 102 114 125 140 120 96 118 125 99 104 134 114 103 121 114 122 105 97 121 127 117 120 114 111 109 115 128 116 132 122 115 107 120 103 111 103 122 107 107 130 113 124 104 107 111 122 125 122 150 119 95 129 116 120 116 114 126 112 112 99 130 130 116 123 123 135 121 117 121 129 139 111 134 110 127 132 127 128 123 124 116 136 119 131 116 135 122 109 135 151 118 98 114 103 111 149 159 143 116 112 116 124 114 147 131 116 123 107 132 110 117 125 117 123 130 124 119 114 127 124 127 137 120 117 116 107 119 129 110 122 108 144 134 134 141 122 122 124 134 122 120 124 135 144 133 133 128 136 109 131 106 109 125 149 137 126 114 146 125 141 102 147 137 127 134 139 126 127 135 136 147 135 137 137 147 137 144 151 154 166 136 170 140 180 178 156 163 168 156 178 176 189 179 185 197 193 184 188 191 187 172 203 205 214 230 197 200 221 214 209 189 193 169 188 171 180 186 168 176 182 178 181 160 148 166 166 152 151 136 125 140 144 125 125 121 118 115 117 143 129 126 114 142 116 141 137 120 128 128 128 130 134 141 143 117 135 119 128 135 120 121 112 134 127 121 111 123 112 115 120 115 117 126 119 118 120 125 110 110 125 131 122 113 124 112 145 131 102 126 102 111 109 109 119 114 121 129 109 130 103 116 131 116 124 123 130 118 115 122 122 119 119 125 111 105 149 124 118 125 107 116 125 130 93 112 119 121 113 122 109 93 106 109 109 125 119 112 112 124 107 127 112 121 125 122 111 100 127 122 117 105 118 108 126 121 101 115 109 97 120 115 130 110 110 108 113 111 120 117 112 119 124 120 103 119 116 103 107 128 101 124 113 122 125 116 113 139 99 106 130 107 102 108 119 120 117 107 128 110 111 128 128 141 118 122 109 118 127 94 115 119 90 119 122 126 112 107 107 129 117 106 101 141 123 116 133 118 120 113 108 112 110 126 125 111 100 127 114 117 103 118 99 109 126 112 112 135 102 132 132 108 124 106 115 108 109 104 117 118 113 105 119 92 121 127 124 122 146 112 120 92 110 122 119 135 124 110 121 106 111 128 129 107 124 106 112 133 115 120 123 99 123 120 120 125 116 98 119 107 118 104 117 112 117 109 111 106 112 110 121 115 120 92 127 103 101 131 115 131 116 133 132 122 140 131 126 128 137 126 111 107 130 109 128 136 105 113 117 129 113 112 127 132 121 126 126 123 135 128 137 113 122 120 116 125 127 118 123 121 121 120 113 112 115 116 111 131 117 121 118 110 112 102 106 112 124 95 129 123 129 129 118 117 135 104 118 114 117 111 114 112 115 112 117 112 126 104 129 117 104 94 103 120 102 109 123 112 115 132 138 112 122 129 125 105 121 115 123 110 104 106 121 120 127 108 93 112 117 119 124 103 107 118 100 135 117 129 121 125 124 122 122 122 117 122 109 129 123 126 111 125 131 115 135 115 119 112 131 114 134 98 95 133 118 116 122 119 119 107 115 118 131 117 113 114 124 108 106 94 132 115 132 128 132 118 97 123 116 125 131 116 123 110 123 120 122 111 128 131 128 110 147 133 126 124 144 114 116 130 118 109 107 105 134 119 119 111 118 127 103 141 102 128 136 124 114 142 123 108 119 126 104 121 131 107 126 128 113 120 111 104 127 108 121 117 121 102 126 93 137 132 106 112 112 113 118 118 132 119 126 140 113 123 122 110 99 124 130 111 102 134 105 115 98 115 107 111 110 116 118 119 114 127 128 131 141 118 129 128 104 122 106 105 130 121 113 114 103 126 142 123 128 117 111 127 126 113 125 127 105 122 125 117 105 116 111 110 111 105 105 112 123 136 120 110 129 131 112 129 129 131 107 123 123 122 114 114 122 104 91 116 113 93 114 117 106 124 128 120 133 94 114 137 114 107 124 127 104 115 118 107 131 91 105 118 122 135 118 119 119 121 147 110 128 119 128 99 135 129 136 119 131 109 122 125 126 122 120 109 120 109 128 128 124 140 118 112 124 121 135 130 113 117 103 112 126 112 119 111 108 118 117 112 112 110 138 119 113 121 122 120 141 106 114 122 113 127 108 128 125 121 138 117 124 130 110 122 115 123 130 130 117 141 133 112 111 107 118 116 122 120 126 110 146 114 130 134 124 141 116 121 135 127 110 128 120 111 116 119 131 129 132 138 146 127 117 130 129 121 122 115 114 113 149 124 131 113 109 135 115 129 121 103 123 129 116 128 120 132 116 116 121 108 122 141 116 114 113 128 115 123 126 127 138 136 124 108 146 121 127 116 106 112 122 129 123 107 115 129 144 122 122 114 131 125 131 120 112 118 121 119 118 114 113 119 116 128 133 103 112 121 121 118 141 142 128 100 122 108 119 131 127 99 125 131 124 117 121 138 117 120 96 132 107 113 124 109 141 124 113 117 116 119 88 112 127 108 133 119 116 130 114 116 121 125 114 124 122 147 116 113 115 117 112 113 124 100 106 112 129 127 124 125 135 127 123 125 140 118 122 113 104 143 134 129 123 126 101 102 124 136 113 106 108 127 120 110 108 94 129 112 133 122 134 127 124 125 118 143 116 115 114 132 115 124 108 131 118 124 124 123 135 116 110 112 115 115 121 117 116 108 126 144 137 129 138 147 117 116 118 116 124 137 143 108 123 126 141 109 137 142 128 117 128 117 117 122 120 144 141 135 112 113 130 119 120 124 133 122 103 144 115 139 125 102 149 102 141 108 125 120 128 124 106 122 109 127 139 123 136 121 119 119 134 101 132 115 116 100 111 129 118 139 122 116 128 117 113 120 133 124 108 108 118 118 132 121 114 125 120 123 141 114 124 128 121 115 113 138 98 116 107 128 124 121 104 118 112 115 122 137 112 129 136 118 120 123 116 124 130 123 123 106 131 117 101 112 121 142 124 115 125 113 127 111 121 97 126 115 117 136 98 121 122 129 115 108 124 108 129 126 114 126 105 118 134 111 141 123 123 116 115 118 136 111 126 120 112 141 121 134 131 123 120 121 124 139 121 126 126 105 109 121 116 111 155 98 127 135 134 115 109 118 130 107 121 136 128 120 117 145 110 108 126 115 140 119 124 133 128 136 116 116 112 112 116 144 125 136 144 112 126 126 122 122 136 113 138 130 114 124 143 107 118 144 117 113 118 130 119 138 120 100 126 135 138 139 133 122 116 128 134 112 127 124 127 117 123 126 122 133 136 142 123 119 117 118 128 137 121 121 107 122 132 132 129 153 133 138 118 104 141 112 119 125 136 117 110 116 139 113 116 108 106 110 124 112 127 135 112 130 108 100 136 142 129 111 122 122 120 142 117 124 107 121 134 141 108 109 132 115 172 140 114 102 124 134 131 136 133 115 130 131 132 122 114 113 131 121 110 120 117 128 122 111 114 113 139 122 110 126 105 123 98 141 131 122 130 138 133 128 108 129 123 124 145 118 135 114 135 118 118 115 139 125 125 127 132 121 113 142 134 128 129 148 140 136 130 136 119 118 144 117 138 126 119 131 110 145 111 151 128 157 128 128 122 108 131 106 129 138 121 131 134 134 128 120 107 106 119 124 118 106 131 135 114 128 112 124 112 126 117 125 107 138 131 110 125 111 116 104 141 132 131 113 116 98 99 117 118 123 126 130 119 110 134 114 137 119 133 131 126 113 141 112 129 149 111 160 125 118 134 111 124 111 133 95 126 114 107 119 128 124 133 114 127 110 125 135 127 114 119 118 117 121 116 126 135 119 131 104 131 121 132 122 116 122 142 122 144 133 118 119 132 155 135 119 122 126 114 110 128 111 115 135 125 131 139 137 121 159 136 136 121 131 123 117 124 117 123 104 120 123 126 119 149 118 125 146 136 120 128 121 123 141 139 121 102 118 134 129 122 142 111 133 119 118 101 128 134 128 111 107 133 119 131 112 153 113 121 132 102 132 139 126 146 123 114 136 129 126 121 135 137 128 127 127 134 133 124 133 92 123 132 146 128 129 103 122 122 130 108 124 153 119 116 136 125 120 139 121 127 138 118 139 110 123 138 143 136 127 141 126 115 117 108 106 134 120 113 115 131 116 117 121 122 123 130 127 127 140 120 146 138 138 126 116 134 118 122 133 139 122 108 120 130 157 127 137 128 138 120 123 129 127 108 131 130 150 151 140 136 124 124 124 133 118 130 145 120 130 117 120 135 111 144 128 142 136 130 129 124 120 110 110 130 116 132 120 132 132 139 150 127 136 121 125 112 123 129 118 132 121 146 120 130 139 102 111 124 124 137 112 125 140 129 134 115 117 126 132 128 122 127 133 131 145 129 118 131 129 144 116 121 109 134 111 130 146 124 107 126 133 123 137 126 127 129 124 132 118 115 126 107 142 138 119 136 123 115 127 116 133 117 137 126 127 124 100 133 135 115 109 133 127 148 124 130 116 132 135 111 117 139 140 120 137 140 134 122 116 140 133 130 113 108 139 142 142 127 152 138 105 122 139 117 144 121 127 139 151 114 122 114 142 123 149 126 124 138 133 98 137 110 129 112 146 139 145 121 107 151 122 127 124 144 150 103 128 143 140 143 134 121 110 120 126 113 115 127 133 125 146 115 143 125 107 125 140 147 133 128 140 131 140 125 114 141 113 127 132 156 141 129 134 127 139 128 119 145 120 130 118 143 138 146 139 130 125 124 129 129 106 140 111 138 125 136 128 119 124 131 115 127 130 120 117 125 124 135 131 142 127 139 131 113 105 128 113 114 142 131 134 124 112 108 121 124 108 167 130 140 105 124 135 113 128 127 132 109 115 121 126 118 135 147 127 133 116 126 129 140 124 137 134 122 123 141 118 144 111 118 122 123 123 139 119 157 137 130 117 128 127 123 109 132 135 124 130 135 142 128 112 129 124 124 124 133 119 123 131 125 159 113 130 142 122 143 157 105 128 138 154 141 129 118 120 127 144 135 126 145 129 133 141 136 135 152 136 132 135 115 117 132 150 129 146 142 120 138 138 142 143 106 146 124 128 125 149 133 153 129 136 145 122 131 117 130 135 131 127 139 146 124 119 119 127 129 129 135 134 141 119 135 132 123 140 158 143 108 134 132 132 152 123 123 126 134 136 132 148 143 141 156 126 152 127 120 110 121 137 124 138 147 121 130 139 132 133 144 138 128 148 143 138 139 142 125 128 115 133 139 144 145 141 110 128 142 101 118 115 128 118 125 123 127 136 146 151 133 127 138 124 144 137 120 118 127 140 127 129 124 123 137 124 128 113 129 125 140 140 130 128 150 108 131 133 150 107 113 137 120 128 104 142 140 129 124 119 147 139 123 147 130 141 117 144 122 125 133 143 132 133 135 165 133 118 130 148 114 125 133 125 107 139 126 114 124 121 121 122 134 136 120 130 126 124 112 129 119 129 143 142 123 141 126 134 149 124 134 145 133 139 133 130 142 120 136 132 141 129 129 144 134 144 141 124 148 126 133 120 126 146 146 133 119 117 135 116 118 143 147 135 138 140 155 116 140 125 143 121 144 141 144 122 119 145 115 136 124 117 116 128 137 148 132 126 115 120 148 129 119 125 126 145 135 136 134 122 112 116 141 130 153 125 126 129 142 136 133 111 129 134 126 134 153 140 125 136 141 133 137 124 132 118 129 137 137 118 120 133 125 133 123 116 132 137 127 132 117 129 145 138 134 134 137 119 124 125 137 141 132 151 142 103 111 154 151 153 114 135 120 124 122 131 116 148 143 108 135 134 121 114 140 119 110 131 160 158 140 111 141 112 116 136 145 140 121 129 126 123 138 139 123 137 112 118 127 133 114 142 124 143 115 129 137 113 131 126 145 136 155 131 116 128 132 127 121 142 119 100 116 113 139 136 133 122 135 114 121 118 124 135 133 124 132 135 114 131 132 113 120 135 150 118 131 149 144 107 140 124 128 133 133 139 146 112 128 127 133 129 106 142 126 118 139 130 135 144 113 137 153 111 138 123 111 121 132 125 126 108 134 128 136 133 121 129 135 135 121 111 126 128 144 132 127 133 140 135 148 130 136 154 142 129 140 131 124 144 136 128 122 146 140 150 112 145 127 131 144 154 131 142 124 109 141 131 126 129 104 137 118 130 124 151 116 133 141 147 143 109 141 134 136 145 131 135 141 146 147 140 130 144 142 129 139 128 141 149 135 125 137 131 141 125 142 127 134 137 145 122 126 151 142 155 144 125 133 133 114 127 136 125 124 124 136 117 114 119 134 141 139 132 126 146 119 123 120 127 138 142 125 140 136 129 128 136 114 144 125 115 130 109 120 129 116 148 138 143 122 150 127 129 130 118 119 120 129 123 126 125 119 126 131 131 141 158 143 123 130 131 147 148 127 145 133 143 117 129 129 133 124 145 136 135 156 148 123 112 127 117 130 139 149 124 131 127 141 103 146 135 130 128 134 126 132 115 127 150 124 116 146 151 115 124 125 150 147 127 139 148 140 131 115 141 119 130 131 137 124 137 144 128 140 145 139 131 149 139 124 118 122 144 120 125 105 131 152 144 120 118 134 138 142 157 133 121 122 123 144 129 122 151 109 146 135 146 131 154 142 142 148 142 130 106 153 131 123 125 129 118 138 127 119 124 129 127 132 134 131 142 161 130 133 147 135 145 124 100 126 123 110 114 125 141 137 120 126 138 141 140 135 138 138 126 132 144 139 120 122 133 142 145 123 114 129 139 152 123 111 126 127 128 141 138 127 115 147 139 156 136 128 130 125 126 137 150 125 144 127 125 131 139 123 128 134 130 146 119 141 123 142 112 124 148 143 147 114 153 134 110 131 156 124 135 133 132 148 138 123 119 121 131 139 137 135 113 116 135 134 130 130 133 116 124 118 140 141 125 130 131 137 131 135 118 114 140 125 139 128 145 126 117 125 119 108 126 112 115 139 138 144 113 150 123 127 140 141 131 119 125 129 128 139 142 128 126 118 132 122 124 145 130 121 143 121 127 132 122 122 124 126 121 127 135 147 105 154 109 123 134 131 124 138 114 100 116 122 140 131 136 132 143 135 126 112 127 138 130 116 133 145 133 161 129 136 135 131 137 137 132 136 112 148 125 130 127 132 123 132 111 120 153 130 113 140 132 113 119 138 127 128 127 130 114 146 124 142 131 143 145 137 126 109 140 139 149 132 103 157 143 125 124 112 135 121 121 142 139 129 137 125 136 137 110 140 139 127 116 125 144 117 129 144 145 134 127 105 147 135 127 135 119 128 133 135 126 118 128 131 139 113 133 118 141 103 137 146 135 141 136 113 127 140 129 124 145 142 121 126 139 151 114 145 126 135 151 133 137 138 118 126 129 138 131 117 115 113 153 127 128 149 118 137 109 159 129 123 131 136 128 149 122 121 141 142 132 115 126 122 135 120 126 150 135 136 130 145 141 130 116 122 147 132 149 113 134 108 119 106 150 113 126 112 114 142 137 140 122 134 134 129 126 132 135 121 125 126 132 122 138 131 129 145 133 143 109 115 146 124 124 117 142 139 133 124 147 154 130 120 133 137 144 125 146 128 133 128 141 117 128 141 134 113 151 125 139 132 112 142 117 110 125 131 140 115 118 127 139 139 130 128 131 147 131 137 120 119 160 110 130 137 143 128 121 124 155 134 134 129 147 140 131 120 142 120 120 134 128 155 128 117 130 136 132 120 106 129 155 130 111 132 155 124 135 127 143 114 135 105 119 118 140 142 147 137 134 143 122 115 137 144 107 126 136 130 125 153 125 125 112 148 126 128 133 128 110 129 134 133 133 127 132 153 108 110 135 144 131 131 132 138 123 136 130 122 127 120 141 118 121 125 157 133 117 120 129 120 131 120 140 138 138 146 117 136 120 132 159 149 137 141 128 144 117 112 132 133 122 108 140 137 131 138 129 124 130 115 129 116 136 146 116 111 129 135 125 110 117 141 116 139 125 119 135 125 136 123 115 131 132 129 126 129 121 139 120 143 138 117 135 97 107 105 123 140 126 135 132 139 126 125 109 122 128 145 129 122 137 107 120 150 137 120 140 144 131 127 129 130 141 130 128 139 135 137 128 158 118 125 148 123 139 136 136 126 139 119 137 130 128 138 144 155 129 127 115 120 144 121 135 114 129 126 119 131 131 125 133 105 137 140 123 132 115 127 124 119 146 124 149 138 117 126 108 128 139 111 131 151 141 140 111 131 137 123 111 109 103 141 121 130 128 122 128 122 131 146 122 123 133 160 139 140 139 133 131 138 137 119 145 132 136 126 132 155 128 141 115 131 124 154 135 122 139 111 112 157 141 129 121 115 139 136 142 130 107 128 113 110 134 126 140 113 118 116 121 128 163 151 121 146 136 122 116 123 139 130 127 144 111 114 133 127 129 136 122 143 140 137 111 131 122 120 116 125 135 138 139 145 131 134 132 123 140 118 149 146 135 125 136 136 133 132 126 125 112 139 117 131 131 147 124 139 137 129 139 121 133 157 118 118 128 126 137 111 141 140 132 147 139 120 123 117 121 132 132 130 135 128 106 137 128 133 165 138 113 151 142 124 130 137 145 126 121 117 132 111 138 131 131 135 116 132 129 144 138 123 133 128 134 126 171 129 145 139 144 109 137 121 125 115 144 139 132 144 161 133 141 146 138 133 156 130 129 122 133 142 132 130 124 155 126 116 132 133 138 139 132 144 143 139 140 135 128 136 137 140 125 135 109 143 139 146 115 125 127 129 139 121 121 122 133 130 144 153 143 145 143 121 131 129 126 141 125 130 117 134 153 140 117 136 113 146 154 134 157 133 134 139 123 119 135 164 115 137 133 139 134 135 142 124 141 140 122 125 135 135 121 126 153 133 128 149 114 135 139 125 135 119 149 126 144 139 123 121 136 138 133 127 118 140 124 129 141 134 121 153 123 135 134 144 113 140 145 139 130 130 141 127 135 124 157 155 136 138 129 125 126 138 149 142 125 138 132 136 139 149 135 136 155 139 131 133 137 132 130 155 145 144 130 136 138 125 142 127 153 110 149 143 119 151 139 135 160 142 140 152 141 144 139 141 108 124 138 155 130 152 154 152 130 158 142 140 130 134 157 152 143 153 158 172 141 137 144 126 155 167 139 144 152 153 156 131 158 153 126 135 128 151 140 143 144 146 151 141 155 155 138 175 139 145 146 118 149 143 132 152 136 138 141 153 134 144 125 119 116 121 135 139 136 159 162 148 129 153 152 138 147 136 144 139 151 134 125 150 158 152 154 131 141 142 123 149 144 116 156 147 123 132 115 154 116 152 124 131 120 115 148 123 139 141 126 141 130 140 159 125 140 105 122 138 154 115 144 133 134 149 151 134 150 119 129 129 128 142 133 128 129 121 122 127 111 137 109 136 130 128 147 136 135 132 134 142 134 135 149 132 121 129 121 122 123 128 141 121 121 113 143 149 117 146 130 113 130 144 125 131 141 107 110 114 142 135 130 117 126 123 120 142 133 124 126 130 140 144 147 122 139 119 123 117 113 120 111 133 122 145 122 125 136 143 132 142 124 105 117 136 135 112 123 143 121 112 142 128 140 133 135 132 138 153 124 132 139 125 136 122 147 119 134 136 156 117 142 135 117 132 146 116 129 129 141 142 147 117 125 114 138 140 128 121 125 127 110 125 141 138 123 147 135 151 118 132 124 135 113 111 126 149 132 121 141 125 118 123 137 117 132 108 124 118 128 138 103 118 133 128 130 134 143 121 113 119 107 137 144 132 124 138 129 111 122 117 115 123 141 109 131 148 146 122 150 138 129 128 117 135 131 131 132 129 125 123 119 139 132 125 116 147 125 141 123 136 119 136 117 132 122 132 125 117 135 141 130 130 127 136 100 131 131 143 147 152 128 128 135 117 110 119 127 139 126 127 131 130 140 126 123 124 113 119 123 138 128 118 113 137 118 116 135 114 132 114 135 139 112 132 123 103 113 113 140 124 124 132 116 109 147 138 137 117 129 141 117 115 131 156 124 118 123 136 111 123 121 125 120 119 135 127 130 93 125 128 142 140 140 110 113 128 118 120 128 121 135 133 126 119 132 126 125 99 119 123 123 124 136 147 139 149 117 139 129 125 125 131 132 124 132 127 110 127 138 119 115 129 134 116 131 111 138 137 132 112 128 113 130 137 126 128 124 141 134 131 118 147 131 131 110 114 129 148 115 122 142 128 112 132 120 120 135 115 131 112 116 105 124 120 116 113 120 127 137 109 126 138 135 118 112 123 117 119 120 110 136 109 116 121 123 118 140 128 126 126 128 125 132 123 144 135 112 138 131 132 102 140 140 128 126 110 126 126 120 120 111 144 144 134 139 132 148 127 122 141 142 120 134 118 111 126 126 114 132 110 146 128 145 110 127 113 135 123 130 151 113 132 147 128 139 129 127 120 131 125 115 140 131 108 99 121 121 107 146 134 119 131 140 111 120 114 119 132 154 130 123 117 125 139 109 120 116 106 124 105 127 137 106 106 116 136 120 131 139 127 122 122 138 124 124 134 132 127 135 126 131 123 125 137 147 120 127 125 131 126 132 141 126 144 148 105 104 129 135 121 114 131 140 126 141 134 131 141 122 128 138 119 106 139 140 141 136 100 140 140 111 110 118 119 125 135 116 124 130 133 112 129 132 124 124 130 117 140 125 127 120 142 142 138 115 112 120 114 139 111 118 120 124 112 121 129 112 133 133 127 151 117 135 120 115 145 130 142 159 130 140 114 134 116 130 121 123 115 118 102 128 111 123 133 114 113 126 127 162 122 139 143 149 105 128 136 144 119 111 106 112 122 122 140 122 150 155 138 114 119 133 127 114 131 135 135 131 125 123 120 134 124 137 116 121 113 145 115 134 141 109 135 119 136 124 122 125 128 142 125 132 122 137 125 130 130 141 116 126 132 122 132 143 119 145 119 123 149 124 128 133 117 144 138 143 136 124 129 137 128 122 120 129 110 110 109 125 120 108 121 126 126 123 135 120 110 118 125 152 137 138 138 127 121 129 109 122 123 129 130 133 124 135 125 134 129 117 123 129 129 123 129 144 143 128 117 142 129 112 137 141 109 132 116 116 137 125 112 157 123 121 144 127 134 131 109 136 125 124 132 121 140 125 125 131 117 122 123 111 128 140 132 114 135 122 141 105 124 121 131 122 121 124 128 127 121 129 117 135 106 124 125 125 118 122 128 126 142 109 129 148 114 96 127 132 126 102 133 117 114 116 150 138 116 137 123 119 136 141 137 115 121 130 111 139 130 138 115 126 145 123 89 117 120 133 135 120 114 128 128 109 142 130 127 148 136 135 138 117 121 120 126 126 109 126 123 144 114 117 127 144 106 113 143 132 144 121 130 118 107 123 130 125 137 126 126 132 141 117 116 137 105 118 126 125 145 143 136 110 123 129 98 124 132 117 147 115 123 130 118 127 126 141 128 118 126 132 126 123 120 115 134 132 122 131 125 127 111 135 136 127 141 128 120 126 127 141 149 132 120 125 120 140 125 109 118 121 113 124 127 131 115 130 117 119 113 121 100 134 102 123 116 133 124 125 118 118 125 116 134 124 131 129 122 117 137 121 128 129 134 124 121 108 135 108 143 114 132 134 102 141 135 122 132 119 125 124 135 116 115 127 118 113 131 128 144 147 125 136 138 121 145 139 133 138 122 115 106 132 131 122 137 124 123 112 139 133 114 129 125 118 128 140 133 121 119 114 140 137 142 123 125 124 124 122 129 129 91 131 95 134 137 135 139 140 137 138 127 130 135 104 115 136 142 125 143 127 140 124 114 131 131 117 125 128 131 135 110 120 143 118 133 129 127 133 114 130 117 136 135 134 137 127 124 126 120 121 142 135 114 114 120 113 128 111 127 122 135 132 138 146 119 125 133 144 145 115 125 139 104 128 132 113 129 105 132 124 114 129 139 137 126 121 128 141 141 117 129 127 135 133 135 115 121 132 126 131 110 124 122 149 131 123 104 116 145 120 118 127 126 129 137 114 129 111 125 137 109 120 114 127 138 127 133 140 117 133 145 119 112 135 144 138 116 128 118 133 120 139 115 116 113 145 115 113 123 121 119 130 125 125 135 121 137 117 92 127 130 122 124 114 130 120 124 108 120 131 97 130 116 142 125 135 136 136 126 129 134 135 123 117 120 114 116 142 130 150 104 108 130 121 118 127 133 114 121 139 127 146 132 125 140 126 140 131 125 134 115 122 136 142 145 144 125 126 127 123 134 134 108 139 127 134 129 112 131 120 124 114 134 113 98 122 107 126 113 118 128 132 120 115 130 134 131 126 110 154 117 123 136 139 138 129 128 117 117 124 119 107 107 140 121 121 134 131 128 116 135 133 149 127 119 119 106 141 113 121 123 120 115 127 146 119 115 135 111 114 119 128 113 143 138 125 125 121 135 115 117 129 118 139 121 154 113 113 123 106 128 134 144 112 122 114 132 139 128 129 153 129 116 125 129 124 128 115 131 130 114 121 132 112 148 111 113 148 118 122 143 108 134 122 125 133 119 147 135 130 125 143 121 141 127 119 140 123 128 108 125 144 139 129 125 107 117 136 132 121 128 122 127 119 110 134 141 115 132 136 129 135 126 125 132 102 131 129 112 120 126 124 139 122 140 124 126 108 129 129 107 133 141 134 140 119 144 132 128 114 156 129 132 147 122 150 123 136 132 117 117 144 134 153 118 145 121 134 127 125 133 125 134 125 131 115 145 128 142 141 103 132 127 125 136 125 139 132 136 135 124 129 116 130 141 122 142 129 105 123 133 140 128 137 141 137 127 130 130 151 130 150 124 137 139 124 129 128 123 134 130 132 121 117 139 121 148 137 115 125 121 116 157 150 118 129 152 133 105 105 120 146 153 147 142 136 134 124 132 132 126 130 131 138 153 161 136 138 154 137 134 135 130 149 106 131 135 153 120 148 147 112 122 137 122 110 164 141 139 130 135 141 123 153 142 134 145 128 126 154 141 124 130 131 154 142 119 142 131 96 132 125 129 139 120 110 120 128 121 125 129 119 133 156 130 112 138 142 124 121 125 121 133 134 114 117 128 149 138 129 126 137 119 109 148 115 121 124 140 127 137 128 141 132 124 128 130 129 131 107 127 127 122 129 129 129 131 130 138 109 133 145 148 130 109 135 125 124 128 140 114 127 126 127 135 125 112 132 121 116 145 125 136 124 129 120 125 139 122 117 127 131 133 141 110 112 128 118 145 126 121 116 140 128 134 122 119 141 120 122 104 123 138 134 124 142 139 139 126 123 141 106 130 108 113 120 129 124 138 144 117 151 137 131 146 119 126 148 118 104 129 129 147 110 131 138 125 142 125 127 114 130 127 129 130 143 103 112 123 138 116 114 136 132 121 141 110 129 138 126 150 110 149 116 126 125 125 133 111 120 125 136 135 121 134 120 143 128 128 129 136 125 112 126 124 132 133 134 127 116 138 133 110 127 121 138 136 126 133 116 125 130 123 122 137 122 144 117 128 121 118 124 136 140 105 136 147 123 126 138 146 140 135 135 127 105 145 118 115 143 123 130 116 122 123 112 113 127 120 124 117 138 127 106 132 128 128 119 120 127 115 125 134 116 123 114 125 149 135 122 128 113 134 120 122 102 138 126 124 133 127 126 121 147 145 126 123 130 120 130 122 116 138 152 134 121 121 144 129 129 137 141 132 154 153 134 128 130 150 127 123 117 131 133 119 113 137 109 129 116 103 123 135 132 104 115 144 123 148 129 119 131 114 111 116 120 127 121 95 142 109 117 122 112 116 121 128 122 132 133 101 133 124 132 128 120 116 139 126 122 132 122 136 132 138 122 117 135 118 143 114 123 151 108 111 116 135 125 114 127 134 126 132 144 121 127 96 117 127 145 135 125 136 106 120 105 116 133 126 122 143 133 117 128 134 126 130 115 108 134 115 145 134 125 133 120 117 150 134 143 131 115 144 109 125 119 140 129 114 132 129 119 115 135 112 156 136 124 151 126 127 130 127 121 144 138 116 120 109 112 135 125 138 138 141 114 119 116 134 110 109 124 116 115 138 130 133 133 120 127 135 122 122 129 140 123 114 141 130 131 98 127 135 114 126 129 126 133 137 115 101 152 114 134 113 129 124 113 138 107 133 127 140 116 120 133 124 137 136 121 136 137 127 119 127 130 131 117 148 130 118 138 142 138 116 110 112 139 132 127 135 141 125 110 119 132 137 149 135 117 119 142 110 127 151 138 136 124 145 149 145 127 134 104 126 153 139 113 140 149 112 122 114 126 123 113 114 124 120 131 116 114 139 115 127 124 135 138 122 127 123 124 111 136 135 122 132 128 128 123 117 130 136 140 114 128 122 138 127 144 128 123 149 129 136 132 131 143 109 160 119 129 145 132 120 128 105 132 106 129 105 123 124 139 108 135 143 123 119 108 127 128 124 134 139 133 135 138 143 119 124 126 133 143 123 139 132 142 137 116 136 141 135 119 150 129 117 119 130 126 129 139 119 120 130 105 115 121 126 128 111 137 125 116 137 121 113 121 130 92 129 106 138 150 132 127 114 143 113 134 127 126 126 124 129 134 97 117 144 116 135 141 139 115 140 115 109 103 115 129 127 131 140 127 126 125 126 127 120 109 126 130 129 119 111 118 121 131 129 121 140 113 131 145 134 136 127 122 138 127 134 132 129 120 134 132 150 116 126 131 139 128 128 148 115 123 126 124 117 113 126 116 136 112 147 125 121 131 112 141 119 117 119 139 119 125 118 133 110 118 134 133 139 109 132 135 118 137 106 128 112 98 119 125 144 122 126 124 121 109 98 112 133 134 115 102 140 127 134 136 143 130 114 124 120 126 119 102 140 133 112 103 127 119 115 121 127 117 123 128 119 121 133 150 125 121 131 122 132 115 133 134 115 133 137 111 118 135 122 126 121 115 116 133 115 133 134 126 129 130 133 122 133 135 140 117 120 127 119 116 136 133 130 118 118 121 146 114 131 122 119 119 122 128 125 134 120 98 127 126 112 124 128 129 128 128 126 114 122 127 129 136 123 119 149 113 125 154 125 124 147 136 139 126 158 125 117 131 113 123 132 125 101 136 122 123 138 116 121 142 134 127 116 104 114 132 140 114 120 118 122 143 119 109 108 121 143 152 133 132 110 133 128 122 124 124 119 119 99 122 120 117 142 125 107 134 111 116 114 133 109 123 119 124 122 132 127 95 131 122 131 139 124 125 139 129 115 127 112 127 126 123 126 136 139 144 118 106 115 108 115 131 132 146 128 108 133 116 123 133 141 126 136 115 144 108 133 118 132 100 148 111 111 127 131 132 132 121 114 107 123 128 120 155 113 121 139 129 126 129 128 126 132 114 113 157 164 115 131 131 131 140 117 132 110 130 132 120 126 128 117 127 113 121 128 121 141 125 127 128 142 107 114 119 135 125 149 116 104 100 153 115 116 131 148 120 112 135 133 143 133 119 135 134 130 122 121 134 135 145 103 136 100 131 119 127 119 121 121 129 129 131 126 121 121 105 111 118 139 118 126 111 143 140 148 112 135 123 127 127 130 116 124 122 139 108 142 117 119 122 138 112 152 126 109 146 129 113 127 138 142 125 121 121 135 132 123 114 124 107 115 129 108 129 103 127 111 127 132 151 133 128 135 110 116 118 122 104 109 119 122 123 107 139 117 130 118 122 135 128 117 113 129 135 128 130 114 128 141 124 151 120 117 128 129 112 133 125 125 138 130 125 99 130 117 115 133 119 124 114 120 127 102 124 133 109 134 133 134 135 118 142 128 132 112 126 132 131 118 129 133 129 128 107 127 126 129 115 123 121 112 115 114 120 149 146 120 129 115 116 148 134 124 122 129 143 129 129 127 114 132 120 98 105 132 136 114 114 133 108 111 136 135 125 134 139 119 132 121 127 109 132 132 115 105 128 126 143 105 132 121 141 128 109 139 125 116 128 133 117 127 94 125 138 137 132 117 101 108 124 107 133 133 120 136 127 146 143 139 122 148 138 124 124 101 118 122 122 126 147 126 129 119 117 147 120 105 123 124 107 117 117 126 106 122 131 124 133 133 114 96 132 122 145 128 123 114 117 133 114 131 132 132 128 137 121 112 128 133 120 132 94 139 125 110 101 132 93 135 120 134 114 137 116 118 117 123 126 127 122 146 129 134 155 125 123 114 144 112 106 138 102 108 130 132 135 113 128 142 126 121 110 145 112 101 128 133 128 107 125 116 127 130 115 128 124 130 118 112 130 131 145 116 128 131 123 123 118 121 117 124 117 119 123 97 129 128 123 134 142 133 139 121 113 143 105 123 129 129 141 106 105 129 119 113 125 125 119 119 138 132 126 122 125 126 121 124 118 130 123 128 157 124 134 113 123 143 116 130 123 126 129 125 117 110 144 123 114 140 115 110 131 103 122 128 130 124 113 132 135 125 117 121 108 116 130 137 120 108 129 138 126 123 125 143 121 119 136 122 129 130 131 112 128 128 132 111 111 101 115 130 134 107 145 106 147 135 121 131 128 123 125 114 122 102 112 128 141 127 142 133 129 131 126 141 115 102 130 116 117 119 124 114 118 132 103 131 121 114 124 124 122 135 127 129 134 152 137 141 117 124 121 117 135 128 126 116 108 119 128 123 133 140 120 119 125 149 134 133 127 123 112 130 124 123 119 116 115 134 146 124 120 128 135 115 113 118 129 118 129 140 134 114 130 124 119 137 123 126 145 103 109 143 126 121 113 116 109 126 117 132 126 141 131 139 128 119 132 125 144 128 134 134 125 125 137 115 138 148 128 128 139 132 115 132 129 137 132 135 126 108 114 160 125 136 122 108 134 139 150 135 140 125 133 129 137 127 138 125 150 132 143 141 134 124 122 121 126 134 120 127 155 137 137 138 135 112 118 130 111 124 137 141 142 131 144 133 119 120 134 121 129 122 156 123 115 116 133 123 134 145 133 154 123 130 143 136 137 135 143 131 152 127 138 118 121 112 119 139 156 145 107 124 120 127 128 123 114 124 112 125 134 142 128 151 117 134 141 122 97 118 140 117 129 128 133 138 140 138 145 122 141 140 126 100 126 136 127 140 124 131 135 135 119 108 119 122 119 128 140 146 136 129 151 133 132 125 104 115 139 108 118 126 135 135 105 121 129 129 146 109 128 127 128 119 129 117 128 117 120 126 116 141 119 131 120 117 104 137 148 129 143 124 127 109 106 129 131 99 145 125 118 138 131 122 142 125 140 129 113 114 106 132 122 130 142 123 130 128 124 115 116 109 124 129 119 124 136 117 122 119 125 146 118 124 98 113 118 133 136 121 125 122 123 120 160 122 125 112 126 139 120 139 108 124 117 124 134 111 130 125 133 114 142 120 119 138 111 127 143 137 111 131 121 134 121 126 125 139 123 134 116 126 105 101 126 142 114 124 123 129 124 130 123 107 125 120 123 125 107 132 117 118 121 128 129 115 142 133 122 130 98 134 100 106 126 125 122 126 117 144 118 123 113 114 117 124 114 126 128 96 112 137 102 141 147 126 113 141 119 127 114 132 123 140 107 145 125 127 130 127 129 97 131 120 117 119 137 126 112 129 133 113 134 106 150 136 124 124 135 139 136 131 126 133 109 132 116 124 117 125 124 131 120 150 126 108 111 144 113 114 120 131 133 133 121 116 119 100 119 132 106 125 122 123 129 140 101 116 110 131 131 116 140 143 124 108 143 131 117 127 116 115 115 138 104 125 120 137 134 135 127 114 120 129 98 93 114 107 114 124 108 116 123 132 116 122 132 111 132 116 127 148 111 135 122 109 109 116 128 139 121 111 117 135 108 113 125 127 114 121 151 121 116 138 126 113 139 106 133 124 130 114 122 129 146 137 132 121 112 110 140 124 125 115 108 120 122 119 118 109 126 148 122 118 127 136 127 125 130 131 120 113 128 113 130 121 115 107 126 118 109 125 114 124 114 133 123 127 125 115 103 124 126 137 126 114 137 122 114 104 126 138 133 106 121 127 127 113 113 116 120 117 103 118 120 117 133 115 135 112 146 102 136 125 109 117 121 131 124 109 121 122 128 133 136 110 117 120 129 136 137 139 112 127 137 113 113 119 122 120 113 132 131 129 133 139 128 126 133 130 123 113 122 85 105 124 140 122 128 121 121 110 144 130 124 130 128 135 124 127 122 146 120 141 112 111 122 120 102 144 126 118 113 128 129 117 128 130 155 123 124 140 120 120 138 126 141 109 138 121 122 122 128 120 116 127 118 139 141 118 111 105 115 144 120 132 122 119 138 111 134 102 96 130 135 126 113 117 131 151 120 128 136 122 124 139 131 123 126 126 121 140 135 124 116 99 113 127 117 133 120 125 102 112 114 133 139 113 115 123 125 108 120 112 134 133 116 134 105 136 113 133 127 114 107 139 129 100 131 127 130 109 140 137 134 128 111 118 118 116 113 114 138 138 136 129 114 116 134 114 136 128 139 121 115 141 130 115 137 160 121 115 123 122 115 133 119 126 120 136 110 115 103 146 140 113 102 140 97 119 118 132 128 121 117 106 124 121 115 122 125 135 117 120 117 120 127 103 128 130 130 132 133 117 132 123 119 137 113 168 113 147 121 112 120 121 127 130 123 139 134 108 139 111 112 118 123 124 117 124 115 115 122 97 144 120 116 124 118 122 124 129 114 124 116 127 112 121 107 125 119 124 130 132 125 134 119 123 126 137 127 123 129 119 123 115 113 124 134 118 123 117 124 107 114 130 115 128 129 117 140 110 117 122 112 128 137 125 112 120 113 135 126 114 133 130 117 123 118 125 138 128 118 155 123 121 117 137 109 129 109 136 131 132 114 139 103 119 120 115 117 115 113 116 133 131 108 116 128 124 139 125 127 125 100 124 115 129 114 114 134 130 127 111 107 122 107 121 125 139 111 121 130 137 128 124 113 131 109 103 111 129 141 119 108 129 137 96 99 103 137 120 147 117 108 134 118 126 120 129 143 129 112 116 131 124 132 113 125 111 139 89 111 118 118 119 131 125 135 125 135 133 109 131 117 154 115 124 124 145 147 128 126 121 101 97 102 145 132 119 117 114 116 154 132 147 128 123 143 142 111 149 108 143 123 128 142 109 123 131 120 126 133 91 118 136 124 118 112 120 113 137 119 105 112 126 132 112 136 111 122 124 119 147 132 117 135 120 120 133 119 126 126 124 115 136 116 142 137 126 147 121 107 125 127 139 123 119 113 131 115 126 111 142 109 119 105 138 125 126 133 111 121 140 125 143 115 119 126 129 132 125 129 128 127 125 131 132 121 121 121 126 144 138 149 153 144 119 125 134 115 105 134 113 120 141 130 109 117 152 127 144 129 118 103 136 120 125 110 137 123 121 125 120 127 130 108 116 146 127 151 114 130 128 116 95 138 119 121 126 125 139 143 141 120 133 120 142 112 132 116 116 112 118 124 132 124 134 126 129 138 135 134 123 128 125 133 143 128 128 125 129 113 112 128 110 143 103 116 120 138 117 110 109 145 134 129 151 115 119 129 136 142 130 117 120 127 119 126 136 127 116 130 124 122 150 127 104 123 117 137 113 125 130 127 130 131 123 139 107 138 117 121 145 125 138 128 125 126 137 120 127 132 146 111 144 134 122 108 133 142 131 132 116 118 132 117 122 134 127 137 120 123 117 126 132 126 109 112 112 136 124 138 133 135 120 119 124 134 123 130 138 128 122 146 119 133 135 120 134 121 130 143 124 121 123 118 126 127 137 125 127 118 133 116 140 130 119 122 123 147 128 124 123 129 149 135 127 131 132 125 139 139 142 140 132 114 145 138 120 131 130 117 114 118 116 129 126 129 117 128 119 127 126 136 114 116 143 135 148 123 114 127 138 128 139 126 118 134 135 130 141 112 131 118 135 102 131 132 108 144 119 139 122 111 107 117 110 121 128 144 129 116 133 117 107 114 112 131 125 103 137 144 115 151 121 134 108 127 108 118 129 109 122 124 127 125 129 133 136 129 122 132 128 114 137 119 150 112 118 115 130 113 124 115 121 122 103 118 106 102 114 121 114 138 120 117 127 106 146 112 105 135 126 120 124 116 138 110 119 130</counts>
			</dataPoints>
		</scan>
	</xrdMeasurement>
</xrdMeasurements>