File: data/XRD/_misc/old/XG-650C/W6821-1A_absolute_2th-om_10-130deg_PIXscan_56min_1.xrdml
<xrdMeasurements xmlns="http://www.xrdml.com/XRDMeasurement/2.1" xmlns:xsi="http://www.w3.org/2001/XMLSchema-instance" xsi:schemaLocation="http://www.xrdml.com/XRDMeasurement/2.1 http://www.xrdml.com/XRDMeasurement/2.1/XRDMeasurement.xsd" status="Completed">
	<comment>
		<entry>Configuration=Factory configuration, Owner=User-1, Creation date=7/8/2013 4:01:53 PM</entry>
		<entry>Goniometer=PW3050/65 (Theta/2Theta); Minimum step size 2Theta:0.0001; Minimum step size Omega:0.0001</entry>
		<entry>Sample stage=MRD Cradle; Minimum step size Phi:0.01; Minimum step size Chi:0.01; Minimum step size X:0.01; Minimum step size Y:0.01; Minimum step size Z:0.001</entry>
		<entry>Diffractometer system=XPERT-PRO</entry>
		<entry>Measurement program=C:\PANalytical\Data Collector\Programs\Jorrit\2thom\_absolute_2th-om_10-130deg_PIXscan_56min.xrdmp, Identifier={15BCCF57-2807-42BD-B5B9-ECC0B3DC9284}</entry>
		<entry>Batch program=C:\PANalytical\Data Collector\Programs\SimonL\batch4x_2thom_10-130°_z9.1_x0,10,20,30_y0_57min.xrdmp, Identifier={EED9823A-2BEB-424C-9252-345C4EF2834A}</entry>
	</comment>
	<sample type="To be analyzed">
		<id></id>
		<name></name>
		<preparedBy></preparedBy>
	</sample>
	<xrdMeasurement measurementType="Scan" status="Completed" sampleMode="Reflection">
		<comment>
			<entry>_absolute_2th-om_10-130deg_PIXscan_56min</entry>
			<entry>PHD Lower Level = 4.83 (keV), PHD Upper Level = 11.27 (keV)</entry>
		</comment>
		<usedWavelength intended="K-Alpha 1">
			<kAlpha1 unit="Angstrom">1.5405980</kAlpha1>
			<kAlpha2 unit="Angstrom">1.5444260</kAlpha2>
			<kBeta unit="Angstrom">1.3922500</kBeta>
			<ratioKAlpha2KAlpha1>0.5000</ratioKAlpha2KAlpha1>
		</usedWavelength>
		<incidentBeamPath>
			<radius unit="mm">320.00</radius>
			<xRayTube id="1010048" name="Empyrean Cu LFF HR (9430 033 7310x) DK442154">
				<tension unit="kV">40.0</tension>
				<current unit="mA">40.0</current>
				<anodeMaterial>Cu</anodeMaterial>
				<focus type="Line">
					<length unit="mm">12.0</length>
					<width unit="mm">0.4</width>
					<takeOffAngle unit="deg">4.2</takeOffAngle>
				</focus>
			</xRayTube>
			<xRayMirror id="27010001" name="Inc. Beam Cu W/Si (parabolic MRD)" hybrid="false">
				<crystal type="Graded" shape="Parabolic">W/Si</crystal>
				<acceptanceAngle unit="deg">0.800</acceptanceAngle>
				<length unit="mm">60.0</length>
			</xRayMirror>
			<sollerSlit id="21010002" name="Soller slits 0.04 rad.">
				<opening unit="rad">0.0400</opening>
			</sollerSlit>
			<mask id="22030007" name="Fixed mask 2 mm">
				<distanceToSample unit="mm">220.00</distanceToSample>
				<width unit="mm">2.00</width>
			</mask>
			<divergenceSlit id="22010007" name="Fixed slit 1/8°" xsi:type="fixedDivergenceSlitType">
				<distanceToSample unit="mm">220.00</distanceToSample>
				<height unit="mm">0.19</height>
			</divergenceSlit>
		</incidentBeamPath>
		<diffractedBeamPath>
			<radius unit="mm">320.00</radius>
			<sollerSlit id="21010002" name="Soller slits 0.04 rad.">
				<opening unit="rad">0.0400</opening>
			</sollerSlit>
			<receivingSlit id="22010001" name="Fixed slit 4°">
				<height unit="mm">5.88</height>
			</receivingSlit>
			<detector id="7010017" name="PIXcel3D 1x1 detector" xsi:type="areaDetectorType">
				<phd unit="%">
					<lowerLevel>30.0</lowerLevel>
					<upperLevel>70.0</upperLevel>
				</phd>
				<mode>Scanning</mode>
				<activeChannelsEquatorial>255</activeChannelsEquatorial>
				<activeChannelsAxial>255</activeChannelsAxial>
				<pitchEquatorial unit="mm">0.05500</pitchEquatorial>
				<pitchAxial unit="mm">0.05500</pitchAxial>
				<readOutPeriod unit="seconds">0.135</readOutPeriod>
			</detector>
		</diffractedBeamPath>
		<scan appendNumber="0" mode="Continuous" scanAxis="2Theta-Omega" status="Completed">
			<header>
				<startTimeStamp>2024-08-29T18:17:15+02:00</startTimeStamp>
				<endTimeStamp>2024-08-29T19:13:20+02:00</endTimeStamp>
				<author>
					<name>PRO-MRD</name>
				</author>
				<source>
					<applicationSoftware version="6.1b">Data Collector</applicationSoftware>
					<instrumentControlSoftware version="7.0E 20130304">XPERT-PRO</instrumentControlSoftware>
					<instrumentID>0000000011142674</instrumentID>
				</source>
			</header>
			<dataPoints>
				<positions axis="2Theta" unit="deg">
					<startPosition>9.99826193</startPosition>
					<endPosition>129.99755682</endPosition>
				</positions>
				<positions axis="Omega" unit="deg">
					<startPosition>4.99913096</startPosition>
					<endPosition>64.99877841</endPosition>
				</positions>
				<positions axis="Phi" unit="deg">
					<commonPosition>0.00</commonPosition>
				</positions>
				<positions axis="Chi" unit="deg">
					<commonPosition>0.00</commonPosition>
				</positions>
				<positions axis="X" unit="mm">
					<commonPosition>0.00</commonPosition>
				</positions>
				<positions axis="Y" unit="mm">
					<commonPosition>0.00</commonPosition>
				</positions>
				<positions axis="Z" unit="mm">
					<commonPosition>9.100</commonPosition>
				</positions>
				<commonCountingTime unit="seconds">32.895</commonCountingTime>
				<counts 217 239 216 247 244 227 223 221 227 237 213 231 212 227 235 213 215 217 229 224 237 256 202 224 233 216 195 217 238 239 214 211 209 233 210 234 192 242 201 224 229 229 221 224 226 218 228 257 189 205 226 241 222 237 227 247 222 220 226 212 219 206 205 209 237 208 224 233 211 224 226 247 195 215 219 188 225 202 230 259 218 212 223 211 231 229 234 219 188 208 227 200 228 208 221 190 210 202 204 232 241 237 228 190 195 230 233 199 219 218 208 208 204 202 224 205 228 217 197 226 196 214 212 227 207 233 188 228 205 191 209 217 225 225 240 216 214 198 219 191 210 207 201 227 223 204 185 212 212 182 216 198 213 209 209 196 227 191 185 224 209 197 211 214 205 222 194 203 175 210 186 208 233 186 212 215 199 215 210 208 200 180 205 189 213 186 218 191 218 171 208 216 199 231 205 206 219 229 204 218 213 171 208 213 187 194 190 206 190 221 186 215 233 202 205 194 207 215 193 194 194 205 216 179 194 197 219 180 194 205 225 212 194 200 200 184 214 206 216 220 189 190 203 230 206 211 175 221 204 207 193 211 202 173 200 202 200 204 192 163 196 187 172 172 200 184 196 184 186 184 192 183 220 190 195 212 210 212 197 185 203 193 175 181 187 224 209 183 173 223 186 212 204 191 187 186 188 207 198 213 196 164 190 204 189 163 182 184 193 180 189 167 186 159 204 198 187 168 198 200 164 176 159 198 214 163 189 189 184 175 172 198 197 209 186 175 195 189 179 193 213 177 184 204 169 177 193 178 174 197 189 168 187 184 184 176 204 164 205 164 177 192 165 169 180 185 174 197 172 178 172 201 184 176 174 186 156 167 160 149 193 193 174 185 168 203 203 159 187 180 179 175 168 173 171 189 165 198 196 163 170 155 165 185 187 170 183 196 187 186 179 187 169 193 182 173 182 173 165 193 166 177 170 192 186 166 163 195 180 161 183 178 179 165 191 174 172 181 199 139 153 185 152 172 197 196 188 182 168 179 160 151 168 159 160 190 155 166 184 174 184 164 182 183 190 181 192 150 167 160 195 168 156 174 172 156 166 182 185 158 165 162 185 173 181 160 168 168 214 172 171 176 153 157 179 172 156 175 189 175 171 188 163 162 158 157 167 168 170 165 161 178 189 184 168 182 176 164 177 169 161 166 160 166 154 146 174 161 175 139 163 163 164 178 131 173 175 170 177 166 181 153 163 179 156 161 182 169 166 180 163 199 152 161 156 171 190 169 161 166 172 188 160 161 193 173 147 192 159 179 149 170 158 169 144 166 169 155 146 197 180 143 169 167 163 142 166 172 156 153 164 159 156 185 191 151 175 168 179 177 161 171 186 158 165 164 155 145 158 146 166 167 145 180 172 155 151 167 151 175 168 161 181 160 152 169 161 169 157 170 171 161 158 140 171 134 155 155 180 155 146 131 180 135 155 163 172 174 162 178 161 147 176 139 174 152 166 169 163 171 151 174 160 175 154 190 142 171 198 147 159 151 147 163 149 147 168 153 152 147 185 170 189 151 163 182 169 164 161 161 176 158 172 184 167 175 150 166 154 152 172 151 161 169 148 149 163 164 163 173 184 138 134 154 159 145 149 172 181 147 169 148 190 160 179 162 145 172 166 175 158 149 149 157 139 166 148 175 171 156 154 148 150 164 150 182 161 137 160 150 159 165 159 147 180 162 151 167 157 174 142 161 166 164 166 154 155 172 168 163 149 178 164 167 145 162 147 140 147 134 143 155 137 167 167 157 163 177 161 178 156 151 140 138 124 191 147 153 157 174 180 154 158 161 156 164 160 173 167 168 155 181 190 138 168 166 168 150 161 153 135 158 163 175 190 160 177 168 145 160 174 162 154 150 158 168 151 157 158 141 162 186 157 153 175 155 156 156 179 157 161 168 167 170 150 158 160 159 153 180 169 170 132 179 153 156 152 144 160 156 181 157 158 175 182 175 172 158 155 164 162 151 151 184 159 141 169 167 170 172 164 182 164 156 177 156 158 144 130 143 189 163 171 168 156 156 159 157 156 155 152 162 184 163 163 173 176 153 181 191 169 152 160 163 177 169 152 159 181 146 161 151 150 158 175 166 149 144 178 154 163 169 168 190 167 165 167 171 177 164 188 177 156 158 165 172 168 170 158 142 179 150 160 186 163 195 168 131 181 159 151 189 158 162 144 174 171 168 164 156 172 163 187 146 160 190 190 157 164 159 167 177 203 168 181 180 152 144 163 178 147 163 158 166 191 177 180 162 178 171 205 160 168 162 180 184 177 154 178 185 143 171 162 160 180 191 200 158 153 159 153 168 175 143 175 157 169 154 157 181 173 180 158 199 149 167 187 161 160 156 193 152 177 161 168 172 174 163 163 181 168 162 154 165 185 170 171 168 166 150 177 178 201 183 160 162 176 168 166 180 165 167 180 157 182 150 159 160 151 167 167 157 156 162 194 163 170 152 159 133 172 166 168 169 162 187 185 184 183 166 169 138 173 170 163 172 164 182 184 166 174 185 176 179 178 154 145 176 185 180 174 170 169 167 170 147 176 165 171 177 180 170 183 173 174 184 171 155 161 183 182 168 188 160 158 189 174 158 161 171 178 187 151 168 162 194 171 187 155 189 166 164 153 174 191 183 164 165 170 168 177 175 161 179 167 189 155 154 176 166 179 164 169 180 166 153 155 153 182 192 178 183 180 172 177 171 150 188 202 181 209 173 177 197 155 172 188 186 178 152 161 172 180 173 169 171 169 167 143 179 168 208 153 172 164 170 161 175 176 183 151 189 160 167 161 145 171 166 175 157 162 181 176 176 181 173 218 193 174 172 184 175 181 157 173 192 168 172 165 187 172 168 147 173 177 165 143 200 186 179 166 160 203 166 167 161 161 157 183 168 154 170 174 157 163 163 173 206 196 180 176 176 147 167 152 174 172 173 172 182 188 165 174 149 189 183 189 179 183 171 169 165 166 159 166 178 180 177 187 169 184 184 150 148 173 185 182 167 171 184 175 155 153 193 189 164 168 152 178 181 159 177 158 183 157 166 180 173 175 159 193 167 206 171 176 155 176 182 194 191 187 151 169 172 182 163 157 185 185 189 178 145 159 173 182 154 181 151 172 179 173 171 171 184 166 147 173 205 158 170 150 161 146 169 156 152 163 158 173 167 175 176 168 170 182 149 177 160 155 169 160 193 154 159 158 166 178 162 161 175 176 150 183 190 168 161 180 153 148 174 172 158 172 158 170 153 175 178 168 184 150 161 186 170 176 180 160 191 165 156 164 157 166 161 169 161 177 157 167 147 160 178 186 175 163 148 160 145 164 155 152 150 174 181 176 155 154 172 173 158 148 157 173 155 171 178 161 185 179 154 156 160 148 159 140 178 167 145 163 179 178 157 166 160 156 175 168 166 162 178 147 153 156 174 177 186 147 168 169 154 154 161 136 167 168 128 147 146 178 155 148 159 163 159 171 191 155 165 150 172 157 154 156 148 158 172 162 178 151 174 180 148 150 160 164 144 158 161 138 138 142 144 163 132 167 162 161 161 126 157 162 159 144 176 167 165 158 176 152 174 167 134 160 157 135 165 150 167 168 157 154 187 160 155 151 169 162 163 146 137 167 165 176 170 151 176 140 157 183 167 169 152 154 160 169 158 174 167 148 147 163 158 154 175 159 174 145 157 150 162 163 142 148 175 138 139 166 181 147 169 145 147 143 140 154 161 181 158 151 165 157 170 129 146 164 153 145 166 156 163 169 158 124 158 141 157 158 163 146 145 150 139 159 155 171 116 144 163 154 161 168 125 149 141 173 143 152 154 150 161 157 151 137 154 133 142 144 126 153 144 152 148 167 157 165 164 139 149 144 136 155 129 147 119 158 148 152 146 134 149 159 155 156 162 162 127 144 165 148 131 158 151 182 138 152 154 162 150 156 162 144 165 150 135 155 144 138 156 133 159 150 152 140 142 143 145 153 166 144 135 140 150 142 164 178 149 149 154 154 160 135 160 150 169 156 138 156 158 146 144 129 120 121 128 147 178 151 137 142 127 167 161 135 134 153 138 129 148 151 149 120 136 134 145 138 117 146 152 139 141 149 141 133 153 118 142 134 141 124 146 158 134 174 131 129 124 152 142 125 123 140 155 149 154 139 135 137 143 141 140 134 147 129 135 141 131 120 141 134 139 122 151 152 136 137 148 158 130 149 144 122 133 134 149 143 140 137 125 124 107 122 150 149 153 156 158 136 153 129 142 138 135 151 155 149 135 139 138 124 172 142 143 134 136 144 149 132 165 136 111 118 131 131 148 123 153 156 148 114 148 138 156 157 172 163 133 153 150 158 130 145 142 133 117 141 124 147 137 150 135 149 135 153 133 132 137 160 128 137 139 152 145 156 136 155 128 154 153 137 133 123 146 133 141 131 147 120 139 154 144 146 134 146 130 158 136 136 143 156 122 154 128 140 131 129 127 146 147 153 129 129 139 129 129 127 135 135 131 166 143 161 126 132 122 153 128 132 127 146 155 132 136 130 145 120 142 132 127 151 145 152 141 111 98 132 143 133 135 141 141 146 129 124 120 124 148 141 137 110 140 139 151 138 113 135 123 125 140 136 147 134 145 140 140 135 122 146 131 148 125 116 153 129 123 122 143 140 126 150 129 154 148 135 130 141 118 149 128 105 115 140 151 135 145 136 131 140 137 132 121 119 145 127 128 134 96 140 124 133 126 120 114 130 137 135 129 136 133 135 142 142 123 131 139 113 135 136 124 114 124 140 126 148 142 124 138 126 140 139 131 142 142 116 122 130 127 138 132 120 130 161 125 111 124 145 133 134 127 132 134 141 129 127 127 134 133 131 131 122 144 164 127 138 133 126 130 130 114 162 126 130 122 148 125 135 125 112 153 135 122 122 127 152 149 134 129 128 161 130 141 137 135 134 148 123 139 127 125 155 122 124 127 128 142 127 115 118 126 123 131 131 135 149 139 142 124 135 139 126 119 119 161 135 121 144 139 144 119 112 131 124 136 114 133 129 142 136 152 123 131 112 120 112 143 125 128 139 135 138 128 142 125 133 139 114 137 131 134 124 131 112 123 122 149 118 123 119 112 138 124 118 117 139 123 123 129 111 136 141 126 147 114 152 132 144 141 125 135 158 144 146 120 132 133 109 144 131 124 128 124 148 121 131 137 135 128 130 132 123 130 130 129 116 124 143 132 131 127 141 117 131 144 129 125 119 124 125 129 127 129 139 136 126 102 112 147 144 119 126 120 134 131 128 125 129 123 119 138 139 131 131 125 122 123 140 134 134 135 118 123 111 122 132 122 133 141 115 148 127 123 115 113 110 138 149 128 137 134 139 119 115 124 123 122 113 119 121 125 130 117 114 119 108 137 115 115 128 105 105 126 119 133 112 129 124 120 124 126 136 126 132 154 123 128 128 142 130 136 142 127 146 154 132 111 127 135 123 139 136 115 109 121 140 124 139 127 139 133 115 119 108 117 125 115 122 127 148 142 126 143 131 112 113 123 125 134 125 135 127 135 115 110 123 122 125 131 115 99 132 131 133 141 123 137 111 120 130 134 126 137 125 121 135 115 119 122 138 107 115 116 159 128 125 120 128 120 113 124 118 131 141 131 119 123 123 116 123 130 140 143 137 124 132 132 135 121 118 134 149 130 142 133 115 140 134 129 141 118 113 145 130 119 141 137 137 111 134 105 139 164 112 115 115 123 147 121 119 123 128 119 138 129 133 116 142 113 117 118 121 120 122 130 128 132 125 112 111 126 133 150 138 128 143 139 135 128 135 136 125 138 144 119 121 131 113 118 126 108 129 126 147 128 146 146 143 119 122 133 127 128 116 106 131 110 129 140 115 126 131 113 116 126 115 117 115 111 127 114 121 136 121 109 125 116 123 125 112 150 123 161 117 124 143 126 128 128 140 121 132 152 133 112 136 133 156 166 128 116 141 122 122 113 115 132 130 151 135 139 142 125 111 130 141 125 145 122 111 116 144 132 125 143 125 120 126 107 129 122 139 124 130 119 132 149 126 107 139 121 127 116 112 118 122 119 118 131 124 115 110 123 124 118 114 134 128 139 119 146 101 125 138 122 136 127 121 117 105 122 114 122 130 118 138 130 133 124 124 130 129 111 143 127 138 126 132 141 128 130 113 117 138 140 118 123 113 129 142 134 118 125 129 113 121 112 117 122 129 119 143 117 131 117 109 115 127 124 139 129 105 125 116 128 106 129 134 137 134 117 129 133 120 128 132 145 145 117 115 125 112 123 126 124 110 116 136 119 120 125 128 124 128 120 115 124 127 113 119 132 109 115 144 125 131 116 120 128 123 114 141 135 101 142 126 130 128 121 117 122 130 109 134 121 122 108 146 124 146 134 138 121 121 126 137 134 132 128 112 103 130 129 130 120 146 129 117 119 115 101 102 142 124 137 123 114 116 119 151 127 138 133 132 124 113 140 116 135 120 117 125 87 94 140 128 134 108 113 126 134 118 130 130 124 131 140 113 147 143 115 146 131 131 126 116 128 117 132 150 139 131 105 156 131 119 123 114 122 124 128 147 124 125 119 129 142 134 128 129 121 135 120 112 124 130 152 122 127 118 138 130 112 103 110 114 125 135 113 133 123 126 134 118 137 119 95 151 122 119 123 129 124 114 139 115 117 124 108 129 121 139 120 117 118 117 115 117 112 111 135 136 110 118 117 130 115 147 130 112 127 141 138 110 130 137 126 120 134 117 102 117 102 135 135 130 134 115 116 129 124 92 114 114 132 122 136 115 132 141 120 126 113 123 131 141 141 141 121 102 147 139 129 112 141 124 113 129 123 132 153 152 112 147 133 128 120 135 120 132 139 131 117 135 138 122 111 154 129 108 114 136 102 119 113 135 126 145 140 107 126 119 137 128 123 141 133 126 127 135 146 128 127 101 126 134 127 152 136 132 140 128 103 130 124 118 130 129 137 109 122 126 134 110 132 132 125 128 124 126 111 135 128 125 124 111 134 137 125 124 115 136 127 130 126 118 135 111 148 123 129 113 128 133 121 115 115 170 122 124 121 131 120 122 149 115 130 128 117 135 122 138 122 147 130 131 130 141 147 98 152 132 151 108 133 122 129 148 131 128 115 138 138 142 125 114 139 114 129 124 120 138 119 136 148 122 123 125 122 128 122 131 149 126 140 144 128 139 121 115 115 128 120 106 142 130 129 151 125 138 125 116 124 125 131 133 133 128 134 137 120 131 132 134 114 134 130 120 119 143 120 124 137 110 149 127 136 138 121 126 129 134 141 143 109 125 116 125 118 124 128 127 140 134 150 115 116 123 113 132 115 130 120 132 139 133 135 124 115 123 135 131 129 134 148 119 128 125 122 110 134 112 125 117 159 128 115 137 134 141 128 114 121 98 116 115 110 129 120 132 139 118 118 128 135 117 116 126 134 131 143 127 120 122 109 122 120 136 141 136 157 144 132 142 127 122 141 133 132 121 137 138 135 112 115 121 126 131 128 133 154 111 129 114 122 119 135 154 126 137 128 139 139 118 129 156 118 143 124 132 148 144 127 131 134 134 154 122 149 121 144 118 125 101 140 120 127 133 133 122 129 142 142 142 138 142 139 144 133 147 138 133 134 143 113 135 144 151 146 132 126 151 144 148 135 120 128 144 155 133 140 129 168 130 143 132 131 134 141 143 140 139 149 145 154 143 146 124 143 154 142 152 144 143 144 155 152 166 134 159 138 142 165 170 154 146 168 154 168 140 136 169 146 128 140 148 144 170 160 178 168 170 169 164 189 179 178 182 178 200 188 172 193 241 193 207 227 198 216 243 238 211 232 231 255 258 282 227 272 236 263 256 218 285 247 222 237 238 217 193 207 187 191 203 205 199 177 203 186 159 171 173 153 154 166 168 169 141 145 144 166 165 152 169 120 129 154 146 147 139 158 136 130 145 138 137 152 133 123 141 142 143 159 123 116 140 173 148 146 137 123 137 138 124 136 130 149 147 130 123 115 138 141 146 142 131 129 146 135 156 153 127 134 124 119 122 121 136 126 160 113 142 127 151 115 139 130 129 128 127 91 125 116 139 122 118 132 122 119 145 140 128 145 133 149 135 135 132 127 137 134 125 119 126 120 143 114 141 125 140 116 119 104 147 153 126 124 112 153 126 123 112 134 118 121 131 105 115 121 125 140 121 136 132 126 140 139 116 116 127 143 121 123 134 129 137 142 113 143 129 129 129 116 123 138 123 108 143 129 121 142 123 134 128 124 106 139 136 126 112 131 129 138 127 124 120 131 124 104 146 127 114 130 126 124 121 135 126 126 127 143 135 132 129 123 114 144 119 142 139 124 152 115 122 138 127 129 146 123 128 130 124 130 140 118 133 117 132 108 119 130 123 130 145 133 134 135 127 139 146 132 139 126 143 132 128 151 133 152 135 130 128 109 131 113 131 154 122 144 130 133 126 133 118 113 136 154 128 123 118 126 127 111 131 126 135 136 152 132 114 135 122 129 103 129 130 130 116 123 150 136 133 109 143 120 127 140 122 125 129 113 124 121 137 126 132 127 124 125 130 126 119 126 120 148 113 125 109 113 124 144 117 123 118 124 120 127 131 94 118 136 118 138 125 139 113 111 129 126 113 121 133 122 131 126 119 133 137 149 144 142 140 133 132 126 113 139 118 143 137 122 142 152 119 130 137 135 147 131 115 139 142 136 146 126 114 114 127 128 146 129 126 124 139 135 134 117 132 125 130 132 148 129 154 128 118 120 124 126 115 133 118 114 125 127 147 112 126 122 141 144 148 120 115 160 140 118 131 117 142 105 130 125 124 116 130 144 128 137 129 135 112 124 126 139 123 129 129 142 130 118 134 128 111 129 133 116 131 132 108 117 124 121 142 121 136 147 141 129 129 125 118 133 141 125 150 115 137 138 118 141 121 145 140 136 139 124 123 127 124 127 123 130 126 123 127 129 127 130 140 114 134 135 116 137 114 125 144 126 131 141 137 135 121 124 127 129 130 140 112 146 115 129 138 119 117 155 130 118 119 120 126 129 129 131 120 113 131 139 129 114 128 121 130 101 114 130 135 121 123 127 152 125 127 127 137 108 127 122 131 123 120 131 136 146 138 132 141 140 156 126 120 124 118 131 125 122 130 145 127 117 153 129 130 148 133 146 122 119 146 136 134 138 132 138 124 120 110 122 116 138 128 134 142 121 147 135 111 125 130 100 109 115 136 124 122 120 123 116 124 128 150 136 117 136 135 131 120 126 132 120 118 134 116 131 144 122 128 130 124 122 110 107 113 150 131 115 122 136 115 131 132 130 125 128 139 138 136 118 115 132 139 139 129 131 110 130 126 129 141 139 124 104 133 111 139 120 121 131 118 128 119 113 121 142 145 127 130 124 136 149 138 152 136 134 128 118 120 145 123 134 128 130 139 134 107 129 115 115 121 130 118 132 141 125 121 117 130 129 122 134 124 126 130 128 112 134 154 133 137 141 130 127 112 118 141 132 127 121 133 111 130 128 149 133 132 126 122 131 138 130 132 130 129 131 125 135 148 125 127 129 138 123 112 130 144 118 121 123 130 131 131 152 129 128 116 133 130 127 134 109 148 108 136 143 112 118 133 130 120 131 116 127 134 136 110 136 135 123 128 147 144 128 141 136 113 145 138 162 132 134 119 116 147 120 124 145 112 127 162 124 133 121 126 125 131 131 142 121 121 109 137 112 112 134 141 129 140 150 119 119 128 120 130 140 129 135 110 117 133 121 142 136 152 128 103 136 138 127 132 144 142 138 122 144 116 135 116 141 154 126 129 128 134 113 123 110 111 116 119 107 137 127 111 152 140 158 129 129 105 120 132 126 139 146 135 130 107 148 132 129 131 101 132 116 152 146 119 137 127 133 142 140 139 139 131 143 132 137 134 130 125 132 138 122 149 134 108 130 154 108 138 122 123 117 128 129 111 133 132 142 119 152 120 139 136 149 130 133 112 134 148 122 123 137 127 134 131 128 135 130 130 117 145 131 109 121 133 116 145 114 123 141 149 154 134 146 119 137 118 111 133 132 127 137 121 123 137 121 112 117 124 133 112 119 126 136 133 118 136 132 146 127 125 120 117 138 138 131 131 129 136 133 115 128 138 136 132 136 124 132 141 122 126 126 121 142 130 131 125 126 123 124 137 153 142 119 121 128 135 129 124 138 137 143 138 131 122 108 134 127 122 130 137 115 132 128 112 128 145 113 148 130 144 137 111 127 135 133 115 101 108 122 116 113 125 128 126 137 115 129 141 139 140 117 116 118 142 138 131 129 132 116 140 130 118 140 127 122 129 127 115 132 113 133 140 120 133 140 131 124 131 129 140 127 125 112 129 132 147 125 128 137 128 127 127 137 134 140 139 147 125 137 145 120 114 130 122 95 133 149 116 140 126 134 140 118 134 102 113 126 125 112 112 119 129 132 128 128 124 130 131 126 138 119 126 117 145 119 122 130 137 126 130 124 123 134 128 119 126 126 127 140 128 133 114 146 123 115 103 134 141 148 126 130 142 124 136 132 113 147 138 127 122 140 136 141 131 142 123 129 133 107 129 132 133 127 94 136 118 123 125 112 112 128 123 95 123 119 143 121 116 126 129 119 131 129 122 109 133 137 127 131 122 129 159 153 155 129 137 120 138 109 135 114 125 110 134 139 126 136 122 143 128 123 135 119 112 124 129 120 117 134 137 133 139 134 143 136 149 119 133 138 129 135 128 142 129 134 128 111 123 116 127 112 122 122 128 126 145 136 137 141 135 105 120 123 120 130 112 129 137 127 142 136 129 105 115 116 102 151 108 116 126 137 124 142 139 128 131 135 127 118 138 106 118 143 146 135 126 125 112 124 148 128 125 135 139 135 111 127 116 129 127 133 112 119 121 131 122 145 136 120 131 114 135 138 107 114 149 113 115 120 133 149 138 128 121 132 140 145 115 140 119 136 130 122 110 127 126 119 138 113 131 135 133 112 127 141 122 132 136 129 140 128 122 143 127 114 122 127 126 119 129 130 126 137 131 115 132 147 108 125 125 122 127 113 129 126 122 143 138 120 113 123 154 121 114 124 128 135 132 122 137 133 145 133 133 118 119 139 139 122 120 121 122 121 146 113 130 109 123 137 125 120 149 122 121 133 162 124 133 129 140 118 122 112 141 139 121 140 135 140 136 135 145 110 127 132 114 121 128 133 129 116 146 140 115 154 131 123 130 137 143 143 126 127 114 137 133 130 125 114 127 119 130 118 129 135 147 132 125 136 149 128 128 127 160 123 149 123 113 150 155 138 138 123 119 118 137 119 137 141 136 125 131 119 144 142 130 134 121 142 143 118 132 140 146 126 136 124 116 141 131 120 136 134 132 131 117 120 130 132 143 123 134 114 126 135 127 136 129 117 114 130 139 122 126 135 131 126 136 118 147 136 138 120 127 129 118 123 135 146 140 131 129 131 113 122 123 147 136 124 135 146 128 123 130 143 122 130 149 141 143 141 117 141 132 120 128 131 146 125 140 131 121 148 114 136 138 144 123 141 120 134 137 111 131 141 116 111 142 146 144 134 133 115 140 127 129 133 130 128 142 130 146 129 141 130 151 153 137 126 117 135 138 134 122 133 134 116 128 130 112 159 130 140 130 132 150 135 134 119 127 123 131 127 150 143 124 123 135 127 129 132 145 141 139 142 109 131 131 126 120 122 141 140 112 127 157 139 137 147 134 123 128 127 122 136 130 139 127 137 144 120 121 116 142 136 127 135 136 153 137 118 147 139 129 128 145 118 158 128 132 133 134 120 149 128 126 124 128 126 134 130 128 130 140 150 132 123 129 146 132 107 126 108 154 115 136 134 120 142 124 110 135 131 116 125 132 146 145 118 150 131 112 148 128 112 123 121 115 144 132 135 112 129 133 138 150 132 141 144 125 126 138 115 147 144 141 135 142 111 138 133 124 128 178 130 149 130 146 173 130 108 140 115 139 126 121 112 105 136 140 148 118 127 159 126 137 145 162 153 123 158 134 137 121 121 113 128 134 132 141 150 142 146 109 150 148 149 138 149 128 134 145 137 120 130 130 134 112 118 125 137 131 139 127 112 137 123 137 154 152 117 129 145 128 124 155 112 124 127 128 148 123 131 163 141 128 145 136 133 126 133 143 136 124 157 141 133 137 132 103 145 138 143 138 134 139 136 159 128 156 146 123 121 153 133 110 155 133 111 139 124 131 150 134 125 159 155 144 136 139 122 144 119 144 135 118 133 134 135 126 130 149 130 136 138 114 146 121 136 138 120 114 128 146 120 145 161 149 147 146 144 128 123 128 162 111 151 129 133 140 126 149 146 134 137 152 135 123 105 131 133 123 142 121 136 147 133 149 129 130 139 139 118 142 138 135 139 134 139 147 153 148 129 139 130 134 145 147 116 137 163 141 150 150 138 152 137 149 152 139 133 134 148 146 164 153 146 148 146 168 137 140 156 156 130 167 142 145 131 144 131 147 121 132 130 147 133 162 126 152 144 128 132 153 145 151 141 129 126 137 145 165 148 144 151 128 162 143 140 110 127 121 132 124 130 132 144 152 123 142 145 124 165 151 140 122 129 131 142 152 140 111 146 112 138 135 144 150 147 143 127 130 142 152 128 135 140 142 141 150 132 150 131 138 127 118 145 110 128 149 142 116 131 118 136 118 137 128 126 113 135 122 149 149 135 138 124 147 163 111 154 138 134 138 156 159 141 133 135 146 128 140 148 153 128 129 132 137 139 113 117 122 141 129 111 131 125 127 135 120 136 132 126 124 123 123 134 118 136 149 142 146 126 140 135 133 130 136 146 139 150 127 127 128 121 130 149 125 147 142 136 140 138 127 130 129 139 149 148 128 124 118 136 111 138 113 128 137 117 139 130 133 133 142 116 140 132 118 141 156 134 121 123 136 113 144 127 131 142 128 135 135 137 148 134 133 118 125 123 127 162 128 112 132 128 122 127 127 131 126 126 129 142 127 134 134 125 125 136 137 118 120 147 138 144 118 130 124 138 138 122 133 119 140 124 137 114 130 129 133 133 142 147 150 123 143 124 123 131 138 111 115 136 126 120 131 136 139 134 135 145 130 141 127 116 141 147 124 115 136 136 110 126 125 132 117 128 145 144 152 128 123 105 140 153 129 123 118 125 124 131 117 123 128 133 133 132 117 137 123 130 159 134 117 136 137 125 130 113 112 141 130 125 135 140 112 125 143 135 139 139 138 135 107 143 108 148 162 146 120 141 116 157 134 138 132 154 124 133 122 123 141 144 135 140 133 134 139 119 146 131 119 133 133 132 129 129 153 133 124 120 129 145 139 128 136 136 132 130 134 135 140 127 119 116 122 120 130 128 142 146 155 143 147 153 150 141 136 118 148 135 137 120 143 107 145 130 128 112 124 115 150 132 150 130 130 117 103 136 155 131 132 127 129 139 146 137 128 115 137 138 116 102 146 143 129 145 118 116 144 151 141 128 118 130 132 143 156 124 151 157 137 134 110 130 161 141 130 124 115 120 126 146 139 124 144 134 127 174 119 133 148 151 121 121 127 139 120 125 134 132 130 138 131 127 150 142 112 141 129 114 131 134 120 133 115 131 159 131 119 136 131 133 115 132 133 149 150 105 138 123 138 143 129 144 142 130 158 157 114 136 141 118 128 148 123 138 139 160 125 134 128 102 141 134 130 143 158 143 147 127 140 151 133 107 135 133 158 145 147 138 137 111 161 135 127 118 142 138 123 133 139 125 138 125 126 130 134 126 150 135 126 132 117 130 128 128 140 128 127 120 114 141 110 121 133 144 165 121 138 116 127 134 129 120 137 134 143 119 144 136 126 139 131 128 138 133 117 106 146 110 139 119 133 137 155 129 133 126 112 127 125 135 119 139 118 132 143 132 111 151 131 138 136 144 130 128 128 138 120 119 148 156 119 116 146 99 143 134 120 139 118 144 143 134 138 140 133 143 123 125 133 132 136 143 138 135 123 135 144 122 126 119 128 126 115 143 139 135 140 125 136 146 138 128 128 143 139 127 143 136 136 127 149 120 132 121 142 148 114 127 163 117 145 143 128 147 136 132 108 121 137 141 127 150 146 121 131 151 131 139 121 126 131 118 132 117 147 119 127 126 124 139 122 133 138 121 131 118 135 141 133 131 130 141 140 134 130 114 137 146 139 134 122 137 130 139 105 128 118 136 151 129 132 114 137 138 123 129 144 147 117 130 125 146 132 135 134 122 114 110 128 120 133 121 150 134 135 133 123 140 130 140 140 121 130 135 137 133 149 158 124 120 138 143 145 131 154 141 138 143 123 131 136 137 157 135 113 121 112 163 110 125 140 142 140 122 123 130 134 131 120 148 131 151 151 157 121 128 132 121 140 132 90 129 125 117 140 120 125 125 135 154 133 136 133 120 120 130 118 136 136 124 123 99 138 128 115 137 135 116 117 140 133 139 128 128 135 136 110 137 127 120 131 141 116 122 133 120 174 138 146 132 143 150 117 135 138 128 122 132 128 136 130 115 124 150 131 146 153 121 121 115 145 118 114 151 124 115 128 113 150 131 140 138 116 111 134 135 128 143 144 132 143 119 127 136 113 135 124 147 119 139 135 143 110 133 137 156 129 123 138 129 127 129 117 122 133 141 136 138 124 127 133 132 122 108 145 132 141 147 127 140 141 118 127 140 129 154 123 138 133 129 118 139 148 145 118 166 125 143 139 129 123 147 138 112 120 139 127 110 141 150 128 149 116 130 147 149 142 132 137 144 131 134 133 131 138 118 126 140 128 133 113 130 129 140 126 124 137 128 139 132 122 132 129 124 131 136 141 137 114 137 118 150 138 142 123 123 141 153 126 125 144 126 126 133 122 121 127 112 131 134 145 162 138 133 151 134 139 133 148 130 144 127 125 140 125 123 138 110 134 107 122 129 146 117 119 126 143 136 143 145 129 136 147 130 134 132 139 111 158 127 140 138 130 129 107 124 114 129 125 138 161 107 124 128 126 153 119 136 104 121 128 137 150 120 129 144 139 115 129 140 133 150 133 129 135 123 139 125 138 150 128 122 147 157 137 122 127 149 124 116 116 128 143 131 141 151 107 121 125 128 148 147 123 128 127 136 139 127 132 123 111 139 112 126 122 142 129 124 134 136 135 134 107 117 130 116 133 147 125 119 137 144 138 130 116 140 113 115 128 137 128 141 130 133 131 127 123 140 117 148 149 129 134 122 103 132 140 144 127 118 135 131 134 134 117 126 136 146 133 135 138 123 138 133 123 136 119 126 141 136 128 136 132 125 131 151 146 130 143 135 115 111 132 135 128 120 133 130 115 148 139 136 127 136 142 123 146 123 129 129 120 119 137 117 146 139 128 127 127 150 134 139 133 135 129 127 140 120 143 151 119 128 132 148 128 135 134 143 137 131 127 121 120 148 133 140 139 127 123 118 132 135 125 121 127 130 129 126 140 135 139 130 104 113 144 123 134 161 142 133 114 128 133 113 148 135 124 128 127 123 123 131 123 137 137 135 130 132 139 127 142 139 129 116 129 132 118 145 126 150 129 124 143 139 137 127 129 130 118 124 145 134 124 125 118 115 133 126 143 135 126 129 97 137 116 133 111 106 142 127 147 137 154 113 104 116 153 125 132 126 119 109 131 118 129 135 145 111 118 130 121 127 124 110 121 146 132 133 136 148 127 118 122 135 129 129 131 136 109 127 157 113 142 127 145 126 125 134 129 143 126 125 137 134 110 148 138 115 129 113 125 125 128 147 135 123 119 137 134 136 130 130 113 140 130 130 125 124 132 116 123 142 137 127 146 137 108 123 120 115 144 131 143 130 119 127 120 109 117 136 125 135 121 131 117 108 122 167 148 136 132 114 122 136 141 144 142 136 116 121 117 112 114 115 130 111 126 131 108 109 132 144 125 131 130 134 135 117 137 147 126 147 139 117 134 116 132 133 131 143 134 138 140 141 111 124 125 132 130 128 119 124 131 115 128 139 117 142 132 141 117 137 134 141 142 118 135 140 140 139 144 124 143 125 131 129 139 125 124 136 105 127 127 126 152 129 132 120 147 146 113 138 134 131 128 127 101 111 115 117 129 122 148 145 144 143 141 147 147 121 133 119 115 120 113 139 149 132 122 147 132 127 116 129 132 133 135 139 131 119 138 136 111 119 118 149 140 121 128 132 113 140 138 130 128 133 139 116 162 127 141 129 141 129 123 128 145 146 137 114 148 136 134 138 119 134 143 106 141 124 138 123 132 122 141 131 112 130 128 137 151 131 130 159 122 140 138 121 125 111 125 130 125 112 153 120 118 160 128 124 135 131 134 145 131 133 122 131 121 139 134 115 130 154 144 131 137 134 122 123 132 125 128 133 144 131 145 140 154 143 127 151 142 166 123 147 133 111 126 133 157 154 144 133 151 153 160 131 137 133 163 151 143 147 153 152 157 156 148 151 164 153 151 167 141 166 157 134 146 159 134 142 146 136 142 144 142 135 165 157 147 118 155 127 146 131 139 160 165 153 138 166 156 151 135 147 123 132 129 151 150 139 153 118 150 167 144 129 138 140 138 131 130 135 121 115 143 124 120 146 138 103 152 138 140 135 129 130 137 135 136 134 103 126 142 131 112 132 137 121 113 122 132 124 148 144 133 134 140 131 118 144 129 144 116 115 100 119 135 145 123 147 109 139 129 123 111 123 114 115 117 124 136 151 133 131 131 127 120 135 143 130 150 132 128 120 135 138 132 114 146 125 136 127 139 137 129 123 143 131 146 134 134 148 133 152 138 113 142 121 132 133 128 141 124 110 133 143 124 120 123 127 139 159 145 112 132 129 129 126 147 142 110 123 139 128 123 131 118 140 141 128 122 115 136 133 124 124 128 125 110 130 123 130 126 147 132 135 111 127 139 117 134 143 141 116 135 125 132 139 130 147 134 146 123 126 119 159 105 116 125 133 125 127 121 137 119 136 116 127 139 134 135 119 135 121 125 116 124 132 123 132 130 124 134 113 132 121 128 126 134 124 149 116 124 127 118 131 144 136 122 142 130 116 155 135 124 112 136 146 140 135 133 156 136 139 138 135 130 131 128 129 114 116 143 131 130 112 124 126 116 130 120 110 107 131 130 129 148 139 128 133 134 132 145 123 139 143 145 111 115 129 130 128 114 131 113 138 110 136 115 101 137 140 121 147 116 119 125 104 121 139 127 132 123 144 124 134 128 133 133 138 117 124 130 113 126 119 123 115 142 117 123 134 107 119 114 149 130 139 141 123 131 136 127 130 128 124 115 125 136 132 134 134 136 122 149 118 140 117 122 138 120 146 136 127 125 129 114 131 111 136 119 137 114 134 136 131 121 132 129 136 135 140 138 126 130 107 117 140 139 129 131 129 129 125 125 112 109 121 124 134 118 130 119 131 95 136 133 119 119 124 117 134 133 128 139 127 124 130 154 116 129 125 151 122 141 128 134 140 131 146 142 112 130 148 126 125 130 123 120 138 125 131 123 122 143 145 111 115 131 145 124 132 130 127 132 123 124 132 104 129 140 142 134 156 127 112 121 115 124 132 133 127 135 159 141 128 126 129 142 139 143 152 132 130 140 148 117 131 127 139 124 142 131 132 154 145 119 109 140 137 129 127 119 133 127 118 124 129 126 135 134 135 119 113 127 142 110 138 140 128 112 110 160 110 122 124 114 133 124 117 130 119 144 132 135 120 120 135 122 113 140 137 132 156 133 157 131 131 122 136 149 115 128 151 139 114 118 156 122 126 117 150 139 132 120 128 140 120 131 134 133 112 111 129 125 133 114 114 119 130 123 156 111 136 131 133 132 111 136 138 135 136 125 121 134 103 145 139 119 141 132 146 135 132 132 148 124 123 132 151 132 107 139 113 145 134 108 132 155 128 108 135 123 142 137 125 139 144 122 134 146 122 120 145 146 121 127 131 140 125 117 130 127 151 115 131 123 115 138 119 131 127 134 111 128 125 124 148 126 113 134 137 123 123 151 157 139 110 125 129 128 132 130 119 124 115 140 120 133 131 139 118 120 125 122 144 131 135 145 124 135 137 135 134 143 119 131 127 111 127 131 134 124 132 103 128 120 140 140 139 104 129 119 134 133 117 139 128 140 125 134 121 154 119 115 130 120 124 132 118 142 134 125 123 134 129 126 123 117 137 117 128 135 132 118 137 114 128 131 147 140 133 122 127 113 141 140 139 128 128 135 131 118 126 136 142 120 150 131 124 111 145 118 129 139 114 136 127 122 133 119 117 135 121 125 143 132 140 115 126 136 131 124 132 144 146 119 132 127 143 142 118 155 124 111 124 127 127 129 127 117 145 139 145 123 142 130 122 127 137 136 113 134 110 155 146 133 125 150 130 122 117 139 133 147 121 127 128 118 125 114 122 133 126 146 137 134 106 142 132 128 135 145 129 123 111 124 122 125 134 117 110 126 132 106 138 124 123 123 135 125 125 128 125 123 131 109 123 114 114 147 135 132 123 120 148 124 116 128 132 125 146 129 131 132 105 135 131 119 137 143 112 147 133 138 119 125 126 137 130 130 138 119 144 119 118 97 116 131 133 123 119 125 108 129 128 134 128 111 125 140 125 143 127 135 153 130 145 108 119 140 133 107 110 141 114 115 121 135 157 129 114 145 129 129 144 114 128 118 121 150 133 124 119 137 114 131 134 127 129 124 109 151 139 144 130 119 123 114 125 119 122 133 117 147 143 133 131 128 118 137 104 132 126 123 122 129 133 131 108 137 116 138 126 130 120 125 134 125 135 151 121 129 143 149 110 121 148 131 133 131 105 138 114 128 145 129 126 120 112 126 120 136 144 116 134 126 157 130 141 126 126 146 130 130 117 130 145 112 115 113 148 133 138 128 132 147 130 135 124 133 132 118 146 123 121 142 123 121 128 97 121 133 138 116 122 143 154 102 122 125 126 115 117 131 124 116 129 113 149 124 122 119 128 119 126 118 113 125 120 127 133 129 133 136 132 110 125 125 142 130 124 111 144 105 134 119 120 127 129 130 131 121 100 139 143 136 162 118 128 135 137 134 134 123 129 123 117 131 133 122 128 120 148 97 141 116 140 121 117 138 117 139 133 125 131 134 126 123 112 129 117 114 124 145 129 106 117 121 144 115 130 123 138 140 130 121 115 126 119 137 127 137 128 142 120 128 130 130 129 111 140 147 136 125 134 120 118 121 125 130 99 123 154 124 152 132 122 130 138 129 141 128 124 134 132 111 106 136 154 142 104 139 118 129 142 126 146 134 117 123 120 137 129 131 134 113 136 132 120 133 144 123 143 102 124 139 111 114 105 129 144 131 126 135 142 138 111 137 124 105 114 126 115 113 121 115 135 142 111 125 119 132 120 120 119 128 120 129 119 138 131 116 132 102 111 117 141 152 131 111 111 141 142 127 128 131 131 133 154 113 123 157 121 124 132 126 125 115 139 120 129 132 138 123 110 132 124 150 132 124 150 134 123 120 134 128 131 128 141 105 127 117 138 141 133 141 132 132 125 127 125 137 141 117 128 144 136 119 147 128 126 128 129 142 145 135 130 138 116 126 108 115 129 118 125 118 134 120 125 122 125 126 143 122 138 148 123 131 124 120 133 122 121 113 142 137 130 125 131 116 112 114 127 157 147 139 121 120 122 137 147 127 118 133 127 139 140 141 125 131 120 107 102 126 140 140 149 142 135 135 142 119 136 133 136 141 150 139 142 129 131 112 154 119 144 138 134 130 134 123 122 132 114 105 142 114 123 124 129 143 131 132 111 125 123 133 130 133 112 142 143 139 132 143 142 130 150 127 140 141 125 137 137 131 111 132 124 144 120 131 116 129 130 124 128 158 127 121 122 122 131 134 150 149 128 140 128 124 116 151 136 121 127 131 152 131 139 154 121 101 145 148 128 122 132 137 153 135 142 139 121 129 128 141 137 139 114 137 127 147 138 112 148 134 129 138 144 129 125 114 140 141 141 132 134 111 127 126 125 119 131 147 118 143 142 133 138 148 133 130 158 119 136 147 117 113 136 139 136 121 127 127 119 107 117 122 131 125 124 126 151 130 121 144 151 123 153 109 127 125 119 125 116 146 141 126 115 147 142 142 123 122 146 133 139 119 141 120 128 141 134 136 140 139 151 116 124 112 142 118 128 129 134 127 138 128 146 125 121 123 148 102 128 137 146 129 141 135 150 129 129 133 141 129 146 134 116 103 112 132 116 152 119 130 150 128 148 129 148 137 128 111 126 116 139 159 116 134 142 126 134 133 127 156 150 144 133 134 128 138 139 122 124 155 120 149 116 155 104 122 123 129 132 141 130 129 128 146 132 139 131 154 136 143 141 142 136 144 117 120 141 139 131 126 141 128 136 132 118 140 113 142 132 142 135 116 106 121 129 126 139 136 151 132 131 139 145 139 122 126 114 133 136 145 139 127 148 130 130 137 127 148 146 126 134 125 129 134 128 99 113 129 148 135 112 132 115 140 116 124 138 142 134 126 131 139 96 162 123 156 113 121 123 129 124 130 118 134 129 134 134 120 137 149 159 128 151 132 131 142 149 143 129 138 108 126 166 139 129 137 148 119 124 131 123 126 122 135 135 120 120 138 131 129 125 126 119 121 128 133 134 166 135 128 136 119 134 149 126 136 151 139 131 130 116 143 112 138 145 138 146 119 115 115 121 111 118 141 141 157 120 125 131 122 135 122 137 146 110 138 127 139 125 135 142 114 118 124 149 121 118 133 144 114 130 114 142 136 118 127 125 138 122 122 127 130 126 129 135 117 131 123 119 133 165 142 135 143 139 151 134 128 144 137 120 127 147 128 128 131 132 120 125 130 138 130 127 134 135 146 130 122 142 142 130 126 120 135 141 123 118 133 104 118 122 128 131 158 122 137 110 119 124 166 129 131 133 120 134 121 136 139 117 122 126 123 117 123 134 135 132 149 136 131 139 150 129 123 136 140 143 141 126 133 128 132 121 115 127 99 130 124 136 130 153 115 99 119 126 116 125 148 127 125 121 138 138 133 119 114 121 115 156 138 135 127 140 101 131 112 121 113 124 127 148 130 136 147 109 139 140 136 140 140 134 137 128 118 126 153 126 126 119 132 121 112 129 123 121 120 116 123 133 122 134 125 144 126 121 110 121 142 121 127 127 142 142 131 133 117 129 145 120 129 136 111 126 132 133 122 121 125 139 137 122 131 115 120 131 124 115 122 141 127 129 125 134 113 123 113 107 166 141 142 137 132 112 119 137 133 117 130 140 91 159 149 141 134 131 143 125 120 134 132 117 135 140 123 119 131 147 144 113 116 132 117 127 119 120 127 121 156 111 125 144 118 119 129 137 135 107 141 118 152 131 125 124 101 135 146 125 106 124 113 135 130 129 116 110 125 158 145 132 133 126 113 129 135 131 109 142 118 121 158 130 113 128 117 122 116 135 119 143 115 103 112 129 147 139 121 130 121 114 129 137 138 134 140 138 130 135 120 116 122 137 136 121 123 119 121 124 131 149 117 117 119 139 123 118 131 134 118 139 131 133 124 136 126 133 117 133 122 123 127 126 130 134 141 133 111 128 147 135 140 146 136 114 136 114 135 102 132 131 128 125 122 138 132 135 115 106 102 125 132 128 133 114 131 138 123 133 124 133 123 120 124 114 111 142 131 121 136 124 125 111 125 99 128 155 124 121 135 133 133 139 147 139 133 101 133 139 117 118 130 119 120 130 124 132 122 104 114 140 129 176 147 112 118 137 119 134 126 129 120 130 143 124 118 128 127 136 126 137 128 149 134 132 148 136 124 129 125 143 142 139 109 114 132 119 137 107 124 111 128 128 116 140 118 129 133 116 140 122 135 130 127 139 136 147 149 127 128 125 132 125 111 121 141 128 139 115 139 147 129 142 129 126 116 119 147 144 109 122 128 139 102 122 121 119 144 136 135 127 135 145 133 158 120 140 126 131 143 141 106 132 130 132 135 132 122 138 116 127 125 130 129 123 124 126 139 160 121 140 138 120 134 142 136 138 121 127 126 143 109 145 108 138 138 139 131 115 116 140 132 144 136 139 106 125 116 121 119 126 141 117 124 129 154 112 129 118 135 118 116 123 131 114 136 131 118 128 115 128 145 123 122 113 133 138 130 133 138 129 139 141 129 138 107 120 124 150 127 127 123 101 142 132 130 141 127 138 128 142 137 129 144 133 155 129 134 125 134 123 118 135 120 128 118 120 143 125 148 127 129 113 118 127 141 131 127 140 158 139 117 119 132 117 137 148 121 146 131 127 111 122 142 138 126 134 118 129 133 147 134 140 128 157 129 126 118 136 122 120 129 120 138 132 127 145 149 127 134 137 140 129 134 136 107 120 133 123 136 132 143 128 118 118 135 129 137 123 132 140 147 111 123 146 134 161 124 116 138 130 122 123 136 127 142 136 129 145 131 147 117 119 143 144 123 96 128 146 137 137 137 125 128 127 124 146 133 128 119 122 119 148 130 142 142 127 121 116 135 140 135 104 149 145 147 129 123 130 145 142 138 117 134 135 117 140 116 126 135 123 101 133 110 128 130 143 119 141 145 126 123 130 136 134 139 131 126 139 149 105 123 120 133 142 113 133 120 131 130 139 141 128 135 118 140 151 137 138 132 129 144 140 132 130 135 113 162 138 138 127 125 135 113 141 117 161 117 144 141 124 132 133 138 125 129 120 104 139 147 134 121 122 134 123 115 121 132 148 116 129 127 159 130 130 109 152 133 132 122 121 143 140 130 128 126 132 103 127 132 116 123 130 121 132 120 149 119 139 137 132 115 123 123 129 125 134 151 140 135 119 132 122 138 140 120 149 132 155 134 142 149 131 130 130 129 99 122 145 131 129 134 134 123 121 152 133 131 134 134 143 129 128 136 120 147 128 154 114 127 131 143 123 118 139 144 127 128 126 128 133 127 138 109 130 115 130 129 117 137 143 131 124 137 155 129 141 127 126 129 129 146 113 148 133 130 117 129 138 110 124 131 139 143 169 136 138 135 123 136 135 131 119 130 137 128 127 141 123 114 121 117 127 131 130 116 133 138 130 135 123 128 127 135 109 131 140 112 130 132 138 145 126 122 119 139 132 129 118 131 130 145 133 136 133 112 130 122 133 123 121 143 127 130 156 138 143 129 129 141 128 134 145 112 128 136 143 135 129 131 146 141 132 144 131 127 147 127 133 111 124 128 133 164 147 139 145 126 135 136 125 127 136 129 153 128 128 126 137 134 124 151 122 119 142 132 122 125 136 133 121 129 142 147 134 133 132 145 127 133 139 124 128 117 131 128 127 146 128 142 122 121 140 124 146 122 147 127 114 115 160 138 131 136 132 118 143 142 155 118 123 126 147 133 131 132 137 134 137 124 113 126 122 144 141 112 130 156 134 125 148 133 118 118 132 130 117 111 151 139 132 120 120 141 126 137 122 134 139 163 134 128 122 119 144 151 119 150 129 127 120 134 129 129 128 134 133 139 129 125 125 123 129 141 132 140 135 121 135 137 132 121 125 128 141 148 139 136 104 133 117 129 128 116 135 125 131 139 132 124 138 131 122 120 122 123 157 122 122 137 117 134 125 136 102 124 148 106 130 123 153 137 125 118 148 137 130 137 138 139 116 133 123 113 151 131 125 134 132 139 134 140 146 118 163 129 127 120 116 118 132 133 127 134 154 124 120 144 155 130 140 118 172 108 121 135 108 109 138 127 124 112 123 120 151 124 137 130 147 137 116 140 135 114 123 135 138 126 144 138 126 131 142 129 137 108 109 105 137 144 140 110 136 153 128 150 120 129 113 150 142 124 139 144 136 158 123 116 123 131 142 135 152 132 136 138 123 130 148 133 118 142 117 154 137 136 145 121 118 143 133 146 149 130 120 134 136 129 122 125 134 115 138 115 135 144 132 127 139 130 112 98 134 128 115 127 117 128 125 145 129 114 114 132 138 140 127 144 135 137 129 112 138 176 136 130 138 137 120 132 130 124 137 121 124 138 127 129 138 128 133 146 125 152 139 135 143 118 121 141 140 156 126 136 128 156 117 118 158 147 125 148 148 122 128 129 131 126 128 131 154 143 142 143 132 150 133 136 164 127 140 140 143 121 121 150 143 134 142 115 143 135 142 123 141 145 139 121 143 118 129 136 136 154 125 144 152 137 127 129 144 115 134 133 142 141 126 121 121 140 140 115 123 119 164 133 128 139 133 130 133 140 145 128 148 130 151 159 144 147 130 138 136 152 114 135 149 155 154 150 149 122 145 169 130 146 127 155 146 149 146 156 149 136 109 136 149 147 131 139 154 152 154 128 148 127 135 149 128 159 138 145 142 147 132 124 151 151 122 120 153 122 146 126 133 136 149 127 135 126 128 138 135 146 139 140 151 135 137 133 147 110 107 138 133 134 132 132 115 142 136 127 123 129 134 133 129 140 139 155 122 139 157 143 136 133 111 138 127 133 142 138 107 150 117 142 141 154 145 126 122 128 128 113 131 123 138 140 136 155 134 120 148 123 124 153 124 146 136 142 140 133 108 141 149 130 126 118 136 128 123 129 110 119 118 127 143 127 135 136 121 125 115 123 129 118 138 140 157 125 139 147 117 135 133 126 128 139 117 133 136 124 127 145 144 133 128 145 135 140 132 126 145 148 134 114 146 144 142 143 143 130 130 123 127 137 123 123 110 147 119 141 133 143 128 118 147 134 135 149 123 120 131 116 146 145 137 121 137 135 157 122 145 128 130 121 134 124 150 121 109 119 134 152 147 159 140 132 126 132 113 116 145 131 146 153 123 120 149 154 139 113 127 141 141 128 132 146 136 118 132 130 151 124 126 155 137 139 140 154 138 144 156 125 124 150 127 114 154 126 140 118 134 152 137 104 146 139 121 158 128 164 122 153 109 143 135 158 123 122 138 136 115 115 124 149 129 130 140 127 130 137 118 138 175 133 138 146 122 126 130 147 124 141 143 132 131 132 139 136 158 128 157 144 134 156 122 143 129 139 127 126 128 118 158 132 129 142 118 109 142 116 125 128 131 137 119 131 127 147 137 127 112 138 151 128 121 136 143 101 110 126 112 134 122 144 121 140 131 139 134 134 111 135 135 120 122 124 123 115 130 132 137 132 122 127 156 121 124 134 146 148 120 148 111 134 123 142 126 130 136 137 114 119 127 123 148 143 131 143 142 122 126 128 110 120 142 128 114 142 125 148 130 126 121 120 123 131 131 151 126 147 123 140 132 140 133 127 122 135 129 134 131 152 143 132 136 123 141 138 124 144 131 136 150 143 121 125 111 133 132 127 117 142 115 138 133 135 124 120 135 146 143 126 122 113 128 122 131 126 126 147 133 129 125 117 144 130 136 114 142 120 135 143 150 123 141 125 125 123 130 111 119 130 134 131 142 133 116 116 144 117 125 138 141 131 144 140 120 120 138 113 147 143 144 142 139 126 117 137 140 122 126 148 125 133 135 142 124 130 131 105 106 127 131 130 139 130 151 130 125 127 130 140 118 146 107 137 129 121 130 157 129 121 145 131 135 133 120 136 144 136 135 150 116 140 122 135 154 135 142 148 141 126 139 137 137 140 140 152 123 122 121 126 123 142 120 124 129 137 128 123 118 155 118 128 130 132 139 134 131 125 126 131 149 128 131 132 131 170 121 110 134 143 108 128 131 135 148 143 154 152 141 132 120 141 149 143 153 110 129 143 122 136 144 149 150 131 118 141 141 120 120 152 135 135 150 137 118 130 147 153 145 132 140 153 128 141 127 129 135 116 140 131 134 134 136 140 157 138 140 154 133 142 105 130 115 137 115 154 136 134 116 143 127 121 130 131 110 125 117 139 135 134 113 148 135 124 132 127 127 131 143 156 138 122 134 140 152 135 143 124 148 111 147 128 118 141 117 137 122 113 120 131 139 150 132 141 126 143 134 104 130 140 152 141 123 147 122 149 143 115 147 139 123 125 138 131 139 155 130 142 124 138 113 131 150 126 124 125 150 117 127 130 144 130 117 120 129 132 135 112 111 140 142 118 137 137 134 128 152 114 120 133 124 158 128 160 123 114 118 154 128 112 134 139 130 144 138 148 119 139 131 129 115 148 120 124 133 152 143 136 137 126 146 118 134 152 131 138 127 132 145 117 131 138 135 137 113 138 128 121 143 131 125 137 130 133 157 126 124 129 123 134 128 125 130 120 151 136 122 144 144 113 131 151 134 129 124 128 124 114 135 138 119 121 141 151 135 122 131 138 125 119 154 116 135 134 156 134 138 107 147 119 126 117 144 127 127 141 115 114 131 123 140 138 136 121 120 113 139 136 150 133 120 117 142 136 129 134 133 151 132 125 144 134 126 120 113 140 120 122 115 130 127 149 110 142 129 144 150 136 150 126 112 116 117 129 119 128 134 128 130 129 109 145 142 134 120 125 144 132 102 123 131 141 135 130 128 126 119 154 134 132 139 112 135 132 133 133 125 128 131 114 120 117 131 148 130 135 121 149 134 131 134 119 132 150 134 112 104 130 145 132 142 119 134 113 128 114 134 138 139 130 127 144 116 125 134 140 137 133 161 123 144 139 126 131 159 120 126 126 153 129 110 138 133 151 122 137 130 138 132 142 112 148 114 134 133 142 116 108 132 141 133 129 124 149 128 145 128 133 123 128 145 123 131 125 128 137 131 145 136 153 117 124 147 148 129 129 128 131 116 140 150 149 110 119 139 129 126 123 132 126 132 134 139 131 140 135 123 130 118 137 131 122 132 114 113 133 128 148 140 131 132 125 124 129 139 133 108 117 143 132 117 135 157 126 160 128 138 120 128 134 143 136 138 116 142 119 122 121 149 130 150 133 137 142 124 129 117 137 131 133 110 137 116 122 126 125 129 132 133 121 145 122 126 136 126 136 132 145 111 135 135 129 131 144 129 160 146 111 113 123 135 115 133 127 111 130 150 157 141 118 134 129 152 155 119 143 125 131 140 137 138 130 129 132 111 135 130 142 127 138 141 134 151 126 116 159 126 127 124 153 118 125 128 131 151 146 136 120 116 122 135 141 141 110 122 122 132 142 116 153 119 119 147 134 128 116 130 131 132 131 124 125 134 146 139 133 101 134 116 128 161 129 141 148 122 119 120 129 136 124 116 130 142 109 134 117 94 146 126 140 137 127 125 119 131 132 128 122 148 131 124 129 138 153 133 122 127 145 137 131 146 135 142 109 125 115 135 162 140 125 129 131 118 150 118 130 126 135 121 130 149 133 145 120 120 149 148 110 123 138 137 135 134 127 132 136 105 134 102 116 126 147 142 127 119 140 145 127 128 157 119 128 137 132 139 144 153 125 133 110 113 145 131 160 114 134 140 138 113 105 129 132 137 121 159 131 117 150 121 119 127 147 147 146 120 140 130 109 142 148 154 145 153 128 133 127 140 140 150 123 143 137 149</counts>
			</dataPoints>
		</scan>
	</xrdMeasurement>
</xrdMeasurements>