File: data/XRD/XG-Luft/XG-800/W6822-1D_XG_Luft_800.xrdml
<xrdMeasurements xmlns="http://www.xrdml.com/XRDMeasurement/2.1" xmlns:xsi="http://www.w3.org/2001/XMLSchema-instance" xsi:schemaLocation="http://www.xrdml.com/XRDMeasurement/2.1 http://www.xrdml.com/XRDMeasurement/2.1/XRDMeasurement.xsd" status="Completed">
	<comment>
		<entry>Configuration=Factory configuration, Owner=User-1, Creation date=7/8/2013 4:01:53 PM</entry>
		<entry>Goniometer=PW3050/65 (Theta/2Theta); Minimum step size 2Theta:0.0001; Minimum step size Omega:0.0001</entry>
		<entry>Sample stage=MRD Cradle; Minimum step size Phi:0.01; Minimum step size Chi:0.01; Minimum step size X:0.01; Minimum step size Y:0.01; Minimum step size Z:0.001</entry>
		<entry>Diffractometer system=XPERT-PRO</entry>
		<entry>Measurement program=C:\PANalytical\Data Collector\Programs\Jorrit\2thom\_absolute_2th-om_10-130deg_PIXscan_56min.xrdmp, Identifier={15BCCF57-2807-42BD-B5B9-ECC0B3DC9284}</entry>
		<entry>Batch program=C:\PANalytical\Data Collector\Programs\SimonL\batch6x_2thom_10-130°_z9.1_x0,10,20,30_y20,40_57min - Kopie.xrdmp, Identifier={8874E540-C3F4-4307-831A-CD55F073CDCD}</entry>
	</comment>
	<sample type="To be analyzed">
		<id></id>
		<name></name>
		<preparedBy></preparedBy>
	</sample>
	<xrdMeasurement measurementType="Scan" status="Completed" sampleMode="Reflection">
		<comment>
			<entry>_absolute_2th-om_10-130deg_PIXscan_56min</entry>
			<entry>PHD Lower Level = 4.83 (keV), PHD Upper Level = 11.27 (keV)</entry>
		</comment>
		<usedWavelength intended="K-Alpha 1">
			<kAlpha1 unit="Angstrom">1.5405980</kAlpha1>
			<kAlpha2 unit="Angstrom">1.5444260</kAlpha2>
			<kBeta unit="Angstrom">1.3922500</kBeta>
			<ratioKAlpha2KAlpha1>0.5000</ratioKAlpha2KAlpha1>
		</usedWavelength>
		<incidentBeamPath>
			<radius unit="mm">320.00</radius>
			<xRayTube id="1010048" name="Empyrean Cu LFF HR (9430 033 7310x) DK442154">
				<tension unit="kV">40.0</tension>
				<current unit="mA">40.0</current>
				<anodeMaterial>Cu</anodeMaterial>
				<focus type="Line">
					<length unit="mm">12.0</length>
					<width unit="mm">0.4</width>
					<takeOffAngle unit="deg">4.2</takeOffAngle>
				</focus>
			</xRayTube>
			<xRayMirror id="27010001" name="Inc. Beam Cu W/Si (parabolic MRD)" hybrid="false">
				<crystal type="Graded" shape="Parabolic">W/Si</crystal>
				<acceptanceAngle unit="deg">0.800</acceptanceAngle>
				<length unit="mm">60.0</length>
			</xRayMirror>
			<sollerSlit id="21010002" name="Soller slits 0.04 rad.">
				<opening unit="rad">0.0400</opening>
			</sollerSlit>
			<mask id="22030007" name="Fixed mask 2 mm">
				<distanceToSample unit="mm">220.00</distanceToSample>
				<width unit="mm">2.00</width>
			</mask>
			<divergenceSlit id="22010007" name="Fixed slit 1/8°" xsi:type="fixedDivergenceSlitType">
				<distanceToSample unit="mm">220.00</distanceToSample>
				<height unit="mm">0.19</height>
			</divergenceSlit>
		</incidentBeamPath>
		<diffractedBeamPath>
			<radius unit="mm">320.00</radius>
			<sollerSlit id="21010002" name="Soller slits 0.04 rad.">
				<opening unit="rad">0.0400</opening>
			</sollerSlit>
			<receivingSlit id="22010001" name="Fixed slit 4°">
				<height unit="mm">5.88</height>
			</receivingSlit>
			<detector id="7010017" name="PIXcel3D 1x1 detector" xsi:type="areaDetectorType">
				<phd unit="%">
					<lowerLevel>30.0</lowerLevel>
					<upperLevel>70.0</upperLevel>
				</phd>
				<mode>Scanning</mode>
				<activeChannelsEquatorial>255</activeChannelsEquatorial>
				<activeChannelsAxial>255</activeChannelsAxial>
				<pitchEquatorial unit="mm">0.05500</pitchEquatorial>
				<pitchAxial unit="mm">0.05500</pitchAxial>
				<readOutPeriod unit="seconds">0.135</readOutPeriod>
			</detector>
		</diffractedBeamPath>
		<scan appendNumber="0" mode="Continuous" scanAxis="2Theta-Omega" status="Completed">
			<header>
				<startTimeStamp>2024-10-28T21:59:23+01:00</startTimeStamp>
				<endTimeStamp>2024-10-28T22:55:29+01:00</endTimeStamp>
				<author>
					<name>PRO-MRD</name>
				</author>
				<source>
					<applicationSoftware version="6.1b">Data Collector</applicationSoftware>
					<instrumentControlSoftware version="7.0E 20130304">XPERT-PRO</instrumentControlSoftware>
					<instrumentID>0000000011142674</instrumentID>
				</source>
			</header>
			<dataPoints>
				<positions axis="2Theta" unit="deg">
					<startPosition>9.99826193</startPosition>
					<endPosition>129.99755682</endPosition>
				</positions>
				<positions axis="Omega" unit="deg">
					<startPosition>4.99913096</startPosition>
					<endPosition>64.99877841</endPosition>
				</positions>
				<positions axis="Phi" unit="deg">
					<commonPosition>0.00</commonPosition>
				</positions>
				<positions axis="Chi" unit="deg">
					<commonPosition>0.00</commonPosition>
				</positions>
				<positions axis="X" unit="mm">
					<commonPosition>10.00</commonPosition>
				</positions>
				<positions axis="Y" unit="mm">
					<commonPosition>0.00</commonPosition>
				</positions>
				<positions axis="Z" unit="mm">
					<commonPosition>9.100</commonPosition>
				</positions>
				<commonCountingTime unit="seconds">32.895</commonCountingTime>
				<counts 382 429 400 415 441 393 410 463 408 431 428 434 408 395 381 415 390 418 457 408 415 405 409 379 444 476 401 438 403 421 426 414 447 404 446 411 439 423 409 436 385 438 424 450 434 418 468 456 429 435 437 451 427 456 437 423 423 430 417 469 445 434 409 436 437 407 385 403 443 429 443 406 419 442 423 383 436 435 412 424 412 427 404 424 356 405 389 421 377 381 416 376 420 417 389 409 417 407 383 392 398 435 412 399 421 419 428 418 436 385 357 374 382 378 361 384 375 388 393 403 430 413 367 381 384 400 391 383 389 385 399 402 427 397 406 414 391 396 399 414 385 441 418 404 391 357 405 416 398 388 359 367 374 399 426 359 388 370 383 372 417 347 418 354 357 380 415 391 382 389 373 391 377 389 351 346 417 422 394 327 400 365 357 386 417 368 367 389 394 385 388 362 364 379 391 351 390 381 370 383 392 353 397 377 375 385 364 399 369 351 384 400 338 399 374 406 373 403 412 390 389 381 368 352 367 350 336 377 329 394 355 361 361 383 378 341 335 363 359 345 345 388 382 385 372 363 354 346 360 363 383 357 334 337 379 358 366 374 387 374 345 356 363 379 405 373 316 354 368 369 374 388 390 359 329 439 386 355 383 367 349 388 362 369 371 407 341 357 339 355 330 367 323 345 358 397 365 347 311 368 354 343 359 357 333 352 376 360 343 357 342 365 323 322 354 327 311 331 354 372 327 359 339 354 355 327 321 349 342 356 335 319 339 364 340 345 373 349 327 343 367 353 308 355 375 332 362 343 337 344 363 339 327 340 323 375 350 358 341 320 368 348 333 324 347 356 354 310 335 356 304 348 355 333 330 335 318 301 343 336 335 259 296 323 309 350 347 323 373 337 316 348 333 338 348 313 313 309 323 336 318 327 363 315 347 323 314 346 301 318 331 341 353 328 314 316 335 360 310 321 336 337 307 319 342 336 324 346 339 320 327 314 288 347 337 309 310 332 327 313 322 331 317 322 370 296 323 314 317 312 328 318 287 318 309 316 327 324 312 313 290 311 314 337 331 313 325 328 315 307 317 320 317 312 330 331 342 283 303 325 301 337 313 299 285 350 338 341 304 320 317 337 299 318 309 335 311 313 307 319 287 294 316 306 322 313 302 325 321 296 335 325 306 275 306 307 297 277 301 318 331 311 335 306 318 308 319 322 318 306 311 301 278 305 260 335 294 315 302 293 307 316 300 331 323 282 291 331 276 312 284 300 262 349 303 302 303 329 312 299 280 299 276 304 325 330 286 277 301 308 267 306 318 284 301 311 283 308 293 304 299 313 314 285 310 320 305 276 341 295 288 290 296 299 315 303 324 286 290 308 270 311 270 305 320 257 320 310 309 293 339 314 312 287 285 307 294 288 280 287 309 305 321 302 293 335 291 292 270 299 313 274 323 319 298 331 287 320 265 294 307 271 293 304 299 316 280 319 298 284 270 275 298 328 296 325 263 299 330 302 321 304 298 326 291 290 266 256 289 258 294 292 308 271 302 304 295 311 293 287 288 293 284 294 322 293 287 301 302 313 291 307 286 272 266 304 310 281 285 285 282 271 294 297 314 272 278 290 295 295 302 313 297 286 301 274 324 266 281 269 299 320 324 328 270 269 303 285 269 262 295 300 291 263 320 307 273 298 282 310 279 310 293 287 289 291 281 270 277 340 267 319 267 297 263 292 302 287 261 291 312 309 300 282 307 293 293 274 308 264 290 305 273 292 277 294 321 291 291 267 288 286 288 309 267 298 292 290 307 278 289 293 291 300 279 295 281 303 306 309 258 275 314 299 305 263 286 308 302 274 293 291 308 280 282 268 291 271 307 285 280 291 293 286 287 263 257 272 277 278 297 288 269 261 292 274 350 285 307 310 291 295 304 295 314 299 326 255 265 311 285 248 311 294 282 287 255 286 280 272 310 278 293 298 300 304 321 292 269 309 289 268 317 272 289 325 287 295 245 277 286 310 313 318 272 322 280 273 279 277 299 273 280 300 295 295 296 277 300 305 255 293 288 298 290 276 309 302 337 323 296 269 298 273 309 299 303 255 296 305 332 311 273 284 274 299 297 287 323 267 325 325 303 306 294 343 293 306 292 304 299 289 272 304 311 276 296 301 336 313 307 334 279 289 283 296 293 334 296 277 314 285 322 245 283 268 271 274 302 280 282 281 304 299 291 268 309 296 301 282 292 303 301 289 314 285 303 319 328 304 312 286 285 301 311 294 292 276 284 301 297 320 287 311 316 297 273 309 296 296 294 300 279 259 240 287 297 343 290 319 284 308 266 315 294 332 289 311 309 282 269 317 299 312 284 288 295 271 301 285 307 299 292 310 318 309 295 322 340 280 306 265 323 279 283 286 328 289 326 324 296 287 287 294 277 319 281 298 314 318 286 288 297 271 288 295 309 250 287 314 263 317 338 276 313 281 296 281 296 292 271 299 300 283 321 306 317 271 327 302 300 294 280 300 287 327 294 327 313 303 325 278 306 326 310 309 277 309 318 299 305 279 329 282 315 292 292 311 304 298 297 320 324 286 296 302 315 301 333 289 311 311 302 318 310 301 319 285 294 323 295 329 306 325 288 270 298 307 297 275 334 331 305 334 274 308 320 262 293 308 301 279 275 305 299 325 305 305 319 278 304 317 274 292 297 323 314 316 296 302 297 306 312 321 308 287 307 319 309 310 286 278 294 306 305 325 288 309 305 288 307 310 311 316 285 319 302 343 286 304 314 302 329 284 305 333 338 316 300 303 286 290 339 291 296 311 301 293 285 320 324 296 321 299 287 328 306 314 278 323 295 292 287 299 288 286 333 293 309 298 311 312 293 284 319 303 284 283 318 315 308 293 313 316 303 308 309 296 276 306 311 341 318 314 302 338 301 301 300 296 317 309 271 332 305 302 288 313 351 294 301 312 277 291 327 305 283 309 293 344 310 322 324 277 306 278 291 277 290 285 292 299 319 310 332 307 291 304 285 319 335 301 313 289 277 304 280 308 297 313 295 331 302 293 303 315 315 300 325 318 319 307 310 311 285 329 315 292 321 276 290 321 301 330 296 283 315 290 280 308 318 322 311 325 302 304 312 302 299 313 305 304 327 287 308 289 292 282 330 318 301 310 283 287 307 295 327 321 295 283 319 320 298 277 288 267 291 290 294 297 281 279 336 272 300 293 323 366 305 315 317 306 308 277 302 287 292 323 322 292 305 331 339 293 300 282 300 318 307 301 296 276 291 329 316 324 298 286 277 315 314 311 344 297 268 288 303 281 271 286 264 295 327 337 308 303 297 303 324 298 345 301 290 318 308 267 305 296 307 291 263 290 271 276 320 268 303 302 281 289 311 256 263 298 299 283 314 302 264 297 290 282 284 304 299 322 304 296 284 303 300 269 322 298 274 307 304 280 297 277 310 276 301 320 309 296 300 326 246 323 318 271 309 273 313 321 299 306 256 267 304 299 261 297 315 271 318 312 301 271 284 318 274 287 283 313 286 292 281 293 308 286 282 282 270 309 282 265 311 303 274 286 288 273 276 305 297 293 299 312 306 276 268 258 306 285 320 286 284 310 283 304 274 291 299 288 299 272 299 280 302 289 274 277 305 292 295 275 292 304 289 341 274 303 304 287 256 275 268 269 279 285 307 281 260 302 307 300 298 293 282 286 306 292 282 287 299 291 293 248 267 263 292 284 297 296 255 288 288 259 274 267 284 295 276 284 282 277 262 278 277 303 282 303 292 277 269 274 289 282 296 271 291 296 288 259 257 274 284 292 308 267 285 292 276 275 302 314 280 292 285 256 265 316 289 288 294 281 288 309 298 279 263 298 271 285 280 315 300 276 317 248 298 260 291 275 241 306 275 258 283 292 285 273 296 294 279 264 257 274 268 255 281 258 299 292 256 274 235 263 270 277 264 247 284 255 248 259 280 291 255 269 278 283 257 277 272 260 237 271 306 246 278 311 290 293 281 274 284 269 237 271 239 271 269 310 295 281 294 294 246 291 277 272 292 264 284 262 272 277 274 280 284 283 249 275 241 284 260 264 274 288 272 240 266 295 239 291 284 281 256 257 256 292 229 294 276 262 285 289 247 266 278 259 267 260 259 280 267 271 284 284 289 270 275 222 272 229 281 304 276 284 258 286 257 245 271 242 295 331 248 237 274 266 284 284 236 238 276 289 269 277 284 267 271 285 261 259 260 262 282 277 282 249 263 258 256 273 270 247 287 277 264 293 286 237 262 281 266 262 256 263 231 270 267 255 282 232 255 276 285 263 248 290 242 273 264 214 270 246 238 286 277 276 226 317 232 233 255 263 296 290 255 250 268 290 294 220 295 256 263 242 268 266 237 246 256 244 242 243 266 247 241 290 242 243 236 249 258 246 241 283 272 228 276 259 268 237 271 294 242 261 243 264 267 270 266 285 264 287 263 272 259 202 261 268 272 255 276 276 273 244 248 228 262 294 244 271 256 262 237 272 260 264 268 270 237 211 277 231 293 274 243 249 262 236 262 249 236 298 234 271 267 265 261 237 247 240 266 258 240 271 272 276 268 234 259 244 271 267 263 267 244 248 224 270 261 258 263 261 255 229 258 236 261 276 236 230 247 244 245 278 228 243 240 241 239 277 280 262 227 238 247 250 269 263 239 237 241 273 249 284 277 219 214 275 232 249 261 245 230 242 241 224 233 237 250 247 255 224 225 260 248 245 258 256 232 243 233 243 226 243 242 245 284 267 270 276 279 242 236 271 233 269 249 230 239 255 258 256 269 227 246 256 261 240 240 265 258 261 259 270 231 224 227 257 247 259 233 263 242 263 247 294 268 287 236 275 241 275 236 278 229 236 247 248 271 283 264 282 234 283 281 243 277 273 270 258 268 265 275 242 277 240 230 263 220 269 250 259 263 237 213 236 221 237 275 234 208 280 245 268 242 248 244 221 275 215 260 270 226 265 243 278 276 231 255 263 238 262 239 260 247 262 248 263 287 272 271 279 235 243 275 235 237 228 240 199 279 262 241 243 225 237 234 276 256 258 257 259 248 237 218 241 236 247 228 241 259 245 234 260 255 244 258 228 233 255 244 250 242 278 236 226 243 269 237 214 261 244 277 227 229 241 265 241 234 230 264 268 218 235 262 220 247 248 234 229 240 268 236 250 264 236 208 218 247 236 219 234 228 269 232 255 246 269 234 245 263 239 259 238 258 260 226 263 240 211 234 266 212 247 205 212 239 242 267 274 255 230 226 260 261 255 269 245 233 261 249 229 249 256 242 246 247 219 255 237 220 260 258 256 258 234 262 262 246 271 257 228 224 269 256 233 271 257 235 248 243 220 225 240 261 243 247 229 268 214 244 245 236 239 255 232 230 213 258 246 199 235 230 237 241 236 279 244 250 222 219 223 227 231 236 234 267 256 238 241 248 235 250 230 239 221 243 248 259 226 195 256 258 249 261 246 239 245 220 259 228 218 267 255 234 237 267 198 297 212 257 227 240 225 265 258 227 222 211 249 260 260 222 240 264 242 225 242 258 230 258 236 218 208 245 256 245 250 244 246 221 262 247 255 277 245 242 223 241 270 242 250 263 264 240 259 264 219 242 266 199 245 250 228 241 262 242 225 245 223 275 235 225 238 233 242 229 236 256 236 232 217 223 261 236 218 225 237 248 247 236 232 239 268 270 263 248 221 209 278 270 221 226 245 234 228 255 242 256 232 242 234 238 242 217 232 246 210 227 244 221 257 247 236 255 231 279 211 248 235 240 199 246 229 265 264 233 255 264 239 233 246 235 269 237 255 269 237 228 259 248 239 258 241 215 278 217 228 227 255 265 260 249 242 243 260 222 257 214 217 232 261 247 245 224 255 238 249 232 222 245 242 226 217 241 217 233 271 273 231 217 244 216 226 236 247 241 247 234 223 227 227 248 227 261 222 243 246 246 243 278 243 245 242 238 243 260 229 242 246 223 232 262 276 244 238 237 255 261 218 238 260 235 245 247 284 236 257 240 233 241 229 221 236 257 186 243 243 243 216 243 247 283 249 271 238 239 236 248 231 234 241 270 242 230 247 261 244 247 231 232 273 246 236 240 271 281 277 231 227 247 246 243 245 259 247 243 239 269 257 255 231 242 269 270 259 277 240 257 267 230 247 262 244 247 285 255 288 231 249 290 275 268 268 277 239 242 267 234 241 240 268 269 266 255 268 260 224 224 237 280 241 265 245 204 256 235 237 241 240 233 244 236 223 292 203 218 244 222 234 237 240 261 237 241 237 258 234 255 267 229 287 257 263 267 250 256 265 247 211 222 250 242 222 272 246 219 239 263 274 228 225 233 244 243 243 245 261 256 248 237 223 246 233 242 230 244 223 235 238 272 256 247 239 265 231 229 215 226 235 244 266 224 236 270 240 214 264 245 233 232 220 247 240 226 236 250 222 197 262 241 222 235 232 235 210 235 268 261 255 237 248 245 238 261 216 230 258 225 246 259 263 276 241 234 245 226 231 242 244 265 265 249 214 258 206 240 240 236 238 257 232 249 224 221 223 236 240 240 240 279 225 205 243 235 233 211 235 229 213 237 233 235 238 244 243 242 234 243 258 213 244 260 231 255 246 244 245 247 287 242 227 262 227 247 257 245 255 229 229 235 237 232 240 231 231 221 214 237 217 229 233 256 247 214 263 236 223 230 229 229 243 212 218 280 213 212 232 239 210 234 245 249 244 220 235 239 219 266 233 256 269 238 255 226 225 229 237 264 232 239 243 261 257 214 244 223 247 225 279 266 230 284 248 232 229 230 256 243 243 234 260 244 235 241 220 240 259 267 269 221 228 241 231 226 228 220 245 225 242 234 249 228 236 217 205 244 237 269 235 234 260 215 249 261 238 265 237 232 228 242 228 214 284 238 220 256 241 276 242 233 221 261 244 237 208 248 214 233 242 257 222 265 241 232 234 214 247 230 246 223 221 228 214 233 226 223 237 207 257 242 274 244 242 264 230 227 258 223 241 218 276 231 237 234 267 239 202 224 247 247 233 273 258 220 261 226 255 234 238 245 242 228 234 222 209 256 240 238 261 249 262 217 227 236 267 258 220 245 242 255 227 222 258 246 261 232 272 231 260 235 264 257 204 270 220 245 240 234 237 258 237 256 208 243 249 222 236 241 228 256 236 274 242 279 248 206 244 242 242 245 247 246 213 217 268 259 270 224 257 242 229 276 241 212 241 243 241 259 248 234 242 230 255 228 276 243 226 257 266 263 216 245 287 234 232 245 227 238 236 231 248 260 236 228 234 236 234 243 223 240 255 242 268 217 235 255 223 258 248 247 236 225 229 236 233 249 275 237 220 234 228 249 237 263 247 248 249 259 258 265 256 221 230 290 234 274 267 245 300 257 266 264 233 232 229 238 244 262 266 236 229 239 271 255 282 244 229 260 237 257 242 231 267 224 271 268 246 242 248 257 212 260 237 256 263 244 229 226 279 222 228 236 262 282 234 228 259 248 267 246 273 208 237 278 271 244 235 224 273 245 266 234 260 249 259 247 228 265 236 244 248 247 228 228 273 293 265 265 268 287 247 243 243 232 249 246 275 238 265 242 264 238 247 257 265 261 241 273 231 276 265 281 261 242 272 240 306 238 256 271 244 259 212 259 278 250 265 261 272 248 260 259 247 247 219 260 248 280 256 290 286 285 275 245 259 258 285 269 255 241 277 268 262 267 266 290 269 283 278 282 241 249 292 277 273 302 262 302 301 306 246 263 285 318 312 269 256 271 288 293 293 294 309 291 306 303 288 310 336 312 321 312 321 336 339 350 340 335 391 356 365 401 375 401 377 387 423 418 395 414 454 412 453 452 458 474 453 429 453 441 439 421 417 430 401 383 419 397 398 357 372 374 374 395 346 341 375 364 330 312 349 320 303 275 322 295 335 283 278 305 294 287 294 287 281 257 287 298 265 281 291 292 275 287 286 266 266 280 240 272 270 243 270 246 283 270 282 263 279 248 250 273 246 255 245 233 283 248 268 213 271 225 262 269 287 244 273 269 243 247 270 266 243 243 248 248 210 248 233 270 288 267 222 237 268 199 219 236 240 287 243 255 228 267 277 274 239 255 246 226 248 224 259 274 237 239 255 258 236 226 242 227 229 248 263 264 244 233 227 277 250 266 229 233 222 277 261 247 245 248 266 237 275 240 244 282 261 272 238 270 260 208 248 262 225 261 264 237 246 247 257 231 236 261 268 239 226 260 244 240 263 236 260 242 249 246 239 243 234 240 249 248 244 244 227 214 263 240 256 231 263 224 223 249 218 240 275 263 247 247 236 207 225 233 240 224 233 244 246 261 222 236 273 265 226 237 245 262 234 238 290 278 235 222 272 227 235 256 287 243 256 261 249 266 218 239 246 257 234 255 236 237 268 280 243 240 214 238 249 246 210 238 275 259 249 242 268 265 239 256 244 229 268 216 260 263 248 241 257 280 250 244 250 289 226 235 280 230 247 207 277 244 221 265 222 246 213 242 270 227 256 261 270 256 243 265 236 246 259 260 263 256 249 256 274 248 247 266 264 275 257 261 241 250 228 244 255 261 266 278 249 206 261 276 263 237 273 214 265 261 250 209 268 245 237 260 274 276 242 269 241 260 275 264 262 237 241 236 242 243 260 219 259 242 255 269 248 265 258 270 247 240 225 272 239 266 267 261 224 263 232 239 213 274 234 249 284 262 258 229 244 264 246 281 249 294 232 275 256 250 240 260 229 255 259 263 266 268 245 258 240 245 263 244 239 246 247 269 269 257 264 247 240 260 256 269 268 279 255 227 236 234 222 247 280 258 264 238 268 248 237 256 240 234 247 255 257 281 246 235 262 225 262 249 221 266 239 230 242 227 244 273 221 275 263 234 256 241 275 249 242 266 283 263 265 242 256 273 238 280 255 257 243 238 248 242 244 269 266 247 261 237 212 243 295 243 228 234 241 225 272 249 268 282 237 284 239 265 266 248 236 272 232 264 247 230 275 273 242 224 243 241 257 227 244 264 232 277 238 226 239 227 260 241 266 234 256 273 247 250 269 249 269 256 271 257 262 239 235 283 269 234 266 239 246 259 263 286 239 240 270 262 257 255 214 260 246 216 242 256 237 249 281 246 302 244 264 256 243 270 256 237 206 238 287 222 268 246 240 235 261 262 225 248 255 222 256 278 244 243 232 235 258 233 228 224 276 260 273 216 243 256 237 235 235 248 248 270 240 255 242 249 238 255 238 235 203 272 255 263 246 261 239 228 225 258 225 246 257 227 258 227 236 264 243 233 269 255 263 266 235 231 261 257 258 233 273 223 233 265 285 269 242 225 212 255 241 256 246 255 261 269 261 240 238 264 245 247 249 269 239 266 237 302 248 241 238 256 275 235 271 272 246 241 273 245 215 257 227 248 255 238 255 225 225 245 238 243 248 273 234 264 260 260 258 269 232 238 267 237 250 227 235 232 241 229 240 234 219 238 243 248 225 255 241 262 235 234 234 255 226 275 233 245 256 265 202 258 259 207 274 266 260 220 259 215 226 239 223 241 258 256 226 247 257 248 268 250 279 282 245 262 271 241 264 268 265 224 223 248 249 236 227 249 256 271 246 248 224 247 267 229 239 243 222 241 255 229 261 255 215 259 262 259 249 269 262 256 242 261 257 239 238 237 230 263 241 256 241 234 242 242 248 271 229 266 255 237 264 266 273 244 286 277 242 238 255 247 248 236 241 243 242 226 280 248 218 239 277 215 247 235 239 246 235 222 243 238 231 263 222 235 247 277 261 255 261 241 260 247 256 272 227 261 249 270 271 270 258 216 256 261 241 248 240 234 235 222 256 259 234 272 266 265 261 250 209 234 276 262 244 225 241 261 271 220 212 216 228 258 281 231 224 250 218 248 238 262 237 231 248 226 232 289 290 224 214 266 226 244 221 236 237 241 286 292 279 257 265 246 239 264 240 249 240 285 260 231 242 272 218 266 215 221 231 248 257 255 233 259 233 223 208 280 250 198 256 223 276 256 225 249 279 260 269 237 282 231 229 240 259 288 239 238 272 263 233 215 255 263 245 229 235 229 227 228 256 221 255 242 266 266 281 236 246 231 223 227 249 249 228 220 228 239 259 257 264 256 257 280 272 235 255 257 250 246 234 216 240 223 232 255 220 217 275 239 249 240 276 240 235 215 279 244 234 280 197 226 243 234 219 246 248 282 283 266 266 262 255 232 241 261 285 249 214 238 234 237 244 228 218 265 255 264 241 267 264 225 226 240 231 256 266 234 249 255 268 258 220 234 228 241 265 218 255 223 236 248 219 237 250 237 235 256 237 239 218 217 269 239 248 267 237 249 275 247 244 240 261 220 233 235 245 245 224 245 213 239 248 268 243 258 241 247 247 235 262 271 240 235 262 237 259 232 230 228 245 248 237 233 267 221 226 234 236 266 275 245 234 267 266 250 247 225 262 260 218 236 247 260 248 244 246 256 268 225 266 261 233 258 213 259 239 246 256 233 257 260 270 282 229 235 250 235 239 270 207 230 260 249 245 220 224 213 237 229 236 238 275 224 261 264 264 235 238 241 238 228 246 244 207 269 229 215 257 237 237 261 215 258 248 260 274 247 230 233 224 257 224 257 248 239 261 268 238 240 211 294 247 256 240 279 272 246 277 213 217 223 303 260 242 277 232 248 242 246 221 218 244 220 280 267 241 218 228 212 215 224 280 238 264 256 268 260 258 267 262 259 271 272 265 255 231 233 236 205 264 256 267 232 274 283 243 232 270 233 235 247 248 263 229 238 260 235 262 249 257 237 256 246 249 205 246 233 226 267 267 235 232 273 248 236 268 231 241 242 243 235 262 226 235 268 234 237 248 270 244 261 226 258 244 224 260 216 256 271 236 249 220 236 239 240 246 244 231 290 269 245 264 261 242 245 239 246 256 221 233 260 263 268 260 234 220 214 264 230 245 234 232 258 260 272 273 246 264 274 227 248 268 247 263 256 257 228 247 242 259 265 212 266 249 241 263 276 217 239 239 241 236 257 262 248 244 236 220 235 249 243 259 255 211 228 233 242 267 245 231 245 247 263 249 247 248 264 223 243 231 229 213 247 228 277 227 218 257 264 239 232 239 246 242 247 266 248 257 234 249 217 259 205 249 257 231 244 256 284 225 264 259 234 260 277 220 256 240 248 259 259 245 238 226 271 223 219 260 261 256 234 233 217 220 257 224 258 261 241 235 265 238 262 235 277 259 266 248 269 240 264 258 272 229 239 259 249 235 219 222 269 236 256 242 228 259 217 279 243 263 247 264 232 243 282 255 233 241 266 238 244 273 249 238 244 248 268 221 213 242 260 245 269 218 244 255 266 259 257 230 236 231 222 271 246 245 265 208 239 232 241 230 278 267 233 242 278 229 255 259 257 237 236 240 242 243 232 267 228 241 241 272 257 225 273 234 276 275 258 241 247 274 248 243 222 245 220 248 237 234 270 212 240 248 248 227 228 239 241 247 257 221 241 258 281 218 262 256 245 245 235 264 249 268 237 268 247 259 263 227 271 260 255 274 242 270 238 262 240 255 247 242 256 230 290 221 233 260 245 242 289 233 247 273 243 218 264 281 258 235 243 283 272 268 260 261 269 231 236 269 256 242 255 238 240 221 256 244 268 299 259 248 241 256 272 256 247 246 262 237 247 237 277 264 225 249 244 226 239 255 228 271 235 267 280 264 259 202 245 261 258 260 235 225 235 223 240 261 267 275 264 242 258 287 298 257 279 227 240 246 248 266 240 216 285 247 256 270 228 226 214 244 291 241 246 232 280 240 273 232 255 256 256 270 244 247 226 275 248 244 279 239 259 225 256 281 274 239 248 236 269 285 230 247 239 229 241 246 240 298 273 260 256 259 262 246 234 245 272 293 249 248 230 276 280 272 273 245 259 286 268 241 247 255 243 247 224 268 240 256 232 260 232 230 243 270 268 241 266 248 229 236 256 271 264 261 247 258 229 257 235 240 249 219 242 259 232 302 257 242 227 277 265 267 261 225 277 232 265 229 272 243 243 255 260 264 229 270 237 275 247 267 257 291 247 256 247 272 264 244 283 279 259 263 263 247 266 239 246 245 238 257 240 255 206 256 250 267 276 242 260 242 266 249 267 248 264 265 249 258 266 264 255 230 281 274 259 249 258 282 219 281 245 249 242 262 266 229 244 243 263 274 238 255 257 274 275 273 281 234 275 260 270 257 221 256 243 244 233 272 246 259 261 262 237 302 250 249 248 273 241 235 231 246 256 236 266 288 269 270 244 259 237 270 244 273 259 218 222 247 240 232 264 222 244 264 256 249 243 246 258 268 244 248 261 267 262 222 249 264 261 248 277 264 258 263 248 248 229 246 268 261 231 284 258 265 250 268 263 271 255 226 237 279 227 288 243 266 241 239 260 271 237 277 291 248 278 294 295 272 265 266 243 246 241 236 267 239 255 279 278 266 266 260 273 255 276 282 260 260 273 271 274 282 274 247 277 298 235 283 275 295 263 263 244 262 262 270 262 255 260 246 233 270 276 264 268 278 272 267 282 260 270 271 272 248 264 241 292 288 236 285 275 265 256 255 261 272 283 276 248 281 241 260 273 279 277 248 242 268 226 273 247 281 278 258 269 246 226 287 275 260 244 239 223 261 263 247 266 257 304 265 245 239 235 241 247 272 272 257 246 282 262 265 267 266 231 276 229 270 239 277 280 257 277 278 247 272 278 270 258 287 259 262 247 255 255 248 244 263 255 237 290 268 268 276 255 232 236 259 277 244 272 256 264 228 255 247 232 268 269 250 247 234 223 243 256 247 224 236 239 249 249 236 238 226 275 274 249 247 259 263 259 261 228 263 264 243 271 231 277 225 281 219 258 233 245 359 276 244 246 259 244 225 260 285 227 235 271 259 272 246 234 229 255 273 246 241 274 260 267 241 280 231 243 257 273 239 257 256 247 268 268 286 227 232 263 268 223 240 257 269 265 287 225 234 266 266 238 241 257 257 229 248 268 275 273 289 273 299 257 241 226 263 287 303 228 264 268 221 271 271 260 244 261 238 261 266 255 256 236 260 240 268 287 282 236 241 265 259 270 298 258 232 283 267 258 231 235 257 239 280 278 266 279 244 267 245 237 263 246 258 259 261 234 243 276 277 231 276 236 256 232 277 272 245 276 260 246 244 263 225 270 269 249 233 236 246 288 257 234 274 259 239 237 278 256 276 273 233 270 262 307 272 273 233 273 250 273 289 258 247 239 289 255 271 285 248 263 260 263 257 237 270 237 275 268 282 265 275 264 256 250 285 248 242 248 267 264 261 225 249 259 268 238 276 247 248 246 249 246 290 234 263 267 256 279 236 261 261 228 274 231 237 246 275 248 259 263 241 264 247 276 241 263 268 272 259 247 232 244 259 270 267 260 260 282 261 288 235 259 262 249 257 228 235 260 259 242 239 216 277 238 257 265 300 281 279 246 264 236 245 234 264 221 229 241 273 279 259 249 256 256 244 250 238 238 272 255 232 243 215 256 261 286 246 241 262 226 244 242 233 227 222 239 278 270 266 245 256 276 259 255 274 231 245 261 245 244 241 256 261 246 255 213 238 225 219 266 234 260 239 260 261 267 225 277 267 245 277 217 267 271 258 235 244 256 270 274 227 245 273 238 238 227 266 243 247 267 255 257 271 240 242 242 241 276 270 246 221 245 293 244 242 258 246 257 261 231 258 246 228 255 280 244 236 237 276 246 224 259 266 271 227 256 215 262 272 242 207 242 225 243 221 249 258 245 247 278 248 276 234 239 273 255 230 235 277 262 256 250 226 259 243 258 256 245 281 245 231 234 283 230 230 256 227 244 238 255 255 248 263 256 227 216 255 261 276 284 202 246 243 216 266 272 230 242 257 262 260 260 292 265 260 264 227 230 266 258 258 239 256 261 260 239 279 242 255 258 277 272 277 268 256 257 275 258 281 242 265 257 260 276 284 269 222 218 246 260 271 259 238 275 224 224 260 280 250 274 249 245 244 248 246 271 238 232 257 262 278 249 273 273 258 273 278 220 257 234 237 258 240 225 283 242 258 265 236 248 273 248 244 266 247 257 258 260 225 244 236 219 246 261 272 209 262 231 274 241 266 255 287 229 255 246 285 258 261 238 244 273 250 271 256 260 250 230 258 250 268 269 271 270 232 258 243 257 264 290 264 268 241 259 232 267 246 280 278 280 240 241 264 255 228 278 280 236 301 230 249 230 266 241 261 269 242 247 263 262 265 244 247 216 227 228 241 270 247 246 255 247 227 245 276 240 256 256 233 247 257 247 231 255 247 225 264 271 228 282 263 260 244 271 257 231 262 242 270 270 240 255 269 259 231 256 243 260 233 268 255 264 221 236 280 263 258 230 233 256 240 271 259 234 245 278 250 246 242 261 221 262 269 257 260 248 257 287 292 230 257 246 248 255 256 255 245 243 247 274 216 256 261 234 264 247 282 248 278 261 245 261 242 271 246 227 257 233 266 245 244 249 263 268 278 282 230 290 231 265 250 248 255 258 233 260 265 232 249 259 270 224 255 260 224 266 259 219 241 243 265 259 242 258 260 245 240 217 237 268 265 227 270 259 241 229 235 255 243 258 266 256 236 238 248 248 212 222 273 286 225 255 275 247 249 267 256 279 217 274 226 247 259 250 221 261 281 266 255 259 217 256 269 245 246 249 243 258 240 237 233 266 255 260 242 259 283 247 232 242 230 271 227 255 264 274 239 255 244 260 260 269 227 261 237 226 259 256 238 257 245 229 248 262 265 239 257 258 255 248 248 243 280 259 243 240 260 278 240 269 283 248 239 257 233 239 249 255 248 262 246 263 244 255 268 259 276 264 274 271 270 233 230 250 258 247 235 268 245 266 227 258 273 263 225 280 257 234 269 246 262 248 240 261 281 272 236 263 257 223 239 248 250 233 257 261 244 237 266 229 287 255 234 266 257 248 239 228 264 231 281 268 240 264 259 299 226 243 262 256 236 256 228 256 264 237 244 244 260 239 261 255 226 280 255 259 271 215 260 262 266 264 277 269 260 272 243 223 259 284 266 244 267 228 236 256 238 236 236 237 235 262 225 232 290 232 271 245 244 259 269 242 283 244 239 247 247 237 263 244 261 264 218 246 280 249 259 228 255 226 262 233 245 260 279 271 266 282 260 247 274 247 269 258 278 238 243 250 235 265 272 269 265 262 241 279 241 249 276 263 264 242 282 263 257 278 280 288 266 256 276 232 240 250 248 267 231 228 258 272 284 263 268 225 262 277 257 275 288 269 270 243 244 262 262 273 255 240 255 284 239 249 243 233 282 248 261 270 249 261 248 238 237 233 265 239 255 233 240 274 286 297 243 241 231 236 271 278 263 228 280 259 240 260 241 223 242 274 226 244 248 219 233 261 238 259 236 243 255 248 242 263 207 278 283 280 263 240 256 230 259 242 261 270 280 279 274 260 277 246 248 240 255 274 264 249 280 256 287 269 262 238 229 223 225 263 241 261 241 248 229 262 269 273 262 226 279 259 264 278 233 271 273 235 244 267 239 259 270 247 293 285 255 273 241 244 284 231 294 273 255 246 267 235 278 272 271 222 230 249 285 274 262 238 246 275 247 293 240 261 271 262 298 241 255 232 257 240 271 221 241 261 247 255 249 264 229 267 236 243 281 243 273 236 260 268 236 235 263 238 240 228 269 295 281 259 232 260 256 256 234 301 260 226 232 278 261 263 266 238 241 285 237 264 265 260 267 261 249 272 244 291 234 279 271 269 234 270 244 295 247 285 245 263 233 243 284 238 267 265 257 319 256 219 271 255 238 262 271 237 266 259 262 264 249 273 221 244 272 238 255 244 244 269 261 279 270 249 248 263 238 281 242 274 265 279 245 268 266 285 271 261 279 280 261 248 266 230 245 249 282 257 238 238 259 249 236 243 263 281 272 244 262 259 257 240 225 281 238 245 261 258 258 240 276 270 246 245 241 262 245 270 242 268 241 245 285 263 266 242 246 263 270 246 267 242 244 230 235 209 270 242 260 256 227 279 210 281 241 231 263 263 272 267 258 285 249 245 205 256 262 259 243 258 244 234 273 271 263 290 269 264 236 255 270 247 263 263 266 257 272 202 264 258 248 238 226 241 262 258 275 239 271 256 272 271 257 282 250 246 257 261 241 243 276 272 275 288 259 245 274 242 290 246 237 274 268 271 267 238 259 247 287 266 270 245 255 269 248 248 228 265 240 230 268 270 262 247 243 232 274 282 239 244 283 255 265 248 242 279 280 284 269 256 255 249 241 276 265 271 242 262 257 245 267 292 248 290 268 267 285 238 246 240 260 297 262 243 281 259 284 289 281 299 276 268 272 275 263 280 292 282 276 289 262 277 274 269 299 240 288 281 257 305 268 319 271 271 278 300 301 295 309 314 280 306 262 276 281 291 274 297 308 335 296 295 297 288 278 288 279 337 302 304 302 303 307 293 312 312 301 277 297 273 259 299 276 286 272 306 268 282 294 281 302 281 289 295 283 262 268 242 305 283 270 282 303 273 268 264 287 271 278 262 259 244 307 248 298 298 271 282 263 269 284 263 275 244 244 293 221 295 275 247 258 271 265 274 295 273 279 280 267 261 257 265 282 245 241 271 275 244 257 280 227 296 236 281 277 213 266 293 240 243 235 275 259 248 264 235 286 267 264 260 257 238 237 271 267 272 276 246 260 262 261 301 260 286 268 272 269 290 274 258 285 272 265 246 247 270 249 284 283 280 247 262 277 274 256 235 266 244 230 275 274 264 245 255 257 248 250 278 240 282 256 240 244 248 240 290 234 276 262 272 276 268 270 259 268 261 244 275 289 234 273 257 291 262 226 266 287 239 222 272 255 244 282 257 276 241 265 258 238 243 234 249 222 266 227 247 267 259 234 243 249 256 248 244 262 255 269 286 234 256 272 270 270 225 269 244 266 247 250 209 236 249 273 255 259 233 285 270 270 233 258 244 272 242 258 276 263 262 265 261 250 238 227 255 248 244 235 245 258 244 268 287 264 263 228 226 238 243 246 259 245 234 240 265 240 257 274 245 250 238 250 242 225 264 242 230 258 287 250 245 263 247 236 228 240 228 258 231 206 242 230 250 244 265 256 270 269 229 224 263 266 239 245 262 244 243 234 249 273 232 241 280 234 236 258 236 259 238 230 244 282 257 276 285 234 263 245 241 229 272 260 258 257 224 264 287 228 248 236 247 247 248 265 265 230 236 220 264 241 249 236 248 276 248 256 243 244 280 282 242 264 237 235 259 243 235 261 288 278 225 240 235 235 247 245 264 258 245 240 266 247 245 275 250 243 240 248 263 238 238 256 224 267 259 225 226 267 243 237 280 256 240 191 242 240 233 248 259 250 230 256 275 261 228 261 256 259 228 219 227 289 236 265 231 249 258 245 262 246 248 243 240 210 257 243 245 273 239 238 262 236 245 228 256 218 245 292 268 271 257 243 238 265 225 256 246 260 233 229 276 243 238 243 263 224 262 240 256 247 226 288 283 292 256 242 245 233 237 286 232 259 237 281 238 262 283 225 280 224 226 262 224 234 280 233 249 270 266 240 220 261 268 265 249 226 266 258 257 235 244 244 271 265 231 275 231 246 228 232 255 257 246 207 257 216 264 264 231 230 261 256 262 269 245 265 268 257 248 234 232 246 248 258 268 230 230 277 259 267 239 228 247 256 237 270 255 265 241 240 243 244 222 247 287 290 246 279 262 266 259 234 232 250 255 248 243 273 232 241 236 235 258 276 233 244 225 220 225 259 266 257 223 247 243 233 209 289 274 281 260 245 248 286 256 259 262 245 240 266 282 227 249 236 265 240 246 278 281 232 258 242 279 256 259 275 243 243 259 245 272 277 268 262 261 236 255 258 259 258 238 264 231 244 307 242 273 245 300 243 249 241 240 241 255 277 248 231 277 249 261 232 220 287 233 243 237 249 245 267 246 245 256 240 245 261 246 239 265 211 271 240 269 262 258 248 246 274 240 263 278 269 268 266 235 244 255 260 262 235 264 242 263 242 269 246 243 229 269 263 278 245 259 274 266 232 245 234 272 231 238 241 228 236 257 268 241 275 244 245 237 286 265 236 257 214 285 258 283 257 288 226 271 256 262 244 281 246 258 234 225 269 233 250 231 270 244 237 281 281 272 268 260 256 228 262 235 278 287 235 261 260 235 261 249 259 236 220 216 271 256 236 236 256 274 240 285 222 232 265 238 274 249 260 268 238 261 242 221 259 247 224 235 234 242 265 260 260 244 259 275 270 266 299 233 256 249 286 231 262 281 265 274 261 242 244 256 227 261 226 261 264 230 219 239 249 208 238 258 263 282 272 248 305 257 267 232 243 235 273 308 271 263 244 223 269 242 260 266 271 276 229 241 235 217 269 241 243 235 263 242 234 261 266 230 226 257 271 224 270 223 270 247 246 234 258 258 238 246 276 283 255 263 229 245 276 231 274 227 256 244 250 284 240 264 300 255 284 260 219 277 266 240 267 288 274 264 245 270 271 259 256 247 281 201 227 238 246 265 226 225 228 259 249 230 265 248 260 223 248 282 230 259 266 238 258 256 217 244 246 278 235 227 275 232 242 258 260 258 281 238 264 242 272 256 260 247 256 221 240 237 280 269 240 244 238 241 224 232 266 271 228 248 259 272 255 260 231 244 245 263 281 240 267 228 223 269 236 238 229 226 232 264 257 247 223 245 271 286 234 231 261 248 279 260 275 266 257 244 240 243 236 270 265 219 208 268 239 241 255 235 247 260 238 258 227 270 258 286 262 224 239 256 238 230 235 272 244 269 296 263 255 247 222 256 237 261 245 288 228 240 267 248 242 262 234 212 239 231 256 273 235 232 248 280 241 222 262 220 260 242 231 232 246 270 255 246 267 273 244 270 249 238 256 284 271 256 221 247 269 278 259 237 238 230 237 215 263 258 231 216 256 275 274 262 209 264 222 263 244 271 235 246 246 250 259 248 285 272 219 248 258 261 264 258 248 238 271 271 266 259 230 271 236 261 241 259 215 268 257 269 242 242 227 244 266 233 208 242 262 258 273 267 228 262 267 263 268 270 255 275 239 261 276 232 258 255 258 257 226 260 242 246 263 242 217 266 264 232 245 233 250 240 228 289 245 273 237 275 280 272 259 220 243 237 249 255 268 295 245 276 256 267 273 227 234 286 271 261 263 231 268 216 249 275 272 278 258 267 276 270 256 249 263 248 258 245 243 256 262 272 269 238 258 247 288 241 269 286 263 263 276 235 259 280 229 246 241 256 232 269 229 231 257 256 248 233 283 246 262 241 249 246 297 261 259 229 245 235 246 242 242 228 238 247 245 248 278 295 248 241 236 268 248 264 258 248 259 269 243 237 262 262 271 264 270 255 258 249 246 263 275 226 234 240 265 225 243 223 250 248 219 237 258 265 223 269 288 257 224 277 241 271 241 256 231 238 238 265 233 264 247 280 249 269 255 243 264 273 258 246 215 270 249 215 243 259 233 242 270 277 247 248 249 295 258 274 259 266 255 272 245 243 264 256 278 247 273 233 248 270 284 236 218 270 241 237 255 297 259 248 245 229 262 234 277 245 266 232 241 241 237 231 239 285 241 257 265 259 255 244 257 258 291 264 261 260 231 228 244 234 235 243 240 267 256 262 234 261 230 237 236 228 261 234 241 249 237 256 248 212 263 239 276 269 257 283 256 292 237 263 235 283 261 289 290 233 257 244 259 237 221 282 263 267 237 247 262 246 235 241 241 237 234 257 209 237 246 238 259 259 259 284 264 255 246 246 267 240 249 264 262 273 258 233 255 259 265 242 248 255 248 263 257 245 243 282 269 265 257 265 265 264 263 263 249 231 270 264 234 236 281 245 228 257 272 256 272 258 277 263 241 263 258 237 236 243 235 232 229 256 257 277 238 262 264 237 234 280 270 268 286 231 231 271 276 261 257 220 238 259 231 273 222 241 279 247 239 260 275 243 269 260 221 243 232 243 265 260 233 269 208 261 238 244 298 276 266 270 264 239 255 244 256 249 235 242 227 258 270 257 273 272 249 236 222 258 265 258 272 270 255 268 244 282 271 282 249 242 243 246 236 241 249 267 264 286 258 236 259 262 243 223 249 285 244 236 272 273 257 270 218 263 292 275 255 245 264 266 241 291 281 257 260 272 244 263 257 276 240 274 270 283 278 261 287 266 259 283 232 270 259 250 267 278 284 260 257 270 245 276 259 250 268 226 247 260 291 262 298 276 265 265 247 244 245 236 309 263 293 263 279 267 271 258 267 270 273 243 276 244 256 276 280 278 293 239 265 246 265 261 268 236 278 229 245 258 289 265 265 263 233 241 277 273 256 269 260 266 297 241 235 257 243 258 248 274 255 237 269 241 262 245 265 275 257 271 256 268 268 278 257 247 264 267 250 227 294 297 243 275 262 241 263 263 259 278 249 291 278 267 258 249 257 258 274 272 255 290 262 247 256 260 255 272 250 259 237 258 287 279 237 246 248 275 236 274 269 271 239 272 250 267 265 264 268 268 273 266 258 277 268 260 265 243 222 286 231 235 265 243 262 262 222 234 256 244 275 262 244 231 236 244 272 247 274 235 265 259 279 221 265 267 268 231 245 259 261 271 231 243 274 256 275 284 265 260 263 281 256 261 258 255 258 258 243 273 256 244 233 218 273 232 249 262 259 225 248 235 271 255 239 245 267 281 259 258 272 271 265 231 276 265 244 249 238 244 233 240 255 272 275 240 246 249 256 249 265 256 275 261 274 278 257 233 262 245 245 260 242 238 246 265 264 266 265 229 245 259 262 260 274 240 264 262 270 259 237 255 274 236 243 285 247 271 266 237 265 247 222 243 283 276 261 263 280 235 246 245 268 261 285 257 261 293 263 291 233 279 256 246 296 260 267 243 258 262 270 270 258 258 273 275 276 265 259 269 273 267 275 255 257 247 246 260 284 284 270 256 271 266 246 245 257 269 289 267 232 232 257 280 257 234 235 284 258 241 275 242 278 231 249 272 242 258 258 243 247 270 273 248 250 268 250 298 259 290 263 285 269 258 255 268 298 221 262 269 240 255 258 243 235 259 239 266 274 262 285 267 216 266 269 244 258 263 277 245 264 267 247 278 244 262 245 279 255 229 269 290 257 239 218 263 248 246 256 273 204 291 264 234 257 256 269 278 273 246 275 238 256 213 258 291 285 272 235 268 279 247 222 274 301 261 227 278 249 242 261 227 287 236 263 255 232 278 299 260 261 249 259 238 278 257 236 243 232 256 271 273 257 243 269 283 286 280 263 247 280 267 235 242 221 221 232 248 279 258 249 270 267 226 263 264 237 258 265 261 257 279 260 301 248 277 250 256 275 263 277 246 238 241 282 265 244 241 242 258 265 277 246 257 235 222 248 240 247 267 232 275 264 239 248 260 277 281 231 235 247 261 246 245 247 236 229 248 258 271 249 260 215 231 258 297 219 231 235 274 281 280 278 243 248 263 279 268 237 258 268 250 269 256 271 263 247 228 268 283 273 269 247 281 256 239 249 234 230 257 257 276 270 297 291 249 261 292 249 243 264 279 258 265 275 264 260 277 261 261 260 294 242 240 243 288 283 233 265 260 259 248 265 232 236 214 241 236 246 233 245 239 255 244 230 292 265 262 226 238 255 282 269 240 264 278 281 234 260 245 286 231 238 275 243 257 248 276 249 282 243 245 235 242 262 250 237 257 249 302 243 266 260 249 276 213 247 282 240 269 255 243 240 259 258 233 288 265 271 264 247 248 230 262 264 260 268 269 255 266 297 255 261 248 247 267 258 245 245 219 270 243 237 232 255 283 267 242 277 232 298 243 244 260 249 268 235 262 248 232 261 240 239 266 229 247 255 235 260 259 245 256 239 259 247 231 244 240 261 281 270 272 265 267 257 271 256 249 268 243 269 269 246 259 276 285 266 269 245 213 280 271 241 262 278 264 247 247 278 242 221 222 268 279 285 263 243 275 262 249 268 249 235 243 240 257 244 239 239 272 240 245 261 258 266 249 238 228 263 247 232 301 255 225 278 274 275 249 277 225 238 271 266 228 243 225 233 244 289 240 264 248 248 269 247 244 240 243 238 238 248 248 245 244 258 261 236 270 244 280 246 237 277 281 241 272 238 276 256 279 258 221 267 283 239 257 248 298 270 244 260 261 286 265 261 220 275 230 255 272 274 234 257 230 223 259 249 266 263 239 280 265 234 267 234 255 275 225 245 262 244 271 288 256 256 240 277 274 282 265 258 241 233 261 268 263 228 245 231 249 288 266 290 269 239 234 238 256 271 234 224 237 256 247 243 275 241 273 247 270 260 259 246 242 288 264 277 245 241 262 231 269 255 249 260 297 264 277 274 243 273 247 244 259 250 224 245 237 224 268 244 269 267 228 245 260 268 231 243 235 245 265 247 246 242 237 265 269 274 240 241 243 235 288 247 248 248 226 271 250 248 273 225 244 243 241 236 244 248 259 231 241 268 260 247 259 236 237 245 245 279 248 244 255 270 257 263 262 226 288 262 266 259 239 255 258 228 219 270 258 271 240 285 229 249 296 271 231 299 284 273 259 232 263 275 258 268 293 235 270 267 257 261 235 277 242 250 243 269 261 288 261 262 250 273 260 256 259 256 225 245 242 257 272 237 249 281 237 257 273 243 258 263 215 264 280 236 262 267 234 233 255 229 258 271 262 236 245 235 264 267 248 240 245 228 238 243 247 241 249 269 236 260 249 224 290 266 246 273 267 227 256 282 226 244 237 261 284 262 272 215 273 276 275 242 239 245 267 218 260 274 263 255 244 284 271 226 235 288 262 238 277 260 228 260 272 261 265 261 216 243 276 228 238 256 276 261 279 259 228 230 236 240 262 243 267 264 267 264 261 224 286 271 227 232 258 235 262 273 236 265 259 232 229 243 247 258 255 270 274 244 281 233 255 279 278 284 233 241 232 256 283 246 285 256 248 246 272 278 258 276 247 260 238 257 272 238 265 274 266 278 265 259 297 245 224 272 241 257 248 231 243 264 239 268 248 287 279 236 290 272 261 244 239 230 261 282 231 276 238 265 247 224 241 285 280 273 243 256 262 268 268 272 271 243 244 244 263 265 257 272 279 262 245 264 267 255 275 245 239 230 242 260 261 222 262 219 275 289 236 274 278 273 246 290 233 219 273 224 283 264 261 240 244 267 224 281 271 260 283 248 222 255 283 293 260 287 249 255 241 261 243 244 259 271 246 260 271 259 273 238 264 283 259 267 241 246 225 260 248 283 289 293 242 293 260 265 239 264 261 286 264 276 248 263 274 230 258 244 274 242 258 242 247 265 272 258 244 249 260 244 245 246 243 256 255 266 263 258 260 255 272 230 272 245 264 265 249 258 257 231 280 277 230 280 274 263 226 261 255 235 276 243 243 260 272 237 215 269 269 270 236 238 247 260 221 256 267 283 241 272 279 282 221 257 281 264 237 244 238 248 250 234 260 249 257 286 236 264 247 260 263 263 275 257 241 256 285 269 261 281 232 238 232 289 232 247 264 270 275 232 280 291 246 263 268 263 247 236 257 276 290 278 217 274 259 269 279 232 262 272 258 243 231 233 288 261 266 261 239 276 241 263 247 264 258 242 247 278 279 231 277 263 270 275 243 283 242 250 255 286 268 275 256 220 244 259 242 228 266 290 243 266 229 244 280 255 262 255 249 285 267 233 264 235 237 247 234 229 265 242 230 256 239 260 274 269 266 269 248 242 249 258 273 256 272 255 275 234 263 268 270 232 236 242 270 257 265 269 242 266 265 280 245 280 244 270 239 236 271 262 261 225 264 286 260 231 246 255 274 270 293 267 238 247 274 272 257 271 257 281 274 289 284 281 274 281 260 223 256 260 262 240 261 230 260 271 275 242 265 228 262 276 244 262 261 221 249 269 268 290 250 280 250 249 278 267 258 244 264 256 242 250 241 276 287 276 270 268 258 236 268 246 275 264 241 267 279 264 275 258 286 240 267 266 259 266 250 266 264 265 260 259 244 274 303 267 260 267 237 281 260 243 276 290 263 276 256 278 226 242 245 268 275 265 279 268 245 256 266 293 262 310 258 237 270 290 271 267 284 258 280 259 268 271 248 298 241 258 271 249 269 228 270 290 287 245 277 294 276 298 275 269 240 259 264 292 285 295 262 264 243 268 271 273 266 268 248 278 246 275 290 286 270 279 245 301 301 311 260 245 285 287 265 273 266 283 308 278 276 276 291 266 249 270 286 261 286 268 263 272 282 263 280 265 280 263 280 279 266 283 260 263 281 266 215 299 275 273 277 248 287 272 255 247 244 265 229 288 281 291 232 256 271 283 270 243 243 296 235 260 284 282 237 294 265 284 262 257 281 310 277 275 310 296 256 261 278 243 291 258 238 288 232 269 264 255 265 274 274 284 271 261 266 265 269 223 273 270 275 249 255 258 275 256 258 255 262 272 249 218 240 256 274 269 276 256 271 248 242 273 279 276 237 285 279 255 236 265 255 256 265 281 266 280 258 279 278 278 265 257 236 273 248 247 240 271 264 245 282 237 245 286 262 268 276 265 264 278 258 260 241 285 241 277 274 317 260 263 255 236 270 266 265 232 245 264 229 256 271 301 235 284 267 244 274 234 231 295 249 234 272 275 246 256 248 282 260 270 246 255 279 222 262 237 276 241 256 255 227 263 241 246 301 302 229 278 283 275 227 228 261 235 263 280 238 248 265 261 244 244 269 288 269 259 242 226 278 268 245 249 242 226 247 274 262 248 230 227 259 241 266 243 233 243 250 248 256 259 243 219 266 286 274 273 235 267 283 241 237 259 295 262 276 250 259 262 233 240 242 260 256 247 238 269 277 234 259 267 231 264 264 246 250 248 238 264 228 273 263 272 240 246 274 250 240 242 258 267 258 238 257 258 262 255 261 270 261 258 266 236 240 239 276 255 248 256 230 268 270 233 220 230 282 238 247 291 256 286 241 245 259 247 258 259 248 236 256 241 256 231 270 246 227 256 244 249 256 285 242 246 263 222 236 234 279 221 258 247 266 264 289 240 249 281 261 232 266 228 256 260 277 266 256 255 272 216 234 238 267 263 258 255 258 233 249 258 249 260 237 248 212 276 246 239 264 244 246 271 256 274 230 267 229 236 231 256 241 255 231 242 261 241 269 229 230 308 273 214 265 237 272 225 259 250 239 233 234 245 242 269 226 281 236 243 265 238 278 262 288 255 238 280 256 239 256 269 247 264 271 266 267 283 276 285 260 261 255 275 238 265 245 222 266 274 259 240 260 262 229 225 241 250 255 264 284 245 249 238 230 263 232 230 239 248 260 206 287 268 279 239 236 257 281 258 266 242 275 228 262 267 238 245 238 240 270 282 236 265 234 235 264 259 259 256 262 266 247 248 265 235 285 258 256 295 279 266 266 235 274 246 267 276 245 264 258 248 242 238 237 235 257 257 259 270 240 261 268 242 245 239 258 262 228 258 292 274 282 284 274 255 246 241 245 276 256 243 248 287 242 269 292 277 244 243 258 279 256 258 277 260 269 229 256 248 245 248 267 236 249 257 281 271 263 227 268 238 265 292 264 247 250 236 243 231 271 236 228 262 240 260 220 258 259 268 272 274 262 222 248 281 289 292 235 260 249 236 273 273 243 257 259 261 263 259 248 284 273 244 255 271 241 230 260 260 244 240 258 271 266 290 255 287 236 264 290 271 267 267 258 235 264 257 220 256 284 261 234 265 279 257 284 244 262 248 241 256 270 273 267 270 244 274 283 276 264 243 280 246 257 260 258 236 284 244 239 257 259 237 222 231 247 271 271 269 284 274 261 282 277 265 234 282 307 258 246 269 234 260 233 265 247 270 256 278 269 259 230 269 244 284 286 266 267 285 246 261 265 239 278 256 272 246 238 248 279 277 225 237 271 242 260 287 260 261 242 272 276 234 238 243 257 225 242 261 258 267 267 269 260 238 249 263 268 265 283 286 274 244 234 273 257 248 259 235 260 223 278 257 255 262 247 255 256 263 278 290 275 273 230 263 260 263 231 232 255 243 228 269 249 245 244 260 287 242 264 248 237 244 264 287 259 234 257 235 247 287 266 262 230 244 270 266 237 263 259 269 260 275 242 236 262 266 295 232 272 242 245 243 259 284 247 271 257 229 237 256 261 276 262 237 238 249 271 277 284 249 260 256 265 280 274 257 302 269 263 237 217 271 288 256 236 266 270 266 245 280 235 264 282 256 257 228 261 227 249 290 238 298 249 233 256 242 235 256 274 260 261 260 280 248 274 279 287 242 263 291 285 258 260 267 279 233 266 244 274 270 258 269 233 245 238 238 267 271 275 249 255 255 271 225 257 269 266 240 244 293 258 229 247 282 277 260 232 280 259 275 236 255 286 227 286 277 244 256 262 215 242 245 264 288 267 260 306 264 241 265 258 261 265 245 242 226 268 284 230 286 262 268 261 233 284 261 271 279 275 259 246 284 244 255 274 294 258 238 270 293 247 230 299 268 273 229 273 291 236 222 276 299 266 259 240 259 258 270 255 233 247 261 256 229 221 267 247 219 272 284 259 225 248 282 263 234 245 280 232 224 273 255 257 258 237 266 280 276 271 243 248 272 236 259 270 262 270 285 290 271 225 248 258 232 268 267 256 267 272 269 266 282 256 268 246 259 228 281 270 245 261 279 293 237 243 279 242 286 241 270 265 264 229 257 239 261 279 293 267 243 243 231 269 232 261 286 231 275 270 260 249 227 286 258 233 244 268 258 264 245 278 269 262 287 236 278 236 268 257 238 274 243 275 230 288 235 250 237 284 263 242 269 233 259 249 272 272 279 257 292 260 265 260 241 275 264 256 261 264 249 242 266 256 284 244 238 264 292 238 240 271 246 268 246 244 279 259 274 290 268 275 259 249 289 245 265 247 259 223 258 249 246 285 303 249 255 237 272 282 211 277 228 249 258 277 258 261 274 266 269 263 274 242 287 262 264 297 284 247 262 270 276 236 227 291 265 263 236 273 214 249 236 247 284 243 261 262 260 244 276 280 239 226 270 275 260 280 273 276 287 272 241 259 267 234 273 278 289 267 263 263 272 242 242 259 224 258 263 242 268 275 255 245 242 284 236 238 255 261 257 282 238 231 233 277 233 238 286 276 258 241 247 258 255 241 295 257 268 246 246 277 270 284 266 285 234 290 256 236 260 226 246 256 248 265 239 272 278 245 247 255 247 272 281 265 270 245 231 274 247 255 260 273 246 235 245 249 310 282 278 268 274 257 277 289 266 275 269 276 259 286 288 272 276 248 255 239 260 241 269 232 267 261 272 233 258 264 241 287 262 247 267 258 269 247 269 234 250 263 279 269 243 273 265 237 234 311 258 288 272 265 257 272 264</counts>
			</dataPoints>
		</scan>
	</xrdMeasurement>
</xrdMeasurements>