File: data/XRD/XG-Luft/XG-800/W6821-1D_XG_Luft_800.xrdml
<xrdMeasurements xmlns="http://www.xrdml.com/XRDMeasurement/2.1" xmlns:xsi="http://www.w3.org/2001/XMLSchema-instance" xsi:schemaLocation="http://www.xrdml.com/XRDMeasurement/2.1 http://www.xrdml.com/XRDMeasurement/2.1/XRDMeasurement.xsd" status="Completed">
	<comment>
		<entry>Configuration=Factory configuration, Owner=User-1, Creation date=7/8/2013 4:01:53 PM</entry>
		<entry>Goniometer=PW3050/65 (Theta/2Theta); Minimum step size 2Theta:0.0001; Minimum step size Omega:0.0001</entry>
		<entry>Sample stage=MRD Cradle; Minimum step size Phi:0.01; Minimum step size Chi:0.01; Minimum step size X:0.01; Minimum step size Y:0.01; Minimum step size Z:0.001</entry>
		<entry>Diffractometer system=XPERT-PRO</entry>
		<entry>Measurement program=C:\PANalytical\Data Collector\Programs\Jorrit\2thom\_absolute_2th-om_10-130deg_PIXscan_56min.xrdmp, Identifier={15BCCF57-2807-42BD-B5B9-ECC0B3DC9284}</entry>
		<entry>Batch program=C:\PANalytical\Data Collector\Programs\SimonL\batch6x_2thom_10-130°_z9.1_x0,10,20,30_y20,40_57min - Kopie.xrdmp, Identifier={8874E540-C3F4-4307-831A-CD55F073CDCD}</entry>
	</comment>
	<sample type="To be analyzed">
		<id></id>
		<name></name>
		<preparedBy></preparedBy>
	</sample>
	<xrdMeasurement measurementType="Scan" status="Completed" sampleMode="Reflection">
		<comment>
			<entry>_absolute_2th-om_10-130deg_PIXscan_56min</entry>
			<entry>PHD Lower Level = 4.83 (keV), PHD Upper Level = 11.27 (keV)</entry>
		</comment>
		<usedWavelength intended="K-Alpha 1">
			<kAlpha1 unit="Angstrom">1.5405980</kAlpha1>
			<kAlpha2 unit="Angstrom">1.5444260</kAlpha2>
			<kBeta unit="Angstrom">1.3922500</kBeta>
			<ratioKAlpha2KAlpha1>0.5000</ratioKAlpha2KAlpha1>
		</usedWavelength>
		<incidentBeamPath>
			<radius unit="mm">320.00</radius>
			<xRayTube id="1010048" name="Empyrean Cu LFF HR (9430 033 7310x) DK442154">
				<tension unit="kV">40.0</tension>
				<current unit="mA">40.0</current>
				<anodeMaterial>Cu</anodeMaterial>
				<focus type="Line">
					<length unit="mm">12.0</length>
					<width unit="mm">0.4</width>
					<takeOffAngle unit="deg">4.2</takeOffAngle>
				</focus>
			</xRayTube>
			<xRayMirror id="27010001" name="Inc. Beam Cu W/Si (parabolic MRD)" hybrid="false">
				<crystal type="Graded" shape="Parabolic">W/Si</crystal>
				<acceptanceAngle unit="deg">0.800</acceptanceAngle>
				<length unit="mm">60.0</length>
			</xRayMirror>
			<sollerSlit id="21010002" name="Soller slits 0.04 rad.">
				<opening unit="rad">0.0400</opening>
			</sollerSlit>
			<mask id="22030007" name="Fixed mask 2 mm">
				<distanceToSample unit="mm">220.00</distanceToSample>
				<width unit="mm">2.00</width>
			</mask>
			<divergenceSlit id="22010007" name="Fixed slit 1/8°" xsi:type="fixedDivergenceSlitType">
				<distanceToSample unit="mm">220.00</distanceToSample>
				<height unit="mm">0.19</height>
			</divergenceSlit>
		</incidentBeamPath>
		<diffractedBeamPath>
			<radius unit="mm">320.00</radius>
			<sollerSlit id="21010002" name="Soller slits 0.04 rad.">
				<opening unit="rad">0.0400</opening>
			</sollerSlit>
			<receivingSlit id="22010001" name="Fixed slit 4°">
				<height unit="mm">5.88</height>
			</receivingSlit>
			<detector id="7010017" name="PIXcel3D 1x1 detector" xsi:type="areaDetectorType">
				<phd unit="%">
					<lowerLevel>30.0</lowerLevel>
					<upperLevel>70.0</upperLevel>
				</phd>
				<mode>Scanning</mode>
				<activeChannelsEquatorial>255</activeChannelsEquatorial>
				<activeChannelsAxial>255</activeChannelsAxial>
				<pitchEquatorial unit="mm">0.05500</pitchEquatorial>
				<pitchAxial unit="mm">0.05500</pitchAxial>
				<readOutPeriod unit="seconds">0.135</readOutPeriod>
			</detector>
		</diffractedBeamPath>
		<scan appendNumber="0" mode="Continuous" scanAxis="2Theta-Omega" status="Completed">
			<header>
				<startTimeStamp>2024-10-28T21:02:48+01:00</startTimeStamp>
				<endTimeStamp>2024-10-28T21:58:52+01:00</endTimeStamp>
				<author>
					<name>PRO-MRD</name>
				</author>
				<source>
					<applicationSoftware version="6.1b">Data Collector</applicationSoftware>
					<instrumentControlSoftware version="7.0E 20130304">XPERT-PRO</instrumentControlSoftware>
					<instrumentID>0000000011142674</instrumentID>
				</source>
			</header>
			<dataPoints>
				<positions axis="2Theta" unit="deg">
					<startPosition>9.99826193</startPosition>
					<endPosition>129.99755682</endPosition>
				</positions>
				<positions axis="Omega" unit="deg">
					<startPosition>4.99913096</startPosition>
					<endPosition>64.99877841</endPosition>
				</positions>
				<positions axis="Phi" unit="deg">
					<commonPosition>0.00</commonPosition>
				</positions>
				<positions axis="Chi" unit="deg">
					<commonPosition>0.00</commonPosition>
				</positions>
				<positions axis="X" unit="mm">
					<commonPosition>0.00</commonPosition>
				</positions>
				<positions axis="Y" unit="mm">
					<commonPosition>0.00</commonPosition>
				</positions>
				<positions axis="Z" unit="mm">
					<commonPosition>9.100</commonPosition>
				</positions>
				<commonCountingTime unit="seconds">32.895</commonCountingTime>
				<counts 443 409 435 413 404 431 434 431 437 423 390 429 423 418 464 432 422 445 416 444 385 437 409 413 433 402 412 418 402 372 383 446 402 394 436 405 390 416 431 386 402 460 453 451 412 427 429 392 430 412 381 380 419 430 435 405 418 404 419 414 391 421 390 404 391 433 396 371 438 442 422 391 385 435 407 372 408 396 411 421 433 381 408 419 379 407 436 357 417 401 392 394 401 382 396 418 417 395 394 437 417 386 385 400 427 362 391 380 391 411 417 394 378 388 405 375 389 386 364 424 413 354 406 362 372 387 393 412 388 387 428 378 373 398 368 412 417 385 369 380 370 401 393 378 399 432 393 417 381 421 385 370 409 399 401 427 392 386 372 392 387 397 355 375 363 386 375 358 397 371 381 354 359 370 370 408 350 395 371 362 353 394 362 365 345 343 380 392 362 375 349 396 401 365 354 330 393 328 398 385 396 387 372 421 366 379 371 345 403 369 408 338 339 353 357 393 396 388 352 361 375 388 410 377 373 370 382 392 357 406 365 375 346 353 396 362 372 410 363 366 341 360 400 345 336 344 360 368 386 355 335 390 330 369 347 366 371 338 373 341 390 389 342 375 352 365 348 332 374 353 392 346 323 345 349 332 360 392 370 345 387 351 324 333 366 358 350 353 361 356 363 353 367 344 366 355 360 345 378 339 332 344 326 380 339 399 333 378 359 336 355 358 365 389 341 329 363 328 359 327 336 379 348 355 339 367 349 330 379 348 370 376 347 349 358 331 343 351 357 335 361 355 353 350 339 349 345 328 339 359 321 363 331 385 323 308 339 353 335 337 327 351 337 328 351 354 355 341 346 315 352 328 346 331 321 328 341 326 332 333 329 322 302 345 326 349 309 314 378 314 316 290 340 332 316 305 327 317 334 335 322 328 337 344 315 288 328 333 321 332 335 328 317 328 347 328 305 300 329 306 318 338 347 311 350 313 338 318 328 354 306 312 310 324 335 295 349 342 296 294 310 303 329 365 321 356 317 330 325 312 325 324 310 324 354 331 337 319 298 359 313 309 271 309 354 332 327 322 343 319 343 326 329 296 283 289 301 306 335 321 343 337 329 276 308 293 327 320 323 304 323 312 303 307 300 287 279 335 304 303 297 324 316 327 326 339 337 279 289 327 299 295 304 320 303 305 334 291 346 311 291 330 321 337 316 298 294 307 325 329 301 305 337 324 286 317 308 340 301 352 303 302 293 291 299 310 363 298 305 303 314 321 273 298 335 288 314 340 305 296 301 296 355 295 320 315 297 275 321 303 296 317 323 307 300 273 307 334 317 315 299 337 300 332 314 295 305 298 306 280 284 331 300 300 305 305 286 313 320 313 313 343 290 285 285 291 305 310 316 304 288 309 298 300 312 318 306 286 317 293 297 304 318 316 298 281 295 323 274 314 330 298 325 288 302 298 247 297 297 306 317 329 303 320 344 323 280 288 290 329 292 287 274 303 330 294 306 306 319 284 291 305 267 279 296 299 302 308 299 273 310 302 278 311 315 303 283 312 321 291 295 291 296 294 300 300 328 329 304 310 279 280 315 284 306 295 302 271 326 304 322 322 311 332 298 277 324 283 309 270 298 299 307 295 329 293 266 295 296 320 320 299 285 317 300 308 295 306 313 299 274 294 315 305 304 293 273 303 304 331 309 305 298 317 304 293 264 293 316 325 300 291 302 294 279 286 321 335 300 286 301 303 299 279 299 314 309 312 292 305 302 272 303 301 279 287 295 313 300 304 302 301 311 305 316 307 279 303 291 324 282 282 314 335 272 319 289 262 320 298 293 302 288 304 323 289 287 327 306 307 303 273 309 335 321 325 299 314 308 333 297 300 309 285 287 307 306 288 309 293 292 311 321 321 322 317 294 316 297 324 313 337 293 308 307 301 313 334 276 332 314 287 279 309 280 300 325 290 283 281 290 287 339 303 277 306 287 277 299 315 302 298 283 320 299 309 310 264 289 329 299 318 303 326 273 286 323 293 304 291 285 316 291 318 293 280 299 299 291 305 326 306 297 291 308 323 308 279 308 316 312 299 307 318 281 322 299 289 319 279 299 327 300 323 331 281 318 267 322 300 283 303 323 317 307 297 283 298 295 295 291 283 321 341 275 327 304 294 307 283 327 292 327 331 305 312 344 318 316 337 311 307 314 291 326 319 302 277 303 300 270 312 316 318 286 313 293 268 308 293 310 292 278 305 325 301 324 338 315 341 351 299 306 302 306 297 325 299 331 311 283 332 335 294 303 314 318 275 300 326 333 323 309 320 280 268 315 325 327 317 317 293 292 298 327 331 301 301 341 300 299 282 342 327 293 303 332 285 306 324 330 324 300 328 311 297 307 314 294 318 313 332 315 305 279 291 326 307 318 327 315 301 299 262 328 302 290 319 303 294 331 325 347 310 318 331 304 316 307 340 319 339 335 318 327 296 305 318 299 315 321 322 317 338 327 267 325 315 316 294 339 305 286 346 275 299 332 322 328 309 327 320 311 285 310 294 302 327 320 283 324 340 302 316 325 328 331 316 323 341 297 326 316 301 347 329 330 303 328 315 299 340 324 342 318 356 310 329 312 319 310 311 341 308 321 290 323 315 300 306 279 315 339 325 283 307 300 308 317 327 314 298 332 332 322 282 310 301 324 328 327 338 337 284 339 297 317 341 294 318 320 334 279 342 322 326 316 358 333 308 345 334 320 340 303 355 330 322 330 310 322 348 324 293 322 300 303 324 340 352 326 331 302 312 345 333 322 308 324 296 321 311 310 275 298 323 330 302 305 311 328 349 314 319 303 326 336 316 332 298 332 338 306 305 330 304 316 336 315 310 308 295 321 302 344 350 321 294 326 282 309 294 321 322 309 330 355 328 295 319 302 344 285 313 306 308 326 305 300 314 311 304 312 331 322 319 308 330 332 335 312 344 303 304 305 336 308 323 294 300 356 330 342 306 331 309 340 317 294 337 307 336 304 349 329 310 334 371 315 314 322 329 321 302 305 313 330 343 335 332 306 351 312 304 301 335 332 311 328 321 308 302 301 318 333 310 324 326 303 329 331 301 313 316 276 306 304 288 334 319 304 311 315 317 300 329 326 311 286 325 294 287 325 316 324 322 347 293 304 340 288 311 343 298 308 313 307 300 283 332 353 315 319 272 284 304 298 295 312 308 298 312 318 284 332 328 327 305 292 314 318 306 313 289 331 301 325 297 264 315 308 335 301 282 343 309 347 280 286 295 305 311 293 322 289 296 319 295 318 311 317 294 301 321 311 313 303 320 312 299 295 288 306 274 276 269 291 307 293 310 310 316 290 337 290 342 305 299 317 329 287 296 303 328 310 332 305 286 308 293 344 320 295 290 303 333 278 303 321 277 320 292 312 290 315 323 298 294 320 306 289 290 269 329 321 333 310 339 248 320 280 310 298 294 320 302 325 275 296 261 306 307 324 315 281 298 304 265 305 301 269 315 276 308 280 292 295 288 310 277 290 324 311 297 289 283 299 297 308 318 321 309 240 304 325 304 319 287 304 326 281 291 302 285 318 265 282 303 324 320 318 322 271 326 306 307 296 290 286 285 313 324 304 283 308 307 308 312 295 309 330 275 316 311 278 317 274 305 293 285 283 289 264 281 281 303 265 295 281 307 292 306 293 336 273 297 298 306 267 294 295 307 286 275 292 300 297 291 280 278 303 311 289 290 310 297 287 311 292 316 323 278 303 308 277 303 288 271 292 322 274 267 292 297 302 302 289 269 284 275 308 309 314 327 282 294 297 290 307 240 284 315 264 265 278 293 303 306 331 295 298 279 263 293 304 300 293 334 291 272 287 285 320 295 326 287 284 268 302 296 287 266 260 288 318 292 302 289 282 270 292 275 296 300 264 258 310 268 242 272 257 318 275 308 281 272 305 303 287 276 308 294 292 291 279 308 292 285 301 315 284 288 294 305 277 281 310 266 280 304 281 294 312 294 286 284 292 306 287 319 274 262 284 304 286 294 283 279 275 293 298 295 274 284 295 280 297 275 261 285 280 258 301 310 317 287 299 281 302 249 280 263 277 288 272 303 291 277 298 273 309 277 267 290 326 297 288 278 279 278 281 283 287 292 265 317 297 315 302 282 292 284 271 303 280 283 301 274 269 278 270 284 264 289 284 319 288 302 282 243 293 277 269 296 282 296 297 284 289 291 306 297 282 276 271 262 294 267 314 281 266 306 281 212 292 289 299 281 266 292 296 271 269 305 279 286 277 288 271 299 269 259 290 248 261 260 226 282 295 270 267 288 274 272 290 273 287 286 274 287 257 297 238 268 279 293 284 270 275 265 281 311 312 279 279 239 269 311 290 287 268 288 288 294 296 245 274 238 255 285 249 272 250 260 276 261 299 263 282 296 268 246 266 295 263 292 269 263 294 256 270 273 280 272 279 280 250 275 277 250 292 255 262 286 263 283 280 286 305 265 292 284 272 275 268 274 283 272 242 249 270 283 297 275 248 290 256 293 263 274 260 295 260 247 274 259 265 301 273 264 279 280 232 282 309 241 288 243 298 248 266 247 261 241 269 267 256 255 261 267 262 233 241 284 258 279 302 265 297 264 232 275 267 279 284 247 277 241 279 276 255 292 279 261 238 241 292 273 269 275 235 234 246 241 260 307 240 267 271 230 280 278 279 283 234 245 244 262 249 277 232 262 271 262 279 240 266 296 309 243 260 263 271 257 270 267 269 282 259 262 305 293 266 270 269 280 271 268 273 240 287 235 248 220 259 271 282 256 261 274 240 296 275 269 280 275 302 261 259 242 235 263 289 272 260 248 260 294 278 268 300 247 268 269 278 294 276 280 265 247 271 288 256 267 270 287 275 256 273 267 236 284 267 294 284 270 245 259 243 255 265 274 275 245 261 282 247 289 260 263 270 283 259 278 305 259 262 275 286 265 291 246 263 264 277 265 261 245 249 245 266 262 285 255 278 293 273 283 264 241 243 272 275 260 261 233 294 276 297 275 292 240 239 271 280 258 274 272 272 292 257 250 274 225 266 282 258 272 281 256 229 218 272 231 278 277 280 262 266 281 277 246 264 278 292 281 281 264 245 258 256 248 249 265 249 302 307 244 269 274 244 266 261 246 268 278 289 256 261 278 227 255 282 267 261 286 255 265 242 272 284 262 290 243 269 265 270 288 244 286 264 270 261 269 284 269 256 218 272 275 270 266 270 241 279 287 262 272 257 300 269 290 258 247 273 279 261 231 240 287 310 246 261 274 241 295 289 284 266 233 258 261 273 293 242 246 273 258 274 249 299 278 282 305 263 277 256 287 257 267 262 272 260 276 268 269 275 223 249 288 264 263 283 233 281 259 266 262 281 267 255 262 284 229 259 288 267 273 262 237 232 283 275 281 259 271 267 275 259 287 272 283 237 289 273 258 276 285 242 262 248 241 267 259 260 235 281 246 265 300 231 262 244 234 268 273 264 259 272 270 262 257 261 263 263 257 260 257 286 259 270 270 260 269 263 273 270 290 266 227 238 264 259 260 242 263 247 280 299 244 266 258 234 248 273 245 287 257 263 286 270 234 244 263 270 260 280 246 290 247 273 275 255 248 225 259 243 267 239 243 248 273 271 270 245 245 278 233 287 279 280 259 241 245 238 276 248 258 274 266 242 265 245 267 274 285 288 247 266 273 236 269 260 256 261 289 262 277 276 246 240 233 228 240 282 287 259 226 260 277 260 259 278 277 234 280 287 255 266 271 235 235 280 247 237 265 242 243 285 302 261 255 264 260 290 239 243 238 292 263 266 269 274 260 227 261 266 255 241 264 284 246 273 278 257 266 260 268 241 287 244 261 265 277 263 284 244 223 283 271 264 261 263 247 237 248 229 263 240 259 261 233 238 280 235 255 265 240 255 240 246 249 275 266 226 242 225 228 257 267 272 297 272 265 234 286 280 236 261 258 262 265 243 255 258 240 229 287 280 283 239 267 249 259 274 258 240 237 299 268 234 308 258 259 289 264 256 277 286 262 241 277 264 260 278 255 245 268 266 243 234 292 278 291 260 243 246 241 266 264 281 277 262 222 262 255 260 230 283 257 221 242 238 232 274 261 233 243 269 272 275 262 262 286 264 284 228 265 256 291 286 246 280 282 258 259 258 279 242 244 246 259 242 247 274 250 277 273 285 286 259 236 284 247 270 259 270 256 241 249 258 271 288 283 244 245 233 244 245 284 278 261 241 274 264 238 255 268 242 244 243 262 229 281 261 247 249 245 250 263 245 261 270 272 267 249 255 265 243 245 260 242 226 246 229 216 263 225 276 267 278 235 238 268 258 261 280 239 277 268 272 220 282 232 256 242 257 299 273 230 237 234 257 243 232 281 227 286 266 238 248 284 233 280 280 263 255 266 244 256 232 263 289 226 244 231 242 260 268 230 262 269 231 265 246 269 245 266 276 237 261 271 265 256 242 289 259 245 271 212 261 263 238 245 287 221 264 261 264 245 241 248 238 229 227 248 288 259 265 227 263 257 261 280 230 268 244 245 264 259 246 247 247 241 286 279 288 242 268 226 266 270 267 240 285 231 273 257 223 247 219 263 290 278 218 231 272 242 256 225 246 240 257 273 243 241 267 239 256 256 230 249 267 278 266 246 244 263 227 271 279 267 232 248 257 264 271 269 267 255 280 248 250 259 281 242 258 241 241 266 266 265 281 269 261 222 259 280 291 256 239 237 268 269 273 250 261 266 283 244 238 291 278 247 260 248 258 267 273 255 246 238 269 262 283 229 281 274 255 231 249 279 262 283 263 237 231 264 257 261 262 246 259 260 291 255 264 271 270 241 259 221 281 256 267 264 249 236 266 232 241 262 245 279 259 261 241 229 243 276 233 257 267 273 283 271 236 227 278 245 266 261 231 233 247 274 256 242 234 263 255 249 275 239 255 241 247 283 262 259 259 276 260 276 244 228 242 263 259 256 282 235 239 248 263 274 263 297 260 287 228 236 263 272 257 271 273 259 273 236 267 236 273 256 265 261 274 290 277 259 263 245 273 255 268 249 250 290 236 238 257 249 272 264 273 256 298 280 260 230 234 266 282 240 279 268 270 275 248 227 261 270 265 247 285 271 265 283 226 248 245 276 243 234 270 236 275 258 270 247 255 262 227 273 281 248 231 270 256 245 274 244 241 243 269 275 262 258 259 262 242 259 255 271 248 276 261 242 264 248 239 272 248 273 276 269 257 272 295 266 257 207 263 270 265 272 281 267 289 244 248 295 264 234 265 286 233 284 243 246 229 282 241 247 261 264 265 243 239 243 234 258 270 269 263 241 237 292 257 233 257 276 278 281 280 271 242 269 238 258 274 265 275 243 266 273 244 214 250 235 293 261 257 267 263 270 256 292 237 260 271 255 264 271 270 246 274 242 260 250 248 256 264 233 258 271 242 230 246 269 243 270 258 272 249 256 263 247 288 242 235 267 271 310 272 269 286 247 277 282 280 243 266 261 272 222 283 276 283 246 292 239 268 255 283 266 247 276 261 269 259 246 290 277 267 269 255 283 294 279 260 240 286 244 274 278 256 275 287 311 269 270 271 295 258 273 257 305 287 242 261 266 256 270 279 279 256 264 249 300 274 264 286 263 288 263 273 257 297 269 263 305 296 286 266 279 313 282 277 290 267 286 283 264 304 269 266 274 297 273 278 291 294 284 242 265 283 280 264 334 261 298 293 319 297 298 327 294 288 296 333 295 300 261 326 266 306 282 324 313 293 299 321 280 330 311 301 319 325 302 341 311 303 337 338 349 341 347 360 361 389 386 330 351 363 391 416 372 394 420 410 422 444 439 444 444 467 482 510 517 452 522 514 521 522 491 519 491 526 498 511 524 451 475 458 474 462 499 417 456 436 367 401 389 385 361 403 367 375 346 366 329 343 347 308 324 309 308 307 288 299 315 302 285 324 346 301 293 265 293 302 301 288 290 311 310 283 260 277 291 273 272 291 275 247 277 300 279 279 264 301 292 261 271 264 250 268 267 288 275 275 289 265 288 261 268 272 284 287 264 224 278 245 268 249 268 276 274 262 261 269 273 260 267 267 262 300 261 245 262 264 267 256 266 249 271 291 291 262 260 278 237 259 265 267 245 248 256 269 260 286 243 242 266 260 279 235 292 276 290 257 272 267 290 257 260 245 271 301 237 260 248 246 226 278 284 266 265 256 282 271 236 268 284 263 235 287 222 245 239 261 285 296 297 266 262 264 235 274 241 280 277 272 297 270 274 262 267 290 230 264 248 282 266 265 243 259 257 271 245 299 285 270 256 262 271 247 262 256 260 298 266 271 240 270 264 261 258 224 278 268 258 234 255 255 224 282 255 246 290 240 242 269 293 240 235 283 255 286 278 278 247 278 256 277 248 250 260 262 273 264 259 247 260 264 236 307 243 272 266 270 277 238 257 261 260 262 274 273 265 269 269 245 243 231 259 257 273 228 269 282 298 264 264 289 269 277 242 223 281 239 249 258 262 244 247 279 249 275 238 260 266 247 261 307 267 267 302 247 242 275 261 268 241 300 271 270 266 271 272 230 279 257 286 270 270 282 231 242 270 246 256 258 288 292 263 284 280 244 250 268 242 270 258 286 248 274 270 277 268 299 269 226 245 277 260 278 259 259 260 261 273 280 258 275 256 241 285 232 260 273 272 267 280 289 278 256 270 240 265 241 247 261 260 265 255 270 281 207 263 236 261 282 248 217 222 250 289 243 273 281 274 270 299 261 284 290 278 285 275 248 261 291 240 262 282 256 269 303 236 222 244 271 269 255 255 268 307 273 287 232 278 309 270 223 276 277 277 256 258 263 275 277 273 280 273 272 247 291 273 262 262 275 239 259 266 266 241 275 265 292 275 243 279 258 280 257 257 264 270 234 259 290 242 271 279 297 238 260 265 263 299 268 270 264 259 241 273 275 274 261 265 272 230 262 259 260 267 242 299 250 284 223 292 263 266 231 238 249 287 286 269 262 256 236 279 281 262 233 242 289 266 263 243 279 265 274 240 275 270 234 265 273 258 262 295 281 236 290 288 291 270 278 239 246 257 246 264 263 285 285 245 264 284 263 231 275 279 282 265 230 261 246 260 264 269 277 299 239 265 248 240 271 243 277 257 267 270 274 247 293 270 279 266 285 239 264 267 256 307 274 237 258 275 229 278 273 236 267 224 281 285 239 271 266 292 259 246 259 259 232 256 240 249 240 299 257 239 257 258 231 243 242 280 257 272 267 264 271 272 270 276 290 261 283 269 272 260 290 235 266 284 269 284 233 233 261 272 255 265 248 302 266 234 255 262 259 267 231 268 231 269 285 264 265 264 300 268 279 270 272 267 262 246 257 256 261 286 267 298 268 268 261 292 276 270 279 256 256 270 244 274 264 262 261 269 313 276 269 247 275 278 277 290 304 257 246 285 269 268 277 241 269 257 247 277 270 298 285 279 259 266 232 250 230 276 276 279 268 266 264 266 246 275 282 291 239 240 257 224 257 261 264 282 266 283 264 260 232 283 269 236 255 281 276 293 238 227 277 248 279 286 283 278 255 271 274 294 247 275 269 295 221 278 258 290 276 261 285 245 272 271 287 267 286 282 261 292 258 263 239 242 273 248 267 237 264 220 255 283 223 233 319 288 230 248 272 266 265 274 268 273 268 268 310 274 244 268 269 266 270 259 281 267 257 237 247 298 279 271 262 260 249 275 248 258 265 240 297 275 246 260 272 283 297 283 285 242 264 255 261 240 277 272 259 262 289 260 241 286 258 277 259 255 277 291 229 287 283 274 282 278 276 292 271 271 278 291 274 265 260 261 273 263 284 266 286 259 277 295 248 232 294 265 273 258 271 245 250 250 245 264 268 232 264 261 272 260 275 236 270 241 265 231 268 282 242 266 293 261 297 258 293 258 272 275 247 261 288 260 260 231 277 266 277 284 276 276 270 265 281 272 259 271 274 273 280 249 245 264 277 232 269 274 265 290 262 265 278 222 243 288 257 258 267 274 275 238 276 248 230 281 271 282 280 236 283 248 284 223 270 262 269 279 267 275 277 259 282 278 250 255 216 241 243 270 269 311 265 288 259 267 284 221 255 249 262 258 244 290 262 265 257 237 275 286 306 273 260 264 235 280 266 256 270 249 276 256 225 245 245 276 278 236 265 277 288 258 279 280 240 248 245 279 267 287 266 265 282 256 272 296 235 249 271 286 261 259 244 275 262 272 279 285 284 287 258 291 296 241 246 279 249 232 277 215 274 247 271 261 256 248 298 267 280 280 255 271 240 249 250 265 267 247 243 277 243 235 263 274 282 271 265 279 255 299 233 278 270 281 235 249 230 282 267 286 292 265 266 292 263 259 296 280 266 219 283 258 288 264 268 230 263 256 269 242 255 277 291 266 262 234 280 233 299 233 272 272 271 268 264 283 230 266 273 265 248 285 269 259 309 270 266 247 287 267 275 268 274 244 264 278 276 244 297 284 272 288 262 263 240 270 301 296 277 271 263 249 273 269 290 295 270 270 281 278 266 289 244 263 258 287 287 288 264 291 275 257 248 292 262 264 259 267 256 278 295 246 286 247 284 249 290 288 281 276 238 285 277 249 262 303 298 256 245 298 292 269 288 284 237 278 263 281 258 239 255 285 275 277 256 238 295 258 280 272 237 277 234 257 269 285 256 301 281 238 250 269 248 292 256 288 249 258 269 234 268 257 281 236 284 270 298 273 274 239 245 264 261 272 289 296 267 245 294 293 273 256 294 295 291 279 242 239 260 290 262 279 293 241 272 239 260 265 258 233 293 275 282 288 243 269 268 272 267 267 275 258 248 234 282 248 257 286 281 266 288 274 249 262 271 303 268 265 287 309 245 275 266 296 282 240 261 267 247 255 271 266 249 268 271 300 260 271 238 255 310 245 271 275 289 289 288 276 278 276 283 271 266 245 279 281 255 294 273 277 294 257 269 258 279 290 283 289 279 273 310 268 275 273 291 280 280 241 260 279 240 226 255 249 262 279 283 246 288 234 269 256 262 259 289 248 276 262 269 269 268 284 267 260 274 288 259 294 287 297 260 269 261 258 262 298 283 279 292 293 292 273 241 260 282 260 306 257 259 260 294 274 295 273 292 240 272 267 268 286 262 256 258 281 293 288 275 274 230 258 290 262 300 266 271 229 239 235 264 276 246 289 310 282 280 235 279 257 235 271 275 271 280 281 275 249 289 262 249 269 295 260 255 270 279 279 261 290 264 263 239 296 278 263 270 285 270 292 267 257 274 245 274 271 267 266 266 298 274 310 264 269 280 248 241 281 264 265 267 279 261 279 261 269 278 277 292 262 259 242 255 285 272 283 237 235 260 267 246 249 269 242 238 257 262 229 262 242 248 240 272 289 268 258 290 271 286 256 302 283 286 238 285 269 249 244 279 270 286 255 250 284 222 262 248 267 292 285 259 280 255 239 287 286 264 269 259 249 277 248 271 259 245 270 271 296 277 296 240 271 286 267 270 221 242 242 271 265 267 261 239 265 279 268 270 277 307 270 259 264 278 248 273 285 248 277 287 286 280 258 281 256 284 283 279 285 279 259 272 283 280 295 265 277 273 284 283 249 268 269 285 244 249 281 267 282 264 289 261 286 278 279 242 278 299 282 274 285 269 277 269 235 306 282 290 268 259 256 271 269 267 264 247 279 283 293 277 264 292 241 293 278 278 243 283 268 297 258 290 283 258 261 235 234 259 245 278 290 285 258 234 257 262 289 295 263 273 267 237 264 263 295 273 272 242 283 262 278 271 276 235 239 284 277 275 283 276 259 282 243 273 275 277 272 273 261 267 236 307 312 291 275 265 262 270 232 261 282 272 274 290 288 293 276 249 265 284 269 281 247 249 263 285 266 279 286 321 271 255 265 288 226 273 287 230 284 271 303 309 279 307 258 256 291 270 237 273 267 276 274 291 260 269 258 243 268 286 271 293 281 262 257 255 296 261 279 262 293 243 291 290 284 274 266 261 248 284 250 263 285 275 258 284 272 281 292 298 247 241 282 267 278 272 298 246 273 298 307 286 258 260 305 279 279 303 288 247 269 325 271 282 294 262 289 260 248 267 247 267 275 244 261 276 269 281 285 280 269 281 288 267 281 271 296 266 238 241 284 286 264 279 260 277 291 265 265 296 302 287 267 277 264 240 279 269 274 322 255 280 239 285 257 264 267 266 255 278 310 288 276 264 289 283 264 287 249 265 273 273 261 279 245 285 242 270 272 265 279 275 305 260 269 267 288 285 286 284 276 280 258 323 295 286 261 302 281 300 247 288 272 297 277 263 277 302 276 282 271 266 261 295 274 300 296 292 279 290 278 294 329 270 270 266 276 290 260 290 258 268 249 285 278 287 279 262 294 265 295 267 284 282 259 279 271 287 272 264 276 299 248 276 272 276 283 272 299 304 287 289 276 283 279 293 288 316 285 259 290 280 307 259 301 274 302 297 290 279 303 296 318 288 280 288 296 291 284 293 287 294 293 297 277 280 303 282 274 303 304 285 277 277 302 274 258 304 271 249 297 275 313 291 262 275 257 294 277 287 273 281 313 281 274 250 271 268 264 266 244 318 281 281 302 273 283 265 275 278 280 302 284 266 282 266 262 309 248 288 283 303 281 325 278 269 257 288 265 334 257 258 284 296 274 248 262 269 238 266 296 288 271 269 270 274 281 223 259 236 272 269 276 287 279 299 261 278 272 282 288 273 260 232 204 273 262 295 280 273 284 247 278 268 285 293 301 290 273 268 287 280 289 272 321 270 291 265 256 287 309 299 299 264 249 270 258 279 267 270 275 278 274 300 273 261 293 266 293 266 277 255 276 271 284 258 285 295 285 264 243 272 275 284 292 301 275 256 270 279 260 284 288 268 287 241 229 257 280 272 255 257 278 272 280 274 264 301 258 248 260 270 279 311 279 278 267 269 249 246 281 276 298 288 269 289 289 263 268 259 267 261 271 273 281 281 312 264 298 291 285 299 255 286 284 264 262 267 293 248 247 280 276 263 272 282 297 275 308 286 276 255 287 276 272 289 275 275 256 266 244 267 290 321 285 239 275 296 288 280 282 291 266 284 261 266 257 292 277 246 263 288 288 298 245 286 286 278 269 282 237 274 300 241 279 241 277 290 267 287 303 279 271 293 279 283 273 279 257 248 248 301 304 275 277 274 296 278 289 278 276 235 260 272 272 291 268 264 258 264 259 271 274 273 286 284 278 283 271 271 261 291 244 261 291 271 266 285 262 260 276 275 273 266 271 299 269 275 276 290 257 266 280 258 281 262 303 269 291 269 297 272 274 279 276 279 279 291 265 278 276 249 286 264 285 303 299 292 283 273 266 307 278 271 261 272 228 302 247 260 273 271 278 259 263 272 267 273 261 300 279 264 275 268 295 234 243 277 292 272 274 279 302 280 268 280 271 274 285 284 272 271 262 285 274 282 265 243 272 269 227 237 270 270 291 287 261 283 242 261 259 271 263 298 278 298 260 275 225 291 289 273 270 273 242 297 321 303 275 286 259 280 292 249 287 256 275 294 277 272 276 281 281 289 271 266 257 240 273 265 276 278 261 271 270 269 262 255 282 295 299 270 270 268 277 275 278 304 250 245 262 266 297 279 290 290 298 262 294 274 310 293 278 276 278 302 283 281 260 280 246 292 236 276 248 272 275 266 280 266 267 257 277 266 297 272 247 268 266 293 244 287 256 298 260 299 297 296 279 294 269 308 299 270 285 248 322 244 259 247 266 278 300 286 280 278 277 262 273 305 276 279 294 275 274 274 281 283 258 283 299 288 300 268 266 238 271 274 279 264 282 270 265 265 275 248 274 269 283 255 250 267 267 297 305 280 306 284 290 273 278 295 266 271 262 283 256 277 293 281 261 295 272 271 278 267 285 292 260 285 255 258 264 280 304 317 287 277 277 265 296 282 273 307 262 246 274 274 288 275 270 261 291 262 267 272 280 275 290 280 261 258 267 263 288 276 314 270 258 316 276 287 306 293 287 286 269 280 276 249 291 291 283 295 265 264 292 284 270 271 269 268 302 295 263 271 279 281 265 286 279 247 291 267 291 283 287 279 274 285 256 266 240 282 293 303 266 305 265 311 274 270 283 284 283 260 292 283 278 278 285 300 300 281 240 276 271 298 282 303 298 296 292 255 246 291 264 278 288 290 285 264 267 291 261 285 285 278 299 312 267 295 300 273 268 264 282 274 259 270 282 295 287 278 295 277 275 262 257 271 307 258 266 241 293 286 266 308 283 268 301 245 264 265 304 280 265 263 267 272 268 304 235 238 242 286 281 248 263 272 249 273 291 284 261 260 273 310 289 269 262 298 271 237 265 286 280 279 262 237 290 273 281 270 260 271 278 273 265 296 238 295 297 301 286 291 288 285 270 248 230 272 282 285 287 242 289 282 277 275 303 294 302 279 284 274 282 301 300 269 296 290 304 294 281 242 276 250 301 235 241 263 273 257 281 290 275 270 278 282 295 278 232 270 264 285 263 299 293 305 276 316 284 271 299 285 271 272 247 269 275 255 250 273 278 266 246 291 299 262 304 291 263 266 307 279 286 288 290 281 289 268 291 290 304 284 262 278 291 296 291 283 304 291 257 285 284 285 295 289 285 273 264 305 280 300 293 274 277 282 257 288 274 262 285 269 273 280 270 285 288 293 249 304 273 291 297 275 263 292 267 299 289 309 285 280 245 273 301 278 282 261 278 265 273 257 277 239 290 262 292 274 260 291 281 276 234 279 289 286 248 300 263 266 278 245 291 258 260 261 305 274 277 271 287 259 259 269 280 263 300 295 291 285 279 303 279 304 291 272 272 243 269 283 257 276 293 250 274 261 270 263 304 274 320 273 280 296 244 286 316 267 270 266 284 258 307 274 305 272 296 279 273 262 302 280 274 267 306 290 287 284 297 270 268 280 301 274 288 303 240 257 283 291 283 245 298 301 279 282 273 282 282 301 324 268 283 294 246 270 303 274 275 276 284 281 271 272 297 284 296 256 298 291 266 238 234 263 285 264 235 263 279 258 265 291 272 290 295 276 277 283 272 273 302 241 271 307 264 273 285 286 275 269 264 247 324 261 272 274 283 284 269 273 272 259 275 248 278 242 260 266 259 315 290 278 288 283 296 267 291 294 277 301 258 292 268 275 273 276 279 275 268 258 286 261 270 291 289 262 293 282 263 271 284 280 290 263 280 296 284 279 260 272 281 276 295 281 279 282 276 265 289 295 278 264 322 294 303 280 290 299 267 248 279 284 283 258 296 278 280 265 280 227 271 278 291 278 276 260 241 272 302 249 297 274 273 239 294 259 278 270 293 249 284 262 258 275 284 295 283 288 285 246 278 295 242 258 257 273 281 301 289 276 298 276 269 297 277 264 274 278 284 274 313 236 284 283 292 277 293 277 273 293 323 290 286 302 289 248 280 290 274 243 286 285 273 268 281 234 295 258 270 302 286 282 282 256 266 265 267 275 287 269 299 239 273 277 273 279 322 265 259 271 308 295 262 261 303 289 305 261 319 289 270 293 309 257 278 244 285 271 293 278 268 305 257 260 298 288 277 293 273 255 265 255 261 272 279 277 278 259 266 297 255 288 282 278 271 271 236 244 285 304 310 274 293 275 266 244 264 281 307 248 258 258 283 262 278 242 290 298 310 288 266 260 305 286 298 293 306 283 287 295 287 242 299 260 270 278 279 255 269 282 291 294 273 292 273 276 284 297 280 301 297 275 282 277 282 271 262 287 271 289 286 226 300 315 290 265 281 303 233 278 310 291 286 261 268 264 270 292 264 272 214 276 272 263 240 294 273 301 259 320 329 255 272 247 267 281 284 293 266 258 275 265 272 279 262 239 285 270 281 306 285 283 319 281 286 298 278 260 273 306 277 258 262 275 281 268 299 292 298 242 283 264 289 315 287 267 270 292 305 285 269 277 288 278 302 310 267 261 269 248 284 281 284 297 287 262 300 310 278 291 307 255 281 297 291 286 268 276 273 281 266 283 273 264 277 257 292 241 266 262 288 291 279 278 275 269 277 286 296 288 298 271 247 274 281 301 289 280 241 275 270 264 300 287 279 249 292 272 283 257 315 294 249 267 274 277 304 299 287 275 285 290 277 249 286 282 261 287 291 267 246 276 298 299 300 249 283 295 255 255 279 291 285 289 289 284 287 295 291 292 313 247 272 280 299 294 293 274 290 271 299 278 305 302 264 310 276 269 257 288 264 246 263 290 280 301 302 293 268 311 269 285 269 279 286 285 276 280 277 264 303 262 289 266 289 274 297 305 274 269 270 241 316 303 300 288 272 273 279 286 268 280 235 294 314 273 285 298 308 298 298 294 295 302 274 296 294 331 280 272 288 323 307 269 289 290 330 288 283 303 296 337 297 321 327 319 332 314 301 311 281 347 291 301 334 335 314 311 280 332 317 306 324 322 320 312 325 294 317 307 305 321 316 309 332 330 298 337 307 287 302 301 317 300 291 308 322 341 296 325 336 348 308 297 321 288 293 299 288 289 283 296 303 307 318 288 291 291 283 335 294 324 289 294 281 285 270 297 316 267 290 312 282 296 286 264 280 301 301 288 250 268 310 306 306 305 286 275 299 273 306 279 296 322 282 290 305 286 255 268 297 305 266 285 262 319 289 290 290 255 288 312 315 287 271 286 245 244 279 274 296 263 285 283 287 277 319 296 279 287 289 294 274 279 295 256 258 292 284 294 276 289 297 312 294 291 283 278 273 270 278 272 282 278 317 247 300 265 258 271 292 271 276 294 256 314 286 275 277 241 264 285 287 274 295 274 281 268 289 263 290 297 257 268 285 259 265 243 264 279 294 274 264 293 276 278 259 240 246 271 269 267 314 255 267 270 278 280 272 236 298 276 276 296 301 286 264 269 264 282 278 257 274 290 247 263 293 277 286 265 296 302 296 278 271 303 290 261 270 286 295 300 307 273 314 267 291 287 282 299 322 265 246 247 297 307 291 308 305 278 284 279 278 248 265 282 262 238 300 281 286 279 295 277 299 294 246 297 256 280 278 301 268 271 290 286 265 276 293 281 287 289 282 280 281 248 282 265 236 280 295 274 292 266 281 257 296 284 282 278 276 286 246 281 299 308 282 287 308 280 268 275 288 267 289 288 262 274 262 310 270 260 265 263 269 270 284 315 275 257 259 264 297 290 271 273 265 284 261 276 282 301 300 309 308 285 290 293 296 306 288 280 298 319 284 282 311 270 280 256 249 289 293 301 249 280 237 292 277 292 313 243 267 295 279 306 289 272 307 267 300 268 291 246 287 274 292 300 293 286 281 286 300 301 244 276 261 274 290 290 279 279 267 312 277 262 272 278 267 290 298 292 268 286 287 292 295 265 286 273 291 270 272 279 274 258 276 272 263 305 266 283 274 276 286 257 286 228 238 316 275 302 256 296 292 277 303 275 259 317 268 290 265 281 268 290 263 310 260 264 285 285 267 300 278 284 283 290 266 277 310 247 287 297 240 307 270 284 281 283 280 289 272 282 294 268 272 271 291 281 287 285 295 247 258 259 273 289 246 286 262 264 265 272 281 312 264 262 273 275 246 286 279 302 250 309 280 296 267 297 281 280 241 284 290 272 300 298 294 274 288 276 320 304 299 272 261 250 272 283 312 296 261 275 273 283 305 289 278 321 294 268 276 293 290 299 295 283 309 256 291 287 267 247 248 302 283 284 280 283 279 296 295 285 308 263 264 286 260 246 285 283 277 269 301 270 277 281 269 269 249 281 257 263 280 307 285 278 270 306 290 271 250 265 261 299 282 282 259 266 297 280 259 259 274 274 308 284 274 286 282 264 313 271 269 261 274 276 276 288 273 289 278 304 274 243 282 282 247 277 275 276 309 259 304 272 263 282 242 269 303 293 276 303 259 295 274 270 283 281 278 317 261 282 291 263 268 276 281 241 308 282 236 333 300 281 276 298 266 285 248 262 279 273 241 277 275 273 280 299 270 257 276 273 300 271 278 299 264 281 265 287 298 270 245 278 248 283 263 264 258 271 263 303 269 281 280 267 305 279 280 266 280 282 273 295 288 262 274 278 272 265 272 303 263 296 267 298 286 263 283 281 270 279 242 264 269 266 273 267 302 257 260 277 308 257 295 247 285 283 292 272 290 295 297 282 261 283 292 268 272 277 296 276 262 264 250 292 271 297 256 272 298 262 242 271 281 263 292 298 266 263 282 247 291 280 293 267 245 309 280 280 264 297 307 275 284 292 256 294 277 262 282 287 275 275 278 285 293 259 278 278 303 287 261 305 283 257 242 258 294 289 300 300 295 285 276 277 294 250 288 284 271 248 256 291 310 270 289 306 279 289 313 265 289 299 281 299 239 265 283 297 297 282 246 264 279 267 288 268 285 261 261 268 269 269 266 282 273 302 269 270 287 293 306 270 290 286 309 306 262 311 309 265 286 246 266 267 267 297 274 289 278 276 318 315 289 281 293 272 287 285 289 271 282 277 265 290 312 266 297 311 257 259 309 285 263 303 282 287 284 281 287 271 278 277 293 332 265 276 272 272 291 264 281 263 246 293 257 274 289 287 273 249 272 285 299 322 229 262 227 280 283 260 261 242 284 290 290 266 271 263 282 299 306 272 275 266 230 307 309 306 274 306 259 272 276 261 286 269 256 277 289 267 278 284 264 278 238 243 293 290 240 265 278 271 284 281 276 255 327 286 284 277 298 269 272 267 281 286 274 276 284 277 265 285 271 290 274 291 299 279 269 265 275 265 280 270 305 267 276 269 277 286 311 259 267 274 271 294 282 238 274 307 260 306 294 284 275 264 280 285 264 286 286 279 288 273 273 287 297 272 279 290 315 297 286 279 264 286 277 290 270 271 283 282 265 255 311 302 276 257 259 287 267 273 278 257 249 274 260 283 281 266 299 286 297 265 272 247 264 287 266 255 279 239 295 303 279 238 277 273 282 248 267 307 277 290 308 275 264 239 270 268 247 284 261 307 292 273 272 283 263 310 315 271 265 284 276 262 284 298 264 269 284 260 291 282 286 234 280 238 245 295 274 260 274 274 266 295 295 284 273 286 298 289 275 286 296 259 259 271 287 279 291 298 263 243 243 299 307 283 279 276 267 247 275 283 289 301 262 260 281 266 257 297 278 263 288 269 289 311 263 288 310 296 243 257 262 267 282 290 268 293 262 260 279 264 276 280 258 290 294 286 289 255 305 289 279 271 280 299 280 304 299 257 274 287 309 243 255 304 285 284 288 290 277 263 275 281 297 280 293 274 267 284 295 282 256 278 268 246 283 273 300 287 291 242 243 270 248 266 276 270 255 285 280 288 265 273 264 289 249 285 289 256 276 280 256 267 259 300 228 283 295 274 279 277 280 293 292 290 276 268 284 286 274 306 312 280 271 292 272 273 264 266 239 263 284 269 271 280 267 292 292 279 292 269 256 286 282 283 293 271 281 259 284 248 285 286 270 298 273 269 276 278 275 268 277 272 285 300 257 264 290 247 279 270 261 281 299 260 255 246 293 288 277 282 271 258 245 275 257 261 269 273 239 293 270 274 270 277 256 255 268 298 268 270 291 261 261 277 272 242 298 262 303 290 275 307 289 265 263 238 309 245 278 275 249 263 312 273 261 268 305 280 265 265 287 265 242 273 256 255 274 286 262 248 255 300 274 246 282 284 275 283 249 280 293 255 292 275 266 291 259 245 257 270 275 267 281 264 284 260 276 280 291 269 245 267 293 266 272 265 266 269 271 247 299 283 270 294 288 257 249 264 281 265 258 275 268 286 267 278 255 271 258 277 279 286 264 261 269 315 291 280 268 248 288 247 282 285 256 260 272 239 270 276 255 281 245 245 280 274 283 294 281 285 285 255 247 292 294 280 255 303 292 276 310 279 239 244 272 291 290 294 277 295 282 240 263 287 304 247 259 282 267 273 268 256 281 283 270 248 243 275 267 278 282 247 275 273 259 282 274 244 268 274 279 258 267 230 260 265 292 284 274 263 241 273 262 290 274 304 265 291 309 280 269 274 276 286 293 283 271 281 285 283 274 272 266 246 304 272 295 225 280 267 284 266 287 282 256 267 272 298 275 266 286 300 291 309 287 326 282 294 279 246 271 293 301 301 262 281 270 273 288 285 279 275 268 282 300 286 281 266 281 302 300 299 272 304 282 275 291 276 280 271 285 268 274 294 281 298 305 274 268 266 268 266 291 283 266 234 303 292 288 316 279 284 280 279 311 249 280 284 281 267 302 283 291 294 301 278 292 284 306 283 283 297 287 279 305 275 318 241 266 295 272 295 278 288 278 307 296 282 271 281 286 305 273 302 296 294 287 286 292 284 258 298 282 275 294 281 263 273 266 256 291 289 276 289 275 312 282 268 273 289 265 312 256 290 284 272 298 260 273 246 268 285 276 289 289 276 259 304 266 273 287 271 274 235 269 297 293 304 276 280 273 292 287 270 299 308 250 259 291 287 249 282 283 282 301 268 272 301 237 275 274 238 260 259 284 256 272 238 302 270 289 287 279 255 298 257 281 276 311 265 300 293 283 244 291 265 265 260 270 284 283 285 267 291 270 256 265 268 248 263 281 293 274 244 308 286 301 260 292 277 271 265 263 275 273 307 277 304 267 290 258 276 274 281 277 280 270 296 286 284 266 262 248 284 285 282 257 262 281 284 296 281 259 267 280 314 294 288 245 265 293 281 279 289 288 257 259 275 243 286 242 290 279 274 278 249 269 281 283 259 298 258 269 275 295 283 260 249 286 286 287 260 249 272 268 269 286 260 298 257 237 281 290 276 276 245 270 268 239 279 262 288 296 321 309 273 256 274 240 286 259 279 286 287 268 280 276 275 285 285 299 283 278 283 264 276 259 279 268 272 259 281 283 260 258 284 269 270 274 272 248 265 304 259 274 269 257 277 267 290 259 259 275 279 271 315 276 261 258 273 275 249 303 240 276 267 288 288 289 303 266 267 277 259 286 284 300 291 272 297 273 283 280 286 324 266 266 273 257 283 247 267 308 274 309 279 290 282 247 255 285 277 268 295 302 283 263 304 302 261 287 280 261 269 271 270 292 274 260 258 262 284 265 282 265 275 274 259 266 272 306 257 273 294 297 273 297 262 296 264 274 274 285 293 301 249 296 276 278 279 287 275 268 293 295 276 247 275 264 259 298 277 284 289 301 288 258 276 268 285 280 256 262 285 316 285 298 262 255 287 247 293 269 307 307 311 265 257 261 286 304 279 241 278 255 286 292 281 283 284 265 257 278 284 262 278 255 290 288 284 276 267 276 264 303 266 257 283 281 260 285 286 258 268 284 290 264 225 260 248 281 266 274 262 305 286 288 262 273 250 305 276 260 281 258 248 279 281 280 244 285 266 292 247 265 240 279 284 238 281 294 265 264 280 281 282 272 310 287 288 260 285 294 276 264 279 276 304 276 242 271 284 281 293 275 277 279 302 270 293 274 288 223 245 273 277 259 286 313 278 256 291 281 289 262 257 265 247 277 275 285 306 300 269 255 316 285 266 289 312 261 266 275 262 294 264 295 273 296 293 261 284 244 257 261 304 286 276 274 292 278 299 275 291 271 269 281 299 282 279 268 282 274 281 286 279 263 278 267 267 268 281 270 264 247 278 295 250 284 282 265 297 270 298 288 244 261 244 266 290 305 260 278 287 285 265 276 304 289 287 294 292 255 245 282 304 300 267 285 279 241 285 282 284 311 270 285 273 285 258 307 280 269 303 275 242 273 257 288 260 256 268 268 280 295 280 265 282 279 276 272 297 269 301 286 275 296 273 290 294 286 266 282 289 279 277 327 248 286 271 302 276 270 290 282 279 288 297 270 312 293 287 288 291 305 277 288 258 237 299 246 281 246 260 273 271 306 288 287 290 279 312 276 261 248 258 286 281 280 283 277 248 294 278 279 295 300 260 258 293 304 248 241 249 279 277 255 269 283 267 312 308 282 281 262 275 296 292 283 299 298 294 285 298 269 288 285 288 299 275 272 307 261 286 303 259 241 267 271 233 286 292 279 286 301 259 263 278 277 247 255 277 284 280 274 262 292 297 238 256 297 297 282 274 296 280 282 290 283 279 293 277 287 275 280 297 277 264 268 287 312 280 247 303 284 278 304 302 293 275 269 261 262 287 320 269 285 276 274 290 299 278 297 277 272 269 270 264 284 291 291 295 277 280 260 293 288 290 278 294 285 288 299 273 255 283 242 288 259 283 301 275 263 264 270 269 285 303 246 296 291 279 267 279 271 297 289 280 284 313 271 303 275 247 285 281 286 269 273 271 316 285 311 288 288 256 309 267 308 284 279 281 298 308 305 290 286 242 329 277 290 255 280 291 279 241 275 288 276 295 306 285 278 309 299 269 288 280 271 331 264 261 292 286 276 288 268 287 247 269 286 258 290 287 326 283 266 303 274 266 292 258 264 289 283 315 311 265 285 298 283 285 307 272 278 301 329 291 307 278 291 272 282 288 308 243 263 295 279 286 284 284 276 305 242 278 277 292 285 283 264 293 290 286 271 296 272 280 281 279 289 266 265 274 264 272 300 272 278 264 274 295 296 292 307 268 260 290 282 297 261 284 297 300 265 295 277 290 282 267 316 265 283 278 281 283 307 292 232 286 269 281 308 287 272 303 275 298 289 249 296 296 261 284 267 279 296 298 279 291 284 248 303 311 297 258 286 285 293 264 284 304 282 288 286 277 302 292 310 279 277 269 297 280 289 295 290 300 268 299 284 293 271 291 292 268 283 309 266 292 277 277 277 311 279 305 284 269 276 279 310 281 281 287 299 266 261 271 277 288 258 278 292 280 267 280 285 260 262 268 266 286 309 274 275 259 285 302 258 269 279 301 284 272 280 280 264 268 275 308 262 291 281 249 274 281 260 246 296 271 289 249 296 266 277 284 270 280 268 291 286 282 282 277 275 298 264 296 284 299 288 289 286 273 296 271 312 276 274 284 289 298 296 284 293 293 263 300 267 300 294 285 292 302 305 291 305 258 275 278 270 285 297 306 298 270 305 249 256 285 288 298 257 274 281 273 299 246 318 282 260 282 268 308 324 284 260 306 304 259 289 291 289 266 235 269 261 307 244 262 235 297 277 286 290 272 296 304 280 302 270 243 287 303 270 267 276 274 271 282 307 243 280 311 247 257 284 265 281 292 261 289 292 273 284 286 249 265 280 259 281 286 300 269 249 279 281 268 249 287 236 293 302 268 267 288 283 298 249 270 302 290 246 295 284 288 281 286 291 298 285 286 287 305 258 291 259 298 257 318 220 278 282 264 294 275 292 274 271 272 262 289 285 322 299 300 309 280 261 257 262 286 268 324 295 292 260 246 289 257 291 258 255 290 284 248 288 248 290 271 262 260 285 245 264 286 292 275 301 291 273 281 269 287 326 287 248 266 314 279 289 277 266 301 275 295 239 282 233 244 271 297 271 293 275 310 281 276 264 262 261 318 274 279 278 270 273 285 291 278 268 311 257 277 285 281 284 279 295 240 278 293 279 277 279 280 245 246 277 291 248 255 285 279 282 297 285 269 268 293 289 285 279 273 262 283 290 275 264 281 290 256 280 286 267 312 259 279 318 303 273 282 285 307 276 272 259 280 282 278 263 273 272 287 309 269 286 269 269 285 301 282 246 302 272 270 309 279 302 287 276 267 262 308 320 270 300 271 297 243 278 299 288 249 288 238 268 290 279 255 279 291 287 271 282 241 297 303 282 284 283 315 281 280 289 270 280 269 264 291 287 301 284 266 276 290 296 284 288 262 269 268 282 288 300 285 267 266 317 320 285 279 312 276 278 271 298 307 281 289 262 266 285 288 272 266 304 282 285 262 306 267 291 305 285 326 299 270 286 277 295 301 257 303 286 285 262 255 280 292 273 268 256 293 315 283 307 277 288 307 306 287 264 268 317 288 301 295 279 280 319 263 287 277 290 298 263 299 262 282 288 268 288 280 231 289 270 249 302 276 290 292 265 279 293 272 284 300 235 289 285 290 280 292 258 295 259 300 284 280 303 307 315 289 319 316 313 307 303 302 305 285 269 316 319 302 256 303 293 330 304 255 276 283 295 276 305 300 304 288 310 319 299 291 302 316 291 299 295 287 301 317 292 291 300 277 304 309 291 316 263 306 279 294 286 289 290 320 323 301 310 307 300 292 287 303 309 288 291 286 317 306 296 317 346 307 284 267 306 293 276 312 300 283 314 289 318 310 270 309 291 311 298 306 304 309 319 296 276 287 292 315 306 286 308 311 291 280 287 300 308 317 305 304 290 284 282 278 280 304 285 311 294 301 291 274 285 266 270 272 259 300 267 296 305 290 288 241 302 264 291 294 256 292 299 313 306 289 304 270 306 305 300 264 293 309 283 287 260 268 282 281 259 248 299 313 277 297 309 259 303 285 274 298 276 265 298 281 257 263 321 273 268 282 309 305 268 274 284 258 313 261 269 307 271 265 319 304 277 286 289 296 291 304 288 282 269 301 277 288 274 300 283 264 286 269 279 287 297 269 236 295 278 287 291 310 271 281 295 264 261 287 260 307 296 246 306 265 272 270 290 280 300 277 272 273 245 292 279 287 265 259 320 303 286 274 292 308 275 288 301 291 276 269 294 261 282 281 283 278 280 315 264 284 260 264 275 261 288 307 277 299 267 288 257 272 240 273 286 270 316 284 298 280 279 287 278 256 277 278 314 273 288 288 304 298 278 287 279 286 291 277 298 279 274 273 275 279 295 285 284 284 263 308 294 277 289 280 289 274 278 259 264 296 289 274 306 284 294 259 315 279 286 298 303 267 313 281 279 248 289 295 285 283 272 297 246 285 264 277 283 287 277 267 284 276 289 277 272 284 300 245 300 299 272 309 290 285 296 266 288 275 278 301 289 289 270 278 281 276 303 283 291 315 270 291 281 283 297 278 304 274 270 282 297 287 285 268 293 286 284 284 288 274 282 266 264 280 302 256 303 280 275 276 285 292 289 259 303 296 274 269 289 264 279 281 277 265 315 294 294 276 273 264 292 262 287 294 285 271 283 305 267 296 282 328 303 281 283 283 315 303 269 346 239 320 247 282 310 279 308 298 273 299 260 284 274 275 269 289 280 279 302 289 262 271 322 277 284 284 260 303 270 277 268 285 261 317 288 274 290 282 291 278 293 278 268 294 272 276 281 272 283 269 298 255 271 295 313 273 293 318 324 278 290 308 307 293 296 308 287 297 302 274 288 283 302 283 310 282 277 298 273 265 294 313 265 325 303 311 264 280 261 269 297 259 296 293 289 284 285 262 299 308 283 292 294 319 307 295 295 268 265 306 273 303 287 285 259 274 294 268 275 294 276 261 285 288 279 317 289 286 265 265 279 315 280 279 290 274 272 291 300 295 291 283 303 267 270 280 270 281 275 314 288 268 289 291 292 325 315 276 282 305 295 273 256 278 274 277 317 269 269 274 301 298 312 277 288 295 269 270 280 298 288 267 294 248 306 284 300 262 273 284 304 280 274 289 258 289 303 285 237 273 255 299 297 274 295 242 282 283 295 281 280 314 249 294 320 317 300 291 283 305 313 276 280 289 302 288 299 297 260 247 272 323 287 280 246 264 260 286 289 279 288 278 315 290 261 272 306 282 276 289 286 269 261 255 283 279 279 305 268 282 288 286 271 277 297 282 300 277 271 292 269 286 285 285 282 296 291 276 269 307 277 282 272 285 301 275 286 274 291 322 261 284 265 304 289 301 285 299 281 287 318 306 285 289 270 298 314 260 264 291 279 255 320 301 287 292 307 269 270 278 273 281 292 303 268 340 288 275 303 280 306 240 279 294 305 274 302 268 247 307 266 260 266 271 293 312 303 298 281 260 306 281 260 287 308 289 293 275 311 277 290 260 266 296 277 284 279 265 297 279 257 270 279 264 275 259 294 275 281 300 307 276 313 273 282 274 270 256 299 306 299 280 264 284 291 271 296 300 269 265 280 308 283 263 266 270 250 297 282 276 290 289 282 282 261 316 267 291 295 266 245 286 276 290 279 280 269 277 283 269 278 295 288 295 282 300 299 283 302 297 275 288 303 270 266 272 284 264 276 294 297 262 263 302 267 291 267 287 300 242 289 310 285 305 304 298 313 299 264 289 297 299 320 296 308 318 269 293 283 284 281 309 302 301 268 272 268 310 277 284 300 288 297 287 300 284 243 300 277 293 308 267 256 282 248 298 282 264 288 297 276 314 299 285 270 261 277 296 287 282 281 268 286 282 271 290 290 269 281 284 273 279 249 308 282 316 270 311 277 261 292 319 289 297 311 280 277 271 272 269 284 281 239 277 270 281 286 321 291 276 267 314 306 277 263 295 276 288 275 268 317 275 257 281 301 276 290 287 302 301 283 275 302 263 267 281 282 266 249 280 278 282 289 288 303 308 260 294 300 246 262 264 315 298 280 295 301 271 290 304 291 284 300 283 284 249 302 272 285 271 274 267 277 285 278 299 304 281 246 302 278 277 290 270 298 293 303 278 279 311 307 294 299 285 255 289 296 269 282 291 294 278 263 289 240 283 310 288 301 284 305 283 325 274 291 275 263 305 259 276 294 295 282 266 308 281 297 280 272 281 267 276 285 276 313 316 300 280 283 284 274 273 289 286 280 301 289 283 321 261 257 288 264 309 301 274 306 264 274 294 306 291 258 292 258 271 309 288 280 289 317 272 306 300 308 291 261 270 276 289 287 317 276 275 311 291 273 324 278 270 276 285 292 286 306 320 298 311 264 293 293 271 312 298 259 299 289 307 275 275 283 282 264 295 295 293 276 273 280 281 285 280 272 274 268 284 293 297 295 293 284 312 294 292 258 281 273 287 283 264 284 266 286 277 289 293 283 278 283 284 287 298 310 285 304 283 272 309 302 273 304 267 334 300 322 293 271 313 292 266 292 268 269 288 277 297 276 283 266 274 272 258 299 289 316 293 277 294 287 285 272 322 301 282 269 288 307 258 321 246 303 281 304 296 291 274 285 277 314 285 301 314 336 292 300 292 302 259 294 280 289 304 300 268 280 287 248 315 287 299 270 279 266 306 292 295 285 305 308 277 300 273 298 286 270 282 282 292 299 316 271 299 298 289 297 308 316 274 278 281 291 286 291 280 278 307 283 275 269 289 295 284 283 302 269 297 318 300 274 318 307 278 276 275 298 285 303 303 259 323 307 303 303 312 285 274 273 314 298 310 285 248 280 271 270 285 273 302 316 292 292 266 281 285 284 278 304 296 265 303 277 255 269 268 297 298 278 274 299 290 303 291 297 298 312 255 308 286 273 301 272 303 305 265 274 308 300 285 318 271 303 316 280 294 295 289 288 297 258 296 275 310 265 269 303 273 297 304 278 300 272 292 288 283 282 274 300 299 322 323 312 287 289 292 247 278 301</counts>
			</dataPoints>
		</scan>
	</xrdMeasurement>
</xrdMeasurements>