File: data/XRD/XG-Luft/XG-800/W6824-1D_XG_Luft_800.xrdml
<xrdMeasurements xmlns="http://www.xrdml.com/XRDMeasurement/2.1" xmlns:xsi="http://www.w3.org/2001/XMLSchema-instance" xsi:schemaLocation="http://www.xrdml.com/XRDMeasurement/2.1 http://www.xrdml.com/XRDMeasurement/2.1/XRDMeasurement.xsd" status="Completed">
	<comment>
		<entry>Configuration=Factory configuration, Owner=User-1, Creation date=7/8/2013 4:01:53 PM</entry>
		<entry>Goniometer=PW3050/65 (Theta/2Theta); Minimum step size 2Theta:0.0001; Minimum step size Omega:0.0001</entry>
		<entry>Sample stage=MRD Cradle; Minimum step size Phi:0.01; Minimum step size Chi:0.01; Minimum step size X:0.01; Minimum step size Y:0.01; Minimum step size Z:0.001</entry>
		<entry>Diffractometer system=XPERT-PRO</entry>
		<entry>Measurement program=C:\PANalytical\Data Collector\Programs\Jorrit\2thom\_absolute_2th-om_10-130deg_PIXscan_56min.xrdmp, Identifier={15BCCF57-2807-42BD-B5B9-ECC0B3DC9284}</entry>
		<entry>Batch program=C:\PANalytical\Data Collector\Programs\SimonL\batch6x_2thom_10-130°_z9.1_x0,10,20,30_y20,40_57min - Kopie.xrdmp, Identifier={8874E540-C3F4-4307-831A-CD55F073CDCD}</entry>
	</comment>
	<sample type="To be analyzed">
		<id></id>
		<name></name>
		<preparedBy></preparedBy>
	</sample>
	<xrdMeasurement measurementType="Scan" status="Completed" sampleMode="Reflection">
		<comment>
			<entry>_absolute_2th-om_10-130deg_PIXscan_56min</entry>
			<entry>PHD Lower Level = 4.83 (keV), PHD Upper Level = 11.27 (keV)</entry>
		</comment>
		<usedWavelength intended="K-Alpha 1">
			<kAlpha1 unit="Angstrom">1.5405980</kAlpha1>
			<kAlpha2 unit="Angstrom">1.5444260</kAlpha2>
			<kBeta unit="Angstrom">1.3922500</kBeta>
			<ratioKAlpha2KAlpha1>0.5000</ratioKAlpha2KAlpha1>
		</usedWavelength>
		<incidentBeamPath>
			<radius unit="mm">320.00</radius>
			<xRayTube id="1010048" name="Empyrean Cu LFF HR (9430 033 7310x) DK442154">
				<tension unit="kV">40.0</tension>
				<current unit="mA">40.0</current>
				<anodeMaterial>Cu</anodeMaterial>
				<focus type="Line">
					<length unit="mm">12.0</length>
					<width unit="mm">0.4</width>
					<takeOffAngle unit="deg">4.2</takeOffAngle>
				</focus>
			</xRayTube>
			<xRayMirror id="27010001" name="Inc. Beam Cu W/Si (parabolic MRD)" hybrid="false">
				<crystal type="Graded" shape="Parabolic">W/Si</crystal>
				<acceptanceAngle unit="deg">0.800</acceptanceAngle>
				<length unit="mm">60.0</length>
			</xRayMirror>
			<sollerSlit id="21010002" name="Soller slits 0.04 rad.">
				<opening unit="rad">0.0400</opening>
			</sollerSlit>
			<mask id="22030007" name="Fixed mask 2 mm">
				<distanceToSample unit="mm">220.00</distanceToSample>
				<width unit="mm">2.00</width>
			</mask>
			<divergenceSlit id="22010007" name="Fixed slit 1/8°" xsi:type="fixedDivergenceSlitType">
				<distanceToSample unit="mm">220.00</distanceToSample>
				<height unit="mm">0.19</height>
			</divergenceSlit>
		</incidentBeamPath>
		<diffractedBeamPath>
			<radius unit="mm">320.00</radius>
			<sollerSlit id="21010002" name="Soller slits 0.04 rad.">
				<opening unit="rad">0.0400</opening>
			</sollerSlit>
			<receivingSlit id="22010001" name="Fixed slit 4°">
				<height unit="mm">5.88</height>
			</receivingSlit>
			<detector id="7010017" name="PIXcel3D 1x1 detector" xsi:type="areaDetectorType">
				<phd unit="%">
					<lowerLevel>30.0</lowerLevel>
					<upperLevel>70.0</upperLevel>
				</phd>
				<mode>Scanning</mode>
				<activeChannelsEquatorial>255</activeChannelsEquatorial>
				<activeChannelsAxial>255</activeChannelsAxial>
				<pitchEquatorial unit="mm">0.05500</pitchEquatorial>
				<pitchAxial unit="mm">0.05500</pitchAxial>
				<readOutPeriod unit="seconds">0.135</readOutPeriod>
			</detector>
		</diffractedBeamPath>
		<scan appendNumber="0" mode="Continuous" scanAxis="2Theta-Omega" status="Completed">
			<header>
				<startTimeStamp>2024-10-28T23:52:37+01:00</startTimeStamp>
				<endTimeStamp>2024-10-29T00:48:43+01:00</endTimeStamp>
				<author>
					<name>PRO-MRD</name>
				</author>
				<source>
					<applicationSoftware version="6.1b">Data Collector</applicationSoftware>
					<instrumentControlSoftware version="7.0E 20130304">XPERT-PRO</instrumentControlSoftware>
					<instrumentID>0000000011142674</instrumentID>
				</source>
			</header>
			<dataPoints>
				<positions axis="2Theta" unit="deg">
					<startPosition>9.99826193</startPosition>
					<endPosition>129.99755682</endPosition>
				</positions>
				<positions axis="Omega" unit="deg">
					<startPosition>4.99913096</startPosition>
					<endPosition>64.99877841</endPosition>
				</positions>
				<positions axis="Phi" unit="deg">
					<commonPosition>0.00</commonPosition>
				</positions>
				<positions axis="Chi" unit="deg">
					<commonPosition>0.00</commonPosition>
				</positions>
				<positions axis="X" unit="mm">
					<commonPosition>30.00</commonPosition>
				</positions>
				<positions axis="Y" unit="mm">
					<commonPosition>0.00</commonPosition>
				</positions>
				<positions axis="Z" unit="mm">
					<commonPosition>9.100</commonPosition>
				</positions>
				<commonCountingTime unit="seconds">32.895</commonCountingTime>
				<counts 401 413 402 433 428 393 412 362 377 432 415 423 396 401 394 399 368 410 400 383 377 372 356 414 412 434 388 414 411 404 395 406 416 396 406 434 401 386 395 441 374 416 383 406 391 415 400 368 402 379 386 432 410 392 392 405 433 385 389 387 367 389 359 387 405 407 392 428 373 384 406 383 396 379 364 377 368 388 350 397 398 393 401 391 359 403 397 397 340 365 406 346 397 377 386 362 358 384 395 351 383 379 407 372 364 364 332 400 386 355 371 406 409 363 399 381 398 374 398 371 381 409 384 404 350 389 359 348 341 390 393 384 377 344 378 352 383 355 384 398 362 350 413 373 362 347 386 339 363 373 388 392 377 370 353 370 375 388 399 376 361 393 353 355 377 345 347 379 374 356 366 396 340 344 358 367 379 384 365 343 371 352 364 353 356 378 346 378 355 343 359 387 357 366 360 334 368 369 367 343 370 342 352 342 345 343 370 374 354 337 377 346 343 360 439 357 342 337 323 347 342 366 331 340 390 379 355 367 377 357 369 335 349 353 334 363 315 380 341 345 384 375 370 310 344 390 344 345 351 326 357 352 354 350 317 367 341 337 364 323 364 301 369 324 360 360 333 348 334 329 329 350 372 371 343 345 324 326 341 316 353 350 361 354 346 311 343 334 341 344 347 336 316 292 353 332 340 353 371 366 330 330 341 358 341 367 319 347 340 319 342 341 315 377 335 326 355 354 348 338 332 328 335 347 301 356 335 348 349 325 343 307 359 333 355 340 304 357 336 315 333 346 316 345 363 328 349 340 333 342 313 316 342 324 346 338 335 323 316 331 321 331 316 292 316 333 339 335 314 310 333 328 312 304 361 369 335 307 327 310 327 334 332 317 366 299 298 338 319 312 336 308 345 306 311 306 327 310 335 315 316 335 339 293 354 304 329 328 333 302 327 285 296 290 316 307 328 321 340 351 317 366 321 334 284 318 321 313 302 328 323 320 301 322 305 304 340 326 316 339 340 304 306 289 315 319 317 281 301 340 322 307 302 306 323 368 305 321 305 326 339 307 305 329 300 326 294 291 287 310 338 307 290 298 333 324 290 311 302 287 292 281 308 313 282 299 280 295 276 315 316 314 293 287 309 307 290 336 320 298 312 310 302 286 287 297 309 361 295 261 289 335 295 337 326 327 305 307 299 309 301 320 307 300 295 322 315 290 302 290 309 289 303 304 312 324 299 315 298 313 296 286 262 316 310 310 272 308 306 327 304 295 304 286 302 345 274 308 272 303 300 320 302 295 298 290 316 275 320 290 311 320 281 309 324 334 306 308 283 284 301 296 280 300 288 291 298 280 280 291 291 306 302 305 306 300 288 293 289 319 315 318 291 262 301 316 288 285 242 296 302 302 299 286 246 294 290 291 304 282 306 306 315 302 314 287 268 287 303 291 295 292 294 314 261 286 324 299 281 318 277 298 286 283 290 297 293 274 283 290 282 292 308 289 296 293 293 275 304 274 301 246 307 274 297 248 296 287 287 300 299 278 292 291 283 274 294 300 258 243 299 280 314 291 318 302 339 275 296 306 315 270 300 292 299 279 262 288 279 289 281 320 304 315 286 261 298 284 290 308 307 259 273 292 300 293 275 274 323 301 298 266 320 278 298 281 301 299 267 307 310 274 313 297 262 244 307 294 291 286 303 302 299 277 273 290 298 291 276 280 298 260 317 273 315 274 294 288 294 261 333 327 304 304 289 285 274 292 286 285 295 260 281 246 288 237 303 274 245 295 270 294 276 286 305 283 317 298 291 266 271 263 276 266 269 247 271 268 297 271 295 268 286 301 272 291 266 283 308 300 314 278 270 296 284 279 276 325 281 271 273 308 281 285 296 290 271 277 280 269 285 324 287 266 292 289 281 314 284 289 309 295 258 290 295 292 281 329 258 296 298 305 291 279 288 287 317 287 312 294 283 280 282 298 258 300 302 275 279 261 309 301 270 323 283 309 297 305 305 297 292 294 282 320 320 288 273 271 280 272 278 273 290 270 273 283 285 273 302 316 278 295 275 278 268 283 315 273 268 275 290 286 274 263 300 262 295 269 292 302 270 299 274 298 283 289 290 276 287 270 275 290 266 307 281 314 283 280 278 279 308 245 288 291 272 286 272 285 291 294 293 283 294 262 291 303 276 314 301 285 297 288 318 305 299 317 297 287 276 284 295 276 276 317 325 310 312 301 288 284 304 291 288 274 281 321 281 290 267 286 267 332 288 273 294 309 292 307 286 312 283 263 291 301 291 271 278 280 298 291 265 271 285 294 298 275 296 278 296 285 293 279 302 298 273 290 270 303 300 287 289 317 298 288 267 268 267 268 297 306 308 328 256 297 299 284 319 279 303 281 273 314 275 288 275 318 306 285 314 302 311 233 272 273 263 266 275 298 279 295 293 294 313 304 323 312 303 302 280 288 281 300 285 298 279 295 288 307 289 305 309 300 292 269 288 276 324 291 335 289 296 315 280 278 305 282 286 292 301 279 305 271 331 315 284 294 300 268 280 318 293 316 296 298 299 293 287 285 300 292 299 316 299 318 285 291 294 291 306 314 318 300 295 287 300 326 287 279 297 303 313 279 318 259 308 332 282 313 291 298 291 283 316 303 286 309 275 302 310 263 291 271 298 275 272 260 297 303 306 282 296 310 260 314 267 286 283 299 300 316 312 281 319 326 307 263 292 316 301 276 315 316 284 288 314 308 288 263 263 310 302 275 309 276 296 305 286 298 285 312 288 307 257 292 308 299 297 281 306 302 306 301 307 290 262 316 309 305 288 286 292 284 296 303 316 305 279 325 293 315 309 306 301 289 272 284 301 282 280 282 282 297 289 263 283 285 309 280 309 291 299 306 259 292 276 303 320 329 272 276 305 286 291 288 283 294 306 275 264 266 296 308 272 294 279 291 258 281 291 281 287 281 290 296 304 257 280 268 284 298 276 288 273 287 298 292 312 293 299 275 281 263 269 280 292 304 284 291 294 304 274 305 286 311 288 277 318 289 314 275 273 303 287 260 271 314 312 311 299 302 295 239 284 292 286 289 282 278 270 285 285 268 273 302 266 298 313 279 327 272 284 277 263 313 307 305 288 277 306 286 290 285 268 274 295 255 293 311 277 271 284 286 289 310 298 273 305 302 300 245 282 301 287 296 285 286 271 266 272 303 301 294 301 256 271 310 288 270 256 314 294 292 292 286 310 244 267 310 260 256 294 286 275 281 286 297 269 294 294 305 294 248 331 301 295 272 292 290 277 268 280 282 294 285 279 284 276 270 281 291 271 289 272 296 313 282 257 286 283 306 284 318 263 273 266 266 258 261 250 274 262 277 304 282 265 280 312 296 282 262 264 279 273 264 247 262 264 285 266 265 274 261 273 245 282 289 286 274 273 262 312 263 263 266 292 280 284 295 262 274 266 282 293 287 271 259 284 265 267 278 287 278 301 273 283 287 279 277 309 300 293 273 246 274 245 282 270 262 283 271 277 282 273 269 289 262 238 246 263 264 222 278 245 262 269 293 269 267 282 257 261 258 289 274 222 276 292 281 273 302 283 265 257 279 278 272 284 234 281 275 282 292 255 265 281 267 259 281 280 280 277 231 267 300 286 255 250 281 261 267 262 286 270 292 238 260 273 255 247 289 233 268 270 262 266 272 242 238 281 247 281 291 269 276 260 209 235 246 258 274 290 283 230 293 261 296 261 232 272 223 246 289 263 232 258 233 261 262 268 280 267 261 248 264 259 217 263 295 256 264 268 247 260 278 273 266 257 300 274 288 222 256 236 245 227 288 258 248 271 269 231 243 239 237 219 263 298 261 292 270 272 284 268 257 245 267 261 246 222 290 255 246 244 286 255 271 257 220 278 269 223 226 266 276 279 281 245 273 255 262 260 274 248 248 238 255 284 264 226 272 243 267 240 271 241 248 255 268 239 269 291 257 242 277 234 245 259 276 299 270 258 224 235 218 228 257 271 232 263 263 228 248 255 248 288 268 237 257 258 236 267 216 261 265 258 231 212 233 256 277 244 237 286 283 265 276 249 234 239 233 279 224 262 241 225 257 238 268 227 278 228 258 248 218 266 238 255 249 239 263 272 245 249 228 263 232 244 242 267 247 247 256 246 275 258 265 209 245 270 279 255 286 261 223 257 244 268 259 223 230 280 272 281 245 270 232 266 235 257 257 272 239 260 248 246 225 231 266 257 232 264 240 258 256 271 247 233 243 231 235 236 257 231 225 249 236 231 244 229 224 217 262 243 220 244 235 212 261 234 238 218 226 231 231 243 242 244 240 233 235 236 241 259 224 229 260 257 266 247 261 224 286 229 230 226 267 219 221 259 246 237 234 224 226 247 258 249 261 202 220 222 295 273 268 227 201 240 257 248 240 239 245 234 240 223 240 244 256 233 226 264 231 234 248 235 232 235 241 255 245 218 205 225 243 244 263 238 238 239 241 244 221 258 236 225 226 219 239 237 239 240 236 222 241 240 247 257 236 234 229 221 258 258 239 274 212 221 241 250 256 229 215 233 245 240 256 230 284 233 230 246 270 268 215 239 232 259 256 220 231 196 256 259 205 222 224 242 241 246 273 257 223 271 228 231 250 248 236 233 248 240 230 227 220 267 236 245 220 231 240 247 219 201 212 240 212 232 201 261 247 258 209 231 221 227 227 242 228 249 212 239 277 259 235 222 271 227 236 238 234 240 248 228 240 236 244 247 231 232 264 224 241 230 215 230 277 215 263 225 227 243 233 263 210 235 230 234 233 224 216 219 219 243 232 207 233 248 224 249 218 236 243 225 228 238 238 210 214 241 260 227 238 224 255 244 259 266 226 240 264 223 233 249 238 256 227 268 215 224 226 230 269 264 228 260 244 221 265 284 231 231 234 214 240 215 263 246 231 256 221 222 234 236 194 242 248 226 217 242 218 250 236 211 228 238 220 232 245 208 221 209 223 241 236 226 260 220 224 201 267 223 243 220 205 227 214 209 223 245 221 228 221 223 235 238 220 204 224 249 236 227 238 242 257 223 216 260 231 239 224 219 266 227 259 226 235 231 205 238 208 239 228 233 233 243 226 241 243 224 207 218 281 262 214 227 235 240 241 212 232 240 256 204 231 232 231 229 225 245 210 204 224 203 213 212 219 224 233 221 236 235 220 235 248 208 246 232 203 227 208 240 255 216 227 223 236 234 241 243 219 203 186 215 236 242 190 233 225 220 232 208 219 213 247 247 201 227 219 225 224 209 193 228 238 235 178 214 228 243 220 213 234 222 216 246 223 208 209 206 226 215 231 227 226 249 231 244 236 212 211 222 222 233 224 204 210 243 221 237 225 241 240 229 230 244 211 231 207 255 223 267 241 227 209 237 222 234 194 232 236 225 226 223 268 215 214 239 238 216 240 264 246 225 225 211 246 239 273 242 214 202 245 194 201 221 231 236 206 232 223 211 223 225 263 235 227 237 205 211 261 208 220 214 232 257 215 231 202 224 214 182 255 191 231 226 233 219 220 248 241 205 234 221 222 244 228 229 233 237 238 221 228 239 243 236 247 232 220 213 211 255 228 242 231 235 218 223 218 248 201 250 204 223 207 220 219 225 219 223 233 239 241 212 225 278 236 216 235 250 245 207 239 232 234 224 213 233 208 206 217 218 236 232 208 238 201 228 239 231 220 226 232 231 241 195 212 224 227 216 243 249 199 215 232 213 230 224 242 240 259 235 224 262 226 193 221 210 229 226 235 230 230 261 209 244 244 203 231 276 236 236 235 225 262 223 247 225 241 201 230 224 260 231 229 226 237 247 238 257 225 219 228 215 233 207 225 214 233 214 230 213 212 236 213 258 215 216 257 220 247 226 238 233 233 210 247 233 228 229 227 225 221 228 239 247 232 210 220 276 243 224 207 230 215 231 226 255 218 209 227 225 225 247 247 222 243 256 262 245 225 247 216 235 235 226 229 234 231 240 220 221 233 247 233 219 209 204 212 230 245 215 221 224 237 236 247 212 219 190 221 242 237 224 233 245 230 223 234 206 234 248 264 235 231 231 226 228 232 233 243 226 202 236 244 206 219 213 219 244 234 233 218 234 213 220 223 223 212 229 242 202 255 242 237 236 236 265 258 276 267 269 256 239 239 242 269 246 275 227 259 271 285 261 258 234 290 260 255 270 239 230 257 231 257 232 247 247 250 227 244 222 221 233 246 255 224 256 247 222 256 241 248 237 246 249 225 237 239 245 220 222 225 213 207 266 255 243 210 216 261 224 241 209 219 248 241 207 249 215 262 236 224 259 220 240 238 220 214 218 224 256 235 216 222 212 221 220 201 244 231 246 247 240 224 219 238 223 217 215 214 243 227 230 225 230 242 227 268 221 202 228 208 246 231 220 230 232 204 240 215 233 229 224 200 234 203 221 212 240 211 242 258 225 203 207 230 202 229 219 247 214 225 227 222 228 224 227 210 221 203 207 220 238 215 239 232 229 232 238 247 237 215 222 237 244 231 185 215 262 236 237 202 226 231 199 208 223 240 238 213 229 205 217 207 239 220 214 255 248 233 246 233 231 244 228 226 222 224 201 218 227 231 216 208 228 228 240 217 216 216 195 226 226 210 211 219 187 223 223 218 226 235 211 250 231 203 266 245 209 214 213 237 249 249 210 223 219 201 228 228 192 213 211 217 210 213 218 226 220 205 230 203 214 227 256 218 231 229 245 221 229 212 211 227 212 224 212 218 261 224 221 244 223 200 230 235 218 216 231 232 207 218 230 230 222 229 211 234 202 211 208 197 231 215 218 209 263 247 216 256 225 228 230 224 239 257 213 225 223 233 212 256 256 233 232 228 200 230 241 241 239 197 199 229 228 234 228 202 226 216 221 236 212 221 229 217 240 220 223 207 219 235 231 220 231 238 244 242 245 217 230 238 214 197 198 234 226 230 237 211 206 206 225 235 234 224 261 243 222 228 207 234 200 214 232 223 225 229 255 238 240 243 220 187 224 235 200 261 229 223 204 223 221 227 232 240 226 201 237 220 212 235 258 246 218 263 244 247 222 226 230 218 198 235 203 226 226 233 218 214 228 225 243 204 245 210 206 246 206 211 204 258 197 243 205 248 220 209 255 213 218 265 238 227 206 239 227 213 245 194 221 242 221 210 214 246 189 235 235 201 231 244 211 245 246 209 207 226 218 215 212 223 220 223 229 225 240 219 222 187 255 222 238 239 225 227 219 256 220 227 225 213 228 246 242 230 230 221 200 204 209 217 220 219 231 255 210 205 224 219 190 231 208 225 214 222 263 239 202 222 232 218 212 227 212 229 210 245 226 238 226 243 235 227 202 205 219 239 244 241 214 233 231 209 207 223 233 255 226 229 239 229 215 217 243 234 215 247 219 228 221 224 196 202 218 217 227 225 247 229 237 242 222 230 258 227 229 211 255 273 228 212 259 237 208 227 227 221 224 220 218 235 241 229 230 257 232 255 245 239 206 219 226 195 218 233 245 221 240 233 259 255 267 229 205 204 218 236 184 242 216 249 209 246 227 225 226 197 260 259 233 229 218 242 216 241 215 237 263 225 224 263 237 219 225 245 229 234 213 241 222 220 222 224 258 258 219 236 230 243 191 177 234 223 236 209 223 235 242 221 237 230 270 228 240 267 213 227 223 270 229 211 227 263 230 247 244 235 235 236 245 243 242 240 247 256 202 237 233 264 224 246 239 236 247 237 248 263 244 258 262 229 246 265 261 232 245 242 239 293 279 275 272 263 282 270 259 248 275 295 259 293 256 289 271 281 266 296 299 283 286 276 288 337 314 288 311 319 318 319 349 369 376 320 362 355 376 389 393 379 402 425 428 432 418 397 449 398 417 397 411 369 375 447 420 379 398 364 376 332 352 347 335 360 320 345 355 313 318 297 333 304 262 277 269 333 262 242 263 267 264 258 275 273 224 232 287 234 280 265 266 257 271 248 261 249 272 221 230 234 267 264 247 223 279 222 231 235 241 243 215 259 224 264 229 233 245 260 237 223 268 233 235 240 263 212 236 245 218 236 223 233 230 229 202 220 225 207 215 225 204 229 232 239 227 257 215 204 201 219 234 206 217 237 216 231 235 226 223 204 246 236 228 211 228 223 220 235 229 230 245 218 222 231 230 230 221 231 237 231 226 236 204 219 233 227 213 242 209 190 245 219 222 217 236 225 224 211 256 229 223 205 210 216 266 233 231 218 271 240 240 214 209 219 233 255 219 242 222 258 235 199 241 223 212 244 226 239 213 235 218 237 229 240 234 212 231 227 239 214 231 210 214 241 205 212 230 228 273 227 228 223 230 212 222 238 220 214 226 212 244 209 225 207 272 243 227 244 246 201 240 213 216 260 221 269 234 239 231 202 221 226 202 222 260 219 242 210 227 232 231 203 220 228 214 239 226 255 265 212 229 228 222 270 241 232 245 200 240 202 234 217 218 213 236 210 195 228 241 232 204 216 221 219 249 240 229 232 226 226 203 221 239 258 256 231 249 214 241 241 228 199 255 259 237 219 241 225 236 225 219 243 261 242 223 245 231 232 240 211 238 224 224 243 234 206 256 213 202 236 234 230 247 228 226 230 213 263 227 233 240 236 237 258 236 263 241 224 222 218 218 223 219 203 236 215 272 244 232 227 232 229 230 235 247 234 212 224 187 238 225 259 212 197 220 230 237 243 219 236 235 233 225 244 245 235 247 248 232 228 218 244 218 242 237 244 221 218 219 211 231 216 248 234 207 249 214 242 232 213 260 245 236 258 223 241 245 198 240 233 231 220 223 231 216 210 242 242 241 216 228 211 227 232 256 266 233 246 209 211 222 231 269 245 249 243 233 262 213 219 225 209 242 210 245 233 255 193 233 242 216 234 236 231 248 215 236 235 226 217 233 244 225 249 242 236 237 232 234 224 248 284 232 260 215 232 238 240 242 274 269 238 281 212 237 277 232 229 239 231 250 245 235 247 257 243 208 209 245 213 236 238 244 241 230 246 269 217 220 206 222 237 225 233 241 223 227 233 231 218 206 233 209 255 210 220 226 216 268 246 227 247 256 246 225 220 244 260 226 219 216 242 229 263 240 234 238 221 264 213 240 245 225 227 242 262 217 226 242 224 221 257 242 201 236 216 218 248 260 234 204 232 273 268 241 234 215 212 220 224 237 236 244 202 245 230 230 233 240 216 234 241 214 228 234 232 256 257 235 225 288 239 227 220 250 231 232 240 270 232 226 225 247 261 236 262 249 231 228 255 248 229 227 242 236 245 228 264 235 225 241 216 224 247 219 240 227 240 236 208 227 244 214 239 226 218 225 243 239 240 230 259 265 234 264 226 227 229 238 226 211 221 262 264 235 228 269 273 260 241 259 239 246 259 219 248 241 245 235 233 247 238 259 217 231 233 231 244 261 240 230 241 223 245 238 233 217 231 222 223 227 243 268 248 256 267 235 223 245 238 233 263 245 220 220 262 240 227 220 238 231 189 220 223 204 255 240 248 258 229 229 244 241 236 234 249 231 247 223 243 244 213 224 257 262 247 219 217 228 243 243 213 246 228 216 243 232 244 239 233 271 248 243 255 256 248 232 243 229 244 218 230 239 233 265 208 260 213 256 272 248 240 220 249 226 266 228 229 231 238 247 235 246 210 279 222 239 273 245 227 266 258 225 223 228 217 245 269 239 232 218 256 237 242 234 230 241 227 238 258 237 232 272 230 241 239 230 247 257 229 272 234 227 245 249 234 257 218 261 245 245 220 236 230 236 199 256 235 242 234 216 228 250 227 238 266 243 259 235 184 235 244 228 243 211 241 224 226 216 246 229 221 231 215 227 229 265 232 238 237 229 266 243 257 215 215 246 260 240 268 250 230 244 230 261 225 284 264 247 239 228 246 247 219 205 230 218 235 247 228 235 229 234 238 238 265 245 261 249 239 258 271 205 257 225 221 205 246 285 255 240 243 223 266 245 236 248 227 243 233 243 247 226 236 224 236 217 221 233 244 240 240 267 246 260 247 219 275 240 256 227 226 243 277 269 238 210 227 235 229 241 256 244 245 239 228 217 226 249 238 259 246 233 255 218 257 236 230 256 255 219 236 256 226 238 255 283 210 223 256 214 271 261 256 233 197 237 217 247 246 256 236 217 237 236 258 222 245 233 235 234 241 247 268 217 258 247 235 237 216 237 241 255 230 233 248 228 237 222 281 228 234 249 232 229 232 220 234 237 236 241 248 234 225 228 243 247 262 264 275 229 205 238 243 214 228 222 259 217 223 256 259 242 231 243 235 258 243 216 243 229 217 243 228 221 224 239 255 227 233 247 247 243 239 236 243 269 235 230 225 221 216 241 264 260 258 243 259 228 207 227 239 255 236 243 262 221 233 205 263 225 216 213 233 241 270 230 218 270 241 232 223 262 237 247 217 227 245 247 264 238 250 243 249 281 241 236 272 264 249 265 240 241 207 248 257 227 226 230 257 228 225 272 256 269 240 247 228 239 247 273 238 272 244 249 241 245 273 225 231 243 260 208 258 229 250 248 213 257 258 264 220 238 234 234 270 233 267 229 250 260 224 233 256 255 237 228 261 224 266 263 243 276 263 237 258 235 244 219 241 258 264 243 240 242 221 247 267 248 233 231 215 240 231 235 199 236 223 221 258 197 248 219 235 258 232 240 231 283 266 228 243 224 219 261 244 230 210 238 268 248 236 246 239 242 260 269 226 265 230 221 237 236 227 214 246 230 230 229 236 219 267 245 234 220 243 243 235 242 235 262 259 238 231 242 228 219 240 260 233 267 222 216 277 239 216 221 234 228 238 248 243 240 278 236 268 200 247 215 227 243 228 221 281 259 276 223 281 224 227 234 277 223 212 270 259 208 255 260 244 261 263 262 246 236 219 233 233 235 267 227 246 248 236 242 241 268 282 248 229 230 215 246 225 236 277 258 276 257 238 229 259 268 213 239 259 218 242 261 234 235 259 255 269 268 272 245 217 244 257 242 240 248 243 257 276 244 258 274 245 245 215 244 255 214 244 235 283 276 243 235 264 266 221 239 267 245 232 275 270 227 227 246 248 244 247 236 271 246 244 249 250 233 223 255 246 210 219 245 229 234 228 273 246 237 232 239 281 234 259 264 273 266 234 244 238 234 260 237 232 232 236 256 234 244 266 242 265 244 249 243 268 240 261 245 267 237 216 228 188 258 238 232 243 246 272 244 249 243 295 232 240 247 245 268 257 222 233 265 241 247 224 219 234 270 212 232 237 204 259 232 232 263 260 246 261 232 255 256 225 262 246 235 231 245 266 244 268 266 226 245 257 217 230 262 241 258 290 237 256 259 259 223 246 224 268 237 243 244 259 285 266 270 242 246 269 230 269 238 275 281 244 234 241 278 236 240 244 236 238 260 240 277 234 236 249 223 238 237 287 244 261 241 233 239 226 258 257 238 225 247 226 262 226 223 261 245 241 241 234 241 242 248 227 236 242 280 241 264 226 239 242 230 234 248 259 244 244 259 246 265 233 263 264 246 237 237 227 263 234 208 247 250 230 229 209 236 242 269 246 234 234 239 201 235 226 265 271 244 271 243 261 240 233 204 216 225 262 231 231 243 234 268 234 245 233 265 242 244 230 244 228 256 291 265 263 247 232 235 229 242 276 247 257 248 243 261 260 244 224 241 274 211 221 227 265 266 257 262 243 231 236 231 272 220 221 268 278 239 242 224 247 234 266 217 240 255 238 241 248 226 241 239 229 265 247 264 228 269 249 241 240 265 236 240 259 255 257 275 275 226 232 239 242 277 215 242 245 265 243 244 244 203 237 243 216 225 221 240 276 265 216 256 249 272 234 229 243 226 263 278 246 256 260 266 268 236 261 245 225 248 255 258 261 271 232 255 250 220 246 291 271 238 275 239 283 228 248 222 283 300 245 263 233 241 267 235 277 260 234 219 279 246 230 231 257 262 261 239 248 269 241 264 258 245 239 242 229 245 264 241 275 257 223 237 241 243 217 283 260 273 292 249 240 255 259 221 275 257 256 266 244 255 249 242 218 238 269 247 246 233 255 275 263 257 225 262 256 245 262 268 282 237 220 245 239 264 276 265 268 240 271 283 272 240 240 227 266 239 284 256 276 245 255 236 275 247 266 245 275 274 268 266 267 249 248 272 261 258 247 277 243 235 263 223 235 267 237 228 243 242 212 243 259 265 276 243 241 266 249 250 256 289 231 258 245 269 249 258 231 248 255 255 244 244 271 269 246 249 269 271 286 244 237 249 249 262 263 234 244 273 273 248 247 239 242 281 241 239 250 219 230 244 258 264 264 263 265 259 239 226 223 257 279 201 226 256 224 276 245 275 266 257 244 237 237 273 267 258 278 272 297 264 273 255 238 275 282 248 248 262 283 276 228 226 269 288 262 291 289 235 243 264 261 246 248 264 275 293 261 248 279 274 264 245 281 257 279 263 240 259 238 275 258 255 245 264 270 269 247 268 261 261 274 278 295 269 263 243 274 283 278 247 280 243 247 250 277 274 268 269 279 238 264 236 266 283 249 234 260 259 234 288 248 255 268 255 274 265 259 280 223 247 235 273 238 273 239 261 263 246 280 236 259 243 282 247 283 259 243 279 266 257 287 261 293 256 234 258 262 238 241 239 220 256 268 248 272 268 243 232 284 275 231 262 270 256 269 250 249 221 248 280 234 249 274 277 269 247 264 255 235 249 270 272 258 270 232 278 241 257 258 262 267 250 230 263 256 257 249 260 271 228 272 238 273 267 258 247 214 243 266 244 276 222 271 261 276 278 256 264 257 239 262 238 259 247 232 243 258 269 246 268 260 246 239 239 262 204 262 259 263 271 228 256 271 230 242 232 225 249 258 244 209 264 240 245 259 237 278 269 248 234 263 243 249 265 275 238 231 264 259 227 247 267 255 249 280 257 294 258 255 247 275 222 276 269 275 243 250 265 269 260 256 261 241 282 241 249 272 242 218 268 286 265 261 247 236 267 271 230 248 268 250 270 247 248 274 226 206 288 264 240 242 274 243 241 258 263 273 280 288 231 271 245 258 266 249 267 246 262 222 228 244 278 238 267 236 261 265 222 269 257 281 243 275 275 280 244 239 266 275 276 243 268 278 245 245 272 278 266 266 237 275 266 229 243 292 265 259 255 276 250 238 217 265 279 273 260 230 267 279 240 229 243 235 273 255 249 291 255 263 248 237 264 275 261 242 260 287 242 244 224 262 228 265 248 240 259 271 272 277 241 269 241 265 238 249 282 259 264 274 282 282 261 255 280 265 248 261 291 244 273 264 271 255 268 267 239 276 260 281 242 257 287 279 230 272 258 237 263 235 281 243 260 257 265 265 245 276 262 280 279 264 266 265 235 239 274 260 243 257 272 255 238 279 261 239 264 265 245 236 265 269 271 245 234 260 245 236 284 256 247 275 271 279 271 249 277 259 262 286 269 276 279 270 270 240 310 258 246 248 248 237 257 223 241 258 260 288 268 235 261 222 224 231 221 258 238 218 266 265 263 232 241 285 261 244 245 240 244 272 256 247 284 277 243 236 245 263 270 271 242 237 265 273 257 244 242 261 261 245 270 268 243 278 271 245 239 281 256 279 233 222 256 231 255 288 242 284 287 247 267 264 274 260 269 234 235 258 266 239 272 260 272 231 272 273 246 248 257 264 247 267 279 243 258 290 258 268 238 241 237 240 248 268 288 262 279 243 268 231 300 246 264 269 277 234 278 270 220 270 290 282 269 260 230 265 287 228 291 275 283 248 261 244 245 261 295 241 287 277 260 239 266 272 243 247 258 284 263 248 258 289 234 231 227 277 284 233 268 212 272 270 271 249 263 282 257 259 247 261 242 273 249 247 258 227 241 281 267 273 286 248 273 255 243 269 260 249 269 258 248 296 236 245 257 257 217 257 238 242 245 247 238 236 270 264 256 259 284 277 265 248 259 260 249 265 280 255 267 276 267 248 278 248 240 285 250 259 248 237 260 256 241 258 265 261 272 265 237 271 230 263 255 279 262 261 257 277 261 248 229 250 245 273 269 267 266 277 257 269 265 257 224 237 282 239 234 267 231 247 272 233 267 246 259 270 276 243 263 241 236 265 264 260 239 266 245 272 262 215 262 241 295 243 263 240 270 247 230 232 279 266 245 238 280 265 268 239 262 246 218 311 245 272 272 285 230 235 248 262 243 257 265 249 232 260 244 271 258 246 232 274 248 257 268 247 273 275 238 239 279 233 225 247 283 258 278 264 258 273 271 261 289 273 275 236 263 257 257 246 243 250 255 235 262 256 258 258 240 270 272 246 273 279 243 245 256 271 232 240 256 257 255 263 240 232 280 242 269 224 255 273 274 240 277 246 278 277 247 261 244 280 231 292 240 265 244 229 260 268 236 264 267 271 232 277 237 259 272 268 227 248 292 215 244 268 236 260 260 259 273 240 234 261 270 238 258 228 257 245 245 239 245 257 272 273 245 221 272 238 224 249 232 248 220 301 208 259 255 258 270 238 248 245 267 246 240 235 267 235 258 245 245 259 242 230 221 261 223 256 244 264 264 240 290 266 239 274 255 271 236 256 256 227 273 218 259 272 249 256 258 217 277 261 246 227 248 264 224 277 282 237 263 267 279 255 236 226 245 288 226 245 227 277 282 258 247 269 258 245 282 243 268 259 237 238 276 274 278 249 275 236 265 260 245 268 261 247 237 229 222 248 224 242 289 259 243 300 230 259 255 247 258 263 272 248 297 262 250 269 274 283 224 246 263 249 261 277 272 274 243 246 249 265 277 268 263 239 258 245 242 258 232 256 241 258 275 288 241 243 290 247 258 265 277 274 278 224 244 289 262 262 274 262 246 274 249 246 250 274 272 278 233 281 270 262 276 243 259 255 262 230 275 267 275 270 258 262 246 237 231 284 277 274 264 235 233 243 258 225 282 244 275 291 262 239 259 278 256 237 211 249 262 264 288 291 290 272 273 266 277 244 262 280 256 277 260 268 296 265 236 243 268 234 265 277 255 263 268 299 246 256 247 272 263 222 245 243 269 279 257 261 279 248 239 237 249 258 286 227 241 257 259 265 281 273 256 288 246 245 268 266 270 226 248 266 224 267 233 268 269 261 266 280 240 271 263 232 225 248 271 285 279 265 271 271 273 241 273 302 256 280 246 294 290 266 265 248 268 242 290 230 245 234 256 265 272 266 260 265 291 272 283 292 269 269 245 260 243 255 236 260 266 263 240 265 274 255 286 259 260 256 299 242 260 245 270 271 250 235 258 289 237 271 255 273 241 227 280 263 273 276 271 256 260 266 322 283 246 281 276 256 226 272 255 259 273 261 264 243 258 277 270 278 270 279 296 257 259 264 227 274 267 274 264 280 256 259 280 243 249 248 243 256 266 268 258 235 286 270 247 259 281 233 257 263 236 287 257 261 280 261 248 243 265 265 269 248 297 258 241 271 264 288 273 245 255 263 259 256 242 272 270 239 240 281 242 275 266 265 245 229 219 266 257 265 262 257 272 246 290 232 259 275 273 221 258 260 260 291 258 249 261 262 278 246 261 261 277 262 278 256 245 262 275 287 224 288 268 224 260 236 257 271 259 242 261 271 268 267 246 272 269 274 262 265 271 300 270 273 264 258 276 265 278 288 242 257 255 284 283 259 266 287 274 290 272 256 259 248 286 264 262 248 277 239 265 245 277 270 235 285 246 246 246 266 231 260 225 275 222 238 228 260 261 263 265 257 257 240 267 229 264 249 282 266 274 264 247 291 292 246 306 267 243 247 272 290 245 266 289 256 304 228 239 282 261 291 282 270 274 284 250 237 282 259 255 263 270 263 233 287 277 257 240 312 245 292 288 287 236 248 248 249 245 263 259 257 271 240 259 263 274 271 258 242 248 272 287 256 269 262 234 234 276 241 266 258 269 255 243 289 256 245 257 257 273 238 234 265 265 248 257 259 248 249 243 299 215 239 256 242 262 268 243 294 290 263 269 238 297 214 272 246 246 262 263 232 284 269 277 244 261 272 241 269 263 244 273 258 276 276 281 258 239 248 275 264 261 258 263 244 259 267 242 224 268 258 272 258 263 237 283 284 266 242 236 268 227 248 230 285 281 271 241 274 290 279 246 260 242 270 229 266 246 263 273 262 293 248 288 265 244 281 234 258 275 241 268 233 271 278 229 265 269 267 272 247 283 264 310 265 242 270 264 259 228 266 258 264 257 282 306 264 257 271 278 277 242 260 245 263 278 270 240 243 273 287 265 264 281 257 293 278 280 230 288 248 257 243 248 267 282 292 259 284 268 242 232 264 286 264 246 277 291 262 283 260 284 267 250 260 270 280 279 225 271 285 301 262 248 275 267 272 301 272 266 284 263 271 307 281 294 283 256 269 288 256 283 268 295 268 282 284 276 296 310 317 276 285 275 307 291 275 287 285 283 315 284 266 327 249 313 285 288 297 331 297 317 290 243 283 308 271 301 308 294 300 303 283 282 312 306 303 261 292 314 289 295 305 268 314 278 285 297 292 289 288 310 286 282 320 266 313 287 320 272 262 261 295 286 286 281 272 237 288 270 259 267 299 238 275 281 283 308 273 264 290 268 324 270 293 263 298 277 247 300 272 266 243 255 261 229 248 261 295 295 277 265 262 259 268 271 270 285 271 266 263 265 269 281 255 269 290 274 259 275 267 271 278 245 242 242 294 255 248 269 265 262 245 247 273 271 245 266 241 286 268 236 260 243 265 271 269 240 258 260 228 258 289 269 261 274 282 278 241 270 264 230 274 268 287 275 267 271 283 244 269 262 282 289 245 259 250 257 294 256 245 241 255 286 239 265 263 247 236 243 262 278 270 274 238 227 289 258 233 271 216 269 273 260 298 265 270 264 235 256 281 256 266 260 234 250 256 261 216 261 267 266 243 279 249 262 245 263 236 248 255 260 272 240 277 260 222 236 268 244 271 276 234 265 257 260 211 283 266 275 247 216 281 247 241 273 243 270 265 237 264 264 270 259 264 245 264 230 275 284 239 269 272 300 231 271 266 263 284 238 279 263 265 262 278 265 237 269 263 259 300 223 248 272 268 270 242 229 276 248 232 262 286 233 286 277 222 215 260 259 240 273 288 256 244 288 227 264 247 246 256 271 260 272 266 248 244 240 234 241 247 246 257 230 248 269 271 236 265 257 261 272 267 249 226 243 281 232 291 238 236 271 259 236 238 277 249 249 266 263 228 275 261 270 259 259 238 255 256 285 261 238 276 288 292 275 237 222 278 261 243 269 264 267 233 288 240 257 271 239 266 243 263 258 277 267 261 246 270 237 255 236 217 262 244 248 225 248 240 259 270 239 262 271 244 261 272 289 265 260 271 249 233 301 258 268 235 240 245 287 242 247 239 218 294 257 263 263 269 261 261 277 271 263 247 270 240 239 237 235 279 232 230 275 249 258 264 236 229 267 234 272 282 249 281 242 265 246 259 244 274 239 277 270 278 271 267 268 256 243 256 223 271 259 262 262 247 263 262 277 239 239 286 245 282 282 257 269 242 256 277 248 294 235 259 267 257 244 264 231 245 244 232 258 272 258 221 256 270 256 231 230 241 267 245 227 244 268 236 271 226 258 272 234 276 287 238 256 271 257 237 275 270 278 258 258 275 244 283 246 269 245 255 224 262 233 232 271 257 266 260 260 234 241 247 259 259 269 234 267 286 287 265 261 276 257 245 246 255 244 290 247 281 240 285 248 240 239 246 263 263 272 272 245 248 235 242 249 276 223 261 237 247 264 271 257 238 297 277 274 258 227 259 255 268 270 234 257 286 257 263 257 285 256 236 233 230 255 273 270 230 274 248 212 278 242 279 236 245 274 249 243 238 279 268 238 286 263 290 256 276 266 256 239 281 260 247 282 234 273 234 228 282 238 233 239 247 237 273 243 248 276 260 223 261 284 221 260 261 282 241 313 261 227 240 241 268 284 255 248 280 237 257 267 244 264 257 226 281 260 225 270 237 255 277 264 245 262 267 277 263 295 275 266 233 276 256 270 263 255 276 246 289 267 260 265 271 267 259 259 256 269 268 221 248 290 270 270 259 255 278 265 242 278 260 206 234 243 234 289 258 266 264 238 223 277 245 275 232 246 237 294 256 270 273 234 242 233 271 241 248 276 234 235 276 238 262 237 249 275 238 263 264 242 220 238 277 288 277 276 263 259 257 265 263 276 266 245 265 250 297 256 239 272 246 241 240 271 275 234 230 260 249 272 231 236 247 255 256 265 271 259 286 258 262 264 261 272 279 248 255 260 246 275 295 256 235 282 255 247 247 269 238 268 212 286 262 249 277 286 246 224 281 244 274 230 255 271 245 270 257 275 231 222 268 243 249 250 283 249 272 241 243 290 287 284 241 288 264 268 256 238 280 285 281 262 244 272 233 244 256 242 268 226 256 257 259 239 242 286 268 273 281 260 255 271 271 271 274 271 271 271 237 232 225 263 228 266 273 271 238 258 247 255 260 274 259 211 265 259 219 259 261 258 261 245 258 285 223 230 269 257 261 233 235 261 259 238 243 276 264 264 249 250 290 217 259 242 286 276 239 255 265 243 274 257 247 267 259 244 230 285 233 243 278 243 224 246 244 248 240 239 263 241 280 275 246 261 226 271 272 225 258 237 263 267 219 249 209 266 232 228 262 249 285 242 241 245 247 264 237 260 240 229 261 240 258 243 270 276 246 231 285 242 233 285 220 257 237 262 279 268 276 281 262 256 267 257 248 276 243 257 271 265 281 277 256 265 283 279 231 264 247 255 244 233 256 241 245 265 255 264 247 237 285 247 266 236 244 271 299 269 279 245 278 269 243 267 264 256 238 274 257 219 283 264 281 235 270 236 268 269 283 267 259 234 217 265 243 234 277 248 248 230 255 273 263 229 258 247 244 246 243 238 256 249 305 246 291 264 279 266 255 269 230 261 259 249 278 250 257 268 244 255 263 255 244 269 236 258 278 240 232 287 257 247 266 236 291 232 277 280 282 225 257 223 231 260 234 246 260 228 230 273 228 222 284 268 231 262 222 261 247 264 275 287 238 274 244 277 260 264 277 243 223 264 262 243 260 256 247 261 266 289 238 262 269 229 249 271 272 242 268 246 271 255 243 271 242 249 257 233 256 227 268 276 225 267 242 233 249 232 259 268 266 280 275 288 260 239 270 246 238 269 235 261 227 245 262 245 224 222 261 242 260 281 240 268 262 285 269 279 272 262 247 230 272 284 257 227 255 270 283 233 249 267 247 267 218 255 287 258 236 244 246 264 262 270 244 244 279 224 245 246 287 263 266 236 279 246 243 248 269 236 266 264 287 231 250 290 235 244 249 259 244 280 259 268 300 241 242 271 261 241 257 256 272 248 285 269 265 292 264 261 276 237 289 247 261 260 248 269 262 265 266 257 271 276 234 266 228 263 226 281 265 266 237 273 278 241 231 266 288 210 262 242 242 240 269 249 248 270 243 247 256 272 272 259 280 242 264 256 258 266 259 269 257 233 238 277 274 226 215 267 239 294 275 241 276 269 256 266 259 261 256 262 263 259 240 256 271 263 215 261 267 256 269 261 242 265 261 262 244 296 225 256 246 246 271 268 228 236 238 273 279 242 249 249 269 277 266 272 241 277 243 241 228 248 257 281 246 281 228 248 262 269 269 275 264 248 284 264 277 231 255 229 223 243 264 262 268 275 259 227 242 241 270 238 245 245 244 249 226 244 271 263 248 239 247 255 267 285 260 229 275 264 240 245 260 248 242 267 260 264 269 256 240 228 228 291 234 289 244 281 268 249 240 233 237 268 265 244 243 278 232 222 258 267 230 231 240 243 246 278 261 261 259 276 233 283 291 263 250 261 269 255 237 256 243 235 244 255 241 268 237 239 249 232 264 249 234 268 265 270 262 238 264 246 240 249 262 226 274 277 234 237 268 258 257 265 225 214 257 249 239 249 234 255 276 240 260 278 234 244 272 264 244 275 267 228 278 222 262 229 264 263 256 270 243 233 229 258 241 244 269 249 264 236 266 246 229 248 247 274 263 249 247 258 258 264 241 240 219 271 257 249 246 238 297 233 256 256 240 276 242 283 240 229 248 246 244 244 289 264 286 259 258 245 261 259 261 256 228 275 260 263 225 257 261 268 269 260 246 225 256 272 247 267 248 255 290 248 247 262 271 289 245 250 242 280 299 246 260 247 272 303 273 260 233 300 264 284 286 272 260 294 301 274 280 247 258 258 262 285 249 309 256 260 262 287 246 273 297 287 248 276 293 261 236 257 249 281 264 284 286 322 259 259 249 275 230 272 295 216 266 264 273 258 238 255 283 250 276 274 275 261 264 273 278 281 274 287 265 264 261 280 269 249 292 287 273 239 268 240 265 260 275 269 270 288 281 243 236 246 257 228 239 263 240 294 304 241 255 258 231 266 264 248 276 281 221 275 257 262 222 262 259 292 280 273 238 262 278 267 282 278 249 259 275 255 232 237 288 273 265 267 290 289 245 272 250 245 275 255 230 288 247 248 243 256 268 299 264 284 233 274 256 297 282 267 242 306 245 266 290 270 260 269 264 245 278 265 249 272 292 261 249 269 263 262 260 232 283 263 266 276 294 232 249 230 278 290 240 231 248 247 259 249 249 265 258 277 289 285 275 276 248 282 243 261 288 241 274 276 246 285 240 226 245 285 246 285 257 272 231 298 260 260 295 256 255 299 290 236 259 228 272 284 289 262 225 274 290 276 263 258 261 238 248 279 247 270 286 263 281 271 279 282 237 287 273 237 269 283 262 256 273 232 259 262 267 273 246 246 265 244 246 236 259 262 271 255 263 268 260 247 272 230 276 264 237 280 268 235 284 249 246 285 259 229 268 263 280 286 244 243 246 275 248 284 243 239 277 247 257 311 238 255 287 267 261 272 272 255 260 274 281 280 281 273 257 266 270 293 289 242 248 230 260 266 304 258 274 236 283 247 256 248 270 232 278 272 289 243 245 248 263 248 244 271 274 264 274 260 256 273 277 260 270 234 270 283 257 287 234 271 264 270 269 256 248 236 247 247 279 272 262 264 277 264 269 261 267 233 244 265 246 292 265 237 227 264 271 269 275 267 276 248 288 290 258 240 266 267 244 244 244 266 238 279 261 275 258 265 267 258 247 258 267 231 236 296 290 278 282 261 276 233 243 268 296 282 273 250 271 294 269 290 238 268 283 271 234 258 262 246 296 283 221 240 245 241 289 249 295 282 248 286 272 270 243 264 212 239 268 264 259 221 235 272 280 264 296 232 241 273 256 257 258 278 250 278 268 264 223 246 278 282 280 273 249 275 258 281 275 260 281 265 226 278 223 282 255 258 240 263 221 264 275 255 286 257 273 255 242 266 278 250 258 259 260 286 269 274 261 245 264 280 233 268 279 244 285 250 266 264 236 272 267 267 249 267 245 259 280 259 294 274 261 272 255 279 276 285 268 276 238 238 246 268 236 268 270 277 287 256 237 267 269 237 247 270 248 257 269 278 269 247 269 285 247 230 240 286 239 264 274 275 261 280 250 241 232 288 273 285 256 242 293 274 256 232 287 258 292 246 256 274 279 276 265 268 231 256 278 264 258 274 242 260 238 260 241 261 280 259 255 249 280 284 294 263 286 242 265 244 260 238 273 263 267 264 247 275 290 235 287 256 258 260 229 247 264 248 245 229 283 272 237 269 238 236 258 258 259 245 279 269 248 245 256 279 249 263 262 265 273 265 278 256 261 248 280 255 243 271 280 258 249 289 231 268 260 281 270 302 283 275 235 248 272 286 248 244 273 238 247 278 279 257 257 221 271 258 260 296 260 243 267 259 267 237 259 269 256 267 235 265 286 281 267 240 248 262 263 275 244 242 287 264 242 247 233 259 230 281 300 231 255 286 268 271 231 234 274 228 248 262 264 241 268 292 245 233 271 229 239 283 222 273 271 261 278 247 266 260 267 263 282 272 261 276 282 245 261 268 231 263 234 271 255 239 258 260 255 267 284 244 282 283 279 267 233 272 284 261 275 234 264 267 272 274 235 276 242 246 277 268 259 238 267 271 259 278 264 260 256 255 258 244 304 260 266 239 279 256 231 267 258 232 250 267 270 246 243 310 285 280 266 259 259 285 276 244 258 236 281 268 298 272 281 286 256 265 271 283 240 274 268 264 285 231 231 246 279 237 257 255 257 256 261 256 261 225 244 269 282 270 275 239 250 259 279 248 243 237 273 256 274 256 266 233 274 232 237 270 274 249 261 269 261 291 239 257 264 229 292 249 261 264 267 298 258 282 232 277 281 242 262 282 273 282 263 262 215 290 258 281 238 244 263 244 282 293 246 259 275 243 262 238 266 287 219 258 231 268 271 257 265 255 269 237 263 281 280 236 255 269 274 234 278 238 241 238 258 288 272 225 248 243 238 266 237 284 286 291 278 245 279 246 243 247 241 256 276 273 256 225 257 266 297 280 259 272 235 275 285 267 289 276 266 261 279 257 256 247 273 276 241 271 282 280 264 239 275 264 266 271 246 291 275 243 281 245 266 280 234 263 271 243 267 255 240 236 248 282 264 255 250 265 275 232 232 306 283 269 276 248 272 273 264 235 234 241 255 259 262 282 255 241 242 237 242 238 278 248 260 231 298 230 288 265 271 266 261 276 245 249 290 269 271 245 261 272 285 284 264 276 241 257 269 268 278 271 247 227 292 296 243 307 266 263 232 225 236 266 260 257 249 265 256 263 284 228 272 284 228 250 259 232 271 246 266 263 240 220 267 240 284 245 241 262 267 272 263 283 248 285 255 273 260 269 245 239 278 284 259 274 255 287 270 248 279 266 246 231 247 249 272 229 223 290 259 248 249 265 262 262 258 271 245 270 242 237 241 304 258 264 267 277 284 258 264 216 242 272 270 285 241 229 267 248 228 257 247 279 260 283 288 282 283 238 262 249 271 243 258 249 256 264 242 246 268 271 237 265 247 271 265 283 280 275 268 282 280 234 270 259 268 273 245 270 274 275 283 264 215 258 278 276 274 262 262 280 279 228 245 298 263 270 288 256 288 267 278 270 268 275 282 243 272 282 243 245 277 246 236 261 283 266 282 272 257 248 289 256 293 275 288 264 306 273 271 281 291 292 287 272 265 272 274 260 290 284 269 256 249 246 243 268 255 247 256 231 256 285 296 260 270 242 274 229 276 263 274 247 256 233 246 274 259 257 277 236 236 262 268 264 257 263 268 302 267 247 290 287 256 238 227 256 276 255 273 265 223 246 267 240 262 263 263 245 273 258 263 280 280 281 276 295 278 275 255 271 282 267 286 274 272 283 249 236 231 232 257 262 268 279 278 247 257 268 258 261 266 258 270 243 262 261 279 288 259 259 262 276 245 238 231 271 278 246 285 295 244 244 289 249 259 275 282 257 276 275 237 261 255 250 288 260 240 249 256 263 280 273 267 259 270 268 250 273 296 291 245 269 283 276 264 244 276 271 298 262 249 276 289 263 280 272 248 266 261 249 263 265 283 275 221 266 295 260 266 245 243 267 247 275 280 278 269 249 248 280 249 276 293 274 277 266 227 272 267 265 285 286 246 310 283 293 285 268 247 272 288 275 237 230 233 278 272 223 265 226 278 243 265 259 243 276 257 279 285 272 242 265 262 265 275 272 260 281 246 289 258 261 275 263 271 242 282 285 265 255 272 281 247 279 285 293 285 263 227 245 243 270 288 287 298 260 259 231 289 271 259 260 266 225 271 245 263 270 262 279 269 270 272 258 265 269 288 278 291 298 268 267 247 279 258 250 244 256 282 263 299 279 255 290 236 245 286 240 247 272 264 248 248 286 260 261 247 265 265 268 241 273 266 233 286 267 257 298 259 255 297 239 284 257 273 238 272 273 283 256 272 273 260 238 244 263 286 227 249 232 281 278 258 274 295 258 242 263 279 259 265 255 288 265 261 240 260 242 246 241 260 263 272 255 256 280 238 266 265 240 298 263 271 290 229 238 271 263 256 264 305 300 248 248 276 257 310 277 274 248 265 256 243 274 288 272 324 263 283 274 257 283 269 245 264 276 280 281 247 269 262 278 269 256 279 250 284 271 291 259 285 246 278 278 268 285 277 267 259 281 273 263 281 255 282 265 275 280 260 244 289 273 264 278 266 280 262 263 240 288 278 231 283 287 267 269 272 249 249 264 288 277 287 282 279 299 270 316 272 299 292 268 262 297 257 281 276 275 275 269 288 285 295 301 272 275 295 279 271 285 291 264 318 285 241 248 265 287 277 233 257 284 305 280 237 291 261 287 277 262 263 274 301 268 264 285 263 288 277 272 316 300 279 244 291 283 286 270 275 284 295 277 246 271 293 274 257 283 311 285 306 243 264 234 314 263 292 268 275 283 257 288 262 267 268 296 240 294 281 267 280 247 247 289 305 273 281 269 268 277 280 278 298 258 304 296 285 278 278 278 262 259 275 283 290 287 263 295 244 269 235 286 260 284 279 271 262 263 299 269 270 265 273 286 267 283 246 256 277 256 284 232 263 284 236 280 231 241 298 290 246 264 264 234 230 275 269 263 269 283 268 273 257 281 272 266 257 295 244 280 238 274 278 272 271 257 260 261 269 269 291 273 255 283 262 246 306 269 278 273 257 259 249 261 258 258 277 270 260 272 274 260 244 255 267 240 274 305 269 290 281 295 292 260 257 271 266 271 261 263 274 277 267 242 285 259 250 267 255 274 268 275 246 268 241 280 261 260 229 280 270 269 229 227 263 306 234 283 246 243 283 290 256 274 271 261 290 271 284 273 231 275 272 245 288 270 255 273 265 237 277 228 286 249 283 278 264 266 238 275 256 232 231 262 217 265 244 273 241 230 278 289 284 286 267 244 274 273 273 274 265 277 223 263 243 244 247 261 249 270 237 260 272 264 230 285 241 262 263 275 305 277 246 257 273 234 255 241 305 256 265 227 291 275 293 261 299 272 279 247 263 258 294 245 289 245 264 234 243 276 273 232 265 245 256 267 247 263 266 272 233 263 277 291 219 245 233 292 271 300 249 269 265 268 264 247 260 260 270 289 229 243 274 277 277 259 218 246 262 288 245 258 273 288 300 270 267 288 221 274 249 273 255 266 289 249 261 246 259 270 241 286 261 278 265 272 235 260 267 305 283 230 244 237 270 306 248 255 269 267 234 275 244 279 243 266 260 247 260 236 249 234 243 279 276 250 284 266 263 269 249 241 226 277 270 269 243 228 267 281 285 243 259 284 246 262 231 288 281 259 264 288 234 245 261 296 278 249 244 247 277 287 265 275 246 242 285 238 271 257 284 277 275 239 233 241 255 283 272 266 269 247 263 259 262 290 290 259 276 281 242 268 256 280 281 279 242 256 256 264 248 289 299 264 261 234 245 260 263 280 264 259 281 265 269 244 259 283 258 297 268 260 233 266 245 292 267 271 262 231 263 263 270 289 271 293 245 289 226 283 262 269 265 244 262 255 283 270 243 241 234 293 296 236 255 234 277 274 256 256 236 225 286 301 262 285 248 255 274 238 259 273 247 249 257 263 279 288 278 263 245 287 264 282 264 243 244 279 288 278 230 306 272 281 279 274 272 280 244 240 301 249 266 270 255 276 232 279 284 258 248 237 242 291 270 291 261 292 269 267 264 268 267 245 270 242 270 267 259 255 281 261 278 263 237 258 233 262 238 267 246 245 236 267 255 271 274 277 243 284 269 268 280 257 241 268 245 244 278 273 271 262 280 255 287 238 233 301 242 284 268 264 269 268 267 246 249 290 284 286 278 277 294 235 277 267 270 246 258 290 271 244 243 279 293 258 260 273 258 284 264 287 262 272 267 260 281 297 271 259 280 277 277 273 274 264 275 264 245 243 275 240 298 266 316 262 273 238 257 275 275 292 261 284 267 269 244 261 262 250 301 278 255 269 261 247 238 273 269 270 285 275 265 267 276 270 247 273 269 258 249 285 247 277 275 241 293 257 302 280 264 285 257 264 261 245 271 276 272 265 275 242 266 257 249 230 278 275 268 271 281 276 243 250 227 246 244 221 276 257 272 266 282 264 274 248 279 286 266 260 269 294 233 262 258 275 268 258 289 274 265 264 245 270 240 230 274 269 256 273 233 285 278 270 273 325 250 235 231 249 261 255 256 284 255 264 265 267 314 286 304 258 271 258 256 301 267 244 277 283 267 261 266 274 267 266 270 288 283 237 247 248 272 276 283 292 265 248 303 278 282 257 275 288 283 220 243 280 274 260 281 247 247 268 267 283 222 272 284 270 241 276 298 288 235 263 302 275 265 283 270 230 247 273 292 277 262 272 242 277 284 278 294 270 233 273 247 247 232 261 292 249 267 291 276 259 299 301 294 279 282 261 268 281 294 257 262 248 280 275 286 263 242 260 286 258 273 279 276 256 241 243 276 244 261 260 274 269 227 245 266 285 255 280 277 239 279 237 281 232 279 236 282 265 297 264 280 267 244 256 260 262 287 267 264 248 226 256 283 299 210 261 261 262 263 284 283 249 264 256 275 269 279 265 282 277 259 284 276 250 256 247 260 280 269 270 262 260 243 241 268 286 267 255 255 283 258 273 263 285 230 266 285 288 195 242 238 257 270 274 266 248 258 249 295 298 241 291 299 271 282 238 222 249 232 267 279 260 265 281 277 261 281 240 287 258 263 260 270 304 259 270 265 256 287 273 255 274 269 279 265 271 261 298 257 287 274 256 228 286 257 235 286 271 236 281 257 271 289 286 272 265 261 287 270 260 273 279 244 269 276 286 278 258 272 283 261 292 236 274 245 267 293 269 278 282 277 279 275 267 263 237 284 285 258 281 238 268 276 249 282 270 311 284 282 268 277 219 286 272 230 255 236 285 264 283 275 270 267 263 274 277 256 283 260 287 242 274 255 241 249 247 239 242 288 246 286 291 241 249 283 266 276 278 277 245 266 277 272 242 282 283 272 285 297 280 265 295 280 293 292 283 247 266 232 293 268 259 268 211 211 269 238 311 279 246 290 271 275 292 267 291 243 283 275 301 278 292 235 284 275 265 262 271 257 284 295 237 278 248 267 266 279 261 272 261 280 225 279 265 249 271 244 274 265 257 279 245 287 240 264 267 268 300 259 269 261 231 274 288 256 282 265 282 276 269 288 244 263 275 271 248 279 282 245 282 258 282 264 265 275 240 262 298 293 261 264 234 299 256 278 282 256 271 242 304 271 276 290 306 248 269 232 264 258 285 268 284 255 258 249 258 271 234 247 269 259 260 263 264 257 274 267 301 275 264 233 287 234 281 237 255 256 274 276 259 239 303 294 256 318 219 270 275 240 263 243 275 292 293 264 273 279 286 272 296 279 259 292 258 292 280 303 264 242 278 264 240 275 260 262 284 259 284 268 267 232 256 242 275 265 270 283 245 269 263 242 281 244 296 263 276 261</counts>
			</dataPoints>
		</scan>
	</xrdMeasurement>
</xrdMeasurements>