File: data/XRD/XG-Luft/XG-800/W6823-1D_XG_Luft_800.xrdml
<xrdMeasurements xmlns="http://www.xrdml.com/XRDMeasurement/2.1" xmlns:xsi="http://www.w3.org/2001/XMLSchema-instance" xsi:schemaLocation="http://www.xrdml.com/XRDMeasurement/2.1 http://www.xrdml.com/XRDMeasurement/2.1/XRDMeasurement.xsd" status="Completed">
	<comment>
		<entry>Configuration=Factory configuration, Owner=User-1, Creation date=7/8/2013 4:01:53 PM</entry>
		<entry>Goniometer=PW3050/65 (Theta/2Theta); Minimum step size 2Theta:0.0001; Minimum step size Omega:0.0001</entry>
		<entry>Sample stage=MRD Cradle; Minimum step size Phi:0.01; Minimum step size Chi:0.01; Minimum step size X:0.01; Minimum step size Y:0.01; Minimum step size Z:0.001</entry>
		<entry>Diffractometer system=XPERT-PRO</entry>
		<entry>Measurement program=C:\PANalytical\Data Collector\Programs\Jorrit\2thom\_absolute_2th-om_10-130deg_PIXscan_56min.xrdmp, Identifier={15BCCF57-2807-42BD-B5B9-ECC0B3DC9284}</entry>
		<entry>Batch program=C:\PANalytical\Data Collector\Programs\SimonL\batch6x_2thom_10-130°_z9.1_x0,10,20,30_y20,40_57min - Kopie.xrdmp, Identifier={8874E540-C3F4-4307-831A-CD55F073CDCD}</entry>
	</comment>
	<sample type="To be analyzed">
		<id></id>
		<name></name>
		<preparedBy></preparedBy>
	</sample>
	<xrdMeasurement measurementType="Scan" status="Completed" sampleMode="Reflection">
		<comment>
			<entry>_absolute_2th-om_10-130deg_PIXscan_56min</entry>
			<entry>PHD Lower Level = 4.83 (keV), PHD Upper Level = 11.27 (keV)</entry>
		</comment>
		<usedWavelength intended="K-Alpha 1">
			<kAlpha1 unit="Angstrom">1.5405980</kAlpha1>
			<kAlpha2 unit="Angstrom">1.5444260</kAlpha2>
			<kBeta unit="Angstrom">1.3922500</kBeta>
			<ratioKAlpha2KAlpha1>0.5000</ratioKAlpha2KAlpha1>
		</usedWavelength>
		<incidentBeamPath>
			<radius unit="mm">320.00</radius>
			<xRayTube id="1010048" name="Empyrean Cu LFF HR (9430 033 7310x) DK442154">
				<tension unit="kV">40.0</tension>
				<current unit="mA">40.0</current>
				<anodeMaterial>Cu</anodeMaterial>
				<focus type="Line">
					<length unit="mm">12.0</length>
					<width unit="mm">0.4</width>
					<takeOffAngle unit="deg">4.2</takeOffAngle>
				</focus>
			</xRayTube>
			<xRayMirror id="27010001" name="Inc. Beam Cu W/Si (parabolic MRD)" hybrid="false">
				<crystal type="Graded" shape="Parabolic">W/Si</crystal>
				<acceptanceAngle unit="deg">0.800</acceptanceAngle>
				<length unit="mm">60.0</length>
			</xRayMirror>
			<sollerSlit id="21010002" name="Soller slits 0.04 rad.">
				<opening unit="rad">0.0400</opening>
			</sollerSlit>
			<mask id="22030007" name="Fixed mask 2 mm">
				<distanceToSample unit="mm">220.00</distanceToSample>
				<width unit="mm">2.00</width>
			</mask>
			<divergenceSlit id="22010007" name="Fixed slit 1/8°" xsi:type="fixedDivergenceSlitType">
				<distanceToSample unit="mm">220.00</distanceToSample>
				<height unit="mm">0.19</height>
			</divergenceSlit>
		</incidentBeamPath>
		<diffractedBeamPath>
			<radius unit="mm">320.00</radius>
			<sollerSlit id="21010002" name="Soller slits 0.04 rad.">
				<opening unit="rad">0.0400</opening>
			</sollerSlit>
			<receivingSlit id="22010001" name="Fixed slit 4°">
				<height unit="mm">5.88</height>
			</receivingSlit>
			<detector id="7010017" name="PIXcel3D 1x1 detector" xsi:type="areaDetectorType">
				<phd unit="%">
					<lowerLevel>30.0</lowerLevel>
					<upperLevel>70.0</upperLevel>
				</phd>
				<mode>Scanning</mode>
				<activeChannelsEquatorial>255</activeChannelsEquatorial>
				<activeChannelsAxial>255</activeChannelsAxial>
				<pitchEquatorial unit="mm">0.05500</pitchEquatorial>
				<pitchAxial unit="mm">0.05500</pitchAxial>
				<readOutPeriod unit="seconds">0.135</readOutPeriod>
			</detector>
		</diffractedBeamPath>
		<scan appendNumber="0" mode="Continuous" scanAxis="2Theta-Omega" status="Completed">
			<header>
				<startTimeStamp>2024-10-28T22:56:00+01:00</startTimeStamp>
				<endTimeStamp>2024-10-28T23:52:06+01:00</endTimeStamp>
				<author>
					<name>PRO-MRD</name>
				</author>
				<source>
					<applicationSoftware version="6.1b">Data Collector</applicationSoftware>
					<instrumentControlSoftware version="7.0E 20130304">XPERT-PRO</instrumentControlSoftware>
					<instrumentID>0000000011142674</instrumentID>
				</source>
			</header>
			<dataPoints>
				<positions axis="2Theta" unit="deg">
					<startPosition>9.99826193</startPosition>
					<endPosition>129.99755682</endPosition>
				</positions>
				<positions axis="Omega" unit="deg">
					<startPosition>4.99913096</startPosition>
					<endPosition>64.99877841</endPosition>
				</positions>
				<positions axis="Phi" unit="deg">
					<commonPosition>0.00</commonPosition>
				</positions>
				<positions axis="Chi" unit="deg">
					<commonPosition>0.00</commonPosition>
				</positions>
				<positions axis="X" unit="mm">
					<commonPosition>20.00</commonPosition>
				</positions>
				<positions axis="Y" unit="mm">
					<commonPosition>0.00</commonPosition>
				</positions>
				<positions axis="Z" unit="mm">
					<commonPosition>9.100</commonPosition>
				</positions>
				<commonCountingTime unit="seconds">32.895</commonCountingTime>
				<counts 390 366 393 376 401 376 384 387 362 393 412 418 387 401 402 387 382 388 401 371 383 412 398 373 361 372 414 394 403 402 357 384 385 371 403 375 405 382 400 442 431 406 393 403 398 382 386 423 418 383 413 414 382 408 411 412 419 388 367 422 404 385 410 412 344 362 364 377 394 376 421 372 368 428 415 364 395 367 374 379 405 395 387 385 366 393 361 370 391 359 350 380 357 375 388 381 392 387 367 398 372 349 398 378 361 356 372 371 359 357 342 361 379 361 357 367 354 366 363 361 380 389 392 326 399 354 391 383 358 374 352 368 397 395 364 334 374 383 373 353 331 383 390 347 367 369 354 343 383 356 348 345 369 368 339 325 360 384 381 359 380 331 387 335 375 335 378 380 361 359 373 347 330 347 345 382 361 366 349 371 382 359 376 347 377 365 343 349 364 377 388 378 361 365 335 352 321 367 362 347 347 326 339 345 355 351 348 321 350 337 379 330 343 343 337 374 370 341 385 353 342 326 352 347 366 364 347 331 396 329 343 367 317 364 363 393 386 392 347 342 351 349 323 318 332 342 365 318 372 360 348 377 349 345 363 346 347 368 351 333 339 375 338 351 344 284 336 360 378 349 345 340 351 342 359 382 360 337 333 315 357 356 372 296 379 342 332 328 367 342 298 337 342 354 370 337 352 329 376 345 357 342 340 333 359 339 326 353 362 315 358 338 333 317 304 330 343 350 312 326 343 327 372 348 326 339 324 320 334 343 320 340 323 346 314 315 343 328 317 335 327 321 333 362 281 290 361 336 335 350 369 322 323 321 311 323 322 334 309 348 325 318 346 327 283 302 306 324 328 308 321 321 295 332 320 336 319 358 319 314 300 323 318 333 322 326 331 330 327 313 323 324 319 331 329 295 361 295 313 348 323 307 331 291 292 315 312 306 296 312 308 330 339 327 318 342 320 313 353 319 312 326 297 334 325 323 309 286 337 321 282 310 305 343 334 314 324 305 340 312 298 303 295 315 292 296 297 338 287 303 280 289 331 331 324 319 293 300 304 328 292 291 310 314 311 312 323 293 322 282 333 303 345 296 304 298 331 351 308 334 308 300 324 313 313 338 314 351 303 330 336 322 291 273 308 283 288 295 291 366 281 334 297 305 291 318 289 298 298 278 301 286 297 305 340 307 320 298 300 299 320 317 312 318 315 289 281 283 306 302 261 292 316 289 331 345 287 297 300 299 343 319 305 320 305 300 299 308 273 280 324 326 286 297 299 286 270 320 308 300 314 293 305 305 318 269 282 270 320 312 307 307 281 297 289 302 321 302 324 286 279 285 293 328 332 288 314 297 324 292 263 292 304 308 283 285 290 279 291 315 275 297 310 338 313 299 289 287 305 311 303 330 289 287 288 293 311 244 318 297 267 288 291 258 262 270 310 343 307 303 297 277 310 269 306 292 288 288 275 298 292 257 298 322 284 284 285 329 299 278 282 300 318 300 298 300 299 241 267 310 305 288 289 287 283 300 266 300 292 303 284 304 294 303 308 275 306 304 260 299 259 308 294 287 301 278 320 275 289 295 306 307 312 275 261 281 278 306 288 297 307 288 275 278 299 293 323 306 323 282 267 290 279 300 299 314 311 271 301 295 280 301 306 314 299 296 315 291 247 323 268 323 277 273 312 296 269 270 260 336 332 289 283 297 282 293 314 285 309 259 314 283 284 291 268 295 323 280 282 283 250 313 295 288 261 299 285 313 277 326 322 302 293 311 302 304 260 264 283 295 295 255 303 314 292 295 317 322 294 298 315 288 297 324 290 237 295 320 314 288 269 301 293 315 302 295 284 312 301 287 293 277 277 288 314 278 292 283 293 294 289 315 283 286 294 309 293 310 313 302 281 275 278 288 278 286 284 288 272 283 296 278 278 290 303 291 292 306 313 280 292 289 294 295 308 276 278 293 283 286 310 292 295 311 296 305 290 294 299 289 301 277 315 311 297 296 340 281 311 289 279 285 262 286 301 288 304 299 285 300 283 333 303 304 299 310 281 308 309 271 303 299 278 310 285 300 277 291 312 295 279 290 318 305 309 313 263 325 272 267 325 333 292 304 278 283 261 332 301 280 306 298 301 314 278 287 292 328 292 295 312 324 304 304 286 301 285 291 285 290 323 291 301 293 324 272 342 303 278 269 293 300 271 290 309 297 308 280 314 307 299 283 271 304 273 351 307 303 283 269 290 280 303 303 312 266 314 294 290 313 296 304 295 294 286 298 332 287 302 281 318 309 302 324 297 298 283 283 322 327 303 292 323 297 308 297 307 296 294 320 330 325 297 314 281 292 301 320 280 300 308 303 302 328 293 301 312 313 274 304 289 294 300 292 307 312 303 315 309 299 324 300 318 297 293 283 303 301 261 297 310 317 297 310 308 294 302 287 306 316 292 306 307 290 293 320 320 297 321 321 291 300 287 336 294 314 315 322 282 292 300 310 281 281 302 329 336 297 275 271 280 310 309 323 312 304 301 294 278 330 317 321 332 323 286 307 296 294 311 280 312 319 309 281 311 313 296 329 300 275 301 296 312 268 373 307 281 309 313 279 309 313 305 286 320 357 339 322 274 289 344 303 303 297 308 341 304 274 283 316 302 323 295 309 317 328 311 329 293 310 313 279 304 323 314 305 337 317 344 297 319 325 303 301 293 309 324 297 311 292 326 330 319 309 302 318 338 319 319 327 318 334 286 300 294 304 301 305 306 330 295 289 282 289 339 301 276 294 285 275 295 335 313 326 292 322 337 277 292 285 320 310 295 283 303 301 301 294 285 305 307 284 283 307 299 345 299 290 297 266 294 345 306 304 280 302 329 305 259 317 322 324 283 292 346 332 303 298 333 303 313 330 301 295 336 319 330 269 315 312 279 297 271 266 301 319 279 314 312 296 320 258 302 308 280 272 298 287 292 311 301 306 311 289 282 298 342 300 328 302 295 325 312 322 309 291 325 329 336 314 317 297 320 297 299 313 286 317 290 270 299 320 315 296 283 334 260 284 320 283 281 278 314 296 298 299 279 316 310 289 287 300 324 310 309 284 304 301 284 308 313 290 331 295 279 301 286 328 318 312 298 305 290 301 285 314 314 317 295 308 304 285 295 286 301 308 296 271 274 304 321 289 284 290 305 287 278 278 266 279 307 297 300 289 349 287 290 283 295 289 290 300 276 281 299 309 294 300 307 331 302 268 277 303 295 313 266 262 257 294 275 300 304 293 278 306 283 270 276 289 287 282 276 299 316 285 292 299 271 284 297 298 289 241 270 271 298 283 298 278 287 304 289 279 310 309 287 281 272 285 282 286 315 308 284 290 300 274 311 273 296 247 279 273 314 292 297 264 285 296 285 275 286 276 262 295 268 278 304 285 269 257 265 263 285 294 273 276 282 285 272 241 256 275 299 292 306 247 256 280 276 279 290 287 250 278 298 276 299 269 292 286 288 312 276 240 273 270 287 281 274 289 265 274 273 260 275 261 256 300 267 300 297 246 283 315 236 230 305 250 240 297 279 282 278 278 263 259 314 278 271 273 262 269 275 270 276 272 272 265 307 281 275 320 288 262 284 255 264 258 263 293 289 244 269 308 250 268 260 267 279 256 244 267 249 269 243 292 279 266 289 288 271 293 279 267 268 265 273 277 274 308 249 277 257 287 245 262 255 263 261 284 269 267 294 244 272 271 263 263 273 265 245 279 278 246 246 266 244 269 242 223 240 222 242 273 256 292 225 280 263 229 258 280 248 269 270 270 255 241 282 246 270 271 245 239 246 229 275 264 264 259 269 260 259 244 256 262 255 231 245 276 249 273 275 258 245 236 250 241 261 215 293 262 279 273 242 257 269 286 255 256 247 271 230 267 247 240 257 265 269 275 261 266 259 273 234 215 264 238 297 228 245 233 236 231 262 274 232 261 248 262 261 233 238 262 262 239 257 246 258 255 264 233 248 281 243 239 243 218 239 233 221 225 255 240 260 233 256 266 239 268 260 238 262 225 262 238 246 222 237 265 243 228 232 232 259 245 227 223 259 276 257 259 219 216 245 230 275 234 278 258 245 260 234 250 235 248 207 230 230 230 223 240 262 269 261 245 226 222 231 248 236 235 232 223 245 222 256 265 247 244 263 246 238 215 221 230 239 219 225 233 246 256 223 235 277 235 240 270 241 214 228 259 232 238 212 256 216 285 257 222 217 210 219 228 229 218 231 235 228 230 281 233 217 222 232 229 217 228 232 243 228 224 225 235 222 228 212 255 249 229 231 232 233 224 245 276 249 257 233 217 225 215 246 220 229 226 219 238 255 261 260 223 232 244 223 223 220 235 217 223 233 229 257 215 218 223 249 240 225 224 221 221 229 236 239 243 229 230 227 233 199 225 234 241 204 230 217 214 257 190 222 236 222 245 199 240 209 240 234 211 222 236 227 235 216 213 213 247 205 257 226 244 227 210 239 246 221 235 224 256 201 213 211 231 212 230 229 273 217 232 237 232 203 259 221 222 207 224 196 209 230 219 221 225 224 206 237 216 219 212 222 228 240 229 214 231 235 217 214 194 213 208 229 233 234 211 240 236 203 209 231 234 222 227 189 243 229 220 247 193 242 216 226 200 197 232 209 220 193 204 220 262 228 245 226 258 238 226 214 214 225 237 219 210 226 201 213 207 184 216 215 244 201 217 215 193 221 213 217 225 217 203 226 196 210 229 226 220 226 202 200 188 206 212 209 221 245 231 194 237 212 205 200 192 182 228 230 218 210 217 198 211 221 223 223 226 223 214 216 214 196 223 223 205 227 204 237 224 206 205 232 194 189 227 211 193 205 208 223 215 204 230 214 202 239 198 210 212 216 203 216 178 195 190 211 218 240 196 218 203 195 209 216 224 224 195 202 209 245 215 227 222 220 227 204 196 222 216 197 205 214 214 249 189 218 219 216 225 192 224 194 204 210 228 200 198 206 212 217 197 213 226 218 226 207 195 194 221 218 206 206 207 249 190 215 210 217 210 203 209 196 242 205 192 205 226 222 207 224 234 184 197 196 214 217 203 220 207 204 195 224 224 191 211 190 201 216 236 216 220 181 210 193 227 207 209 201 221 200 204 220 205 192 214 206 189 223 189 194 171 196 214 208 196 226 240 199 171 198 195 217 192 220 194 211 185 180 188 247 178 178 222 180 204 192 204 220 186 197 199 213 180 200 200 201 183 228 199 218 203 222 213 194 218 199 194 190 225 210 215 207 209 217 204 216 213 196 179 205 213 195 186 224 202 194 188 225 228 190 216 224 215 221 222 208 196 215 205 185 214 195 217 181 223 196 207 203 219 189 183 190 200 212 214 246 188 163 219 200 213 214 204 195 202 201 182 195 205 209 236 199 206 197 200 205 225 197 185 198 223 210 219 199 199 214 224 183 228 199 197 215 199 188 205 210 203 208 192 214 221 212 211 210 205 214 225 200 186 211 214 202 185 186 189 215 201 196 200 209 212 196 184 214 199 206 214 194 204 187 198 179 217 214 199 178 202 177 166 185 199 219 186 173 204 212 203 185 209 201 188 204 194 199 178 194 201 181 202 211 204 198 196 186 244 221 229 193 192 209 203 214 203 201 186 210 206 213 181 215 169 207 204 215 198 175 196 192 184 181 191 190 202 219 198 193 210 194 187 205 187 200 190 242 189 186 189 199 213 191 199 207 192 204 216 200 187 211 210 206 203 183 174 202 208 206 227 186 181 196 207 216 207 194 176 185 204 189 181 172 190 188 192 190 200 195 178 191 180 214 204 208 186 181 225 204 191 195 193 178 204 201 204 208 200 226 190 197 197 196 190 197 168 198 217 208 200 200 188 215 207 228 207 176 198 202 198 200 193 210 206 215 208 199 208 203 192 204 183 188 207 170 222 196 173 191 203 204 219 184 195 190 207 204 192 191 200 196 197 203 192 197 216 198 196 183 205 206 186 196 202 204 191 169 175 176 190 201 206 208 217 218 196 185 199 214 197 194 204 219 200 181 215 209 194 219 163 182 204 194 200 217 195 176 210 219 187 200 185 213 189 196 201 189 216 197 204 184 208 224 202 217 216 190 186 199 210 181 202 207 190 181 211 203 226 205 197 211 215 210 196 195 205 181 203 206 223 221 200 207 193 196 196 212 202 187 219 201 170 192 221 189 212 202 223 169 180 216 214 218 210 190 184 201 211 192 207 206 210 185 186 207 196 186 183 183 205 182 189 227 213 200 207 196 186 187 208 192 185 199 178 188 180 166 210 195 216 193 200 201 185 196 198 191 184 185 206 203 208 191 185 197 193 204 207 227 181 209 200 202 178 212 197 208 197 211 235 195 207 189 179 205 219 185 187 193 215 189 171 208 197 194 202 208 222 193 217 218 198 196 201 196 191 180 194 214 206 193 226 211 198 202 195 189 208 209 207 204 216 195 212 207 186 199 208 211 193 201 202 177 197 218 199 189 206 206 203 183 210 216 185 187 197 216 188 195 199 173 183 181 199 183 201 203 225 213 184 192 213 194 215 178 205 211 223 174 209 217 222 206 195 202 200 212 186 200 224 206 205 209 201 170 206 173 192 206 201 192 213 195 191 194 210 203 183 207 205 182 179 180 183 202 177 217 196 204 221 172 188 172 179 206 214 209 201 192 224 190 193 173 194 187 229 212 196 194 205 198 202 177 189 198 171 185 217 190 180 198 169 178 183 198 212 181 202 215 199 195 203 190 201 216 213 233 172 228 206 177 205 221 207 207 203 184 224 185 192 194 188 188 190 181 205 209 190 220 181 194 211 194 184 215 200 182 208 196 203 196 190 216 226 199 216 188 193 193 189 207 198 217 228 205 192 195 193 189 187 192 211 185 209 195 200 180 239 211 211 180 200 212 209 211 178 203 199 170 179 176 177 187 192 200 194 181 184 185 183 204 234 184 192 187 202 175 175 196 205 227 194 196 206 186 186 207 201 208 185 213 169 189 216 185 209 197 232 205 211 216 179 194 201 196 207 208 225 200 195 182 209 212 202 184 194 175 242 193 181 215 179 230 182 207 199 198 207 180 195 181 193 242 214 197 195 187 187 216 214 194 175 199 212 223 199 185 212 209 214 167 190 179 210 207 223 209 205 222 185 208 228 194 174 202 198 194 189 186 192 193 184 189 196 228 199 209 238 199 201 170 228 207 195 203 178 234 221 191 195 210 203 212 202 220 208 193 217 214 216 192 195 186 210 221 177 196 205 170 223 212 218 210 194 191 218 200 199 217 204 198 190 205 178 194 197 203 175 210 204 223 225 222 203 197 192 209 240 186 197 200 229 217 216 195 194 214 216 203 198 214 205 210 171 176 205 226 213 206 216 201 176 187 204 242 226 205 184 195 187 207 187 198 201 185 199 202 201 216 215 206 190 206 209 209 223 184 215 204 244 203 190 176 219 192 188 202 198 215 201 210 239 223 227 198 200 222 231 219 226 210 194 211 219 231 182 201 185 205 217 227 231 190 208 194 226 204 203 205 208 194 226 245 194 231 199 219 207 205 225 218 217 232 224 195 215 231 219 204 233 208 220 226 222 259 203 217 213 228 235 237 217 201 232 240 228 208 212 216 243 228 237 229 218 195 208 221 228 223 202 208 237 194 196 188 223 229 225 210 219 200 262 207 203 231 207 214 206 207 231 203 247 220 218 228 208 247 219 233 217 242 216 205 214 242 201 216 267 243 211 214 226 260 229 221 237 193 244 232 263 242 230 229 234 230 231 270 236 215 227 225 215 268 221 287 242 248 230 256 275 244 228 239 249 240 242 241 249 241 247 288 234 263 301 275 280 265 273 275 284 278 281 307 305 311 312 321 356 338 356 358 369 383 355 401 339 342 384 361 370 393 359 388 351 380 358 366 352 354 363 303 308 323 301 312 286 304 285 296 270 290 261 275 232 264 260 261 220 265 232 271 235 269 267 227 218 265 241 218 223 196 234 208 263 197 225 248 197 233 215 234 228 207 240 213 226 226 245 224 208 223 213 200 238 234 225 220 220 236 217 223 224 228 205 285 203 226 215 214 218 213 219 219 213 214 189 203 225 219 227 225 198 196 200 197 226 206 240 207 217 219 210 217 234 212 213 230 223 184 212 207 217 217 203 233 218 228 202 229 192 214 205 221 218 211 198 218 204 207 232 194 249 207 223 223 229 211 185 223 213 223 210 208 221 245 230 223 206 209 221 206 230 201 209 213 229 239 234 189 194 193 194 191 226 217 218 226 192 208 210 216 226 189 231 213 190 207 231 186 221 212 204 199 199 204 226 212 211 195 216 195 220 197 219 228 208 206 231 214 197 180 199 210 203 208 242 198 187 223 206 221 195 192 180 199 230 202 233 215 217 181 216 208 219 203 208 225 201 197 195 209 209 207 217 224 168 197 219 219 204 211 187 199 223 193 207 241 223 219 188 229 221 210 232 210 239 230 208 219 210 212 210 206 204 215 198 214 185 230 202 218 187 186 231 203 196 201 198 208 218 217 202 204 222 230 209 198 203 219 210 219 195 224 219 200 183 189 241 238 194 184 214 218 209 211 180 206 207 192 199 202 208 200 200 196 232 234 218 187 174 222 208 204 213 210 187 178 189 205 213 200 216 213 211 223 212 217 217 208 201 204 235 202 226 250 192 193 216 215 220 207 210 198 206 206 199 231 221 214 207 206 212 181 190 191 194 212 208 223 196 197 203 209 212 192 196 212 170 196 198 189 177 210 212 208 209 199 193 217 197 195 189 216 216 193 195 186 200 190 190 165 208 205 210 182 224 180 222 194 218 222 197 223 194 204 191 193 218 213 223 184 181 216 239 201 196 192 218 198 196 184 198 203 222 213 202 215 180 206 195 201 222 212 211 202 199 207 192 187 174 228 218 200 181 199 172 212 221 191 221 202 186 226 217 181 197 204 221 211 199 203 184 197 203 194 190 200 209 204 200 201 197 204 221 242 204 193 199 218 181 198 217 190 215 192 223 204 213 195 214 193 190 200 232 242 179 219 206 217 206 202 239 197 213 205 187 195 195 192 221 210 206 232 180 213 228 182 202 208 216 184 202 209 210 205 217 195 208 200 221 219 221 211 205 189 186 205 196 187 220 208 194 231 202 189 199 215 199 200 187 176 215 216 219 193 217 200 204 226 212 208 232 211 200 207 193 201 205 226 191 191 214 201 208 204 241 175 225 201 187 233 210 185 208 209 197 190 220 207 241 223 195 224 205 216 220 202 199 200 205 214 223 192 214 198 208 208 228 212 196 205 205 207 172 211 223 247 213 226 186 190 221 227 193 189 218 222 201 206 205 197 231 227 194 219 198 220 231 218 190 207 212 201 190 204 186 203 203 195 210 212 205 199 236 209 188 208 178 206 224 194 195 224 183 216 216 206 166 243 215 217 187 212 219 212 182 220 211 187 236 218 216 207 194 206 172 237 194 193 191 181 205 191 207 205 202 196 216 203 202 224 199 238 164 221 196 213 215 207 211 208 204 183 204 228 226 197 205 174 210 200 194 171 236 255 234 215 197 195 207 191 206 220 200 210 222 201 206 233 191 209 218 199 177 207 218 236 204 238 204 206 223 193 215 197 205 210 203 217 214 187 187 218 219 203 223 208 211 211 209 184 219 214 202 209 224 209 199 220 199 210 202 179 201 212 187 213 201 187 200 191 213 240 205 232 186 219 182 213 185 189 214 209 223 191 207 216 230 222 213 168 204 225 197 223 206 199 189 205 201 211 201 194 198 177 218 207 206 207 196 203 200 197 187 196 220 205 188 213 211 201 204 203 206 216 220 213 214 219 197 190 201 192 204 192 199 223 208 206 193 183 184 236 225 205 171 213 215 232 205 169 207 204 185 207 210 208 196 220 205 250 228 204 208 212 208 214 192 208 199 213 222 184 201 217 200 203 194 221 236 217 199 181 208 211 222 196 206 203 207 209 209 206 200 218 226 199 180 190 205 207 226 199 200 210 196 198 224 218 217 216 202 200 229 193 207 221 191 210 207 208 195 202 196 184 211 202 200 198 214 198 196 212 216 224 212 189 219 204 220 219 196 203 218 229 234 184 194 221 217 205 187 193 190 231 185 174 208 223 225 211 186 212 234 201 204 223 206 184 216 220 238 202 189 208 203 234 223 225 217 197 217 225 217 216 223 218 224 214 213 217 210 178 209 210 216 217 217 200 209 219 215 217 196 207 203 200 216 191 197 180 207 201 198 197 230 219 223 205 216 227 202 214 183 223 209 224 190 228 188 206 229 230 226 202 211 216 225 187 214 213 200 226 211 226 185 208 180 193 190 193 179 190 228 194 202 213 210 209 202 197 207 197 223 188 198 215 189 201 225 228 206 218 194 184 215 203 210 204 202 191 207 200 196 225 233 215 221 189 207 228 194 242 224 221 242 199 205 217 208 217 203 211 204 206 245 200 226 203 224 201 203 195 204 207 203 193 219 196 200 179 194 228 214 218 217 214 204 214 210 195 218 209 227 222 207 220 205 227 205 217 200 203 192 217 220 225 203 177 223 216 222 209 221 210 234 226 211 224 220 205 209 225 201 183 213 218 230 200 219 219 203 216 218 231 201 203 240 225 212 177 217 196 212 211 213 183 214 217 195 180 195 215 198 202 203 230 197 209 208 207 213 200 211 215 214 218 227 216 192 201 210 227 211 227 195 206 208 196 192 236 235 210 181 212 194 236 185 226 208 204 225 217 188 214 228 211 211 202 204 198 186 210 226 208 199 227 186 211 210 219 179 222 221 179 188 204 228 222 200 216 243 212 217 195 218 201 214 225 239 218 234 207 218 205 205 221 192 223 217 202 199 216 194 202 216 207 199 226 211 213 234 198 206 197 221 189 198 208 241 233 207 211 180 204 215 212 208 215 183 237 231 201 180 189 214 211 210 224 206 195 186 220 210 243 226 234 195 209 247 218 233 237 232 216 197 206 189 224 229 196 229 198 233 205 225 218 214 206 187 220 182 217 211 257 208 217 244 225 202 216 184 226 227 199 207 192 204 237 213 210 212 236 217 202 187 209 206 228 210 240 230 213 229 207 249 209 191 230 235 217 205 193 211 259 200 200 206 221 206 207 208 210 196 195 189 238 217 196 205 202 213 210 210 217 192 230 228 227 227 246 216 211 218 208 213 222 184 225 209 214 212 197 205 255 216 216 227 221 213 208 206 184 229 211 216 232 205 259 195 217 199 222 213 227 185 221 219 201 200 219 197 224 225 225 215 200 209 247 209 235 207 229 223 223 234 216 211 225 220 231 219 212 204 218 207 205 223 205 188 210 226 217 222 226 220 217 216 214 215 233 210 256 237 222 205 217 221 222 222 237 222 225 201 222 189 222 208 216 204 210 202 203 229 234 217 238 238 227 201 206 239 232 232 231 229 217 234 182 189 233 240 172 209 225 205 208 234 197 239 199 203 188 209 225 236 205 203 216 225 187 230 218 188 221 207 201 209 211 226 200 220 208 230 211 197 187 231 230 215 218 223 220 214 221 221 221 203 214 214 213 225 210 216 211 228 206 213 214 207 218 210 212 202 211 215 202 229 245 205 235 213 219 232 193 219 202 222 238 216 202 241 213 200 207 215 229 248 232 228 211 218 201 203 219 218 235 221 206 246 196 219 201 195 228 208 204 195 198 243 213 218 216 204 223 198 194 209 260 213 215 228 207 212 187 213 219 195 217 224 199 205 206 212 215 222 210 220 221 222 250 197 201 222 220 229 210 192 220 234 203 233 247 208 213 207 204 239 203 235 216 211 228 230 218 199 202 233 231 235 184 239 208 204 207 223 248 212 239 210 181 208 235 192 203 233 239 249 211 228 209 230 198 193 211 232 208 215 213 207 207 188 209 222 232 224 225 229 233 198 208 211 223 201 226 223 227 204 241 215 222 199 225 210 220 226 244 216 228 209 220 222 211 217 227 203 207 193 233 217 203 226 243 199 212 223 211 226 238 215 215 223 225 209 225 215 256 195 222 216 197 244 226 207 206 211 205 214 226 208 236 271 236 236 232 233 223 211 214 219 229 231 220 207 243 215 218 232 223 229 240 227 222 201 186 211 199 210 245 198 240 190 219 201 226 220 202 205 201 246 225 225 233 230 203 236 216 209 222 198 211 194 219 236 217 213 217 230 199 222 239 227 217 211 217 217 255 232 222 242 213 210 204 216 211 194 235 222 219 214 231 216 202 214 221 227 232 193 229 236 198 241 228 207 220 215 218 200 217 216 215 215 223 206 213 226 202 198 260 196 217 214 200 205 215 196 234 228 210 242 226 243 234 185 223 199 223 210 199 240 229 215 202 236 220 227 206 215 217 199 222 178 219 236 248 220 231 208 255 221 233 225 245 216 234 240 222 210 257 230 221 211 198 217 221 242 241 232 224 237 203 219 217 211 213 224 228 245 227 228 218 195 236 221 198 255 224 234 225 222 257 208 246 249 195 241 220 219 230 218 230 232 214 258 286 222 220 228 236 273 237 219 239 241 232 248 218 223 257 266 226 216 239 234 222 229 229 230 260 207 233 222 245 241 245 229 263 260 213 245 216 256 228 213 241 227 244 223 220 224 234 226 234 211 231 220 240 225 229 229 209 224 243 185 220 209 249 220 206 214 220 249 225 229 240 230 232 250 240 228 225 234 223 225 195 261 236 242 235 215 233 233 265 236 211 236 238 238 230 236 222 231 226 221 218 214 200 258 223 247 236 240 249 196 236 243 224 220 204 225 238 240 226 232 205 229 208 221 212 222 229 226 208 234 232 216 221 238 230 212 237 207 207 222 220 230 200 209 230 224 219 219 215 227 214 230 210 226 208 224 231 236 225 224 246 219 217 255 223 226 213 194 201 212 201 235 268 220 217 234 220 236 236 222 223 221 214 210 209 220 234 202 224 224 213 214 200 236 243 231 215 214 237 212 236 216 196 257 223 224 198 258 220 231 189 229 214 230 188 211 202 214 208 220 237 245 236 238 221 216 243 210 213 237 216 204 212 244 203 236 241 207 223 217 231 217 191 217 219 223 240 233 243 243 227 201 222 230 230 201 202 221 199 238 210 227 225 223 239 222 257 235 224 222 235 227 212 211 226 231 225 237 216 222 196 213 230 231 245 237 231 187 215 221 241 196 232 212 230 219 214 234 238 212 206 231 218 235 224 220 220 209 224 203 227 207 226 213 234 211 241 210 222 216 227 233 238 222 238 211 227 230 257 220 232 219 210 228 227 236 212 205 208 220 203 221 229 201 206 222 224 215 229 210 218 217 218 213 186 202 228 198 205 212 211 210 214 239 244 234 243 208 208 236 210 214 208 166 236 249 198 211 224 214 236 225 229 236 233 225 261 211 231 240 237 218 224 209 231 232 214 234 202 218 255 262 203 225 249 232 244 247 236 223 223 211 213 220 255 255 219 217 211 207 210 224 223 223 225 218 232 223 199 201 208 237 227 244 224 215 214 204 257 218 221 228 192 227 218 225 216 235 233 239 217 234 221 207 227 255 214 241 203 231 218 243 208 214 221 230 223 222 215 232 231 207 238 221 221 211 221 227 225 212 195 204 242 255 211 205 216 259 226 216 241 222 229 210 201 232 225 225 182 226 187 244 216 224 238 236 198 249 215 205 206 213 222 228 220 218 220 230 222 223 226 227 232 203 247 245 225 235 214 239 206 209 232 196 213 235 210 227 235 249 205 225 210 224 212 226 243 232 220 212 218 211 231 223 218 228 196 219 239 192 257 259 226 214 209 239 230 229 236 199 213 232 236 215 219 230 221 240 228 210 209 221 213 211 223 214 216 223 203 212 219 203 219 248 216 219 209 248 228 232 225 256 232 196 270 223 206 240 242 207 209 223 243 245 200 264 221 236 227 238 241 243 240 219 237 231 218 205 225 235 229 243 232 226 219 229 224 226 234 217 214 218 243 231 228 205 220 208 229 225 218 216 224 224 241 214 240 218 240 204 210 229 217 222 208 229 220 231 259 207 237 255 232 211 215 226 207 229 245 232 235 222 207 227 225 202 229 233 233 221 224 234 230 226 231 235 217 221 223 276 215 266 242 234 255 196 202 246 233 256 229 226 236 236 214 222 236 209 218 273 236 236 212 245 239 207 249 196 221 241 220 198 213 206 205 224 210 212 231 264 202 238 216 203 234 215 246 209 234 216 216 235 249 231 222 258 218 215 220 191 237 210 206 212 196 193 238 215 212 228 217 208 235 224 222 222 240 230 200 239 234 238 232 206 235 208 225 226 231 222 204 218 229 211 205 230 241 220 236 203 232 217 224 225 225 237 239 227 230 224 228 262 223 228 208 208 232 226 244 207 200 243 208 202 203 226 208 208 228 226 234 257 202 209 228 245 203 218 213 211 196 225 218 259 215 226 245 281 250 241 218 203 226 227 242 240 210 228 224 211 231 220 215 242 255 215 221 242 222 212 196 224 216 206 194 256 209 215 196 223 218 214 243 225 226 240 230 215 237 210 237 236 210 248 238 237 215 236 268 249 233 206 237 267 219 221 243 225 206 240 244 213 218 232 234 231 209 203 235 216 215 232 203 224 259 255 229 235 240 223 247 217 208 225 220 219 214 263 202 218 227 249 231 224 233 208 231 243 215 232 213 222 230 208 235 235 223 232 234 264 197 223 233 215 234 224 216 258 212 223 249 226 227 230 222 225 206 263 231 225 228 234 198 204 245 235 224 212 255 222 230 222 221 229 247 235 201 238 215 227 236 238 264 226 209 208 236 211 223 217 231 219 247 229 231 236 224 235 209 240 259 213 194 217 211 244 239 225 248 210 257 227 232 246 224 224 209 202 208 229 208 210 217 208 226 233 214 218 228 229 240 242 220 217 207 233 194 191 221 233 210 206 218 262 235 215 201 259 213 207 210 245 231 212 195 227 203 237 201 256 208 232 203 220 230 255 226 240 276 212 234 217 200 223 237 225 215 201 219 229 244 223 248 237 215 227 224 214 226 232 194 231 221 226 240 240 230 234 222 224 219 244 224 215 208 233 184 214 197 260 223 257 215 231 227 230 207 240 211 231 235 217 215 264 215 195 222 223 223 223 205 250 208 237 217 208 226 215 209 211 233 217 215 222 228 230 213 225 233 228 210 231 229 225 180 201 246 221 239 232 234 232 246 245 225 241 219 211 195 206 231 208 221 255 246 223 205 233 236 219 208 234 218 221 234 206 208 210 228 226 191 223 203 189 195 220 198 221 195 241 215 216 249 232 208 194 232 183 226 230 233 245 223 219 226 207 224 256 225 225 221 214 204 215 218 238 241 230 238 212 234 215 195 208 232 199 209 226 203 208 217 213 243 205 217 215 205 221 200 216 203 238 218 216 214 242 204 204 221 193 237 209 218 213 198 203 190 218 236 208 276 198 228 208 241 229 225 204 217 208 199 247 230 217 243 224 216 218 228 225 223 219 218 201 212 236 219 218 247 222 194 203 222 242 237 221 206 217 232 206 224 236 204 231 229 222 246 256 210 234 209 255 236 199 219 219 200 199 203 214 214 234 221 224 220 225 218 223 229 205 229 225 226 230 223 239 223 232 222 235 206 231 232 225 208 244 212 212 227 207 209 198 229 213 224 216 206 235 214 215 220 202 221 211 210 228 193 211 200 213 203 215 209 232 213 230 233 215 203 210 206 228 243 231 239 216 255 197 228 212 216 202 206 216 211 217 233 219 212 205 219 232 220 200 218 231 209 210 228 202 206 210 204 189 231 215 219 209 228 226 222 204 229 198 206 218 223 209 193 256 241 241 238 205 208 202 215 218 226 246 223 199 225 228 244 237 226 235 224 218 221 205 215 214 227 202 210 190 210 224 209 217 211 235 235 207 232 209 241 199 237 204 218 238 221 228 202 196 220 235 223 206 191 240 230 215 219 206 230 231 226 216 224 197 187 229 199 224 228 221 238 215 227 226 199 211 203 222 207 228 189 216 219 235 216 218 238 245 215 193 201 218 215 221 225 229 220 215 207 216 225 247 224 216 203 221 205 233 230 231 232 226 234 213 245 226 219 199 216 213 196 239 212 225 217 223 201 213 217 202 238 204 199 210 218 203 221 206 242 216 213 202 204 220 223 225 228 197 229 188 199 227 221 220 210 227 213 261 228 219 241 209 207 218 219 225 228 209 217 227 203 205 219 223 228 206 217 222 229 226 209 213 236 187 187 215 230 228 213 191 202 227 211 209 179 215 239 213 208 232 228 201 210 215 219 218 225 225 227 231 208 220 220 221 209 196 200 226 249 226 248 202 214 232 210 217 201 191 262 216 189 206 219 209 214 213 233 209 232 231 225 229 238 218 215 211 235 235 223 216 214 238 208 211 221 224 261 250 218 226 217 231 199 204 202 210 210 221 229 244 256 243 217 241 233 260 201 216 234 212 225 225 226 242 237 244 210 221 232 239 206 223 247 206 243 266 258 227 218 243 243 240 274 243 248 240 241 216 258 239 239 243 261 222 199 234 236 290 265 269 280 259 249 258 267 237 266 257 234 246 255 246 240 234 268 240 245 247 236 240 262 256 235 224 249 267 232 230 247 240 267 257 276 270 233 228 281 248 243 250 278 207 234 220 204 229 242 205 222 219 235 225 228 221 225 215 233 238 227 232 208 230 240 243 192 189 201 215 224 220 209 212 223 233 225 232 205 202 226 213 219 222 218 217 249 225 223 225 219 191 202 215 242 195 231 197 217 218 210 212 241 204 226 205 220 219 237 215 242 211 236 225 226 225 214 218 227 203 213 210 223 234 216 225 255 195 209 199 231 213 217 205 207 186 225 191 226 221 198 204 193 222 242 218 205 245 206 226 200 236 235 215 231 215 217 234 212 231 220 238 212 199 226 218 218 236 211 231 218 200 258 189 246 220 217 215 200 221 189 202 206 212 213 230 227 213 223 213 219 225 227 216 222 203 194 217 219 203 226 203 204 213 205 231 210 204 220 214 213 213 229 217 214 190 216 219 210 211 208 205 212 211 220 229 224 197 230 228 228 232 240 207 212 229 216 211 228 194 230 229 218 222 225 222 226 196 219 215 218 219 217 211 213 220 194 234 201 213 234 213 238 220 204 202 206 194 215 181 210 237 216 190 217 206 181 216 236 241 201 213 210 240 214 221 248 223 230 214 222 233 224 210 191 220 235 212 221 229 211 205 212 210 245 230 244 232 199 216 205 199 201 204 211 196 223 215 246 207 215 192 215 222 222 230 211 198 211 239 206 215 204 239 195 208 227 216 230 211 223 202 212 245 246 215 214 234 203 230 204 218 214 220 231 232 220 231 221 187 217 213 209 256 232 212 203 210 202 208 227 237 238 203 190 211 239 203 217 234 191 181 203 203 242 219 215 227 223 185 234 226 210 198 214 229 209 217 231 218 200 207 219 216 234 210 216 198 238 213 200 234 221 223 219 210 200 220 228 196 236 225 223 231 210 196 232 196 191 243 239 216 194 226 209 249 226 214 215 207 239 222 229 195 230 235 208 195 263 185 229 234 215 222 225 195 219 211 183 177 223 231 233 205 195 229 186 189 206 213 223 205 218 198 223 238 216 256 229 199 194 202 205 204 199 225 190 202 209 213 195 190 226 225 241 222 210 200 215 205 220 214 196 210 216 208 202 237 220 227 213 194 226 218 213 216 216 207 204 220 247 239 201 194 174 229 219 190 189 206 202 209 209 216 227 198 187 221 213 215 208 215 227 256 235 207 219 198 211 244 206 206 204 207 232 218 225 188 207 212 222 215 195 211 227 227 232 196 230 224 196 200 199 235 224 221 200 223 193 190 191 215 198 198 255 259 238 209 216 226 210 232 223 219 218 208 221 203 224 171 232 222 206 213 204 229 190 180 208 209 238 194 204 223 223 207 201 233 189 195 192 192 220 224 212 230 224 208 220 225 235 224 231 204 195 212 200 235 211 203 207 213 223 211 212 225 223 225 210 229 204 190 208 195 193 198 204 210 225 192 212 219 201 231 221 217 215 229 224 226 208 213 194 217 198 218 212 198 243 202 228 237 225 235 214 220 227 214 225 221 242 192 211 210 186 230 210 210 221 199 230 233 193 228 207 217 219 208 222 214 208 207 210 216 203 195 228 190 217 214 220 193 229 219 221 204 192 215 206 211 198 215 220 213 214 199 224 214 218 209 260 178 228 192 198 215 219 220 203 223 194 216 203 230 225 212 228 222 207 207 209 220 220 211 198 225 248 202 232 229 201 194 193 226 211 196 227 215 200 203 203 224 226 226 228 195 200 200 216 218 219 214 184 189 228 227 200 216 237 241 200 215 207 230 203 223 202 178 235 231 205 201 234 223 232 243 225 208 212 208 236 195 198 203 231 218 236 203 203 215 227 232 213 208 203 211 223 215 222 204 191 191 209 199 215 222 209 200 201 232 219 200 235 212 212 206 184 196 213 205 206 247 194 248 226 210 220 223 231 215 191 171 221 234 234 244 178 232 207 209 213 195 212 224 209 224 212 225 201 212 237 205 209 209 221 232 206 224 256 215 209 218 213 208 197 217 210 211 199 199 227 223 222 231 215 218 229 217 213 222 205 195 171 219 214 222 237 231 217 197 210 222 215 211 176 204 214 234 214 198 223 229 192 216 208 202 217 217 193 221 225 227 236 231 193 212 205 250 230 215 214 206 210 208 233 186 205 227 226 227 216 220 210 213 233 219 227 216 213 218 221 222 237 234 216 233 207 218 214 215 209 234 213 256 218 231 209 225 180 232 213 216 216 214 249 246 226 238 209 234 231 214 217 195 221 219 216 231 215 208 223 230 174 219 204 209 244 204 231 220 224 215 244 221 227 204 210 220 220 207 207 195 244 219 205 192 209 231 202 206 203 211 242 208 193 225 232 213 216 220 217 241 189 202 224 225 228 199 271 228 232 202 205 207 200 199 208 218 245 202 234 208 219 213 214 215 221 215 220 204 213 188 209 213 210 190 183 224 197 226 170 195 211 232 213 238 212 196 223 209 182 219 230 203 213 217 226 228 224 208 228 213 202 200 229 233 196 235 198 215 191 215 204 227 220 216 206 237 218 202 201 201 237 209 210 241 198 213 229 222 220 228 233 221 208 204 210 226 213 205 207 219 233 234 228 220 238 213 223 194 245 220 212 191 210 213 195 239 187 197 211 224 223 209 210 199 210 229 221 210 210 214 213 235 239 209 203 198 226 212 197 227 227 203 208 213 244 222 226 197 225 209 227 223 187 239 211 214 247 203 204 224 202 215 217 221 236 199 213 225 210 216 215 216 216 214 192 192 201 245 225 206 227 223 220 189 222 235 202 202 213 188 227 215 206 220 199 217 197 211 218 240 227 186 232 198 206 236 216 217 212 227 218 211 214 210 212 198 246 220 214 204 221 231 241 221 270 235 217 227 206 238 211 220 217 212 197 240 203 227 227 226 190 237 227 214 203 195 190 235 228 216 222 185 208 229 215 212 243 232 227 213 223 214 214 217 217 212 233 242 201 215 224 197 201 250 217 208 212 218 227 215 221 239 199 236 231 227 213 193 207 246 216 222 203 213 234 243 234 229 212 199 218 206 223 210 244 198 262 242 192 222 213 214 195 225 211 219 227 212 236 230 199 227 232 213 217 228 193 234 222 212 222 235 228 218 218 223 226 224 231 246 218 201 193 213 222 210 202 229 227 218 231 207 211 209 233 237 215 239 202 208 220 245 223 212 235 225 218 176 256 219 204 218 194 187 225 221 207 204 224 205 205 215 226 225 229 232 228 213 221 209 227 205 227 224 226 203 223 205 201 217 198 212 211 204 207 232 198 203 209 231 192 222 213 209 242 205 229 209 214 226 204 199 192 195 216 220 215 218 228 206 218 203 207 206 209 233 231 232 214 247 208 222 226 217 184 220 234 213 207 238 223 220 208 216 227 208 236 214 199 216 190 202 189 204 247 231 214 221 192 228 225 231 212 194 202 222 243 190 214 182 230 219 196 222 202 213 217 206 231 227 233 207 204 196 215 240 199 225 231 212 200 202 203 203 204 239 198 208 234 225 239 211 183 234 234 219 212 200 202 197 200 207 256 205 206 236 204 184 196 205 240 218 223 223 204 247 218 228 209 202 241 202 225 226 207 226 235 210 231 205 208 214 213 215 216 213 247 234 227 234 217 227 213 224 214 209 208 238 202 180 225 226 220 205 211 215 226 222 218 196 213 213 211 247 222 205 225 208 218 223 211 207 225 224 209 191 228 230 231 243 178 197 245 233 221 249 216 231 210 196 223 207 251 217 233 245 228 217 195 225 236 220 218 226 226 214 221 225 227 216 225 246 241 230 222 227 242 237 237 248 230 238 194 218 227 222 197 221 219 255 201 246 220 213 206 230 256 212 223 224 244 195 226 207 201 221 242 236 204 199 205 223 210 222 236 194 223 221 220 217 187 226 232 221 212 206 238 219 258 227 218 228 265 178 198 223 232 214 191 226 214 202 256 227 210 201 232 221 233 242 223 234 202 203 220 180 213 230 216 248 219 199 210 218 228 228 214 216 205 216 207 197 224 214 237 192 225 226 220 201 215 237 218 217 236 222 217 213 198 230 212 207 242 221 226 203 214 223 200 222 228 210 209 214 204 212 206 224 215 228 206 177 214 215 231 224 219 218 205 226 207 201 208 205 231 241 208 213 234 205 233 206 206 229 198 194 233 222 217 232 213 217 224 212 204 213 208 222 223 217 207 230 231 227 206 220 265 205 221 232 221 245 209 213 202 201 221 232 218 208 196 213 217 229 206 199 214 227 240 179 213 243 216 210 199 241 219 228 233 213 227 206 202 215 222 215 223 217 214 209 241 226 216 187 221 230 207 234 210 195 209 217 221 221 228 201 198 237 225 220 249 196 215 192 216 208 178 216 188 205 199 209 205 228 213 240 208 182 212 183 210 213 219 222 223 215 209 204 225 204 210 195 214 211 208 229 223 199 200 233 188 228 214 210 212 200 216 232 239 218 203 215 202 213 221 220 226 193 201 216 189 223 196 221 195 214 219 203 221 178 223 214 217 213 217 219 197 229 223 194 220 198 221 233 232 207 246 214 241 217 236 204 223 210 218 226 215 194 211 235 215 214 221 189 204 216 200 245 221 220 201 219 235 214 206 214 202 215 215 232 207 202 222 203 213 194 235 184 202 201 213 216 223 215 210 227 214 215 235 232 221 206 233 177 225 224 209 219 182 219 206 198 230 222 216 230 238 210 231 219 217 207 212 244 229 192 218 216 182 255 230 243 226 213 209 200 206 227 220 230 194 221 200 203 223 206 221 229 217 201 200 201 244 225 217 235 262 229 207 195 222 207 238 245 242 247 192 193 238 194 226 231 211 211 236 221 219 234 209 202 229 227 188 210 218 205 210 211 202 246 221 217 208 197 206 210 234 189 222 213 246 212 217 226 245 209 206 227 248 236 227 222 190 222 221 206 230 220 203 211 223 237 221 203 214 224 201 216 213 233 219 228 187 233 225 197 178 237 208 217 234 200 220 240 209 213 201 250 225 207 221 181 221 240 207 210 230 223 201 226 266 241 215 245 207 223 209 185 208 198 208 190 248 247 205 215 218 232 212 226 205 249 217 221 209 220 227 217 236 225 217 233 203 216 224 216 222 216 195 238 214 226 196 201 226 228 226 224 185 207 233 221 222 240 214 209 178 213 226 233 222 217 206 203 235 234 214 215 220 229 237 225 227 212 210 226 231 210 203 208 219 195 204 194 209 195 239 211 212 221 229 209 197 232 197 232 229 223 200 215 236 208 201 237 219 211 217 219 217 188 225 206 211 227 197 235 199 246 242 219 225 204 206 237 212 222 222 217 225 211 239 225 219 234 200 232 203 212 221 217 206 195 214 224 220 213 239 220 210 197 217 224 220 211 202 221 237 245 195 210 220 212 222 207 225 223 256 210 203 233 196 228 222 231 228 211 204 225 224 224 221 226 240 212 209 212 227 205 220 193 227 215 233 231 206 203 193 206 213 233 199 205 186 218 231 220 203 195 207 197 208 220 206 217 199 218 220 196 226 201 231 222 230 182 206 236 245 202 196 221 226 225 208 217 233 230 199 187 223 202 226 247 214 235 212 202 215 221 238 214 220 224 221 209 204 213 200 216 207 235 214 204 228 194 210 228 229 234 196 179 228 201 215 219 248 219 231 216 196 215 194 179 202 239 224 235 238 206 199 185 239 216 242 213 198 229 224 216 201 226 175 212 223 226 223 213 210 217 213 221 216 205 226 202 189 226 203 217 194 202 218 199 207 207 219 222 211 191 186 205 212 202 226 169 232 219 224 210 232 229 184 197 200 214 221 224 209 234 232 205 190 209 218 236 203 218 208 190 194 189 196 208 224 207 195 219 258 211 256 192 226 233 210 229 225 221 248 200 223 219 208 223 239 228 223 218 244 208 230 207 218 216 207 208 233 203 232 199 229 225 244 234 235 218 209 215 221 214 192 236 222 198 222 217 214 233 207 220 212 228 196 202 209 196 207 207 195 209 215 211 214 213 243 218 219 200 223 219 209 209 207 214 224 233 211 233 184 230 224 215 193 197 225 221 200 226 210 201 210 213 219 213 208 247 205 222 204 226 199 214 205 240 232 246 231 233 210 221 236 187 225 217 207 222 242 228 227 203 208 232 218 217 230 220 201 212 220 246 222 205 212 238 210 215 231 216 190 228 226 232 210 213 207 191 223 222 223 224 196 218 210 225 236 235 225 208 214 207 212 214 238 213 229 217 213 201 235 232 214 239 203 223 222 222 203 236 243 224 214 198 220 217 227 226 198 210 213 214 244 213 188 190 200 196 235 222 227 198 219 216 214 230 211 213 203 212 198 217 211 186 203 236 219 220 258 229 219 196 206 207 216 224 214 203 210 208 225 223 229 204 211 237 224 235 210 235 183 192 207 196 197 199 212 222 199 197 200 234 212 207 250 239 222 204 197 209 208 203 238 221 215 241 230 231 211 212 225 217 219 216 214 221 225 232 211 201 217 199 214 202 212 198 191 204 230 203 231 218 247 203 248 214 212 234 218 231 204 211 201 173 214 230 194 213 199 180 182 214 195 215 218 175 231 206 223 227 208 208 215 235 210 193 221 218 196 223 226 220 202 227 220 242 181 239 206 219 213 212 211 232 200 264 212 198 218 216 223 223 191 207 247 221 232 212 215 218 212 207 213 220 212 197 194 215 197 220 217 212 221 212 197 223 197 215 234 229 212 211 218 198 221 233 225 223 214 246 227 228 245 207 202 208 214 223 210 218 214 226 204 207 228 228 213 236 207 218 215 174 207 222 214 219 208 221 234 231 213 221 218 209 206 230 189 215 218 226 198 227 236 223 195 190 227 224 226 217 208 217 228 205 227 230 239 201 212 228 248 235 212 227 215 207 224 202 224 249 213 205 222 212 225 212 191 203 216 217 206 200 229 208 232 236 189 193 210 196 232 200 228 192 192 207 223 197 207 232 219 230 200 195 207 232 217 258 211 238 192 231 195 219 223 210 216 225 242 209 204 233 218 184 231 203 226 217 212 219 212 203 244 211 193 237 225 204 210 234 211 202 195 220 214 195 197 197 221 215 215 208 207 200 220 212 226 223 206 224 202 206 231 217 213 195 190 225 205 212 234 210 226 228 227 231 201 217 207 219 223 216 235 211 202 215 215 213 219 244 232 249 206 244 223 221 210 219 219 213 200 211 239 208 201 208 203 223 206 217 219 196 200 182 222 203 232 237 199 211 220 216 235 223 224 232 247 209 219 229 213 212 228 202 229 212 238 205 198 210 248 192 232 250 225 202 211 201 193 224 202 247 218 255 203 200 211 218 230 216 208 217 229 223 241 224 219 241 221 222 210 228 228 227 215 248 243 204 196 206 216 217 228 216 220 217 211 227 239 207 202 211 222 220 212 236 236 224 229 220 193 225 216 215 215 209 248 239 208 223 218 236 239 213 231 231 221 223 222 212 233 197 238 233 216 238 241 238 236 197 240 207 235 232 236 255 222 224 215 182 236 213 266 225 231 218 209 202 230 247 192 227 206 233 199 209 219 224 243 214 246 219 225 201 225 214 216 211 225 228 230 227 196 221 225 213 224 255 233 244 199 240 211 232 220 228 248 228 223 202 240 228 214 218 232 228 201 222 238 235 234 238 227 187 218 211 232 221 212 240 230 229 242 226 243 235 214 211 210 212 225 260 230 245 229 221 241 222 241 232 248 200 201 227 229 239 209 208 231 235 269 227 231 222 237 229 215 191 243 236 220 241 256 242 225 227 234 237 242 226 247 247 221 238 246 232 259 231 239 236 248 235 246 215 238 207 261 216 260 240 256 220 227 248 229 226 213 228 209 238 266 200 227 205 238 270 234 241 223 232 260 216 243 259 219 230 203 231 248 212 225 210 230 191 233 232 244 234 223 231 234 242 220 216 219 259 236 219 238 236 202 212 220 227 209 241 240 235 223 213 218 224 242 213 221 242 239 210 224 212 239 208 223 211 213 242 213 193 231 203 213 243 243 222 240 216 209 216 217 228 212 226 249 200 210 228 219 237 200 234 220 216 215 202 221 227 197 243 225 214 236 229 241 280 210 249 203 216 215 217 221 230 226 220 232 211 239 235 234 198 217 223 203 225 230 212 216 223 221 202 221 198 218 216 218 203 218 211 221 214 240 236 238 209 226 229 215 220 212 216 224 250 246 217 227 213 224 227 210 237 231 232 256 241 223 238 202 245 213 220 226 213 217 239 209 225 209 195 204 213 244 233 188 210 205 201 220 225 223 219 228 209 229 206 236 234 229 219 214 231 222 187 221 223 217 242 212 233 229 225 212 238 232 215 241 229 255 220 243 220 201 205 228 227 228 231 211 222 221 218 213 249 219 211 230 217 221 230 199 208 212 203 220 206 207 223 265 215 231 226 195 229 238 214 230 221 197 205 236 219 231 203 201 197 203 201 219 226 210 223 195 199 220 246 228 238 211 234 205 190 222 231 200 213 232 201 210 205 213 200 222 223 211 191 217 213 210 234 217 231 193 218 246 204 224 225 212 218 207 221 213 214 205 227 231 214 195 219 227 227 195 226 224 209 221 184 209 219 207 255 199 203 225 224 227 214 242 227 220 236 188 235 211 236 235 229 232 186 265 222 222 193 234 256 213 209 241 230 216 210 226 234 210 236 196 214 215 214 180 195 205 219 215 222 240 209 227 210 223 215 218 196 243 227 236 226 232 242 220 234 221 206 203 209 232 213 233 217 199 238 236 228 209 227 231 218 219 205 233 216 228 222 183 232 203 233 243 223 230 221 236 238 210 218 261 227 221 221 202 218 226 224 198 205 188 208 246 226 211 192 207 218 198 216 202 204 205 199 215 232 217 225 200 225 210 234 195 215 205 203 211 211 224 233 235 201 221 238 233 201 208 209 239 206 222 197 222 215 207 205 223 241 226 238 220 208 217 206 236 231 232 211 216 208 184 228 197 193 224 218 217 218 217 213 215 228 214 216 223 236 209 210 215 202 214 232 233 220 219 233 214 231 229 218 220 229 203 203 215 214 236 191 215 210 220 261 202 245 232 211 206 209 207 226 212 228 228 231 237 218 224 219 235 196 203 196 227 216 202 221 193 231 210 183 198 207 262 210 225 203 191 222 222 211 244 225 220 219 216 209 242 213 230 194 226 218 196 185 211 231 212 218 223 241 231 207 230 226 229 210 219 216 212 211 198 205 181 203 231 238 212 240 233 237 221 236 227 234 261 242 229 208 221 222 205 186 212 217 198 227 220 224 194 229 227 217 222 211 215 192 189 195 240 203 248 220 218 224 215 220 230 202 237 202 231 244 209 202 208 213 205 217 225 227 208 226 230 227 215 223 212 201 229 256 205 229 226 209 224 222 209 224 204 201 201 215 212 219 233 242 209 213 229 225 248 215 224 217 215 209 217 242 257 215 203 198 236 203 221 223 225 203 229 225 227 193 240 209 219 215 231 209 226 226 181 212 218 221 213 230 201 220 211 225 241 239 218 216 204 200 217 205 217 194 222 215 215 217 218 213 221 234 215 204 207 233 260 219 219 218 227 218 241 201 225 213 218 224 203 217 264 222 232 190 218 224 197 210 199 209 204 212 211 227 223 219 239 208 216 205 228 215 239 239 213 202 217 226 232 220 221 207 212 211 203 233 216 201 212 184 231 211 219 224 238 255 228 233 218 234 223 219 261 217 210 237 200 239 227 225 225 229 241 231 241 213 239 202 199 231 215 183 205 224 263 218 236 241 225 222 228 213 219 219 195 209 257 233 211 207 203 248 218 214 219 214 216 228 244 217 249 235 223 236 211 230 219 207 204 205 223 219 222 222 244 232 222 208 245 234 225 222 190 224 225 203 249 222 229 260 224 220 203 211 211 227 224 233 216 229 214 221 242 234 203 207 213 213 201 211 212 211 241 208 222 228 223 216 214 230 216 225 214 228 214 221 231 226 220 220 225 208 229 210 220 211 220 238 225 216 219 217 222 228 212 233 229 266 230 209 236 189 234 197 232 201 212 206 208 192 218 223 237 222 206 214 214 207 235 249 190 224 221 238 197 264 229 204 242 231 236 256 199 194 224 210 207 235 231 260 240 255 219 215 202 194 215 208 263 184 210 233 226 220 201 255 234 247 210 211 200 207 204 218 223 242 224 209 234 221 226 234 228 230 200 190 243 217 213 245 226 210 228 232 227 223 236 240 206 212 244 237 207 201 220 230 222 207 240 203 212 238 228 209 188 221 228 222 214 220 198 220 222 226 224 210 231 217 227 228 194 205 239 205 220 210 213 205 228 233 214 227 203 222 234 228 234 247 224 233 207 206 211 208 224 237 217 208 198 203 195 217 213 205 220 262 227 205 215 221 210 192 225 203 227 210 226 236 236 220 218 215 209 199 218 227 205 256 219 209 228 197 199 210 222 210 190 215 220 211 204 217 216 238 211 234 229 222 223 216 201 222 234 223 201 262 204 232 214 231 249 217 207 219 223 220 209 228 207 210 231 220 237 225 184 233 221 243 199 209 220 246 230 228 240 224 205 206 209 230 208 221 229 224 225 212 192 208 222 205 196 215 185 244 215 212 197 222 263 237 220 224 197 238 203 199 199 202 211 214 238 214 216 204 220 236 218 228 224 194 225 217 213 208 207 190 212 226 234 244 222 208 211 217 186 203 191 231 229 187 206 208 223 212 221 215 215 214 202 222 228 213 208 213 208 218 225 185 213 216 227 245 236 243 220 235 215 215 219 205 218 221 240 207 216 202 233 198 188 209 236 217 210 223 237 213 242 209 250 223 213 217 203 222 219 229 210 207 189 231 227 220 224 256 231 216 225 215 222 214 217 179 190 237 248 217 210 218 203 217 227 208 235 199 228 205 240 223 217 230 272 238 236 247 198 215 224 227 220 232 198 214 224 199 215 199 213 213 230 221 234 217 219 240 201 226 205 239 223 246 196 203 240 198 233 198 204 223</counts>
			</dataPoints>
		</scan>
	</xrdMeasurement>
</xrdMeasurements>