File: data/XRD/XG-Vakuum/XG-500/W6822-1C_XG_Vakuum_500.xrdml
<xrdMeasurements xmlns="http://www.xrdml.com/XRDMeasurement/2.1" xmlns:xsi="http://www.w3.org/2001/XMLSchema-instance" xsi:schemaLocation="http://www.xrdml.com/XRDMeasurement/2.1 http://www.xrdml.com/XRDMeasurement/2.1/XRDMeasurement.xsd" status="Completed">
	<comment>
		<entry>Configuration=Factory configuration, Owner=User-1, Creation date=7/8/2013 4:01:53 PM</entry>
		<entry>Goniometer=PW3050/65 (Theta/2Theta); Minimum step size 2Theta:0.0001; Minimum step size Omega:0.0001</entry>
		<entry>Sample stage=MRD Cradle; Minimum step size Phi:0.01; Minimum step size Chi:0.01; Minimum step size X:0.01; Minimum step size Y:0.01; Minimum step size Z:0.001</entry>
		<entry>Diffractometer system=XPERT-PRO</entry>
		<entry>Measurement program=C:\PANalytical\Data Collector\Programs\Jorrit\2thom\_absolute_2th-om_10-130deg_PIXscan_56min.xrdmp, Identifier={15BCCF57-2807-42BD-B5B9-ECC0B3DC9284}</entry>
		<entry>Batch program=C:\PANalytical\Data Collector\Programs\SimonL\batch4x_2thom_10-130°_z9.1_x0,10,20,30_y0_57min.xrdmp, Identifier={EED9823A-2BEB-424C-9252-345C4EF2834A}</entry>
	</comment>
	<sample type="To be analyzed">
		<id></id>
		<name></name>
		<preparedBy></preparedBy>
	</sample>
	<xrdMeasurement measurementType="Scan" status="Completed" sampleMode="Reflection">
		<comment>
			<entry>_absolute_2th-om_10-130deg_PIXscan_56min</entry>
			<entry>PHD Lower Level = 4.83 (keV), PHD Upper Level = 11.27 (keV)</entry>
		</comment>
		<usedWavelength intended="K-Alpha 1">
			<kAlpha1 unit="Angstrom">1.5405980</kAlpha1>
			<kAlpha2 unit="Angstrom">1.5444260</kAlpha2>
			<kBeta unit="Angstrom">1.3922500</kBeta>
			<ratioKAlpha2KAlpha1>0.5000</ratioKAlpha2KAlpha1>
		</usedWavelength>
		<incidentBeamPath>
			<radius unit="mm">320.00</radius>
			<xRayTube id="1010048" name="Empyrean Cu LFF HR (9430 033 7310x) DK442154">
				<tension unit="kV">40.0</tension>
				<current unit="mA">40.0</current>
				<anodeMaterial>Cu</anodeMaterial>
				<focus type="Line">
					<length unit="mm">12.0</length>
					<width unit="mm">0.4</width>
					<takeOffAngle unit="deg">4.2</takeOffAngle>
				</focus>
			</xRayTube>
			<xRayMirror id="27010001" name="Inc. Beam Cu W/Si (parabolic MRD)" hybrid="false">
				<crystal type="Graded" shape="Parabolic">W/Si</crystal>
				<acceptanceAngle unit="deg">0.800</acceptanceAngle>
				<length unit="mm">60.0</length>
			</xRayMirror>
			<sollerSlit id="21010002" name="Soller slits 0.04 rad.">
				<opening unit="rad">0.0400</opening>
			</sollerSlit>
			<mask id="22030008" name="Fixed mask 4 mm">
				<distanceToSample unit="mm">220.00</distanceToSample>
				<width unit="mm">4.00</width>
			</mask>
			<divergenceSlit id="22010007" name="Fixed slit 1/8°" xsi:type="fixedDivergenceSlitType">
				<distanceToSample unit="mm">220.00</distanceToSample>
				<height unit="mm">0.19</height>
			</divergenceSlit>
		</incidentBeamPath>
		<diffractedBeamPath>
			<radius unit="mm">320.00</radius>
			<sollerSlit id="21010002" name="Soller slits 0.04 rad.">
				<opening unit="rad">0.0400</opening>
			</sollerSlit>
			<receivingSlit id="22010001" name="Fixed slit 4°">
				<height unit="mm">5.88</height>
			</receivingSlit>
			<detector id="7010017" name="PIXcel3D 1x1 detector" xsi:type="areaDetectorType">
				<phd unit="%">
					<lowerLevel>30.0</lowerLevel>
					<upperLevel>70.0</upperLevel>
				</phd>
				<mode>Scanning</mode>
				<activeChannelsEquatorial>255</activeChannelsEquatorial>
				<activeChannelsAxial>255</activeChannelsAxial>
				<pitchEquatorial unit="mm">0.05500</pitchEquatorial>
				<pitchAxial unit="mm">0.05500</pitchAxial>
				<readOutPeriod unit="seconds">0.135</readOutPeriod>
			</detector>
		</diffractedBeamPath>
		<scan appendNumber="0" mode="Continuous" scanAxis="2Theta-Omega" status="Completed">
			<header>
				<startTimeStamp>2024-10-07T18:02:28+02:00</startTimeStamp>
				<endTimeStamp>2024-10-07T18:58:34+02:00</endTimeStamp>
				<author>
					<name>PRO-MRD</name>
				</author>
				<source>
					<applicationSoftware version="6.1b">Data Collector</applicationSoftware>
					<instrumentControlSoftware version="7.0E 20130304">XPERT-PRO</instrumentControlSoftware>
					<instrumentID>0000000011142674</instrumentID>
				</source>
			</header>
			<dataPoints>
				<positions axis="2Theta" unit="deg">
					<startPosition>9.99826193</startPosition>
					<endPosition>129.99755682</endPosition>
				</positions>
				<positions axis="Omega" unit="deg">
					<startPosition>4.99913096</startPosition>
					<endPosition>64.99877841</endPosition>
				</positions>
				<positions axis="Phi" unit="deg">
					<commonPosition>0.00</commonPosition>
				</positions>
				<positions axis="Chi" unit="deg">
					<commonPosition>0.00</commonPosition>
				</positions>
				<positions axis="X" unit="mm">
					<commonPosition>10.00</commonPosition>
				</positions>
				<positions axis="Y" unit="mm">
					<commonPosition>0.00</commonPosition>
				</positions>
				<positions axis="Z" unit="mm">
					<commonPosition>9.100</commonPosition>
				</positions>
				<commonCountingTime unit="seconds">32.895</commonCountingTime>
				<counts 472 418 473 453 456 458 435 470 449 446 448 470 463 442 431 481 455 475 449 494 489 446 457 458 454 407 472 436 465 460 466 434 458 445 478 480 454 437 436 447 494 455 493 460 453 492 456 471 494 444 431 485 448 430 455 457 469 442 467 459 441 432 441 432 451 502 449 489 442 425 441 483 436 434 454 420 446 416 409 499 485 450 436 452 435 420 464 458 466 469 464 458 477 434 408 416 470 474 408 407 412 420 451 438 425 429 416 390 455 431 466 439 429 450 430 437 435 435 406 433 453 441 442 468 450 417 439 431 415 419 440 431 425 412 463 386 417 415 436 453 471 428 417 440 426 384 392 421 441 417 395 425 450 437 420 426 432 402 435 427 403 424 419 394 404 377 429 431 429 405 403 402 389 424 434 457 414 378 428 426 401 420 414 374 449 421 423 428 408 428 385 415 417 428 413 412 397 408 423 430 447 429 408 422 396 420 388 389 418 425 412 393 410 392 395 384 443 404 417 418 419 406 393 415 413 407 450 368 404 437 387 414 440 384 418 359 413 349 412 425 398 383 394 402 438 405 423 426 406 386 416 371 411 383 425 356 396 394 378 383 365 419 373 418 380 447 382 405 381 413 340 391 435 368 412 401 432 371 349 376 370 395 423 386 410 386 374 380 396 396 409 377 390 390 417 388 398 373 400 415 392 347 406 399 367 403 373 369 379 386 367 378 405 372 375 395 357 388 380 373 387 396 395 348 386 400 395 408 366 349 363 346 393 384 365 356 343 385 393 407 364 411 389 377 411 361 399 379 409 367 360 365 389 334 409 377 384 377 392 381 375 355 377 397 365 392 392 336 374 364 398 372 373 353 334 365 366 359 358 364 339 365 361 355 326 398 364 377 367 376 382 374 349 380 396 367 401 332 356 369 394 338 379 379 344 350 370 358 328 362 394 350 374 335 361 376 337 362 347 344 358 362 355 346 336 386 350 345 319 342 329 361 357 375 331 336 375 387 333 342 357 323 342 345 353 349 326 353 345 357 342 352 346 376 362 354 369 377 382 387 364 366 377 353 310 324 335 370 353 348 375 386 343 340 335 362 348 348 382 352 365 348 364 362 370 340 332 358 350 331 337 331 359 356 385 349 351 336 360 346 374 359 345 326 354 321 359 336 338 340 340 354 353 347 351 347 344 302 356 348 337 331 337 313 341 339 346 318 313 328 364 351 386 354 336 354 318 365 313 356 348 339 343 332 331 342 343 330 293 336 333 358 328 343 355 365 344 317 367 335 341 315 356 358 373 339 364 328 326 347 361 336 334 342 352 334 328 323 334 346 361 336 378 360 336 344 361 314 346 344 336 326 328 297 320 320 337 377 337 317 343 334 344 340 314 322 342 338 346 319 341 302 306 321 351 329 318 336 333 359 331 332 326 340 323 332 332 328 310 318 340 323 332 327 287 345 335 315 314 316 318 328 334 326 338 394 371 320 324 330 325 314 314 333 295 341 312 337 332 364 351 328 323 308 308 326 307 316 321 340 332 315 325 363 349 335 334 329 337 320 330 345 349 336 324 326 332 332 325 300 338 354 289 344 318 312 321 334 337 366 332 364 340 340 338 343 341 327 364 335 326 333 339 320 312 351 320 319 302 332 330 324 340 356 331 352 311 320 324 348 319 338 310 327 340 331 324 338 343 357 321 323 320 364 324 299 354 343 296 319 318 321 337 310 291 336 313 353 345 326 324 316 310 294 330 326 346 317 338 317 333 302 308 329 328 318 308 293 319 300 314 349 305 345 306 366 313 318 322 296 297 342 335 304 322 318 286 368 333 310 344 306 312 355 291 344 340 323 330 296 359 297 342 323 327 328 339 299 311 334 306 312 335 305 321 324 321 336 315 324 330 296 302 328 299 303 314 318 305 357 333 307 331 313 323 309 301 327 339 361 332 355 311 326 300 309 321 324 298 328 303 343 320 345 340 301 370 301 329 319 331 295 301 341 297 326 337 340 343 298 305 331 330 311 320 310 341 303 313 327 322 317 314 335 355 313 340 319 332 319 330 308 292 332 363 316 306 314 329 318 314 326 308 372 348 318 327 331 359 326 333 336 325 335 315 315 316 311 303 313 333 325 347 311 331 336 354 317 321 326 364 302 350 309 323 309 311 347 316 327 334 302 321 334 358 332 295 314 335 332 327 355 321 337 320 327 324 310 345 321 326 358 335 333 328 323 331 325 351 294 329 317 328 335 329 319 308 356 344 346 315 337 305 346 334 319 333 345 351 346 323 334 322 340 326 319 346 282 313 352 359 338 314 324 346 362 323 338 297 340 359 342 316 333 351 365 360 332 308 304 294 341 301 344 351 313 297 348 338 330 360 333 317 305 360 328 349 289 348 349 337 331 313 342 374 316 340 356 339 364 350 350 338 350 343 316 329 350 352 337 349 315 358 375 337 320 342 352 363 331 340 367 337 348 319 353 359 322 334 344 371 377 340 349 333 356 384 302 338 318 356 360 299 324 332 409 335 324 331 338 348 327 345 324 380 323 399 349 345 336 324 359 343 366 364 351 358 322 348 340 370 340 342 359 367 342 360 320 359 361 336 322 377 385 362 320 362 366 378 327 355 349 326 374 329 323 324 347 349 357 352 322 358 351 338 346 375 341 349 307 336 355 338 337 351 334 383 351 355 336 338 382 347 332 341 362 337 313 334 356 338 356 342 342 333 387 343 352 343 360 339 345 318 353 355 366 363 385 371 345 355 341 334 326 359 339 335 360 334 344 351 369 337 345 337 354 337 345 348 344 369 391 338 341 329 320 346 355 377 370 355 370 405 348 383 319 366 344 364 380 352 341 349 338 375 354 333 375 338 345 337 358 345 358 356 314 343 335 308 364 345 354 347 358 349 317 332 370 383 313 349 395 365 338 377 364 340 331 354 343 366 329 337 328 345 359 345 379 322 350 339 357 351 317 347 362 364 354 348 354 319 337 334 332 319 361 321 336 314 370 340 334 343 336 392 337 350 363 344 354 329 383 334 409 348 323 337 351 347 351 350 349 344 368 389 320 337 333 368 343 334 377 375 341 341 346 342 386 340 345 319 342 336 339 346 363 335 324 370 344 348 355 378 355 356 323 330 319 336 357 341 305 361 320 373 351 377 367 329 337 329 343 328 365 345 308 364 340 327 324 311 365 358 327 340 284 348 329 356 341 322 340 342 355 343 332 337 350 341 323 344 377 372 311 301 353 357 367 331 341 330 330 332 350 322 337 327 303 286 343 325 352 315 325 354 347 350 342 324 312 323 330 322 328 367 332 313 353 352 338 346 358 366 308 343 366 306 329 351 321 323 306 337 343 335 344 323 316 328 347 313 352 308 340 312 302 352 334 324 313 347 334 313 319 317 334 347 312 306 316 337 336 320 326 328 346 341 327 334 294 325 336 338 324 313 316 302 316 313 331 325 300 314 323 347 307 325 337 310 331 303 321 352 342 325 296 332 302 309 326 324 328 311 300 329 303 329 355 348 314 311 309 320 286 314 326 329 295 325 320 333 312 311 336 291 311 319 336 337 328 354 318 314 352 340 299 315 310 303 299 335 290 333 288 307 302 295 287 277 304 330 324 297 339 322 312 332 308 312 302 312 309 318 305 285 300 284 297 331 310 313 294 300 296 339 315 276 350 319 312 299 317 315 299 307 328 309 295 302 316 311 295 315 304 304 319 323 312 272 314 313 292 292 312 304 288 246 270 308 291 283 323 288 291 298 339 304 311 302 283 301 295 316 275 293 299 313 293 307 313 297 275 343 286 337 348 288 319 324 288 309 293 308 281 284 297 298 289 302 305 303 309 294 276 311 282 336 250 306 271 308 307 290 301 319 303 267 302 280 305 302 288 272 293 311 308 271 288 292 303 289 310 281 276 303 296 300 278 304 267 271 274 278 285 248 335 281 300 303 286 295 280 290 294 296 282 294 310 287 274 282 291 303 282 280 268 267 297 250 298 276 280 292 302 302 286 289 282 309 267 311 276 273 297 267 317 281 281 271 288 287 290 323 272 277 309 307 297 296 289 317 279 287 280 273 293 292 314 301 274 308 299 266 271 302 266 308 267 287 264 299 292 272 282 287 308 275 290 320 292 293 240 281 266 271 311 303 297 283 324 284 286 292 277 294 288 275 258 284 264 333 265 292 295 278 282 294 296 266 279 257 265 265 274 277 314 263 284 270 266 268 271 286 248 284 270 272 255 306 261 281 233 285 270 225 282 273 278 266 231 276 290 278 257 232 271 265 276 273 286 235 262 247 276 264 266 270 310 266 265 281 295 256 248 259 283 264 247 266 255 278 290 270 301 265 265 239 275 276 258 261 265 245 248 265 257 266 268 260 296 245 256 276 283 276 287 269 263 265 240 272 271 258 270 300 281 275 256 272 281 276 266 299 256 240 277 273 238 275 231 276 259 311 271 290 236 270 287 234 275 240 262 244 207 270 250 245 246 240 245 285 298 283 282 228 231 258 257 260 258 266 264 241 283 262 239 256 281 266 230 239 263 249 290 240 228 260 281 257 265 289 237 244 243 264 247 288 245 265 257 242 270 261 274 258 259 268 236 270 261 268 261 274 247 275 279 261 277 276 285 232 269 290 228 258 246 267 278 269 243 280 256 230 264 250 263 257 262 249 276 242 235 272 293 238 275 278 247 260 274 238 229 245 247 223 243 255 239 264 255 272 266 240 307 261 271 237 235 238 241 292 236 258 234 223 269 243 272 260 230 239 247 271 242 238 275 273 277 231 279 265 246 203 255 249 201 256 275 228 239 250 247 282 247 246 241 248 242 278 244 227 236 217 234 237 283 299 243 283 269 243 227 249 247 228 245 279 257 228 223 275 265 259 231 241 237 246 256 240 243 242 233 264 245 236 260 241 222 241 237 257 273 233 245 258 264 285 241 240 247 240 247 243 255 262 245 266 239 244 269 248 265 269 226 244 221 264 231 260 243 260 220 255 261 263 243 270 250 267 276 238 260 242 247 259 250 260 234 246 275 245 241 238 246 221 219 228 259 233 265 240 235 267 232 268 269 270 245 258 214 259 230 267 215 239 245 242 226 235 257 212 265 272 272 273 232 257 242 246 226 216 258 239 240 233 234 236 243 238 247 222 232 259 255 233 249 246 260 230 229 264 279 259 248 242 260 242 219 216 242 229 239 257 247 258 219 226 241 243 217 271 242 235 226 224 234 224 230 218 232 249 233 248 239 242 255 230 242 230 271 232 247 245 260 234 236 249 280 245 261 236 238 239 192 281 246 206 239 249 234 261 234 226 240 262 250 210 231 239 233 248 260 238 295 228 242 237 227 229 238 248 228 243 233 225 217 239 245 270 245 230 225 227 237 217 211 260 237 248 233 224 262 261 240 240 246 222 218 238 203 255 263 226 236 268 225 277 240 235 223 218 258 242 232 240 207 247 234 238 247 221 237 260 223 243 240 224 218 260 238 274 218 227 233 233 243 244 249 230 223 227 243 236 249 225 235 217 236 263 223 214 243 246 242 246 222 241 241 234 200 230 217 264 230 236 248 221 217 257 233 222 214 238 232 249 237 224 255 209 262 241 214 233 263 260 238 243 223 227 220 243 200 228 235 223 249 255 231 225 232 221 209 263 238 249 246 230 206 224 249 230 209 238 218 247 230 228 227 224 222 220 218 243 261 234 223 217 259 246 227 220 230 240 223 207 241 243 223 240 244 222 218 220 241 221 235 244 234 226 240 231 214 229 230 217 229 222 235 232 224 244 208 219 248 243 224 222 261 228 196 240 229 232 232 236 227 265 218 230 227 247 264 237 238 265 235 274 236 214 246 245 212 230 224 199 263 224 226 241 217 235 233 239 215 240 211 207 235 223 225 235 248 234 231 271 232 247 259 249 216 224 231 246 232 215 261 266 231 229 230 260 207 242 243 238 216 215 218 218 217 246 232 172 234 232 238 236 212 240 199 192 238 231 224 228 230 210 233 229 235 224 255 243 223 243 230 229 241 239 229 233 220 246 264 239 212 228 207 256 242 247 230 220 261 259 247 213 260 216 243 232 241 220 265 239 223 205 228 223 237 237 226 234 226 224 262 233 240 224 213 219 219 236 227 222 242 244 261 260 268 212 235 228 243 257 267 246 215 271 257 248 214 257 246 190 222 232 256 244 242 235 257 228 228 247 225 228 210 248 236 219 229 226 236 231 263 221 232 265 218 198 206 204 266 232 215 269 227 215 230 229 246 244 245 236 247 199 194 216 203 201 255 224 216 214 218 231 223 261 196 249 241 196 228 230 228 226 226 219 234 234 244 229 215 210 220 238 221 266 220 225 264 217 232 215 210 234 215 217 225 208 220 209 230 206 203 249 218 235 229 246 239 217 218 211 202 222 225 245 224 217 234 207 241 205 223 213 207 200 220 213 196 223 196 229 225 213 220 226 208 215 236 216 230 245 185 216 229 215 212 215 237 211 215 226 234 213 227 200 221 219 248 242 213 220 248 245 226 215 217 234 229 236 207 226 230 223 220 241 213 227 220 208 272 211 206 241 212 215 226 198 225 201 222 242 233 219 207 226 230 231 205 221 193 212 238 231 230 212 228 211 232 219 222 210 222 228 215 243 204 228 229 271 211 192 205 187 228 189 224 193 201 202 243 224 247 187 220 224 237 210 227 243 219 213 236 233 200 203 220 249 228 220 225 220 225 208 224 221 205 224 210 223 227 226 227 225 228 211 210 213 214 188 219 212 211 191 225 228 240 236 249 231 230 219 220 232 221 228 230 211 230 210 243 210 224 218 223 223 226 256 204 231 213 241 236 224 193 236 213 256 242 246 231 232 237 215 212 224 230 207 219 238 225 218 227 229 235 222 198 210 222 256 237 206 208 246 196 194 223 224 222 219 219 262 225 221 231 227 223 228 229 200 205 203 208 230 225 238 228 206 196 187 214 217 227 223 245 225 197 230 222 200 224 231 236 206 221 206 207 210 205 230 234 203 214 247 221 214 214 208 213 201 239 266 224 214 227 244 232 204 224 227 222 234 199 200 192 244 222 220 220 201 209 211 193 236 223 234 220 214 215 197 257 228 249 213 234 228 195 224 257 228 202 239 235 211 243 238 196 224 259 231 185 217 226 236 234 217 234 234 231 222 240 231 218 238 238 205 229 225 231 240 223 224 215 239 261 231 221 230 201 220 220 222 240 245 213 234 237 221 238 241 232 215 220 213 221 194 204 214 207 234 245 218 208 192 201 230 248 224 219 212 201 239 221 216 234 221 215 200 226 224 227 236 228 225 238 226 257 222 221 224 238 209 207 203 223 239 245 197 248 236 248 231 241 224 244 223 233 228 206 249 226 229 229 279 212 237 236 246 202 212 241 244 230 202 245 240 239 199 239 193 248 275 199 214 223 238 228 232 236 259 230 234 208 217 245 201 234 241 238 230 207 248 234 216 256 220 213 216 227 278 217 220 228 233 220 212 240 258 236 246 227 237 233 230 234 244 247 234 263 223 268 236 257 237 209 216 216 263 221 228 222 234 255 245 265 258 216 232 230 230 234 234 215 240 224 255 232 258 242 230 222 203 218 266 220 223 236 244 264 215 268 231 219 258 219 225 244 245 204 270 246 242 261 227 255 256 271 249 209 236 266 226 233 231 255 255 234 260 244 221 240 231 202 236 240 220 246 264 234 223 238 222 222 246 236 241 248 233 248 256 244 220 248 217 242 262 220 244 249 235 259 227 241 211 241 243 270 266 268 248 231 296 284 257 267 264 266 247 289 270 223 256 264 303 255 288 267 288 265 286 262 261 271 268 310 265 289 288 312 273 285 294 288 304 285 323 320 312 357 348 340 367 339 382 399 390 384 393 394 395 394 415 409 377 371 368 381 360 366 364 363 334 366 378 332 359 322 332 334 326 326 286 286 289 328 291 293 279 282 311 285 295 273 284 258 263 244 270 240 257 246 239 257 242 239 265 257 263 260 232 232 246 246 205 248 225 264 197 244 255 263 220 250 255 217 229 215 220 232 233 249 239 233 235 221 226 240 224 231 216 216 231 248 204 226 231 262 218 230 220 204 247 233 239 222 233 225 220 223 238 204 211 269 214 236 222 221 256 234 240 263 198 206 216 202 232 227 221 256 214 239 230 197 219 243 268 236 226 241 207 242 213 211 214 257 235 200 243 258 222 242 223 203 197 216 218 219 239 214 215 238 244 224 220 233 222 226 214 216 207 231 232 200 250 201 219 220 249 217 212 243 213 224 217 232 234 260 215 233 216 234 221 199 220 232 213 194 235 213 228 220 241 228 234 195 258 220 212 220 213 224 206 223 238 213 233 209 226 234 230 228 204 227 225 213 213 227 214 259 217 212 236 215 199 234 196 219 213 214 216 213 215 235 231 228 239 222 245 236 222 209 234 211 214 225 217 209 183 216 245 220 223 214 245 247 185 232 230 225 215 246 220 211 226 226 214 210 222 208 240 219 243 219 196 213 221 225 217 224 237 208 239 210 193 242 213 226 222 200 212 227 192 201 220 213 207 212 249 227 228 214 220 227 229 210 216 237 227 199 230 207 231 223 221 224 202 234 230 222 224 227 234 238 218 233 213 201 221 217 208 185 216 264 195 212 202 190 220 214 223 229 223 201 229 243 227 222 214 221 203 214 213 206 216 217 193 224 243 255 210 218 196 230 224 197 220 219 225 209 234 212 230 224 271 209 212 204 237 210 217 221 235 221 201 232 225 241 229 211 212 219 198 227 234 237 199 231 200 205 211 227 203 220 224 255 207 214 208 212 229 234 220 221 225 220 213 227 215 208 213 215 208 217 217 229 220 226 219 195 218 227 219 221 228 208 232 219 217 222 237 203 239 222 222 202 216 233 218 246 225 222 213 214 214 216 213 225 209 224 226 243 211 238 201 207 202 237 195 210 189 208 234 216 217 208 216 248 203 210 245 218 241 220 225 233 207 213 210 226 223 238 218 200 199 227 227 211 223 231 212 215 235 236 219 222 235 223 207 224 227 206 228 216 221 236 206 227 220 216 185 236 236 209 215 214 200 214 232 222 222 237 199 220 222 215 233 212 195 235 217 211 209 242 209 209 218 204 247 213 208 214 217 213 219 218 201 197 223 236 217 222 212 211 232 215 245 216 209 201 195 222 207 204 224 242 219 213 224 229 237 192 197 245 215 223 232 223 240 218 204 200 225 262 210 194 206 240 230 229 196 179 231 236 239 205 226 220 231 217 215 239 233 193 218 228 240 226 248 220 227 217 216 199 226 206 204 234 232 231 222 212 227 224 250 204 214 205 204 201 197 207 193 239 206 219 232 235 228 232 196 210 225 244 215 201 237 223 178 216 205 195 206 210 208 208 223 233 213 198 219 231 216 221 212 207 199 186 246 226 197 239 232 236 226 239 231 221 233 193 189 231 230 235 220 231 225 219 233 213 212 238 209 239 209 211 213 206 227 248 221 234 234 248 209 219 217 203 233 210 201 227 233 239 205 223 216 235 227 204 237 210 236 209 202 221 224 257 209 212 213 211 205 203 225 220 224 225 209 196 227 190 215 218 209 203 219 212 215 208 208 226 212 219 204 216 211 209 205 234 226 225 230 215 227 203 230 223 230 225 244 220 242 195 240 232 197 235 224 200 213 228 213 207 199 219 197 223 230 205 218 220 236 202 201 216 240 242 183 200 230 205 204 210 221 229 230 222 207 200 242 227 231 207 224 215 209 214 265 231 212 218 172 203 210 217 227 213 237 219 237 183 215 223 182 213 221 234 232 216 228 228 202 230 249 210 235 235 202 235 215 211 236 217 207 240 199 194 216 202 212 237 205 212 231 210 206 248 195 220 233 188 215 207 241 228 196 235 227 238 223 192 209 225 232 208 217 217 208 266 235 239 222 231 210 209 225 224 207 195 255 213 228 214 196 224 214 216 234 232 197 227 237 184 202 225 218 236 226 237 218 236 199 237 201 241 193 212 224 219 217 231 217 224 225 195 210 211 235 215 197 203 224 226 236 199 246 232 234 227 208 248 223 193 184 229 236 217 202 221 230 224 214 220 267 223 217 222 191 193 217 215 210 209 193 226 208 230 227 202 204 229 218 223 232 222 191 225 214 215 216 208 217 213 204 243 189 229 212 234 183 193 222 243 217 227 232 224 233 220 220 223 228 210 210 230 213 224 243 222 235 191 215 206 185 199 229 222 210 210 233 222 211 225 204 211 215 210 218 219 220 215 224 245 232 223 209 198 245 219 212 195 216 240 216 227 209 210 192 215 212 210 198 218 198 216 233 233 214 228 234 225 240 225 213 222 232 210 228 225 223 226 219 213 239 213 215 191 245 222 212 189 210 216 230 225 214 224 217 199 219 238 217 216 228 205 233 226 201 238 227 222 184 222 197 210 211 223 210 233 197 223 224 216 212 219 209 211 219 232 223 230 223 226 222 218 216 236 203 211 192 217 240 226 240 202 228 238 225 212 217 216 229 217 201 247 223 220 238 259 232 192 220 231 218 229 214 192 207 247 215 177 262 225 230 230 231 213 223 248 218 235 221 214 204 205 239 222 239 225 217 209 212 238 234 233 232 210 221 229 234 221 230 203 188 223 218 232 229 240 216 219 226 229 230 225 241 209 212 227 218 208 233 227 246 234 215 228 189 210 219 238 208 229 210 231 222 207 229 226 211 220 200 216 221 241 234 204 212 201 233 203 230 239 230 219 244 215 218 222 214 215 212 206 215 198 231 212 222 234 214 241 221 230 232 232 210 221 220 207 209 217 174 188 205 229 238 186 198 233 206 207 207 216 202 204 214 242 218 223 241 218 209 233 221 223 190 199 215 222 224 250 247 232 218 192 215 238 255 200 247 245 214 204 215 205 226 207 242 205 250 230 226 244 221 234 228 204 214 226 199 215 207 230 216 257 277 220 213 202 208 220 215 244 211 212 226 216 211 228 199 237 227 204 206 216 199 227 207 197 187 244 190 217 218 195 231 212 224 206 198 220 222 218 255 255 208 224 227 207 217 209 240 219 223 225 274 234 221 218 232 257 226 232 212 224 224 186 224 223 202 212 238 243 227 213 215 231 198 226 241 213 217 236 227 233 242 210 202 232 224 207 211 204 247 233 238 226 226 216 256 214 214 224 211 227 218 246 244 225 218 231 209 208 236 227 202 233 202 225 257 224 190 233 233 198 248 214 235 212 207 241 235 210 227 235 216 227 228 215 241 208 192 217 231 217 225 237 219 241 216 241 213 227 204 199 216 220 210 233 272 218 220 202 241 218 218 228 198 237 231 222 236 234 207 209 216 206 225 196 230 214 243 213 222 236 226 213 239 218 217 245 222 210 213 195 226 222 228 217 217 235 221 229 204 212 232 215 206 187 205 235 223 227 227 208 234 246 206 231 193 221 199 240 200 197 212 221 242 187 222 229 203 222 237 198 221 243 235 208 191 231 212 239 235 215 234 200 221 209 239 211 246 224 205 208 226 247 208 201 209 221 250 206 224 238 207 224 210 215 222 222 226 231 221 223 232 201 259 232 191 210 267 212 214 239 225 263 208 235 221 215 243 246 225 223 214 229 219 210 238 180 256 208 227 217 229 209 226 230 232 229 205 213 187 246 244 228 225 197 224 224 218 228 211 219 224 209 215 221 196 237 207 229 239 222 225 237 218 221 222 230 224 213 199 233 235 237 222 230 215 213 208 210 215 244 232 264 222 188 259 243 230 225 229 233 225 225 214 215 209 206 256 258 224 189 263 229 219 203 223 234 236 238 239 207 236 223 205 237 233 213 269 239 245 240 241 229 224 205 231 242 205 231 202 231 240 188 215 205 210 234 248 203 243 222 219 240 243 233 205 239 211 214 216 221 248 216 235 226 222 220 223 267 209 203 238 229 223 239 220 225 223 229 211 220 227 196 233 214 267 242 255 231 260 212 216 243 222 263 213 244 214 222 209 222 205 216 250 227 217 229 223 238 227 232 243 208 218 222 245 228 233 214 232 228 221 212 240 234 234 206 202 233 230 224 209 244 250 213 233 229 190 228 216 244 230 213 201 255 226 212 220 208 210 229 210 249 245 211 218 236 220 238 229 217 240 225 227 238 243 239 202 200 225 258 220 209 218 238 230 237 228 211 211 242 211 208 241 221 228 198 247 213 271 232 211 247 230 230 221 215 228 245 199 235 235 236 227 219 208 244 263 265 204 237 264 202 211 210 214 225 220 234 230 215 226 222 219 200 219 229 225 223 223 223 264 207 215 232 263 227 214 230 213 176 222 229 223 196 212 271 221 213 222 227 202 216 236 209 231 225 206 221 224 257 240 230 227 212 228 220 228 218 255 225 236 236 245 214 250 210 223 229 262 241 213 232 240 213 223 212 217 216 216 208 204 240 221 219 221 222 197 224 194 234 220 237 223 232 244 233 216 202 219 216 239 219 221 249 248 199 225 231 243 244 226 260 216 229 217 233 218 268 237 245 223 244 238 222 229 210 257 219 208 257 213 242 249 235 223 227 230 245 225 277 218 241 228 261 229 236 209 218 256 259 247 248 233 242 231 224 221 209 199 232 227 228 262 231 204 240 257 235 248 229 224 229 228 248 232 244 210 194 227 206 242 233 214 243 208 200 212 227 208 223 222 219 213 215 234 221 243 263 216 266 237 228 222 218 206 222 211 239 221 223 193 246 232 255 242 238 237 222 212 207 246 232 229 239 197 211 256 227 228 197 226 221 239 203 197 206 230 221 236 213 216 209 221 273 209 232 205 211 211 231 240 225 227 234 196 224 214 210 233 245 222 192 224 225 220 213 218 212 198 232 246 207 234 231 215 210 211 212 240 213 229 236 218 205 248 243 235 190 205 243 217 225 225 221 240 200 247 233 241 204 209 216 214 231 192 215 238 228 224 212 236 244 210 241 221 208 237 225 215 205 246 223 220 223 223 208 212 217 215 214 225 209 224 232 192 206 211 210 237 209 209 212 248 241 265 219 204 212 230 217 240 226 211 223 201 214 242 216 216 235 222 232 216 214 214 219 225 243 214 236 207 192 223 227 195 216 239 231 240 231 237 216 255 226 213 232 228 207 219 198 213 214 211 205 216 224 209 241 222 208 223 206 209 218 200 201 223 214 220 222 221 221 202 226 229 272 228 228 214 258 191 225 228 211 204 213 234 217 220 231 210 243 206 210 211 235 236 194 203 231 244 230 218 202 259 217 241 224 223 219 202 206 226 256 243 257 222 238 220 209 234 224 199 211 229 239 225 222 235 230 246 230 242 205 235 220 225 219 188 230 228 221 211 260 229 197 227 217 233 185 239 234 200 208 208 239 203 226 230 248 223 221 230 228 221 209 226 209 240 224 220 232 220 220 215 218 187 205 236 234 222 207 213 237 199 229 224 205 215 234 241 246 232 215 206 213 221 241 223 227 208 223 228 244 237 223 243 191 214 203 215 219 229 222 228 227 225 206 189 233 227 236 197 242 210 234 225 210 211 198 215 240 211 229 233 191 262 230 242 197 231 202 245 209 224 217 229 225 210 225 225 218 208 236 215 226 222 241 197 243 243 219 229 238 217 221 219 204 248 218 222 182 212 215 230 211 217 234 241 220 209 220 240 222 235 202 219 255 236 219 226 263 192 221 224 203 214 241 227 240 182 221 205 233 201 219 194 235 249 226 236 195 219 203 236 231 219 249 222 203 193 224 230 224 221 224 260 209 227 192 212 216 196 200 211 225 226 226 224 219 214 219 220 197 191 203 214 216 227 243 218 215 241 243 208 205 208 221 228 235 223 215 220 227 194 226 216 219 227 260 227 215 242 202 233 234 226 215 226 232 234 222 223 245 224 226 216 200 210 209 221 216 202 223 223 210 211 224 208 228 225 224 222 210 216 234 221 211 219 247 239 227 228 195 231 230 228 202 234 230 238 220 230 235 202 213 169 194 222 239 240 210 268 204 212 233 225 211 226 218 213 225 230 217 230 203 220 204 191 222 227 215 204 225 224 224 228 250 208 235 236 234 191 217 224 232 231 222 218 200 240 217 227 215 218 226 229 232 223 191 212 211 229 220 227 209 209 227 228 227 189 217 193 226 206 228 235 219 230 249 219 213 217 223 234 207 213 221 186 209 217 209 210 222 214 232 216 220 209 224 216 233 191 201 225 224 203 207 222 214 199 199 248 225 215 230 229 212 214 193 207 215 219 244 183 196 213 212 235 238 209 245 217 234 230 218 220 256 190 218 217 206 233 230 212 201 205 228 219 194 229 226 233 236 226 228 216 219 195 232 213 218 222 223 226 245 204 213 221 203 235 207 206 193 244 195 205 219 202 237 228 201 239 197 222 217 217 235 230 234 238 202 193 207 203 221 217 225 233 223 205 215 199 214 228 221 220 209 203 203 216 218 206 207 232 191 235 228 212 231 207 227 207 235 222 217 202 204 207 224 198 236 203 218 192 231 229 212 229 216 218 226 233 208 197 221 213 222 203 211 225 216 234 208 197 223 217 222 223 231 205 216 237 187 201 227 223 216 200 230 209 212 201 205 226 213 186 214 218 232 208 197 227 230 228 185 224 212 219 214 215 216 212 216 209 221 213 211 230 216 262 200 229 237 185 224 221 211 205 230 199 203 214 246 250 194 205 226 208 224 227 202 237 203 228 208 188 230 217 217 221 212 208 216 217 217 207 231 210 234 226 241 201 228 210 237 210 209 226 221 225 221 202 218 201 220 226 223 206 237 215 204 212 218 217 244 240 244 199 196 207 238 228 205 228 207 210 231 236 188 261 243 240 227 218 255 231 257 208 189 197 219 229 184 237 190 200 205 210 204 219 188 238 209 223 205 203 231 229 225 223 222 224 225 223 210 224 219 196 235 237 206 232 194 213 200 204 195 203 231 203 210 230 213 233 208 226 215 226 219 204 207 234 232 250 224 233 220 230 224 259 226 226 245 231 223 225 197 184 218 211 232 240 215 235 219 232 218 235 244 238 217 187 220 225 239 220 217 235 220 232 255 236 243 211 230 197 239 209 249 216 217 210 229 205 202 219 214 227 256 221 202 230 205 244 228 204 202 214 190 234 232 219 207 221 190 200 210 230 228 226 247 226 221 197 231 233 199 223 196 275 225 211 231 216 214 243 256 228 203 215 210 222 217 213 225 250 218 210 219 220 228 203 239 208 217 208 215 236 224 257 191 229 220 191 205 222 201 184 211 226 202 232 232 230 235 222 237 247 199 195 257 218 220 215 223 204 217 205 209 257 230 236 223 233 230 207 229 218 190 215 215 211 216 209 229 203 213 218 193 198 225 203 219 204 213 206 228 212 216 221 235 226 213 195 231 234 219 200 204 190 204 218 224 211 205 226 212 216 198 178 221 216 193 209 206 234 208 222 209 216 205 232 241 216 208 218 226 206 211 228 212 199 233 225 218 211 246 212 197 207 206 211 222 213 230 225 224 242 200 233 220 236 209 204 234 176 221 217 227 240 240 255 189 220 207 209 204 231 218 234 190 207 221 226 212 208 260 240 221 211 212 212 236 216 205 233 244 223 230 198 204 222 211 202 215 220 226 229 229 236 217 205 215 230 241 230 257 222 232 229 224 240 212 206 228 229 211 187 205 207 233 227 197 241 210 213 194 207 235 208 220 214 203 225 209 237 241 196 233 198 218 227 183 225 204 189 218 226 235 214 255 216 238 231 216 219 235 206 218 261 223 224 229 201 221 184 235 229 228 202 262 199 216 226 215 221 225 218 216 217 213 268 206 230 176 242 206 208 223 225 225 192 247 221 181 205 223 214 208 199 217 241 205 223 184 228 222 218 237 211 216 220 212 216 177 230 227 178 228 220 179 214 223 239 208 195 244 214 192 245 208 225 190 229 213 208 214 231 208 235 228 231 219 235 234 197 208 213 205 210 206 215 223 229 223 274 199 244 214 221 221 185 197 225 219 219 199 218 206 221 243 227 203 216 200 234 274 218 217 209 226 204 211 231 217 216 220 220 207 210 218 225 196 210 216 237 211 222 218 192 221 213 225 210 227 223 225 194 209 220 223 237 224 206 197 204 262 236 180 216 213 200 223 209 213 245 219 193 236 239 239 231 223 211 231 209 189 194 212 245 220 215 202 238 213 217 219 210 212 225 224 209 204 224 241 228 201 212 227 256 205 208 213 259 219 218 220 227 193 212 191 209 234 231 224 229 204 225 231 231 231 207 226 213 220 219 205 222 226 208 235 215 209 191 203 222 211 212 209 233 191 216 194 218 216 188 232 228 201 206 244 234 218 205 233 214 200 212 212 226 262 247 206 258 220 199 212 235 198 236 234 225 243 225 220 199 241 200 199 227 213 216 220 229 216 214 210 223 214 219 220 210 233 224 221 232 226 230 205 222 212 226 245 202 236 207 243 241 205 233 230 214 224 220 228 239 224 210 259 236 212 257 233 228 235 233 231 205 230 238 211 223 244 266 232 239 215 236 223 270 230 250 262 236 269 217 262 237 237 242 234 240 258 241 264 274 260 228 247 249 261 279 257 230 262 247 225 277 212 239 262 255 240 241 238 271 222 236 237 240 229 248 235 214 216 256 256 239 233 245 248 225 227 225 235 257 217 220 224 227 229 233 224 236 214 226 231 207 229 209 233 233 219 227 214 240 219 207 204 229 235 227 209 229 213 229 242 208 224 223 240 230 215 229 206 208 206 204 217 220 231 224 227 231 211 229 230 207 230 213 226 213 206 236 209 193 217 222 202 216 214 223 227 207 208 224 230 196 221 211 214 206 227 187 219 239 220 208 201 239 215 225 227 187 213 202 230 241 221 242 223 208 214 259 243 214 197 233 226 225 180 218 201 218 207 201 235 218 195 214 233 213 209 190 210 211 224 210 206 217 197 212 230 216 219 208 222 197 196 215 222 227 246 218 226 174 248 207 204 209 213 227 221 214 200 244 229 223 215 267 236 213 213 226 236 245 235 212 210 222 211 217 201 199 178 222 240 181 230 221 215 227 220 244 202 201 213 213 211 219 197 194 202 200 212 202 205 228 196 222 210 220 228 211 205 228 238 230 220 194 221 219 199 233 230 190 224 235 218 198 225 215 238 208 216 194 220 199 204 231 191 218 194 203 224 206 219 193 229 211 214 187 206 205 201 240 199 221 232 221 203 211 227 197 210 189 213 202 173 197 234 195 223 218 204 197 239 234 218 224 224 198 203 207 208 229 233 174 216 207 202 192 225 259 225 201 204 212 212 215 205 219 222 210 233 195 216 222 230 215 202 237 208 231 208 235 213 208 214 198 220 204 213 225 211 228 228 206 207 210 205 234 230 225 220 208 195 190 205 230 215 222 211 193 202 221 192 207 220 218 209 199 186 235 209 214 210 221 200 241 226 229 232 200 204 202 200 227 198 200 224 205 218 230 204 208 180 201 225 223 241 208 225 214 192 200 212 224 206 202 212 210 220 240 216 236 218 219 199 211 220 232 224 230 209 222 210 217 211 181 196 215 219 220 189 224 244 217 196 225 199 213 177 227 207 180 191 200 209 218 215 199 174 201 183 222 196 222 219 206 194 228 218 208 199 207 208 205 227 219 199 192 216 201 215 215 230 211 210 203 223 181 229 221 198 209 201 207 192 222 207 213 198 186 199 209 222 220 212 208 221 219 216 206 202 201 205 190 234 205 179 209 207 187 233 201 207 218 211 225 206 201 183 218 218 193 206 198 188 225 201 221 206 175 206 204 222 194 224 196 200 185 214 211 209 203 210 200 218 206 230 209 200 229 186 211 195 181 217 186 206 195 196 211 202 191 235 208 220 206 218 180 210 190 200 189 205 211 211 216 205 229 198 212 216 203 196 208 213 211 197 206 207 215 205 226 221 213 193 200 193 233 194 227 216 218 203 202 232 216 196 177 193 210 213 201 194 208 208 237 213 195 218 208 219 229 209 238 201 224 198 223 214 225 194 210 214 200 206 238 197 218 200 186 201 220 241 229 227 191 232 202 204 190 183 204 220 205 195 194 213 192 211 233 195 244 225 176 187 213 205 200 202 200 199 198 177 220 200 216 189 225 199 206 224 243 205 206 216 200 230 207 202 217 186 199 178 206 214 169 220 183 194 216 237 214 204 186 209 204 193 206 192 199 191 218 216 226 186 180 231 217 192 201 222 202 223 215 187 207 204 217 214 190 215 204 209 215 202 225 215 228 209 202 208 207 207 227 219 196 206 219 225 211 194 220 206 224 228 214 184 223 238 195 193 206 223 214 215 209 235 226 232 211 236 204 201 213 206 223 203 189 196 210 213 195 214 211 196 218 205 190 203 220 234 211 217 203 208 213 199 219 194 194 205 202 210 190 223 173 218 201 216 216 200 223 189 185 228 202 212 188 196 195 192 200 231 235 216 200 200 216 207 212 175 212 216 200 204 217 215 203 214 211 203 229 207 203 222 206 217 208 202 211 230 203 180 231 198 208 203 195 203 216 199 204 193 221 222 225 194 205 185 191 201 212 217 233 222 221 206 204 204 208 215 224 211 187 192 186 231 228 191 208 217 174 202 210 180 247 199 169 204 214 194 210 235 218 200 189 202 202 240 186 196 214 187 218 194 214 205 220 212 216 205 217 213 209 219 201 256 202 194 209 223 220 241 229 218 196 207 199 187 215 186 235 192 215 234 194 190 203 204 238 209 217 224 210 183 196 215 200 189 198 238 190 205 224 204 210 217 210 183 211 202 222 219 211 207 225 184 209 216 213 197 211 195 199 194 201 205 236 212 206 187 208 215 199 192 215 208 257 213 215 206 202 221 239 226 203 182 208 217 194 198 201 209 199 212 216 220 205 215 210 205 218 221 190 210 198 215 219 217 210 227 210 195 217 219 200 197 186 194 217 197 218 192 218 197 207 188 213 188 200 199 231 249 197 220 223 206 198 224 206 209 196 186 189 221 234 218 202 213 230 198 221 224 217 179 204 206 230 215 207 192 197 207 172 211 204 202 188 210 191 198 223 204 205 199 184 207 211 199 210 201 190 207 194 189 218 194 212 191 199 204 176 187 199 186 223 226 200 228 200 190 214 199 200 203 192 233 216 228 172 230 194 263 199 225 212 219 224 200 200 207 208 204 233 204 227 217 210 184 242 198 216 210 197 208 210 208 210 234 207 204 207 195 217 213 194 181 231 241 216 227 214 191 214 199 194 202 202 226 219 221 231 211 228 244 216 201 222 207 192 216 221 244 230 218 227 219 238 216 204 213 215 189 195 211 226 210 208 199 220 197 205 238 207 227 202 220 218 224 194 212 186 194 201 214 190 232 218 205 198 169 205 188 214 229 194 211 212 193 228 219 201 200 209 193 224 205 214 221 210 188 211 203 186 241 195 208 205 204 208 206 222 204 203 240 193 211 201 223 218 211 216 243 218 216 206 226 202 204 198 226 221 188 202 212 192 230 221 231 212 221 192 220 222 207 214 206 213 241 200 226 214 204 223 213 222 197 240 215 230 214 189 189 198 203 235 190 211 210 191 227 217 203 212 196 211 191 224 208 204 216 200 209 200 227 221 218 181 197 223 223 190 208 200 227 203 231 213 220 203 204 194 221 230 188 207 233 207 210 197 200 194 233 208 223 241 213 213 207 207 202 237 219 183 225 213 213 191 225 180 220 245 236 214 219 204 205 198 214 220 186 198 204 187 214 195 203 206 193 203 191 208 213 219 227 215 187 204 186 215 229 222 192 208 234 198 216 196 209 207 219 199 223 215 200 192 219 202 202 206 204 219 229 214 217 211 210 211 209 233 218 218 223 233 192 188 189 216 231 172 202 197 215 206 207 207 233 229 216 209 215 203 202 181 216 171 220 199 224 207 202 206 215 196 212 232 214 187 208 195 185 194 259 200 203 210 230 214 194 215 208 188 213 220 222 205 209 198 199 196 209 222 208 212 210 215 203 186 191 230 206 197 208 219 207 185 221 241 191 212 206 219 201 208 224 223 194 206 199 216 210 223 211 198 229 223 218 240 214 200 231 201 213 209 211 223 182 189 219 212 190 220 212 178 214 198 213 190 196 175 215 195 192 225 206 213 200 230 194 180 228 208 198 213 210 186 208 214 190 211 210 215 201 214 203 232 179 214 213 211 207 227 214 200 208 212 209 212 208 212 212 225 211 199 221 185 184 193 213 209 188 243 235 199 227 197 215 217 212 212 210 207 194 193 205 198 227 214 203 205 210 205 206 205 230 210 204 205 211 210 224 203 220 230 204 238 213 225 206 205 222 219 214 231 203 236 224 223 204 198 239 257 198 234 205 195 214 229 236 217 195 222 202 203 234 221 207 217 226 230 221 224 210 231 213 192 224 231 231 209 210 220 240 210 220 219 245 225 212 193 233 216 216 220 210 232 197 239 215 210 232 230 227 220 211 223 225 246 229 217 197 229 230 205 190 233 234 212 224 228 217 215 231 178 218 212 239 205 229 220 229 196 238 217 218 199 228 198 206 221 206 208 216 193 212 210 211 215 216 185 216 235 220 225 168 221 191 192 204 210 201 235 239 223 211 209 191 208 210 234 225 194 206 228 206 229 224 210 206 206 237 212 201 246 210 226 182 197 227 222 192 205 228 217 199 205 202 206 242 204 233 198 181 226 203 166 195 199 223 212 203 197 223 222 235 215 203 217 211 214 223 249 199 212 215 179 204 202 225 196 198 230 238 230 207 210 228 214 232 222 197 185 205 182 210 225 197 197 200 199 214 212 211 189 202 205 201 204 220 202 201 228 213 199 232 227 206 204 223 198 205 204 189 233 198 204 197 244 200 196 224 196 207 227 212 194 235 209 196 184 210 204 225 212 210 176 213 218 213 197 205 203 217 220 204 198 234 192 218 201 203 221 225 211 210 241 213 206 219 224 229 210 228 207 223 193 214 240 223 219 197 201 210 215 223 244 233 208 231 206 224 194 228 179 205 228 214 206 233 243 182 178 216 222 202 222 208 204 224 214 195 222 204 222 216 184 205 220 177 187 202 211 192 219 207 206 198 213 208 197 202 210 240 224 217 224 225 188 210 195 217 235 168 220 222 205 202 245 212 201 227 171 217 209 227 208 201 170 204 213 220 182 221 209 198 201 213 212 240 243 206 199 178 204 174 224 199 208 218 206 199 200 223 213 211 206 180 227 192 209 182 211 214 210 214 218 197 213 180 240 215 206 197 191 219 202 219 205 203 228 206 211 225 210 226 197 193 229 208 206 204 216 196 223 209 208 222 201 236 208 213 214 191 209 223 218 201 179 188 219 176 192 231 216 210 218 196 208 221 231 219 219 224 198 234 193 198 212 222 217 204 215 193 195 197 201 215 212 190 225 214 209 229 216 197 212 204 199 219 235 190 204 210 202 225 209 198 204 186 216 202 225 202 230 206 204 215 203 228 226 221 219 212 207 236 215 185 230 238 220 218 217 188 227 236 212 208 232 216 222 218 215 230 227 235 216 195 205 201 207 213 219 263 207 183 189 187 198 218 225 215 216 202 224 227 193 217 214 214 205 236 208 242 193 196 217 240 219 198 221 220 220 193 208 211 236 207 207 218 208 203 189 230 235 196 199 215 180 220 220 218 213 192 193 212 217 203 212 240 202 207 239 198 224 211 233 225 193 227 203 210 192 187 235 237 225 208 194 198 240 209 209 213 192 227 204 209 220 205 212 222 196 225 223 211 193 237 198 210 219 231 222 187 212 228 222 212 185 196 216 195 238 203 212 206 202 210 199 216 220 187 227 217 238 216 216 230 209 203 210 194 213 222 195 191 223 183 211 226 199 226 229 218 229 238 203 218 227 192 217 207 211 211 223 231 239 232 236 227 220 202 215 207 227 225 213 213 213 219 224 215 206 220 219 210 223 189 208 202 223 225 205 241 198 225 221 238 231 237 250 218 214 227 205 215 200 209 197 182 205 214 209 201 212 216 224 234 203 207 213 193 196 204 223 211 239 229 210 217 208 224 221 231 229 202 207 218 189 198 212 190 220 206 209 222 214 249 202 223 208 213 213 220 234 241 226 217 183 212 224 195 198 221 196 231 228 221 237 210 237 218 200 222 209 223 200 229 222 232 230 236 255 213 239 194 198 206 229 195 224 200 215 223 234 223 201 222 199 233 213 201 201 227 210 226 233 194 222 212 218 221 205 217 243 186 227 191 207 237 239 204 216 213 213 208 213 194 213 198 213 213 207 212 209 203 242 236 218 211 242 232 197 227 204 204 213 201 241 217 207 211 213 203 206 206 234 219 231 166 227 217 238 226 214 212 185 215 214 201 245 242 235 243 209 186 196 221 206 200 216 224 210 205 228 208 219 201 199 233 239 202 208 212 237 203 202 244 199 197 206 231 214 216 220 220 196 226 195 200 217 212 213 188 238 213 210 246 211 194 198 246 210 225 207 234 199 208 221 205 204 236 221 209 235 200 237 202 225 206 218 223 239 226 249 243 199 182 212 198 238 218 201 230 197 203 227 232 223 232 225 218 195 201 213 215 216 218 214 216 197 198 220 205 230 221 194 223 220 215 215 209 221 229 214 214 212 210 209 203 217 215 245 207 207 188 202 197 198 217 203 187 229 230 209 211 194 213 207 221 214 231 242 232 217 215 245 204 211 209 213 203 207 201 205 174 237 212 196 196 238 225 209 203 228 222 217 218 201 211 196 194 202 210 220 208 190 228 214 218 242 216 197 231 204 218 201 221 233 215 201 189 199 217 213 196 213 194 224 211 219 196 189 222 218 240 196 220 216 217 231 208 228 217 201 221 222 214 257 200 216 246 221 188 195 229 193 189 218 214 223 204 223 223 227 228 217 210 202 244 201 232 225 211 214 194 219 212 224 215 200 198 195 200 207 213 220 219 201 225 203 229 189 256 241 231 207 191 186 210 220 222 215 226 205 215 195 212 194 233 215 216 217 223 218 202 186 207 246 205 197 231 225 202 225 257 179 192 243 225 224 232 222 204 231 213 215 215 174 191 184 218 206 190 242 228 214 199 199 230 225 207 196 196 196 215 212 224 221 211 218 198 235 241 203 223 218 227 222 213 226 210 210 211 240 218 209 204 213 212 204 218 227 212 224 209 199 233 236 215 215 195 235 203 220 203 194 230 191 248 196 228 225 215 221 218 234 193 192 212 222 209 207 218 205 192 215 193 203 231 226 220 230 233 199 218 192 200 229 193 193 237 192 200 212 187 187 222 180 200 209 213 195 206 185 207 226 201 237 220 243 191 210 224 196 172 217 200 236 196 225 215 214 217 233 204 202 208 218 219 220 198 219 194 192 222 223 216 207 189 226 221 213 211 218 203 231 211 221 204 218 214 206 222 214 218 205 213 199 186 207 212 206 227 224 236 214 216 230 209 201 237 232 210 206 246 222 205 202 197 217 241 208 211 199 205 226 214 225 201 214 210 196 226 211 204 224 208 228 220 226 200 204 230 220 204 202 230 224 230 213 217 222 219 216 206 246 240 214 223 195 218 185 206 215 189 237 235 209 221 230 197 211 188 213 210 193 226 203 249 197 219 195 228 200 237 216 206 212 221 215 207 235 235 217 229 226 194 220 214 264 201 198 204 186 231 188 211 230 213 218 226 224 215 220 193 196 223 226 190 215 213 223 234 212 198 217 221 262 246 195 195 171 201 234 210 212 214 203 241 205 233 199 231 196 203 196 211 207 208 216 207 176 206 209 212 219 217 194 226 213 200 228 223 206 200 249 207 231 217 207 222 231 243 206 231 207 213 223 210 218 209 221 220 206 221 216 247 209 216 226 205 213 225 221 214 199 237 211 266 232 212 228 198 190 221 196 212 202 213 202 212 218 218 212 209 237 214 197 207 201 220 232 225 213 207 191 219 217 206 233 232 218 178 260 247 181 212 193 224 213 206 230 208 215 210 198 249 189 198 201 219 216 217 236 209 225 206 214 229 205 191 239 235 217 227 213 186 220 199 216 215 199 219 241 233 217 229 190 197 217 218 212 197 206 211 237 215 218 207 204 219 200 262 225 243 202 212 208 199 212 225 228 207 216 227 213 232 242 224 198 228 214 199 213 229 217 232 222 213 225 194 232 206 205 226 231 207 205 233 226 219 219 218 226 218 244 205 211 231 242 228 219 216 212 231 220 222 198 242 206 223 214 207 208 225 226 215 197 225 237 237 239 236 243 230 227 246 215 213 238 232 243 236 210 237 204 217 209 256 196 213 233 217 201 238 233 217 260 209 197 248 223 224 226 219 217 244 226 217 230 255 199 204 234 241 227 230 233 228 213 259 219 237 239 220 210 223 247 225 221 236 235 231 245 256 225 222 206 208 247 208 236 239 220 240 232 233 238 236 242 207 214 261 235 206 216 223 237 226 225 234 238 238 199 243 261 226 226 235 220 240 239 220 202 215 238 214 199 259 242 239 215 232 226 237 244 211 227 241 249 230 200 224 242 232 215 257 199 239 236 206 230 215 234 223 202 180 238 245 225 220 241 208 224 227 240 218 212 238 230 211 226 204 209 224 272 245 201 227 219 229 198 184 228 250 218 208 230 213 207 238 220 213 210 242 209 213 217 234 213 228 234 217 214 242 231 200 245 195 231 208 196 224 226 205 232 223 231 196 223 220 211 210 223 196 232 242 192 226 220 217 233 214 224 208 193 211 236 224 217 205 216 200 217 222 203 210 199 209 217 210 210 216 205 212 262 206 214 213 217 225 197 197 205 194 220 209 225 227 197 272 187 243 211 211 201 215 214 203 210 207 228 212 235 213 207 221 213 207 205 215 221 206 200 217 217 199 214 200 227 245 217 222 224 214 235 215 227 222 216 225 236 214 197 237 211 197 237 221 215 218 226 236 215 222 215 220 206 216 230 210 208 226 197 208 197 207 213 208 192 221 213 199 210 182 228 210 241 256 208 218 220 195 224 198 220 199 213 238 234 232 198 219 217 199 200 209 214 221 217 206 222 213 220 191 233 192 218 226 215 170 205 225 230 225 211 208 244 197 198 220 223 233 229 207 194 223 212 223 225 207 215 190 190 208 229 214 235 207 214 211 229 229 194 195 223 213 197 238 235 202 210 206 213 209 227 199 208 223 218 212 224 246 196 217 200 209 222 216 234 224 219 228 221 218 216 191 236 218 222 209 194 186 239 203 224 201 205 222 196 210 240 215 243 221 198 219 231 201 231 213 221 230 204 216 220 194 222 227 224 230 198 223 213 205 222 193 230 238 200 186 218 222 220 214 212 266 241 225 231 199 212 197 242 226 209 221 222 212 215 219 231 210 218 206 218 189 224 226 214 224 218 219 206 214 213 216 198 232 191 213 206 212 209 207 204 227 196 203 206 225 195 201 201 247 226 219 212 222 218 210 241 201 212 216 227 203 211 210 196 192 257 199 209 201 216 233 204 197 234 216 218 208 244 223 241 217 187 208 235 217 222 222 212 216 212 211 241 214 224 199 222 208 221 219 205 212 214 203 214 210 222 225 213 239 223 208 210 222 235 187 233 206 237 213 239 215 193 226 188 232 220 207 197 208 193 222 201 196 210 220 226 216 200 214 213 244 215 235 221 219 217 196 207 224 205 213 208 205 224 204 236 211 204 238 198 216 208 233 225 223 226 224 204 215 213 261 184 211 228 222 210 196 228 245 206 207 227 231 223 214 207 209 231 239 195 222 215 198 211 217 233 238 211 200 216 217 209 199 219 205 196 196 209 233 223 225 230 231 206 229 198 216 221 204 214 213 216 192 225 213 240 225 215 195 222 224 212 188 227 215 226 227 213 206 215 218 224 192 232 231 211 222 259 214 231 216 208 215 210 239 263 226 217 241 208 210 217 248 239 218 224 219 204 222 233 225 221 212 218 220 205 216 183 219 201 194 213 228 218 224 226 203 237 203 220 218 224 246 203 221 220 201 194 210 202 229 218 208 227 231 215 208 219 234 207 219 244 222 247 223 215 219 204 206 221 205 221 240 209 224 210 222 240 223 199 212 215 215 202 217 203 216 222 219 212 213 195 239 225 213 211 211 218 225 217 222 214 223 213 216 227 240 228 234 203 234 213 205 230 227 238 201 221 222 236 208 214 211 240 234 244 230 219 226 207 218 237 199 230 207 213 239 200 212 225 237 231 228 207 212 222 222 238 216 246 234 232 232 232 215 198 218 210 224 227 232 218 213 228 216 227 243 225 212 211 204 229 234 226 219 228 203 235 235 211 196 219 218 225 220 271 241 219 197 231 230 195 248 218 206 217 213 212 207 223 217 207 233 224 223 209 243 215 234 234 245 216 233 205 220 246 255 229 263 204 210 206 200 227 237 218 215 222 209 234 223 223 258 218 221 241 194 231 209 233 218 210 228 224 197 236 227 212 226 231 216 218 211 211 220 217 209 211 208 240 215 212 221 240 214 228 234 208 238 240 250 229 198 224 220 220 231 215 242 249 230 206 243 216 212 217 220 221 214 215 242 224 184 222 208 202 214 208 217 230 227 234 199 236 225 201 216 255 242 218 207 234 235 236 214 242 247 230 243 264 267 219 265 234 227 215 221 243 217 229 215 228 249 243 206 219 225 266 261 235 219 238 223 237 228 255 214 250 223 236 217 246 240 245 222 215 210 187 222 229 230 203 246 236 224 259 212 239 224 228 212 218 246 242 240 209 246 223 225 224 224 241 210 232 206 211 229 223 216 234 233 243 222 222 236 230 229 214 219 202 209 239 233 201 224 216 246 226 232 207 225 202 233 215 220 228 237 257 223 233 221 211 209 244 257 240 231 212 232 229 233 250 242 229 249 242 208 236 243 201 207 239 220 235 212 223 222 236 229 239 234 229 238 232 217 219 223 240 256 237 213 242 238 267 221 237 233 246 220 238 221 243 244 243 240 233 246 246 236 227 222 235 219 221 226 247 234 223 218 238 219 231 229 218 243 209 258 232 233 245 217 230 233 261 215 237 233 230 226 255 244 214 228 237 239 207 228 231 224 209 208 263 238 216 227 240 201 243 261 228 224 221 208 241 259 240 218 250 260 221 266 236 230 222 246 214 210 240 246 224 224 210 233 224 248 222 260 222 259 236 227 249 222 231 227 220 240 234 242 226 223 235 220 231 249 214 248 227 219 269 229 235 209 259 212 271 259 248 256 237 257 213 218 219 240 236 256 233 248 226 238 239 202 229 248 228 217 216 238 223 224 207 227 225 228 237 242 244 229 228 213 228 231 216 235 215 205 225 227 241 224 215 241 235 223 231 243 234 245 220 248 234 245 225 240 248 249 244 247 221 237 249 239 220 237 240 240 227 226 244 225 230 220 230 213 230 229 230 247 212 256 215 245 208 222 247 207 206 246 230 241 233 221 213 261 226 234 263 226 224 257 238 234 217 243 237 227 231 228 237 268 235 217 239 258 220 219 243 225 226 246 235 237 230 243 219 216 211 215 233 241 261 249 225 258 227 230 256 221 267 217 216 217 231 247 224 222 259 226 217 226 261 225 220 223 222 203 209 235 223 246 223 233 221 226 227 243</counts>
			</dataPoints>
		</scan>
	</xrdMeasurement>
</xrdMeasurements>