File: data/XRD/XG-Vakuum/XG-500/W6823-1C_XG_Vakuum_500.xrdml
<xrdMeasurements xmlns="http://www.xrdml.com/XRDMeasurement/2.1" xmlns:xsi="http://www.w3.org/2001/XMLSchema-instance" xsi:schemaLocation="http://www.xrdml.com/XRDMeasurement/2.1 http://www.xrdml.com/XRDMeasurement/2.1/XRDMeasurement.xsd" status="Completed">
	<comment>
		<entry>Configuration=Factory configuration, Owner=User-1, Creation date=7/8/2013 4:01:53 PM</entry>
		<entry>Goniometer=PW3050/65 (Theta/2Theta); Minimum step size 2Theta:0.0001; Minimum step size Omega:0.0001</entry>
		<entry>Sample stage=MRD Cradle; Minimum step size Phi:0.01; Minimum step size Chi:0.01; Minimum step size X:0.01; Minimum step size Y:0.01; Minimum step size Z:0.001</entry>
		<entry>Diffractometer system=XPERT-PRO</entry>
		<entry>Measurement program=C:\PANalytical\Data Collector\Programs\Jorrit\2thom\_absolute_2th-om_10-130deg_PIXscan_56min.xrdmp, Identifier={15BCCF57-2807-42BD-B5B9-ECC0B3DC9284}</entry>
		<entry>Batch program=C:\PANalytical\Data Collector\Programs\SimonL\batch4x_2thom_10-130°_z9.1_x0,10,20,30_y0_57min.xrdmp, Identifier={EED9823A-2BEB-424C-9252-345C4EF2834A}</entry>
	</comment>
	<sample type="To be analyzed">
		<id></id>
		<name></name>
		<preparedBy></preparedBy>
	</sample>
	<xrdMeasurement measurementType="Scan" status="Completed" sampleMode="Reflection">
		<comment>
			<entry>_absolute_2th-om_10-130deg_PIXscan_56min</entry>
			<entry>PHD Lower Level = 4.83 (keV), PHD Upper Level = 11.27 (keV)</entry>
		</comment>
		<usedWavelength intended="K-Alpha 1">
			<kAlpha1 unit="Angstrom">1.5405980</kAlpha1>
			<kAlpha2 unit="Angstrom">1.5444260</kAlpha2>
			<kBeta unit="Angstrom">1.3922500</kBeta>
			<ratioKAlpha2KAlpha1>0.5000</ratioKAlpha2KAlpha1>
		</usedWavelength>
		<incidentBeamPath>
			<radius unit="mm">320.00</radius>
			<xRayTube id="1010048" name="Empyrean Cu LFF HR (9430 033 7310x) DK442154">
				<tension unit="kV">40.0</tension>
				<current unit="mA">40.0</current>
				<anodeMaterial>Cu</anodeMaterial>
				<focus type="Line">
					<length unit="mm">12.0</length>
					<width unit="mm">0.4</width>
					<takeOffAngle unit="deg">4.2</takeOffAngle>
				</focus>
			</xRayTube>
			<xRayMirror id="27010001" name="Inc. Beam Cu W/Si (parabolic MRD)" hybrid="false">
				<crystal type="Graded" shape="Parabolic">W/Si</crystal>
				<acceptanceAngle unit="deg">0.800</acceptanceAngle>
				<length unit="mm">60.0</length>
			</xRayMirror>
			<sollerSlit id="21010002" name="Soller slits 0.04 rad.">
				<opening unit="rad">0.0400</opening>
			</sollerSlit>
			<mask id="22030008" name="Fixed mask 4 mm">
				<distanceToSample unit="mm">220.00</distanceToSample>
				<width unit="mm">4.00</width>
			</mask>
			<divergenceSlit id="22010007" name="Fixed slit 1/8°" xsi:type="fixedDivergenceSlitType">
				<distanceToSample unit="mm">220.00</distanceToSample>
				<height unit="mm">0.19</height>
			</divergenceSlit>
		</incidentBeamPath>
		<diffractedBeamPath>
			<radius unit="mm">320.00</radius>
			<sollerSlit id="21010002" name="Soller slits 0.04 rad.">
				<opening unit="rad">0.0400</opening>
			</sollerSlit>
			<receivingSlit id="22010001" name="Fixed slit 4°">
				<height unit="mm">5.88</height>
			</receivingSlit>
			<detector id="7010017" name="PIXcel3D 1x1 detector" xsi:type="areaDetectorType">
				<phd unit="%">
					<lowerLevel>30.0</lowerLevel>
					<upperLevel>70.0</upperLevel>
				</phd>
				<mode>Scanning</mode>
				<activeChannelsEquatorial>255</activeChannelsEquatorial>
				<activeChannelsAxial>255</activeChannelsAxial>
				<pitchEquatorial unit="mm">0.05500</pitchEquatorial>
				<pitchAxial unit="mm">0.05500</pitchAxial>
				<readOutPeriod unit="seconds">0.135</readOutPeriod>
			</detector>
		</diffractedBeamPath>
		<scan appendNumber="0" mode="Continuous" scanAxis="2Theta-Omega" status="Completed">
			<header>
				<startTimeStamp>2024-10-07T18:59:05+02:00</startTimeStamp>
				<endTimeStamp>2024-10-07T19:55:11+02:00</endTimeStamp>
				<author>
					<name>PRO-MRD</name>
				</author>
				<source>
					<applicationSoftware version="6.1b">Data Collector</applicationSoftware>
					<instrumentControlSoftware version="7.0E 20130304">XPERT-PRO</instrumentControlSoftware>
					<instrumentID>0000000011142674</instrumentID>
				</source>
			</header>
			<dataPoints>
				<positions axis="2Theta" unit="deg">
					<startPosition>9.99826193</startPosition>
					<endPosition>129.99755682</endPosition>
				</positions>
				<positions axis="Omega" unit="deg">
					<startPosition>4.99913096</startPosition>
					<endPosition>64.99877841</endPosition>
				</positions>
				<positions axis="Phi" unit="deg">
					<commonPosition>0.00</commonPosition>
				</positions>
				<positions axis="Chi" unit="deg">
					<commonPosition>0.00</commonPosition>
				</positions>
				<positions axis="X" unit="mm">
					<commonPosition>20.00</commonPosition>
				</positions>
				<positions axis="Y" unit="mm">
					<commonPosition>0.00</commonPosition>
				</positions>
				<positions axis="Z" unit="mm">
					<commonPosition>9.100</commonPosition>
				</positions>
				<commonCountingTime unit="seconds">32.895</commonCountingTime>
				<counts 386 416 389 431 405 441 388 390 386 424 424 383 394 413 386 413 398 387 438 377 399 402 413 413 392 416 399 441 376 414 385 390 391 376 451 442 406 438 441 367 424 421 395 417 393 427 411 430 438 370 476 407 445 440 391 429 392 418 421 388 396 415 393 383 398 395 400 394 411 384 414 387 388 405 382 363 390 410 409 354 425 412 433 370 390 372 385 364 412 363 378 401 380 416 380 365 370 359 398 393 370 371 379 380 368 365 327 354 377 401 400 386 385 408 384 367 378 393 402 400 375 370 412 358 392 371 348 379 406 379 410 383 357 428 361 386 337 375 369 396 363 388 402 354 381 390 380 374 370 393 416 349 358 371 388 387 346 337 398 373 352 354 346 357 349 343 409 376 371 349 336 357 382 357 370 358 341 371 333 350 377 364 343 373 382 366 362 318 382 344 363 384 340 343 343 373 341 379 368 370 402 363 371 361 357 376 353 332 358 378 350 345 356 376 382 350 381 349 357 364 349 340 322 361 352 325 373 343 388 349 356 377 366 368 368 336 355 347 370 341 329 336 409 360 314 351 383 370 346 357 352 308 355 335 333 350 349 368 351 320 316 341 378 338 346 354 363 360 344 360 369 364 345 338 349 417 305 387 342 345 360 348 344 340 353 338 334 322 362 368 373 319 337 345 356 327 333 317 357 342 344 307 355 328 378 335 350 344 335 318 341 333 315 333 353 315 340 312 311 331 342 309 323 361 317 326 358 301 316 354 356 329 320 342 315 386 320 371 363 298 335 344 335 317 314 340 348 295 303 315 316 327 317 321 319 308 344 361 316 340 347 330 320 320 331 335 319 321 307 304 338 326 343 337 312 328 322 332 324 300 316 342 328 284 331 329 322 329 321 312 327 331 325 320 347 320 312 312 309 327 347 339 374 308 313 335 301 320 341 299 329 325 307 306 289 309 310 315 313 299 325 304 309 328 297 320 271 293 311 332 314 299 341 309 326 332 324 322 330 323 337 338 335 297 313 273 290 315 331 305 299 299 298 311 301 333 288 303 325 310 303 279 304 296 277 297 331 293 300 297 301 306 300 315 296 323 310 322 323 293 287 299 289 298 312 318 328 331 272 295 306 310 329 321 291 287 287 263 315 299 334 326 313 279 315 310 307 288 296 306 280 308 322 315 324 292 285 306 295 289 287 317 315 283 317 295 280 307 349 311 306 288 277 262 283 280 283 303 330 302 313 301 285 312 286 284 261 282 292 286 298 292 294 311 293 312 322 283 331 293 294 300 292 278 276 298 282 308 342 270 281 289 283 296 294 295 306 298 265 297 260 288 274 298 270 302 269 288 280 293 273 246 276 290 286 283 299 285 301 280 289 282 317 276 282 284 290 294 282 300 320 281 272 264 247 307 283 293 299 291 278 291 276 291 293 289 275 295 272 307 289 292 298 315 287 268 274 299 286 302 286 293 261 272 297 320 273 305 306 282 281 298 269 265 293 272 261 265 259 298 273 311 310 275 269 290 290 298 325 263 292 276 300 262 291 289 321 299 280 305 311 288 319 279 306 242 314 311 259 289 263 275 295 300 280 298 318 281 260 285 265 286 288 300 304 297 243 290 290 270 260 290 282 314 284 311 285 307 292 282 278 319 281 274 293 284 332 334 291 286 297 271 260 285 274 288 271 284 291 296 309 290 258 294 280 241 275 287 286 306 283 308 255 311 300 267 273 303 299 288 295 285 302 273 239 291 284 290 274 270 285 311 263 281 272 282 285 258 276 293 248 296 257 274 326 297 313 294 302 284 328 317 304 267 259 278 287 247 299 296 325 287 309 290 269 292 273 272 285 280 292 292 282 310 281 291 319 292 269 279 274 256 297 312 294 278 297 285 289 273 264 264 275 290 269 309 297 277 281 335 282 313 298 275 319 294 314 294 300 294 265 262 274 305 285 282 297 271 289 270 282 315 288 275 268 289 279 280 301 289 265 274 259 280 299 295 297 289 301 306 279 257 280 274 324 309 256 273 296 294 306 277 315 309 284 315 276 311 259 285 286 311 287 297 289 292 249 301 272 290 268 280 267 237 314 286 277 292 285 312 304 298 286 282 294 272 284 244 297 280 302 285 293 324 329 306 310 294 272 310 291 262 284 299 261 275 285 260 310 278 272 288 292 285 286 324 278 306 302 290 293 273 296 298 292 295 310 276 308 289 317 290 323 293 300 322 299 291 282 315 257 270 302 276 296 285 270 316 330 309 316 279 273 322 318 315 359 308 275 291 298 297 275 315 306 307 299 329 320 308 272 301 291 283 317 305 329 311 290 314 293 288 310 314 306 257 297 277 298 312 274 285 291 300 307 290 304 297 324 311 338 291 291 297 306 314 285 318 309 301 310 315 312 326 308 283 312 275 305 297 351 306 309 297 293 297 298 297 333 280 306 305 250 306 283 322 291 315 322 315 314 307 293 312 303 301 293 288 302 302 283 312 291 305 307 311 311 300 291 286 277 285 333 290 331 323 327 321 300 316 321 286 316 284 309 315 309 294 323 311 265 315 329 293 314 299 364 322 283 299 320 323 322 302 290 334 326 310 310 297 308 346 314 303 344 310 342 318 293 298 327 313 322 290 314 300 345 291 296 308 310 319 343 324 314 332 302 296 347 316 328 321 309 355 298 318 312 294 308 311 324 314 308 334 322 361 327 309 355 313 344 311 321 356 324 343 311 308 298 337 311 300 306 339 314 299 339 298 323 291 297 315 336 328 307 325 322 298 317 306 309 315 332 316 324 313 340 291 326 311 338 330 309 336 324 284 353 321 347 390 291 341 357 333 316 347 340 321 329 313 327 307 325 337 293 328 311 317 342 325 340 296 327 334 293 320 300 300 306 327 329 334 290 324 334 311 309 345 377 325 350 308 340 309 300 294 316 342 296 297 315 350 337 303 328 321 321 340 366 297 310 336 297 318 307 325 307 328 328 341 319 332 328 328 296 303 314 326 345 321 327 304 317 319 311 319 306 309 288 316 291 315 309 316 320 330 350 317 315 333 331 330 368 301 313 311 318 332 328 310 307 301 310 357 338 325 305 317 301 343 290 347 317 346 341 333 296 309 350 303 354 318 341 329 315 309 309 330 321 323 334 324 318 329 335 314 332 333 329 294 337 291 347 316 344 331 310 321 351 334 326 326 324 326 306 310 341 288 320 307 291 312 322 360 310 330 346 303 307 340 330 338 316 337 308 331 334 307 281 314 281 337 341 337 309 332 346 322 296 298 313 322 329 324 312 332 326 335 333 302 298 315 335 305 314 315 306 307 309 351 339 347 312 319 332 298 317 329 344 306 339 311 313 323 321 291 331 304 331 313 292 304 329 334 325 325 326 315 297 310 316 325 319 324 332 292 341 330 326 290 310 341 323 309 310 294 315 336 318 291 334 304 314 325 290 298 325 309 356 289 293 333 321 312 329 359 315 321 295 307 311 309 308 339 286 315 288 330 294 299 307 270 298 325 286 290 302 286 321 275 306 313 315 281 303 312 304 307 311 309 309 293 326 323 325 299 305 294 328 296 303 308 323 341 308 337 315 308 314 291 297 298 283 321 310 310 294 318 288 283 296 279 333 303 322 297 294 289 299 328 267 317 299 330 275 274 306 313 291 298 320 304 319 341 315 277 313 289 284 283 313 306 297 304 268 280 281 287 301 309 293 288 317 294 305 311 320 308 301 319 313 287 261 294 303 287 296 293 294 278 312 299 329 289 300 322 271 260 294 295 294 283 303 313 297 321 280 266 259 320 287 315 305 292 270 312 307 258 301 287 302 255 283 278 277 272 300 305 294 276 280 290 268 303 257 296 314 289 271 320 279 284 298 284 277 277 282 298 303 276 272 248 275 304 267 283 268 308 292 277 287 248 289 309 273 283 287 232 269 293 279 307 270 291 297 291 287 289 307 270 298 258 289 264 270 288 298 270 280 267 265 269 308 283 308 282 263 291 263 283 276 275 312 266 288 274 298 276 280 234 273 255 287 271 291 281 311 248 296 282 270 277 272 289 276 244 295 271 265 257 294 288 288 264 276 263 308 269 299 244 285 262 292 280 260 280 259 285 262 275 220 276 274 257 276 278 270 243 258 300 238 270 268 259 290 286 281 296 272 261 267 262 287 283 243 259 266 250 227 263 243 241 266 299 298 279 273 260 237 271 265 258 276 250 289 279 282 291 297 210 269 232 288 262 261 277 246 269 273 264 233 267 261 273 264 274 242 245 246 272 258 239 260 237 240 268 274 294 260 277 264 266 280 258 268 246 266 255 236 231 264 257 221 242 226 281 283 255 273 243 259 256 260 247 244 261 230 240 269 270 242 258 274 269 258 282 258 214 228 229 259 248 269 222 238 239 249 265 255 278 242 248 279 284 237 237 261 274 236 275 242 230 246 255 261 269 228 233 273 215 266 223 278 276 237 255 267 250 248 245 262 278 258 256 242 237 247 229 262 272 265 246 233 278 231 241 237 261 259 228 238 273 226 259 270 238 220 274 230 264 256 242 245 270 230 257 255 265 231 229 272 211 217 230 259 242 234 226 220 257 262 267 219 277 258 258 268 257 225 229 277 222 266 214 216 239 233 242 239 260 249 261 239 286 227 221 238 243 265 223 256 232 245 242 240 233 230 230 221 247 227 266 226 241 263 216 241 214 262 248 233 238 248 237 215 244 232 223 258 255 248 239 228 247 240 269 255 235 266 229 229 236 235 230 226 238 230 231 214 270 227 227 226 217 266 229 256 228 235 229 248 241 219 258 247 232 235 262 219 225 238 218 224 224 262 246 226 226 242 242 267 197 227 234 244 237 264 266 221 243 232 248 248 261 214 236 240 211 241 232 215 234 220 221 243 247 248 210 263 249 255 246 241 205 226 224 204 241 283 242 226 271 241 235 227 237 224 229 197 257 245 228 233 211 221 195 249 224 227 235 239 211 222 226 255 261 229 244 225 220 238 227 242 224 249 212 232 217 241 240 237 212 245 225 215 262 211 241 212 198 220 223 271 225 231 244 229 231 214 248 237 225 237 242 245 230 234 276 237 239 220 233 224 235 245 243 238 241 221 261 227 270 227 236 225 230 222 230 221 214 233 223 221 246 257 226 228 197 275 238 243 232 209 223 255 212 231 240 242 232 246 209 225 248 219 224 216 200 232 217 262 232 272 237 222 245 212 197 229 220 236 219 219 212 228 230 226 218 198 239 219 238 232 203 222 227 238 229 241 203 220 212 226 210 219 212 231 226 224 236 219 208 225 203 206 225 235 212 239 245 231 257 229 210 261 206 232 221 239 256 240 220 204 238 208 244 227 226 239 229 222 222 237 224 234 219 208 222 208 228 219 256 259 202 238 224 226 257 209 211 226 260 263 219 233 241 201 191 238 247 228 222 219 220 211 228 207 242 219 240 229 212 237 195 206 246 209 223 209 227 232 224 213 227 242 224 224 222 244 201 212 212 228 217 200 223 194 226 216 228 245 206 199 220 256 242 239 232 208 217 214 193 213 203 214 209 213 256 208 227 223 214 231 234 212 204 202 246 210 247 228 208 246 235 220 205 237 215 233 216 202 194 228 236 212 210 215 210 242 216 242 234 236 222 217 214 228 233 239 224 224 233 236 189 188 200 220 237 222 193 228 237 218 208 228 214 224 238 231 223 198 193 206 208 217 217 199 225 216 218 231 210 227 225 215 195 216 208 216 225 239 224 222 216 210 206 223 207 219 228 211 213 217 234 249 219 221 223 264 218 201 190 222 216 218 224 215 213 242 228 241 211 209 247 217 216 237 216 212 184 215 245 219 200 241 216 214 214 196 211 218 193 211 209 214 209 255 244 194 220 211 223 209 219 205 206 213 223 207 227 210 211 241 188 200 225 216 236 204 202 213 211 216 225 207 197 197 243 213 188 224 202 223 223 214 222 209 226 203 208 217 206 203 222 205 211 226 230 232 221 219 220 213 203 215 214 190 219 221 214 230 225 206 228 236 192 235 204 222 192 198 218 227 249 243 198 219 238 203 231 179 234 212 208 212 242 223 210 242 210 243 229 207 229 217 223 217 235 217 221 206 224 200 229 210 209 193 220 203 205 225 228 214 190 197 217 208 200 197 215 212 221 214 231 216 246 188 195 236 200 196 207 207 200 203 206 191 214 226 222 209 216 250 196 202 237 206 232 211 234 211 214 226 211 201 227 201 213 192 200 206 229 194 260 231 233 229 189 210 230 219 217 228 209 195 212 213 217 217 213 200 242 219 219 210 212 216 220 207 210 210 218 206 218 237 267 226 231 215 210 239 211 214 208 215 235 230 204 215 227 211 213 208 212 233 236 210 230 221 207 236 197 205 242 199 210 202 224 229 220 193 234 230 226 224 203 180 195 212 238 206 203 223 233 219 232 224 216 238 204 249 216 213 220 214 228 211 218 197 212 236 230 228 231 250 173 210 219 238 223 220 224 207 223 225 226 202 218 206 225 209 206 226 179 199 202 264 218 231 204 226 217 236 193 207 227 199 239 218 232 219 201 212 224 233 215 202 237 203 215 203 235 224 221 213 222 195 223 224 222 217 213 198 231 198 202 195 205 211 192 193 227 212 220 224 223 197 209 241 185 216 228 213 244 225 216 204 219 213 216 197 197 213 202 205 220 204 195 237 221 214 215 231 225 233 217 230 243 237 210 233 221 218 209 219 236 203 197 216 223 245 196 194 233 177 217 230 217 221 234 207 217 233 244 195 221 202 225 194 234 240 205 203 210 216 219 201 217 226 194 220 239 202 175 222 232 212 213 216 228 215 200 210 217 211 219 260 213 202 205 198 200 205 218 217 228 207 202 214 236 232 234 218 218 230 204 218 207 213 204 250 224 200 219 204 219 227 211 226 234 222 209 222 238 225 225 212 209 234 209 211 240 240 214 234 209 223 214 212 228 202 222 216 202 205 213 211 187 225 211 229 193 221 241 211 202 200 228 234 225 231 218 216 222 208 205 235 200 216 230 224 241 214 218 213 218 208 233 215 214 213 205 238 203 206 242 215 260 232 204 244 221 215 217 259 221 223 221 206 192 205 183 210 209 211 211 194 221 222 215 226 220 242 213 222 243 245 223 243 233 235 242 214 204 229 213 220 225 224 208 215 212 211 226 201 227 228 232 229 240 222 225 202 230 198 212 218 243 228 223 230 213 243 202 234 265 226 231 223 225 200 238 220 256 241 227 248 248 216 223 213 257 211 216 218 226 232 222 225 182 234 207 214 208 222 224 194 221 210 248 232 226 202 246 226 230 218 222 222 214 227 207 237 250 234 235 223 207 213 228 207 210 238 230 237 229 223 223 205 212 228 221 212 216 247 226 219 198 263 215 255 217 224 214 232 236 215 230 192 224 228 195 206 187 215 234 218 237 226 218 249 234 211 210 212 234 221 223 264 237 233 237 223 211 208 217 215 202 229 212 227 226 233 228 207 232 220 226 216 220 176 242 234 209 249 214 240 204 226 213 215 217 225 216 230 203 194 227 211 233 225 236 205 237 213 212 241 200 233 223 229 224 205 211 216 214 235 231 225 261 216 227 234 211 228 219 226 237 246 217 238 232 223 233 239 241 210 237 223 222 236 228 225 230 228 229 212 231 223 228 248 223 229 215 221 236 249 242 209 273 240 217 238 224 241 221 238 208 216 247 265 230 238 242 228 264 231 255 222 220 263 235 267 236 233 214 232 246 211 281 234 211 220 242 278 264 255 243 268 242 243 280 248 263 270 230 257 236 244 256 244 281 275 269 270 259 289 258 270 269 281 273 275 239 270 313 313 303 314 276 283 294 337 312 316 301 309 327 267 338 319 337 331 367 335 392 366 376 365 390 392 378 398 429 407 410 406 428 393 413 422 391 398 425 403 349 351 370 293 357 343 329 322 326 319 306 307 311 322 304 291 281 332 278 287 300 274 227 271 249 272 278 277 245 223 274 258 268 277 236 262 242 247 232 251 228 237 215 259 249 220 228 257 257 238 208 247 258 237 217 246 228 255 250 257 239 213 233 241 210 272 221 238 237 234 276 203 208 248 232 260 232 243 230 216 198 231 228 231 233 266 228 248 221 215 231 211 233 224 203 242 213 264 204 231 236 231 260 244 242 225 212 266 234 222 237 228 247 230 221 218 255 222 220 223 243 267 223 242 236 209 225 219 220 227 226 239 236 215 218 243 255 236 195 197 230 233 209 248 227 229 236 220 209 224 217 225 225 259 219 226 230 244 245 249 206 211 245 243 248 225 244 247 219 217 220 241 212 234 212 203 255 212 236 237 213 242 214 228 221 248 207 219 221 221 220 222 234 240 226 258 235 232 233 248 217 237 213 228 229 219 218 217 213 225 246 243 255 227 207 216 214 213 209 227 238 231 234 203 214 200 233 242 236 210 226 220 228 232 234 224 255 248 213 225 226 216 239 240 264 242 225 225 231 241 244 241 213 204 232 232 204 201 239 234 241 212 215 263 197 231 218 247 218 234 225 241 212 258 206 212 237 236 231 230 250 212 214 239 249 221 232 242 218 233 234 212 259 224 225 221 260 191 232 226 217 237 225 215 214 207 203 239 232 226 217 255 219 237 223 236 207 250 245 232 255 230 226 209 234 213 203 188 229 238 204 209 215 260 214 225 241 207 232 241 238 200 248 209 219 216 216 225 208 263 225 232 223 232 205 230 230 228 246 225 255 255 213 219 210 195 207 189 205 228 215 235 242 248 233 216 212 212 220 245 220 222 241 224 189 207 225 245 214 213 221 229 199 231 246 240 217 232 240 203 228 223 219 223 256 248 228 220 215 222 243 240 235 281 237 225 217 221 247 248 203 227 227 227 237 223 229 245 211 203 222 236 215 209 229 232 228 229 250 218 232 227 219 246 237 210 206 214 257 222 236 233 247 230 216 241 228 237 220 247 245 235 224 231 236 209 219 222 211 222 240 228 241 230 210 229 237 205 211 225 212 201 237 245 220 228 233 220 208 214 228 219 230 230 196 244 228 263 235 228 234 225 217 248 230 243 232 229 230 224 211 225 229 235 206 208 211 209 213 220 229 221 222 207 229 219 226 202 231 220 238 231 256 227 257 223 223 218 214 192 246 240 221 238 227 242 265 210 213 229 216 219 233 240 225 225 248 234 240 246 225 260 199 210 228 232 222 213 207 224 221 256 241 236 229 208 223 243 255 234 213 219 225 229 250 226 230 234 240 245 203 211 223 236 223 205 212 243 227 207 224 239 202 242 223 237 202 225 231 259 210 214 218 223 238 241 237 230 220 206 239 239 234 213 237 230 213 227 204 210 231 223 259 216 240 246 214 218 206 263 230 212 228 248 212 258 223 222 213 217 256 237 218 258 243 260 227 242 237 224 255 210 220 197 214 219 239 258 213 203 216 237 219 226 231 214 240 232 231 225 225 267 231 231 222 255 209 233 222 244 248 227 230 219 225 255 242 239 243 236 232 234 219 198 206 256 217 204 244 244 229 209 227 246 225 214 206 232 204 234 227 224 219 221 226 245 220 188 237 209 230 224 212 258 233 203 236 243 229 209 234 222 214 229 218 219 210 195 231 237 240 223 242 228 233 238 228 225 241 248 224 235 226 236 241 235 220 204 240 243 212 247 234 210 255 242 240 247 232 224 234 224 236 225 201 261 226 257 226 222 207 231 248 214 199 234 240 221 212 235 214 203 216 222 230 224 234 244 221 218 220 261 230 230 213 262 208 214 201 249 265 237 233 216 226 238 239 231 222 262 262 245 223 241 231 237 236 235 241 227 240 225 229 222 233 238 230 232 211 256 233 232 232 228 242 206 257 207 236 225 219 230 216 210 227 205 221 243 218 223 220 240 227 229 259 228 219 221 233 205 217 232 225 242 230 265 202 231 241 281 222 206 243 220 216 237 235 228 263 221 263 239 216 219 257 231 236 206 233 250 211 223 211 242 236 197 222 220 223 220 244 229 211 222 218 237 224 202 231 263 249 225 200 234 264 256 242 223 233 220 212 247 247 229 218 238 234 247 231 224 231 230 227 240 256 222 221 270 258 229 208 259 208 235 210 200 232 246 214 224 237 242 255 221 224 263 223 205 244 245 241 214 235 221 220 225 243 216 220 221 248 227 248 248 243 247 238 221 230 240 226 214 255 227 221 229 240 206 234 225 226 212 238 224 242 243 228 210 241 239 256 205 204 255 264 232 241 243 235 257 234 233 231 238 234 239 255 205 246 231 203 243 228 267 238 233 245 233 241 224 204 238 230 224 225 248 238 227 214 225 272 239 221 237 239 245 210 228 268 230 225 223 264 257 239 237 228 235 181 237 232 226 243 224 209 230 224 222 229 239 255 206 222 231 224 222 258 237 216 243 249 240 241 267 245 230 221 243 240 212 225 239 215 245 222 209 245 264 276 225 233 231 238 219 208 222 261 242 240 215 204 229 223 238 256 241 223 270 219 220 237 223 237 223 223 240 226 245 226 244 215 258 236 241 249 223 257 255 215 217 226 248 246 205 228 209 227 221 233 222 257 228 280 225 227 242 232 238 220 219 240 248 255 216 257 255 225 247 257 280 233 232 265 244 249 212 232 228 259 235 221 265 227 233 218 250 221 202 241 272 234 234 247 223 240 210 261 243 237 255 238 249 230 260 243 248 227 235 227 209 227 233 224 249 246 229 231 223 223 232 220 244 247 243 215 217 240 242 232 264 243 233 223 240 257 229 225 241 241 240 236 218 244 225 224 280 225 232 228 257 205 212 235 244 268 255 268 245 246 248 232 244 248 269 236 245 240 225 243 219 209 262 264 211 261 241 217 250 238 221 235 247 274 218 220 222 247 223 232 236 223 215 243 240 209 230 257 224 218 241 227 214 242 235 266 268 241 229 240 231 245 222 224 243 201 260 227 225 245 224 259 237 239 219 227 255 245 258 255 228 238 228 247 208 233 220 245 243 233 248 238 243 232 272 237 264 238 217 215 241 238 262 228 230 205 205 216 211 246 234 223 249 225 237 229 233 215 244 266 241 224 242 250 235 235 255 239 233 231 269 255 238 249 256 226 221 222 270 232 214 244 241 246 261 233 241 235 256 240 233 260 244 263 262 239 238 217 242 281 248 245 274 236 245 243 226 235 230 246 233 258 245 242 222 237 264 247 259 240 238 283 249 243 246 260 233 259 229 260 233 241 268 235 241 257 221 247 268 258 256 265 239 238 236 257 247 238 241 237 270 245 266 243 227 222 243 264 243 236 225 273 249 239 244 264 239 239 224 210 236 227 238 233 230 245 229 207 222 269 274 229 230 256 226 241 275 241 258 258 212 239 232 259 258 237 227 256 234 249 246 234 268 245 257 207 257 243 224 276 264 257 231 247 265 243 234 238 259 220 218 260 228 255 248 269 259 240 242 261 214 242 238 227 257 262 221 242 237 234 249 247 231 219 259 249 225 240 261 264 231 208 229 239 265 223 208 231 267 261 231 272 228 255 219 231 242 277 259 247 267 243 237 246 255 243 233 211 229 232 258 245 260 241 241 242 203 241 245 248 263 239 250 230 231 231 269 260 231 224 239 265 274 241 230 240 235 218 227 259 285 247 232 247 245 258 228 236 241 267 238 247 248 243 259 247 230 260 221 256 257 264 244 239 235 231 250 268 255 238 257 255 269 293 234 241 247 234 241 247 256 226 270 237 258 232 242 196 257 246 255 289 245 241 221 273 268 242 249 260 227 242 228 239 249 260 225 258 243 233 258 284 255 255 239 249 268 238 249 230 231 244 232 231 221 265 255 243 256 262 236 269 244 269 262 257 269 215 261 248 240 260 235 232 226 232 224 226 249 276 236 227 258 233 226 233 220 279 244 236 235 258 220 233 242 270 224 259 248 241 220 241 261 227 231 260 279 257 266 249 276 273 263 223 248 249 261 261 215 232 245 230 258 239 270 273 272 222 231 255 240 232 267 249 237 243 233 257 237 225 229 226 240 225 269 244 243 232 238 263 238 238 284 271 268 226 257 224 236 247 279 270 260 257 297 228 247 246 263 272 243 261 264 286 234 234 282 243 246 273 228 231 243 271 258 246 263 249 233 262 257 206 264 225 241 216 225 228 241 287 242 256 239 212 247 239 239 236 215 269 261 260 222 274 267 230 235 226 249 216 245 248 235 228 241 262 244 244 273 226 293 243 259 233 241 261 243 224 228 249 261 261 258 244 218 268 217 231 270 263 261 229 255 243 227 271 249 255 267 228 231 232 237 244 269 259 242 270 230 212 221 240 262 271 222 241 246 220 238 259 259 219 244 239 241 215 237 243 241 229 235 244 217 258 232 236 236 226 226 262 242 239 237 239 277 257 244 248 273 257 244 258 267 235 267 263 258 228 233 237 238 258 266 240 226 237 236 231 242 248 258 234 246 241 271 278 259 244 247 262 233 245 272 239 262 228 232 246 241 250 259 264 269 242 227 247 239 270 231 259 233 261 244 239 244 267 267 238 241 262 282 241 262 247 246 238 236 261 272 255 268 271 276 262 247 231 240 300 273 255 255 247 245 248 248 242 256 291 257 261 290 255 244 276 263 240 246 231 274 275 257 235 264 244 287 245 271 236 289 247 222 276 255 265 264 229 249 226 229 268 262 267 224 265 244 255 267 234 262 246 278 255 288 226 263 234 257 242 255 222 217 242 260 226 243 237 280 257 244 256 241 250 235 229 257 234 232 298 210 232 234 212 249 250 241 276 246 248 212 241 269 295 216 269 223 268 229 239 238 261 236 301 247 220 226 265 233 259 239 223 268 246 239 247 229 261 238 222 238 236 242 259 248 237 261 246 265 240 209 240 223 231 269 259 229 245 258 223 241 268 229 230 238 232 248 239 242 227 264 222 228 243 244 246 264 226 257 259 235 247 250 229 244 248 261 256 244 235 208 233 248 269 246 232 260 265 235 249 258 230 271 227 268 232 258 270 245 269 224 265 243 219 219 269 221 246 272 235 247 292 204 239 210 237 246 258 227 261 258 256 259 282 247 227 255 240 250 242 273 239 273 244 231 249 244 257 223 248 235 228 241 263 242 247 234 247 215 257 264 236 230 237 237 242 258 239 259 243 256 220 247 271 266 217 245 265 245 261 234 277 246 272 235 238 267 218 249 287 257 238 258 209 235 226 241 256 234 233 224 267 224 283 281 256 265 258 260 278 261 245 274 255 230 284 271 237 237 247 223 248 223 246 234 221 259 244 246 263 239 248 264 224 242 236 237 224 273 258 235 264 260 244 243 225 260 244 256 234 242 269 259 228 227 236 237 225 261 228 263 236 241 263 244 237 249 248 221 240 239 265 241 259 225 235 268 245 262 229 212 235 261 291 241 241 274 246 264 255 229 243 220 235 255 228 284 272 284 259 212 275 256 260 224 236 260 245 244 239 286 248 244 237 243 237 240 229 246 258 241 239 263 247 234 223 277 232 240 272 233 232 272 243 250 222 263 233 268 256 264 248 266 234 219 267 235 258 240 257 264 241 281 235 244 238 267 233 226 246 260 243 222 232 246 262 238 278 297 259 245 282 239 240 227 233 267 232 246 249 265 283 239 281 239 216 261 240 218 266 250 233 268 238 233 258 290 235 237 266 225 260 227 239 242 242 227 230 246 269 235 288 258 262 248 263 223 225 219 245 238 270 267 231 243 276 231 273 263 245 248 272 266 246 220 258 276 314 218 238 257 242 260 242 248 262 238 271 226 242 286 243 247 221 227 234 225 267 273 266 259 235 234 240 266 231 276 262 230 266 256 237 263 241 243 262 258 247 247 294 275 240 242 241 265 257 275 237 242 262 259 239 232 271 268 241 265 259 246 271 239 233 255 287 225 222 239 274 290 278 228 228 227 245 263 240 282 249 283 271 257 275 263 235 256 245 261 257 224 261 233 243 226 290 234 249 217 258 262 226 242 244 242 244 256 235 265 284 262 227 236 246 275 231 240 268 287 239 260 240 261 255 249 267 267 246 281 238 262 204 243 268 221 232 234 271 240 237 260 268 263 266 264 240 226 260 247 249 238 256 256 269 258 258 241 239 242 274 209 246 237 258 235 230 239 241 242 264 247 249 261 262 247 256 246 248 263 262 220 235 248 262 228 239 244 249 231 241 238 249 271 242 241 238 246 242 243 259 247 249 261 246 243 263 274 241 267 257 233 244 242 240 248 255 242 272 282 258 228 229 247 250 218 241 271 258 261 282 266 237 255 235 237 232 242 261 262 272 255 268 245 247 265 247 270 207 246 247 263 272 263 282 215 228 249 248 239 246 232 238 244 262 244 247 270 212 237 284 238 256 268 240 233 229 227 260 258 256 257 246 258 241 236 245 273 233 270 256 250 229 268 248 265 274 249 250 219 285 248 278 242 226 217 260 243 262 264 242 249 215 218 240 261 267 249 277 271 244 247 262 255 256 245 275 291 268 248 263 258 286 256 277 264 231 228 265 264 274 228 263 261 239 244 229 250 278 278 287 257 240 266 222 244 241 271 240 236 268 271 284 258 246 261 239 222 294 259 267 257 257 226 262 265 256 255 259 271 258 238 284 242 250 235 221 245 274 263 238 234 276 260 248 290 245 233 246 239 237 247 243 250 239 256 263 257 270 264 265 255 255 262 237 249 259 235 256 244 259 264 244 225 259 263 263 243 221 255 218 245 286 226 245 271 244 240 263 271 232 261 258 220 218 244 264 262 235 270 234 255 237 275 264 246 231 271 256 234 247 286 277 257 235 246 225 288 241 270 258 263 265 276 245 284 273 297 273 224 275 223 271 268 231 243 220 262 241 267 266 286 267 231 275 265 283 261 262 273 260 269 241 262 272 228 273 258 242 246 249 245 234 259 235 241 221 281 235 265 238 267 255 259 271 237 246 268 282 240 244 302 257 243 260 236 261 241 261 231 260 240 290 257 272 224 280 269 279 250 260 256 246 248 259 248 264 241 263 269 267 233 273 262 244 217 239 239 256 263 257 243 227 241 222 247 270 248 237 257 262 218 244 278 260 247 257 258 250 274 235 258 256 227 216 268 273 243 283 284 256 263 224 269 236 234 235 230 242 246 245 243 269 235 265 235 272 256 258 256 267 246 268 257 267 259 245 218 258 250 242 278 233 242 278 250 239 269 239 244 262 242 265 237 268 241 268 301 257 248 230 245 231 258 249 234 262 243 246 261 248 240 244 232 264 256 234 242 287 258 283 267 286 264 246 255 274 277 247 257 263 241 257 242 237 271 265 260 276 224 236 221 218 256 285 263 256 227 221 240 263 232 276 238 269 225 217 246 256 257 236 285 244 234 249 239 221 230 274 269 303 265 226 258 275 238 261 265 234 255 241 245 231 194 249 280 274 230 277 267 275 244 232 230 235 264 238 257 263 243 250 257 239 263 256 290 241 264 245 259 262 245 239 242 271 267 256 270 225 231 248 279 249 236 228 269 235 256 256 255 244 232 241 277 218 262 239 288 259 286 261 241 280 249 225 265 262 272 272 265 284 263 244 265 278 290 278 264 239 234 256 257 241 232 211 224 242 272 264 246 269 261 256 282 257 264 248 267 230 218 296 237 276 242 259 248 248 261 262 263 243 229 279 260 256 274 243 274 228 234 281 223 257 261 246 286 280 234 228 242 260 261 229 249 243 237 233 240 262 260 244 274 238 268 255 237 263 283 292 228 248 262 265 238 243 260 246 263 275 267 247 234 270 225 240 268 217 265 257 284 272 265 263 242 273 258 261 255 238 273 224 268 260 267 275 237 285 215 236 233 282 255 247 263 286 218 273 266 234 240 262 261 249 232 230 246 241 281 255 270 257 247 264 270 276 276 269 216 249 244 263 268 237 242 294 260 255 232 260 223 249 247 259 228 245 260 274 280 262 284 247 227 263 248 235 221 256 228 268 266 276 266 255 217 267 268 271 242 258 256 248 261 255 244 276 234 239 214 268 237 249 255 261 235 273 248 229 275 244 224 256 250 248 264 247 246 236 244 250 237 248 225 229 255 262 235 267 282 234 272 258 247 232 263 217 247 248 247 238 285 229 231 208 245 262 228 255 262 261 260 250 271 258 231 256 259 245 242 279 243 285 261 264 239 244 234 274 233 243 260 239 239 248 221 235 255 273 270 220 230 258 255 264 269 281 273 240 262 240 274 266 267 275 235 228 286 240 237 264 219 265 237 243 258 248 247 235 225 272 275 229 269 260 208 263 238 237 240 246 255 265 289 236 270 229 265 248 260 246 241 237 282 271 244 237 266 241 284 246 291 240 237 244 247 263 255 237 233 256 257 260 238 244 213 291 262 273 277 240 260 259 267 285 267 243 257 259 249 227 257 265 272 264 241 241 282 279 267 256 248 266 231 235 244 226 289 267 244 261 238 218 258 223 246 261 264 269 262 277 231 242 242 279 249 260 243 263 292 242 264 227 240 232 283 266 282 248 289 285 299 259 280 279 241 265 258 295 301 257 270 263 275 263 263 266 270 282 258 256 282 260 284 266 268 291 283 312 278 288 280 282 294 320 280 296 268 290 283 271 279 280 265 288 271 247 275 263 269 271 260 306 265 279 265 272 275 272 257 240 269 244 258 289 294 255 255 284 276 266 274 247 220 237 244 232 291 261 257 268 299 277 267 238 260 245 269 248 248 256 274 239 247 226 245 243 287 246 256 222 236 283 229 240 279 272 260 266 271 260 247 242 261 259 255 270 263 260 243 265 215 240 233 279 250 241 236 222 244 262 269 261 276 238 250 234 263 239 258 265 255 235 242 241 212 248 226 200 267 226 245 239 220 219 261 225 243 264 246 264 226 231 258 265 238 259 239 242 223 258 237 270 223 256 242 263 247 263 260 263 261 232 230 270 242 267 242 244 223 209 256 223 262 255 232 260 233 225 275 229 224 263 244 258 263 247 233 229 231 258 261 249 263 256 244 238 236 220 241 255 288 235 234 258 236 266 237 211 221 225 228 295 242 279 236 245 218 260 238 238 264 230 258 230 217 233 231 248 234 267 273 232 230 237 230 255 234 237 218 226 229 224 278 240 231 224 262 247 238 264 271 241 269 232 227 272 229 211 238 256 242 227 226 267 238 239 258 237 232 241 272 234 267 224 246 260 240 228 235 244 249 241 232 257 261 242 246 255 237 256 258 236 241 209 270 235 244 259 230 222 224 247 226 235 223 245 286 239 241 247 231 237 223 272 224 227 261 262 232 270 244 219 232 237 247 281 223 268 232 245 257 231 239 238 260 245 281 257 248 265 220 241 247 224 226 243 239 257 225 278 240 233 259 223 263 272 238 270 213 262 285 248 261 258 242 240 250 246 233 240 225 243 229 248 237 220 258 237 263 228 239 214 215 217 259 228 264 218 230 231 232 246 226 218 249 226 237 222 238 235 274 229 239 244 263 236 244 221 230 246 238 255 263 235 255 255 257 220 221 219 230 243 244 239 224 258 233 267 242 261 240 229 277 259 219 224 256 229 238 215 263 243 242 249 248 261 244 267 227 223 242 229 207 210 257 244 256 234 238 235 258 222 236 237 243 217 231 240 256 229 241 243 235 266 236 238 247 226 255 225 235 265 264 243 271 281 234 213 220 240 269 223 229 245 225 269 235 259 260 231 237 283 223 225 236 235 237 265 239 231 259 232 276 262 247 238 244 274 233 227 263 261 235 239 244 250 235 236 250 215 223 244 236 222 237 246 256 263 246 243 270 226 242 243 265 258 247 258 221 282 264 249 242 241 245 239 248 240 259 226 217 260 262 224 257 233 261 218 250 233 239 239 242 236 236 234 213 233 248 239 259 238 259 267 257 224 235 239 236 229 238 216 228 235 235 212 219 242 237 234 227 236 273 219 225 219 259 248 212 229 233 244 235 245 226 233 237 240 248 219 242 245 259 235 269 222 266 238 241 242 263 218 235 220 230 255 234 238 233 264 265 234 221 233 273 246 232 236 227 262 222 245 256 249 255 269 244 233 231 243 258 239 239 244 233 234 248 245 270 266 234 236 209 237 271 267 228 239 240 244 244 246 230 245 235 246 232 244 243 263 257 216 223 250 271 240 229 231 255 274 249 243 220 261 245 240 256 241 231 230 237 258 262 218 275 231 242 264 256 276 267 215 238 229 224 263 239 255 236 235 230 222 239 270 256 242 249 265 261 228 250 230 261 223 227 270 249 229 217 237 217 212 220 235 245 256 239 242 245 228 249 257 228 243 242 225 225 242 248 215 247 269 243 234 244 208 243 237 245 229 248 278 246 224 276 247 238 258 238 244 262 232 227 240 287 280 243 234 268 258 227 265 231 228 238 258 256 245 247 246 215 209 231 259 243 259 207 239 256 245 279 240 226 248 257 243 245 249 262 244 257 234 277 244 243 233 285 221 248 204 260 249 225 245 267 218 233 258 228 245 240 236 227 260 237 249 238 248 246 224 211 260 242 215 228 247 235 236 225 240 241 223 237 240 220 241 224 225 236 249 238 245 270 237 247 259 243 246 241 235 242 242 273 233 231 222 273 273 265 236 260 225 242 244 236 238 243 270 273 237 269 236 236 206 234 223 221 245 239 259 230 249 244 226 255 248 270 236 246 248 237 245 236 218 226 244 249 265 271 240 258 262 231 234 271 243 244 224 284 227 247 249 245 284 259 249 242 259 283 259 234 256 260 222 201 238 228 255 240 231 273 257 248 219 247 285 241 229 263 231 241 263 272 220 259 224 286 255 235 225 241 249 237 220 256 232 227 238 265 241 247 235 241 216 231 204 261 228 240 247 233 226 224 236 268 240 255 234 257 229 259 237 240 255 228 235 272 231 225 255 238 236 238 236 231 240 242 267 245 269 239 256 260 243 213 269 245 249 229 258 258 255 229 236 238 221 256 268 261 229 243 244 236 240 262 236 234 246 256 277 240 259 207 243 236 232 261 258 241 239 223 240 234 225 243 255 257 304 240 265 257 219 239 223 235 222 245 264 248 261 236 249 241 268 216 237 230 227 263 239 206 233 243 242 243 242 277 211 255 233 230 268 248 270 227 230 274 226 234 236 226 267 285 242 241 231 260 224 243 259 249 244 243 233 221 257 247 241 237 228 246 260 234 229 206 245 266 280 236 226 263 250 241 233 236 276 262 262 220 247 270 231 266 222 279 239 227 275 225 241 208 246 268 248 248 261 233 237 286 240 233 258 240 233 263 245 222 257 227 239 234 229 284 234 238 224 260 256 222 250 224 236 238 261 246 255 232 266 247 239 267 256 220 240 250 226 248 233 235 237 227 224 250 248 239 240 245 244 256 234 258 210 262 243 237 231 266 229 278 277 229 243 239 245 233 229 257 248 228 240 262 235 256 249 245 255 240 215 236 246 236 248 262 235 239 240 233 267 230 243 233 237 269 248 247 245 220 258 225 234 219 233 228 234 233 230 238 221 230 249 236 262 255 223 274 237 233 240 283 243 209 229 240 247 261 248 258 229 240 242 234 247 257 257 255 267 262 216 248 279 248 259 249 249 237 260 274 213 222 242 244 236 241 235 242 226 259 247 235 261 237 244 274 257 268 232 225 246 247 226 231 242 265 247 278 221 256 248 235 231 228 237 237 226 243 218 248 257 248 232 229 245 247 224 190 236 235 247 212 231 234 237 262 226 256 255 255 235 260 230 224 218 250 233 257 265 245 222 266 212 273 240 221 244 235 243 227 229 261 256 235 249 234 241 264 237 233 245 264 234 267 240 241 234 255 219 273 265 277 250 219 238 213 238 222 248 264 249 268 281 226 244 240 233 247 243 243 224 262 224 257 235 255 248 264 271 232 255 228 245 279 262 246 261 265 226 236 250 245 235 259 232 242 259 239 257 237 247 236 217 274 255 271 266 231 267 222 228 262 245 258 263 243 241 258 245 244 225 284 257 259 242 224 260 289 262 263 262 255 222 264 246 241 226 256 258 256 262 219 249 259 223 260 247 234 244 240 232 274 260 286 227 246 264 272 232 234 225 236 250 228 259 247 212 257 259 236 237 228 255 258 259 210 231 263 241 257 270 259 238 256 246 247 248 233 265 257 240 268 216 222 224 236 232 243 272 243 255 259 265 267 263 242 245 276 222 234 226 258 259 211 234 249 247 272 241 236 222 233 261 268 241 222 245 261 239 266 296 227 259 265 237 259 257 227 238 240 264 245 228 257 263 241 238 233 219 223 256 258 275 229 230 262 213 248 258 250 230 262 256 236 272 258 263 257 263 265 262 262 264 259 244 267 247 239 245 265 270 248 259 222 264 245 275 235 259 275 284 278 265 267 275 270 271 244 245 261 260 278 267 227 226 266 261 263 232 280 241 268 279 256 277 249 269 276 240 270 258 237 267 248 239 237 264 273 247 263 255 225 265 240 231 217 244 245 241 216 210 234 248 255 273 280 268 266 228 246 288 234 271 239 241 263 243 274 270 241 263 243 231 240 258 236 240 235 240 258 247 224 263 238 275 265 240 245 271 257 245 267 259 237 234 297 249 265 235 246 224 266 263 232 291 263 245 228 216 223 266 249 238 227 236 241 206 255 257 244 263 236 231 247 266 282 239 259 221 247 219 242 238 234 231 246 256 249 277 265 259 239 250 269 255 246 233 236 228 290 256 256 246 206 224 240 240 243 265 255 219 257 259 219 255 242 255 225 219 265 217 234 239 256 257 259 259 235 261 243 230 260 239 290 266 249 217 270 235 236 245 242 255 259 272 256 242 205 225 227 223 241 248 250 257 255 228 227 240 236 225 263 269 229 239 240 220 268 222 247 242 234 240 257 234 245 216 236 228 241 270 271 232 246 233 227 205 285 224 241 223 240 201 240 234 266 259 239 201 269 275 238 224 277 228 240 236 219 237 260 231 247 286 227 226 242 240 260 247 231 258 214 239 233 222 233 230 237 243 246 240 231 235 222 241 277 221 266 250 231 246 241 235 234 238 277 247 210 212 236 235 230 227 232 248 263 225 224 244 232 257 217 214 247 224 258 220 262 260 237 219 257 233 236 235 237 225 234 233 215 258 255 267 237 263 238 217 240 243 265 237 245 221 235 261 231 275 241 238 260 213 242 235 248 242 244 287 229 240 230 235 240 221 264 261 219 233 260 280 268 257 214 256 266 240 243 217 249 260 233 223 275 263 234 246 256 244 228 233 246 245 222 285 236 231 231 247 213 250 238 223 256 237 263 213 221 235 208 232 217 232 242 211 243 224 255 228 230 246 238 247 218 235 234 270 250 231 223 235 215 249 274 206 249 233 229 249 225 227 257 239 256 234 233 261 281 226 233 233 243 237 230 278 246 235 256 257 229 245 249 257 216 249 234 270 261 261 265 229 260 262 215 245 239 261 216 236 242 241 206 258 213 241 216 208 226 246 244 220 265 236 264 185 244 256 215 217 241 246 245 232 228 241 272 236 228 260 223 238 284 215 223 243 248 222 248 262 210 238 229 256 203 216 261 238 222 246 264 244 243 216 232 258 227 247 238 233 230 250 244 209 231 266 246 283 240 265 244 250 265 216 224 272 242 237 264 216 233 224 232 258 246 255 255 249 275 212 242 248 246 270 250 238 232 256 229 215 257 229 267 237 238 228 242 247 227 217 256 241 247 267 242 237 244 277 236 245 231 232 245 256 256 230 261 227 256 237 247 243 226 269 231 208 255 236 237 245 241 231 234 272 234 219 264 247 238 221 233 244 217 237 260 230 262 261 235 214 236 246 230 259 218 237 217 262 232 222 265 228 232 257 244 244 255 237 238 227 263 219 245 240 232 233 238 250 249 264 215 231 283 218 229 246 276 243 226 246 243 232 242 236 273 233 265 269 213 222 240 209 255 230 226 216 221 218 243 255 244 245 266 219 234 258 211 230 225 240 231 226 277 255 238 259 247 248 223 214 256 236 234 239 243 222 237 241 248 225 238 285 241 233 261 248 255 269 255 279 257 226 257 243 258 275 237 256 270 228 259 243 268 257 232 274 246 219 227 278 249 255 247 245 243 226 249 248 232 227 206 258 261 222 256 222 256 267 247 226 264 249 225 239 249 238 238 219 231 232 264 264 273 247 247 221 226 239 273 238 262 241 257 244 241 225 259 233 267 242 259 273 260 247 262 217 247 208 233 249 230 261 244 259 244 241 225 262 245 232 258 262 245 235 293 235 243 237 234 247 236 245 230 268 263 246 225 221 221 230 240 248 261 260 248 216 243 224 226 249 242 249 262 267 246 261 245 219 233 242 256 237 234 231 242 266 234 218 227 247 220 233 245 220 211 240 282 225 216 258 260 260 210 223 242 232 279 222 257 237 218 246 241 268 225 237 239 270 237 225 208 237 210 258 271 246 275 232 263 255 244 285 255 256 237 260 238 267 263 220 275 224 280 233 232 246 241 236 230 271 248 236 231 256 255 234 249 238 258 238 234 223 282 258 242 249 282 275 237 226 260 233 264 258 233 247 270 229 239 241 237 229 270 236 238 269 263 279 245 232 231 245 257 244 243 243 246 219 241 264 235 239 215 220 267 240 245 248 247 260 230 263 238 244 255 241 210 237 229 248 281 248 241 231 247 249 228 244 264 280 260 250 210 282 246 246 231 271 216 231 249 232 241 243 225 240 246 242 273 237 232 264 263 225 247 241 246 241 241 222 230 259 234 247 250 244 230 238 261 231 241 248 236 256 235 255 223 249 225 241 239 217 269 244 258 225 242 233 255 255 246 275 215 238 243 200 239 246 247 255 222 261 255 257 256 210 238 220 220 221 213 236 220 229 219 225 224 241 248 255 271 260 263 249 256 234 262 248 244 209 241 278 264 229 235 247 257 231 247 241 243 214 236 235 229 279 243 263 230 256 242 234 244 275 231 229 232 267 236 233 238 269 262 238 244 267 226 246 247 282 256 269 239 235 249 227 231 267 204 246 294 277 268 235 242 256 239 248 268 236 271 218 260 240 230 230 233 250 229 274 250 278 262 257 257 226 259 260 205 256 229 247 248 237 213 256 219 261 269 228 256 247 219 233 263 265 245 210 275 260 247 238 262 263 231 219 246 228 220 233 227 239 292 239 273 246 239 259 243 223 246 257 265 236 264 242 266 244 241 245 269 235 240 240 260 231 225 236 222 280 247 258 233 249 245 242 262 258 273 241 273 248 230 286 256 248 230 243 247 232 276 277 273 225 235 237 223 234 235 257 245 241 221 255 240 246 233 269 259 267 266 260 243 258 249 220 245 294 231 256 234 234 263 249 262 278 248 239 246 224 262 243 249 205 235 238 249 226 255 267 286 243 245 262 274 244 257 280 239 255 230 244 237 226 236 246 226 228 260 243 263 274 270 231 221 266 258 236 263 257 260 242 245 227 259 230 232 237 285 239 237 243 236 262 248 262 244 229 233 227 214 236 230 249 261 227 221 234 249 232 264 243 240 240 262 243 229 219 241 243 241 265 238 243 272 228 260 281 274 233 249 261 225 271 227 272 244 222 225 242 240 218 273 267 256 241 243 270 227 236 233 233 247 296 210 243 227 247 260 232 271 248 229 219 232 273 250 235 262 272 264 279 233 228 257 246 257 257 243 261 263 259 237 273 234 241 243 245 231 272 244 243 236 241 257 256 267 258 242 233 266 240 238 236 286 264 264 226 214 223 222 255 266 233 259 221 247 280 220 241 237 230 271 220 240 229 273 267 237 229 282 226 242 267 225 247 226 229 260 275 214 245 247 272 255 270 233 258 237 235 233 228 256 213 235 248 283 269 261 257 245 229 226 239 250 231 215 278 209 230 249 248 236 271 264 243 237 229 233 266 229 216 225 240 263 228 262 231 243 237 236 249 255 241 246 291 262 249 221 258 222 241 240 238 276 242 231 285 248 224 212 236 258 277 229 265 246 269 233 259 256 229 240 245 230 248 220 236 257 238 229 247 260 212 245 219 259 266 273 255 245 229 248 256 248 248 225 237 237 265 266 250 257 244 273 229 246 270 235 265 239 273 260 218 271 277 264 220 256 270 240 237 255 238 224 240 260 242 272 262 259 258 233 246 236 271 256 249 231 246 236 228 262 220 219 225 261 209 246 203 264 241 249 257 241 244 239 244 264 266 247 223 277 241 255 255 246 235 242 255 221 234 242 241 263 237 246 277 271 238 243 263 235 250 266 215 258 247 226 248 243 259 257 255 238 245 263 277 261 232 270 259 288 269 272 260 232 222 246 235 234 239 267 265 249 265 255 213 248 241 241 259 245 289 257 243 265 270 261 283 273 234 263 289 286 284 240 242 276 284 262 275 275 237 275 247 255 229 267 260 240 257 246 231 267 262 247 281 264 243 256 238 242 281 247 275 265 274 272 263 276 274 284 268 286 246 281 268 261 244 263 224 258 282 286 238 270 269 241 238 240 291 239 271 235 226 285 264 269 247 274 229 260 261 260 259 249 267 228 265 289 263 256 267 263 220 268 245 291 249 257 270 256 271 262 272 234 243 274 268 260 267 261 243 229 227 263 266 255 241 221 213 267 262 261 247 238 277 241 240 256 235 226 229 224 258 279 260 244 270 230 236 221 259 277 241 218 259 242 259 281 248 261 215 271 233 213 235 268 264 256 255 239 219 246 238 262 256 235 236 240 243 227 269 243 248 237 281 240 247 260 225 246 280 242 272 231 258 262 259 240 276 260 261 264 266 247 231 234 245 266 268 233 240 250 247 258 238 246 265 263 258 237 239 280 230 231 281 269 228 256 269 268 223 234 221 266 245 230 243 240 294 249 270 236 259 266 236 263 223 227 244 263 258 232 244 260 221 233 238 227 229 264 239 234 226 219 234 247 269 218 241 248 259 237 258 259 265 269 215 239 223 257 246 260 246 249 280 277 264 236 249 246 228 216 247 231 244 266 228 244 241 239 271 248 241 262 232 250 260 226 238 224 238 214 249 264 233 229 249 264 247 211 271 264 232 288 248 235 287 246 242 234 229 244 260 267 230 255 243 256 225 239 256 209 234 260 219 249 260 235 263 255 237 226 236 255 237 241 238 267 239 263 238 248 250 281 263 247 246 226 235 236 233 261 231 258 215 273 240 245 230 247 236 263 236 255 244 218 265 256 267 244 231 245 234 246 259 207 240 240 259 262 247 241 234 265 249 269 238 238 260 247 249 236 262 220 236 249 218 246 228 273 271 228 227 278 223 236 237 250 236 278 220 274 246 226 229 249 236 248 238 244 225 229 243 259 239 257 221 265 219 242 227 241 246 235 258 246 248 289 257 256 241 232 264 238 222 237 247 237 230 240 244 233 240 280 282 262 263 225 235 250 238 224 241 244 235 228 297 257 271 259 249 276 275 263 216 248 221 280 231 237 228 246 247 280 210 300 271 234 242 267 278 206 262 223 257 266 230 269 246 241 266 226 231 235 245 256 261 238 240 259 259 241 263 239 237 262 228 245 237 236 233 242 211 255 240 256 240 248 235 246 260 235 256 263 273 235 223 248 263 256 236 278 257 246 277 257 259 232 236 263 217 249 217 255 258 258 260 243 240 282 234 227 257 239 260 227 243 260 261 246 222 230 229 240 223 277 282 255 258 226 272 255 243 247 246 269 236 236 274 230 247 238 240 210 222 264 250 216 264 257 241 235 260 246 265 244 240 209 207 236 230 226 271 229 249 240 215 261 231 283 264 240 225 239 263 268 264 228 257 241 237 266 220 246 238 245 234 247 247 240 241 266 259 260 271 238 234 237 241 216 221 268 266 243 258 243 278 249 265 266 255 218 241 249 228 263 224 248 230 250 241 230 263 243 271 237 237 255 219 236 264 270 218 244 261 230 243 263 260 237 229 228 244 227 260 260 238 226 255 232 243 212 224 237 234 240 217 244 258 259 236 230 231 238 241 231 261 236 263 249 209 227 279 246 256 245 255 257 294 267 259 234 217 232 228 270 230 255 260 242 228 214 268 243 258 240 225 262 264 246 249 229 269 226 224 246 258 222 238 257 282 223 222 239 237 242 239 249 231 255 257 223 239 232 229 268 217 255 258 266 266 268 242 267 246 241 247 269 244 230 235 265 247 229 223 237 245 242 212 231 267 242 228 249 234 263 235 256 227 233 229 241 237 239 228 240 237 233 241 242 241 242 256 255 222 238 267 218 211 238 257 270 231 246 227 239 220 218 245 236 246 255 228 240 236 240 239 232 248 235 228 235 243 231 247 255 255 223 249 260 240 236 238 262 225 242 258 238 255 244 246 217 262 294 228 257 229 266 226 268 239 278 224 256 220 259 241 241 233 245 264 238 246 241 237 231 242 246 241 263 234 234 241 225 236 219 246 260 236 255 227 249 278 226 237 228 209 259 240 262 234 257 245 230 249 228 229 258 228 244 227 268 246 258 255 243 241 242 226 256 245 259 223 238 223 209 243 241 231 217 235 270 227 248 248 229 230 200 225 248 245 246 256 257 245 275 233 243 234 217 266 248 230 287 224 228 249 246 231 228 241 246 241 217 231 263 216 239 232 246 225 240 199 229 211 242 222 207 229 249 242 242 245 272 238 243 245 210 232 227 241 245 250 246 245 238 247 240 213 260 233 266 229 248 247 234 213 246 256 239 219 243 256 266 259 228 228 262 235 239 220 221 242 246 235 226 244 262 285 203 240 215 237 258 237 242 226 217 248 207 221 213 250 218 225 231 274 220 248 238 223 268 221 194 222 249 229 274 238 232 223 237 229 210 237 275 248 227 231 240 258 240 268 223 229 260 231 258 235 264 272 261 223 235 224 246 240 235 221 232 248 238 240 210 265 226 237 234 234 263 267 196 212 248 245 238 222 246 244 243 250 255 216 263 216 235 229 230 236 218 240 234 236 259 234 261 250 258 259 227 249 250 227 202 228 232 260 245 270 231 229 238 240 256 235 227 265 240 214 255 231 234 231 217 259 223 242 256 225 229 249 219 272 264 224 245 263 219 242 278 216 245 228 236 250 226 267 243 233 256 241 271 245 227 214 219 233 268 255 266 256 270 260 239 234 242 256 230 265 231 228 236 236 244 237 256 210 247 247 245 249 236 222 225 270 242 216 240 256 257 227 227 234 222 243 237 236 258 250 204 231 242 234 233 222 262 248 214 236 230 276 258 239 226 250 236 239 229 228 264 231 233 234 228 271 245 203 226 269 240 245 261 239 239 248 267 262 256 226 233 233 237 240 248 222 273 256 240 227 269 256 238 263 270 257 244 243 247 228 213 213 229 238 229 246 236 255 247 270 265 239 268 279 261 261 260 231 239 242 268 232 273 247 231 272 288 267 258 241 212 228 245 226 222 236 247 225 239 260 249 255 232 275 239 230 276 245 238 258 271 245 221 249 271 242 245 245 257 240 256 249 263 260 234 247 227 234 244 269 245 248 268 264 241 278 257 260 243 256 280 219 248 231 243 259 242 236 289 225 264 246 262 241 263 244 244 228 235 217 269 242 246 236 255 225 245 224 249 233 234 258 282 222 230 240 249 249 236 234 239 239 225 248 270 256 273 236 249 242 224 270</counts>
			</dataPoints>
		</scan>
	</xrdMeasurement>
</xrdMeasurements>