File: data/XRD/XG-Vakuum/XG-500/W6821-1C_XG_Vakuum_500.xrdml
<xrdMeasurements xmlns="http://www.xrdml.com/XRDMeasurement/2.1" xmlns:xsi="http://www.w3.org/2001/XMLSchema-instance" xsi:schemaLocation="http://www.xrdml.com/XRDMeasurement/2.1 http://www.xrdml.com/XRDMeasurement/2.1/XRDMeasurement.xsd" status="Completed">
	<comment>
		<entry>Configuration=Factory configuration, Owner=User-1, Creation date=7/8/2013 4:01:53 PM</entry>
		<entry>Goniometer=PW3050/65 (Theta/2Theta); Minimum step size 2Theta:0.0001; Minimum step size Omega:0.0001</entry>
		<entry>Sample stage=MRD Cradle; Minimum step size Phi:0.01; Minimum step size Chi:0.01; Minimum step size X:0.01; Minimum step size Y:0.01; Minimum step size Z:0.001</entry>
		<entry>Diffractometer system=XPERT-PRO</entry>
		<entry>Measurement program=C:\PANalytical\Data Collector\Programs\Jorrit\2thom\_absolute_2th-om_10-130deg_PIXscan_56min.xrdmp, Identifier={15BCCF57-2807-42BD-B5B9-ECC0B3DC9284}</entry>
		<entry>Batch program=C:\PANalytical\Data Collector\Programs\SimonL\batch4x_2thom_10-130°_z9.1_x0,10,20,30_y0_57min.xrdmp, Identifier={EED9823A-2BEB-424C-9252-345C4EF2834A}</entry>
	</comment>
	<sample type="To be analyzed">
		<id></id>
		<name></name>
		<preparedBy></preparedBy>
	</sample>
	<xrdMeasurement measurementType="Scan" status="Completed" sampleMode="Reflection">
		<comment>
			<entry>_absolute_2th-om_10-130deg_PIXscan_56min</entry>
			<entry>PHD Lower Level = 4.83 (keV), PHD Upper Level = 11.27 (keV)</entry>
		</comment>
		<usedWavelength intended="K-Alpha 1">
			<kAlpha1 unit="Angstrom">1.5405980</kAlpha1>
			<kAlpha2 unit="Angstrom">1.5444260</kAlpha2>
			<kBeta unit="Angstrom">1.3922500</kBeta>
			<ratioKAlpha2KAlpha1>0.5000</ratioKAlpha2KAlpha1>
		</usedWavelength>
		<incidentBeamPath>
			<radius unit="mm">320.00</radius>
			<xRayTube id="1010048" name="Empyrean Cu LFF HR (9430 033 7310x) DK442154">
				<tension unit="kV">40.0</tension>
				<current unit="mA">40.0</current>
				<anodeMaterial>Cu</anodeMaterial>
				<focus type="Line">
					<length unit="mm">12.0</length>
					<width unit="mm">0.4</width>
					<takeOffAngle unit="deg">4.2</takeOffAngle>
				</focus>
			</xRayTube>
			<xRayMirror id="27010001" name="Inc. Beam Cu W/Si (parabolic MRD)" hybrid="false">
				<crystal type="Graded" shape="Parabolic">W/Si</crystal>
				<acceptanceAngle unit="deg">0.800</acceptanceAngle>
				<length unit="mm">60.0</length>
			</xRayMirror>
			<sollerSlit id="21010002" name="Soller slits 0.04 rad.">
				<opening unit="rad">0.0400</opening>
			</sollerSlit>
			<mask id="22030008" name="Fixed mask 4 mm">
				<distanceToSample unit="mm">220.00</distanceToSample>
				<width unit="mm">4.00</width>
			</mask>
			<divergenceSlit id="22010007" name="Fixed slit 1/8°" xsi:type="fixedDivergenceSlitType">
				<distanceToSample unit="mm">220.00</distanceToSample>
				<height unit="mm">0.19</height>
			</divergenceSlit>
		</incidentBeamPath>
		<diffractedBeamPath>
			<radius unit="mm">320.00</radius>
			<sollerSlit id="21010002" name="Soller slits 0.04 rad.">
				<opening unit="rad">0.0400</opening>
			</sollerSlit>
			<receivingSlit id="22010001" name="Fixed slit 4°">
				<height unit="mm">5.88</height>
			</receivingSlit>
			<detector id="7010017" name="PIXcel3D 1x1 detector" xsi:type="areaDetectorType">
				<phd unit="%">
					<lowerLevel>30.0</lowerLevel>
					<upperLevel>70.0</upperLevel>
				</phd>
				<mode>Scanning</mode>
				<activeChannelsEquatorial>255</activeChannelsEquatorial>
				<activeChannelsAxial>255</activeChannelsAxial>
				<pitchEquatorial unit="mm">0.05500</pitchEquatorial>
				<pitchAxial unit="mm">0.05500</pitchAxial>
				<readOutPeriod unit="seconds">0.135</readOutPeriod>
			</detector>
		</diffractedBeamPath>
		<scan appendNumber="0" mode="Continuous" scanAxis="2Theta-Omega" status="Completed">
			<header>
				<startTimeStamp>2024-10-07T17:05:50+02:00</startTimeStamp>
				<endTimeStamp>2024-10-07T18:01:57+02:00</endTimeStamp>
				<author>
					<name>PRO-MRD</name>
				</author>
				<source>
					<applicationSoftware version="6.1b">Data Collector</applicationSoftware>
					<instrumentControlSoftware version="7.0E 20130304">XPERT-PRO</instrumentControlSoftware>
					<instrumentID>0000000011142674</instrumentID>
				</source>
			</header>
			<dataPoints>
				<positions axis="2Theta" unit="deg">
					<startPosition>9.99826193</startPosition>
					<endPosition>129.99755682</endPosition>
				</positions>
				<positions axis="Omega" unit="deg">
					<startPosition>4.99913096</startPosition>
					<endPosition>64.99877841</endPosition>
				</positions>
				<positions axis="Phi" unit="deg">
					<commonPosition>0.00</commonPosition>
				</positions>
				<positions axis="Chi" unit="deg">
					<commonPosition>0.00</commonPosition>
				</positions>
				<positions axis="X" unit="mm">
					<commonPosition>0.00</commonPosition>
				</positions>
				<positions axis="Y" unit="mm">
					<commonPosition>0.00</commonPosition>
				</positions>
				<positions axis="Z" unit="mm">
					<commonPosition>9.100</commonPosition>
				</positions>
				<commonCountingTime unit="seconds">32.895</commonCountingTime>
				<counts 435 461 423 419 450 411 450 425 491 448 480 440 445 438 443 454 421 449 446 462 464 414 415 415 442 440 451 471 458 422 449 418 429 449 445 452 443 419 437 478 397 478 490 430 402 457 396 458 431 449 421 428 427 443 485 431 420 472 426 462 449 449 432 423 415 413 430 435 436 410 433 416 428 445 472 422 464 443 450 436 434 443 387 450 407 436 433 419 405 426 451 416 450 397 466 392 411 398 430 475 443 432 429 438 405 383 441 405 412 398 442 384 407 427 451 406 408 386 412 397 439 402 425 379 411 415 389 429 411 421 418 391 378 371 406 429 454 417 439 436 404 388 391 384 425 401 386 469 440 418 424 402 407 384 439 394 415 420 445 404 420 437 402 421 422 397 392 401 385 371 389 409 406 391 363 359 419 413 425 396 361 376 423 418 412 386 398 456 388 425 395 424 388 374 382 365 395 383 388 423 398 409 377 388 380 426 411 397 388 381 415 401 408 387 418 410 411 370 345 383 389 368 388 392 380 371 390 375 371 388 394 402 382 387 392 356 383 416 412 394 379 371 386 387 407 373 373 394 390 399 364 392 394 369 406 397 385 401 387 372 376 403 389 402 429 400 364 367 412 374 387 371 373 387 370 370 393 410 377 359 401 410 378 352 384 396 365 375 352 371 368 340 427 392 391 348 361 388 404 381 362 353 370 367 384 380 364 359 364 373 360 398 362 349 396 367 392 345 410 379 318 372 362 337 392 392 374 375 384 370 405 368 370 355 403 384 367 357 356 372 367 400 361 365 350 359 364 340 359 355 364 335 365 369 347 368 369 373 355 382 337 369 366 375 330 344 341 358 385 351 352 362 337 351 380 326 365 358 369 378 370 370 368 380 379 371 378 395 326 356 371 374 387 389 373 348 388 355 360 350 342 339 372 347 356 359 360 371 387 341 327 347 336 396 381 361 353 353 371 344 359 366 370 341 356 374 330 358 381 376 358 372 366 355 348 347 341 340 346 326 381 360 331 355 374 355 355 347 373 348 353 338 382 345 368 358 327 334 351 392 352 378 339 344 356 342 334 326 335 351 317 335 313 343 358 357 324 342 358 342 363 353 378 384 331 340 355 326 344 330 336 369 334 355 360 316 335 360 327 325 323 346 377 334 308 330 327 373 366 348 321 358 340 348 369 353 315 325 335 316 314 323 355 357 346 333 346 356 332 369 366 369 312 336 320 346 368 312 352 352 385 306 344 311 347 357 341 322 307 342 347 346 357 346 304 349 331 354 327 321 356 333 344 330 355 359 381 320 312 347 358 351 350 362 340 375 369 331 340 350 311 348 347 331 359 331 345 324 355 339 341 338 337 357 350 339 357 319 349 341 331 315 352 341 331 348 346 297 324 316 332 370 339 345 362 350 316 346 343 296 365 324 332 353 311 355 358 356 343 320 365 355 368 330 377 333 341 315 332 333 332 326 357 375 346 354 355 315 369 370 320 358 356 335 380 316 309 323 343 330 349 356 375 327 319 344 339 336 379 357 330 328 306 304 368 361 334 349 349 364 332 342 339 387 331 352 302 334 337 315 369 352 354 334 325 318 343 340 324 301 380 378 353 353 332 328 363 365 391 345 333 350 357 341 322 339 362 350 358 351 369 322 336 319 322 358 367 327 353 339 331 349 342 322 321 373 346 360 352 356 344 341 345 349 361 323 319 357 353 370 373 326 358 355 356 364 341 381 374 331 339 364 341 323 331 313 374 379 359 355 323 323 327 370 363 357 365 364 317 345 363 350 395 338 352 354 356 342 339 350 339 356 365 349 371 366 343 355 340 362 366 359 391 395 390 357 374 336 360 339 354 355 318 342 323 331 345 337 345 370 327 367 346 343 314 346 340 325 362 367 356 374 318 321 312 357 365 359 337 354 348 380 327 361 364 388 335 349 385 342 360 334 340 363 333 376 368 326 336 301 325 333 380 332 346 354 351 376 326 358 349 339 389 361 345 316 330 334 367 372 361 357 347 343 377 363 363 386 359 397 333 336 346 333 339 313 373 348 357 323 322 335 350 340 369 333 355 341 342 375 373 316 393 357 369 370 388 388 333 345 390 373 320 349 380 368 358 362 388 358 366 347 344 376 353 312 356 320 356 334 363 357 371 397 370 379 364 382 363 345 348 386 366 347 363 338 379 371 350 388 375 370 341 339 362 358 369 363 345 354 361 380 345 355 387 353 398 375 363 363 359 385 364 366 368 341 373 367 347 340 363 352 352 357 334 400 355 369 344 378 373 383 361 392 370 372 382 370 369 320 380 360 378 362 352 354 372 384 339 342 368 382 342 363 360 350 375 349 366 381 343 373 363 359 360 365 381 349 333 367 356 379 331 355 409 361 391 356 383 340 384 351 361 360 366 338 337 361 364 381 349 325 369 352 369 353 360 346 330 354 390 376 361 363 349 347 352 400 377 343 362 348 357 368 364 351 364 380 341 368 356 380 373 339 356 374 359 354 362 344 380 309 353 339 351 379 390 378 356 338 376 342 327 350 326 372 346 333 368 349 368 326 360 343 377 339 339 342 338 347 401 351 317 398 363 356 344 358 364 383 380 378 348 318 408 367 373 337 394 373 335 328 391 375 355 357 373 345 355 355 357 348 331 371 342 349 342 350 376 355 367 381 348 369 378 346 364 326 363 327 355 314 376 354 343 369 375 342 331 374 348 352 368 386 389 341 360 366 362 368 331 385 387 352 370 356 342 352 371 338 365 354 364 376 348 350 356 374 340 332 347 350 386 354 345 340 374 390 374 377 347 363 344 368 326 389 359 367 357 364 319 351 324 347 340 388 344 362 349 387 367 356 346 392 370 355 380 371 324 363 413 351 388 339 406 385 368 376 361 350 357 366 395 370 358 384 367 367 354 378 364 357 329 339 372 348 342 360 349 332 356 348 353 351 370 386 349 341 352 328 368 360 394 334 358 374 347 392 317 343 364 360 367 345 342 349 351 354 365 345 333 351 375 326 371 339 338 339 342 341 383 371 316 360 350 360 350 402 345 360 361 337 359 332 340 367 354 353 353 393 359 340 360 350 307 343 374 346 343 336 379 372 340 359 332 365 374 379 367 378 358 342 326 311 338 333 356 367 328 342 331 365 313 351 348 383 373 327 340 343 346 365 350 343 387 351 340 346 370 347 338 352 347 360 345 319 346 343 347 329 316 338 357 344 367 347 331 353 332 337 322 353 337 322 337 346 332 337 333 340 333 360 392 359 348 350 345 370 341 355 343 341 333 394 334 326 351 365 342 323 365 330 370 366 359 334 360 344 332 334 364 335 361 387 315 338 334 343 329 353 356 357 354 350 336 317 334 344 350 351 332 325 330 341 313 356 345 330 350 328 352 338 373 331 346 347 330 326 367 321 342 331 327 311 356 345 314 354 337 287 345 337 323 349 322 301 340 351 344 313 337 359 354 347 341 320 342 318 327 322 358 325 345 328 325 354 300 333 352 324 317 335 325 332 333 304 329 357 358 310 323 314 341 349 337 346 326 315 343 311 314 335 320 307 303 331 343 307 324 306 304 340 341 321 314 313 373 330 345 311 333 343 307 312 309 340 353 300 347 309 339 342 333 317 329 340 306 357 336 314 309 360 347 308 326 288 338 283 335 307 324 325 337 331 323 333 350 296 332 293 288 331 300 328 329 341 307 319 299 305 337 298 318 356 328 334 292 314 290 311 314 305 351 298 344 324 348 317 293 352 315 337 301 329 294 299 312 339 316 281 311 283 311 276 271 324 311 305 280 310 311 325 328 316 311 311 336 366 280 296 328 317 294 334 311 312 335 287 327 298 282 327 297 323 286 284 307 304 319 303 291 292 294 319 295 305 321 292 305 285 319 302 334 306 314 319 291 281 314 300 307 312 264 318 313 290 342 335 306 270 344 293 302 304 309 299 333 321 297 302 315 314 302 289 289 316 296 270 287 320 293 305 297 297 307 331 300 307 301 319 304 311 301 291 334 275 289 294 289 317 336 300 291 290 284 295 278 343 315 326 325 288 286 249 330 292 294 282 321 285 301 303 301 315 307 304 281 305 297 287 269 284 285 276 274 296 306 293 277 294 283 288 262 269 290 339 302 323 307 299 303 293 305 312 325 258 311 302 293 306 290 330 310 272 286 296 304 308 284 338 311 315 303 309 293 320 255 315 305 311 288 297 277 297 293 311 287 285 300 296 283 283 278 331 292 288 307 286 311 309 298 295 271 282 298 274 292 286 287 285 294 293 295 284 298 281 283 295 319 294 291 302 290 307 280 322 282 286 316 282 314 300 293 289 320 311 314 306 277 314 290 317 284 275 308 286 277 278 282 309 304 287 279 286 300 310 323 317 276 309 292 279 296 297 277 271 279 312 257 284 272 295 313 292 263 300 287 263 298 296 294 307 298 274 261 268 227 275 304 282 298 294 279 262 281 286 273 308 267 313 289 280 305 305 270 284 281 283 294 282 233 277 283 302 300 257 282 285 279 287 289 271 277 305 299 247 284 312 298 272 292 284 279 235 275 264 245 286 268 288 263 275 246 286 282 274 302 269 278 284 290 256 276 304 268 299 294 297 296 285 274 288 268 289 280 271 267 297 245 286 285 292 276 273 265 303 297 267 274 295 282 272 299 262 275 280 287 270 270 291 287 309 256 244 258 259 263 248 265 278 264 280 257 286 292 301 313 277 258 301 294 241 256 245 286 281 289 292 243 269 267 315 287 275 273 273 262 269 284 265 272 284 283 278 280 263 272 294 241 322 281 271 275 248 283 287 279 280 296 270 289 263 290 255 295 282 295 294 256 277 306 274 284 243 288 265 260 284 301 270 240 284 296 248 286 281 239 277 264 255 257 268 299 237 257 294 294 288 249 240 257 288 247 304 255 247 276 247 269 295 308 286 288 289 285 280 294 274 267 244 266 282 269 233 273 261 270 267 289 274 261 281 284 264 255 247 310 265 245 275 289 266 292 318 228 241 241 275 272 289 293 246 274 249 296 278 292 259 285 272 248 267 257 269 279 248 282 282 263 272 284 289 280 295 262 276 287 255 246 288 273 286 265 276 273 271 234 283 270 274 299 259 284 235 266 289 257 257 274 294 266 246 256 281 281 256 247 246 251 262 272 279 245 258 258 283 266 242 294 307 265 249 260 298 276 269 239 236 290 265 280 267 279 290 274 274 276 273 268 270 259 263 302 265 277 241 284 258 244 229 272 265 284 270 280 256 275 263 268 296 277 264 236 269 239 259 276 237 266 243 271 293 290 265 282 273 292 265 257 263 283 264 272 238 271 286 244 248 260 274 237 264 295 260 262 271 264 264 240 246 269 263 257 247 264 259 288 247 245 245 292 284 276 247 262 241 289 273 269 246 274 275 272 249 270 259 257 289 267 240 267 268 273 239 240 264 235 241 276 235 248 270 274 267 286 270 247 237 271 257 271 292 223 264 257 272 258 273 283 224 268 271 234 242 258 239 238 282 278 262 287 245 247 290 263 269 281 255 257 304 267 258 267 275 287 234 231 264 281 285 258 283 233 238 239 224 287 260 281 278 272 246 275 262 268 284 270 266 232 283 284 264 271 267 210 263 264 236 246 255 247 272 278 277 258 262 255 247 261 285 273 287 243 240 263 247 218 265 269 215 259 261 276 281 280 219 263 270 270 245 288 261 264 235 263 255 240 294 249 279 243 290 266 231 278 258 288 236 284 265 272 245 247 245 279 274 237 256 248 236 260 262 256 241 250 277 278 248 281 269 266 265 302 249 306 255 247 277 268 277 269 259 236 276 245 238 256 265 262 248 261 263 238 277 276 277 265 240 244 246 273 250 272 233 259 263 261 297 239 286 246 263 268 257 273 215 256 235 260 270 257 262 261 227 267 265 281 280 293 259 288 260 274 305 247 262 270 266 262 263 247 272 261 277 272 233 249 260 245 272 276 235 235 273 239 255 292 214 261 285 259 242 267 270 245 277 267 232 241 272 267 260 268 241 237 280 233 217 298 239 280 221 257 229 287 227 245 257 263 261 234 278 260 277 272 231 236 275 270 248 270 242 233 268 272 255 229 291 265 256 280 233 270 246 281 267 231 267 268 248 264 284 259 263 277 293 268 246 273 248 275 294 256 229 281 249 257 241 273 233 249 255 258 234 273 222 258 256 288 264 261 296 270 272 279 271 279 258 257 264 267 273 262 246 271 229 225 235 280 247 283 260 274 274 242 240 248 239 245 241 255 262 264 223 264 279 276 265 243 218 239 247 270 270 258 267 242 265 261 265 243 266 276 266 245 249 241 285 240 237 282 235 236 218 272 234 228 241 245 234 224 273 246 256 241 261 249 219 240 242 255 261 242 250 265 231 230 248 248 245 244 231 229 228 249 270 245 246 261 269 239 258 262 247 256 218 246 238 258 246 243 238 246 256 242 243 267 265 255 247 225 236 227 283 268 246 233 262 225 221 246 266 258 277 246 231 229 261 265 243 276 246 274 266 246 255 285 249 240 276 223 241 242 233 243 224 244 240 241 259 268 247 258 233 263 218 235 244 245 258 262 239 236 248 239 279 261 270 233 223 244 258 256 245 248 236 228 269 265 223 244 273 238 277 284 234 220 246 262 238 259 250 247 274 265 259 257 259 233 227 237 283 266 282 237 237 245 243 231 260 266 264 263 232 241 264 249 282 263 230 220 255 247 228 265 265 224 257 245 222 258 263 268 231 239 249 268 263 228 278 238 243 239 241 239 229 266 235 215 242 241 221 245 241 240 230 242 255 227 238 247 224 239 235 227 236 250 258 244 213 245 266 256 248 237 264 261 256 267 262 259 232 242 244 255 272 258 258 235 259 248 228 255 228 270 274 256 228 225 267 226 265 245 235 248 249 239 276 273 279 248 247 259 275 255 271 269 229 246 239 261 229 285 258 263 218 245 243 239 239 260 222 243 278 221 246 264 243 249 245 248 215 242 247 229 265 277 249 244 239 246 274 275 255 259 262 220 246 261 283 241 264 246 240 256 276 269 260 248 221 235 227 285 257 241 239 261 247 259 242 239 244 240 259 292 248 235 247 269 236 245 247 259 255 274 257 267 227 288 262 270 259 258 266 277 274 272 246 238 247 291 273 220 239 264 259 244 265 250 229 257 269 224 227 268 260 269 244 236 256 273 269 223 259 269 279 259 241 241 247 257 234 278 267 208 242 292 228 288 243 271 240 269 258 244 259 260 291 271 286 247 236 263 263 250 281 263 263 227 238 266 247 246 230 239 266 233 266 256 291 236 264 267 281 214 231 283 268 282 260 257 258 235 243 238 257 259 249 260 277 230 288 228 249 255 268 249 264 249 295 275 282 265 242 263 267 267 276 238 232 235 233 232 248 263 276 282 236 272 271 318 268 263 279 259 227 231 273 261 272 245 261 256 289 256 277 262 262 245 285 239 264 261 263 277 269 248 246 240 239 241 249 281 284 250 297 216 262 246 237 243 242 283 269 268 278 282 211 255 243 272 248 266 291 298 273 266 278 275 246 237 262 304 250 257 283 226 266 255 274 307 275 276 247 266 302 314 293 267 240 270 285 249 284 257 248 264 258 241 262 268 285 224 276 271 269 276 285 257 269 225 292 271 260 277 235 292 282 279 293 264 280 234 261 266 259 294 276 278 288 282 244 239 308 221 270 303 269 298 280 278 276 266 287 274 291 270 289 286 247 283 256 277 291 271 294 241 271 305 273 301 291 285 282 292 291 294 277 274 311 270 304 271 290 279 263 303 284 286 288 296 337 310 297 299 334 309 324 344 294 304 318 329 341 315 325 331 296 333 349 363 338 340 389 374 374 353 396 400 374 422 422 450 438 446 457 475 473 474 475 482 476 456 485 484 477 488 483 545 498 441 483 455 495 460 473 456 435 418 410 392 367 373 383 359 377 364 368 324 322 347 296 294 328 327 306 297 312 305 313 351 316 291 278 296 293 287 280 281 309 287 283 291 281 289 281 285 269 310 270 279 277 304 270 272 268 298 278 268 261 269 279 280 285 244 270 284 276 285 284 259 266 277 306 296 278 274 258 270 284 286 286 275 228 284 285 272 272 236 268 244 268 277 244 241 231 260 241 237 257 240 287 269 239 259 257 258 274 247 299 261 266 288 270 263 266 234 290 236 257 250 241 221 283 213 246 257 302 260 268 260 258 246 248 270 266 260 245 234 261 245 230 246 246 267 262 233 237 280 271 234 213 273 272 292 262 262 238 300 258 286 263 267 250 247 275 274 262 255 242 285 249 255 266 276 224 267 268 269 241 272 241 245 276 260 268 294 245 269 247 278 256 265 261 247 255 276 229 224 225 243 262 236 281 267 237 249 269 284 275 259 248 224 238 280 266 237 239 239 266 269 300 274 281 283 265 250 229 264 284 245 246 264 232 237 238 258 278 259 257 265 282 248 221 282 261 276 255 261 289 273 272 266 246 261 280 243 273 241 267 285 277 257 274 241 259 265 267 223 265 296 259 257 275 257 274 264 281 245 230 275 265 262 256 248 266 240 246 248 272 244 270 249 289 264 276 262 241 238 256 272 267 257 269 274 270 259 244 236 235 246 248 258 259 267 240 241 218 287 261 256 263 244 275 226 272 235 236 269 262 271 228 279 256 235 275 262 274 246 271 284 256 281 247 273 235 268 244 248 275 272 236 247 278 262 241 274 241 274 271 246 284 240 266 272 242 240 255 265 292 280 277 268 239 261 258 248 267 275 236 260 278 238 248 243 264 276 261 271 228 258 236 258 300 220 230 269 236 281 248 268 245 266 264 265 264 249 255 267 258 260 239 249 271 277 231 249 285 247 276 265 230 236 241 276 277 261 238 264 269 274 261 245 259 259 248 259 259 258 292 273 268 240 233 249 268 235 305 274 256 276 282 293 242 301 240 260 273 273 270 265 260 219 269 264 256 240 298 264 263 245 228 239 257 277 268 277 270 270 235 284 233 242 258 286 245 237 267 271 259 265 249 224 272 232 238 246 276 263 272 281 264 267 236 275 272 237 256 281 271 264 217 268 264 279 248 265 262 259 264 274 238 250 237 247 262 234 258 270 228 262 257 274 220 247 249 261 227 265 276 236 245 267 278 267 226 266 257 263 256 280 271 281 270 276 267 263 259 245 272 275 264 290 263 274 261 247 291 246 272 257 295 283 260 279 268 239 267 276 236 274 266 269 238 270 291 277 267 279 274 241 266 258 282 265 270 289 259 272 267 284 268 264 271 259 255 263 269 250 257 279 246 222 238 259 262 283 238 230 266 247 299 274 278 281 240 281 241 260 262 278 265 283 248 290 282 249 244 260 277 268 261 259 276 239 257 236 243 291 234 245 286 261 279 261 247 263 275 249 265 314 242 261 282 247 246 270 256 281 246 263 304 257 263 241 285 247 273 243 268 266 244 262 248 266 243 257 263 232 275 255 271 297 237 288 243 257 255 277 275 243 270 250 230 247 255 275 237 248 240 277 237 273 262 255 240 286 245 241 266 310 261 219 265 273 264 306 231 234 231 268 258 274 263 278 285 248 268 272 241 262 274 238 280 226 258 270 275 234 258 239 246 292 268 266 267 275 247 260 260 283 283 278 298 233 285 273 261 276 263 273 280 270 287 259 262 269 269 248 280 240 282 288 268 244 256 246 268 273 244 258 248 235 245 241 255 262 255 266 262 274 265 237 247 266 260 273 259 275 244 248 257 242 278 264 283 241 208 264 260 273 284 260 287 243 238 266 245 282 267 261 275 275 279 247 275 247 286 247 233 273 271 244 268 271 249 265 267 238 268 279 292 256 247 240 272 274 246 236 240 233 283 275 260 261 249 279 264 267 281 262 260 282 259 265 246 274 270 276 242 265 264 265 275 268 272 271 258 272 284 233 259 230 266 264 257 278 272 260 262 249 257 282 244 261 271 296 247 263 276 267 269 219 272 279 263 302 266 297 295 264 247 280 286 246 242 288 232 274 233 260 278 261 274 239 256 272 269 259 255 255 243 245 246 250 287 235 276 245 267 264 279 268 290 232 276 237 257 273 270 275 266 268 291 269 242 248 276 244 245 272 267 268 258 255 249 284 274 263 247 271 240 266 287 270 279 247 269 264 228 248 268 268 240 276 297 265 242 284 276 247 223 263 265 263 238 264 280 264 249 245 295 249 226 265 280 267 226 291 260 303 276 280 256 241 242 280 268 267 290 282 225 302 269 257 261 265 274 265 258 270 287 250 287 272 261 256 247 260 269 294 259 277 271 287 255 277 240 248 271 260 285 265 272 286 276 259 270 258 237 266 239 259 274 257 257 303 272 242 260 308 261 255 272 283 291 246 292 281 237 236 308 266 268 272 270 268 280 292 261 277 276 289 265 267 256 266 244 279 280 264 293 277 249 264 229 260 293 287 272 302 250 296 249 257 233 247 298 270 289 278 264 296 286 275 244 274 279 262 243 282 259 262 266 261 275 244 268 306 285 278 272 284 270 257 261 273 258 286 294 258 282 273 289 281 248 267 228 264 267 265 273 227 280 265 245 266 259 262 281 238 262 297 272 264 301 294 269 262 267 255 244 268 282 291 243 278 265 294 268 284 264 246 262 265 275 258 275 278 257 266 258 266 249 285 272 266 272 308 276 246 273 249 278 274 247 244 277 291 263 273 265 261 243 249 284 268 246 274 248 282 278 274 293 263 263 273 268 285 277 274 276 264 283 249 262 276 269 270 275 274 262 281 264 261 295 298 234 276 241 245 232 247 272 256 276 270 272 288 269 283 256 257 246 259 264 287 261 260 280 276 262 248 256 260 242 275 268 257 246 241 231 258 288 273 293 291 274 245 297 257 268 269 274 280 273 283 271 274 289 221 266 260 273 298 275 267 255 273 238 260 275 241 242 258 275 277 272 260 280 269 287 266 259 280 234 255 259 241 284 264 248 261 264 261 264 291 287 256 248 264 270 246 245 272 291 270 264 305 263 229 258 244 277 270 245 250 271 247 294 270 269 282 241 287 255 284 242 240 279 264 249 256 294 289 233 233 285 259 286 270 270 265 269 291 295 226 267 266 237 229 257 267 273 242 269 301 256 259 261 300 261 289 264 269 271 259 265 264 268 255 290 289 241 282 222 290 263 270 271 281 242 270 281 267 257 300 285 293 270 289 289 234 275 291 278 270 257 266 276 274 277 245 264 273 290 277 286 238 285 245 269 262 243 241 283 289 245 244 265 282 295 302 268 238 274 306 294 259 271 247 268 268 262 247 266 231 269 259 260 239 293 222 270 276 249 268 258 255 280 267 285 261 258 277 257 229 247 239 275 234 224 242 271 255 243 274 286 237 256 243 248 268 236 260 258 246 258 272 239 231 284 285 255 257 235 268 307 248 285 268 274 263 256 270 280 226 260 240 291 262 284 261 245 277 256 272 258 269 244 276 249 287 291 267 276 250 249 247 248 257 260 265 266 250 243 300 246 246 267 286 278 289 239 271 260 276 229 299 229 281 263 270 285 249 272 248 266 248 277 270 274 262 285 249 271 290 267 243 299 248 298 277 277 271 279 271 235 244 278 279 232 262 278 245 244 249 266 276 279 239 276 264 265 249 289 256 272 264 227 248 244 279 269 259 273 261 262 257 245 269 261 265 268 246 227 247 279 288 269 248 263 259 270 279 266 285 240 308 277 303 246 264 249 271 227 216 242 256 301 270 270 265 271 242 234 289 287 275 284 278 277 268 259 213 260 268 260 241 300 265 268 270 271 243 262 243 277 263 259 237 270 247 258 265 274 274 241 279 270 265 278 291 247 238 225 281 255 275 283 280 277 256 275 238 272 270 304 248 287 290 243 297 247 258 319 271 268 249 228 237 286 259 272 272 265 261 282 272 264 258 248 266 285 291 283 270 281 274 287 269 238 249 242 290 283 270 243 266 295 264 268 278 250 276 275 246 262 279 246 269 244 257 288 256 261 263 237 271 294 291 270 282 291 273 257 268 283 242 257 249 294 235 290 237 265 277 277 240 268 272 241 246 291 249 259 274 261 259 292 278 248 258 248 261 271 276 281 281 279 269 280 248 274 292 280 270 280 280 284 273 223 293 280 261 256 280 236 248 295 249 257 256 265 275 256 248 233 292 295 289 289 245 281 264 265 283 230 284 263 279 267 268 257 244 255 278 238 275 299 272 270 262 246 258 286 236 284 272 288 270 284 258 267 272 264 298 298 280 281 261 261 273 290 244 269 259 282 277 276 285 287 279 234 269 265 276 267 266 287 264 290 262 279 281 276 245 284 272 268 315 263 284 268 281 270 266 281 275 283 277 255 281 277 241 263 285 279 285 262 282 245 269 245 268 269 245 237 273 278 286 291 257 271 275 274 281 280 282 280 264 264 278 297 256 298 322 269 283 287 273 278 283 256 262 293 258 294 275 291 257 260 286 295 240 279 287 268 312 301 263 302 274 272 273 276 274 308 308 304 291 279 273 268 296 279 249 312 301 295 302 304 305 311 303 282 289 322 283 285 286 288 287 266 281 294 316 269 302 267 279 283 301 264 298 310 298 275 279 319 297 298 310 284 246 281 285 259 289 250 287 279 282 301 241 288 281 295 322 283 265 278 280 267 278 279 300 287 250 249 299 277 304 280 274 280 259 297 259 315 290 246 279 262 285 267 268 243 305 289 259 268 244 270 276 296 269 277 284 238 270 269 313 296 278 270 292 277 272 301 262 297 256 309 241 279 273 287 269 294 232 306 247 291 289 277 289 276 261 264 307 279 247 279 269 277 278 261 246 282 294 284 286 278 276 295 275 290 268 305 272 249 291 261 262 276 287 279 278 255 287 292 274 256 267 255 258 290 279 256 279 275 275 244 290 292 276 286 265 270 272 283 235 294 261 311 275 262 256 283 257 284 289 284 284 266 277 309 263 281 275 268 268 264 282 290 285 260 290 282 308 292 312 278 296 270 292 296 291 274 289 271 257 261 268 302 263 239 300 256 273 280 228 235 255 265 282 288 272 277 284 298 273 237 261 239 274 273 276 259 240 257 281 279 302 291 280 257 283 272 266 288 278 269 274 260 310 280 269 284 279 284 279 250 266 284 266 277 292 269 265 244 258 265 299 272 238 279 279 280 273 274 275 294 260 277 280 292 273 289 245 263 264 291 284 307 284 247 248 271 286 264 306 242 284 229 283 281 292 262 285 275 292 298 258 288 257 280 278 277 249 310 284 258 269 293 277 255 277 298 278 293 279 298 228 284 282 299 267 282 279 280 239 268 262 306 271 285 273 298 260 269 258 275 284 262 281 256 310 306 284 271 232 283 257 260 247 268 256 276 271 270 268 279 275 265 272 274 259 290 270 283 285 292 261 266 260 265 262 281 258 281 277 272 246 274 275 270 259 288 292 269 302 255 283 286 283 286 238 279 270 314 262 265 295 277 272 270 273 278 275 269 257 270 272 299 310 268 264 261 270 256 286 261 297 278 243 276 289 284 269 315 264 296 277 249 276 264 273 279 294 242 257 257 318 265 247 273 308 255 275 287 262 231 278 274 271 266 244 237 293 292 260 274 264 270 246 270 280 255 288 258 273 276 255 274 282 309 272 244 273 276 264 261 248 226 237 272 271 279 289 275 292 275 250 243 243 257 267 300 260 263 263 283 297 257 277 271 260 281 301 275 259 259 275 279 257 272 274 244 286 275 270 275 236 215 269 292 248 268 284 267 268 272 250 297 260 266 279 277 260 274 273 294 268 248 246 282 274 283 261 261 285 317 249 232 283 281 259 270 243 242 278 245 291 275 263 255 301 273 237 283 288 283 280 264 274 284 291 288 270 290 235 261 292 290 260 277 284 241 285 261 258 273 261 296 255 264 257 285 292 264 242 284 296 270 258 277 279 260 287 255 263 265 278 268 285 260 320 273 250 277 261 273 283 263 273 286 289 278 290 263 266 263 278 261 257 292 262 259 269 275 259 264 269 299 244 261 298 279 299 298 272 287 282 282 259 286 273 235 279 287 247 257 289 271 266 259 263 292 262 270 294 303 262 257 270 241 248 261 262 242 286 268 276 275 238 276 269 256 259 283 236 276 269 247 279 264 265 267 275 269 294 311 249 243 288 299 306 270 291 290 248 282 230 246 234 247 283 242 262 286 263 279 301 279 267 265 280 278 279 285 268 268 261 276 249 286 261 280 272 275 282 302 265 306 272 288 289 274 285 283 282 275 277 306 271 284 243 271 281 291 277 269 289 275 255 298 264 232 242 294 242 263 261 277 272 281 243 273 280 259 234 241 288 293 255 272 276 288 233 273 272 282 274 266 263 266 263 292 268 247 268 263 259 270 291 287 263 276 242 268 286 270 284 268 265 272 286 265 234 267 271 245 282 294 281 268 256 233 279 267 281 281 268 263 266 283 235 276 262 297 258 280 262 270 278 263 270 260 306 276 266 285 258 291 290 289 256 262 293 261 286 282 248 275 279 258 300 255 282 280 267 263 285 296 274 241 269 283 281 244 289 281 248 282 256 259 274 281 247 271 264 302 270 306 291 260 285 289 259 256 240 258 286 271 273 286 289 273 228 246 262 276 235 297 284 249 269 257 276 280 245 255 273 265 258 287 278 264 265 232 224 258 249 263 249 255 249 271 298 283 266 257 265 272 286 295 267 289 290 278 294 229 275 272 240 273 299 249 266 278 249 248 262 267 282 246 295 264 255 257 267 268 243 308 276 263 264 282 296 241 296 247 272 284 266 291 282 273 235 264 268 236 315 275 291 242 264 255 257 287 281 274 288 257 267 295 291 249 300 273 238 284 257 300 277 222 286 259 271 281 289 274 249 263 247 247 262 262 277 273 289 274 240 260 279 237 272 275 312 272 262 294 282 283 280 274 273 269 274 279 263 241 289 235 278 275 296 285 270 290 280 293 262 261 239 279 255 277 237 260 323 284 248 314 260 262 281 280 270 239 267 257 290 272 260 272 262 295 281 274 262 277 255 233 265 292 266 266 263 265 301 272 257 276 247 257 272 285 304 267 240 265 297 270 311 294 284 279 243 263 262 241 249 281 265 279 272 275 265 292 256 241 248 270 290 295 283 270 279 285 274 264 262 272 241 274 282 261 285 292 270 257 261 275 307 298 247 276 256 287 278 243 260 268 246 269 238 266 263 259 286 255 280 250 269 276 270 288 288 280 282 288 281 265 239 266 268 265 264 257 227 271 281 279 256 264 237 282 269 279 297 284 286 247 274 262 257 262 260 249 268 289 269 284 242 283 268 241 257 255 273 244 245 265 268 276 263 274 269 274 267 268 288 277 269 259 232 282 291 295 275 266 271 284 259 248 273 272 266 271 269 287 300 267 287 283 272 282 255 270 275 266 238 237 250 275 262 256 259 263 268 242 249 282 236 256 272 245 281 239 256 241 260 298 300 266 271 288 259 270 292 297 248 273 263 265 226 299 274 281 272 281 262 276 319 265 261 269 248 281 294 264 267 248 267 267 281 288 265 314 286 262 267 284 258 278 277 259 269 290 275 263 293 274 300 248 257 278 293 262 274 268 290 296 265 262 264 273 227 279 265 272 255 285 256 280 283 270 269 264 263 292 290 304 277 271 291 236 260 273 225 243 290 271 295 259 270 227 283 274 282 294 255 264 275 260 260 294 262 278 271 226 272 272 278 243 284 227 255 284 269 278 276 283 236 262 277 258 248 288 242 278 242 263 266 285 265 255 266 260 246 255 275 283 244 305 287 232 293 237 286 296 237 272 233 258 264 250 258 292 263 258 273 265 265 219 279 243 279 303 285 248 270 280 277 267 288 279 245 297 237 255 291 233 275 282 279 277 247 243 235 246 241 269 271 258 283 308 283 272 264 266 274 243 278 243 274 287 270 244 279 271 276 308 287 246 279 268 270 247 292 266 299 279 269 276 261 267 289 290 265 281 238 249 232 258 267 267 265 211 272 258 238 270 250 242 264 243 271 273 281 259 298 224 261 258 274 243 261 259 228 283 276 248 264 258 236 276 267 273 237 261 266 249 248 265 250 276 269 298 271 276 247 285 281 264 248 269 293 280 243 257 247 255 263 249 270 247 301 272 240 268 264 261 246 245 259 267 247 277 258 259 282 247 293 291 295 275 243 265 271 234 278 297 238 262 258 232 269 268 291 266 259 244 267 262 269 259 263 282 311 270 248 245 233 263 275 293 282 247 281 289 273 295 257 293 255 274 296 248 285 264 244 235 292 249 261 281 261 258 301 276 257 256 285 263 237 249 246 263 276 308 262 235 276 258 229 263 260 277 271 264 272 272 279 277 259 238 267 281 302 293 249 235 294 266 281 290 259 232 286 266 291 297 286 265 269 260 247 295 277 269 262 296 271 244 306 257 281 278 264 256 288 294 265 302 274 293 244 264 288 282 303 269 256 281 265 280 278 275 287 306 286 288 292 272 271 299 281 283 255 307 287 298 299 307 278 315 287 309 273 294 279 304 281 306 321 283 286 324 340 313 296 290 323 284 307 350 313 320 296 297 312 319 267 304 290 337 316 307 297 317 347 310 305 325 306 304 274 282 257 306 311 260 312 257 296 296 273 335 315 279 300 270 308 293 325 290 293 280 299 300 263 267 331 272 267 259 284 267 276 276 271 267 289 267 275 279 246 296 256 283 266 306 258 249 271 287 274 259 243 271 255 267 263 272 258 290 296 275 250 296 266 274 292 286 290 285 294 234 237 284 272 282 244 282 284 267 287 301 271 293 266 272 264 266 277 292 256 266 265 269 298 259 246 269 281 280 255 279 259 274 263 244 307 260 264 283 261 291 272 264 259 264 255 272 286 277 308 263 241 271 246 261 279 248 256 267 284 270 272 246 235 280 243 276 224 290 264 270 249 291 274 291 271 278 286 277 271 265 267 282 270 274 263 242 289 283 248 261 288 259 237 293 269 258 244 284 279 290 271 261 230 242 273 275 235 280 269 263 242 257 267 278 255 247 296 265 265 236 248 262 273 272 287 273 265 236 263 323 247 279 294 275 286 298 247 247 272 260 258 271 275 263 305 257 285 267 248 228 248 225 286 247 282 275 267 249 246 273 286 256 255 296 268 278 238 273 268 287 269 256 289 284 283 270 291 265 273 238 261 269 267 259 263 280 243 267 247 255 282 247 259 255 313 256 242 275 269 276 264 267 286 280 248 264 272 302 242 246 292 240 269 293 285 247 270 278 273 274 311 297 280 220 268 287 288 230 257 278 279 244 266 256 241 278 266 255 244 281 284 280 241 264 244 272 287 298 256 274 294 276 222 230 274 269 281 303 246 243 263 299 243 279 292 286 262 256 282 302 259 265 231 280 279 291 279 272 275 271 287 279 290 268 232 318 222 259 267 258 269 249 266 287 271 277 292 290 238 280 248 288 255 315 263 285 275 263 277 268 272 277 238 292 282 274 283 247 266 270 233 284 249 241 270 279 284 308 286 256 255 255 271 277 255 278 227 258 264 273 261 277 277 269 235 256 267 257 271 270 279 274 267 239 268 298 263 297 268 256 280 240 289 256 273 260 291 248 280 238 259 267 257 296 248 269 250 269 266 300 301 269 272 286 270 289 290 262 278 245 272 247 270 265 262 280 268 220 256 278 271 237 290 284 291 270 272 241 264 245 263 271 273 264 273 281 274 274 243 289 241 257 255 246 297 271 272 261 245 288 258 259 228 277 258 245 262 272 256 265 280 244 266 281 264 237 287 278 246 246 281 267 263 266 282 260 249 265 291 267 272 295 286 276 272 270 294 270 263 277 266 246 261 241 289 270 273 290 279 245 244 261 240 217 256 267 248 262 293 259 268 245 276 285 301 257 286 296 296 266 302 236 279 287 290 277 282 266 292 272 262 268 277 271 278 243 267 283 234 247 273 281 279 261 277 267 248 292 308 283 245 289 272 235 245 267 278 263 250 270 260 281 266 297 282 278 273 290 286 273 282 289 262 255 283 271 291 267 265 266 265 269 255 255 256 260 249 232 311 270 243 245 270 276 268 255 255 224 267 255 287 287 278 265 258 272 273 293 249 258 270 271 275 245 259 258 291 275 272 268 257 289 265 270 277 255 261 298 249 259 267 261 273 278 281 281 263 275 279 263 283 273 285 284 275 233 267 257 233 271 315 269 275 267 280 265 242 224 259 277 249 258 277 282 258 246 287 270 223 267 249 276 260 281 273 261 264 235 246 261 263 269 263 272 223 234 276 258 275 261 263 248 233 224 287 263 280 245 258 242 282 236 273 278 293 292 272 242 272 278 280 256 261 282 270 248 289 265 240 263 249 265 279 239 248 246 263 280 225 246 295 256 255 261 274 256 287 236 255 279 234 273 257 242 270 265 242 250 290 291 244 268 263 273 229 248 228 242 273 262 271 256 281 246 274 275 279 231 296 234 242 281 265 276 258 287 291 256 270 266 277 269 238 267 281 257 248 247 264 247 256 239 264 267 243 270 267 273 287 256 283 290 230 258 261 232 258 239 248 277 265 267 259 274 229 274 244 247 286 276 246 307 274 270 273 278 235 247 218 276 256 267 255 257 260 285 290 274 260 268 249 283 266 290 249 261 235 266 239 293 250 289 260 257 276 277 267 275 256 255 224 236 231 261 259 269 274 259 273 272 235 250 256 282 267 256 263 236 243 238 311 294 249 242 234 263 267 268 278 260 273 263 257 230 269 276 232 276 244 264 270 247 244 262 250 277 237 275 245 248 258 216 248 261 247 250 287 246 270 272 260 268 272 229 278 258 273 265 255 273 248 248 236 263 286 237 263 295 258 264 248 305 275 255 278 262 305 258 233 231 245 282 232 270 247 237 283 233 301 246 260 242 264 259 239 268 257 258 270 283 272 260 257 278 263 227 270 238 284 268 264 271 262 230 287 241 257 286 263 240 271 246 231 288 288 274 275 258 276 287 278 227 257 268 270 227 242 263 261 250 269 278 281 237 243 277 259 272 248 294 294 265 277 284 282 233 232 263 279 237 235 268 256 274 236 281 249 257 274 278 259 246 249 242 269 278 259 267 256 259 263 271 256 230 300 259 218 270 247 256 275 275 263 269 249 261 280 245 277 280 290 274 277 282 275 279 229 279 257 263 281 263 246 243 284 280 265 269 282 288 256 249 292 277 290 226 295 288 229 276 272 295 267 271 247 240 269 278 270 248 265 272 270 259 276 256 239 276 265 271 286 270 255 236 261 275 245 237 275 277 280 296 285 288 259 282 280 279 277 305 249 264 278 260 266 283 273 279 241 235 289 271 232 245 260 267 265 230 264 258 275 243 295 250 268 243 224 273 264 264 269 241 257 261 241 281 272 275 248 244 272 260 275 260 258 267 256 273 269 239 260 271 256 279 247 260 321 246 244 271 257 264 271 281 256 247 269 243 272 260 263 258 302 272 274 265 279 284 259 259 295 267 242 276 271 249 265 276 244 265 257 283 243 278 279 267 247 271 261 240 281 262 289 229 263 256 261 262 248 271 277 293 305 255 257 264 255 262 278 260 262 279 270 244 274 225 264 288 264 273 285 270 225 259 281 281 261 255 244 257 272 281 264 267 277 268 274 286 264 277 271 258 282 267 242 296 272 267 257 276 261 238 244 258 259 269 277 282 293 290 256 233 269 288 313 277 257 278 260 268 283 275 280 246 243 245 280 255 263 274 260 271 242 278 283 277 267 269 264 274 264 265 280 270 270 266 247 274 269 263 256 271 266 255 276 269 286 257 290 269 294 276 294 257 284 269 279 245 260 265 256 244 279 288 249 262 262 258 263 244 286 286 265 273 287 261 286 287 232 275 262 278 256 300 240 241 259 263 245 248 239 245 269 264 279 273 283 280 289 300 247 260 279 267 280 292 275 266 262 234 268 259 271 279 294 268 294 282 297 283 299 273 266 277 275 303 283 242 277 272 241 286 240 257 267 262 272 284 280 249 290 255 275 276 271 242 262 247 282 265 274 257 278 276 281 258 272 278 258 279 264 258 243 273 291 302 242 263 273 259 267 255 247 256 269 289 262 244 255 268 269 260 270 238 294 287 284 278 263 268 274 273 279 263 264 277 287 286 286 244 288 249 280 248 261 289 267 275 281 267 277 270 272 293 294 301 306 306 304 284 275 265 288 264 258 271 262 247 242 263 271 268 271 256 300 281 280 308 269 260 279 282 274 280 292 305 281 249 272 269 270 293 274 264 269 275 279 270 278 269 260 238 267 280 280 262 305 257 281 277 290 304 279 292 271 271 285 262 295 281 282 311 288 285 275 269 230 274 294 314 266 290 278 309 238 261 293 277 293 286 292 294 271 289 273 271 277 294 290 284 281 270 305 280 304 285 282 288 287 266 313 282 285 308 275 269 293 282 310 304 282 302 256 295 259 293 309 290 283 277 272 275 324 301 298 271 248 272 287 317 284 267 274 292 300 258 293 279 256 272 270 291 279 281 291 263 265 292 281 297 241 282 244 270 279 237 275 268 248 271 255 278 269 259 293 321 285 280 247 288 243 248 263 255 288 277 264 255 266 285 262 273 269 260 282 283 288 301 283 247 247 241 286 278 246 246 286 263 278 286 221 262 262 284 257 258 271 246 259 273 312 234 264 269 284 299 261 294 289 263 277 245 267 248 269 265 279 266 276 274 279 279 296 247 285 264 264 275 261 243 244 263 281 261 256 260 267 276 274 241 262 230 262 255 255 246 274 280 265 284 209 262 256 281 290 296 306 278 274 311 303 270 271 256 267 271 234 267 279 270 304 257 293 280 291 279 260 264 268 283 273 239 263 263 280 244 255 257 248 286 260 260 273 278 258 259 289 244 283 264 258 273 276 266 270 281 292 255 286 260 256 268 261 291 246 289 303 247 280 260 294 262 270 258 286 285 260 292 285 271 276 256 279 289 267 230 260 259 242 276 291 275 256 259 258 263 267 249 267 279 270 203 288 303 287 233 275 248 285 247 286 272 282 279 268 280 262 291 297 245 276 275 272 243 266 263 259 275 264 271 263 296 276 262 260 263 237 284 249 240 264 276 290 293 288 266 285 257 272 258 259 262 307 273 276 261 229 266 246 286 264 261 286 239 264 293 244 269 271 288 260 259 278 303 267 285 292 259 267 258 270 277 291 259 279 269 247 249 271 233 267 277 240 283 243 259 267 281 285 235 279 265 288 277 268 259 284 262 268 264 267 278 270 288 272 283 243 291 270 301 277 239 261 263 281 271 298 249 256 267 299 245 289 289 271 259 267 250 276 262 271 267 301 237 261 287 301 282 264 293 247 260 307 269 274 277 249 261 275 292 277 285 281 283 258 227 298 273 273 283 276 257 266 255 263 259 295 272 256 234 282 288 297 267 306 274 259 244 279 234 255 272 264 288 273 244 266 229 271 245 291 287 245 287 258 280 315 259 298 230 308 257 279 259 276 263 244 265 265 261 264 260 268 273 264 274 291 261 308 276 267 270 317 269 267 255 274 307 263 288 238 257 283 274 248 272 273 282 266 255 217 275 279 270 264 264 290 244 244 260 268 238 279 286 261 280 267 289 275 270 247 247 239 258 306 256 278 267 264 274 239 264 287 300 287 266 290 269 257 246 274 277 255 242 286 301 267 278 285 259 295 301 280 311 281 273 261 297 282 270 270 290 265 262 279 239 276 277 280 287 278 245 256 264 282 277 278 283 260 227 249 271 274 262 263 289 247 313 301 292 279 262 300 256 232 274 250 280 268 272 244 266 281 258 246 268 241 270 275 282 278 271 299 262 290 280 265 273 300 276 261 271 274 283 283 264 288 288 325 276 249 274 263 271 268 277 278 276 249 288 270 244 281 244 302 255 282 285 266 279 264 273 256 257 239 283 279 264 264 274 269 273 260 261 249 259 257 298 261 243 282 276 282 255 275 246 260 297 277 263 247 317 258 272 279 270 280 280 260 301 304 278 247 274 304 298 269 268 261 307 247 257 271 255 257 283 259 281 310 281 270 290 314 264 269 266 224 264 257 310 261 281 246 260 278 285 264 264 270 266 313 281 279 272 262 269 272 280 249 270 281 260 280 277 238 264 288 294 270 301 229 303 274 269 255 278 260 273 263 246 273 247 289 272 247 291 274 286 270 295 261 244 274 286 274 264 306 267 261 257 249 283 288 279 263 276 287 282 291 234 294 256 283 238 270 260 286 286 301 293 282 294 279 261 265 285 285 305 285 288 289 296 296 263 273 248 263 282 242 294 240 303 296 240 311 295 263 270 240 293 286 318 269 241 255 288 244 291 265 259 275 245 281 271 275 284 269 277 270 259 242 282 289 295 290 245 275 279 255 260 258 277 278 275 259 259 290 260 283 281 289 266 246 276 266 234 280 269 262 294 300 257 292 281 271 269 276 279 273 281 272 241 262 265 298 309 263 249 264 303 271 278 285 303 266 282 269 274 273 248 272 300 260 288 287 247 270 273 250 298 282 270 281 286 278 272 285 269 274 287 267 293 239 304 269 310 281 249 313 276 298 256 280 267 298 261 266 258 269 279 282 269 259 237 249 270 266 279 272 284 275 276 238 265 273 263 291 277 288 276 273 275 250 285 262 267 282 250 250 282 262 283 275 270 274 295 263 281 247 286 249 263 278 307 307 272 276 264 283 269 289 229 274 273 238 263 269 277 274 262 276 271 256 260 257 262 257 274 260 296 272 284 269 245 287 276 273 268 293 245 276 272 257 275 261 238 266 267 293 283 285 269 288 293 282 277 242 290 288 276 296 298 283 283 286 272 290 274 279 262 286 290 260 272 276 277 246 287 268 278 282 311 286 276 284 269 259 262 280 306 277 245 273 237 274 263 281 269 267 274 264 288 258 278 276 246 292 281 260 269 277 230 291 305 291 264 260 261 261 272 261 267 296 275 290 286 285 300 275 260 255 282 280 261 285 303 293 271 300 282 243 297 248 260 279 279 263 277 286 248 267 278 265 257 292 279 286 271 261 264 261 270 268 260 258 279 271 305 280 295 282 281 296 275 282 241 272 269 289 267 281 267 286 287 260 290 278 287 292 282 264 266 281 270 272 267 280 314 269 274 275 290 296 259 231 290 281 289 272 267 279 262 287 246 286 241 249 296 249 262 283 272 295 242 262 281 260 258 274 271 269 299 287 245 284 316 275 281 274 267 299 302 288 266 273 270 285 285 268 241 247 249 255 288 236 260 256 265 242 276 275 261 277 229 284 273 223 248 277 242 270 272 238 288 265 240 257 293 240 272 246 236 268 265 268 272 269 281 291 256 246 285 268 266 282 280 244 298 296 288 225 230 261 256 285 287 244 272 243 260 255 249 281 274 274 277 267 261 265 285 265 287 261 311 264 263 260 294 279 258 270 241 285 283 258 278 248 269 299 230 285 283 273 248 287 277 243 301 298 247 259 303 267 246 264 273 256 283 243 234 276 261 305 268 267 246 261 247 265 264 270 255 275 276 287 270 257 266 280 286 287 263 261 248 284 273 275 278 265 278 261 260 269 274 283 275 287 277 257 244 246 281 283 269 255 258 259 262 259 236 279 274 270 272 289 239 289 280 270 263 243 243 257 275 243 249 292 271 271 260 227 271 260 240 279 257 296 257 263 271 244 293 265 283 271 266 239 295 263 275 282 295 248 269 305 279 268 261 286 290 290 286 276 276 264 256 282 266 247 269 267 262 267 255 262 259 275 269 283 263 246 272 249 281 249 271 280 246 272 274 248 296 301 247 261 228 266 240 266 275 286 283 272 249 294 260 285 276 280 292 284 277 245 269 241 290 264 290 278 293 287 285 284 271 293 278 234 258 292 267 292 291 241 262 250 287 289 256 244 271 256 289 261 233 266 295 295 295 299 268 297 267 281 268 264 279 290 290 273 259 287 303 271 270 310 277 279 284 296 297 274 268 262 264 275 273 263 264 255 306 268 271 301 273 263 273 292 266 298 284 281 284 267 271 282 262 288 278 312 284 279 281 297 255 313 235 288 263 275 295 277 273 307 307 300 261 260 267 298 270 274 271 276 279 283 308 282 259 295 301 261 234 271 255 264 286 281 278 280 291 282 286 267 272 298 267 281 249 305 260 274 270 257 275 277 289 270 275 290 269 292 277 260 270 221 243 289 271 313 310 296 307 294 300 285 266 261 280 295 265 303 271 313 289 250 290 293 320 288 307 246 303 312 300 291 290 305 281 265 308 288 284 320 288 298 289 296 296 305 318 266 301 292 279 279 266 290 295 270 246 295 274 297 307 264 302 313 313 315 271 276 298 294 281 280 317 296 279 288 304 302 269 299 283 281 264 315 287 304 289 303 290 309 287 329 317 288 312 283 283 311 290 313 302 281 301 274 280 260 290 293 287 297 311 257 289 303 310 291 298 274 306 283 293 285 267 330 288 304 323 294 289 290 261 287 309 305 287 302 321 268 271 300 276 290 285 275 275 249 291 310 312 234 284 304 286 318 293 326 290 276 280 267 292 291 288 261 296 307 292 268 289 270 306 289 296 310 291 291 290 265 290 298 305 271 291 274 274 279 288 292 279 274 307 283 294 303 283 301 266 285 275 290 294 258 281 287 293 283 282 274 272 240 263 282 280 267 280 302 281 300 284 288 306 259 275 293 267 278 309 268 280 285 272 277 264 272 246 305 264 282 286 271 273 301 247 284 257 294 272 271 275 275 292 310 267 281 309 274 309 246 262 270 292 296 288 296 285 235 267 244 267 268 269 288 280 275 283 287 256 294 300 296 301 261 288 271 266 277 274 287 294 259 288 245 263 243 260 302 259 275 277 291 291 299 261 279 301 279 284 262 255 272 303 302 315 294 278 285 301 271 304 269 265 286 279 296 286 325 278 276 272 290 280 277 291 281 286 233 285 276 281 285 267 290 274 272 262 274 262 278 284 269 299 269 257 291 280 291 272 261 245 286 274 269 279 265 288 270 265 268 233 287 300 307 273 217 276 276 275 273 267 239 278 279 275 244 281 293 295 265 276 286 260 288 249 264 265 255 295 291 241 290 278 264 267 286 273 272 272 281 287 265 277 264 292 293 245 288 286 266 288 280 263 286 273 276 276 274 273 298 279 288 234 234 290 262 277 287 305 261 248 255 292 315 284 270 261 272 272 268 268 281 246 245 227 240 278 291 288 262 283 260 263 264 243 238 294 304 302 291 303 266 284 238 278 280 267 291 292 274 260 274 299 298 263 282 259 275 261 292 281 262 289 289 286 273 284 287 288 290 334 302 278 284 232 301 229 267 272 283 275 278 243 273 304 276 278 281 279 277 292 246 261 265 301 306 278 257 262 263 275 276 266 255 236 267 256 273 266 273 266 283 268 276 292 274 283 301 291 271 292 287 240 263 260 277 238 265 274 292 284 256 281 291 285 225 297 280 245 290 286 265 232 250 294 263 241 269 305 282 262 286 280 278 258 275 239 282 245 292 273 258 267 284 272 280 255 249 265 226 278 269 277 261 301 259 277 291 277 265 276 242 260 267 269 259 256 255 281 280 289 263 269 265 282 256 272 300 259 237 280 289 298 273 288 274 249 260 270 281 263 289 279 275 281 288 264 283 274 248 268 272 307 242 284 283 277 276 306 263 284 260 263 271 290 262 267 286 275 294 268 291 249 276 257 271 287 307 267 281 268 249 287 293 292 277 285 270 267 247 261 285 262 281 271 278 271 289 297 263 285 292 266 242 296 284 287 275 282 275 247 264 235 232 222 291 291 278 264 275 243 297 266 247 279 283 256 263 289 258 292 290 280 269 284 271 299 297 270 279 295 264 282 283 243 270 248 262 269 223 250 291 304 262 286 242 247 261 269 258 302 272 306 245 280 262 262 288 264 239 262 269 261 265 263 287 263 282 257 295 289 320 277 280 268 271 242 298 272 265 267 286 285 241 283 266 247 285 271 281 300 234 273 263 273 273 245 295 280 258 310 265 238 264 262 277 310 287 280 257 235 281 240 256 249 292 264 249 268 271 248 271 274 242 263 247 270 271 285 263 267 241 280 270 269 284 270 271 278 263 246 282 288 285 283 296 294 270 277 273 235 260 273 240 311 268 286 269 277 242 266 266 249 285 267 282 275 272 241 264 247 278 299 270 255 318 267 298 244 267 307 266 255 285 272 266 258 271 285 284 296 271 274 330 240 294 275 283 299 270 243 280 259 290 275 262 296 261 280 310 288 282 272 274 280 239 243 299 264 265 294 249 239 249 302 286 265 288 258 304 282 276 270 295 316 294 294 268 269 258 269 272 286 274 284 247 272 293 223 300 248 249 255 248 290 231 293 271 262 266 327 257 298 270 278 280 271 259 241 246 273 260 282 291 305 246 296 245 269 291 260 281 316 262 276 284 266 262 286 275 298 279 266 241 239 288 273 294 244 282 275 256 273 250 261 280 294 272 298 245 266 260 285 283 284 295 275 301 262 267 265 274 289 272 262 280 255 245 288 286 286 275 280 256 276 276 269 276 270 266 286 270 276 300 278 284 260 272 262 293 287 291 293 284 284 246 276 293 271 289 283 292 284 303 264 242 274 281 305 295 291 303 294 282 314 285 278 284 261 283 284 264 285 287 259 302 245 262 265 292 286 243 304 268 292 286 293 261 284 281 302 272 265 280 259 278 276 287 301 291 273 294 280 277 301 270 269 310 283 273 266 282 244 284 262 247 289 287 271 269 294 289 258 299 272 298 302 281 249 296 323 293 263 276 293 266 249 279 261 311 278 278 285 290 292 275 312 292 286 286 250 296 296 262 278 261 265 288 270 292 293 276 302 284 264 301 262 307 272 236 278 277 266 291 289 283 290 290 285 269 293 246 282 273 304 297 285 275 301 283 286 260 272 274 266 282 294 306 308 284 264 292 289 299 290 292 277 269 257 269 283 281 271 300 288 322 306 261 270 290 308 259 292 290 258 275 277 320 283 312 288 303 279 237 293 291 304 310 297 285 311 289 321 289 266 286 300 265 317 265 290 297 295 291 288 256 259 291 305 262 310 292 305 280 277 300 300 297 274 287 270 247 309 282 287 277 260 289 309 277 289 299 247 274 295 272 288 298 264 280 277 290 304 273 299 273 289 310 293 304 273 275 276 279 277 266 294 280 273 283 272 300 311 258 291 282 302 283 321 303 286 271 298 288 304 274 295 269 275 271 307 293 311 281 286 312 291 290 239 279 300 274 292 305 279 272 287 293 270 293 279 290 280 278 291 301 276 274 269 289 293 299 277 282 286 311 284 277 292 310 289 256 313 283 310 308 301 298 309 293 290 270 293 307 263 279 276 266 281 280 301 289 291 293 275 330 302 282 279 286 297 280 280 241 277 269 299 286 320 279 312 290 299 316 274 308 273 272 288 289 290 323 315 255 282 283 300 310 295 309 281 264 294 297 289 274 270 289 321 280 301 286 307 324 277 284 297 271 305 285 286 307 274 281 301 287 289 278 281 283 291 309 293 321 283 277 283 292 297 299 275 276 281 258 280 284 285 292 290 302 276 327 334 307 301 293 309 278 300 241 269 305 318</counts>
			</dataPoints>
		</scan>
	</xrdMeasurement>
</xrdMeasurements>