File: data/XRD/XG-Vakuum/XG-500/W6824-1C_XG_Vakuum_500.xrdml
<xrdMeasurements xmlns="http://www.xrdml.com/XRDMeasurement/2.1" xmlns:xsi="http://www.w3.org/2001/XMLSchema-instance" xsi:schemaLocation="http://www.xrdml.com/XRDMeasurement/2.1 http://www.xrdml.com/XRDMeasurement/2.1/XRDMeasurement.xsd" status="Completed">
	<comment>
		<entry>Configuration=Factory configuration, Owner=User-1, Creation date=7/8/2013 4:01:53 PM</entry>
		<entry>Goniometer=PW3050/65 (Theta/2Theta); Minimum step size 2Theta:0.0001; Minimum step size Omega:0.0001</entry>
		<entry>Sample stage=MRD Cradle; Minimum step size Phi:0.01; Minimum step size Chi:0.01; Minimum step size X:0.01; Minimum step size Y:0.01; Minimum step size Z:0.001</entry>
		<entry>Diffractometer system=XPERT-PRO</entry>
		<entry>Measurement program=C:\PANalytical\Data Collector\Programs\Jorrit\2thom\_absolute_2th-om_10-130deg_PIXscan_56min.xrdmp, Identifier={15BCCF57-2807-42BD-B5B9-ECC0B3DC9284}</entry>
		<entry>Batch program=C:\PANalytical\Data Collector\Programs\SimonL\batch4x_2thom_10-130°_z9.1_x0,10,20,30_y0_57min.xrdmp, Identifier={EED9823A-2BEB-424C-9252-345C4EF2834A}</entry>
	</comment>
	<sample type="To be analyzed">
		<id></id>
		<name></name>
		<preparedBy></preparedBy>
	</sample>
	<xrdMeasurement measurementType="Scan" status="Completed" sampleMode="Reflection">
		<comment>
			<entry>_absolute_2th-om_10-130deg_PIXscan_56min</entry>
			<entry>PHD Lower Level = 4.83 (keV), PHD Upper Level = 11.27 (keV)</entry>
		</comment>
		<usedWavelength intended="K-Alpha 1">
			<kAlpha1 unit="Angstrom">1.5405980</kAlpha1>
			<kAlpha2 unit="Angstrom">1.5444260</kAlpha2>
			<kBeta unit="Angstrom">1.3922500</kBeta>
			<ratioKAlpha2KAlpha1>0.5000</ratioKAlpha2KAlpha1>
		</usedWavelength>
		<incidentBeamPath>
			<radius unit="mm">320.00</radius>
			<xRayTube id="1010048" name="Empyrean Cu LFF HR (9430 033 7310x) DK442154">
				<tension unit="kV">40.0</tension>
				<current unit="mA">40.0</current>
				<anodeMaterial>Cu</anodeMaterial>
				<focus type="Line">
					<length unit="mm">12.0</length>
					<width unit="mm">0.4</width>
					<takeOffAngle unit="deg">4.2</takeOffAngle>
				</focus>
			</xRayTube>
			<xRayMirror id="27010001" name="Inc. Beam Cu W/Si (parabolic MRD)" hybrid="false">
				<crystal type="Graded" shape="Parabolic">W/Si</crystal>
				<acceptanceAngle unit="deg">0.800</acceptanceAngle>
				<length unit="mm">60.0</length>
			</xRayMirror>
			<sollerSlit id="21010002" name="Soller slits 0.04 rad.">
				<opening unit="rad">0.0400</opening>
			</sollerSlit>
			<mask id="22030008" name="Fixed mask 4 mm">
				<distanceToSample unit="mm">220.00</distanceToSample>
				<width unit="mm">4.00</width>
			</mask>
			<divergenceSlit id="22010007" name="Fixed slit 1/8°" xsi:type="fixedDivergenceSlitType">
				<distanceToSample unit="mm">220.00</distanceToSample>
				<height unit="mm">0.19</height>
			</divergenceSlit>
		</incidentBeamPath>
		<diffractedBeamPath>
			<radius unit="mm">320.00</radius>
			<sollerSlit id="21010002" name="Soller slits 0.04 rad.">
				<opening unit="rad">0.0400</opening>
			</sollerSlit>
			<receivingSlit id="22010001" name="Fixed slit 4°">
				<height unit="mm">5.88</height>
			</receivingSlit>
			<detector id="7010017" name="PIXcel3D 1x1 detector" xsi:type="areaDetectorType">
				<phd unit="%">
					<lowerLevel>30.0</lowerLevel>
					<upperLevel>70.0</upperLevel>
				</phd>
				<mode>Scanning</mode>
				<activeChannelsEquatorial>255</activeChannelsEquatorial>
				<activeChannelsAxial>255</activeChannelsAxial>
				<pitchEquatorial unit="mm">0.05500</pitchEquatorial>
				<pitchAxial unit="mm">0.05500</pitchAxial>
				<readOutPeriod unit="seconds">0.135</readOutPeriod>
			</detector>
		</diffractedBeamPath>
		<scan appendNumber="0" mode="Continuous" scanAxis="2Theta-Omega" status="Completed">
			<header>
				<startTimeStamp>2024-10-07T19:55:42+02:00</startTimeStamp>
				<endTimeStamp>2024-10-07T20:51:48+02:00</endTimeStamp>
				<author>
					<name>PRO-MRD</name>
				</author>
				<source>
					<applicationSoftware version="6.1b">Data Collector</applicationSoftware>
					<instrumentControlSoftware version="7.0E 20130304">XPERT-PRO</instrumentControlSoftware>
					<instrumentID>0000000011142674</instrumentID>
				</source>
			</header>
			<dataPoints>
				<positions axis="2Theta" unit="deg">
					<startPosition>9.99826193</startPosition>
					<endPosition>129.99755682</endPosition>
				</positions>
				<positions axis="Omega" unit="deg">
					<startPosition>4.99913096</startPosition>
					<endPosition>64.99877841</endPosition>
				</positions>
				<positions axis="Phi" unit="deg">
					<commonPosition>0.00</commonPosition>
				</positions>
				<positions axis="Chi" unit="deg">
					<commonPosition>0.00</commonPosition>
				</positions>
				<positions axis="X" unit="mm">
					<commonPosition>30.00</commonPosition>
				</positions>
				<positions axis="Y" unit="mm">
					<commonPosition>0.00</commonPosition>
				</positions>
				<positions axis="Z" unit="mm">
					<commonPosition>9.100</commonPosition>
				</positions>
				<commonCountingTime unit="seconds">32.895</commonCountingTime>
				<counts 455 402 437 441 438 427 462 444 425 439 433 431 440 442 425 399 441 447 431 444 425 468 438 426 454 455 444 437 440 464 466 462 439 472 475 451 473 431 474 444 441 472 440 443 440 425 434 487 512 463 490 461 474 454 462 415 458 451 469 416 460 468 482 432 412 430 455 420 426 418 434 418 435 394 447 429 415 414 422 452 450 449 387 436 440 435 436 422 412 451 414 420 399 424 399 428 411 421 410 426 405 383 448 401 434 413 460 454 394 404 438 426 416 380 399 407 387 400 399 389 437 426 431 428 412 414 422 420 415 408 410 407 405 410 426 431 445 441 390 450 436 405 395 415 389 418 438 370 384 397 416 413 390 389 390 424 459 435 422 408 389 399 443 419 408 421 379 450 412 386 430 412 414 411 387 384 401 355 395 420 418 402 391 369 398 422 367 412 381 384 379 387 389 432 364 382 411 420 402 433 413 353 418 373 362 399 396 376 457 387 405 390 388 401 352 400 417 411 393 374 408 399 417 377 362 384 427 404 398 384 414 415 403 391 424 375 396 415 394 399 346 385 405 399 388 419 357 401 367 371 411 375 433 378 403 425 388 378 372 403 393 398 373 383 360 390 418 430 411 367 400 389 375 393 406 401 383 354 379 391 374 381 391 408 327 353 353 348 386 349 397 384 399 374 348 388 379 351 367 369 374 367 383 388 397 359 387 399 343 371 361 385 396 374 355 401 349 388 347 355 407 367 372 373 372 367 354 377 367 390 382 390 368 336 375 364 377 356 351 351 348 364 317 393 367 354 365 347 353 371 378 405 351 378 356 359 393 374 371 393 388 358 339 355 360 350 369 371 411 398 338 357 378 327 336 361 330 381 345 371 356 325 391 370 336 347 363 367 386 344 336 337 351 315 338 354 334 376 327 363 343 360 330 338 370 359 321 343 318 349 358 319 379 360 315 352 323 347 356 338 344 340 329 327 336 335 351 361 358 358 330 356 359 327 357 353 370 354 353 371 387 339 356 331 342 325 357 380 349 326 339 347 376 386 357 354 354 333 386 362 343 360 381 327 346 329 343 319 363 331 357 393 336 363 370 322 352 344 319 374 359 322 338 321 336 330 352 367 338 350 340 314 320 334 309 334 373 376 326 331 388 366 343 314 339 334 322 386 305 337 316 314 317 374 310 332 386 348 338 344 306 361 379 338 330 353 337 340 354 339 334 332 362 341 330 343 337 354 327 355 300 348 346 339 315 360 333 338 307 336 341 338 339 342 334 313 325 354 321 318 296 312 336 343 323 353 342 345 306 302 337 340 343 329 347 362 310 305 346 314 320 350 344 310 313 327 360 361 323 340 343 336 335 340 297 298 365 381 326 296 307 338 326 318 346 325 338 321 316 312 328 358 336 302 290 347 350 333 372 322 350 337 320 328 347 308 321 345 338 298 302 336 317 303 323 340 329 323 317 318 350 320 313 301 348 355 306 356 347 303 334 335 367 309 301 329 305 339 332 362 306 303 340 318 312 335 344 347 305 341 319 318 290 303 331 318 330 316 323 359 335 316 344 338 316 333 326 372 316 302 319 296 329 301 298 333 314 326 309 318 287 302 296 346 324 339 332 311 357 321 329 313 343 293 328 330 301 311 328 306 356 348 351 348 335 340 345 313 308 320 315 301 327 298 323 320 308 305 360 325 307 315 306 300 311 353 322 342 354 317 345 333 329 314 312 320 334 312 313 338 314 306 336 329 319 334 300 351 308 303 304 335 328 381 327 341 346 340 339 361 297 327 340 322 328 310 334 299 355 303 290 307 329 310 340 316 306 335 332 339 348 308 313 319 322 336 342 285 305 333 318 349 309 334 346 326 333 297 334 305 309 337 333 329 317 335 332 310 314 329 319 290 327 290 311 315 367 301 350 332 328 342 348 301 310 346 303 298 328 330 342 347 310 314 344 311 368 358 314 310 321 316 331 325 315 331 328 319 304 300 329 323 324 338 369 323 379 322 360 330 297 334 291 339 313 336 335 339 315 345 307 321 330 321 334 294 309 326 322 346 319 329 364 318 325 356 321 328 324 345 335 334 344 321 325 308 317 330 329 338 346 277 301 342 345 328 324 315 347 300 310 322 311 314 378 292 332 331 322 307 335 301 288 279 350 330 349 318 313 313 326 356 326 337 339 314 314 323 324 284 357 350 311 333 360 314 319 318 355 361 327 311 364 332 331 305 324 324 351 325 342 343 329 319 362 326 337 285 344 330 323 353 303 367 331 321 332 315 334 347 336 345 375 307 321 363 344 324 359 308 315 334 323 313 283 305 318 345 270 349 354 344 318 326 345 350 326 352 343 323 322 346 349 314 330 348 349 318 350 334 342 334 341 382 341 334 329 355 343 326 335 340 314 334 363 333 349 330 319 327 342 321 332 321 329 311 329 318 334 331 329 329 335 332 331 358 315 328 353 330 312 331 351 351 336 322 334 365 328 360 363 319 350 354 330 314 339 343 355 318 350 329 372 364 357 363 343 357 353 349 358 361 328 343 333 348 374 321 346 351 329 325 363 377 358 357 350 345 309 320 354 348 341 320 340 333 346 366 322 322 366 319 325 303 350 324 330 322 312 326 309 333 356 331 346 300 361 302 321 344 355 327 332 336 318 312 351 330 344 347 321 360 324 321 360 312 313 326 355 323 345 364 318 359 337 320 369 342 316 342 318 321 321 382 344 336 343 354 353 331 319 324 354 330 317 350 326 351 342 306 322 319 333 321 356 338 345 321 385 326 354 330 377 368 326 335 328 334 366 332 345 322 377 371 344 329 336 332 330 340 329 334 375 348 335 344 333 366 384 355 357 341 341 322 353 364 350 292 355 327 327 319 347 334 340 325 360 350 350 310 338 342 355 325 327 362 339 342 326 351 343 361 347 359 342 342 325 316 329 323 349 340 341 335 336 350 288 355 314 313 340 356 338 326 337 355 335 347 347 331 320 338 331 313 336 308 312 349 329 320 318 343 325 303 328 308 335 319 332 343 381 344 324 337 325 328 320 350 302 342 360 356 335 322 303 330 331 305 322 330 303 329 316 334 333 328 321 308 358 354 314 336 343 306 355 351 310 314 285 363 327 301 338 333 334 310 334 328 351 336 331 315 352 343 344 311 323 335 320 319 342 357 318 318 359 323 334 309 265 306 321 349 299 335 345 322 326 308 306 305 314 315 306 344 320 326 305 318 362 337 355 329 319 301 310 310 305 326 318 308 295 289 337 314 307 345 329 334 324 319 371 296 331 341 329 329 333 341 321 336 305 334 329 304 304 320 336 342 317 334 327 309 327 315 349 300 311 319 309 303 330 296 341 294 323 326 344 350 304 308 324 301 332 290 316 322 296 293 335 304 329 317 311 290 310 333 305 287 290 341 310 325 322 302 317 319 317 306 321 295 290 335 329 318 304 315 333 323 294 333 325 318 307 310 307 307 300 307 313 317 334 325 301 355 308 310 315 315 331 313 341 329 341 293 349 313 278 324 295 300 305 317 298 310 313 289 301 311 301 301 323 308 306 291 276 322 299 299 316 296 257 304 311 305 345 282 305 313 298 312 295 303 291 287 329 277 294 309 315 311 303 329 332 314 322 288 302 312 311 366 325 294 313 284 262 265 312 304 305 297 279 285 272 272 272 297 297 293 304 310 318 318 292 296 339 329 304 305 310 282 272 294 313 271 288 283 324 323 288 301 282 305 329 288 273 286 337 288 278 283 295 279 294 263 286 296 304 302 310 279 280 282 313 273 311 284 288 281 282 264 327 287 272 275 300 322 248 277 283 308 270 300 256 310 296 314 277 290 286 288 311 258 278 274 273 300 317 295 267 296 313 261 282 314 273 307 288 281 299 265 272 294 246 282 297 285 296 275 284 281 277 297 287 302 255 294 303 287 286 294 288 290 283 297 282 240 244 280 286 291 309 307 290 272 306 350 302 297 290 293 279 296 267 291 310 319 297 285 275 298 293 301 289 287 277 282 287 305 282 278 308 297 292 278 287 311 274 320 269 297 294 339 272 282 302 307 268 271 268 295 260 292 294 256 270 299 290 302 265 285 266 299 306 292 293 285 271 272 300 248 275 247 279 283 299 288 280 264 306 270 270 256 239 247 283 307 265 297 274 266 325 285 247 293 303 294 247 302 288 267 274 282 274 263 261 258 285 260 296 310 283 270 298 265 288 285 265 304 250 248 259 294 267 292 290 265 269 283 281 292 294 257 265 268 284 257 273 264 260 260 307 272 261 257 255 265 257 282 278 288 293 300 229 275 222 256 223 283 234 245 234 287 259 264 279 299 290 243 276 265 256 268 256 236 264 265 241 242 261 274 249 281 280 263 271 266 288 235 249 309 245 241 265 280 261 300 255 243 269 276 267 246 274 241 248 272 269 281 235 280 270 248 258 294 247 272 256 278 274 277 266 246 246 271 246 218 255 232 284 255 245 257 260 243 288 256 270 295 238 245 259 242 248 264 255 262 238 282 257 268 240 239 265 226 221 262 264 245 248 248 248 258 270 239 285 261 264 248 269 257 230 262 264 222 267 247 245 278 269 257 261 261 243 297 241 228 264 261 274 290 260 213 306 256 258 259 234 267 275 267 265 240 287 236 262 255 277 247 256 233 256 256 214 289 246 228 240 239 230 280 217 260 266 259 236 250 264 264 220 235 272 226 232 231 235 246 228 259 262 273 257 238 238 261 247 229 257 232 224 261 242 240 263 246 227 230 231 262 241 276 223 280 261 266 294 255 268 234 268 224 266 241 243 239 243 259 216 261 250 260 249 276 228 238 245 241 222 231 223 219 238 244 275 258 282 274 192 244 242 260 243 240 239 241 237 269 237 231 267 229 227 210 249 241 222 230 265 235 240 223 237 232 269 240 245 243 210 249 219 257 223 270 219 263 219 212 255 247 228 233 243 259 258 261 221 231 198 240 269 221 256 261 255 259 243 255 224 238 260 261 240 211 244 260 243 255 235 220 231 234 263 217 236 235 261 264 245 242 226 242 240 259 238 258 230 261 245 247 258 218 225 235 246 232 242 219 245 267 219 232 231 227 220 248 228 230 235 216 222 242 214 233 268 230 264 236 246 240 238 259 265 220 221 233 221 230 264 237 269 256 224 218 244 221 210 224 223 208 200 228 261 224 238 228 222 202 214 222 210 232 230 212 267 233 232 203 239 229 219 244 269 211 249 218 245 231 256 247 256 260 227 249 218 232 255 232 228 227 224 238 225 225 264 255 213 209 243 227 221 233 243 233 227 244 217 229 231 230 263 232 212 262 229 212 202 214 218 230 241 227 220 223 238 209 259 209 212 236 213 239 231 226 223 214 220 215 217 242 228 237 216 209 210 235 220 211 222 232 241 229 241 238 248 246 228 229 237 218 223 202 223 244 245 218 238 240 255 212 205 224 223 217 259 225 232 220 224 232 204 191 228 213 270 230 243 239 202 235 225 217 235 196 222 217 232 217 210 208 239 237 242 244 213 226 233 228 221 257 268 230 224 228 220 238 238 230 257 225 200 236 238 228 271 233 222 222 239 229 198 213 218 222 218 242 209 237 227 213 246 225 243 195 211 224 262 209 234 234 239 223 225 258 235 214 225 245 240 226 232 223 222 210 224 239 233 207 206 207 216 220 238 220 267 193 231 203 225 239 236 218 228 238 219 235 215 212 261 236 206 199 209 218 226 227 215 214 224 216 221 229 256 230 219 224 237 226 238 205 207 222 221 211 224 221 229 223 230 210 218 228 236 227 233 264 215 258 234 246 225 238 264 230 232 202 239 220 232 206 197 195 247 258 225 215 217 212 222 225 220 208 220 194 227 209 205 223 216 278 219 223 249 209 230 221 228 230 244 246 221 231 229 186 226 212 230 225 248 223 212 234 234 234 245 203 227 234 230 222 229 221 209 219 235 217 204 217 221 236 234 224 187 214 230 197 201 238 241 218 256 237 232 209 230 230 221 212 264 216 189 216 212 210 227 230 222 208 188 237 207 209 260 205 189 199 236 246 220 255 198 205 226 233 204 241 219 233 222 207 214 235 238 246 209 228 223 234 232 230 233 217 242 237 238 260 245 232 226 190 213 202 208 219 208 233 227 218 237 219 223 229 205 259 218 228 267 220 238 227 231 234 233 243 222 219 240 241 220 224 243 242 220 248 226 224 237 224 207 233 226 211 241 235 224 217 207 216 205 249 186 226 217 225 207 208 226 239 213 215 216 208 238 232 198 216 220 234 213 205 205 196 196 217 225 210 230 220 230 209 230 223 227 220 230 231 231 217 242 216 225 214 221 218 241 214 208 224 211 220 260 220 242 225 204 228 231 208 220 219 206 245 235 215 222 221 210 210 213 232 224 229 213 255 209 217 235 223 207 227 184 244 228 226 209 234 215 221 201 195 224 208 221 209 217 220 241 210 222 240 224 217 204 223 215 210 210 226 225 185 199 240 187 228 237 230 206 195 218 233 219 226 243 198 210 216 224 180 220 214 226 217 214 219 233 221 186 216 235 227 230 216 203 216 222 213 235 221 230 226 200 219 210 199 240 237 211 197 216 228 229 229 238 246 240 223 205 201 208 227 210 224 216 211 230 215 205 209 208 196 228 224 212 213 207 221 230 206 213 224 203 233 225 228 243 210 188 223 228 203 214 222 212 235 210 221 206 221 217 199 220 201 237 232 212 221 221 219 240 210 231 219 210 241 232 218 219 230 193 209 189 207 197 205 230 226 224 212 225 226 220 224 226 215 182 219 208 208 200 230 236 226 224 247 225 217 230 232 227 225 239 219 233 204 239 227 217 213 238 223 232 246 209 222 213 241 218 192 208 246 218 206 223 220 210 222 205 221 222 211 238 212 197 209 232 212 203 213 231 217 220 215 214 231 236 208 248 217 211 198 197 210 201 214 219 234 222 209 227 236 240 236 236 203 211 286 236 207 225 216 244 199 187 243 223 233 210 234 219 237 230 215 213 209 230 216 198 211 204 239 229 209 203 225 226 218 212 216 216 240 226 206 237 225 212 205 219 203 249 214 211 263 227 215 231 213 213 235 229 210 206 243 233 232 224 224 216 224 227 206 238 203 202 209 223 218 204 233 218 237 224 222 229 202 234 230 244 238 192 218 213 225 196 206 236 213 235 238 207 227 220 255 227 207 213 220 225 213 201 256 242 198 225 211 227 219 221 236 225 216 237 202 228 232 237 211 226 230 250 226 227 224 213 209 257 248 244 208 248 244 226 222 235 229 213 181 234 229 216 245 219 208 218 215 239 211 213 215 209 199 224 223 215 205 208 233 249 245 224 224 232 203 212 212 214 222 210 200 208 261 216 245 232 233 221 232 226 220 245 224 219 220 227 217 204 245 221 201 230 229 235 222 232 199 222 247 218 248 194 200 206 227 225 243 211 207 216 225 228 245 211 234 226 230 214 240 230 232 239 201 222 224 211 224 211 231 260 230 209 264 233 223 220 213 227 245 221 226 225 219 238 249 244 232 240 217 209 242 229 237 241 240 265 225 210 228 242 248 235 257 243 211 228 227 207 256 228 217 244 233 220 229 209 240 245 220 234 239 235 244 234 220 234 256 224 235 239 262 213 229 243 231 222 227 264 271 205 213 219 211 229 230 228 232 244 228 203 234 237 244 227 232 213 226 270 227 271 258 230 217 245 260 258 234 221 267 265 250 244 245 246 250 246 236 234 279 248 217 260 263 238 240 246 255 266 245 234 268 265 238 257 248 255 241 234 266 271 256 247 238 250 297 235 238 238 255 276 262 266 270 286 263 275 263 276 300 294 307 289 278 305 300 312 294 325 316 292 311 297 331 314 311 329 364 320 342 334 373 352 382 382 388 370 396 380 389 419 387 431 438 410 445 412 378 381 338 393 387 373 345 377 346 350 373 371 366 317 329 345 315 287 284 310 285 293 298 268 271 256 286 298 266 233 245 285 260 247 249 265 276 269 275 242 268 275 248 291 225 239 246 246 262 216 229 242 237 256 231 217 244 258 242 220 235 233 233 229 268 243 230 235 225 211 227 239 231 243 245 265 227 238 231 247 242 219 220 228 212 227 218 259 232 224 220 261 217 260 241 216 235 266 259 244 245 233 206 204 229 215 229 238 242 225 240 214 206 227 241 203 224 213 205 235 256 220 211 211 248 223 262 232 237 208 231 240 222 234 239 225 245 228 221 242 215 232 237 208 222 225 204 233 213 210 214 242 241 221 205 266 249 234 227 238 227 229 209 230 226 221 227 208 248 235 224 225 228 248 244 239 222 202 260 255 226 213 245 227 242 235 225 226 221 237 220 242 276 215 198 262 248 211 225 237 234 222 228 223 205 218 229 189 213 220 203 225 216 233 248 221 231 224 188 240 249 235 231 198 227 227 230 258 228 219 218 220 217 203 221 219 241 223 224 231 246 229 228 230 234 261 246 258 212 202 233 217 247 221 226 236 219 223 249 243 227 241 226 203 211 248 233 219 238 213 203 233 265 211 269 212 232 224 230 209 260 211 228 229 211 221 238 210 210 229 214 232 216 231 256 211 238 226 248 210 281 242 243 221 243 247 237 226 238 219 257 233 225 230 265 238 235 214 238 245 223 247 204 238 197 225 238 229 234 186 243 238 195 218 230 230 236 218 239 215 227 260 223 219 224 244 244 233 223 241 231 204 222 217 236 268 224 246 216 239 228 228 249 220 247 240 244 223 230 230 235 227 239 215 228 230 238 218 203 228 243 242 238 230 248 204 224 214 225 232 235 222 214 224 221 200 226 224 217 233 215 240 237 235 264 226 244 247 233 226 224 205 233 231 239 227 241 230 223 214 223 219 220 225 205 217 217 219 214 219 223 203 205 234 231 243 227 224 222 236 226 245 225 233 230 230 244 225 224 231 236 234 223 259 217 259 227 212 221 233 226 245 230 236 245 216 244 243 217 212 241 247 246 273 215 226 232 222 225 231 230 247 231 234 246 228 223 226 209 224 264 225 220 231 227 217 256 221 228 257 231 215 220 243 232 239 261 221 235 256 234 226 255 239 236 264 249 236 229 230 248 218 231 227 221 224 220 255 237 208 223 237 243 234 214 205 222 214 262 226 218 218 240 230 220 245 214 220 239 233 239 247 233 227 247 228 240 234 212 234 232 262 200 231 242 242 227 213 236 224 230 221 239 226 230 243 217 258 237 232 230 242 265 234 230 197 221 241 255 246 230 242 232 209 262 221 224 209 238 224 222 225 227 209 219 219 220 235 195 240 233 234 230 228 257 228 200 227 228 241 266 242 226 242 227 225 216 259 221 230 222 213 214 218 202 206 235 231 226 256 214 236 204 231 245 210 211 248 214 208 237 242 219 223 239 231 222 233 234 232 232 259 235 221 237 236 202 255 215 230 246 228 256 229 229 227 224 230 208 225 225 210 228 236 220 247 235 222 241 214 211 234 242 216 240 240 245 203 232 231 225 229 221 265 229 216 217 248 234 212 243 242 228 215 224 232 248 219 237 215 220 242 229 231 210 236 266 272 227 230 202 232 227 248 218 226 216 257 216 235 231 225 248 195 213 215 225 244 262 255 217 259 242 248 238 247 227 235 208 241 229 244 241 232 208 261 237 220 221 219 228 250 245 244 244 223 226 244 243 258 208 222 216 215 247 219 239 229 229 233 223 213 231 246 242 236 270 218 205 239 238 226 267 211 214 227 238 235 226 237 264 228 224 220 241 241 234 225 216 272 225 221 220 232 229 231 191 229 227 231 241 249 225 240 219 215 200 232 242 228 239 228 216 221 232 242 207 221 231 208 244 235 246 244 233 239 230 235 227 214 208 193 221 217 248 228 241 241 207 238 247 237 241 260 213 226 240 256 249 210 256 248 235 248 223 224 267 260 214 225 206 248 242 261 238 241 233 256 233 232 219 248 257 226 249 247 257 238 208 212 259 209 242 222 246 235 258 207 231 221 198 232 232 222 226 225 226 205 221 207 242 235 240 245 228 255 237 264 245 239 265 218 249 245 243 242 220 207 233 225 223 228 231 242 231 248 244 197 214 277 260 233 255 224 229 241 234 234 245 219 211 240 265 221 228 242 265 239 196 220 221 216 232 233 227 223 228 248 234 229 261 218 225 250 220 235 207 245 233 228 203 215 216 231 217 215 223 225 237 243 245 223 220 229 218 218 230 238 248 227 222 222 229 217 224 274 245 244 243 229 208 222 223 258 236 229 221 215 227 261 230 242 223 260 243 239 224 240 260 235 259 246 256 207 224 232 215 235 248 221 262 219 244 259 243 288 242 222 240 235 244 215 212 223 238 219 212 211 221 259 212 237 233 211 238 226 228 243 239 229 195 260 258 249 223 213 223 218 241 218 198 231 241 234 238 233 230 243 236 233 211 232 263 235 271 245 243 222 233 225 236 247 233 223 256 221 231 222 215 247 238 246 243 223 223 237 270 229 248 225 232 205 239 198 237 214 232 266 223 244 255 231 276 255 263 238 242 247 212 227 223 224 243 222 235 242 257 235 232 245 250 245 221 226 224 229 244 222 234 234 240 244 231 231 255 236 220 270 233 227 258 259 249 272 212 273 259 262 236 239 238 235 230 235 212 255 211 213 212 237 242 214 216 220 244 206 257 231 211 236 204 243 239 208 234 219 241 232 227 258 261 228 229 205 246 219 250 240 231 288 255 218 235 232 220 225 261 241 250 219 231 237 232 241 231 247 228 260 243 232 223 212 256 221 237 215 235 221 243 240 235 246 240 257 260 230 214 232 267 231 229 241 221 247 234 257 239 242 280 248 232 234 242 269 221 232 228 208 235 234 222 210 240 242 248 237 233 245 228 259 268 228 237 248 245 242 230 247 247 246 239 234 248 216 229 271 220 245 204 259 236 214 222 243 242 227 204 248 239 249 247 226 239 200 246 214 248 228 243 230 223 225 227 241 243 259 249 212 234 262 259 208 220 230 205 214 232 243 247 243 249 232 237 242 249 227 207 242 232 247 260 208 223 261 232 243 208 247 221 257 225 240 255 241 226 255 219 228 221 237 215 198 223 239 238 212 236 226 242 223 224 255 285 258 235 189 224 227 236 233 243 258 255 242 223 228 223 230 244 239 236 214 226 220 244 233 217 238 249 261 236 234 238 225 242 256 259 240 239 260 237 229 225 258 227 214 238 257 258 238 259 233 226 227 217 235 228 264 229 187 243 225 233 264 236 270 217 257 257 258 229 270 244 265 255 263 249 241 230 237 243 262 258 234 256 226 264 221 261 212 231 257 245 273 248 213 228 280 233 220 234 224 219 233 256 243 236 240 235 244 249 247 249 219 210 212 240 230 227 259 234 241 267 222 232 222 219 274 248 228 233 246 196 228 238 241 240 260 237 243 271 228 236 233 223 258 221 235 241 224 241 245 248 233 209 211 233 226 217 242 234 226 236 244 248 240 258 233 272 244 231 244 230 213 240 244 269 271 227 244 240 249 261 227 244 255 241 216 255 234 240 229 215 246 248 267 223 240 286 222 245 242 239 237 222 244 230 241 275 241 242 247 241 235 236 258 235 243 263 239 249 262 224 228 219 225 224 231 261 286 258 239 218 238 230 234 238 239 240 227 242 267 219 220 274 209 262 234 240 266 243 238 250 238 242 238 231 236 255 267 255 241 228 276 224 217 230 220 238 257 230 248 232 280 212 220 247 216 232 256 238 257 207 224 236 255 238 266 240 249 265 235 244 237 230 288 226 223 236 248 224 242 221 228 248 264 227 263 290 255 244 244 238 244 226 282 262 227 245 248 245 226 257 245 221 274 226 266 229 248 232 239 268 225 275 223 228 242 269 229 263 224 256 243 256 241 280 224 245 217 219 243 242 243 244 258 245 226 266 261 233 246 248 257 240 246 224 248 241 248 256 214 243 266 259 245 236 234 246 236 235 278 245 232 285 274 240 231 268 234 243 237 257 238 212 245 276 235 245 241 259 275 241 279 245 284 276 220 270 244 238 262 282 260 220 241 249 262 282 250 262 239 263 259 267 258 248 234 255 233 255 238 234 227 231 231 257 250 238 243 234 227 258 247 256 221 236 263 276 218 224 233 244 276 238 243 241 233 257 244 229 261 232 236 249 266 245 272 231 243 199 247 228 226 245 275 269 240 248 235 277 255 258 237 285 234 224 226 279 224 273 239 235 276 242 242 230 228 248 245 265 240 230 230 255 212 243 259 247 239 245 280 255 223 248 272 269 211 216 233 237 270 236 242 221 262 238 226 228 233 258 246 237 249 269 269 256 237 250 257 275 222 222 235 241 224 262 260 268 240 256 237 234 245 229 223 239 266 219 261 231 219 217 262 244 256 255 255 255 261 245 255 243 285 279 262 247 269 244 213 249 245 256 222 241 223 227 233 245 231 235 261 297 269 220 232 234 281 245 264 266 263 268 240 277 266 219 242 269 228 239 259 258 258 260 277 273 237 269 269 233 258 245 264 273 263 281 247 259 243 221 262 242 268 246 264 221 250 264 230 238 259 250 294 256 211 231 247 246 247 233 280 283 247 263 282 227 222 237 244 302 236 281 258 240 242 228 243 246 242 241 270 248 256 246 271 243 223 281 270 276 249 259 213 266 270 262 247 267 240 236 261 268 235 257 221 212 261 231 215 285 272 243 257 227 241 246 235 283 210 244 230 275 214 264 220 246 236 283 238 270 238 267 266 234 242 256 239 248 239 228 245 231 239 220 206 238 255 237 231 222 241 280 235 247 255 249 229 250 218 261 232 212 230 228 281 245 243 246 265 248 236 233 279 235 249 240 284 261 233 242 275 230 277 235 232 244 263 219 273 250 225 257 275 223 235 228 202 223 222 239 255 235 273 238 248 249 223 242 227 244 235 224 237 222 263 226 225 232 250 277 250 265 256 261 244 259 264 226 234 226 260 240 238 234 258 241 269 238 248 258 259 262 266 230 270 241 255 241 233 258 243 239 229 227 276 270 238 268 259 237 236 240 227 239 228 240 263 239 246 246 235 263 247 231 222 236 233 246 236 248 274 250 238 226 267 238 245 225 225 243 217 220 234 238 237 245 235 231 263 250 245 221 235 238 270 262 233 250 221 234 246 233 226 257 240 233 270 194 246 239 223 246 248 229 264 255 260 236 226 223 246 265 233 258 230 235 249 259 258 231 256 227 217 256 243 217 271 265 247 261 232 262 264 245 269 234 227 247 256 241 245 242 239 243 256 218 215 241 224 245 233 258 245 262 242 229 230 268 270 259 267 260 232 246 255 267 232 233 244 221 234 241 239 239 262 271 233 276 242 231 229 255 234 245 224 214 226 236 236 243 239 229 247 208 259 228 266 217 223 267 235 229 264 278 263 258 219 234 221 206 258 236 256 226 244 241 259 273 231 246 249 237 221 245 247 245 235 223 256 222 276 263 274 227 227 266 242 249 257 245 259 242 238 248 229 266 257 256 274 228 259 231 232 208 247 225 264 241 247 231 264 284 232 261 248 225 227 235 240 223 258 227 261 227 225 247 225 248 258 210 239 226 230 230 243 232 238 271 230 266 266 263 235 205 238 239 266 237 247 264 239 223 258 239 220 241 247 264 225 226 237 270 260 228 208 226 268 222 224 257 221 244 224 247 222 240 223 221 213 237 257 241 241 230 229 260 223 244 244 232 244 256 286 217 218 240 237 247 269 242 242 235 207 230 283 262 239 240 227 259 239 265 232 268 237 235 262 249 255 237 263 246 256 236 227 246 249 243 245 237 246 270 258 259 213 233 243 245 255 258 249 227 233 256 257 242 210 263 212 264 237 221 273 245 271 235 215 256 262 243 246 246 248 227 255 260 233 222 221 221 239 206 232 280 273 260 255 266 235 233 225 222 245 246 226 245 233 243 226 240 256 249 276 242 239 234 266 209 222 260 268 239 260 261 231 235 255 229 238 218 281 222 256 241 243 263 244 241 239 217 273 214 229 240 246 257 263 238 230 218 235 265 231 266 245 240 261 236 262 237 237 260 276 224 214 245 239 243 267 234 225 242 264 226 267 212 224 265 271 224 246 230 258 240 257 265 248 233 232 241 230 241 249 261 237 230 271 222 260 258 231 229 227 257 226 210 227 247 227 241 226 218 237 232 237 260 228 234 255 258 219 260 292 239 265 227 237 256 237 273 248 237 274 278 242 233 237 218 247 233 249 237 261 260 242 242 256 217 233 241 231 223 270 215 255 217 247 242 234 208 234 244 242 256 240 269 245 221 256 213 235 241 259 247 232 283 257 258 246 239 245 271 221 231 249 260 259 273 234 224 291 230 240 232 259 236 247 262 236 214 242 228 260 239 237 241 224 227 272 260 225 228 228 218 259 228 244 277 260 245 243 235 241 263 246 213 239 225 214 267 214 224 258 261 242 235 247 266 246 291 229 219 246 281 248 241 284 282 216 227 229 269 272 266 267 275 257 229 240 255 249 262 228 228 246 244 255 231 226 265 261 227 225 262 262 273 259 269 241 266 256 247 245 249 237 265 268 240 235 246 225 247 248 243 229 233 262 222 244 232 234 245 268 249 208 228 267 250 230 257 244 262 246 274 255 273 255 237 269 262 221 225 258 245 230 263 240 217 239 238 242 264 267 278 277 234 243 216 240 240 241 228 230 284 226 209 240 235 249 265 282 240 268 276 262 258 236 227 225 267 228 263 248 268 276 268 224 282 249 237 234 233 264 233 224 240 264 243 247 264 276 216 238 242 261 256 263 240 264 259 276 239 239 239 243 266 242 248 230 262 240 233 248 266 276 268 248 248 244 229 222 224 237 247 246 269 276 261 282 242 260 237 239 257 242 238 260 267 274 243 227 259 228 249 247 241 239 224 269 256 231 257 240 232 256 260 238 239 241 266 230 270 257 256 238 262 266 259 278 231 223 250 280 265 264 264 250 259 237 240 221 266 234 230 262 249 233 217 274 194 288 231 250 257 241 260 268 233 276 267 241 231 224 226 247 226 259 256 232 232 217 225 211 259 264 247 256 248 245 222 244 261 242 238 272 242 247 247 259 265 244 282 269 265 236 242 255 235 225 245 246 264 266 229 239 285 215 235 257 261 224 245 257 245 259 246 228 226 257 236 243 227 239 243 230 245 267 266 242 231 259 265 242 223 257 249 220 221 243 238 246 232 266 241 246 234 222 258 260 247 237 258 250 245 233 260 256 227 240 237 205 267 243 219 213 264 275 245 259 284 263 257 235 247 249 241 235 268 240 237 246 233 236 238 231 239 259 247 226 207 245 278 219 234 238 228 265 226 233 222 248 230 277 257 267 229 238 223 240 237 226 270 230 214 247 217 232 233 260 235 237 224 256 240 233 244 230 207 227 243 227 229 259 212 248 250 220 261 245 255 241 224 256 263 234 227 226 239 239 261 240 244 240 224 260 239 228 228 244 218 255 225 227 236 225 267 243 260 240 236 263 242 243 265 232 256 261 224 244 241 262 235 224 248 258 261 236 239 255 262 239 238 238 235 235 287 234 257 268 263 278 263 247 259 225 245 243 213 233 236 229 244 248 218 232 243 264 214 255 257 223 268 230 238 258 264 241 222 250 249 271 232 256 244 260 246 273 244 264 255 249 224 236 267 280 216 233 232 237 240 278 243 278 265 232 238 245 237 234 241 257 259 255 292 268 245 243 225 263 243 260 223 258 260 232 247 260 240 245 245 258 239 243 234 239 241 232 239 239 271 241 268 236 236 276 258 246 240 275 269 255 264 248 269 284 266 272 241 229 240 227 250 257 231 243 249 260 268 237 272 239 246 247 255 236 220 238 244 240 227 260 236 245 230 242 221 239 259 234 236 211 244 242 272 244 267 233 246 262 214 232 234 220 263 242 231 263 221 245 248 240 247 272 266 244 205 231 255 212 235 247 258 248 269 224 245 245 267 243 226 245 242 266 240 259 214 267 227 255 264 244 240 212 260 262 238 268 258 248 229 261 246 241 246 247 267 240 266 237 268 231 238 236 255 234 265 244 217 265 266 266 235 262 261 249 263 273 260 219 250 258 245 246 276 259 272 229 265 250 272 229 270 263 243 242 240 247 246 278 239 244 231 237 235 242 233 240 259 225 217 257 260 234 222 246 265 236 242 266 244 256 243 244 226 290 238 278 261 266 227 261 244 269 235 263 243 247 227 282 265 258 256 255 217 226 231 240 232 274 225 249 273 263 249 218 238 239 226 268 268 229 256 239 246 233 236 269 244 233 276 250 270 240 290 257 238 225 269 255 240 242 244 234 223 235 255 228 250 255 256 263 239 249 248 242 229 243 229 241 278 227 270 233 230 242 261 286 229 237 248 247 264 217 229 243 274 293 242 228 257 236 282 245 248 247 291 229 229 260 238 270 288 246 275 288 245 268 265 246 257 228 260 240 222 243 243 277 249 240 281 244 294 280 266 249 269 267 255 257 260 224 276 291 281 248 292 279 261 278 271 262 285 271 247 258 279 285 306 320 309 281 262 256 265 289 299 258 297 283 280 289 292 271 301 279 295 266 271 255 275 292 288 300 308 288 270 270 272 277 285 295 280 294 273 257 276 292 274 293 276 250 259 244 300 283 247 291 286 260 245 244 271 260 225 263 264 304 255 279 272 250 245 259 267 263 260 269 273 247 280 277 249 280 258 232 236 257 259 249 286 256 277 242 246 267 248 217 278 249 232 290 266 247 245 269 244 255 260 248 230 235 249 226 241 238 282 240 267 236 267 261 232 284 262 225 269 226 244 250 224 257 263 211 256 275 274 229 247 232 228 258 231 250 248 228 232 236 237 266 262 249 278 247 261 218 222 238 235 243 217 238 273 217 241 234 226 197 245 235 255 248 247 285 238 265 234 272 242 212 246 267 223 222 236 248 225 247 247 256 223 229 227 274 260 245 246 233 266 266 279 235 214 234 258 233 235 231 246 238 259 265 263 241 274 260 242 244 230 243 282 246 274 260 262 233 242 241 273 256 209 236 244 266 260 266 282 242 269 235 238 227 265 248 232 235 221 239 220 217 257 264 257 245 242 236 238 210 269 260 241 255 246 262 262 216 240 267 243 235 271 244 241 277 243 216 280 276 269 265 246 255 268 265 210 248 276 225 249 241 223 237 267 226 214 245 258 241 243 255 258 242 265 224 237 242 222 219 216 243 257 214 230 227 243 264 235 238 225 240 271 218 239 241 259 246 228 229 247 238 267 233 226 258 259 221 243 236 224 267 227 262 243 217 240 239 226 259 230 259 237 262 232 283 236 267 224 247 235 266 255 240 249 208 260 259 228 218 188 261 256 248 211 246 248 207 224 248 258 243 215 255 275 238 261 238 255 238 257 246 239 263 219 262 243 248 231 235 247 238 259 239 235 229 256 245 266 223 257 257 270 245 213 240 203 238 246 267 236 229 236 232 264 268 270 226 255 229 257 232 214 244 241 246 227 196 264 225 261 265 245 264 244 258 220 246 239 236 258 259 246 244 248 233 245 233 249 222 255 258 256 227 231 229 221 264 257 255 248 222 232 245 209 226 241 234 235 233 230 245 256 249 255 272 262 264 263 255 223 241 250 235 221 262 222 222 237 249 237 270 262 211 221 235 260 226 241 207 244 258 239 261 226 223 228 224 260 260 234 238 240 228 272 217 241 245 215 281 236 242 255 221 271 230 211 233 239 243 262 233 264 238 223 227 214 244 240 259 259 236 233 266 238 221 235 246 232 230 234 244 265 225 259 249 246 227 211 238 246 221 237 249 217 205 244 243 222 234 274 228 247 245 242 256 257 215 265 235 232 262 220 247 267 233 258 248 225 230 230 257 234 230 255 245 229 260 225 232 242 229 258 228 228 236 225 240 224 258 262 226 242 256 277 232 231 241 242 247 261 255 227 237 256 261 245 264 239 299 230 229 222 218 261 234 235 214 261 221 249 258 259 209 246 230 217 229 257 248 272 236 275 266 239 221 246 224 241 239 244 218 235 199 242 263 230 258 230 244 247 261 246 247 203 240 250 258 224 245 235 222 229 247 256 234 228 263 218 224 234 243 216 234 247 249 256 236 223 273 230 209 234 257 223 245 264 233 236 230 256 232 243 227 227 258 237 261 244 236 270 230 244 231 233 261 230 208 237 228 227 243 241 268 224 207 234 226 229 235 276 248 299 247 245 265 226 227 235 255 285 239 217 262 238 247 216 234 236 259 212 205 226 255 223 257 238 247 233 258 242 225 234 272 217 232 228 241 241 261 246 234 234 242 212 265 237 244 256 255 262 245 218 244 258 235 261 232 234 256 231 234 245 217 265 226 264 263 242 220 218 213 210 237 238 228 204 236 242 210 259 249 228 248 235 224 265 237 247 280 243 256 249 233 239 228 221 238 224 216 245 243 255 232 246 233 221 242 257 229 255 230 219 226 230 247 258 235 221 228 230 235 287 284 222 245 259 261 270 223 257 232 212 239 241 269 233 264 223 229 238 232 247 218 270 248 225 247 249 268 224 238 268 273 229 249 243 233 195 234 227 259 267 241 245 215 241 231 227 232 240 209 236 265 242 255 250 224 242 263 248 265 243 273 224 223 220 232 242 256 237 255 248 229 270 227 261 230 245 232 249 257 257 250 224 245 264 238 260 238 231 249 231 229 223 246 246 265 247 239 230 245 231 255 241 234 235 217 241 248 235 262 249 219 224 195 233 258 247 231 233 229 268 228 232 261 240 247 268 235 238 224 220 241 241 259 238 247 240 234 233 230 243 227 246 239 229 247 256 227 217 259 249 247 246 229 240 233 265 245 255 233 238 215 224 222 236 214 229 276 211 246 233 213 256 222 260 227 224 243 246 242 237 268 219 242 227 262 250 220 250 259 272 255 248 227 223 245 260 266 224 265 266 232 276 262 223 242 220 231 258 260 218 245 290 240 220 226 236 273 234 229 246 243 260 236 259 247 205 221 272 219 247 259 232 269 224 262 260 269 241 244 246 239 259 207 244 272 238 235 239 227 230 230 248 255 216 264 238 234 260 217 256 233 232 270 246 248 226 250 239 271 234 234 237 275 280 255 226 220 234 258 246 215 267 246 204 245 220 264 266 265 275 230 244 230 227 240 237 227 231 236 243 255 258 246 230 215 257 240 248 222 249 242 270 237 270 255 222 237 258 231 240 226 244 276 255 237 246 236 231 257 256 242 231 263 228 249 226 214 243 237 237 267 230 234 220 213 256 257 241 234 256 261 228 230 235 221 214 218 230 232 262 249 225 248 239 240 240 223 245 221 242 246 268 270 187 272 259 231 230 241 244 229 255 260 222 224 250 231 211 262 213 256 248 233 263 268 245 237 239 226 245 248 213 271 241 236 228 256 208 218 226 223 236 243 236 225 240 249 247 213 244 222 203 284 259 268 234 237 255 238 221 247 209 267 229 229 224 242 257 265 271 233 240 272 219 233 237 234 234 241 209 242 236 240 279 246 240 224 210 223 238 228 212 236 233 236 230 270 262 257 264 236 224 244 216 232 246 237 230 259 248 244 234 213 271 269 231 257 258 219 236 217 220 234 237 224 257 250 233 258 238 262 237 236 242 240 247 233 246 229 255 271 227 193 226 229 261 270 259 229 271 240 215 210 235 243 229 242 222 267 238 243 260 228 247 239 263 220 259 260 226 241 241 261 261 237 216 239 217 229 222 231 235 229 255 225 240 228 228 188 233 239 239 259 238 246 221 248 261 225 211 232 234 228 247 235 241 230 261 264 228 271 229 236 218 269 216 238 211 244 212 245 213 246 221 259 224 231 233 244 248 223 229 235 230 231 237 238 249 231 244 250 214 245 258 215 277 261 271 241 244 228 231 212 241 268 230 230 236 245 262 228 268 258 238 245 249 213 238 222 255 246 220 240 213 223 274 257 197 257 224 278 239 242 247 223 231 261 245 224 258 221 222 227 249 233 249 198 214 270 215 235 230 242 243 227 233 261 236 242 255 230 239 245 244 279 209 236 230 256 226 265 247 229 243 259 247 243 234 240 217 202 263 281 246 231 238 239 207 225 249 228 221 242 256 220 229 269 250 231 250 244 231 243 231 234 238 244 230 249 262 232 235 246 242 255 231 269 242 243 225 257 201 227 248 236 268 250 240 263 244 231 242 234 244 229 221 275 261 247 272 298 272 239 222 244 219 276 227 220 236 258 238 230 247 228 206 287 232 238 258 233 233 255 248 200 240 249 241 241 231 255 257 240 269 246 263 231 256 241 219 234 261 234 238 248 238 249 250 263 227 274 279 249 233 278 243 242 259 270 240 268 271 248 235 261 227 231 238 203 280 246 273 289 229 262 218 237 238 231 263 271 238 279 273 248 243 238 240 269 234 292 245 268 244 234 291 266 257 262 258 238 242 248 246 248 281 268 239 268 266 255 233 283 263 248 221 245 257 223 259 239 237 244 283 269 286 244 291 262 214 249 215 262 234 264 262 256 273 229 221 241 258 247 270 243 204 247 214 235 231 243 264 235 256 227 261 257 248 243 232 237 258 233 258 238 237 211 236 239 225 238 260 248 259 244 255 241 269 257 225 236 232 227 229 266 248 233 236 268 269 240 238 223 223 232 256 236 237 219 232 247 217 234 258 248 239 223 235 231 241 233 243 235 208 275 227 213 239 232 267 205 259 260 242 238 243 242 241 261 258 248 269 237 223 229 256 250 258 228 200 227 273 265 261 236 233 244 263 221 223 228 223 272 227 246 242 250 229 235 244 243 228 242 230 228 249 230 242 249 231 256 242 255 234 233 278 204 221 227 236 275 261 272 231 217 242 259 234 269 285 262 247 227 239 237 224 256 237 236 247 255 245 260 235 256 278 270 231 232 243 236 245 232 213 234 259 234 257 220 239 275 258 255 212 238 257 224 210 258 244 245 264 241 247 211 219 212 239 258 256 256 262 267 279 264 238 242 232 259 272 245 217 233 256 268 246 209 236 234 238 224 235 256 262 213 231 228 243 202 218 241 237 238 223 285 232 241 214 234 220 246 215 238 244 233 223 228 283 271 264 262 286 222 241 264 232 242 237 275 255 261 263 277 262 211 214 214 221 233 260 249 248 244 227 233 225 228 242 279 231 269 225 228 260 236 241 244 239 224 229 228 270 226 266 256 239 232 241 225 270 225 255 244 210 242 262 268 225 227 233 224 249 234 248 238 231 240 289 240 226 250 226 248 244 216 243 242 249 261 261 228 236 247 243 212 273 246 229 261 209 257 238 217 273 250 237 266 281 239 250 258 241 241 228 239 234 261 240 214 257 248 201 273 279 257 233 247 245 239 271 233 227 223 249 261 228 248 256 247 205 224 283 228 221 263 245 256 207 245 237 230 221 242 235 240 261 249 258 262 244 258 257 243 237 228 260 240 224 250 256 229 235 229 262 234 244 235 245 212 259 214 239 228 231 236 240 278 237 257 271 231 216 271 241 239 237 248 244 234 217 233 241 245 248 214 270 241 275 236 228 256 242 248 233 238 208 264 234 269 247 240 232 250 212 255 217 234 229 260 236 226 241 247 263 258 262 233 248 239 245 244 247 260 215 287 255 274 239 232 240 214 242 243 236 240 271 227 264 235 221 256 231 228 197 202 248 249 241 235 235 239 234 274 271 233 216 224 247 243 241 246 261 250 256 239 271 235 226 243 233 263 234 224 226 245 244 240 223 262 261 217 233 207 257 248 227 250 268 229 235 258 242 260 247 228 262 239 224 256 239 259 264 227 255 260 281 260 261 240 265 232 241 250 261 227 236 248 257 261 233 235 255 275 224 256 217 242 221 229 255 246 256 269 276 295 230 235 244 268 261 210 233 241 242 263 218 234 249 230 265 267 235 244 261 242 268 225 244 215 271 250 230 217 211 245 256 258 214 247 246 244 246 233 257 234 265 243 244 270 224 281 267 246 236 271 193 275 271 230 222 256 242 230 232 222 212 255 238 245 236 261 235 267 247 241 242 236 246 240 211 260 243 274 240 236 226 273 258 237 240 229 286 230 233 244 229 244 193 258 238 269 255 235 271 242 235 239 241 266 234 228 269 229 256 245 246 241 223 259 217 272 237 241 238 223 214 234 261 258 232 216 255 231 227 271 210 248 270 260 220 265 257 215 237 228 271 238 234 275 210 233 244 243 241 233 262 234 268 240 242 255 235 227 238 247 274 250 227 233 245 237 235 239 242 228 248 235 248 244 218 220 233 249 240 230 219 220 232 259 212 263 248 243 260 208 228 262 212 288 258 235 241 241 232 240 264 234 249 240 242 263 225 239 225 270 260 235 229 220 222 226 232 234 240 262 262 234 224 249 239 246 231 239 262 233 205 212 224 260 266 244 282 219 266 237 233 217 230 234 261 247 224 232 226 215 239 256 263 218 229 249 256 219 240 224 236 226 260 234 267 247 233 247 230 240 273 242 267 248 246 201 242 236 269 256 230 207 235 247 222 237 237 242 246 239 269 225 233 216 280 229 227 249 258 226 222 270 234 227 238 247 221 236 223 240 217 229 256 255 245 248 200 260 240 237 256 223 246 219 229 264 230 226 257 234 241 215 265 247 198 270 255 268 242 239 231 234 279 231 243 255 230 265 261 240 258 239 240 256 227 259 231 232 241 259 243 247 237 247 247 210 234 218 240 264 231 240 262 212 238 201 244 235 245 219 243 232 205 269 240 240 227 239 275 267 250 235 213 272 277 268 273 237 256 242 248 248 221 235 245 240 270 243 261 221 249 249 257 256 247 259 223 279 256 275 224 235 257 248 215 229 247 227 230 248 257 233 240 229 236 263 238 248 236 228 222 230 244 267 232 246 259 257 266 246 230 234 234 230 236 224 223 241 232 249 234 246 249 270 244 238 279 255 231 215 266 241 200 243 237 256 268 216 271 260 230 235 257 226 283 240 280 256 231 255 285 255 267 240 244 247 259 225 255 249 226 242 272 256 267 246 231 241 264 228 209 223 212 248 235 243 267 234 228 230 233 240 232 221 219 268 260 232 243 223 264 238 215 243 247 239 233 269 239 221 230 270 216 238 228 255 262 222 219 264 262 233 260 259 239 263 247 246 255 231 248 231 263 264 269 233 228 242 237 255 267 269 255 273 237 230 245 238 244 221 246 211 241 247 249 206 235 277 240 229 230 248 261 241 238 257 242 241 259 261 270 255 199 247 258 227 231 282 229 225 223 255 242 276 238 243 230 246 246 246 271 246 224 232 246 266 249 231 217 231 244 237 245 217 231 244 275 232 210 222 248 225 229 277 271 244 245 265 229 242 230 245 256 256 223 262 239 241 242 276 233 263 232 248 219 257 269 244 247 231 248 265 236 244 229 241 233 265 238 250 274 231 228 255 239 233 268 228 249 245 249 249 223 241 271 255 230 261 243 231 255 257 245 263 256 249 217 263 266 227 266 257 239 230 248 213 241 229 235 216 257 258 293 282 242 240 237 241 255 211 246 243 272 302 231 269 236 241 238 243 236 232 240 270 243 245 284 261 232 236 213 242 247 299 219 245 229 215 223 245 234 224 239 231 244 223 216 247 234 230 256 228 274 232 242 231 242 256 242 232 215 270 240 262 242 247 247 249 226 261 248 230 243 232 247 231 238 242 271 243 245 238 260 270 233 238 265 272 238 225 240 266 237 255 246 213 259 275 208 244 249 236 203 233 266 278 242 244 270 223 233 245 243 242 269 255 261 261 249 278 241 211 274 241 278 240 235 234 234 231 246 214 242 275 235 224 236 258 280 278 212 244 248 245 224 243 241 250 232 239 214 276 255 263 263 234 227 261 227 261 260 279 238 262 237 248 233 273 264 222 277 255 245 235 244 241 235 255 220 248 276 226 267 272 255 227 271 248 247 226 265 260 215 277 231 205 258 249 284 249 237 234 279 266 226 262 283 262 243 257 299 238 255 231 240 264 264 244 246 236 242 241 247 247 238 222 248 280 269 235 212 238 266 244 246 261 223 258 278 224 235 263 263 245 249 250 266 247 260 269 242 267 257 282 248 275 235 227 258 220 241 232 288 238 266 244 223 214 267 256 268 257 226 245 239 220 274 236 231 222 248 228 242 241 226 238 262 241 242 221 245 256 222 268 226 236 282 258 283 241 282 241 266 278 249 231 257 277 242 277 258 231 243 276 264 240 258 269 245 259 248 261 268 244 245 244 240 231 223 236 269 269 266 228 270 246 275 247 264 258 280 268 259 256 308 260 241 276 247 266 268 284 274 287 268 284 241 243 276 248 245 244 243 264 222 236 274 272 234 232 202 243 269 272 237 279 227 282 274 244 262 269 240 267 273 282 222 268 258 246 273 255 226 274 267 281 249 259 274 231 256 244 263 258 231 260 266 260 246 282 241 262 260 257 263 235 246 247 286 273 272 273 293 259 270 259 247 235 243 255 280 235 237 270 286 235 225 289 276 256 256 258 243 242 218 277 259 265 232 235 270 236 231 239 258 272 222 267 245 266 266 247 261 277 227 248 241 266 247 286 245 248 243 277 217 247 287 295 240 246 231 271 264 239 236 267 263 265 268 282 242 240 235 273 263 241 223 242 268 259 237 290 266 219 247 221 242 228 263 244 234 234 263 255 271 289 277 265 257 255 281 212 257 220 246 266 240 244 282 234 239 243 217 250 265 258 264 256 232 278 236 235 218 245 231 240 228 249 229 232 236 264 261 261 220 268 224 219 238 226 228 234 231 259 236 245 262 249 278 225 262 236 229 229 260 240 258 232 268 263 243 212 239 242 245 246 248 246 227 220 235 231 234 234 233 261 209 236 265 264 199 263 262 261 241 248 235 270 233 248 201 231 255 236 234 248 285 233 233 255 223 245 230 240 250 244 222 223 260 238 257 240 244 261 268 239 243 245 234 217 293 219 265 244 247 229 259 264 262 248 228 260 209 238 269 233 256 201 269 229 221 236 248 216 236 246 231 235 250 242 242 228 233 221 234 237 234 257 271 255 234 240 255 248 259 260 261 236 243 224 246 247 245 230 242 219 269 234 239 240 217 225 232 249 242 245 257 242 247 244 250 223 226 226 243 235 259 245 220 246 227 246 245 270 217 226 244 248 248 241 238 236 246 260 227 237 259 239 229 242 224 238 240 272 242 257 241 269 255 244 243 255 235 241 258 234 225 235 236 257 274 223 218 247 256 223 256 263 240 262 249 228 225 268 281 266 225 245 248 241 222 224 244 221 245 240 231 220 222 221 237 221 238 282 238 237 221 257 230 222 257 262 226 230 228 227 236 261 230 255 241 273 263 261 219 223 226 269 238 262 222 226 258 244 230 270 232 224 225 221 248 238 248 234 266 212 240 213 228 238 225 231 249 234 249 246 234 270 241 207 240 258 228 260 236 242 256 273 221 206 219 246 261 228 248 238 202 244 238 239 238 229 223 245 263 241 231 214 248 227 245 240 245 222 256 258 242 236 233 261 262 243 231 212 257 266 240 230 233 232 229 228 256 259 247 207 269 222 236 262 263 246 262 237 231 231 268 224 257 257 244 242 199 236 214 228 228 255 290 265 236 240 255 232 273 245 241 224 269 214 233 247 231 265 207 265 217 234 227 242 243 221 262 232 279 233 255 225 232 249 258 261 242 239 227 266 269 249 242 214 233 244 258 261 241 266 244 268 273 249 241 243 266 267 255 228 211 242 235 243 209 242 224 228 237 268 219 223 260 233 222 205 259 228 232 241 239 265 228 230 246 229 271 227 244 245 224 209 270 261 265 260 242 239 221 231 231 219 213 272 248 213 255 231 243 235 227 267 208 235 239 244 276 228 216 235 261 259 230 237 281 240 263 210 233 228 216 243 209 245 224 260 237 243 229 256 242 243 247 233 236 224 263 261 241 266 268 260 241 246 240 206 208 228 227 247 218 213 242 266 257 276 225 239 244 237 239 210 264 239 265 247 199 234 226 230 229 262 267 275 262 231 273 267 260 271 271 262 245 243 276 248 227 237 245 265 238 235 239 228 216 241 222 260 223 239 232 235 228 226 232 255 211 220 228 239 232 250 221 226 228 256 265 282 270 259 242 243 236 234 239 246 243 242 232 231 233 259 248 211 229 248 237 271 233 236 262 261 269 264 247 229 221 234 262 239 240 221 246 230 247 231 261 255 230 244 237 237 267 228 220 258 235 237 255 234 236 221 272 229 249 222 220 248 238 237 258 240 228 258 245 231 239 231 227 237 248 228 223 266 238 244 240 249 277 238 260 263 237 223 226 237 234 270 240 241 241 249 275 238 244 265 215 226 232 232 240 227 228 211 229 231 241 245 224 234 246 244 222 243 222 237 259 243 229 229 249 269 223 243 255 266 201 266 241 262 223 239 240 268 221 265 248 256 230 240 237 233 265 231 247 234 233 256 228 239 267 259 217 244 239 216 214 255 248 242 220 245 226 239 241 259 236 256 242 290 228 243 246 264 263 262 219 255 262 244 244 225 238 268 232 278 272 218 243 240 248 239 237 240 241 228 249 235 268 267 246 234 266 250 248 225 249 230 240 209 255 229 240 237 236 234 234 246 215 270 228 245 236 276 237 244 266 268 236 225 266 259 242 265 248 244 243 261 261 234 223 234 215 223 262 236 223 229 217 271 261 246 276 227 237 233 239 243 240 225 236 227 224 245 247 210 234 234 207 262 228 256 230 220 234 237 228 242 243 235 278 267 276 257 226 246 237 248 243 260 233 227 230 233 220 233 244 244 241 244 255 221 258 216 240 230 259 240 242 245 241 213 227 242 259 231 266 279 228 244 221 224 216 260 220 258 256 271 234 234 230 281 200 263 247 249 231 241 239 260 240 216 262 241 255 255 260 273 225 264 245 247 227 227 224 255 242 258 240 235 229 227 268 241 245 244 264 275 225 267 218 233 242 235 224 263 256 241 236 269 262 269 274 264 220 258 229 256 230 235 237 270 270 221 239 244 241 245 247 267 245 250 242 229 262 207 238 234 247 248 274 233 247 234 258 287 249 255 240 284 256 217 225 266 281 228 233 242 222 219 274 256 230 278 261 227 242 233 224 285 262 250 240 242 260 244 230 260 244 246 230 256 239 211 229 249 238 230 266 231 257 269 240 242 265 268 244 260 244 258 228 238 248 225 245 236 236 232 245 261 263 292 248 247 239 280 236 245 216 250 250 255 232 232 279 238 261 239 247 264 232 227 248 262 265 208 233 231 235 246 256 264 261 231 225 247 228 239 248 247 246 218 245 242 233 247 230 267 232 234 231 232 244 237 226 231 258 204 230 272 267 213 289 232 238 246 278 262 243 287 248 237 230 243 243 241 248 237 241 234 216 259 257 230 273 243 265 272 236 226 249 245 231 229 210 229 211 243 232 218 278 238 238 239 257 234 275 240 261 211 286 224 260 235 238 248 267 246 283 247 245 241 228 241 239 222 225 249 240 243 242 239 238 265 257 228 250 220 206 226 225 259 249 218 214 255 244 246 234 242 257 241 276 246 276 241 246 235 269 266 225 224 249 249 261 238 260 249 272 234 244 238 237</counts>
			</dataPoints>
		</scan>
	</xrdMeasurement>
</xrdMeasurements>