File: data/XRD/XG-Sauerstoff/XG-750/W6823-1B_XG_Sauerstoff_750.xrdml
<xrdMeasurements xmlns="http://www.xrdml.com/XRDMeasurement/2.1" xmlns:xsi="http://www.w3.org/2001/XMLSchema-instance" xsi:schemaLocation="http://www.xrdml.com/XRDMeasurement/2.1 http://www.xrdml.com/XRDMeasurement/2.1/XRDMeasurement.xsd" status="Completed">
	<comment>
		<entry>Configuration=Factory configuration, Owner=User-1, Creation date=7/8/2013 4:01:53 PM</entry>
		<entry>Goniometer=PW3050/65 (Theta/2Theta); Minimum step size 2Theta:0.0001; Minimum step size Omega:0.0001</entry>
		<entry>Sample stage=MRD Cradle; Minimum step size Phi:0.01; Minimum step size Chi:0.01; Minimum step size X:0.01; Minimum step size Y:0.01; Minimum step size Z:0.001</entry>
		<entry>Diffractometer system=XPERT-PRO</entry>
		<entry>Measurement program=C:\PANalytical\Data Collector\Programs\Jorrit\2thom\_absolute_2th-om_10-130deg_PIXscan_56min.xrdmp, Identifier={15BCCF57-2807-42BD-B5B9-ECC0B3DC9284}</entry>
		<entry>Batch program=C:\PANalytical\Data Collector\Programs\SimonL\batch4x_2thom_10-130°_z9.1_x0,10,20,30_y0_57min.xrdmp, Identifier={EED9823A-2BEB-424C-9252-345C4EF2834A}</entry>
	</comment>
	<sample type="To be analyzed">
		<id></id>
		<name></name>
		<preparedBy></preparedBy>
	</sample>
	<xrdMeasurement measurementType="Scan" status="Completed" sampleMode="Reflection">
		<comment>
			<entry>_absolute_2th-om_10-130deg_PIXscan_56min</entry>
			<entry>PHD Lower Level = 4.83 (keV), PHD Upper Level = 11.27 (keV)</entry>
		</comment>
		<usedWavelength intended="K-Alpha 1">
			<kAlpha1 unit="Angstrom">1.5405980</kAlpha1>
			<kAlpha2 unit="Angstrom">1.5444260</kAlpha2>
			<kBeta unit="Angstrom">1.3922500</kBeta>
			<ratioKAlpha2KAlpha1>0.5000</ratioKAlpha2KAlpha1>
		</usedWavelength>
		<incidentBeamPath>
			<radius unit="mm">320.00</radius>
			<xRayTube id="1010048" name="Empyrean Cu LFF HR (9430 033 7310x) DK442154">
				<tension unit="kV">40.0</tension>
				<current unit="mA">40.0</current>
				<anodeMaterial>Cu</anodeMaterial>
				<focus type="Line">
					<length unit="mm">12.0</length>
					<width unit="mm">0.4</width>
					<takeOffAngle unit="deg">4.2</takeOffAngle>
				</focus>
			</xRayTube>
			<xRayMirror id="27010001" name="Inc. Beam Cu W/Si (parabolic MRD)" hybrid="false">
				<crystal type="Graded" shape="Parabolic">W/Si</crystal>
				<acceptanceAngle unit="deg">0.800</acceptanceAngle>
				<length unit="mm">60.0</length>
			</xRayMirror>
			<sollerSlit id="21010002" name="Soller slits 0.04 rad.">
				<opening unit="rad">0.0400</opening>
			</sollerSlit>
			<mask id="22030007" name="Fixed mask 2 mm">
				<distanceToSample unit="mm">220.00</distanceToSample>
				<width unit="mm">2.00</width>
			</mask>
			<divergenceSlit id="22010007" name="Fixed slit 1/8°" xsi:type="fixedDivergenceSlitType">
				<distanceToSample unit="mm">220.00</distanceToSample>
				<height unit="mm">0.19</height>
			</divergenceSlit>
		</incidentBeamPath>
		<diffractedBeamPath>
			<radius unit="mm">320.00</radius>
			<sollerSlit id="21010002" name="Soller slits 0.04 rad.">
				<opening unit="rad">0.0400</opening>
			</sollerSlit>
			<receivingSlit id="22010001" name="Fixed slit 4°">
				<height unit="mm">5.88</height>
			</receivingSlit>
			<detector id="7010017" name="PIXcel3D 1x1 detector" xsi:type="areaDetectorType">
				<phd unit="%">
					<lowerLevel>30.0</lowerLevel>
					<upperLevel>70.0</upperLevel>
				</phd>
				<mode>Scanning</mode>
				<activeChannelsEquatorial>255</activeChannelsEquatorial>
				<activeChannelsAxial>255</activeChannelsAxial>
				<pitchEquatorial unit="mm">0.05500</pitchEquatorial>
				<pitchAxial unit="mm">0.05500</pitchAxial>
				<readOutPeriod unit="seconds">0.135</readOutPeriod>
			</detector>
		</diffractedBeamPath>
		<scan appendNumber="0" mode="Continuous" scanAxis="2Theta-Omega" status="Completed">
			<header>
				<startTimeStamp>2024-09-18T23:12:04+02:00</startTimeStamp>
				<endTimeStamp>2024-09-19T00:08:10+02:00</endTimeStamp>
				<author>
					<name>PRO-MRD</name>
				</author>
				<source>
					<applicationSoftware version="6.1b">Data Collector</applicationSoftware>
					<instrumentControlSoftware version="7.0E 20130304">XPERT-PRO</instrumentControlSoftware>
					<instrumentID>0000000011142674</instrumentID>
				</source>
			</header>
			<dataPoints>
				<positions axis="2Theta" unit="deg">
					<startPosition>9.99826193</startPosition>
					<endPosition>129.99755682</endPosition>
				</positions>
				<positions axis="Omega" unit="deg">
					<startPosition>4.99913096</startPosition>
					<endPosition>64.99877841</endPosition>
				</positions>
				<positions axis="Phi" unit="deg">
					<commonPosition>0.00</commonPosition>
				</positions>
				<positions axis="Chi" unit="deg">
					<commonPosition>0.00</commonPosition>
				</positions>
				<positions axis="X" unit="mm">
					<commonPosition>20.00</commonPosition>
				</positions>
				<positions axis="Y" unit="mm">
					<commonPosition>0.00</commonPosition>
				</positions>
				<positions axis="Z" unit="mm">
					<commonPosition>9.100</commonPosition>
				</positions>
				<commonCountingTime unit="seconds">32.895</commonCountingTime>
				<counts 201 172 201 204 200 180 217 213 177 198 226 162 171 176 167 208 181 184 188 200 173 158 212 188 202 187 199 194 177 199 189 208 192 186 190 230 219 185 181 197 183 210 198 186 206 210 170 198 194 182 192 188 188 236 181 200 186 179 215 188 216 188 177 196 213 172 192 184 206 170 183 186 210 198 191 191 175 189 175 203 180 194 163 183 177 183 194 172 179 182 160 174 177 215 157 165 202 188 200 202 165 168 205 179 186 175 187 193 203 162 205 210 169 176 183 202 182 183 183 205 188 202 208 189 183 187 165 187 170 196 192 198 181 191 203 167 193 200 203 169 197 188 191 173 171 173 193 187 207 183 178 178 185 175 202 190 170 176 191 159 204 177 182 162 179 174 172 182 209 161 189 191 168 182 185 167 190 176 187 199 189 172 173 207 188 191 166 171 178 181 185 185 171 195 164 178 169 178 187 211 207 185 157 181 185 168 149 173 188 183 187 162 173 191 192 156 154 177 178 151 165 203 171 198 191 181 166 164 183 180 152 173 153 163 156 148 182 182 164 182 169 199 203 175 161 187 153 153 181 159 164 202 198 179 199 146 195 157 170 199 166 177 183 167 156 158 188 179 150 177 183 176 172 168 162 166 165 172 180 178 169 185 176 188 190 156 182 176 177 154 161 198 136 169 177 198 163 178 161 178 161 181 171 156 189 177 179 170 160 151 174 170 159 155 169 149 166 155 181 162 170 188 169 177 172 180 177 161 182 160 140 157 153 168 173 157 152 181 171 159 182 189 161 195 162 175 164 179 165 153 173 160 149 178 168 166 179 168 151 178 175 174 170 159 175 177 155 165 156 168 159 168 138 136 155 174 177 180 158 172 176 159 149 162 137 166 177 149 183 166 147 151 186 162 162 161 176 151 151 175 142 140 161 162 175 172 185 139 175 170 154 181 152 165 125 157 152 158 168 156 125 186 150 159 170 140 155 143 151 160 173 153 172 171 159 149 182 164 170 151 161 127 173 155 147 165 149 167 139 172 161 153 146 138 149 128 186 159 171 161 166 164 145 171 142 147 140 155 162 162 176 129 167 156 149 163 171 177 145 158 157 175 151 155 145 164 155 156 148 161 148 161 145 158 160 155 167 155 146 164 167 156 165 157 148 152 174 148 150 163 153 149 163 155 157 166 163 136 159 152 161 143 159 139 148 138 146 149 175 153 161 147 149 147 141 172 139 147 185 158 170 156 156 168 143 144 137 162 141 144 177 140 161 150 151 163 150 155 164 159 149 154 155 171 140 160 158 170 152 151 155 149 157 144 157 167 158 175 150 144 156 175 155 160 151 149 151 158 151 148 165 159 147 149 162 154 189 130 167 161 159 150 153 156 157 176 152 142 163 182 163 162 155 173 167 149 144 161 137 156 151 172 146 150 160 133 185 153 147 159 144 153 151 167 170 132 148 134 165 160 158 150 146 154 154 149 166 144 165 161 170 153 185 126 148 173 160 150 152 155 160 142 160 159 154 143 146 161 138 139 149 164 147 181 150 162 145 156 156 161 126 158 153 149 166 154 159 157 178 157 146 125 161 175 193 135 168 154 135 155 166 143 142 142 163 146 147 123 167 119 143 151 144 165 140 137 124 160 157 142 147 172 166 148 163 142 134 162 142 162 156 163 159 146 144 148 155 167 146 134 144 151 159 151 158 157 150 152 137 145 170 146 166 145 133 156 157 149 164 155 135 140 150 163 160 144 140 148 140 160 165 150 141 137 161 161 165 165 169 175 175 134 168 148 156 161 156 153 143 158 151 133 134 148 142 139 162 140 167 161 136 159 150 131 161 153 141 162 151 156 155 153 161 153 147 143 141 167 137 144 150 148 161 156 161 136 142 135 145 159 149 144 145 131 144 146 150 160 162 147 168 155 169 137 162 147 153 135 142 156 142 142 162 158 137 159 158 151 178 174 130 162 167 149 150 153 159 160 140 151 140 146 131 171 166 176 150 164 152 147 164 176 152 155 167 158 157 164 157 137 174 166 162 154 141 145 159 159 148 154 159 161 156 172 174 142 155 155 170 131 147 166 154 142 141 150 171 146 175 127 152 164 154 168 152 154 142 160 151 168 159 186 155 162 133 188 135 155 162 161 137 138 171 168 171 169 146 157 158 132 153 159 138 162 174 163 141 167 140 156 157 163 178 158 131 145 143 138 167 166 147 156 142 154 169 161 170 154 164 165 146 160 140 135 159 140 160 162 158 166 146 166 126 175 154 152 181 172 165 143 156 160 154 166 161 157 141 190 146 160 158 142 164 155 179 144 178 141 163 128 151 163 153 168 173 172 157 183 141 151 146 164 155 162 162 160 137 170 160 160 160 162 159 161 149 154 164 147 175 167 148 150 148 147 174 178 157 176 171 169 168 184 160 161 147 160 168 158 146 185 153 181 118 173 161 146 174 169 169 157 138 176 173 158 161 157 186 173 147 165 159 161 158 167 175 183 172 155 150 163 155 161 163 175 164 148 171 151 157 181 166 150 156 164 141 174 166 142 186 193 160 154 137 154 164 160 157 153 136 190 167 151 162 148 165 142 161 165 158 137 158 159 165 145 162 182 142 190 170 138 178 186 177 157 164 186 142 165 150 162 177 157 161 163 167 143 150 185 158 167 151 163 158 166 171 161 157 189 162 171 155 147 151 162 174 169 185 143 166 160 176 160 146 144 177 167 171 152 171 180 154 154 153 169 141 178 195 155 167 142 138 146 161 161 185 181 160 163 158 166 156 170 155 138 158 159 164 162 172 164 159 143 165 193 186 168 169 157 187 158 168 179 161 181 162 165 156 176 169 150 167 169 147 162 148 179 162 144 139 162 161 202 183 131 164 181 149 148 168 188 165 158 156 150 163 149 172 141 168 175 152 159 150 185 166 183 173 167 161 202 170 157 169 164 156 143 149 151 164 155 137 162 169 152 174 167 157 175 160 170 148 155 174 169 158 156 174 169 163 149 174 168 161 164 162 155 159 153 175 175 162 163 156 163 150 148 167 163 152 164 153 155 188 153 172 158 162 165 174 158 151 161 161 144 162 163 147 183 180 154 169 173 149 148 180 154 175 149 169 152 150 168 140 154 163 146 173 139 169 159 161 177 155 162 142 143 162 162 167 173 151 151 160 169 158 151 178 167 132 172 172 138 155 160 134 162 180 181 148 156 161 160 157 165 154 183 143 140 159 153 166 170 139 151 157 132 169 157 155 144 149 171 139 162 156 182 159 148 156 142 149 157 157 161 148 153 164 151 140 162 155 160 148 168 157 156 146 155 154 152 141 140 139 154 135 144 163 154 150 176 141 154 155 171 161 157 149 147 147 137 141 130 130 146 144 173 166 157 154 145 150 148 133 159 129 152 144 158 153 143 149 149 165 132 149 134 146 143 155 154 138 139 149 159 135 160 163 143 158 168 150 146 137 141 132 148 162 125 151 128 139 163 137 145 157 161 160 148 141 140 141 152 133 117 141 142 154 150 159 157 138 151 123 142 157 129 164 141 154 126 114 156 144 145 145 138 160 152 172 139 138 133 126 154 141 147 142 121 150 139 116 143 150 156 133 113 141 135 138 145 130 156 126 152 158 131 143 127 132 117 143 150 119 136 128 131 132 122 160 142 147 124 146 130 136 144 137 156 135 140 130 131 143 148 141 147 158 144 130 140 119 137 165 128 148 129 158 128 121 151 124 113 127 137 136 136 146 124 125 132 123 155 138 145 143 132 163 127 123 148 163 134 142 137 151 132 142 135 142 143 126 148 143 134 138 148 126 123 125 127 133 151 139 131 109 126 137 126 122 138 116 129 123 138 124 138 139 144 122 154 120 121 135 145 126 139 147 138 139 128 133 135 144 138 139 121 130 133 132 120 132 158 130 137 126 109 116 127 113 154 121 124 121 121 142 116 114 140 125 131 123 155 136 143 112 135 125 114 131 130 132 130 148 122 128 117 132 134 107 132 133 129 113 125 125 129 139 111 136 143 138 118 107 137 140 119 139 124 133 117 120 124 153 146 145 137 136 133 126 129 128 129 133 137 97 153 127 121 131 125 124 107 130 124 122 140 121 127 127 130 96 139 109 135 128 135 142 118 137 117 127 116 141 120 125 144 133 134 143 125 133 123 136 128 129 120 114 99 140 130 128 131 145 120 123 141 143 137 124 147 126 160 148 129 150 123 107 136 131 138 112 119 138 131 123 104 138 115 117 129 120 113 109 128 124 120 142 131 133 122 114 122 137 138 127 133 128 130 104 126 112 118 137 131 105 139 123 122 104 126 118 130 110 111 106 133 140 141 126 115 113 115 102 116 125 112 132 110 114 136 107 126 137 119 119 112 125 119 115 115 112 126 134 96 133 103 124 130 112 121 101 113 128 102 121 92 121 120 111 121 108 131 123 111 134 121 108 117 108 119 121 126 114 125 138 119 110 111 114 111 125 116 125 107 105 119 109 109 106 112 121 116 115 104 115 115 144 116 118 117 122 99 113 106 130 116 128 125 125 99 151 132 122 96 110 94 122 111 139 115 92 133 104 126 106 98 100 117 132 120 106 107 107 123 101 136 120 102 98 113 103 132 109 110 123 108 119 104 96 106 99 126 108 121 126 118 117 102 119 112 105 133 138 120 137 101 106 102 110 110 112 121 130 119 100 109 111 112 109 105 108 118 103 115 103 126 138 118 125 99 108 117 85 119 128 100 117 119 113 102 100 120 93 125 99 119 120 109 101 111 107 111 104 120 94 125 101 97 115 108 114 102 121 130 109 113 105 116 114 109 112 100 115 114 96 111 121 111 132 114 116 108 129 111 136 115 103 112 124 114 107 99 126 116 102 126 115 104 111 110 107 109 121 115 114 101 117 134 94 104 116 119 104 95 124 120 109 98 121 117 108 107 101 92 114 103 109 114 107 94 122 118 105 113 122 98 105 113 97 122 94 93 121 93 98 124 118 115 104 109 110 101 110 103 119 126 105 99 110 111 100 131 91 115 97 112 121 111 117 104 106 107 112 113 97 118 97 102 112 106 105 104 114 128 97 95 111 115 100 98 97 113 103 105 96 109 107 116 109 118 106 129 129 106 110 117 106 100 112 98 105 110 83 113 109 100 106 98 108 124 105 117 96 115 121 115 105 96 111 115 116 118 97 114 111 102 97 102 118 114 112 112 104 124 117 108 103 98 104 104 98 103 120 107 129 102 107 116 109 111 112 108 104 110 112 105 107 109 102 122 109 115 87 124 108 103 101 125 92 89 111 101 123 78 110 108 121 108 116 109 96 109 108 104 124 115 111 98 103 105 123 119 103 95 120 111 118 97 127 100 106 103 111 115 106 111 113 104 116 105 115 97 109 89 110 112 125 100 105 124 118 119 106 104 84 106 107 108 113 107 111 107 111 119 93 113 123 105 98 97 96 101 108 109 109 122 86 113 106 124 105 114 109 96 97 114 88 95 106 101 95 102 102 92 118 89 84 104 79 94 105 90 95 100 108 86 99 95 96 130 104 114 96 102 125 107 108 117 109 99 120 107 111 102 98 82 114 114 111 116 88 123 94 127 111 114 110 108 89 106 106 121 133 104 89 113 91 113 111 106 119 109 96 105 101 120 95 107 111 124 122 96 99 106 134 112 105 106 127 131 90 106 112 104 114 114 113 92 119 96 110 111 108 113 106 104 100 102 95 97 107 106 95 112 102 90 104 115 86 101 97 112 102 128 103 101 109 101 99 107 122 95 101 103 117 109 103 102 81 130 105 108 83 111 106 85 98 108 121 106 111 116 115 92 100 104 102 112 119 117 106 118 92 98 88 101 94 95 105 101 115 104 83 100 99 92 125 95 114 118 111 104 116 101 77 113 128 88 83 112 105 102 110 113 107 102 92 111 88 101 117 118 93 85 99 110 106 117 93 100 91 120 115 107 113 103 84 122 115 84 109 112 117 117 120 101 102 111 104 114 113 102 110 90 99 108 105 100 101 119 96 113 96 87 100 95 107 102 97 106 102 76 114 100 99 103 92 114 112 113 106 102 99 101 99 101 98 113 106 97 100 107 97 88 107 116 99 115 97 104 100 104 109 125 113 84 122 114 94 102 110 123 120 96 117 94 107 118 103 117 120 92 98 127 110 115 110 91 107 98 99 114 92 103 112 109 92 97 94 115 116 100 109 95 102 112 98 90 99 96 103 98 94 115 106 122 104 104 111 106 102 99 113 117 94 101 117 101 99 109 106 108 99 110 103 105 94 107 112 97 102 109 92 114 100 107 96 97 115 105 96 101 95 112 112 106 102 113 106 99 91 97 92 105 100 107 113 96 118 100 131 110 108 110 119 112 102 94 110 96 102 111 101 119 100 116 90 120 88 84 89 92 114 100 109 93 92 105 97 96 112 106 116 103 103 105 102 72 92 105 102 108 104 101 94 120 112 91 104 116 86 112 114 92 112 113 99 93 100 115 88 98 96 98 101 98 103 119 110 77 112 102 114 113 105 108 116 107 99 88 104 111 100 108 109 94 109 109 90 101 118 111 97 97 122 108 94 118 111 128 111 109 100 97 112 111 91 95 99 97 117 112 97 112 110 108 102 106 101 99 108 95 102 98 108 87 104 106 102 103 116 94 100 109 103 108 109 114 78 83 93 100 97 73 98 126 92 100 96 88 108 96 108 98 101 101 101 104 102 86 108 110 104 101 94 101 98 103 109 119 122 141 114 107 114 107 103 99 116 104 99 115 104 99 113 105 112 108 116 107 105 131 111 130 106 110 109 97 99 120 99 106 106 100 120 96 100 106 99 124 105 117 115 101 93 109 118 105 117 124 104 99 103 105 104 102 122 108 111 107 92 116 104 98 111 96 117 96 104 95 104 101 105 104 113 120 94 81 107 108 101 97 115 97 109 102 105 103 109 131 106 99 123 111 99 114 94 95 110 96 93 102 106 98 101 119 100 76 107 96 103 98 102 96 86 103 109 92 101 94 109 98 97 116 124 118 124 109 100 115 99 102 96 105 107 105 103 109 111 111 97 108 107 109 123 95 101 112 103 99 130 110 104 113 98 92 98 95 109 121 95 98 116 108 94 82 100 109 110 91 98 103 97 106 103 104 110 106 110 117 97 106 109 116 113 119 89 129 97 96 115 114 105 106 111 105 97 123 101 109 115 99 99 113 91 119 118 92 107 100 124 102 107 95 102 105 108 108 107 94 90 108 97 103 84 111 119 123 113 133 112 107 123 123 119 100 116 111 84 111 101 122 105 105 139 110 120 130 91 119 116 121 96 100 105 125 93 101 121 108 101 126 101 103 132 109 103 118 110 111 111 93 109 95 107 123 114 116 108 120 128 116 112 99 95 120 93 108 111 118 115 105 113 115 99 119 107 117 118 112 110 110 113 106 107 107 114 109 102 102 110 103 111 115 122 109 97 120 102 125 114 103 128 138 109 121 104 118 104 114 95 121 108 102 111 117 109 118 106 117 102 120 95 117 131 102 129 119 113 102 110 113 111 122 125 117 112 122 126 120 90 131 114 94 148 96 97 113 116 114 124 116 117 109 111 118 101 115 121 122 119 120 134 132 119 137 121 112 122 118 143 138 136 145 128 121 127 116 134 128 122 115 125 116 124 110 111 117 106 104 90 101 102 113 120 125 102 120 93 116 128 102 116 133 94 117 125 100 111 112 125 119 108 120 117 108 125 92 126 129 136 109 116 114 111 127 130 130 117 135 121 134 100 119 121 119 118 111 109 132 139 112 131 125 126 132 109 138 132 104 133 115 133 135 122 130 123 117 125 139 126 139 138 128 127 127 133 122 148 118 141 128 168 158 183 145 129 169 139 152 156 155 181 147 186 193 181 196 163 214 199 198 193 182 173 186 185 183 196 165 211 167 182 179 192 179 185 158 181 172 150 146 158 148 143 133 151 157 131 138 121 144 160 129 133 140 142 138 136 141 98 128 108 122 131 130 130 114 103 111 101 119 125 122 125 124 132 118 108 112 127 111 130 112 114 140 116 115 137 149 101 108 102 128 116 112 124 135 120 102 104 101 128 122 121 132 127 116 124 98 126 102 109 120 111 117 127 143 100 101 121 123 108 102 99 105 114 105 102 108 120 114 97 102 91 99 101 101 116 115 118 133 105 110 127 119 100 129 110 117 104 130 120 113 111 122 95 109 115 96 88 108 93 117 111 115 111 123 110 99 109 121 88 121 105 129 111 92 114 125 117 126 115 96 106 119 99 98 110 110 109 121 90 113 108 114 108 97 112 103 102 103 115 109 123 104 104 103 96 114 123 96 116 115 99 119 105 132 111 101 122 130 101 98 118 115 131 126 100 115 126 111 131 112 126 98 118 113 106 118 98 135 112 99 110 121 119 127 108 118 117 108 110 107 99 132 105 126 116 114 104 118 111 119 114 121 116 126 120 103 121 106 103 124 137 99 127 120 117 107 114 106 127 110 117 96 110 129 113 108 110 105 112 112 96 118 110 119 108 117 111 119 104 105 105 91 124 126 97 107 125 114 102 99 124 104 101 95 110 109 106 98 108 112 98 121 104 118 105 119 108 93 113 119 95 121 114 98 117 120 101 102 131 98 117 94 118 130 114 108 118 94 108 115 95 102 111 113 88 104 111 97 100 109 114 92 120 100 101 110 116 127 105 115 113 116 96 120 133 108 113 126 113 117 99 114 100 114 107 108 116 89 107 91 110 103 106 96 117 114 95 123 124 112 99 96 112 118 102 97 121 117 105 117 101 119 110 108 117 111 96 107 113 124 118 115 115 95 103 89 125 123 102 116 110 113 124 107 113 109 123 97 113 126 104 113 124 90 109 96 114 107 116 107 103 124 112 121 116 91 129 129 105 113 111 88 98 125 88 103 93 121 108 96 104 124 97 129 140 123 110 125 109 105 106 120 140 107 122 114 118 105 109 117 105 115 109 122 122 112 108 106 105 119 116 108 112 119 93 125 125 115 117 122 123 104 115 126 102 101 102 106 114 119 125 118 108 104 114 97 100 105 126 109 111 115 115 127 118 127 99 114 106 98 119 123 108 110 99 104 104 105 107 112 110 104 87 108 112 89 107 91 124 122 102 124 106 91 109 118 106 107 105 113 115 95 111 109 92 110 99 107 107 117 104 91 107 128 112 128 106 86 115 114 123 122 109 114 106 119 103 117 93 108 87 103 119 113 114 113 121 115 116 113 111 109 119 123 124 127 104 123 111 113 119 117 126 103 106 109 118 112 92 118 103 108 107 109 109 96 126 108 116 117 108 107 108 113 116 123 121 104 120 116 110 110 112 106 115 128 122 96 112 95 92 88 102 127 120 116 96 114 103 112 98 110 79 118 114 127 112 124 111 107 100 112 116 104 99 113 121 120 92 102 105 93 111 110 108 124 104 117 107 123 101 93 92 105 131 117 126 114 107 100 98 101 108 127 108 128 105 119 102 111 97 112 102 117 107 104 104 118 105 114 113 111 99 120 95 109 100 118 107 96 100 95 94 101 121 95 109 124 111 120 117 111 114 126 103 114 128 118 100 96 105 85 88 121 109 129 97 97 114 120 96 128 121 115 104 111 127 84 103 107 102 110 115 119 106 111 108 108 101 114 114 107 104 102 118 92 116 104 112 124 109 128 132 109 113 104 127 93 116 111 105 104 118 106 111 105 116 115 122 140 103 130 116 100 94 115 92 85 116 110 112 125 102 108 125 97 96 110 121 118 107 106 154 115 108 121 100 122 92 118 133 115 130 108 101 123 107 114 113 121 122 119 115 96 132 126 122 112 96 89 119 95 116 107 108 117 120 118 120 131 117 109 107 126 109 111 111 118 103 126 119 117 114 99 104 110 89 89 118 110 105 105 129 107 102 110 99 107 114 118 101 98 107 126 133 127 104 116 85 112 123 105 104 110 111 108 105 108 132 96 104 108 113 94 121 115 116 121 108 114 102 116 108 106 109 114 110 96 102 109 116 124 123 116 116 110 124 108 117 115 125 105 110 96 120 106 106 109 103 108 103 94 127 108 117 100 104 128 139 126 121 119 130 113 117 121 116 130 122 117 111 115 94 95 109 119 106 111 96 107 116 109 94 112 115 104 116 95 134 105 123 102 116 123 118 119 116 111 114 98 137 106 128 119 103 112 135 101 118 115 113 111 103 110 127 111 107 121 115 100 110 113 121 103 104 123 101 108 104 109 99 113 106 95 132 120 111 116 101 129 144 116 98 116 118 96 106 107 109 101 131 121 109 95 101 113 121 118 112 108 101 107 123 117 99 113 100 120 94 112 102 115 129 90 115 112 116 123 127 120 147 108 104 134 115 96 120 102 118 106 89 109 105 99 112 111 107 97 118 112 106 112 105 88 117 111 107 108 104 92 136 105 109 123 116 108 104 99 106 106 106 122 122 105 130 92 111 116 124 105 104 113 117 114 131 117 109 116 120 104 116 123 104 111 103 115 119 87 115 129 108 103 108 122 121 103 118 120 113 113 85 125 111 98 107 127 121 100 108 118 135 100 104 110 109 126 109 124 92 99 101 97 127 131 115 100 114 110 101 105 116 94 115 110 113 99 89 125 108 114 122 111 104 110 111 118 108 115 114 108 110 117 127 123 107 123 133 120 108 117 113 97 117 127 117 107 85 94 108 111 98 93 96 104 100 115 105 114 115 110 128 116 107 135 95 109 115 132 108 128 109 113 123 94 134 105 117 106 128 112 99 121 126 120 113 102 102 103 103 101 129 123 123 131 116 103 117 95 105 110 110 105 106 98 109 109 113 105 102 117 123 107 112 100 110 109 115 112 113 112 106 110 123 95 93 98 114 108 109 102 120 102 115 101 121 107 95 115 108 111 123 108 114 117 112 111 102 114 112 109 106 121 120 101 126 103 102 97 117 121 106 105 117 84 108 123 93 106 101 96 107 98 103 101 111 114 113 90 113 107 106 112 108 87 126 135 113 110 106 113 104 120 94 124 116 116 101 112 95 114 106 106 113 104 119 102 108 112 122 110 112 105 105 114 110 122 91 111 87 110 100 117 109 124 129 112 97 113 126 112 129 110 117 113 104 105 128 102 122 105 111 104 118 102 112 114 107 111 100 105 100 121 133 87 109 127 130 118 111 105 111 125 104 116 121 118 113 105 121 117 118 119 86 122 98 109 140 109 116 82 118 110 110 116 120 135 117 127 107 120 91 106 117 109 107 108 113 110 99 128 106 108 92 114 119 93 106 115 100 121 118 126 115 104 108 111 115 110 123 142 121 108 103 128 122 101 107 107 123 119 128 103 135 120 114 129 97 115 114 107 107 119 131 93 109 124 120 115 124 113 120 111 116 136 109 123 131 114 107 102 116 99 132 117 92 98 111 111 131 114 113 119 93 128 116 106 123 115 118 129 94 108 109 109 115 103 111 87 129 120 103 115 117 105 115 98 97 113 117 122 140 115 104 139 114 115 110 122 123 114 109 123 126 101 123 101 111 116 117 111 111 113 120 130 128 119 109 108 118 129 109 137 138 112 127 87 129 117 99 131 110 126 103 99 109 120 109 119 121 121 109 97 122 97 120 117 102 113 115 112 112 128 108 94 129 110 118 112 126 134 91 126 121 118 111 82 93 116 92 110 112 111 107 103 138 99 112 126 103 119 115 113 106 126 120 104 113 136 115 89 120 95 110 117 128 104 115 121 130 109 124 108 123 129 107 121 117 92 112 115 100 129 121 121 117 96 113 109 108 115 123 137 123 131 112 102 122 111 122 113 106 133 124 120 139 117 135 116 104 112 111 101 115 108 105 138 111 104 91 113 119 100 115 110 129 110 81 128 112 102 127 109 111 117 112 141 114 110 130 121 120 113 109 133 127 121 73 109 107 126 132 110 113 102 101 105 108 118 117 131 109 104 117 141 130 106 119 97 106 109 112 135 93 124 108 108 112 117 108 109 111 108 107 136 120 113 116 115 111 100 111 115 106 110 109 125 103 114 125 107 134 117 99 122 122 116 111 132 113 125 115 113 136 105 117 113 101 115 106 119 111 94 119 129 114 118 108 98 123 122 112 127 124 121 97 126 120 117 117 114 128 126 111 132 128 104 134 109 119 128 113 130 116 114 116 114 137 125 119 114 99 119 125 116 119 112 98 118 115 131 111 124 119 83 109 99 117 116 113 113 96 106 107 92 120 122 140 125 121 107 119 123 107 121 118 107 109 111 131 129 121 114 119 131 105 119 123 128 114 103 115 131 110 104 116 117 121 112 110 109 118 97 125 109 102 113 111 124 113 107 118 114 108 105 130 110 99 115 99 122 129 113 148 117 126 116 120 103 117 102 120 128 112 108 115 118 119 118 123 126 118 108 123 117 94 102 114 123 107 109 121 109 123 124 134 123 107 104 125 122 134 119 111 104 95 135 128 120 118 114 110 109 107 120 109 111 127 109 126 117 121 137 136 122 111 88 132 123 130 110 101 120 122 111 132 110 118 118 124 138 109 107 111 113 129 124 133 119 108 148 132 112 119 116 131 125 133 122 125 94 107 109 143 103 114 113 92 115 133 114 113 125 115 113 132 124 155 142 114 127 145 117 117 123 139 137 105 123 118 128 133 124 121 110 130 114 129 126 126 131 117 115 120 134 119 118 141 151 119 131 129 126 123 127 105 107 127 138 141 128 115 112 122 109 101 134 109 112 105 114 105 122 101 115 125 132 127 106 95 117 105 117 111 116 129 105 118 126 126 113 128 95 122 110 125 133 126 100 124 117 119 108 122 102 126 134 125 141 104 108 111 130 122 111 144 133 110 114 112 119 95 112 117 126 124 118 123 119 104 105 123 121 102 123 130 104 116 112 122 108 135 128 145 132 117 120 116 109 115 121 118 114 117 145 106 129 129 119 104 120 104 113 130 105 114 93 111 117 119 125 117 107 104 116 99 128 115 108 115 126 121 121 132 99 130 109 142 119 105 114 130 99 116 143 98 138 125 113 125 122 116 116 118 127 117 112 121 128 109 119 122 111 100 135 122 107 109 126 98 104 121 126 121 108 100 133 100 97 114 133 138 111 105 102 116 112 120 123 118 116 107 109 106 108 125 107 118 123 145 108 107 123 121 133 135 105 113 95 125 114 107 116 100 114 99 126 114 114 113 127 117 110 121 119 117 126 132 100 96 115 103 110 144 127 108 126 112 108 114 88 118 122 103 116 111 129 103 118 119 112 100 127 126 136 108 129 114 110 120 112 105 115 121 127 106 98 110 110 118 128 120 111 120 102 121 108 129 125 115 117 114 85 137 106 115 109 113 125 93 111 115 104 127 108 100 132 125 119 114 115 117 96 119 109 109 91 129 121 101 119 91 120 112 121 112 124 114 126 114 125 110 122 134 114 118 118 122 105 102 126 126 122 129 128 118 115 101 109 117 120 122 127 109 127 110 90 123 123 106 126 116 103 139 117 121 131 108 121 110 100 116 99 114 119 113 116 119 135 137 100 126 103 119 97 116 108 107 109 101 113 133 114 122 104 95 113 122 106 141 99 104 115 124 111 115 125 129 125 121 121 114 105 120 128 125 135 121 121 119 123 118 131 123 139 120 120 100 97 125 113 118 142 107 119 109 101 133 125 111 113 109 122 127 113 95 99 124 117 122 99 108 126 121 96 98 107 118 94 104 120 103 123 102 89 109 135 107 108 115 120 108 121 128 118 116 103 119 82 106 102 119 102 111 110 121 143 109 123 120 116 100 101 113 128 123 113 111 100 121 126 118 113 113 115 108 108 115 106 112 131 124 125 132 116 108 111 105 99 91 113 121 102 103 123 124 123 114 124 111 110 123 119 105 118 115 114 127 112 118 113 100 116 102 117 114 116 104 103 92 97 114 113 127 103 121 111 100 115 121 118 106 125 128 121 126 109 116 110 118 102 111 106 118 111 121 116 127 121 117 132 118 112 122 130 118 87 120 104 111 101 137 113 99 102 137 119 108 120 116 111 110 106 111 126 113 116 107 95 117 109 136 121 130 122 116 118 106 108 105 105 106 112 112 105 118 123 116 104 107 116 122 104 142 132 139 113 127 116 132 127 133 109 120 120 102 124 127 125 106 120 126 116 105 112 100 120 103 101 114 114 98 107 105 137 89 121 108 100 112 116 115 133 124 131 101 99 110 108 109 110 115 121 108 112 111 125 119 112 124 111 105 97 110 95 113 122 113 135 107 105 114 107 112 105 112 122 117 108 111 98 109 109 126 115 97 105 114 114 116 119 115 125 98 114 121 99 108 111 111 123 104 109 103 144 111 134 103 105 113 101 104 112 102 119 106 113 117 94 119 105 112 105 101 114 135 126 101 120 110 113 111 110 110 107 121 119 129 111 120 86 115 114 124 113 117 124 115 119 123 95 107 119 114 124 104 93 118 99 121 115 127 110 111 127 108 116 126 127 93 113 105 133 114 119 107 110 107 126 122 140 112 110 124 96 120 113 115 104 100 113 124 110 105 102 113 121 123 114 118 104 130 129 134 126 115 99 109 104 112 102 100 118 125 113 106 105 122 119 117 111 146 123 101 106 124 114 110 129 116 114 122 95 117 116 132 123 108 118 127 125 125 100 104 107 108 100 115 117 106 134 127 101 125 108 109 93 114 112 115 126 118 124 111 123 106 114 112 124 129 109 106 114 104 108 110 95 114 112 122 124 99 141 124 107 114 133 113 119 103 114 101 116 106 125 110 108 105 122 110 104 108 125 126 93 103 126 115 103 95 95 90 107 99 122 105 101 114 107 111 139 146 98 104 109 115 108 116 105 102 99 107 113 107 99 118 98 104 106 112 105 125 105 108 123 111 122 123 123 124 117 114 122 113 107 115 127 110 92 107 137 107 125 99 120 100 109 97 106 109 107 120 132 121 119 115 116 107 102 108 113 108 105 106 114 110 91 111 123 121 110 102 105 109 123 82 114 96 114 114 97 109 118 124 104 123 107 120 118 111 103 132 112 115 117 116 112 138 122 94 120 118 131 123 127 115 124 111 103 121 112 105 103 116 133 125 112 115 117 113 114 115 110 105 96 106 107 124 120 106 132 135 112 125 103 111 109 100 125 114 117 112 123 123 113 110 123 107 109 92 108 97 95 112 123 103 119 109 124 112 107 106 101 101 122 124 102 127 124 109 115 126 124 106 127 103 122 122 117 139 101 129 115 118 102 112 129 105 130 94 118 126 119 113 119 115 107 124 122 142 119 112 116 106 100 118 118 126 110 118 129 115 129 106 100 113 117 123 118 126 91 118 124 132 111 112 129 117 119 135 97 100 100 100 126 116 126 102 112 124 111 128 120 123 113 116 116 121 113 102 117 110 98 107 113 107 130 122 117 104 98 141 96 136 117 106 95 114 117 124 109 138 119 117 116 111 120 104 107 115 109 121 126 113 109 113 99 124 106 124 105 107 121 113 119 124 115 109 122 125 116 118 130 133 118 114 117 99 128 121 118 108 122 127 117 124 108 107 117 120 115 115 109 116 112 109 122 96 114 108 107 113 96 117 133 110 124 132 107 109 111 135 131 108 115 109 119 118 109 108 126 108 98 98 112 111 106 121 119 122 128 116 108 102 107 117 113 109 104 111 104 118 119 107 96 121 125 120 127 113 108 91 108 121 104 107 113 121 114 114 129 125 123 106 115 118 120 106 117 112 135 108 108 106 102 130 132 112 104 104 118 110 108 116 120 112 127 110 108 111 115 130 113 138 124 104 117 115 124 100 110 118 124 97 113 125 116 113 90 106 117 123 127 119 105 119 116 120 121 113 143 129 120 115 120 126 97 111 117 117 122 115 104 109 122 125 94 112 108 116 107 124 129 122 147 124 124 106 106 127 131 113 125 107 123 123 133 114 121 127 110 110 113 120 106 116 111 108 123 99 109 120 111 96 122 134 127 136 119 100 108 118 116 100 122 111 119 104 137 103 130 131 128 130 114 137 114 113 119 114 96 113 116 103 92 111 125 116 112 114 106 109 124 116 101 107 120 107 101 96 120 117 128 108 117 120 119 130 124 124 136 103 120 129 112 111 108 108 107 104 129 128 96 113 128 133 109 117 115 108 117 123 117 100 136 110 121 123 113 119 106 111 99 127 120 114 101 124 100 116 103 117 91 94 108 125 106 108 100 109 101 109 116 127 118 119 126 106 124 147 120 105 124 97 115 98 120 123 113 113 115 120 112 129 103 95 136 124 136 111 121 136 105 120 106 118 113 105 130 123 109 126 112 103 99 101 114 98 115 114 126 141 141 99 104 113 110 116 114 113 114 124 126 110 113 120 113 117 122 121 95 123 116 120 136 109 114 131 123 113 111 121 121 128 120 129 127 116 117 112 115 121 117 134 114 132 118 110 116 115 120 108 111 127 132 121 119 113 100 123 112 123 120 115 155 102 101 117 112 120 115 127 132 116 131 132 114 121 121 146 123 117 125 124 147 116 116 112 135 133 133 125 101 113 130 139 136 124 127 136 121 129 133 124 134 128 129 124 144 134 145 116 130 122 118 126 126 136 143 144 120 137 122 127 134 136 115 116 124 144 140 132 136 125 138 121 137 142 138 156 122 129 146 149 124 133 129 108 137 145 142 132 141 127 121 132 124 117 109 135 126 127 116 118 130 111 127 113 103 126 118 106 139 129 144 125 112 120 106 101 117 122 121 111 116 124 110 115 109 132 119 111 129 132 111 112 115 126 119 112 128 124 106 136 122 102 121 105 101 135 114 115 97 124 103 114 114 112 98 110 139 114 122 108 89 109 130 128 104 97 109 129 99 133 113 118 116 102 125 115 130 99 122 113 114 95 123 109 141 116 133 107 116 118 99 117 129 105 127 113 124 105 116 118 125 106 114 107 104 104 122 124 114 108 121 109 114 120 120 111 114 119 99 107 103 111 115 126 105 127 138 124 95 124 113 124 111 119 119 98 116 118 111 124 122 100 105 114 131 103 124 118 118 105 120 99 97 103 101 109 109 104 98 115 109 108 107 116 114 119 126 114 134 125 131 121 107 110 137 115 105 131 116 109 120 107 121 96 107 100 108 125 117 128 108 121 118 105 100 123 102 123 119 124 130 115 106 125 106 127 113 96 118 126 96 117 124 121 119 121 118 112 129 111 108 121 123 118 110 113 106 119 121 114 132 120 120 99 122 110 111 116 102 103 105 118 93 117 108 116 115 122 123 121 106 122 112 112 103 116 129 105 133 128 113 103 107 105 104 133 119 103 110 134 111 95 86 123 126 100 118 110 121 134 105 114 93 94 121 97 127 123 122 102 122 115 116 111 113 107 115 108 90 109 116 115 115 104 115 104 86 102 126 110 108 121 106 112 99 114 113 123 123 109 138 115 96 105 126 119 116 124 101 107 97 86 131 117 106 108 105 115 110 113 115 113 120 90 100 117 119 129 101 116 93 107 131 104 91 97 98 87 113 125 118 103 119 139 115 107 114 104 97 93 122 106 117 118 113 110 108 107 107 106 115 118 120 113 101 106 106 114 109 91 114 123 115 126 105 97 123 112 101 92 107 104 121 131 122 113 114 114 106 95 105 113 99 123 99 112 113 113 110 109 120 94 114 108 105 103 121 94 113 104 130 109 98 105 110 115 120 115 106 114 119 119 119 114 115 105 150 120 114 117 109 110 124 115 115 105 117 94 118 126 94 122 117 100 113 97 98 120 108 118 101 105 130 112 115 117 120 105 102 110 95 115 100 109 119 136 104 120 106 97 93 105 110 135 114 103 106 105 105 97 115 107 117 127 113 101 112 111 111 114 111 123 107 115 112 106 119 116 111 114 109 127 93 108 102 126 112 107 101 120 112 116 112 109 114 121 116 117 97 113 127 119 117 120 102 103 116 102 119 95 87 113 102 129 123 116 130 93 132 108 112 122 121 97 106 107 135 108 118 113 127 125 101 111 95 101 118 113 104 105 97 102 130 115 117 116 101 100 103 95 118 117 108 104 114 114 113 114 109 93 114 96 111 97 116 114 102 118 110 117 105 106 102 128 128 99 109 124 104 110 100 100 125 112 103 107 116 115 117 105 114 126 91 97 120 116 111 126 104 98 108 122 96 101 119 126 103 114 115 119 116 104 105 119 122 97 106 120 125 107 125 116 91 106 111 117 104 107 123 120 131 123 120 113 111 107 109 116 134 112 120 127 100 117 125 127 107 94 111 95 119 99 126 125 105 104 92 109 117 114 102 100 134 101 118 111 116 110 97 107 125 123 101 115 127 105 98 115 117 113 96 105 115 125 113 113 120 123 106 124 124 108 112 110 105 92 113 118 102 114 107 120 112 115 117 107 115 111 111 95 117 113 91 119 123 111 116 95 131 104 113 101 108 138 112 115 119 97 122 104 112 85 111 110 132 108 104 116 103 116 105 115 134 103 123 117 90 106 92 108 118 105 121 118 105 125 109 123 104 97 117 114 103 97 103 137 116 117 111 111 92 118 104 132 115 131 105 98 109 120 88 110 105 106 102 110 103 91 100 101 107 128 104 96 115 114 106 113 122 107 100 125 94 114 113 118 99 97 97 103 110 104 128 108 130 110 113 108 103 109 95 103 130 115 98 97 119 114 122 130 108 109 108 111 119 122 116 113 121 102 122 116 109 94 127 134 101 105 114 110 105 108 105 100 132 87 101 93 115 112 122 114 114 106 109 103 112 111 97 103 95 108 115 127 118 119 113 111 92 103 131 118 94 112 102 119 104 119 111 125 85 105 109 124 118 93 108 103 124 98 107 116 126 127 95 106 120 112 118 98 91 102 113 109 108 113 126 122 128 109 100 100 95 114 113 102 101 112 102 111 114 107 118 115 111 102 125 96 97 107 108 114 103 102 114 113 125 117 125 105 103 110 105 114 96 93 104 105 100 103 99 99 115 103 114 116 96 112 107 99 128 102 110 98 105 107 97 97 108 121 112 101 111 113 112 133 83 122 106 103 118 113 124 123 110 127 120 110 102 93 113 107 132 121 122 113 95 117 111 103 117 115 121 110 109 100 135 104 105 100 115 131 125 105 104 103 114 116 119 108 115 101 108 95 122 98 99 116 105 119 111 106 102 107 88 108 123 92 113 115 94 102 111 117 115 94 108 125 102 108 120 93 113 109 108 129 118 105 96 122 104 98 118 100 107 127 109 116 108 119 153 115 116 113 86 111 104 123 101 106 115 87 101 116 106 118 123 121 90 109 111 121 119 119 98 122 128 104 101 104 111 121 93 112 105 119 110 121 115 97 120 118 108 109 105 117 124 126 106 105 104 103 135 116 112 108 106 100 113 111 127 107 108 95 107 114 116 119 103 111 104 116 111 130 111 108 115 120 120 95 109 102 106 117 124 108 106 112 96 98 119 115 114 114 117 105 124 125 106 109 109 99 119 97 106 97 123 107 108 123 120 115 111 112 94 100 119 114 113 118 121 113 111 112 113 112 112 102 116 119 108 115 116 106 110 100 119 123 90 114 121 138 116 108 125 102 113 108 119 106 125 117 105 119 114 116 122 114 103 126 112 125 106 113 107 119 92 116 113 111 99 99 98 106 117 126 117 121 106 124 121 121 121 114 119 117 108 124 121 108 107 121 117 108 98 121 100 126 113 120 113 95 110 128 120 116 125 111 108 111 94 102 108 117 115 118 131 112 106 125 122 111 128 105 110 100 126 113 121 99 113 114 126 103 133 111 132 114 100 141 123 106 96 118 122 125 121 102 101 110 118 125 116 125 137 101 126 127 124 112 121 105 113 101 111 112 120 114 109 122 115 116 113 112 104 115 111 112 121 123 119 96 95 110 118 114 121 112 137 125 115 115 106 129 112 119 126 114 112 109 109 125 129 107 123 79 111 98 111 114 106 92 116 115 106 111 130 120 103 103 111 97 108 112 127 124 113 94 117 96 111 115 118 105 103 108 110 115 112 81 114 121 99 100 124 93 112 98 118 94 120 97 130 105 106 103 111 106 103 117 117 114 113 98 106 90 96 105 112 103 102 106 112 98 137 118 117 103 105 98 124 117 116 100 125 89 114 121 135 109 100 118 116 128 113 127 92 108 140 116 116 106 121 120 110 120 126 116 111 110 122 111 105 112 129 119 116 130 99 105 129 113 127 117 102 146 133 124 118 109 95 107 120 124 106 109 118 108 117 116 109 111 100 122 135 101 112 117 110 117 115 114 109 103 132 119 121 124 102 99 117 111 88 117 127 116 125 111 124 102 132 122 97 104 115 130 125 127 125 127 118 112 113 94 134 133 111 131 109 93 132 114 127 113 109 108 100 122 133 111 113 127 131 124 103 101 103 132 119 114 119 121 123 119 127 100 125 115 114 114 107 99 129 119 122 122 134 126 111 113 130 127 122 125 126 128 130 101 116 120 111 134 118 102 114 106 105 118 121 111 115 132 124 114 90 115 122 109 119 115 124 108 120 113 121 116 103 120 99 114 103 123 111 130 105 116 120 101 121 89 115 122 127 92 133 96 113 121 130 117 125 111 138 102 112 112 145 128 134 131 109 123 130 110 107 109 108 106 132 105 120 108 127 117 114 123 116 103 130 122 113 109 117 119 126 105 103 125 114 123 102 113 111 114 115 122 116 117 122 115 119 118 119 99 101 130 129 110 118 122 103 98 110 116 122 127 118 88 96 114 120 108 125 122 109 112 109 136 121 95 116 119 123 111 126 114 111 127 88 117 92 107 117 103 109 105 115 100 110 90 115 106 97 75 111 134 113 121 96 122 101 86 105 96 116 129 119 116 105 106 103 110 115 94 102 122 106 89 120 124 110 115 114 114 111 109 119 123 109 128 117 121 118 104 115 106 118 131 104 115 112 118 107 113 105 124 132 137 124 110 124 112 104 126 107 111 128 109 102 107 116 104 128 112 114 108 110 105 107 113 119 93 100 109 105 106 103 124 89 122 109 110 120 109 112 97 104 110 125 123 117 115 115 119 112 107 118 107 128 123 125 107 113 114 133 108 88 107 120 94 111 98 101 99 115 107 101 131 113 115 119 103 106 127 107 119 103 123 129 104 104 107 114 101 83 116 90 113 98 108 114 124 99 97 106 108 107 114 110 106 131 118 126 133 124 116 104 111 107 123 108 125 101 127 97 110 109 108 115 105 123 107 98 85 102 96 106 109 118 113 115 105 122 100 118 92 114 105 122 112 108 96 115 106 112 110 110 114 86 116 115 109 111 101 109 118 117 103 106 100 98 106 100 109 96 101 126 101 105 94 113 115 110 106 108 98 119 95 104 121 108 116 94 119 102 126 91 101 114 106 134 129 113 107 119 111 114 125 108 116 117 105 106 107 112 108 104 89 117 101 119 136 100 99 118 105 100 97 111 107 120 109 126 119 111 113 91 100 112 115 101 98 110 102 113 117 99 130 130 106 100 95 108 109 125 127 117 118 106 108 109 116 116 118 91 111 108 119 130 105 119 126 128 111 120 117 115 133 118 114 108 123 103 107 107 106 124 123 115 117 131 94 106 104 111 123 99 107 133 108 100 106 117 103 103 102 103 100 97 117 117 117 107 105 93 126 108 107 120 117 113 100 96 123 117 139 105 111 135 94 110 120 108 95 111 106 103 100 118 114 109 79 115 104 114 107 102 105 111 125 136 131 125 127 103 105 110 101 123 102 100 106 113 105 108 102 103 122 105 121 126 121 109 101 102 109 115 101 127 112 113 113 122 96 111 105 106 105 110 97 97 116 118 120 107 102 120 111 114 127 96 105 102 112 122 98 116 100 110 107 98 103 120 109 123 83 102 95 103 102 116 105 118 112 110 116 106 106 109 113 116 108 111 124 104 135 112 102 113 113 119 105 108 116 99 105 114 108 127 134 109 126 99 112 102 109 112 100 130 105 100 120 102 113 100 108 110 114 119 114 131 97 93 121 121 104 112 111 119 106 97 123 112 120 136 101 103 103 108 90 90 122 110 103 121 115 107 117 112 102 123 115 116 119 104 111 111 108 110 107 139 105 121 120 101 109 122 113 114 112 122 116 124 126 111 121 99 113 90 125 107 123 117 114 108 112 93 113 123 106 97 98 104 92 118 110 134 115 105 117 113 98 120 111 114 115 118 105 102 119 107 101 111 109 98 87 109 118 111 119 132 95 102 101 105 104 123 121 127 103 100 107 114 112 103 123 108 118 120 109 108 111 114 107 110 111 95 110 86 117 132 101 117 107 102 104 120 145 117 110 114 123 85 79 104 101 124 110 89 115 131 120 111 122 107 112 98 128 103 137 128 119 119 113 104 102 117 119 117 98 116 96 105 93 113 99 106 116 106 122 127 121 100 107 105 110 108 112 104 98 124 102 115 118 110 109 128 110 104 101 107 98 127 116 131 115 95 123 115 121 107 115 117 103 101 116 100 102 134 120 109 119 107 96 113 129 105 122 112 112 115 116 128 116 111 94 124 110 101 111 103 110 123 107 114 114 102 98 117 101 117 128 116 110 122 99 134 115 118 109 106 86 132 108 121 117 111 110 110 127 114 112 86 110 111 108 110 120 123 111 99 98 109 123 117 114 118 106 115 114 112 105 94 132 120 102 114 109 105 100 122 105 103 107 112 122 128 118 78 105 122 117 99 115 123 109 122 98 115 113 115 105 115 103 124 130 109 113 129 123 111 108 97 116 105 119 114 110 106 114 109 101 88 126 88 114 114 92 100 97 121 94 113 106 115 116 128 121 126 115 126 134 95 102 113 122 112 113 110 107 96 96 128 114 108 109 91 116 129 112 112 106 106 113 120 131 121 106 103 105 114 131 113 103 131 90 116 99 96 107 115 123 109 120 97 98 114 106 100 95 93 97 108 105 108 107 105 112 120 121 126 115 115 102 109 97 129 116 115 113 110 116 89 118 107 104 123 123 114 128 76 121 105 105 99 121 124 106 103 113 111 119 121 113 107 120 122 125 91 118 96 122 107 117 97 133 107 127 109 105 101 113 102 118 112 116 111 117 104 103 124 137 112 101 108 87 100 104 111 107 88 104 121 126 120 105 123 107 102 121 118 138 109 109 113 108 113 92 120 124 110 105 105 88 115 134 136 120 123 114 122 106 102 122 112 131 109 106 106 114 102 104 128 127 86 81 116 112 97 109 110 125 103 129 113 114 107 108 101 112 109 113 132 103 109 105 123 124 104 97 105 115 108 112 113 92 108 103 116 102 106 101 107 97 117 114 105 131 103 122 115 110 101 105 109 85 115 102 87 107 117 112 100 113 112 115 114 97 89 112 96 98 108 109 107 120 110 110 116 110 102 105 100 114 103 109 112 98 117 102 104 88 118 111 130 134 111 103 112 117 117 105 119 112 109 98 118 94 115 106 110 92 106 113 114 101 112 110 98 101 108 115 113 105 109 106 117 103 113 104 130 120 116 106 109 112 116 109 112 124 126 118 106 102 108 107 92 109 108 118 103 103 115 119 130 105 109 104 108 113 109 101 104 113 112 120 117 103 102 112 114 104 116 133 118 106 106 126 98 106 122 126 104 97 107 92 121 119 118 106 132 105 117 114 123 92 127 112 121 106 126 98 89 109 108 114 106 104 111 113 104 113 100 97 92 100 89 110 100 86 107 106 89 121 119 112 101 124 107 93 94 109 114 103 111 111 127 98 84 106 108 123 113 98 110 112 117 98 112 93 107 102 103 115 101 106 106 107 115 97 111 120 99 97 108 102 97 101 109 105 119 95 100 118 117 96 127 107 112 109 90 118 129 117 132 124 105 100 108 109 97 93 99 89 99 116 136 122 128 120 121 95 124 110 118 105 91 131 113 100 110 93 98 127 96 109 94 118 126 101 103 104 127 114 116 106 104 102 117 119 99 107 103 124 126 114 108 128 112 95 116 82 115 98 118 106 113 109 96 108 110 103 100 83 105 106 99 106 128 110 116 94 107 118 88 122 125 124 108 104 108 123 105 112 100 120 109 114 118 122 132 125 103 108 112 109 117 123 103 92 121 103 124 100 95 115 106 114 132 113 114 121 118 114 114 121 104 100 99 99 105 99 123 89 108 113 116 91 130 100 113 110 99 107 127 131 117 119 117 112 115 105 98 109 100 117 116 96 115 139 112 123 111 113 95 118 114 113 113 109 109 108 130 126 100 106 113 106 112 126 101 103 125 123 100 110 100 110 122 109 112 127 112 95 112 109 121 110 95 97 88 108 121 113 97 109 125 109 110 119 128 126 104 121 98 96 124 91 122 135 116 116 114 112 117 113 114 104 123 96 105 138 119 103 118 92 125 109 120 106 101 90 102 117 113 134 115 111 110 114 105 105 116 120 112 109 131 116 126 96 117 116 111 127 117 128 115 106 104 133 121 113 122 98 113 95 120 130 106 100 109 113 109 99 108 113 104 128 123 110 109 120 114 114 102 109 110 122 126 125 117 127 135 113 125 97 127 128 113 118 108 113 113 116 130 112 104 106 120 124 112 108 112 107 119 99 122 103 151 130 122 98 125 107 129 102 98 88 120 123 90 116 131 110 98 106 103 107 89 119 112 113 130 107 112 99 96 130 108 100 123 119 111 110 103 137 105 118 107 101 120 96 113 112 119 96 121 105 112 107 102 103 110 88 135 114 118 123 116 107 109 117 103 110 118 121 105 98 124 104 92 118 119 115 101 112 106 100 101 115 119 117 115 111 125 105 110 112 89 105 122 108 109 109 110 91 111 101 110 132 120 93 107 101 106 110 96 91 105 102 94 110 130 105 89 106 131 102 114 105 147 97 101 84 104 102 116 111 100 94 100 129 82 117 102 108 104 113 111 108 107 117 122 123 103 104 122 112 116 103 94 114 112 112 111 103 112 100 98 93 103 119 102 111 119 92 94 104 106 121 115 122 112 119 100 88 108 116 91 116 121 105 111 106 113 90 109 99 108 110 103 105 95 104 110 117 103 115 112 124 106 91 121 111 124 91 123 116 98 100 103 85 114 114 125 98 88 106 86 104 97 121 110 118 116 117 109 107 103 130 112 114 100 97 104 112 109 116 105 108 117 91 125 115 93 102 114 103 122 103 108 103 132 124 94 114 99 123 99 110 104 124 91 113 100 114 107 109 109 110 109 112 95 120 125 116 100 118 112 87 107 130 101 112 107 89 104 94 108 114 116 103 96 101 101 107 103 96 107 88 104 131 96 119 112 97 122 97 99 113 88 113 91 112 112 131 117 105 99 108 117 97 114 121 101 128 107 120 115 118 105 97 88 114 102 122 115 99 110 115 92 99 110 114 94 113 135 122 124 110 120 127 116 101 96 109 98 110 102 100 107 133 94 107 100 105 104 117 93 102 99 112 84 116 120 103 107 112 100 100 115 106 127 103 82 107 100 100 99 92 107 128 125 113 119 99 94 102 99 108 105 109 98 106 130 109 135 99 92 107 96 94 122 116 127 108 98 100 89 105 130 104 117 138 107 116 114 116 92 99 107 93 102 104 116 103 104 138 110 117 123 113 105 107 85 97 104 109 105 93 100 114 102 116 117 107 108 129 125 91 105 95 101 111 118 92 97 96 101 106 98 122 104 116 108 112 108 126 125 103 120 112 131 95 125 103 97 111 111 96 96 122 101 106 111 116 99 116 123 108 94 111 113 98 117 104 113 99 118 132 114 97 101 112 100 115 127 92 90 116 93 106 110 126 114 107 110 95 112 103 108 107 118 100 121 116 107 101 118 115 102 91 116 125 92 110 130 123 111 111 101 103 106 124 94 97 125 114 131 105 108 107 100 102 117 98 123 123 102 108 95 102 96 118 102 123 89 99 112 95 97 91 110 102 117 119 92 104 109 116 114 111 116 89 81 96 107 91 91 110 100 101 117 112 94 112 101 122 109 88 110 106 101 115 109 98 102 97 95 105 91 108 94 111 122 127 123 103 93 103 114 117 102 105 117 120 95 115 108 116 94 115 106 108 109 123 123 96 95 130 97 90 102 87 94 105 105 128 102 108 86 95 114 93 102 93 94 107 109 111 95 106 104 101 89 91 112 94 105 110 124 100 116 129 87 104 84 107 104 103 98 109 109 128 112 101 97 88 105 111 107 91 97 114 128 97 127 103 98 126 109 96 94 103 103 112 99 102 107 112 116 117 108 96 97 113 96 101 106 100 105 110 117 96 94 133 114 110 124 92 92 115 123 100 121 102 128 109 95 93 100 116 117 94 121 111 85 99 114 108 105 107 99 109 105 106 117 102 96 102 118 93 113 105 107 102 112 102 137 101 85 120 106 99 98 92 116 100 102 98 117 99 116 96 112 137 95 117 99 101 130 108 102 115 93 89 113 112 96 111 97 99 102 104 95 118 87 121 111 102 131 105 99 106 98 115 112 95 93 102 109 95 105 120 94 103 117 121 99 101 100 116 116 103 104 109 96 89 115 105 106 94 85 94 90 108 105 116 89 116 89 107 100 92 124 113 106 98 116 100 103 110 110 90 95 92 105 106 112 120 93 115 87 103 117 120 124 96 107 101 114 89 108 99 111 104 100 99 105 118 100 109 110 107 102 117 92 106 97 113 105 103 98 93 104 95 99 113 111 84 114 105 108 95 114 94 114 88 95 104 127 132 80 107 110 104 106 108 117 109 89 104 119 116 108 115 102 104 100 107 115 96 102 107 93 99 113 127 112 114 106 96 111 102 121 112 104 102 91 115 103 96 101 120 112 111 102 104 105 123 106 103 75 113 108 101 100 108 98 91 116 121 110 104 124 98 110 109 115 103 111 96 126 100 97 124 113 96 117 110 120 107 105 103 98 95 124 100 92 104 90 96 102 96 106 123 102 118 106 97 114 116 104 109 113 108 114 107 110 100 115 105 104 111 121 111 88 103 97 105 107 102 99 101 114 116 95 99 105 101 108 107 99 99 90 111 136 116 111 96 114 121 109 101 113 105 94 89 91 115 105 109 119 106 99 116 105 99 112 94 111 108 116 102 98 119 111 109 97 104 88 112 101 112 102 127 103 105 99 87 107 113 107 106 107 89 125 96 111 131 119 104 100 127 108 116 93 121 106 120 115 111 100 98 112 102 101 120 113 105 96 105 90 99 110 96 118 100 95 99 109 106 122 110 110 118 102 112 112 98 100 117 113 114 113 94 101 112 106 113 103 113 104 113 93 117 110 113 118 115 137 104 119 111 130 109 107 104 131 106 113 116 100 111 109 112 110 128 106 107 117 113 108 118 115 91 113 107 116 106 95 107 108 110 119 109 110 113 96 106 108 108 106 103 110 104 110 114 102 91 126 102 93 116 122 107 122 110 101 97 116 114 92 110 126 109 112 113 98 114 131 120 106 118 122 99 97 84 102 98 114 101 114 96 99 92 116 89 108 110 121 89 112 121 121 116 108 104 115 103 113 130 108 105 109 109 97 97 112 105 110 119 116 117 95 116 98 115 97 116 112 100 113 93 97 101 114 115 121 117 118 104 118 113 133 117 108 100 124 122 100 113 101 106 100 109 111 105 127 124 107 109 114 125 115 115 111 94 114 106 111 113 123 113 95 109 117 121 122 108 113 104 107 109 87 106 135 131 107</counts>
			</dataPoints>
		</scan>
	</xrdMeasurement>
</xrdMeasurements>