File: data/XRD/XG-Sauerstoff/XG-750/W6824-1B_XG_Sauerstoff_750.xrdml
<xrdMeasurements xmlns="http://www.xrdml.com/XRDMeasurement/2.1" xmlns:xsi="http://www.w3.org/2001/XMLSchema-instance" xsi:schemaLocation="http://www.xrdml.com/XRDMeasurement/2.1 http://www.xrdml.com/XRDMeasurement/2.1/XRDMeasurement.xsd" status="Completed">
	<comment>
		<entry>Configuration=Factory configuration, Owner=User-1, Creation date=7/8/2013 4:01:53 PM</entry>
		<entry>Goniometer=PW3050/65 (Theta/2Theta); Minimum step size 2Theta:0.0001; Minimum step size Omega:0.0001</entry>
		<entry>Sample stage=MRD Cradle; Minimum step size Phi:0.01; Minimum step size Chi:0.01; Minimum step size X:0.01; Minimum step size Y:0.01; Minimum step size Z:0.001</entry>
		<entry>Diffractometer system=XPERT-PRO</entry>
		<entry>Measurement program=C:\PANalytical\Data Collector\Programs\Jorrit\2thom\_absolute_2th-om_10-130deg_PIXscan_56min.xrdmp, Identifier={15BCCF57-2807-42BD-B5B9-ECC0B3DC9284}</entry>
		<entry>Batch program=C:\PANalytical\Data Collector\Programs\SimonL\batch4x_2thom_10-130°_z9.1_x0,10,20,30_y0_57min.xrdmp, Identifier={EED9823A-2BEB-424C-9252-345C4EF2834A}</entry>
	</comment>
	<sample type="To be analyzed">
		<id></id>
		<name></name>
		<preparedBy></preparedBy>
	</sample>
	<xrdMeasurement measurementType="Scan" status="Completed" sampleMode="Reflection">
		<comment>
			<entry>_absolute_2th-om_10-130deg_PIXscan_56min</entry>
			<entry>PHD Lower Level = 4.83 (keV), PHD Upper Level = 11.27 (keV)</entry>
		</comment>
		<usedWavelength intended="K-Alpha 1">
			<kAlpha1 unit="Angstrom">1.5405980</kAlpha1>
			<kAlpha2 unit="Angstrom">1.5444260</kAlpha2>
			<kBeta unit="Angstrom">1.3922500</kBeta>
			<ratioKAlpha2KAlpha1>0.5000</ratioKAlpha2KAlpha1>
		</usedWavelength>
		<incidentBeamPath>
			<radius unit="mm">320.00</radius>
			<xRayTube id="1010048" name="Empyrean Cu LFF HR (9430 033 7310x) DK442154">
				<tension unit="kV">40.0</tension>
				<current unit="mA">40.0</current>
				<anodeMaterial>Cu</anodeMaterial>
				<focus type="Line">
					<length unit="mm">12.0</length>
					<width unit="mm">0.4</width>
					<takeOffAngle unit="deg">4.2</takeOffAngle>
				</focus>
			</xRayTube>
			<xRayMirror id="27010001" name="Inc. Beam Cu W/Si (parabolic MRD)" hybrid="false">
				<crystal type="Graded" shape="Parabolic">W/Si</crystal>
				<acceptanceAngle unit="deg">0.800</acceptanceAngle>
				<length unit="mm">60.0</length>
			</xRayMirror>
			<sollerSlit id="21010002" name="Soller slits 0.04 rad.">
				<opening unit="rad">0.0400</opening>
			</sollerSlit>
			<mask id="22030007" name="Fixed mask 2 mm">
				<distanceToSample unit="mm">220.00</distanceToSample>
				<width unit="mm">2.00</width>
			</mask>
			<divergenceSlit id="22010007" name="Fixed slit 1/8°" xsi:type="fixedDivergenceSlitType">
				<distanceToSample unit="mm">220.00</distanceToSample>
				<height unit="mm">0.19</height>
			</divergenceSlit>
		</incidentBeamPath>
		<diffractedBeamPath>
			<radius unit="mm">320.00</radius>
			<sollerSlit id="21010002" name="Soller slits 0.04 rad.">
				<opening unit="rad">0.0400</opening>
			</sollerSlit>
			<receivingSlit id="22010001" name="Fixed slit 4°">
				<height unit="mm">5.88</height>
			</receivingSlit>
			<detector id="7010017" name="PIXcel3D 1x1 detector" xsi:type="areaDetectorType">
				<phd unit="%">
					<lowerLevel>30.0</lowerLevel>
					<upperLevel>70.0</upperLevel>
				</phd>
				<mode>Scanning</mode>
				<activeChannelsEquatorial>255</activeChannelsEquatorial>
				<activeChannelsAxial>255</activeChannelsAxial>
				<pitchEquatorial unit="mm">0.05500</pitchEquatorial>
				<pitchAxial unit="mm">0.05500</pitchAxial>
				<readOutPeriod unit="seconds">0.135</readOutPeriod>
			</detector>
		</diffractedBeamPath>
		<scan appendNumber="0" mode="Continuous" scanAxis="2Theta-Omega" status="Completed">
			<header>
				<startTimeStamp>2024-09-19T00:08:41+02:00</startTimeStamp>
				<endTimeStamp>2024-09-19T01:04:47+02:00</endTimeStamp>
				<author>
					<name>PRO-MRD</name>
				</author>
				<source>
					<applicationSoftware version="6.1b">Data Collector</applicationSoftware>
					<instrumentControlSoftware version="7.0E 20130304">XPERT-PRO</instrumentControlSoftware>
					<instrumentID>0000000011142674</instrumentID>
				</source>
			</header>
			<dataPoints>
				<positions axis="2Theta" unit="deg">
					<startPosition>9.99826193</startPosition>
					<endPosition>129.99755682</endPosition>
				</positions>
				<positions axis="Omega" unit="deg">
					<startPosition>4.99913096</startPosition>
					<endPosition>64.99877841</endPosition>
				</positions>
				<positions axis="Phi" unit="deg">
					<commonPosition>0.00</commonPosition>
				</positions>
				<positions axis="Chi" unit="deg">
					<commonPosition>0.00</commonPosition>
				</positions>
				<positions axis="X" unit="mm">
					<commonPosition>30.00</commonPosition>
				</positions>
				<positions axis="Y" unit="mm">
					<commonPosition>0.00</commonPosition>
				</positions>
				<positions axis="Z" unit="mm">
					<commonPosition>9.100</commonPosition>
				</positions>
				<commonCountingTime unit="seconds">32.895</commonCountingTime>
				<counts 198 205 236 205 194 226 204 205 198 208 216 218 180 215 188 211 195 216 208 188 191 208 204 198 235 221 184 218 211 195 197 190 219 206 218 198 255 231 189 205 209 188 221 195 213 214 213 192 214 229 207 214 200 216 207 195 194 212 196 194 215 230 198 195 202 223 213 196 214 203 210 197 194 218 203 219 223 187 188 206 194 187 192 190 198 191 206 193 205 185 201 209 198 211 207 179 215 202 173 203 190 199 200 211 192 195 168 195 203 191 211 226 181 180 200 194 201 230 209 228 183 173 195 192 203 192 194 194 203 211 212 209 192 203 206 220 209 198 192 199 198 193 215 193 200 235 224 185 211 173 223 203 181 188 203 219 200 201 173 217 199 210 182 184 201 203 203 216 209 195 194 192 192 191 203 219 191 167 187 187 189 213 203 201 197 207 191 192 215 226 180 161 176 184 188 190 176 200 188 207 196 179 201 193 178 194 203 186 180 195 212 178 203 197 181 162 184 186 165 199 190 185 169 204 189 199 179 186 206 177 204 170 156 185 187 171 174 207 191 191 209 199 195 219 206 185 192 190 195 186 169 164 216 184 179 173 199 164 189 193 182 190 182 187 189 162 164 176 207 183 196 188 179 194 179 151 185 194 184 192 200 203 175 174 195 174 170 171 198 168 180 205 188 172 215 171 178 190 184 171 192 191 199 174 161 164 198 189 191 183 171 171 175 167 188 168 174 197 181 170 201 179 169 168 179 178 175 194 196 173 186 172 178 172 180 173 183 187 166 178 181 177 195 193 164 195 168 224 163 190 154 169 189 151 171 185 182 170 167 174 154 200 140 170 188 175 168 170 175 149 204 168 181 171 163 181 180 192 167 187 165 167 159 191 163 171 175 166 173 164 190 154 173 171 173 170 188 182 187 184 178 179 170 157 166 176 183 184 213 170 192 147 184 186 180 189 167 168 173 194 166 176 168 170 173 163 169 156 177 162 155 169 164 181 167 157 163 160 166 197 155 167 151 172 192 155 152 191 170 173 133 167 173 184 180 165 167 192 155 157 160 161 179 141 158 163 165 144 186 175 187 166 183 161 151 156 185 160 179 181 157 177 150 167 154 161 168 164 162 165 168 180 197 160 163 153 163 154 156 186 157 180 165 142 165 184 159 171 170 145 184 151 160 166 167 164 157 162 166 183 177 165 160 151 162 146 134 159 152 174 161 150 158 176 156 171 162 156 151 162 156 164 167 177 159 161 182 153 183 173 169 168 158 177 157 158 171 180 159 164 150 176 172 158 146 150 134 133 151 143 149 152 155 168 148 141 152 148 156 152 149 173 142 148 172 184 160 142 154 145 173 167 164 184 169 155 141 142 165 190 173 169 130 139 158 151 133 125 182 166 147 150 140 163 142 155 167 146 150 141 165 151 158 173 152 166 166 169 154 178 139 155 141 169 163 140 171 159 175 143 149 165 186 166 162 176 132 148 156 136 162 147 145 153 144 153 157 149 168 161 134 155 170 145 150 177 140 138 165 161 149 174 152 158 159 152 179 167 156 190 158 139 135 167 167 156 169 165 165 164 186 145 148 155 155 144 176 165 131 169 145 133 161 178 140 161 149 179 155 164 149 144 145 186 150 149 145 156 132 169 190 152 137 130 153 136 162 168 139 146 172 136 170 162 149 158 165 153 150 152 163 144 142 166 143 173 149 151 152 171 151 136 145 163 146 147 163 128 153 149 171 163 147 160 150 153 174 180 162 169 154 165 175 163 157 139 166 155 157 151 153 194 143 160 156 175 162 146 160 170 146 181 163 160 136 156 161 155 158 181 175 133 174 179 162 164 168 157 156 151 147 167 181 154 164 148 151 151 151 138 141 152 183 172 141 128 143 175 174 135 138 187 148 175 172 142 169 169 176 155 161 165 177 153 163 178 143 146 153 145 153 147 145 158 144 173 165 152 180 157 149 165 159 148 129 171 154 171 164 150 162 148 161 160 161 142 151 147 153 173 149 171 137 160 152 147 171 174 168 184 142 165 165 185 135 147 143 161 149 163 173 156 148 161 174 141 158 166 156 161 182 149 156 176 157 178 159 152 171 149 180 175 162 148 165 179 156 162 158 154 167 143 167 172 172 171 157 157 159 135 156 177 196 158 149 172 166 160 182 163 165 169 168 178 158 168 166 166 148 146 141 168 146 157 174 145 154 161 167 143 146 153 151 178 166 166 167 158 159 174 171 164 176 157 169 160 169 165 184 161 148 183 165 157 171 161 170 156 159 150 194 150 175 153 159 148 149 177 153 150 175 167 174 154 163 140 178 176 182 158 166 173 176 167 176 141 185 192 163 165 163 176 156 159 177 141 175 157 168 164 156 158 158 167 168 162 182 176 166 160 174 168 169 168 168 150 166 173 165 159 178 147 152 168 156 158 162 172 161 162 136 174 171 164 161 159 151 156 163 165 203 184 196 168 187 173 182 151 146 176 146 158 195 162 163 154 172 168 164 164 144 167 200 170 183 160 148 158 173 188 191 155 187 199 174 151 166 171 173 180 171 176 164 161 201 173 165 198 159 172 185 184 191 172 174 174 181 173 177 175 163 169 174 186 178 155 161 179 174 169 174 180 183 174 174 189 172 165 176 147 185 170 159 153 152 175 171 197 177 166 175 170 157 184 172 191 173 170 162 187 182 170 166 161 164 156 170 175 160 186 186 180 168 162 167 180 169 162 154 159 176 140 179 177 188 164 154 172 190 182 181 170 156 160 172 171 159 176 177 164 171 156 166 176 192 174 183 160 165 174 192 156 160 191 190 195 168 171 189 156 163 163 194 146 138 172 157 149 144 191 174 170 162 188 169 206 174 178 172 171 181 142 175 192 168 166 190 173 178 179 168 198 184 171 178 165 166 161 179 186 167 152 187 172 178 159 174 185 158 174 158 173 160 140 178 172 171 168 144 170 173 198 174 196 173 150 175 178 164 191 173 197 164 170 183 167 146 156 204 153 180 187 191 171 165 178 174 169 163 186 184 158 189 185 158 167 171 174 170 193 155 161 171 190 182 189 153 164 195 192 135 164 179 186 167 152 162 186 184 170 146 179 152 166 180 180 188 177 172 154 185 163 172 145 176 164 181 189 170 167 171 183 179 168 153 170 144 136 165 163 180 175 156 195 174 183 159 169 169 182 180 166 146 200 186 179 189 171 168 172 167 173 163 162 168 189 164 179 187 163 176 184 142 156 139 158 176 168 154 170 180 173 161 181 174 167 184 169 163 187 161 186 193 171 165 171 167 155 147 154 177 196 178 176 196 177 163 176 144 181 162 163 185 166 159 163 171 177 159 178 173 163 142 167 143 158 162 191 152 145 163 158 158 173 166 169 163 158 151 174 158 172 168 160 177 164 170 161 166 171 174 169 177 149 163 159 160 157 155 163 174 152 170 136 161 161 164 145 182 159 167 157 142 156 143 155 170 173 161 140 170 177 158 171 169 141 166 166 147 142 147 183 141 158 168 170 166 158 146 159 163 163 166 159 170 177 158 166 171 145 166 160 149 176 170 166 159 166 168 166 132 144 160 161 165 149 197 163 172 152 147 163 146 141 154 142 153 163 142 159 163 162 175 124 162 149 164 169 167 149 136 158 165 151 190 176 135 178 139 149 167 127 139 147 118 153 166 138 172 157 175 156 169 157 155 139 172 166 137 169 124 152 156 128 149 165 134 154 155 131 150 157 139 153 148 139 155 151 134 139 156 137 140 139 147 140 151 169 152 136 129 153 154 136 140 157 144 161 140 172 161 176 134 126 160 129 156 148 161 135 152 135 173 163 143 128 154 182 141 157 146 152 167 126 145 134 151 129 150 155 172 168 149 148 147 151 139 143 155 170 131 130 129 157 133 138 163 171 160 138 146 163 157 148 144 150 164 148 132 153 174 154 149 140 150 132 148 159 159 166 172 130 119 154 159 137 154 137 139 147 140 149 147 124 141 147 145 139 144 140 144 125 126 140 127 136 160 155 139 121 136 150 142 136 143 156 133 138 131 160 136 161 147 143 149 151 145 134 150 140 136 142 125 136 144 142 146 141 118 147 154 149 140 158 143 126 133 136 148 133 124 146 130 147 156 157 140 130 142 125 143 137 140 130 139 164 143 127 149 137 139 116 153 150 156 130 134 118 146 139 144 142 134 137 136 132 143 154 133 149 140 143 123 145 125 141 140 148 119 116 139 110 137 158 141 146 143 151 155 152 132 124 136 137 127 141 134 140 149 131 133 146 139 141 131 136 152 132 146 169 133 136 123 133 145 126 138 145 150 149 128 133 152 153 125 124 142 140 118 153 138 125 136 124 146 131 127 118 131 157 136 128 147 132 125 134 157 140 122 113 134 153 110 136 117 139 128 132 122 131 134 128 146 134 153 134 130 130 112 138 125 144 142 112 136 124 128 121 112 142 141 140 122 150 126 133 107 133 137 160 151 142 124 140 125 138 147 139 130 122 124 119 137 138 145 139 129 146 143 141 117 133 127 130 156 144 108 131 136 123 120 134 148 136 133 146 118 124 133 137 139 128 125 139 107 139 123 137 121 139 105 129 150 130 124 142 138 152 107 129 122 133 155 134 112 129 150 116 111 137 114 130 123 144 126 118 135 141 121 139 140 114 132 127 110 123 114 140 126 130 129 117 133 124 115 116 125 118 107 126 131 120 130 142 131 133 134 144 120 120 110 120 128 125 118 139 143 115 124 114 127 117 133 131 136 129 128 128 115 121 127 145 123 121 116 123 117 144 122 138 109 124 119 131 118 144 120 141 111 130 120 121 137 117 119 123 119 147 124 122 138 107 111 127 111 121 96 131 137 138 122 109 118 143 110 113 119 143 111 115 141 137 142 146 120 127 111 128 110 137 107 142 121 129 114 130 121 117 121 108 107 124 108 123 140 134 123 122 117 133 105 120 116 114 119 122 115 145 118 136 126 133 127 147 128 106 131 117 126 133 118 112 120 138 123 122 112 111 102 112 121 116 124 115 116 119 121 129 110 128 144 140 132 113 129 113 126 133 103 123 120 107 136 133 117 111 104 123 143 124 115 126 124 125 140 108 123 134 118 107 113 103 123 126 104 117 117 99 123 127 99 123 107 136 131 131 136 118 129 105 127 131 120 127 105 119 130 123 128 151 105 109 113 123 126 114 136 109 130 148 102 111 125 124 120 114 121 130 126 106 116 118 133 103 102 112 108 113 123 97 121 102 128 125 106 104 116 127 119 133 137 113 119 127 119 116 98 145 113 117 123 131 129 115 112 104 124 137 121 120 120 109 130 113 123 107 123 102 137 121 113 111 116 126 110 108 99 110 113 113 124 137 107 94 131 120 132 124 136 128 115 117 127 129 110 128 106 99 116 118 136 120 114 128 127 128 108 131 117 123 118 106 136 122 122 110 135 108 100 103 116 135 107 120 109 120 126 120 118 117 133 126 114 112 95 113 112 116 137 115 109 107 115 116 116 115 126 126 129 119 112 98 122 106 118 131 106 113 117 120 106 114 128 108 115 145 115 99 120 115 123 137 106 118 119 129 120 117 100 129 96 111 122 117 136 112 125 99 112 132 121 111 124 103 130 120 104 134 129 139 118 106 115 129 121 117 135 130 127 113 124 114 134 102 97 106 105 114 137 124 130 86 121 129 123 109 115 115 98 125 110 109 129 122 120 119 114 144 126 108 117 117 120 114 118 113 120 147 125 113 126 96 127 124 120 97 118 100 99 92 111 132 115 110 101 122 109 130 111 101 98 118 117 107 129 133 103 134 121 117 125 115 118 110 123 115 123 109 108 112 97 95 127 102 139 88 122 115 119 117 117 124 116 132 117 122 122 119 117 109 112 105 104 116 115 123 122 97 109 122 106 112 81 132 116 113 101 113 129 124 125 118 101 106 122 117 123 120 124 111 117 129 118 107 111 145 124 125 132 121 94 102 102 124 119 110 118 106 116 116 127 114 136 121 120 109 103 116 96 132 127 105 114 132 107 106 120 122 136 120 129 125 103 107 117 116 107 125 112 111 122 108 117 105 134 107 112 115 112 106 128 126 122 109 102 119 108 106 95 119 123 130 106 121 102 114 113 123 110 126 107 112 129 118 109 117 119 121 103 128 124 99 137 119 114 122 126 141 125 98 138 108 113 121 133 126 120 145 132 122 124 120 109 136 136 121 120 143 134 122 130 127 111 140 144 109 116 138 133 138 129 131 129 133 125 139 109 125 119 117 97 122 146 106 110 120 120 133 121 128 109 125 100 121 88 114 126 116 95 111 122 113 135 101 118 109 94 116 143 129 104 124 126 112 109 100 108 119 119 124 104 111 120 104 101 127 125 89 114 104 90 120 112 116 124 101 106 118 117 120 126 107 106 99 119 113 112 126 101 104 105 109 116 118 116 93 110 101 118 132 107 120 112 98 104 109 123 100 105 121 129 115 96 99 106 113 107 116 121 117 112 89 118 126 120 134 105 124 125 109 106 98 100 121 114 114 112 110 120 123 104 112 102 108 114 126 120 112 103 111 115 110 114 119 123 106 117 114 103 111 91 117 124 106 113 100 131 122 127 130 128 121 124 103 88 123 117 111 111 114 124 107 100 94 120 141 112 120 108 129 128 126 96 107 138 100 113 114 109 116 127 120 110 124 107 128 115 101 126 111 121 114 123 107 126 109 114 116 125 105 96 108 99 130 127 111 106 98 95 118 128 101 108 117 121 117 111 115 96 126 117 119 121 118 105 104 129 119 108 110 120 110 110 90 144 117 106 118 98 98 130 128 115 111 107 104 111 110 111 106 112 121 113 109 118 122 116 130 118 114 110 119 109 119 116 131 108 118 119 109 116 120 126 105 113 122 116 108 119 111 104 124 102 108 110 109 121 114 96 115 107 113 111 113 120 123 114 125 131 120 119 120 104 124 119 112 122 109 95 124 107 121 112 96 109 88 110 114 114 106 118 109 107 111 115 123 112 113 112 106 118 102 123 111 118 118 105 85 107 134 120 108 105 115 107 110 99 109 91 124 141 127 119 116 121 119 108 117 112 115 104 98 115 99 125 99 120 117 103 117 101 109 119 97 119 107 98 113 122 113 110 113 127 100 110 118 108 126 116 120 128 112 115 105 136 126 116 107 107 110 103 98 127 125 112 122 119 115 140 115 103 100 121 112 130 123 99 96 131 115 111 126 115 96 114 114 120 99 112 103 113 103 143 122 125 117 114 111 106 109 93 111 130 107 90 105 117 123 133 117 111 117 108 117 101 113 123 127 109 102 114 127 129 114 122 116 113 108 134 85 112 127 124 108 124 125 101 116 101 112 97 110 125 118 122 120 120 110 111 114 128 114 128 117 108 129 98 109 124 126 110 122 108 104 125 120 121 120 108 129 118 108 121 137 113 118 150 119 108 112 106 138 104 115 113 106 106 146 132 122 111 121 127 117 127 110 149 119 117 135 125 136 101 113 125 107 123 144 107 143 122 108 118 114 123 133 129 136 116 122 94 113 110 119 114 117 113 116 104 122 120 125 116 105 126 120 127 130 115 111 105 119 115 121 129 114 120 114 107 124 108 117 126 120 108 131 130 117 139 92 159 134 104 124 109 131 113 129 114 113 111 117 108 119 137 113 130 132 132 129 110 124 107 109 116 135 114 116 123 128 111 131 130 114 114 131 115 119 123 127 116 116 118 122 138 127 129 112 133 124 124 127 132 116 133 123 131 119 124 117 119 115 115 117 130 124 136 152 125 124 135 117 102 115 128 129 134 131 125 131 135 127 132 132 116 141 136 131 145 143 129 148 140 148 135 138 161 147 169 130 172 148 169 152 149 152 166 178 156 187 166 186 177 175 220 211 186 213 195 227 210 191 215 231 216 220 184 229 227 241 216 204 223 196 213 177 186 200 187 181 161 173 164 168 169 164 159 158 152 175 133 144 155 138 149 120 150 144 140 154 135 136 132 119 146 141 131 110 147 129 118 130 122 125 124 129 128 128 121 135 136 140 125 108 123 105 143 131 127 140 131 98 123 111 94 103 117 104 135 114 130 153 103 124 125 116 116 129 128 135 107 117 128 134 122 116 96 111 132 110 132 99 119 133 107 113 119 134 126 131 110 137 103 115 124 121 112 139 124 120 118 126 106 111 124 120 100 115 123 103 120 134 121 114 120 130 113 109 113 110 126 119 106 133 109 124 118 98 115 125 120 117 108 114 126 111 109 102 112 116 118 127 122 120 118 137 106 97 115 123 109 126 114 124 109 103 102 106 104 128 100 112 130 121 122 101 115 122 120 120 124 134 107 121 132 131 119 112 130 117 120 114 129 104 111 120 111 97 109 113 117 137 108 116 144 109 135 116 125 125 106 119 137 124 116 120 114 117 117 131 121 114 118 125 110 114 95 120 119 132 123 123 116 127 113 105 130 115 106 119 108 127 96 116 123 131 123 134 101 117 98 116 121 94 127 116 111 135 110 112 119 115 119 128 123 112 110 116 117 133 118 130 106 108 112 114 130 119 137 115 115 107 125 117 114 150 112 116 103 115 122 117 121 96 105 117 127 116 118 112 120 112 119 113 116 93 120 120 122 118 104 107 129 138 119 117 113 124 131 118 112 115 132 110 97 109 122 128 127 117 111 129 103 128 114 116 122 106 120 113 116 146 118 130 114 122 113 114 127 114 104 132 111 113 119 121 115 110 100 121 101 137 143 107 112 108 103 117 125 121 116 132 126 138 119 123 120 123 102 112 120 123 121 109 127 93 124 134 138 118 111 133 108 111 108 104 108 136 112 142 114 121 123 119 102 123 124 112 110 101 116 125 125 111 125 120 120 121 105 117 140 106 115 125 126 120 104 104 104 116 130 100 142 148 123 108 113 140 98 106 118 133 113 97 114 113 129 130 102 120 117 120 127 111 108 124 109 100 121 121 108 111 118 119 123 122 133 116 115 128 119 120 110 108 115 131 123 132 107 118 116 112 117 138 147 116 118 132 110 124 99 109 115 110 90 117 109 119 107 115 138 103 117 118 107 143 116 121 113 126 132 128 115 112 111 104 138 120 115 110 109 115 133 115 138 101 105 139 114 139 125 100 95 139 130 102 123 115 121 129 125 129 122 123 103 127 120 116 107 104 124 131 122 120 110 105 124 111 123 124 94 125 124 129 116 117 124 117 118 112 124 104 130 117 110 120 126 131 95 111 113 125 101 115 111 115 107 110 125 113 121 125 112 130 121 112 112 114 113 115 115 102 115 121 99 112 118 120 101 130 133 108 128 112 111 124 112 112 106 106 122 103 119 127 99 107 132 109 113 118 110 120 122 133 123 105 115 125 137 140 126 107 109 125 115 105 143 114 106 107 98 102 120 115 122 112 124 124 137 115 118 124 101 134 137 136 132 116 99 129 117 113 110 121 114 106 129 108 88 110 109 133 128 127 112 138 116 110 114 124 128 135 127 126 107 131 132 101 114 125 125 134 122 131 141 109 122 115 95 136 132 137 124 124 103 100 103 114 118 112 98 116 102 111 110 118 112 113 104 102 123 115 120 102 134 117 122 134 119 107 113 111 122 126 134 121 115 116 122 121 114 116 108 92 114 125 134 134 119 117 115 121 125 113 130 115 109 118 132 114 132 114 124 100 128 113 106 103 127 125 114 114 114 126 131 113 113 118 136 116 130 107 144 136 123 125 120 124 122 128 116 107 120 119 102 107 128 111 135 122 133 126 103 118 119 119 149 109 123 142 113 106 96 98 101 108 114 137 96 127 105 126 116 111 111 110 134 111 110 94 108 127 121 114 98 114 123 137 126 103 120 97 101 120 148 117 135 119 120 105 125 120 139 126 124 122 119 115 126 133 118 132 99 129 109 130 115 102 126 126 120 124 122 112 123 118 99 101 121 134 115 112 120 118 103 121 121 122 127 126 119 110 115 106 114 121 112 102 110 117 104 125 100 127 120 129 108 103 110 116 115 111 119 102 124 116 109 107 120 109 126 102 105 121 115 111 117 120 123 114 115 121 128 120 102 115 114 137 130 121 116 115 112 121 103 119 109 122 116 91 113 124 112 128 128 117 128 110 147 120 117 109 125 119 136 131 109 130 117 108 126 131 121 134 127 117 130 114 96 131 95 126 119 126 137 134 122 115 113 122 132 115 118 128 108 112 109 118 109 99 100 140 110 125 125 115 118 98 117 117 102 114 121 127 117 117 108 111 126 132 116 115 123 118 121 117 117 129 132 122 130 113 118 117 114 129 102 119 98 139 137 120 127 103 120 107 121 107 119 111 115 127 113 116 93 143 117 120 112 118 110 137 88 134 121 105 104 128 103 119 112 125 117 119 100 120 123 104 100 96 117 104 116 113 102 116 119 109 116 117 118 115 120 114 117 134 118 116 108 126 137 126 106 121 112 117 129 133 154 117 122 119 122 119 115 97 137 101 101 128 103 122 139 135 98 120 122 117 105 110 124 98 136 99 130 114 126 127 111 125 122 126 117 119 129 104 116 102 130 122 113 109 121 129 132 119 116 112 122 113 110 113 121 122 147 123 113 109 120 120 130 113 102 128 136 107 103 120 138 120 134 123 104 112 110 114 116 106 126 127 114 134 114 106 123 106 101 110 115 124 107 114 120 139 141 124 109 106 109 119 136 137 88 125 106 115 125 116 139 95 110 116 122 106 135 121 124 104 125 121 126 116 126 116 132 118 135 99 121 112 109 122 107 114 115 90 123 100 141 116 111 119 140 144 117 144 111 106 130 116 112 140 119 110 120 112 132 118 116 115 123 114 113 97 128 110 115 117 105 115 117 115 126 125 102 126 122 146 114 126 123 115 118 117 123 129 117 134 114 121 96 119 116 122 95 106 100 108 115 110 108 127 123 123 117 125 135 113 122 133 99 130 115 133 115 121 144 114 104 124 119 118 117 114 119 116 137 120 120 131 121 127 104 132 113 134 133 130 114 122 122 118 97 135 117 125 111 116 115 113 122 126 131 104 108 114 114 115 119 124 123 104 116 114 119 118 134 116 102 125 117 105 122 122 104 95 126 135 116 107 120 130 110 117 162 109 123 109 125 119 118 111 118 102 116 147 136 130 103 119 137 126 131 120 123 130 123 132 121 102 119 148 125 129 125 125 125 116 128 113 122 118 119 115 113 125 118 132 122 142 124 121 124 156 130 122 124 129 107 107 128 106 122 149 114 120 120 109 128 115 125 116 117 100 134 141 111 124 116 122 127 114 121 105 100 130 117 132 132 122 133 130 110 147 96 130 126 132 114 108 129 105 142 121 116 104 109 106 124 110 118 112 113 110 115 133 132 109 108 108 127 120 123 122 116 114 125 123 111 120 129 108 122 134 120 137 114 123 126 105 136 137 117 100 125 112 137 116 107 135 115 128 106 136 119 117 108 120 128 113 121 115 129 113 129 126 110 134 151 139 118 110 143 128 116 119 122 137 111 132 136 119 114 109 98 121 131 119 137 133 96 133 96 129 130 125 118 135 127 127 114 120 119 117 117 108 128 136 127 125 107 130 124 111 126 112 133 117 114 140 131 134 116 126 140 139 119 114 121 111 108 119 121 127 97 120 124 133 133 109 121 120 126 119 118 139 133 130 110 126 116 146 120 103 119 111 102 111 115 116 100 119 125 123 115 137 137 113 122 127 90 117 118 112 133 120 133 123 111 115 137 140 124 133 111 100 124 129 114 116 125 121 108 126 103 121 116 135 148 118 135 130 138 117 125 122 134 104 110 128 140 116 127 110 136 122 134 131 128 129 100 115 121 107 118 130 116 120 122 133 141 111 113 122 120 116 121 129 132 140 128 124 131 151 134 134 137 115 122 118 133 129 128 131 133 119 139 135 107 133 111 128 119 118 121 127 128 117 126 99 131 124 115 120 115 111 112 131 127 130 143 132 138 112 108 133 117 123 117 122 124 127 124 118 130 112 116 123 122 134 128 133 125 137 122 109 119 157 129 135 120 124 138 121 119 116 131 95 139 128 116 128 123 130 132 127 118 131 120 135 124 112 141 131 138 118 108 125 127 120 115 128 124 114 131 121 120 125 138 138 111 135 143 115 111 111 129 125 128 120 128 128 150 108 128 130 125 115 134 151 131 121 127 133 115 127 128 116 131 123 138 115 132 131 104 137 116 139 139 130 137 128 127 119 129 114 114 138 122 112 131 132 137 128 150 124 140 135 131 103 132 128 130 122 130 136 118 125 136 109 111 136 128 134 105 123 124 111 87 118 109 121 122 105 115 116 100 126 130 113 126 126 113 132 126 122 120 119 122 137 135 123 128 127 110 133 113 133 118 126 110 118 117 113 124 140 111 104 136 129 114 148 136 108 130 143 134 125 116 112 138 118 130 116 120 123 109 130 141 140 127 131 134 118 141 135 111 114 125 124 104 141 143 119 134 136 121 121 128 135 134 132 138 135 151 135 112 130 123 119 158 154 125 137 156 128 143 125 122 132 119 140 132 140 145 130 134 134 150 123 141 154 135 148 132 125 130 128 136 126 145 135 122 121 111 133 128 124 141 127 112 132 140 135 131 164 129 124 160 140 123 128 127 131 131 160 138 127 129 127 148 130 137 136 142 144 126 136 118 137 125 131 125 134 111 112 133 136 147 136 126 137 142 116 127 128 136 120 106 126 129 135 133 149 140 123 147 135 150 137 129 118 118 145 101 128 125 132 120 122 149 114 132 121 139 130 130 154 140 118 120 147 131 125 123 137 134 115 127 130 137 128 140 135 138 103 123 143 139 136 130 128 110 113 127 130 142 130 119 125 148 135 133 126 133 136 154 120 122 142 141 136 121 131 136 137 134 109 131 136 129 125 112 120 115 120 130 120 119 120 140 129 116 115 134 105 130 149 130 114 138 121 124 143 138 117 98 126 148 129 140 132 132 138 133 134 116 120 85 129 129 150 113 121 130 132 130 126 132 133 126 142 118 112 123 129 122 141 132 123 141 132 116 130 116 138 140 132 153 111 138 138 159 117 135 141 105 133 138 135 121 129 152 135 118 128 127 140 122 144 125 126 154 132 113 149 111 140 136 132 102 126 114 134 134 107 137 113 130 127 124 142 116 108 138 127 138 133 127 106 116 134 130 149 132 123 132 124 108 130 107 133 108 119 162 113 127 100 119 116 122 124 117 118 124 128 126 129 135 123 117 132 133 149 129 120 120 120 139 131 137 99 128 125 121 140 128 131 137 109 141 118 107 138 115 130 104 127 112 139 133 135 119 123 116 132 126 135 131 117 129 137 95 118 108 130 132 132 136 130 116 118 127 138 138 121 136 137 122 94 135 120 131 149 117 154 134 103 135 121 137 111 113 123 128 125 120 136 141 133 129 124 111 116 136 129 109 152 140 134 131 114 126 131 144 134 135 130 128 131 119 125 122 97 132 116 105 133 109 125 123 146 118 133 125 114 130 132 129 121 116 148 125 102 157 129 119 123 116 132 144 133 133 117 116 115 110 106 119 130 134 113 128 135 109 115 115 122 130 106 143 143 147 148 168 123 132 126 125 137 114 120 135 121 143 113 122 128 133 119 137 144 125 126 126 125 98 134 134 141 138 112 117 129 127 108 138 135 111 129 119 134 118 133 136 108 123 116 137 129 134 132 117 124 122 128 137 146 133 142 140 133 134 134 111 115 125 133 129 136 127 134 136 138 139 128 99 134 133 124 119 135 131 128 115 116 123 117 116 120 127 126 109 144 131 123 122 118 110 128 119 131 117 127 140 117 126 109 116 117 139 122 127 133 117 130 121 118 133 118 117 125 108 111 136 107 147 121 118 112 139 117 153 139 119 117 132 116 147 129 124 136 114 103 135 140 122 135 143 136 139 125 127 109 124 133 130 136 120 128 128 123 122 117 137 133 127 133 136 134 97 119 144 115 117 121 112 127 133 132 114 120 135 121 120 139 128 137 133 126 126 138 137 114 119 120 114 114 133 119 142 113 133 128 104 133 118 121 117 111 145 119 128 121 121 121 137 151 130 133 141 126 134 130 137 110 145 147 133 118 128 133 155 141 158 125 114 118 140 132 134 128 120 115 122 124 136 110 120 122 123 152 116 119 132 133 112 131 132 122 125 125 131 127 134 155 129 115 136 130 134 110 93 133 119 109 136 108 120 141 119 131 120 141 148 118 130 122 141 140 115 113 120 149 97 127 128 133 119 131 137 145 127 119 130 131 116 111 136 128 121 147 142 107 144 143 130 123 121 145 135 135 131 153 144 146 111 127 132 126 131 136 119 125 138 120 108 111 127 131 144 139 123 104 111 121 119 100 116 127 124 115 119 136 133 132 123 128 130 112 133 111 138 138 157 127 119 136 130 134 122 114 117 127 125 124 128 121 131 124 136 143 137 110 129 143 135 121 127 135 132 132 127 143 152 142 141 123 133 137 118 155 120 126 116 119 131 136 124 110 128 154 130 116 138 140 118 149 137 146 125 126 125 126 115 132 130 134 143 121 148 131 138 125 135 114 125 143 98 123 128 134 131 138 131 139 138 134 125 118 131 125 120 151 107 134 125 140 124 109 126 115 135 129 147 119 130 124 127 139 118 143 126 118 119 123 138 149 121 131 108 140 159 129 126 130 131 106 124 122 117 143 119 130 138 128 152 136 113 139 135 133 141 130 135 139 127 110 104 123 144 124 140 129 119 128 156 132 134 155 124 139 137 119 116 117 142 134 123 127 115 145 134 138 136 120 125 119 117 117 120 110 135 131 154 114 134 136 122 131 113 124 111 119 121 112 91 167 114 144 129 144 116 132 117 132 138 120 119 147 112 120 131 122 140 124 121 123 121 154 134 130 130 117 132 137 144 122 139 115 134 119 121 133 136 122 124 134 145 121 119 121 120 130 123 125 117 127 135 117 141 123 100 127 119 142 117 138 131 116 141 128 108 119 142 113 109 142 107 133 126 131 128 129 119 136 154 140 145 137 121 135 132 128 126 123 154 125 132 119 123 126 132 137 117 105 103 142 137 112 124 135 156 127 116 124 115 128 124 138 140 137 123 135 124 145 132 138 149 140 116 125 133 126 117 124 130 120 116 142 120 127 129 140 123 123 131 123 131 125 123 129 127 125 140 127 123 126 130 131 142 139 121 143 133 138 122 120 108 105 131 123 132 139 134 121 112 149 131 132 118 121 129 137 130 130 144 116 135 121 111 137 116 139 116 142 117 141 112 143 126 134 124 130 111 128 121 131 152 138 114 111 128 144 135 141 136 128 125 128 117 138 112 136 117 124 125 142 105 125 122 130 123 143 130 141 129 147 128 127 113 119 132 128 127 125 125 146 132 128 134 129 135 122 140 131 93 110 112 149 134 124 137 117 134 123 133 139 132 117 136 133 115 128 144 146 134 105 122 123 123 124 125 127 130 113 134 133 140 138 128 109 103 137 114 125 127 116 106 115 114 133 135 138 141 135 139 115 150 136 124 130 130 127 117 114 135 132 133 129 124 112 138 126 117 130 146 144 132 120 122 114 132 123 140 143 118 127 134 125 133 125 111 120 105 149 129 128 122 135 111 132 113 128 114 138 119 147 111 129 133 142 140 151 144 107 125 130 131 136 148 134 134 110 127 152 134 127 130 124 135 125 143 130 118 128 111 140 147 115 139 119 135 143 129 110 115 117 125 126 126 140 117 125 126 118 128 125 121 130 128 145 131 148 122 122 125 136 120 123 138 134 139 147 134 102 128 158 121 126 131 135 138 144 148 125 136 113 133 132 134 112 145 125 127 119 122 138 127 119 125 126 120 128 129 137 114 122 125 128 120 111 125 135 135 120 130 110 127 137 154 119 123 135 132 128 120 155 127 127 139 128 128 117 121 141 143 124 123 137 131 109 118 102 124 126 145 141 109 128 129 135 139 124 118 116 131 130 119 129 111 131 132 127 119 129 145 117 126 119 122 121 151 131 111 125 132 154 121 130 123 116 106 115 138 132 138 130 117 134 107 127 122 139 120 130 128 122 133 133 149 121 136 151 119 116 133 131 111 119 123 129 123 123 135 130 121 125 137 114 131 147 118 133 149 116 126 132 109 150 132 136 143 132 131 123 117 141 133 123 121 136 153 138 130 120 123 142 112 123 131 134 139 126 125 124 109 116 152 132 139 125 122 140 127 128 121 112 133 117 153 149 127 140 121 109 131 110 124 116 119 135 140 144 132 148 109 131 128 104 113 133 129 118 128 151 111 105 132 130 131 136 137 113 105 104 141 117 135 121 124 103 124 136 134 127 131 120 134 120 116 127 145 125 142 115 125 126 136 102 145 123 147 116 125 122 128 122 128 139 117 138 145 120 134 126 126 137 132 124 133 116 124 112 138 140 133 149 137 122 127 132 146 143 143 127 142 121 139 114 110 132 135 113 136 122 136 107 133 132 135 134 133 130 113 104 138 148 126 139 123 154 116 141 135 143 144 115 136 128 139 121 135 145 148 137 128 147 132 135 131 140 129 156 130 126 159 143 121 168 130 116 161 168 148 123 145 135 149 120 151 128 146 150 137 146 150 168 161 153 158 160 136 144 131 159 145 146 120 158 135 120 148 135 143 146 146 136 143 123 171 144 131 133 156 141 144 122 149 156 119 120 135 143 129 125 144 120 146 146 136 129 133 156 124 140 113 136 135 140 119 155 129 145 131 139 130 139 122 136 140 134 124 133 143 137 123 128 131 126 119 113 127 115 120 118 139 129 126 123 129 120 136 128 143 118 112 130 135 125 133 154 135 129 142 111 136 121 134 124 116 121 136 158 114 121 134 151 125 153 114 113 131 117 153 118 130 124 117 128 121 104 116 129 109 128 105 142 118 141 148 113 135 127 139 115 113 137 143 122 111 111 121 138 131 109 117 146 134 151 141 124 136 119 117 120 129 125 135 124 125 121 129 134 139 113 126 144 125 138 131 104 132 111 136 125 125 103 140 137 135 119 116 129 138 144 120 130 109 149 110 126 110 130 126 119 132 136 129 141 128 133 117 135 114 137 121 112 116 113 118 109 109 103 121 116 162 128 119 106 130 129 139 144 126 139 121 115 113 112 128 120 120 111 134 134 122 139 115 119 130 131 132 126 128 139 124 139 136 116 119 134 112 123 131 142 146 113 135 141 104 127 114 111 119 111 107 126 131 139 113 128 142 112 119 130 115 133 117 141 134 123 138 114 121 103 115 132 119 120 122 112 108 128 118 133 122 122 129 140 138 124 124 122 120 120 139 123 110 125 125 127 131 130 142 123 128 139 123 113 134 126 115 119 125 116 133 127 119 120 135 133 139 137 116 115 99 126 119 124 121 133 118 137 126 124 135 122 115 124 107 109 119 97 99 138 116 126 161 131 131 131 119 138 136 126 111 145 112 104 118 130 113 121 117 122 133 120 109 110 106 117 119 119 108 113 132 124 125 122 123 136 116 125 124 142 133 119 134 123 134 130 134 147 100 142 126 144 128 128 115 134 119 118 122 105 141 129 129 110 120 103 119 151 138 99 118 137 150 132 134 124 121 134 136 130 153 145 126 127 138 123 128 123 123 138 143 136 110 128 115 118 129 127 107 126 118 124 128 118 125 113 138 132 128 144 147 142 136 129 142 157 114 133 122 118 118 146 143 112 116 131 110 114 136 146 127 137 123 133 140 116 126 122 131 127 137 146 132 120 147 146 136 126 127 130 151 122 134 108 150 119 116 134 140 125 147 125 126 121 130 124 124 119 132 141 118 123 146 138 134 118 119 123 134 132 128 128 135 108 107 122 119 142 127 122 136 115 139 126 112 118 120 124 137 129 133 141 132 126 118 127 122 117 133 123 134 132 167 118 120 125 142 133 107 151 124 137 116 100 115 138 132 140 121 120 122 136 132 123 128 116 138 138 117 132 132 123 122 134 116 128 122 126 134 138 131 128 125 112 142 132 118 116 125 108 117 127 148 133 133 126 117 118 120 132 128 134 119 135 122 122 152 115 160 134 122 132 103 122 122 141 128 114 129 114 134 121 140 121 138 131 127 126 151 138 121 128 128 121 129 139 129 158 112 133 137 131 122 134 106 132 140 132 122 116 150 125 123 138 137 125 125 126 119 116 122 146 131 134 143 129 130 122 134 123 125 128 118 137 118 133 141 129 116 106 134 111 101 137 122 144 119 138 127 109 126 113 125 132 132 121 126 111 126 148 133 120 134 104 126 116 109 128 123 130 110 140 141 117 117 135 128 117 145 120 117 133 104 143 135 136 111 134 142 128 116 126 131 144 108 92 116 141 120 132 128 114 141 94 122 114 122 143 124 133 108 117 129 116 132 133 113 121 133 122 118 136 135 137 144 138 115 134 146 133 107 142 126 135 132 113 115 145 133 148 112 126 130 127 132 115 133 133 123 122 125 103 115 136 121 118 134 140 140 118 134 139 132 115 144 121 109 135 133 138 122 119 131 132 115 124 152 108 112 107 133 115 131 122 126 131 124 114 130 110 130 124 146 117 125 110 128 123 131 147 140 121 115 117 121 134 138 134 128 142 134 110 120 145 123 118 132 129 114 124 107 113 114 145 134 108 143 136 95 128 118 124 129 126 107 131 125 140 122 127 121 126 141 132 117 143 109 137 128 109 110 153 119 143 128 121 150 135 133 132 129 112 111 138 120 125 128 113 123 137 105 129 125 118 130 119 140 138 126 137 131 138 126 112 125 132 116 131 135 119 122 130 134 155 121 118 142 137 118 121 136 123 127 130 138 124 112 118 135 105 126 128 122 119 127 121 119 121 129 111 126 123 118 134 136 118 121 103 148 122 138 122 136 132 135 144 141 116 120 131 141 128 89 113 100 118 136 122 148 129 125 118 121 111 134 131 128 118 120 120 120 121 122 117 117 120 147 155 139 144 133 122 105 133 146 117 138 125 113 115 132 121 129 121 141 115 144 129 130 122 107 137 124 136 121 139 122 140 126 132 147 111 133 137 142 133 124 145 121 130 137 120 117 138 120 106 134 123 130 132 111 120 141 112 142 125 120 133 137 144 128 141 124 136 131 120 115 119 124 106 105 150 112 117 119 139 119 148 139 124 137 144 119 102 134 134 112 124 125 111 129 131 132 130 132 105 122 128 129 127 106 123 111 132 134 133 124 106 126 128 129 134 127 130 119 129 134 118 136 125 120 126 112 130 135 120 117 127 127 129 114 113 120 134 139 140 125 111 127 144 142 127 132 126 143 126 138 132 108 143 117 116 126 115 129 136 115 129 140 127 134 113 117 121 112 125 123 140 128 111 135 128 128 127 121 111 138 137 104 127 101 132 128 130 135 122 108 133 142 123 130 132 122 116 125 137 136 112 112 125 131 119 131 125 144 133 127 129 128 129 129 132 127 146 132 114 142 131 130 124 126 140 140 104 111 122 129 136 114 121 144 132 137 124 139 114 117 142 112 117 123 114 116 93 123 151 134 120 134 137 116 139 154 126 148 116 106 117 121 119 152 147 118 126 131 133 123 118 121 145 118 116 138 133 117 134 138 136 128 119 140 118 123 119 120 119 127 117 140 125 120 114 157 116 121 126 142 115 143 127 124 126 141 137 131 139 122 120 124 120 130 128 130 122 137 131 140 111 138 129 136 132 104 134 123 132 108 99 129 119 125 121 150 107 106 134 138 125 124 139 123 150 152 132 118 121 121 121 132 131 131 117 124 123 104 118 118 121 129 127 132 120 131 118 133 137 129 106 130 102 105 117 113 128 127 131 123 127 119 108 136 127 138 110 123 134 124 121 121 117 121 145 137 135 117 108 114 115 131 128 121 101 137 142 133 113 139 119 103 122 138 129 122 136 155 119 111 132 130 124 130 144 124 117 112 134 128 127 123 131 146 136 144 125 115 113 113 120 131 132 136 110 127 125 129 129 143 136 129 127 132 120 107 124 109 104 127 146 114 118 135 117 124 128 113 118 127 140 123 113 134 105 157 117 127 118 116 128 142 137 120 120 136 116 122 119 120 131 119 127 97 134 111 130 120 129 130 122 104 143 125 135 116 154 137 122 130 131 119 122 122 131 127 121 123 115 162 124 136 122 139 132 143 131 116 118 137 119 135 144 129 115 121 123 121 111 116 117 133 120 142 120 116 133 122 130 108 132 128 131 104 111 124 127 109 136 132 119 95 145 113 126 122 105 125 103 135 115 129 138 118 134 144 121 122 112 137 151 124 142 115 127 142 134 129 136 121 132 112 116 131 123 138 116 111 136 129 128 135 119 141 117 117 143 114 131 128 133 125 146 133 138 139 111 122 132 142 134 116 125 145 133 136 116 134 136 134 143 121 131 129 142 126 143 144 150 112 147 124 136 142 128 126 129 124 131 131 113 137 131 120 126 112 145 137 130 131 129 142 130 122 112 143 149 130 129 134 137 134 112 140 141 136 150 138 145 134 126 137 152 152 127 130 119 125 135 131 150 114 126 134 120 151 130 113 133 117 115 125 100 112 159 139 134 125 123 126 143 134 105 141 127 145 111 116 134 128 119 113 132 126 120 136 128 121 129 119 118 122 124 144 135 135 120 137 122 138 136 118 137 136 137 120 121 121 133 126 114 126 147 109 138 125 152 124 124 118 131 140 128 122 122 107 121 136 112 144 109 139 137 140 127 113 113 119 111 126 128 120 127 130 122 125 119 115 120 138 122 146 136 138 136 114 110 112 133 124 115 108 132 119 126 145 104 140 129 127 150 120 120 114 134 122 140 146 133 134 128 120 145 127 114 143 145 108 116 129 122 126 113 129 127 134 113 110 113 135 122 118 137 123 123 142 120 132 113 124 130 122 140 130 125 139 132 142 106 129 123 116 128 124 116 140 118 127 126 122 130 135 125 131 136 144 131 138 143 125 129 139 127 162 117 130 111 138 144 137 143 116 131 110 124 120 127 133 126 143 110 129 122 116 133 122 110 129 120 132 126 120 125 137 116 135 119 116 114 135 122 110 139 138 112 117 119 131 127 142 114 116 135 145 149 131 123 130 117 136 125 154 119 127 128 134 114 136 120 149 120 102 133 134 114 137 113 132 120 141 115 127 129 104 126 112 118 140 131 141 132 130 116 114 120 111 133 130 124 137 120 119 139 112 114 115 144 123 127 142 121 141 133 130 137 139 117 126 123 134 130 135 144 146 142 137 128 118 131 128 136 135 136 110 129 140 153 139 111 118 132 146 111 103 131 127 111 130 128 126 130 128 127 125 127 120 118 115 112 127 128 128 126 131 130 133 155 129 121 128 120 124 128 136 132 118 110 143 118 115 113 116 130 120 128 131 140 134 116 139 136 133 115 128 132 133 133 116 137 118 124 121 137 145 127 131 112 140 119 122 116 124 132 131 138 141 119 123 117 135 115 121 148 111 133 125 128 126 138 127 122 126 116 126 151 129 135 123 128 116 131 123 126 123 123 126 131 116 152 138 128 139 125 134 112 144 137 146 104 122 158 126 110 123 138 128 153 122 148 127 145 138 127 101 134 121 128 126 139 146 138 113 116 138 128 138 109 122 120 142 141 118 121 98 123 138 129 108 128 128 139 131 136 131 146 132 116 144 126 116 118 128 132 133 136 125 125 108 128 115 129 131 135 93 125 115 140 124 119 133 125 131 129 132 118 121 137 150 121 136 126 142 131 124 126 142 122 132 128 120 116 131 116 128 134 111 148 136 133 117 119 126 135 135 144 130 135 119 129 134 141 138 138 121 146 130 144 125 122 117 128 145 107 134 144 143 141 122 124 135 131 119 141 122 128 113 132 124 133 138 109 105 142 142 147 116 141 114 116 132 137 121 120 152 125 140 153 141 126 134 124 120 137 132 112 131 145 142 132 126 123 119 133 120 130 126 118 120 114 120 127 145 139 132 112 130 135 117 158 118 139 131 141 136 135 116 110 133 111 124 105 127 120 123 142 116 143 129 126 139 147 150 125 111 124 108 142 151 123 116 151 127 126 124 119 144 123 139 123 120 136 140 138 135 123 136 117 142 147 125 130 112 124 130 95 121 145 122 126 132 138 121 118 136 111 140 116 115 142 136 133 133 119 142 126 143 141 114 118 135 122 111 132 138 123 123 126 135 117 116 127 118 120 138 146 118 132 119 119 114 114 134 142 130 123 113 116 127 124 117 134 130 138 127 122 137 115 127 128 131 115 119 148 117 138 128 123 115 126 131 118 141 122 133 128 111 101 140 130 131 139 122 120 116 127 112 131 133 143 138 119 140 143 123 126 121 137 136 128 108 131 142 125 126 131 146 128 128 125 101 124 149 119 107 127 122 146 134 113 121 113 123 129 135 116 123 143 125 139 112 123 123 135 127 161 128 139 102 126 113 132 137 141 125 124 143 150 134 143 149 134 101 128 120 118 132 133 144 115 101 140 114 110 114 133 119 130 134 116 116 120 128 132 129 109 105 122 125 124 146 137 122 131 133 118 128 140 114 154 125 115 116 130 134 131 136 129 130 136 150 107 133 122 132 126 132 118 130 142 152 128 133 132 143 106 124 125 117 115 134 132 122 141 133 136 123 126 124 133 124 125 108 129 134 117 122 117 139 141 129 129 132 138 126 139 145 129 146 123 100 128 123 123 120 122 116 141 130 116 126 111 140 131 128 111 129 135 112 138 127 124 139 142 117 133 139 126 139 140 119 123 109 128 128 129 123 126 131 130 112 117 127 126 140 126 135 138 123 153 126 132 132 137 135 129 116 135 127 131 125 131 120 141 117 135 136 140 111 122 138 126 133 138 133 137 134 135 122 121 137 110 118 126 121 126 116 139 136 114 144 125 119 130 114 144 130 103 124 122 113 126 136 130 125 139 117 136 127 135 148 122 128 112 130 168 128 119 143 136 143 144 124 132 127 126 118 144 122 107 156 115 153 136 143 126 115 136 141 116 130 148 149 118 150 136 127 140 118 140 120 138 130 136 116 120 146 132 137 130 155 125 121 121 130 130 119 139 142 107 133 116 149 118 127 122 118 133 123 142 137 130 123 114 134 132 124 124 120 133 141 135 127 126 139 125 151 137 112 133 136 113 141 121 136 144 132 137 116 141 149 102 126 132 129 119 136 122 129 119 116 128 129 119 131 131 139 120 122 121 141 137 140 131 130 139 109 117 119 125 113 130 128 140 105 133 123 123 122 133 104 131 115 117 120 145 136 142 118 121 125 110 115 144 128 138 125 137 135 146 130 123 137 139 137 127 125 110 129 112 136 138 133 136 117 156 116 148 132 111 125 132 116 143 117 131 145 116 129 126 134 124 117 134 130 136 127 138 129 117 142 130 127 102 117 131 139 127 125 128 131 117 123 111 129 109 123 133 134 145 146 112 112 133 128 136 124 139 119 119 137 132 105 124 123 132 121 134 130 132 132 127 118 130 126 134 149 109 119 108 105 124 111 146 132 135 115 119 121 135 127 126 146 137 138 134 155 139 128 106 128 121 133 135 121 116 124 116 148 129 124 131 128 116 134 121 126 137 125 149 143 120 100 129 123 129 144 126 117 116 119 118 128 141 140 118 127 116 120 158 117 124 114 130 132 121 111 123 145 132 130 138 130 133 116 120 128 131 115 132 128 132 119 144 117 145 128 132 131 108 128 136 103 109 137 145 121 137 102 118 116 131 143 124 133 120 133 137 144 128 151 125 143 127 135 115 132 112 133 127 128 133 116 128 142 144 135 124 109 112 133 129 141 144 121 109 137 143 101 143 107 118 131 105 130 117 119 148 117 124 114 130 126 134 139 141 140 136 143 125 125 132 118 147 115 132 131 136 135 133 125 120 121 102 138 148 119 138 133 111 125 121 134 121 130 139 112 128 143 144 109 136 144 141 122 124 113 142 119 122 135 133 150 118 127 142 115 114 121 139 136 133 129 143 164 133 118 134 134 113 135 118 134 128 144 121 137 137 136 133 125 141 137 132 112 124 133 129 119 119 130 129 118 131 122 118 136 132 132 127 120 128 142 133 122 123 137 123 135 125 129 147 137 112 135 115 132 131 122 146 133 134 145 134 130 141 129 122 150 148 144 146 123 125 116 128 135 141 154 135 136 134 131 152 114 114 130 131 118 146 134 132 126 143 150 104 134 131 119 124 139 109 132 138 141 122 130 126 129 138 159 134 125 144 131 146 119 140 146 127 133 131 116 133 129 134 124 153 119 147 114 122 126 146 131 134 136 126 132 114 114 114 127 131 132 129 116 110 145 147 123 124 139 140 135 137 109 131 141 117 132 119 145 129 123 129 144 128 118 127 108 145 151 125 121 141 144 143 136 139 120 121 136 133 140 143 141 152 128 137 119 139 119 122 139 110 114 147 126 121 128 124 136 132 143 105 143 158 110 129 116 121 122 130 148 135 139 132 138 137 121 129 146 107 129 142 144 147 130 141 142 128 130 122 125 142 143 146 142 119 130 126 126 151 127 131 117 132 122 141 125 147 139 151 129 139 119 144 147 120 130 147 144 139 114 120 154 141 139 129 131 147 123 139 138 127 131 120 123 134 118 127 121 147 148 143 142 123 120 137 135 142 124 129 124 141 140 119 146 139 126 139 126 127 146 146 125 141 120 134 108 135 137 131 129 126 128 126 132 117 108 129 115 121 98 134 140 139 124 131 135 135 122 117 145 119 130 139 127 130 123 120 120 138 128 116 144 150 123 121 127 119 139 128 107 114 116 122 118 128 147 105 139 122 146 121 121 136 124 118 132 118 137 134 139 127 138 117 125 158 144 126 135 127 145 151 125 131 125 117 122 137 137 126 150 124 139 114 134 113 140 119 120 137 121 136 107 151 124 144 139 125 137 145 132 123 114 126 123 122 126 136 133 126 118 119 134 129 116 140 115 132 106 139 136 118 129 141 143 162 139 125 139 128 141 112 128 128 132 149 139 156 141 127 146 112 115 133 136 112 125 107 121 141 118 127 119 135 103 138 123 137 142 101 112 121 121 130 131 132 135 131 131 119 119 130 136 127 128 137 114 118 115 112 124 123 119 130 124 117 109 139 124 125 140 125 118 121 128 138 125 158 133 109 123 124 140 123 139 108 131 115 102 126 125 125 117 113 137 124 136 128 131 140 140 123 126 135 118 147 140 124 122 131 132 107 135 126 124 122 132 109 116 125 136 105 130 126 129 127 125 143 120 144 127 131 139 132 116 118 126 110 127 107 132 142 140 118 141 107 117 148 136 121 126 119 136 131 128 119 133 131 136 127 127 132 134 142 128 135 137 120 128 125 126 115 128 103 109 150 128 132 108 118 119 129 125 121 127 121 119 124 107 114 121 112 138 121 111 106 121 124 123 118 124 160 127 138 123 129 110 140 130 148 115 105 127 128 136 113 134 117 147 103 127 127 128 134 120 121 103 138 110 125 126 127 129 143 116 111 126 119 125 126 129 135 121 128 128 111 126 125 132 129 120 135 116 144 132 130 129 114 126 122 117 124 124 120 131 123 117 131 133 130 130 129 121 121 115 118 110 132 121 123 129 125 139 111 111 92 115 129 140 137 115 154 130 115 126 117 87 141 125 117 146 121 135 112 128 120 140 123 111 117 152 149 119 116 110 125 134 124 125 106 102 121 104 127 121 115 132 116 134 124 121 149 133 137 123 128 122 131 125 132 115 113 148 118 136 117 124 123 116 127 124 131 113 117 113 114 134 121 120 116 110 124 121 129 113 131 126 137 127 132 131 119 125 128 117 121 125 127 140 127 125 110 126 127 119 111 122 142 115 107 112 134 99 115 113 119 118 147 131 132 119 112 135 131 143 143 123 132 130 129 131 118 126 94 121 116 118 113 118 140 127 116 145 133 129 126 117 114 119 136 114 113 133 110 139 113 114 126 123 138 122 118 108 133 139 99 118 108 133 123 119 112 128 96 134 118 118 137 125 119 131 171 153 117 129 111 128 137 116 125 144 116 126 129 109 122 138 118 118 119 135 131 112 139 117 128 107 108 123 130 118 119 136 128 121 119 124 117 123 129 133 118 125 137 124 133 107 115 145 126 119 120 124 131 129 122 138 132 119 130 107 128 126 111 127 137 150 117 106 156 135 100 111 134 120 121 129 131 125 121 122 113 96 106 105 122 129 111 115 134 153 105 132 141 116 135 109 117 118 118 112 106 137 134 118 121 130 118 129 112 114 107 103 137 105 118 127 102 137 99 132 130 116 101 132 111 139 108 135 110 120 119 125 112 114 136 128 137 131 107 112 123 138 109 115 120 116 118 120 135 127 130 121 106 132 116 129 126 127 130 128 119 137 132 107 119 123 154 127 136 120 100 128 118 130 118 117 129 110 118 112 106 135 127 124 125 125 118 108 120 122 108 105 131 120 113 139 112 112 125 110 121 138 100 131 103 110 137 137 136 115 116 119 129 117 139 132 151 123 111 125 149 119 120 135 126 105 135 120 128 123 112 116 114 130 145 121 117 136 115 144 136 122 140 102 129 113 113 132 125 110 125 130 103 144 123 92 120 101 128 116 137 120 127 117 115 114 122 121 152 133 117 123 114 123 138 127 119 137 133 112 118 116 121 152 114 120 117 116 138 119 124 124 119 126 112 133 140 109 125 146 124 117 123 105 130 115 109 104 121 128 102 130 134 108 120 149 114 129 110 134 146 126 129 126 109 137 123 106 119 132 122 118 121 122 113 112 152 117 121 134 125 115 133 141 118 142 106 109 123 115 120 110 109 100 129 138 126 133 140 134 124 104 105 114 114 117 121 109 124 112 139 111 112 101 113 131 132 121 141 124 121 104 109 118 112 117 126 120 117 128 124 128 110 146 137 129 119 97 113 124 143 114 119 128 142 125 139 142 118 108 117 134 125 127 130 118 129 117 113 126 128 109 106 117 122 105 112 131 115 117 92 107 108 133 124 116 129 123 107 123 119 125 112 121 141 115 109 128 118 117 123 112 131 102 105 119 121 127 116 122 114 131 130 131 135 111 110 98 124 116 106 128 134 126 123 119 115 147 136 131 133 127 119 130 135 136 133 116 138 135 121 111 131 127 147 119 112 121 123 121 114 117 118 121 106 120 106 139 109 130 121 132 123 134 138 118 130 129 126 119 123 137 108 112 119 127 128 138 126 105 84 134 134 115 111 122 137 116 128 136 120 110 136 110 137 118 125 110 121 116 123 119 143 109 115 128 114 115 132 115 131 115 117 118 120 123 124 114 108 130 122 124 115 132 123 103 133 123 136 118 111 133 126 114 127 122 124 140 128 125 122 134 148 110 124 127 127 136 136 113 118 144 120 135 119 111 116 126 106 113 110 125 135 126 100 107 128 118 129 114 108 141 118 113 127 113 132 128 124 132 137 125 118 129 113 113 103 115 135 124 127 108 120 125 114 104 121 119 132 107 117 119 114 144 135 119 116 114 111 131 128 111 108 120 107 120 112 103 100 101 116 123 133 134 119 129 118 109 105 100 145 107 136 116 105 91 126 136 134 118 133 119 142 130 131 123 123 113 123 134 122 120 136 143 125 122 126 124 123 129 117 117 117 116 104 119 120 142 113 131 139 133 121 117 132 122 136 131 114</counts>
			</dataPoints>
		</scan>
	</xrdMeasurement>
</xrdMeasurements>