File: data/XRD/XG-Sauerstoff/XG-750/W6822-1B_XG_Sauerstoff_750.xrdml
<xrdMeasurements xmlns="http://www.xrdml.com/XRDMeasurement/2.1" xmlns:xsi="http://www.w3.org/2001/XMLSchema-instance" xsi:schemaLocation="http://www.xrdml.com/XRDMeasurement/2.1 http://www.xrdml.com/XRDMeasurement/2.1/XRDMeasurement.xsd" status="Completed">
	<comment>
		<entry>Configuration=Factory configuration, Owner=User-1, Creation date=7/8/2013 4:01:53 PM</entry>
		<entry>Goniometer=PW3050/65 (Theta/2Theta); Minimum step size 2Theta:0.0001; Minimum step size Omega:0.0001</entry>
		<entry>Sample stage=MRD Cradle; Minimum step size Phi:0.01; Minimum step size Chi:0.01; Minimum step size X:0.01; Minimum step size Y:0.01; Minimum step size Z:0.001</entry>
		<entry>Diffractometer system=XPERT-PRO</entry>
		<entry>Measurement program=C:\PANalytical\Data Collector\Programs\Jorrit\2thom\_absolute_2th-om_10-130deg_PIXscan_56min.xrdmp, Identifier={15BCCF57-2807-42BD-B5B9-ECC0B3DC9284}</entry>
		<entry>Batch program=C:\PANalytical\Data Collector\Programs\SimonL\batch4x_2thom_10-130°_z9.1_x0,10,20,30_y0_57min.xrdmp, Identifier={EED9823A-2BEB-424C-9252-345C4EF2834A}</entry>
	</comment>
	<sample type="To be analyzed">
		<id></id>
		<name></name>
		<preparedBy></preparedBy>
	</sample>
	<xrdMeasurement measurementType="Scan" status="Completed" sampleMode="Reflection">
		<comment>
			<entry>_absolute_2th-om_10-130deg_PIXscan_56min</entry>
			<entry>PHD Lower Level = 4.83 (keV), PHD Upper Level = 11.27 (keV)</entry>
		</comment>
		<usedWavelength intended="K-Alpha 1">
			<kAlpha1 unit="Angstrom">1.5405980</kAlpha1>
			<kAlpha2 unit="Angstrom">1.5444260</kAlpha2>
			<kBeta unit="Angstrom">1.3922500</kBeta>
			<ratioKAlpha2KAlpha1>0.5000</ratioKAlpha2KAlpha1>
		</usedWavelength>
		<incidentBeamPath>
			<radius unit="mm">320.00</radius>
			<xRayTube id="1010048" name="Empyrean Cu LFF HR (9430 033 7310x) DK442154">
				<tension unit="kV">40.0</tension>
				<current unit="mA">40.0</current>
				<anodeMaterial>Cu</anodeMaterial>
				<focus type="Line">
					<length unit="mm">12.0</length>
					<width unit="mm">0.4</width>
					<takeOffAngle unit="deg">4.2</takeOffAngle>
				</focus>
			</xRayTube>
			<xRayMirror id="27010001" name="Inc. Beam Cu W/Si (parabolic MRD)" hybrid="false">
				<crystal type="Graded" shape="Parabolic">W/Si</crystal>
				<acceptanceAngle unit="deg">0.800</acceptanceAngle>
				<length unit="mm">60.0</length>
			</xRayMirror>
			<sollerSlit id="21010002" name="Soller slits 0.04 rad.">
				<opening unit="rad">0.0400</opening>
			</sollerSlit>
			<mask id="22030007" name="Fixed mask 2 mm">
				<distanceToSample unit="mm">220.00</distanceToSample>
				<width unit="mm">2.00</width>
			</mask>
			<divergenceSlit id="22010007" name="Fixed slit 1/8°" xsi:type="fixedDivergenceSlitType">
				<distanceToSample unit="mm">220.00</distanceToSample>
				<height unit="mm">0.19</height>
			</divergenceSlit>
		</incidentBeamPath>
		<diffractedBeamPath>
			<radius unit="mm">320.00</radius>
			<sollerSlit id="21010002" name="Soller slits 0.04 rad.">
				<opening unit="rad">0.0400</opening>
			</sollerSlit>
			<receivingSlit id="22010001" name="Fixed slit 4°">
				<height unit="mm">5.88</height>
			</receivingSlit>
			<detector id="7010017" name="PIXcel3D 1x1 detector" xsi:type="areaDetectorType">
				<phd unit="%">
					<lowerLevel>30.0</lowerLevel>
					<upperLevel>70.0</upperLevel>
				</phd>
				<mode>Scanning</mode>
				<activeChannelsEquatorial>255</activeChannelsEquatorial>
				<activeChannelsAxial>255</activeChannelsAxial>
				<pitchEquatorial unit="mm">0.05500</pitchEquatorial>
				<pitchAxial unit="mm">0.05500</pitchAxial>
				<readOutPeriod unit="seconds">0.135</readOutPeriod>
			</detector>
		</diffractedBeamPath>
		<scan appendNumber="0" mode="Continuous" scanAxis="2Theta-Omega" status="Completed">
			<header>
				<startTimeStamp>2024-09-18T22:15:28+02:00</startTimeStamp>
				<endTimeStamp>2024-09-18T23:11:33+02:00</endTimeStamp>
				<author>
					<name>PRO-MRD</name>
				</author>
				<source>
					<applicationSoftware version="6.1b">Data Collector</applicationSoftware>
					<instrumentControlSoftware version="7.0E 20130304">XPERT-PRO</instrumentControlSoftware>
					<instrumentID>0000000011142674</instrumentID>
				</source>
			</header>
			<dataPoints>
				<positions axis="2Theta" unit="deg">
					<startPosition>9.99826193</startPosition>
					<endPosition>129.99755682</endPosition>
				</positions>
				<positions axis="Omega" unit="deg">
					<startPosition>4.99913096</startPosition>
					<endPosition>64.99877841</endPosition>
				</positions>
				<positions axis="Phi" unit="deg">
					<commonPosition>0.00</commonPosition>
				</positions>
				<positions axis="Chi" unit="deg">
					<commonPosition>0.00</commonPosition>
				</positions>
				<positions axis="X" unit="mm">
					<commonPosition>10.00</commonPosition>
				</positions>
				<positions axis="Y" unit="mm">
					<commonPosition>0.00</commonPosition>
				</positions>
				<positions axis="Z" unit="mm">
					<commonPosition>9.100</commonPosition>
				</positions>
				<commonCountingTime unit="seconds">32.895</commonCountingTime>
				<counts 215 233 223 238 211 226 190 222 207 215 239 211 206 218 207 230 230 228 219 234 222 216 227 209 238 204 218 241 208 218 202 222 224 218 205 225 219 232 199 201 225 217 228 221 218 226 214 239 211 201 199 203 231 216 236 227 240 234 222 238 197 218 213 203 223 221 212 199 217 235 207 215 246 206 225 202 205 214 227 205 208 182 205 185 205 200 215 220 192 203 201 218 198 207 198 199 227 223 194 192 214 187 194 219 225 192 213 197 200 216 218 214 208 229 199 185 201 183 219 207 201 186 203 171 193 206 195 203 211 189 237 210 183 188 193 197 202 207 196 216 190 200 181 192 217 179 210 219 191 184 181 185 214 195 196 205 207 178 187 201 207 180 195 197 181 185 198 199 207 233 200 203 175 193 214 191 194 202 190 181 199 212 201 188 197 198 190 183 211 199 180 182 197 198 218 181 194 211 205 195 204 196 184 199 180 206 202 200 191 201 200 160 210 219 168 181 197 176 208 197 193 192 194 180 206 200 189 184 166 195 202 181 216 187 189 205 196 192 195 195 159 179 204 201 186 175 169 182 177 195 196 174 213 207 177 182 185 196 195 203 182 163 202 191 194 209 175 160 186 217 195 195 201 191 179 175 186 175 205 206 215 171 196 195 189 157 186 186 180 186 189 184 190 178 174 171 178 211 192 184 192 167 187 198 186 173 168 188 184 190 200 186 185 216 184 184 191 187 161 201 216 168 174 184 164 174 207 184 171 182 182 187 195 171 185 179 177 157 172 181 199 155 189 189 176 189 183 143 147 159 181 169 195 206 185 178 186 187 158 188 170 159 157 162 168 190 198 162 157 179 184 171 174 175 185 187 166 161 198 193 185 171 178 176 178 178 183 165 162 183 191 194 172 171 180 180 173 184 151 166 184 147 190 186 185 164 167 166 176 149 189 151 147 171 160 198 175 178 189 194 183 163 174 163 170 175 185 167 175 164 168 170 147 183 177 164 152 180 157 149 162 174 153 157 166 162 166 170 172 179 179 172 141 167 150 195 161 153 162 171 168 182 197 169 179 180 196 161 179 158 174 145 194 175 144 172 159 146 181 191 174 168 158 159 177 186 166 174 160 149 190 185 165 164 158 167 148 162 197 158 149 168 173 183 174 175 165 182 191 149 151 163 183 145 151 149 167 147 160 170 173 169 165 154 171 153 147 149 169 164 153 168 166 159 169 150 160 163 155 146 173 143 177 182 163 160 140 158 136 150 165 169 180 163 167 180 167 153 151 165 156 158 139 142 135 163 167 161 145 184 167 165 168 168 152 166 135 177 131 163 156 167 145 158 164 170 142 160 175 162 173 167 147 165 164 159 143 148 166 174 160 152 155 146 165 147 157 145 160 151 163 168 159 182 180 154 182 203 161 164 160 147 156 167 150 164 190 177 170 163 152 150 156 174 152 167 159 160 157 147 170 176 156 166 150 132 138 170 165 132 160 158 163 166 158 168 152 156 155 158 157 138 174 146 181 142 166 158 161 148 143 180 119 174 156 148 158 139 175 156 159 153 184 154 159 167 155 129 159 147 151 163 158 141 143 163 179 176 144 149 157 162 124 161 162 148 166 165 156 149 149 144 153 148 143 176 186 144 165 177 142 136 147 155 167 180 160 154 176 164 180 149 155 177 161 153 149 165 174 148 165 173 176 156 142 156 159 162 150 173 171 160 158 176 168 154 145 165 167 147 153 155 165 144 153 150 128 171 138 163 164 151 140 160 156 155 148 167 134 149 164 143 162 159 143 157 148 155 147 146 150 142 144 144 178 167 134 131 135 166 161 143 158 154 149 151 151 146 143 144 150 154 157 148 141 135 176 146 159 156 150 146 166 165 183 147 150 160 158 143 170 158 158 144 170 160 166 177 188 159 155 174 180 167 154 130 158 154 172 145 152 171 169 153 158 151 142 164 164 145 157 155 160 152 151 155 147 146 150 175 175 154 149 158 152 174 146 155 155 139 153 163 144 149 153 138 149 155 170 126 154 154 164 157 149 158 176 145 166 159 159 136 187 147 171 171 146 143 159 154 159 149 150 145 156 162 162 166 158 152 158 133 165 151 139 145 149 158 152 162 157 140 166 154 167 161 159 146 166 162 174 169 167 168 187 148 136 149 152 163 150 146 155 161 161 130 157 166 150 138 154 167 158 161 172 162 171 170 166 174 129 161 156 150 173 166 157 141 167 154 167 160 146 160 177 169 159 169 152 162 164 150 148 142 164 152 168 177 169 153 144 164 153 150 142 172 159 142 169 158 159 151 159 153 158 167 180 153 185 152 175 177 157 154 173 172 177 154 162 146 148 162 178 156 171 162 173 162 159 168 159 162 178 175 182 180 172 176 163 146 158 180 160 153 167 150 156 152 165 172 168 159 147 166 147 176 141 176 136 160 155 171 154 144 157 154 170 161 166 153 140 170 160 178 155 145 155 157 165 161 163 154 171 162 159 158 147 171 176 157 160 156 189 163 154 146 164 158 160 165 144 135 163 147 167 161 163 160 168 153 156 169 167 156 169 176 171 164 184 144 169 171 139 157 180 164 143 162 177 176 168 159 208 161 149 139 148 143 173 162 154 152 169 175 152 166 168 173 150 169 145 172 145 177 168 170 166 148 138 160 180 179 152 151 158 152 175 157 172 176 171 177 154 175 143 168 161 159 169 154 185 154 169 172 152 162 178 163 145 142 141 164 146 183 169 152 154 154 148 146 144 166 136 160 159 180 178 159 179 154 180 164 173 156 140 171 167 189 164 172 156 163 167 145 157 153 154 155 180 184 160 169 166 172 146 158 154 168 170 167 165 152 154 184 136 156 183 177 158 163 139 159 151 166 149 150 158 167 134 147 142 159 169 153 150 144 196 165 173 194 136 152 175 150 166 169 158 189 166 171 144 135 159 151 167 154 175 156 156 140 157 158 175 167 175 150 151 173 157 183 146 138 162 149 151 141 177 167 165 171 167 171 140 150 149 158 155 166 163 134 144 138 140 141 139 167 148 179 164 184 168 166 155 141 170 184 166 170 144 157 165 158 157 155 159 153 165 149 146 155 173 182 151 155 168 170 147 140 151 148 135 164 148 167 158 164 146 134 160 159 161 170 155 175 169 181 150 163 146 155 159 143 157 183 136 166 154 158 175 160 140 164 151 137 128 182 165 169 184 149 177 141 147 159 170 155 152 138 161 152 160 176 157 167 147 166 152 150 161 137 150 149 154 164 164 156 169 137 146 154 161 144 155 163 137 164 148 169 149 162 150 146 151 159 141 169 146 158 164 168 155 141 147 137 161 142 145 146 174 135 148 138 164 159 156 158 154 133 156 163 149 146 141 158 159 185 146 138 149 155 156 161 141 125 150 177 145 138 158 152 156 140 164 161 137 144 154 158 172 141 158 140 137 150 162 144 155 146 158 142 130 165 142 162 155 148 137 163 163 162 176 137 137 130 142 129 154 162 127 149 163 147 164 155 161 180 156 142 143 166 153 154 145 131 134 161 150 126 159 144 172 146 123 166 147 120 138 145 148 130 161 149 158 148 157 136 142 158 160 170 141 150 140 136 128 143 159 127 132 136 136 137 159 145 144 130 145 144 145 161 135 132 153 151 136 146 137 134 139 135 127 146 130 151 117 163 159 152 133 145 131 153 163 159 132 143 167 144 151 142 153 159 158 148 128 137 141 148 151 149 136 132 158 141 144 127 152 158 122 155 152 145 159 141 144 140 144 143 141 144 132 135 146 142 136 159 130 152 152 140 112 155 137 150 141 143 148 156 117 142 154 115 138 140 130 130 150 127 138 144 135 145 173 137 135 132 153 150 149 129 146 115 146 125 138 146 134 137 135 150 122 146 113 135 153 142 139 135 138 158 142 129 144 135 140 125 118 131 114 132 141 135 118 121 140 147 125 137 138 134 124 128 169 138 138 143 122 151 142 109 110 153 133 116 116 131 138 136 136 133 127 134 147 132 127 150 153 153 129 123 127 126 131 142 116 144 119 153 144 144 143 123 128 122 142 133 116 122 132 142 124 133 119 137 132 127 147 136 130 158 132 129 137 136 151 124 129 124 129 105 126 123 128 123 129 116 136 113 132 134 118 152 124 99 111 144 121 122 121 140 118 122 145 138 131 130 127 120 117 132 150 120 122 133 122 129 129 132 133 116 138 118 117 126 139 121 150 132 130 148 131 127 135 122 140 120 130 128 132 138 129 115 125 118 139 135 131 130 119 124 144 100 126 136 119 117 130 152 121 115 122 116 122 155 104 130 133 124 156 125 153 124 138 110 144 110 128 132 118 134 120 116 117 91 134 116 116 125 164 121 122 109 114 120 143 133 143 132 132 130 120 140 134 127 131 135 108 133 112 139 119 138 119 102 132 130 120 151 121 122 124 109 114 112 113 113 126 123 119 135 112 109 137 119 113 118 126 97 123 113 131 112 125 126 125 129 136 127 124 102 117 124 105 132 135 148 99 133 121 110 115 134 111 118 120 131 118 121 115 112 117 123 107 151 131 141 112 110 105 119 137 134 166 130 120 115 108 122 130 136 129 118 119 114 111 118 131 120 132 147 127 113 116 127 138 126 139 122 115 114 134 106 113 116 136 108 114 106 111 125 141 120 110 123 124 127 126 140 113 122 107 129 116 138 119 123 107 122 118 104 112 107 98 122 122 126 137 109 104 96 128 131 133 125 102 100 120 124 99 110 94 133 108 116 115 109 111 122 114 129 114 117 113 106 113 111 116 111 121 124 98 97 114 102 123 125 111 111 134 112 130 115 114 105 132 131 136 115 129 127 106 134 135 129 134 100 113 151 133 140 118 118 119 106 131 119 108 136 128 124 129 113 124 135 107 128 117 130 112 139 128 111 106 132 121 104 123 116 94 139 132 152 130 116 124 107 101 132 128 125 116 114 127 121 107 125 111 116 116 90 109 112 122 107 129 130 128 102 107 110 112 119 117 103 120 130 116 112 107 112 118 106 112 119 111 106 117 126 127 107 100 124 132 98 108 111 104 126 114 112 114 117 108 107 117 102 104 111 125 137 98 113 116 112 115 123 133 119 116 103 105 132 108 108 147 112 113 98 128 103 119 109 100 106 97 111 123 119 112 112 103 123 111 120 120 125 124 104 116 117 120 124 113 109 108 108 107 98 116 111 111 116 136 93 107 118 124 106 121 134 92 106 104 101 137 96 125 102 110 113 97 118 105 125 113 116 127 116 111 100 97 129 108 106 122 112 102 136 105 112 99 129 130 113 105 119 106 110 99 126 106 103 115 92 114 115 98 109 101 123 94 110 124 115 119 104 108 133 116 95 121 111 101 108 100 110 125 109 109 104 122 107 105 126 113 95 118 122 123 111 106 117 100 122 97 110 98 130 115 125 105 116 90 131 123 90 111 115 110 113 111 110 104 111 102 102 110 99 88 97 114 117 115 124 113 95 99 105 107 118 130 119 105 103 136 102 125 113 99 113 109 100 113 140 119 93 99 132 107 105 92 107 129 108 128 105 88 95 109 138 111 106 99 117 93 90 83 119 105 107 97 102 110 105 108 92 85 135 115 98 117 104 126 112 132 111 119 100 113 110 104 109 99 86 98 110 86 128 114 111 102 112 105 101 115 114 94 106 99 102 104 105 113 104 107 96 106 121 106 105 83 104 101 114 97 117 101 95 95 106 89 103 98 101 109 108 111 125 110 115 110 115 106 102 107 91 97 106 104 109 138 104 106 107 115 110 115 108 115 93 119 110 104 104 120 95 109 96 103 95 99 96 107 106 108 89 101 120 106 97 121 126 98 119 106 119 110 103 122 106 89 119 92 113 116 115 119 113 100 101 121 123 102 124 109 105 123 105 101 104 94 97 116 127 101 85 132 102 123 120 97 105 126 108 108 101 89 118 113 123 105 102 117 98 99 127 110 115 108 114 117 115 110 119 112 102 109 124 103 96 116 116 116 102 117 115 96 110 119 112 95 117 99 100 87 106 131 116 101 99 118 117 102 108 93 112 94 123 110 94 108 99 129 106 97 105 104 93 112 117 113 114 116 85 109 99 120 97 123 102 100 111 104 100 112 90 85 117 102 117 101 102 123 100 96 139 113 99 102 111 109 99 93 114 120 95 115 109 100 136 123 104 111 94 137 117 123 110 125 117 130 129 115 127 134 127 111 132 134 136 128 136 129 109 110 132 111 130 109 117 114 121 119 115 114 105 103 106 127 122 122 103 131 98 109 134 118 105 102 102 113 109 117 110 99 114 114 126 118 90 106 104 100 113 108 101 101 99 88 105 104 83 99 118 108 98 96 94 113 100 108 105 100 94 97 118 128 98 97 111 105 115 112 115 90 109 107 93 98 92 116 125 105 111 114 96 111 102 105 128 99 103 95 105 95 117 105 98 107 115 98 112 98 105 98 114 88 110 112 111 123 97 105 126 109 109 98 99 104 96 109 108 116 110 91 104 115 112 108 104 109 113 115 89 100 106 106 112 123 102 103 117 109 116 96 101 103 107 114 93 110 102 109 122 105 109 100 95 94 107 103 119 109 97 105 96 113 98 89 99 94 123 125 109 104 125 101 80 117 102 110 93 109 105 99 100 100 108 89 106 121 125 103 110 110 100 103 105 125 114 104 99 112 106 109 117 113 101 115 91 114 111 83 109 94 117 109 111 115 110 110 99 121 111 109 104 104 112 91 107 103 99 114 112 98 106 95 97 113 112 87 109 109 87 103 117 86 99 110 120 113 97 95 112 106 112 122 107 91 109 102 102 116 95 129 114 80 113 90 113 102 100 93 123 113 110 126 107 115 115 118 98 109 86 107 101 121 103 102 96 109 114 114 125 93 101 100 105 96 106 107 107 91 99 113 112 93 103 112 113 93 109 110 114 106 89 114 99 98 116 103 117 96 110 104 100 92 87 101 103 101 135 91 107 91 106 121 108 109 122 111 100 117 109 101 112 118 103 97 108 91 125 107 105 117 96 96 113 97 98 91 113 105 116 100 109 104 95 109 102 109 99 111 104 99 107 125 104 91 99 101 103 88 111 92 100 84 120 110 100 102 114 111 107 115 108 118 86 116 102 104 106 115 117 108 89 104 97 117 110 106 122 102 116 108 112 108 119 101 91 92 136 113 114 110 125 96 87 104 105 81 121 92 109 106 105 101 130 110 104 95 105 81 114 104 105 94 108 116 111 114 101 121 94 130 91 93 96 117 110 102 105 96 117 99 104 121 106 101 125 97 105 109 119 115 123 115 111 94 94 108 100 93 111 99 100 100 118 107 94 104 99 131 111 103 103 120 108 109 99 110 111 127 108 119 114 101 115 114 99 114 115 121 98 119 109 100 106 123 119 107 96 110 110 88 116 108 111 111 128 105 101 91 105 111 92 107 103 97 113 102 102 118 85 109 111 115 118 102 95 131 133 108 101 125 88 101 107 119 103 109 107 100 114 113 114 100 102 120 99 104 87 90 103 97 101 108 96 110 102 127 94 111 126 107 107 117 100 100 114 137 121 94 124 97 125 126 108 128 97 123 117 100 115 107 132 100 114 96 106 112 111 140 116 128 105 123 114 124 122 110 108 126 123 130 115 97 119 100 146 134 117 119 119 108 118 108 121 101 111 135 102 107 90 118 101 116 101 111 113 103 127 123 96 112 118 118 109 119 103 120 106 123 116 102 99 113 125 116 106 133 109 109 100 117 108 117 112 117 94 111 115 94 108 102 131 120 127 141 133 124 118 130 126 119 135 113 114 110 125 129 128 115 125 124 118 110 112 122 122 119 143 124 135 122 134 140 125 133 130 145 143 145 145 140 171 149 142 162 152 155 150 161 145 190 173 167 186 198 184 222 188 172 201 170 178 152 144 200 188 175 179 156 176 172 163 179 148 170 161 176 158 132 142 138 150 139 131 134 151 135 140 134 126 138 143 107 140 123 144 116 120 114 115 118 94 125 112 110 122 108 125 116 122 113 106 133 105 107 120 120 118 102 106 99 112 121 120 116 117 117 113 112 122 135 100 104 110 123 104 121 109 104 114 121 97 123 91 117 111 107 108 100 123 104 120 105 98 107 113 109 118 116 94 117 125 107 123 85 113 107 116 91 110 111 99 127 108 113 114 111 108 97 100 113 113 107 111 106 107 112 103 107 125 108 99 117 118 106 106 132 111 108 117 102 113 107 109 122 105 105 101 108 100 116 97 104 113 123 120 98 131 118 112 109 105 96 125 113 124 96 113 96 113 109 103 83 107 107 130 111 103 113 109 123 105 93 122 120 109 89 111 108 96 128 105 106 100 118 96 108 101 114 91 112 116 101 110 104 94 104 106 108 108 116 111 96 126 113 104 96 112 100 102 108 99 115 123 94 109 110 94 109 100 101 97 106 107 82 99 108 126 115 110 108 109 115 124 112 109 105 100 93 105 95 105 100 100 79 98 89 87 116 118 102 101 96 101 100 93 130 133 96 108 111 110 116 112 107 124 105 103 96 105 133 112 100 100 128 103 115 103 129 114 128 113 108 100 117 102 108 121 104 98 107 96 107 109 120 114 105 107 103 96 120 108 99 97 90 106 128 122 119 91 112 104 107 106 96 109 106 83 107 103 110 97 112 101 125 107 109 103 113 109 101 98 100 97 91 105 103 112 99 108 106 106 106 84 94 121 97 118 108 90 99 116 82 119 114 114 100 104 98 106 126 122 73 105 88 114 119 97 93 109 105 102 107 117 90 104 110 95 75 85 116 119 122 127 108 103 102 107 97 114 108 106 117 87 116 109 112 122 108 112 103 120 118 109 101 111 107 102 114 81 106 105 93 100 97 120 111 98 112 101 95 113 108 111 105 105 105 112 119 107 120 88 104 104 101 118 110 91 112 97 101 86 108 101 99 107 84 104 112 103 132 113 91 91 96 89 111 97 117 92 117 99 109 116 112 101 106 95 97 105 105 119 108 98 105 100 118 125 87 116 115 116 101 114 98 100 92 102 105 116 99 105 98 108 122 105 132 104 108 123 108 109 92 99 118 107 91 90 90 111 109 101 117 86 122 117 89 104 103 96 113 107 114 105 106 91 101 105 98 105 104 105 121 111 100 94 102 92 123 103 117 107 122 106 125 89 122 109 114 101 105 119 117 105 99 106 88 112 119 101 98 106 117 103 120 101 92 92 93 128 111 105 95 117 102 95 94 107 106 91 112 105 99 102 103 99 122 97 118 85 112 98 124 106 114 112 109 115 123 112 105 101 119 127 124 109 112 100 100 108 112 130 98 119 97 89 109 92 117 86 117 118 78 121 90 86 94 109 97 106 118 92 86 100 111 94 100 90 106 127 94 123 108 108 109 96 115 100 120 102 90 105 106 93 118 102 105 112 106 82 89 100 95 116 108 77 94 107 102 88 117 98 106 106 106 110 89 98 107 94 118 115 85 113 102 92 101 106 112 107 105 100 114 93 91 118 105 102 122 116 103 101 102 93 102 86 112 121 101 94 108 98 122 94 113 91 94 119 104 107 117 91 93 89 110 99 109 113 88 101 109 98 109 124 103 95 103 114 103 95 98 112 106 111 113 133 99 111 115 114 117 97 98 97 108 118 122 101 114 125 96 108 108 98 72 122 115 108 112 96 103 109 117 102 119 118 90 117 95 97 117 112 95 88 106 98 97 119 93 115 91 114 105 122 105 93 94 102 104 115 108 109 111 96 134 120 99 115 124 98 125 113 104 102 105 107 96 111 100 101 110 91 99 82 108 100 96 103 114 110 110 98 110 121 106 98 99 103 121 102 92 88 106 105 98 131 107 113 101 96 99 94 103 97 110 108 113 101 105 108 98 111 83 111 125 93 93 101 101 88 83 100 108 99 103 116 96 114 101 123 105 98 119 99 111 116 109 96 111 114 91 117 102 118 131 88 92 134 102 94 109 110 105 107 111 104 99 93 101 111 125 108 111 113 108 118 106 97 94 103 108 113 122 97 98 89 113 98 112 102 112 98 83 106 113 97 112 108 108 112 90 95 95 85 100 106 97 118 121 115 111 119 104 102 116 115 77 106 113 115 95 110 116 118 109 109 98 118 94 125 113 98 110 121 88 107 82 118 107 95 109 117 110 120 104 80 91 110 99 112 108 107 104 96 105 100 83 121 114 110 109 135 103 104 111 103 117 96 114 104 112 103 91 99 128 99 96 106 103 85 104 105 111 119 115 75 137 116 108 105 104 101 123 100 108 106 83 97 118 128 116 98 111 98 115 94 107 108 97 88 88 89 101 117 114 114 112 88 113 105 100 108 116 107 101 111 96 97 101 86 86 109 99 108 105 94 122 101 94 99 111 95 110 102 106 106 114 108 125 104 87 112 120 100 111 94 102 110 104 89 101 109 99 106 104 97 92 109 133 103 109 96 114 112 96 99 87 100 98 114 104 111 98 107 93 107 105 96 115 117 105 86 115 85 90 119 106 103 94 115 118 99 119 87 92 108 106 101 128 105 77 104 96 105 102 118 125 103 78 99 102 108 121 116 104 109 101 91 118 102 100 100 118 96 115 135 121 92 97 97 105 106 112 110 105 99 112 106 107 121 95 99 105 103 110 110 88 121 110 117 119 99 99 88 104 98 106 118 95 93 102 111 95 101 99 105 115 96 88 95 104 108 107 109 88 120 111 95 99 113 115 118 95 97 115 108 97 99 109 107 100 106 109 113 109 103 117 95 91 114 113 116 88 122 99 118 112 109 98 105 113 95 114 111 115 118 84 119 109 106 90 113 84 109 101 117 134 103 100 102 99 107 106 117 116 117 88 123 126 98 105 106 95 95 103 107 105 116 106 104 121 82 99 107 105 105 104 102 127 90 133 94 124 108 93 100 107 116 108 110 102 101 98 94 98 99 102 106 116 104 99 120 106 109 105 104 118 91 105 116 98 100 121 76 96 124 96 96 89 104 114 94 119 97 125 111 116 102 102 97 112 138 101 111 126 104 94 104 99 113 123 106 101 99 104 130 103 124 124 100 95 96 107 107 122 105 99 105 95 102 99 100 105 123 125 102 104 132 128 98 124 114 106 106 88 99 91 117 106 108 99 106 141 109 117 98 100 112 91 106 107 120 97 104 97 115 117 114 111 114 102 101 118 102 119 124 109 106 107 103 110 125 92 102 110 101 86 118 94 115 82 109 106 113 110 112 94 89 95 95 100 125 94 121 109 115 118 123 89 109 107 108 112 112 85 116 102 135 98 116 85 107 105 85 112 104 109 106 87 135 121 99 120 118 99 94 102 95 104 77 105 121 107 92 96 118 122 105 114 104 108 94 110 104 106 97 85 99 97 116 104 108 96 128 91 106 105 97 97 112 113 99 106 101 98 135 112 106 110 94 118 94 111 124 103 120 98 116 94 97 108 101 87 117 121 114 98 100 93 100 126 111 103 95 114 122 118 98 91 106 112 119 102 85 115 98 121 108 118 110 108 110 109 108 98 105 117 85 108 112 112 110 113 128 98 94 106 114 106 107 110 115 91 112 102 92 97 122 93 115 124 111 103 93 116 102 107 120 95 94 97 111 107 90 111 102 109 118 101 95 94 101 95 119 110 97 104 101 106 116 105 125 109 106 98 114 114 104 95 97 102 103 112 100 109 115 89 117 115 99 108 102 118 100 99 114 117 102 127 126 101 105 87 117 124 103 107 112 106 117 105 84 96 112 99 87 115 111 112 115 105 94 114 105 97 90 118 106 96 100 106 120 124 123 95 98 93 100 100 117 116 107 116 104 105 114 109 112 120 88 104 110 90 118 118 97 99 107 117 99 103 114 103 98 106 100 104 104 118 98 124 97 113 101 120 96 114 108 96 111 108 114 104 101 113 85 109 107 118 94 114 105 107 99 116 108 115 107 83 103 120 117 111 103 100 106 120 104 105 86 101 114 122 107 111 120 85 104 88 102 96 118 119 100 90 97 113 101 90 116 86 100 118 106 149 101 109 111 92 99 107 116 104 102 117 119 100 111 113 113 105 101 121 91 103 110 102 113 117 129 113 108 88 107 101 127 115 112 90 105 108 118 111 103 111 118 110 124 111 103 100 111 108 113 106 110 119 107 126 105 108 127 111 94 111 99 106 99 96 121 94 101 104 104 118 113 122 111 127 106 96 106 107 128 114 113 111 121 98 116 111 114 111 126 119 96 105 99 116 116 99 138 125 99 118 104 125 97 90 95 109 98 101 106 124 92 123 118 98 106 105 103 114 122 110 105 97 110 129 124 101 113 114 119 99 102 107 108 91 116 113 101 109 99 87 113 114 107 97 80 110 123 101 119 101 102 102 98 113 116 113 120 112 135 99 96 103 121 104 113 102 112 104 113 114 101 112 103 101 105 113 103 113 103 113 109 99 114 115 99 108 104 102 100 103 104 126 110 116 125 127 121 113 98 107 116 121 102 115 107 112 97 107 95 114 100 113 121 104 91 123 127 129 109 124 119 99 122 108 118 132 114 104 112 120 134 100 136 114 122 98 101 116 129 99 125 120 101 128 115 110 126 120 106 102 124 136 111 107 122 134 121 101 117 113 117 137 91 111 114 122 125 118 108 127 109 116 116 107 102 112 113 112 103 113 115 120 114 112 107 116 83 118 123 94 113 120 105 90 120 99 123 121 126 110 122 118 110 102 90 119 108 113 120 107 114 113 107 120 111 116 122 106 110 101 104 122 110 108 96 113 113 123 91 117 113 95 108 123 108 134 112 105 116 121 113 114 95 109 110 132 86 114 106 116 99 109 110 116 119 119 96 103 130 106 118 130 105 105 89 123 116 100 101 111 96 111 128 114 112 126 124 119 90 119 101 91 104 111 111 103 122 92 101 94 97 124 118 107 103 97 119 114 133 118 126 102 104 102 115 91 109 114 112 115 119 110 99 116 90 108 120 107 101 113 94 114 127 107 106 105 106 104 92 110 105 119 99 114 112 110 102 112 110 98 108 94 112 114 105 108 109 127 114 112 118 122 125 107 120 112 114 102 113 131 93 120 123 117 121 128 97 114 102 106 114 118 115 102 127 110 100 86 113 118 97 116 93 103 96 90 100 97 109 100 111 111 118 100 109 107 129 105 106 114 122 107 116 107 108 131 121 123 109 122 115 106 116 108 122 93 126 102 111 92 104 114 106 119 120 105 104 117 134 115 94 108 108 103 115 102 107 89 108 94 100 120 103 112 101 106 97 118 120 104 127 100 119 93 111 102 126 101 112 102 86 122 110 103 103 111 106 98 104 112 106 110 113 114 92 119 123 102 105 105 80 115 145 114 97 98 122 115 111 91 113 128 91 132 110 104 92 127 121 126 107 106 124 105 132 107 109 125 111 97 112 96 99 116 135 108 95 120 107 119 98 110 99 127 112 106 102 106 118 98 119 94 121 115 113 116 103 110 112 122 102 109 114 111 107 117 133 98 104 111 125 102 121 117 131 104 97 115 117 102 81 106 105 126 109 110 112 103 109 110 108 110 117 112 118 104 106 100 112 120 120 119 101 108 95 99 111 107 106 111 120 101 103 96 123 88 121 116 95 106 103 102 101 120 121 121 98 111 97 81 124 96 110 104 120 115 110 113 107 101 107 116 101 106 103 120 110 109 104 101 103 121 124 102 117 101 104 87 122 124 95 100 102 92 117 94 107 107 127 105 98 112 111 113 99 107 110 128 103 117 107 101 119 115 118 103 100 92 118 80 115 98 105 126 101 106 110 108 97 94 102 105 103 92 121 109 117 120 103 113 114 103 101 112 106 122 100 131 111 96 120 123 110 114 117 93 90 103 121 111 117 113 107 119 104 110 104 109 89 93 98 103 103 111 108 119 103 130 93 85 101 106 122 105 98 114 119 98 96 117 99 115 108 104 84 107 120 115 108 117 107 127 114 109 133 112 97 90 126 113 106 99 108 117 112 128 107 106 96 113 108 106 121 89 119 104 113 83 103 113 101 111 109 126 129 101 118 122 99 99 118 114 109 101 117 112 93 106 118 80 121 121 107 109 101 85 108 133 113 101 103 111 103 110 129 96 134 109 85 116 107 110 110 94 99 118 105 110 122 111 105 101 91 111 103 94 100 118 94 127 111 106 114 117 100 117 117 131 126 111 106 112 103 104 100 120 96 130 111 100 107 84 95 107 126 103 101 109 120 102 105 105 104 112 99 118 103 109 122 108 119 97 93 100 91 105 119 92 93 103 125 119 120 100 97 108 100 98 108 94 98 108 105 98 115 107 108 113 107 102 105 101 96 93 94 105 99 129 106 114 118 95 99 109 107 97 89 103 110 98 110 125 110 99 106 100 107 103 101 124 117 104 109 101 95 98 113 114 107 89 117 92 127 105 117 89 117 104 120 107 86 109 123 90 110 103 100 101 88 109 113 97 103 105 111 121 103 110 100 105 125 111 98 108 107 92 105 111 115 110 112 113 100 97 107 115 105 101 104 98 95 100 94 104 104 105 96 99 117 114 106 109 111 102 112 101 104 108 90 104 115 108 92 122 94 109 98 113 107 96 124 125 95 108 102 104 114 96 116 111 108 111 111 101 101 95 99 100 96 100 103 108 101 115 115 100 133 106 112 102 120 111 119 109 102 101 99 93 109 114 100 137 114 123 82 108 127 110 105 113 94 100 103 107 122 101 103 102 113 109 115 90 114 119 119 83 104 108 107 118 119 101 89 123 105 102 120 112 104 100 97 102 107 111 103 93 113 110 104 118 119 113 113 100 106 112 114 99 99 100 102 115 111 98 92 116 110 119 125 102 119 129 81 103 109 105 119 109 103 110 106 94 99 121 129 115 102 101 108 110 94 105 115 118 114 125 96 105 110 100 117 120 124 101 110 84 96 93 103 108 107 91 122 110 91 109 108 106 111 112 107 101 109 112 114 111 130 113 108 104 106 116 117 107 129 106 106 105 102 111 107 109 89 122 113 124 116 114 128 83 118 95 103 104 107 101 117 104 100 114 111 129 102 109 98 103 115 98 109 112 111 117 125 106 120 110 105 92 100 117 110 102 120 99 119 98 101 116 129 107 102 133 109 94 117 106 105 117 101 102 100 109 108 116 141 122 117 104 109 128 104 106 92 102 94 109 96 98 130 108 115 92 106 109 85 106 108 110 107 138 92 114 116 133 105 115 109 88 103 118 83 113 117 106 119 115 99 128 94 102 101 126 108 83 118 99 117 113 117 102 93 99 105 104 109 108 114 110 112 116 116 132 119 110 118 91 128 92 112 92 106 99 120 85 107 105 116 115 95 107 116 106 111 106 104 109 106 93 118 98 92 102 115 111 97 98 122 92 90 95 118 98 92 92 107 96 86 94 97 97 106 113 89 128 107 102 94 103 101 101 107 101 97 87 78 111 103 105 114 85 97 100 102 112 105 115 97 124 97 100 117 106 102 104 117 99 114 102 93 123 120 121 110 128 109 98 90 109 116 106 90 84 100 95 106 129 120 86 106 99 107 100 89 108 109 104 103 119 112 90 116 90 96 103 104 94 113 84 126 106 101 105 109 116 103 115 122 97 115 108 107 104 109 111 98 95 117 90 92 96 118 107 117 110 110 93 94 110 113 104 129 93 104 93 133 94 100 109 93 87 107 108 127 93 131 112 129 94 103 102 91 99 98 101 120 107 131 101 122 116 90 112 102 84 106 101 106 98 105 104 112 110 107 121 102 79 120 113 106 99 103 90 99 104 107 103 103 116 106 106 107 108 101 108 99 128 92 104 104 102 116 98 103 108 95 113 103 106 104 95 105 93 99 91 104 129 111 93 92 105 82 105 110 108 107 115 80 122 108 86 100 91 87 91 101 102 90 106 106 99 118 99 103 104 113 92 98 93 95 109 122 105 95 97 113 116 108 110 108 95 122 117 103 115 113 96 104 94 101 105 110 117 101 98 114 102 106 112 105 113 106 112 106 119 97 107 82 96 93 103 121 95 108 101 115 107 116 97 108 108 90 104 106 117 102 107 116 102 114 110 111 100 121 85 99 90 100 115 93 106 100 112 93 103 112 105 106 100 106 94 86 116 89 110 113 123 105 116 93 88 117 115 97 120 94 115 111 96 102 83 106 137 122 110 88 102 102 113 112 99 90 116 92 99 104 110 105 136 131 105 122 95 124 93 119 90 113 106 93 95 108 108 110 90 87 108 111 101 120 104 92 114 90 101 110 104 104 108 98 99 95 113 114 94 105 113 117 102 104 109 107 104 124 103 98 106 116 88 89 103 111 107 102 92 102 109 95 99 114 102 108 107 97 105 108 101 115 87 104 121 115 95 104 119 91 98 109 102 105 107 99 108 99 111 101 109 86 97 103 106 103 115 84 104 103 121 98 94 109 119 119 106 111 106 105 96 102 100 104 108 99 101 93 96 110 122 102 102 102 113 109 99 89 112 112 93 108 112 97 91 117 93 112 111 118 97 105 104 93 117 119 114 121 120 105 107 114 102 120 109 111 131 120 129 112 126 110 99 127 118 122 109 113 123 104 105 97 113 130 104 131 118 130 108 120 96 95 117 124 120 113 132 105 129 133 117 120 96 109 130 129 108 124 98 123 119 122 120 129 122 118 114 120 106 113 114 89 122 105 122 101 114 107 99 115 115 114 103 116 119 104 103 107 101 103 103 101 108 100 95 103 104 107 106 106 90 83 125 104 93 107 94 83 103 102 102 89 96 93 135 111 103 98 97 96 97 121 101 88 106 118 108 104 103 131 90 111 93 109 105 110 107 97 114 116 102 100 94 99 103 94 128 108 96 112 93 94 94 102 109 105 113 130 106 93 73 123 100 97 104 108 110 109 108 90 95 107 103 100 127 114 105 105 89 98 90 116 96 79 99 122 101 121 98 94 94 107 113 99 103 115 108 94 88 98 110 99 99 119 113 121 108 91 89 107 104 88 110 93 89 107 107 108 104 93 88 99 114 95 88 86 121 90 103 98 108 105 133 128 99 110 102 97 107 90 91 103 110 115 111 75 104 103 100 112 101 102 95 101 113 106 108 90 109 99 102 125 106 95 103 100 98 88 112 113 102 94 105 96 108 113 101 105 84 94 99 115 99 98 111 113 98 102 94 98 108 90 103 120 95 87 93 103 102 98 104 104 119 85 97 115 102 111 97 112 92 103 98 102 92 114 95 102 94 81 99 90 99 105 106 96 114 98 106 106 99 87 92 105 111 93 82 109 101 115 134 108 110 106 97 105 107 80 104 109 100 83 120 118 100 84 103 119 109 99 81 96 98 93 90 103 104 89 109 96 106 105 100 98 84 103 82 88 96 106 83 89 118 94 101 117 94 100 109 100 88 87 95 94 106 131 103 93 100 94 118 99 108 95 100 100 108 103 103 79 109 101 99 94 106 87 112 103 113 96 102 85 97 110 94 108 120 110 109 79 98 105 102 117 94 99 89 117 101 106 89 92 97 81 98 100 90 94 94 90 108 104 93 99 103 84 115 95 104 96 100 103 102 94 94 99 95 102 86 96 97 103 105 103 91 78 83 77 112 97 103 109 94 95 109 99 103 90 108 89 103 111 94 115 116 98 114 101 106 99 99 96 122 96 106 82 99 101 96 89 103 84 96 107 119 97 104 88 92 96 96 95 83 118 83 90 94 96 86 106 93 110 93 95 122 114 104 102 102 87 89 105 89 98 110 107 98 107 97 95 109 92 100 96 110 99 114 116 91 93 85 92 112 104 102 114 100 104 122 101 91 94 90 115 95 93 110 112 99 105 99 90 87 102 96 114 116 107 92 102 115 96 94 106 98 99 95 94 88 109 108 110 105 100 117 111 112 109 111 88 116 112 95 89 99 94 116 103 91 95 113 101 101 108 103 90 99 117 106 99 113 92 100 106 98 101 93 91 91 110 118 99 77 91 90 94 98 98 93 98 101 106 106 97 94 96 107 101 102 93 103 102 102 98 103 118 90 102 103 109 94 80 96 115 89 106 112 114 115 109 77 94 96 102 102 98 98 106 101 97 84 71 107 98 91 121 92 100 92 91 103 77 95 91 96 94 102 90 106 80 95 95 94 96 95 116 93 114 112 102 105 94 114 118 85 84 107 79 103 97 109 107 92 117 122 101 100 90 97 90 89 78 101 100 93 119 99 88 98 90 104 89 101 104 122 100 97 100 106 106 105 107 97 104 105 101 109 84 83 117 95 84 97 111 105 87 107 102 112 98 86 105 104 92 101 92 112 86 104 102 96 114 102 107 90 102 106 100 101 94 114 103 83 96 90 96 87 98 105 107 105 110 110 94 92 90 118 99 79 108 90 111 108 105 107 102 114 98 122 94 115 112 90 115 101 108 100 91 95 76 86 96 97 99 86 96 91 100 103 90 98 103 97 96 107 110 108 113 101 110 92 85 100 119 83 101 96 96 112 120 90 82 97 107 90 101 103 92 87 81 94 91 105 81 103 102 101 103 105 100 85 111 98 99 113 109 102 110 98 91 106 94 100 113 100 85 77 110 96 113 102 92 113 85 97 103 96 91 89 99 97 104 92 94 116 99 90 101 97 99 100 118 106 108 88 111 113 100 105 78 93 91 116 105 100 110 102 92 98 108 98 105 115 108 115 75 96 102 84 88 104 100 92 101 104 94 108 101 90 88 100 113 102 103 104 92 93 87 91 112 98 102 98 96 95 100 87 108 91 107 89 104 110 100 115 95 106 97 93 103 99 97 95 80 102 113 93 111 103 94 103 112 108 93 84 85 100 90 82 111 79 101 79 109 96 107 105 90 99 111 89 91 95 129 98 107 89 90 98 91 85 83 92 97 83 98 99 99 91 117 98 102 105 115 81 104 101 96 103 91 109 96 102 124 119 87 106 88 92 94 100 96 105 95 93 95 105 97 117 107 114 85 94 97 114 98 91 79 114 82 112 105 98 99 94 82 98 102 87 90 114 105 108 104 92 106 96 96 85 81 115 99 99 97 92 102 114 101 91 102 86 79 100 101 104 102 107 101 102 116 102 122 106 87 96 94 90 92 89 88 104 98 103 115 88 83 74 95 86 100 97 88 82 99 84 100 92 106 108 111 91 112 94 102 96 107 103 104 115 105 97 110 92 101 82 92 103 100 115 106 110 98 104 94 101 88 99 106 116 87 116 98 96 103 98 93 89 94 94 107 108 88 101 107 91 110 105 113 97 87 96 96 102 112 93 90 92 122 88 102 98 113 117 104 118 85 98 96 103 99 103 117 94 101 89 108 105 101 100 112 93 112 103 116 101 82 97 91 109 107 109 88 115 88 114 102 89 96 109 85 103 100 105 102 88 76 98 97 112 74 107 98 109 95 118 93 106 106 94 114 86 103 114 109 89 95 113 94 110 110 103 98 113 123 89 99 81 94 113 84 103 101 102 97 99 87 99 106 98 100 109 110 116 109 123 93 85 96 95 83 86 108 113 109 108 124 102 107 99 115 91 108 100 105 105 116 94 90 95 105 86 96 83 91 94 90 90 110 117 85 100 102 91 88 108 99 89 105 97 93 100 92 103 109 113 95 90 92 86 91 89 117 105 104 90 95 71 83 109 104 89 106 114 112 117 112 95 89 96 110 108 112 101 126 95 97 92 91 106 95 113 103 106 115 90 104 101 88 94 102 94 79 102 95 105 110 102 97 101 94 93 107 87 97 91 101 91 99 91 95 89 119 99 93 102 97 87 106 90 124 80 105 107 113 94 116 111 100 110 94 106 103 110 106 93 102 90 72 103 114 112 99 97 98 96 94 97 97 80 98 106 93 116 88 103 98 110 85 99 98 107 100 98 98 101 96 114 89 102 103 93 111 93 107 104 104 82 74 98 91 96 107 93 93 98 85 94 106 106 82 117 92 82 82 106 105 90 92 102 81 108 97 119 95 94 107 101 83 81 94 111 105 89 94 86 92 100 102 103 105 100 92 114 105 94 90 91 91 92 96 104 112 85 100 94 98 107 97 84 100 87 113 100 91 79 102 91 97 91 105 97 105 97 88 121 117 93 96 133 102 103 107 95 104 90 105 82 99 100 94 99 99 104 90 101 102 97 99 91 102 94 97 106 105 97 95 105 98 113 89 106 113 93 84 101 100 92 79 105 106 108 99 88 120 106 95 88 106 101 101 97 106 101 113 102 90 109 107 114 93 107 97 118 82 90 107 111 98 105 100 90 93 85 81 114 100 109 80 97 109 109 91 97 89 111 93 101 101 110 113 102 99 96 111 108 105 93 101 119 101 86 89 107 107 95 87 86 91 71 99 100 104 87 109 94 89 105 130 106 109 113 99 101 122 118 97 106 109 108 93 95 88 115 104 101 90 108 83 113 84 91 100 107 100 106 99 122 97 116 100 97 96 106 110 101 100 108 93 112 96 89 115 99 84 113 106 110 109 112 90 91 113 97 93 113 120 122 106 98 94 94 106 109 111 107 108 82 90 83 114 100 103 102 116 80 90 115 106 90 103 102 111 102 105 110 96 90 90 96 110 91 81 104 80 96 96 107 96 105 90 113 122 108 90 103 101 74 104 86 90 100 97 91 111 109 102 113 106 94 93 94 99 74 113 92 96 81 107 113 95 106 95 74 98 91 95 98 85 105 94 99 102 91 96 104 87 115 100 83 120 98 108 102 80 104 83 100 101 82 106 103 94 81 101 116 94 93 79 83 114 102 104 104 89 107 87 105 87 98 83 101 108 98 117 110 111 108 95 124 92 106 102 94 101 96 96 104 90 96 90 103 91 103 104 102 92 111 100 99 94 98 97 96 96 93 107 110 104 102 103 113 101 89 113 116 103 102 101 101 103 103 111 99 77 82 102 116 92 93 100 112 91 96 99 110 106 107 94 114 105 103 109 88 103 95 90 116 130 111 97 83 88 86 89 84 106 81 93 97 98 98 91 98 102 123 87 97 105 104 105 105 107 107 106 87 101 101 94 112 104 104 97 102 108 101 95 87 103 89 101 98 95 99 84 96 100 97 100 102 105 123 107 88 86 99 101 98 86 84 98 97 125 89 103 95 93 92 92 90 118 100 98 113 84 109 98 101 128 108 99 109 111 107 80 83 117 91 102 73 88 92 100 84 104 110 89 97 96 95 107 99 93 99 103 111 97 106 79 110 86 98 112 92 83 105 91 112 89 96 98 118 102 98 102 108 107 104 97 107 96 107 108 89 113 90 89 118 105 109 95 83 85 84 101 105 112 80 85 90 107 91 127 108 93 97 80 108 94 79 99 95 102 98 88 79 104 111 83 101 78 99 87 100 99 96 106 85 96 106 90 100 101 88 111 113 129 96 100 113 100 99 107 101 100 89 84 95 101 92 84 105 108 104 102 94 101 115 93 93 94 91 122 73 112 91 107 100 85 120 91 99 86 76 93 103 97 128 94 108 88 93 96 84 103 87 93 109 105 98 86 95 89 92 110 96 83 120 100 88 87 93 104 95 100 100 96 104 104 91 88 104 95 90 104 85 111 92 103 129 111 89 98 89 96 101 97 103 94 109 108 100 99 103 94 84 86 121 86 93 101 109 101 83 118 87 102 112 100 94 108 106 89 96 100 83 101 98 84 86 102 100 92 107 92 109 96 93 83 93 112 89 100 101 75 122 103 106 104 88 89 105 100 111 95 88 92 101 107 91 109 110 81 113 108 71 102 84 93 95 103 105 84 113 100 100 84 99 104 84 101 106 113 119 90 83 99 81 95 93 110 101 105 92 101 108 100 104 104 105 94 100 120 95 99 88 83 90 102 117 86 110 94 92 106 112 89 97 95 92 105 101 95 88 100 104 96 93 94 103 96 99 94 107 96 98 126 97 97 100 108 98 106 106 94 127 111 97 88 98 94 117 106 81 98 110 90 103 84 104 98 91 96 81 88 109 84 88 99 93 93 98 111 92 103 99 115 95 120 90 97 105 104 88 105 96 113 97 109 97 109 110 116 110 92 94 95 85 97 95 105 92 91 104 92 104 101 89 100 113 86 94 88 102 98 102 99 114 94 93 109 96 100 91 89 73 132 99 106 112 93 108 79 94 85 77 114 96 82 92 100 90 107 83 101 95 101 99 91 95 82 89 96 75 98 100 105 80 107 107 102 89 91 85 100 104 111 105 111 116 94 102 98 110 124 116 115 95 101 106 95 94 102 97 98 94 114 114 98 107 95 117 103 117 97 92 104 101 116 110 108 103 96 105 106 104 97 92 100 104 99 94 111 123 111 103 96 109 101 118 102 90 102 101 114 98 86 106 99 113 98 121 87 96 105 89 96 105 104 88 92 103 93 108 98 93 102 106 101 112 87 99 105 100 81 91 91 96 99 112 101 95 90 93 89 106 93 96 64 125 109 80 106 115 91 112 85 103 91 107 94 105 91 103 96 81 100 99 82 90 92 96 80 108 96 96 89 109 101 116 89 104 115 108 102 99 92 95 86 102 103 87 117 87 98 90 95 113 109 88 109 102 119 117 108 113 98 98 86 104 112 114 98 94 103 97 92 101 99 102 100 88 100 104 93 90 96 88 108 97 97 97 89 99 105 93 103 97 116 100 89 91 92 98 92 88 92 114 85 100 86 115 121 104 102 102 112 106 105 92 93 109 94 120 82 97 106 99 97 101 86 93 95 82 106 121 104 76 83 78 97 104 103 97 92 95 96 88 94 100 88 94 98 99 126 87 89 94 123 96 100 104 122 98 99 94 102 105 97 101 81 99 89 100 103 109 111 104 100 112 90 100 101 98 98 98 96 91 116 122 102 77 100 111 99 106 98 115 90 125 108 108 100 106 106 93 109 107 115 98 97 116 99 99 102 91 98 103 88 104 97 93 105 92 112 107 89 92 114 92 104 97 112 104 98 112 105 104 98 82 97 91 70 89 103 113 101 121 97 109 111 92 100 88 118 104 103 101 114 91 97 107 113 100 87 98 110 119 92 97 79 113 103 82 102 93 90 106 87 95 92 117 106 96 93 102 91 106 113 93 103 96 99 83 82 91 102 124 88 110 115 101 102 105 107 93 107 102 118 81 109 105 90 103 114 103 117 106 108 86 103 108 95 81 94 111 108 100 91 88 103 105 108 107 116 92 101 120 110 99 97 94 82 87 92 100 82 107 107 97 88 93 95 90 117 92 105 74 103 109 100 126 86 101 101 95 108 116 93 100 105 106 96 102 87 109 111 119 113 100 108 98 96 102 98 90 112 94 100 94 104 95 95 103 98 111 103 102 95 118 102 116 99 99 112 94 115 95 110 103 84 97 100 84 82 97 112 107 113 100 97 89 93 104 99 102 89 92 112 98 98 85 75 111 114 116 101 111 96 88 101 98 104 98 119 118 101 109 99 91 94 107 95 83 106 96 105 96 95 99 103 94 103 94 97 91 112 97 108 99 82 104 94 93 85 94 104 87 98 99 125 106 91 95 110 92 97 95 115 108 103 89 100 105 78 98 76 98 76 82 92 110 105 93 95 100 91 87 99 98 91 98 92 100 101 100 102 124 107 94 88 112 76 106 107 93 85 98 105 92 113 100 100 100 106 93 94 98 111 101 104 97 107 86 87 88 86 94 110 102 81 80 101 97 93 87 96 87 89 104 86 81 98 111 96 102 106 85 117 94 108 110 121 103 96 122 116 120 96 83 90 92 97 75 109 110 91 79 97 102 101 93 89 93 106 95 97 101 116 95 104 106 104 92 77 93 99 111 95 95 107 99 98 108 93 96 104 92 113 107 101 103 118 101 109 97 99 90 92 90 80 98 106 90 119 97 94 128 95 98 113 115 92 97 107 108 99 85 80 100 94 80 85 94 83 91 102 97 96 83 93 109 97 127 87 111 107 105 96 100 105 91 92 96 106 100 90 111 92 105 96 106 97 110 112 112 81 103 84 103 105 93 125 102 106 99 82 101 94 105 94 94 92 90 114 79 97 87 97 107 102 108 104 98 101 92 109 98 87 86 102 89 115 99 96 108 90 103 110 103 97 103 102 97 93 105 106 109 108 109 114 106 79 102 93 110 120 114 116 102 103 109 97 97 101 97 118 101 99 112 75 93 89 105 89 106 100 95 107 91 87 117 68 82 102 85 82 92 91 108 82 112 97 101 93 129 99 129 107 124 103 111 115 118 93 88 113 101 122 111 110 108 113 86 93 80 101 97 91 117 103 105 110 99 105 91 112 131 95 96 114 123 98 106 103 107 111 121 100 100 105 120 114 110 110 108 105 93 94 101 97 87 101 87 103 92 95 103 119 100 104 97 105 115 115 103 106 92 101 107 113 107 92 110 124 90 114 105 95 111 105 101 102 105 121 86 123 104 118 105 98 97 115 85 118 108 113 104 116 96 115 100 103 107 121 112 94 105 97 129 107 109 88 116 102 122 112 98 124 86 102 118 122 87 97 100 122 102 99 123 98 99 110 98 112 115 116 101 84 103 109 105 106 75 102 115 118 113 98 131 92 84 113 101 89 88 108 108 119 115 132 89 124 92 105 116 80 105 95 102 114 123 106 116 101 103 110 104 92 120 113 124 126 95 124 108 99 97 106 94 118 103 118 101 113 116 91 99 109 89 106 106 92 116 110 83 108 100 103 114 112 100 106 91 100 110 107 97 111 119 80 81 95 109 111 86 106 95 104 108 90 97 104 102 92 91 105 117 100 93 111 117 89 100 86 113 125 103 106 110 112 116 105 93 96 122 89 117 114 96 96 100 102 97 112 111 91 90 107 73 106 92 102 98 106 101 97 82 107 109 109 112 110 94 97 100 92 89 104 105 112 107 110 104 89 104 98 104 93 96 108 109 107 88 93 96 93 95 106 119 94 116 114 119 105 86 113 93 117 102 92 101 105 114 118 113 122 113 109 89 94 108 108 108 94 107 121 109 91 93 95 87 113 89 107 92 101 95 97 87 108 116 124 93 94 89 87 101 112 113 103 86 111 100 81 109 93 104 95 122 104 93 111 101 104 114 118 101 116 112 85 100 107 114 104 89 100 110 113 95 106 114 88 93 101 99 107 101 93 108 88 103 95 91 107 100 112 115 109 85 109 96 92 114 98 86 92 91 113 86 88 99 91 106 112 82 105 121 93 108 106 106 104 105 94 106 119 107 107 104 119 104 93 112 102 101 104 106 101 105 95 99 102 106 96 113 104 97 101 103 103 102 98 94 112 85 100 113 100 91 98 116 106 107 106 100 103 89 88 109 114 110 95 89 105 116 98 88 92 105 92 102 102 111 117 88 89 95 104 124 99 116 105 99 113 107 101 94 86 89 92 115 104 114 106 113 94 96 101 95 102 113 99 108 96 103 92 120 125 99 109 100 123 94 97 102 94 96 116 110 113 103 107 86 103 99 105 108 101 101 108 120 84 100 102 103 108 103 83 127 101 116 120 113 106 87 90 114 117 113 103 106 109 110 99 110 110 90 97 97 114 113 93 104 102 109 99 101 94 95 95 99 122 96 87 99 94 107 70 110 111 88 99 103 99 106 94 93 109 116 113 106 112 91 110 104 106 108 97 89 110 123 111 80 104 122 100 96 113 81 112 103 92 86 104 126 98 90 111 123 95 101 102 93 96 111 101 102 101 105 102 109 88 98 115 111 106 93 106 100 100 106 116 99 98 105 110 112 92 110 121 103 84 105 110 103 112 119 102 99 96 98 108 111 121 93 108 93 118 102 104 91 123 103 117 103 105 111 113 103 95 128 103 97 104 122 114 97 96 104 112 100 104 116 115 104 112 101 90 118 128 107 109 87 111 125 104 108 112 95 129 102 114 103 85 86 97 101 118 96 108 97 106 106 110 111 98 96 100 103 96 108 106 125 105 90 99 83 104 112 98 108 96 134 93 104 101 110 109 101 110 113 102 112 113 121 99 94 121 80 104 101 119 110 125 95 88 113 111 101 88 89 108 118 105 105 114 107 106 103 92 99 81 102 116 104 91 98 104 99 99 109 98 102 126 81 98 106 112 121 112 105 105 103 111 116 105 113 88 99 100 90 99 111 109 116 87 89 120 99 96 110 91 106 97 105 121 100 115 93 101 105 112 100 103 110 84 97 103 109 90 115 124 86 104 110 92 94 112 127 96 91 96 126 112 139 91 98 102 129 110 108 106 98 108 119 92 100 92 91 115 94 128 106 92 92 104 92 108 113 121 108 129 100 126 100 99 98 115 113 92 91 104 94 98 112 95 92 110 109 84 124 129 96 91 112 97 82 124 116 106 123 98 82 109 104 94 105 106 118 96 107 91 103 117 104 95 118 113 87 118 96 110 95 110 92 109 100 94 117 114 113 94 105 108 111 100 107 116 102 104 88 100 112 103 127 114 112 93 91 111 104 106 84 105 122 109 108 97 116 103 98 113 101 113 109 108 109 79 113 94 100 108 89 105 117 111 111 114 90 103 115 122 111 104 90 111 120 105 105 104 100 121 111 99 94 117 123 105 119 91 115 112 83 107 115 111 121 109 117 103 106 103 107 98 110 99 117 103 108 112 93 102 96 130 103 98 105 108 125 114 91 93 102 83 117 112 104 92 107 109 107 96 115 98 95 104 113 106 118 102 117 83 103 114 113 130 93 99 100 105 106 94 99 110 123 119 93 120 86 100 115 104 128 98 110 94 124 108 97 112 107 89 116 106 105 121 97 104 89 109 101 93 98 114 109 92 108 124 102 103 137 104 110 117 123 94 91 113 127 100 105 104 99 92 131 119 96 100 107 114 103 91 123 106 110 97 108 90 114 109 117 126 100 112 103 115 124 90 118 106 111 121 109 99 96 119 117 98 125 120 104 108 126 114 120 94 125 100 99 109 101 101 120 108 112 102 121 113 118 89 107 86 109 119 104 105 112 128 93 112 91 88 122 92 111 114 99 122 116 94 108 105 116 107 119 111 94 117 123 109 124 106 105 103 113 116 109 93 122 85 106 103 114 97 110 104 111 125 109 114 118 101 106 114 108 114 114 119 117 92 94 114 106 113 117 100 102 100 92 114 111 94 114 112 107 104 94 106 118 121 107 95 123 121 143 114 104 117 105 129 114 110 122 111 115 106 112 107 103 104 109 101 125 99 102 117 98 114 109 106 104 98 115 105 116 129 102 106 109 108 83 114 99 128 122 101 112 97 104 110 117 101 110 111 115 101 96 104 109 116 113 108 102 111 107 101 106 100 115 106 121 100 96 121 125 110 115 104 115 133 117 103 106 111 103 98 104 104 137 107 110 91 108 103 99 101 123 113 108 98 112 123 113 87 98 95 126 113 102 134 103 91 109 120 122 107 126 125 121 103 110 102 90 130 119 113 101 119 113 120 94 104 116 105 100 111 93 110 129 111 112 114 111 94 119 106 114 105 109 114 122 116 112 103 100 91 137 104 96 107 106 105 97 118 103 106 90 103 146 114 114 143 107 138 125 103 81 128 116 110 102 121 119 117 117 118 112 113 104 114 117 125 126 109 108 121 96 111 108 123 112 129 97 108 117 113 122 135 104 113 115 121 112 102 120 127 112 94 116 99 119 105 125 116 95 113 107 104 114 125 119 119 97 104 102 116 117 101 112 103 118 97</counts>
			</dataPoints>
		</scan>
	</xrdMeasurement>
</xrdMeasurements>