File: data/XRD/XG-Sauerstoff/XG-750/W6821-1B_XG_Sauerstoff_750.xrdml
<xrdMeasurements xmlns="http://www.xrdml.com/XRDMeasurement/2.1" xmlns:xsi="http://www.w3.org/2001/XMLSchema-instance" xsi:schemaLocation="http://www.xrdml.com/XRDMeasurement/2.1 http://www.xrdml.com/XRDMeasurement/2.1/XRDMeasurement.xsd" status="Completed">
	<comment>
		<entry>Configuration=Factory configuration, Owner=User-1, Creation date=7/8/2013 4:01:53 PM</entry>
		<entry>Goniometer=PW3050/65 (Theta/2Theta); Minimum step size 2Theta:0.0001; Minimum step size Omega:0.0001</entry>
		<entry>Sample stage=MRD Cradle; Minimum step size Phi:0.01; Minimum step size Chi:0.01; Minimum step size X:0.01; Minimum step size Y:0.01; Minimum step size Z:0.001</entry>
		<entry>Diffractometer system=XPERT-PRO</entry>
		<entry>Measurement program=C:\PANalytical\Data Collector\Programs\Jorrit\2thom\_absolute_2th-om_10-130deg_PIXscan_56min.xrdmp, Identifier={15BCCF57-2807-42BD-B5B9-ECC0B3DC9284}</entry>
		<entry>Batch program=C:\PANalytical\Data Collector\Programs\SimonL\batch4x_2thom_10-130°_z9.1_x0,10,20,30_y0_57min.xrdmp, Identifier={EED9823A-2BEB-424C-9252-345C4EF2834A}</entry>
	</comment>
	<sample type="To be analyzed">
		<id></id>
		<name></name>
		<preparedBy></preparedBy>
	</sample>
	<xrdMeasurement measurementType="Scan" status="Completed" sampleMode="Reflection">
		<comment>
			<entry>_absolute_2th-om_10-130deg_PIXscan_56min</entry>
			<entry>PHD Lower Level = 4.83 (keV), PHD Upper Level = 11.27 (keV)</entry>
		</comment>
		<usedWavelength intended="K-Alpha 1">
			<kAlpha1 unit="Angstrom">1.5405980</kAlpha1>
			<kAlpha2 unit="Angstrom">1.5444260</kAlpha2>
			<kBeta unit="Angstrom">1.3922500</kBeta>
			<ratioKAlpha2KAlpha1>0.5000</ratioKAlpha2KAlpha1>
		</usedWavelength>
		<incidentBeamPath>
			<radius unit="mm">320.00</radius>
			<xRayTube id="1010048" name="Empyrean Cu LFF HR (9430 033 7310x) DK442154">
				<tension unit="kV">40.0</tension>
				<current unit="mA">40.0</current>
				<anodeMaterial>Cu</anodeMaterial>
				<focus type="Line">
					<length unit="mm">12.0</length>
					<width unit="mm">0.4</width>
					<takeOffAngle unit="deg">4.2</takeOffAngle>
				</focus>
			</xRayTube>
			<xRayMirror id="27010001" name="Inc. Beam Cu W/Si (parabolic MRD)" hybrid="false">
				<crystal type="Graded" shape="Parabolic">W/Si</crystal>
				<acceptanceAngle unit="deg">0.800</acceptanceAngle>
				<length unit="mm">60.0</length>
			</xRayMirror>
			<sollerSlit id="21010002" name="Soller slits 0.04 rad.">
				<opening unit="rad">0.0400</opening>
			</sollerSlit>
			<mask id="22030007" name="Fixed mask 2 mm">
				<distanceToSample unit="mm">220.00</distanceToSample>
				<width unit="mm">2.00</width>
			</mask>
			<divergenceSlit id="22010007" name="Fixed slit 1/8°" xsi:type="fixedDivergenceSlitType">
				<distanceToSample unit="mm">220.00</distanceToSample>
				<height unit="mm">0.19</height>
			</divergenceSlit>
		</incidentBeamPath>
		<diffractedBeamPath>
			<radius unit="mm">320.00</radius>
			<sollerSlit id="21010002" name="Soller slits 0.04 rad.">
				<opening unit="rad">0.0400</opening>
			</sollerSlit>
			<receivingSlit id="22010001" name="Fixed slit 4°">
				<height unit="mm">5.88</height>
			</receivingSlit>
			<detector id="7010017" name="PIXcel3D 1x1 detector" xsi:type="areaDetectorType">
				<phd unit="%">
					<lowerLevel>30.0</lowerLevel>
					<upperLevel>70.0</upperLevel>
				</phd>
				<mode>Scanning</mode>
				<activeChannelsEquatorial>255</activeChannelsEquatorial>
				<activeChannelsAxial>255</activeChannelsAxial>
				<pitchEquatorial unit="mm">0.05500</pitchEquatorial>
				<pitchAxial unit="mm">0.05500</pitchAxial>
				<readOutPeriod unit="seconds">0.135</readOutPeriod>
			</detector>
		</diffractedBeamPath>
		<scan appendNumber="0" mode="Continuous" scanAxis="2Theta-Omega" status="Completed">
			<header>
				<startTimeStamp>2024-09-18T21:18:53+02:00</startTimeStamp>
				<endTimeStamp>2024-09-18T22:14:57+02:00</endTimeStamp>
				<author>
					<name>PRO-MRD</name>
				</author>
				<source>
					<applicationSoftware version="6.1b">Data Collector</applicationSoftware>
					<instrumentControlSoftware version="7.0E 20130304">XPERT-PRO</instrumentControlSoftware>
					<instrumentID>0000000011142674</instrumentID>
				</source>
			</header>
			<dataPoints>
				<positions axis="2Theta" unit="deg">
					<startPosition>9.99826193</startPosition>
					<endPosition>129.99755682</endPosition>
				</positions>
				<positions axis="Omega" unit="deg">
					<startPosition>4.99913096</startPosition>
					<endPosition>64.99877841</endPosition>
				</positions>
				<positions axis="Phi" unit="deg">
					<commonPosition>0.00</commonPosition>
				</positions>
				<positions axis="Chi" unit="deg">
					<commonPosition>0.00</commonPosition>
				</positions>
				<positions axis="X" unit="mm">
					<commonPosition>0.00</commonPosition>
				</positions>
				<positions axis="Y" unit="mm">
					<commonPosition>0.00</commonPosition>
				</positions>
				<positions axis="Z" unit="mm">
					<commonPosition>9.100</commonPosition>
				</positions>
				<commonCountingTime unit="seconds">32.895</commonCountingTime>
				<counts 220 203 208 222 187 213 223 224 216 237 209 224 217 223 207 211 202 199 201 216 203 204 206 223 218 181 235 234 225 222 192 216 231 240 210 216 199 204 184 202 201 206 202 196 207 211 196 203 222 208 228 218 219 210 210 204 206 218 209 200 207 222 215 189 211 219 222 212 213 206 208 211 197 200 210 189 177 207 198 208 198 186 199 207 220 206 201 220 204 201 211 209 212 181 212 208 210 206 206 197 166 197 205 174 184 184 176 194 203 226 199 227 209 187 203 220 195 185 211 219 166 188 206 210 209 210 192 179 172 200 203 194 216 201 176 200 199 199 204 191 195 215 188 199 206 177 210 202 220 193 166 208 194 207 210 180 210 190 201 202 186 156 232 187 200 191 185 183 213 237 178 178 172 183 195 206 209 194 197 189 208 193 199 204 203 195 168 192 212 179 200 224 211 177 175 179 187 180 197 178 186 181 172 162 176 191 175 171 173 176 188 192 183 194 169 204 174 199 204 178 168 193 193 192 203 194 184 196 197 174 188 197 179 186 191 190 202 183 236 162 210 188 188 183 178 189 195 179 171 170 170 200 170 193 172 170 180 205 169 210 194 197 204 188 172 172 180 196 192 166 184 170 165 177 184 180 179 191 167 199 162 190 187 169 182 167 185 186 158 151 206 181 180 169 193 182 180 176 171 206 209 168 186 159 169 187 193 184 167 170 191 184 176 166 176 187 189 192 169 169 173 163 173 159 164 196 171 173 160 184 167 182 157 213 191 178 177 181 169 183 172 155 166 192 161 192 181 184 171 155 142 167 163 174 176 188 172 179 166 155 157 202 160 166 168 156 179 167 174 158 159 182 202 167 169 154 164 167 166 151 175 158 176 179 168 154 171 173 164 164 160 165 143 163 186 143 182 159 176 178 166 188 156 177 156 181 182 182 178 166 184 172 161 182 175 184 153 167 185 161 155 176 156 199 152 170 147 158 172 148 169 164 177 146 162 174 174 156 163 174 150 156 177 169 155 162 165 189 176 149 174 181 179 167 178 158 187 155 139 163 181 151 165 172 167 165 147 161 163 177 161 162 175 144 146 147 160 200 156 155 170 175 184 160 151 152 171 165 169 165 160 159 161 158 168 140 175 164 142 168 171 153 183 149 144 156 148 137 155 185 162 143 175 171 169 181 159 170 154 177 159 168 140 169 173 141 158 158 160 174 140 163 133 142 168 146 180 142 165 175 169 166 148 164 150 132 152 141 164 154 152 163 150 139 189 172 160 176 154 143 140 166 178 165 161 170 169 168 157 171 151 163 169 190 167 178 164 151 156 165 144 162 145 159 141 149 161 155 162 178 142 178 157 171 160 165 177 154 133 157 151 152 152 162 185 152 159 158 163 151 163 168 152 156 168 161 150 172 157 165 156 136 136 138 159 170 182 140 157 156 138 175 172 154 127 142 157 153 160 169 155 142 149 164 142 165 179 174 159 169 144 147 153 149 159 149 163 168 147 168 164 167 163 165 158 144 159 162 163 137 138 177 157 158 157 171 150 167 175 144 166 155 169 182 153 165 162 155 151 160 167 152 189 159 164 156 157 174 182 163 168 170 173 156 167 162 175 140 152 155 158 150 139 185 151 171 161 150 171 151 156 156 150 182 160 163 157 173 184 134 154 153 144 173 169 165 155 154 137 146 162 154 163 169 175 174 171 167 140 175 140 156 164 162 141 184 169 165 166 159 150 165 182 162 152 173 173 163 143 158 163 168 161 178 152 166 175 133 163 172 166 162 187 156 162 181 178 161 163 162 171 157 169 182 152 185 163 176 184 174 149 185 166 161 165 159 174 174 183 145 162 191 166 178 166 161 145 174 157 159 170 171 124 172 168 168 171 162 154 159 170 154 187 161 183 173 171 172 155 169 183 184 162 175 170 170 149 178 144 153 158 166 174 175 195 182 182 158 160 180 170 163 188 165 197 171 176 175 170 159 156 186 169 182 172 186 178 186 160 170 155 163 168 166 158 161 178 160 184 167 172 166 184 170 170 181 191 160 154 155 164 180 151 181 139 160 177 146 172 167 152 178 153 191 173 163 157 182 200 149 175 169 158 153 185 170 177 165 169 193 173 169 157 191 177 173 185 159 167 185 167 189 140 185 162 189 175 163 147 179 175 177 138 149 179 142 199 175 163 186 162 169 174 155 162 172 163 154 166 165 187 159 194 173 139 176 179 188 191 168 149 193 178 162 185 142 177 158 177 171 195 167 175 188 193 168 149 168 185 188 164 161 174 158 177 167 173 159 171 194 164 191 174 157 169 180 160 173 196 152 182 179 173 168 177 169 168 182 179 150 156 162 172 188 162 175 171 171 172 180 166 167 187 188 152 172 172 174 188 183 162 169 177 140 189 173 156 174 161 169 164 187 166 180 146 165 183 161 183 165 177 179 174 194 183 160 172 193 169 168 170 168 173 189 179 175 174 167 168 174 155 163 179 195 172 176 170 155 185 178 159 162 167 150 171 176 153 176 174 192 164 169 175 188 188 160 175 165 179 155 173 162 171 171 164 167 177 180 164 133 155 181 164 169 188 160 160 187 173 153 196 177 170 171 185 162 167 185 179 186 146 191 132 184 168 165 167 193 167 154 180 178 155 159 165 169 163 185 157 172 181 151 174 147 152 186 145 171 176 175 156 160 171 154 149 181 165 169 173 165 173 186 174 178 186 166 174 186 189 159 168 166 177 160 154 181 171 185 153 205 164 156 187 169 155 175 191 173 164 172 169 159 173 183 162 172 173 167 180 188 168 162 174 180 189 170 180 190 162 168 168 157 183 180 162 154 178 141 178 148 190 174 157 203 178 168 153 184 165 173 191 157 177 172 182 161 185 173 171 168 162 179 164 171 166 180 162 166 168 182 168 171 168 149 152 178 158 163 135 165 171 161 166 169 173 190 158 152 172 163 173 169 171 167 155 152 166 172 182 177 187 165 154 170 175 161 160 178 164 189 178 156 148 154 154 151 166 169 167 159 171 152 177 173 161 154 174 163 164 155 171 160 152 161 152 214 168 157 149 173 179 180 187 181 185 166 149 158 189 153 166 190 167 152 162 154 164 160 144 176 163 160 164 161 174 169 165 166 161 173 187 166 148 150 179 158 173 162 159 161 154 138 173 166 184 171 158 157 156 186 176 160 184 166 171 158 178 186 177 136 155 149 162 159 148 166 154 184 164 159 153 158 142 160 179 169 172 162 152 192 147 163 159 187 163 154 172 162 156 191 154 154 155 140 171 138 161 189 157 155 165 153 173 147 165 175 159 164 137 155 153 145 157 165 156 132 168 142 145 164 155 159 165 156 172 144 177 139 176 175 171 158 165 159 158 154 172 158 152 157 158 151 174 162 152 158 160 167 177 181 182 153 154 144 164 167 177 143 157 167 165 153 161 144 159 136 165 152 163 149 169 169 144 171 161 148 172 145 147 149 169 177 140 155 154 163 149 164 157 169 164 157 143 178 160 165 159 154 145 149 161 153 175 147 161 154 132 155 163 142 152 172 139 162 153 164 151 148 164 156 148 133 163 150 153 199 148 145 151 155 161 149 167 135 143 144 166 150 151 136 157 171 153 167 166 159 149 135 172 173 121 155 157 151 151 146 162 150 117 153 155 169 152 157 147 136 157 158 166 152 130 133 158 129 144 151 142 165 134 150 147 137 165 145 145 135 188 137 160 162 145 150 145 149 154 163 166 137 152 159 155 142 160 137 151 143 152 148 164 140 150 141 143 141 155 142 146 132 149 164 157 159 162 148 157 154 155 146 140 165 140 131 132 145 160 140 140 155 149 146 174 128 127 175 146 152 145 161 173 173 154 160 150 141 129 163 156 142 149 161 143 139 145 132 141 128 125 143 145 141 160 154 140 143 147 134 149 132 148 148 146 121 171 138 151 155 156 165 137 154 147 148 148 158 148 154 134 146 149 142 154 158 162 152 147 130 137 150 138 132 143 134 152 138 144 127 153 145 150 156 122 158 162 164 143 133 133 157 146 135 137 140 139 145 143 165 139 142 143 138 134 142 128 157 151 140 134 134 129 152 150 149 130 137 117 138 113 139 157 136 121 141 167 157 146 137 145 163 149 125 131 122 128 137 133 141 152 136 142 127 149 123 165 138 136 138 123 143 136 131 137 131 144 121 141 159 153 154 148 145 153 150 159 126 133 164 146 118 122 139 139 149 143 135 150 158 148 141 120 160 106 147 115 140 134 154 152 130 123 135 134 148 132 140 152 144 131 126 136 118 128 120 145 145 156 161 137 125 135 162 145 128 121 127 138 128 136 139 131 138 159 119 141 123 140 127 143 138 114 135 151 134 150 139 148 147 124 143 144 126 144 121 128 101 153 124 120 149 128 135 153 118 146 141 117 136 126 150 124 131 129 143 113 137 122 157 138 128 142 130 131 127 146 111 136 141 127 141 134 120 142 145 137 141 117 136 142 161 132 159 120 127 128 141 137 130 136 121 125 129 139 132 118 163 151 138 154 138 141 136 124 145 127 146 123 129 148 118 146 150 130 139 147 143 120 131 145 127 127 142 118 150 124 127 123 142 152 143 149 149 129 133 132 116 125 118 140 130 132 120 127 152 115 142 140 134 122 122 125 143 133 130 139 150 146 129 144 125 154 141 140 136 125 125 144 140 115 129 132 121 135 140 121 128 145 135 115 152 132 138 128 133 133 130 135 124 137 136 145 140 124 123 137 121 132 127 119 132 141 123 133 148 137 138 142 120 144 160 120 128 120 108 117 130 135 122 133 134 114 147 121 125 130 112 133 145 142 133 113 113 133 151 134 125 130 160 120 126 136 107 120 140 160 143 147 130 115 127 131 124 164 148 131 132 135 134 135 132 142 125 115 134 133 139 141 126 110 125 131 125 131 145 127 138 134 134 132 125 109 133 135 141 114 146 116 124 144 143 139 114 133 142 131 140 130 118 136 142 126 147 128 122 123 116 131 127 134 112 113 127 138 119 130 135 146 146 122 136 140 112 123 135 133 130 116 149 127 127 120 124 133 123 145 119 127 147 140 120 136 125 125 149 131 136 125 135 120 157 110 117 154 140 119 127 110 133 140 129 125 125 146 113 124 152 118 116 140 133 135 132 135 125 112 118 131 128 134 124 123 124 111 125 117 137 126 122 113 127 126 169 120 126 152 135 139 136 131 116 121 133 119 119 120 106 114 138 111 148 155 119 128 110 146 137 111 125 139 113 122 147 101 144 142 113 128 152 107 117 102 140 141 125 134 127 123 117 137 110 118 130 132 129 134 150 133 120 129 110 131 126 120 128 125 138 112 137 116 115 122 129 130 119 115 119 129 124 120 116 128 116 132 121 130 132 139 139 138 139 123 136 114 139 140 142 136 122 134 127 162 127 117 124 145 115 129 113 121 139 116 112 128 123 133 110 123 102 127 131 124 114 120 126 149 118 127 127 128 129 116 119 119 123 139 130 120 130 119 120 125 124 125 134 111 133 133 119 114 113 124 103 120 126 136 141 113 139 127 121 117 120 134 136 135 116 136 120 118 119 160 110 120 131 135 133 134 148 116 127 113 124 111 132 162 137 131 130 124 124 135 139 122 139 123 116 122 115 117 120 123 108 102 112 131 109 131 119 130 137 122 115 133 119 136 123 133 116 114 123 108 125 137 117 118 148 116 131 119 127 140 135 137 146 120 139 119 119 117 115 128 118 123 127 132 142 118 113 126 142 124 124 144 109 99 125 114 127 117 122 133 144 139 118 102 119 125 128 128 139 117 146 121 116 126 125 131 114 125 126 139 116 128 133 129 103 132 121 124 132 115 132 121 137 117 108 122 120 134 129 135 104 105 117 137 126 121 114 138 131 105 123 132 124 132 112 133 116 125 132 137 118 121 128 142 136 127 114 129 114 131 117 128 143 128 118 122 114 125 131 142 128 123 113 127 133 128 133 142 105 120 128 112 118 101 126 151 110 114 116 109 154 117 111 114 110 115 143 116 108 123 126 124 125 120 109 112 130 115 125 128 127 122 143 126 116 141 108 113 119 120 120 138 127 155 126 143 119 125 129 139 119 122 134 138 121 117 119 129 122 119 128 139 122 102 140 124 122 130 118 122 115 155 118 122 130 134 139 131 134 128 136 145 144 144 132 122 129 127 144 140 133 141 146 160 154 127 149 118 134 117 142 132 136 148 145 130 134 133 129 142 115 149 111 122 133 133 116 135 131 127 129 125 159 140 129 98 108 137 113 121 131 123 120 129 97 107 135 129 119 116 112 145 111 120 126 122 133 131 119 119 119 126 136 116 117 105 124 138 124 124 111 125 113 113 142 149 116 121 118 116 105 126 116 133 125 118 139 121 122 111 123 110 122 122 142 114 111 135 117 120 104 112 120 117 124 111 139 120 101 105 133 120 116 129 114 115 125 127 118 136 113 109 133 134 118 121 115 126 122 98 126 127 103 103 122 122 132 127 143 134 120 104 131 140 121 117 140 135 121 112 129 120 139 136 127 112 147 110 117 114 132 100 113 139 140 125 105 131 138 143 131 133 119 145 111 105 120 139 142 128 148 130 134 110 127 111 134 119 126 119 125 124 128 136 118 148 125 121 137 132 128 149 129 123 130 129 118 129 133 118 117 114 129 107 121 130 130 130 128 130 127 111 143 121 109 118 121 124 116 125 106 122 126 120 146 118 120 129 112 128 106 116 151 132 119 129 112 126 115 131 114 121 131 136 130 126 119 133 115 99 129 132 123 119 132 140 134 130 159 113 125 121 123 128 108 112 144 105 132 128 130 135 142 107 132 121 146 132 111 127 123 131 119 113 126 134 127 129 130 116 127 110 115 135 133 129 134 113 123 109 106 119 127 123 97 143 133 118 128 109 132 145 127 116 104 129 124 113 131 142 120 140 143 136 132 139 140 140 108 121 105 121 133 122 129 134 131 115 141 121 114 110 121 144 148 128 141 123 118 117 116 139 135 127 125 136 137 128 119 135 122 128 122 119 125 132 109 111 131 108 136 152 130 140 130 129 101 122 131 134 143 108 136 128 141 108 140 132 124 139 127 112 126 117 136 118 131 116 118 127 117 113 123 128 121 138 153 143 126 113 128 143 114 112 125 139 127 134 137 120 132 126 128 118 136 136 125 128 129 140 136 120 117 121 137 117 126 138 122 139 124 126 103 128 125 135 132 143 117 130 133 130 134 134 123 97 132 139 118 125 122 136 138 117 139 149 129 144 130 132 137 138 116 115 119 127 115 124 129 121 125 127 130 117 103 126 135 136 138 137 117 117 107 124 126 134 142 129 144 138 120 116 124 136 136 149 137 116 132 139 129 141 132 139 129 134 115 113 127 120 124 126 127 108 116 142 123 130 117 145 126 126 108 119 117 130 116 139 123 127 126 117 113 135 140 141 134 124 134 134 131 139 147 138 137 118 137 114 133 117 129 113 141 127 118 130 119 116 110 115 123 132 126 136 143 124 118 128 137 121 136 131 131 146 122 119 133 138 129 126 138 131 127 131 119 121 123 127 127 115 116 154 128 139 129 122 144 111 114 158 115 125 138 129 133 137 136 125 126 134 127 134 125 132 149 133 130 127 138 138 153 172 116 144 156 138 129 143 141 123 133 138 143 139 132 144 120 126 139 130 118 139 135 120 123 124 144 110 136 117 138 130 134 126 116 137 126 118 135 121 142 141 141 136 148 124 123 133 141 144 141 144 156 154 144 128 116 130 144 127 147 147 135 140 142 144 164 138 151 139 147 129 147 171 145 113 144 122 171 166 154 137 158 181 167 178 177 162 141 193 159 159 204 164 170 173 176 193 199 188 194 194 235 201 227 232 214 237 246 240 246 240 243 237 224 273 248 267 271 248 226 230 229 256 262 238 219 232 206 194 215 209 194 187 188 189 185 160 179 150 158 164 139 150 153 144 150 168 152 167 142 129 141 171 139 140 147 134 157 140 164 147 152 132 163 134 139 129 151 147 139 147 140 132 126 176 138 145 155 121 130 164 157 137 112 134 117 119 136 144 163 131 126 135 138 132 143 137 127 108 143 134 120 139 155 137 124 149 120 128 116 118 141 138 135 140 134 111 118 143 127 121 128 143 118 111 111 129 114 124 116 114 116 127 148 118 125 117 120 124 119 123 123 123 110 126 147 127 143 127 145 133 129 115 136 112 144 137 109 138 129 133 143 159 133 135 115 134 141 143 110 114 125 117 128 138 120 133 117 110 118 124 131 126 118 137 134 126 116 129 140 124 149 123 144 110 139 121 128 142 128 141 147 130 126 129 136 119 146 127 132 139 124 132 123 128 132 122 125 120 125 122 135 122 144 122 154 152 133 130 127 116 127 125 142 134 126 134 153 131 140 132 103 123 114 141 130 130 126 122 149 123 126 135 123 118 123 130 129 126 135 116 154 112 133 136 123 132 139 120 143 145 116 133 141 120 114 129 140 131 133 116 127 148 116 122 151 149 130 106 123 159 127 121 130 154 126 134 144 117 145 136 135 139 146 127 145 131 108 127 142 122 137 135 120 126 127 128 132 122 121 145 112 140 138 141 134 117 151 120 140 150 120 136 126 141 132 119 116 129 117 126 136 145 144 132 132 139 133 123 111 144 122 131 148 125 132 133 140 135 124 135 133 129 128 140 139 138 132 142 134 147 141 116 152 121 119 146 110 125 127 112 139 122 115 133 126 142 146 110 122 143 125 146 127 119 121 113 134 133 127 129 142 122 122 116 110 148 117 146 130 131 136 116 129 127 110 119 135 127 124 134 124 144 137 120 141 146 127 118 133 137 146 134 148 120 120 130 135 152 121 141 140 145 132 126 146 150 108 132 134 118 123 127 130 124 99 140 123 119 122 120 120 117 133 141 123 124 136 145 125 137 126 120 134 133 145 133 127 122 115 131 120 128 142 126 147 130 135 134 121 144 123 161 132 137 115 130 131 132 108 111 128 113 156 144 132 123 138 138 115 128 124 133 110 128 142 136 134 146 121 124 117 128 140 128 140 115 114 135 139 117 130 128 123 132 121 136 130 132 130 145 128 150 134 135 142 130 142 120 109 126 118 127 159 146 120 150 132 138 131 127 140 140 124 127 116 107 144 132 130 134 127 122 118 141 133 125 121 151 142 137 112 122 131 153 143 140 125 113 138 124 118 149 118 128 108 131 116 120 130 117 131 139 129 118 123 118 117 138 129 120 131 154 136 140 136 129 130 142 137 117 130 143 129 139 138 88 119 134 127 115 117 134 141 154 124 140 126 123 137 130 137 130 112 131 131 129 120 141 151 122 122 152 135 123 127 119 135 122 135 133 130 127 132 138 121 135 136 136 116 126 131 104 126 154 121 106 126 101 139 124 131 133 125 123 145 113 118 128 134 131 118 132 132 113 131 137 135 140 121 136 109 134 127 129 134 139 126 129 152 142 143 127 142 120 128 130 132 113 138 134 113 110 124 137 141 121 133 129 135 120 131 134 147 130 117 139 117 138 161 122 117 152 141 127 146 132 131 148 109 124 134 104 134 133 116 142 117 100 136 130 105 143 148 126 114 134 119 130 115 116 133 127 137 114 127 125 138 144 115 134 121 147 134 124 124 129 126 117 144 126 153 144 140 136 136 129 135 124 132 121 117 144 115 131 144 113 120 135 139 143 138 134 134 126 120 102 124 138 124 138 142 144 125 123 116 135 117 132 113 146 130 107 135 115 115 134 127 140 116 106 144 117 143 116 129 137 110 121 132 147 121 119 114 145 153 127 127 125 152 120 137 138 140 112 120 135 126 118 122 130 120 132 129 142 119 141 125 119 133 131 136 131 110 139 142 135 129 124 139 138 115 113 133 118 125 114 145 137 117 125 121 137 133 121 105 126 137 131 139 119 123 138 146 117 114 138 117 113 131 127 137 136 144 133 141 116 121 129 138 142 129 115 123 124 113 126 128 136 136 125 124 139 138 129 110 125 117 141 139 143 128 133 127 126 108 128 130 115 131 119 130 142 134 143 125 141 132 138 134 128 143 144 144 126 123 138 128 124 139 130 118 111 132 115 122 126 135 125 152 124 118 150 108 116 129 119 113 133 126 116 127 114 119 122 106 140 122 136 130 135 112 122 127 135 150 144 140 127 120 127 136 122 125 137 120 128 114 130 139 123 131 120 119 114 102 120 155 124 134 140 119 108 120 126 119 109 126 111 113 134 123 130 129 126 124 115 144 134 114 121 118 129 121 140 102 106 126 136 134 140 123 98 131 122 155 143 129 131 118 128 124 133 144 121 133 149 134 129 130 128 106 106 149 124 136 145 126 120 121 116 117 127 146 130 136 135 133 129 123 130 133 119 108 138 121 121 151 133 112 144 124 118 139 127 114 128 124 131 120 158 128 128 118 141 140 114 97 141 129 119 135 137 138 136 128 113 130 122 129 132 127 113 133 125 109 115 113 120 124 136 107 108 138 118 136 133 130 133 142 120 130 132 141 119 122 129 131 125 143 133 116 123 120 106 144 129 128 137 150 121 120 133 138 133 139 121 137 127 124 120 136 134 135 122 129 130 130 109 142 144 125 120 152 124 126 129 120 132 112 121 129 136 125 142 130 102 115 104 126 119 142 135 146 138 125 132 118 118 110 135 123 145 113 123 141 130 140 127 132 153 128 123 119 111 137 119 125 137 143 130 139 127 129 136 141 140 126 140 121 130 123 137 131 116 137 120 114 112 132 130 145 142 132 115 119 134 118 138 115 117 113 122 139 148 136 128 135 140 123 121 117 143 129 120 118 141 132 132 115 124 128 125 107 123 124 118 113 116 144 125 137 126 123 131 137 108 125 133 119 123 125 131 149 130 149 139 123 123 132 116 136 149 139 120 143 136 130 114 131 119 136 145 149 112 121 122 123 137 119 131 123 116 120 130 143 138 115 127 124 123 123 132 133 140 127 154 144 123 127 134 121 137 136 142 105 147 127 130 123 137 123 107 152 117 134 141 125 116 152 108 138 128 150 122 127 110 125 124 128 145 144 146 128 143 129 129 130 134 116 121 142 135 133 124 139 136 137 132 119 134 148 139 129 132 136 133 124 135 116 130 143 129 124 143 130 134 145 141 153 130 114 119 130 114 122 122 128 130 143 137 120 122 127 143 114 147 132 140 146 133 142 110 135 126 145 139 143 123 125 137 116 113 129 125 133 110 133 141 132 131 122 121 107 127 115 136 114 130 120 116 144 122 127 126 144 133 128 118 116 121 133 140 130 152 132 126 126 125 141 133 131 123 120 142 124 134 119 107 117 136 137 136 143 129 124 130 123 140 127 122 136 135 136 144 115 151 158 127 157 130 118 139 134 119 139 132 136 142 123 111 143 139 128 139 139 127 126 131 107 122 120 110 139 119 117 147 124 102 112 140 140 144 145 118 123 132 140 112 129 138 134 132 141 124 124 121 134 131 112 136 124 132 145 156 126 126 122 142 144 118 136 149 115 115 128 124 132 128 134 145 128 139 123 135 131 139 105 128 124 144 163 107 128 147 113 132 142 120 135 133 128 126 129 141 131 135 142 131 130 146 153 133 125 121 109 116 135 124 111 133 144 113 128 108 148 121 125 133 145 144 134 130 139 134 136 135 134 151 130 135 135 130 121 124 128 118 148 139 136 133 131 129 130 147 129 138 136 140 118 119 148 130 140 128 133 131 132 165 138 132 128 141 116 133 128 119 152 131 135 126 128 141 135 118 124 125 120 135 124 136 133 144 121 140 133 136 124 134 158 121 133 117 128 120 115 142 122 114 135 123 117 117 136 144 146 121 127 125 141 136 125 131 142 132 146 129 123 125 149 152 135 164 136 126 148 130 119 120 125 146 124 116 131 125 118 131 146 110 143 115 121 144 127 128 135 142 135 118 134 138 120 129 121 119 132 144 108 118 127 148 131 116 120 150 127 124 114 119 115 118 119 142 149 153 132 111 157 121 124 142 136 142 142 130 145 157 124 135 131 151 136 142 137 123 146 120 134 126 141 132 139 132 138 140 146 139 126 145 137 143 142 147 137 120 150 136 139 169 148 134 133 133 134 135 129 138 144 149 131 132 110 129 134 117 135 113 148 143 159 118 140 137 135 122 131 128 127 152 134 158 127 139 106 134 143 148 119 127 138 111 140 153 147 122 112 146 131 121 115 146 143 117 138 136 125 148 118 129 127 128 150 129 124 126 135 146 136 118 123 139 135 129 133 118 141 143 147 137 134 138 122 158 140 138 118 125 137 133 143 132 119 124 147 140 117 113 129 131 125 110 139 123 133 124 145 131 150 144 124 130 129 123 148 125 140 136 129 125 137 154 121 117 126 133 134 147 107 126 135 129 137 124 146 123 149 107 132 114 129 145 124 137 136 127 133 139 136 142 123 134 130 168 138 124 145 140 122 126 121 158 116 144 137 147 137 150 130 120 124 161 131 130 157 135 122 120 149 142 135 120 155 133 158 131 136 146 134 123 138 152 137 137 122 138 144 137 155 146 143 139 155 137 131 158 130 133 145 152 141 148 147 148 132 145 174 141 131 133 129 126 158 138 136 124 152 154 128 135 133 143 123 135 157 160 128 138 131 125 128 149 128 131 132 153 137 153 141 147 152 137 131 130 122 148 140 124 148 131 123 153 124 142 146 133 131 130 137 138 125 123 116 114 154 131 147 135 124 137 148 127 127 144 146 129 134 135 148 113 122 130 135 127 145 147 142 132 157 132 153 148 146 156 139 151 148 146 119 124 133 135 140 136 144 119 102 145 147 128 140 123 144 133 146 137 113 107 151 128 131 132 135 126 124 139 135 120 140 139 134 145 142 146 146 125 133 144 121 130 126 128 126 132 132 130 140 124 150 121 128 133 123 148 148 125 134 137 131 145 123 113 128 123 127 129 118 126 156 137 125 134 124 131 153 117 126 125 109 145 144 122 130 152 133 132 123 134 118 138 130 137 143 135 122 142 122 115 114 138 128 154 122 124 142 121 143 123 135 107 153 147 121 141 127 149 124 123 140 132 142 139 137 152 138 128 144 137 133 135 141 143 123 141 134 159 137 151 123 145 145 157 134 130 132 148 140 147 134 156 136 123 144 132 137 112 143 142 150 144 143 137 137 117 136 125 124 137 142 133 136 131 130 121 134 131 128 118 124 137 137 135 128 134 138 141 120 142 149 141 136 132 154 134 135 123 144 147 141 139 143 147 125 131 131 133 144 125 140 137 135 161 118 131 143 134 124 149 124 141 135 133 110 116 132 153 126 124 152 140 126 148 120 145 136 129 145 131 136 137 135 140 108 141 148 116 130 144 138 141 135 156 137 139 150 119 137 134 127 128 126 136 144 122 128 140 143 125 132 116 142 126 139 140 144 131 144 134 156 154 142 137 171 153 138 155 117 146 129 146 124 158 137 136 146 135 126 150 120 128 130 141 132 140 118 133 143 121 150 142 115 99 140 118 133 128 110 130 125 135 118 120 123 123 125 144 129 134 142 146 129 161 111 130 120 146 125 132 133 138 122 128 141 122 119 140 121 140 150 159 132 150 123 131 142 130 123 157 149 154 130 124 130 162 140 128 122 151 136 136 107 107 135 138 115 123 131 140 133 134 128 155 149 146 154 144 137 134 147 118 141 146 129 120 126 120 145 106 107 128 128 116 135 136 126 117 151 132 120 121 134 127 172 125 141 136 137 134 133 136 152 142 153 143 136 122 140 150 142 111 132 152 149 156 133 134 117 120 135 135 137 141 124 132 112 124 123 112 135 126 133 116 128 129 149 114 148 123 125 116 124 127 127 140 122 124 129 147 127 140 132 121 137 133 122 136 129 132 125 134 128 129 136 135 145 145 126 140 145 143 144 136 132 122 122 147 146 119 119 148 121 156 129 108 117 128 156 125 153 132 136 151 115 164 128 133 146 131 144 154 132 149 140 128 141 142 138 123 131 137 168 131 121 132 128 139 120 152 147 132 153 130 126 129 143 137 142 128 142 144 128 128 129 125 138 131 130 137 137 132 136 133 131 117 131 143 145 130 135 122 135 122 125 135 132 131 127 124 143 116 156 120 131 157 127 138 141 140 124 144 139 124 138 128 115 127 134 115 127 132 133 127 134 131 148 128 136 134 124 139 142 137 168 122 156 138 127 138 150 124 135 131 124 150 135 128 145 121 134 135 121 150 139 131 128 132 122 150 151 141 114 98 126 117 133 127 144 130 139 117 133 138 142 140 161 126 137 129 144 136 145 143 120 142 134 130 153 122 128 131 130 116 139 140 136 123 134 135 147 136 147 121 139 147 124 126 126 134 146 126 127 141 158 127 162 136 154 132 139 134 149 129 123 141 126 133 140 146 123 102 144 149 135 132 108 129 128 131 121 129 154 152 137 117 139 115 146 139 145 127 131 130 138 127 123 126 140 135 141 143 126 137 128 139 119 131 136 131 138 125 120 144 130 149 145 123 134 136 134 133 114 124 127 116 114 145 105 127 124 135 137 139 133 123 121 150 135 124 122 140 140 135 145 118 113 142 127 139 121 113 139 138 120 130 126 126 141 134 142 142 144 134 123 129 144 133 136 139 142 145 122 147 129 133 130 132 127 117 112 122 131 142 140 143 142 109 140 126 122 121 143 117 121 126 139 118 111 145 118 138 136 138 137 144 125 141 145 153 140 120 144 145 138 127 120 131 132 110 146 145 126 141 127 117 143 123 135 141 131 138 141 154 134 124 153 147 138 130 115 121 147 142 139 132 132 133 136 149 125 125 126 147 138 124 140 139 113 141 143 133 148 110 134 150 120 130 138 145 147 130 141 132 154 133 125 130 130 121 132 125 132 130 129 130 137 133 132 147 150 139 123 129 135 116 119 142 126 132 128 135 136 143 134 143 138 137 114 129 134 138 128 118 126 131 128 139 130 124 128 111 116 138 141 132 164 136 124 128 134 144 121 119 155 137 140 138 133 122 148 122 117 152 135 128 121 117 147 133 151 136 128 138 120 149 129 120 140 148 130 133 139 151 139 143 142 117 137 126 128 144 117 110 132 136 125 125 124 128 129 135 153 133 155 117 133 138 131 105 120 143 120 144 147 128 127 141 139 140 123 147 126 134 142 148 142 131 129 144 122 111 149 139 146 136 133 139 107 121 136 130 134 146 126 131 134 133 129 146 123 115 116 143 124 140 149 136 138 152 144 107 138 131 127 136 114 140 128 141 136 138 128 127 148 148 111 137 124 118 126 129 115 131 135 110 140 131 121 134 140 119 139 149 127 143 130 123 122 134 130 140 128 144 122 145 125 156 119 127 126 123 115 128 122 130 127 124 144 142 130 115 135 143 129 95 128 125 130 152 125 133 154 106 123 119 129 123 117 130 138 137 123 130 142 111 130 124 128 138 121 124 128 138 135 124 108 121 145 151 121 136 120 137 135 130 128 122 135 153 129 101 135 115 133 142 116 127 126 121 105 131 135 127 130 125 124 134 127 110 143 136 125 124 136 129 118 124 114 139 131 153 113 115 131 132 124 130 138 141 142 122 149 131 130 135 144 136 110 144 109 138 157 127 146 125 144 131 118 115 127 129 136 134 122 140 130 134 141 139 119 153 131 111 127 129 118 125 158 126 126 147 130 102 135 122 136 143 136 122 125 127 114 158 128 128 129 124 131 115 114 124 121 149 115 131 144 136 124 122 108 133 131 142 135 129 141 111 135 108 146 143 118 126 143 135 148 117 147 116 139 121 140 130 138 119 123 148 125 138 108 144 125 122 149 124 113 120 129 149 133 139 145 144 121 130 134 123 154 139 122 133 134 138 114 147 135 119 137 120 144 144 139 117 131 130 133 133 124 128 116 126 133 145 147 136 146 108 146 117 122 131 120 121 128 130 130 138 137 134 122 135 132 127 135 127 135 132 134 128 138 120 111 108 130 133 148 126 135 113 131 113 124 123 134 131 130 121 123 134 122 138 119 141 135 128 128 127 141 145 134 119 139 129 119 134 119 122 150 122 130 118 132 128 134 116 146 138 133 150 119 146 113 144 116 120 121 120 158 129 124 113 127 131 147 127 122 130 145 138 146 126 116 147 129 149 139 138 126 144 138 127 136 135 148 157 104 116 130 115 132 130 151 119 134 132 133 126 136 132 130 137 107 130 125 119 112 134 138 134 139 137 112 135 130 109 117 146 115 132 117 134 139 131 123 128 125 140 132 134 128 143 127 127 135 145 139 124 118 135 134 98 128 149 127 147 121 121 127 142 144 125 119 130 130 115 124 120 127 140 131 108 137 125 127 136 127 113 136 112 126 133 126 136 155 133 142 131 144 152 108 119 147 109 138 126 147 123 117 133 153 123 133 137 133 123 98 149 146 124 130 155 153 137 150 140 125 109 138 143 128 119 116 127 132 141 137 115 113 133 155 118 136 131 136 133 154 130 151 147 135 136 133 138 155 125 153 138 127 129 125 153 127 146 157 140 141 139 134 137 152 145 152 154 148 126 134 169 144 146 150 140 157 137 133 150 172 148 156 142 152 144 139 149 155 157 152 125 148 159 145 138 140 150 161 170 158 131 142 123 132 147 149 142 159 124 123 131 148 136 137 136 137 135 139 169 131 131 153 146 147 161 142 141 134 141 155 149 137 121 130 140 152 121 121 145 128 128 127 126 122 112 129 132 124 144 136 129 126 135 137 133 144 137 137 139 127 138 130 133 119 135 122 132 119 141 128 121 121 135 132 141 122 115 127 115 146 112 137 122 128 121 119 131 134 122 139 136 128 131 129 121 127 135 119 148 135 132 141 122 138 113 135 123 148 114 133 136 119 128 122 114 132 102 119 117 121 124 135 131 131 130 142 144 110 125 130 115 120 146 126 116 111 117 125 114 124 143 138 127 132 134 124 136 117 119 134 153 122 134 126 135 116 126 117 122 134 128 145 121 139 136 119 118 133 138 143 148 141 132 133 135 133 134 134 127 127 106 127 134 117 127 110 113 116 131 127 135 150 137 137 117 128 110 113 130 142 118 131 120 121 131 126 121 122 120 135 146 136 123 129 136 112 125 135 140 128 125 122 128 119 138 118 124 129 126 117 140 134 127 117 139 120 142 109 145 135 119 111 125 142 127 122 140 146 136 142 136 134 137 122 122 148 146 122 126 124 142 127 136 142 128 130 119 127 121 127 124 116 129 112 156 110 123 130 104 137 137 125 141 136 130 105 146 140 108 122 130 120 132 124 141 135 149 144 125 126 140 121 115 136 128 110 143 145 131 145 123 136 135 119 129 141 112 134 144 110 134 121 112 124 106 129 129 121 128 135 128 118 135 132 134 132 141 126 116 141 125 123 114 132 130 110 120 128 118 128 148 139 126 139 133 112 127 140 115 145 135 126 161 148 126 126 124 108 131 133 120 112 128 152 117 131 153 119 119 116 132 119 118 143 127 144 127 116 115 141 134 123 134 117 127 127 151 142 113 136 141 121 140 140 127 132 153 128 134 132 117 115 129 143 137 149 128 139 128 123 135 120 144 123 111 127 136 149 126 120 132 118 133 153 138 147 135 114 124 124 118 122 128 117 127 130 125 140 133 120 114 131 123 139 110 131 118 123 135 114 130 131 133 139 137 142 118 103 127 152 126 136 109 146 110 148 141 124 127 119 145 145 110 122 129 130 143 136 124 115 108 140 154 128 133 118 145 123 141 111 109 111 127 128 145 126 107 122 119 129 144 125 134 139 121 134 130 119 137 121 122 124 141 133 117 142 136 131 130 116 141 131 129 140 123 142 110 139 135 135 141 132 131 122 123 112 123 118 147 120 129 127 112 131 136 118 141 122 116 128 136 142 117 147 111 126 150 130 110 130 118 122 174 144 125 149 137 131 133 110 104 124 140 117 123 120 142 124 111 147 136 138 134 130 128 126 143 151 134 121 138 129 143 125 139 142 132 129 126 124 112 132 99 130 142 138 149 144 125 130 130 144 127 120 135 141 124 129 115 135 130 130 127 118 121 122 134 129 105 139 127 112 141 136 141 125 145 136 121 125 148 120 144 143 131 100 102 117 124 135 142 123 122 135 150 141 143 135 131 120 131 129 152 130 120 148 108 131 126 136 128 149 133 116 147 119 126 119 125 113 113 142 129 130 131 121 142 136 105 129 117 129 123 138 140 149 127 159 122 122 128 136 121 123 120 139 120 137 134 105 116 118 129 133 113 115 125 160 128 123 137 133 114 115 122 136 114 138 120 109 121 133 120 118 120 134 129 144 127 126 129 131 125 118 127 130 119 139 128 122 137 118 144 129 143 114 139 142 103 118 127 131 149 147 136 122 114 122 117 113 127 140 112 128 138 131 113 131 141 117 138 120 131 130 134 130 123 144 118 140 121 142 143 122 124 123 121 144 139 128 134 124 123 118 117 128 117 142 141 122 115 129 134 124 110 132 149 126 135 124 127 141 126 129 144 121 154 142 126 142 123 133 118 137 137 127 125 145 131 118 131 139 139 123 125 134 124 130 148 130 137 131 142 134 116 126 128 119 118 122 130 143 154 107 145 136 122 121 125 122 134 126 147 125 146 124 121 149 131 122 144 134 131 158 133 141 122 138 132 123 122 123 135 140 134 137 118 132 120 127 137 152 118 141 113 144 135 120 123 123 120 106 129 122 113 114 137 128 143 139 131 146 130 113 150 125 152 129 144 131 126 134 126 131 129 138 137 136 133 137 130 128 125 137 121 133 130 127 149 125 138 152 138 152 134 149 140 134 133 119 152 130 144 130 123 124 140 114 127 119 166 145 127 136 130 132 113 152 141 117 153 134 142 141 123 110 129 134 148 125 122 126 116 135 128 139 136 139 145 128 130 116 148 132 114 129 139 144 142 112 133 119 129 138 125 128 151 143 146 155 132 146 117 131 115 120 136 139 142 126 122 125 138 110 116 144 141 129 126 105 131 138 136 144 113 135 125 126 132 134 123 123 111 133 119 132 137 118 122 119 142 123 121 146 118 144 141 121 115 120 145 131 128 119 128 137 115 122 137 113 107 135 113 138 142 138 121 115 132 130 126 111 130 124 144 124 149 134 132 130 129 122 119 123 131 138 123 145 115 152 122 128 144 131 115 152 129 106 133 141 129 140 134 135 137 132 134 155 129 143 127 152 148 128 133 141 149 108 148 131 144 151 147 120 128 147 135 119 145 123 122 126 131 131 129 133 132 141 152 128 121 114 139 142 131 137 138 134 128 125 132 133 104 128 157 140 150 133 105 133 122 104 117 136 122 131 128 113 138 119 109 136 141 153 134 131 129 137 133 127 125 125 121 135 133 119 131 133 112 129 143 123 126 144 133 123 121 134 120 146 130 132 126 144 146 134 121 125 129 127 132 134 115 121 129 132 139 139 116 135 126 166 133 133 127 141 130 117 108 131 116 130 139 143 122 145 129 134 135 125 126 122 134 139 128 145 119 160 132 129 130 138 130 121 121 130 130 118 137 136 140 117 146 129 143 109 145 137 121 143 111 138 130 142 127 134 147 117 156 124 108 139 104 127 145 152 124 143 128 108 122 127 114 143 116 126 144 156 120 138 113 127 152 123 133 141 134 126 128 134 127 135 141 144 125 128 113 129 138 132 137 138 141 147 146 121 120 127 133 140 123 140 155 135 108 122 126 128 127 128 145 121 145 109 105 137 121 122 117 135 119 139 124 143 136 122 137 142 112 148 113 131 126 119 124 122 133 132 143 130 148 115 137 131 105 101 118 143 109 126 133 125 128 135 130 128 120 125 122 138 128 122 116 136 144 139 117 133 154 115 142 140 115 152 148 117 139 118 113 135 128 135 117 163 127 108 118 148 120 136 133 114 116 139 134 107 123 131 143 119 124 143 129 125 119 123 128 96 123 139 121 120 122 105 133 113 147 126 151 137 166 118 138 125 129 109 133 142 127 127 134 160 129 106 140 123 131 132 117 127 141 133 143 140 137 118 137 117 125 118 133 136 139 118 112 128 138 138 124 130 135 143 131 141 125 156 125 128 125 126 113 125 125 110 135 133 123 111 118 123 144 114 147 101 145 127 119 147 139 147 127 134 133 152 148 140 116 123 129 143 154 138 120 142 112 129 147 113 156 142 132 121 110 135 128 137 137 117 131 131 125 130 132 132 105 120 134 104 137 131 134 120 122 118 127 107 143 119 135 144 139 130 147 138 129 131 137 119 149 133 121 140 159 139 126 122 115 141 125 145 148 144 132 139 144 153 132 127 126 134 135 130 134 142 118 146 145 148 148 150 148 138 133 132 150 153 133 138 145 152 148 136 122 139 129 140 134 146 143 138 133 137 154 126 138 146 140 152 135 125 149 132 143 156 169 140 120 126 137 154 138 140 135 121 148 129 130 126 133 137 143 129 121 135 131 121 124 125 139 134 125 131 134 127 136 125 162 148 151 112 136 130 133 155 133 146 117 144 140 133 128 147 136 131 137 133 122 137 127 140 120 126 104 133 135 121 138 139 130 128 133 111 147 135 151 138 141 112 136 142 140 141 142 134 153 123 126 147 151 134 134 126 128 131 130 130 137 127 116 111 131 134 136 140 145 122 127 132 137 135 149 150 131 126 147 127 140 121 128 116 111 121 161 124 137 135 130 139 169 108 112 105 123 142 132 155 131 119 126 127 128 121 151 110 129 136 130 121 151 125 134 131 121 114 123 151 122 131 155 135 133 136 121 126 120 117 137 127 136 120 139 140 144 110 136 141 133 128 134 123 146 143 138 133 135 141 122 133 143 127 134 118 143 129 146 126 135 124 153 117 127 141 134 128 136 138 125 112 136 134 132 139 127 125 120 133 130 143 133 154 146 156 132 131 126 121 141 128 129 127 128 143 117 153 117 140 138 133 124 118 132 128 141 125 160 123 122 135 114 117 118 140 156 145 124 124 131 139 143 152 134 129 125 133 100 151 127 129 114 131 123 152 145 142 116 157 121 148 143 115 129 146 113 125 122 148 131 133 151 143 138 113 147 125 131 133 128 124 144 123 150 124 137 136 143 125 146 125 142 134 132 132 108 135 123 132 147 121 136 126 125 126 132 131 122 125 124 126 133 120 133 137 120 138 138 131 113 154 151 130 130 151 122 147 151 140 120 132 113 137 134 141 129 134 126 113 123 138 137 117 118 148 157 126 117 138 127 136 122 136 136 119 124 117 136 128 142 134 123 129 128 126 115 126 128 126 140 151 129 122 130 140 125 134 146 137 134 127 123 146 143 128 150 119 121 127 146 119 146 124 142 152 117 128 125 144 119 122 125 148 140 138 139 130 134 151 115 130 140 133 136 146 122 138 141 104 112 121 114 105 128 133 137 131 134 131 127 131 125 99 128 128 150 133 131 141 145 147 122 117 131 147 124 139 122 135 122 147 122 115 146 132 136 130 142 126 137 129 135 116 130 118 123 122 145 116 128 125 152 140 139 125 110 111 144 134 120 116 118 147 119 109 149 135 122 130 116 157 127 136 136 157 128 157 136 122 121 121 135 161 117 134 136 142 113 132 130 116 127 124 146 121 98 129 125 147 133 138 140 123 145 118 128 123 153 139 128 151 126 140 112 132 127 158 129 141 138 137 141 132 149 114 131 122 142 125 140 127 152 124 121 138 147 129 126 125 122 115 132 129 121 144 115 125 146 130 141 126 141 145 135 136 129 125 129 129 128 134 124 139 130 146 133 116 141 131 115 119 111 111 132 143 131 122 129 134 112 116 128 96 133 119 144 127 134 116 130 128 128 151 122 131 131 136 131 135 138 120 131 123 136 111 127 127 157 141 117 130 130 132 126 146 112 111 113 123 105 141 135 140 128 148 141 128 125 110 160 143 120 108 112 144 132 126 145 133 128 142 129 114 135 110 119 145 109 158 130 108 144 116 153 137 139 119 117 119 154 122 119 129 126 123 134 140 128 129 135 116 142 128 134 131 133 141 113 131 124 125 109 127 141 121 126 113 130 130 161 111 130 136 136 139 135 137 135 134 135 129 115 135 142 115 148 130 134 134 123 133 122 117 117 123 98 136 124 127 116 146 119 135 109 156 135 100 126 128 140 117 123 147 137 127 134 115 127 128 154 125 115 126 133 134 131 126 140 129 109 138 151 131 141 127 130 141 136 150 138 118 133 122 121 147 114 115 118 134 137 138 121 129 122 121 132 140 148 137 144 135 118 144 129 143 134 137 123 145 129 119 112 141 150 129 131 125 147 141 117 133 135 140 128 125 131 126 140 142 114 141 112 117 125 108 112 125 131 114 116 141 123 104 129 137 117 120 137 145 129 116 153 135 139 129 140 125 151 151 115 149 145 110 149 123 119 121 142 137 142 140 125 138 130 119 123 149 149 138 126 142 138 149 137 130 131 119 114 134 151 133 122 151 123 144 137 131 111 137 142 156 122 122 134 124 133 125 115 133 159 128 144 146 115 134 132 138 120 119 137 141 123 122 135 128 128 140 131 132 122 122 154 133 129 135 134 126 130 150 126 128 138 142 137 120 126 131 126 130 138 118 124 117 133 129 142 148 142 114 132 130 144 146 131 120 150 130 123 159 117 122 147 120 127 139 117 127 121 133 119 140 140 132 120 133 142 166 121 141 125 128 154 140 130 143 134 151 138 143 154 135 132 135 144 149 119 129 133 142 150 129 137 125 126 117 122 110 100 140 119 137 126 139 129 157 131 129 126 114 146 141 143 142 132 127 134 141 129 128 155 137 130 158 137 125 135 124 120 106 123 127 137 124 148 137 118 126 150 133 127 130 152 125 141 142 128 133 137 153 139 150 148 150 147 135 154 136 126 136 132 154 143 107 137 136 126 139 125 134 143 136 145 129 134 135 127 143 119 145 137 117 136 136 110 145 136 117 124 113 129 122 133 144 137 128 143 139 142 149 141 118 143 131 132 148 127 129 140 147 133 137 130 125 142 136 143 136 139 142 122 132 135 132 130 139 119 144 141 137 114 138 138 131 152 122 140 151 144 139 123 143 136 122 148 149 133 143 135 115 150 129 123 120 114 131 116 124 119 132 111 124 116 132 139 133 127 105 136 137 125 128 154 150 131 132 114 134 130 120 150 143 139 121 140 139 129 142 104 118 138 125 144 142 143 133 115 142 138 145 139 140 149 129 134 117 127 141 105 132 140 144 133 144 155 161 113 132 126 134 135 167 134 129 114 133 140 107 130 126 145 144 132 139 119 131 135 128 152 140 142 106 133 145 134 123 138 124 137 122 135 133 145 136 140 161 119 135 136 124 140 140 158 146 133 147 119 131 146 131 121 113 137 145 130 135 115 128 135 118 116 144 119 139 141 132 136 149 127 135 141 125 137 144 149 136 140 118 149 126 125 130 150 138 141 138 172 137 135 134 135 111 128 153 116 122 131 123 139 140 115 128 119 125 141 133 142 156 141 132 137 134 134 124 148 126 127 126 135 128 155 145 145 127 148 138 119 126 146 103 130 142 135 130 145 131 115 128 132 140 141 127 131 146 125 145 127 127 128 125 131 124 140 113 125 134 135 125 135 133 131 158 142 133 135 134 141 124 150 133 127 123 143 157 119 143 133 129 159 124 131 143 128 137 125 127 105 156 145 148 115 141 134 118 125 145 150 138 141 126 131 136 127 120 132 132 144 116 131 164 147 139 137 135 123 138 126 143 116 141 140 137 117 134 121 132 136 148 119 127 147 132 127 149 143 129 150 144 146 131 121 117 116 141 136 110 133 144 114 146 138 137 136 150 137 143 149 156 130 132 117 132 133 130 137 152 121 128 133 143 141 138 143 148 121 112 130 124 147 148 119 107 155 134 131 152 124 132 143 141 142 142 155 115 129 119 135 141 154 121 147 136 131 124 135 136 143 133 149 113 139 114 120 139 142 110 136 156 120 129 139 135 151 139 157 163 148 129 131 133 154 141 144 134 130 132 153 130 145 146 132 112 135 122 135 140 141 126 129 154 120 135 152 122 139 147 137 141 132 127 147 153 114 147 161 139 163 152 119 133 140 135 126 128 141 143 152 135 132 130 131 126 141 118 146 131 135 166 141 150 121 121 128 148 124 116 136 141 156 162 135 125 143 132 137 142 132 171 144 152 144 137 151 143 147 132 144 135 140 124 151 140 148 120 141 158 137 115 148 132 144 139 152 136 141 137 149 155 112 158 145 142 156 124 141 128 124 127 154 145 146 137 138 135 134 151 159 145 136 150 154 118 128 151 105 165 145 147 128 140 152 153 144 142 129 134 146 139 129 129 144 145 135 135 146 145 122 142 138 169 145 139 160 116 117 134 134 129 157 163 143 118 130 147 147 144 151 145 150 143 143 158 163 135 128 132 140 144 146 142 162 131 126 145 155 124 140 135 146 135 156 135 145 123 130 135 147 132 136 138 161 138 148 135 111 119 128 132 136 161 142 132 126 138 139 153 129 136 140 128 139 145 138 159 131 136 124 159 162 127 126 118 145 138 165 128 144 136 130 149 145 136 130 135 132 143 138 137 148 141 93 132 109 147 120 141 129 128 137 127 123 134 122 145 145 161 160 130 153 125 144 140 125 145 141 160 124 155 137 149 107 157 141 145 151 152 143 168 147 123 133 139 126 140 147 143 147 129 142 143 130 143 129 136 119 129 126 149 98 147 136 165 133 134 146 142 144 138 123 133 134 152 136 166 130 135 143 134 156 135 139 137 137 140 140 141 140 138 132 122 134 144 141 115 131 136 146 123 159 135 116 139 143 138 147 127 135 163 136 134 154 109 138 154 126 134 122 126 154 140 123 152 140 122 140 131 135 147 136 133 125 134 123 135 127 143 149 134 152 126 125 153 146 141 127 132 126 137 127 138 152 158 131 122 124 150 128 136 135 115 104 151 161 143 150 132 135 145 139 123 134 144 136 132 139 122 133 134 140 152 106 116 115 129 141 128 141 119 144 134 158 119 164 151 124 128 126 138 141 153 140 123 123 141 139 130 121 123 141 126 134 123 131 135 135 142 135 140 134 128 130 143 130 127 117 137 127 133 152 140 146 115 151 129 137 131 129 133 144 140 130 141 149 128 147 145 121 147 149 171 134 117 167 159 129 147 131 124 123 170 131 130 127 146 137 146 150 137 121 138 134 130 133 140 137 140 127 137 164 151 137 146 143 128 117 151 118 127 128 125 132 139 140 124 123 140 132 144 122 106 146 146 139 137 133 108 151 132 150 132 151 136 128 145 137 128 127 137 154 160 121 150 128 154 140 122 150 130 141 141 130 153 129 137 141 136 140 137 157 129 154 156 127 127 138 146 131 146 111 120 117 131 136 131 124 120 136 138 135 140 136 146 127 125 128 141 128 140 122 121 132 148 147 148 148 140 132 132 137 127 138 130 130 138 131 144 136 156 123 116 161 130 129 130 141 125 121 139 119 119 159 139 142 123 121 127 155 110 119 131 144 116 117 138 124 118 139 122 137 144 132 121 132 140 135 133 131 135 136 119 132 151 120 145 133 128 133 130 135 134 115 129 136 135 158 130 147 143 145 126 128 131 144 133 136 130 122 147 115 129 134 151 133 118 142 137 143 136 143 128 141 145 132 146 134 143 139 141 140 146 134 137 136 152 136 125 124 150 149 142 148 126 133 140 140 116 123 143 121 150 140 135 140 148 164 142 110 148 147 129 123 130 146 152 132 159 130 128 145 152 149 137 135 138 146 117 143 128 143 144 126 126 137 121 151 134 127 132 144 144 140 160 149 133 157 122 138 152 128 138 126 143 143 136 131 142 145 135 167 122 127 138 128 156 138 131 123 131 115 128 126 127 124 142 134 138 115 131 113 141 136 134 120 121 137 129 140 141 128 143 125 147 141 130 155 118 127 132 140 121 135 129 152 147 151 151 145 145 132 135 137 126 152 118 138 129 143 118 143 135 138 136 150 126 152 157 153 141 150 127 142 127 132 136 155 125 132 138 161 135 121 121 142 136 135 122 132 128 119 163 151 123 135 131 139 110 142 154 149 133 119 134 133 140 154 150 122 143 137 125 137 142 144 139 154 122 138 121 121 150 129 154 134 140 143 126 130 135 145 129 141 152 131 126 123 134 143 145 122 134 142 135 133 123 126 131 129 127 124 130 113 119 123 133 110 150 143 147 146 148 122 123 127 139 146 119 129 117 142 131 138 127 124 133 150 160 147 130 146 151 136 131 130 161 129 124 149 122 119 163 129 143 128 129 151 138 151 135 141 146 151 143 128 143 141 130 131 142 146 127 128 141 133 134 139 142 134 148 120 110 119 118 134 161 129 125 150 135 133 119 130 131 138 145 146 124 132 126 116 124 130 149 120 141 147 129 134 118 122 121 148 127 128 125 146 141 148 136 133 131 121 157 135 113 130 130 128 146 143 135 124 152 139 128 140 149 133 152 157 148 136 129 117 128 147 128 136 148 129 127 132 140 123 125 144 118 132 134 124 121 136 115 131 140 139 155 149 121 161 140 121 127 124 136 147 144 126 151 151 156 144 135 141 134 137 140 125 121 148 128 124 133 145 134 135 144 145 128 129 120 147 137 142 132 142 141 156 142 144 136 133 129 114 135 131 130 142 143 122 130 143 146 126 119 148 144 161 157 127 123 137 131 128 124 158 145 130 146 132 141 140 148 136 130 108 142 135 138 123 151 146 119 135 145 165 143 145 139 149 131 127 140 108 141 143 159 142 156 139 143 148 143 122 129 124 114 136 131 138 130 133 145 161 139 119 131 144 132 148 134 139 117 130 139 146 137 150 142 149 138 138 127 146 113 129 141 126 135 136 129 150 135 141 141 132 130 151 148 121 135 137 139 134 135 132 123 149 158 119 140 145 145 149 143 143 123 112 138 159 153 117 128 132 136 158 132 119 165 122 139 126 131 132 119 136 147 135 165 147 150 147 134 138 130 112 134 130 142 133 131 132 120 149 131 143 129 140 135 117 131 134 147 140 138 135 122 138 132 137 122 143 147 123 114 158 137 132 148 121 117 167 115 126 131 142 146 139 135 128 121 132 144 135 148 105 138 151 122 131 134 139 142 152 119 139 144 132 145 120 164 133 152 126 119 128 119 146 128 132 144 114 138 155 126 155 123 131 136 136 140 150 134 122 149 151 152 147 142 151 134 131 150 132 153 129 136 143 128 134 139 133 134 140 134 114 132 143 132 138 135 123 135 139 142 140 157 144 143 128 126 118 112 125 143 134 139 150 147 121 146 124 127 127 93 116 145 118 133 145 155 133 137 126 112 163 146 121 146 133 136 136 121 165 154 119 175 140 139 147 142 135 148 142 134 122 140 131 141 137 126 122 135 135 130 128 147 135 141 136 129 121 135 122 144 130 135 159 141 140 160 142 130 120 141 116 124 148 117 155 121 139 130 119 129 132 134 123 138 127 132 145 122 130 143 124 148 123 149 146 114 164 127 107 126 139 156 135 130 139 129 150 149 142 147 150 139 128 142 135 138 130 138 123 127 154 126 133 125 127 159 144 126 151 121 123 132 132 129 130 144 148 128 120 124 140 132</counts>
			</dataPoints>
		</scan>
	</xrdMeasurement>
</xrdMeasurements>