File: data/XRD/CS-Vakuum/XG-pre/W6824-3A_CS_Vakuum_pre.xrdml
<xrdMeasurements xmlns="http://www.xrdml.com/XRDMeasurement/2.1" xmlns:xsi="http://www.w3.org/2001/XMLSchema-instance" xsi:schemaLocation="http://www.xrdml.com/XRDMeasurement/2.1 http://www.xrdml.com/XRDMeasurement/2.1/XRDMeasurement.xsd" status="Completed">
	<comment>
		<entry>Configuration=Factory configuration, Owner=User-1, Creation date=7/8/2013 4:01:53 PM</entry>
		<entry>Goniometer=PW3050/65 (Theta/2Theta); Minimum step size 2Theta:0.0001; Minimum step size Omega:0.0001</entry>
		<entry>Sample stage=MRD Cradle; Minimum step size Phi:0.01; Minimum step size Chi:0.01; Minimum step size X:0.01; Minimum step size Y:0.01; Minimum step size Z:0.001</entry>
		<entry>Diffractometer system=XPERT-PRO</entry>
		<entry>Measurement program=C:\PANalytical\Data Collector\Programs\Jorrit\2thom\_absolute_2th-om_10-130deg_PIXscan_56min.xrdmp, Identifier={15BCCF57-2807-42BD-B5B9-ECC0B3DC9284}</entry>
		<entry>Batch program=C:\PANalytical\Data Collector\Programs\SimonL\batch8x_2thom_10-130°_z9.1_x0,10,20,30_y20,30,40,50_57min.xrdmp, Identifier={9A1B954C-70C5-4DE2-A2B5-D0000261ED0F}</entry>
	</comment>
	<sample type="To be analyzed">
		<id></id>
		<name></name>
		<preparedBy></preparedBy>
	</sample>
	<xrdMeasurement measurementType="Scan" status="Completed" sampleMode="Reflection">
		<comment>
			<entry>_absolute_2th-om_10-130deg_PIXscan_56min</entry>
			<entry>PHD Lower Level = 4.83 (keV), PHD Upper Level = 11.27 (keV)</entry>
		</comment>
		<usedWavelength intended="K-Alpha 1">
			<kAlpha1 unit="Angstrom">1.5405980</kAlpha1>
			<kAlpha2 unit="Angstrom">1.5444260</kAlpha2>
			<kBeta unit="Angstrom">1.3922500</kBeta>
			<ratioKAlpha2KAlpha1>0.5000</ratioKAlpha2KAlpha1>
		</usedWavelength>
		<incidentBeamPath>
			<radius unit="mm">320.00</radius>
			<xRayTube id="1010048" name="Empyrean Cu LFF HR (9430 033 7310x) DK442154">
				<tension unit="kV">40.0</tension>
				<current unit="mA">40.0</current>
				<anodeMaterial>Cu</anodeMaterial>
				<focus type="Line">
					<length unit="mm">12.0</length>
					<width unit="mm">0.4</width>
					<takeOffAngle unit="deg">4.2</takeOffAngle>
				</focus>
			</xRayTube>
			<xRayMirror id="27010001" name="Inc. Beam Cu W/Si (parabolic MRD)" hybrid="false">
				<crystal type="Graded" shape="Parabolic">W/Si</crystal>
				<acceptanceAngle unit="deg">0.800</acceptanceAngle>
				<length unit="mm">60.0</length>
			</xRayMirror>
			<sollerSlit id="21010002" name="Soller slits 0.04 rad.">
				<opening unit="rad">0.0400</opening>
			</sollerSlit>
			<mask id="22030008" name="Fixed mask 4 mm">
				<distanceToSample unit="mm">220.00</distanceToSample>
				<width unit="mm">4.00</width>
			</mask>
			<divergenceSlit id="22010007" name="Fixed slit 1/8°" xsi:type="fixedDivergenceSlitType">
				<distanceToSample unit="mm">220.00</distanceToSample>
				<height unit="mm">0.19</height>
			</divergenceSlit>
		</incidentBeamPath>
		<diffractedBeamPath>
			<radius unit="mm">320.00</radius>
			<sollerSlit id="21010002" name="Soller slits 0.04 rad.">
				<opening unit="rad">0.0400</opening>
			</sollerSlit>
			<receivingSlit id="22010001" name="Fixed slit 4°">
				<height unit="mm">5.88</height>
			</receivingSlit>
			<detector id="7010017" name="PIXcel3D 1x1 detector" xsi:type="areaDetectorType">
				<phd unit="%">
					<lowerLevel>30.0</lowerLevel>
					<upperLevel>70.0</upperLevel>
				</phd>
				<mode>Scanning</mode>
				<activeChannelsEquatorial>255</activeChannelsEquatorial>
				<activeChannelsAxial>255</activeChannelsAxial>
				<pitchEquatorial unit="mm">0.05500</pitchEquatorial>
				<pitchAxial unit="mm">0.05500</pitchAxial>
				<readOutPeriod unit="seconds">0.135</readOutPeriod>
			</detector>
		</diffractedBeamPath>
		<scan appendNumber="0" mode="Continuous" scanAxis="2Theta-Omega" status="Completed">
			<header>
				<startTimeStamp>2024-10-04T14:04:34+02:00</startTimeStamp>
				<endTimeStamp>2024-10-04T15:00:40+02:00</endTimeStamp>
				<author>
					<name>PRO-MRD</name>
				</author>
				<source>
					<applicationSoftware version="6.1b">Data Collector</applicationSoftware>
					<instrumentControlSoftware version="7.0E 20130304">XPERT-PRO</instrumentControlSoftware>
					<instrumentID>0000000011142674</instrumentID>
				</source>
			</header>
			<dataPoints>
				<positions axis="2Theta" unit="deg">
					<startPosition>9.99826193</startPosition>
					<endPosition>129.99755682</endPosition>
				</positions>
				<positions axis="Omega" unit="deg">
					<startPosition>4.99913096</startPosition>
					<endPosition>64.99877841</endPosition>
				</positions>
				<positions axis="Phi" unit="deg">
					<commonPosition>0.00</commonPosition>
				</positions>
				<positions axis="Chi" unit="deg">
					<commonPosition>0.00</commonPosition>
				</positions>
				<positions axis="X" unit="mm">
					<commonPosition>0.00</commonPosition>
				</positions>
				<positions axis="Y" unit="mm">
					<commonPosition>-50.00</commonPosition>
				</positions>
				<positions axis="Z" unit="mm">
					<commonPosition>9.300</commonPosition>
				</positions>
				<commonCountingTime unit="seconds">32.895</commonCountingTime>
				<counts 508 473 498 534 459 472 493 480 493 495 448 499 480 468 497 523 473 509 439 479 533 532 509 490 471 482 500 485 497 482 480 468 456 484 458 531 520 481 506 501 517 494 457 512 518 501 457 516 507 481 452 474 474 485 465 485 483 504 483 538 476 503 505 497 470 543 474 472 508 477 457 466 481 476 456 467 453 458 449 483 492 482 476 509 505 562 471 476 450 474 490 488 498 461 463 479 504 470 513 500 459 470 502 495 493 506 486 451 513 505 484 494 473 493 455 492 486 497 481 454 484 474 470 445 444 489 483 467 465 444 459 475 481 514 496 480 509 477 446 500 449 487 452 494 470 462 487 469 447 452 479 458 508 453 486 475 481 484 465 516 490 496 472 476 451 465 468 433 458 470 495 468 460 462 434 473 488 472 489 486 495 490 479 463 490 497 441 478 484 478 479 504 470 481 476 485 491 469 475 477 482 461 439 468 500 445 484 450 493 470 478 492 466 471 497 462 451 521 492 455 453 502 472 444 460 428 472 493 457 431 457 460 465 441 475 463 442 513 446 453 513 431 458 493 497 479 472 456 468 461 498 450 476 463 443 451 407 466 487 465 444 475 455 480 498 498 512 455 467 451 466 431 474 467 487 450 454 492 439 470 434 491 450 458 476 452 459 474 483 476 515 418 471 483 434 462 503 434 475 430 496 487 458 429 470 433 446 453 447 496 438 475 473 436 496 447 464 487 488 418 457 459 481 440 479 477 462 437 478 491 456 427 467 456 450 476 484 484 485 410 452 480 463 475 498 451 497 467 426 448 464 455 487 439 468 465 452 439 475 452 491 461 430 481 453 476 472 485 469 499 446 427 502 457 448 468 453 435 464 463 456 457 433 415 418 424 432 492 455 519 450 477 439 476 477 457 474 461 418 447 420 419 436 463 437 447 473 434 460 443 434 447 475 460 479 443 449 472 478 423 453 455 426 407 444 441 465 429 459 456 493 406 450 435 443 449 448 438 445 448 437 501 457 453 460 437 424 452 445 466 451 444 429 486 454 413 430 452 445 464 437 444 441 410 435 454 413 436 440 426 435 443 455 411 480 488 454 418 458 439 440 404 422 460 405 436 443 465 426 420 440 456 438 436 416 437 436 394 432 399 409 458 414 420 441 473 448 429 398 465 442 433 415 432 435 432 418 426 404 446 435 423 423 461 427 412 460 435 423 432 449 439 438 403 470 429 414 419 442 429 448 470 457 414 421 388 429 418 422 444 454 442 427 421 399 403 421 402 421 425 418 411 456 416 449 414 438 452 392 405 430 417 453 451 411 417 403 445 430 436 426 439 416 411 439 413 389 424 411 417 428 411 402 405 474 431 413 407 398 393 399 403 428 418 421 404 408 396 452 469 425 427 403 411 394 426 426 417 420 410 391 397 418 401 418 405 403 431 421 454 385 394 403 428 471 418 459 430 426 417 418 434 432 409 404 391 414 405 403 421 417 390 410 425 405 469 426 431 409 413 406 462 428 429 399 419 435 410 392 371 436 426 386 395 410 389 382 388 386 419 407 432 405 410 454 410 415 409 472 407 388 394 425 363 380 393 436 411 389 397 378 406 429 401 472 385 385 409 376 421 423 419 367 437 421 452 433 444 401 409 350 423 374 412 375 392 418 440 410 405 392 396 391 402 392 383 426 388 399 389 377 383 382 406 439 376 411 406 403 484 423 401 423 419 396 392 450 416 423 362 412 393 411 382 379 399 427 416 422 412 385 448 382 412 409 395 378 435 391 391 420 441 426 406 414 415 406 392 402 453 428 397 393 419 404 424 355 391 421 425 383 396 449 405 387 391 403 394 383 381 389 373 402 400 382 381 344 391 391 397 414 364 390 400 389 409 402 387 349 378 383 377 426 406 364 371 343 415 361 373 396 371 373 382 391 385 394 340 396 362 408 368 361 374 355 374 364 406 403 387 359 375 368 366 377 404 406 391 392 397 381 351 389 403 359 358 348 376 357 401 375 384 409 344 380 353 388 383 356 396 402 383 388 388 352 360 356 368 380 381 359 379 365 346 387 327 408 403 347 386 366 358 352 365 394 391 404 401 385 337 344 347 373 346 365 372 359 389 369 371 318 352 350 375 381 399 386 375 352 390 355 389 331 347 318 405 379 378 343 384 383 352 371 347 353 375 342 362 353 335 347 391 374 377 334 359 382 355 374 343 388 296 351 379 345 381 373 406 358 342 353 316 375 366 346 361 353 381 354 361 345 333 398 355 406 364 350 386 347 351 354 375 357 332 327 326 318 364 367 335 364 352 361 325 379 383 349 363 327 352 342 326 353 358 370 373 349 346 340 370 369 358 358 350 357 357 341 345 396 349 353 310 313 356 343 342 345 362 322 353 354 360 366 363 309 348 333 368 335 336 367 353 344 323 365 347 349 332 323 375 368 389 360 354 351 366 333 342 358 354 364 374 353 370 378 318 355 334 337 341 366 326 327 338 360 364 324 334 338 351 348 334 326 380 357 333 323 351 386 356 342 339 351 309 339 336 325 330 310 331 343 345 351 341 330 330 334 346 360 328 326 339 343 356 336 361 321 348 356 371 356 337 387 334 322 346 354 341 365 328 321 321 323 352 339 346 318 360 357 349 300 322 340 326 316 353 325 366 345 334 320 306 309 328 339 284 327 313 331 303 343 295 343 343 319 357 342 373 290 325 316 319 301 299 301 361 347 317 315 323 326 311 332 319 308 328 295 323 314 354 365 300 293 307 292 315 345 329 316 290 288 344 315 343 360 337 319 345 345 311 334 317 263 331 335 310 311 320 340 335 309 308 327 319 322 292 298 300 310 334 301 327 297 332 332 302 297 347 338 311 316 315 297 312 333 299 345 317 292 302 305 305 297 309 337 295 284 308 322 338 283 300 321 313 339 307 337 363 312 304 317 309 290 308 295 338 304 337 310 307 326 310 323 331 302 326 349 312 337 342 344 300 308 302 339 304 318 324 292 335 299 296 317 313 312 285 291 317 293 294 313 299 308 290 308 300 284 308 310 301 287 295 286 315 283 330 300 307 304 296 303 325 316 310 298 269 269 311 295 303 325 318 311 272 317 288 304 317 317 319 320 283 279 315 313 285 322 295 305 294 294 304 280 303 298 321 280 312 290 316 302 295 307 296 289 302 281 263 311 271 284 269 292 285 275 295 294 305 293 300 321 337 298 319 307 310 292 317 272 312 312 289 280 267 291 276 286 293 287 305 302 295 283 275 274 311 313 306 284 301 294 289 268 323 286 273 300 302 309 276 284 258 282 285 300 286 285 290 284 312 319 273 315 271 307 300 299 305 247 262 294 298 286 286 280 293 268 288 286 300 292 297 299 313 298 294 259 256 256 280 287 287 312 293 268 273 287 276 283 297 270 266 283 281 298 275 296 282 261 306 245 279 264 310 284 267 298 280 297 264 274 297 291 272 271 290 272 307 263 243 275 274 265 261 262 277 267 274 284 266 257 263 293 287 278 267 272 264 261 270 245 279 259 291 289 271 255 289 260 291 259 307 290 281 261 280 269 273 314 292 258 310 276 262 305 293 299 304 273 285 275 273 264 273 297 276 265 317 258 250 249 278 284 286 278 268 271 303 269 267 276 236 280 286 265 269 279 270 281 257 269 259 240 267 267 261 296 264 248 249 284 228 273 248 270 283 272 256 259 280 296 261 271 227 291 293 268 267 262 268 240 266 260 296 259 267 290 272 279 281 258 277 283 277 267 277 257 286 279 242 296 278 295 274 275 271 274 239 306 279 247 279 280 286 265 256 261 271 248 289 285 267 291 231 279 232 271 278 249 269 256 272 267 287 247 280 232 260 239 219 268 263 269 268 273 266 268 272 247 236 246 249 278 269 226 221 272 244 261 292 276 265 268 275 280 242 234 279 282 248 243 265 270 283 229 240 284 241 276 265 261 227 257 256 283 302 277 268 269 258 263 247 255 263 255 250 296 268 271 217 248 255 236 266 266 279 233 257 270 283 296 281 269 240 246 281 257 246 279 226 270 264 259 279 259 247 246 233 239 255 228 246 231 277 259 229 274 275 278 256 247 261 283 257 262 265 241 268 247 269 275 264 246 270 250 246 271 282 234 245 258 235 255 240 272 265 257 247 277 286 236 268 245 237 257 224 231 275 214 266 233 249 262 281 242 274 279 238 223 243 247 289 246 268 301 228 241 255 268 267 249 284 284 222 269 285 250 240 270 285 277 240 246 250 250 242 288 272 244 234 247 231 246 268 238 267 238 271 256 237 257 226 280 266 247 263 242 267 288 264 260 277 239 218 235 275 225 235 281 218 267 201 260 245 261 231 249 256 272 267 270 247 247 243 232 264 266 256 224 240 275 279 256 266 238 232 288 236 264 257 271 257 242 243 256 264 240 228 257 270 230 269 262 246 247 255 272 279 245 264 274 234 260 241 275 243 241 233 257 219 283 221 220 243 220 267 239 256 227 238 238 237 217 235 232 278 285 270 234 232 283 242 237 243 270 231 227 290 231 248 248 271 274 269 262 218 261 248 248 243 221 306 261 218 219 249 275 248 268 262 263 227 217 225 244 226 241 238 224 243 240 261 246 233 232 245 233 262 208 246 262 206 223 240 259 256 239 242 233 230 256 214 277 232 239 227 238 240 241 267 229 281 234 237 225 288 230 293 265 237 261 228 263 238 268 232 236 247 258 274 260 266 242 242 259 245 258 277 267 237 242 256 236 247 240 226 245 256 241 225 258 226 220 256 242 264 234 246 233 281 243 262 274 238 230 272 239 271 247 248 243 246 243 233 239 226 233 247 271 232 241 246 249 259 212 238 231 230 236 238 225 247 221 269 227 265 229 248 257 222 220 225 209 230 226 213 258 244 236 257 259 237 240 238 248 240 240 234 223 242 223 262 257 240 222 263 245 233 242 262 246 265 248 272 240 231 263 241 230 260 228 223 248 227 257 278 236 213 227 212 232 256 244 241 242 239 235 258 233 228 213 276 242 220 249 275 284 270 226 231 241 228 225 230 276 212 230 235 261 257 223 250 257 228 248 222 246 232 263 225 233 260 265 227 241 259 241 241 236 264 240 236 238 250 231 233 210 266 212 227 237 237 232 261 246 225 205 238 223 244 246 237 265 215 244 246 243 260 220 183 257 248 264 221 261 221 268 232 250 249 262 235 229 219 242 231 238 243 269 237 223 273 236 262 240 266 250 237 262 257 227 228 229 237 248 267 233 244 256 258 239 227 228 238 222 207 242 233 266 225 257 235 208 236 221 246 203 255 255 219 226 261 281 244 224 249 227 229 224 283 245 220 236 241 258 242 233 228 232 242 258 263 232 255 214 266 224 232 237 244 230 240 240 237 220 210 237 269 234 241 243 237 256 234 249 260 231 266 230 266 257 231 225 265 211 226 223 236 262 258 230 257 248 234 206 267 245 248 257 212 272 249 225 229 276 242 231 240 237 266 263 262 243 248 259 223 224 238 228 261 238 243 264 233 237 233 258 245 225 233 238 208 256 238 231 235 219 224 216 234 239 228 239 208 262 255 256 237 240 218 280 241 258 271 223 260 245 276 247 224 228 238 239 243 230 279 219 246 263 239 241 222 219 240 225 241 236 249 263 223 215 234 229 220 235 247 244 241 227 224 202 226 242 248 247 218 229 221 204 250 229 229 226 238 233 224 242 242 242 261 231 226 241 276 227 233 229 264 235 233 233 240 274 222 233 228 249 224 241 228 236 243 241 263 228 242 275 234 266 244 219 239 248 236 241 285 225 268 218 262 238 241 234 247 247 249 255 227 235 257 218 261 257 227 232 242 261 238 273 234 262 210 279 256 241 232 237 255 264 223 239 229 241 271 263 279 259 262 260 213 238 256 238 257 237 265 242 283 282 247 289 257 267 260 257 272 256 269 247 284 229 224 243 239 269 279 240 270 267 270 293 268 265 282 261 310 261 282 316 322 309 315 334 302 330 305 343 314 351 335 370 356 364 334 356 397 355 391 373 356 355 363 380 374 393 354 363 391 405 395 340 379 356 411 380 374 328 352 351 340 355 319 334 324 321 328 322 302 325 313 322 312 303 284 300 278 260 315 271 283 247 257 271 271 272 265 239 240 273 269 256 266 238 272 235 260 264 237 285 246 276 275 238 273 257 276 233 250 248 282 232 239 286 247 234 240 224 236 271 274 261 259 237 240 258 234 243 233 234 274 237 260 249 235 225 220 220 236 233 258 266 223 233 235 211 243 216 224 233 267 235 241 235 225 242 235 228 271 258 260 236 235 239 223 219 277 226 264 242 222 264 238 218 235 226 229 256 217 218 212 237 236 242 245 220 246 257 204 226 246 258 236 234 237 223 233 219 278 226 218 242 256 223 230 199 238 243 215 268 239 261 228 245 236 222 214 229 237 228 245 226 225 237 227 236 214 221 232 230 264 243 244 230 255 233 213 224 258 230 238 225 235 236 222 266 228 230 219 247 232 215 241 244 222 250 234 233 221 234 227 222 243 264 208 222 234 233 244 237 241 248 238 220 226 242 237 238 235 223 241 184 242 229 245 260 222 231 228 219 215 228 213 216 227 239 221 210 228 265 229 233 238 232 227 257 232 248 235 220 219 233 228 231 228 257 232 223 227 274 249 198 233 231 205 249 228 229 259 261 256 234 245 256 231 210 209 236 226 244 192 213 211 221 215 224 236 241 216 230 244 228 257 257 247 240 206 216 221 226 241 202 231 260 225 221 256 238 242 238 223 255 219 225 229 229 231 229 224 233 215 231 240 243 229 227 234 204 232 241 238 237 245 210 250 236 224 219 246 220 232 197 257 222 236 235 231 206 228 245 225 233 249 248 259 226 230 256 228 271 215 244 244 227 250 245 218 255 237 259 206 261 227 225 249 247 242 211 223 220 244 225 221 236 205 200 223 225 217 225 238 212 238 234 223 228 233 213 233 263 222 215 256 239 211 233 223 223 244 245 258 219 243 192 275 270 241 234 233 249 255 243 264 215 236 210 234 244 208 216 230 224 234 233 276 220 245 268 264 246 234 222 262 209 226 249 239 217 226 243 210 235 236 212 244 262 267 242 244 267 240 226 232 221 227 232 247 221 257 239 261 262 237 267 255 239 240 233 236 230 261 260 229 239 231 271 240 275 272 235 236 261 265 257 244 242 246 239 285 255 240 256 210 238 285 231 279 281 287 325 341 321 328 325 364 377 312 362 380 393 392 433 515 608 822 1066 1442 2183 3548 6465 10326 10569 5443 2518 1398 1073 1014 1178 1541 2281 3505 5344 5414 3245 1599 907 583 521 512 424 405 399 385 375 356 353 353 333 327 365 331 332 342 306 332 337 303 310 291 292 297 310 293 304 276 301 286 331 277 234 263 308 287 280 244 294 267 260 263 239 243 288 319 271 257 295 284 242 237 279 263 247 235 302 263 233 228 271 258 258 263 239 263 277 239 248 309 261 228 256 268 262 263 258 276 247 229 273 230 255 245 246 255 245 265 264 278 246 245 248 229 276 221 255 266 232 223 246 247 219 224 230 245 242 261 240 270 265 221 239 229 269 238 237 262 244 249 222 264 269 271 265 246 283 218 249 214 214 229 278 263 241 242 256 258 224 264 256 256 249 280 229 243 265 235 230 232 256 264 228 261 244 260 243 242 262 271 220 248 238 240 237 279 278 229 286 233 269 237 291 226 258 268 257 237 285 237 271 241 236 283 277 281 238 238 270 246 235 269 245 287 281 269 257 284 259 260 258 290 250 291 266 242 255 260 294 281 279 263 283 324 280 284 287 300 304 305 305 280 302 307 305 330 272 293 306 332 303 317 332 326 333 339 354 314 338 367 340 332 368 371 373 372 399 366 379 419 404 403 422 463 491 482 491 481 537 543 533 548 516 588 530 529 560 528 563 497 515 551 501 566 520 550 516 480 445 446 401 458 399 414 441 354 381 416 361 333 345 351 331 354 329 299 319 335 327 282 300 283 283 267 293 278 280 308 284 268 271 294 259 273 273 280 245 278 232 263 282 290 241 237 230 269 233 268 286 261 266 290 282 231 232 259 263 233 238 207 261 265 264 257 268 262 270 277 243 228 241 261 257 224 221 239 240 209 257 270 262 275 244 246 239 210 223 245 233 228 232 230 263 245 234 237 232 247 240 230 237 217 247 265 214 243 245 230 267 243 257 246 244 240 235 238 213 261 239 229 213 224 223 232 222 264 212 291 224 240 239 269 262 229 199 222 271 233 229 224 225 242 285 220 255 247 238 256 228 239 208 230 244 227 220 280 241 227 238 245 228 210 266 232 263 245 255 238 234 240 267 237 223 235 241 237 221 242 249 230 249 208 233 245 249 231 257 231 259 233 209 220 218 259 231 227 241 218 232 256 259 259 238 224 265 236 281 222 266 239 215 234 240 248 235 246 218 240 209 220 282 218 271 247 232 209 224 241 239 219 257 225 241 223 246 255 235 255 274 235 216 247 192 249 234 263 231 266 238 261 241 246 233 227 231 223 226 257 236 217 257 269 226 269 242 241 258 235 225 275 217 213 238 221 225 225 207 233 232 246 230 226 232 250 216 239 224 215 224 212 266 240 208 262 225 235 257 212 239 231 227 203 262 246 219 258 224 226 201 233 237 249 242 234 218 213 230 240 212 248 265 236 267 263 235 235 259 246 236 255 232 264 233 233 221 232 218 256 236 273 256 221 232 232 243 226 237 226 218 243 266 218 214 271 236 276 237 217 261 242 236 210 235 210 245 255 245 220 239 262 262 243 245 235 221 257 229 263 245 214 273 245 247 230 231 248 233 247 212 233 228 223 243 240 230 269 262 239 219 266 259 215 266 247 263 273 220 249 221 226 239 207 239 263 200 234 241 270 255 229 236 245 232 234 239 232 227 222 204 237 244 260 241 238 261 260 261 224 247 236 233 263 240 278 239 233 274 230 215 222 261 249 236 219 240 244 241 236 234 243 229 259 249 236 217 237 235 240 271 242 236 231 247 227 256 231 226 259 243 240 227 230 237 255 256 220 227 214 238 247 261 274 226 232 241 236 235 244 259 206 230 236 213 217 240 231 232 228 277 240 259 259 244 231 215 240 235 241 224 231 247 232 255 245 236 235 245 232 227 223 268 259 216 257 242 243 238 249 228 238 249 264 247 272 250 218 222 240 217 230 236 218 226 237 220 268 237 245 238 234 241 233 277 233 235 230 199 244 221 240 231 257 237 243 229 240 230 203 258 217 227 236 226 268 224 237 239 230 244 219 265 232 223 230 250 226 224 226 242 242 260 235 233 241 235 231 233 261 263 232 225 237 228 237 239 260 242 231 270 224 243 242 227 232 249 245 237 246 273 228 224 236 225 273 215 235 257 208 246 277 232 227 234 263 238 226 247 232 216 270 244 221 198 223 233 246 205 247 234 246 221 228 210 241 224 230 230 271 250 236 239 225 270 238 266 243 236 243 215 197 248 249 249 270 263 270 241 269 242 234 233 231 236 262 238 248 263 280 261 272 240 235 233 230 229 222 248 241 259 248 219 263 244 236 239 225 267 263 236 229 263 243 246 239 245 231 230 233 260 267 247 237 199 232 219 255 240 257 238 221 248 243 235 244 222 245 258 227 234 235 238 256 243 237 226 229 247 273 230 233 287 258 249 255 225 264 224 209 224 225 260 248 245 256 257 230 237 246 229 205 272 237 264 246 275 242 257 231 259 258 235 249 239 247 227 231 244 247 235 222 227 220 233 264 212 236 233 232 245 259 272 256 236 247 248 260 260 247 239 228 246 244 242 229 214 236 278 247 261 220 224 262 229 256 202 280 272 226 228 210 245 249 229 238 259 222 222 233 241 248 236 210 269 232 231 225 259 257 231 267 245 235 230 229 235 209 244 239 218 229 244 237 226 246 238 230 215 235 232 264 216 218 240 222 241 220 232 277 268 265 236 256 234 245 210 250 227 222 233 250 231 208 247 224 274 247 238 232 248 229 243 261 240 255 228 258 224 258 247 238 235 244 268 269 236 234 235 225 232 244 229 239 267 240 279 242 263 224 248 243 239 260 244 211 210 227 241 237 223 256 249 225 246 239 304 238 224 271 239 226 229 240 268 281 225 301 213 242 255 264 227 238 261 217 270 244 230 269 243 232 245 231 241 274 247 272 255 249 226 243 226 265 244 231 243 241 260 238 278 227 284 227 261 229 264 243 247 229 224 246 237 219 245 260 262 267 269 264 241 221 261 235 235 259 223 205 230 248 231 241 228 249 245 221 270 228 256 239 231 228 256 225 260 257 245 262 223 244 274 238 247 268 233 221 214 249 244 249 261 223 237 247 225 226 242 237 264 241 244 257 243 237 239 248 227 217 240 212 233 233 223 248 243 233 236 243 215 263 241 223 246 261 223 206 279 217 206 242 241 281 203 240 221 262 242 247 265 227 237 270 269 244 240 219 244 245 227 244 248 241 229 271 217 249 267 246 256 224 261 266 233 223 248 237 246 225 232 226 245 235 286 248 220 220 256 245 246 239 247 228 239 224 233 259 274 277 230 201 228 243 245 236 245 247 244 256 257 221 245 217 260 260 265 237 240 221 242 232 247 219 235 275 241 259 269 262 264 247 275 223 278 241 264 235 241 218 224 256 274 255 261 257 234 261 221 280 233 256 234 262 264 222 265 218 224 272 262 255 267 257 260 275 261 240 249 264 245 239 274 257 244 232 237 244 220 255 258 238 281 235 264 234 232 247 249 232 248 270 241 247 265 234 255 261 205 272 232 255 268 235 233 203 265 249 260 225 214 270 230 244 229 247 256 234 272 224 281 262 224 246 230 247 238 266 219 236 247 249 231 274 274 226 219 234 271 245 279 244 280 233 234 234 265 225 256 214 259 223 211 271 246 255 269 229 218 230 261 242 207 228 247 270 261 262 235 278 232 234 264 256 248 243 246 250 224 236 233 218 222 234 244 270 219 231 255 272 223 223 244 213 255 271 266 230 242 255 263 236 255 248 214 268 239 276 268 248 271 219 225 246 262 229 259 204 228 268 239 244 245 248 241 239 224 264 247 242 234 229 269 256 234 243 211 241 243 238 215 245 262 244 229 230 219 231 261 242 219 230 224 236 220 212 263 248 261 246 214 248 230 228 247 243 244 234 234 220 220 227 223 205 228 219 222 268 214 257 244 237 235 222 224 233 245 259 234 247 267 241 233 258 230 255 209 242 223 219 227 209 200 235 263 232 240 229 226 210 221 249 257 237 219 236 241 234 248 204 229 245 218 246 256 237 266 228 234 267 236 246 255 273 231 248 258 242 228 229 234 259 214 237 241 256 240 237 263 226 245 239 225 275 259 246 213 243 218 264 279 247 248 267 224 262 238 272 257 233 230 235 265 238 226 219 239 236 261 223 224 247 243 242 249 288 246 263 260 222 262 261 240 257 245 261 237 263 197 247 246 242 243 218 240 276 259 267 247 231 239 223 210 245 256 244 242 267 245 235 255 220 229 244 230 232 235 229 218 257 242 228 227 241 224 213 232 249 244 230 231 226 248 257 234 249 256 240 263 226 244 257 259 236 245 217 248 259 222 229 262 257 241 233 245 260 238 246 210 258 246 241 204 236 228 235 244 243 258 241 259 261 264 272 246 247 233 246 234 241 278 238 238 245 230 216 275 247 242 239 233 235 230 244 242 235 230 229 235 266 230 238 233 260 219 216 255 267 211 227 264 231 228 244 243 262 249 259 259 245 233 257 248 261 259 265 240 269 239 266 214 262 241 216 238 274 232 262 203 224 263 260 221 245 232 247 221 223 272 234 276 216 258 250 223 229 227 256 244 244 244 245 238 233 234 239 242 226 239 221 259 228 209 205 234 220 272 255 258 227 237 256 293 248 225 217 242 262 241 230 246 242 229 214 227 263 229 236 263 242 245 241 232 227 230 243 282 226 239 248 214 239 248 223 232 271 224 246 259 219 267 240 244 218 240 232 274 283 240 248 258 258 270 233 241 255 219 228 222 245 241 247 241 219 239 246 243 258 255 225 249 257 238 268 291 233 242 236 267 260 264 229 276 262 200 222 256 225 264 246 230 250 256 219 249 255 261 247 226 213 247 223 256 248 262 237 239 223 234 265 267 248 264 228 265 230 260 266 223 257 257 232 264 271 243 241 284 240 229 260 236 239 234 238 221 223 219 269 244 264 255 227 272 270 220 249 274 235 243 218 236 230 272 243 234 246 245 257 235 227 230 229 228 245 230 246 241 235 229 239 211 264 240 237 213 260 214 249 263 239 232 249 237 238 235 237 226 228 226 244 245 231 243 237 258 271 246 213 229 220 266 228 264 248 262 263 260 246 222 201 259 231 233 237 241 245 239 258 283 247 223 256 265 271 249 224 229 272 227 228 235 221 237 249 228 246 256 284 213 235 268 247 246 209 243 238 275 234 273 237 271 238 243 235 274 231 274 266 235 242 228 219 265 246 216 242 237 231 247 279 236 228 235 265 243 236 262 212 268 220 229 261 271 260 261 230 262 260 250 238 249 280 288 275 284 265 273 260 267 272 265 268 274 232 260 257 267 262 279 276 295 259 243 221 230 266 269 233 259 244 255 303 257 275 282 261 268 281 275 267 267 240 304 240 245 248 269 245 247 269 249 246 256 274 255 241 283 224 241 245 266 234 235 255 229 258 240 240 236 268 270 242 272 227 281 239 269 273 227 239 273 224 240 231 241 245 244 267 246 264 231 230 260 264 238 216 230 237 235 229 247 286 216 235 237 224 259 237 249 256 238 268 240 273 257 261 233 236 238 256 246 280 231 243 238 239 284 267 224 255 220 209 264 245 228 248 255 239 226 258 291 245 236 265 245 245 235 245 245 255 256 256 246 263 292 229 258 277 243 221 261 212 255 235 226 223 219 243 231 243 230 241 187 247 245 229 245 258 262 248 243 261 268 261 261 242 263 249 248 248 245 228 255 261 247 233 255 237 248 248 240 273 241 227 223 263 247 230 268 271 229 237 248 266 249 238 221 204 248 246 274 255 222 201 247 263 273 232 248 231 212 229 273 197 255 261 226 197 244 248 276 232 224 234 245 276 229 240 217 265 233 236 258 234 261 260 232 268 247 244 274 208 246 258 224 233 269 284 266 232 276 247 271 241 250 243 224 223 219 218 239 257 232 228 267 259 235 231 278 279 220 237 237 266 242 245 244 227 275 274 235 235 232 244 261 286 224 233 233 249 244 246 200 233 268 227 225 243 256 243 249 243 238 261 242 249 271 298 211 238 239 244 234 218 256 235 278 256 243 257 245 238 228 236 246 282 243 248 248 244 218 226 238 236 219 246 256 235 258 256 226 247 235 221 227 220 257 242 259 248 240 234 232 255 264 232 270 244 273 249 277 268 255 217 226 230 231 233 243 230 211 232 256 240 257 272 217 230 243 226 238 266 218 234 264 233 231 278 263 292 238 242 255 244 216 243 234 241 228 271 222 264 228 249 245 255 275 262 255 238 263 239 258 238 240 245 243 239 247 246 247 281 250 261 257 261 226 245 237 223 248 240 257 283 238 238 274 231 240 243 265 247 238 262 259 261 238 247 255 265 232 209 249 271 237 259 244 255 237 228 240 245 265 227 246 232 236 259 274 228 265 246 231 218 258 255 269 222 245 224 232 258 240 238 237 266 274 262 244 267 232 239 237 237 231 232 257 264 245 277 255 264 223 245 288 241 270 272 264 260 258 268 244 256 264 259 255 212 246 236 256 258 280 210 266 228 250 225 243 262 240 269 282 246 271 221 223 230 258 220 265 238 258 246 279 249 227 276 219 262 232 255 264 272 255 247 267 242 223 229 271 245 244 227 249 261 263 231 245 234 234 226 224 216 269 233 242 239 255 241 274 255 236 264 214 218 242 231 249 227 225 263 256 266 280 235 257 262 262 236 217 275 241 215 247 264 266 289 282 238 262 226 269 249 231 246 286 257 255 283 276 207 258 255 263 244 260 262 247 239 264 247 228 266 231 247 226 259 260 244 231 227 234 247 246 285 244 236 269 262 246 255 282 249 229 293 257 225 236 247 248 256 226 287 246 227 242 282 263 225 220 240 271 240 266 270 264 273 262 263 264 245 274 234 262 227 243 238 258 231 247 246 258 232 249 257 267 256 267 245 239 243 267 270 260 233 227 268 280 274 220 247 255 273 269 280 242 264 279 275 237 233 233 244 246 292 282 247 278 249 258 244 279 262 242 245 242 250 244 227 249 226 269 262 255 264 221 233 255 218 234 263 243 229 255 209 234 258 246 250 263 262 270 261 241 258 244 266 237 224 286 238 266 246 238 266 243 245 239 242 273 268 246 262 229 234 214 246 262 246 261 261 243 283 260 238 260 239 233 266 232 268 240 247 225 248 241 236 229 271 273 214 291 250 262 263 248 257 275 260 241 259 294 266 247 249 229 262 282 238 232 262 233 217 225 247 237 270 278 273 284 245 265 275 267 272 246 256 258 271 260 245 287 248 233 234 239 240 242 264 249 245 258 249 245 220 269 248 249 274 270 241 258 259 268 228 280 242 248 248 221 262 233 285 277 264 243 265 240 259 255 222 245 237 260 266 245 234 245 263 240 220 249 267 238 240 262 235 222 241 242 239 237 233 262 244 236 272 257 260 272 257 260 273 227 219 243 272 225 218 231 250 240 242 249 266 255 222 245 256 242 229 258 242 222 274 245 236 244 273 249 244 216 243 226 221 232 256 276 240 234 257 264 247 257 241 266 268 269 250 247 258 261 255 266 224 267 246 238 241 261 217 236 258 237 238 225 238 273 221 262 246 240 247 229 242 230 226 246 243 262 229 267 270 248 236 239 282 263 262 238 272 245 272 257 249 245 230 222 275 237 232 240 256 226 257 258 258 246 233 238 234 256 224 268 237 227 259 264 237 283 235 268 269 240 226 225 258 277 280 258 266 240 246 246 263 248 261 255 260 257 228 236 245 255 257 246 260 244 248 272 242 261 246 258 267 224 247 255 261 258 290 238 257 228 229 240 264 278 247 259 262 244 266 263 261 265 258 235 258 268 227 290 265 284 278 257 228 275 262 231 233 255 269 248 256 209 261 237 263 240 250 235 225 245 293 256 227 259 244 281 262 239 236 214 235 270 243 268 265 245 242 278 258 250 271 240 271 258 270 257 235 204 245 249 274 273 238 243 262 243 242 259 284 277 275 280 245 255 276 242 242 245 273 262 265 267 227 260 200 259 232 261 250 244 275 246 277 264 242 221 261 243 247 250 261 261 238 271 276 265 263 311 237 258 242 268 260 285 215 281 236 278 265 250 270 281 228 238 238 260 257 269 279 226 276 259 269 194 282 248 229 265 267 240 227 283 267 231 291 265 256 242 256 302 273 258 273 268 255 258 283 257 245 260 272 261 261 255 267 266 287 245 250 284 288 296 246 263 235 257 297 287 263 284 242 235 256 278 246 240 264 261 240 217 273 239 286 241 248 248 284 285 262 242 259 256 268 268 271 259 245 248 269 277 285 229 267 277 268 262 266 286 219 236 272 238 234 227 259 274 234 255 283 241 229 244 265 266 248 260 223 271 241 235 246 256 243 282 244 263 236 245 231 242 285 224 265 255 263 266 230 225 268 247 280 244 264 255 279 233 255 271 218 283 241 255 261 264 301 245 217 263 257 261 269 263 260 228 266 246 259 250 260 264 266 235 250 284 265 256 276 260 234 238 275 235 257 239 231 244 230 272 225 268 242 218 230 226 213 256 267 242 255 300 284 269 226 228 285 242 225 260 257 258 249 240 268 259 284 266 241 229 266 266 238 268 244 266 267 266 280 249 241 248 239 285 260 275 249 241 240 262 228 228 259 248 235 271 260 225 266 286 258 289 261 243 257 258 283 243 262 229 238 285 234 227 231 240 264 255 285 259 294 264 241 270 297 262 277 235 240 255 277 274 244 271 273 247 258 257 232 248 266 248 237 280 277 271 266 248 267 255 257 226 250 260 242 250 297 256 249 270 267 268 242 266 273 240 263 269 275 296 276 256 244 272 270 259 301 286 311 306 317 334 310 302 300 275 291 281 241 273 276 247 296 270 259 279 238 242 278 243 284 300 293 240 266 272 268 290 268 236 270 243 234 264 268 240 280 287 240 274 256 273 241 267 261 222 263 269 238 255 257 259 239 244 273 256 257 249 275 278 268 259 269 228 307 279 247 264 270 244 267 278 244 276 244 275 266 257 257 289 274 272 239 264 303 246 269 263 248 263 232 289 256 267 276 221 289 243 273 258 259 248 261 234 261 243 274 235 282 236 272 268 256 261 243 265 284 292 280 245 247 272 234 284 265 242 277 281 277 279 231 281 268 283 288 264 236 294 256 276 298 255 279 263 271 269 271 292 282 274 275 245 321 247 282 274 310 297 297 248 281 288 266 287 269 256 264 290 287 255 257 228 289 286 269 277 276 258 283 256 271 301 266 293 295 292 265 276 292 270 284 308 259 307 293 301 279 277 303 337 301 288 282 273 316 302 312 272 288 314 308 318 285 348 318 273 309 286 277 283 310 338 313 305 298 306 317 297 334 291 326 284 274 276 312 312 311 302 286 307 289 306 289 306 287 258 272 289 292 293 283 296 283 279 290 286 277 271 276 263 258 282 266 290 272 283 245 289 249 270 293 270 293 278 270 264 287 269 262 269 291 259 270 272 243 277 255 259 294 232 262 273 249 286 283 266 259 256 266 256 271 242 232 256 267 289 272 274 276 299 246 274 268 247 280 233 289 264 267 299 270 245 250 260 285 232 245 249 264 246 260 236 256 261 274 255 262 276 246 291 267 274 262 285 234 261 244 262 239 234 243 274 241 268 238 245 237 280 236 255 267 244 255 278 272 276 249 273 281 262 260 265 256 278 244 240 257 236 282 273 262 246 262 265 255 240 249 281 223 276 265 266 211 243 227 245 226 243 244 244 243 268 246 265 233 256 278 262 275 259 266 270 256 277 248 242 263 237 268 247 275 245 237 238 257 258 271 241 236 257 279 248 257 248 249 299 240 294 262 268 299 256 262 264 258 224 222 267 263 255 258 234 279 266 259 234 244 260 226 260 238 232 269 245 260 230 256 246 263 266 240 271 230 238 258 239 269 233 267 256 221 248 258 274 225 249 262 268 260 247 234 249 279 269 266 258 237 270 255 271 241 285 260 266 261 231 272 255 238 237 270 245 239 293 227 265 282 280 258 248 282 256 258 265 260 238 292 272 267 247 278 271 277 221 255 261 278 288 266 266 256 233 279 241 255 256 274 248 257 266 277 278 239 268 276 265 283 292 242 248 248 265 280 262 237 267 259 226 240 233 258 263 255 258 259 246 265 248 246 234 267 261 285 259 248 260 266 236 261 246 227 271 247 271 234 258 273 275 260 294 281 298 262 245 261 284 269 278 281 289 259 241 297 259 264 264 239 269 237 266 257 270 263 239 271 255 268 267 269 276 257 280 232 259 263 270 237 259 229 240 290 272 257 239 239 266 235 271 296 271 247 280 243 270 266 280 239 255 270 236 234 297 285 260 275 284 274 259 263 239 275 257 273 229 249 271 276 230 256 265 238 266 250 269 296 248 268 260 249 255 237 239 270 262 263 264 277 275 249 279 291 256 293 291 264 271 305 257 258 281 246 267 275 263 266 277 235 293 264 279 248 268 264 276 255 235 250 289 250 296 272 276 286 258 242 278 238 285 287 256 241 266 287 260 230 271 235 266 244 220 241 232 275 255 280 274 280 255 303 248 290 245 298 258 260 248 277 274 287 295 295 249 271 257 269 294 272 271 276 279 287 248 273 288 239 275 247 316 280 285 280 258 257 262 241 289 276 269 278 258 249 255 274 261 269 279 258 279 238 241 270 284 243 257 266 267 272 249 258 248 272 260 304 276 276 299 298 250 263 266 265 286 271 290 257 263 305 243 277 285 262 237 273 318 294 295 267 270 274 276 280 255 283 229 279 267 270 284 244 267 264 268 290 293 267 283 275 264 262 274 269 302 279 270 259 281 245 263 298 287 291 264 310 290 232 267 288 280 297 284 278 275 303 297 278 293 281 296 275 283 282 277 273 291 275 297 233 292 266 277 262 279 273 298 286 284 284 312 292 280 296 310 323 276 284 321 280 302 306 324 274 318 271 265 307 297 260 285 278 330 269 297 284 284 308 289 294 307 321 275 244 293 284 289 299 316 301 288 321 284 283 323 314 315 316 302 322 325 315 284 273 307 327 285 295 329 298 322 300 316 288 324 293 275 300 313 339 352 310 310 333 345 315 325 329 366 353 326 324 351 329 358 317 303 352 368 320 345 360 372 375 354 354 340 382 356 389 393 382 371 428 396 402 403 376 408 473 456 494 496 476 477 562 591 583 555 605 590 563 605 598 612 635 596 623 600 546 540 555 588 563 561 565 611 619 636 642 661 649 692 690 817 751 779 876 932 1009 1062 1208 1245 1334 1512 1546 1885 2041 2425 2995 3581 4515 5792 7969 11686 17538 25867 35520 44432 49445 46479 36369 25000 17709 12877 9236 6980 5251 4179 3399 2938 2643 2333 2036 1979 1903 2107 2197 2367 2638 3140 3697 4798 6261 8800 12328 16444 20602 23105 23159 19978 15628 11538 8336 6019 4508 3558 2777 2266 1955 1657 1504 1241 1217 1176 1039 929 882 887 811 800 736 729 703 680 636 720 655 622 632 560 577 551 508 539 551 533 547 508 485 473 470 483 510 461 501 469 488 440 427 425 419 434 429 394 384 432 409 387 426 376 420 439 370 418 399 383 370 396 400 397 391 379 363 381 389 408 370 333 350 356 367 395 375 389 373 332 378 345 321 343 378 325 355 336 352 306 336 334 320 373 354 339 335 348 341 321 312 339 323 296 309 338 315 323 330 317 342 343 304 323 321 304 314 303 298 298 310 314 315 295 298 321 317 303 336 342 318 336 282 319 294 303 310 315 318 350 304 310 323 299 320 274 296 317 318 313 318 293 306 298 321 290 310 304 310 321 280 291 322 314 290 291 293 312 282 302 314 275 310 289 293 292 299 297 275 291 299 278 298 284 282 285 272 319 293 288 300 289 283 277 287 285 290 276 278 309 256 293 271 274 277 249 289 283 263 296 318 275 280 278 272 266 297 277 298 262 294 288 274 283 271 281 297 266 300 249 274 242 299 279 280 286 297 273 257 276 295 287 284 296 267 278 271 278 237 266 266 258 273 310 243 263 285 262 268 223 284 282 278 271 268 295 263 276 247 232 287 245 264 299 247 247 239 277 282 245 270 264 262 266 245 280 269 250 266 274 249 266 247 257 263 261 246 261 233 286 289 240 307 278 268 299 271 273 283 278 244 261 267 272 287 234 272 287 269 290 240 286 272 268 225 272 262 271 268 265 247 272 263 242 268 293 245 272 260 266 267 240 286 287 276 284 273 269 269 279 259 268 290 266 275 282 275 277 265 240 267 258 266 263 239 259 241 259 257 266 276 261 245 248 266 229 256 261 256 274 267 276 257 266 281 224 286 244 265 273 247 247 213 274 257 275 267 261 274 248 226 214 267 245 266 261 294 261 256 276 277 275 267 258 230 280 273 244 264 240 276 237 269 279 272 274 258 279 235 298 288 272 268 245 289 262 269 277 277 249 276 261 260 288 232 265 259 275 245 237 222 261 290 277 256 275 260 270 277 235 248 290 258 262 264 256 259 274 265 237 265 258 265 243 245 276 274 261 268 287 270 260 268 299 269 241 270 280 243 247 266 287 222 262 242 263 277 269 235 280 248 277 267 272 271 287 247 261 279 229 311 256 259 282 276 277 259 257 268 257 258 261 247 264 282 261 271 283 248 243 279 234 269 279 261 236 239 241 245 280 265 249 262 265 270 274 244 263 266 262 247 269 276 238 272 289 250 248 255 285 260 229 267 267 282 237 285 264 266 272 257 267 237 222 239 255 266 297 279 243 262 240 278 273 278 278 277 237 270 233 255 270 263 246 273 264 233 236 270 277 281 256 250 259 265 270 278 269 308 261 262 299 266 286 267 273 242 240 267 249 273 250 267 236 250 273 274 282 231 232 262 237 275 249 219 273 241 272 267 277 239 249 234 247 272 217 261 249 265 266 275 256 269 261 279 256 256 275 265 284 238 267 247 231 261 271 261 274 289 246 240 258 260 241 293 234 259 285 295 248 221 271 241 281 255 248 240 241 262 246 277 269 278 276 261 258 270 261 282 244 238 247 247 246 217 264 243 256 260 263 232 264 278 259 281 271 281 272 281 257 215 277 269 272 261 255 240 273 244 240 301 268 243 296 282 245 234 260 295 267 235 227 280 257 266 270 299 285 243 255 268 261 270 247 278 231 266 294 272 286 264 263 291 248 277 269 272 279 284 282 280 286 285 255 264 280 272 296 275 273 278 247 310 246 296 310 273 248 277 267 265 282 285 273 281 282 280 262 287 288 292 302 269 305 283 264 277 268 281 271 277 246 270 276 289 277 321 264 283 278 285 265 280 280 284 293 273 266 271 289 266 277 268 285 297 234 271 264 246 258 266 222 279 263 277 258 255 271 259 265 273 271 274 285 240 260 271 289 301 231 273 245 283 246 262 256 262 278 270 238 290 270 285 282 256 293 246 269 285 267 257 272 281 259 270 267 240 272 272 230 255 245 270 258 268 245 259 260 258 260 270 266 246 246 241 275 273 263 270 284 268 291 288 255 265 302 264 245 248 241 268 231 264 297 270 258 303 249 273 246 261 238 270 208 259 243 228 239 239 285 250 300 244 265 266 280 262 257 266 288 232 244 228 259 256 240 293 265 234 263 287 286 288 266 267 289 261 283 277 267 282 271 247 259 239 268 245 273 263 272 258 288 257 229 279 273 277 273 245 263 236 278 249 273 256 268 269 255 261 270 284 240 280 256 272 247 241 280 257 257 245 230 274 257 283 271 263 264 284 266 271 276 285 241 260 265 269 240 249 243 240 280 301 265 237 266 262 259 276 280 265 231 263 271 300 260 240 225 263 257 268 255 286 274 241 275 238 265 296 245 241 241 275 244 242 248 248 250 264 280 258 317 240 242 304 241 274 263 225 225 245 255 314 267 285 264 243 258 269 260 273 272 247 246 236 257 256 287 260 283 283 232 284 232 263 264 239 245 285 258 262 255 265 223 261 256 241 267 257 242 282 238 282 255 271 268 266 256 260 288 284 296 250 272 274 271 264 231 285 234 260 240 264 261 246 258 277 272 274 262 271 234 278 244 278 261 225 260 267 279 267 237 267 271 239 230 267 271 296 249 266 296 257 279 312 267 262 247 263 240 249 250 300 274 260 246 242 249 281 265 221 256 288 246 294 247 260 277 248 255 245 281 265 271 258 262 248 277 256 267 241 241 240 262 265 257 267 268 266 289 279 247 258 287 241 263 256 275 287 290 268 271 263 256 266 261 240 224 315 267 241 291 248 259 301 248 238 240 249 248 243 312 268 237 274 246 244 281 286 242 270 256 267 301 236 274 265 239 236 232 269 263 290 247 273 294 270 236 295 245 260 256 235 280 235 267 269 298 236 282 249 233 269 271 238 257 248 279 255 274 261 234 232 248 303 230 281 260 234 272 257 269 284 275 233 271 265 269 258 256 289 271 296 245 263 283 237 281 241 247 243 247 271 256 283 268 273 276 288 244 260 264 297 273 275 249 255 272 249 263 256 231 278 265 283 241 241 236 242 245 260 235 281 272 263 271 307 247 242 267 280 279 245 242 270 245 279 259 266 255 261 280 263 257 283 312 259 273 279 285 262 236 264 290 286 243 275 239 256 278 264 234 268 235 247 266 265 281 267 265 260 237 260 264 283 271 230 256 271 248 287 258 241 276 305 248 290 264 265 283 267 275 265 278 265 267 256 260 257 279 295 256 292 275 275 269 268 269 246 259 264 275 272 250 274 256 260 272 272 271 257 268 233 272 263 237 262 265 289 278 289 275 287 271 261 266 286 271 245 246 259 277 262 260 275 241 267 262 269 257 249 281 209 267 263 267 273 262 241 266 260 241 279 258 250 269 243 222 286 258 277 256 282 309 233 262 263 280 263 247 306 281 242 267 270 245 281 244 265 248 269 262 293 273 283 288 303 285 247 280 271 262 261 278 309 262 263 241 297 273 228 268 266 248 246 274 235 267 258 275 260 300 262 278 269 308 243 255 272 282 242 299 247 276 243 259 232 280 236 256 237 256 272 255 257 237 265 270 265 316 274 276 272 268 288 255 273 249 288 277 237 272 257 281 281 274 278 264 270 256 287 238 243 250 273 283 284 267 275 265 268 270 266 266 270 309 260 297 242 264 287 255 245 255 256 267 269 273 243 271 243 308 274 265 250 266 278 258 274 275 246 274 283 275 241 287 275 234 263 255 265 272 257 255 255 294 259 283 282 241 230 246 225 261 261 258 250 295 262 284 261 246 266 247 261 294 248 263 314 285 274 243 220 264 257 280 265 291 301 247 244 248 264 272 261 283 283 282 246 286 293 221 299 243 267 264 289 241 262 279 221 221 267 296 262 282 267 273 290 259 259 283 271 268 279 301 271 249 258 236 266 278 258 298 241 256 241 258 281 270 289 265 279 262 248 276 270 261 220 273 246 274 280 273 272 275 273 243 280 282 286 271 234 260 265 266 285 246 285 288 257 247 271 260 245 246 246 249 272 277 267 234 234 240 280 238 248 277 283 246 257 273 291 234 262 256 266 293 272 260 268 276 307 275 278 262 271 259 249 272 243 244 262 286 231 262 279 279 268 230 293 276 246 235 261 272 263 271 256 257 281 284 300 270 269 267 315 278 284 267 249 279 277 268 264 279 287 248 257 256 285 276 272 282 242 274 249 255 284 288 283 247 268 265 240 261 273 281 269 243 270 279 247 269 263 233 287 263 264 248 273 241 273 279 255 294 266 276 267 266 268 284 279 246 261 268 261 294 226 258 263 286 289 255 268 241 300 281 298 243 265 261 246 280 303 296 245 258 245 242 247 264 275 263 244 237 265 291 266 242 272 277 291 270 277 250 231 260 240 243 246 305 293 259 244 257 265 274 259 248 255 282 264 292 289 275 256 242 261 279 274 263 264 271 246 232 250 256 255 259 283 257 266 268 239 288 242 279 277 262 303 269 258 289 257 276 246 217 256 257 242 281 245 261 275 272 261 269 273 241 282 264 249 271 233 274 286 257 245 273 236 287 287 266 270 236 242 267 247 240 243 266 268 271 267 267 270 276 273 294 274 249 284 231 297 256 289 256 255 240 277 241 239 235 278 276 286 262 277 249 288 241 247 272 243 242 246 298 275 274 249 243 291 263 284 250 261 240 302 255 269 255 282 275 292 298 272 249 267 246 265 248 264 275 284 247 297 278 243 265 292 228 236 274 266 246 242 279 260 287 257 235 263 271 272 280 286 279 257 268 271 258 261 234 236 274 258 259 235 271 307 271 287 243 234 284 267 305 223 237 228 229 262 288 287 270 263 267 244 265 256 283 255 263 244 257 292 271 267 271 246 271 281 259 276 317 236 240 261 240 276 280 248 309 261 278 285 294 289 260 273 246 249 268 295 277 288 258 262 250 274 281 255 275 263 232 289 260 230 264 284 256 222 240 274 272 248 238 266 272 257 243 276 279 260 278 293 257 287 295 273 259 273 283 280 268 270 225 270 255 270 280 244 243 273 291 274 258 242 248 277 246 233 270 265 248 287 284 249 271 261 270 276 266 241 262 244 259 233 260 249 244 271 293 255 243 287 281 256 244 242 255 255 260 279 270 286 267 264 270 287 246 245 259 261 265 233 245 228 265 269 274 249 261 260 260 262 278 255 272 233 269 288 281 262 271 235 258 268 273 230 245 231 299 266 317 259 247 270 274 278 239 281 267 259 246 248 280 267 292 265 279 271 248 238 284 241 293 269 248 258 280 278 282 293 244 285 271 247 260 270 257 278 281 247 240 239 261 236 248 287 265 280 293 272 243 259 263 274 266 257 244 265 271 273 257 270 298 241 303 266 248 261 275 290 262 271 272 272 275 260 270 241 248 259 268 267 246 270 285 257 297 261 244 241 274 298 265 235 276 229 267 275 255 214 282 240 278 239 258 268 276 259 256 286 283 268 256 259 286 268 288 277 280 298 258 249 269 264 283 272 264 275 273 275 269 270 274 257 244 287 269 272 302 247 275 268 246 237 244 280 295 259 281 279 248 270 271 257 258 265 272 278 264 280 281 284 298 301 294 272 260 270 274 260 235 278 264 278 256 284 246 269 271 293 264 311 269 267 277 246 283 294 220 280 291 258 282 285 269 286 265 247 275 261 275 288 263 241 287 283 248 269 281 291 246 263 288 293 287 296 281 266 278 270 248 270 296 238 257 274 269 232 228 307 269 277 282 275 289 297 276 315 243 270 291 259 280 312 267 311 268 292 299 273 313 300 264 286 283 292 277 266 297 287 287 274 297 310 281 301 293 274 293 292 280 288 263 282 274 275 269 283 255 274 245 278 285 265 296 271 279 292 282 281 263 299 286 285 276 265 274 270 280 311 312 318 268 262 276 274 301 255 284 288 240 311 294 294 294 277 278 268 284 276 264 273 257 250 277 257 263 299 289 260 299 278 279 288 248 286 294 273 278 267 261 258 280 260 263 279 262 291 278 295 283 289 314 273 288 272 286 291 245 280 262 244 292 298 314 268 281 287 279 256 278 280 264 280 264 261 280 280 263 296 274 295 237 276 271 296 281 244 286 265 248 266 276 298 280 288 249 237 270 268 276 280 265 276 276 259 265 278 263 293 269 267 256 259 296 294 274 273 275 286 242 258 286 247 267 278 261 267 287 268 263 216 276 299 292 247 266 276 246 271 270 239 276 258 280 297 277 284 271 299 274 296 274 237 301 297 248 296 270 284 271 290 291 225 278 287 270 264 236 261 282 249 277 284 265 261 285 258 263 273 260 280 296 280 243 291 239 271 291 257 276 227 277 280 293 279 248 241 245 261 235 279 279 262 245 267 242 269 277 274 243 236 292 259 269 269 274 303 267 248 264 268 284 278 255 274 276 278 266 276 285 268 283 290 235 242 288 259 261 246 299 274 266 242 278 243 277 257 302 249 268 291 275 243 238 278 268 298 263 240 236 272 262 275 260 287 263 228 271 268 266 259 263 258 264 272 274 289 262 267 274 246 249 290 257 258 269 222 230 243 223 271 283 261 228 257 289 270 255 249 284 259 287 260 288 272 290 295 287 280 258 269 262 248 241 262 265 261 255 278 277 262 257 295 258 278 279 255 272 288 275 273 266 258 283 279 277 228 261 282 245 280 236 294 246 275 257 288 262 264 255 227 267 268 285 286 248 267 258 247 260 297 235 297 246 237 269 292 277 248 271 283 280 267 273 277 263 288 268 263 276 274 270 283 239 282 236 282 248 279 234 281 276 229 257 278 256 259 274 241 280 265 270 264 279 286 260 267 304 232 271 276 281 246 264 260 263 268 249 291 277 257 255 276 262 302 276 288 247 267 234 272 263 277 240 260 271 293 275 284 278 278 268 257 287 278 255 277 247 277 229 240 278 280 265 266 237 282 290 279 269 294 256 255 268 288 285 245 273 272 245 274 299 277 268 262 266 291 277 264 287 227 242 291 263 287 260 290 276 264 280 293 243 260 219 275 269 273 266 245 243 265 271 263 278 269 285 260 244 289 297 256 258 260 258 270 263 269 265 271 283 261 248 259 243 279 282 255 281 282 293 280 280 278 272 265 250 255 282 275 246 263 262 240 269 273 289 267 247 292 287 288 289 262 291 297 272 279 269 265 266 259 266 268 267 263 272 261 284 266 235 242 258 258 270 265 280 265 289 286 302 272 265 285 280 278 273 233 275 290 279 269 262 238 280 260 258 233 230 267 241 278 262 264 293 267 278 258 265 281 263 296 247 261 256 243 281 265 249 285 259 258 257 283 246 293 274 250 263 274 260 259 258 285 273 255 287 245 273 281 272 304 245 271 264 220 242 302 277 303 286 276 259 281 256 275 286 268 273 270 255 271 231 275 262 289 279 259 305 256 277 263 256 256 225 285 277 266 216 276 296 279 272 243 255 301 256 240 268 262 260 245 283 281 306 273 246 255 263 278 269 293 262 243 259 267 268 293 266 268 266 243 299 286 241 225 278 272 265 267 287 258 276 266 260 238 266 243 264 246 244 293 280 288 272 288 242 260 262 295 245 266 226 267 277 235 265 239 267 269 273 268 263 271 246 247 265 257 243 275 266 275 267 269 279 268 273 233 277 269 244 260 304 238 270 270 265 289 274 241 264 310 245 260 234 267 290 258 299 276 266 275 263 247 291 280 278 281 243 287 275 263 234 286 284 270 282 256 279 284 261 227 266 291 263 237 282 273 267 274 272 299 274 268 280 249 247 269 270 249 243 258 285 266 245 267 259 279 280 277 266 256 233 272 268 240 238 266 282 272 288 273 246 273 281 290 298 277 250 291 283 266 290 281 276 267 288 237 266 282 284 274 241 280 256 266 287 266 294 281 272 272 241 259 316 262 273 280 293 269 275 255 286 286 244 242 292 250 261 286 272 283 275 243 291 270 262 271 304 256 270 275 285 271 248 260 263 281 262 247 262 265 250 305 257 257 241 235 305 306 311 256 277 255 257 222 293 266 262 274 283 263 296 272 304 282 281 274 282 290 288 270 234 249 246 270 257 262 267 259 264 276 285 260 261 262 276 280 280 273 277 248 280 295 248 225 281 243 266 267 282 279 262 218 261 288 296 260 239 274 268 286 236 288 263 242 264 237 286 293 299 270 269 298 283 273 297 290 268 262 270 300 264 262 276 291 279 290 243 294 262 256 265 291 271 288 282 271 272 239 245 289 249 257 283 299 268 272 237 264 282 273 272 278 274 262 255 287 247 318 282 276 278 266 279 284 296 266 260 286 269 314 275 274 272 256 296 274 262 248 267 255 282 276 240 279 263 271 266 257 297 223 262 276 314 270 260 277 241 269 281 302 291 294 264 282 255 271 263 259 268 288 264 289 264 258 249 262 289 269 262 286 258 267 259 302 288 280 230 265 293 262 298 269 263 278 259 275 295 289 276 282 276 248 276 262 282 272 265 230 259 265 276 271 279 274 280 299 280 282 289 247 264 271 287 289 247 269 282 249 289 273 264 329 297 274 213 272 243 274 244 274 248 268 269 275 241 271 267 256 267 256 289 255 258 276 260 258 279 297 257 247 246 247 320 269 233 259 298 260 258 278 293 274 260 291 282 265 256 274 281 291 274 291 266 271 289 269 260 280 271 244 276 265 284 267 300 304 305 255 280 265 286 271 268 294 264 335 282 260 245 244 293 297 294 265 242 299 272 259 260 275 280 235 282 245 295 293 291 282 281 262 275 291 266 290 261 265 292 271 242 275 256 279 245 255 281 289 278 266 277 307 281 264 259 284 270 290 274 255 285 274 261 246 281 288 281 305 276 275 263 275 256 283 273 263 294 282 266 268 278 299 282 231 238 243 242 286 282 266 268 260 258 259 298 244 290 266 260 290 290 282 275 247 260 267 285 270 279 307 271 259</counts>
			</dataPoints>
		</scan>
	</xrdMeasurement>
</xrdMeasurements>