File: data/XRD/CS-Vakuum/XG-pre/W6823-3A_CS_Vakuum_pre.xrdml
<xrdMeasurements xmlns="http://www.xrdml.com/XRDMeasurement/2.1" xmlns:xsi="http://www.w3.org/2001/XMLSchema-instance" xsi:schemaLocation="http://www.xrdml.com/XRDMeasurement/2.1 http://www.xrdml.com/XRDMeasurement/2.1/XRDMeasurement.xsd" status="Completed">
	<comment>
		<entry>Configuration=Factory configuration, Owner=User-1, Creation date=7/8/2013 4:01:53 PM</entry>
		<entry>Goniometer=PW3050/65 (Theta/2Theta); Minimum step size 2Theta:0.0001; Minimum step size Omega:0.0001</entry>
		<entry>Sample stage=MRD Cradle; Minimum step size Phi:0.01; Minimum step size Chi:0.01; Minimum step size X:0.01; Minimum step size Y:0.01; Minimum step size Z:0.001</entry>
		<entry>Diffractometer system=XPERT-PRO</entry>
		<entry>Measurement program=C:\PANalytical\Data Collector\Programs\Jorrit\2thom\_absolute_2th-om_10-130deg_PIXscan_56min.xrdmp, Identifier={15BCCF57-2807-42BD-B5B9-ECC0B3DC9284}</entry>
		<entry>Batch program=C:\PANalytical\Data Collector\Programs\SimonL\batch8x_2thom_10-130°_z9.1_x0,10,20,30_y20,30,40,50_57min.xrdmp, Identifier={9A1B954C-70C5-4DE2-A2B5-D0000261ED0F}</entry>
	</comment>
	<sample type="To be analyzed">
		<id></id>
		<name></name>
		<preparedBy></preparedBy>
	</sample>
	<xrdMeasurement measurementType="Scan" status="Completed" sampleMode="Reflection">
		<comment>
			<entry>_absolute_2th-om_10-130deg_PIXscan_56min</entry>
			<entry>PHD Lower Level = 4.83 (keV), PHD Upper Level = 11.27 (keV)</entry>
		</comment>
		<usedWavelength intended="K-Alpha 1">
			<kAlpha1 unit="Angstrom">1.5405980</kAlpha1>
			<kAlpha2 unit="Angstrom">1.5444260</kAlpha2>
			<kBeta unit="Angstrom">1.3922500</kBeta>
			<ratioKAlpha2KAlpha1>0.5000</ratioKAlpha2KAlpha1>
		</usedWavelength>
		<incidentBeamPath>
			<radius unit="mm">320.00</radius>
			<xRayTube id="1010048" name="Empyrean Cu LFF HR (9430 033 7310x) DK442154">
				<tension unit="kV">40.0</tension>
				<current unit="mA">40.0</current>
				<anodeMaterial>Cu</anodeMaterial>
				<focus type="Line">
					<length unit="mm">12.0</length>
					<width unit="mm">0.4</width>
					<takeOffAngle unit="deg">4.2</takeOffAngle>
				</focus>
			</xRayTube>
			<xRayMirror id="27010001" name="Inc. Beam Cu W/Si (parabolic MRD)" hybrid="false">
				<crystal type="Graded" shape="Parabolic">W/Si</crystal>
				<acceptanceAngle unit="deg">0.800</acceptanceAngle>
				<length unit="mm">60.0</length>
			</xRayMirror>
			<sollerSlit id="21010002" name="Soller slits 0.04 rad.">
				<opening unit="rad">0.0400</opening>
			</sollerSlit>
			<mask id="22030008" name="Fixed mask 4 mm">
				<distanceToSample unit="mm">220.00</distanceToSample>
				<width unit="mm">4.00</width>
			</mask>
			<divergenceSlit id="22010007" name="Fixed slit 1/8°" xsi:type="fixedDivergenceSlitType">
				<distanceToSample unit="mm">220.00</distanceToSample>
				<height unit="mm">0.19</height>
			</divergenceSlit>
		</incidentBeamPath>
		<diffractedBeamPath>
			<radius unit="mm">320.00</radius>
			<sollerSlit id="21010002" name="Soller slits 0.04 rad.">
				<opening unit="rad">0.0400</opening>
			</sollerSlit>
			<receivingSlit id="22010001" name="Fixed slit 4°">
				<height unit="mm">5.88</height>
			</receivingSlit>
			<detector id="7010017" name="PIXcel3D 1x1 detector" xsi:type="areaDetectorType">
				<phd unit="%">
					<lowerLevel>30.0</lowerLevel>
					<upperLevel>70.0</upperLevel>
				</phd>
				<mode>Scanning</mode>
				<activeChannelsEquatorial>255</activeChannelsEquatorial>
				<activeChannelsAxial>255</activeChannelsAxial>
				<pitchEquatorial unit="mm">0.05500</pitchEquatorial>
				<pitchAxial unit="mm">0.05500</pitchAxial>
				<readOutPeriod unit="seconds">0.135</readOutPeriod>
			</detector>
		</diffractedBeamPath>
		<scan appendNumber="0" mode="Continuous" scanAxis="2Theta-Omega" status="Completed">
			<header>
				<startTimeStamp>2024-10-04T13:07:57+02:00</startTimeStamp>
				<endTimeStamp>2024-10-04T14:04:03+02:00</endTimeStamp>
				<author>
					<name>PRO-MRD</name>
				</author>
				<source>
					<applicationSoftware version="6.1b">Data Collector</applicationSoftware>
					<instrumentControlSoftware version="7.0E 20130304">XPERT-PRO</instrumentControlSoftware>
					<instrumentID>0000000011142674</instrumentID>
				</source>
			</header>
			<dataPoints>
				<positions axis="2Theta" unit="deg">
					<startPosition>9.99826193</startPosition>
					<endPosition>129.99755682</endPosition>
				</positions>
				<positions axis="Omega" unit="deg">
					<startPosition>4.99913096</startPosition>
					<endPosition>64.99877841</endPosition>
				</positions>
				<positions axis="Phi" unit="deg">
					<commonPosition>0.00</commonPosition>
				</positions>
				<positions axis="Chi" unit="deg">
					<commonPosition>0.00</commonPosition>
				</positions>
				<positions axis="X" unit="mm">
					<commonPosition>0.00</commonPosition>
				</positions>
				<positions axis="Y" unit="mm">
					<commonPosition>-40.00</commonPosition>
				</positions>
				<positions axis="Z" unit="mm">
					<commonPosition>9.300</commonPosition>
				</positions>
				<commonCountingTime unit="seconds">32.895</commonCountingTime>
				<counts 470 480 536 467 438 470 484 470 455 497 490 477 461 472 461 517 454 505 486 452 485 458 481 460 494 476 462 480 508 508 500 458 470 498 521 436 462 461 471 462 447 484 476 475 480 494 462 457 478 478 474 487 447 467 496 466 473 444 470 434 499 483 452 463 489 429 501 482 492 469 455 481 494 492 420 483 434 467 475 467 477 454 495 481 452 475 466 433 468 482 436 498 498 469 475 499 426 449 450 494 474 514 473 498 448 485 486 485 451 494 467 471 515 497 443 468 489 515 507 437 485 457 426 481 517 485 444 504 485 448 486 457 484 427 478 467 445 475 458 505 475 479 456 458 467 445 475 464 469 446 387 484 489 478 457 482 464 443 489 448 419 473 460 420 504 490 464 456 474 457 514 468 446 480 486 498 443 469 464 507 477 457 474 468 484 474 476 456 470 451 498 486 428 487 501 428 468 464 494 466 487 484 500 449 472 452 459 460 464 450 475 493 474 442 512 466 455 482 442 426 472 507 472 490 495 479 462 458 433 439 469 465 481 430 463 468 532 460 450 466 434 457 482 471 491 483 460 506 459 448 478 462 504 463 473 466 420 469 464 443 447 449 421 459 462 429 474 454 462 460 491 422 435 460 495 524 465 455 503 448 463 497 447 480 459 453 493 481 430 440 478 501 491 436 445 441 442 435 450 438 459 448 441 497 456 410 476 455 477 474 475 457 489 463 403 502 439 442 437 485 439 444 449 468 485 420 468 416 511 478 457 454 474 483 431 454 486 437 498 448 480 454 431 426 477 499 495 480 468 458 447 423 439 448 463 469 453 455 453 431 444 441 459 458 454 460 455 470 446 439 419 417 440 505 421 484 456 466 444 419 434 416 486 459 479 484 443 453 463 436 453 473 479 446 447 456 499 469 504 498 490 426 503 435 450 492 437 461 417 473 506 454 479 428 436 452 423 405 449 453 446 462 412 430 427 467 480 467 459 462 443 449 467 428 415 439 439 451 477 460 426 482 432 490 420 410 448 433 449 452 459 495 443 451 439 458 434 482 492 432 440 442 486 467 437 399 441 439 403 423 427 451 463 436 450 430 453 437 467 440 446 420 442 459 424 426 424 423 416 417 445 462 425 470 437 456 438 441 431 457 428 452 421 420 418 440 422 438 436 469 461 434 434 458 445 417 401 467 444 410 447 439 422 448 440 420 417 429 409 429 448 409 414 449 441 453 441 417 440 438 448 471 450 464 442 464 434 468 458 406 433 460 435 450 414 472 386 461 448 447 452 432 437 441 468 436 432 442 424 406 444 443 400 468 479 445 424 430 415 456 433 452 414 443 406 466 409 396 467 439 435 436 451 409 424 429 377 442 420 417 442 417 424 391 422 423 487 405 410 470 439 422 420 450 414 411 443 446 426 421 409 462 424 436 434 442 449 461 431 433 458 421 451 436 430 393 432 458 418 455 401 462 434 449 420 415 402 447 415 432 424 421 411 416 461 441 411 391 419 373 425 407 413 420 425 447 440 444 425 437 407 441 431 435 429 417 388 427 419 447 412 435 460 418 430 455 429 411 396 433 394 419 399 412 393 437 393 398 388 436 405 421 428 407 405 428 378 427 429 408 421 430 385 393 409 391 427 401 407 425 445 445 461 412 399 412 419 394 362 389 418 419 410 423 410 418 395 423 415 434 380 420 367 390 425 429 384 431 450 440 421 398 402 404 453 390 416 425 415 441 413 411 378 422 428 417 395 433 410 432 434 389 465 399 412 421 402 399 402 423 403 440 424 421 452 439 403 420 456 420 445 431 434 477 436 399 395 396 447 405 405 401 437 390 370 410 391 402 395 432 406 436 407 406 412 395 385 389 394 397 432 414 405 417 437 379 390 411 416 381 378 384 380 374 398 358 396 399 428 385 419 375 379 421 426 375 384 358 373 410 393 411 399 436 393 393 408 413 394 405 382 385 382 358 397 414 397 395 414 335 358 402 413 415 391 394 392 401 409 412 408 398 412 389 384 385 393 379 364 419 368 362 367 421 376 371 408 387 392 394 388 380 361 378 390 383 362 343 378 387 384 416 380 373 426 395 399 384 359 368 413 377 382 384 395 418 398 364 367 407 386 407 415 393 386 368 371 361 387 358 378 386 408 381 407 369 391 381 396 391 371 357 420 379 353 368 406 376 388 363 380 373 384 387 361 369 384 396 414 401 373 372 398 399 398 349 377 397 402 405 362 360 366 462 382 405 378 372 351 365 368 344 407 393 370 379 394 377 364 353 395 385 392 373 386 393 365 350 382 395 373 368 415 374 380 393 369 399 396 417 384 357 390 404 393 400 359 377 386 380 366 391 374 376 394 398 382 384 419 454 432 407 384 439 448 454 519 503 512 595 649 934 1443 2237 3241 3409 2729 2192 2109 2243 2007 1702 1247 920 757 614 502 439 433 419 419 411 392 413 370 397 384 413 394 362 376 378 390 371 414 365 388 336 393 401 366 383 381 357 352 387 355 392 357 345 335 353 401 375 359 367 323 356 393 330 324 363 339 376 341 376 359 344 343 350 357 353 336 382 356 344 343 385 343 338 337 298 355 354 372 334 383 390 345 352 357 346 338 374 352 368 369 341 316 342 357 336 376 344 333 341 347 339 376 347 322 360 351 332 332 356 370 403 349 367 334 349 363 339 403 371 352 331 345 358 350 353 326 350 369 338 341 325 356 341 355 367 341 343 393 364 337 360 339 336 333 306 341 326 372 328 324 350 320 348 352 331 327 349 352 351 346 336 329 338 362 350 359 320 311 360 317 368 362 330 369 317 326 372 355 338 359 335 332 338 321 328 301 342 338 337 326 302 326 363 355 307 364 342 327 337 323 345 331 342 313 331 354 368 304 319 371 329 371 355 337 338 304 340 319 325 349 346 337 370 315 323 318 366 342 313 316 341 309 356 353 295 351 309 342 316 325 355 315 318 349 360 353 320 309 329 296 326 311 351 337 324 330 309 310 337 348 343 351 357 349 337 335 336 332 333 360 336 321 345 343 319 304 311 341 340 334 359 337 323 302 337 358 363 305 338 311 325 321 327 320 331 321 326 320 347 341 332 345 343 338 340 315 323 339 355 336 290 318 325 340 316 324 298 341 313 323 303 316 319 305 320 308 320 308 331 300 322 315 367 332 310 351 285 310 316 305 316 342 334 332 323 300 341 324 324 316 351 306 330 278 312 318 318 279 329 333 339 319 313 317 323 320 320 291 322 317 334 319 303 344 335 354 308 326 322 286 317 316 274 337 331 296 303 335 309 294 313 318 325 314 331 276 308 314 340 312 302 326 332 295 335 306 327 281 312 302 289 310 321 318 323 324 300 321 288 314 298 301 319 286 288 326 309 337 288 310 313 327 305 302 292 279 322 286 283 279 284 303 302 311 298 320 317 305 304 315 315 295 331 301 320 291 311 280 293 295 308 304 279 307 292 296 312 311 323 317 301 299 331 281 310 266 313 289 294 307 325 330 307 281 311 283 316 265 313 298 282 292 312 301 280 305 295 302 267 303 300 331 309 272 299 291 345 275 292 284 289 330 298 291 312 285 293 319 249 294 290 288 257 311 281 274 315 289 317 286 276 308 310 270 343 289 297 291 272 280 303 293 293 285 329 292 311 289 310 256 259 282 277 291 275 323 267 325 311 303 295 321 309 278 284 285 323 292 298 327 274 300 299 331 312 297 326 330 301 271 263 311 260 296 289 281 261 279 287 298 275 265 289 314 292 304 309 310 298 281 347 264 293 301 294 267 295 290 270 279 283 272 330 305 306 286 300 273 278 277 285 299 287 282 264 273 307 270 290 315 282 297 318 292 275 319 283 317 283 308 248 284 303 298 272 283 262 284 296 268 280 283 300 259 313 308 281 277 246 285 282 289 294 297 294 279 273 290 279 310 297 305 312 291 277 295 312 275 312 246 275 312 279 290 272 300 257 290 257 268 307 315 268 267 286 274 292 284 305 291 255 280 236 264 293 280 289 293 288 301 277 287 285 239 293 270 280 280 257 308 244 272 245 275 292 286 281 255 272 278 271 304 276 257 266 291 306 242 265 294 279 298 314 238 271 276 274 305 269 274 282 269 272 278 271 249 285 288 299 261 264 288 255 270 275 259 249 283 290 282 285 234 267 246 284 268 272 287 258 282 282 276 259 305 291 247 271 285 266 256 238 261 274 276 263 259 273 293 270 268 293 269 268 268 330 291 273 277 259 276 293 265 273 260 241 295 274 280 285 277 267 240 266 304 242 255 284 277 276 288 266 282 269 272 279 281 311 257 244 275 307 259 260 265 273 242 263 263 268 268 290 288 284 290 221 261 248 267 266 255 275 281 231 286 275 242 296 305 268 280 301 265 230 247 285 302 267 233 272 248 276 278 283 260 269 261 248 281 268 270 261 263 258 232 271 294 258 249 247 293 258 250 231 279 243 268 241 238 266 276 264 275 249 259 290 230 257 261 295 262 258 267 271 243 289 250 268 267 276 248 272 272 274 255 258 263 292 247 276 279 246 247 283 256 244 247 263 266 248 266 247 256 238 243 243 242 238 264 283 242 246 260 226 269 241 262 292 267 246 277 259 281 273 266 225 255 263 255 250 268 270 275 255 247 229 269 258 244 245 231 257 228 258 256 234 279 259 260 229 243 193 247 249 214 220 255 243 243 267 248 261 259 234 266 282 230 249 256 261 241 293 264 262 271 272 265 259 269 264 276 263 240 279 258 239 281 241 237 248 290 241 260 274 255 220 226 267 291 243 268 244 247 236 259 255 266 243 265 271 257 256 249 260 240 247 257 240 238 232 243 269 228 244 240 237 263 245 255 226 259 242 242 261 262 260 257 292 261 243 279 245 274 261 260 265 272 249 255 259 212 255 268 246 258 247 213 232 241 230 249 241 288 249 257 222 258 280 245 283 277 230 272 222 241 228 261 245 235 246 267 238 234 243 242 232 230 282 239 266 215 277 245 289 249 232 230 259 263 230 255 258 232 228 240 217 244 267 259 272 236 237 249 250 247 232 222 271 265 265 280 265 272 234 240 258 261 248 258 215 266 242 238 230 224 222 274 267 236 238 222 260 244 247 248 246 263 244 278 228 224 263 248 230 264 257 247 237 222 219 282 266 249 261 235 266 267 271 262 257 255 224 260 240 266 230 227 234 226 246 231 243 248 232 233 246 233 213 214 227 266 281 230 234 258 242 246 241 234 238 225 232 267 260 210 230 242 231 242 234 219 219 243 236 233 239 233 228 229 229 247 217 220 220 243 281 232 286 244 278 230 235 223 247 237 227 240 198 223 242 269 270 213 223 221 215 246 240 250 259 264 255 242 259 237 243 247 244 257 278 269 242 222 239 298 210 228 262 233 225 238 231 235 276 243 262 255 244 223 272 255 249 218 240 227 230 246 256 232 266 237 245 245 225 223 230 231 246 228 213 267 258 222 263 229 260 244 277 229 241 241 234 239 241 228 202 237 240 241 240 237 228 226 243 210 234 283 264 278 231 262 250 265 261 228 242 267 260 246 233 244 235 237 256 219 247 225 249 224 242 233 221 203 237 237 260 213 231 238 231 229 268 267 250 239 247 221 238 229 218 212 270 215 228 216 245 230 221 215 237 274 239 258 240 238 261 261 243 242 277 199 231 261 243 265 236 246 239 235 248 244 243 237 255 242 258 241 245 230 235 223 226 268 268 244 247 249 226 264 264 247 248 255 244 248 239 207 270 261 235 240 275 231 235 229 258 236 205 228 227 236 212 242 262 230 234 291 240 247 239 239 233 234 264 245 210 266 212 235 244 239 261 228 245 230 226 204 261 232 217 219 235 258 237 262 235 243 240 227 263 243 249 264 259 243 239 246 259 222 234 232 237 226 248 278 219 243 220 269 241 246 240 238 247 248 212 226 222 226 264 236 265 235 244 238 263 245 233 230 262 271 244 237 224 225 240 261 243 236 237 214 248 230 256 217 244 212 226 235 225 236 257 243 243 255 248 224 234 230 245 262 226 224 234 224 246 226 235 259 203 236 228 236 246 270 242 238 263 245 234 235 269 244 234 261 257 233 224 243 234 249 276 233 235 264 261 229 209 264 249 260 247 243 291 239 239 239 250 242 218 233 260 262 243 277 262 273 268 214 256 258 242 246 258 238 233 230 265 234 248 230 236 227 238 249 225 257 238 241 236 213 258 235 265 236 232 242 283 256 255 238 245 246 246 224 237 246 288 286 241 249 239 269 272 220 241 216 245 256 234 262 237 218 246 267 245 242 271 262 258 257 270 255 299 317 386 475 497 497 450 464 396 341 311 290 289 284 215 222 261 232 245 258 291 258 246 230 216 260 241 237 220 234 255 242 280 264 214 262 262 270 239 223 237 215 224 220 237 222 249 230 265 242 224 249 224 219 215 266 285 229 246 263 237 260 223 241 238 263 224 260 278 226 243 265 199 205 240 237 221 231 272 240 203 225 226 211 242 209 233 211 289 248 243 220 220 222 248 257 244 260 238 232 241 256 209 216 202 238 219 259 244 238 235 265 219 213 242 255 233 242 248 263 218 258 237 260 208 241 262 229 258 267 239 239 258 225 235 239 276 272 235 217 220 226 199 240 264 257 244 269 206 244 235 261 240 234 233 224 232 218 246 264 227 233 233 239 225 256 235 274 233 278 245 201 261 239 244 221 243 271 232 230 231 262 228 210 217 224 227 245 223 218 237 225 240 243 237 230 241 221 282 272 245 230 225 246 246 208 226 237 200 242 230 242 226 228 221 259 248 218 235 240 241 242 261 243 237 243 228 226 261 227 282 269 230 208 237 222 246 238 239 265 278 241 262 266 302 269 269 278 255 242 262 271 270 238 209 262 242 233 261 237 259 260 237 269 237 218 273 255 266 263 268 244 234 272 267 235 257 282 243 284 223 243 291 228 243 237 278 268 265 263 237 264 263 213 225 259 261 256 239 265 286 266 259 235 283 265 261 280 287 277 283 259 277 236 281 308 266 283 317 308 267 293 242 293 298 284 291 239 308 287 302 241 292 310 277 304 315 327 314 299 299 327 312 314 310 335 312 329 327 322 311 296 335 314 294 316 367 327 363 304 328 335 331 316 373 327 359 336 359 376 345 337 373 378 368 385 364 363 363 336 364 398 403 359 396 409 404 428 424 453 457 458 457 475 454 469 502 528 541 524 525 623 570 668 668 807 890 937 1077 1172 1267 1344 1417 1339 1414 1431 1422 1509 1731 1941 2230 2748 3818 5163 8269 16010 39464 69887 82052 82653 79849 70890 47189 22316 12250 9606 11822 22266 36138 42511 42689 40132 35369 23960 12145 6052 3654 2599 2078 1755 1502 1326 1193 1013 1034 875 875 831 772 778 661 703 658 628 585 575 585 580 565 516 523 529 494 509 471 460 466 468 419 431 442 391 372 438 419 420 415 378 387 343 363 360 359 355 365 324 338 345 311 362 343 335 349 329 330 336 348 324 333 324 329 283 321 293 309 301 300 300 298 273 277 282 312 278 319 299 291 324 293 269 273 321 277 264 243 298 273 262 273 266 269 288 287 283 289 303 281 272 256 259 281 302 297 256 290 304 276 293 298 271 258 269 286 261 246 278 286 268 289 258 260 281 284 271 263 279 294 277 268 246 282 273 290 266 278 246 288 238 297 294 265 262 246 263 311 272 301 258 299 249 271 247 274 282 279 270 287 264 273 270 268 255 276 257 262 279 280 286 264 255 285 279 283 270 272 295 270 274 259 259 258 276 270 245 272 261 273 276 298 288 314 260 278 312 286 295 269 289 309 284 282 277 299 285 320 301 277 292 282 291 291 262 260 328 295 287 308 296 285 306 289 296 325 308 331 303 299 326 331 331 345 344 357 326 332 321 341 345 345 355 318 347 380 382 377 396 407 403 468 443 454 448 504 487 483 523 535 542 529 504 547 524 580 515 562 540 589 574 568 579 545 473 498 516 506 476 463 447 449 404 429 398 401 429 340 391 348 371 362 357 333 346 328 299 315 311 330 305 313 264 294 287 278 285 283 261 292 282 274 273 278 255 300 289 274 259 271 284 268 278 239 243 225 265 268 287 262 244 237 264 261 227 236 267 250 258 263 283 246 247 213 236 261 262 229 256 276 244 286 271 247 223 243 249 237 270 260 263 247 244 259 246 249 279 279 229 255 234 258 246 243 240 258 228 234 238 281 240 227 235 221 238 256 232 235 218 240 220 259 229 259 227 222 236 250 245 235 249 215 257 242 219 246 250 247 239 249 216 264 224 221 231 224 235 216 212 239 270 245 232 295 256 228 236 266 292 225 243 227 242 239 241 237 231 244 263 239 223 220 258 217 238 224 246 282 261 227 275 242 259 230 237 235 214 231 238 210 224 275 218 241 231 196 234 232 230 225 216 257 216 235 240 234 214 240 270 215 241 230 260 224 242 225 240 244 222 240 257 240 224 276 216 277 236 246 217 233 267 231 237 215 234 236 244 235 273 205 242 202 206 245 228 221 259 248 236 243 222 265 229 213 247 213 262 246 212 242 222 230 200 260 239 230 248 236 257 221 245 218 228 232 241 264 257 262 248 216 241 219 265 211 255 213 216 248 238 228 222 224 232 212 196 224 223 248 222 255 226 229 221 233 266 249 256 212 238 198 249 259 211 246 232 243 258 230 238 223 226 227 233 255 223 245 256 242 244 255 218 257 223 227 199 247 233 237 222 264 241 209 256 249 267 245 228 247 218 236 210 236 238 225 259 245 248 245 256 255 230 271 223 238 248 225 200 262 226 219 222 256 266 227 234 234 220 261 241 240 246 270 247 240 220 232 247 234 244 215 231 237 250 246 208 268 222 242 217 292 224 231 248 247 221 239 262 244 222 249 259 233 236 262 240 255 262 233 267 220 244 240 235 243 234 273 229 221 248 237 214 211 233 245 259 231 263 236 258 234 221 235 236 242 258 216 237 246 230 227 265 246 226 242 266 220 231 260 242 227 227 239 204 299 248 220 230 223 213 246 243 247 241 263 273 229 233 265 269 265 270 238 256 222 234 247 220 239 219 217 271 227 226 226 229 226 239 198 279 247 212 255 247 246 218 215 224 248 263 245 239 256 225 249 247 274 245 245 243 248 215 235 237 228 257 256 219 220 237 264 265 238 239 236 245 237 234 212 230 225 240 210 231 217 265 237 245 228 233 259 255 233 246 222 230 241 259 226 234 237 236 227 225 223 264 255 230 234 232 226 238 266 266 263 245 268 228 267 212 230 257 238 247 226 277 249 237 238 248 232 248 231 217 232 226 217 259 217 258 220 239 242 227 222 231 238 263 255 242 234 245 270 217 212 247 220 224 209 240 230 240 235 243 261 268 226 243 238 212 213 230 227 271 260 229 239 239 255 233 273 243 197 260 263 258 213 234 208 236 216 234 235 242 227 231 257 205 222 233 230 211 219 232 224 212 264 229 219 238 240 264 263 268 221 234 241 235 260 239 267 257 246 265 245 232 246 258 249 231 257 258 233 216 239 229 231 238 259 234 275 216 224 223 249 205 225 246 258 198 226 230 279 236 267 232 236 255 262 225 213 242 228 242 212 218 244 226 237 239 269 229 236 236 222 240 246 236 269 235 240 230 222 262 224 259 259 241 247 215 245 232 245 265 231 236 255 262 235 265 260 231 250 205 248 248 229 266 238 231 234 242 232 218 256 227 229 244 221 261 250 229 249 235 270 235 237 237 214 234 265 268 259 248 221 229 230 234 233 244 238 244 242 243 212 241 238 262 238 248 218 241 244 260 239 242 244 232 237 243 240 219 256 231 220 244 266 269 248 242 222 232 261 226 245 246 245 273 264 214 243 239 237 241 205 247 243 237 259 233 265 260 250 257 215 238 226 247 233 249 256 256 258 230 216 246 237 236 223 224 276 233 245 228 222 249 258 240 242 245 245 244 230 242 241 219 243 244 234 223 256 270 259 259 244 240 274 231 243 245 194 233 271 243 216 255 245 231 236 248 256 246 232 220 229 263 270 235 274 246 241 244 244 242 278 241 270 228 229 235 213 246 260 224 261 220 248 247 219 243 265 237 249 221 276 231 240 249 227 227 220 273 247 264 256 255 218 284 232 243 231 235 210 243 286 231 219 243 257 258 264 246 233 214 228 245 250 250 266 217 240 278 227 267 266 225 257 264 241 235 263 270 245 261 205 255 259 226 223 255 211 257 222 269 244 265 232 255 239 274 242 229 262 242 272 228 232 261 228 224 232 248 236 231 240 255 239 237 268 271 246 250 237 235 248 256 221 225 261 235 250 241 261 263 266 242 238 256 261 234 268 263 258 228 228 242 265 264 250 237 227 248 238 244 269 245 229 237 265 242 246 264 230 291 243 264 242 236 230 238 256 245 240 235 255 267 227 237 249 238 281 262 220 273 224 233 240 247 280 276 224 221 256 208 272 227 242 241 206 240 259 240 262 241 257 262 259 235 273 238 239 276 274 203 225 286 243 238 258 238 249 244 259 238 276 231 246 243 295 256 262 267 207 241 248 238 242 273 243 267 261 256 256 259 256 245 214 243 268 227 243 249 259 247 221 267 266 243 261 236 242 249 244 265 271 247 227 241 263 239 246 248 291 260 218 245 267 240 216 242 240 240 237 225 262 240 257 245 265 237 229 257 224 256 247 277 286 260 239 241 224 230 237 264 246 237 260 247 218 262 244 228 239 264 243 260 259 236 238 228 277 238 235 261 235 246 262 223 256 231 227 267 228 264 276 250 256 259 256 257 221 266 256 237 240 255 228 266 241 257 256 288 237 250 225 283 249 264 218 257 257 226 261 238 239 260 258 267 260 244 244 289 266 259 288 247 240 250 263 227 234 241 232 245 242 234 241 274 232 242 221 245 217 267 238 244 239 268 245 242 233 236 219 259 249 268 220 255 242 241 214 250 244 227 232 256 282 277 242 218 231 231 224 255 259 260 266 245 260 245 236 275 266 272 264 264 273 263 240 275 278 276 235 287 240 265 246 285 224 265 248 301 262 259 256 267 262 236 272 260 233 238 259 225 228 228 246 259 265 248 250 233 284 240 262 249 242 236 270 229 247 248 237 260 241 285 247 315 277 260 236 274 198 248 255 280 257 278 224 294 231 279 291 256 277 265 258 238 281 218 248 231 247 272 265 277 244 241 255 262 285 234 248 268 247 282 274 249 264 267 245 260 259 257 268 248 239 271 225 240 270 239 229 245 226 248 235 215 239 249 244 275 230 257 259 246 272 259 281 281 280 234 303 242 240 260 282 275 245 255 271 247 234 266 236 267 223 220 264 265 248 261 257 239 215 249 260 268 235 250 242 265 246 224 259 235 234 256 257 223 280 236 242 234 236 242 258 266 249 262 266 279 271 238 271 232 236 242 268 257 264 220 244 267 238 279 233 242 258 266 261 240 263 275 262 274 277 274 276 259 236 276 206 262 215 243 233 265 219 287 256 262 211 242 268 241 236 234 256 271 270 267 261 256 245 264 273 255 247 260 260 266 256 227 257 225 248 239 231 245 247 262 273 263 237 244 272 243 264 293 266 248 269 269 246 264 233 215 260 265 248 244 242 255 279 259 273 257 238 215 249 239 237 231 244 261 260 249 219 268 298 270 255 248 225 235 244 257 216 279 234 220 243 259 238 250 224 268 258 236 285 217 255 270 261 257 274 273 241 246 261 261 264 232 267 276 262 233 265 271 241 265 280 239 249 225 243 260 213 243 273 236 237 226 235 223 247 271 274 261 248 248 262 270 263 249 230 242 225 266 276 291 247 261 256 275 240 268 276 257 293 242 248 276 233 241 271 224 276 260 236 273 260 249 278 228 257 260 261 260 261 250 258 260 241 270 263 265 259 249 258 259 255 257 272 270 276 249 248 242 270 281 255 257 241 243 257 270 261 259 242 239 232 269 247 280 246 230 283 280 233 259 259 277 230 242 243 290 277 266 267 263 260 238 268 249 213 265 219 284 244 273 256 258 283 280 237 222 280 247 283 250 239 275 226 277 239 248 233 245 227 264 246 256 277 284 241 229 238 234 275 261 270 244 230 240 232 274 219 239 304 261 248 239 244 241 265 266 255 243 237 262 293 245 233 239 243 273 260 279 242 257 273 268 237 256 268 242 276 263 261 259 215 268 259 226 269 260 264 278 216 229 268 241 246 234 242 226 247 291 245 255 242 249 209 244 244 213 234 264 247 263 249 260 240 250 227 266 269 230 258 258 246 224 223 241 278 275 266 249 274 271 268 260 230 245 258 256 238 271 271 249 228 237 232 248 272 226 234 246 256 236 287 267 269 238 243 265 257 261 224 260 227 264 276 211 242 270 221 279 277 270 279 267 286 259 256 229 282 238 228 260 257 263 226 268 271 239 271 244 258 248 263 246 249 271 272 228 236 264 234 249 247 238 248 256 222 255 259 268 261 232 227 237 260 246 267 273 256 268 231 257 295 246 238 241 262 238 265 262 277 269 277 285 271 268 273 265 270 265 256 258 280 241 282 240 257 269 247 263 286 264 276 283 293 242 291 278 261 287 276 260 266 231 238 278 287 246 264 266 269 277 243 259 263 249 249 261 285 263 272 225 292 280 281 287 274 266 285 283 277 266 293 247 271 291 268 268 272 229 267 283 268 293 244 261 284 273 275 287 274 264 290 241 288 280 271 255 279 270 241 278 274 269 269 246 236 286 272 267 241 286 233 242 264 258 266 233 271 270 234 262 258 242 249 209 246 250 242 242 267 260 243 256 242 234 259 259 267 245 259 278 257 240 226 227 295 227 249 256 241 245 266 247 240 203 257 262 238 238 275 275 227 248 246 264 275 261 239 236 235 238 232 223 241 241 261 263 241 245 242 249 258 224 272 269 238 261 259 267 283 259 268 284 247 270 272 246 263 237 264 262 256 232 234 240 243 244 225 256 281 228 225 256 275 245 272 257 265 234 259 216 261 245 277 236 249 287 269 263 243 289 231 280 247 234 237 225 279 261 274 237 269 244 229 243 245 232 230 246 248 233 259 268 230 249 261 270 272 276 237 264 212 249 266 234 226 238 237 245 217 216 262 233 221 238 267 255 250 247 233 241 245 230 274 268 263 269 255 258 275 246 232 249 266 258 283 263 249 227 239 236 261 241 249 244 215 236 257 258 257 219 256 236 196 229 220 261 229 237 239 303 243 256 248 241 259 228 260 231 246 276 245 264 226 259 211 243 237 247 266 255 270 247 248 224 227 281 212 263 239 261 210 215 246 249 247 243 264 244 262 263 279 227 228 247 281 286 235 259 232 267 292 296 266 236 266 261 241 236 246 272 225 248 260 260 230 264 234 214 229 288 271 220 259 275 257 243 246 261 292 239 214 262 259 238 237 268 288 257 272 228 247 232 267 232 303 257 231 239 265 258 255 296 266 249 245 235 246 280 246 261 280 257 255 238 259 258 246 247 236 235 211 271 266 258 262 241 271 276 228 266 228 258 220 234 227 271 271 230 277 245 242 244 264 231 239 245 221 220 226 257 264 260 248 257 209 256 256 229 265 269 270 218 242 262 246 246 272 236 260 250 275 265 280 272 247 243 260 241 246 240 226 225 264 267 243 260 227 259 257 272 281 249 260 257 248 233 262 259 243 243 246 262 239 212 248 232 230 260 221 275 261 239 216 248 241 240 237 249 263 217 264 248 241 259 219 232 260 208 221 241 266 247 278 267 224 268 231 245 220 222 244 261 268 270 272 249 257 235 265 202 237 228 227 255 260 261 247 246 243 230 264 240 231 271 234 232 279 245 248 214 283 256 231 262 245 270 257 246 256 256 264 256 281 241 263 259 230 230 249 237 265 237 249 259 245 238 240 283 257 260 266 256 273 246 247 260 258 272 229 236 269 283 285 247 248 277 257 224 256 230 264 233 241 219 221 272 261 258 280 231 226 255 248 261 280 249 268 235 255 238 223 259 243 219 263 255 224 242 259 246 247 240 243 255 234 231 245 258 249 234 238 226 257 234 259 259 256 246 238 276 277 285 232 231 235 232 231 260 269 249 233 247 276 263 238 256 262 268 231 279 222 229 238 249 245 219 258 274 285 246 246 238 239 228 235 259 248 281 231 236 218 244 248 268 255 219 247 239 246 248 227 221 259 225 239 237 242 268 232 261 282 284 230 262 217 265 242 237 231 239 277 247 228 260 260 242 264 240 296 246 278 238 235 239 260 226 289 259 257 274 271 216 226 244 247 220 231 267 267 257 222 257 256 272 245 277 259 266 258 239 269 242 233 233 226 268 265 266 269 258 249 243 214 260 248 243 247 255 264 248 270 267 242 257 257 276 286 258 243 220 235 244 266 233 249 247 261 266 262 245 235 244 248 218 248 268 266 278 239 277 287 237 277 256 239 232 257 244 224 233 273 267 238 237 242 266 255 260 247 226 242 267 260 256 246 298 248 270 275 249 238 242 241 267 265 257 264 232 283 271 244 242 269 258 271 240 248 242 265 261 276 222 285 276 232 243 249 246 269 277 271 248 240 266 270 248 243 281 270 264 303 267 250 234 267 264 229 275 265 245 247 246 239 245 239 238 243 278 259 226 241 256 266 240 270 258 269 261 250 247 264 234 242 271 260 242 245 241 211 273 259 240 257 241 248 267 265 233 258 287 269 292 260 242 244 264 245 255 241 291 279 266 261 256 278 278 260 271 238 241 241 269 260 236 275 273 249 234 250 265 259 268 260 240 248 248 267 244 265 240 281 244 274 256 242 255 248 264 232 246 248 255 249 268 249 281 260 257 258 278 278 260 236 279 249 241 278 246 269 245 269 240 256 225 271 264 235 244 260 244 240 274 239 273 249 247 263 222 249 248 255 267 275 258 267 241 237 271 257 279 258 241 239 224 265 300 272 242 235 247 258 248 230 229 271 279 289 242 233 270 285 248 280 272 267 228 244 255 240 238 245 262 249 263 265 246 244 240 249 241 274 260 257 222 279 256 263 266 279 261 271 255 267 227 236 272 272 258 243 221 234 244 267 230 245 249 255 260 232 216 260 248 262 246 248 249 248 238 240 255 277 257 259 274 256 267 234 231 257 264 271 258 262 277 238 255 270 238 236 247 260 236 284 233 258 269 286 258 270 250 247 246 240 206 260 268 264 246 248 257 247 238 267 268 263 240 268 261 256 262 229 258 261 259 267 292 248 243 255 247 248 271 225 246 236 277 259 263 241 258 236 255 257 212 259 269 263 249 258 278 238 282 241 262 244 230 264 248 247 262 237 244 263 265 233 262 244 241 284 242 259 244 273 233 255 241 261 244 263 257 261 248 265 257 262 264 266 264 243 276 245 238 245 291 237 262 255 245 260 266 269 249 247 273 233 273 248 263 245 270 264 258 207 246 246 243 240 265 223 231 272 234 262 248 234 264 277 278 281 297 265 235 291 266 264 262 257 245 249 266 299 277 282 295 262 284 265 245 273 228 243 281 264 237 267 259 272 276 255 262 228 258 265 290 278 260 300 267 229 265 269 255 243 263 257 247 262 218 228 245 281 241 268 256 268 232 258 234 265 263 263 222 262 278 229 226 234 256 232 279 268 208 280 256 236 247 230 265 248 238 237 232 248 263 266 233 265 248 270 283 264 241 241 272 255 248 243 246 275 264 237 267 256 261 242 227 289 275 256 241 282 267 242 288 260 275 258 239 260 261 243 243 263 278 273 272 258 247 244 232 289 247 256 292 266 245 270 234 260 237 269 267 239 258 232 278 242 229 269 277 247 278 273 260 260 260 243 243 273 259 281 243 276 284 236 262 262 257 243 228 266 274 256 220 240 264 262 245 295 261 235 267 263 244 266 258 283 255 236 226 245 274 271 261 255 249 280 249 270 265 245 266 245 240 238 265 259 264 243 283 227 260 247 264 277 247 272 257 280 291 234 270 246 263 258 242 273 229 250 272 247 272 257 264 269 292 246 262 282 273 286 260 259 228 259 249 240 258 276 262 286 287 282 247 274 275 239 240 295 235 272 264 287 280 267 247 284 270 250 275 298 269 241 259 291 241 265 289 278 266 279 272 260 258 276 291 306 310 301 315 329 362 391 425 475 518 564 543 574 573 542 458 486 379 358 311 295 316 287 294 339 308 258 277 279 299 292 282 276 292 270 242 283 279 287 268 223 269 291 280 292 269 278 274 223 244 276 265 295 258 268 275 256 279 291 256 265 246 258 283 274 267 257 271 259 279 270 255 275 262 292 244 261 269 255 268 293 283 277 273 243 274 263 239 246 274 296 272 273 262 265 267 282 280 284 281 248 242 266 261 276 272 278 235 282 255 275 272 262 271 288 260 260 250 271 291 266 276 266 218 289 272 299 248 288 260 276 278 260 244 237 275 255 257 263 262 288 260 260 286 280 272 262 269 299 257 304 274 278 276 244 282 280 319 281 296 256 256 267 287 268 276 266 278 280 308 249 278 277 275 301 209 266 281 286 270 246 283 290 298 293 284 263 264 309 282 295 288 258 272 282 305 274 273 283 312 289 308 277 281 312 292 289 290 318 299 332 312 304 279 289 299 296 300 294 278 283 292 337 310 331 328 301 291 289 332 311 323 323 312 324 319 268 304 302 319 331 322 295 326 311 288 304 307 315 298 290 287 294 315 321 293 287 302 289 314 300 278 301 294 271 277 272 293 290 274 263 275 302 292 279 300 273 290 285 247 258 275 242 276 276 279 312 279 265 281 256 287 312 264 277 285 270 262 289 256 282 268 264 283 285 293 244 267 265 286 274 275 268 286 255 256 245 239 264 284 273 257 267 296 261 226 298 248 289 269 276 281 274 263 247 241 238 279 258 255 264 266 271 243 265 270 273 276 277 276 275 273 282 280 284 265 258 278 290 283 241 308 277 268 246 258 284 241 256 279 267 255 274 246 266 237 258 258 286 269 268 241 262 255 293 281 279 267 273 269 275 265 261 278 290 260 275 248 269 250 272 277 282 284 255 243 261 264 269 278 231 287 278 238 264 277 258 292 274 274 266 262 282 248 311 260 260 243 233 258 245 294 250 285 224 237 268 245 268 266 272 261 233 273 286 256 280 287 279 290 296 269 273 264 274 288 255 275 245 233 279 273 280 276 267 247 264 288 229 257 268 245 241 258 270 287 246 289 239 263 285 259 292 271 305 245 225 266 277 280 294 266 282 270 235 262 309 241 259 313 278 287 270 278 287 239 279 281 271 262 267 249 265 259 265 243 290 262 264 290 271 229 262 266 244 276 272 248 297 261 263 270 277 274 250 305 259 271 269 258 293 255 302 280 262 258 303 276 275 261 268 264 319 269 273 277 246 292 283 257 241 265 285 256 290 258 219 283 280 274 263 248 247 274 273 261 275 263 262 271 258 286 282 285 274 282 268 284 291 289 277 269 282 257 292 299 263 250 297 301 270 272 282 296 279 277 283 284 238 300 264 322 293 316 284 312 321 291 305 302 301 308 283 286 283 270 274 262 276 262 281 257 295 279 288 282 271 263 274 266 270 276 264 292 300 257 288 290 240 265 259 279 250 257 284 262 285 302 258 296 295 285 295 264 268 255 262 265 267 307 305 285 282 283 300 262 274 290 263 278 272 302 267 274 279 245 244 275 261 248 263 247 279 317 259 264 303 297 327 288 295 266 297 282 274 245 266 262 270 294 277 247 273 323 298 297 262 266 267 262 261 263 317 275 294 242 268 256 274 291 259 268 289 264 287 270 249 277 247 277 290 319 275 288 289 288 302 285 294 258 285 309 276 283 285 270 296 276 280 298 269 277 290 296 265 290 291 283 303 277 307 297 266 274 284 290 280 307 287 289 291 256 301 280 298 274 293 284 315 290 287 295 286 291 292 295 312 280 320 280 288 309 288 300 303 330 321 298 274 269 297 274 300 298 265 309 277 306 275 322 293 295 321 294 318 293 294 307 317 300 309 313 295 300 305 327 303 295 313 299 307 296 291 315 279 278 306 274 295 279 289 293 297 267 319 334 301 306 319 310 318 313 304 317 315 332 299 315 325 322 329 329 296 333 326 318 309 292 322 298 327 345 333 296 330 300 310 313 300 336 313 315 329 306 327 276 342 325 319 290 319 295 322 294 347 285 335 348 301 303 320 305 322 347 336 359 331 327 349 347 367 351 352 347 337 343 340 354 338 356 335 323 322 363 337 343 331 341 336 314 327 345 389 363 332 344 350 337 345 310 341 356 375 330 347 366 342 314 358 362 382 349 349 357 369 370 378 329 373 389 330 374 380 353 351 364 364 376 372 377 399 358 360 400 406 372 349 393 414 395 429 390 412 402 392 430 397 429 400 398 430 430 405 396 449 458 454 458 423 452 451 426 433 428 467 450 457 447 482 471 493 480 507 442 505 513 524 524 488 530 545 573 578 613 666 564 674 712 704 782 894 895 869 947 961 907 1014 1046 973 1015 1040 1036 1067 1057 1071 1089 1098 1040 994 975 1021 954 963 1084 1107 1104 1122 1131 1140 1210 1302 1311 1424 1491 1590 1634 1739 1914 2039 2234 2503 2624 3064 3350 3821 4366 5027 6073 7369 9197 11690 15919 22721 34960 54925 78503 94224 100807 100426 91235 74417 53283 37115 26284 19367 14477 10949 8798 7350 6266 5375 4814 4443 4316 4311 4613 4873 5159 6184 7570 9365 12388 17465 25538 34983 43596 48520 49497 46616 40401 31438 23590 17235 12362 9156 6927 5576 4520 3709 3184 2696 2413 2234 2009 1805 1670 1570 1449 1391 1281 1286 1214 1114 1112 1022 975 940 1003 961 924 929 851 853 812 803 846 783 731 706 737 729 681 686 679 649 651 679 631 620 608 630 568 582 588 560 572 583 538 564 520 565 531 499 493 497 527 452 514 484 458 467 465 514 472 475 453 440 442 477 406 430 416 439 483 425 410 413 412 425 438 413 438 380 418 406 400 394 415 418 385 410 392 415 412 404 378 367 419 385 367 395 401 384 383 361 380 381 364 392 396 367 362 395 351 385 361 380 342 355 332 319 368 362 341 378 331 344 353 319 361 337 363 352 338 320 328 332 344 311 324 338 310 338 299 347 383 307 324 333 349 335 312 325 319 346 318 302 304 313 313 326 328 318 300 301 340 359 321 282 305 321 311 310 323 333 300 321 314 321 305 312 308 334 280 302 307 316 328 291 317 307 310 291 320 360 279 299 309 286 297 298 270 313 293 308 310 307 290 280 318 293 295 269 298 289 311 301 285 306 257 295 299 276 276 281 299 276 241 310 315 284 281 270 282 278 294 290 317 301 286 256 276 295 278 327 275 301 276 283 323 279 279 306 264 318 280 282 290 283 291 288 295 280 283 273 298 278 271 293 295 295 297 291 292 287 263 290 309 262 246 300 271 282 266 293 244 280 268 318 268 288 283 296 299 280 297 259 294 277 269 273 273 236 271 276 247 295 282 283 280 275 276 288 261 282 295 284 267 324 279 279 258 284 268 309 241 305 295 292 267 294 244 280 234 264 283 278 279 276 230 274 295 270 273 292 297 282 248 260 280 248 243 243 243 274 263 300 302 267 277 261 247 267 259 245 282 292 266 295 289 287 270 270 307 298 274 277 273 270 289 296 323 281 289 270 268 289 243 260 263 261 238 257 275 267 260 290 235 269 265 289 286 279 299 276 304 291 278 289 273 266 288 281 276 268 310 261 296 267 260 285 270 294 264 302 264 269 241 249 258 263 270 258 263 277 288 294 259 278 309 267 284 264 298 273 269 271 302 264 288 258 270 280 294 291 294 291 311 281 271 285 282 265 273 274 282 275 274 286 267 262 269 273 279 263 266 280 267 241 263 276 289 288 277 299 261 294 281 301 291 294 280 296 247 286 261 245 244 281 271 235 289 274 281 285 283 302 259 293 262 264 279 296 245 294 294 276 256 278 270 285 240 275 246 273 257 288 268 282 283 275 277 269 256 259 248 240 288 270 299 243 234 284 276 271 246 262 244 261 256 287 236 267 318 272 290 280 267 268 258 285 271 270 282 282 267 277 255 248 296 284 302 279 269 238 296 267 268 269 292 247 271 297 263 273 309 276 275 300 283 264 271 275 305 269 265 326 266 274 243 280 269 294 277 266 263 257 269 275 295 293 290 325 264 274 278 248 243 289 280 262 296 267 269 306 287 310 257 289 287 246 265 273 285 260 279 296 308 282 266 276 261 297 281 275 279 247 294 275 275 293 276 300 279 263 287 266 274 246 262 255 250 296 243 293 317 311 279 272 294 290 287 299 274 238 271 285 248 248 273 257 280 265 279 265 296 295 281 282 284 272 278 272 231 282 274 278 260 298 271 276 276 286 277 286 276 245 233 315 290 284 269 296 242 261 301 275 255 261 270 241 278 274 277 284 282 266 299 277 297 275 301 255 302 275 291 280 247 280 272 244 282 286 292 311 265 274 274 269 290 283 285 263 296 263 288 292 263 289 283 284 286 282 269 295 286 282 279 311 289 284 269 288 292 284 282 287 327 299 291 319 314 267 283 278 297 267 288 272 291 305 264 275 284 294 286 298 283 284 259 293 288 284 281 302 296 292 272 263 271 242 302 294 292 239 255 289 294 286 313 299 299 281 266 263 272 287 292 293 286 272 264 224 261 307 295 275 298 265 265 277 263 258 278 274 260 269 305 268 281 271 268 305 275 234 280 284 256 274 264 281 287 276 278 284 247 289 258 307 283 283 255 306 292 264 281 288 261 283 298 286 258 262 245 268 268 259 281 282 276 275 286 286 263 285 273 255 288 286 266 274 258 268 244 272 304 273 264 288 287 268 246 305 241 300 276 260 292 282 275 270 246 315 244 277 249 261 268 289 260 262 261 249 247 233 283 274 272 276 289 277 276 274 245 288 306 294 280 301 295 284 260 263 259 245 266 255 268 283 239 276 268 280 277 276 269 275 271 268 274 279 246 249 249 249 289 275 268 273 244 269 262 277 295 271 241 231 280 282 291 241 266 271 271 265 276 270 281 266 310 286 247 264 270 308 257 291 247 280 242 294 270 277 286 263 272 309 261 244 270 301 293 304 281 282 262 276 249 282 291 263 271 258 294 286 247 273 294 273 265 272 265 262 281 295 282 290 263 306 269 282 260 287 257 292 265 274 276 295 294 249 276 276 262 295 294 278 257 294 276 290 305 289 289 284 300 257 284 262 236 258 276 283 276 277 273 271 272 293 263 280 261 284 246 293 279 218 248 268 304 278 287 283 274 239 306 277 281 261 234 264 265 258 282 259 262 233 235 269 268 249 266 276 274 266 277 269 261 256 248 256 238 273 261 282 284 276 291 295 268 242 288 278 263 282 274 281 278 277 266 261 290 276 284 278 307 261 293 256 296 261 257 268 275 258 264 242 235 260 281 304 270 289 247 269 263 277 277 289 279 279 266 276 303 275 274 265 265 239 247 274 272 282 255 303 267 279 256 280 284 277 259 268 273 260 276 286 246 289 285 278 274 307 261 270 276 262 288 295 282 277 290 262 270 271 276 276 271 262 267 249 273 264 240 273 262 261 280 272 256 282 289 287 259 264 274 269 260 291 272 288 269 261 284 265 284 269 314 278 276 244 277 269 258 264 290 271 277 290 286 273 255 247 286 234 257 250 255 291 271 274 290 269 264 264 271 267 275 278 268 271 299 246 279 278 266 261 270 263 269 273 292 301 262 281 264 297 263 269 274 244 272 277 263 262 302 291 281 298 285 241 318 288 241 270 270 295 248 271 271 260 268 304 237 289 255 292 265 269 291 269 298 249 304 270 270 279 281 274 259 257 242 269 294 267 290 265 266 246 282 282 265 294 277 289 291 250 278 241 276 264 278 272 233 266 247 273 292 274 236 264 231 276 281 244 285 264 264 270 276 280 274 289 274 260 265 277 255 260 261 298 271 264 298 271 319 278 286 277 257 275 258 257 279 274 270 275 232 239 282 272 271 270 268 239 248 264 265 270 269 263 269 287 274 274 260 258 258 257 291 235 271 285 260 263 267 271 286 276 272 273 249 277 314 263 291 268 248 256 281 293 260 276 264 240 258 289 293 269 282 273 267 287 308 291 257 278 262 262 258 280 284 293 284 279 239 276 281 266 262 275 244 294 249 243 284 263 256 284 266 297 271 256 285 255 272 277 267 286 302 261 281 244 249 231 271 298 298 266 242 299 265 246 283 240 256 274 262 247 310 282 311 304 287 245 271 238 273 241 286 262 264 270 258 301 268 255 265 265 237 261 277 275 243 235 260 324 284 276 228 256 277 277 262 275 238 243 269 256 283 267 249 239 284 260 279 273 266 281 257 275 258 283 289 279 262 283 267 249 267 265 262 266 243 229 248 255 280 276 278 226 262 273 267 240 261 260 244 275 245 246 246 281 257 286 248 240 258 257 286 282 276 256 279 249 260 273 260 286 296 260 270 243 288 274 272 267 228 249 284 236 267 284 290 257 255 270 255 298 276 265 228 267 260 289 280 264 271 269 265 240 270 246 261 270 245 247 274 266 242 268 283 258 317 258 268 248 273 256 283 282 261 258 260 301 260 278 289 262 264 248 256 279 278 247 269 268 260 277 290 266 264 266 283 280 285 246 258 268 263 262 281 258 269 212 257 270 246 280 247 243 267 205 257 273 243 275 275 249 289 286 281 259 248 286 290 265 241 229 241 282 279 238 242 281 287 269 285 297 258 244 262 263 243 268 278 275 242 249 267 261 290 260 246 296 277 268 280 278 267 267 271 264 275 268 279 265 249 268 269 261 265 285 243 274 267 270 239 247 227 258 270 291 290 256 300 257 267 268 247 259 283 297 278 255 276 288 265 270 263 267 234 258 231 284 243 289 282 268 234 299 285 245 226 276 246 302 285 260 261 271 250 266 267 267 263 275 262 272 261 256 290 291 269 281 255 283 245 249 270 297 275 313 288 260 291 266 277 316 310 270 244 286 291 248 271 266 286 256 268 249 295 242 257 259 276 293 275 265 265 237 264 278 257 281 295 285 284 287 287 287 293 282 271 286 312 279 241 281 256 295 242 264 281 285 281 285 257 289 259 277 262 261 315 261 276 286 264 255 248 257 287 290 263 271 257 272 275 234 261 264 276 271 232 269 263 261 265 305 257 275 283 304 309 321 266 264 289 293 276 279 258 237 275 295 276 277 298 262 288 266 263 270 271 290 269 249 287 269 295 264 288 267 274 257 280 261 267 224 258 294 280 273 277 270 292 291 269 256 258 269 279 295 284 313 271 258 275 312 263 295 281 274 274 300 277 258 274 282 267 296 275 278 263 294 292 272 272 277 247 241 274 264 296 289 282 276 259 275 277 289 248 277 288 264 259 262 282 255 280 240 236 255 286 295 286 293 267 266 243 240 297 245 301 245 287 258 297 302 284 287 264 219 284 271 233 287 279 303 281 302 262 272 286 264 307 258 256 260 247 301 296 263 275 324 302 270 273 259 261 287 294 280 259 301 244 264 289 265 235 293 264 281 282 247 262 263 263 266 292 292 284 287 325 279 296 282 261 296 286 299 263 270 259 276 297 267 289 270 271 265 283 275 268 274 281 288 268 281 284 298 277 310 275 270 264 296 268 262 266 284 244 285 265 275 248 267 287 303 245 271 289 270 277 273 287 283 249 283 269 274 288 270 273 231 288 260 281 248 256 316 294 301 294 273 300 240 268 280 268 266 279 250 268 285 240 278 283 295 285 317 241 279 279 289 289 267 267 237 273 277 244 278 283 262 262 266 265 255 272 282 289 248 275 281 269 288 247 267 289 274 297 293 289 265 257 273 264 267 244 291 245 269 285 265 286 275 263 272 250 247 286 246 275 268 276 292 260 287 241 267 284 278 248 246 284 256 278 248 269 272 248 240 301 276 275 279 296 264 288 287 284 280 291 292 288 260 248 233 270 290 258 273 262 295 283 272 299 242 294 258 290 280 261 276 276 256 286 303 247 276 260 280 269 279 305 300 271 263 279 244 287 265 263 291 239 268 262 266 268 290 275 259 266 268 276 284 270 244 260 293 274 293 280 263 283 264 286 284 264 270 279 255 276 234 263 273 261 278 274 271 249 278 270 270 272 244 263 270 275 270 279 274 272 265 260 292 258 284 300 244 276 257 269 268 257 259 265 249 296 255 267 268 273 278 258 266 296 264 293 267 262 257 258 278 277 277 262 267 262 272 269 257 244 269 284 292 295 266 260 264 301 272 268 290 310 291 275 269 298 278 268 238 256 295 280 280 267 287 283 236 280 237 279 276 283 282 263 275 293 268 261 281 295 288 267 284 273 284 285 277 268 245 292 276 241 245 291 310 309 309 273 286 298 247 293 262 229 307 276 257 279 322 284 274 243 281 298 242 243 276 288 282 271 272 279 277 283 264 276 272 322 287 286 287 261 286 279 320 263 268 277 311 277 302 275 243 280 266 308 296 280 282 256 277 284 269 308 286 318 274 279 280 304 291 295 282 296 271 302 271 264 310 290 280 275 260 281 243 283 270 288 277 244 286 258 291 332 293 306 293 323 267 298 321 289 297 267 248 328 327 288 283 286 290 264 309 283 307 283 248 288 289 280 277 300 268 278 299 289 265 277 284 274 277 308 287 300 289 240 300 295 308 294 299 282 309 259 284 277 289 270 288 329 226 274 276 260 288 300 288 283 288 303 292 300 289 274 292 264 285 267 276 265 288 288 293 287 279 288 296 293 299 294 267 269 277 326 282 278 288 261 289 228 275 271 282 330 272 256 315 280 293 268 282 245 264 280 276 305 270 265 284 303 269 288 282 273 270 270 286 260 269 278 264 308 281 267 229 271 296 281 289 309 275 273 266 264 293 292 303 289 285 301 256 303 281 290 279 259 282 296 255 267 256 279 293 294 273 270 273 263 267 256 290 242 288 276 244 274 300 248 273 290 267 290 234 245 232 270 288 249 260 302 263 312 268 289 280 261 241 286 270 270 294 258 280 287 283 305 282 243 292 256 284 276 303 263 275 276 281 302 288 269 284 284 264 282 292 274 266 266 245 280 303 272 291 291 277 270 296 272 303 268 285 270 256 288 282 269 277 275 289 264 263 259 292 291 245 280 237 267 255 269 289 292 293 261 271 291 266 280 288 250 244 249 286 287 242 299 273 291 247 265 282 246 290 270 268 271 291 290 304 302 280 269 274 271 239 282 247 272 265 290 305 243 290 243 289 256 269 283 284 280 283 292 260 287 295 255 293 265 279 246 259 273 246 294 240 259 273 298 264 243 279 264 279 270 296 271 271 277 297 297 255 255 277 275 261 272 305 265 315 280 284 268 268 289 284 302 261 221 261 295 264 292 311 266 271 246 283 257 273 239 270 292 292 296 243 294 289 282 302 273 272 300 309 270 283 279 263 279 269 258 256 264 226 232 261 245 250 273 264 260 268 265 294 262 236 257 235 268 272 280 266 256 287 289 298 240 290 257 279 299 260 265 271 284 248 295 258 271 281 272 250 284 276 270 261 266 285 284 274 255 295 288 283 270 265 278 248 283 279 255 295 286 262 261 300 258 291 263 272 265 285 269 290 276 264 278 304 259 258 248 266 276 261 282 276 298 272 269 294 267 299 274 291 285 267 285 258 278 274 275 255 263 292 256 248 263 244 317 269 269 258 261 272 274 295 277 274 272 299 266 262 246 279 237 301 284 270 298 272 262 267 291 267 297 291 279 274 294 243 232 266 279 262 275 315 271 279 283 265 268 230 268 256 263 273 308 272 286 283 302 278 262 269 246 262 318 247 246 287 277 285 268 282 261 266 282 262 271 290 270 261 255 274 224 262 265 270 286 281 278 247 313 296 286 282 255 298 256 272 290 310 266 261 264 265 307 265 246 264 275 277 292 283 281 284 268 285 266 292 279 277 264 277 298 260 300 255 277 267 287 312 285 284 283 245 319 275 286 307 272 274 267 275 279 278 249 281 280 270 300 294 233 291 281 237 286 239 257 243 270 232 295 289 277 290 241 300 293 235 276 274 295 275 291 228 271 261 246 286 281 255 286 246 293 287 268 280 282 307 260 285 270 287 289 264 283 295 247 280 291 280 286 273 262 264 283 273 282 280 264 247 231 246 276 289 297 246 243 262 298 293 290 292 276 300 269 273 300 306 289 257 228 249 261 289 275 287 299 300 288 259 276 291 273 333 270 302 233 269 300 277 298 276 284 244 269 266 276 240 278 271 275 267 268 306 271 255 276 274 288 287 259 275 290 271 277 284 323 282 257 292 285 296 267 306 246 289 306 292 277 273 295 289 264 249 264 273 281 285 298 274 312 298 258 272 293 289 273 267 284 273 259 276 280 287 274 278 281 281 325 283 303 293 271 262 270 268 287 259 239 272 276 291 268 270 272 292 287 286 245 268 288 282 279 263 283 269 268 290 261 305 259 277 309 290 267 297 268 279 298 292 276 293 305 271 284 280 290 264 285 280 282 274 336 270 267 286 278 288 264 283 287 294 261 283 297 291 279 269 267 286 295 288 257 276 271 281 283 276 289 270 268 311 279 281 274 300 268 272 292 276 257 287 265 315 299 244 263 312 294 308 281 241 288 299 248 293 292 279 266 279 280 304 282 266 269 282 266 263 276 270 277 245 279 281 300 292 284 297 298 303 314 256 292 278 308 300 246 328 297 309 298 307 268 295 301 283 306 260 268 284 293 250 305 298 272 263 247 289 259 301 272 233 321 263 263 290 296 267 294 270 273 285 294 292 303 262 298 273 301 273 294 308 309 277 280 269 277 286 274 285 268 260 290 292 288 277 281 290 241 297 289 293 297 303 303 294 282 300 279 313 273 295 291 258 308 295 285 270 267 304 287 282 278 264 278 279 282 277 260 299 266 264 269 268 245 267 276 275 310 248 280 255 270 267 258 288 289 267 247 305 241 265 302 222 279 283 266 286 319 286 264 271 292 286 256 282 302 293 280 293 259 277 261 245 274 239 309 307 309 288 247 264 278 302 282 282 291 246 296 277 294 285 267 245 293 263 305 268 279 275 264 291 297 275 293 276 302 245 230 291 287 262 269 274 291 274 270 235 271 285 284 287 300 268 273 271 277 270 260 271 315 291 293 303 272 263 241 257 276 259 316 288 273 288 284 291 295 289 268 296 279 285 303 267 259 319 285 277 277 301 292 278 307 288 273 258 280 264 283 291 288 291 283 270 289 270 279 278 270 281 266 243 291 264 284 266 307 271 289 278 284 335 282 300 274 263 305 295 268 279 299 271 262 263 266 275 257 266 265 263 279 301 244 238 243 264 284 289 290 261 272 292 295 285 290 274 262 277 285 237 283 283 292 287 319 255 273 315 304 256 280 245 262 292 287 302 290 269 271 281 294 283 287 278 261 272 261 297 289 266 295 288 282 273 261 278 271 285 283 266 266 289 304 286 289 270 303 264 275 276 281 270 281 289 256 286 239 271 328 306 275 296 259 288 264 247 259 295 285 294 270 294 269 261 299 311 281 264 277 277 256 287 317 293 290 270 265 288 246 285 298 279 302 298 305 306 278 270 301 281 281 270 295 280 286 261 301 279 267 297 289 286 298 299 293 262 277 265 281 276 281 257 261 283 264 276 267 270 280 272 294 259 271 262 245 274 246 258 262 266 299 255 273 291 289 297 264 235 288 272 236 266 267 281 262 281 247 281</counts>
			</dataPoints>
		</scan>
	</xrdMeasurement>
</xrdMeasurements>