File: data/XRD/CS-Vakuum/XG-pre/W6822-3A_CS_Vakuum_pre.xrdml
<xrdMeasurements xmlns="http://www.xrdml.com/XRDMeasurement/2.1" xmlns:xsi="http://www.w3.org/2001/XMLSchema-instance" xsi:schemaLocation="http://www.xrdml.com/XRDMeasurement/2.1 http://www.xrdml.com/XRDMeasurement/2.1/XRDMeasurement.xsd" status="Completed">
	<comment>
		<entry>Configuration=Factory configuration, Owner=User-1, Creation date=7/8/2013 4:01:53 PM</entry>
		<entry>Goniometer=PW3050/65 (Theta/2Theta); Minimum step size 2Theta:0.0001; Minimum step size Omega:0.0001</entry>
		<entry>Sample stage=MRD Cradle; Minimum step size Phi:0.01; Minimum step size Chi:0.01; Minimum step size X:0.01; Minimum step size Y:0.01; Minimum step size Z:0.001</entry>
		<entry>Diffractometer system=XPERT-PRO</entry>
		<entry>Measurement program=C:\PANalytical\Data Collector\Programs\Jorrit\2thom\_absolute_2th-om_10-130deg_PIXscan_56min.xrdmp, Identifier={15BCCF57-2807-42BD-B5B9-ECC0B3DC9284}</entry>
		<entry>Batch program=C:\PANalytical\Data Collector\Programs\SimonL\batch8x_2thom_10-130°_z9.1_x0,10,20,30_y20,30,40,50_57min.xrdmp, Identifier={9A1B954C-70C5-4DE2-A2B5-D0000261ED0F}</entry>
	</comment>
	<sample type="To be analyzed">
		<id></id>
		<name></name>
		<preparedBy></preparedBy>
	</sample>
	<xrdMeasurement measurementType="Scan" status="Completed" sampleMode="Reflection">
		<comment>
			<entry>_absolute_2th-om_10-130deg_PIXscan_56min</entry>
			<entry>PHD Lower Level = 4.83 (keV), PHD Upper Level = 11.27 (keV)</entry>
		</comment>
		<usedWavelength intended="K-Alpha 1">
			<kAlpha1 unit="Angstrom">1.5405980</kAlpha1>
			<kAlpha2 unit="Angstrom">1.5444260</kAlpha2>
			<kBeta unit="Angstrom">1.3922500</kBeta>
			<ratioKAlpha2KAlpha1>0.5000</ratioKAlpha2KAlpha1>
		</usedWavelength>
		<incidentBeamPath>
			<radius unit="mm">320.00</radius>
			<xRayTube id="1010048" name="Empyrean Cu LFF HR (9430 033 7310x) DK442154">
				<tension unit="kV">40.0</tension>
				<current unit="mA">40.0</current>
				<anodeMaterial>Cu</anodeMaterial>
				<focus type="Line">
					<length unit="mm">12.0</length>
					<width unit="mm">0.4</width>
					<takeOffAngle unit="deg">4.2</takeOffAngle>
				</focus>
			</xRayTube>
			<xRayMirror id="27010001" name="Inc. Beam Cu W/Si (parabolic MRD)" hybrid="false">
				<crystal type="Graded" shape="Parabolic">W/Si</crystal>
				<acceptanceAngle unit="deg">0.800</acceptanceAngle>
				<length unit="mm">60.0</length>
			</xRayMirror>
			<sollerSlit id="21010002" name="Soller slits 0.04 rad.">
				<opening unit="rad">0.0400</opening>
			</sollerSlit>
			<mask id="22030008" name="Fixed mask 4 mm">
				<distanceToSample unit="mm">220.00</distanceToSample>
				<width unit="mm">4.00</width>
			</mask>
			<divergenceSlit id="22010007" name="Fixed slit 1/8°" xsi:type="fixedDivergenceSlitType">
				<distanceToSample unit="mm">220.00</distanceToSample>
				<height unit="mm">0.19</height>
			</divergenceSlit>
		</incidentBeamPath>
		<diffractedBeamPath>
			<radius unit="mm">320.00</radius>
			<sollerSlit id="21010002" name="Soller slits 0.04 rad.">
				<opening unit="rad">0.0400</opening>
			</sollerSlit>
			<receivingSlit id="22010001" name="Fixed slit 4°">
				<height unit="mm">5.88</height>
			</receivingSlit>
			<detector id="7010017" name="PIXcel3D 1x1 detector" xsi:type="areaDetectorType">
				<phd unit="%">
					<lowerLevel>30.0</lowerLevel>
					<upperLevel>70.0</upperLevel>
				</phd>
				<mode>Scanning</mode>
				<activeChannelsEquatorial>255</activeChannelsEquatorial>
				<activeChannelsAxial>255</activeChannelsAxial>
				<pitchEquatorial unit="mm">0.05500</pitchEquatorial>
				<pitchAxial unit="mm">0.05500</pitchAxial>
				<readOutPeriod unit="seconds">0.135</readOutPeriod>
			</detector>
		</diffractedBeamPath>
		<scan appendNumber="0" mode="Continuous" scanAxis="2Theta-Omega" status="Completed">
			<header>
				<startTimeStamp>2024-10-04T12:11:20+02:00</startTimeStamp>
				<endTimeStamp>2024-10-04T13:07:26+02:00</endTimeStamp>
				<author>
					<name>PRO-MRD</name>
				</author>
				<source>
					<applicationSoftware version="6.1b">Data Collector</applicationSoftware>
					<instrumentControlSoftware version="7.0E 20130304">XPERT-PRO</instrumentControlSoftware>
					<instrumentID>0000000011142674</instrumentID>
				</source>
			</header>
			<dataPoints>
				<positions axis="2Theta" unit="deg">
					<startPosition>9.99826193</startPosition>
					<endPosition>129.99755682</endPosition>
				</positions>
				<positions axis="Omega" unit="deg">
					<startPosition>4.99913096</startPosition>
					<endPosition>64.99877841</endPosition>
				</positions>
				<positions axis="Phi" unit="deg">
					<commonPosition>0.00</commonPosition>
				</positions>
				<positions axis="Chi" unit="deg">
					<commonPosition>0.00</commonPosition>
				</positions>
				<positions axis="X" unit="mm">
					<commonPosition>0.00</commonPosition>
				</positions>
				<positions axis="Y" unit="mm">
					<commonPosition>-30.00</commonPosition>
				</positions>
				<positions axis="Z" unit="mm">
					<commonPosition>9.300</commonPosition>
				</positions>
				<commonCountingTime unit="seconds">32.895</commonCountingTime>
				<counts 458 469 441 435 441 434 445 422 422 436 476 423 461 454 463 500 458 469 444 435 461 455 436 424 404 449 461 414 438 455 416 430 435 476 434 447 442 449 457 439 465 456 478 446 397 435 449 451 419 390 467 447 410 451 393 447 452 406 443 462 418 426 428 455 472 420 453 473 424 451 438 434 409 447 420 418 445 418 422 395 426 466 420 408 428 462 426 442 428 417 415 483 447 444 433 385 394 436 401 448 439 402 418 439 454 386 464 449 442 396 439 440 420 444 438 421 451 401 430 470 460 404 436 438 439 419 449 400 418 421 424 429 456 446 401 401 444 412 415 419 427 458 469 418 420 373 425 468 453 403 432 440 415 401 435 382 453 437 389 431 405 433 407 379 411 419 429 398 432 409 390 451 440 362 406 411 431 396 405 376 405 439 429 437 400 444 415 416 436 425 398 404 411 410 401 470 416 448 437 471 396 421 432 423 397 412 450 438 436 424 409 416 380 414 415 421 430 405 438 406 402 450 415 386 417 384 440 407 398 419 430 430 401 434 420 403 389 408 395 407 397 414 451 417 395 391 399 405 405 415 387 447 408 365 398 386 405 403 420 375 417 409 403 417 406 400 401 396 374 402 380 422 449 427 422 420 438 413 449 423 434 409 367 416 419 429 387 378 474 405 406 391 427 423 415 407 377 407 382 411 383 363 442 417 413 433 395 411 418 379 398 377 419 350 403 387 392 421 410 459 430 407 414 424 405 372 425 412 408 368 425 442 393 403 400 391 369 417 403 438 377 372 392 376 393 388 388 413 420 396 412 400 391 408 382 394 381 393 383 400 434 368 387 429 395 387 414 406 422 381 402 385 406 387 420 409 435 363 425 390 418 369 383 418 390 396 382 374 398 386 413 419 369 406 405 386 369 380 356 392 349 369 374 387 385 387 399 379 380 429 376 391 416 376 340 412 388 381 413 393 379 390 381 396 403 383 379 395 367 364 402 366 380 389 362 412 377 394 366 395 360 377 342 360 385 338 404 402 360 347 364 421 369 365 391 393 366 379 373 333 349 333 351 367 373 371 362 356 393 360 369 342 347 394 392 386 390 368 362 390 395 372 380 348 386 393 374 362 346 365 357 337 373 361 410 371 356 380 420 354 365 369 343 360 380 365 367 338 367 386 368 374 374 372 377 351 363 334 361 399 336 380 374 348 402 374 366 335 373 372 396 382 325 339 401 380 358 385 383 377 329 356 343 357 345 336 386 349 350 365 361 370 363 348 367 354 359 349 350 358 356 348 373 359 359 330 392 390 376 336 379 357 355 404 395 377 374 394 350 358 383 339 386 341 350 378 345 361 361 354 365 368 349 336 346 376 321 342 369 337 351 337 385 352 353 363 382 369 396 338 341 330 353 342 358 345 362 365 342 359 344 409 355 330 358 368 383 376 345 356 347 371 356 317 366 363 319 322 372 344 372 348 365 333 359 333 376 336 354 356 372 349 344 332 311 356 363 329 320 345 390 334 318 344 346 343 399 343 370 351 311 310 352 333 337 344 371 349 333 336 360 339 349 352 364 351 352 376 317 354 348 309 336 352 341 341 321 330 319 372 338 372 333 360 351 348 347 347 331 337 348 331 309 329 361 350 341 335 338 364 357 333 362 325 321 332 332 360 314 358 365 325 331 331 331 340 319 328 363 372 359 348 338 369 355 345 360 311 326 350 310 330 346 320 346 350 359 366 340 370 323 325 335 354 342 359 368 341 340 363 345 312 334 355 331 374 330 381 315 338 360 329 342 373 367 340 364 343 334 341 312 323 349 346 352 341 324 319 348 362 307 317 323 345 328 340 346 341 384 317 326 359 322 355 363 330 339 333 317 321 366 305 311 375 319 349 304 298 337 326 336 317 348 347 332 330 358 344 334 327 285 315 318 352 318 326 318 334 343 307 338 362 376 329 378 304 355 325 365 317 336 304 340 296 343 326 347 316 322 352 333 330 347 342 337 324 317 311 328 314 334 348 300 312 318 332 323 328 293 326 347 318 322 339 310 300 323 333 340 328 307 299 328 321 355 348 333 321 338 354 323 324 332 322 322 332 316 327 304 342 350 343 343 299 352 350 305 345 354 312 325 301 335 301 335 334 317 321 339 356 318 340 319 332 306 330 317 326 312 344 322 345 345 310 319 320 349 341 336 313 337 325 319 343 318 338 347 307 339 315 359 321 334 290 323 325 317 284 328 317 325 341 322 325 299 349 329 331 340 321 351 338 338 334 330 320 295 306 342 298 357 301 336 307 327 329 286 342 288 340 301 323 321 321 312 321 329 345 304 313 298 316 323 321 327 328 314 327 330 313 309 336 304 315 311 313 336 296 341 317 304 284 345 334 343 329 299 312 282 319 311 303 298 341 309 348 315 324 330 302 329 345 316 311 322 335 310 310 317 349 300 301 329 310 318 313 327 312 313 316 289 304 333 314 318 313 344 334 322 304 345 325 339 320 287 327 329 333 299 300 282 314 325 305 319 290 351 308 305 298 305 318 327 275 338 299 298 299 295 303 300 350 312 316 312 302 327 303 315 301 301 299 311 334 278 300 326 329 337 309 314 308 305 330 327 298 337 301 309 289 339 308 285 276 310 322 303 334 304 321 300 314 302 312 308 320 285 321 321 299 319 307 332 330 285 320 298 329 292 278 273 310 319 291 290 321 296 343 296 315 289 312 310 290 314 329 327 322 282 312 268 282 297 300 277 283 305 313 293 287 283 320 293 331 301 283 289 305 311 300 319 311 284 286 294 318 300 301 311 289 311 305 285 325 289 329 281 300 294 295 299 337 300 280 319 325 331 307 312 289 304 262 297 327 298 312 294 302 311 296 292 330 310 291 296 296 305 317 303 308 298 321 301 321 323 285 307 290 313 318 280 291 290 296 303 298 302 317 326 319 300 310 299 319 308 341 321 292 269 305 304 293 304 299 288 296 293 298 297 338 317 332 331 317 332 257 327 320 323 314 313 298 319 284 319 296 287 287 324 306 296 284 281 300 297 288 325 272 300 291 287 276 280 306 277 313 293 256 274 277 292 303 272 313 295 260 278 274 294 289 325 273 310 287 288 283 280 296 294 325 292 303 309 302 249 317 336 307 286 303 315 339 301 280 265 285 315 304 263 298 299 257 289 284 322 286 258 287 278 269 274 322 272 285 295 286 296 274 302 285 288 292 307 299 300 280 290 275 264 298 290 288 285 310 287 275 286 292 283 280 307 298 303 286 299 295 293 278 307 267 291 264 289 283 298 307 248 303 308 287 274 334 282 297 303 286 287 270 287 275 263 281 259 272 281 239 314 267 293 272 303 312 291 273 296 298 293 300 318 304 288 276 308 293 311 278 287 297 288 287 303 295 277 263 295 249 287 312 246 276 265 317 284 282 300 293 281 305 296 303 312 297 275 286 278 276 296 289 285 299 294 303 313 303 248 261 281 271 294 292 266 303 272 287 265 301 284 256 302 319 311 331 294 298 265 287 255 276 290 301 319 294 299 305 303 267 292 288 265 283 313 283 277 272 268 284 294 270 290 291 303 270 257 299 258 277 303 292 268 315 276 284 288 273 306 273 281 277 291 290 271 288 318 282 286 259 274 279 294 338 294 290 290 273 288 318 309 309 259 277 262 286 281 280 277 294 262 292 293 278 268 310 278 280 262 291 287 275 315 262 273 262 284 289 295 287 283 259 286 323 291 287 296 281 274 265 297 288 266 274 277 291 285 297 291 288 280 247 282 275 275 290 299 259 277 263 240 269 282 286 272 299 292 257 311 285 299 268 264 289 291 289 269 263 232 292 271 283 275 284 295 296 284 272 289 273 232 280 283 269 262 288 280 263 284 276 284 260 313 264 300 286 290 299 291 243 292 273 256 275 290 264 268 269 291 273 267 281 270 291 294 264 285 263 267 268 245 259 272 291 288 255 282 277 279 263 259 288 273 295 286 286 277 248 276 290 265 270 287 278 277 276 255 241 261 241 277 290 295 263 292 249 261 275 268 261 322 270 265 279 269 272 263 274 279 303 262 275 276 307 266 257 258 265 278 258 270 250 291 248 291 269 270 276 291 275 257 241 260 271 269 272 280 268 264 256 256 293 264 280 266 257 274 259 248 249 256 287 263 256 270 280 293 246 268 268 281 281 276 278 243 265 285 258 281 274 292 280 276 238 266 284 273 255 306 290 278 240 293 273 233 289 308 236 297 266 256 245 284 263 266 284 285 256 277 273 233 242 248 273 267 285 271 281 266 281 265 281 291 285 265 224 277 303 288 256 235 266 280 293 288 286 289 262 282 247 261 257 276 290 280 316 270 281 277 226 272 262 294 246 283 272 267 268 268 276 245 272 279 244 274 284 276 258 266 270 275 276 286 256 265 308 244 274 286 280 290 278 248 272 249 289 271 276 283 283 270 259 243 278 228 272 237 279 273 256 272 261 286 287 275 262 244 269 280 284 300 276 320 290 233 229 288 239 248 240 265 319 285 278 255 286 256 264 296 271 272 232 242 281 292 293 220 287 264 275 292 258 273 301 265 285 247 280 262 269 263 265 248 248 258 249 240 279 271 249 249 309 279 275 293 282 242 224 288 261 235 284 292 261 270 268 305 289 246 266 266 285 268 267 270 291 250 247 262 248 281 246 246 280 265 283 237 259 263 264 263 281 256 280 247 283 226 255 248 283 265 273 305 270 277 246 247 269 267 290 249 275 284 240 245 271 269 256 233 296 265 264 278 293 249 244 266 275 287 257 281 234 300 247 264 248 262 283 259 242 265 272 222 268 286 231 231 269 270 284 232 297 290 234 281 277 271 255 276 255 276 272 247 238 249 249 258 278 279 269 217 244 275 277 276 249 288 282 227 259 278 269 248 249 234 274 281 295 229 271 267 281 284 230 275 294 278 309 240 239 289 224 285 267 262 247 248 272 246 282 248 270 250 299 269 281 294 267 272 241 258 247 250 247 295 242 267 249 289 263 263 283 292 265 235 240 263 244 262 248 270 307 284 237 274 280 240 279 258 258 256 261 284 277 278 279 243 265 255 284 221 273 266 243 282 286 274 269 270 262 271 293 275 244 249 278 279 262 259 298 257 281 258 260 267 244 264 243 246 270 264 303 280 273 242 259 270 285 235 274 292 285 256 247 273 246 278 239 302 278 291 292 233 237 256 267 279 263 259 268 272 276 241 233 287 239 241 275 282 275 241 267 242 285 269 284 262 279 267 257 257 266 273 255 255 278 263 255 237 273 246 267 278 258 258 259 270 268 276 226 275 269 235 265 265 280 261 289 249 276 246 257 259 275 243 292 249 241 274 227 258 262 258 258 276 249 275 265 247 279 264 271 277 249 250 244 234 259 288 271 271 267 272 260 259 249 261 247 237 271 239 279 239 280 237 261 244 261 274 283 249 293 271 273 257 241 269 241 265 240 285 257 271 296 272 242 281 274 244 271 270 250 249 266 257 271 264 250 279 263 248 260 258 231 278 269 276 276 270 235 246 224 284 273 271 238 245 263 260 258 223 277 273 289 263 247 268 239 257 279 248 284 243 268 236 233 268 264 234 242 236 258 247 257 269 264 247 242 261 261 232 248 242 236 241 247 291 267 308 275 257 262 267 263 255 299 246 275 269 243 240 289 265 261 256 214 272 290 266 259 261 270 276 260 270 262 281 265 275 284 267 267 261 304 237 258 257 238 242 264 260 292 273 295 308 267 258 278 258 268 286 240 238 247 266 247 241 248 245 281 277 276 278 273 268 273 245 240 273 256 244 258 272 275 266 261 273 269 297 286 286 269 266 244 248 256 309 271 272 246 245 274 278 264 241 289 288 289 269 274 290 272 245 249 276 298 259 277 266 249 298 278 288 282 296 258 290 279 287 267 278 263 268 258 277 293 285 291 304 310 279 274 304 311 300 289 302 279 363 297 301 321 312 322 337 295 315 318 313 320 312 297 314 311 353 337 312 380 345 364 373 358 350 344 331 391 355 369 311 335 325 356 351 293 339 324 350 335 316 316 318 342 325 338 351 315 314 296 327 298 298 333 283 315 287 309 297 307 272 292 312 292 310 288 275 323 298 288 295 289 283 298 309 280 296 301 297 291 297 308 272 266 279 306 295 281 267 275 296 274 289 256 270 289 293 248 285 322 273 273 237 265 273 271 249 257 275 286 244 268 281 272 237 277 276 280 287 263 291 285 273 294 272 275 270 265 269 273 301 271 295 276 249 274 292 266 281 236 270 244 293 259 263 279 244 276 285 257 277 298 269 266 265 326 314 357 429 548 564 540 529 455 423 401 335 316 285 287 282 296 291 238 290 244 267 306 289 288 306 245 263 256 267 293 256 271 242 264 258 287 268 266 274 283 263 255 293 306 231 295 258 288 282 284 277 279 279 278 244 235 279 273 245 240 248 277 295 245 276 278 256 263 259 257 268 282 240 260 265 241 260 266 258 277 290 248 272 289 249 260 250 261 265 247 249 269 260 274 265 241 275 257 245 262 283 304 296 279 262 285 291 272 290 275 290 250 269 237 272 274 264 249 276 243 275 282 279 281 283 275 281 243 270 289 255 257 281 262 295 248 268 270 267 307 289 278 242 276 266 262 280 264 275 246 283 265 257 289 241 249 266 257 272 242 263 260 228 248 276 297 268 267 245 226 283 270 246 262 263 296 255 202 266 234 286 291 290 261 307 269 257 274 268 239 244 278 270 269 271 277 264 256 245 270 237 281 261 260 260 262 259 262 231 246 264 257 277 262 272 263 295 281 231 270 260 287 270 295 280 257 272 287 275 265 268 258 249 275 262 247 288 238 287 281 305 285 266 306 296 294 307 309 295 311 279 267 261 283 269 317 279 276 279 282 276 291 258 308 291 298 273 256 269 278 267 293 262 298 278 291 294 320 328 308 299 300 292 262 246 327 290 299 299 281 264 313 301 291 264 286 302 286 278 302 287 295 235 288 297 286 333 260 282 297 303 302 275 313 308 302 298 310 325 297 297 321 301 313 327 336 298 319 350 324 306 315 301 349 333 298 325 332 319 323 325 324 326 347 348 318 351 356 352 377 341 372 331 367 358 372 366 349 378 354 343 344 331 365 353 385 385 361 364 368 383 388 367 401 419 437 416 384 389 379 396 441 433 390 427 430 449 499 434 443 477 488 460 504 467 529 492 528 527 571 575 609 611 631 724 829 964 1024 1256 1384 1437 1402 1498 1429 1397 1482 1399 1551 1714 1976 2515 3087 4184 6175 10318 22211 52531 78562 86347 85748 80999 67113 38377 18155 10984 9730 14609 27537 39531 43732 43096 39985 33045 20101 9644 5249 3441 2508 2056 1625 1431 1308 1188 1100 990 971 889 882 807 744 766 721 702 664 623 627 599 636 559 569 540 546 507 462 486 486 460 448 445 445 434 434 419 418 431 407 385 377 391 396 378 382 414 401 369 373 369 375 359 377 340 367 338 353 366 358 325 316 355 331 313 312 341 317 331 362 344 354 281 305 309 317 322 327 298 301 325 324 325 318 306 315 331 311 291 270 313 276 325 285 294 284 296 303 289 287 286 320 300 279 303 293 240 289 270 270 296 298 268 246 300 244 280 300 290 284 285 284 302 288 272 288 284 264 282 327 259 293 285 279 263 334 276 307 268 286 267 289 295 286 281 257 283 265 270 293 278 293 281 300 265 262 266 289 263 274 270 263 280 242 239 271 281 280 267 304 287 300 301 315 302 293 286 315 294 299 268 297 292 273 270 256 280 292 287 257 284 274 289 276 278 280 271 305 293 290 291 286 305 277 299 336 290 290 287 283 280 326 292 287 298 283 309 312 315 338 345 325 336 332 326 304 339 273 347 337 323 343 345 352 302 338 342 344 361 381 368 365 356 359 384 390 386 414 445 444 403 460 445 453 476 499 495 482 537 538 555 566 547 508 563 550 567 567 582 555 531 559 534 528 517 502 488 520 508 525 447 449 476 397 424 437 405 413 420 324 384 348 374 306 352 315 343 339 321 327 333 310 340 315 327 313 292 326 312 304 281 295 248 322 334 316 311 326 293 298 286 306 275 298 290 258 279 295 260 280 298 233 292 272 247 269 242 326 287 278 274 266 258 245 226 290 243 263 292 259 282 268 260 242 300 279 278 266 304 286 264 290 244 274 268 284 290 249 260 280 267 281 284 281 293 269 248 248 270 226 259 291 273 274 245 256 269 280 243 273 255 269 261 258 265 275 258 272 265 255 284 256 264 276 229 280 264 275 258 264 303 263 244 260 263 270 246 238 273 264 255 255 265 280 259 269 256 257 281 280 298 232 248 267 271 236 295 257 257 261 250 267 278 261 267 255 267 261 265 269 319 266 246 284 222 264 255 259 249 269 271 284 272 283 240 247 256 278 278 274 235 276 246 248 256 255 284 280 231 287 270 288 240 230 261 240 265 298 257 275 269 263 258 250 235 273 267 257 257 263 249 268 245 281 275 263 266 247 240 224 242 271 240 276 276 282 279 282 264 269 246 271 274 272 295 294 245 244 232 268 236 230 276 255 297 261 287 262 250 273 265 258 280 259 255 245 224 245 236 271 248 264 237 246 285 269 231 258 270 261 262 230 231 268 240 258 273 249 263 249 256 255 244 267 262 270 279 229 270 280 262 248 232 247 248 276 274 278 235 236 271 273 259 237 266 242 256 256 230 257 285 255 261 263 261 276 236 248 270 228 241 257 257 269 275 281 228 260 260 264 256 255 270 229 265 249 241 271 271 278 229 270 246 277 287 229 257 234 258 264 277 263 244 280 233 248 279 267 245 256 260 280 273 274 277 225 271 288 258 256 288 245 286 296 262 257 243 236 248 241 237 274 232 273 273 294 295 234 249 236 273 261 276 228 255 245 229 271 287 277 274 264 247 219 291 262 244 258 238 257 272 240 287 264 267 265 249 256 260 235 260 272 230 274 260 271 243 232 256 258 265 267 260 280 257 248 246 260 257 271 242 228 274 260 278 243 265 232 271 269 262 265 263 270 260 244 267 267 266 248 266 248 278 259 284 277 247 231 280 248 258 239 263 261 258 248 288 271 286 243 222 248 282 259 245 248 279 220 260 278 256 247 220 285 256 273 255 263 266 273 264 245 246 294 268 265 271 238 235 272 269 267 288 276 273 231 266 282 270 267 259 257 278 236 264 263 248 215 248 237 223 274 228 264 276 230 246 242 259 207 260 249 273 289 274 246 260 271 286 273 282 249 271 269 232 238 269 266 259 231 270 256 275 244 267 273 290 255 242 240 258 261 266 258 271 233 278 286 273 245 289 231 242 268 241 243 240 248 234 265 237 271 279 241 256 245 242 225 261 258 245 269 274 247 260 268 229 270 232 227 223 267 265 263 229 282 248 282 267 247 242 262 236 278 237 275 266 255 244 243 279 265 261 232 285 258 289 261 248 268 260 260 258 233 234 257 263 295 263 212 262 283 249 261 248 278 288 235 276 268 265 262 280 265 259 244 279 273 247 283 271 304 271 270 261 248 241 258 277 261 285 236 247 278 243 267 267 262 255 255 274 258 248 247 259 271 248 272 273 232 241 261 239 233 236 261 238 234 241 248 269 222 261 261 266 233 262 268 272 287 286 228 244 262 278 286 237 268 270 212 284 259 249 245 277 266 256 268 263 247 231 279 260 244 265 268 268 259 260 274 261 271 237 282 241 258 272 271 245 257 285 239 311 266 241 270 220 284 237 228 257 263 226 244 233 273 248 278 241 229 277 274 262 273 270 262 241 257 243 243 261 246 265 273 277 243 287 278 248 279 246 234 258 225 243 227 255 230 275 258 257 264 273 270 273 256 248 248 231 250 249 229 266 274 239 270 222 283 264 265 245 235 238 240 260 234 265 262 276 239 273 276 264 255 268 257 248 230 258 279 278 276 256 269 282 263 244 298 266 226 237 242 261 263 270 268 262 248 264 247 214 259 214 236 279 237 260 280 238 247 257 237 247 234 270 246 235 269 243 281 238 290 223 272 274 228 220 278 231 279 248 249 261 248 269 285 233 260 284 260 260 245 212 243 258 245 267 273 225 256 267 282 263 257 268 266 230 245 264 221 264 236 258 230 250 231 256 259 238 265 248 249 241 229 262 221 269 261 277 228 250 282 245 273 264 265 220 283 272 258 268 233 255 255 264 257 258 261 256 228 268 233 276 239 234 283 256 238 298 270 258 243 266 264 268 266 240 281 240 260 269 255 258 255 249 287 283 244 291 259 291 245 270 245 237 238 242 242 258 204 272 275 245 280 288 272 272 225 243 271 261 225 273 259 241 238 245 241 232 268 225 234 232 278 221 240 244 223 284 270 302 261 283 260 241 272 248 235 272 279 273 255 279 286 218 246 268 263 279 267 270 245 255 289 271 246 240 258 273 242 235 274 239 263 270 244 288 240 263 233 275 259 268 282 274 255 241 279 262 267 270 281 241 255 270 278 278 224 232 241 221 282 262 250 263 265 264 279 257 276 279 255 295 273 276 268 240 329 270 293 231 284 271 243 267 270 248 242 258 242 221 255 242 272 268 245 273 263 270 259 282 273 281 266 278 267 280 246 246 245 274 256 270 259 271 296 264 240 240 262 223 284 255 237 258 274 278 236 278 276 231 243 271 245 276 277 281 235 260 270 245 256 248 267 246 284 248 241 274 285 255 263 279 236 286 255 262 263 269 279 277 281 250 246 248 272 249 256 261 233 249 266 262 256 236 234 244 262 261 239 267 239 249 274 267 272 225 250 224 275 244 266 274 250 283 265 214 260 262 271 279 247 267 302 241 273 229 275 275 289 247 244 282 263 228 235 265 240 277 250 255 267 256 287 245 260 269 266 273 264 297 246 243 281 233 257 285 281 264 259 267 270 266 231 241 283 239 267 256 244 248 263 271 272 248 256 272 222 259 270 232 291 296 238 273 255 238 250 248 283 244 261 263 280 257 256 234 249 285 269 255 235 230 240 267 287 236 227 244 276 288 238 261 226 262 264 295 274 258 272 265 271 265 241 268 259 268 233 257 258 250 266 256 277 216 256 272 243 239 245 233 257 293 285 268 280 281 248 263 290 258 269 265 268 285 263 256 270 269 219 291 259 242 265 262 235 279 269 257 244 240 283 265 257 260 257 231 270 262 275 272 261 266 272 234 269 241 274 269 272 259 273 270 268 265 259 244 258 271 281 261 265 276 259 265 259 266 271 248 273 249 281 266 256 255 279 232 266 277 262 233 275 261 258 260 256 276 234 246 276 269 235 305 274 235 245 276 279 260 267 233 275 292 236 234 245 247 267 240 238 258 305 237 262 296 277 245 296 267 250 261 290 223 244 263 279 242 268 281 261 299 261 285 272 278 263 272 270 274 271 265 257 243 282 265 245 260 280 260 268 246 273 267 245 282 290 247 249 249 268 295 238 277 272 273 262 270 255 292 225 281 268 242 265 289 290 226 248 238 257 307 265 222 221 238 277 247 259 234 260 259 244 247 255 272 264 264 230 235 258 275 234 307 246 267 279 274 288 294 237 276 277 265 294 274 280 236 265 261 283 237 265 265 280 249 296 262 242 281 278 239 256 234 229 246 291 273 220 297 289 258 268 284 276 271 290 257 235 267 274 281 255 260 264 261 274 248 267 269 256 284 256 279 287 247 282 268 262 260 294 271 258 264 245 238 244 281 233 236 271 271 288 244 273 285 264 275 282 245 265 280 258 259 240 238 275 248 279 273 243 249 280 261 274 279 249 272 274 271 256 276 262 278 243 259 245 259 248 269 287 286 257 242 264 241 225 255 265 291 260 238 267 244 271 269 241 257 275 274 288 277 261 275 265 239 224 224 284 260 272 240 269 283 300 282 248 261 277 260 239 311 270 295 240 303 261 284 266 261 247 262 241 236 275 310 255 238 264 260 250 262 245 245 256 261 284 256 266 236 256 244 300 267 264 248 239 256 249 248 283 290 262 279 276 263 270 233 268 269 272 239 277 245 247 285 283 276 276 264 264 279 289 249 277 243 280 267 284 229 269 285 240 262 259 297 237 308 256 242 290 264 282 257 287 262 270 256 228 255 286 309 272 228 267 247 286 221 247 257 246 255 281 234 287 262 246 240 277 270 276 296 263 287 262 255 255 277 281 255 261 256 272 241 241 237 242 236 261 269 247 235 256 272 269 259 271 243 278 262 270 258 256 280 247 278 266 286 284 264 249 241 277 233 262 234 267 248 267 278 239 268 280 268 285 237 259 296 289 304 280 270 263 263 255 276 273 255 294 228 276 225 278 286 263 295 281 266 244 233 265 265 250 274 246 234 258 227 265 244 257 297 265 280 240 277 289 275 263 282 281 267 264 267 272 255 271 245 278 248 270 261 232 244 276 278 232 249 284 246 282 263 283 281 237 235 271 248 226 249 256 270 265 283 246 256 260 261 255 279 233 263 283 247 286 268 279 263 268 285 281 279 277 249 229 288 267 259 280 284 262 265 240 246 270 266 263 250 257 296 258 259 291 279 271 278 285 257 262 293 264 290 308 309 293 268 277 300 271 278 267 275 286 239 246 263 283 235 304 285 281 277 280 315 295 264 285 296 258 274 280 306 274 280 284 277 297 292 290 296 270 312 300 263 262 258 294 297 280 293 249 285 271 243 276 292 264 271 234 256 273 240 273 282 256 273 281 257 285 271 269 269 236 289 261 273 289 278 283 263 257 238 271 283 262 271 264 261 283 283 273 255 216 279 282 279 257 267 240 275 272 242 257 257 270 265 243 260 232 239 271 247 239 247 260 300 286 247 261 271 258 270 260 293 260 255 239 234 269 272 281 293 240 247 260 259 241 238 282 278 269 258 258 255 293 264 264 264 260 260 272 261 292 225 247 274 256 260 246 260 264 269 212 234 225 244 242 242 280 248 264 249 265 268 262 265 266 255 261 244 247 264 240 265 246 257 238 277 220 301 260 247 276 268 265 256 261 230 274 241 271 267 258 279 257 232 263 279 247 247 241 264 318 259 282 243 270 261 209 261 235 267 247 280 257 278 255 247 248 262 265 306 259 275 268 226 267 228 273 255 271 282 276 273 302 274 248 249 276 279 245 262 257 246 262 238 232 261 248 262 265 260 270 239 239 243 249 271 264 242 267 236 235 247 259 266 247 278 279 255 264 277 279 273 247 259 244 264 236 275 281 264 267 256 272 219 258 247 236 265 227 271 262 273 247 259 275 262 239 258 247 235 276 271 263 263 234 246 268 241 277 292 258 290 240 247 249 258 272 269 268 244 296 272 250 273 249 268 256 256 255 261 238 240 261 267 276 259 275 269 260 267 265 230 265 255 258 249 256 272 256 249 273 264 233 258 277 242 258 256 304 244 285 251 270 280 228 248 235 260 290 268 249 236 238 246 234 264 275 242 223 248 270 265 283 236 281 258 269 284 249 279 246 277 273 244 266 258 263 275 283 256 264 242 281 229 234 280 286 245 287 265 269 275 266 247 245 242 245 260 248 267 242 298 270 288 282 246 261 239 263 259 242 268 267 255 247 276 303 263 259 264 236 244 238 289 263 255 261 277 257 267 247 224 267 250 285 258 266 270 259 262 300 266 265 283 260 241 236 232 314 290 277 276 242 279 223 258 217 281 271 279 266 280 266 270 232 245 250 277 257 237 285 282 255 269 241 255 240 242 274 278 293 226 257 260 261 286 245 239 234 244 250 268 284 236 249 269 234 284 256 244 250 248 266 245 269 240 278 267 297 258 235 228 264 264 249 275 271 246 272 245 233 267 282 283 277 272 281 270 278 270 271 279 266 269 283 280 258 259 278 256 255 289 259 262 222 269 274 239 273 241 235 245 255 234 282 232 261 285 263 273 266 271 281 263 258 260 238 269 288 242 240 238 262 290 263 258 245 257 271 237 275 265 276 256 217 240 268 266 274 256 260 234 264 259 234 270 267 255 234 264 248 263 234 272 232 263 270 248 239 243 256 262 242 260 262 260 288 269 245 273 260 228 269 266 231 272 264 274 288 290 271 231 278 272 249 260 247 240 255 285 266 255 260 267 216 257 257 261 266 264 264 293 278 240 280 262 277 243 282 243 273 267 281 276 269 275 261 274 277 217 258 267 242 298 270 239 261 296 257 265 275 286 292 257 249 264 265 273 242 242 295 239 232 247 256 284 274 265 257 249 245 298 273 304 289 241 297 245 263 263 259 278 291 260 245 279 249 262 232 270 260 278 285 272 238 255 272 272 245 244 268 259 259 264 238 278 244 264 232 240 255 272 240 248 272 256 274 233 237 282 275 285 277 267 286 223 308 244 285 244 221 274 295 277 266 278 283 270 277 270 265 266 288 266 275 243 282 257 234 242 259 260 277 283 295 281 274 313 279 241 277 278 277 293 257 273 259 287 247 283 277 244 261 249 266 258 245 269 255 247 286 262 241 259 226 259 270 272 243 300 283 269 235 262 259 265 269 238 242 298 262 275 257 283 263 235 272 232 271 248 272 289 277 278 281 287 246 271 278 273 268 235 261 245 303 224 288 289 264 280 265 269 270 277 255 249 273 281 272 240 242 271 260 222 272 244 271 265 277 265 272 290 227 263 265 290 264 241 273 247 271 225 236 256 267 249 268 263 279 255 234 282 255 269 210 234 264 237 256 256 268 271 274 225 247 268 247 271 235 287 233 240 266 265 243 281 261 266 292 255 289 287 268 242 231 239 273 272 271 260 246 238 227 299 274 245 302 264 237 246 233 249 256 260 258 284 288 262 225 266 255 278 233 258 260 267 271 250 268 243 207 292 241 257 261 278 270 257 274 264 265 291 268 268 283 271 247 230 269 285 233 279 286 281 235 299 278 284 267 262 262 280 256 281 243 249 272 263 260 273 261 267 258 275 264 258 258 245 248 260 247 269 260 272 233 260 237 270 276 234 256 284 243 275 263 245 261 248 269 249 282 283 258 283 271 266 269 257 278 274 264 259 263 288 298 269 258 265 265 247 299 264 232 231 269 232 269 241 258 285 260 274 270 243 238 259 276 226 238 243 271 246 228 284 262 290 236 267 231 263 246 281 274 222 273 271 259 248 242 258 282 282 230 275 269 247 260 246 265 235 264 269 265 295 257 238 271 268 256 271 234 269 242 272 230 263 268 265 272 245 211 260 283 245 269 281 278 279 264 250 209 266 270 240 259 246 283 255 260 232 243 257 249 274 276 260 268 283 267 261 264 243 277 231 255 284 248 264 257 264 272 263 264 309 262 272 276 288 236 292 286 273 261 285 239 267 261 274 265 298 300 276 245 270 236 271 285 303 272 288 285 284 269 284 244 276 240 228 287 271 280 294 262 234 231 277 281 265 267 278 282 286 275 249 258 266 295 309 237 245 257 239 248 259 257 297 262 260 277 288 233 284 286 294 269 260 237 275 219 238 263 262 260 266 289 270 246 276 272 285 261 283 264 256 272 236 260 274 259 255 243 259 263 271 245 225 271 272 260 274 236 273 244 223 264 258 255 256 259 284 249 291 276 256 267 245 295 264 246 264 265 286 233 236 260 242 237 267 268 285 294 274 271 266 260 273 228 266 277 219 266 263 271 247 261 278 265 274 267 239 279 279 260 277 258 270 259 250 292 265 278 282 244 278 287 261 246 261 295 221 242 268 270 258 281 278 255 275 298 271 256 243 245 239 278 284 242 310 249 268 273 243 241 255 262 278 265 278 283 297 278 245 297 274 241 265 238 256 256 245 236 290 261 271 263 245 279 279 266 282 268 286 269 243 258 283 247 281 283 304 272 260 265 249 256 260 270 261 279 243 277 235 240 284 264 277 283 249 247 256 267 283 245 232 266 305 290 220 281 241 259 274 275 271 268 256 242 273 280 291 242 286 290 276 269 290 235 268 271 282 247 255 263 265 243 284 268 271 262 242 292 281 249 260 275 273 264 273 291 240 272 288 274 270 264 292 278 300 272 257 271 277 275 278 285 264 291 263 247 255 264 267 293 247 259 283 259 257 280 293 276 277 257 272 264 271 277 260 267 272 270 290 281 280 260 289 264 278 304 265 268 276 267 301 304 299 298 291 303 318 319 333 364 380 437 485 540 589 587 558 590 536 493 456 470 457 437 431 434 343 385 379 373 297 288 318 293 281 287 288 311 292 280 284 307 279 263 287 299 280 277 306 291 281 317 277 286 268 267 318 267 301 256 279 281 245 276 259 293 274 294 248 290 297 269 274 289 283 280 264 282 278 308 305 265 243 264 247 256 280 306 287 276 298 285 276 280 277 294 307 277 240 257 292 267 279 271 291 309 279 290 270 303 308 257 298 267 294 312 276 271 310 322 285 269 267 247 298 310 285 236 301 286 299 288 289 239 275 277 286 275 273 260 279 278 288 295 298 260 272 247 311 256 281 305 284 282 281 274 276 255 237 289 294 288 276 287 315 293 306 245 290 279 285 278 268 240 304 272 259 296 301 276 259 281 248 287 267 261 259 291 268 288 290 289 309 267 284 264 311 315 271 297 298 301 299 315 241 329 274 310 305 313 298 330 346 338 316 280 318 305 273 321 289 314 336 311 295 327 350 333 328 319 336 308 305 350 323 328 315 310 308 334 313 339 347 330 336 312 322 305 325 311 306 301 299 330 290 298 328 324 300 296 321 301 310 302 285 326 295 298 301 305 311 297 317 304 290 321 276 296 303 311 286 308 270 280 282 286 301 299 292 291 282 249 298 303 294 287 300 260 275 303 285 261 290 276 277 297 280 314 278 294 289 260 280 277 302 289 315 282 265 263 272 263 316 239 295 298 281 308 296 257 258 266 304 304 240 277 292 273 242 283 283 261 292 249 306 267 278 246 282 326 239 277 255 257 269 283 282 323 298 273 280 284 283 279 276 279 274 266 267 280 278 287 291 264 285 267 289 283 289 268 281 255 296 228 266 280 291 260 291 276 273 273 247 298 263 279 287 258 286 289 265 298 263 267 299 287 235 257 296 285 294 237 286 304 301 286 304 265 266 291 266 274 290 266 294 274 284 258 289 315 257 285 327 247 262 284 272 268 264 267 285 298 271 285 277 275 275 292 247 274 267 268 258 256 268 281 262 243 276 273 284 260 276 282 264 277 276 289 289 237 238 239 288 268 268 243 271 288 255 306 265 274 266 280 276 272 289 240 276 269 263 291 237 269 272 297 282 289 261 274 297 233 277 294 266 285 267 293 279 281 282 239 273 288 288 243 277 280 269 282 283 274 261 272 284 273 281 294 260 296 297 284 292 235 270 263 285 274 263 260 278 258 257 256 276 244 269 286 288 270 273 263 292 311 294 277 275 256 296 289 295 260 272 262 277 259 257 310 314 282 222 282 277 281 262 282 261 302 293 291 290 286 266 268 292 259 271 270 284 261 295 287 301 272 273 273 284 279 247 239 281 266 283 277 275 289 290 289 306 248 277 300 305 238 279 245 308 300 315 280 283 291 307 291 276 317 280 273 283 265 279 319 279 285 296 286 282 301 243 247 294 262 245 278 290 255 279 294 310 282 286 306 286 255 293 288 298 248 290 266 294 247 298 286 304 286 259 290 298 282 332 267 288 263 295 271 277 236 292 265 290 278 277 263 295 286 278 265 288 298 286 296 271 285 281 296 313 261 287 303 303 257 295 273 272 277 287 261 284 328 288 257 265 307 299 255 316 281 265 298 288 314 241 279 277 287 300 283 281 280 272 323 265 285 284 292 260 278 303 297 279 286 314 268 277 255 293 302 277 307 277 288 275 279 295 269 281 293 275 290 296 303 280 291 281 284 275 286 303 264 296 305 301 280 327 287 281 278 247 271 274 277 275 283 289 298 299 313 310 256 247 298 308 295 289 322 312 280 296 260 297 338 325 294 284 276 288 291 307 325 276 302 270 286 265 296 326 303 336 304 322 297 273 318 286 298 319 279 307 321 303 299 299 336 295 309 288 302 267 273 268 324 299 292 319 304 304 309 296 322 286 331 311 306 300 308 306 320 324 314 328 312 295 283 317 360 297 316 285 299 349 305 363 305 343 336 317 302 301 330 296 314 299 302 302 365 314 317 335 310 330 305 306 319 330 321 330 313 321 317 341 351 333 327 311 297 345 348 295 317 321 323 312 328 314 324 343 354 348 318 336 324 303 362 325 321 328 349 305 323 349 323 357 356 353 307 351 330 327 382 381 332 382 343 357 349 328 353 324 310 358 355 336 371 375 364 360 381 365 370 331 376 350 387 364 340 377 373 349 362 331 360 381 352 406 353 346 379 396 351 380 385 405 353 383 383 410 383 366 390 373 389 404 409 389 433 399 406 391 404 438 398 404 412 425 392 401 418 419 398 403 449 425 463 433 454 469 441 448 474 430 454 470 437 481 480 502 479 511 499 475 550 534 577 547 530 566 558 648 676 690 677 737 764 833 837 902 912 922 1009 939 1043 935 947 995 998 1059 1067 1057 1003 1049 1011 979 1022 967 1023 1050 1096 1043 1152 1099 1131 1153 1199 1298 1324 1411 1502 1546 1722 1834 1993 2195 2303 2429 2852 3059 3487 3883 4581 5433 6559 7905 9916 12867 17800 26327 41000 63411 84729 96172 99100 94923 82966 63166 44211 31170 22721 16665 12670 9838 7752 6399 5726 5006 4623 4385 4212 4274 4427 4954 5399 6526 7938 10188 14192 20108 29189 38186 45189 48205 48050 43166 35747 26743 19773 14261 10483 7886 6092 4978 4144 3451 3061 2544 2335 2104 1851 1804 1632 1540 1446 1341 1319 1233 1222 1153 1138 1062 996 944 973 961 883 904 882 833 843 805 747 782 781 687 679 642 628 673 672 638 665 614 605 609 626 577 535 573 609 571 541 572 537 587 521 543 565 489 522 493 519 516 503 514 454 487 465 487 499 445 461 418 456 450 425 466 410 429 394 403 430 424 445 451 417 392 435 426 418 409 379 412 383 398 419 384 370 397 423 420 396 353 373 382 389 389 377 412 375 359 377 371 377 416 365 347 367 377 386 384 360 338 357 354 397 366 341 367 358 353 362 326 372 364 335 367 374 344 381 375 346 342 331 328 362 387 343 359 316 350 335 330 333 363 305 336 293 326 354 354 334 335 341 330 308 332 357 296 298 311 349 352 306 329 344 326 325 290 305 275 322 343 302 330 320 304 341 337 345 283 332 303 296 317 310 335 314 344 318 302 351 281 299 331 312 306 320 317 300 317 321 299 305 303 297 305 291 290 315 299 324 282 329 283 312 296 306 290 302 300 317 302 306 307 301 287 289 317 303 283 273 297 304 290 280 288 275 329 301 317 302 301 258 297 299 306 278 297 311 303 302 279 296 283 298 266 292 323 297 299 303 293 274 296 278 321 307 305 310 277 302 300 318 288 301 316 277 277 256 267 282 328 291 296 246 283 260 307 288 264 298 300 289 318 297 318 268 282 287 282 287 295 296 255 275 276 274 290 305 310 309 282 291 274 279 278 278 304 301 325 296 303 293 280 248 278 311 294 272 295 294 287 294 273 318 267 290 279 267 295 276 273 303 307 263 295 301 266 287 272 286 292 271 273 283 314 255 268 270 280 269 297 239 272 291 274 305 262 274 243 277 319 287 277 290 284 265 264 249 269 273 248 260 268 287 278 283 292 310 281 260 297 287 263 282 283 287 259 272 289 308 246 301 286 298 294 281 314 300 268 276 286 257 262 276 244 270 269 280 278 281 265 286 281 301 286 229 276 274 277 289 265 291 283 287 268 300 303 272 285 273 283 271 268 307 267 265 275 290 306 262 266 296 243 257 272 263 292 296 323 274 288 275 316 285 265 265 306 296 270 257 261 275 285 289 288 277 287 276 277 294 293 304 268 278 294 274 270 312 280 292 288 274 270 288 283 258 278 271 275 258 297 294 270 302 245 279 291 259 289 274 268 298 248 289 279 280 295 277 259 304 270 294 294 307 255 273 278 276 281 313 284 293 268 277 269 242 293 265 268 282 284 275 263 261 267 283 224 287 302 267 269 294 258 275 283 271 241 269 272 261 271 243 284 259 296 274 289 276 290 282 310 289 310 286 261 259 250 294 275 295 284 270 269 302 284 281 308 295 278 302 272 256 293 264 282 310 285 268 287 272 264 275 296 295 256 309 282 309 299 282 296 256 267 274 290 295 281 265 257 237 268 277 270 292 282 274 282 292 299 276 277 293 289 291 284 264 307 272 278 271 285 270 290 297 272 284 273 277 264 287 263 294 273 278 307 287 260 280 301 286 271 272 233 271 256 285 279 283 260 291 279 266 267 261 273 266 282 276 296 280 316 238 290 271 301 274 303 270 281 294 298 296 288 261 270 271 272 293 282 249 298 248 266 303 256 270 272 302 290 294 291 248 263 268 294 259 268 302 277 286 271 269 273 302 272 270 281 287 245 301 282 246 308 294 285 319 296 287 279 287 285 294 259 295 269 257 270 283 272 301 272 279 313 278 295 271 288 282 284 288 278 284 263 285 273 258 293 260 297 285 303 267 303 276 258 277 263 268 299 296 309 300 295 291 282 279 267 278 304 284 305 276 282 288 264 268 293 274 266 259 277 298 277 273 282 261 300 276 280 286 294 284 294 265 276 277 288 292 283 303 298 270 297 267 272 291 314 273 249 268 278 270 305 266 278 246 261 266 261 246 276 231 291 272 270 281 273 256 259 283 256 271 293 284 268 267 247 283 263 291 277 282 278 275 290 230 292 291 282 285 320 280 257 264 289 303 268 279 258 265 273 286 268 286 295 299 304 284 305 266 267 272 286 275 277 295 287 269 284 289 261 268 234 297 262 305 301 307 261 271 257 248 243 286 274 239 287 272 269 261 314 276 280 269 285 263 255 266 273 285 305 285 256 267 275 311 280 274 297 290 305 260 273 258 286 247 259 268 290 278 273 259 266 259 294 259 292 272 279 246 266 272 275 275 278 296 277 239 243 273 291 264 290 247 263 275 262 242 255 257 267 294 272 281 272 288 267 241 285 242 267 239 274 261 283 249 296 266 268 275 293 242 248 246 261 263 284 246 231 286 269 244 278 295 261 264 266 316 282 263 278 267 272 278 282 275 265 275 278 244 271 269 275 284 260 260 269 277 272 259 286 274 268 289 262 311 248 279 266 256 283 277 246 282 298 266 286 285 266 241 326 259 265 271 283 284 240 279 287 269 277 293 279 273 250 281 287 274 284 277 247 270 250 239 298 294 270 255 289 278 271 290 264 279 280 284 287 278 285 263 270 270 309 270 264 263 284 280 279 260 302 249 292 317 255 236 264 268 233 286 281 273 282 287 279 284 265 298 244 273 258 268 289 260 264 256 268 266 286 263 264 264 274 265 276 259 274 288 288 271 284 236 267 297 268 264 287 272 277 285 270 277 289 283 305 258 274 279 293 249 276 263 256 247 244 247 249 269 265 267 260 292 246 261 259 242 291 264 284 273 240 285 304 204 265 266 264 258 259 267 247 267 245 273 275 269 264 248 263 273 290 244 284 244 277 270 260 276 271 280 275 263 262 249 268 247 266 262 261 272 281 258 265 265 243 263 280 282 300 246 268 247 277 284 256 274 266 238 270 302 244 246 257 262 263 280 248 262 282 237 302 269 224 292 267 282 279 263 264 257 284 272 274 256 245 274 293 268 263 269 258 278 237 266 281 273 246 280 262 283 279 278 270 272 271 292 279 245 292 241 272 263 263 288 269 275 275 262 243 285 241 243 268 258 284 276 305 241 272 264 290 272 279 294 229 260 272 286 277 272 273 258 255 288 256 280 260 277 269 269 247 256 289 267 240 243 266 293 273 237 285 237 256 256 257 257 288 246 231 245 267 277 303 282 259 283 259 272 265 271 249 276 270 266 248 247 247 263 272 284 242 232 270 258 256 235 273 257 269 260 292 288 264 269 282 277 285 267 285 290 272 293 280 238 246 295 262 262 276 263 275 249 286 262 243 262 275 275 249 275 269 244 247 286 269 268 271 261 277 266 263 256 287 277 280 315 244 284 268 242 278 278 298 282 278 296 246 255 273 243 232 266 273 272 270 262 269 266 278 246 270 255 255 276 295 268 248 267 273 284 279 290 257 276 282 282 262 247 262 270 286 227 300 264 273 244 282 308 269 276 233 275 271 259 245 281 265 277 268 242 266 296 245 301 257 279 306 285 283 241 284 263 289 283 288 237 290 237 295 286 278 249 261 264 283 256 265 294 256 240 228 272 273 295 271 270 243 274 271 294 244 271 296 281 265 247 274 264 279 272 272 284 272 274 270 284 274 278 269 268 276 272 247 297 255 277 262 274 239 280 267 293 241 266 280 241 257 269 300 273 266 265 284 274 290 290 239 285 256 308 290 284 289 314 287 312 289 286 299 275 272 270 263 260 301 258 256 290 257 294 273 266 267 285 299 274 247 292 230 258 264 261 262 268 272 284 274 285 291 282 245 280 249 282 269 302 275 271 231 314 268 312 241 274 286 271 295 257 233 292 283 291 275 267 277 233 247 289 267 296 321 270 281 276 238 286 257 257 288 293 275 282 266 307 275 264 279 249 268 278 266 282 247 277 249 271 264 277 273 294 255 284 280 279 267 289 240 287 256 241 291 273 284 258 279 291 271 306 262 273 287 302 271 274 287 283 327 261 281 259 268 284 298 285 291 298 291 274 263 286 285 279 285 220 250 298 292 290 271 271 281 263 284 286 237 278 293 238 284 287 271 285 249 261 296 314 325 281 296 282 313 287 281 281 295 272 281 278 276 237 240 272 272 265 256 286 290 278 260 301 255 272 289 267 302 249 277 238 282 278 272 245 266 265 276 294 292 289 239 280 274 222 231 272 262 276 277 274 279 272 274 281 277 293 275 257 290 287 305 257 309 282 283 280 267 266 306 274 269 273 290 268 260 275 301 276 312 277 275 276 276 278 267 272 265 285 280 260 277 259 279 271 276 263 273 286 277 283 275 277 257 270 274 293 287 255 266 257 268 290 246 271 256 268 256 294 281 272 265 266 277 273 286 306 250 286 269 297 284 290 259 303 293 260 279 248 272 282 272 282 283 284 278 278 282 289 263 313 267 268 258 270 296 266 278 275 274 258 255 299 282 263 236 274 294 300 268 291 278 281 259 292 284 278 247 261 276 273 280 291 283 274 270 302 260 286 305 285 287 270 295 283 271 291 249 291 281 300 268 279 261 297 263 262 250 300 268 300 284 289 263 284 244 269 259 262 260 301 274 281 288 314 262 267 273 265 243 248 231 278 284 296 297 247 288 303 267 300 286 266 263 289 283 276 293 296 303 270 277 269 283 279 292 292 294 307 290 256 245 265 285 267 273 304 295 280 272 258 282 293 300 293 276 280 301 274 279 283 292 287 286 236 249 268 263 229 293 309 262 279 280 263 264 299 236 284 275 249 281 269 305 291 244 260 282 260 269 299 272 296 276 241 269 288 281 277 296 308 277 260 262 267 259 309 284 272 292 290 269 278 291 312 276 271 301 280 281 282 250 262 308 293 274 277 265 268 304 237 304 262 269 264 270 276 282 273 291 296 275 290 257 228 239 289 287 279 258 296 267 289 284 233 282 245 266 276 288 286 283 298 267 282 244 257 303 276 278 289 261 275 261 291 282 279 255 284 299 283 305 268 270 266 299 266 246 285 286 265 285 260 316 277 274 269 266 256 294 269 289 280 276 260 247 277 319 271 289 273 292 304 279 264 287 265 286 281 277 248 279 267 295 275 263 281 288 271 282 285 247 301 281 277 263 275 283 289 320 274 267 257 292 284 261 258 276 255 274 298 319 261 244 285 274 258 278 259 313 300 244 292 277 287 303 264 296 301 266 283 238 265 297 240 297 294 289 279 284 261 247 283 272 284 262 287 269 275 300 275 291 241 288 307 298 278 271 282 301 298 282 297 279 256 275 289 275 280 287 282 298 248 245 284 280 261 281 281 289 295 298 280 282 265 279 295 281 281 290 242 287 239 262 289 292 292 278 294 270 295 288 304 266 287 295 329 280 268 268 293 305 268 293 267 279 281 247 261 268 279 249 326 247 284 314 288 290 294 323 275 276 284 281 248 313 292 279 281 268 300 256 295 269 295 309 282 272 246 293 288 281 275 258 267 303 271 255 294 283 268 264 274 247 286 297 270 290 269 267 272 297 258 278 255 288 300 274 289 288 248 296 282 282 288 281 305 296 291 296 304 298 291 275 280 272 299 278 313 291 306 282 298 280 291 273 264 308 302 305 286 295 333 289 316 259 307 281 296 263 275 305 264 304 300 312 292 287 281 273 270 297 285 287 260 268 297 288 304 275 323 296 316 280 303 302 297 293 305 271 280 292 299 274 292 302 285 303 264 302 304 293 286 294 280 283 298 303 294 304 298 303 308 310 305 269 282 302 324 289 300 283 290 285 312 318 273 303 296 303 319 296 327 295 298 285 297 299 322 271 312 293 331 299 303 284 273 292 285 273 319 319 284 294 289 298 304 304 336 308 278 298 315 295 305 289 315 308 272 306 297 286 304 327 305 291 273 291 287 308 302 293 310 284 329 305 278 311 321 325 273 343 262 289 281 278 290 281 299 262 273 283 291 299 314 309 324 298 311 296 297 313 303 302 308 300 302 288 302 301 292 289 295 307 273 274 280 313 297 307 248 289 274 282 296 270 315 303 277 317 304 298 286 306 293 271 295 281 281 260 310 303 298 301 278 282 284 298 298 278 287 294 243 326 239 270 295 335 263 320 291 290 267 290 289 276 302 314 275 287 317 276 271 278 267 271 274 275 277 292 270 300 290 295 296 265 295 302 282 297 247 308 270 312 286 320 291 280 296 290 319 285 241 298 282 275 300 300 291 291 291 277 286 284 273 277 271 297 234 310 279 281 276 270 264 315 277 294 248 272 267 256 279 285 296 282 281 300 259 281 293 272 282 297 288 269 278 282 278 313 307 249 280 256 274 290 299 300 247 285 265 293 296 282 289 285 280 289 259 260 233 299 266 282 282 225 272 266 276 313 293 269 238 258 265 280 302 286 293 298 281 286 294 267 277 265 276 270 307 286 294 256 275 292 244 310 276 293 300 255 270 270 312 302 299 282 275 313 278 263 286 306 302 297 261 262 283 290 262 273 282 276 270 289 302 278 277 262 278 301 269 274 293 279 289 285 294 255 294 289 298 283 296 262 280 282 283 283 296 279 223 269 288 275 286 304 308 276 282 289 313 294 282 284 295 301 287 320 274 261 282 260 264 274 312 292 287 285 278 263 247 292 281 276 272 292 298 313 293 286 275 259 293 259 269 287 295 277 298 282 292 249 294 294 272 285 290 292 281 300 248 302 292 243 281 293 255 286 290 292 288 274 247 278 281 300 299 264 285 245 310 289 297 297 281 285 294 299 297 301 288 319 296 282 296 301 266 289 297 340 249 314 247 290 281 321 280 291 293 284 278 271 261 311 280 281 277 285 275 316 309 267 289 302 280 297 290 290 287 301 272 321 304 264 272 273 296 271 274 269 304 290 293 304 311 283 288 300 315 270 284 291 297 255 264 295 246 266 280 295 281 293 287 309 271 303 284 276 303 237 293 266 284 306 264 294 278 270 293 275 274 285 261 307 277 291 264 243 287 293 276 261 291 276 276 282 276 287 279 269 299 318 289 298 267 258 272 289 285 271 295 285 298 297 292 283 302 310 265 320 279 299 301 281 276 263 307 301 268 271 239 291 261 303 293 272 304 302 314 316 260 280 265 313 290 305 295 306 297 268 310 273 302 302 278 265 277 284 284 274 280 276 285 282 270 276 283 275 290 296 281 274 295 283 277 310 285 288 289 291 281 264 289 296 271 293 315 316 295 294 236 282 292 312 282 270 285 287 246 275 284 292 285 267 315 308 249 290 255 284 238 297 301 284 313 289 248 284 284 272 296 258 305 267 232 290 294 294 285 303 292 265 277 310 291 244 279 278 301 266 281 288 293 271 295 302 261 312 312 314 265 321 291 293 265 266 263 312 292 284 304 267 281 300 302 310 273 289 271 303 278 317 295 297 307 273 260 298 305 273 298 315 287 270 287 298 277 300 312 290 264 282 293 276 283 291 260 286 295 293 269 306 299 294 283 285 295 288 266 293 307 294 272 271 305 304 269 305 264 289 299 306 271 262 275 302 285 261 282 321 280 303 278 289 282 308 247 314 272 307 284 264 316 289 306 296 286 275 288 278 297 287 264 290 283 341 295 288 322 247 291 295 282 286 285 291 260 266 259 299 269 260 271 297 289 283 238 291 284 307 277 300 261 289 278 269 303 268 317 288 293 296 289 282 307 292 291 283 317 307 288 279 299 290 298 246 303 287 301 277 290 300 260 287 308 266 302 265 270 275 276 277 267 285 286 291 284 290 295 288 277 301 300 293 296 286 274 260 267 294 286 309 294 294 288 301 304 292 297 305 266 285 277 288 268 305 285 290 298 276 245 267 299 281 301 262 291 281 292 281 294 297 268 294 278 246 289 306 287 290 302 287 288 296 273 276 255 301 310 276 286 271 288 301 300 267 256 279 272 275 308 289 286 275 311 279 275 262 307 289 317 263 298 271 312 282 282 294 271 292 270 311 260 261 292 285 322 272 285 263 263 285 288 279 304 257 275 247 310 298 286 292 278 275 275 315 282 286 297 272 295 290 297 287 287 316 265 288 281 297 319 286 262 287 298 290 287 286 293 284 298 260 301 282 267 287 280 268 318 286 309 286 269 296 273 277 261 286 275 288 311 274 281 292 277 292 278 244 269 287 263 281 283 302 293 284 275 265 264 303 291 278 301 302 276 298 272 288 284 296 242 273 285 312 278 267 285 290 313 271 284 317 286 277 281 293 313 264 274 289 268 300 284 265 262 288 239 274 284 272 275 269 278 259 268 288 293 277 281 292 265 273 283 296 261 268 277 278 292 284 290 271 255 289 304 293 260 278 257 298 288 275 266 281 276 275 305 286 275 263 301 266 283 283 318 289 283 290 292 320 280 283 271 278 286 304 281 281 263 269 266 262 249 264 318 300 283 304 271 315 248 275 262 271 265 296 222 273 289 291 287 294 273 306 291 291 273 276 283 266 249 273 288 284 284 275 276 310 271 298 291 257 288 275 268 280 285 267 299 276 268 282 280 282 306 298 256 305 278 235 263 284 302 294 302 237 246 300 293 256 296 284 306 269 320 298 274 263 275 283 262 273 267 263 291 305 277 284 286 291 290 276 274 291 295 274 272 296 264 280 281 274 291 281 280 294 310 288 282 284 280 269 298 291 236 234 290 288 265 300 293 299 287 286 299 293 319 295 297 312 280 282 282 271 294 274 311 296 240 314 269 294 261 271 285 219 299 267 285 277 268 248 313 257 287 279 272 283 314 270 305 302 270 283 271 269 284 276 291 285 267 296 247 283 296 288 278 300 281 255 256 303 292 301 270 287 288 267 314 305 296 274 291 299 277 303 275 302 305 285 259 302 301 287 307 265 274 286 270 311 299 300 303 265 292 264 272 290 259 306 279 289 277 310 277 316 317 283 288 268 301 302 301 280 306 282 286 279 265 310 307 262 318 289 287 256 283 301 295 273 319 256 285 285 259 288 283 264 296 236 262 297 273 275 290 291 256 282 298 300 283 272 304 282 275 280 295 315 310 284 219 287 269 294 282 293 303 287 310</counts>
			</dataPoints>
		</scan>
	</xrdMeasurement>
</xrdMeasurements>