File: data/XRD/CS-Vakuum/XG-pre/W6821-3A_CS_Vakuum_pre.xrdml
<xrdMeasurements xmlns="http://www.xrdml.com/XRDMeasurement/2.1" xmlns:xsi="http://www.w3.org/2001/XMLSchema-instance" xsi:schemaLocation="http://www.xrdml.com/XRDMeasurement/2.1 http://www.xrdml.com/XRDMeasurement/2.1/XRDMeasurement.xsd" status="Completed">
	<comment>
		<entry>Configuration=Factory configuration, Owner=User-1, Creation date=7/8/2013 4:01:53 PM</entry>
		<entry>Goniometer=PW3050/65 (Theta/2Theta); Minimum step size 2Theta:0.0001; Minimum step size Omega:0.0001</entry>
		<entry>Sample stage=MRD Cradle; Minimum step size Phi:0.01; Minimum step size Chi:0.01; Minimum step size X:0.01; Minimum step size Y:0.01; Minimum step size Z:0.001</entry>
		<entry>Diffractometer system=XPERT-PRO</entry>
		<entry>Measurement program=C:\PANalytical\Data Collector\Programs\Jorrit\2thom\_absolute_2th-om_10-130deg_PIXscan_56min.xrdmp, Identifier={15BCCF57-2807-42BD-B5B9-ECC0B3DC9284}</entry>
		<entry>Batch program=C:\PANalytical\Data Collector\Programs\SimonL\batch8x_2thom_10-130°_z9.1_x0,10,20,30_y20,30,40,50_57min.xrdmp, Identifier={9A1B954C-70C5-4DE2-A2B5-D0000261ED0F}</entry>
	</comment>
	<sample type="To be analyzed">
		<id></id>
		<name></name>
		<preparedBy></preparedBy>
	</sample>
	<xrdMeasurement measurementType="Scan" status="Completed" sampleMode="Reflection">
		<comment>
			<entry>_absolute_2th-om_10-130deg_PIXscan_56min</entry>
			<entry>PHD Lower Level = 4.83 (keV), PHD Upper Level = 11.27 (keV)</entry>
		</comment>
		<usedWavelength intended="K-Alpha 1">
			<kAlpha1 unit="Angstrom">1.5405980</kAlpha1>
			<kAlpha2 unit="Angstrom">1.5444260</kAlpha2>
			<kBeta unit="Angstrom">1.3922500</kBeta>
			<ratioKAlpha2KAlpha1>0.5000</ratioKAlpha2KAlpha1>
		</usedWavelength>
		<incidentBeamPath>
			<radius unit="mm">320.00</radius>
			<xRayTube id="1010048" name="Empyrean Cu LFF HR (9430 033 7310x) DK442154">
				<tension unit="kV">40.0</tension>
				<current unit="mA">40.0</current>
				<anodeMaterial>Cu</anodeMaterial>
				<focus type="Line">
					<length unit="mm">12.0</length>
					<width unit="mm">0.4</width>
					<takeOffAngle unit="deg">4.2</takeOffAngle>
				</focus>
			</xRayTube>
			<xRayMirror id="27010001" name="Inc. Beam Cu W/Si (parabolic MRD)" hybrid="false">
				<crystal type="Graded" shape="Parabolic">W/Si</crystal>
				<acceptanceAngle unit="deg">0.800</acceptanceAngle>
				<length unit="mm">60.0</length>
			</xRayMirror>
			<sollerSlit id="21010002" name="Soller slits 0.04 rad.">
				<opening unit="rad">0.0400</opening>
			</sollerSlit>
			<mask id="22030008" name="Fixed mask 4 mm">
				<distanceToSample unit="mm">220.00</distanceToSample>
				<width unit="mm">4.00</width>
			</mask>
			<divergenceSlit id="22010007" name="Fixed slit 1/8°" xsi:type="fixedDivergenceSlitType">
				<distanceToSample unit="mm">220.00</distanceToSample>
				<height unit="mm">0.19</height>
			</divergenceSlit>
		</incidentBeamPath>
		<diffractedBeamPath>
			<radius unit="mm">320.00</radius>
			<sollerSlit id="21010002" name="Soller slits 0.04 rad.">
				<opening unit="rad">0.0400</opening>
			</sollerSlit>
			<receivingSlit id="22010001" name="Fixed slit 4°">
				<height unit="mm">5.88</height>
			</receivingSlit>
			<detector id="7010017" name="PIXcel3D 1x1 detector" xsi:type="areaDetectorType">
				<phd unit="%">
					<lowerLevel>30.0</lowerLevel>
					<upperLevel>70.0</upperLevel>
				</phd>
				<mode>Scanning</mode>
				<activeChannelsEquatorial>255</activeChannelsEquatorial>
				<activeChannelsAxial>255</activeChannelsAxial>
				<pitchEquatorial unit="mm">0.05500</pitchEquatorial>
				<pitchAxial unit="mm">0.05500</pitchAxial>
				<readOutPeriod unit="seconds">0.135</readOutPeriod>
			</detector>
		</diffractedBeamPath>
		<scan appendNumber="0" mode="Continuous" scanAxis="2Theta-Omega" status="Completed">
			<header>
				<startTimeStamp>2024-10-04T11:14:44+02:00</startTimeStamp>
				<endTimeStamp>2024-10-04T12:10:49+02:00</endTimeStamp>
				<author>
					<name>PRO-MRD</name>
				</author>
				<source>
					<applicationSoftware version="6.1b">Data Collector</applicationSoftware>
					<instrumentControlSoftware version="7.0E 20130304">XPERT-PRO</instrumentControlSoftware>
					<instrumentID>0000000011142674</instrumentID>
				</source>
			</header>
			<dataPoints>
				<positions axis="2Theta" unit="deg">
					<startPosition>9.99826193</startPosition>
					<endPosition>129.99755682</endPosition>
				</positions>
				<positions axis="Omega" unit="deg">
					<startPosition>4.99913096</startPosition>
					<endPosition>64.99877841</endPosition>
				</positions>
				<positions axis="Phi" unit="deg">
					<commonPosition>0.00</commonPosition>
				</positions>
				<positions axis="Chi" unit="deg">
					<commonPosition>0.00</commonPosition>
				</positions>
				<positions axis="X" unit="mm">
					<commonPosition>0.00</commonPosition>
				</positions>
				<positions axis="Y" unit="mm">
					<commonPosition>-20.00</commonPosition>
				</positions>
				<positions axis="Z" unit="mm">
					<commonPosition>9.300</commonPosition>
				</positions>
				<commonCountingTime unit="seconds">32.895</commonCountingTime>
				<counts 446 422 445 425 422 437 411 474 467 430 426 456 424 425 414 436 397 456 443 471 437 461 465 448 421 454 487 415 426 431 436 442 435 471 427 439 416 427 416 421 401 446 433 469 459 469 449 413 469 426 447 463 444 454 416 429 445 425 429 428 435 416 486 429 393 466 420 420 471 454 419 448 454 423 448 446 410 405 443 415 410 448 414 422 430 430 448 456 433 422 433 434 452 427 431 431 466 418 434 434 410 440 453 380 439 415 419 427 473 417 448 436 442 448 468 424 428 437 467 468 443 419 461 378 407 443 405 417 420 409 404 421 365 387 434 433 425 402 431 428 435 446 446 403 416 428 406 427 451 433 406 446 400 396 426 461 415 399 440 408 412 410 422 426 444 435 430 399 425 428 424 397 441 410 395 428 425 427 405 421 460 402 394 420 432 422 414 416 391 418 400 386 403 448 432 407 416 428 400 423 407 434 408 450 456 448 407 421 448 446 428 412 422 374 413 374 409 453 427 448 402 414 410 410 433 401 401 475 424 394 423 409 451 404 432 424 396 378 425 430 410 428 409 449 393 394 429 407 403 409 425 408 444 407 406 449 436 417 427 384 390 393 441 387 421 460 411 441 450 425 405 412 411 425 457 418 422 389 424 401 389 427 425 415 414 375 388 392 393 460 383 401 405 418 398 434 406 445 424 402 407 405 395 421 455 449 405 407 368 415 423 402 418 406 420 380 360 399 396 413 433 401 382 369 397 394 374 394 435 420 390 391 409 390 402 364 428 387 392 400 386 370 394 422 400 423 402 384 384 409 382 401 366 371 409 398 382 442 403 419 378 415 398 409 404 381 411 424 418 415 404 417 397 387 371 389 385 398 408 404 390 387 372 390 413 392 457 378 413 415 387 384 395 401 403 417 414 388 360 400 410 397 359 415 419 398 397 360 396 339 346 384 426 388 404 429 393 371 416 378 413 406 433 388 382 390 378 394 389 391 365 382 411 373 395 413 408 382 403 361 363 391 408 401 359 383 354 369 399 371 403 402 374 387 364 413 404 415 351 421 393 427 380 419 390 411 390 381 404 370 353 350 393 408 430 385 433 400 427 381 397 388 356 372 407 384 391 405 386 379 368 408 365 367 394 378 387 387 343 357 392 381 445 389 408 404 400 387 374 384 373 405 416 375 377 368 365 409 336 386 360 364 381 407 384 358 391 353 381 334 387 344 386 379 360 375 345 396 370 367 367 419 396 393 372 371 379 384 392 419 394 427 393 372 379 375 358 373 335 365 346 369 357 370 366 382 383 376 373 373 401 322 403 396 414 378 329 363 366 358 382 387 378 376 405 388 402 380 378 368 397 362 358 381 373 399 394 375 366 374 394 369 351 342 378 379 380 396 393 353 382 389 401 366 372 339 380 369 377 375 361 394 354 358 372 345 359 391 391 349 340 361 407 351 375 386 387 369 381 335 382 382 328 405 364 392 385 376 398 383 413 361 411 385 352 388 385 359 370 385 356 369 375 375 385 385 340 371 371 408 366 386 320 368 358 358 380 402 377 376 327 403 384 363 359 359 367 343 386 344 393 377 362 408 345 343 340 379 358 333 401 359 328 383 385 389 367 370 352 370 393 331 373 363 316 348 342 326 383 342 387 386 389 382 380 404 388 348 327 348 350 344 390 391 382 361 362 350 360 328 344 371 352 352 377 358 377 353 371 358 364 383 332 356 361 382 388 338 339 375 385 369 383 343 356 369 348 371 358 381 333 344 345 330 390 379 356 358 352 354 342 410 360 374 380 339 400 366 351 359 369 344 366 392 336 356 365 341 337 337 328 356 368 380 383 349 361 297 331 342 345 384 324 359 340 357 350 332 329 371 351 381 359 368 368 346 381 351 366 353 370 334 371 327 330 354 328 329 373 326 364 359 382 352 341 383 351 339 325 355 364 341 328 345 354 352 361 348 374 306 357 367 337 383 380 349 331 323 349 358 335 350 349 357 352 349 328 328 334 384 327 334 395 364 339 338 332 335 325 364 350 346 326 330 332 366 336 334 316 322 324 305 361 316 348 332 362 340 367 361 346 290 325 341 326 315 371 340 306 323 340 354 336 320 352 337 332 358 342 310 326 334 365 287 353 333 342 313 340 342 325 321 328 322 321 315 332 339 360 326 327 333 342 333 325 314 332 324 346 315 335 323 335 316 304 343 335 334 331 337 313 365 329 356 322 343 317 297 325 349 325 343 302 351 346 295 317 321 303 332 319 343 330 321 337 329 355 308 358 302 333 333 319 299 328 311 319 347 318 321 339 304 329 304 332 332 309 359 311 358 333 334 316 327 290 345 330 329 316 327 310 326 315 305 339 337 322 309 325 290 326 299 326 374 292 340 309 315 279 293 315 314 308 301 320 351 328 293 323 331 328 336 293 302 355 327 333 346 300 329 343 345 288 315 299 308 307 302 317 265 340 343 332 300 332 327 320 286 313 317 325 317 337 304 293 293 306 312 330 322 319 300 316 281 298 297 284 302 299 334 335 308 304 328 297 317 296 302 293 322 318 300 313 319 258 309 285 318 329 328 302 329 316 331 325 300 289 286 309 303 330 316 299 318 318 282 275 319 297 311 313 327 309 286 309 295 308 290 287 294 293 312 308 300 338 290 305 313 346 309 302 339 319 265 297 332 289 282 317 318 285 312 318 300 305 298 316 301 298 296 292 286 265 310 306 298 291 269 308 285 301 324 298 273 315 298 307 289 305 322 308 307 293 301 288 314 276 259 298 280 283 304 324 292 290 293 291 310 302 296 304 298 265 314 293 282 270 319 320 289 288 307 272 306 279 302 292 288 273 277 315 311 295 325 309 288 278 323 297 310 305 304 315 302 295 309 285 306 279 298 313 308 286 288 276 325 289 292 289 329 283 284 314 286 284 286 307 288 264 301 279 293 316 297 288 304 327 324 266 270 275 289 278 306 317 282 282 297 322 279 315 247 307 281 296 290 321 290 287 280 263 295 287 273 303 309 296 266 297 299 307 314 265 286 283 304 266 294 286 301 274 289 273 282 271 279 294 293 289 292 291 294 278 240 260 302 304 313 262 304 294 272 270 274 286 308 270 310 290 296 308 277 279 277 259 294 305 294 308 303 263 284 281 319 243 300 266 273 266 282 271 272 266 315 258 284 321 302 285 274 298 267 307 280 303 281 290 300 301 262 311 279 298 283 266 256 266 288 279 291 280 273 290 241 266 302 298 282 272 320 290 287 257 284 293 293 280 298 289 271 281 306 270 281 286 289 264 269 277 258 268 266 301 264 291 273 290 258 279 287 257 285 276 282 323 258 282 292 314 291 301 298 284 286 288 287 278 293 278 325 293 282 297 288 303 284 277 305 272 284 301 271 307 290 259 276 264 269 283 246 278 292 275 270 266 308 263 269 295 268 261 256 305 288 285 266 272 281 288 282 282 275 291 274 270 271 306 305 309 259 285 282 277 272 280 272 283 280 259 267 289 285 284 293 298 273 243 293 274 249 285 271 276 228 292 271 290 294 268 222 255 272 307 274 294 273 287 266 297 291 300 270 273 261 308 302 260 273 281 292 272 274 275 274 275 287 280 263 292 276 291 274 285 269 269 287 270 303 289 267 271 287 250 243 310 296 279 240 258 258 295 242 262 288 265 296 283 278 247 245 256 280 293 276 262 255 279 273 294 258 272 260 285 266 291 265 281 275 316 241 248 306 288 246 282 261 260 257 263 275 292 268 267 247 259 301 299 242 276 288 288 269 262 238 257 243 255 286 256 279 291 274 270 311 279 265 287 255 259 264 288 305 290 263 281 227 289 247 281 257 292 245 267 281 287 282 259 267 270 266 297 249 278 265 291 304 285 244 273 282 259 257 271 277 265 256 249 316 262 243 244 300 304 288 256 258 278 265 263 275 269 289 269 262 279 269 238 221 269 239 235 269 273 281 264 295 296 267 255 268 269 269 271 246 281 273 274 259 245 261 249 259 284 260 229 289 235 273 280 242 258 272 245 289 294 233 281 278 277 278 265 264 263 263 243 305 298 281 286 300 287 304 270 233 218 262 270 264 274 245 295 264 268 293 246 258 238 246 263 249 260 274 263 262 282 274 307 277 273 263 246 237 245 274 307 266 267 287 240 283 265 260 289 269 248 263 280 248 316 265 243 287 264 268 249 266 275 263 278 260 271 244 262 263 293 245 258 264 260 279 262 284 294 270 272 269 242 260 290 310 264 259 244 285 255 271 274 241 233 272 275 247 261 257 273 284 274 261 258 278 271 297 256 250 284 288 275 292 261 285 282 285 283 272 272 248 285 310 277 266 260 256 279 303 298 264 264 271 243 281 284 264 248 265 240 276 229 246 280 262 265 261 255 287 232 224 248 272 276 259 242 278 249 282 266 262 285 242 301 267 243 281 260 243 282 229 273 276 267 271 277 294 260 250 274 279 259 268 274 263 280 240 237 288 271 276 264 246 239 276 265 264 258 250 229 264 240 269 265 277 286 284 246 278 242 278 248 262 287 280 258 263 285 270 264 243 279 273 260 282 281 227 292 292 262 259 235 292 265 272 259 292 274 285 294 275 287 267 275 269 277 272 287 303 260 295 283 272 261 279 291 240 274 245 257 249 287 244 277 256 279 264 264 267 302 263 258 240 256 245 308 243 274 269 302 255 236 278 306 301 279 295 258 270 275 263 308 243 249 263 255 268 272 267 266 275 277 264 258 233 266 288 259 271 293 265 267 270 283 286 259 258 263 265 268 269 262 239 245 271 282 247 239 263 226 248 231 266 276 281 234 257 242 268 240 248 297 278 246 276 278 267 235 258 244 267 259 248 261 246 266 268 321 255 246 260 272 236 270 268 274 287 272 267 284 244 245 272 235 263 245 282 291 232 273 258 283 249 241 240 263 268 270 268 244 283 233 263 248 264 269 277 272 299 265 310 267 256 288 255 259 276 265 283 256 281 291 257 269 276 271 286 272 250 274 284 242 234 274 273 238 271 276 274 264 280 292 276 271 262 264 243 281 266 255 263 261 248 284 281 281 273 235 265 279 230 262 294 260 264 285 272 261 256 264 228 239 248 256 259 246 270 272 237 288 235 292 267 260 266 274 280 272 259 277 265 228 234 257 270 277 236 265 277 263 236 288 267 274 256 272 306 273 239 270 280 230 256 262 230 258 269 286 268 243 243 246 255 267 278 255 265 267 229 290 262 269 246 272 242 265 263 213 249 262 276 273 244 263 266 275 281 265 262 273 264 276 235 258 263 273 239 223 284 266 272 278 281 259 244 267 269 281 268 237 261 239 265 237 258 262 273 258 249 273 259 302 266 260 248 244 222 249 262 272 266 247 283 255 228 279 299 278 256 271 255 257 279 228 245 272 260 225 261 273 244 260 247 267 274 263 268 233 268 269 262 233 241 260 265 265 280 256 237 267 261 267 247 295 282 293 257 309 268 269 255 243 232 265 248 275 266 237 256 241 277 259 268 301 278 266 263 290 260 245 275 280 290 241 301 271 262 233 246 235 255 284 255 274 221 272 279 271 270 238 280 275 258 286 239 262 260 231 245 250 255 230 266 269 247 257 238 278 262 264 249 270 289 270 258 268 286 249 246 265 241 250 267 273 280 282 259 243 255 261 295 230 281 283 277 276 259 273 261 301 270 247 244 264 255 288 248 249 280 279 296 256 288 244 273 235 296 238 247 265 241 262 266 267 286 290 265 282 300 259 267 274 243 282 230 246 267 255 291 248 262 264 234 266 281 259 240 280 236 275 271 225 262 262 247 277 278 284 279 258 233 243 264 246 261 278 258 269 249 261 255 281 244 256 276 269 244 277 228 272 271 283 274 285 264 284 267 282 256 287 281 317 235 263 235 267 257 261 266 273 260 234 297 272 286 313 280 279 234 280 260 236 286 280 274 243 259 311 270 277 278 239 290 274 294 277 286 245 291 318 268 316 269 300 290 321 255 334 310 297 301 344 317 325 361 309 315 333 328 300 331 303 323 322 333 335 324 329 362 323 320 302 348 333 367 332 297 303 315 344 327 298 314 342 354 290 309 362 298 292 322 305 308 301 322 277 278 316 285 326 273 290 265 266 305 323 291 269 257 282 275 269 266 289 282 258 299 296 269 301 267 289 257 279 275 247 276 255 257 288 291 258 263 243 267 283 233 277 274 282 303 263 259 259 274 249 260 274 267 276 244 246 277 280 273 282 270 229 263 278 284 287 298 256 265 250 273 260 241 260 245 267 250 276 268 269 256 267 247 285 247 276 268 267 265 304 296 388 407 515 603 529 489 463 452 343 296 292 280 277 247 243 276 292 282 261 268 289 263 238 262 273 273 248 246 268 236 308 242 256 257 278 243 258 265 272 279 245 291 285 255 290 237 261 273 283 256 247 262 278 239 287 270 278 240 292 273 262 269 258 297 236 269 269 281 265 297 282 270 258 234 291 265 259 244 267 223 246 240 286 255 243 264 247 265 257 256 250 243 249 258 280 243 256 257 279 248 301 259 269 235 281 295 232 283 261 276 256 267 257 274 256 238 283 260 268 289 274 299 276 273 227 246 260 269 262 261 273 259 263 245 260 273 248 248 284 244 276 234 284 276 242 244 266 230 228 277 272 244 270 242 266 245 271 272 278 275 259 239 270 247 248 270 280 271 282 266 249 297 265 236 265 299 269 273 289 281 278 277 235 272 260 262 275 268 227 269 241 244 259 248 266 266 281 276 282 231 280 259 281 271 248 269 293 259 258 279 286 247 275 271 287 278 245 256 264 299 278 269 265 245 269 257 257 263 246 266 302 235 291 294 255 275 295 286 294 273 270 312 329 298 300 313 307 302 274 311 245 248 266 287 262 274 290 269 241 286 286 269 271 263 267 280 275 288 272 286 263 297 291 272 314 305 282 293 279 285 311 282 297 296 294 282 270 302 306 337 297 288 286 288 288 300 289 269 280 303 291 287 299 258 298 330 302 316 287 310 292 293 298 286 280 316 331 327 283 276 338 321 322 327 275 333 296 334 319 319 391 338 279 348 350 331 345 344 356 302 323 352 376 322 337 341 333 379 348 328 360 366 341 387 362 359 352 389 338 400 404 353 397 389 375 385 424 393 402 389 422 376 426 415 431 386 375 425 432 403 411 410 430 470 412 461 457 492 524 494 523 487 553 477 512 560 513 559 610 590 630 613 664 825 912 1052 1212 1377 1527 1495 1479 1488 1412 1437 1505 1567 1696 1834 2250 2647 3414 4812 6802 12016 27981 61627 85599 91883 90341 82961 65448 34905 16735 10854 10856 17539 32878 43911 47366 45820 42008 32252 17944 8844 5008 3268 2448 1942 1648 1516 1348 1195 1071 1000 1021 951 818 752 742 718 697 664 646 647 629 621 572 583 598 559 517 486 522 521 502 502 481 490 440 445 457 444 437 444 452 419 389 392 416 354 399 414 405 400 384 393 346 358 384 371 376 352 351 342 351 327 359 351 345 326 353 312 311 315 319 332 368 322 305 349 330 348 336 310 319 343 317 296 302 306 288 296 285 275 285 298 310 295 293 282 249 294 292 299 287 306 336 298 280 276 273 298 290 314 299 280 283 292 281 277 273 249 295 291 292 326 271 309 280 282 255 313 287 299 272 286 313 280 288 285 274 308 317 293 288 310 304 247 300 310 263 292 292 301 273 300 315 280 314 304 276 261 303 285 285 278 276 305 282 308 288 287 292 288 246 302 278 300 266 280 290 285 303 290 275 269 284 300 286 282 286 301 308 306 284 313 289 304 306 320 317 280 285 314 294 291 313 311 301 279 291 325 336 296 310 316 312 289 336 316 319 313 340 290 357 304 329 324 332 302 326 311 357 349 361 307 325 336 368 346 369 359 340 389 351 384 397 374 397 394 420 400 420 441 439 453 435 465 445 522 514 472 533 527 586 518 614 567 569 553 552 557 572 607 502 590 557 534 527 530 503 494 484 463 440 441 462 424 420 435 424 392 407 417 400 331 372 362 346 343 320 334 334 339 334 356 343 294 313 292 325 326 315 309 298 324 298 296 306 307 285 294 290 277 289 263 312 312 283 271 299 317 255 297 260 304 273 284 278 264 258 276 281 243 298 276 258 256 267 264 265 265 279 239 291 267 241 270 303 277 265 290 291 272 298 264 295 262 280 264 266 249 276 262 280 235 263 264 221 277 268 236 247 256 266 282 268 288 296 243 272 268 276 262 292 261 244 277 246 292 245 269 277 271 257 291 291 257 266 258 235 222 264 260 265 298 269 259 286 248 266 243 297 258 241 262 287 275 257 240 272 274 259 274 276 278 264 237 263 256 296 255 248 255 285 283 227 248 234 265 286 269 295 247 296 248 236 280 244 262 274 259 242 266 261 246 261 269 247 272 294 273 264 274 289 274 243 241 263 274 282 259 304 271 260 287 291 262 269 243 265 279 227 255 245 255 235 270 267 273 258 264 301 241 235 275 255 287 262 277 265 276 248 257 262 263 249 275 269 234 246 276 276 226 272 283 250 224 260 272 281 248 228 265 249 262 275 232 233 286 266 278 234 259 244 264 241 219 280 261 282 272 267 276 275 247 268 274 259 272 288 258 264 264 249 231 272 260 290 280 257 264 308 301 267 266 238 260 285 233 222 240 267 241 259 262 306 298 271 279 248 237 260 239 293 279 270 293 246 262 296 246 247 231 243 249 229 247 281 227 269 281 256 273 276 266 262 232 270 249 258 258 258 239 243 233 242 285 255 274 265 271 273 279 294 222 245 269 274 267 257 265 271 255 275 269 242 248 282 259 244 257 279 247 245 290 280 279 268 266 268 293 243 257 286 283 264 240 235 264 280 258 270 242 277 273 247 255 270 246 274 248 243 240 296 256 260 258 259 235 263 234 279 242 259 235 262 242 266 247 290 257 268 273 269 235 279 276 272 277 263 267 270 242 257 262 258 257 235 243 242 244 274 222 262 274 267 284 256 222 260 267 238 260 262 262 243 295 272 231 270 257 267 278 277 266 248 257 233 265 233 234 263 278 268 259 247 240 240 275 243 245 249 247 277 227 271 274 289 233 262 245 280 267 265 283 265 259 262 278 245 249 272 279 266 263 260 262 231 246 264 259 236 239 278 264 258 277 295 237 249 265 261 275 315 239 263 249 263 261 273 239 272 239 310 264 270 260 258 271 226 258 260 257 244 258 256 293 257 257 249 294 281 276 264 277 291 215 272 256 283 267 245 280 235 259 249 259 280 262 275 292 287 257 279 273 289 248 272 273 264 257 260 259 275 240 265 283 273 266 262 244 305 245 263 260 291 248 257 266 237 286 283 267 267 297 269 237 259 264 283 278 260 260 262 270 282 284 255 271 271 246 279 264 276 243 263 280 280 247 240 247 270 233 237 283 263 275 256 279 282 263 274 290 255 263 290 260 300 257 256 270 280 249 281 269 293 269 245 300 273 296 272 247 246 286 241 243 235 268 268 255 267 238 238 281 293 239 309 267 263 270 303 240 268 244 260 231 264 265 248 270 271 278 298 286 265 261 266 262 256 248 265 247 275 277 258 242 246 263 302 261 308 287 231 246 249 265 265 235 271 226 272 274 256 264 263 239 275 267 271 247 276 256 255 273 302 225 281 272 221 280 238 266 287 262 262 274 256 269 234 248 261 249 279 255 264 244 256 258 277 287 237 248 224 279 246 279 273 279 264 237 255 288 302 279 262 259 274 238 260 256 259 258 261 268 261 265 286 303 266 238 262 243 233 273 270 270 245 302 305 239 273 245 279 265 278 234 291 271 245 284 245 242 280 294 277 255 258 279 242 264 283 257 274 291 293 274 298 260 244 268 239 303 246 279 292 279 266 256 270 265 248 278 242 257 247 274 320 262 275 265 256 243 264 270 279 265 255 285 266 261 269 284 257 261 247 266 247 267 260 268 255 276 283 275 299 270 294 276 272 277 244 286 243 256 281 259 269 247 242 264 239 264 256 273 257 231 263 273 261 248 256 283 298 289 289 258 287 270 294 281 233 286 278 262 257 267 271 281 246 257 271 282 301 249 267 257 236 256 261 259 240 231 269 239 268 258 225 260 275 265 260 237 272 257 280 275 234 285 284 277 280 273 285 246 242 281 238 280 232 257 270 281 277 304 290 275 296 272 292 239 262 280 285 260 260 296 276 295 262 258 275 220 239 248 268 282 227 291 282 269 243 262 317 289 304 288 266 257 258 276 271 283 294 303 270 257 243 288 248 289 274 289 246 240 256 275 264 273 264 249 261 249 276 267 261 280 248 272 263 267 267 265 276 275 286 265 260 262 292 284 285 268 281 265 248 257 245 264 246 273 264 272 266 277 280 269 263 280 286 282 276 272 255 255 269 238 268 299 295 232 270 214 258 257 261 260 258 257 268 274 281 285 282 291 269 271 290 247 278 261 261 277 282 242 269 249 296 284 275 278 280 269 234 270 279 269 247 282 286 269 287 256 248 262 301 267 247 275 248 283 238 262 279 234 242 273 274 255 265 271 281 284 234 279 255 274 275 287 255 242 238 280 280 260 263 256 283 266 273 247 257 277 314 245 262 259 235 257 288 273 290 279 268 292 299 303 266 292 280 255 245 280 300 237 265 275 299 271 270 264 292 278 256 288 273 282 246 255 248 255 312 279 263 249 282 298 285 280 276 264 258 280 266 256 269 269 279 271 238 268 290 278 259 271 281 241 270 275 269 286 245 248 272 272 285 255 288 280 264 279 280 244 270 294 271 299 270 261 295 289 257 264 239 242 264 270 242 282 276 248 284 265 262 283 279 279 272 255 325 260 237 272 290 233 283 280 281 243 281 272 294 256 258 277 296 276 246 307 302 282 282 263 258 297 244 264 238 270 293 272 277 267 283 288 282 283 283 292 277 250 281 296 264 266 277 249 278 230 292 278 285 296 268 277 261 285 271 260 288 314 287 238 237 243 274 279 258 272 281 278 278 248 258 259 280 282 282 278 268 286 268 258 257 270 276 268 245 243 255 261 247 273 317 239 273 234 267 275 282 255 280 300 273 284 293 289 280 302 271 265 302 288 248 267 283 272 270 239 280 272 275 289 256 276 267 268 226 266 270 257 282 275 295 285 273 285 237 268 282 269 245 257 285 245 275 273 276 287 248 242 287 259 274 268 223 276 266 281 288 265 287 280 277 266 275 243 278 280 286 257 257 283 258 268 294 260 276 275 278 293 271 235 280 269 283 270 263 258 269 246 288 229 255 249 276 250 280 245 289 265 267 260 272 266 289 292 292 270 257 282 282 265 247 273 294 246 248 274 271 281 286 243 267 266 281 248 268 274 290 263 269 286 278 270 259 262 247 277 275 272 236 275 271 297 238 270 259 278 259 264 245 243 284 283 260 260 258 244 302 258 257 276 276 268 277 258 248 257 270 277 228 268 237 273 248 276 249 269 293 263 270 268 226 243 281 259 242 284 296 301 256 268 290 261 268 267 298 241 236 267 295 268 279 280 247 271 263 276 246 265 275 260 271 284 269 264 268 275 280 265 283 229 269 245 280 277 237 264 258 241 275 273 249 286 263 261 278 260 295 290 266 276 285 260 239 250 294 273 261 238 268 284 259 240 286 259 277 232 231 256 263 278 264 238 284 255 267 210 293 247 282 256 272 268 273 283 248 259 270 278 272 272 248 271 272 282 275 258 244 275 270 279 264 271 264 298 245 273 261 283 248 246 263 276 290 274 273 270 233 277 255 257 266 262 296 264 264 272 249 294 247 263 246 262 241 279 285 269 278 275 286 283 315 269 260 246 283 262 246 285 274 278 282 264 241 268 258 290 283 304 271 303 261 301 263 266 280 245 295 265 299 265 310 311 264 289 262 268 241 272 225 258 261 285 283 278 257 277 249 275 270 256 282 286 249 262 276 273 270 258 274 240 277 268 269 278 270 244 269 285 276 296 248 290 259 263 284 280 224 268 289 302 280 271 271 244 231 260 267 230 315 255 258 292 280 268 286 284 259 236 261 296 272 280 288 256 275 263 288 280 237 236 273 241 289 292 268 270 291 246 281 267 263 249 283 245 282 277 258 261 277 262 290 267 258 228 286 264 259 232 265 299 258 241 277 264 299 270 287 263 249 296 263 276 295 272 287 269 294 234 274 249 280 279 246 271 246 260 243 285 259 250 277 274 264 266 261 275 260 263 287 275 300 276 263 261 269 281 260 291 269 265 269 295 233 247 272 255 264 336 283 278 297 271 278 293 232 247 272 279 215 265 255 241 278 244 256 283 263 286 273 286 281 260 273 259 248 255 245 275 267 260 297 276 261 286 256 242 268 290 260 239 249 247 262 269 281 286 265 267 267 238 270 292 273 268 279 271 272 274 276 271 274 299 284 263 273 231 237 269 260 265 267 286 280 267 263 271 265 244 267 241 295 257 248 307 257 269 271 284 291 255 285 266 263 275 232 265 263 291 264 265 280 264 291 256 268 273 269 268 270 279 275 274 287 291 291 273 273 288 285 259 264 290 258 292 274 298 261 312 255 280 307 315 262 297 292 276 301 300 278 266 285 273 315 284 258 280 275 282 302 274 309 283 289 287 284 282 282 282 296 283 285 259 265 277 291 293 264 295 286 289 276 262 313 293 279 257 284 282 286 289 301 277 282 276 274 300 282 276 292 264 245 287 278 239 241 296 270 277 277 282 273 269 272 275 284 262 283 266 269 272 299 264 261 271 258 261 275 299 270 274 235 268 265 296 232 223 233 264 264 263 271 283 255 277 249 276 267 261 256 223 269 257 268 259 274 298 287 279 271 281 275 271 284 294 265 238 309 260 275 240 256 255 278 267 269 260 263 298 269 261 266 264 288 249 240 268 262 255 264 242 260 275 266 262 278 293 277 238 248 281 268 279 247 280 287 244 285 255 260 291 284 277 270 257 248 262 290 266 246 255 268 295 262 269 234 287 273 243 291 273 242 256 269 274 289 265 299 256 220 279 289 246 269 294 287 257 269 263 272 265 288 230 275 267 266 244 279 255 277 262 284 264 240 291 263 286 290 297 246 285 240 249 270 260 267 285 244 262 258 290 259 263 258 289 269 275 265 285 246 246 277 227 260 285 268 264 256 243 260 232 297 247 274 270 266 263 275 266 224 244 258 229 272 294 292 241 297 265 294 279 267 277 241 261 296 298 260 268 245 225 307 289 271 249 277 270 278 259 280 273 243 267 245 285 238 273 243 297 263 265 247 264 264 288 281 238 304 259 287 288 287 275 302 275 288 268 239 292 264 264 277 264 262 284 291 262 260 261 243 239 276 245 278 268 265 296 284 264 249 293 256 260 242 217 263 276 270 285 269 249 240 265 287 273 248 284 257 277 231 284 304 239 235 230 264 285 260 291 274 238 308 293 282 292 273 266 242 231 239 266 270 278 265 237 261 243 250 249 280 242 269 265 248 248 291 262 227 270 257 289 272 265 290 262 285 279 293 289 273 262 269 272 282 265 270 269 238 281 290 256 287 274 235 240 263 281 293 269 293 280 304 222 268 285 267 284 290 290 258 267 282 272 290 265 280 239 262 240 260 291 259 235 281 275 292 265 243 267 272 250 235 281 275 281 227 282 266 266 283 261 263 249 305 258 264 257 292 280 236 259 260 262 282 238 280 291 259 247 246 271 240 276 305 277 283 274 273 276 283 277 284 280 263 266 290 270 296 265 244 239 256 272 256 274 260 264 278 249 291 274 234 244 288 270 279 292 290 271 259 242 239 267 298 284 241 280 268 273 269 249 295 299 296 265 284 310 244 283 271 284 268 299 269 284 274 276 259 285 269 269 244 243 277 263 268 277 269 247 276 291 285 276 262 247 283 236 268 257 265 278 278 260 260 276 285 273 288 283 272 290 287 278 298 263 237 280 261 288 237 265 267 256 271 266 255 268 290 237 247 257 278 256 260 285 296 248 282 265 280 304 273 277 259 293 250 250 297 269 285 235 260 290 291 242 266 265 261 284 269 279 271 235 283 270 299 288 326 256 280 293 260 270 276 269 267 236 246 286 284 243 256 263 288 279 287 287 261 292 269 289 260 259 258 294 259 271 246 295 306 279 269 263 273 275 290 307 299 284 286 262 291 300 292 271 277 309 263 267 282 273 278 274 247 281 268 271 300 277 301 302 289 257 306 292 286 299 286 275 255 270 290 293 305 265 276 262 277 268 321 262 287 275 264 250 272 257 264 286 326 271 309 304 281 296 269 275 309 285 271 306 262 275 263 260 288 272 301 264 267 292 257 325 246 281 268 287 282 276 268 270 259 273 284 241 269 289 295 288 277 278 278 274 293 319 319 245 277 290 232 310 248 278 293 266 284 263 283 275 273 275 262 274 304 275 284 279 243 260 274 277 284 296 291 289 275 293 256 264 280 268 270 279 242 266 281 246 283 275 274 264 248 288 305 281 274 310 262 300 281 274 279 271 284 263 264 293 280 278 267 265 279 331 301 277 290 274 243 240 269 247 304 272 258 274 256 271 268 277 242 282 255 302 284 313 280 265 270 281 301 264 282 260 272 223 221 241 281 271 283 273 256 237 229 264 262 264 279 277 268 309 299 305 296 316 288 263 246 305 242 255 269 284 296 279 284 286 277 288 297 280 262 279 295 264 284 282 260 339 285 264 305 271 261 268 288 269 257 299 283 320 285 285 277 272 299 271 255 287 261 267 268 281 249 281 261 264 281 271 233 287 294 278 274 268 247 245 296 284 277 296 261 293 283 277 269 257 297 275 286 256 299 255 249 272 281 277 263 270 269 280 314 305 248 271 261 261 267 284 267 264 293 307 292 291 301 274 268 270 263 311 255 274 236 281 302 295 249 287 288 263 282 306 280 285 279 310 307 238 276 299 301 245 277 293 314 271 280 309 272 278 248 278 264 294 263 301 278 282 286 314 282 277 268 249 293 262 297 287 279 309 282 279 298 269 288 283 256 268 275 226 298 260 259 283 270 234 246 274 282 293 290 298 272 255 285 279 305 259 260 284 260 294 280 297 280 293 258 275 262 311 301 289 277 293 267 303 277 265 272 286 278 282 271 304 286 271 279 243 269 259 280 257 264 261 274 235 249 245 244 243 281 269 269 309 279 278 271 280 269 296 281 233 282 297 276 236 262 271 256 237 271 301 273 306 255 243 302 270 286 274 257 280 290 270 290 279 265 245 290 281 296 301 273 297 261 288 284 273 269 296 239 304 275 265 287 288 269 258 259 271 249 272 255 305 269 255 259 287 261 318 306 255 242 288 274 294 277 267 279 270 268 299 282 261 281 286 288 268 241 269 276 216 298 295 267 278 291 278 300 298 283 269 271 277 255 263 268 278 278 308 266 246 297 263 260 258 270 257 263 257 276 295 261 282 243 283 262 274 247 307 279 293 264 221 275 310 260 263 272 255 280 274 311 274 267 266 266 258 302 259 301 244 305 250 272 271 287 224 297 271 292 265 307 259 287 256 262 284 297 276 291 248 272 279 259 262 261 281 277 267 305 297 295 279 274 258 312 261 289 271 276 291 245 291 283 260 271 287 273 288 299 283 284 280 270 255 269 274 269 296 268 279 260 241 248 267 283 290 267 237 261 259 282 280 260 276 262 255 289 292 301 292 270 301 241 282 262 266 274 275 237 273 280 258 295 264 265 264 284 293 279 275 289 231 307 281 274 310 260 278 297 297 259 298 277 255 279 294 273 303 277 283 266 271 290 257 274 296 255 286 287 273 283 285 307 289 298 310 267 285 233 257 289 224 282 288 278 269 298 261 285 245 312 307 287 287 270 271 310 311 278 292 273 275 286 243 298 271 289 285 284 300 298 259 260 274 290 275 260 245 255 275 257 261 288 291 270 284 270 271 296 316 273 261 277 299 278 257 297 270 267 280 269 299 250 268 268 258 250 307 276 288 274 284 256 282 260 281 282 288 283 297 312 300 246 268 283 266 271 279 294 261 291 258 274 263 291 290 277 260 258 280 287 289 260 287 300 275 267 297 286 258 279 282 275 305 294 280 284 267 301 257 268 314 297 269 257 255 290 257 262 275 269 304 301 317 308 313 311 319 308 347 360 377 408 451 499 541 607 610 650 651 648 553 535 466 465 477 457 443 405 369 386 352 314 305 354 306 297 323 292 298 324 279 296 332 266 272 279 288 265 297 281 282 283 274 279 311 268 305 269 288 278 286 268 261 248 296 285 300 291 290 311 300 291 260 295 258 285 300 302 280 291 261 266 311 275 292 293 290 296 296 291 320 324 275 279 300 273 286 279 301 309 320 300 225 294 311 321 278 273 287 275 301 286 279 261 287 319 289 296 279 293 294 286 324 264 283 278 270 311 286 287 287 286 273 268 318 281 284 302 293 273 287 269 270 308 313 256 292 296 271 274 285 267 302 289 257 250 289 288 282 282 279 270 311 307 291 296 307 294 284 290 258 303 292 267 317 300 283 303 318 316 318 304 280 277 276 299 310 298 302 295 314 292 271 309 307 297 304 288 279 299 281 287 325 290 346 313 325 306 327 333 301 283 318 319 300 336 307 298 343 326 317 332 368 322 324 327 318 347 355 349 315 339 334 328 304 337 348 332 335 338 319 320 315 318 321 328 317 314 324 316 327 291 338 296 325 308 302 282 328 295 332 308 351 296 295 310 302 313 353 285 280 321 310 287 293 340 322 290 296 284 308 312 330 301 316 319 289 295 287 308 311 289 304 323 333 289 315 290 299 285 262 297 266 303 297 292 292 291 300 283 265 297 310 305 286 300 279 291 269 295 298 291 300 298 288 285 287 265 299 291 279 287 277 256 293 314 294 267 322 319 278 260 286 279 269 271 290 272 291 261 288 283 284 290 255 283 280 295 276 315 300 291 257 278 311 283 268 280 273 303 303 270 315 276 285 293 286 277 285 274 322 301 276 283 274 290 272 279 270 266 285 279 301 300 287 286 294 276 299 270 297 281 257 293 291 298 294 294 283 258 278 304 295 284 307 256 267 275 309 310 277 302 291 302 237 300 294 238 288 303 295 277 278 246 269 292 266 289 270 258 262 289 277 283 303 274 276 264 301 289 297 266 269 259 310 266 244 277 291 282 277 300 265 276 284 282 304 264 302 285 261 268 287 262 289 303 275 271 245 275 295 276 273 313 269 282 285 262 316 274 298 282 273 295 241 274 247 278 259 278 295 258 260 287 304 282 278 280 278 302 303 276 258 279 303 267 273 236 264 293 302 272 293 331 300 280 245 291 300 326 303 271 263 277 243 267 260 297 249 289 309 301 279 282 286 282 290 259 264 285 266 263 290 274 288 303 280 285 301 289 244 262 266 293 246 244 297 288 270 262 279 288 283 292 299 240 267 283 265 281 273 289 283 281 268 283 269 298 290 337 276 297 289 279 276 294 300 289 297 247 264 257 264 300 268 277 308 280 278 286 279 261 276 309 272 274 302 259 308 299 321 307 302 315 322 286 315 310 299 293 285 292 271 289 281 284 306 293 303 289 287 296 290 288 284 304 267 287 265 281 283 303 290 272 294 269 290 309 295 303 288 279 294 300 263 289 282 281 290 301 281 306 281 288 285 288 284 318 283 288 284 281 310 284 266 286 294 285 307 320 285 280 312 317 270 269 314 287 271 323 294 306 303 263 312 279 314 292 270 284 295 275 267 309 289 272 302 257 286 303 285 328 282 297 280 299 291 309 289 290 298 281 283 308 316 285 268 285 313 291 291 304 280 299 274 279 299 276 323 280 281 310 336 282 293 270 315 307 270 337 262 288 309 305 322 302 266 321 308 315 308 301 282 276 267 292 298 275 276 304 293 313 287 280 296 301 300 300 286 295 283 329 336 295 335 289 306 310 292 290 320 327 301 327 274 305 308 286 268 311 290 321 313 298 334 302 304 302 326 337 339 323 328 293 337 304 289 315 315 305 320 307 301 312 314 323 319 322 321 333 277 316 351 294 288 335 294 324 316 356 331 319 316 307 344 358 334 304 310 348 301 319 344 317 300 309 325 347 323 332 329 318 328 323 296 340 308 338 341 344 318 379 302 300 295 326 335 323 343 322 366 333 309 325 322 317 333 338 386 308 351 333 322 320 329 312 370 363 338 329 349 356 321 352 353 326 310 330 348 323 348 373 351 329 324 344 355 365 340 350 319 359 375 361 349 307 345 358 316 329 312 339 341 355 369 369 346 337 384 353 353 335 321 374 381 397 410 380 353 379 374 359 381 362 393 402 377 375 395 412 402 317 387 367 394 386 427 395 364 380 364 356 384 416 407 409 407 424 437 431 385 435 393 418 444 419 397 419 429 422 418 469 461 372 418 410 406 430 424 456 414 439 463 446 461 480 452 478 430 436 481 478 464 491 474 482 545 530 494 568 513 549 582 573 599 622 593 577 672 648 683 693 804 775 849 861 901 892 963 1002 1037 1091 1112 1084 1049 1094 1140 1188 1090 1073 1064 1041 1081 1057 1046 1102 1048 1123 1150 1135 1087 1135 1219 1317 1295 1326 1338 1492 1559 1621 1783 1855 1975 2207 2432 2622 2813 3146 3491 4030 4573 5418 6496 7663 9688 12341 16396 23627 35939 56858 82475 101202 109609 108549 100725 81683 59002 41308 29219 21702 16174 12411 9649 7894 6617 5867 5252 4911 4516 4676 4757 5098 5498 6437 7693 9695 12954 18330 26860 36603 45315 50893 52505 49896 43479 34170 25441 18375 13117 10053 7468 5911 4837 4050 3468 2960 2522 2301 2094 1968 1828 1659 1536 1455 1436 1365 1327 1206 1157 1144 1045 1072 1071 960 948 921 881 888 838 829 835 822 775 750 802 722 681 692 705 622 678 664 627 609 633 625 594 566 552 624 567 593 580 590 514 565 544 529 516 545 541 498 523 514 497 490 461 472 464 514 460 505 485 459 465 435 409 401 441 446 430 459 442 394 455 429 405 412 464 436 346 429 420 422 395 406 420 412 416 411 429 403 394 423 406 373 403 414 377 390 370 416 366 387 394 371 378 404 410 432 376 364 380 348 374 375 393 365 387 366 380 375 406 407 386 347 342 392 360 371 369 369 337 351 338 331 337 362 328 352 383 323 338 342 354 377 348 343 314 329 349 320 334 343 335 316 330 330 328 302 326 310 322 325 333 305 323 319 330 336 344 333 334 333 347 299 329 285 338 331 318 295 293 343 298 375 309 321 322 307 310 288 292 343 307 303 288 306 295 342 316 327 334 326 322 326 332 293 300 334 266 326 302 325 296 299 325 294 340 278 333 330 288 302 313 290 313 299 313 343 277 315 316 300 319 337 290 269 279 301 290 318 343 331 341 312 331 300 316 282 294 301 341 318 284 300 286 310 323 285 294 266 289 279 351 317 281 299 297 306 311 304 312 256 301 293 313 300 309 302 334 305 312 276 275 322 312 280 312 281 278 293 300 296 310 299 275 304 309 273 333 280 276 283 303 338 295 299 268 316 303 308 301 285 288 279 290 301 314 265 288 290 275 302 305 299 284 310 286 298 282 287 270 300 285 291 278 309 291 295 301 313 285 302 275 264 304 278 313 279 277 312 303 280 314 288 259 295 268 339 298 270 289 273 291 278 300 275 274 298 283 298 277 294 279 323 322 291 314 278 317 280 294 320 312 278 290 276 282 296 258 306 262 287 317 230 261 280 290 285 278 267 297 280 288 298 282 280 292 284 263 306 305 278 276 290 291 281 297 297 269 280 280 301 296 282 298 283 297 280 261 271 290 316 283 289 274 298 280 288 282 270 281 269 294 276 281 280 311 297 288 282 290 276 316 285 284 301 280 314 262 283 304 264 287 290 303 292 259 308 285 273 282 280 299 278 289 262 289 284 273 283 228 282 298 257 274 292 294 288 306 295 267 302 288 294 311 314 268 303 240 285 299 294 298 295 276 259 296 277 282 292 258 296 336 291 300 304 293 255 281 267 271 267 283 299 293 275 268 283 265 274 281 293 271 292 294 286 263 262 310 263 315 272 262 286 271 282 241 283 277 265 276 319 263 274 313 262 282 280 296 249 290 292 260 276 272 295 285 282 288 288 281 295 261 271 257 271 279 285 275 289 270 271 273 296 267 285 312 296 282 274 272 283 287 281 281 259 293 284 277 274 304 272 296 279 280 298 279 273 297 301 275 307 278 312 270 284 265 265 289 272 283 279 276 309 305 290 289 305 274 276 306 278 271 295 301 263 289 277 309 273 293 306 271 296 294 309 256 249 266 244 271 269 290 295 265 293 298 256 283 293 267 246 274 308 287 287 257 256 275 282 271 292 283 266 273 263 268 259 306 290 298 283 276 275 285 269 305 287 302 280 302 241 281 313 287 256 257 286 272 299 286 292 286 331 243 270 280 265 286 316 307 305 306 260 286 310 281 282 301 300 310 265 308 286 296 283 280 286 291 296 280 266 282 285 274 295 304 298 300 270 298 312 308 281 293 267 295 304 261 291 304 327 274 302 320 274 265 325 293 288 276 293 286 299 339 293 267 325 283 302 324 289 281 294 302 306 294 303 306 295 286 279 306 307 294 322 334 323 315 295 273 279 300 297 286 308 290 286 274 271 280 281 276 296 307 290 301 281 316 282 250 300 315 301 300 328 282 280 274 300 282 262 263 278 274 274 267 283 306 288 287 266 308 289 268 287 281 265 292 260 292 302 285 268 276 269 294 313 287 283 309 259 279 289 278 293 292 267 288 296 294 281 304 271 275 261 276 285 301 282 285 281 265 245 305 236 292 279 312 278 285 286 286 275 282 267 267 279 311 306 285 262 299 280 288 295 276 268 326 292 302 296 245 258 273 269 294 260 268 268 286 276 270 274 287 283 284 282 278 268 299 279 270 266 295 242 265 273 274 284 288 295 274 274 285 259 293 280 283 324 285 292 316 278 287 283 272 279 277 311 298 275 262 271 255 272 278 291 274 288 261 266 289 273 292 280 304 296 286 287 276 293 290 284 294 268 266 297 288 275 298 286 258 276 309 271 309 281 263 265 285 290 304 304 266 268 286 293 292 290 266 292 265 266 259 268 273 275 260 281 310 272 299 276 300 284 272 277 279 289 299 281 301 248 266 260 267 287 299 297 286 277 274 306 296 295 286 306 281 280 307 289 311 305 303 300 285 249 260 245 277 288 274 291 283 297 275 291 259 284 267 279 260 314 307 294 293 286 291 278 282 233 240 266 269 282 269 262 287 273 296 276 290 278 273 292 282 298 300 321 276 249 267 282 312 259 275 280 292 275 286 296 279 290 267 321 256 285 331 268 281 282 284 278 278 293 293 299 288 282 289 279 285 281 277 272 272 303 270 303 265 261 267 284 304 285 280 281 266 283 282 291 278 307 285 290 264 276 305 287 263 304 303 260 284 279 302 256 291 293 249 294 285 288 280 275 292 281 243 281 260 291 255 247 242 279 293 268 300 268 267 299 270 288 276 274 267 274 276 296 282 294 271 282 277 257 303 265 274 291 273 242 294 273 295 269 294 280 291 280 260 269 298 270 296 304 308 305 289 305 276 249 314 285 309 256 285 283 296 285 286 299 301 280 300 265 248 284 287 296 315 288 312 294 268 272 284 314 278 306 297 291 282 304 288 272 263 278 278 261 269 283 270 310 294 301 264 290 273 297 284 290 290 273 275 250 292 282 288 277 278 281 272 247 283 291 256 302 295 310 308 273 262 293 271 296 296 291 291 285 298 282 280 288 300 291 302 290 286 280 274 270 285 248 288 256 256 294 290 307 305 245 308 295 281 283 276 283 284 282 314 313 289 288 304 302 287 295 335 302 276 269 273 276 303 300 309 259 310 294 275 260 308 275 294 299 245 263 296 267 305 314 285 325 301 285 277 281 279 239 308 291 307 284 282 264 313 268 307 317 273 272 270 258 293 266 276 284 279 308 277 295 284 283 276 301 287 258 278 291 293 291 276 259 269 270 266 302 290 326 271 318 302 277 282 273 342 293 290 322 288 298 296 275 274 255 303 265 291 255 297 290 285 269 292 261 280 288 275 265 288 299 292 285 264 304 269 315 272 307 282 278 285 265 313 281 281 281 244 312 299 299 290 306 281 297 308 321 289 250 302 270 266 268 316 297 298 266 301 273 270 306 295 276 288 262 262 270 298 332 261 285 278 295 281 293 271 281 284 245 279 274 313 258 290 303 311 312 282 273 263 303 285 318 259 305 304 295 278 265 290 298 278 285 277 295 281 288 288 283 272 270 288 314 262 277 288 300 268 294 280 280 291 321 262 288 279 260 282 273 286 268 303 276 266 273 291 293 259 294 290 310 263 312 310 284 305 269 293 283 295 291 282 300 282 262 294 264 290 265 257 284 289 268 282 282 318 283 284 292 293 311 300 281 297 266 294 275 287 268 274 314 267 266 246 324 291 269 314 290 270 276 317 273 287 291 289 317 255 283 261 288 282 282 316 292 281 277 283 266 278 294 287 277 274 300 303 269 289 303 274 318 282 298 310 317 295 286 286 277 282 286 298 264 248 272 289 284 289 290 287 260 262 278 260 261 286 297 289 307 285 290 278 246 296 278 279 278 265 268 286 286 281 289 283 295 273 270 291 257 269 283 312 290 281 276 273 265 307 275 306 287 277 290 277 317 280 291 246 272 282 261 293 285 262 264 288 270 290 303 297 275 293 286 235 278 229 277 255 281 264 273 289 282 283 267 277 263 294 263 289 262 274 256 287 290 277 287 281 287 303 291 264 274 237 270 291 250 283 239 273 306 289 224 293 280 285 248 269 282 281 261 301 270 315 320 284 316 334 299 273 296 289 300 235 265 258 283 277 281 275 262 293 286 267 265 264 288 299 265 280 281 287 264 246 259 287 258 272 275 269 273 299 291 278 290 322 310 243 255 291 281 294 256 297 271 270 239 272 294 288 290 278 275 275 289 268 297 259 311 282 281 296 302 259 243 256 266 300 259 275 291 316 280 272 273 303 287 258 298 296 299 245 291 270 269 247 292 275 263 289 276 276 277 279 258 313 261 292 273 263 275 294 247 282 277 239 288 257 291 301 277 278 280 286 303 267 277 261 276 266 265 258 288 266 266 272 301 290 272 284 239 285 273 290 290 280 300 281 274 282 245 274 262 271 273 261 259 250 273 286 284 247 315 271 271 280 256 270 280 229 285 245 260 265 260 279 307 299 274 309 275 259 276 278 272 285 279 274 274 246 301 268 285 262 291 259 315 284 238 256 301 284 273 277 292 285 268 281 284 282 278 298 279 289 264 279 326 279 298 293 285 280 260 300 249 305 262 284 303 258 265 290 278 309 267 278 261 296 258 280 255 263 259 258 285 270 284 258 266 279 233 279 281 287 299 242 274 272 295 242 257 309 283 277 263 262 266 277 290 286 261 299 258 260 292 280 266 263 275 299 273 236 274 284 310 221 276 271 295 266 271 237 264 237 282 241 289 262 273 278 267 280 278 283 277 271 261 295 270 275 264 266 278 270 300 283 256 285 243 240 271 293 270 261 275 294 258 295 289 314 283 295 262 261 277 260 281 244 274 259 267 266 256 283 243 256 268 241 292 285 293 239 266 243 269 278 277 257 249 277 278 297 267 279 295 263 300 235 301 270 303 301 245 287 278 228 240 270 282 292 284 273 282 266 265 262 290 264 269 298 291 288 279 270 277 264 246 295 243 247 255 305 258 263 248 275 257 289 276 266 294 277 260 267 293 299 272 283 242 283 297 287 272 281 260 299 269 272 281 294 283 272 267 289 290 245 271 308 279 274 272 312 262 260 265 268 284 263 261 238 262 284 263 270 281 284 255 291 271 274 306 279 280 294 271 314 272 293 301 257 293 280 248 271 270 267 263 265 267 298 297 288 284 288 295 274 246 262 283 271 248 316 242 255 309 286 272 300 297 274 272 263 263 280 286 278 277 275 235 261 279 268 288 271 291 227 265 288 298 289 282 289 274 275 269 255 298 277 246 271 258 291 269 242 273 291 281 278 242 279 290 288 297 276 268 301 305 285 264 264 288 288 259 284 294 293 288 264 273 293 225 281 305 268 300 282 269 285 269 285 259 272 270 268 271 264 262 309 310 268 283 281 301 284 294 261 281 287 276 303 295 270 287 288 293 267 290 282 234 261 258 261 264 269 282 282 291 298 281 288 264 288 257 273 290 267 263 264 260 297 300 235 295 301 263 328 280 320 281 256 301 279 284 298 272 264 269 258 265 271 279 266 292 283 301 311 284 258 278 286 262 321 262 258 284 272 293 289 235 278 277 245 291 265 271 289 267 272 255 283 275 284 290 271 296 276 276 306 287 267 283 279 277 299 314 267 298 328 281 293 293 312 298 262 306 262 299 285 267 300 278 296 291 303 269 299 277 291 298 296 290 273 277 295 314 265 276 287 280 294 262 304 294 282 278 307 292 320 313 292 259 286 309 281 294 259 303 288 307 308 289 303 284 321 316 322 297 268 295 288 280 310 286 321 300 334 307 291 285 303 271 268 274 267 282 321 292 302 293 314 305 318 306 286 305 278 295 300 301 317 296 307 264 262 310 308 270 287 275 257 324 295 306 319 287 277 282 310 333 304 327 317 315 297 287 308 328 322 306 311 298 317 283 307 285 325 302 276 296 280 289 289 289 280 289 307 301 326 259 323 306 301 269 295 277 296 320 306 290 269 281 353 292 318 281 294 280 279 282 288 333 294 298 320 294 274 295 294 301 329 303 277 288 286 278 262 304 301 309 288 271 281 289 297 291 285 275 278 250 288 286 270 291 319 294 290 286 317 286 317 315 281 288 267 291 296 303 291 290 276 300 293 279 277 278 306 300 299 275 295 261 293 263 270 293 309 301 309 256 288 237 267 265 280 291 246 283 291 291 290 269 283 273 315 275 287 270 296 266 297 285 291 284 272 238 290 303 307 289 297 300 299 264 265 284 283 276 317 283 280 273 283 287 283 271 267 296 287 299 276 288 310 292 297 289 290 289 289 298 284 284 301 277 321 300 278 268 275 298 298 281 299 285 283 298 291 261 315 281 279 285 310 257 287 279 289 295 245 281 267 286 306 300 291 290 285 277 289 243 298 289 269 294 287 274 289 280 291 295 287 282 318 288 281 297 290 283 300 288 274 293 281 299 316 281 284 262 286 292 286 285 315 265 289 290 265 280 322 280 312 315 286 272 273 287 282 289 296 281 284 288 281 292 288 324 273 303 259 259 270 273 269 335 291 281 292 308 279 280 285 295 313 273 310 283 314 303 285 261 282 310 289 269 288 279 265 289 264 291 277 277 305 276 291 301 272 271 296 314 289 274 303 301 263 298 284 269 308 301 278 302 299 300 268 267 299 240 286 280 285 305 248 284 273 291 271 311 288 278 285 285 292 275 281 282 293 277 276 248 303 268 299 294 291 280 278 269 299 272 276 310 297 264 276 271 302 262 259 259 290 298 304 311 283 284 295 311 286 284 274 276 296 293 270 273 311 267 277 281 281 288 297 239 308 276 279 286 282 284 271 282 283 283 274 323 264 248 275 292 287 278 268 303 271 295 315 294 259 291 292 299 259 250 265 248 264 274 272 276 257 288 287 265 281 270 312 294 300 296 294 246 297 320 266 273 296 302 295 301 283 283 263 264 273 299 285 298 257 281 278 246 277 301 262 316 287 243 293 282 299 315 267 273 275 287 289 280 289 314 293 263 272 307 290 278 296 293 278 258 299 282 284 265 283 286 283 289 258 275 278 285 249 293 304 276 292 289 244 286 295 279 281 229 312 264 273 266 294 280 298 287 262 267 304 304 278 296 315 268 291 292 306 291 266 264 294 300 284 241 310 267 295 274 311 261 332 289 300 288 282 291 276 273 303 304 285 248 283 270 277 291 315 317 276 283 294 262 249 261 274 264 305 262 272 311 279 263 262 273 295 290 281 279 242 275 262 287 286 289 287 271 257 287 314 264 278 292 297 299 285 243 270 272 300 291 284 286 293 272 308 275 293 295 284 274 294 282 288 304 284 287 296 275 263 289 288 268 319 281 289 280 258 309 297 316 269 296 290 309 291 268 274 315 300 277 295 296 264 288 271 276 275 315 280 291 288 278 284 290 300 250 292 286 259 297 263 285 317 288 276 258 238 282 312 291 272 255 315 257 294 293 278 303 309 275 270 288 275 257 284 276 301 287 282 307 290 269 300 294 282 256 310 310 261 301 276 293 271 300 305 263 273 313 281 273 286 293 258 273 266 288 280 292 295 289 293 294 272 288 272 298 287 255 300 249 289 277 301 318 248 304 266 294 275 287 266 288 282 289 313 281 276 290 329 307 302 301 288 307 271 301 308 285 291 274 278 298 237 284 306 255 277 324 279 283 266 274 288 290 284 268 264 273 278 289 293 325 290 306 303 297 318 277 288 292 337 292 273 304 304 276 281 308 266 275 281 281 294 293 284 267 293 271 311 286 270 284 312 302 280 293 290 295 285 288 282 296 273 299 306 275 279 270 288 273 280 277 299 289 290 261 301 285 298 287 287 342 277 286 282 297 300 274 291 267 293 280 334 295 286 271 297 266 287 275 240 298 306 292 285 299 267 289 259 276 301 286 313 296 269 286 289 279 302 289 271 271 297 289 283 275 275 297 293 260 295 319 316 276 307 273 323 272 302 269 278 292 288 308 249 264 303 298 301 270 291 285 273 286 292 296 288 295 271 282 288 280 291 242 264 280 282 266 288 309 312 283 278 290 307 273 301 265 266 271 285 304 269 275 263 289 291 260 303 306 278 315 274 255 296 279 291 306 304 306 262 301 289 283 279 301 288 295 273 271 291 282 301 279 287 291 299 273 270 306 295 285 302 307 299 272 262 275 292 266 296 265 266 279 306 275 318 276 285 272 335 260 324 290 266 266 309 273 283 311 296 290 296 309 290 279 307 320 322 303 277 283 290 279 284 297 312 300 297 273 307 288 287 289 291 312 317 285 269 277 263 272 273 318 308 291 302 278 257 290 295 281 250 272 332 318 308 307 298 271 258 288 249 272 271 314 310 309 279 293 299 299 280 286 287 285 311 319 286 265 286 308 301 272 300 293 256 306 292 310 293 280 304 271 317 304 323 290 295 262 295 282 307 261 263 310 280 275 276 283 278 293 270 315 279 274 288 316 306 243 304 300 306 293 282 309 275 275 289 285 305 246 292 264 315 301 272 275 280 288 287 318 288 258 267 284 319 273 274 315 283 261 289 319 315 311 317 289 277 284 306 262 299 261 275 258 287 293 313 303 310 289 269 284 288 296 274 296 256 300 295 311 325 287 317 283 295 301 278 304 282 278 313 296 304 289 312 286 271 298 247 290 299 235 277 282 301 306 274 298 290 323 292 313 269 298 309 248 281 305 270 302 295 270 286 283 296 278 269 282 267 302 285 297 290 266 302 284 281 279 259 288 286 272 308 316 294 290 276 286 303 282 301 281 308 294 265 281 276 286 281 280 259 299 296 269 289 326 247 262 279 266 275 283 306 274 311 265 248 267 277 282 285 293 269 281 290 281 311 284 268 275 278 270 280 277 281 310 298 311 277 334 313 266 302 270 282 282 280 312 290 306 271 270 291 261 311 283 293 319 311 267 298 275 285 284 275 285 287 287 302 293 298 300 286 280 303 290 283 293 319 307 295 301 279 315 270 275 293 282 293 292 257 287 288 296 289 320 293</counts>
			</dataPoints>
		</scan>
	</xrdMeasurement>
</xrdMeasurements>