File: data/XRD/XG-Vakuum/XG-600/W6823-1C_XG_Vakuum_600.xrdml
<xrdMeasurements xmlns="http://www.xrdml.com/XRDMeasurement/2.1" xmlns:xsi="http://www.w3.org/2001/XMLSchema-instance" xsi:schemaLocation="http://www.xrdml.com/XRDMeasurement/2.1 http://www.xrdml.com/XRDMeasurement/2.1/XRDMeasurement.xsd" status="Completed">
	<comment>
		<entry>Configuration=Factory configuration, Owner=User-1, Creation date=7/8/2013 4:01:53 PM</entry>
		<entry>Goniometer=PW3050/65 (Theta/2Theta); Minimum step size 2Theta:0.0001; Minimum step size Omega:0.0001</entry>
		<entry>Sample stage=MRD Cradle; Minimum step size Phi:0.01; Minimum step size Chi:0.01; Minimum step size X:0.01; Minimum step size Y:0.01; Minimum step size Z:0.001</entry>
		<entry>Diffractometer system=XPERT-PRO</entry>
		<entry>Measurement program=C:\PANalytical\Data Collector\Programs\Jorrit\2thom\_absolute_2th-om_10-130deg_PIXscan_56min.xrdmp, Identifier={15BCCF57-2807-42BD-B5B9-ECC0B3DC9284}</entry>
		<entry>Batch program=C:\PANalytical\Data Collector\Programs\SimonL\batch4x_2thom_10-130°_z9.1_x0,10,20,30_y0_57min.xrdmp, Identifier={EED9823A-2BEB-424C-9252-345C4EF2834A}</entry>
	</comment>
	<sample type="To be analyzed">
		<id></id>
		<name></name>
		<preparedBy></preparedBy>
	</sample>
	<xrdMeasurement measurementType="Scan" status="Completed" sampleMode="Reflection">
		<comment>
			<entry>_absolute_2th-om_10-130deg_PIXscan_56min</entry>
			<entry>PHD Lower Level = 4.83 (keV), PHD Upper Level = 11.27 (keV)</entry>
		</comment>
		<usedWavelength intended="K-Alpha 1">
			<kAlpha1 unit="Angstrom">1.5405980</kAlpha1>
			<kAlpha2 unit="Angstrom">1.5444260</kAlpha2>
			<kBeta unit="Angstrom">1.3922500</kBeta>
			<ratioKAlpha2KAlpha1>0.5000</ratioKAlpha2KAlpha1>
		</usedWavelength>
		<incidentBeamPath>
			<radius unit="mm">320.00</radius>
			<xRayTube id="1010048" name="Empyrean Cu LFF HR (9430 033 7310x) DK442154">
				<tension unit="kV">40.0</tension>
				<current unit="mA">40.0</current>
				<anodeMaterial>Cu</anodeMaterial>
				<focus type="Line">
					<length unit="mm">12.0</length>
					<width unit="mm">0.4</width>
					<takeOffAngle unit="deg">4.2</takeOffAngle>
				</focus>
			</xRayTube>
			<xRayMirror id="27010001" name="Inc. Beam Cu W/Si (parabolic MRD)" hybrid="false">
				<crystal type="Graded" shape="Parabolic">W/Si</crystal>
				<acceptanceAngle unit="deg">0.800</acceptanceAngle>
				<length unit="mm">60.0</length>
			</xRayMirror>
			<sollerSlit id="21010002" name="Soller slits 0.04 rad.">
				<opening unit="rad">0.0400</opening>
			</sollerSlit>
			<mask id="22030008" name="Fixed mask 4 mm">
				<distanceToSample unit="mm">220.00</distanceToSample>
				<width unit="mm">4.00</width>
			</mask>
			<divergenceSlit id="22010007" name="Fixed slit 1/8°" xsi:type="fixedDivergenceSlitType">
				<distanceToSample unit="mm">220.00</distanceToSample>
				<height unit="mm">0.19</height>
			</divergenceSlit>
		</incidentBeamPath>
		<diffractedBeamPath>
			<radius unit="mm">320.00</radius>
			<sollerSlit id="21010002" name="Soller slits 0.04 rad.">
				<opening unit="rad">0.0400</opening>
			</sollerSlit>
			<receivingSlit id="22010001" name="Fixed slit 4°">
				<height unit="mm">5.88</height>
			</receivingSlit>
			<detector id="7010017" name="PIXcel3D 1x1 detector" xsi:type="areaDetectorType">
				<phd unit="%">
					<lowerLevel>30.0</lowerLevel>
					<upperLevel>70.0</upperLevel>
				</phd>
				<mode>Scanning</mode>
				<activeChannelsEquatorial>255</activeChannelsEquatorial>
				<activeChannelsAxial>255</activeChannelsAxial>
				<pitchEquatorial unit="mm">0.05500</pitchEquatorial>
				<pitchAxial unit="mm">0.05500</pitchAxial>
				<readOutPeriod unit="seconds">0.135</readOutPeriod>
			</detector>
		</diffractedBeamPath>
		<scan appendNumber="0" mode="Continuous" scanAxis="2Theta-Omega" status="Completed">
			<header>
				<startTimeStamp>2024-10-08T21:44:26+02:00</startTimeStamp>
				<endTimeStamp>2024-10-08T22:40:32+02:00</endTimeStamp>
				<author>
					<name>PRO-MRD</name>
				</author>
				<source>
					<applicationSoftware version="6.1b">Data Collector</applicationSoftware>
					<instrumentControlSoftware version="7.0E 20130304">XPERT-PRO</instrumentControlSoftware>
					<instrumentID>0000000011142674</instrumentID>
				</source>
			</header>
			<dataPoints>
				<positions axis="2Theta" unit="deg">
					<startPosition>9.99826193</startPosition>
					<endPosition>129.99755682</endPosition>
				</positions>
				<positions axis="Omega" unit="deg">
					<startPosition>4.99913096</startPosition>
					<endPosition>64.99877841</endPosition>
				</positions>
				<positions axis="Phi" unit="deg">
					<commonPosition>0.00</commonPosition>
				</positions>
				<positions axis="Chi" unit="deg">
					<commonPosition>0.00</commonPosition>
				</positions>
				<positions axis="X" unit="mm">
					<commonPosition>20.00</commonPosition>
				</positions>
				<positions axis="Y" unit="mm">
					<commonPosition>0.00</commonPosition>
				</positions>
				<positions axis="Z" unit="mm">
					<commonPosition>9.100</commonPosition>
				</positions>
				<commonCountingTime unit="seconds">32.895</commonCountingTime>
				<counts 385 385 385 407 370 392 385 369 386 383 394 394 389 369 397 348 372 395 381 388 355 392 390 407 422 391 353 387 396 352 342 363 394 366 384 319 370 398 375 390 389 401 375 344 398 382 405 402 394 390 338 382 403 402 396 377 373 388 390 401 400 380 362 350 397 367 396 397 343 349 394 379 391 400 379 392 376 392 347 351 361 386 412 361 340 365 417 373 406 420 354 369 358 348 374 372 380 389 337 383 350 358 368 372 348 365 348 362 360 358 332 406 346 351 356 355 360 349 377 363 343 402 367 348 344 338 375 373 374 339 376 354 366 350 325 342 376 326 344 353 361 333 344 381 352 357 363 345 346 342 334 342 362 355 361 327 328 355 339 347 326 329 342 350 378 332 347 385 344 379 354 337 362 353 340 339 356 383 365 328 332 340 336 378 376 344 337 359 350 345 342 339 343 337 330 359 351 377 314 343 331 365 351 321 346 344 361 326 334 361 350 339 358 324 309 309 373 355 318 331 317 334 342 342 336 335 369 306 338 348 320 346 355 320 328 348 348 342 327 333 352 322 324 389 344 312 348 318 334 342 347 339 320 353 313 335 348 348 335 311 334 306 354 347 327 323 336 329 321 336 352 357 363 331 347 336 314 355 324 333 377 346 348 316 306 320 346 345 315 328 353 327 329 364 340 342 346 309 332 341 328 361 317 324 296 327 344 330 306 326 299 342 315 334 300 329 340 331 357 316 344 341 320 337 309 310 306 320 341 338 332 338 316 281 294 312 314 336 321 321 328 344 305 307 317 330 342 333 341 334 330 334 303 312 290 352 304 319 301 339 307 310 321 311 348 336 287 281 336 287 285 316 310 354 288 327 313 309 289 327 309 325 306 329 293 299 312 314 297 327 312 301 296 281 313 332 324 300 314 333 307 297 333 280 310 309 275 314 296 331 330 347 362 301 326 310 316 305 299 286 314 326 307 277 299 304 312 285 299 319 313 306 309 283 264 297 336 299 288 291 301 311 296 304 318 306 318 312 320 313 303 284 316 341 295 277 292 283 319 321 301 318 290 323 311 295 322 291 325 307 274 292 259 316 286 286 271 308 278 300 289 290 315 318 299 312 326 313 297 333 314 275 271 317 305 301 302 300 292 286 286 299 302 299 272 301 285 276 280 314 295 264 282 309 305 332 312 279 302 291 315 283 306 289 320 296 293 285 301 281 312 307 293 321 285 275 281 289 269 286 278 289 266 285 318 269 291 319 268 271 288 274 301 272 286 291 307 292 303 296 248 292 305 277 304 303 286 281 271 314 281 300 288 284 276 289 323 281 285 300 294 285 272 297 297 297 272 301 266 280 283 240 270 311 293 290 272 297 300 277 303 281 280 271 303 290 300 267 307 290 279 274 279 276 281 282 256 320 283 265 268 316 288 249 277 264 285 307 283 305 316 312 276 329 250 273 294 300 320 266 283 299 273 288 293 310 237 290 288 293 290 285 278 265 291 286 266 272 295 304 302 304 245 279 288 308 297 276 297 318 259 241 317 297 291 281 274 313 292 282 258 294 308 308 283 289 293 290 303 276 301 265 265 299 326 275 300 282 310 268 305 297 300 313 265 306 272 278 246 277 277 274 266 294 273 279 278 276 261 296 269 284 288 276 297 273 288 299 276 282 305 297 285 300 280 300 272 242 298 273 308 273 292 288 295 273 291 279 308 292 287 286 310 311 288 285 266 267 283 264 302 287 307 264 292 311 248 292 287 295 290 272 262 294 271 309 291 286 302 316 286 280 273 311 264 273 320 281 299 300 260 289 298 297 294 269 285 279 283 307 283 280 272 275 282 282 295 275 297 290 307 308 289 294 285 279 269 265 304 294 291 284 301 270 290 317 288 277 323 293 307 286 293 292 298 305 325 304 273 282 268 284 281 316 299 285 289 292 319 289 316 314 281 286 307 307 322 303 312 280 303 290 240 288 277 265 309 283 287 291 301 264 295 306 294 290 282 278 287 305 301 295 276 305 286 294 327 279 298 296 301 285 301 334 319 285 304 283 241 320 305 302 275 282 302 283 303 306 316 304 296 293 272 296 290 284 269 288 298 301 291 305 280 301 295 323 283 332 336 289 311 280 296 325 294 298 300 301 315 290 337 324 301 291 351 293 310 295 325 306 274 310 330 298 300 294 314 271 293 299 309 314 290 288 296 292 264 301 308 313 317 290 282 299 305 284 290 287 295 286 339 312 288 278 296 301 319 303 288 316 271 289 306 338 321 288 303 285 313 300 306 307 308 273 288 310 314 298 317 306 308 320 308 304 317 296 312 314 294 300 310 293 310 291 304 328 309 306 301 295 328 310 302 293 313 300 291 301 303 310 329 297 314 316 318 323 319 311 326 297 308 358 321 293 322 323 313 300 334 292 351 333 304 325 275 308 311 327 351 330 317 320 306 321 310 324 300 299 317 316 309 316 349 294 339 301 282 296 317 308 323 286 306 319 316 326 318 293 320 304 306 306 332 322 315 312 311 324 310 272 305 334 301 328 317 321 314 308 320 326 324 312 335 297 334 327 327 300 315 317 327 328 350 298 321 293 309 337 343 293 352 296 316 306 350 309 331 306 293 269 296 299 317 324 336 346 298 296 343 296 273 306 328 299 315 314 322 294 295 294 317 302 332 325 320 314 314 312 310 324 319 362 296 325 304 335 333 339 318 316 344 354 312 333 340 293 293 326 316 286 331 325 320 310 333 332 327 292 307 289 320 313 317 292 329 322 331 344 342 333 310 392 338 308 334 301 351 308 300 337 341 331 345 316 324 279 285 320 289 345 333 298 346 335 314 321 338 321 328 336 330 322 335 310 305 327 330 302 329 331 305 309 288 303 293 331 354 317 322 337 306 360 304 292 295 321 306 339 316 334 313 334 323 318 352 319 302 329 331 317 340 305 355 314 305 332 308 287 305 325 355 308 336 315 316 344 333 290 300 309 329 288 298 322 312 333 310 328 315 342 356 316 318 291 291 296 347 309 317 326 300 297 345 297 299 318 295 311 307 307 320 323 318 323 307 339 325 336 301 311 307 342 310 292 343 325 303 308 313 305 324 282 291 330 304 335 305 313 312 290 328 307 285 320 321 324 330 305 297 331 291 318 330 321 295 284 316 338 298 288 324 316 319 321 354 282 344 341 335 343 310 318 347 323 310 317 290 319 318 282 288 291 307 328 277 270 326 327 341 290 327 335 295 342 298 304 302 333 313 296 330 337 303 282 307 309 288 287 294 337 278 309 323 258 321 273 322 330 345 312 304 320 316 305 276 297 320 324 278 294 279 305 303 279 292 300 297 282 303 305 311 303 309 313 271 278 324 321 312 317 290 315 288 276 294 292 262 317 302 302 321 303 286 295 321 302 298 298 298 311 328 286 274 294 344 276 312 295 284 297 268 289 317 308 289 312 277 326 283 336 233 313 299 288 304 310 287 307 302 329 291 316 310 248 305 288 274 298 282 302 309 313 313 306 302 320 272 288 280 310 279 287 272 296 308 245 315 298 322 296 290 269 270 285 287 280 274 263 307 295 307 272 285 316 306 283 278 297 275 273 281 287 269 280 268 267 274 270 308 308 264 291 305 288 287 294 272 279 264 294 274 319 268 292 284 269 324 326 285 295 284 275 281 300 316 311 275 292 281 268 312 273 274 317 232 297 287 308 306 300 306 285 297 302 289 306 265 272 248 303 280 255 235 243 280 274 287 269 282 293 290 288 263 282 284 241 285 315 271 273 265 277 266 247 274 301 265 298 317 246 288 281 296 274 274 308 293 270 268 247 292 256 279 265 284 295 281 273 263 267 277 260 292 287 258 274 285 236 261 275 285 295 257 292 279 275 278 270 287 242 290 275 247 268 267 258 266 290 277 264 265 296 266 244 271 280 270 286 276 280 278 263 275 240 247 301 282 261 262 280 279 265 290 249 245 258 262 278 260 264 262 257 258 265 271 238 268 282 244 268 277 277 290 294 274 256 260 271 278 259 258 274 246 301 244 260 273 242 235 297 264 238 245 266 246 270 275 261 271 283 266 247 264 275 267 248 266 261 306 243 263 270 286 249 268 278 262 238 275 256 277 248 272 279 281 304 245 290 257 244 301 257 243 267 264 283 259 240 272 241 256 264 257 229 245 281 233 283 237 286 231 244 259 277 224 235 257 249 242 244 258 247 281 243 276 245 262 277 259 259 263 231 304 268 229 257 227 260 259 265 262 245 265 284 243 274 236 244 238 243 221 225 255 266 256 246 267 250 249 247 260 282 256 289 257 244 245 232 225 243 250 246 265 221 221 245 232 245 256 263 255 243 225 244 232 272 257 246 261 247 249 235 224 218 236 245 276 223 263 222 273 234 259 246 237 280 248 243 238 261 230 249 229 249 233 236 264 231 232 263 210 206 270 246 234 237 239 230 219 257 208 264 247 214 243 280 248 236 258 258 267 233 243 231 261 241 231 256 235 222 239 257 234 239 237 222 231 247 239 243 215 198 206 245 237 234 226 240 230 244 257 267 240 231 256 230 236 235 242 241 250 260 233 227 233 220 234 242 230 250 219 216 264 219 220 234 242 237 203 233 232 273 226 225 239 230 229 240 229 237 195 248 233 229 222 216 269 217 221 242 257 258 225 236 239 246 221 240 222 208 227 261 230 240 235 216 226 212 233 265 227 242 226 220 227 213 234 231 224 250 239 235 226 231 218 225 244 258 219 217 243 225 224 236 215 238 256 241 227 261 237 203 227 221 220 231 229 219 232 246 224 228 256 215 235 228 205 214 197 222 210 232 244 211 234 210 235 224 227 233 214 204 217 239 200 236 250 212 234 232 209 222 197 201 224 202 207 234 238 209 203 224 209 196 235 219 210 225 223 227 187 228 244 267 228 244 213 219 225 224 241 233 235 222 222 205 216 233 218 235 203 231 201 191 232 219 208 233 221 221 233 245 242 224 214 238 219 211 212 227 217 216 229 232 229 226 202 265 247 214 237 224 217 216 203 211 211 236 208 209 232 222 200 218 240 249 237 189 219 257 222 212 203 222 234 229 220 242 266 213 214 236 230 220 195 241 221 224 215 259 198 229 217 229 223 223 205 248 218 228 180 198 219 212 201 234 210 224 229 189 211 217 186 216 232 225 259 221 224 218 228 222 224 223 217 208 233 245 196 202 231 220 207 220 209 237 206 228 194 245 173 270 231 188 201 207 221 235 237 211 218 200 218 221 240 213 213 219 228 205 228 220 231 221 221 229 240 233 198 238 212 207 220 239 203 221 230 205 225 214 225 233 206 222 208 208 215 211 212 221 235 208 202 219 225 189 223 222 223 212 244 202 203 214 230 234 218 234 221 226 223 241 245 232 237 232 193 245 237 206 211 216 229 227 264 209 209 216 207 237 227 210 231 207 216 233 204 218 217 222 221 215 221 200 208 235 199 219 199 216 188 184 247 204 234 217 196 211 234 201 222 213 209 206 200 200 212 246 211 208 224 236 180 203 231 192 222 187 216 214 226 207 209 206 232 221 207 228 238 230 219 206 223 224 208 208 227 199 196 185 224 209 239 233 238 194 171 209 231 203 212 209 220 220 203 230 223 217 201 225 198 239 232 212 210 222 208 229 218 219 232 203 220 201 225 204 221 196 225 212 222 190 223 225 245 238 203 202 210 202 205 258 227 210 226 232 213 235 225 217 225 224 229 196 193 212 249 234 232 215 226 208 199 215 189 192 193 219 234 197 222 208 211 202 242 247 237 222 224 219 215 222 222 198 229 230 203 198 224 220 202 214 233 212 200 201 221 200 205 222 207 205 214 228 201 212 218 196 220 204 235 209 198 223 201 208 209 232 207 223 230 213 204 188 216 195 193 221 216 205 219 190 218 185 192 199 199 207 230 230 215 229 213 196 232 231 204 209 213 203 212 219 184 212 221 196 230 208 208 210 208 218 230 193 199 236 215 202 219 208 214 207 214 201 201 219 195 214 240 188 227 203 206 194 222 210 232 207 201 193 213 203 224 214 211 216 237 230 197 215 207 226 215 207 229 198 210 243 211 218 207 203 200 228 256 206 223 207 224 224 203 212 210 248 205 213 213 197 202 220 218 213 212 226 235 225 206 230 233 192 203 198 216 223 209 201 234 184 193 195 213 201 189 202 211 219 222 194 206 224 208 176 189 212 208 187 209 199 233 197 225 225 194 215 201 223 237 223 197 208 223 214 217 200 218 221 204 223 208 217 220 203 205 232 260 194 217 191 186 223 221 202 210 211 226 222 219 200 232 225 194 219 206 197 227 188 214 206 211 203 191 208 239 197 212 214 221 196 213 203 202 204 221 197 213 209 210 206 213 201 226 204 206 193 192 212 202 233 204 207 218 199 203 211 212 210 215 219 201 222 216 224 238 206 198 218 197 190 205 250 218 195 219 200 191 179 218 209 223 229 211 213 229 199 204 212 223 202 211 197 206 237 204 185 196 198 222 190 213 187 201 200 222 209 204 204 196 215 206 214 208 183 225 192 213 222 198 201 171 205 211 224 219 206 206 217 207 190 212 196 217 193 205 207 224 199 205 216 196 215 191 190 201 200 212 217 191 201 217 202 208 183 201 226 186 197 219 202 198 214 221 188 208 210 211 215 233 233 206 205 192 194 179 212 204 184 193 201 211 228 205 193 234 206 191 195 220 206 195 208 203 212 204 212 206 190 206 236 226 217 228 173 192 242 210 217 209 200 231 210 199 210 203 226 206 237 194 192 173 215 195 200 203 190 210 188 204 204 212 209 187 210 184 223 207 188 203 195 231 200 211 204 195 197 230 249 197 218 231 214 208 204 206 208 226 190 223 240 221 226 223 224 221 179 219 228 193 219 210 221 232 246 208 198 214 195 239 189 229 209 228 197 205 201 212 222 239 230 199 218 203 234 217 216 219 175 199 201 177 190 222 187 209 203 210 211 199 200 217 188 187 206 195 203 199 208 206 205 214 202 205 198 213 225 223 177 219 217 203 191 208 220 213 222 231 228 239 195 206 216 196 219 187 222 223 218 212 223 182 205 218 231 228 240 211 192 218 241 205 219 214 222 202 208 221 188 233 172 192 205 202 209 207 207 239 225 226 215 208 223 190 211 200 202 249 195 197 180 214 207 218 211 204 243 204 199 208 202 204 205 210 236 201 210 193 216 214 214 185 235 214 222 225 209 205 198 214 205 215 197 201 207 212 236 203 220 207 197 225 210 223 222 242 217 201 225 240 197 227 242 231 206 187 222 222 205 220 205 223 184 225 208 200 209 200 215 226 225 203 195 222 224 234 189 184 211 211 209 219 214 217 201 213 228 200 237 210 224 203 214 199 204 209 219 222 236 194 236 216 228 213 207 223 220 215 176 180 211 225 235 217 192 215 194 234 206 236 198 231 220 219 235 204 196 196 230 226 220 203 193 204 226 207 210 206 210 210 203 237 214 222 223 239 207 224 221 196 202 204 257 236 205 214 216 221 201 195 195 205 205 204 238 219 215 201 197 198 213 239 231 212 216 194 206 210 204 218 213 191 218 219 205 227 221 181 223 206 238 235 237 216 226 208 209 184 215 208 227 230 255 209 218 238 220 221 223 212 205 223 205 244 223 206 241 214 201 207 205 239 215 224 215 262 203 231 204 245 244 236 241 223 231 209 223 186 227 225 224 205 202 237 232 234 234 248 219 227 243 237 269 227 217 230 214 237 260 246 239 245 239 241 247 229 206 228 245 236 243 270 255 265 232 260 264 239 247 232 248 282 278 229 239 243 259 270 264 269 246 267 280 281 267 267 285 264 274 257 310 299 286 287 313 320 297 315 314 310 293 328 290 340 344 335 359 360 333 368 364 378 402 370 384 362 389 367 393 412 433 413 387 411 365 368 378 364 378 348 326 373 371 330 342 322 315 308 293 303 309 298 274 289 311 270 271 294 280 289 237 256 244 284 271 227 287 236 285 248 286 257 229 224 212 224 241 217 265 239 255 236 225 263 237 206 225 262 224 247 214 262 270 235 264 268 260 239 220 259 226 191 259 222 218 227 205 219 240 265 217 227 243 210 198 230 205 215 204 234 225 266 256 228 221 223 215 241 235 229 218 218 240 215 217 242 241 212 204 242 199 209 236 233 218 212 216 226 234 211 208 224 218 232 228 240 222 219 223 208 239 235 229 226 224 197 225 194 212 215 202 229 211 209 214 246 229 240 204 234 235 222 210 217 237 200 231 203 187 190 218 221 240 224 202 239 237 219 231 218 222 237 211 207 226 221 235 224 210 242 222 215 225 212 209 245 228 231 242 203 242 217 183 238 214 233 229 189 230 201 238 230 215 232 218 228 233 202 213 242 232 209 211 235 205 226 236 229 227 250 230 202 221 194 212 209 220 226 222 234 220 236 222 206 230 225 218 234 217 200 207 216 201 244 229 225 245 260 195 225 204 230 186 212 218 235 234 190 232 238 220 255 213 203 224 204 206 228 214 222 247 238 197 214 233 215 228 227 224 228 228 218 221 214 211 221 242 243 234 243 226 246 209 235 210 228 208 233 214 241 224 224 261 228 223 234 210 213 210 224 236 234 239 260 213 234 221 224 223 233 229 224 200 185 216 236 239 221 211 226 244 234 203 211 205 243 209 242 215 221 200 193 227 255 199 226 190 235 226 228 216 232 230 215 240 230 217 219 246 228 220 198 231 222 240 218 225 246 233 231 224 209 221 206 250 198 192 215 239 212 226 236 203 214 240 205 233 218 257 225 220 226 248 229 208 228 228 234 207 198 222 197 220 222 223 208 221 224 227 189 219 220 225 210 242 199 227 207 247 220 222 228 260 224 218 239 257 210 249 228 202 230 203 206 217 229 234 219 263 230 238 215 221 260 205 217 203 239 211 240 216 200 198 241 234 239 231 219 222 217 209 258 237 216 224 218 225 224 216 258 233 217 230 230 218 217 176 240 228 259 250 197 227 247 259 262 223 211 198 228 222 235 205 232 213 213 208 210 239 226 213 217 219 241 224 212 237 226 217 238 221 229 204 205 206 221 233 211 228 272 246 228 211 235 213 219 205 191 213 227 209 257 228 207 219 211 246 239 224 233 234 223 220 216 221 205 213 228 229 220 214 226 222 233 206 230 260 215 219 241 195 224 203 225 232 224 231 201 228 232 235 233 209 199 227 218 236 222 216 225 241 235 218 216 235 234 203 215 243 219 230 242 205 220 240 245 232 207 230 227 233 231 226 219 234 228 220 239 234 215 229 215 242 205 239 237 233 225 205 216 214 198 223 196 237 215 197 221 215 257 209 205 206 217 197 201 201 209 223 226 224 243 224 217 236 233 221 239 208 262 207 244 230 239 223 220 225 238 222 229 241 226 221 210 217 202 207 227 226 237 209 215 231 223 233 202 207 232 216 207 218 209 223 248 215 230 247 230 222 182 237 226 222 278 205 215 230 233 217 218 234 215 203 227 220 240 216 271 213 230 224 227 191 196 279 229 249 222 220 206 259 244 218 218 221 242 237 210 215 223 237 224 242 222 227 225 225 229 209 226 255 259 209 225 222 214 234 216 232 229 227 214 231 215 242 226 224 206 255 211 236 229 240 225 236 244 221 233 220 220 224 226 220 242 227 242 246 237 228 228 243 237 227 233 222 236 224 221 231 231 217 246 222 190 237 227 221 237 244 206 230 223 210 235 232 213 247 208 241 234 249 226 241 234 244 195 242 238 267 224 264 250 210 211 237 199 247 225 216 237 231 271 204 215 261 259 225 196 249 229 255 221 223 229 238 189 237 221 223 264 219 216 238 191 241 238 226 226 203 213 223 230 238 246 258 218 219 241 211 224 230 223 210 225 200 216 211 235 247 227 256 221 219 203 233 259 217 236 201 224 240 228 264 224 218 244 204 197 204 234 209 237 215 233 263 223 257 220 232 231 238 217 202 248 206 227 216 214 256 227 244 211 231 218 267 223 227 226 248 232 227 209 188 284 234 221 232 217 220 207 231 245 206 230 231 232 241 237 242 230 248 233 230 237 227 232 229 235 229 236 224 249 233 256 259 228 237 244 259 238 199 228 243 226 227 230 234 242 221 210 244 244 203 235 232 218 225 259 229 213 226 260 237 220 220 208 218 255 235 235 222 257 245 221 235 237 217 220 225 222 235 221 225 246 255 219 224 212 203 213 271 225 215 227 234 214 231 236 222 225 230 229 256 248 220 243 222 235 230 249 223 256 224 209 239 210 255 212 238 214 237 204 222 264 226 239 224 219 219 215 255 228 218 217 212 214 229 220 242 244 216 244 240 243 238 262 220 204 246 221 259 241 223 239 256 212 227 220 217 229 212 237 246 218 228 209 220 224 267 221 228 207 258 218 232 224 219 232 233 221 229 215 212 247 249 245 232 245 238 218 247 239 263 239 223 244 214 225 237 203 211 245 238 230 234 222 240 219 214 215 209 258 228 247 209 208 244 263 227 229 209 229 263 219 231 224 217 236 249 234 226 248 259 240 211 206 222 222 221 245 248 220 221 220 223 224 233 237 230 219 228 231 245 213 233 230 203 230 232 258 218 192 218 231 218 242 235 231 210 242 255 231 214 237 206 206 239 208 216 204 246 200 216 217 220 205 230 273 247 208 230 213 255 234 241 228 212 223 245 234 210 250 246 264 218 216 235 218 236 221 211 220 228 195 218 245 198 207 233 227 216 257 239 229 224 241 226 213 197 215 243 264 240 231 267 231 219 223 241 197 229 235 231 247 239 218 226 198 258 229 256 244 219 223 233 255 244 240 221 213 244 233 220 217 218 225 246 211 224 230 234 235 247 207 237 234 228 213 222 239 219 249 239 225 238 213 223 224 247 219 234 268 222 255 256 246 225 212 231 216 228 221 235 232 214 246 237 219 262 219 220 218 223 213 226 234 241 228 240 205 226 229 255 228 243 229 221 228 241 247 234 237 234 232 208 236 258 213 218 213 240 238 222 225 250 226 215 229 239 239 235 218 227 227 229 219 231 216 241 226 227 228 221 226 221 234 198 228 229 229 222 224 240 230 229 207 256 233 225 230 212 220 236 215 226 209 234 217 204 221 218 225 209 238 225 261 200 229 243 244 225 217 211 233 204 183 224 227 233 237 218 240 227 241 238 242 218 235 218 242 245 267 255 234 233 223 238 250 220 228 209 232 233 229 232 220 226 233 206 201 265 243 239 237 245 236 230 233 220 221 230 232 222 214 219 225 213 214 208 226 239 179 239 256 268 265 241 237 260 224 229 248 261 258 221 220 233 228 245 259 230 248 239 216 226 240 203 235 237 232 239 223 230 261 228 211 219 238 229 246 232 240 226 242 256 233 221 234 242 215 243 233 222 232 206 236 259 211 214 235 232 261 236 232 226 237 258 256 246 213 197 236 263 220 219 214 222 211 234 241 230 197 233 236 229 214 203 229 240 249 228 216 237 237 232 239 224 232 250 237 224 247 258 255 234 234 204 216 230 216 236 247 225 220 219 239 259 248 244 217 217 229 238 242 267 255 260 250 228 237 257 269 218 228 230 256 237 241 278 243 214 229 222 222 228 219 212 220 211 224 230 222 240 240 223 244 224 235 205 198 240 231 241 219 243 222 211 226 219 211 235 265 232 239 227 238 224 238 222 210 207 229 229 231 221 261 244 232 242 208 221 233 235 242 243 263 228 226 228 241 265 232 245 246 230 225 244 228 246 222 227 231 228 231 226 247 223 234 247 238 255 261 232 211 240 204 236 236 214 230 205 230 242 261 211 233 257 220 227 228 267 260 216 216 239 226 236 231 240 230 240 243 226 229 241 220 222 269 234 220 223 227 258 235 239 232 209 244 229 233 225 206 278 264 228 227 243 229 240 233 245 239 226 227 228 266 236 222 249 241 266 236 237 218 247 226 230 242 231 263 237 238 225 292 258 211 207 226 242 260 257 241 245 277 231 260 193 240 261 230 223 214 243 264 249 227 259 222 233 238 247 240 225 245 233 236 240 235 241 249 249 230 259 275 229 235 260 245 261 231 258 220 230 263 265 236 235 258 249 231 215 258 243 230 227 233 229 250 233 221 237 272 244 262 218 236 225 248 260 237 247 228 229 213 202 234 233 259 244 238 220 236 243 225 246 234 270 237 247 243 262 213 275 215 264 258 235 259 226 275 248 237 228 222 246 245 225 240 246 232 247 238 243 234 231 261 236 257 207 233 226 215 223 256 228 221 238 255 277 244 225 243 237 206 231 225 228 204 229 223 261 246 249 264 230 243 245 258 238 260 232 241 259 236 242 292 262 239 258 247 212 241 272 237 228 233 246 264 234 229 266 230 264 249 238 237 246 224 234 270 267 278 265 271 263 240 226 247 277 214 205 266 239 220 248 255 292 241 263 267 259 267 270 237 233 256 223 273 258 259 259 209 265 261 257 268 269 265 261 244 256 230 259 233 246 241 229 237 248 260 255 264 214 227 300 266 258 248 230 248 216 261 236 262 239 249 250 278 267 259 271 257 257 260 290 266 233 267 246 245 267 260 245 246 278 246 241 230 263 264 273 242 249 263 234 268 274 265 205 241 270 272 246 263 263 245 248 264 240 249 248 226 239 240 245 222 237 265 261 257 235 238 278 266 269 246 261 243 249 258 267 229 216 247 268 234 260 233 238 262 255 247 235 245 270 267 247 246 228 255 241 260 229 261 233 213 275 256 236 242 241 279 242 240 238 237 238 231 234 244 256 262 243 231 248 227 215 250 257 266 270 258 256 260 223 235 259 216 267 248 233 241 262 272 259 245 232 231 237 237 241 236 241 243 271 246 230 235 239 256 257 240 232 247 265 258 257 231 256 256 263 225 256 278 258 221 266 241 255 262 210 266 236 228 269 234 229 271 248 233 261 234 241 261 249 263 235 264 266 255 229 294 246 240 233 236 238 270 243 259 241 230 245 238 263 248 256 234 240 242 242 241 250 242 265 239 261 231 223 282 236 247 229 250 242 234 273 212 222 263 277 270 241 236 230 247 224 267 262 225 259 222 250 266 239 216 249 242 230 216 219 246 255 237 249 256 233 244 236 208 259 275 244 257 229 257 226 265 265 245 257 238 242 229 238 262 234 248 270 243 267 246 235 238 259 242 263 241 232 274 269 262 264 267 244 227 231 235 232 227 265 278 227 256 269 238 278 247 248 265 264 249 215 232 241 259 272 229 225 234 234 226 229 227 229 260 260 259 238 227 245 232 234 241 221 212 279 232 225 220 266 239 225 222 227 221 241 270 222 234 292 225 239 215 240 246 235 247 232 239 265 234 245 255 256 258 284 255 236 264 217 277 232 248 244 220 263 219 267 209 247 239 257 244 247 230 219 262 225 260 235 266 259 246 231 208 261 226 230 230 213 232 263 236 239 237 241 260 269 239 244 212 262 248 261 230 256 234 264 258 238 222 230 260 244 224 238 226 230 244 299 262 222 240 231 236 271 247 245 230 229 223 218 267 241 223 239 218 230 256 256 265 230 226 247 228 265 255 247 248 203 237 239 236 249 237 235 216 235 219 260 248 229 262 231 238 248 268 233 293 249 241 256 273 232 260 221 265 223 246 244 225 245 262 234 245 287 232 247 244 262 231 241 239 247 227 240 279 266 265 218 249 230 239 235 231 241 240 221 215 216 244 232 223 222 270 237 260 236 244 256 246 242 255 239 261 238 255 243 242 245 240 245 230 226 236 246 238 234 223 208 268 233 225 228 236 230 246 233 241 256 256 241 237 227 249 241 230 274 233 227 236 208 230 226 240 234 236 228 249 273 263 245 276 239 247 228 230 231 232 225 246 250 238 243 233 244 237 243 239 240 263 272 233 273 255 239 215 233 229 230 246 232 239 232 230 227 269 237 246 230 235 243 247 236 227 271 240 210 246 221 281 212 217 238 242 218 236 215 249 243 237 271 237 247 260 245 248 213 233 223 268 283 220 213 247 224 210 222 227 263 219 245 230 220 242 244 246 247 240 217 226 216 225 242 209 276 232 237 242 237 243 224 234 222 218 232 239 262 279 242 260 232 232 231 232 256 244 236 208 238 229 240 279 239 238 236 230 238 248 261 233 255 266 219 256 218 266 219 246 242 237 246 263 265 242 249 249 220 280 237 237 274 234 237 242 245 214 220 213 267 219 245 239 259 245 239 235 219 242 261 222 235 242 247 235 237 247 234 264 237 228 235 264 256 222 188 226 245 207 262 228 257 238 233 222 224 239 285 260 261 259 230 218 249 225 238 229 224 235 282 238 234 262 262 213 241 223 244 241 231 256 215 218 222 244 260 222 261 233 278 220 233 248 270 267 241 240 227 223 259 242 234 231 234 219 209 256 247 248 239 262 271 243 239 246 216 233 231 260 220 215 232 245 284 242 223 234 234 255 261 229 238 223 243 227 231 235 245 233 234 232 241 231 244 244 262 238 224 217 270 244 219 229 271 238 256 226 247 227 215 255 226 247 249 249 234 231 248 241 229 202 232 199 220 238 259 259 241 225 216 223 204 229 209 202 223 223 266 246 257 221 238 239 233 270 261 220 237 244 250 218 220 237 247 207 257 232 231 245 237 255 219 263 234 227 259 250 244 234 243 229 234 246 243 222 226 260 192 234 224 231 206 208 220 238 225 233 258 213 225 235 219 223 240 235 242 215 236 235 256 217 236 208 203 248 235 244 260 224 225 211 239 242 239 270 222 206 214 248 219 240 223 207 246 231 247 249 221 243 220 246 259 231 266 235 233 238 225 241 245 266 236 233 243 226 219 236 227 237 229 250 243 225 260 216 226 266 213 228 228 232 206 231 231 238 242 223 256 201 238 256 242 239 222 221 221 230 238 236 229 234 211 227 245 205 241 277 238 235 227 242 233 247 268 257 240 230 248 231 242 225 225 265 232 260 230 257 240 262 233 233 239 278 230 223 239 256 217 226 238 239 221 221 209 201 240 245 237 208 241 232 217 234 218 222 233 247 241 239 268 271 210 250 272 247 228 275 193 199 210 230 208 226 220 225 223 257 255 245 229 232 236 238 212 246 275 232 262 225 228 244 238 220 228 236 238 226 207 272 242 247 225 225 260 219 214 260 249 259 245 232 223 249 218 261 235 249 237 256 243 215 227 217 237 245 247 255 237 248 275 228 218 247 257 226 244 212 270 266 262 218 245 247 257 209 213 235 260 216 243 245 216 258 239 224 255 231 263 243 220 250 261 240 223 245 269 206 229 217 231 229 242 238 263 258 249 237 209 231 257 233 224 226 234 265 265 229 260 243 235 245 255 245 270 240 241 263 208 229 245 248 213 256 219 212 234 270 221 245 242 228 242 219 236 229 237 227 257 223 263 240 264 231 228 233 221 244 233 256 249 221 255 258 231 232 231 242 239 244 247 295 242 241 235 244 224 248 260 273 258 240 230 223 223 255 245 247 232 232 233 230 211 225 224 235 229 232 228 250 214 223 248 265 220 241 262 263 219 274 227 247 200 248 230 239 270 240 221 209 264 285 246 214 278 220 281 240 208 270 260 247 227 237 235 248 229 248 231 225 225 248 274 246 228 237 238 255 237 272 227 238 262 225 221 267 244 249 223 243 247 256 216 219 239 248 233 255 285 227 228 257 269 233 247 255 248 233 247 249 266 267 239 231 282 255 203 222 266 277 217 209 221 246 262 265 233 249 270 245 232 208 235 245 250 250 249 214 260 239 217 245 268 242 249 217 249 269 248 267 245 232 235 237 224 232 236 230 261 204 266 246 237 243 263 249 237 245 255 217 231 223 264 242 239 228 242 234 215 223 226 247 264 230 277 241 217 257 236 256 245 229 229 247 234 256 229 243 275 230 204 236 210 255 281 238 257 246 246 248 238 228 225 271 235 244 228 231 214 217 247 245 255 247 242 235 232 233 232 248 255 225 240 256 263 222 233 238 249 257 220 230 257 208 234 219 226 234 248 259 256 231 221 239 246 263 231 232 234 224 246 220 286 237 239 238 230 257 234 277 234 218 240 248 260 258 269 234 261 225 259 238 236 243 222 262 269 264 239 242 259 261 256 265 244 211 224 234 273 269 279 241 230 264 271 263 234 232 263 218 243 270 249 261 205 258 219 238 230 241 262 238 243 246 220 220 243 249 281 239 218 231 228 232 231 237 219 241 231 225 216 243 210 219 267 236 246 255 245 244 245 246 238 206 244 233 266 221 236 244 233 234 226 243 246 241 234 246 249 256 268 230 276 229 220 243 235 258 242 204 259 230 213 239 246 235 250 247 238 227 244 222 238 238 242 222 237 243 242 233 241 273 231 234 218 238 269 235 247 199 257 256 246 227 244 234 236 263 245 268 242 231 286 245 234 275 227 258 261 236 240 230 230 267 275 243 270 276 236 245 247 259 247 216 244 247 243 250 276 240 276 260 245 269 283 203 241 266 255 264 245 296 282 250 241 255 257 237 245 244 268 278 260 273 281 240 239 279 276 263 284 262 268 274 267 247 240 255 261 274 258 266 246 271 287 290 301 257 277 267 287 268 280 270 257 295 288 279 324 287 241 262 272 268 291 291 261 276 267 293 268 270 274 240 267 250 265 243 263 277 283 248 285 228 270 255 270 288 280 261 202 246 269 237 259 235 224 276 234 278 235 264 248 222 272 236 229 218 273 234 305 250 243 258 229 257 249 241 274 224 235 213 269 243 247 220 263 255 262 228 260 263 237 259 201 261 213 238 270 213 234 235 233 242 244 225 239 264 231 249 213 250 245 255 266 242 269 247 249 293 247 213 242 242 246 236 264 242 245 240 223 227 219 231 262 212 207 258 230 244 232 238 243 245 265 239 233 214 224 263 263 247 246 232 240 245 234 236 229 231 228 203 231 221 272 232 238 277 223 234 218 231 238 260 238 211 236 270 220 224 238 255 276 267 225 226 241 229 239 269 255 266 237 231 200 277 238 266 255 244 257 242 234 270 221 202 206 231 237 231 235 249 239 246 266 221 263 230 258 261 236 268 227 275 240 233 227 247 250 222 217 243 226 207 257 248 229 236 255 245 237 207 220 243 259 227 240 238 249 237 237 245 224 240 226 199 229 224 222 228 223 239 235 228 214 258 257 207 225 240 246 226 255 231 235 225 228 214 247 210 202 215 246 257 218 206 261 261 224 219 233 257 217 268 239 214 262 246 244 248 269 242 244 245 233 219 209 233 227 243 225 224 244 236 244 265 250 226 268 250 229 214 247 231 228 234 244 249 233 230 255 240 231 238 225 217 239 215 211 255 264 261 258 221 218 228 228 244 244 263 216 246 236 208 217 241 256 230 229 213 239 214 235 220 226 215 241 214 249 239 240 248 225 265 260 261 257 212 241 209 247 216 243 246 233 260 217 209 232 214 242 224 229 236 242 279 245 215 282 210 222 192 222 234 259 237 231 226 228 229 256 214 221 228 217 216 234 196 223 248 235 219 239 223 220 237 221 210 242 207 241 239 229 226 257 246 231 248 213 231 217 224 236 215 224 234 234 227 240 215 231 195 234 237 257 260 237 216 245 244 225 277 244 214 243 238 211 228 237 220 259 204 225 247 232 217 262 230 237 240 247 259 212 224 239 228 245 216 225 209 218 244 223 241 228 215 227 276 257 218 229 220 230 245 241 234 231 246 231 232 226 235 227 247 240 211 221 235 245 200 244 238 210 221 227 211 209 239 216 230 232 233 229 243 237 230 232 207 231 244 224 234 229 247 228 263 232 230 206 227 228 241 237 222 245 269 234 217 206 243 186 237 225 237 261 221 242 240 220 239 222 217 239 246 208 241 203 256 217 230 224 239 223 220 215 222 244 230 211 248 227 234 239 215 239 234 220 214 256 225 221 214 215 224 215 221 242 231 246 233 216 228 226 217 257 190 226 234 229 247 263 241 222 224 202 212 259 241 237 225 233 237 231 214 233 216 257 221 228 226 210 188 227 195 228 227 262 235 233 205 207 231 231 218 218 213 230 233 214 238 226 235 216 198 219 214 219 243 227 257 212 206 221 224 227 206 222 215 223 234 209 214 227 225 221 217 224 226 216 219 217 217 222 243 233 225 208 229 222 226 255 224 214 195 230 230 234 210 231 233 239 216 217 257 188 223 197 245 231 219 236 248 211 212 207 256 218 234 224 204 216 260 229 224 210 226 228 223 236 231 214 269 222 221 217 222 206 226 241 220 229 210 230 207 205 201 243 236 243 192 205 234 247 226 227 226 280 260 228 209 226 231 232 204 218 266 207 205 264 245 244 240 255 226 261 261 222 203 226 235 225 230 220 248 218 243 207 203 222 237 217 264 199 210 212 223 192 237 214 242 225 217 265 218 229 218 223 241 198 228 213 217 221 195 234 229 227 237 210 235 219 217 264 231 229 232 214 214 239 263 234 225 210 210 232 220 267 228 214 239 233 218 244 242 229 204 205 215 238 220 217 190 241 188 221 213 216 213 233 247 223 244 230 240 219 248 230 215 225 232 231 224 217 216 219 243 246 226 228 246 213 229 212 216 237 210 258 223 229 207 212 200 236 225 237 206 230 226 234 217 223 220 245 228 211 233 223 219 221 230 235 208 226 222 215 230 241 215 241 209 208 246 228 205 226 216 236 229 216 244 207 218 240 219 211 210 233 224 203 229 229 201 267 230 237 238 184 240 200 239 233 235 210 198 238 261 208 220 208 194 217 227 211 227 229 222 232 215 220 243 217 232 226 226 202 227 236 190 228 207 216 223 247 218 209 261 237 210 255 204 200 214 245 245 255 220 231 226 224 268 233 245 224 227 201 244 231 211 214 239 212 226 241 237 249 217 233 244 229 219 236 224 191 231 230 185 207 236 208 242 223 231 224 212 275 216 247 214 214 220 263 226 226 241 211 247 212 218 225 232 217 233 232 241 239 241 213 204 224 209 200 239 233 226 235 231 210 241 242 221 229 225 223 228 230 233 241 217 250 216 217 214 223 209 236 237 234 249 217 219 230 256 242 215 246 265 221 216 240 226 226 225 235 224 235 245 218 237 226 237 235 238 222 238 230 242 227 233 240 187 230 238 249 250 246 239 213 238 214 223 216 235 216 215 227 223 218 210 234 226 248 216 210 215 235 223 229 193 232 217 216 225 243 228 214 219 240 245 197 213 215 218 240 220 209 228 230 243 241 224 238 259 201 235 243 244 235 242 217 241 216 258 226 238 244 229 219 229 242 238 201 249 222 238 222 240 238 242 217 228 247 245 217 188 224 206 245 200 240 281 246 195 217 224 199 210 229 228 234 222 232 260 223 223 218 234 213 247 220 240 227 227 258 236 244 219 222 213 211 224 211 231 216 208 221 233 227 226 258 225 220 256 215 219 237 247 233 247 238 211 199 234 240 221 227 207 212 223 243 237 211 237 240 224 226 238 219 231 212 238 233 259 205 240 207 242 239 231 248 198 227 230 255 228 236 222 229 212 231 256 239 256 232 212 258 224 240 241 197 236 233 247 210 238 233 213 263 217 237 232 225 241 210 210 210 246 229 257 228 223 204 237 233 240 228 212 239 218 235 223 232 207 214 232 235 245 234 237 238 256 218 233 237 225 227 214 210 231 239 230 246 258 234 235 241 198 217 215 206 224 221 222 212 242 198 236 224 217 283 245 246 212 225 240 231 221 222 223 236 245 231 233 218 236 204 243 205 240 222 245 228 230 245 264 208 220 258 240 240 227 239 224 238 199 244 222 238 237 259 229 241 205 232 221 244 227 227 246 233 236 217 227 220 225 232 245 217 219 209 232 228 259 264 228 237 218 244 227 204 228 248 234 261 211 248 249 256 242 223 233 244 209 235 238 261 241 229 239 218 248 219 232 284 227 218 260 267 232 219 265 240 268 222 215 256 257 202 212 208 234 246 229 202 235 240 227 224 213 227 217 216 214 248 226 249 246 246 206 232 234 272 236 227 216 243 229 238 233 236 245 205 231 214 260 250 214 238 236 222 260 212 240 216 212 211 221 237 222 236 229 246 237 246 243 210 218 218 226 220 222 267 231 208 247 208 214 223 229 241 210 217 242 240 247 228 229 235 222 229 204 242 235 201 225 248 224 229 261 228 237 216 222 231 224 238 246 257 225 256 265 249 239 236 190 226 229 237 243 259 232 224 214 214 226 244 234 241 259 208 210 215 225 226 218 221 199 236 239 240 222 227 221 226 246 217 276 202 255 218 237 219 258 257 230 230 268 247 236 225 213 205 214 217 237 201 233 227 215 248 218 257 244 215 268 235 206 250 237 240 235 240 249 226 248 264 231 232 260 238 236 247 259 228 236 242 241 263 250 249 257 266 250 224 242 256 235 242 225 238 221 256 241 248 243 234 194 223 208 279 238 237 216 236 216 230 229 257 227 223 237 265 260 236 242 217 204 213 224 243 256 242 243 267 226 263 221 235 232 243 238 228 225 226 245 231 239 263 210 214 232 273 233 246 220 240 222 235 217 225 240 234 226 214 255 242 224 248 275 261 229 247 211 226 214 227 228 216 222 232 230 231 219 206 248 238 207 266 247 218 267 214 222 220 248 223 224 214 201 223 229 232 213 221 232 197 237 229 237 247 228 227 222 247 268 221 246 236 235 242 260 249 225 223 269 216 227 234 232 217 232 222 228 230 217 238 223 237 233 207 213 213 244 237 225 259 246 256 230 227 228 228 233 233 239 236 236 237 200 236 236 245 248 231 265 242 219 228 213 228 245 230 211 224 211 233 228 226 231 231 234 222 214 228 238 225 205 216 236 218 221 216 228 227 222 239 287 207 228 222 231 243 225 196 231 248 244 245 222 217 214 265 213 217 210 214 242 211 227 193 220 257 232 226 214 262 245 208 242 223 248 234 258 237 243 240 210 242 226 222 209 255 229 258 219 232 226 234 208 221 239 236 223 221 234 249 214 223 228 221 255 238 236 226 223 258 262 243 246 273 227 247 239 236 228 233 235 239 228 232 248 224 233 237 227 240 232 241 226 232 267 206 232 239 216 230 234 221 214 239 243 244 224 242 242 225 259 222 244 246 248 228 217 223 216 217 227 219 258 232 234 263 265 248 245 243 224 228 219 226 231 237 234 216 216 222 213 221 248 231 261 230 262 239 233 247 224 224 211 225 225 249 243 221 280 243 220 217 238 260 236 256 248 245 234 229 257 238 245 236 219 233 236 266 236 233 223 226 264 241 264 229 236 261 221 204 248 218 237 258 245 268 264 217 249 243 228 238 267 262 229 258 245 280 224 226 249 258 217 264 234 216 223 229 229 218 242 199 269 245 228 267 241 255 240 243 235 228 216 216 249 232 234 247 239 224 244 265 248 226 242 238 225 218 255 212 260 230 240 238 262 219 243 267 236 245 261 245 263 229 231 245 224 206 247 259 206 225 264 237 271 269 238 256 235 240 201 226 220 205 205 255 229 270 224 258 234 237 223 267 245 245 256 238 284 235 239 219 242 237 230 237 242 242 239 223 222 241 220 222 250 230 224 239 240 238 232 214 224 285 259 241 245 240 244 238 244 240 237 234 244 238 224 245 226 224 242 219 236 209 233 223 213 245 248 242 235 260 234 263 256 228 256 240 247 238 247 237 237 243 209 210 262 227 239 218 234 257 222 265 246 224 265 267 237 239 264 242 232 233 259 270 209 222 235 233 241 245 241 230 240 235 256 237 236 274 211 242 244 258 241 201 236 248 228 240 248 258 257 260 225 263 244 237 266 255 237 240 241 257 268 262 239 232 225 212 239 242 214 247 217 255 215 231 227 227 209 220 238 235 224 238 230 236 243 271 230 205 243 261 206 226 260 257 235 215 233 270 215 219 234 242 228 235 230 241 237 232 242 241 229 240 246 259 248 238 224 263 221 237 224 238 246 239 222 212 231 240 225 255 255 231 242 283 229 245 244 270 266 223 227 255 235 260 236 236 242 267 258 231 209 242 226 266 262 257 219 228 239 242 239 224 259 241 256 223 237 227 213 230 240 240 261 226 258 228 257 232 214 223 260 230 243 238 259 233 237 237 245 255 233 243 260 235 229 255 267 234 228 248 261 258 255 234 238 262 242 217 220 236 256 247 256 237 228 224 256 244 245 237 262 235 224 249 236 234 231 226 247 258 242 234 262 248 247 246 223 264 227 231 244 241 234 271 234 226 208 261 218 219 232 248 213 222 267 230 236 237 222 265 237 218 214 241 229 241 248 205 218 239 260 231 219 238 246 226 230 242 257 241 280 212 230 266 210 277 219 235 247 222 216 229 241 221 235 237 266 243 269 255 226 262 247 242 205 215 236 249 238 249 230 232 240 256 234 255 224 265 244 230 234 239 232 237 271 206 257 235 266 241 263 236 238 244 216 264 213 236 215 228 244 234 263 247 236 255 268 235 237 242 214 238 256 232 230 272 246 222 233 259 282 224 225 231 265 266 232 239 274 265 256 262 247 220 270 249 263 242 236 222 208 245 247 257 246 236 238 238 231 225 258 275 237 239 209 261 259 238 278 236 229 224 236 235 224 243 231 240 240 204 241 217 226 233 261 245 223 232 261 222 241 234 224 231 220 262 268 234 238 225 261 210 241 225 240 216 271 262 223 239 273 268 235 229 266 256 215 243 268 243 241 264 261 223 235 233 234 247 219 258 244 225 238 214 244 224 260 222 257 219 239 246 234 255 223 244 237 229 218 248 231 219 237 266 223 224 227 222 241 277 241 267 227 231 227 229 228 249 223 222 263 224 219 226 232 255 214 202 242 247 229 218 243 272 255 259 247 255 228 259 226 249 255 278 240 230 233 239 235 223 241 241 240 248 243 222 283 267 231 243 231 221 259 238 232 276 242 220 212 249 234 233 237 257 217 219 239 271 265 214 206 217 275 265 258 246 232 226 256 266 225 265 257 239 239 259 229 265 230 231 220 230 261 247 229 246 257 241 228 249 240 212 216 218 262 223 247 260 234 270 256 265 242 238 274 242 228 224 247 262 242 249 238 238 246 234 227 255 215 262 283 216 274 237 270 220 259 241 235 211 215 244 246 235 277 203 225 225 262 241 216 257 233 226 256 248 239 245 239 279 219 231 241 246 242 261 225 191 242 236 247 199 242 247 230 227 240 238 236 222 238 230 269 264 231 223 249 263 225 250 263 234 232 230 242 233 249 239 234 208 236 255 237 224 262 236 247 224 222 234 285 245 234 245 230 231 243 227 223 238 265 236 247 212 222 223 261 225 233 238 246 239 233 257 242 269 255 242 222 237 259 228 230 236 260 248 256 230 214 237 238 224 240 235 269 236 231 225 228 235 263 231 256 260 210 246 221 258 238 238 236 231 215 270 196 260 232 231 202 241 227 245 259 270 230 246 226 229 237 231 236 242 237 248 233 256 234 232 235 264 210 232 218 198 225 237 260 220 262 218 270 260 268 228 249 260 224 247 268 198 236 248 228 240 223 235 229 231 228 246 228 222 237 221 234 214 261 217 234 271 219 212 229 233 260 274 223 273 241 229 231 244 240 248 241 256 218 256 229 217 216 219 213 259 235 238 237 222 258 268 227 230 222 258 216 268 216 230 220 238 240 246 235 239 234 245 236 244 212 232 235 271 211 221 231 247 224 234 235 250 269 228 234 230 222 239 238 241 226 211 215 235 237 228 218 235 214 236 227 256 238 230 241 208 227 255 231 274 209 261 271 223 232 215 242 228 243 225 212 243 244 212 246 232 242 232 230 241 226 241 243 242 250 240 236 233 217 247 243 213 225 236 211 247 223 241 246 226 214 234 225 218 226 234 240 239 216 239 226 218 233 259 231 240 233 248 277 260 211 225 233 244 217 246 232 247 239 230 245 220 229 239 226 261 245 226 268 230 278 242 231 267 215 260 229 225 217 256 236 255 228 237 214 231 265 255 238 255 245 234 223 221 233 237 218 249 227 227 255 247 236 235 246 208 238 223 242 260 248 249 246 223 268 228 233 255 234 265 233 267 245 231 233 272 240 205 248 221 231 211 266 242 211 214 220 209 232 249 274 242 214 217 236 237 230 234 238 235 229 233 216 234 222 250 236 261 270 238 228 234 263 264 265 249 230 260 245 246 217 237 261 235 257 219 249 267 270 269 239 238 221 249 259 246 228 269 255 261 265 217 239 272 235 250 240 227 259 238 259 222 264 228 238 237 231 237 244 223 226 210 256 213 237 255 279 244 239 240 210 270 235 287 258 245 268 264 274 267 267 263 256 257 217 275 273 264 261 255 259 243 256 233 270 259 207 233 256 259 234 209 264 268 249 233 275 257 261 281 243 267 237 270 272 231 236 264 219 225 294 265 245 269 264 234 278 259 267 255 247 244 230 265 244 218 246 243 248 248 242 275 243 275 235 246 277 218 275 271 243 229 233 259 229 276 245 260 292 242 255 262 239 263 239 243 279 221 222 266 260 263 245 284 283 259 241 255 279 294 222 227 233 243 268 273 262 241 268 245 243 215 231 257 234 260 245 255 232 264 242 231 256 242 229 257 258 241 231 263 212 249 241 248 262 282 244 282 256 275 259 238 233 267 268 246 255 262 237 258 241 276 245 261 260 255 258 233 227 234 234 241 241 216 241 234 222 247 236 245 278 258 237 239 231 243 241 227 257 250 226 236 214 266 255 230 263 231 257 248 239 229 215 245 246 285 227 243 232 267 249 241 267 246 240 210 216 273 233 239 243 244 255 238 216 235 246 223 238 241 241 215 259 210 236 247 222 237 218 264 227 247 228 261 246 230 224 238 223 242 243 230 265 245 270 269 230 230 235 245 257 255 244 242 266 244 242 248 228 238 224 271 265 243 234 217 238 241 224 262 244 260 257 270 268 220 239 231 234 211 245 226 259 228 231 240 242 196 221 256 207 240 238 233 258 217 237 234 230 232 224 239 258 246 245 242 237 231 223 247 212 240 239 263 270 255 233 244 244 237 216 247 246 257 224 234 247 226 215 256 246 269 260 222 211 250 269 247 255 238 239 235 233 241 235 233 227 266 212 239 261 259 248 209 264 199 233 233 242 262 262 234 262 228 208 229 221 263 236 232 240 255 229 216 255 260 255 220 242 239 244 261 268 240 225 239 221 256 239 216 258 241 221 215 217 226 268 229 232 242 250 244 219 225 265 214 244 248 250 218 261 246 243 224 249 234 239 266 235 247 249 221 264 237 211 222 263 238 218 227 226 224 233 255 224 236 228 261 232 226 249 227 202 255 264 218 228 243 226 207 211 186 260 222 277 260 242 236 243 224 266 232 238 238 227 241 274 228 241 239 231 226 235 249 264 239 226 231 248 242 263 248 238 268 199 227 229 237 260 232 256 228 206 237 214 243 242 242 269 216 267 242 236 272 257 266 245 242 245 237 245 247 232 226 229 268 236 256 234 229 256 230 263 223 232 221 250 241 259 260 255 255 278 235 219 245 242 284 228 217 240 223 234 217 235 232 248 236 219 227 241 222 229 245 244 234 213 237 242 235 256 246 275 209 230 264 266 226 228 273 210 241 225 239 264 239 231 236 231 195 244 230 217 220 257 241 256 272 243 243 247 207 224 233 265 245 221 223 246 241 270 243 216 273 223 266 243 239 244 231 236 230 238 238 258 266 245 227 231 232 217 267 233 225 209 248 249 256 236 232 223 240 270 263 217 218 240 246 243 228 236 229 262 230 229 267 227 235 220 221 238 223 231 220 226 245 256 282 259 215 239 259 257 257 226 249 239 216 240 238 216 224 231 260 212 236 267 257 226 247 225 255 263 261 238 267 246 241 239 269 257 221 237 255 258 257 275 274 233 247 222 226 242 263 233 223 250 235 245 256 235 221 233 242 238 231 201 232 224 226 249 225 222 232 217 255 214 275 238 271 249 259 255 216 221 225 234 234 245 265 241 225 230 235 230 228 218 240 238 232 239 227 242 235 258 220 235 219 228 238 244 276 229 224 245 220 223 270 224 259 233 232 268 246 213 225 224 236 238 235 262 268 219 226 238 258 273 246 243 226 232 269 238 245 236 242 226 215 227 232 268 260 202 265 238 225 230 258 247 233 242 232 256 245 267 244 263 240 221 233 231 229 217 223 246 248 242 227 216 243 232 207 235 220 233 228 227 240 226 240 255 228 238 224 245 245 249 268 239 215 255 218 229 244 239 247 262 248 235 238 245 272 227 206 216 270 235 233 233 268 249 264 241 245 242 243 261 267 235 258 243 223 235 269 233 219 265 257 275 266 275 241 249 279 231 249 206 224 229 223 226 217 266 269 227 229 242 261 208 246 239 244 283 228 227 223 241 246 265 244 218 245 221 255 210 222 249 215 231 217 261 238 215 216 233 237 197 228 247 236 242 249 273 258 223 223 234 217 218 243 209 278 247 226 257 234 264 244 211 233 245 237 211 255 224 234 235 244 248 219 231 222 232 242 263 241 227 257 227 208 227 228 207 241 271 270 234 219 247 221 235 243 240 246 232 219 270 257 231 213 231 238 256 282 236 206 229 211 220 259 226 214 219 228 218 256 227 236 255 231 219 221 241 227 239 227 242 204 237 223 222 246 248 202 237 224 224 225 236 255 233 236 232 247 263 255 237 259 264 248 231 256 220 243 227 239 232 232 223 215 228 236 232 238 224 240 239 235 231 218 245 260 239 229 242 235 222 200 248 217 248 221 256 241 225 260 241 250 207 232 221 231 233 236 246 239 243 269 243 244 229 234 227 279 231 235 225 225 221 229 247 248 232 218 212 207 228 222 218 230 266 217 259 231 255 231 244 234 265 217 217 238 231 234 233 235 230 230 212 234 271 277 217 223 234 220 231 215 257 243 241 261 230 257 235 233 219 237 245 226 237 245 242 230 244 263 238 224 259 227 237 267 227 214 223 228 240 233 257 222 236 241 206 247 240 234 232 236 222 223 245 225 238 265 247 225 218 234 216 232 235 270 237 240 235 262 240 231 221 213 233 256 242 241 255 264 216 208 244 234 225 237 260 225 249 234 224 255 239 229 219 234 247 245 234 225 221 210 226 242 239 248 244 242 266 261 225 234 227 235 268 242 246 238 234 238 255 242 245 232 218 224 226 248 233 256 255 225 228 227 241 248 273 248 242 237 227 233 228 229 215 282 278 220 240 229 257 238 247 216 218 230 231 256 250 225 225 226 257 226 218 275 222 226 244 239 235 200 231 226 236 259 230 228 235 217 217 257 250 229 234 216 245 234 231 269 241 258 230 250 245 241 220 266 244 229 236 255 271 229 231 256 218 266 249 220 240 245 238 259 234 241 270 215 215 247 255 226 236 256 211 248 255 205 237 261 237 229 229 239 217 241 214 240 249 223 231 246 234 276 188 272 242 240 244 234 266 222 286 245 239 226 242 247 216 250 243 228 238 260 224 220 257 244 236 237 228 229 213 249 244 260 215 239 221 226 235 231 241 245 233 260 261 261 248 224 244 270 233 243 232 228 259 232 242 239 274 239 241 237 235 264 238 223 233 260 223 258 248 266 240 241 213 262 269 239 257 240 237 263 215 246</counts>
			</dataPoints>
		</scan>
	</xrdMeasurement>
</xrdMeasurements>