File: data/XRD/XG-Vakuum/XG-600/W6824-1C_XG_Vakuum_600.xrdml
<xrdMeasurements xmlns="http://www.xrdml.com/XRDMeasurement/2.1" xmlns:xsi="http://www.w3.org/2001/XMLSchema-instance" xsi:schemaLocation="http://www.xrdml.com/XRDMeasurement/2.1 http://www.xrdml.com/XRDMeasurement/2.1/XRDMeasurement.xsd" status="Completed">
	<comment>
		<entry>Configuration=Factory configuration, Owner=User-1, Creation date=7/8/2013 4:01:53 PM</entry>
		<entry>Goniometer=PW3050/65 (Theta/2Theta); Minimum step size 2Theta:0.0001; Minimum step size Omega:0.0001</entry>
		<entry>Sample stage=MRD Cradle; Minimum step size Phi:0.01; Minimum step size Chi:0.01; Minimum step size X:0.01; Minimum step size Y:0.01; Minimum step size Z:0.001</entry>
		<entry>Diffractometer system=XPERT-PRO</entry>
		<entry>Measurement program=C:\PANalytical\Data Collector\Programs\Jorrit\2thom\_absolute_2th-om_10-130deg_PIXscan_56min.xrdmp, Identifier={15BCCF57-2807-42BD-B5B9-ECC0B3DC9284}</entry>
		<entry>Batch program=C:\PANalytical\Data Collector\Programs\SimonL\batch4x_2thom_10-130°_z9.1_x0,10,20,30_y0_57min.xrdmp, Identifier={EED9823A-2BEB-424C-9252-345C4EF2834A}</entry>
	</comment>
	<sample type="To be analyzed">
		<id></id>
		<name></name>
		<preparedBy></preparedBy>
	</sample>
	<xrdMeasurement measurementType="Scan" status="Completed" sampleMode="Reflection">
		<comment>
			<entry>_absolute_2th-om_10-130deg_PIXscan_56min</entry>
			<entry>PHD Lower Level = 4.83 (keV), PHD Upper Level = 11.27 (keV)</entry>
		</comment>
		<usedWavelength intended="K-Alpha 1">
			<kAlpha1 unit="Angstrom">1.5405980</kAlpha1>
			<kAlpha2 unit="Angstrom">1.5444260</kAlpha2>
			<kBeta unit="Angstrom">1.3922500</kBeta>
			<ratioKAlpha2KAlpha1>0.5000</ratioKAlpha2KAlpha1>
		</usedWavelength>
		<incidentBeamPath>
			<radius unit="mm">320.00</radius>
			<xRayTube id="1010048" name="Empyrean Cu LFF HR (9430 033 7310x) DK442154">
				<tension unit="kV">40.0</tension>
				<current unit="mA">40.0</current>
				<anodeMaterial>Cu</anodeMaterial>
				<focus type="Line">
					<length unit="mm">12.0</length>
					<width unit="mm">0.4</width>
					<takeOffAngle unit="deg">4.2</takeOffAngle>
				</focus>
			</xRayTube>
			<xRayMirror id="27010001" name="Inc. Beam Cu W/Si (parabolic MRD)" hybrid="false">
				<crystal type="Graded" shape="Parabolic">W/Si</crystal>
				<acceptanceAngle unit="deg">0.800</acceptanceAngle>
				<length unit="mm">60.0</length>
			</xRayMirror>
			<sollerSlit id="21010002" name="Soller slits 0.04 rad.">
				<opening unit="rad">0.0400</opening>
			</sollerSlit>
			<mask id="22030008" name="Fixed mask 4 mm">
				<distanceToSample unit="mm">220.00</distanceToSample>
				<width unit="mm">4.00</width>
			</mask>
			<divergenceSlit id="22010007" name="Fixed slit 1/8°" xsi:type="fixedDivergenceSlitType">
				<distanceToSample unit="mm">220.00</distanceToSample>
				<height unit="mm">0.19</height>
			</divergenceSlit>
		</incidentBeamPath>
		<diffractedBeamPath>
			<radius unit="mm">320.00</radius>
			<sollerSlit id="21010002" name="Soller slits 0.04 rad.">
				<opening unit="rad">0.0400</opening>
			</sollerSlit>
			<receivingSlit id="22010001" name="Fixed slit 4°">
				<height unit="mm">5.88</height>
			</receivingSlit>
			<detector id="7010017" name="PIXcel3D 1x1 detector" xsi:type="areaDetectorType">
				<phd unit="%">
					<lowerLevel>30.0</lowerLevel>
					<upperLevel>70.0</upperLevel>
				</phd>
				<mode>Scanning</mode>
				<activeChannelsEquatorial>255</activeChannelsEquatorial>
				<activeChannelsAxial>255</activeChannelsAxial>
				<pitchEquatorial unit="mm">0.05500</pitchEquatorial>
				<pitchAxial unit="mm">0.05500</pitchAxial>
				<readOutPeriod unit="seconds">0.135</readOutPeriod>
			</detector>
		</diffractedBeamPath>
		<scan appendNumber="0" mode="Continuous" scanAxis="2Theta-Omega" status="Completed">
			<header>
				<startTimeStamp>2024-10-08T22:41:02+02:00</startTimeStamp>
				<endTimeStamp>2024-10-08T23:37:08+02:00</endTimeStamp>
				<author>
					<name>PRO-MRD</name>
				</author>
				<source>
					<applicationSoftware version="6.1b">Data Collector</applicationSoftware>
					<instrumentControlSoftware version="7.0E 20130304">XPERT-PRO</instrumentControlSoftware>
					<instrumentID>0000000011142674</instrumentID>
				</source>
			</header>
			<dataPoints>
				<positions axis="2Theta" unit="deg">
					<startPosition>9.99826193</startPosition>
					<endPosition>129.99755682</endPosition>
				</positions>
				<positions axis="Omega" unit="deg">
					<startPosition>4.99913096</startPosition>
					<endPosition>64.99877841</endPosition>
				</positions>
				<positions axis="Phi" unit="deg">
					<commonPosition>0.00</commonPosition>
				</positions>
				<positions axis="Chi" unit="deg">
					<commonPosition>0.00</commonPosition>
				</positions>
				<positions axis="X" unit="mm">
					<commonPosition>30.00</commonPosition>
				</positions>
				<positions axis="Y" unit="mm">
					<commonPosition>0.00</commonPosition>
				</positions>
				<positions axis="Z" unit="mm">
					<commonPosition>9.100</commonPosition>
				</positions>
				<commonCountingTime unit="seconds">32.895</commonCountingTime>
				<counts 413 392 430 425 400 421 401 400 388 432 372 407 411 462 441 434 398 418 394 426 418 425 414 402 411 432 377 446 412 424 399 370 389 423 404 397 418 401 457 401 426 369 417 404 422 409 436 419 456 451 463 413 433 410 387 414 416 414 374 399 425 426 404 413 373 372 440 394 389 412 440 424 404 378 402 393 407 416 369 390 402 424 412 411 368 438 401 381 399 401 421 411 403 418 406 369 388 378 404 379 347 415 419 407 406 399 339 415 404 383 375 407 400 410 377 349 371 388 408 375 415 358 389 389 406 393 387 331 396 396 396 381 382 380 372 360 360 374 371 391 377 408 389 381 366 397 382 384 383 388 372 317 398 352 369 417 370 377 357 380 370 354 362 408 397 380 368 380 368 361 421 358 342 389 345 402 340 379 386 375 386 368 368 342 404 347 372 374 378 366 386 304 363 397 394 391 359 379 371 349 380 338 430 396 351 404 373 365 370 369 376 373 354 377 365 359 380 368 359 381 345 362 363 375 389 350 363 369 359 363 382 354 396 365 370 346 350 361 378 393 372 395 402 370 369 365 341 360 352 353 320 354 376 338 331 339 382 363 370 385 374 315 351 392 348 359 371 360 373 369 360 323 355 360 379 333 353 331 347 354 331 388 314 336 340 360 361 359 359 347 335 318 380 392 355 343 357 387 325 355 354 353 342 333 376 338 350 349 372 352 335 364 349 363 338 346 351 361 349 334 363 322 345 377 393 327 349 367 317 379 341 385 327 313 325 346 339 341 340 353 335 363 341 337 332 369 323 322 318 354 384 357 335 340 361 344 330 328 308 336 335 325 345 338 330 315 305 331 309 339 328 320 322 328 328 357 325 347 368 321 348 354 314 317 332 325 382 344 316 364 335 350 347 321 311 320 308 341 341 336 338 337 333 321 356 334 351 313 365 302 332 353 309 327 318 301 337 358 328 361 309 331 358 314 331 341 306 303 310 292 394 332 290 335 330 330 349 305 350 305 331 314 347 317 345 348 315 298 309 316 320 316 313 346 311 338 322 331 320 333 292 303 303 331 288 338 316 308 308 305 321 318 330 327 311 324 347 317 312 326 331 316 354 289 330 307 357 290 333 326 330 332 331 305 302 298 338 342 303 320 332 292 277 288 338 323 315 327 311 277 312 318 293 317 308 333 338 302 316 305 313 299 308 320 324 326 343 304 326 294 287 301 308 288 304 296 298 334 343 288 311 328 323 340 327 326 310 324 332 337 329 320 310 298 280 311 322 318 360 325 337 342 305 246 324 292 311 313 339 295 307 334 322 336 303 276 317 331 360 318 327 331 323 295 290 304 295 283 291 321 297 302 326 318 310 321 330 297 312 303 291 294 305 325 308 294 310 319 288 326 327 295 325 307 266 273 290 300 294 305 297 273 309 310 287 333 314 299 298 304 306 292 287 322 322 313 306 300 312 285 293 324 275 322 300 288 316 309 285 314 348 330 284 308 269 314 300 323 320 337 306 306 294 302 329 314 298 323 301 331 300 316 303 329 317 297 325 294 317 297 333 308 284 328 288 301 278 290 294 313 303 310 321 291 328 268 297 327 289 289 313 290 269 299 306 321 291 256 319 299 305 306 299 311 279 319 319 316 303 296 288 322 326 296 324 309 294 281 286 304 284 315 303 305 332 321 284 310 335 296 291 311 321 309 310 314 310 318 330 304 301 301 309 293 285 323 310 313 304 289 285 302 328 302 323 332 300 321 292 323 307 313 303 331 259 339 330 320 313 297 283 327 287 281 296 323 300 323 300 308 308 311 283 296 296 270 320 302 303 292 282 296 296 295 314 319 325 325 268 295 307 278 295 300 315 328 275 296 292 284 300 314 329 298 318 299 321 287 277 322 299 315 313 303 339 309 287 288 313 323 329 321 301 310 308 273 324 284 313 305 324 302 272 315 276 297 274 319 280 293 322 279 315 300 287 319 320 292 282 333 297 342 318 319 337 293 304 310 304 360 321 301 340 314 282 322 284 318 279 307 314 300 307 267 272 335 326 319 310 287 315 261 290 274 291 257 311 310 303 272 276 321 313 312 282 286 332 310 319 330 326 324 306 306 292 354 314 334 328 343 306 313 302 313 330 342 336 308 286 316 335 309 289 304 318 294 295 333 309 308 335 306 314 322 304 333 322 318 299 340 306 287 290 303 330 307 333 343 314 311 299 355 284 322 337 313 287 334 273 300 325 319 334 308 314 310 337 290 293 327 283 319 304 345 297 299 306 300 308 280 323 317 310 318 300 302 292 309 301 305 291 303 308 296 322 305 293 318 344 310 332 315 330 327 321 302 309 336 321 306 285 299 307 322 326 325 326 352 312 308 296 362 321 318 337 310 321 318 344 329 332 302 323 360 294 306 290 311 312 329 325 314 313 329 315 289 333 327 345 334 291 300 322 301 328 298 310 310 317 328 300 332 330 305 339 317 330 326 264 296 296 316 308 317 316 296 342 291 344 318 337 301 357 346 324 323 314 332 318 322 286 335 335 323 337 299 324 318 314 296 329 316 292 325 294 331 306 308 322 293 315 335 326 285 321 329 305 290 326 326 328 341 308 348 341 342 358 291 321 314 322 348 319 317 317 321 345 317 319 318 332 310 332 306 309 312 282 337 325 329 305 329 334 326 312 330 352 308 328 317 319 306 308 335 350 289 327 322 308 335 316 342 322 341 304 318 337 315 354 364 306 330 330 303 326 311 351 309 301 327 302 344 320 294 318 312 308 333 341 318 342 316 337 322 329 314 305 328 335 299 339 328 324 308 336 303 283 323 318 302 350 327 339 346 299 346 324 337 348 308 292 311 308 331 298 311 318 327 309 336 316 309 315 334 344 321 303 305 344 320 335 322 317 290 343 303 309 306 308 297 331 338 326 307 320 328 303 336 308 316 305 331 327 312 301 325 305 324 333 308 329 313 309 334 318 347 326 362 326 325 354 320 313 311 283 318 305 354 302 313 335 297 335 325 297 313 319 315 298 350 303 327 331 325 342 329 305 312 340 364 287 323 324 316 301 310 329 325 313 328 301 303 331 265 352 339 344 331 304 317 304 334 316 308 347 305 322 337 282 318 355 306 347 313 334 289 309 326 300 305 315 331 318 304 305 332 291 314 305 297 288 305 349 286 310 301 304 334 336 334 357 286 299 340 321 311 305 346 308 325 299 288 359 340 310 308 342 303 317 313 299 316 349 323 351 341 352 297 313 323 291 309 306 293 316 338 309 308 319 300 343 310 299 302 297 306 296 275 325 286 314 281 317 342 329 310 292 334 303 271 316 328 291 302 279 313 287 303 310 281 288 305 287 301 333 296 298 305 313 305 319 283 323 325 290 277 323 290 303 328 317 299 321 303 294 305 317 303 296 281 326 330 327 333 286 311 318 293 313 321 311 286 314 301 316 291 319 321 327 299 282 321 298 289 300 318 304 289 290 315 315 259 294 296 299 268 296 282 285 287 313 287 301 237 262 259 266 284 305 288 302 302 307 328 316 272 239 316 307 275 265 286 285 270 290 292 325 300 269 264 335 285 286 294 271 297 288 288 295 302 289 301 287 280 300 286 292 278 275 280 277 262 269 307 257 286 305 279 261 298 301 295 277 242 270 260 267 296 296 306 290 296 294 263 282 277 308 280 295 286 307 289 295 274 262 277 279 279 291 299 305 259 260 240 292 297 248 311 297 256 284 277 297 289 274 287 293 292 281 298 326 269 296 306 281 284 278 328 270 285 312 276 269 307 272 306 263 273 300 289 268 282 249 283 263 276 302 286 309 301 267 235 277 259 276 274 304 302 259 269 262 297 263 282 309 292 275 287 272 311 294 270 287 239 304 280 272 229 297 270 235 265 271 296 248 278 284 278 285 276 271 263 258 258 294 275 284 265 260 278 260 263 281 270 260 276 240 261 298 246 228 248 242 285 261 278 261 282 269 265 265 275 249 287 278 273 248 279 259 276 261 264 265 277 267 293 259 240 258 281 275 256 334 257 273 282 297 275 269 264 239 259 270 262 255 264 272 290 310 270 257 239 234 288 266 272 287 244 263 236 261 236 275 266 269 227 268 255 293 255 263 250 221 244 255 266 237 281 265 279 229 265 287 284 255 282 243 283 235 249 243 280 238 259 261 259 243 260 257 258 242 280 266 258 265 250 256 225 242 260 271 277 256 255 273 266 257 257 272 268 263 248 265 243 296 275 256 258 274 270 262 266 271 229 245 258 216 219 232 275 231 242 249 255 208 247 263 274 262 235 243 237 246 229 255 275 240 265 238 239 244 247 296 224 269 261 258 257 228 217 260 226 218 276 242 262 242 241 236 291 238 263 230 258 259 256 224 237 259 235 277 237 255 260 246 241 244 255 240 238 245 242 260 271 229 243 248 267 245 245 226 232 278 273 269 231 259 247 240 264 230 242 246 243 260 258 218 245 224 286 276 247 217 241 243 245 231 221 208 225 256 246 221 213 256 247 230 262 244 236 241 258 224 246 227 244 220 256 248 235 236 246 235 230 234 248 236 209 228 248 278 218 262 250 233 230 243 244 229 230 233 230 249 263 268 239 219 270 225 241 221 225 248 234 256 227 240 216 236 230 223 225 221 229 235 233 220 263 228 236 214 219 272 233 206 216 275 213 229 247 243 239 241 276 220 225 216 238 259 227 245 262 230 233 218 246 225 210 212 232 219 216 269 213 226 207 235 232 245 227 216 226 227 227 245 240 225 232 232 217 247 257 218 228 226 249 225 231 202 264 229 249 173 200 220 242 257 230 237 266 227 212 242 241 219 233 262 223 250 216 230 222 255 257 217 231 187 219 230 235 229 219 204 210 261 238 228 232 221 237 227 246 220 232 238 200 220 232 244 234 239 250 213 263 234 236 229 222 218 231 246 202 257 246 226 223 201 232 227 224 218 209 232 255 230 213 222 233 216 230 238 249 225 229 238 219 202 223 227 201 233 235 243 232 212 212 198 233 224 210 209 212 231 232 212 232 225 229 218 230 213 221 210 194 213 234 220 227 226 226 243 222 215 212 206 231 225 224 270 220 220 220 239 247 222 206 200 240 209 216 215 231 215 223 217 226 245 225 243 230 216 218 230 232 206 209 239 234 205 265 202 219 213 222 236 202 228 220 217 262 246 235 224 237 218 223 246 243 197 223 225 235 238 241 225 216 226 227 204 210 206 220 211 233 200 211 226 219 232 196 234 214 218 229 213 232 229 213 224 208 213 223 209 228 220 228 246 234 228 212 203 221 202 185 231 215 221 211 228 196 236 224 248 223 212 228 209 216 191 245 220 203 240 236 211 210 201 207 229 213 222 206 188 191 199 208 232 220 210 214 222 218 221 229 208 257 237 213 208 227 197 225 241 210 182 204 230 232 239 266 237 229 200 233 212 197 211 229 202 225 194 205 205 260 185 208 199 216 219 201 229 198 209 214 220 237 234 242 225 181 229 246 213 197 199 227 208 217 231 218 205 214 208 221 199 223 215 207 226 226 229 209 221 243 222 215 218 241 221 199 235 215 248 226 240 201 237 180 227 229 220 204 190 208 212 225 224 216 210 229 221 229 258 245 208 221 236 208 218 216 190 218 227 222 235 216 233 200 235 192 221 183 199 217 204 240 227 201 242 219 223 225 223 223 208 206 215 221 208 223 236 227 206 223 214 232 242 217 214 219 205 217 203 208 221 221 209 206 192 193 191 204 228 223 227 238 209 211 198 211 198 217 238 235 210 220 210 217 187 233 205 220 220 195 183 223 222 236 243 197 200 217 192 210 221 195 221 207 224 197 195 198 208 231 188 194 200 200 216 232 204 267 205 202 221 217 218 201 204 216 222 233 220 232 187 212 224 217 203 213 203 221 215 203 230 229 206 202 196 194 187 213 214 210 193 220 233 207 210 197 224 221 222 217 216 210 221 193 194 224 218 202 236 198 213 214 229 211 195 238 207 203 221 202 222 227 212 219 232 198 212 236 236 208 215 206 194 222 202 217 239 226 201 239 185 199 210 214 210 238 233 235 193 202 235 207 226 215 218 216 230 231 203 205 189 210 227 233 232 227 236 203 227 225 215 218 203 214 208 214 221 208 223 196 224 188 220 208 196 200 205 225 194 229 232 210 194 229 228 201 232 237 223 235 179 218 209 207 217 232 218 198 218 219 231 246 200 211 197 216 209 204 211 209 226 193 220 179 228 212 224 189 217 227 220 215 196 225 222 206 207 230 231 201 206 178 230 216 212 239 205 219 209 210 195 202 196 209 230 212 210 193 207 209 212 216 197 199 190 223 224 185 207 190 191 216 218 224 228 213 218 213 205 210 192 205 217 221 199 198 206 225 209 212 194 238 224 231 246 207 192 225 227 201 200 220 216 229 220 193 213 205 227 209 198 201 214 186 198 221 221 202 200 229 208 198 214 212 214 205 207 182 235 213 204 210 188 234 194 204 199 214 201 223 184 207 235 206 226 199 220 225 218 215 219 199 202 190 189 218 235 204 222 234 197 204 225 221 229 225 211 206 211 212 214 209 220 205 194 182 241 201 186 263 198 190 202 199 211 217 243 191 201 193 186 216 207 226 224 197 228 213 202 191 194 216 222 193 220 243 213 205 211 203 213 210 208 197 227 207 229 232 227 200 197 208 195 207 214 193 211 193 222 202 206 221 212 215 179 215 216 239 208 211 208 183 220 178 187 233 206 196 237 189 213 197 219 256 247 212 222 216 229 212 215 214 210 200 228 191 208 224 214 222 206 196 220 212 208 208 213 220 200 215 232 217 191 197 175 231 205 202 206 209 195 213 219 205 219 202 194 203 200 206 214 178 208 225 222 174 218 223 213 193 216 209 201 189 212 212 194 189 211 234 218 230 206 197 196 212 221 217 199 212 202 193 198 224 237 218 228 224 222 199 213 225 209 218 193 204 211 214 194 216 210 198 194 201 208 202 211 201 227 207 186 206 225 218 198 205 206 220 199 210 224 195 239 231 225 249 217 183 182 207 214 214 226 207 203 216 201 210 205 225 226 220 185 224 203 218 192 218 173 212 217 233 219 229 201 199 217 198 228 221 191 172 185 217 230 194 214 221 200 209 210 216 196 223 206 224 192 226 230 205 190 244 184 206 196 203 208 193 219 190 195 208 216 195 194 192 205 241 196 185 232 208 202 217 218 226 215 191 210 203 225 210 223 206 221 201 192 213 196 219 182 214 208 216 213 204 223 207 190 225 213 210 195 210 182 194 202 234 222 205 220 198 223 208 188 204 199 170 200 223 189 225 213 200 190 215 198 235 216 189 199 207 222 215 201 216 216 209 203 191 215 249 220 204 223 194 225 197 197 228 203 195 209 212 232 205 189 195 231 211 217 222 190 198 183 197 224 214 214 219 220 216 207 217 234 219 202 229 215 214 209 200 189 222 215 229 199 190 216 225 220 213 217 189 201 232 213 175 216 231 205 209 205 219 225 205 216 213 216 221 216 228 220 209 206 211 202 218 214 212 203 224 222 220 211 205 228 212 228 233 214 217 226 255 241 232 248 204 199 216 246 204 260 201 228 205 220 207 218 224 228 220 235 214 237 240 230 213 226 203 232 206 208 210 214 197 205 205 216 232 212 206 232 207 221 213 230 217 191 205 223 207 238 211 256 208 213 230 215 233 193 236 193 233 217 224 221 234 198 248 200 236 231 239 212 234 215 210 228 236 220 271 224 206 225 240 209 238 226 230 226 226 241 243 257 256 226 234 220 247 224 246 247 259 266 236 228 243 240 240 226 258 239 272 269 242 221 297 228 274 241 297 303 300 247 273 319 277 272 264 282 323 284 315 303 314 316 310 339 343 353 316 367 378 393 365 372 373 332 377 395 360 405 394 406 402 375 379 369 379 388 355 368 321 335 360 345 315 318 333 322 302 280 310 292 294 283 282 266 283 264 273 239 276 270 265 216 255 230 244 232 234 260 248 229 266 222 215 221 228 217 236 241 242 224 230 214 241 226 233 219 233 243 246 219 214 241 208 234 234 211 218 212 227 236 244 233 208 257 219 232 231 211 212 208 234 196 198 203 229 239 227 199 227 211 222 226 232 208 212 217 247 227 200 232 207 202 216 239 215 213 207 214 235 208 225 193 212 215 223 219 263 217 226 210 199 207 228 214 220 219 244 204 184 226 177 230 226 192 194 220 199 216 209 202 225 216 236 212 196 199 224 202 216 219 198 215 224 198 211 215 205 195 245 197 197 198 191 223 208 225 244 238 222 203 211 179 221 246 216 235 203 227 195 206 222 222 228 225 211 183 225 233 231 200 221 225 212 218 193 216 229 217 211 207 234 210 227 223 197 206 231 202 207 213 216 213 220 227 183 222 222 241 202 241 201 225 218 211 216 201 249 207 221 233 225 177 208 216 212 211 203 202 203 210 204 202 219 243 212 214 212 189 226 195 176 224 193 220 210 231 212 224 186 209 211 218 202 241 225 211 210 196 208 190 239 234 248 224 217 235 231 234 217 190 219 207 219 224 197 231 258 234 201 209 226 204 213 217 209 214 202 216 202 196 232 206 216 237 194 210 213 222 224 185 228 228 208 226 206 206 187 205 225 195 226 226 217 217 196 207 204 216 199 229 197 197 228 219 237 208 231 214 216 176 205 223 215 228 201 220 222 222 209 229 200 175 226 239 187 189 206 202 220 201 194 224 185 217 225 198 222 227 217 193 188 220 206 208 218 209 222 230 238 221 218 231 202 227 218 210 207 268 216 210 195 213 233 198 210 266 212 203 215 214 193 238 206 211 196 221 231 216 200 201 224 207 231 198 204 223 223 233 212 209 218 255 215 232 191 173 224 214 220 231 229 202 219 202 233 208 201 198 218 206 198 209 234 209 218 207 217 216 216 216 190 192 223 173 214 217 172 197 220 200 199 186 229 226 226 202 203 220 180 207 214 195 196 238 165 205 189 210 219 211 198 205 222 190 216 217 237 189 211 229 207 202 224 213 205 228 195 228 189 234 213 202 220 208 198 209 218 208 216 232 236 185 213 233 206 226 183 236 220 203 210 206 177 229 206 227 197 206 200 216 216 203 190 225 205 196 216 175 231 215 195 201 206 207 225 217 224 221 221 224 221 197 230 234 188 219 201 190 199 210 219 225 232 191 187 187 212 214 231 197 202 231 202 234 231 202 196 188 219 239 223 193 231 199 234 226 222 200 208 224 209 212 219 186 216 220 222 196 219 215 202 231 228 218 199 201 219 218 208 222 208 205 212 213 195 205 206 223 184 218 202 228 239 215 223 202 219 236 220 212 213 220 212 221 209 198 217 223 198 225 217 222 221 212 216 245 229 234 213 222 203 191 203 199 240 230 221 214 221 206 205 217 213 206 242 202 238 210 206 187 219 230 203 233 237 223 216 217 224 209 236 211 198 210 195 224 228 236 203 208 210 229 222 230 190 218 217 232 212 214 229 218 200 239 223 218 199 191 234 246 227 226 210 211 221 202 217 214 231 191 238 230 195 194 241 186 216 204 224 187 204 198 220 193 214 218 225 210 191 214 231 204 211 226 229 227 216 237 205 235 224 225 221 209 215 239 215 219 231 171 212 215 237 209 221 230 220 214 233 214 203 196 220 191 222 234 193 206 219 214 211 198 199 202 226 191 232 201 219 221 225 228 231 219 216 211 226 220 212 187 208 215 183 221 236 214 224 206 208 198 216 220 200 182 233 234 223 231 227 210 234 197 203 222 225 240 225 226 260 188 233 204 202 220 212 187 197 201 209 190 255 233 219 230 228 202 232 218 215 219 243 226 208 212 213 221 202 211 220 201 248 215 207 196 200 222 219 243 227 209 207 201 233 209 192 215 200 221 219 197 235 236 226 230 206 204 236 194 223 217 239 234 218 191 214 224 243 205 223 220 214 217 210 219 185 225 212 223 247 232 192 204 221 201 238 210 201 223 222 195 204 216 238 248 238 213 221 200 201 211 194 232 221 216 193 231 192 193 234 231 218 242 227 206 233 190 219 199 221 212 232 200 218 233 217 221 203 238 238 221 207 229 210 238 220 215 223 217 226 202 225 220 226 218 212 225 184 235 194 232 213 235 190 222 222 208 194 220 196 213 207 173 233 220 229 210 216 229 200 221 259 212 243 209 188 196 212 203 221 261 205 221 238 223 218 238 201 228 195 208 244 200 224 220 200 217 214 208 210 226 223 195 212 220 228 196 228 215 220 242 207 245 216 208 223 218 220 216 199 226 239 222 234 220 201 250 218 239 227 222 214 230 218 237 214 194 223 221 211 220 202 214 230 216 227 202 214 204 250 227 193 237 234 215 208 224 239 201 198 207 265 209 199 237 246 213 224 229 233 235 228 226 228 203 224 216 231 220 206 206 201 214 203 222 191 222 241 206 246 218 210 238 188 236 211 245 205 225 228 203 230 210 206 211 211 200 227 216 259 243 214 201 218 218 223 237 207 225 264 234 231 219 221 207 213 216 241 234 219 265 249 214 220 227 223 221 236 218 224 213 198 235 230 223 225 246 220 225 218 222 229 215 234 223 194 229 203 233 236 260 188 222 219 219 210 257 215 241 238 232 223 226 215 217 205 209 231 193 205 216 189 211 221 235 235 217 204 217 237 212 233 226 235 201 194 228 191 229 240 215 230 189 203 222 218 258 188 204 191 220 225 242 210 237 217 227 209 206 203 229 213 241 241 236 198 232 204 216 219 229 226 213 275 211 207 227 218 269 226 195 220 225 238 233 239 182 235 241 228 231 231 220 229 239 239 217 256 241 203 215 234 191 236 216 218 213 222 215 232 226 235 194 220 208 205 221 250 238 207 245 228 204 258 236 210 225 221 222 226 205 202 231 231 239 228 237 225 224 224 221 218 210 219 226 208 209 228 226 227 222 203 195 245 214 244 229 227 217 240 218 216 189 218 227 220 231 219 218 237 208 213 231 224 244 224 205 236 224 255 218 232 228 243 207 238 215 245 201 208 242 228 216 211 260 241 215 224 218 233 224 246 248 231 208 236 225 213 228 230 211 230 239 234 239 209 239 221 191 240 226 240 230 195 215 198 231 214 237 233 226 211 242 206 194 262 224 260 247 230 226 199 255 200 240 215 233 236 256 223 218 245 216 236 229 215 223 226 234 231 236 232 220 245 227 232 222 197 221 225 247 236 205 233 216 217 225 238 216 210 241 224 225 219 229 211 224 218 212 239 205 219 217 222 214 233 202 222 249 244 239 195 246 247 218 206 247 207 212 215 222 206 221 241 232 228 241 241 219 237 210 232 197 241 238 207 213 219 243 228 241 234 221 217 219 210 231 220 214 238 207 260 234 237 238 203 229 235 231 239 225 205 222 209 208 232 239 214 215 264 232 183 265 224 223 227 255 238 238 217 208 224 228 236 210 243 207 206 235 246 220 224 222 232 228 212 234 230 243 217 227 203 211 227 213 230 237 204 232 211 225 215 220 234 218 235 216 220 236 224 217 233 241 223 238 244 218 228 224 249 244 217 220 246 203 200 275 217 232 234 200 216 209 217 234 211 213 205 228 232 228 263 224 206 240 194 198 231 203 199 240 216 226 243 230 200 235 266 213 212 250 224 250 229 202 236 240 221 240 248 227 212 220 234 243 227 225 215 239 220 236 229 243 199 246 209 226 208 258 232 255 210 231 237 257 241 223 232 233 230 218 214 238 215 226 239 221 221 215 208 220 230 214 235 259 225 207 235 263 241 267 197 237 225 219 214 226 227 209 209 240 232 224 203 230 233 267 220 222 206 226 217 239 256 232 221 235 229 259 218 209 216 211 228 216 214 226 235 261 223 233 218 259 222 244 237 237 237 219 209 258 259 256 212 231 218 207 204 245 237 245 256 243 221 255 258 230 223 229 231 217 214 227 214 226 242 237 233 236 227 245 231 220 243 225 240 258 238 217 235 236 237 260 247 230 279 217 226 277 244 206 232 234 204 232 249 259 245 222 209 226 228 236 244 224 223 263 232 239 227 215 245 226 243 223 208 236 245 233 222 239 238 226 234 232 220 240 220 246 233 248 260 223 238 271 242 250 239 206 226 245 245 235 221 240 283 235 236 231 243 220 224 231 218 218 229 209 240 224 208 248 206 235 214 211 230 214 230 222 239 220 226 218 246 264 242 234 197 246 264 223 233 255 245 230 258 243 213 195 247 229 228 244 233 219 216 217 234 191 244 256 226 232 192 259 244 214 213 228 239 236 242 203 206 220 225 221 227 242 216 247 216 234 214 214 238 228 219 229 197 268 205 242 208 214 227 218 231 247 215 216 245 246 196 235 228 272 221 249 223 230 222 215 216 217 218 247 238 257 244 250 225 266 269 240 236 238 216 238 233 239 237 218 255 217 216 242 248 197 243 224 261 239 235 218 250 246 250 241 246 219 247 241 257 249 235 220 213 223 229 235 229 217 246 235 238 249 242 248 250 220 241 236 203 240 239 220 259 220 246 219 237 227 256 218 234 228 227 238 284 249 231 258 290 233 238 225 222 237 238 278 267 196 223 216 247 267 257 249 225 247 265 263 221 232 250 261 260 261 223 261 219 250 234 230 239 228 247 238 257 261 258 239 229 233 249 235 241 263 235 244 224 233 240 262 244 238 262 219 216 211 218 215 200 240 231 218 197 259 224 220 226 268 229 217 259 262 266 243 206 264 221 222 239 216 250 225 248 220 244 237 220 246 233 226 210 227 236 249 245 223 210 225 212 263 246 231 267 238 232 212 240 227 223 216 213 211 248 203 231 230 190 224 242 250 225 263 247 220 234 219 222 257 235 229 263 231 213 226 235 214 216 231 226 241 246 241 241 232 218 216 231 212 228 233 218 260 267 246 241 229 226 217 264 223 263 235 273 227 263 266 230 194 242 230 222 225 222 215 257 224 263 230 243 229 223 226 230 214 232 240 239 221 219 223 236 242 258 234 223 217 207 219 248 247 229 236 243 232 233 232 238 258 227 241 237 222 223 243 215 214 240 226 240 256 243 210 232 236 260 226 236 255 203 218 239 232 257 258 230 236 238 232 263 228 249 232 248 226 240 228 242 262 236 247 241 221 243 243 236 244 248 266 261 243 224 239 248 230 222 217 197 242 226 206 235 222 262 199 222 228 215 210 237 244 199 262 267 219 214 227 220 245 199 237 228 233 255 207 244 259 209 211 240 214 250 240 275 215 219 219 228 235 234 241 255 255 215 241 225 265 241 235 223 227 265 234 233 225 245 232 206 225 256 263 212 228 237 225 238 237 234 215 218 264 231 219 207 229 250 228 221 237 238 224 224 234 218 207 222 226 239 215 259 235 221 243 230 221 226 244 216 233 231 239 247 214 239 236 220 214 229 250 220 231 232 220 264 256 203 205 246 265 234 232 208 223 245 229 220 242 245 236 224 237 219 220 240 245 270 231 224 249 200 226 223 243 225 220 214 229 222 227 244 257 274 209 244 198 247 212 244 214 225 214 247 224 243 217 240 224 226 224 214 219 235 213 214 266 221 220 201 239 235 230 233 257 226 229 227 264 240 248 240 218 218 241 240 245 249 236 243 243 230 212 246 227 235 217 222 266 229 195 225 216 235 257 219 230 209 277 223 205 224 234 259 244 220 227 244 248 244 229 230 218 245 247 231 234 259 266 212 257 237 248 214 226 225 224 231 232 230 222 234 224 249 217 246 232 249 204 235 243 222 223 222 239 261 255 220 267 214 230 231 237 242 230 268 235 224 246 223 243 239 270 249 246 215 231 220 211 266 231 198 223 247 195 227 223 226 236 231 237 200 242 236 208 225 221 242 261 223 234 265 223 225 235 220 221 238 217 258 219 231 255 211 222 225 222 246 225 242 243 224 249 261 235 219 199 248 224 247 224 224 213 212 223 257 221 227 225 236 248 229 238 219 241 246 228 246 237 212 214 246 242 215 233 209 216 257 200 233 248 226 220 224 224 242 224 236 238 272 230 226 256 236 238 217 232 241 243 255 230 260 243 239 230 207 205 213 212 258 205 228 235 237 206 232 221 240 228 212 237 225 215 230 217 258 243 250 223 225 228 238 230 202 237 226 228 221 231 220 229 247 241 228 247 232 223 240 231 223 225 234 258 230 216 261 191 237 242 209 225 245 227 224 218 229 211 257 249 238 224 235 231 224 258 224 241 234 206 243 196 224 224 222 243 221 258 226 215 229 222 226 263 229 248 230 240 235 219 235 221 235 224 247 215 238 248 275 234 206 203 231 216 240 234 226 243 226 242 216 219 242 228 220 238 235 256 224 209 227 216 224 205 236 215 233 229 262 230 224 238 233 215 235 223 230 257 209 204 238 228 206 244 237 226 250 215 211 234 247 201 223 248 229 210 248 231 243 226 244 249 234 222 233 198 240 255 241 225 204 229 236 207 220 236 227 207 243 220 236 240 224 277 239 225 234 246 260 213 221 218 238 229 226 228 211 223 230 245 226 230 213 214 228 222 243 238 238 208 221 223 239 232 221 220 243 244 224 239 216 256 220 234 234 231 219 247 231 242 215 244 233 238 237 214 255 218 219 210 214 216 248 215 236 228 216 238 188 213 219 222 229 239 233 218 255 228 225 222 196 206 235 263 207 239 229 259 230 221 259 227 242 238 237 233 231 244 246 220 261 235 243 231 231 231 264 212 230 201 221 218 209 221 222 218 227 218 233 248 230 217 239 222 231 230 204 248 224 247 213 230 221 241 228 219 239 236 220 267 217 236 228 242 215 235 239 256 248 226 247 265 241 213 214 245 206 221 245 224 237 217 249 269 230 238 235 210 240 224 245 235 266 272 231 255 240 225 216 222 257 236 208 214 207 212 243 231 201 219 221 245 238 244 226 269 259 248 233 231 267 234 218 267 259 235 235 270 227 232 228 227 239 268 212 225 263 243 230 230 228 234 229 238 227 244 241 209 210 191 215 232 277 225 230 247 246 207 229 215 229 212 212 223 226 233 212 245 266 225 234 225 202 267 194 227 249 234 228 215 245 223 228 225 226 257 246 215 213 246 256 236 209 244 232 230 220 231 242 214 233 241 193 219 209 217 217 223 232 242 223 226 200 226 217 247 211 242 209 207 223 257 238 244 241 216 236 231 263 264 214 245 237 233 244 198 236 261 231 233 236 235 224 222 274 217 227 237 222 246 231 229 256 242 234 234 259 230 234 224 235 222 221 226 250 204 226 233 230 240 232 245 236 199 246 228 248 262 221 229 244 228 270 271 250 212 222 244 247 242 221 240 262 193 219 189 235 198 246 201 216 210 220 255 234 211 218 225 206 258 221 234 240 214 232 241 269 234 228 249 240 242 244 233 262 234 220 235 209 221 222 249 235 249 205 243 232 237 257 231 230 237 217 236 231 255 228 234 224 215 245 215 208 210 259 235 235 222 243 275 265 228 238 235 198 238 215 224 200 265 248 211 229 212 220 229 235 220 201 268 217 233 239 262 228 257 240 237 232 229 270 241 263 239 246 234 235 242 259 191 222 228 220 247 235 231 225 216 200 221 205 227 236 247 239 219 243 213 225 221 214 230 227 247 209 245 216 222 213 228 222 213 249 222 231 224 257 216 235 217 210 219 215 256 240 216 236 225 245 234 236 229 236 239 243 224 241 263 214 249 238 215 243 231 229 226 232 207 229 215 221 234 225 235 221 209 246 224 202 215 256 235 202 259 221 212 242 245 219 247 256 228 237 239 242 266 229 234 244 246 208 222 230 221 220 232 219 236 208 229 270 245 216 226 214 212 258 249 246 221 225 239 221 223 222 262 211 201 239 232 264 228 219 255 219 242 226 189 211 228 235 225 204 212 224 228 240 223 227 236 193 218 228 218 229 222 238 256 237 244 219 219 208 232 231 221 237 207 235 228 229 214 215 218 258 204 236 220 232 230 273 223 211 228 226 229 227 268 233 241 222 196 210 224 241 255 242 229 235 241 219 222 212 231 225 240 214 215 230 214 206 215 228 212 225 244 241 211 211 235 223 228 231 233 239 210 197 231 249 242 218 220 239 249 234 235 211 238 245 216 224 219 231 237 226 227 241 230 230 210 223 214 240 237 237 256 267 264 232 216 242 238 218 224 250 215 230 240 212 231 219 237 246 243 220 237 236 216 223 240 266 216 224 225 238 230 242 238 218 249 215 220 231 259 232 242 227 232 241 206 256 258 235 232 206 235 209 203 245 236 202 225 212 220 226 233 232 231 230 215 266 229 224 197 270 229 214 214 234 223 206 227 231 266 238 239 229 242 222 221 225 243 242 234 248 227 241 255 255 243 248 229 245 221 221 214 212 218 229 242 217 222 206 262 233 214 265 240 244 246 264 222 261 271 215 206 229 247 243 211 262 262 255 238 218 243 231 231 265 248 231 220 238 275 231 257 230 243 221 235 240 235 250 230 258 234 247 266 224 260 247 226 258 231 237 248 255 261 219 218 266 223 240 259 269 226 265 275 261 238 259 266 257 265 264 261 267 282 243 279 255 222 266 243 292 244 277 296 267 257 277 273 245 267 249 261 281 238 290 283 248 273 268 262 261 249 258 263 274 272 263 271 271 288 260 244 227 269 244 247 232 264 234 238 265 268 221 259 261 246 282 243 235 260 248 247 255 234 243 249 223 265 232 274 249 219 258 268 233 229 241 265 220 205 231 260 220 220 268 235 236 241 237 246 242 232 223 257 224 219 228 232 242 245 248 259 234 209 242 228 250 212 229 225 229 278 255 237 234 244 239 223 219 212 258 260 230 241 248 262 256 231 217 234 275 243 250 232 217 219 237 195 226 246 235 269 233 233 220 267 230 214 210 239 239 229 259 233 241 263 216 203 267 229 246 230 212 216 246 226 239 226 244 215 221 215 234 224 239 216 221 245 222 227 242 240 236 228 242 249 260 225 237 236 233 243 256 223 246 238 246 217 230 216 241 257 268 245 229 238 200 224 212 249 219 248 276 225 239 221 221 250 222 207 242 223 239 222 262 220 231 247 205 201 223 214 204 230 222 246 255 220 236 239 226 239 236 221 215 218 238 238 211 226 223 236 219 216 211 268 230 244 236 230 220 222 271 245 237 199 222 243 224 214 237 212 221 227 220 224 237 226 230 238 238 232 244 225 260 203 248 239 225 237 228 221 247 225 222 197 245 212 236 228 231 217 212 213 229 214 206 240 222 230 234 230 255 212 240 222 241 207 228 263 242 220 268 256 239 238 223 287 211 245 220 245 245 234 202 237 207 229 207 255 263 217 229 198 231 215 249 195 256 222 238 224 245 218 228 227 196 237 247 232 219 256 248 226 246 234 220 219 227 211 229 210 236 244 223 225 223 205 227 242 259 224 230 213 199 224 224 241 217 259 235 217 210 226 224 216 220 221 229 221 226 242 203 230 229 221 242 242 245 238 230 217 216 224 213 257 223 219 235 237 241 236 214 217 216 227 243 239 220 212 244 207 241 210 208 228 199 211 238 231 222 218 193 237 227 233 222 204 204 233 274 219 229 207 213 239 217 221 192 225 222 201 234 208 257 248 206 212 239 226 245 220 223 230 222 211 228 228 229 212 245 199 228 236 243 220 244 239 230 234 211 218 241 229 240 219 210 233 248 214 260 214 228 221 264 213 233 234 235 223 220 212 212 241 225 232 236 232 238 255 201 220 225 225 228 207 242 226 229 211 233 236 200 231 217 244 226 245 207 244 245 221 188 236 221 226 240 237 215 205 237 215 224 242 216 212 226 248 224 216 197 230 242 201 229 233 212 213 223 209 231 258 227 222 231 260 242 239 229 240 226 239 210 246 244 227 246 234 221 248 248 233 236 214 230 224 224 248 203 227 220 257 236 263 246 220 240 242 218 238 176 242 217 218 204 238 241 236 209 257 238 241 216 219 228 210 210 220 220 242 214 284 219 248 224 206 196 193 203 219 235 211 219 227 212 228 240 235 228 213 235 189 250 218 241 259 223 263 242 233 226 211 234 222 216 245 234 247 234 218 234 263 229 218 226 227 237 248 208 202 201 228 213 201 238 247 219 211 218 218 232 256 204 220 232 249 247 209 200 219 220 237 238 218 216 244 225 237 239 218 211 220 220 216 218 242 240 194 240 228 214 237 217 234 259 224 229 213 204 219 233 219 216 246 249 225 230 226 205 243 216 210 246 219 206 213 229 228 209 263 245 276 221 215 232 229 228 226 261 244 198 229 231 243 225 260 219 213 224 218 231 241 227 233 217 210 223 238 231 232 224 217 220 193 236 237 266 241 239 228 243 243 240 219 228 228 221 236 224 213 221 228 242 232 225 194 233 224 245 245 264 228 246 248 222 223 216 218 227 211 241 222 248 246 233 260 247 240 211 224 192 241 223 244 236 223 233 232 224 243 241 227 224 220 224 234 200 246 267 227 215 218 260 238 218 223 216 227 234 233 233 249 230 248 233 239 239 230 230 225 219 223 219 270 228 228 235 212 223 246 245 238 198 217 231 214 256 231 240 219 228 243 240 235 211 204 230 219 227 205 245 243 220 243 208 215 267 237 245 216 233 216 220 218 235 239 219 215 218 203 218 208 238 247 255 220 220 259 221 207 232 231 240 191 219 221 240 249 241 211 192 207 216 222 246 238 206 229 201 220 233 221 207 255 233 223 227 224 225 235 235 224 232 236 238 224 215 222 223 242 230 214 222 198 236 208 220 225 207 226 262 215 197 206 236 230 205 200 206 274 174 230 210 233 228 232 221 207 221 255 255 231 233 220 223 200 212 240 231 216 220 221 228 215 236 233 194 225 221 238 241 238 233 219 236 227 236 221 235 248 230 217 220 231 229 233 238 210 223 241 216 219 225 219 241 232 220 242 218 216 256 221 256 244 235 233 235 236 205 216 225 214 225 212 235 212 218 260 230 219 229 232 272 206 264 216 203 228 231 217 217 245 201 241 231 258 236 242 224 237 210 249 218 247 205 245 217 223 205 213 218 202 224 236 233 247 244 208 273 229 207 231 230 217 242 224 206 231 258 228 225 229 244 205 239 233 210 233 216 203 213 232 219 236 261 225 223 217 233 235 261 227 212 213 227 248 231 226 227 192 228 224 216 237 216 259 227 229 230 211 257 244 236 224 269 207 233 237 226 235 222 222 275 216 215 243 214 226 243 241 219 230 211 206 222 257 278 244 240 227 229 220 247 241 238 241 211 219 226 213 244 232 243 222 227 238 237 214 233 216 237 246 218 212 262 234 258 224 243 213 222 221 240 204 215 239 247 231 256 242 231 257 223 189 211 263 216 238 206 200 231 215 202 238 207 230 232 224 226 232 227 228 208 214 208 208 239 238 248 233 214 229 238 215 220 217 226 213 220 225 226 207 203 201 237 227 231 201 233 250 233 235 243 223 246 230 239 217 234 229 244 210 232 205 222 229 208 230 236 217 199 244 241 238 227 228 219 219 221 272 203 213 212 218 221 244 204 218 217 247 196 206 235 235 229 240 241 223 202 233 182 233 250 237 228 272 234 213 219 209 215 238 240 222 220 260 233 216 224 243 227 236 248 223 240 209 221 220 230 248 231 234 239 224 256 210 196 215 232 205 247 234 220 203 242 186 231 217 226 243 235 245 220 235 235 203 263 233 214 213 222 229 265 235 230 206 255 220 225 239 230 235 224 211 227 242 218 260 224 222 229 234 224 232 218 218 232 219 248 225 232 228 209 231 214 231 214 237 213 214 232 231 234 227 223 240 209 242 236 217 195 224 239 244 225 223 205 204 219 230 241 214 224 233 234 261 232 238 247 266 204 214 208 256 223 231 246 244 242 225 226 222 244 204 206 212 223 230 231 256 227 244 224 265 247 199 222 235 226 201 216 200 242 281 268 233 281 210 223 217 250 226 221 244 215 240 218 263 220 228 255 216 199 231 220 243 238 230 228 237 224 223 223 241 249 224 206 195 231 239 241 212 221 225 240 226 230 231 207 237 201 237 214 236 257 239 221 248 210 235 245 258 239 208 217 248 223 223 226 200 218 231 241 233 213 258 231 267 229 263 266 211 232 243 244 219 222 225 248 239 245 203 250 207 228 264 264 216 225 216 207 264 221 247 227 236 219 219 237 233 270 244 227 230 212 244 234 260 224 223 239 209 245 224 225 235 228 235 214 244 214 255 242 228 257 221 237 248 259 228 213 246 234 208 247 232 248 245 218 211 224 203 225 206 214 243 247 222 230 240 222 199 240 232 233 259 195 224 226 226 218 262 242 217 202 235 229 272 249 256 257 273 238 257 228 236 223 215 247 212 208 246 224 263 246 235 221 228 233 246 260 237 206 230 248 273 261 249 220 260 245 241 219 243 289 211 239 225 256 218 262 248 241 257 241 220 244 229 221 257 233 219 279 222 244 222 240 245 262 233 220 242 260 261 238 249 234 220 231 247 239 232 209 257 241 243 258 240 260 225 268 227 240 216 218 244 234 220 246 257 267 242 231 206 231 238 239 219 236 264 229 206 218 241 208 244 230 213 217 218 229 214 232 200 218 221 249 233 259 238 228 206 226 244 209 237 231 219 269 240 222 221 238 207 231 208 226 200 248 260 232 229 240 225 218 218 247 225 242 225 235 227 211 239 234 237 259 229 226 226 235 240 226 234 282 224 195 194 224 232 201 234 218 219 240 230 239 221 225 231 228 239 230 203 218 220 233 236 223 235 196 205 229 241 238 232 219 189 205 225 230 226 249 229 265 227 206 255 237 228 213 220 206 203 241 237 227 255 229 239 229 211 223 194 247 211 249 207 241 203 248 249 235 224 233 209 234 225 224 222 244 256 237 234 229 236 235 202 235 233 222 217 193 233 232 212 198 245 278 218 237 230 211 231 225 223 218 246 242 231 209 241 224 204 242 259 246 242 213 206 223 220 243 240 227 232 265 209 226 222 248 235 233 209 229 261 236 223 199 203 215 228 256 214 230 224 241 215 205 198 225 264 219 226 246 205 211 238 224 239 212 228 212 210 233 226 228 244 224 211 227 212 224 207 260 221 218 216 224 232 238 229 216 198 224 214 235 208 244 213 246 250 241 227 223 235 213 228 239 240 218 239 217 238 199 223 197 258 221 217 230 225 232 267 240 223 238 235 245 220 217 217 231 222 237 218 225 219 221 232 206 205 212 221 222 205 209 231 220 219 221 240 223 209 238 234 231 242 221 239 248 237 231 203 225 246 231 222 202 217 239 240 211 202 261 218 231 235 218 246 227 256 240 229 228 226 227 234 230 232 218 206 229 215 209 221 213 235 244 236 238 220 243 216 193 196 218 221 219 216 220 235 243 202 204 219 219 236 241 218 214 232 219 223 228 226 257 214 257 255 223 228 228 214 243 222 217 225 218 225 222 262 226 216 215 258 242 228 255 231 194 261 208 223 223 223 217 238 221 238 246 220 233 264 220 219 228 242 211 237 219 212 209 220 245 230 222 262 204 218 209 213 210 210 211 185 222 235 246 242 249 229 221 240 212 216 236 231 215 211 236 234 202 219 256 218 222 231 238 209 230 211 215 219 217 217 232 259 210 270 264 211 231 211 237 223 195 219 229 227 221 267 219 228 243 224 204 219 240 233 219 204 197 235 215 217 245 224 214 216 233 217 215 216 228 216 191 211 201 249 200 226 217 231 230 214 226 224 230 234 210 230 231 199 210 231 234 204 240 217 218 242 206 241 224 243 242 224 221 222 246 220 236 217 203 228 255 214 231 240 237 266 231 224 235 218 231 269 206 258 224 203 250 231 229 240 234 218 210 233 193 219 228 228 228 225 258 211 219 238 227 248 229 216 230 213 226 234 193 237 221 247 231 220 233 240 248 217 231 225 220 237 227 250 231 249 228 197 218 242 213 220 239 238 230 247 215 218 250 241 231 194 229 225 230 230 242 244 221 221 231 217 233 269 245 237 237 233 235 213 243 260 236 238 204 236 229 213 229 225 225 232 201 229 234 226 236 220 248 221 225 226 221 206 220 216 211 225 260 267 238 215 244 209 231 228 233 227 240 231 210 220 213 220 274 212 219 218 238 228 247 232 230 226 225 230 214 230 263 220 217 235 244 230 215 206 238 218 246 247 244 233 222 233 217 234 221 225 240 219 234 263 206 224 238 211 235 221 243 221 203 230 235 227 250 226 230 226 225 236 249 226 216 238 250 236 229 236 227 222 215 217 216 220 221 240 249 234 232 225 227 212 234 221 206 196 226 235 249 193 217 231 229 202 239 229 208 229 240 221 227 236 226 260 243 259 247 217 221 218 235 233 258 220 234 248 237 237 249 244 231 261 224 228 232 211 258 214 228 213 202 225 243 212 203 235 216 207 216 219 242 225 228 240 218 226 215 215 225 234 208 244 249 229 236 232 255 189 235 215 207 220 239 222 221 218 209 227 228 223 212 242 237 271 213 215 214 215 234 220 215 225 235 243 259 246 221 232 204 245 229 230 237 223 207 220 237 211 215 201 236 233 215 219 231 217 214 233 215 247 235 190 221 213 239 221 236 202 256 223 183 236 218 259 227 243 213 221 212 224 207 243 218 238 206 221 222 267 205 197 199 216 237 235 246 217 243 217 212 231 235 226 217 234 220 262 210 196 220 204 226 200 222 246 214 225 257 238 243 188 260 233 255 259 273 229 255 217 232 233 219 196 212 243 236 229 249 239 223 217 241 217 231 233 212 230 229 205 231 222 237 222 261 241 234 231 238 238 236 229 224 264 259 220 211 231 224 233 198 224 225 205 221 231 231 228 247 202 206 245 238 202 210 236 242 258 271 227 211 229 268 236 229 240 236 221 240 210 236 232 239 238 227 260 214 234 229 244 213 235 205 268 229 204 246 241 238 242 219 246 219 236 216 238 225 208 228 223 246 210 215 225 216 247 247 239 221 237 229 239 231 220 206 207 240 249 228 233 222 244 238 223 216 230 258 222 224 202 226 225 229 256 232 230 210 238 232 224 233 245 250 210 217 236 258 228 245 236 228 201 244 212 231 238 247 241 223 204 224 225 226 219 234 247 249 233 221 266 245 229 230 228 212 214 237 227 224 246 233 207 259 248 238 232 222 225 229 216 238 235 226 215 235 247 226 195 238 217 267 226 255 243 257 256 256 240 227 208 211 212 211 217 241 256 222 215 228 262 222 233 212 243 203 215 231 249 229 235 242 235 210 227 227 214 208 230 229 240 228 217 257 242 213 229 239 264 245 226 233 222 220 210 244 246 244 227 200 263 212 215 225 223 242 242 205 265 223 228 271 223 219 211 219 220 263 199 261 196 229 223 270 225 224 222 231 234 204 205 209 244 220 226 226 247 221 222 228 196 215 225 237 237 238 235 243 214 245 230 222 225 230 258 246 207 232 237 228 213 231 211 243 226 221 233 230 206 238 245 222 275 225 246 229 216 235 213 229 235 238 237 218 226 243 220 256 202 223 208 255 235 241 212 227 233 247 240 215 203 234 270 269 213 244 226 241 248 231 261 246 216 238 237 207 236 229 246 230 230 232 238 229 275 226 232 234 258 192 222 257 209 212 239 218 235 238 239 241 223 239 225 206 224 220 255 238 246 222 226 233 243 207 230 228 245 221 223 233 223 224 214 219 221 227 223 218 217 222 231 237 228 247 255 229 236 245 206 212 208 231 248 218 248 248 229 229 231 231 280 230 242 223 213 239 234 220 217 218 229 226 209 225 221 221 241 227 240 214 223 243 210 227 225 213 239 226 187 224 210 221 203 231 225 238 209 228 224 228 216 234 207 247 237 240 233 208 266 243 233 206 210 206 218 243 230 223 225 216 230 218 220 240 241 202 225 246 230 236 210 217 209 235 241 206 237 217 235 229 220 243 217 228 230 226 220 238 236 222 225 216 214 234 246 220 230 212 239 225 232 259 213 219 255 232 235 219 222 197 262 229 247 260 222 211 260 208 216 234 236 199 236 258 236 238 234 234 263 232 231 234 211 241 232 225 258 211 222 221 218 224 202 262 262 221 206 248 236 215 246 225 263 221 201 215 227 246 206 244 231 218 221 217 244 250 232 257 227 248 240 230 241 226 230 228 225 195 218 243 226 276 226 238 225 220 250 208 224 244 242 227 243 260 228 261 232 257 223 200 226 223 225 230 206 262 226 230 231 227 209 222 267 209 258 259 219 212 236 240 241 217 224 218 234 234 243 235 248 262 246 242 244 227 230 249 243 248 235 208 244 248 235 261 256 227 261 239 221 228 270 234 245 238 230 230 224 242 243 233 256 235 250 255 233 227 226 225 269 246 211 265 263 240 238 228 241 245 239 220 227 261 266 242 240 246 249 243 220 226 229 232 227 237 233 198 241 222 226 246 245 255 239 218 262 213 211 246 220 238 279 249 242 238 212 247 236 264 262 221 259 260 239 246 245 226 241 255 267 243 225 238 264 235 235 259 196 235 263 231 231 264 222 249 264 207 259 226 235 233 235 246 234 273 206 270 258 241 263 232 226 234 240 220 233 246 262 238 245 236 232 247 230 235 244 233 237 226 256 222 235 264 245 232 244 258 245 229 243 223 255 258 195 258 231 238 219 213 262 245 230 222 239 234 216 235 233 263 240 246 223 229 212 228 242 228 228 246 246 238 216 219 209 226 237 256 226 208 247 241 216 245 245 202 217 229 224 235 196 238 199 232 227 219 247 211 245 202 195 236 242 218 196 212 219 221 234 242 229 235 244 229 221 248 224 236 202 229 234 212 234 218 219 227 219 234 223 208 237 190 214 221 210 233 211 217 247 213 198 235 199 236 228 242 255 261 244 198 220 222 223 258 217 230 230 236 235 237 218 244 265 201 235 237 219 238 248 221 230 235 217 249 244 190 234 219 238 226 237 191 212 217 232 231 210 258 227 225 213 222 238 255 216 220 201 233 258 226 232 224 237 218 219 255 211 216 261 218 199 224 228 228 220 234 212 260 227 224 229 229 222 264 234 203 262 193 225 232 212 220 228 226 226 218 212 238 194 233 241 213 201 220 228 230 211 223 218 224 222 221 236 262 247 228 212 218 242 224 230 235 214 228 235 229 229 227 212 213 214 215 267 224 226 236 237 236 232 257 215 225 224 240 248 228 222 205 205 231 221 234 206 230 241 203 234 234 242 206 219 237 204 232 258 230 226 224 218 239 206 207 257 235 241 208 207 220 210 198 236 211 234 214 264 223 205 229 245 231 218 208 210 202 212 203 237 215 227 220 204 271 222 216 217 234 236 248 212 235 221 218 207 231 226 245 231 209 206 206 228 242 231 215 231 211 194 206 242 218 209 223 233 225 197 249 239 235 230 220 221 240 219 223 224 219 212 227 223 223 212 222 246 240 210 189 208 248 216 198 246 221 196 219 238 228 223 243 244 240 218 193 247 222 238 220 242 227 231 196 232 235 229 259 229 220 202 221 231 237 216 221 199 195 203 218 231 224 212 208 217 241 182 231 231 204 206 237 232 264 206 227 226 207 198 215 243 274 216 219 227 229 231 226 189 235 224 219 245 215 241 221 228 244 230 227 288 257 232 229 241 246 209 231 209 192 250 228 235 237 266 198 204 223 198 217 211 232 219 245 243 241 267 212 223 225 257 246 222 225 228 205 228 243 238 227 229 225 227 220 217 231 263 198 239 223 206 229 203 217 234 224 257 212 213 228 211 235 207 260 211 264 237 221 212 219 227 205 233 248 205 240 230 231 202 200 234 243 223 216 220 256 228 230 239 206 224 246 269 230 238 242 215 207 240 220 193 239 242 218 206 233 214 214 227 222 225 240 219 225 229 247 200 204 235 237 241 233 198 224 244 264 218 244 223 239 221 231 208 229 225 238 242 225 268 209 234 240 234 260 192 196 232 205 205 247 230 231 235 202 235 235 232 220 213 232 238 260 235 223 233 256 235 233 211 213 256 238 231 231 223 212 202 230 231 267 255 207 243 228 219 227 231 239 243 229 258 232 216 226 213 223 208 220 224 208 221 248 222 238 206 231 238 241 238 210 242 207 242 233 235 236 221 237 209 198 228 196 226 196 206 259 205 209 217 234 238 235 238 219 222 217 212 231 256 232 255 240 219 264 239 223 237 219 222 222 212 225 213 236 221 242 239 190 219 228 234 202 222 216 219 238 209 239 220 236 228 245 218 235 215 226 213 224 237 237 202 233 234 209 229 219 214 226 236 235 215 222 194 248 214 193 226 233 234 244 247 230 229 223 226 241 213 239 216 242 258 232 221 212 229 267 220 236 242 212 217 224 246 238 230 241 237 225 224 187 220 221 227 237 208 226 225 226 225 232 222 228 217 225 225 218 231 215 212 198 231 211 228 239 238 236 212 235 244 224 210 215 228 232 232 233 222 240 222 212 258 218 225 217 216 242 196 228 207 213 237 217 220 181 211 204 221 212 232 246 232 204 204 189 229 223 209 215 239 243 239 219 246 249 231 219 209 223 266 211 204 236 224 221 242 209 249 237 234 233 219 193 209 218 228 205 228 215 232 221 244 229 227 205 227 225 214 217 211 233 201 204 257 272 232 220 220 227 213 223 225 243 244 231 213 212 241 197 222 244 227 226 235 227 211 229 234 197 239 201 212 223 237 217 225 224 208 232 218 223 220 240 199 219 249 221 230 208 215 202 223 242 227 201 196 264 245 204 219 204 228 199 227 216 235 227 233 228 225 233 237 235 248 214 204 228 216 186 208 243 234 256 210 238 228 239 214 229 247 237 206 209 218 232 237 238 210 221 205 235 231 218 201 199 232 247 239 220 248 220 224 255 226 217 217 236 224 223 238 223 198 213 223 230 225 225 218 205 200 243 230 205 222 202 212 196 207 221 213 238 201 227 217 225 225 216 229 222 225 217 213 223 197 233 227 231 232 212 235 207 259 221 226 237 216 225 223 243 207 217 262 207 214 213 235 222 212 244 205 237 230 216 224 221 215 194 202 236 242 257 213 222 212 206 210 238 225 212 230 220 235 233 210 234 237 227 209 223 205 227 238 223 221 214 228 228 243 224 201 210 261 220 221 242 201 221 230 222 233 245 221 234 221 217 218 222 211 209 243 262 204 221 217 238 210 224 231 224 216 225 237 239 232 236 219 223 224 213 219 233 193 224 238 228 237 238 203 228 222 217 238 219 233 238 226 228 206 211 224 211 261 240 229 188 225 210 231 209 228 202 235 248 235 197 215 220 255 220 236 233 218 213 222 226 211 231 222 230 245 208 235 236 231 222 230 226 249 239 235 241 233 215 201 245 223 223 217 229 263 222 218 210 245 238 240 244 233 219 223 206 213 215 219 205 215 207 206 224 228 200 233 215 226 227 226 208 236 210 207 218 205 238 241 226 239 245 246 234 228 216 243 213 215 217 219 234 199 229 235 221 271 238 215 259 226 218 213 242 259 213 223 222 238 227 240 225 267 234 228 231 210 208 211 232 221 197 242 258 226 240 213 238 230 235 216 236 214 227 223 222 210 215 216 224 223 197 223 204 206 232 217 211 211 246 216 204 207 213 249 220 217 227</counts>
			</dataPoints>
		</scan>
	</xrdMeasurement>
</xrdMeasurements>