File: data/XRD/XG-Vakuum/XG-600/W6822-1C_XG_Vakuum_600.xrdml
<xrdMeasurements xmlns="http://www.xrdml.com/XRDMeasurement/2.1" xmlns:xsi="http://www.w3.org/2001/XMLSchema-instance" xsi:schemaLocation="http://www.xrdml.com/XRDMeasurement/2.1 http://www.xrdml.com/XRDMeasurement/2.1/XRDMeasurement.xsd" status="Completed">
	<comment>
		<entry>Configuration=Factory configuration, Owner=User-1, Creation date=7/8/2013 4:01:53 PM</entry>
		<entry>Goniometer=PW3050/65 (Theta/2Theta); Minimum step size 2Theta:0.0001; Minimum step size Omega:0.0001</entry>
		<entry>Sample stage=MRD Cradle; Minimum step size Phi:0.01; Minimum step size Chi:0.01; Minimum step size X:0.01; Minimum step size Y:0.01; Minimum step size Z:0.001</entry>
		<entry>Diffractometer system=XPERT-PRO</entry>
		<entry>Measurement program=C:\PANalytical\Data Collector\Programs\Jorrit\2thom\_absolute_2th-om_10-130deg_PIXscan_56min.xrdmp, Identifier={15BCCF57-2807-42BD-B5B9-ECC0B3DC9284}</entry>
		<entry>Batch program=C:\PANalytical\Data Collector\Programs\SimonL\batch4x_2thom_10-130°_z9.1_x0,10,20,30_y0_57min.xrdmp, Identifier={EED9823A-2BEB-424C-9252-345C4EF2834A}</entry>
	</comment>
	<sample type="To be analyzed">
		<id></id>
		<name></name>
		<preparedBy></preparedBy>
	</sample>
	<xrdMeasurement measurementType="Scan" status="Completed" sampleMode="Reflection">
		<comment>
			<entry>_absolute_2th-om_10-130deg_PIXscan_56min</entry>
			<entry>PHD Lower Level = 4.83 (keV), PHD Upper Level = 11.27 (keV)</entry>
		</comment>
		<usedWavelength intended="K-Alpha 1">
			<kAlpha1 unit="Angstrom">1.5405980</kAlpha1>
			<kAlpha2 unit="Angstrom">1.5444260</kAlpha2>
			<kBeta unit="Angstrom">1.3922500</kBeta>
			<ratioKAlpha2KAlpha1>0.5000</ratioKAlpha2KAlpha1>
		</usedWavelength>
		<incidentBeamPath>
			<radius unit="mm">320.00</radius>
			<xRayTube id="1010048" name="Empyrean Cu LFF HR (9430 033 7310x) DK442154">
				<tension unit="kV">40.0</tension>
				<current unit="mA">40.0</current>
				<anodeMaterial>Cu</anodeMaterial>
				<focus type="Line">
					<length unit="mm">12.0</length>
					<width unit="mm">0.4</width>
					<takeOffAngle unit="deg">4.2</takeOffAngle>
				</focus>
			</xRayTube>
			<xRayMirror id="27010001" name="Inc. Beam Cu W/Si (parabolic MRD)" hybrid="false">
				<crystal type="Graded" shape="Parabolic">W/Si</crystal>
				<acceptanceAngle unit="deg">0.800</acceptanceAngle>
				<length unit="mm">60.0</length>
			</xRayMirror>
			<sollerSlit id="21010002" name="Soller slits 0.04 rad.">
				<opening unit="rad">0.0400</opening>
			</sollerSlit>
			<mask id="22030008" name="Fixed mask 4 mm">
				<distanceToSample unit="mm">220.00</distanceToSample>
				<width unit="mm">4.00</width>
			</mask>
			<divergenceSlit id="22010007" name="Fixed slit 1/8°" xsi:type="fixedDivergenceSlitType">
				<distanceToSample unit="mm">220.00</distanceToSample>
				<height unit="mm">0.19</height>
			</divergenceSlit>
		</incidentBeamPath>
		<diffractedBeamPath>
			<radius unit="mm">320.00</radius>
			<sollerSlit id="21010002" name="Soller slits 0.04 rad.">
				<opening unit="rad">0.0400</opening>
			</sollerSlit>
			<receivingSlit id="22010001" name="Fixed slit 4°">
				<height unit="mm">5.88</height>
			</receivingSlit>
			<detector id="7010017" name="PIXcel3D 1x1 detector" xsi:type="areaDetectorType">
				<phd unit="%">
					<lowerLevel>30.0</lowerLevel>
					<upperLevel>70.0</upperLevel>
				</phd>
				<mode>Scanning</mode>
				<activeChannelsEquatorial>255</activeChannelsEquatorial>
				<activeChannelsAxial>255</activeChannelsAxial>
				<pitchEquatorial unit="mm">0.05500</pitchEquatorial>
				<pitchAxial unit="mm">0.05500</pitchAxial>
				<readOutPeriod unit="seconds">0.135</readOutPeriod>
			</detector>
		</diffractedBeamPath>
		<scan appendNumber="0" mode="Continuous" scanAxis="2Theta-Omega" status="Completed">
			<header>
				<startTimeStamp>2024-10-08T20:47:49+02:00</startTimeStamp>
				<endTimeStamp>2024-10-08T21:43:55+02:00</endTimeStamp>
				<author>
					<name>PRO-MRD</name>
				</author>
				<source>
					<applicationSoftware version="6.1b">Data Collector</applicationSoftware>
					<instrumentControlSoftware version="7.0E 20130304">XPERT-PRO</instrumentControlSoftware>
					<instrumentID>0000000011142674</instrumentID>
				</source>
			</header>
			<dataPoints>
				<positions axis="2Theta" unit="deg">
					<startPosition>9.99826193</startPosition>
					<endPosition>129.99755682</endPosition>
				</positions>
				<positions axis="Omega" unit="deg">
					<startPosition>4.99913096</startPosition>
					<endPosition>64.99877841</endPosition>
				</positions>
				<positions axis="Phi" unit="deg">
					<commonPosition>0.00</commonPosition>
				</positions>
				<positions axis="Chi" unit="deg">
					<commonPosition>0.00</commonPosition>
				</positions>
				<positions axis="X" unit="mm">
					<commonPosition>10.00</commonPosition>
				</positions>
				<positions axis="Y" unit="mm">
					<commonPosition>0.00</commonPosition>
				</positions>
				<positions axis="Z" unit="mm">
					<commonPosition>9.100</commonPosition>
				</positions>
				<commonCountingTime unit="seconds">32.895</commonCountingTime>
				<counts 417 443 425 429 413 428 402 436 410 431 444 412 417 421 431 415 464 448 426 432 445 430 452 443 422 449 438 453 420 446 451 458 438 425 440 439 397 439 421 426 405 441 467 419 410 419 418 400 472 441 456 460 451 433 423 422 451 420 462 386 403 402 438 445 434 418 416 414 396 449 410 413 386 406 379 396 417 399 486 417 415 448 424 422 417 401 420 381 407 411 395 424 396 374 436 424 422 423 446 377 418 400 428 395 390 436 403 379 442 422 415 381 361 384 377 375 411 416 416 421 422 384 400 430 411 405 406 383 383 412 373 368 420 399 420 424 389 375 421 373 389 375 385 412 438 391 391 371 407 429 403 386 363 416 381 379 424 396 427 431 385 420 400 414 399 407 387 435 431 412 411 389 411 394 400 399 376 405 402 402 400 412 406 381 387 391 395 375 376 389 396 415 392 381 368 397 390 409 335 371 375 385 375 382 370 379 380 378 390 380 406 413 421 377 407 409 365 424 361 398 380 400 369 395 363 381 384 391 389 403 359 409 389 395 347 369 371 430 377 383 418 392 354 405 368 394 362 349 365 366 367 396 411 350 366 384 367 404 412 376 376 415 383 375 392 381 410 377 352 409 377 376 379 389 376 371 369 398 357 396 359 376 380 345 410 394 375 372 392 388 371 389 362 325 377 367 364 378 416 378 382 356 372 378 372 366 426 360 363 385 374 357 355 364 369 385 387 350 376 351 369 386 337 372 358 350 362 360 348 321 388 364 332 349 386 328 352 373 373 367 348 348 355 352 393 375 363 341 366 380 402 366 357 345 345 349 354 341 313 348 360 370 352 376 364 373 309 348 351 359 355 344 338 367 356 365 384 354 361 338 386 367 309 339 320 368 356 312 346 344 347 356 345 352 348 348 349 350 346 343 325 346 356 354 341 340 362 326 330 361 394 355 356 301 380 341 368 382 344 316 351 358 367 350 326 331 348 348 336 328 317 324 351 362 364 342 330 343 340 325 329 338 335 342 332 339 328 373 334 327 321 353 357 348 332 336 328 355 361 342 337 284 301 333 349 337 341 355 316 332 343 361 336 321 350 330 357 327 349 322 308 298 313 346 358 325 364 331 337 308 337 337 330 336 327 369 347 356 349 339 350 313 309 340 344 332 363 332 313 330 349 322 320 343 330 327 315 352 338 316 295 325 360 294 314 328 324 354 328 305 289 314 337 331 322 322 327 324 333 343 290 322 318 303 305 321 303 318 306 352 319 336 316 351 345 358 331 321 308 308 297 305 345 342 342 291 321 313 298 291 323 317 343 324 341 312 320 320 321 334 333 320 313 290 348 335 299 310 328 294 335 316 324 355 304 304 328 293 287 306 299 334 323 317 351 307 311 325 311 287 295 307 368 310 298 354 304 308 314 295 331 346 302 342 314 324 319 319 291 327 322 309 293 340 300 320 306 293 330 294 337 319 331 315 309 313 291 301 324 322 339 331 330 316 318 320 314 319 290 311 327 326 333 321 308 319 295 310 298 293 341 325 343 313 301 321 323 324 329 299 307 332 320 304 297 347 328 310 295 320 339 318 323 342 305 330 295 336 342 319 288 293 300 303 319 301 334 331 314 305 317 303 307 325 314 310 314 305 314 317 323 280 303 324 305 347 323 305 306 310 313 300 317 319 300 314 316 327 288 316 286 311 282 316 312 310 330 313 283 319 300 327 336 294 383 292 304 294 279 330 300 299 310 300 336 306 281 300 315 295 307 309 287 295 307 327 295 308 313 301 335 330 311 311 320 339 304 356 344 310 306 313 287 287 304 283 308 343 288 301 273 242 304 272 286 331 290 314 287 285 300 302 318 329 343 301 288 301 333 295 296 315 315 286 309 287 342 290 352 324 283 304 292 317 286 323 324 292 297 309 313 303 322 299 330 310 309 308 307 318 284 297 307 285 322 330 331 325 319 321 319 309 312 319 339 312 313 327 304 293 276 305 334 325 325 336 293 308 315 300 328 311 333 292 340 321 331 305 304 309 302 303 305 303 326 300 330 341 308 301 321 317 296 302 325 323 307 303 321 298 307 324 296 317 301 319 314 320 301 319 309 333 298 330 318 352 308 335 309 304 340 318 307 305 314 305 297 339 346 307 311 353 345 328 327 284 336 309 336 284 339 340 323 304 299 327 316 356 290 325 318 319 302 292 343 327 328 330 351 323 302 328 351 312 314 306 298 334 319 322 285 333 296 313 328 315 322 334 313 328 319 305 327 332 342 321 337 303 294 344 328 321 320 282 305 289 288 322 338 345 340 284 332 325 304 326 301 332 282 320 333 313 347 305 313 291 290 295 350 330 339 329 327 356 325 330 334 279 327 314 304 355 326 339 327 312 352 319 310 316 328 333 323 303 327 335 306 356 326 308 327 322 315 349 325 323 352 308 336 325 315 325 328 322 326 296 318 352 302 318 312 312 334 336 313 319 329 316 327 336 328 296 323 333 331 327 340 298 332 302 332 342 306 345 323 295 297 315 338 325 349 333 322 348 307 340 341 344 342 351 356 325 329 328 338 323 318 334 305 340 305 342 314 356 346 344 342 333 328 312 330 328 329 312 333 332 326 330 324 307 324 346 318 327 347 333 301 338 340 322 312 320 331 325 345 342 303 342 299 319 317 307 336 348 355 328 338 328 315 330 304 326 366 374 346 316 328 332 310 338 315 316 352 329 332 353 325 312 312 328 356 326 326 318 326 365 335 352 312 322 342 335 329 288 312 345 322 343 343 328 337 350 330 343 321 325 360 321 343 349 336 329 314 339 324 300 332 362 313 312 317 320 324 332 327 335 307 347 347 342 318 294 320 304 332 332 322 312 295 349 332 318 338 336 323 304 300 316 330 312 336 315 333 332 356 319 315 336 301 322 324 310 341 326 350 340 312 331 316 333 326 320 345 326 334 307 313 345 328 345 339 341 313 289 336 367 323 312 311 329 329 326 326 321 316 312 327 357 357 289 319 312 313 346 357 347 331 334 304 308 311 330 333 322 295 321 336 344 325 327 313 311 329 332 336 302 315 319 318 333 305 335 328 303 340 340 307 349 333 319 337 317 318 307 324 300 336 344 300 320 321 325 311 321 313 286 311 335 331 322 318 315 331 299 347 288 301 337 336 325 313 309 305 331 347 335 329 316 283 312 309 342 335 292 323 321 324 343 304 325 320 300 326 319 300 348 315 304 310 324 301 300 336 321 327 304 286 287 332 337 298 337 293 291 358 315 326 295 332 309 291 277 306 339 340 331 304 323 303 292 309 300 318 333 288 335 351 315 309 294 279 328 343 328 294 301 316 300 304 322 306 316 312 271 307 324 317 322 295 315 294 298 328 285 312 344 305 315 281 301 335 304 296 324 264 337 305 306 294 335 310 297 348 297 310 314 305 314 297 280 291 322 304 269 286 317 318 306 306 284 304 297 275 314 314 305 304 288 323 290 313 326 322 304 311 297 305 311 313 328 309 303 337 308 267 304 268 278 317 292 310 310 299 264 299 292 283 287 334 318 311 289 288 285 314 302 336 323 304 311 317 279 291 277 300 306 272 320 316 294 300 352 293 284 283 267 287 354 313 317 293 294 316 307 290 265 289 324 278 309 290 281 291 348 285 277 286 294 297 287 260 268 300 303 293 264 293 296 266 301 306 276 310 291 319 267 291 278 290 299 268 302 286 301 292 288 291 292 271 242 273 241 295 287 280 276 292 291 260 275 307 265 286 304 297 283 306 333 279 276 273 274 274 278 280 300 299 334 293 287 278 278 270 305 264 312 286 315 286 295 272 302 271 280 301 266 282 286 304 260 288 296 307 249 306 281 281 283 248 272 313 255 274 283 295 283 294 294 313 281 275 279 248 284 269 269 259 298 276 276 295 294 271 265 267 284 313 258 283 282 280 271 277 271 240 262 268 261 264 282 299 284 272 278 264 278 277 240 280 323 270 272 267 297 248 270 308 261 285 266 257 291 307 266 299 264 283 302 286 295 263 276 265 276 281 284 263 280 275 264 237 246 260 286 293 250 259 271 279 286 269 272 267 245 294 286 275 266 269 289 242 261 292 256 264 279 268 286 265 287 291 265 245 285 246 256 247 249 270 268 249 248 267 261 237 243 270 287 279 265 283 304 270 264 265 289 242 247 282 274 266 249 284 278 263 240 271 257 281 233 257 261 259 263 244 284 237 283 280 242 277 238 239 243 281 246 268 267 243 276 255 281 273 245 215 260 257 270 256 246 286 278 285 289 281 262 282 246 282 243 228 241 257 237 277 255 241 219 272 234 263 265 259 256 266 255 236 270 233 244 275 229 263 240 270 258 269 256 211 248 227 260 239 232 284 262 238 259 280 268 275 257 263 258 233 255 265 279 245 259 267 241 248 239 270 245 260 248 233 226 255 240 226 231 247 272 240 260 256 255 224 271 214 245 246 255 262 266 279 222 275 246 261 231 266 220 276 245 239 239 230 242 256 256 244 229 258 239 265 245 233 239 234 234 259 240 224 255 236 263 241 229 260 224 235 255 225 243 274 232 246 236 224 246 245 233 245 266 242 244 245 236 231 234 250 264 258 242 242 234 239 244 240 249 207 249 239 275 278 246 232 260 265 250 218 215 241 236 258 247 261 223 281 236 274 228 208 272 223 228 218 237 264 240 226 248 243 244 238 228 242 236 222 238 247 221 241 260 232 267 239 259 210 261 242 256 245 236 230 269 271 245 213 223 217 227 243 222 204 225 257 226 240 209 243 239 258 260 243 262 233 245 240 285 231 212 262 215 264 230 276 226 223 247 225 217 228 212 293 235 227 262 230 241 233 216 223 231 226 247 248 231 243 214 268 240 236 247 237 229 233 231 242 234 236 237 216 266 240 246 222 273 268 226 236 232 260 243 209 258 230 241 203 231 218 230 245 203 238 204 229 232 255 191 201 244 225 219 230 224 218 248 235 237 226 238 194 259 235 235 226 230 264 211 281 211 234 242 232 232 236 242 230 196 236 223 203 267 203 229 222 219 257 224 229 256 226 220 232 230 234 237 210 248 228 236 248 265 237 231 208 215 236 226 200 202 203 221 202 249 255 248 246 220 207 208 229 221 235 256 235 243 250 227 219 244 214 219 232 208 232 220 219 221 276 219 221 238 242 213 226 237 240 232 221 245 237 199 245 213 232 215 221 215 210 219 229 236 188 265 237 218 232 247 211 202 238 217 238 231 219 246 212 242 216 224 249 233 207 213 204 213 256 249 224 239 237 210 218 211 218 206 203 231 222 207 223 226 234 221 248 233 219 204 238 192 215 199 246 210 218 231 210 225 202 269 233 223 226 213 201 223 204 214 247 234 228 181 190 222 210 215 198 229 229 227 213 209 198 233 223 210 235 223 209 203 211 192 198 227 200 264 216 218 211 239 199 199 215 211 205 215 220 241 227 210 239 213 242 193 212 222 233 233 247 225 223 236 210 224 196 226 211 225 211 213 184 250 237 237 264 210 231 233 209 227 232 208 223 227 209 200 195 239 224 188 214 211 198 208 216 216 218 215 240 209 223 206 224 224 228 224 211 223 220 226 205 243 226 191 215 209 216 211 215 261 210 217 187 214 219 229 215 217 205 215 212 194 246 203 210 208 231 228 235 234 227 223 229 244 228 194 210 196 223 208 217 220 215 219 197 220 203 222 222 237 183 212 215 229 203 207 202 204 214 217 245 228 200 222 235 236 189 259 229 234 208 224 205 260 219 198 207 235 220 223 195 198 216 228 198 226 214 195 207 218 224 209 213 212 189 203 200 213 198 212 187 213 187 197 194 211 209 232 222 210 219 207 216 207 199 213 220 196 232 210 196 189 212 213 222 219 235 202 208 218 230 223 205 209 206 204 229 228 205 213 215 225 238 215 200 212 208 219 211 205 207 222 192 214 189 206 235 267 230 189 217 200 230 207 261 181 215 240 213 206 232 219 240 212 203 233 234 216 189 226 199 216 217 215 205 211 224 205 213 203 218 204 238 214 210 195 214 199 211 245 198 209 210 185 192 199 223 210 207 215 204 222 195 203 187 236 198 228 206 223 239 212 192 208 215 212 194 235 208 225 202 202 201 208 189 225 196 188 242 190 205 228 203 221 231 229 201 222 199 205 228 226 193 215 210 178 179 227 221 226 225 187 225 199 215 210 197 211 231 222 221 204 207 202 205 209 196 199 197 215 204 227 209 197 211 233 221 216 181 219 199 224 188 222 204 215 204 206 170 218 198 180 177 222 236 218 225 238 194 218 209 217 212 196 181 201 190 186 203 213 195 193 197 180 193 201 211 217 196 200 201 193 189 182 195 191 216 204 225 216 221 201 209 202 190 168 195 214 207 203 203 203 201 206 197 213 232 196 178 189 196 183 215 237 193 189 197 201 200 218 202 217 214 202 193 221 190 210 186 213 206 189 201 205 211 242 204 186 182 205 192 200 220 213 222 208 214 194 217 203 192 204 212 223 184 230 205 197 210 197 181 194 208 185 219 189 207 235 209 215 231 177 194 211 207 172 214 191 209 208 210 197 180 226 198 211 183 215 195 197 216 210 190 211 216 247 195 231 239 216 223 214 220 192 193 233 200 210 202 193 211 205 224 199 215 207 195 223 203 203 235 225 191 185 202 191 209 221 194 184 211 199 213 189 196 214 217 215 225 207 199 215 224 201 193 216 202 191 200 211 216 195 194 192 235 187 207 193 192 212 215 201 183 224 201 191 197 211 197 204 209 192 176 220 185 198 230 209 193 173 201 197 207 189 189 186 194 193 193 197 229 193 229 211 188 206 201 216 208 219 228 212 230 202 220 199 216 198 200 217 230 210 217 222 211 199 209 210 210 184 191 189 190 208 222 174 203 192 200 203 197 196 216 190 217 201 214 197 207 212 211 215 198 214 207 188 213 216 193 203 187 215 193 200 182 222 198 222 202 208 199 213 210 219 178 199 194 199 178 201 202 193 174 224 212 197 211 183 201 199 208 210 176 219 171 221 214 208 223 212 217 204 214 208 217 209 214 199 193 215 192 195 202 221 189 196 204 197 205 213 201 209 211 213 197 228 220 218 224 199 211 181 215 185 217 202 194 202 200 186 200 212 206 186 203 194 204 188 201 187 201 222 194 190 199 190 201 215 207 210 198 194 227 206 216 232 194 187 193 234 209 218 210 212 197 211 235 196 205 195 215 203 232 206 219 185 217 214 219 192 205 219 198 197 191 171 232 212 200 200 215 223 198 205 182 173 211 197 196 206 195 200 204 169 205 215 216 226 214 196 199 188 259 196 209 210 205 186 211 185 215 211 195 232 206 200 199 221 218 198 199 205 208 221 204 232 221 213 229 216 163 212 195 212 232 218 204 189 226 222 206 204 212 209 209 216 213 207 220 213 206 194 224 206 210 212 199 217 204 231 172 183 216 191 196 202 193 187 201 207 200 216 216 230 207 217 205 202 196 270 207 203 216 192 189 218 201 196 221 209 269 206 218 198 212 228 206 208 230 192 200 217 201 195 189 190 208 227 216 239 237 226 210 230 211 207 208 182 196 214 215 242 212 204 220 189 227 223 244 224 233 232 199 210 217 200 208 208 236 222 219 206 188 220 211 202 215 209 239 209 201 196 228 242 191 198 206 222 198 206 186 204 234 220 200 205 234 197 215 216 205 236 243 228 212 222 221 235 184 210 207 192 237 219 202 208 239 224 215 187 224 206 219 212 210 213 229 236 245 235 195 203 233 231 227 275 210 229 219 219 255 248 246 235 221 228 231 234 274 231 228 224 273 248 217 264 226 280 283 292 274 283 280 243 293 278 278 272 306 293 328 311 294 288 284 311 322 323 321 326 349 350 326 352 349 330 391 337 326 358 313 379 365 361 382 345 307 328 332 317 324 328 315 306 304 290 288 285 275 279 302 276 286 261 234 237 262 243 246 275 237 258 265 255 219 236 241 241 231 237 197 222 206 230 248 205 226 231 228 226 200 265 232 228 208 201 214 204 214 219 232 237 216 217 211 237 239 236 240 219 230 222 219 234 223 222 240 226 205 212 184 201 220 225 215 214 209 195 230 207 229 249 205 212 215 218 226 197 226 194 209 227 200 215 250 196 216 222 195 216 216 223 211 218 203 213 255 229 226 235 214 218 208 222 212 213 236 205 224 226 215 203 160 229 208 190 209 215 194 238 198 208 223 211 193 226 221 227 225 223 226 193 222 206 212 193 206 202 206 191 206 221 217 176 187 230 208 184 215 202 235 212 209 213 230 232 201 227 218 214 265 206 208 232 214 192 198 214 201 237 183 221 229 249 220 228 181 241 214 202 228 231 216 242 234 215 215 217 201 183 181 233 219 208 206 225 245 213 207 183 223 223 209 195 211 192 218 242 226 208 249 211 224 218 213 231 216 208 207 200 210 208 195 212 219 207 222 209 218 217 211 193 208 243 233 212 223 225 200 202 184 218 212 207 240 230 203 207 222 205 247 259 200 211 204 214 195 195 248 237 207 228 200 195 228 206 222 228 201 218 220 195 192 181 190 214 202 242 215 205 229 257 204 198 204 211 220 222 186 200 194 203 233 208 177 218 222 237 212 228 222 208 212 182 227 218 216 224 230 200 185 211 210 224 217 212 213 208 212 199 202 213 217 237 231 205 188 239 210 205 201 206 218 179 201 196 207 214 192 201 215 221 211 207 215 217 248 218 226 223 208 231 210 205 227 239 222 199 210 214 224 195 207 193 223 209 224 230 204 226 189 200 217 171 219 211 205 189 202 216 228 196 175 204 183 207 210 236 210 191 195 178 205 211 216 218 198 215 224 213 215 209 227 212 224 205 204 220 189 235 204 194 205 181 220 228 223 216 214 227 215 208 210 218 202 212 224 214 194 235 227 215 233 216 226 210 201 216 209 211 233 224 195 210 221 185 200 195 197 204 213 202 232 224 243 199 236 204 201 209 228 203 226 190 206 217 258 210 216 245 200 214 221 213 245 212 179 220 204 214 238 185 231 199 195 191 209 208 216 194 206 191 216 199 214 221 172 212 211 211 208 224 239 228 229 210 204 214 204 192 213 223 210 223 223 208 213 212 204 222 213 209 220 225 202 198 210 230 212 231 245 195 244 226 229 215 219 232 217 217 204 222 199 206 222 220 220 232 217 222 241 221 209 226 236 241 224 188 178 210 200 216 210 242 208 209 183 222 225 211 205 201 219 182 196 208 209 186 231 191 223 206 240 199 204 205 189 227 214 185 197 204 210 183 200 202 236 220 205 217 243 205 200 225 194 224 246 204 194 192 212 219 217 216 235 216 211 208 209 229 227 202 216 221 192 218 204 217 181 196 198 208 231 212 226 207 201 189 210 202 219 214 208 214 223 202 207 217 230 199 199 209 201 215 193 215 224 204 238 226 227 213 211 215 209 193 211 217 201 219 199 221 191 182 207 212 205 230 213 218 225 209 187 219 222 200 216 225 223 227 187 214 207 191 210 198 218 228 206 202 187 209 200 206 229 241 212 196 229 218 189 208 212 231 215 198 212 233 207 215 213 212 216 187 187 198 197 205 200 189 211 205 217 202 217 209 191 200 212 223 226 207 231 208 211 208 227 231 186 199 211 186 209 207 194 186 192 194 226 235 205 184 220 197 208 188 231 200 245 218 190 201 226 206 222 202 210 232 199 208 194 207 219 208 201 195 206 233 208 220 202 212 230 222 200 224 231 209 217 192 218 223 229 214 212 202 197 213 216 208 208 188 224 210 215 211 212 190 209 189 194 196 202 193 212 203 223 222 196 200 188 230 211 187 208 203 231 203 214 193 218 211 202 222 194 212 215 183 210 226 204 223 235 204 192 212 237 197 218 208 212 220 217 228 194 206 221 192 216 215 234 215 172 211 202 179 230 230 231 222 174 230 206 220 214 228 202 199 202 212 217 189 208 206 227 197 183 196 197 210 207 216 215 219 236 204 207 207 228 208 221 195 209 206 216 202 165 184 219 217 218 232 241 189 204 200 237 212 203 190 234 216 200 215 231 214 181 201 186 213 201 207 214 203 215 217 202 220 205 198 208 219 227 191 214 209 248 225 197 220 218 230 225 221 212 245 193 204 190 209 203 218 230 199 202 219 188 211 257 206 220 196 225 217 198 195 211 212 203 248 178 222 197 193 224 183 200 213 179 228 199 201 224 185 210 195 206 229 216 215 177 224 233 234 222 214 203 227 208 193 189 180 205 184 186 208 205 199 216 227 196 210 180 201 201 226 212 242 220 197 227 224 223 222 198 203 212 207 172 212 221 222 222 220 221 220 208 194 218 229 219 204 195 192 209 215 176 209 196 196 208 207 215 197 198 217 203 197 205 221 216 233 203 219 214 218 217 194 195 214 217 189 216 211 203 212 220 207 197 186 197 210 194 207 231 216 189 218 224 204 221 223 198 223 199 176 202 202 199 205 212 188 207 216 199 219 194 206 233 204 214 210 180 207 238 207 203 210 206 202 209 196 224 222 207 187 218 193 211 193 201 209 200 202 209 219 203 230 197 222 212 210 204 237 216 179 223 220 221 186 200 226 223 195 210 216 205 180 210 189 191 184 201 199 195 219 189 216 200 219 186 203 196 215 235 191 177 212 225 202 219 207 230 199 214 233 213 216 217 202 197 195 196 191 204 188 215 201 200 192 192 201 227 208 170 179 194 238 219 216 183 202 212 235 236 211 212 188 228 202 210 188 205 198 211 175 180 215 196 209 211 211 213 211 228 199 221 230 206 231 200 224 219 229 202 206 206 217 212 203 238 214 211 216 223 219 211 201 201 196 234 215 228 221 216 208 192 208 211 215 193 200 203 224 201 175 207 222 187 230 216 209 208 218 215 202 180 208 193 230 189 202 214 215 235 218 210 217 197 203 202 201 196 216 200 193 191 177 211 217 234 207 210 198 236 217 208 240 197 231 202 165 220 219 196 213 221 190 202 214 216 223 218 216 208 201 186 215 206 226 198 219 217 197 205 218 226 205 190 220 238 218 214 197 210 222 208 202 194 175 233 242 209 196 207 206 207 210 203 184 209 193 212 226 205 198 209 228 200 222 212 202 205 188 225 226 244 201 209 206 211 229 197 220 192 201 199 194 200 194 199 205 233 223 185 208 206 204 186 224 200 225 203 209 196 215 205 216 220 203 209 212 239 237 221 216 209 212 215 242 217 178 215 216 239 222 200 224 197 222 211 244 210 222 216 217 212 208 202 201 205 224 203 227 192 215 202 198 192 217 227 222 217 206 205 219 228 221 218 196 205 211 215 215 221 216 203 187 235 206 187 230 224 211 209 202 178 203 204 219 225 205 184 213 175 195 196 227 216 234 195 202 218 209 186 221 208 209 202 193 220 216 238 225 205 198 218 218 208 219 207 240 213 207 194 204 215 220 215 210 209 193 215 212 204 237 216 206 236 198 224 230 212 213 218 240 229 210 215 232 229 235 189 236 215 215 214 180 193 239 214 228 219 220 227 195 215 223 236 211 184 203 230 208 243 219 207 229 225 205 213 198 194 194 209 195 198 205 216 232 210 200 213 207 228 219 218 212 191 220 213 209 200 248 207 211 195 191 225 208 223 232 201 226 227 192 220 217 185 194 183 210 207 186 191 219 199 215 205 211 220 202 222 214 218 222 228 184 200 219 205 219 232 203 200 194 216 173 206 207 215 208 206 193 224 196 220 193 231 199 186 202 225 187 228 226 226 207 206 187 256 203 191 217 193 207 200 197 205 202 188 198 210 229 205 195 190 182 206 207 200 215 190 186 213 233 203 206 194 217 217 212 218 191 191 203 212 234 202 227 208 207 243 215 241 227 205 211 217 214 197 220 212 234 218 225 185 236 209 222 234 233 230 174 219 216 190 243 212 208 216 241 189 207 195 243 224 206 199 199 211 222 214 209 220 220 236 228 197 213 226 220 221 216 221 219 221 214 217 194 217 200 232 202 220 232 246 205 231 212 202 208 217 218 212 195 215 221 218 202 225 219 230 224 202 229 209 203 208 224 206 218 208 210 193 217 239 222 215 216 192 209 204 201 243 239 202 219 224 200 222 205 191 200 210 223 183 208 196 195 210 241 192 226 211 227 195 220 224 215 207 217 191 216 193 207 209 204 212 214 230 229 224 226 221 222 230 233 212 216 221 201 205 219 222 235 210 206 227 207 208 231 205 212 209 165 211 212 197 217 205 192 228 209 189 201 202 222 201 200 213 237 220 224 236 227 210 234 209 236 231 204 219 226 200 200 199 215 210 180 212 207 196 220 212 210 212 188 228 210 239 241 219 209 225 210 229 210 205 200 214 221 240 229 217 201 206 220 215 187 243 199 177 232 225 227 217 203 220 227 200 209 195 235 197 188 235 240 203 193 198 188 193 223 243 213 194 219 228 205 194 216 234 227 181 189 216 233 207 228 219 207 229 236 215 230 231 219 218 220 232 232 203 185 219 243 220 215 226 196 208 255 223 234 189 229 227 207 244 224 239 237 202 229 269 193 229 241 222 234 232 247 215 237 234 219 228 212 221 228 212 220 211 194 227 233 209 214 211 204 226 214 229 239 212 233 222 244 219 198 199 235 207 219 223 201 223 215 192 223 225 201 236 232 198 205 202 238 221 241 226 255 201 192 207 224 228 206 200 234 183 211 211 205 228 217 219 192 232 235 214 215 229 240 188 213 244 199 212 246 213 219 201 216 223 220 212 226 187 214 182 214 193 223 212 197 206 235 220 216 239 225 257 221 200 188 232 193 187 216 174 224 232 201 212 224 228 192 212 209 258 199 210 226 196 222 212 187 218 202 222 211 206 208 235 218 213 212 223 219 237 194 229 219 209 237 197 201 222 209 206 205 205 203 237 210 231 197 202 222 209 210 225 213 205 198 236 198 196 196 199 212 197 191 227 185 203 235 213 225 211 220 196 215 205 184 212 208 198 226 219 222 208 215 199 227 210 206 211 219 193 204 213 196 202 219 195 210 197 193 228 189 220 214 213 212 231 224 195 180 207 208 201 212 217 214 208 199 196 215 213 210 204 201 210 215 223 209 223 201 208 195 230 215 179 200 210 218 204 214 217 226 199 207 220 214 239 213 195 244 221 212 198 219 232 202 214 206 205 233 203 217 219 227 199 207 194 232 229 198 216 194 197 232 218 204 215 194 215 195 230 208 188 215 223 203 209 226 221 200 201 230 242 200 216 196 214 204 207 206 217 207 189 209 207 221 205 200 188 211 185 226 210 227 220 209 221 170 185 222 210 202 198 189 233 215 207 180 182 193 206 200 206 186 193 199 208 213 218 206 234 224 218 217 220 216 220 206 178 213 256 216 184 213 214 202 203 216 195 218 195 220 196 217 200 204 211 233 210 236 201 204 208 209 193 240 216 198 219 232 208 211 202 234 201 220 197 213 200 194 203 186 211 208 203 219 222 200 195 216 195 223 208 200 214 220 206 220 206 237 182 215 221 221 187 218 226 203 189 212 188 201 206 189 216 205 239 215 226 191 217 215 182 221 228 231 208 200 188 192 209 209 220 209 234 190 213 220 194 205 205 203 195 200 203 210 200 210 208 201 205 218 190 220 203 194 218 201 195 213 199 218 196 208 215 199 224 200 227 211 202 208 196 211 207 210 237 208 208 205 204 226 199 207 223 179 200 206 206 233 241 185 248 190 208 202 211 213 202 205 186 216 216 194 186 193 223 227 211 202 201 215 209 200 217 184 215 214 199 223 203 195 196 236 221 201 232 195 211 208 220 213 232 199 234 201 216 202 207 217 212 206 204 198 207 217 209 209 195 205 205 206 219 192 198 205 213 202 213 218 204 228 213 204 207 184 213 228 202 227 175 197 216 228 230 223 215 201 200 187 231 216 203 242 197 244 196 193 199 189 213 216 200 196 225 181 196 204 174 212 210 189 222 181 210 173 188 216 214 207 235 218 204 208 172 204 190 209 232 213 181 196 232 207 187 230 220 232 202 235 207 213 198 199 205 221 213 212 209 220 214 193 194 198 204 227 201 209 195 195 194 208 219 216 198 226 189 194 198 202 195 223 181 186 186 191 182 225 211 198 231 214 196 191 221 212 209 206 196 210 198 208 194 205 199 200 215 211 226 209 180 229 203 225 204 211 192 217 194 198 220 212 210 215 210 200 233 207 198 202 195 210 207 192 236 212 208 218 210 204 196 212 206 242 229 210 197 206 205 201 213 228 200 202 208 188 210 224 202 213 226 203 194 229 209 194 173 217 207 223 209 213 198 234 220 217 213 213 208 212 203 225 216 197 182 201 194 218 193 190 219 183 188 192 185 204 224 209 198 223 188 210 206 212 218 203 192 211 195 214 191 204 217 210 214 166 196 213 212 214 192 213 177 208 202 200 218 178 210 199 198 200 221 198 199 192 197 210 201 219 233 194 205 174 184 209 202 195 192 178 185 186 211 207 219 201 229 179 259 206 195 188 182 208 235 221 172 209 200 211 221 198 174 199 222 190 176 217 202 188 215 177 213 215 227 213 208 222 192 197 223 192 200 202 184 199 192 208 194 189 229 210 209 194 202 211 182 186 202 205 206 192 186 211 202 200 196 224 195 181 215 245 175 200 190 208 187 206 210 200 206 191 194 213 223 185 182 197 191 186 220 188 199 216 208 194 204 211 209 189 183 205 185 202 193 238 189 221 200 214 209 190 220 203 191 207 183 202 214 201 203 202 181 190 202 210 209 235 191 188 227 212 193 220 193 207 172 201 219 174 204 208 211 227 227 182 206 208 229 201 239 202 186 220 238 202 195 185 209 217 209 225 210 201 233 213 222 228 218 209 186 184 218 232 209 201 178 225 194 214 214 238 199 221 194 218 221 187 202 220 202 211 189 197 184 219 198 195 199 220 229 188 198 229 220 209 208 217 192 190 187 219 232 219 215 193 225 175 202 179 188 200 204 212 210 199 206 183 212 203 224 208 188 218 195 214 186 201 217 199 192 233 202 225 191 208 198 185 211 227 187 194 229 197 207 186 225 199 195 198 221 223 193 178 204 189 194 229 205 197 194 214 214 201 213 187 201 211 208 203 204 192 217 221 193 201 189 229 230 217 200 202 202 191 190 210 209 202 190 224 203 201 213 213 199 186 203 175 219 197 225 218 224 202 204 202 218 215 230 227 188 210 196 191 203 188 212 220 224 209 199 210 203 213 206 182 212 221 231 184 217 228 200 207 166 195 196 202 238 194 228 196 199 204 246 196 202 200 215 202 196 210 199 194 219 205 219 216 208 209 185 209 245 199 187 211 203 200 207 212 222 204 195 210 212 206 196 197 210 209 168 168 218 222 216 197 188 214 208 182 211 206 207 214 223 220 186 215 190 223 203 207 218 212 202 201 212 207 201 193 205 209 209 209 215 215 205 225 201 198 207 208 193 235 231 196 192 183 187 193 214 190 203 185 175 239 186 211 172 211 186 198 229 220 182 217 223 217 196 236 207 187 234 190 218 213 207 208 215 192 194 185 204 199 204 193 204 214 183 209 224 183 203 199 199 165 179 194 206 229 201 203 199 200 208 233 184 181 191 195 195 211 165 214 187 221 236 197 192 174 186 206 219 220 208 200 186 200 234 203 201 201 195 218 190 201 233 239 206 195 208 192 225 209 220 199 209 212 226 190 247 185 227 211 190 193 204 212 169 209 196 202 195 215 207 211 228 194 192 185 202 223 187 216 207 197 213 226 199 236 177 210 178 185 182 227 211 211 194 183 203 222 223 195 183 188 193 212 197 205 190 203 190 189 223 201 191 217 196 202 193 202 222 216 194 188 216 220 212 199 175 205 217 188 222 210 180 213 200 203 219 233 173 188 214 204 194 199 208 195 191 189 220 190 179 190 179 230 209 171 227 202 200 199 196 168 206 190 196 224 195 228 182 204 197 206 205 197 198 214 194 220 193 211 197 203 219 202 192 213 201 188 190 192 205 189 206 191 205 216 228 220 188 217 214 211 191 175 208 184 211 171 197 197 218 204 195 197 216 188 182 209 218 213 175 197 202 212 201 201 241 214 188 202 196 189 196 197 215 200 185 223 194 192 183 213 179 196 202 203 178 192 202 212 195 195 178 189 207 202 196 179 168 205 191 216 201 185 191 216 171 200 185 208 192 180 214 186 187 199 201 223 197 217 228 197 203 228 196 185 214 188 206 208 205 217 199 203 194 187 182 209 219 193 197 215 184 216 195 203 201 190 197 208 192 194 224 199 198 180 195 172 199 189 201 194 197 178 206 209 219 190 207 202 226 183 208 206 195 191 178 203 210 187 236 233 185 187 198 199 213 204 190 205 211 203 215 181 210 192 195 225 214 220 191 177 211 211 192 229 196 223 199 211 199 221 220 175 208 193 226 185 190 200 232 202 184 209 228 200 209 210 201 204 214 228 192 192 223 196 184 209 219 202 203 227 223 205 228 199 209 213 211 201 214 224 219 227 203 238 224 219 212 233 223 224 184 216 220 237 258 255 220 230 209 230 248 242 227 248 221 221 248 220 218 228 218 211 241 214 215 218 231 233 232 208 196 235 209 199 208 239 218 228 226 224 226 230 210 217 188 215 235 175 218 194 200 180 212 187 227 240 210 200 196 234 220 218 200 203 189 193 216 211 203 229 199 215 198 190 207 220 191 176 189 228 225 218 188 167 201 177 216 218 191 216 216 245 190 201 200 190 186 191 199 218 186 183 209 204 212 197 188 188 199 210 196 160 189 174 199 202 205 241 200 175 203 195 202 211 200 182 215 195 187 181 208 201 207 183 203 188 197 197 193 196 228 190 210 218 205 181 198 198 181 188 189 206 175 188 213 212 209 195 186 193 160 202 185 196 192 184 220 173 185 186 198 188 210 179 188 216 203 197 176 196 222 192 207 202 180 170 223 206 179 205 203 206 185 201 189 204 192 188 192 205 193 187 193 174 209 207 208 195 196 194 194 181 192 207 223 199 213 202 198 214 210 196 188 197 199 200 196 197 186 194 192 205 189 182 206 197 220 197 195 186 201 189 207 207 190 200 203 177 202 206 203 182 202 218 199 188 188 198 173 202 238 194 176 200 205 220 195 192 200 193 176 182 197 184 193 187 201 205 190 193 192 179 196 193 180 183 196 206 191 209 204 171 170 208 190 205 180 186 206 205 204 172 214 193 186 191 186 199 202 182 197 230 186 202 173 179 206 189 193 180 201 193 214 176 217 176 188 181 198 162 191 196 185 209 191 225 204 201 182 218 204 188 189 183 207 200 186 203 200 210 195 192 199 168 189 217 204 176 188 203 208 205 188 197 228 184 188 207 194 194 171 207 208 178 193 193 194 199 177 198 169 197 199 191 215 175 193 176 217 189 184 201 199 181 199 193 207 188 208 143 202 212 195 212 211 188 178 212 203 198 200 190 177 209 199 214 229 198 195 206 205 190 208 181 182 172 190 176 195 177 194 175 188 169 190 175 195 183 196 179 198 178 184 183 168 227 196 197 213 186 205 186 183 172 208 198 208 195 192 192 195 181 229 187 231 184 214 214 183 193 190 179 180 181 198 196 211 239 183 203 204 230 198 203 192 189 186 193 192 191 216 210 192 205 214 178 207 188 189 189 227 196 181 175 200 210 196 206 188 201 180 191 186 196 182 180 202 179 191 195 195 178 188 196 181 202 186 183 221 177 180 197 180 211 196 194 186 186 190 160 194 171 207 193 184 209 201 199 210 194 185 196 193 190 187 184 210 220 189 178 178 212 208 189 206 190 199 211 189 186 196 193 209 188 209 212 166 213 197 195 186 190 191 204 212 177 201 175 189 177 191 188 194 187 179 207 192 193 213 216 199 209 187 177 209 210 170 198 224 186 188 204 201 198 198 197 182 189 188 197 185 185 185 217 178 200 190 212 193 207 204 183 182 195 211 200 172 197 186 221 186 186 170 193 178 196 202 186 214 197 195 212 202 194 196 202 175 195 215 197 201 205 212 206 168 164 197 188 224 198 200 202 204 179 179 183 193 176 203 174 194 172 204 193 205 193 185 190 198 190 186 213 190 177 194 201 200 185 216 195 200 192 181 197 185 224 197 186 217 160 194 186 208 186 196 185 171 185 199 179 185 199 178 179 215 203 194 194 193 193 188 175 209 205 200 226 205 186 184 210 179 201 201 198 199 182 182 195 198 182 222 178 188 199 198 180 190 204 187 175 233 190 202 176 212 193 202 169 210 191 172 185 177 190 199 195 179 198 172 204 209 195 200 192 171 201 177 179 202 205 170 180 186 182 205 200 216 199 206 209 192 186 177 202 183 219 170 170 206 204 213 207 207 195 211 175 174 185 192 188 210 191 188 201 203 186 206 203 186 190 204 201 185 208 193 176 192 193 173 207 191 186 209 189 195 180 199 203 202 182 170 201 175 187 188 179 214 181 184 202 201 189 188 190 175 189 212 189 188 193 196 206 202 221 188 194 194 183 179 168 189 164 177 211 182 176 205 190 195 210 205 203 196 216 193 209 187 198 190 196 228 201 176 173 202 185 181 199 184 190 194 189 202 192 165 173 178 199 184 187 187 202 193 182 196 198 164 180 175 188 177 213 169 202 190 180 178 182 191 196 185 177 195 208 175 179 202 178 193 220 187 201 191 164 182 198 205 206 192 194 195 197 203 200 218 184 186 178 177 208 203 198 200 205 220 175 186 187 216 209 211 171 203 206 186 209 210 190 212 232 186 187 196 185 198 200 197 159 233 197 218 185 198 190 183 175 173 204 191 187 177 170 192 193 206 190 174 184 199 214 172 182 198 184 199 199 198 213 179 190 201 174 186 203 184 194 200 176 197 193 196 179 187 154 206 179 176 216 201 190 181 217 179 208 201 181 209 210 199 212 195 172 172 187 193 194 200 211 214 186 192 179 184 213 171 175 170 205 177 167 213 198 199 186 197 187 175 193 195 222 190 182 197 186 182 218 192 205 186 187 178 191 193 198 184 169 194 197 186 184 176 185 171 190 180 199 175 167 195 187 174 202 225 200 174 188 176 186 185 194 186 211 190 190 191 190 183 211 189 196 213 203 185 174 202 199 199 201 196 187 188 177 223 215 204 190 178 183 187 189 186 212 187 164 193 198 171 199 197 194 194 170 190 186 191 189 175 198 181 208 186 192 191 173 191 189 188 208 188 218 191 176 210 194 168 210 187 211 213 186 177 202 204 187 224 186 198 195 184 178 187 217 193 178 165 210 192 215 218 201 199 185 201 213 198 188 199 212 212 172 203 167 179 187 181 204 197 204 203 199 209 217 195 182 191 194 173 196 184 217 191 186 210 175 190 194 210 194 208 191 201 194 193 211 199 187 216 182 198 182 186 212 181 193 201 170 194 185 209 187 190 202 213 197 192 193 183 171 186 181 186 208 186 182 184 187 195 178 208 198 184 210 183 198 197 190 205 193 200 205 216 195 200 180 169 186 174 200 184 221 177 204 194 192 182 197 205 196 227 186 202 213 197 201 208 180 193 188 170 178 191 216 210 173 221 211 195 188 204 191 190 181 203 157 194 181 171 185 174 211 203 199 191 185 186 195 192 179 203 199 171 193 219 176 187 179 156 174 202 188 199 186 219 193 196 181 218 204 189 196 202 188 179 184 188 192 216 186 175 215 199 209 183 216 191 186 178 208 192 191 179 179 168 214 197 179 185 223 181 168 161 203 178 189 181 208 197 185 192 205 178 183 173 198 202 201 222 197 167 198 175 179 188 203 173 202 172 172 200 179 182 216 173 235 195 185 190 161 202 212 172 190 180 203 181 183 203 175 192 215 204 173 154 190 191 200 205 176 194 186 191 181 193 179 206 194 198 199 206 182 172 221 210 196 210 190 171 179 188 191 202 195 166 216 196 195 172 182 185 174 194 207 212 182 185 194 193 198 201 207 188 186 201 187 202 204 186 212 185 202 190 203 181 182 190 177 201 216 204 187 190 204 212 226 185 180 173 197 162 210 192 173 208 198 189 216 197 192 201 197 194 207 203 172 191 205 213 186 177 172 197 208 210 194 199 184 216 189 215 178 228 195 229 184 188 185 196 178 200 180 173 176 202 195 192 220 183 182 185 172 144 190 204 191 208 188 194 180 185 185 195 192 211 194 198 199 209 190 196 159 183 200 197 197 179 184 183 193 182 182 192 179 205 200 201 207 195 177 210 155 177 183 187 235 180 206 194 194 211 205 191 201 199 196 209 191 199 192 205 209 210 189 191 170 196 200 202 202 213 198 198 201 220 218 207 213 194 209 189 213 194 199 202 188 205 219 205 201 206 200 209 177 213 205 167 213 235 215 193 211 211 195 213 199 192 199 196 183 184 223 182 212 234 196 217 218 199 196 182 187 216 203 208 209 192 217 186 178 206 198 181 215 199 191 195 204 197 205 202 198 233 220 213 196 213 192 202 200 169 205 186 219 187 192 209 216 225 202 206 194 200 193 206 205 190 200 199 207 204 215 196 180 193 203 225 187 181 200 207 192 213 213 204 196 203 203 183 207 207 209 184 190 185 179 213 183 215 182 178 219 175 195 187 225 193 189 195 204 195 196 194 176 222 188 179 188 196 176 199 191 179 198 216 197 200 213 212 226 195 221 190 181 204 206 174 235 169 218 168 206 205 197 200 199 209 194 219 218 208 213 184 177 200 210 204 211 199 213 221 197 196 192 194 203 192 216 176 180 211 190 194 191 200 208 209 173 196 199 200 182 200 211 192 195 191 208 190 216 207 193 201 192 198 181 219 193 195 227 202 207 194 207 206 213 218 186 199 189 174 165 205 211 224 197 217 168 179 189 184 203 204 169 211 199 165 159 214 181 185 203 189 201 223 182 214 194 199 171 201 188 182 181 200 217 200 186 175 164 189 206 180 218 189 209 200 208 212 203 208 171 200 203 205 197 190 195 199 192 205 194 188 173 198 217 192 203 193 178 182 217 200 175 188 210 249 201 218 204 211 197 194 208 188 220 191 211 194 202 185 211 191 205 172 204 202 190 171 177 235 200 207 222 220 206 220 181 215 218 218 173 188 188 200 183 192 174 216 204 206 175 209 195 208 176 182 192 202 199 208 192 188 187 199 196 220 210 190 200 210 205 204 223 202 208 220 202 181 195 189 247 196 216 202 190 177 190 196 207 207 208 183 184 200 182 210 219 225 192 199 218 235 183 197 248 190 204 209 189 185 219 212 213 199 190 202 207 195 205 211 193 208 196 201 210 204 188 189 176 204 192 198 174 203 209 198 193 205 213 208 185 176 187 198 183 230 186 179 189 203 209 178 215 194 211 167 213 200 205 200 206 196 217 221 222 192 205 201 175 209 214 175 185 177 194 211 178 220 205 215 219 186 201 237 176 202 185 207 195 213 189 204 209 200 198 184 215 230 225 186 199 191 194 195 201 206 201 198 213 191 188 205 175 185 186 183 185 191 209 194 203 228 210 207 180 243 180 196 214 192 202 209 182 205 214 204 193 214 211 212 196 187 191 237 196 181 198 197 223 206 193 202 206 218 182 201 187 190 182 176 177 223 181 186 209 204 208 222 194 215 187 191 213 182 223 175 190 213 212 188 217 198 194 178 204 192 186 195 185 198 229 213 189 230 201 210 180 185 200 212 177 184 200 193 191 187 205 213 201 194 191 225 209 223 192 200 197 194 203 218 212 202 214 203 199 191 167 204 201 193 192 208 208 189 198 224 212 198 201 189 210 198 202 216 208 204 203 190 203 185 205 205 203 198 228 203 214 198 192 198 209 219 191 186 215 204 191 205 188 205 212 201 203 204 201 197 210 172 195 188 219 217 194 174 215 183 201 174 222 188 211 215 186 180 197 180 212 208 216 220 196 195 224 206 187 201 194 195 191 202 169 198 228 215 214 183 175 189 178 216 193 184 197 200 188 203 210 203 193 191 187 201 222 201 180 171 181 216 205 199 200 173 186 160 188 205 207 209 186 192 210 221 210 182 210 189 174 216 194 214 199 217 198 230 181 190 201 179 187 205 190 177 206 189 203 193 181 203 182 201 203 216 204 202 188 193 169 195 222 191 204 199 203 194 173 194 208 214 183 183 186 183 204 199 191 207 216 169 182 213 215 194 175 181 216 223 235 212 201 176 174 194 215 179 218 199 198 165 190 213 213 183 233 220 228 193 200 197 170 199 184 164 189 205 205 194 185 204 197 186 234 176 190 222 202 198 203 207 189 211 195 200 191 186 211 220 215 218 188 170 201 209 193 196 181 191 215 202 190 198 193 191 202 188 203 217 208 182 176 186 211 214 212 186 207 182 187 194 202 192 208 206 182 177 195 210 207 216 184 206 196 194 195 190 204 188 232 216 204 185 205 193 202 185 197 201 222 198 218 184 174 175 208 200 200 215 194 187 206 177 198 211 233 198 192 190 189 217 215 220 189 221 207 229 201 204 229 233 197 230 198 181 180 211 221 215 201 170 227 196 188 201 193 181 199 222 214 204 231 192 215 199 193 190 177 215 195 186 213 212 193 191 197 218 216 199 191 220 202 227 187 203 195 213 209 184 205 213 196 188 204 207 187 176 181 218 195 215 177 224 191 198 226 196 197 189 192 201 180 183 203 176 195 220 222 190 199 203 191 185 201 189 200 186 197 222 206 163 197 206 181 206 194 179 209 202 189 197 226 183 217 204 185 217 208 195 197 200 191 180 201 205 226 179 216 197 167 192 193 181 177 222 198 197 201 180 177 211 200 180 210 219 187 197 205 160 205 189 210 206 189 215 200 201 184 221 196 219 184 210 181 202 225 178 209 176 190 185 226 207 174 185 195 194 190 193 237 221 198 183 194 182 203 206 195 185 201 184 192 219 224 213 183 195 218 197 211 218 180 179 159 214 240 193 212 196 199 206 187 185 219 212 194 218 213 198 196 224 214 197 210 189 203 201 184 186 215 182 202 194 212 225 187 213 194 229 187 234 186 191 202 217 187 199 193 204 211 224 173 211 188 194 197 190 189 189 207 181 201 210 190 220 199 190 198 216 196 200 184 212 192 201 192 230 186 216 210 173 203 207 205 192 182 225 218 206 213 181 189 200 190 201 202 192 190 187 202 204 209 209 221 192 195 222 216 210 212 187 207 188 198 199 199 179 212 187 197 203 206 165 202 200 199 221 199 203 210 184 206 209 199 196 231 191 221 200 191 221 203 185 205 209 180 226 179 205 180 180 192 198 175 200 219 211 200 225 220 201 184 205 191 199 213 196 202 211 200 195 197 189 206 201 218 195 205 200 213 210 208 217 222 192 187 197 198 197 183 206 206 206 184 218 201 209 186 199 212 202 197 182 207 225 218 189 207 198 213 221 196 179 198 195 180 194 211 168 185 204 198 211 212 222 201 193 187 182 201 192 212 185 199 182 197 199 194 207 179 194 200 212 192 224 182 220 201 177 209 187 222 202 200 203 198 190 197 216 222 220 198 191 206 205 208 216 214 188 199 190 203 207 212 183 195 188 200 215 186 192 210 173 235 188 179 176 228 176 185 221 192 212 202 203 199 182 183 210 218 195 217 199 212 192 189 214 207 216 204 201 190 205 189 194 222 191 195 230 197 188 206 196 202 192 218 228 182 206 189 195 189 220 193 216 202 180 198 189 184 208 216 210 237 202 200 215 204 210 193 220 220 213 224 204 226 197 194 182 213 211 240 222 210 227 199 218 212 207 217 193 180 197 198 200 190 223 198 202 179 193 212 211 176 194 204 209 209 206 201 205 211 216 208 186 202 212 212 197 195 195 180 211 205 190 186 207 188 197 198 180 195 191 195 192 170 204 195 186 200 208 209 224 188 187 223 227 211 217 191 186 207 224 207 199 183 212 184 214 212 195 207 177 194 208 190 228 208 197 197 198 218 220 199 212 185 196 167 201 241 208 198 204 199 218 211 228 198 227 188 213 212 194 228 204 223 196 214 194 204 189 207 207 197 203 226 215 189 196 208 212 210 207 186 204 214 197 212 191 167 195 204 200 193 193 230 193 195 222 198 207 215 211 212 201 202 171 209 204 187 213 221 218 214 204 208 198 221 202 187 188 214 176 177 194 218 205 185 221 202 191 180 205 191 216 196 202 205 187 211 209 210 209 209 195 208 198 210 195 220 238 234 210 187 212 192 206 182 193 186 216 230 214 219 201 204 194 211 211 204 240 211 218 191 195 204 233 217 228 181 199 205 229 219 223 214 220 231 199 224 199 245 220 201 202 207 200 212 201 213 211 212 218 235 193 224 222 220 194 210 208 193 210 227 213 196 200 192 221 238 197 189 218 193 178 223 223 203 224 200 214 202 208 210 204 237 211 215 215 197 243 221 203 225 200 228 232 190 235 219 216 226 196 222 221 215 212 217 219 215 211 239 243 217 199 209 220 219 190 200 194 210 232 200 212 213 192 228 204 200 219 199 221 210 202 181 212 199 224 217 187 225 203 203 210 227 209 209 245 195 212 203 217 210 202 191 215 206 236 185 207 208 208 218 238 209 198 212 207 212 220 204 209 219 195 221 199 191 218 213 197 224 210 214 223 205 194 203 185 198 251 205 226 188 192 226 209 196 195 207 220 208 180 207 212 223 210 196 202 204 223 174 226 219 228 203 199 199 182 214 208 199 219 198 205 215 195 211 231 247 218 203 173 217 183 190 234 198 203 202 191 208 218 183 204 217 220 223 219 207 181 204 210 217 222 201 186 187 216 193 223 200 204 244 215 195 189 205 198 202 198 201 196 194 204 210 206 195 206 213 183 223 214 242 190 223 204 208 217 201 224 219 256 201 192 206 196 176 239 182 209 221 205 200 205 202 230 211 169 226 214 207 192 215 194 204 202 193 178 206 209 200 216 178 193 194 196 206 222 197 204 203 194 207 221 193 228 185 200 220 192 209 211 232 193 197 209 199 202 212 208 158 221 199 188 187 220 209 203 186 192 216 198 209 204 200 211 216 188 181 192 218 222 193 191 214 210 216 225 209 203 210 214 192 218 219 221 181 214 222 212 185 205 207 213 185 197 207 168 199 190 241 207 209 200 223 208 211 215 235 188 209 210 188 225 218 219 195 213 218 202 212 223 225 228 218 194 197 211 214 203 230 188 218 208 205 217 206 213 220 210 216 179 210 203 193 219 181 223 217 246 216 211 235 187 195 202 182 212 197 221 224 198 213 199 202 190 194 208 206 209 212 216 207 210 203 190 174 224 195 205 208 178 224 224 201 184 213 196 206 196 217 214 188 211 202 193 183 206 209 227 202 232 190 205 224 210 227 234 213 207 197 218 198 232 229 224 184 201 215 211 217 210 216 203 206 183 200 180 203 189 200 222 195 213 224 206 217 198 196 196 221 229 186 199 218 212 216 192 194 193 197 225 217 205 226 202 193 178 216 211 203 173 200 205 203 208 193 208 194 206 184 204 193 212 212 216 203 187 192 219 216 217 184 208 234 211 196 194 208 239 221 207 207 223 206 222 209 208 228 188 216 226 193 231 206 198 203 204 201 218 230 198 232 215 229 235 202 186 197 201 218 207 213 183 217 199 206 234 231 210 188 214 213 188 196 202 197 223 196 197 220 225 201 209 209 201 185 223 201 194 205 201 199 208 205 215 196 215 200 187 204 210 216 175 201 209 197 189 203 195 188 209 214 199 215 197 196 209 210 201 204 201 201 208 215 198 224 191 201 210 236 178 210 204 188 224 167 203 215 207 209 194 226 227 205 211 259 242 195 196 218 212 200 184 186 178 195 186 208 192 230 212 211 201 218 202 208 201 213 210 249 242 196 190 223 215 210 215 200 182 203 199 202 212 206 205 214 202 211 195 203 220 205 190 197 184 210 198 213 186 193 192 196 211 192 220 192 211 217 208 206 200 197 191 223 220 186 266 197 200 209 218 205 208 199 195 192 198 195 198 190 259 192 200 216 192 197 209 195 205 217 211 209 203 206 192 195 208 195 191 228 195 211 198 215 216 174 218 209 189 201 201 183 216 200 193 190 202 213 202 190 209 193 194 213 205 203 200 182 175 199 212 237 203 220 222 193 195 230 186 209 217 207 202 208 196 231 188 204 215 225 199 210 187 176 217 223 211 206 224 225 200 205 192 192 224 196 222 219 229 225 197 220 210 186 223 206 227 225 210 189 198 172 198 210 237 228 210 273 221 218 214 215 210 197 197 203 220 222 206 217 216 199 224 201 226 233 219 210 209 201 211 188 203 204 222 222 221 188 200 187 202 207 238 224 195 199 187 219 224 207 202 189 193 221 204 212 207 220 211 213 187 207 225 229 222 213 202 213 194 172 211 205 194 227 199 220 192 224 216 230 215 188 202 196 236 204 201 192 209 217 212 194 199 210 195 222 192 201 203 195 227 218 186 183 206 203 194 229 204 212 211 219 180 186 205 204 228 220 184 222 204 214 206 229 232 195 206 203 196 210 218 213 191 198 171 179 199 208 214 203 229 219 206 197 196 231 203 210 200 223 230 206 230 202 212 205 230 193 191 205 198 206 217 211 197 195 238 209 217 193 198 223 191 235 189 221 199 205 216 212 210 201 213 212 230 225 208 191 191 229 190 198 216 186 206 213 190 215 231 181 215 205 214 211 195 210 205 218 228 205 202 213 234 224 186 231 228 217 216 209 206 222 223 212 227 212 221 195 194 209 189 175 194 210 219 213 220 233 201 236 204 211 226 208 208 189 216 220 223 201 216 236 223 178 225 217 206 255 229 218 212 217 224 209 228 220 206 222 214 221 217 236 218 212 201 212 195 196 219 221 235 224 218 211 222 213 190 204 224 194 201 204 216 249 221 206 186 210 220 216 204 205 192 196 226 247 219 203 213 220 225 216 200 218 210 209 203 207 209 229 211 211 211 218 221 215 226 227 223 224 219 220 208 236 216 183 214 218 237 226 208 224 205 211 229 226 212 210 235 214 205 212 215 198 216 236 217 212 208 206 227 205 217 208 223 234 207 202 202 211 215 222 219 182 211 211 241 209 232 213 201 228 182 196 207 206 220 225 232 201 196 218 194 215 217 217 242 207 224 219 208 218 213 197 215 215 208 204 204 218 212 214 208 217 210 231 202 203 192 213 202 210 213 225 224 209 206 214 180 211 211 215 220 227 200 238 245 214 231 198 222 218 220 238 218 200 239 205 199 205 184 211 219 210 212 195 217 202 202 203 204 226 206 213 191 206 225 200 218 224 196 235 201 245 205 236 223 228 257 231 200 210 208 211 215 225 218 218 223 240 217 227 239 263 224 226 205 214 246 212 197 219 181 225 215 235 203 234 213 204 209 183 210 236 200 202 221 206 223 200 205 238 230 224 199 238 212 212 223 226 233 205 206 214 216 218 217 203 192 208 195 199 202 213 193 202 248 234 207 226 224 218 211 184 224 247 228 204 224 218 233 215 216 221 220 215 227 229 207 232 236 232 223 226 213 214 207 225 218 231 219 242 218 256 224 213 198 202 213 218 196 216 206 232 201 239 206 211 225 213 236 221 208 199 223 186</counts>
			</dataPoints>
		</scan>
	</xrdMeasurement>
</xrdMeasurements>