File: data/XRD/XG-Vakuum/XG-600/W6821-1C_XG_Vakuum_600.xrdml
<xrdMeasurements xmlns="http://www.xrdml.com/XRDMeasurement/2.1" xmlns:xsi="http://www.w3.org/2001/XMLSchema-instance" xsi:schemaLocation="http://www.xrdml.com/XRDMeasurement/2.1 http://www.xrdml.com/XRDMeasurement/2.1/XRDMeasurement.xsd" status="Completed">
	<comment>
		<entry>Configuration=Factory configuration, Owner=User-1, Creation date=7/8/2013 4:01:53 PM</entry>
		<entry>Goniometer=PW3050/65 (Theta/2Theta); Minimum step size 2Theta:0.0001; Minimum step size Omega:0.0001</entry>
		<entry>Sample stage=MRD Cradle; Minimum step size Phi:0.01; Minimum step size Chi:0.01; Minimum step size X:0.01; Minimum step size Y:0.01; Minimum step size Z:0.001</entry>
		<entry>Diffractometer system=XPERT-PRO</entry>
		<entry>Measurement program=C:\PANalytical\Data Collector\Programs\Jorrit\2thom\_absolute_2th-om_10-130deg_PIXscan_56min.xrdmp, Identifier={15BCCF57-2807-42BD-B5B9-ECC0B3DC9284}</entry>
		<entry>Batch program=C:\PANalytical\Data Collector\Programs\SimonL\batch4x_2thom_10-130°_z9.1_x0,10,20,30_y0_57min.xrdmp, Identifier={EED9823A-2BEB-424C-9252-345C4EF2834A}</entry>
	</comment>
	<sample type="To be analyzed">
		<id></id>
		<name></name>
		<preparedBy></preparedBy>
	</sample>
	<xrdMeasurement measurementType="Scan" status="Completed" sampleMode="Reflection">
		<comment>
			<entry>_absolute_2th-om_10-130deg_PIXscan_56min</entry>
			<entry>PHD Lower Level = 4.83 (keV), PHD Upper Level = 11.27 (keV)</entry>
		</comment>
		<usedWavelength intended="K-Alpha 1">
			<kAlpha1 unit="Angstrom">1.5405980</kAlpha1>
			<kAlpha2 unit="Angstrom">1.5444260</kAlpha2>
			<kBeta unit="Angstrom">1.3922500</kBeta>
			<ratioKAlpha2KAlpha1>0.5000</ratioKAlpha2KAlpha1>
		</usedWavelength>
		<incidentBeamPath>
			<radius unit="mm">320.00</radius>
			<xRayTube id="1010048" name="Empyrean Cu LFF HR (9430 033 7310x) DK442154">
				<tension unit="kV">40.0</tension>
				<current unit="mA">40.0</current>
				<anodeMaterial>Cu</anodeMaterial>
				<focus type="Line">
					<length unit="mm">12.0</length>
					<width unit="mm">0.4</width>
					<takeOffAngle unit="deg">4.2</takeOffAngle>
				</focus>
			</xRayTube>
			<xRayMirror id="27010001" name="Inc. Beam Cu W/Si (parabolic MRD)" hybrid="false">
				<crystal type="Graded" shape="Parabolic">W/Si</crystal>
				<acceptanceAngle unit="deg">0.800</acceptanceAngle>
				<length unit="mm">60.0</length>
			</xRayMirror>
			<sollerSlit id="21010002" name="Soller slits 0.04 rad.">
				<opening unit="rad">0.0400</opening>
			</sollerSlit>
			<mask id="22030008" name="Fixed mask 4 mm">
				<distanceToSample unit="mm">220.00</distanceToSample>
				<width unit="mm">4.00</width>
			</mask>
			<divergenceSlit id="22010007" name="Fixed slit 1/8°" xsi:type="fixedDivergenceSlitType">
				<distanceToSample unit="mm">220.00</distanceToSample>
				<height unit="mm">0.19</height>
			</divergenceSlit>
		</incidentBeamPath>
		<diffractedBeamPath>
			<radius unit="mm">320.00</radius>
			<sollerSlit id="21010002" name="Soller slits 0.04 rad.">
				<opening unit="rad">0.0400</opening>
			</sollerSlit>
			<receivingSlit id="22010001" name="Fixed slit 4°">
				<height unit="mm">5.88</height>
			</receivingSlit>
			<detector id="7010017" name="PIXcel3D 1x1 detector" xsi:type="areaDetectorType">
				<phd unit="%">
					<lowerLevel>30.0</lowerLevel>
					<upperLevel>70.0</upperLevel>
				</phd>
				<mode>Scanning</mode>
				<activeChannelsEquatorial>255</activeChannelsEquatorial>
				<activeChannelsAxial>255</activeChannelsAxial>
				<pitchEquatorial unit="mm">0.05500</pitchEquatorial>
				<pitchAxial unit="mm">0.05500</pitchAxial>
				<readOutPeriod unit="seconds">0.135</readOutPeriod>
			</detector>
		</diffractedBeamPath>
		<scan appendNumber="0" mode="Continuous" scanAxis="2Theta-Omega" status="Completed">
			<header>
				<startTimeStamp>2024-10-08T19:51:12+02:00</startTimeStamp>
				<endTimeStamp>2024-10-08T20:47:18+02:00</endTimeStamp>
				<author>
					<name>PRO-MRD</name>
				</author>
				<source>
					<applicationSoftware version="6.1b">Data Collector</applicationSoftware>
					<instrumentControlSoftware version="7.0E 20130304">XPERT-PRO</instrumentControlSoftware>
					<instrumentID>0000000011142674</instrumentID>
				</source>
			</header>
			<dataPoints>
				<positions axis="2Theta" unit="deg">
					<startPosition>9.99826193</startPosition>
					<endPosition>129.99755682</endPosition>
				</positions>
				<positions axis="Omega" unit="deg">
					<startPosition>4.99913096</startPosition>
					<endPosition>64.99877841</endPosition>
				</positions>
				<positions axis="Phi" unit="deg">
					<commonPosition>0.00</commonPosition>
				</positions>
				<positions axis="Chi" unit="deg">
					<commonPosition>0.00</commonPosition>
				</positions>
				<positions axis="X" unit="mm">
					<commonPosition>0.00</commonPosition>
				</positions>
				<positions axis="Y" unit="mm">
					<commonPosition>0.00</commonPosition>
				</positions>
				<positions axis="Z" unit="mm">
					<commonPosition>9.100</commonPosition>
				</positions>
				<commonCountingTime unit="seconds">32.895</commonCountingTime>
				<counts 480 462 431 472 470 420 415 466 427 438 439 417 451 432 424 395 423 432 440 440 424 473 478 440 411 468 471 433 479 439 481 464 411 408 422 437 440 445 464 458 430 463 421 462 421 417 395 409 413 411 416 414 413 442 386 431 414 433 397 406 397 430 422 415 408 405 429 412 429 422 431 389 409 420 429 426 432 407 440 382 401 398 394 401 411 401 421 429 411 419 400 444 428 382 437 416 437 392 410 413 400 412 390 420 404 409 426 425 432 384 381 434 366 403 389 385 363 424 425 414 407 402 425 391 414 418 394 389 421 386 407 412 403 372 381 393 409 395 414 412 415 431 397 390 381 385 416 396 405 468 392 421 430 395 385 400 392 408 409 412 385 369 403 385 398 400 378 395 383 386 410 354 361 405 378 367 372 412 395 369 401 388 414 389 352 410 395 368 382 363 381 387 366 404 373 389 379 367 372 397 378 398 390 363 384 407 374 365 378 374 404 393 385 378 375 360 366 369 371 408 359 391 389 368 411 398 370 370 399 365 423 365 450 360 354 398 376 377 366 372 363 366 405 359 396 369 356 374 378 360 347 361 342 345 375 399 384 373 372 353 350 363 396 369 377 380 369 363 336 361 379 358 375 339 331 357 358 371 389 355 390 337 389 350 374 373 379 356 390 375 352 365 372 372 366 368 353 347 364 327 355 347 372 334 364 329 371 365 354 346 351 358 301 348 358 370 346 336 357 351 357 384 345 330 354 361 365 349 355 303 311 349 389 339 360 353 341 354 327 339 341 309 373 334 344 341 343 380 345 310 345 332 354 357 367 352 335 372 346 322 358 350 345 362 325 381 311 353 353 327 383 360 360 358 359 361 350 309 327 339 336 304 333 364 334 353 303 350 348 313 353 334 379 362 348 338 367 347 340 351 353 324 362 329 345 330 320 312 344 293 320 337 361 326 331 342 340 334 335 308 360 322 343 316 350 336 309 321 325 328 327 317 322 331 325 316 331 348 304 345 314 326 311 326 336 315 357 312 316 324 357 335 303 360 314 342 330 326 341 314 307 322 310 322 339 312 340 347 317 316 314 282 295 335 290 301 272 345 310 317 361 286 319 319 322 331 319 292 364 307 340 338 331 307 295 335 343 323 330 304 352 320 320 351 325 313 312 344 329 344 328 327 305 332 323 336 312 336 303 318 306 294 344 330 321 295 307 318 324 314 324 315 325 316 314 313 296 322 323 314 308 331 309 283 327 303 334 346 321 321 344 323 309 313 330 301 284 343 307 285 328 325 311 288 283 313 313 317 319 299 324 289 321 330 322 337 294 333 330 323 323 321 327 330 309 315 335 321 286 312 291 305 322 299 311 317 333 305 284 312 302 313 287 310 297 294 288 291 332 329 307 330 297 284 281 306 332 316 320 344 287 312 321 315 296 315 341 274 285 310 330 322 291 312 277 317 305 316 330 344 316 288 315 315 293 327 299 313 283 319 275 302 313 292 336 320 305 304 289 305 314 312 304 312 314 274 291 332 305 269 304 298 293 283 272 310 291 302 302 315 305 284 305 314 321 317 328 307 291 314 333 307 325 312 312 291 277 332 334 301 291 306 301 291 288 307 335 337 283 296 288 309 318 298 320 310 309 299 297 310 323 287 290 297 290 337 305 311 293 298 297 300 333 286 255 292 328 282 299 339 318 304 327 313 302 295 333 305 274 328 294 283 321 268 336 295 302 330 305 306 296 317 309 316 320 331 279 346 354 307 317 287 299 338 307 288 312 292 310 308 320 312 311 338 286 307 325 310 281 267 305 332 311 317 300 303 304 309 268 302 326 276 333 342 299 345 271 320 286 316 312 315 349 315 310 294 303 326 343 312 279 310 303 312 306 303 312 303 287 296 333 307 307 295 323 284 317 299 309 325 278 348 282 303 312 372 290 312 304 336 300 312 316 299 293 288 319 274 301 315 316 293 306 325 283 297 300 313 300 292 290 315 320 275 269 299 322 294 319 299 298 289 313 294 315 276 291 305 320 316 302 306 331 332 327 321 303 328 301 312 334 317 329 300 302 282 309 298 322 317 322 325 286 305 312 298 290 312 302 307 275 278 336 314 330 317 316 313 290 291 322 314 291 296 320 316 286 318 333 306 315 339 309 323 313 296 320 315 321 330 326 335 314 326 303 318 305 290 304 332 317 316 326 287 334 334 330 316 315 339 306 297 352 295 310 351 310 306 333 332 318 292 334 324 315 319 330 324 334 306 335 318 314 302 312 327 293 281 304 308 350 308 324 320 321 330 309 286 333 300 336 296 318 319 331 336 328 264 338 283 300 335 328 299 338 328 345 349 308 275 294 323 338 321 354 333 291 302 327 352 294 311 317 307 328 332 330 320 345 361 327 301 332 326 300 316 308 322 300 324 325 340 337 293 322 328 328 334 305 318 347 356 322 323 295 333 304 303 339 319 313 319 301 308 304 329 361 370 329 319 325 353 304 319 352 328 311 328 291 353 309 288 316 299 313 325 300 338 314 315 318 328 340 320 312 332 331 302 300 323 331 335 350 325 344 340 361 333 332 336 324 326 313 323 323 301 328 342 321 335 321 318 339 320 344 327 329 347 351 307 318 366 308 328 328 301 314 327 359 346 345 347 323 326 327 344 331 330 321 383 309 321 309 340 340 336 321 324 295 333 326 320 347 352 324 318 331 357 311 327 311 320 333 334 354 334 332 343 334 294 335 310 326 343 322 344 319 306 323 335 351 336 312 331 326 349 336 315 299 317 299 319 321 340 332 314 353 321 325 343 327 338 309 318 392 325 351 344 359 309 340 316 326 331 326 323 311 317 327 331 343 323 335 305 359 365 327 311 343 323 315 319 316 331 329 385 371 353 353 344 345 338 337 369 342 334 335 339 329 307 338 337 343 304 343 331 321 343 317 349 327 331 322 350 362 363 332 317 316 339 320 339 311 323 334 354 331 357 356 320 330 313 315 325 314 296 340 314 355 365 359 346 347 305 343 323 354 330 354 344 368 349 338 345 310 303 348 327 341 314 357 316 314 354 311 325 329 307 324 322 318 359 312 333 309 336 316 356 326 332 345 309 342 395 327 303 353 372 349 314 330 312 322 338 303 331 339 310 329 314 334 331 310 323 348 323 312 365 335 339 357 344 351 332 294 321 334 313 300 328 310 353 356 318 328 330 333 300 329 341 345 339 329 309 325 333 330 305 328 306 324 342 315 330 364 319 341 308 359 349 352 320 356 317 349 328 341 316 319 305 313 359 321 315 315 329 294 305 313 322 354 337 340 326 298 326 346 319 323 326 338 361 317 343 315 335 319 315 344 304 286 326 334 318 288 308 307 283 322 323 317 318 342 306 337 317 329 334 333 321 361 300 324 348 310 332 337 337 305 331 315 341 334 302 337 302 344 328 329 308 293 308 329 295 327 319 332 304 332 342 303 297 305 336 347 341 310 305 328 311 330 347 313 323 277 317 318 325 331 346 299 354 322 333 322 325 287 346 320 302 332 350 319 317 308 319 336 320 319 296 313 346 319 318 308 314 296 344 310 337 314 324 319 326 286 341 337 312 290 309 299 322 329 303 297 341 302 318 296 318 337 325 309 303 322 305 312 318 323 350 311 328 301 319 307 291 326 301 280 325 326 305 322 291 318 317 340 325 318 280 317 325 322 286 320 304 318 319 318 296 316 304 338 295 294 313 316 288 283 308 325 316 325 284 327 328 330 307 290 301 291 291 325 307 289 309 299 296 312 325 329 294 318 299 309 294 291 299 280 300 273 300 298 274 302 322 303 311 308 284 277 311 312 302 312 314 277 323 294 289 274 305 318 322 306 309 282 335 319 314 295 309 269 302 320 316 314 292 287 276 314 321 284 286 296 344 290 314 315 284 291 286 297 266 339 301 308 284 293 324 272 297 296 296 292 292 293 312 291 319 305 284 277 294 333 289 295 307 286 316 325 278 302 307 309 308 293 288 260 269 294 288 311 273 312 275 299 272 281 285 264 307 340 308 298 303 292 318 264 274 285 318 265 307 329 277 294 276 309 287 281 304 301 289 286 297 292 319 287 255 246 281 294 313 265 293 262 298 306 305 287 296 293 301 346 274 267 302 284 277 278 295 258 282 309 291 319 287 318 300 288 292 295 329 288 318 294 303 299 318 281 285 272 311 270 295 290 286 264 305 283 328 303 296 279 303 306 287 269 295 256 269 298 265 277 264 275 285 275 279 276 283 302 293 264 274 283 275 309 299 306 267 285 271 282 292 278 298 302 286 318 273 273 307 296 264 276 306 298 296 327 290 288 289 288 282 270 281 282 264 291 275 326 256 269 262 303 287 295 299 281 259 263 278 259 261 301 255 311 268 291 297 314 279 263 245 291 282 282 269 278 278 279 291 288 299 293 257 286 274 304 275 289 274 280 269 304 276 295 303 267 280 299 316 284 266 281 289 265 293 273 286 265 290 269 260 286 262 265 250 267 304 273 283 305 286 261 274 284 275 257 284 292 276 271 259 264 291 264 273 282 274 303 276 282 263 277 291 281 293 246 284 289 241 297 280 240 279 270 240 288 268 270 269 312 280 279 301 270 240 314 259 285 296 303 263 241 275 290 244 287 260 264 272 267 296 283 277 265 247 292 267 280 266 301 270 257 297 274 281 270 267 305 257 281 282 270 272 280 271 264 278 283 259 300 284 292 301 267 267 306 262 272 259 278 280 264 283 291 283 288 232 280 292 304 316 266 265 278 275 244 255 271 285 268 278 276 270 257 272 280 286 287 277 272 287 247 275 262 267 262 267 306 318 289 241 272 259 263 279 264 272 282 271 307 262 312 255 272 311 245 278 230 277 270 279 289 302 289 246 266 294 279 263 267 242 282 265 275 275 285 268 269 227 268 290 263 274 286 266 293 260 261 262 246 282 260 246 262 284 274 236 281 232 249 278 246 275 301 239 291 295 283 256 263 286 284 242 272 288 248 278 236 272 257 286 269 275 269 268 272 262 263 248 279 256 265 234 247 278 271 294 285 260 277 248 269 273 281 240 240 279 283 265 236 273 247 256 233 239 256 242 248 280 272 263 282 288 286 224 281 223 242 281 259 269 250 228 283 236 271 290 278 290 270 263 270 262 293 264 266 284 222 268 258 282 248 268 281 246 255 249 279 237 287 282 255 259 292 262 274 259 232 270 244 268 267 245 289 276 282 238 237 249 285 249 268 245 258 248 250 269 273 243 267 271 244 270 238 293 307 230 218 260 258 279 267 279 261 268 265 290 268 236 270 279 248 260 244 269 248 240 264 255 282 283 284 227 244 272 233 269 274 282 249 263 277 266 241 266 277 261 275 237 263 297 269 274 274 262 258 291 279 284 245 262 264 275 266 281 266 233 241 286 272 247 242 269 283 255 256 263 240 277 270 234 262 250 246 257 239 238 263 231 296 265 238 262 259 261 256 274 278 273 260 287 232 260 266 229 249 260 247 224 258 259 266 261 284 258 249 231 273 275 262 256 257 249 282 269 260 237 288 244 259 246 270 244 270 267 275 246 260 239 269 263 255 273 275 242 248 246 283 244 269 220 263 259 265 243 272 263 275 235 255 293 281 256 305 260 222 256 264 249 273 265 305 255 287 271 238 231 262 237 243 240 244 237 264 239 230 239 256 248 260 273 231 273 281 244 293 242 247 250 243 282 270 244 259 271 274 266 242 244 236 263 259 259 236 243 264 257 293 240 296 248 242 266 291 255 279 282 276 258 219 243 239 272 259 267 259 232 284 228 227 242 274 238 279 242 280 270 278 262 284 238 265 259 267 278 240 238 267 232 297 257 234 257 297 292 234 249 244 273 244 263 262 246 238 247 241 257 282 242 258 264 233 267 255 242 265 237 257 273 227 280 281 237 269 246 271 278 283 278 270 243 228 263 242 241 247 261 283 275 255 228 249 232 247 249 286 245 277 240 259 260 257 229 247 285 265 264 264 238 258 270 270 291 232 275 258 255 261 267 261 259 288 232 258 285 240 242 248 238 245 257 269 246 255 242 248 241 239 283 264 287 270 272 247 275 263 249 274 243 227 220 246 246 256 234 240 246 259 248 274 227 277 238 218 275 310 260 243 234 272 234 273 288 281 292 266 263 260 284 284 264 284 286 260 275 245 273 276 260 259 271 272 241 275 239 267 286 319 290 271 276 272 241 276 266 229 282 249 239 293 249 286 269 248 256 283 270 284 231 260 226 293 246 243 277 272 262 259 276 268 281 268 278 256 235 261 255 259 260 258 230 269 242 242 263 229 275 223 261 231 259 246 249 268 238 250 244 270 265 256 258 239 259 267 280 246 237 301 247 260 275 275 242 269 246 249 271 249 268 246 234 264 271 287 240 281 241 265 237 259 237 273 256 229 284 226 258 262 282 275 235 269 229 241 275 230 271 246 242 267 264 236 274 250 274 258 261 260 244 229 286 264 243 238 232 235 269 236 257 266 232 244 277 239 225 273 244 249 277 262 239 266 270 234 242 271 228 287 262 256 246 233 228 239 256 227 272 265 214 275 265 237 259 241 243 230 225 264 241 237 263 245 242 265 269 243 290 238 275 249 232 237 264 237 269 268 244 224 234 272 236 232 228 279 243 272 262 230 249 257 229 275 233 231 268 275 261 266 245 247 228 255 288 259 248 257 261 264 263 268 259 264 278 234 240 267 223 298 281 275 267 223 270 255 240 240 260 306 255 242 259 277 248 272 237 280 227 258 279 260 271 245 235 265 264 216 240 245 234 247 246 249 242 273 241 242 275 244 219 267 280 247 273 226 288 269 256 259 246 255 244 258 265 257 246 277 237 273 268 261 248 245 279 269 221 257 277 244 280 248 282 255 261 246 279 228 260 237 273 248 265 240 279 261 236 238 237 222 278 230 265 249 281 263 267 230 292 261 273 268 260 245 255 250 231 245 240 234 265 247 277 260 278 271 293 233 229 269 268 261 265 267 276 295 249 262 244 222 282 261 258 287 257 246 239 247 234 234 290 266 240 261 258 234 244 260 282 280 240 256 273 259 270 269 229 259 258 275 212 287 222 238 256 236 233 276 255 286 256 266 266 276 259 280 271 244 255 264 225 273 221 236 264 255 265 248 276 274 289 236 271 250 273 266 238 269 273 288 255 258 297 258 259 260 262 256 214 259 264 262 247 297 242 238 282 263 247 278 231 257 280 248 258 279 284 270 266 263 239 265 262 262 273 260 247 267 255 247 265 284 269 276 241 273 255 247 261 281 243 267 287 281 258 265 266 268 230 258 263 236 289 273 260 275 274 239 280 268 276 247 226 278 260 279 266 241 221 273 258 281 224 249 277 265 280 265 259 246 257 241 293 272 262 239 236 277 270 238 278 238 272 283 261 268 278 273 240 284 268 255 270 269 243 249 285 257 286 283 273 236 278 259 258 249 292 247 330 283 287 244 279 280 277 244 280 267 242 291 284 249 223 264 235 284 268 247 238 271 268 283 258 290 269 276 271 299 283 265 264 257 258 239 263 294 312 283 297 242 275 264 288 263 295 289 277 284 281 294 273 289 286 262 291 294 257 260 261 279 305 269 298 244 315 274 276 286 287 285 310 277 278 274 295 272 242 283 275 297 266 243 242 290 285 290 261 272 255 255 283 268 283 309 241 243 270 327 272 271 273 258 283 269 262 283 265 259 277 264 285 285 288 288 295 272 275 261 270 260 283 281 271 289 270 321 250 274 315 299 289 281 292 290 312 300 310 282 296 278 286 292 302 289 283 343 304 321 308 314 286 283 314 284 313 335 301 294 289 348 285 335 332 324 343 314 361 332 348 355 345 366 378 353 386 366 411 379 405 418 434 438 418 495 467 490 482 480 528 491 525 511 501 487 518 484 511 448 486 458 475 478 453 448 432 379 431 433 386 390 404 388 363 348 367 337 364 336 308 370 332 312 311 327 302 326 323 323 279 323 305 291 305 309 294 293 281 286 282 298 288 301 300 266 297 268 297 258 293 295 285 269 284 274 279 290 258 275 267 274 268 310 286 282 280 275 249 276 266 278 285 267 258 238 242 260 246 241 265 285 258 296 285 241 240 239 278 249 245 274 245 259 267 275 245 277 283 274 279 265 282 242 279 279 258 255 286 261 267 307 259 230 263 268 265 246 248 285 300 264 270 293 263 231 266 279 248 258 246 242 266 230 297 225 287 267 245 248 286 273 276 288 295 307 228 233 258 242 289 246 270 280 275 273 255 257 297 262 243 271 289 258 291 241 290 259 256 233 257 230 282 257 278 297 298 272 240 257 266 249 266 278 272 276 268 283 262 275 255 306 257 274 260 270 247 248 244 245 272 209 244 287 264 275 279 266 268 232 255 241 232 257 259 258 256 246 284 276 267 275 244 224 262 267 244 240 242 255 283 263 227 268 267 242 262 281 257 244 262 259 269 259 273 242 256 294 257 258 271 246 243 257 270 247 267 235 272 268 255 272 273 263 289 240 269 267 239 244 266 261 277 240 293 261 245 266 248 240 272 283 245 279 274 238 302 274 268 276 276 275 274 270 237 255 282 240 278 271 247 261 223 257 240 264 242 234 247 248 234 284 226 260 264 256 258 258 265 247 260 260 233 264 234 264 264 238 242 280 248 280 277 245 261 234 259 244 260 267 259 277 272 291 259 265 210 265 279 243 257 260 246 259 248 279 258 263 256 263 255 261 210 242 228 256 242 298 258 262 227 280 269 266 271 204 237 281 276 245 269 286 244 256 243 237 258 232 245 256 278 267 265 263 269 270 272 249 256 298 249 241 261 235 286 261 258 269 266 245 272 260 276 238 259 242 241 233 266 260 262 255 221 279 255 255 285 272 263 271 263 249 271 244 249 256 265 243 278 280 228 281 265 271 241 246 277 287 248 256 269 269 232 257 233 263 286 263 269 264 304 257 221 276 255 256 275 242 234 246 276 263 282 290 290 258 271 234 261 269 269 266 244 258 239 272 275 255 255 240 225 247 277 247 261 298 281 262 283 275 271 266 245 237 261 259 232 242 231 255 259 236 282 262 237 244 271 260 247 284 262 283 276 289 278 280 236 256 269 247 234 261 290 301 283 271 285 267 236 266 269 266 257 267 276 280 256 260 248 226 240 274 246 239 299 290 219 269 269 248 243 224 246 236 231 260 248 244 288 239 274 265 264 255 273 285 273 250 264 278 234 269 272 271 266 264 263 297 265 261 246 267 259 274 248 238 255 257 273 263 266 258 280 239 243 247 223 256 259 246 246 286 248 214 265 243 240 266 288 249 260 235 272 279 270 255 263 261 269 255 271 272 299 268 207 274 248 275 273 279 255 268 265 283 282 271 243 296 259 230 248 261 270 287 271 281 281 273 260 255 282 238 275 269 279 247 255 283 268 294 277 266 258 280 290 276 240 263 243 246 255 266 257 276 270 260 267 246 272 258 274 277 246 245 264 287 275 273 256 288 272 287 297 284 273 261 285 247 274 298 257 277 271 258 257 280 271 285 268 273 287 257 284 269 276 250 233 260 244 280 284 295 288 290 273 270 285 286 262 276 275 243 230 262 249 255 255 223 282 272 292 245 262 245 283 285 310 227 234 275 278 294 240 272 247 246 273 266 256 258 225 248 266 243 238 259 275 240 267 229 255 268 244 255 258 240 235 280 279 256 257 268 266 262 299 244 280 270 244 232 226 281 276 276 239 262 261 280 234 245 278 273 256 230 249 279 273 286 219 248 256 214 281 231 259 271 226 238 269 257 260 262 233 249 233 294 259 237 241 288 279 214 279 273 267 272 261 263 270 281 284 265 246 250 245 259 244 293 266 258 306 245 240 272 229 271 263 282 284 263 256 247 256 266 264 234 260 278 271 259 260 243 262 275 235 281 258 271 288 257 257 265 259 262 259 244 280 242 255 273 265 235 265 246 267 241 263 235 265 249 242 243 262 284 259 274 286 266 278 216 262 242 275 284 239 247 287 266 267 241 295 284 268 293 263 262 280 267 243 263 270 262 267 272 274 241 266 293 271 256 284 274 265 246 282 239 267 275 247 268 278 296 276 245 233 249 288 262 270 256 295 262 261 277 246 241 243 270 248 266 256 238 263 265 248 230 247 249 262 266 281 265 247 263 298 287 279 256 272 246 271 234 277 263 277 245 248 275 275 264 239 255 235 258 268 276 279 266 265 268 263 239 258 269 241 266 229 242 272 282 273 259 268 233 264 271 261 262 233 236 260 273 246 258 276 250 231 260 290 245 250 246 242 239 267 256 242 274 259 266 261 300 271 259 249 257 255 265 238 284 248 310 247 241 260 230 225 286 275 272 276 270 261 267 229 256 259 266 273 236 264 261 248 263 266 276 275 261 250 284 262 267 245 265 266 276 233 284 271 284 278 237 247 275 246 246 259 274 227 263 263 261 279 232 281 245 274 275 306 257 263 266 245 265 242 265 226 257 248 247 270 266 262 239 261 246 267 265 246 249 282 264 265 271 224 273 290 267 268 265 246 249 237 268 255 237 270 247 276 258 264 281 261 257 259 261 276 243 248 245 248 264 270 275 256 274 256 283 237 240 247 281 272 248 269 285 276 261 279 275 258 249 243 287 267 280 246 260 258 270 232 285 236 257 224 275 242 240 255 260 274 249 235 238 245 241 293 299 281 267 248 262 269 246 265 295 284 269 255 259 283 268 279 227 257 268 217 243 263 227 259 248 271 258 241 248 250 277 297 267 286 265 271 259 262 234 245 299 260 238 272 260 246 264 267 282 234 285 243 262 268 280 296 275 255 259 275 269 273 262 259 269 290 270 292 260 235 221 278 266 280 247 285 258 231 238 304 260 222 278 264 295 264 266 269 255 248 247 229 285 246 245 242 267 224 255 273 238 242 241 224 241 264 280 256 272 263 259 264 278 234 228 255 275 255 268 268 263 271 288 270 284 242 273 299 240 288 271 249 292 287 244 258 277 243 262 274 247 259 245 229 293 283 239 289 270 259 260 284 250 249 272 264 260 270 284 274 241 271 262 216 273 262 249 264 290 281 236 244 266 299 276 279 267 269 262 259 276 238 285 255 290 279 261 269 226 236 257 265 237 263 268 283 287 260 259 270 264 246 264 242 243 265 271 264 291 270 292 218 283 272 260 259 278 278 270 262 260 272 304 279 267 256 239 270 271 279 243 276 291 266 261 267 250 268 277 281 278 270 240 299 266 250 257 249 287 285 273 267 274 269 261 259 255 246 242 242 284 273 273 261 273 260 261 276 256 246 235 256 258 243 276 282 262 258 247 271 280 294 277 307 264 270 282 239 228 292 270 266 276 247 265 265 227 227 249 274 283 265 246 271 249 260 271 248 260 272 260 283 249 255 260 261 241 265 238 294 299 276 284 243 280 271 233 237 283 230 260 262 269 274 284 247 270 232 275 245 263 260 256 260 279 281 248 255 242 250 258 246 267 248 274 275 238 297 270 291 283 247 275 257 292 286 259 255 279 260 276 269 244 260 284 271 258 260 328 281 283 295 292 257 239 232 262 280 280 278 263 245 260 234 259 244 234 275 269 249 237 272 267 286 281 273 260 270 250 284 276 250 300 263 279 238 271 279 260 284 291 295 294 238 231 288 265 240 263 271 288 274 269 264 244 295 263 267 282 289 232 291 268 263 268 266 265 293 291 286 273 266 280 279 275 256 263 235 274 281 250 256 240 274 282 272 237 248 267 263 272 257 264 300 275 240 292 242 283 264 275 289 217 238 288 285 307 273 298 286 271 261 269 274 281 291 266 280 255 260 280 271 242 270 261 261 282 284 264 246 282 279 249 272 263 244 294 262 261 291 274 270 288 275 248 257 261 285 287 296 282 267 266 270 277 248 281 283 271 266 266 278 273 267 256 279 277 225 259 275 276 261 286 265 277 258 237 288 241 279 299 283 282 284 268 243 280 249 282 294 303 279 297 263 298 303 243 277 256 296 266 285 269 259 258 289 248 280 249 261 285 271 289 296 302 262 301 261 262 269 279 262 258 247 277 237 281 304 290 263 262 287 266 273 271 270 275 258 299 267 271 283 277 294 266 304 296 315 266 270 309 264 316 247 268 257 267 262 246 271 302 287 272 264 248 287 271 273 257 266 297 288 273 270 272 275 281 277 276 264 286 277 261 236 260 286 281 246 265 277 287 246 308 275 247 271 277 242 282 265 268 268 285 282 226 256 268 236 272 296 246 280 258 266 266 269 266 271 281 290 298 288 273 262 294 271 282 271 288 259 278 276 299 232 263 266 283 286 276 282 276 275 274 289 268 279 301 281 303 269 275 276 263 286 288 276 263 263 233 299 211 277 281 279 274 318 290 283 266 260 290 286 284 269 245 274 275 262 246 275 290 274 277 267 278 242 260 273 306 324 300 283 275 277 282 282 287 272 229 259 313 246 277 292 270 290 281 263 273 303 295 238 265 303 298 281 288 256 294 275 274 299 324 292 281 309 288 301 279 286 325 293 259 309 295 292 286 302 268 276 285 313 279 267 269 319 321 295 309 311 315 289 286 309 272 269 272 306 292 256 295 301 288 299 302 320 281 290 277 290 276 263 300 319 273 289 246 297 271 318 290 275 289 289 284 290 241 338 242 263 311 265 304 283 258 278 284 294 264 259 260 282 291 272 263 243 275 286 279 292 271 269 258 256 279 269 283 293 280 306 283 283 242 281 300 292 278 271 256 263 266 259 266 289 291 278 234 260 259 265 274 269 258 267 263 296 280 303 281 262 282 270 293 285 257 277 285 264 227 244 274 285 263 262 241 280 283 275 287 269 269 277 271 259 267 247 259 240 262 246 288 265 285 283 271 304 247 265 285 267 263 289 282 277 270 285 285 247 257 271 235 268 293 257 288 271 278 247 304 277 278 264 265 288 261 293 262 270 278 278 272 263 239 271 242 244 281 246 269 276 266 270 278 267 303 287 266 291 246 270 272 272 308 233 248 263 278 265 245 256 262 274 299 261 296 248 267 294 283 265 239 245 239 288 241 272 263 272 236 297 261 244 296 268 281 249 291 274 237 238 265 247 262 266 264 229 273 279 269 255 237 260 260 302 256 290 274 272 276 244 282 286 261 292 249 284 276 272 271 275 262 256 266 258 289 279 262 296 270 287 242 242 241 283 242 270 273 245 243 237 290 269 248 264 257 228 259 260 258 271 294 262 272 273 262 270 265 273 275 255 276 259 266 291 278 312 243 244 256 277 232 241 288 261 248 235 242 284 274 274 270 270 305 279 274 245 258 267 244 258 281 250 268 281 255 279 289 263 279 234 298 275 273 258 278 301 285 243 267 271 261 270 287 279 237 248 279 283 291 241 266 265 267 265 275 280 270 290 263 269 260 293 282 269 235 277 258 286 284 295 282 230 246 296 259 260 289 263 281 274 282 301 248 300 294 286 279 267 256 284 260 287 280 269 291 245 266 249 261 273 246 278 238 255 281 230 269 280 228 266 267 242 294 282 271 236 290 269 282 273 268 275 242 248 273 266 268 259 278 283 273 263 269 261 266 280 268 292 245 260 289 258 236 267 257 250 226 276 270 281 235 287 260 247 238 274 248 242 272 258 279 288 228 294 243 263 281 248 267 270 272 248 258 243 244 282 263 271 279 242 259 265 269 279 240 287 259 273 261 263 241 280 249 265 250 248 266 284 264 264 285 265 271 271 280 296 277 301 247 284 275 262 285 288 273 240 263 247 228 263 268 261 248 283 269 278 234 277 293 266 270 274 288 280 255 256 255 294 284 272 284 263 286 239 274 247 267 267 249 265 274 265 247 280 268 228 256 264 258 262 293 310 245 219 265 277 277 255 261 270 257 311 289 239 262 226 255 276 242 271 249 277 291 271 307 270 289 259 228 256 212 277 238 264 288 262 255 271 267 248 249 276 264 270 273 271 279 276 231 273 282 281 264 269 246 272 245 256 248 286 264 296 272 282 255 279 269 288 259 274 227 270 248 232 262 281 246 263 285 245 239 256 266 250 279 289 314 296 299 245 264 268 280 235 260 272 248 296 273 245 274 282 240 267 275 314 275 259 258 257 259 247 267 271 267 266 260 225 257 264 285 261 276 244 258 232 236 247 274 265 245 260 268 276 267 239 262 269 279 283 244 260 274 261 271 279 292 233 249 276 235 250 282 266 272 247 275 257 249 260 280 264 301 261 263 265 241 256 242 249 259 291 286 297 288 237 277 266 245 255 260 286 263 272 262 258 256 278 249 273 289 270 246 276 265 287 267 275 257 247 274 265 278 261 295 262 255 256 256 280 272 288 274 270 258 277 271 263 283 245 299 279 287 237 245 264 265 248 274 264 259 224 246 271 248 244 266 271 249 228 272 263 278 239 259 243 267 282 282 278 245 286 280 260 276 287 259 280 270 250 271 244 271 264 277 256 265 257 268 248 285 264 256 273 269 284 268 264 265 237 246 260 270 232 274 268 233 248 246 302 276 256 280 280 236 280 260 242 242 239 271 258 247 248 262 289 272 240 262 280 246 277 273 246 248 261 287 248 259 271 274 243 279 238 244 258 278 288 292 270 272 273 287 283 255 245 272 278 286 264 259 276 270 237 282 260 264 293 275 272 256 280 241 256 273 237 248 276 246 276 243 271 263 268 231 241 248 270 268 261 259 278 276 270 247 259 270 263 273 249 249 273 277 261 296 288 295 283 259 277 303 260 233 247 274 265 256 232 265 284 285 269 219 276 266 266 262 271 263 278 271 270 246 265 265 262 246 272 275 274 288 276 280 293 262 270 268 239 281 267 268 274 285 277 258 277 246 243 226 245 289 249 240 247 282 281 242 301 283 296 281 321 262 240 238 242 283 256 267 281 263 291 282 263 248 288 281 258 276 272 248 257 295 318 250 286 268 221 270 257 300 248 272 277 287 286 292 274 266 258 239 260 290 274 263 274 284 258 258 238 273 279 263 272 249 265 262 277 249 282 259 273 281 285 296 246 257 286 246 272 258 280 268 238 273 227 249 303 282 271 249 237 258 300 282 244 263 291 249 263 274 249 277 256 257 262 287 276 282 279 272 250 270 232 285 275 259 258 279 268 264 277 270 260 257 237 244 266 269 275 284 257 269 283 268 261 263 232 239 235 259 287 271 273 272 285 284 271 260 267 233 246 232 245 239 268 283 283 288 289 246 272 277 257 248 265 284 278 258 271 273 245 263 279 271 277 233 277 267 247 268 279 265 262 259 271 288 241 286 223 264 266 250 262 262 281 278 266 269 279 240 287 270 262 269 255 274 267 293 259 286 249 294 266 277 248 247 266 316 259 283 244 282 257 258 260 240 278 210 274 238 279 271 267 281 277 282 261 243 278 269 263 282 283 273 232 278 255 278 271 255 260 257 263 273 269 248 273 278 282 260 276 243 260 274 245 246 297 235 282 288 246 267 248 273 291 272 280 263 282 235 272 268 274 241 291 257 262 294 260 255 270 237 257 233 257 284 270 264 270 279 227 258 230 288 261 266 227 265 260 262 241 291 269 243 280 283 266 242 246 280 257 261 271 293 235 291 231 260 241 290 281 246 275 272 260 270 272 242 234 264 248 268 248 259 239 264 245 239 244 259 277 241 237 276 284 285 264 269 260 258 268 249 270 259 279 244 261 249 269 244 269 265 267 268 268 274 265 257 275 269 273 280 248 229 268 257 239 265 288 249 257 256 277 225 292 309 273 265 236 242 294 240 276 242 265 259 281 258 277 282 264 238 244 272 243 277 249 267 230 283 277 244 299 248 277 256 275 259 269 272 261 283 259 291 285 247 268 270 235 239 247 234 290 262 278 302 224 275 245 280 283 271 272 265 248 277 264 285 267 276 274 247 237 270 267 260 290 282 261 262 246 255 281 236 263 259 262 238 285 270 276 248 249 259 263 277 284 274 265 299 236 295 270 255 266 259 275 266 261 267 291 298 224 255 312 273 279 270 282 236 278 289 246 238 276 249 233 270 276 249 232 241 269 249 260 258 282 282 279 243 232 283 282 230 235 276 246 278 278 257 320 245 272 262 272 261 256 256 280 244 318 272 266 233 282 271 263 280 242 236 241 274 285 241 241 256 264 239 263 242 282 299 277 273 264 228 245 239 266 278 250 286 259 277 264 268 271 300 259 245 258 256 266 248 279 258 272 262 269 272 284 243 264 244 289 233 264 249 244 282 263 226 292 248 270 271 256 288 247 272 283 262 259 274 263 260 276 288 293 281 250 246 266 307 272 259 270 241 285 300 281 230 287 268 297 295 277 263 250 279 276 304 266 265 289 279 295 247 321 261 277 280 243 257 289 280 272 255 272 283 247 268 274 272 267 273 265 306 261 263 305 274 277 274 273 263 228 274 280 292 276 293 298 292 259 270 301 273 276 278 268 257 290 289 295 306 277 322 287 287 277 273 299 222 303 280 271 325 290 280 283 307 278 301 272 307 293 291 295 266 324 282 325 291 325 293 301 334 303 289 288 322 321 339 296 299 296 337 322 288 302 318 312 307 327 302 276 309 342 322 318 338 293 270 327 293 321 306 284 325 319 308 301 291 263 298 286 340 315 290 277 259 311 306 285 264 285 309 305 281 290 300 318 302 315 321 289 316 315 264 319 312 242 288 256 276 293 257 286 269 295 234 309 288 275 262 271 285 265 287 304 292 246 278 301 298 268 263 278 282 269 298 299 289 276 264 287 278 274 249 264 290 266 284 236 290 308 249 273 244 263 243 283 268 269 295 257 295 284 260 273 238 291 291 272 277 264 274 292 279 295 226 232 244 242 274 248 261 288 225 237 286 281 249 273 242 288 269 271 244 281 293 255 249 248 258 265 303 244 280 248 264 243 260 258 262 292 279 267 266 274 271 255 315 255 276 280 270 297 266 272 260 258 295 281 272 245 278 274 242 268 235 287 264 305 267 239 267 277 262 258 236 227 249 255 260 243 273 272 295 279 304 287 242 241 266 236 274 264 267 237 279 248 246 271 268 230 267 294 287 281 260 261 271 237 284 243 248 295 248 256 275 263 239 258 228 245 242 275 272 267 294 241 245 265 278 284 296 276 274 277 264 293 277 283 268 273 266 269 242 302 263 265 243 285 259 248 286 275 280 265 249 261 258 268 290 284 248 266 272 258 247 235 286 263 269 265 297 235 278 248 286 263 271 240 279 279 264 243 227 268 277 260 278 261 275 289 280 275 259 280 273 286 259 250 259 268 243 262 266 260 259 269 242 274 227 243 229 255 228 262 297 272 270 255 249 240 260 270 266 238 263 257 270 272 288 244 259 262 279 257 286 259 259 271 260 233 247 223 256 243 273 267 232 261 264 257 271 257 237 266 282 255 268 235 287 238 245 270 250 260 270 264 280 240 232 244 276 270 279 280 261 286 290 244 263 247 228 264 292 236 242 261 290 275 259 271 228 248 276 262 270 279 245 265 272 240 262 282 260 273 275 244 255 270 238 267 245 274 260 256 257 265 272 235 225 246 241 257 256 244 273 273 262 265 256 259 267 243 241 236 263 263 306 237 246 276 262 246 267 278 282 259 250 287 223 275 282 299 285 237 243 245 256 255 247 257 266 261 262 288 267 266 273 270 243 240 250 240 266 255 283 273 230 280 249 272 275 256 248 277 275 305 267 260 270 241 262 255 245 273 265 259 239 232 281 259 249 268 262 257 242 243 266 231 246 266 295 278 288 273 277 271 278 244 232 257 289 268 272 247 287 297 274 267 271 293 293 271 277 272 264 280 243 273 240 240 240 256 274 262 255 276 246 263 239 262 279 238 248 240 287 256 262 225 270 249 255 259 261 266 234 255 248 264 286 261 257 239 279 262 258 270 249 280 260 269 282 271 256 265 242 249 277 281 273 255 269 264 237 257 280 247 267 280 288 262 249 275 257 256 247 267 229 269 232 273 270 245 280 270 265 263 245 265 226 258 244 272 245 286 272 264 266 230 245 285 263 241 266 269 238 248 269 247 258 272 237 260 267 260 265 286 258 244 275 246 260 274 244 283 223 250 273 273 250 247 249 287 272 249 279 273 258 284 260 257 266 248 278 244 270 260 257 266 265 262 260 223 215 236 275 258 220 243 242 269 282 233 267 261 255 221 258 259 228 270 261 243 209 261 246 278 240 239 256 270 265 229 218 233 263 273 243 271 250 266 242 239 277 293 268 255 239 234 244 225 246 247 289 267 257 257 245 256 248 255 260 226 259 248 246 306 277 232 263 261 272 270 238 244 265 241 280 248 275 249 274 257 237 249 255 239 231 232 228 232 248 234 293 233 274 267 287 241 246 236 270 280 244 280 293 234 231 261 263 264 276 274 273 273 283 255 282 260 235 238 233 260 247 256 290 243 255 276 258 242 265 275 286 228 274 267 271 249 270 227 277 267 262 270 261 231 296 226 264 273 263 234 281 237 239 255 245 269 220 301 244 260 267 273 249 246 236 243 234 275 237 273 269 241 238 238 274 285 256 272 244 246 266 256 219 255 239 213 233 241 278 260 246 239 290 243 245 288 280 234 260 250 276 280 268 291 276 213 237 239 255 260 291 249 268 261 261 230 257 256 262 271 244 223 280 246 260 260 269 245 273 244 238 240 273 269 277 263 245 242 248 276 260 248 261 223 247 246 291 265 238 264 233 272 246 259 231 249 294 300 237 255 268 233 276 270 261 262 234 266 276 268 256 266 235 278 260 264 249 255 246 261 244 264 270 271 281 257 285 267 259 247 238 244 257 238 243 276 224 244 269 247 245 266 274 249 260 261 240 275 239 275 279 244 258 262 259 275 246 248 264 257 261 255 286 239 278 240 300 232 255 244 268 259 248 256 281 242 233 228 232 265 286 260 288 271 220 291 248 255 240 281 293 240 249 239 267 259 247 272 277 237 235 270 272 246 265 241 268 239 259 292 283 269 239 265 256 272 262 267 240 235 229 231 234 244 260 232 239 258 248 255 285 246 265 248 248 222 258 271 229 258 261 278 270 278 268 237 261 264 257 226 287 275 272 239 247 205 270 242 267 247 233 231 285 244 274 263 207 255 276 274 267 219 272 270 246 259 259 248 262 258 238 289 271 271 282 276 275 263 271 260 245 274 265 277 246 268 261 255 247 258 273 266 274 265 262 241 226 249 247 264 249 244 243 241 287 255 239 242 242 273 231 258 262 270 261 262 219 277 261 282 237 221 248 262 275 249 235 273 249 232 244 232 245 257 266 278 277 242 223 256 244 271 269 279 257 243 243 243 256 261 240 255 229 282 273 262 269 255 238 259 243 261 278 271 262 290 218 242 258 260 244 266 278 234 211 267 269 260 275 261 243 256 262 264 283 263 249 263 245 285 263 296 270 265 258 263 279 280 256 262 234 240 247 243 246 271 226 267 241 258 247 281 229 271 258 247 269 265 240 266 268 269 256 269 248 223 244 244 241 228 212 259 267 259 247 242 266 269 247 249 266 278 246 262 276 244 255 279 246 240 266 230 242 286 247 255 275 233 239 269 263 264 215 269 240 248 269 230 250 256 271 260 226 245 276 245 263 278 245 238 240 246 237 260 269 280 246 233 214 242 263 261 272 259 246 281 207 276 222 261 276 242 227 289 264 238 268 266 274 263 261 219 275 245 280 283 248 231 219 261 235 246 257 275 228 263 264 236 282 256 268 235 280 272 268 265 229 264 233 256 266 278 259 244 256 279 226 237 269 276 256 272 276 275 244 275 249 247 283 248 268 225 222 221 258 263 244 255 284 295 261 262 246 279 260 280 283 245 266 257 255 261 246 244 273 216 268 275 248 261 225 255 263 289 257 228 260 264 277 249 236 255 269 266 255 244 283 258 260 239 227 277 280 247 239 262 271 257 282 291 247 235 264 255 237 239 226 248 302 281 259 248 255 266 231 281 236 268 232 277 272 272 281 266 264 258 283 255 241 264 243 234 240 241 265 264 214 260 243 249 243 234 227 260 275 242 258 271 284 256 240 271 268 276 241 277 259 248 273 277 263 260 236 222 257 258 230 269 265 272 290 273 270 248 280 274 248 233 257 247 255 275 246 274 237 249 273 233 224 246 265 271 269 272 255 219 287 241 262 275 246 275 227 255 256 275 246 256 239 263 255 273 274 282 237 257 249 267 260 243 210 239 278 232 241 268 255 249 263 273 271 274 239 269 275 243 260 266 256 238 255 244 259 283 287 258 265 246 255 263 244 235 255 278 259 280 267 269 262 288 250 285 282 257 264 271 257 239 259 275 266 269 263 262 307 230 265 271 249 255 260 265 273 250 245 249 273 262 265 267 278 281 258 263 260 237 302 276 264 268 256 289 246 262 269 270 275 272 286 303 285 244 243 264 272 274 280 268 286 268 256 279 264 292 273 266 248 272 270 246 262 269 268 291 240 277 249 265 232 277 244 277 272 268 276 286 249 248 257 271 239 244 277 227 269 258 256 287 255 237 263 275 258 244 244 270 278 276 278 287 267 246 242 229 244 243 247 247 290 258 262 234 264 238 259 262 279 241 267 271 266 272 256 269 240 276 241 271 248 244 268 265 272 263 246 275 275 274 267 255 281 281 261 239 243 240 258 247 212 266 247 258 276 290 267 314 257 215 265 262 276 246 260 268 240 243 250 227 263 275 270 229 273 249 257 258 241 238 234 268 269 267 272 311 226 218 246 275 259 259 232 272 265 286 266 241 284 260 264 250 298 279 259 260 208 264 271 270 292 267 237 284 245 250 285 228 269 260 240 271 273 244 265 278 270 255 260 291 271 266 259 278 255 274 233 274 275 276 299 268 267 271 241 277 281 256 233 264 283 296 260 265 259 255 262 261 232 243 261 240 273 261 260 274 234 282 228 288 222 245 266 233 273 270 250 261 273 263 287 257 260 239 240 261 268 278 261 235 264 239 275 278 237 280 266 245 256 267 268 265 270 246 242 264 264 258 278 263 259 294 268 239 246 245 267 255 249 234 268 277 264 227 269 260 256 257 257 248 247 237 268 289 238 248 237 280 236 236 278 256 245 245 272 298 247 282 265 237 237 238 289 206 239 262 257 244 258 230 288 258 239 273 271 248 280 289 242 263 288 241 240 257 246 267 267 239 276 232 244 267 248 265 243 269 271 262 298 257 279 258 264 259 259 265 272 266 261 228 269 282 242 241 270 248 256 262 237 273 248 262 276 245 279 257 255 295 267 218 272 286 246 249 262 256 247 269 241 257 255 290 239 265 281 238 301 247 262 257 242 262 280 244 286 290 238 227 256 243 246 255 269 273 249 216 243 284 257 242 296 260 239 279 243 257 259 245 274 272 273 245 269 263 244 240 249 266 286 218 267 293 261 246 264 287 265 276 269 262 278 268 276 277 260 268 263 269 293 283 296 241 267 244 255 258 269 236 283 287 249 283 261 266 249 256 275 261 259 287 247 265 258 258 266 291 257 256 266 262 283 246 283 281 260 284 256 243 266 242 244 269 279 257 279 249 256 274 277 263 293 247 302 269 247 262 275 276 255 240 268 264 243 285 279 273 261 279 304 266 249 259 248 230 277 272 281 273 243 271 264 250 268 272 274 266 266 259 272 269 224 265 256 257 261 257 242 246 261 268 263 265 267 233 246 241 264 274 293 271 288 249 240 255 255 271 274 262 278 287 259 237 297 291 272 259 274 266 244 261 238 283 273 281 236 286 283 272 288 243 267 240 259 293 249 284 262 241 243 258 274 300 240 241 247 281 268 282 285 245 272 274 273 281 267 267 257 263 246 272 267 316 264 293 271 284 259 256 241 225 272 270 256 286 290 268 244 264 273 270 257 279 269 294 301 248 238 219 248 289 290 244 268 268 271 274 256 259 269 260 270 271 263 236 245 261 248 272 274 238 269 245 259 267 239 255 296 232 261 274 265 264 280 269 260 266 276 292 245 269 259 277 248 226 270 250 249 230 243 264 247 239 278 274 284 279 280 274 288 242 261 281 258 260 280 247 267 247 288 280 270 277 271 246 267 263 259 263 256 265 265 261 247 289 261 260 271 304 269 273 275 232 266 291 263 240 275 299 256 245 265 261 265 286 261 284 263 248 282 281 248 261 235 269 233 248 263 275 266 255 260 270 255 276 263 275 272 256 243 267 265 248 261 233 255 263 264 242 282 292 289 259 291 224 273 238 262 239 248 297 270 243 286 267 286 270 295 266 259 294 261 272 261 256 275 248 258 259 264 238 272 236 245 259 264 237 288 301 285 303 265 260 238 225 270 284 262 277 248 273 242 283 272 272 291 264 260 264 277 267 258 240 276 315 261 215 262 256 272 256 279 261 231 273 261 261 281 267 273 262 245 270 268 226 274 273 267 278 270 257 255 276 267 266 287 237 248 237 246 221 257 283 234 246 235 256 259 299 288 224 243 238 289 237 248 286 273 240 248 243 208 265 262 264 239 243 242 291 277 262 288 240 259 289 276 281 246 281 269 259 257 260 265 267 279 279 291 245 282 257 265 245 240 277 260 269 243 268 267 247 258 283 266 258 300 274 265 263 231 229 269 269 284 291 266 245 266 262 265 278 279 271 270 237 271 230 261 260 263 287 266 258 267 263 268 305 277 299 218 227 256 260 265 260 276 263 226 293 242 229 279 240 265 286 288 263 255 242 282 258 276 270 239 265 237 260 259 271 278 264 255 266 269 279 256 258 262 261 264 286 243 233 281 233 278 271 248 263 296 239 290 259 287 266 262 244 268 268 259 244 242 283 245 268 279 282 283 261 281 257 267 247 265 267 246 266 273 275 297 297 260 286 265 270 264 274 265 245 249 255 248 272 281 279 248 271 261 237 292 282 281 284 262 235 269 263 261 259 279 258 245 259 264 241 277 267 267 266 286 285 225 298 270 264 277 237 271 256 283 298 260 235 270 247 242 267 235 293 240 276 231 237 259 245 273 274 271 260 223 276 287 260 280 267 279 240 248 266 264 255 278 262 236 280 243 248 281 255 269 230 256 264 283 230 248 296 275 290 263 286 246 258 243 261 279 258 287 266 245 278 268 255 242 262 275 269 283 224 255 269 277 248 262 240 265 257 279 259 242 265 239 277 248 280 266 277 269 258 278 260 258 256 272 285 293 271 269 290 270 238 261 239 289 302 241 243 275 274 273 241 259 269 274 274 285 313 246 264 286 267 281 273 281 273 258 237 268 264 240 274 290 279 264 261 255 266 263 259 242 268 273 234 299 265 276 274 241 258 273 274 268 247 274 244 278 257 240 259 284 303 277 292 263 264 275 285 242 239 263 303 268 259 275 255 266 267 250 288 276 297 313 266 259 260 276 267 277 275 281 275 244 285 288 290 261 220 295 270 259 276 249 308 263 288 276 259 271 273 244 242 277 259 279 264 261 260 259 290 276 232 270 260 271 246 263 265 248 271 240 266 296 294 263 294 272 258 235 281 260 291 271 242 256 272 273 247 245 278 258 247 272 271 265 273 264 265 260 279 263 266 264 258 267 265 278 311 238 268 232 257 276 295 275 285 249 307 249 274 256 256 241 260 234 256 249 270 274 258 244 281 261 290 235 281 237 259 280 246 279 269 263 268 249 241 270 327 300 278 291 268 248 278 268 275 256 267 277 258 249 244 286 255 255 267 280 267 280 229 250 276 247 297 276 234 281 242 271 288 269 278 287 285 288 288 272 290 286 266 273 271 269 270 275 289 270 272 277 272 256 268 276 294 264 288 263 286 246 269 275 262 286 272 278 283 260 272 284 263 273 286 283 275 258 272 260 291 261 299 247 265 259 295 280 240 265 274 265 270 283 291 255 291 283 238 266 270 310 286 295 267 266 269 272 294 287 260 279 256 265 237 234 244 266 268 276 287 258 242 255 245 235 264 286 292 234 234 249 270 262 299 264 273 268 283 241 323 272 279 248 290 295 276 298 273 245 279 256 293 237 285 238 261 257 218 255 259 262 280 277 270 292 281 277 273 264 275 277 289 270 264 309 316 247 287 263 267 279 245 264 248 271 305 274 272 280 291 283 290 271 265 265 286 270 261 261 284 221 283 272 278 268 299 280 259 261 291 232 266 266 262 269 248 272 279 266 249 281 276 238 284 272 263 257 225 276 312 261 240 272 266 277 261 248 282 276 261 294 278 297 286 263 280 244 255 263 285 256 291 224 269 283 306 265 291 268 294 262 236 257 278 272 319 296 277 266 303 265 282 304 305 279 285 292 247 278 277 272 292 281 284 309 284 297 273 280 308 265 265 294 288 271 283 301 261 284 307 274 298 281 270 271 296 308 276 282 282 316 310 272 279 285 295 299 287 267 282 279 264 288 272 315 288 290 273 291 260 299 276 290 275 290 314 296 276 285 301 308 292 302 333 274 294 276 267 280 270 283 288 288 346 248 243 281 258 256 295 274 292 267 265 270 230 270 245 270 310 263 281 279 276 268 274 313 239 292 274 276 255 261 299 292 294 275 295 284 241 290 273 226 262 279 293 260 255 270 279 249 265 245 281 267 279 270 261 286 292 257 275 298 273 293 266 301 258 279 257 279 264 292 279 256 283 255 266 269 278 280 287 270 262 265 242 286 289 263 292 285 306 274 269 273 248 276 303 263 292 277 270 263 294 273 256 248 264 258 278 295 272 274 269 298 304 258 262 265 264 282 270 227 258 231 277 290 267 263 281 265 265 277 275 302 275 272 255 269 241 284 248 271 280 289 280 279 270 277 274 291 279 274 249 266 301 262 276 282 290 241 295 266 279 281 282 280 289 282 298 245 258 287 226 270 255 257 271 241 233 265 259 277 244 272 274 248 227 260 292 258 271 346 255 304 267 265 280 267 302 256 270 269 262 271 280 282 290 260 255 265 263 260 247 265 277 257 248 277 285 273 257 290 262 285 275 278 283 243 290 302 272 294 288 273 225 279 276 271 247 276 269 264 281 290 271 281 269 279 270 249 249 287 268 240 288 278 265 287 264 261 280 320 247 275 259 257 278 241 246 267 277 281 275 259 255 259 268 270 241 266 263 285 246 262 249 279 286 293 257 268 281 298 236 288 244 242 279 266 261 270 271 282 287 270 277 257 279 296 243 260 264 243 307 255 275 261 247 255 289 286 278 267 286 243 259 266 276 244 302 242 260 265 255 257 280 286 269 269 279 288 258 245 250 271 272 276 283 259 257 269 248 275 262 285 263 249 256 281 273 291 258 288 262 275 270 284 274 248 258 230 320 279 265 281 266 275 270 247 279 284 262 294 261 228 246 268 287 276 271 256 269 258 307 258 274 259 304 286 284 284 270 248 289 282 246 291 276 243 257 257 295 268 242 261 243 247 278 287 286 264 293 266 258 240 291 259 307 268 264 282 258 233 279 282 247 264 255 309 241 264 263 286 281 262 261 266 248 263 283 269 260 285 298 287 246 291 256 257 268 249 279 300 265 241 276 270 272 288 255 260 262 260 281 266 267 289 246 265 268 261 279 274 288 276 260 263 280 264 265 262 297 271 241 277 282 279 259 260 319 308 250 288 260 298 289 286 280 244 301 247 262 288 266 281 279 292 278 272 275 289 277 278 264 248 258 267 262 286 283 255 260 282 273 300 247 259 275 272 281 281 245 279 315 268 279 265 264 269 276 249 280 272 293 264 290 282 260 264 256 298 270 223 234 307 285 284 275 274 267 268 310 257 265 271 278 235 241 298 234 284 292 282 297 259 259 258 233 276 266 286 282 243 260 303 279 270 280 279 310 292 288 266 307 292 291 264 282 282 246 302 301 262 263 274 290 278 245 276 273 270 274 291 260 264 258 298 245 265 288 265 280 274 307 267 261 271 271 273 262 300 288 291 280 268 257 258 244 287 241 255 287 284 255 239 256 267 308 296 272 250 267 255 316 309 323 302 234 310 273 293 277 286 262 240 318 294 274 282 276 272 265 296 278 242 288 266 293 299 289 244 265 297 262 290 274 232 276 291 305 283 263 278 246 292 260 289 270 259 276 279 296 271 272 299 277 291 258 266 303 269 238 274 273 256 260 313 263 262 250 264 245 288 264 283 264 274 260 291 279 292 312 284 266 275 266 267 285 273 272 267 300 268 268 288 290 303 244 262 282 264 233 258 272 250 284 241 283 275 270 296 261 280 241 278 282 272 292 292 311 285 275 298 265 277 263 291 286 263 294 306 274 289 282 236 292 262 294 279 283 282 289 287 280 271 284 291 288 301 243 289 277 291 283 292 246 262 300 292 288 284 288 278 285 218 275 287 259 292 232 257 282 278 255 265 263 273 315 265 261 262 298 298 266 281 266 291 217 290 257 244 245 290 290 238 245 270 287 275 286 294 256 291 260 292 264 242 293 260 266 279 262 312 269 285 257 272 236 229 255 241 276 283 288 269 262 278 301 309 279 274 279 287 278 262 263 273 285 286 236 296 275 298 258 266 268 272 264 281 261 255 270 269 276 272 259 274 297 288 301 279 266 259 267 261 280 273 302 320 289 266 238 281 272 284 248 262 279 236 233 263 281 255 258 304 288 261 285 268 297 248 276 249 267 257 281 277 286 294 281 247 239 284 256 287 271 276 297 294 278 276 298 267 301 277 276 256 270 319 284 288 282 275 245 250 249 281 278 258 273 287 247 277 257 282 293 304 261 273 289 284 247 287 296 264 309 272 294 246 268 262 294 247 258 284 258 282 280 241 273 270 249 322 260 275 247 273 271 288 249 293 282 278 262 274 261 285 306 269 259 282 233 274 275 265 261 279 271 305 309 275 278 273 293 255 282 215 257 290 261 286 264 276 286 282 246 265 274 293 291 272 273 287 327 301 268 273 271 284 270 269 275 281 292 272 269 282 304 265 242 290 265 268 262 240 269 285 280 275 280 273 289 278 283 281 275 300 271 296 280 255 250 250 260 259 269 269 289 300 249 274 296 283 245 294 233 309 275 273 258 292 302 273 261 272 303 276 278 263 266 264 283 285 275 276 277 238 261 265 279 272 289 278 261 278 281 293 260 264 266 283 283 268 275 273 276 276 249 271 281 259 277 242 308 270 272 264 287 286 296 261 291 299 286 276 280 244 295 287 303 271 287 262 293 302 279 277 270 236 269 310 291 285 282 283 311 296 280 260 268 306 277 269 271 280 305 234 282 292 260 249 270 270 284 292 262 279 256 272 222 293 274 282 247 306 260 248 266 266 295 278 261 277 279 246 263 270 270 260 286 291 267 286 244 256 310 262 283 267 292 241 277 270 273 244 259 285 269 273 273 234 269 272 280 261 274 287 276 316 248 273 295 237 290 266 264 276 283 265 266 269 306 282 248 287 270 284 279 284 288 277 286 312 295 293 270 305 277 288 272 296 307 310 284 244 249 272 262 272 257 246 261 290 264 267 267 234 284 272 270 278 270 262 291 284 249 289 281 265 287 286 277 298 248 267 289 287 275 318 273 273 289 268 290 256 284 273 273 262 284 294 281 274 265 265 270 269 296 266 271 288 277 319 256 238 302 255 264 293 291 275 299 256 239 281 289 271 286 276 277 281 288 276 289</counts>
			</dataPoints>
		</scan>
	</xrdMeasurement>
</xrdMeasurements>