File: data/XRD/XG-Sauerstoff/XG-600/W6822-1B_XG_Sauerstoff_600.xrdml
<xrdMeasurements xmlns="http://www.xrdml.com/XRDMeasurement/2.1" xmlns:xsi="http://www.w3.org/2001/XMLSchema-instance" xsi:schemaLocation="http://www.xrdml.com/XRDMeasurement/2.1 http://www.xrdml.com/XRDMeasurement/2.1/XRDMeasurement.xsd" status="Completed">
	<comment>
		<entry>Configuration=Factory configuration, Owner=User-1, Creation date=7/8/2013 4:01:53 PM</entry>
		<entry>Goniometer=PW3050/65 (Theta/2Theta); Minimum step size 2Theta:0.0001; Minimum step size Omega:0.0001</entry>
		<entry>Sample stage=MRD Cradle; Minimum step size Phi:0.01; Minimum step size Chi:0.01; Minimum step size X:0.01; Minimum step size Y:0.01; Minimum step size Z:0.001</entry>
		<entry>Diffractometer system=XPERT-PRO</entry>
		<entry>Measurement program=C:\PANalytical\Data Collector\Programs\Jorrit\2thom\_absolute_2th-om_10-130deg_PIXscan_56min.xrdmp, Identifier={15BCCF57-2807-42BD-B5B9-ECC0B3DC9284}</entry>
		<entry>Batch program=C:\PANalytical\Data Collector\Programs\SimonL\batch4x_2thom_10-130°_z9.1_x0,10,20,30_y0_57min.xrdmp, Identifier={EED9823A-2BEB-424C-9252-345C4EF2834A}</entry>
	</comment>
	<sample type="To be analyzed">
		<id></id>
		<name></name>
		<preparedBy></preparedBy>
	</sample>
	<xrdMeasurement measurementType="Scan" status="Completed" sampleMode="Reflection">
		<comment>
			<entry>_absolute_2th-om_10-130deg_PIXscan_56min</entry>
			<entry>PHD Lower Level = 4.83 (keV), PHD Upper Level = 11.27 (keV)</entry>
		</comment>
		<usedWavelength intended="K-Alpha 1">
			<kAlpha1 unit="Angstrom">1.5405980</kAlpha1>
			<kAlpha2 unit="Angstrom">1.5444260</kAlpha2>
			<kBeta unit="Angstrom">1.3922500</kBeta>
			<ratioKAlpha2KAlpha1>0.5000</ratioKAlpha2KAlpha1>
		</usedWavelength>
		<incidentBeamPath>
			<radius unit="mm">320.00</radius>
			<xRayTube id="1010048" name="Empyrean Cu LFF HR (9430 033 7310x) DK442154">
				<tension unit="kV">40.0</tension>
				<current unit="mA">40.0</current>
				<anodeMaterial>Cu</anodeMaterial>
				<focus type="Line">
					<length unit="mm">12.0</length>
					<width unit="mm">0.4</width>
					<takeOffAngle unit="deg">4.2</takeOffAngle>
				</focus>
			</xRayTube>
			<xRayMirror id="27010001" name="Inc. Beam Cu W/Si (parabolic MRD)" hybrid="false">
				<crystal type="Graded" shape="Parabolic">W/Si</crystal>
				<acceptanceAngle unit="deg">0.800</acceptanceAngle>
				<length unit="mm">60.0</length>
			</xRayMirror>
			<sollerSlit id="21010002" name="Soller slits 0.04 rad.">
				<opening unit="rad">0.0400</opening>
			</sollerSlit>
			<mask id="22030007" name="Fixed mask 2 mm">
				<distanceToSample unit="mm">220.00</distanceToSample>
				<width unit="mm">2.00</width>
			</mask>
			<divergenceSlit id="22010007" name="Fixed slit 1/8°" xsi:type="fixedDivergenceSlitType">
				<distanceToSample unit="mm">220.00</distanceToSample>
				<height unit="mm">0.19</height>
			</divergenceSlit>
		</incidentBeamPath>
		<diffractedBeamPath>
			<radius unit="mm">320.00</radius>
			<sollerSlit id="21010002" name="Soller slits 0.04 rad.">
				<opening unit="rad">0.0400</opening>
			</sollerSlit>
			<receivingSlit id="22010001" name="Fixed slit 4°">
				<height unit="mm">5.88</height>
			</receivingSlit>
			<detector id="7010017" name="PIXcel3D 1x1 detector" xsi:type="areaDetectorType">
				<phd unit="%">
					<lowerLevel>30.0</lowerLevel>
					<upperLevel>70.0</upperLevel>
				</phd>
				<mode>Scanning</mode>
				<activeChannelsEquatorial>255</activeChannelsEquatorial>
				<activeChannelsAxial>255</activeChannelsAxial>
				<pitchEquatorial unit="mm">0.05500</pitchEquatorial>
				<pitchAxial unit="mm">0.05500</pitchAxial>
				<readOutPeriod unit="seconds">0.135</readOutPeriod>
			</detector>
		</diffractedBeamPath>
		<scan appendNumber="0" mode="Continuous" scanAxis="2Theta-Omega" status="Completed">
			<header>
				<startTimeStamp>2024-09-11T20:00:31+02:00</startTimeStamp>
				<endTimeStamp>2024-09-11T20:56:37+02:00</endTimeStamp>
				<author>
					<name>PRO-MRD</name>
				</author>
				<source>
					<applicationSoftware version="6.1b">Data Collector</applicationSoftware>
					<instrumentControlSoftware version="7.0E 20130304">XPERT-PRO</instrumentControlSoftware>
					<instrumentID>0000000011142674</instrumentID>
				</source>
			</header>
			<dataPoints>
				<positions axis="2Theta" unit="deg">
					<startPosition>9.99826193</startPosition>
					<endPosition>129.99755682</endPosition>
				</positions>
				<positions axis="Omega" unit="deg">
					<startPosition>4.99913096</startPosition>
					<endPosition>64.99877841</endPosition>
				</positions>
				<positions axis="Phi" unit="deg">
					<commonPosition>0.00</commonPosition>
				</positions>
				<positions axis="Chi" unit="deg">
					<commonPosition>0.00</commonPosition>
				</positions>
				<positions axis="X" unit="mm">
					<commonPosition>10.00</commonPosition>
				</positions>
				<positions axis="Y" unit="mm">
					<commonPosition>0.00</commonPosition>
				</positions>
				<positions axis="Z" unit="mm">
					<commonPosition>9.100</commonPosition>
				</positions>
				<commonCountingTime unit="seconds">32.895</commonCountingTime>
				<counts 227 221 206 222 211 222 210 217 229 210 227 213 200 223 206 243 212 212 206 229 228 215 212 230 201 215 226 246 236 243 244 236 209 217 213 228 210 231 212 230 211 205 212 217 220 256 240 226 222 258 227 214 210 219 212 220 225 237 231 225 224 217 232 232 203 212 201 216 187 198 194 197 229 236 223 210 239 232 195 199 245 207 194 207 223 206 221 213 193 208 176 211 176 188 205 223 215 202 217 210 189 222 209 208 230 194 205 208 190 221 208 224 199 223 208 197 204 214 208 202 197 194 188 227 237 213 216 222 228 201 210 191 202 196 222 216 215 188 206 211 185 200 196 230 208 228 193 217 183 209 203 186 227 197 194 202 208 215 180 198 177 199 209 208 189 206 223 213 184 227 223 167 208 198 199 200 179 188 226 198 189 182 193 162 232 206 195 206 182 221 201 207 190 202 218 211 195 165 213 189 178 190 188 187 180 211 217 213 187 221 217 216 186 190 183 218 199 195 215 187 191 190 216 206 187 209 189 165 210 198 223 203 211 191 192 187 179 208 182 196 194 168 192 219 172 187 191 188 192 189 162 200 177 205 201 190 224 188 186 194 177 202 174 192 189 183 192 198 187 193 182 171 214 191 196 209 173 197 204 204 205 191 182 182 171 182 180 178 223 180 195 186 200 194 202 195 174 181 174 191 199 211 200 197 186 199 169 198 166 192 205 160 197 165 175 191 160 191 163 161 174 174 176 180 197 173 165 179 170 178 202 194 194 176 158 178 167 156 176 198 153 175 173 166 180 195 184 186 186 152 191 182 158 193 158 168 178 194 181 143 178 188 175 174 157 153 189 181 171 204 174 179 180 170 170 180 171 181 172 184 195 164 159 179 193 193 195 169 170 171 173 155 166 183 175 165 163 177 158 160 166 170 165 191 169 193 185 178 151 156 174 179 185 158 207 186 177 177 179 171 157 158 164 184 167 148 172 167 168 150 167 169 157 176 173 170 157 149 178 162 159 189 150 170 171 158 171 177 148 189 179 171 164 164 185 162 172 159 158 189 182 178 164 168 157 165 173 188 155 182 160 143 176 186 170 178 169 190 167 157 189 132 153 163 161 170 175 177 169 137 186 173 174 189 173 179 176 158 186 162 177 143 162 176 142 160 176 162 175 171 174 149 158 177 186 181 160 165 176 162 143 179 160 179 159 164 148 153 148 148 167 167 170 148 159 160 160 155 146 145 167 167 181 149 163 157 154 170 170 173 151 153 168 155 150 155 163 165 179 167 144 134 143 157 170 129 176 158 166 158 156 142 169 167 160 158 148 165 173 153 157 156 170 171 173 174 184 192 160 146 178 170 170 162 173 166 163 174 146 129 161 160 141 155 158 148 194 156 166 143 155 156 169 162 155 140 161 162 151 169 176 171 150 164 163 159 148 164 148 158 166 172 160 150 161 167 156 172 147 158 174 145 137 173 153 175 160 168 166 171 158 156 169 172 160 154 151 159 165 149 152 152 151 140 159 153 153 154 161 148 137 155 159 197 148 175 167 175 159 143 162 168 154 171 157 163 182 142 160 162 172 168 165 152 152 159 167 161 147 155 149 117 192 150 138 143 158 141 134 150 155 170 162 140 170 151 170 162 169 159 153 145 155 153 158 154 152 154 153 157 178 130 150 145 176 138 172 153 154 150 149 153 173 150 162 146 159 176 140 149 152 155 177 152 164 154 161 169 170 169 157 138 179 154 161 141 172 170 158 139 166 169 181 148 147 150 170 143 161 171 162 151 188 141 144 149 156 155 140 168 187 153 143 165 166 167 174 180 161 172 159 149 164 154 151 161 161 165 155 149 172 162 146 180 143 155 172 164 171 132 152 156 159 162 149 152 151 157 159 154 146 168 156 167 152 141 144 155 164 136 163 145 159 143 148 173 146 167 160 143 156 151 153 176 150 161 159 151 176 147 172 166 162 135 159 163 141 156 159 156 158 171 147 155 150 158 141 183 150 142 144 138 158 156 171 163 162 163 163 155 154 146 160 136 129 142 135 166 157 174 139 172 147 168 164 163 158 160 141 156 158 183 159 164 139 174 159 164 166 160 162 175 180 135 155 141 149 143 148 167 164 148 157 140 154 176 148 150 155 157 155 162 166 157 151 142 146 171 164 165 149 159 154 167 166 150 152 182 159 164 167 162 171 174 182 147 152 163 189 155 165 186 150 139 153 160 159 146 176 158 166 147 162 177 158 177 140 179 170 154 138 158 157 157 150 182 144 163 139 155 144 178 159 157 167 172 150 161 158 147 168 181 155 170 162 140 185 182 153 170 159 160 145 182 157 154 148 167 155 167 170 143 186 168 168 162 162 174 162 183 165 168 146 153 166 163 171 155 180 171 162 158 181 181 152 152 174 165 161 166 151 174 171 140 163 183 179 177 164 149 153 151 181 171 182 157 164 156 162 152 158 160 145 162 171 183 155 173 150 166 169 167 176 171 161 166 171 159 168 148 161 175 181 160 172 181 180 192 149 156 154 176 186 172 154 154 180 182 165 168 175 147 175 175 156 173 156 166 183 171 163 150 175 171 163 154 170 168 164 155 164 162 164 190 189 169 155 152 155 173 186 166 172 170 174 163 175 142 148 153 154 176 166 169 162 177 164 162 191 165 171 165 170 187 173 182 182 166 197 185 185 173 159 184 158 139 154 168 167 159 198 167 177 158 164 177 148 198 171 140 157 176 180 157 164 162 163 169 167 162 151 158 183 172 160 185 188 169 160 174 186 132 177 167 175 176 165 162 158 180 161 168 159 184 180 181 175 165 151 171 161 168 168 167 170 155 169 175 182 159 164 170 193 156 165 173 164 169 159 167 168 171 144 177 165 171 175 156 167 162 177 149 185 147 153 182 174 184 169 169 176 175 158 171 139 150 172 172 182 178 170 183 158 175 150 174 165 174 178 177 155 163 194 149 172 170 166 174 143 164 177 143 166 183 188 173 182 156 146 142 172 202 158 145 153 155 177 171 166 166 181 171 159 169 162 170 162 176 159 183 173 172 163 160 150 159 178 175 172 197 179 173 164 164 174 149 150 162 152 158 158 160 170 152 170 173 138 181 174 158 170 160 169 207 161 181 169 179 155 154 154 165 172 148 193 155 156 188 158 145 163 163 129 186 184 172 160 166 180 181 176 141 175 157 161 167 177 180 158 182 166 167 152 154 142 177 131 162 165 175 164 146 162 165 153 165 147 159 174 134 152 167 166 150 159 170 163 168 144 142 164 150 152 156 165 147 166 149 172 152 179 150 152 159 181 151 175 151 164 154 144 154 163 145 140 154 165 135 152 144 152 164 144 170 136 182 155 167 145 163 158 169 172 145 153 177 172 162 156 155 160 152 153 160 156 152 144 133 142 135 180 154 161 149 153 154 157 161 151 168 146 152 177 158 160 161 155 170 153 170 147 143 146 153 145 150 160 129 160 177 170 157 144 126 155 149 170 147 132 162 159 128 157 163 151 142 138 136 148 144 150 161 159 147 150 146 129 162 144 176 151 134 155 145 163 159 149 142 148 168 165 151 151 148 152 164 149 158 162 134 148 145 147 160 152 155 137 164 149 142 168 166 153 170 153 155 148 169 162 158 140 168 143 143 129 141 133 146 125 139 149 157 145 144 151 138 126 148 138 147 139 163 172 153 152 161 113 137 140 152 140 177 137 135 141 147 153 140 146 159 147 161 145 137 147 148 155 148 149 145 145 146 158 149 145 151 140 146 138 148 158 126 158 150 140 123 147 135 134 145 160 149 153 126 133 128 133 140 157 162 161 129 137 152 151 131 140 119 148 153 129 150 150 131 138 142 149 154 150 156 133 150 132 155 114 123 147 159 147 144 119 145 154 158 175 141 154 135 155 158 120 136 130 134 139 136 138 122 148 121 132 114 143 133 145 125 135 150 140 137 129 139 134 141 133 163 144 138 126 136 143 141 150 119 128 146 122 132 145 123 150 126 119 142 106 121 121 120 131 139 129 144 153 160 127 138 133 134 144 143 134 124 129 145 135 131 158 156 129 147 123 158 120 140 129 102 138 123 134 141 149 131 137 133 143 125 127 134 130 136 122 114 152 131 119 146 131 137 145 159 140 126 135 151 140 147 128 117 116 149 147 119 140 135 146 128 115 122 138 138 119 150 128 125 121 155 133 120 136 155 141 146 129 140 117 131 127 126 129 121 129 143 131 112 136 133 127 113 129 130 154 138 135 147 141 145 131 125 122 122 125 147 136 132 126 125 122 128 127 129 140 138 149 131 145 137 131 121 132 128 142 136 116 115 146 157 132 130 136 130 124 121 144 109 137 131 128 149 139 120 134 127 130 136 130 121 115 124 126 127 127 134 134 135 135 126 121 119 103 141 139 117 118 138 110 131 131 109 116 124 139 134 141 120 144 149 125 126 118 129 123 134 131 140 112 135 123 123 116 110 121 121 135 109 115 146 130 132 125 125 125 128 123 95 131 140 112 129 155 136 131 141 136 137 103 153 138 131 93 119 132 120 132 102 117 137 131 126 123 122 113 134 122 122 118 114 135 144 122 115 113 133 126 132 125 130 111 133 118 121 136 128 110 111 115 114 131 108 127 106 137 119 132 106 135 143 122 115 115 127 131 138 115 124 137 142 115 120 124 134 144 121 138 139 124 143 137 115 136 115 119 136 120 123 150 124 113 124 134 122 127 117 114 134 109 121 128 121 128 117 122 125 140 100 134 118 118 119 108 140 114 123 105 121 107 154 117 140 119 119 126 121 118 127 134 113 134 124 101 120 117 125 133 122 114 142 122 112 143 106 88 131 129 132 125 121 127 110 138 140 110 117 120 109 129 120 125 145 128 121 96 139 118 148 140 132 104 138 133 133 116 131 128 129 113 107 126 111 109 129 134 117 109 116 137 126 115 100 108 127 143 111 116 111 113 124 140 122 128 127 110 130 114 113 99 131 117 118 111 123 104 114 116 123 120 124 138 140 108 113 149 113 110 127 113 124 108 125 113 108 129 111 116 113 134 116 143 121 102 114 108 129 123 137 122 142 102 114 138 142 110 115 121 105 114 120 130 120 124 123 127 115 129 119 130 131 101 135 108 111 121 106 125 122 111 103 113 113 127 135 140 119 128 115 105 114 112 124 121 121 99 130 115 117 115 117 107 124 109 108 112 118 122 95 114 122 140 150 110 120 106 118 109 134 111 129 120 105 132 109 119 134 108 106 118 116 93 119 138 122 120 106 131 113 99 124 104 123 128 110 120 120 125 104 117 130 117 112 126 112 122 129 111 96 98 107 125 132 118 107 125 134 121 111 122 117 114 121 107 130 119 142 126 111 122 113 121 123 120 116 83 104 105 116 108 110 123 116 108 117 118 107 117 119 125 115 113 106 114 107 121 110 110 115 116 124 105 142 121 103 121 124 121 127 96 127 100 120 111 120 101 99 115 98 108 125 122 124 120 125 116 112 136 104 104 118 144 121 115 98 110 114 147 113 121 113 99 119 125 124 109 121 117 136 108 113 124 123 112 110 119 130 121 106 110 133 105 112 111 119 100 104 104 123 113 115 128 133 114 94 125 115 116 103 111 106 115 102 121 105 111 113 125 111 129 127 129 109 110 121 115 118 121 106 108 141 112 135 146 114 121 114 123 119 107 112 134 118 113 105 108 127 119 107 97 106 107 124 113 111 129 112 117 98 119 105 111 104 129 99 117 111 106 113 120 114 131 129 122 107 105 103 101 106 113 114 99 114 141 125 110 138 123 112 108 127 122 100 111 102 125 128 118 124 121 117 101 99 103 123 128 131 138 100 110 112 117 121 120 117 122 116 104 109 118 123 98 112 85 112 103 112 143 129 114 112 106 115 109 126 139 104 111 120 116 115 124 132 136 102 106 107 115 145 99 114 134 114 115 124 112 106 114 121 106 105 95 123 123 107 125 107 112 97 128 113 124 117 105 111 115 107 113 134 103 122 118 115 118 122 129 118 117 117 125 138 124 122 120 115 107 116 109 109 122 119 114 122 117 100 86 105 110 115 123 110 114 117 112 118 86 104 98 122 112 115 125 128 117 118 126 115 116 130 110 115 101 112 94 123 134 122 97 112 100 128 91 122 98 120 129 100 116 127 101 106 118 114 113 118 127 111 106 131 109 131 121 137 107 124 121 133 126 102 104 100 103 116 114 111 109 103 119 120 101 114 90 130 109 120 113 108 111 112 141 108 114 137 102 89 96 128 116 123 101 123 122 115 122 125 95 114 99 113 105 117 119 113 118 104 105 111 132 132 109 113 118 121 109 107 117 87 123 114 111 103 108 121 96 107 101 120 106 88 93 106 99 97 115 113 94 110 101 110 111 106 114 128 116 103 128 110 109 121 119 128 122 106 118 103 112 115 120 106 112 136 115 121 119 100 120 114 122 81 108 130 115 90 120 113 115 107 95 108 104 93 100 122 105 137 104 105 99 114 113 106 122 102 106 132 98 107 111 91 99 113 118 108 110 94 118 116 111 115 108 117 99 104 101 113 110 117 102 106 126 121 107 123 94 124 117 110 103 118 100 118 103 111 122 94 129 120 115 129 113 118 110 110 103 115 122 105 109 105 115 133 107 112 102 100 113 113 101 111 106 109 119 120 97 106 95 112 106 121 120 106 120 112 114 94 123 98 116 117 110 106 100 105 123 110 116 106 113 96 110 111 92 105 103 103 96 117 92 106 113 114 100 111 94 105 106 125 102 122 113 121 103 103 104 106 111 106 98 89 123 114 94 104 133 135 98 102 103 100 112 118 116 107 104 115 111 88 113 92 104 108 130 104 88 104 115 108 117 113 126 110 123 111 103 103 122 110 117 97 138 103 104 111 110 92 121 114 110 110 113 122 112 114 106 100 100 109 126 105 112 109 104 105 108 101 110 100 115 97 133 112 118 108 96 123 103 95 116 109 100 112 89 113 110 114 116 112 126 118 115 114 110 103 102 113 112 111 108 98 102 99 111 95 98 121 106 106 130 85 113 108 107 141 103 105 105 113 92 96 99 111 93 119 100 99 112 105 124 87 100 91 107 118 123 100 106 124 95 118 101 99 132 101 134 114 135 125 107 101 92 93 110 122 113 116 106 119 103 113 115 111 122 106 128 105 98 120 129 110 106 103 99 81 127 98 99 102 90 108 113 111 111 114 100 115 113 127 111 112 112 129 121 100 100 106 120 105 110 128 100 104 135 107 109 115 109 109 120 78 100 127 91 119 111 135 106 115 108 108 95 110 124 96 116 96 111 133 90 112 103 111 113 123 107 109 128 100 107 88 113 112 119 101 112 111 117 106 109 115 96 112 124 99 115 115 116 96 120 123 102 112 101 110 108 122 101 126 112 116 127 91 126 128 97 117 93 122 92 114 91 114 106 115 110 107 100 114 102 95 97 125 120 117 147 117 122 116 106 111 111 109 109 109 106 129 108 118 97 107 106 109 106 98 123 106 133 98 116 99 107 96 87 124 117 110 128 135 135 99 111 128 134 125 126 112 128 106 130 98 112 119 98 100 109 114 106 99 107 100 108 101 121 123 113 102 119 113 104 116 114 117 108 133 125 111 117 120 119 116 115 123 128 138 121 121 101 114 109 122 116 120 97 116 111 111 127 105 116 121 103 126 101 121 91 108 123 120 108 106 109 141 119 100 100 108 112 113 118 115 123 130 116 136 128 102 106 116 124 133 107 114 110 126 112 120 104 127 148 113 122 125 120 100 124 114 140 106 125 126 137 110 122 133 114 123 155 122 136 134 121 141 129 129 127 138 119 121 120 155 154 135 126 146 123 132 144 155 168 153 145 144 139 159 153 169 166 177 180 185 179 185 187 180 173 207 173 192 192 186 177 208 166 199 183 159 193 183 175 174 173 164 161 191 186 139 146 139 134 168 149 141 132 147 150 138 132 134 135 134 132 147 125 124 105 120 126 146 120 127 117 137 127 128 113 115 120 107 117 121 117 121 129 115 127 104 131 130 147 105 121 106 128 126 116 121 112 140 106 118 117 108 144 116 97 106 125 94 105 118 112 119 130 105 114 123 111 123 116 127 122 118 106 110 123 118 114 113 104 115 122 105 111 110 92 109 124 123 112 101 115 109 108 112 108 110 104 114 126 120 100 114 110 101 117 113 103 104 93 125 108 109 108 84 128 118 111 122 116 103 119 100 110 110 131 139 101 110 117 127 115 104 112 132 102 108 128 131 111 111 120 129 106 121 134 129 140 92 123 115 115 108 96 123 100 119 115 111 118 113 106 95 132 90 115 114 112 126 106 89 103 131 112 118 103 98 128 128 109 110 98 120 118 103 95 125 108 104 115 112 131 127 91 111 112 111 98 107 102 113 111 109 115 118 116 110 128 105 97 95 117 102 101 126 107 116 106 106 106 113 115 105 101 111 109 110 99 104 96 107 119 109 105 126 108 97 109 100 118 92 93 98 130 112 109 97 105 106 119 122 106 106 108 92 116 112 127 107 110 102 119 114 90 84 103 110 99 136 115 109 118 100 107 120 123 99 102 94 106 95 103 100 100 129 116 103 122 116 110 108 88 116 110 113 117 113 117 123 100 111 122 103 114 125 118 124 101 124 119 97 115 103 111 110 125 116 112 134 90 119 111 120 123 99 110 114 114 110 113 108 89 105 115 96 99 116 104 99 115 101 114 103 114 106 102 98 126 110 125 103 129 99 106 123 114 116 103 97 104 104 113 108 102 121 111 107 104 117 115 102 109 108 122 107 97 96 116 103 115 125 91 103 116 103 96 103 90 124 105 108 121 108 98 96 109 105 114 107 112 116 115 98 123 92 112 110 105 108 123 118 108 106 135 103 117 116 105 134 123 103 125 113 112 107 115 124 129 102 100 105 117 96 104 106 108 121 109 103 131 111 112 119 103 122 105 120 104 113 116 92 110 118 95 100 111 136 106 119 103 102 114 103 100 112 122 101 113 92 119 115 102 101 112 130 126 106 104 109 111 104 103 105 120 99 110 110 104 95 115 93 103 104 117 103 103 116 108 111 101 77 101 94 110 115 112 105 126 96 99 105 109 100 117 104 118 109 113 129 106 109 99 113 106 108 108 114 120 107 101 108 113 123 84 119 114 104 114 111 94 111 128 91 112 123 121 118 108 95 100 95 103 115 108 122 97 105 106 115 112 113 132 111 113 97 119 113 126 106 96 98 121 93 109 125 106 113 110 113 107 106 105 97 125 116 117 94 123 118 106 111 108 104 97 97 128 120 116 118 97 109 107 107 121 114 83 122 124 102 122 124 128 114 120 115 101 99 99 117 122 107 124 121 117 113 108 104 96 117 79 101 122 114 98 119 102 85 122 124 131 126 127 105 98 130 112 110 102 116 98 100 104 104 111 113 105 89 100 101 110 102 108 117 131 124 100 103 112 114 110 108 112 111 107 97 113 106 106 116 101 109 88 104 119 96 111 101 110 103 115 97 104 124 110 105 96 107 112 121 101 97 129 111 124 114 110 125 94 118 126 104 113 110 121 100 105 99 99 101 108 104 102 107 117 102 97 126 107 125 87 117 91 128 107 103 120 119 118 116 99 103 123 96 110 105 110 108 119 130 110 105 117 107 101 109 120 88 111 102 118 117 129 128 108 111 116 103 92 123 104 95 116 106 89 126 90 93 116 107 122 108 128 91 115 106 127 112 108 120 108 107 111 99 119 99 124 121 113 118 116 112 120 93 121 122 111 121 114 101 96 104 102 122 107 117 110 106 115 128 101 129 107 102 135 103 107 97 125 106 109 108 108 100 111 110 113 94 116 118 123 105 117 112 100 114 102 117 110 108 104 128 100 116 125 96 108 124 111 120 100 113 109 122 118 108 104 91 83 107 98 125 113 114 113 108 105 97 102 100 119 118 100 108 114 110 107 120 123 116 116 121 127 118 111 122 105 122 132 109 104 125 122 106 108 119 104 130 115 113 120 118 105 101 120 124 114 117 91 100 115 83 112 111 122 117 119 111 106 119 127 119 87 111 102 114 102 116 109 115 104 107 107 124 107 110 114 119 94 99 99 114 119 123 104 107 128 107 125 106 104 98 121 96 117 106 107 115 126 117 103 99 123 115 106 106 110 103 100 110 101 112 98 127 96 107 106 107 119 125 108 98 93 85 108 123 100 106 112 111 94 110 110 120 114 105 116 99 114 104 138 102 112 106 112 106 125 116 123 104 116 102 123 105 115 105 114 119 94 85 95 111 109 111 131 122 101 125 117 120 112 99 111 133 110 102 109 74 115 114 110 89 130 99 83 120 102 90 131 115 135 128 100 107 109 110 102 115 115 128 93 120 104 128 88 97 96 127 106 131 106 126 114 94 113 91 99 88 105 111 118 120 130 103 115 109 101 106 110 115 98 94 134 113 101 95 111 99 146 116 97 108 94 104 121 107 103 115 100 100 108 114 111 122 98 121 117 119 110 111 103 97 106 106 109 111 105 115 109 115 120 94 128 114 117 127 112 98 111 107 113 104 120 113 112 94 92 109 104 136 110 105 109 106 109 103 99 116 106 98 111 96 119 105 129 131 127 117 116 103 110 106 111 113 118 122 93 120 98 114 111 121 105 98 111 142 110 113 111 112 90 90 98 104 110 113 118 122 115 120 101 98 83 97 93 94 119 104 95 114 119 105 111 86 123 112 125 87 106 97 94 116 117 90 109 124 111 120 104 101 107 96 122 114 101 109 126 96 94 112 116 115 129 113 96 99 112 106 100 108 121 95 111 117 105 102 107 121 127 107 108 124 110 127 98 115 99 90 130 108 104 117 101 92 98 104 110 108 121 112 113 112 109 105 126 123 116 110 106 118 93 109 109 104 114 101 96 113 111 109 131 128 106 123 105 98 124 124 109 120 84 115 104 114 116 121 108 105 106 104 103 108 89 110 112 116 110 121 97 114 102 111 108 106 101 117 122 126 98 91 115 96 85 118 113 114 103 125 111 113 106 98 120 103 99 133 111 118 95 116 108 111 92 124 97 113 116 102 115 98 108 118 111 123 112 119 126 109 83 106 108 103 108 106 100 113 121 106 92 124 110 125 94 105 103 122 112 116 101 111 115 113 122 110 112 102 97 105 89 128 122 115 107 111 103 109 114 107 114 110 98 95 122 117 96 105 119 108 119 114 100 105 101 87 106 112 113 124 114 122 133 119 115 113 100 97 116 101 131 121 103 129 121 122 84 133 116 120 122 122 102 98 113 85 109 108 116 95 100 98 92 95 105 111 121 127 115 97 97 105 111 123 106 114 106 98 119 117 109 121 100 83 125 94 130 111 103 99 109 126 118 103 116 106 112 141 100 110 125 91 117 113 116 107 116 118 123 105 124 103 102 103 107 88 102 117 109 110 110 103 113 112 103 122 112 118 119 99 94 120 120 117 108 91 111 92 126 101 121 109 100 96 112 115 93 112 114 94 121 114 124 97 94 124 125 96 108 105 111 103 93 105 109 102 105 119 92 131 111 104 121 90 109 104 112 97 119 115 120 99 104 123 109 111 103 119 116 115 106 122 103 113 110 98 121 107 112 124 115 98 106 105 107 116 116 106 106 101 119 117 100 114 101 117 110 109 97 120 112 92 113 118 109 118 107 89 108 110 122 103 114 121 105 98 113 102 96 108 109 122 108 98 95 105 109 125 103 111 111 116 121 135 122 120 127 103 117 114 116 94 93 107 96 99 110 140 111 84 128 114 91 108 119 112 111 119 118 116 85 109 95 110 101 99 97 120 114 99 109 115 106 125 105 113 115 109 127 114 117 122 108 102 100 120 92 109 100 101 92 87 109 124 109 117 118 104 114 108 90 118 113 95 100 119 113 97 115 98 94 99 121 92 127 130 110 110 111 97 106 133 111 107 92 116 116 97 111 137 98 94 106 131 113 102 86 115 108 124 113 116 102 101 95 130 109 108 99 113 116 130 116 105 109 115 104 107 108 125 108 117 111 116 102 112 106 95 114 108 129 129 90 135 120 108 107 104 113 120 118 133 97 116 93 113 123 119 108 101 110 108 98 107 119 116 102 107 135 100 106 108 113 100 102 104 109 95 105 105 113 94 101 106 138 122 112 125 113 134 108 127 116 124 112 103 108 106 112 108 119 110 104 104 113 115 117 121 118 112 116 102 109 126 117 105 86 104 97 108 115 110 101 100 116 118 112 107 109 111 116 121 122 110 103 124 113 107 114 110 116 92 119 110 111 122 115 104 93 137 100 112 127 102 110 105 117 102 107 112 110 115 107 122 112 115 112 99 117 94 110 115 92 107 108 103 96 109 110 128 117 129 123 105 98 118 103 120 110 112 111 103 123 109 111 112 128 112 116 121 126 117 104 133 109 105 118 123 100 130 119 119 117 123 110 115 108 114 104 120 122 109 126 120 116 102 125 108 123 113 125 103 108 120 113 122 120 111 109 107 124 127 112 115 115 118 110 114 105 98 115 109 125 116 122 119 114 116 124 109 106 134 110 110 128 110 107 142 120 125 116 128 112 107 130 116 118 124 124 116 120 107 124 123 134 115 124 112 114 113 123 134 117 135 97 112 107 110 110 117 141 112 118 114 133 140 111 138 101 128 121 107 106 111 100 112 132 115 111 83 117 111 112 108 119 102 105 110 108 123 111 126 117 120 139 95 113 122 119 130 103 106 127 103 124 117 125 113 107 108 112 107 108 123 112 101 124 113 101 115 106 126 118 121 93 122 125 106 106 99 116 107 119 109 125 97 112 94 112 119 105 101 126 97 104 134 117 124 99 97 106 103 98 120 110 111 125 113 108 116 124 109 114 111 116 111 120 113 116 117 137 117 106 114 125 110 100 109 102 112 115 130 123 133 95 120 98 113 118 115 114 124 113 110 99 94 100 114 95 124 115 118 128 113 113 115 105 93 124 108 106 137 106 116 101 116 98 114 114 111 104 112 121 114 110 107 114 124 110 122 121 124 103 125 100 119 102 108 115 102 113 121 105 90 106 125 100 135 110 96 121 104 116 105 125 127 122 118 119 114 144 103 128 113 117 122 104 122 115 118 108 121 116 108 103 97 118 138 121 98 115 105 109 105 102 106 98 108 120 132 124 128 115 103 105 118 108 113 114 125 102 134 126 128 112 107 120 112 105 119 113 100 91 113 97 113 107 132 112 115 109 122 118 121 113 135 101 117 127 113 110 99 121 115 116 118 95 142 130 116 106 83 125 128 121 110 116 112 130 117 110 122 108 105 106 114 125 120 113 112 126 109 96 113 130 105 131 123 109 126 81 112 120 130 100 115 110 117 94 118 116 117 119 130 111 118 113 107 108 101 112 107 111 132 98 104 103 123 98 129 114 127 104 109 108 114 123 111 123 104 113 127 108 115 116 102 103 106 95 124 116 114 120 115 121 110 89 96 109 119 124 126 118 130 115 114 123 117 104 124 104 113 114 108 106 122 116 92 105 113 106 102 117 125 122 127 117 116 125 116 128 122 109 110 108 114 116 115 99 114 122 114 129 130 98 129 103 113 112 116 106 121 123 103 107 134 114 109 122 113 95 119 111 108 114 98 105 99 118 129 115 115 99 103 119 111 120 108 104 92 111 124 118 99 120 126 109 114 113 125 117 118 119 117 116 110 120 117 99 105 100 105 110 116 117 128 108 104 118 110 108 106 131 111 98 104 117 128 136 116 127 117 112 110 99 100 104 122 114 115 104 96 125 100 117 105 116 118 101 102 118 130 115 113 113 110 106 113 108 95 117 98 101 106 124 116 113 101 96 115 100 129 116 111 109 109 106 109 113 133 119 119 104 105 135 121 116 128 115 109 123 115 110 128 106 119 122 109 118 98 120 96 101 111 99 103 109 104 123 125 117 109 103 116 111 118 107 103 106 99 113 102 113 110 111 120 104 118 111 111 108 108 104 116 108 124 104 99 111 124 120 111 107 109 119 91 117 102 107 122 118 82 93 95 120 100 118 122 124 123 112 115 123 115 116 109 136 111 112 105 99 121 100 109 108 97 114 105 113 110 107 100 126 114 106 115 113 103 112 106 92 110 119 96 119 96 102 106 99 111 123 104 107 111 118 106 120 126 120 97 122 112 130 114 106 100 94 112 94 103 95 116 119 119 113 136 110 102 109 117 123 108 126 122 114 101 111 120 118 101 113 124 124 120 125 124 127 95 120 109 104 102 125 111 112 109 125 107 106 109 93 113 107 113 114 125 98 110 87 88 109 117 107 101 102 92 114 126 116 113 129 93 117 112 110 117 126 112 93 115 102 106 122 112 111 111 112 117 118 106 110 106 116 101 124 102 122 118 110 98 121 115 96 124 117 115 114 114 107 93 107 108 93 128 103 100 99 115 124 116 136 114 124 118 114 113 112 116 127 121 106 105 119 106 121 113 99 118 108 102 131 110 104 106 107 126 103 99 121 124 106 119 122 108 122 109 110 105 120 94 110 97 105 119 123 118 130 121 104 121 101 134 104 104 99 121 122 129 111 108 88 108 126 125 120 112 91 106 118 120 111 108 95 110 99 108 135 123 100 110 120 123 120 121 121 109 119 111 132 110 111 135 113 118 108 111 100 110 110 107 121 110 110 113 105 99 121 110 115 106 110 112 98 112 113 95 101 110 108 125 115 103 118 117 125 100 103 109 116 120 123 113 102 105 111 119 113 100 123 118 137 134 105 107 129 104 122 97 107 123 113 101 115 115 125 95 113 121 115 122 109 112 108 141 115 97 97 103 113 104 108 116 109 125 117 122 107 112 120 125 118 114 105 106 108 105 121 112 97 110 106 121 116 106 125 112 121 115 95 131 102 112 108 106 125 140 120 113 122 113 95 115 98 117 119 119 108 105 111 116 118 102 124 104 102 118 110 129 127 116 102 109 122 95 112 110 109 105 120 105 120 104 124 98 91 109 98 113 105 95 116 134 94 115 127 117 123 107 104 102 112 119 125 147 116 120 104 113 100 110 127 119 108 115 107 112 118 119 122 108 123 118 116 117 112 103 107 117 113 110 107 111 117 109 127 119 114 96 116 100 95 120 123 118 105 109 125 121 110 122 127 117 102 100 121 110 99 116 121 121 130 112 103 98 128 127 119 124 112 110 94 108 104 125 103 116 104 123 114 114 91 102 92 115 130 121 112 124 94 107 117 122 94 144 98 112 110 116 116 112 120 94 100 129 97 99 134 101 111 116 117 122 129 122 102 97 96 124 101 106 122 116 101 99 124 108 101 120 107 112 127 119 101 99 101 93 121 112 108 133 116 118 95 93 131 108 116 94 108 112 116 103 110 111 96 115 111 110 133 117 93 97 124 113 120 110 114 121 120 134 132 116 123 108 102 122 109 121 111 117 126 120 117 124 114 113 104 97 95 113 109 122 104 102 108 109 125 111 118 119 107 91 103 103 105 108 115 112 114 122 109 112 115 114 101 100 118 116 115 104 125 112 112 117 128 96 119 113 121 102 128 101 117 114 113 120 127 126 105 113 108 111 102 106 113 99 126 118 112 105 100 131 116 114 94 127 98 99 114 105 111 114 113 113 105 98 101 91 101 93 117 122 128 124 109 112 128 101 119 107 100 110 114 126 119 106 101 118 113 114 100 106 130 122 106 120 107 96 108 135 116 110 107 109 110 116 118 124 114 106 116 105 120 106 109 90 109 95 92 97 98 119 124 115 121 112 98 96 116 84 100 119 90 111 113 104 86 101 102 115 119 110 90 111 93 102 114 94 99 106 111 111 109 107 129 124 81 108 107 112 110 106 103 130 93 101 90 101 101 123 123 133 119 118 113 106 123 109 108 114 111 115 107 109 131 112 101 115 110 114 91 98 107 118 123 113 110 134 110 122 118 95 93 95 102 115 103 87 114 107 98 106 96 118 116 108 114 111 99 106 119 113 134 102 97 126 128 111 112 96 89 129 120 117 105 111 114 100 117 117 116 114 126 110 102 105 110 118 108 117 116 112 118 94 113 122 102 110 101 116 94 111 115 90 118 113 103 110 126 105 113 111 96 116 127 104 98 108 112 114 110 113 125 91 98 107 116 99 123 120 132 105 108 95 114 102 116 108 94 127 100 102 127 153 103 114 114 98 112 87 116 118 117 90 113 93 115 111 121 132 108 129 115 127 121 110 118 104 89 127 104 119 117 103 104 128 92 110 125 120 102 117 123 115 117 105 107 112 82 109 106 119 119 96 116 117 119 106 115 99 117 98 123 98 120 108 109 126 132 118 112 116 120 121 119 106 131 115 123 142 104 130 99 127 118 92 116 101 138 110 109 121 101 112 107 102 108 95 103 114 109 116 108 101 134 111 114 108 102 110 113 110 104 127 110 108 100 129 108 106 96 113 123 121 135 112 109 126 107 104 110 107 116 121 116 114 112 94 131 117 106 97 121 118 121 116 114 111 108 110 117 128 115 127 114 109 120 114 120 106 150 103 127 112 110 121 126 118 124 101 121 119 120 113 128 131 121 112 148 117 131 111 124 120 128 125 137 124 127 131 120 119 140 134 118 130 135 122 137 155 123 109 99 130 133 102 131 119 116 136 129 140 108 123 133 135 114 116 123 119 109 124 109 122 123 109 125 107 130 121 117 115 120 113 116 119 109 111 125 123 128 95 143 131 100 123 114 135 107 123 112 108 115 137 114 103 105 130 105 123 100 114 129 111 111 100 102 119 119 100 97 121 108 115 125 110 118 122 94 92 106 107 116 121 112 106 116 110 110 134 94 104 110 126 114 119 113 116 101 107 104 105 99 108 121 109 112 113 111 128 115 109 107 108 98 121 116 96 97 105 109 118 103 86 125 104 104 87 105 107 118 106 113 115 96 110 124 107 113 99 107 110 96 100 120 126 109 111 126 112 113 137 99 103 121 92 95 96 110 122 125 114 124 115 95 109 125 112 112 90 110 100 124 132 115 122 103 107 111 116 106 113 103 100 112 105 114 97 112 116 118 109 101 105 117 115 119 99 116 124 117 107 108 103 118 96 117 113 110 92 99 85 89 95 109 94 122 114 105 108 126 128 90 117 114 102 116 95 106 113 95 117 117 103 125 125 134 109 112 91 117 108 91 128 99 102 106 117 103 113 106 122 96 105 101 81 106 129 119 100 102 115 85 124 112 102 124 94 113 102 114 92 107 101 115 114 115 112 113 114 88 115 114 106 126 96 119 96 109 99 103 114 102 119 112 100 104 93 100 98 92 110 128 118 118 106 105 93 98 109 128 123 110 110 108 114 123 110 113 124 129 107 101 102 115 89 101 96 83 102 114 107 111 89 92 86 109 102 105 89 97 103 118 95 106 109 117 106 92 110 97 115 117 109 100 105 121 116 112 126 102 100 90 121 90 111 95 115 106 127 107 117 106 122 127 110 113 116 109 93 115 108 101 108 117 120 113 102 92 135 92 93 109 110 130 105 112 111 99 111 102 113 116 96 132 106 114 117 107 105 100 107 103 96 98 106 107 98 104 141 96 108 110 129 104 84 105 99 116 128 119 110 99 102 112 112 125 103 108 116 104 125 89 103 98 97 90 108 100 110 100 101 115 114 97 103 105 100 95 103 119 109 107 108 113 103 103 117 119 110 112 92 119 104 101 111 112 121 113 123 85 110 99 108 109 102 115 91 112 119 113 96 111 136 118 98 100 103 111 108 113 110 99 102 125 109 119 98 128 116 110 110 105 103 117 115 103 126 96 98 118 94 98 112 104 106 100 102 107 104 105 110 117 98 91 111 107 91 110 98 109 97 88 111 106 109 112 97 96 122 111 104 108 115 115 106 94 113 119 101 103 115 108 106 114 113 119 107 118 115 128 108 102 120 108 110 100 100 111 114 111 90 106 106 93 110 101 119 94 106 107 116 93 103 102 111 103 131 126 102 108 108 120 91 101 102 113 116 115 101 90 98 120 121 112 109 125 109 107 116 101 105 112 106 118 100 100 113 121 101 107 93 100 103 93 96 106 111 113 114 105 104 112 114 92 109 103 114 111 115 107 105 112 105 105 107 102 113 108 104 100 118 108 100 110 105 124 97 99 112 105 101 112 104 107 83 108 120 109 116 106 103 109 101 100 113 72 117 116 113 89 131 93 124 120 114 99 94 93 107 102 124 98 120 115 115 112 123 115 92 93 107 120 102 123 125 131 98 113 98 97 98 113 99 114 101 119 100 110 88 89 96 133 87 119 103 113 110 110 108 113 106 92 116 116 123 97 112 91 114 115 104 100 100 113 112 110 89 118 115 104 98 111 105 124 115 98 81 115 98 116 102 114 112 101 113 117 109 109 111 104 101 119 94 108 99 101 107 112 96 90 109 111 105 101 101 119 116 111 84 102 126 109 101 86 89 95 106 106 123 99 110 98 122 88 102 111 116 101 81 115 113 99 107 103 115 88 101 89 93 99 92 102 123 112 102 97 115 117 118 100 126 115 108 113 111 102 79 105 112 91 118 114 112 113 109 104 99 102 117 111 113 106 92 98 111 114 115 103 108 108 108 131 100 127 109 121 102 113 97 98 106 124 113 106 91 110 100 99 87 99 81 111 79 101 102 115 104 96 91 108 97 82 107 84 113 101 115 96 116 118 106 119 96 105 106 91 116 102 118 94 98 111 114 114 106 118 96 107 105 106 124 109 99 91 90 104 124 116 87 93 110 104 105 96 97 89 95 96 122 115 96 112 114 93 109 102 93 118 98 122 122 111 111 110 101 126 104 117 95 107 109 106 119 113 98 114 124 109 103 100 94 87 102 115 105 120 104 102 106 86 113 97 106 104 99 115 99 104 106 107 122 107 102 103 93 102 106 95 105 96 98 109 81 113 88 114 105 116 98 101 106 106 108 119 108 120 110 115 106 123 104 113 106 91 106 100 126 101 109 96 113 88 106 109 121 104 142 110 116 126 109 134 105 108 110 103 100 88 111 99 100 105 117 102 99 97 91 101 89 95 108 110 112 107 100 114 103 110 112 113 107 110 117 99 102 112 99 88 89 103 128 108 117 112 103 96 112 100 97 126 92 112 109 94 123 102 111 133 78 99 102 96 94 113 87 118 108 109 96 105 96 95 98 114 98 91 115 110 96 92 106 126 121 114 126 113 129 113 96 114 88 107 128 90 111 102 117 79 127 117 100 124 101 109 95 89 122 98 108 82 113 107 104 119 104 92 107 111 127 107 107 105 106 80 122 112 94 96 116 89 97 108 80 116 110 92 116 88 106 101 107 98 110 112 119 99 123 129 102 105 102 106 105 113 119 100 98 104 108 119 91 115 121 91 112 115 102 103 113 99 113 107 99 103 84 105 121 100 121 102 111 103 99 100 102 114 104 103 118 74 99 103 100 110 96 102 106 114 120 117 107 128 128 101 98 106 107 112 106 100 118 107 110 98 110 116 104 106 114 109 106 99 112 112 107 115 123 109 112 117 110 108 99 96 96 102 117 115 104 115 110 106 114 110 88 96 103 86 110 100 107 113 99 99 101 117 100 102 101 103 109 103 105 92 101 119 93 102 98 99 120 111 99 123 103 104 105 92 121 107 106 108 121 99 104 104 88 91 111 102 106 135 107 91 106 99 117 103 110 114 103 97 96 104 101 97 107 96 122 127 99 118 118 104 116 103 111 115 98 91 95 97 112 91 98 105 129 111 94 97 104 91 99 125 94 102 111 103 112 109 113 90 99 98 120 100 113 87 94 121 110 97 101 105 89 95 110 115 103 91 93 104 116 107 96 110 110 124 114 112 106 121 117 121 105 107 105 103 104 89 109 106 117 104 101 104 108 102 116 126 94 113 107 90 100 121 128 93 119 128 102 97 105 88 116 118 82 99 94 114 114 107 102 102 110 98 102 91 111 106 120 99 105 109 99 103 120 103 104 100 100 125 106 80 95 111 110 97 108 96 105 103 103 103 103 115 82 104 104 92 101 88 102 109 110 103 103 110 110 99 105 102 126 118 118 95 93 120 102 109 106 110 110 87 121 109 117 102 100 107 92 102 98 92 100 120 110 93 98 124 98 113 88 103 104 113 108 111 100 102 92 100 108 88 115 101 108 124 89 127 94 92 93 107 103 94 116 105 110 120 97 129 101 121 89 108 119 127 127 101 108 95 107 107 107 120 93 104 92 113 90 79 100 101 120 103 117 124 105 106 106 100 107 119 112 88 112 98 108 90 122 105 100 81 110 116 120 110 114 99 117 108 103 100 114 104 99 114 115 98 112 123 98 118 103 104 106 105 131 114 101 124 110 113 92 96 103 105 125 100 110 110 134 109 123 104 95 94 122 114 101 125 103 122 121 128 105 120 117 116 104 121 103 118 107 103 95 99 109 115 110 107 116 110 135 117 110 115 113 103 107 118 109 94 128 107 129 108 115 108 86 116 122 99 121 106 113 90 114 98 118 121 112 97 106 119 98 103 113 103 114 88 112 111 94 125 99 97 112 117 116 94 116 105 84 121 110 120 74 113 98 97 92 107 101 115 95 117 112 129 86 121 102 98 107 85 106 117 120 108 116 83 118 111 137 89 123 103 96 96 96 101 126 99 114 100 109 97 97 117 114 120 98 122 99 103 114 106 111 88 114 99 100 94 122 96 91 98 101 106 107 110 114 91 108 117 124 97 101 117 120 120 105 121 101 80 128 95 109 108 96 111 108 94 113 100 108 119 117 102 96 122 116 109 110 97 97 84 120 111 100 106 104 115 116 127 107 118 117 89 98 106 108 91 118 106 102 123 116 136 101 122 113 101 110 94 130 121 103 98 124 102 106 105 109 101 106 92 102 109 99 119 99 100 100 92 102 95 109 100 105 113 106 109 110 116 102 108 110 102 107 98 117 108 113 103 106 91 100 131 109 109 116 105 111 97 112 89 103 108 106 106 112 88 102 92 117 113 115 103 113 105 88 110 99 107 114 109 93 82 104 101 105 126 112 114 113 117 99 94 88 124 114 105 114 112 115 97 127 96 109 106 101 90 116 118 105 86 102 86 116 120 128 110 112 109 118 101 98 122 113 123 116 100 97 97 106 104 102 100 109 102 105 106 117 113 96 106 117 130 110 83 106 114 102 95 110 95 131 101 124 114 105 111 89 109 118 105 117 101 108 96 96 104 92 112 101 101 107 118 97 89 92 101 103 117 92 102 106 97 81 121 114 111 97 104 85 110 120 115 114 95 117 89 104 111 116 104 105 101 118 93 109 122 103 103 120 132 106 100 98 83 93 108 107 101 109 110 96 107 105 102 98 113 95 87 78 106 131 101 113 107 102 115 98 88 95 108 122 82 119 105 107 102 99 105 101 101 108 97 107 120 108 96 107 107 108 98 92 113 101 99 118 115 113 101 100 102 94 102 115 101 85 112 119 114 98 107 116 101 126 106 95 111 104 100 106 124 104 85 107 104 97 83 118 92 92 96 114 95 95 88 119 100 114 94 113 108 115 111 129 103 98 114 114 117 95 108 105 109 117 107 99 114 109 120 108 108 125 97 96 100 83 104 117 91 107 85 98 114 116 112 106 109 97 95 111 125 106 94 98 109 106 88 102 125 103 108 103 116 108 96 83 108 91 101 123 104 90 103 103 90 115 108 100 97 103 121 83 91 116 104 116 109 104 120 101 105 101 106 90 107 110 111 120 99 94 114 119 110 96 86 108 90 107 109 103 99 102 131 117 108 97 99 99 106 101 108 95 106 107 115 112 95 104 91 117 114 107 86 121 100 101 123 124 123 113 103 83 92 106 103 101 102 120 104 93 99 109 99 99 109 88 100 110 123 96 90 90 125 109 113 123 115 106 108 102 97 130 104 106 85 106 102 126 92 88 124 107 115 98 105 102 105 114 119 94 124 106 110 109 115 111 121 114 98 95 108 90 116 110 102 115 111 99 111 118 108 102 84 117 106 101 89 104 98 126 91 100 95 95 102 123 119 109 100 117 102 110 107 94 99 103 115 100 112 117 108 103 93 112 98 123 117 111 100 105 102 122 109 91 113 105 100 114 123 103 89 104 107 112 121 106 102 105 103 115 105 117 105 127 104 111 114 88 127 134 110 106 106 122 104 119 98 104 113 108 119 106 123 125 95 101 104 112 109 90 117 104 122 97 115 117 109 120 80 103 106 117 122 111 110 105 106 105 107 134 119 114 119 114 137 121 109 104 119 91 98 107 104 95 89 113 106 103 118 100 89 85 103 114 108 132 129 103 115 95 131 118 115 102 88 106 106 106 107 108 88 126 98 111 113 104 111 94 103 106 112 94 119 108 107 107 121 95 115 100 92 96 100 107 95 120 99 104 114 110 97 95 99 111 114 116 117 88 92 115 111 108 97 114 115 112 115 116 116 106 122 103 93 113 109 112 91 113 104 90 103 99 112 104 94 117 86 115 91 97 92 114 120 102 107 118 96 107 125 115 110 98 110 105 63 114 111 101 108 87 90 92 93 97 98 95 105 131 98 98 110 92 113 103 89 106 103 109 108 104 113 103 98 110 107 116 138 94 98 94 115 98 112 106 124 101 104 110 108 117 86 123 107 111 110 115 123 102 106 120 99 119 100 95 107 89 101 83 114 108 112 112 96 117 105 105 110 111 115 107 120 106 96 122 100 106 100 118 97 112 110 129 113 109 136 107 111 102 131 112 118 113 97 102 117 106 94 105 114 121 110 126 106 119 109 112 122 109 134 101 97 103 110 101 110 106 116 104 91 105 110 117 120 112 104 112 90 108 106 108 109 130 114 116 107 105 124 119 111 115 111 110 109 115 105 121 105 109 91 116 99 109 84 103 125 119 132 106 104 109 107 120 109 106 106 116 125 110 101 110 105 104 92 106 107 106 109 127 109 109 114 139 99 132 105 105 119 92 100 98 93 108 102 127 87 119 107 100 108 118 121 108 107 123 105 118 98 92 103 103 106 115 122 98 118 114 98 116 116 105 126 101 125 108 87 94 96 91 110 124 132 131 103 107 121 91 93 120 101 100 114 90 97 97 101 117 87 114 101 117 129 106 118 108 97 101 125 123 108 121 104 113 113 91 114 112 105 111 106 100 95 106 82 112 112 108 100 121 105 126 117 108 116 125 115 119 122 107 103 120 97 127 90 99 115 118 111 147 114 102 128 108 93 115 115 112 107 101 109 118 103 96 122 111 81 105 117 120 120 106 127 121 123 145 126 114 116 114 120 121 112 102 107 108 140 105 102 128 91 112 99 101 119 110 96 115 105 131 113 105 108 99 112 94 109 110 111 119 105 118 106 100 98 109 125 130 108 133 108 111 100 116 97 117 100 129 116 129 105 114 105 116 118 101 104 106 121 120 107 116 127 126 96 103 119 126 116 117 119 124 123 110 113 97 108 116 118 102 120 100 98 105 99 126 115 114 120 102 109 108 99 116 111 120 110 118 100 110 109 121 130 112 121 112 120 118 89 109 132 108 107 112 104 110 94 108 103 120 99 128 113 102 127 123 104 129 103 106 120 98 96 100 120 113 102 125 116 113 103 113 117 106 130 127 113 114 101 120 110 128 128 114 115 116 116 120 109 105 115 113 114 115 117 118 132 111 135 114 96 117 124 94 107 114 118 104 100 124 125 93 132 116 118 111 108 131 103 104 113 117 116 105 130 116 106 119 123 110 141 111 96 102 130 118 124 119 121 114 84 119 126 117 113 106 118 106 112 123 104 111 104 132 106 113 108 107 113 95 132 100 119 113 107 100 98 88 97 129 114 103 116 141 112 120 101 99 108 115 122 97 99 112 84 105 121 127 108 108 120 109 115 110 101 115 125 123 131 106 108 106 128 122 112 123 111 129 125 119 116 104 111 124 128 117 110 119 108 122 112 98 103 110 120 111 107 118 124 108 130 133 101 129 115 107 111 103 106 123 113 120 98 96 116 120 111 120 108 116 120 108 105 123 115 143 117 118 119 103 119 105 123 114 119 122 112 112 121 117 98 116 107 125 118 103 112 112 127 101 112 117 123 96 102 106 114 126 106 124 104 109 98 91 112 122 112 119 118 143 120 113 124 123 120 120 108 105 104 129 121 115 120 120 111 119 102 123 93 100 107 112 118 117 120 110 125 103 90 109 98 120 118 122 117 116 109 105 131 120 131 126 114 105 122 122 125 135 111 119 94 107 123 108 123 90 122 124 117 106 123 110 132 124 116 112 104 111 112 127 101 121 135 121 106 132 119 123 119 87 128 122 122 132 130 117 108 112 115 129 120 118 101 115 124 106 114 111 123 119 117 102 99 114 121 102 133 123 116 124 130 130 133 112 124 119 135 127 100 125 126 117 109 108 115 104 116 126 125 106 119 137 112 126 150 122 113 114 112 112 133 123 132 137 144 131 96 135 116 127 127 115 141 120 110 113 114 113 111 138 125 126 121 132 128 103 137 123 107 132 114 124 107 111 110 135 114 121 124 131 127 101 107 99 131 114 112 121 141 127 125 121 121 125 129 131 114 124 106 126 133 115 105 117 114 95 119 126 119 124 108 119 136 130 119 129 136 123 109 125 117 103 149 137 124 114 103 124 98 112 102 118 115 128 118 128 105 105 120 111 120 110 107 122 141 145 102 123 110 106 117 131 119 122 106 140 131 124 123 128 119 121 133 125 131 115 122 116 111 110 116 126 124 128 129 116 123 104 108 118 117 101 126 116 131 125 122 110 113 105 98 126 122 130 134 143 115 121 107 115 121 134 106 99 97 114 113 132 135 104 115 114 124 110 123 133 114 107 115 119 111 111 142 114 121 113 131 103 122 127 125 111 124 106 132 110 119 127 111 125 120 130 99 127 102 131 126 113 115 125 111 116 96 106 107 100 104 110 131 128 123 117 105 98 122 117 109 112 116 131 109 126 118 104 101 103 125 104 106 137 117 124 131 107 115 115 118 128 117 120 118 110 115 128 124 108 111 113 123 103 109 107 132 108 110 110 120 122 114 113 124 116 109 119 134 97 111 141 113 110 113 120 117 138 110 110 117 122 108 100 112 110 125 114 107 129 118 121 110 118 128 110 112 104 112 127 110 133 108 93 114 115 132 96 107 118 110 122 102 118 112 120 136 108 120 113 117 130 141 102 135 132 111 115 98 114 115 118 121 107 135 113 126 113 132 140 106 102 126 125 116 126 124 127 111 101 96 124 116 124 112 130 129 127 122 92 111 123 109 117 128 100 122 117 127 126 122 115 114 128 117 124 108 104 102 118 122 113 100 110 106 116 94 116 123 114 132 112 135 100 129 129 104 117 116 109 121 126 120 122 124 116 102 116 124 124 131 134 110 108 132 101 104 115 127 108 113 113 91 108 133 124 110 119 136 120 120 122 110 107 136 112 117 119 125 124 129 122 130 115 111 114 130 128 102 105 133 101 118 128 121 115 113 115 125 110 122 139 118 116 106 116 120 106 112 111 129 126 122 129 122 101 140 111 116 132 118 105 117 108 121 98 131 109 125 129 107 127 123 105 133 121 114 131 119 118 116 113 126 129 117 113 116 111 116 94 114 118 123 121 110 109 122 132 111 125 121 117 137 124 125 117 108 92 129 106 119 111 111 109 112 103 124 145 125 125 118 126 103 114 109 107 115 132 133 99 118 118 127 130 132 118 116 143 141 115 126 127 128 116 138 96 115 118 94 113 115 117 122 112 126 137 112 133 113 97 122 125 111 112 129 132 124 98 111 123 136 120 127 117 133 135 111 128 166 112 124 123 116 108 122 130 115 136 115 112 122 100 105 133 112 122 107 150 113 109 121 110 133 115 119 93 130 118 124 123 121 110 116 131 116 107 133 134 122 82 126 112 115 106 120 118 116 133 115 109 110 103 125 102 125 121 123 124 87 123 108 131 99 125 115 128 116 124 104 123 121 135 119 123 121 127 124 118 114 122 109 135 116 106 128 132 115 127 111 121 136 124 132 120 120 136 100 127 131 129 108 125 125 117 118 116 117 103 133 119 113 126 112 120 120 150 131 107 95 120 127 111 117 129 111 142 107 126 133 99 131 115 126 133 112 131 114 110 124 130 112 138 116 117 122 120 116 107 126 140 119 114 110 99 132 128 121 141 136 139 117 132 140 115 127 121 122 123 138 109 120 122 116 110 123 121 132 132 125 111 131 120 125 113 97 112 116 132 113 132 125 119 120 125 127 111 125 128 122 117 109 121 129 121 121 114 123 104 115 119 118 128 114 97 129 128 104 102 109 117 121 121 130 120 123 143 130 115 105 140 126 133 116 113 123 108 133 119 112 97 103 153 105 113 141 128 121 135 121 144 125 122 129 131 98 100 127 115 126 102 123 121 92 111 131 127 103 103 133 134 141 113 109 127 117 123 125 146 121 123 128 125 119 126 115 134 107 116 143 115 117 113 131 102 136 104 128 122 116 118 98 134 109 131 122 120 122 111 115 131 129 109 136 131 146 134 125 117 122 121 141 108 117 118 109 128 117 126 113 130 125 138 116 141 97 125 118 136 132 133 122 125 122 109 121 128 112 139 131 138 126 151 118 101 118 139 106 116 120 118 125 142 125 124 122 115 123 117 112 119 132 132 123 114 114 106 114 119 131 123 114 124 125 119 134 120 135 125 116 134 101 129 127 132 130 120 118 118 138 126 126 114 144 130 125 153 123 132 120 113 117 124 132 130 140 124 129 130 125 131 141 131 124 152 120 109 101 124 141 125 112 114 124 125 127 121 128 150 115 113 115 132 124 144 99 122 133 126 122 134 104 121 113 122 114 120 121 127 112 117 127 128 113 110 115 113 126 117 127 125 108 108 155 115 131 113 111 117 129 132 112 118 146 105 120 114 132 119 119 150 139 139 124 111 135 131 129 134 116 111 108 134 112 139 120 130 122 115 108 119 115 118 120 135 125 116 120 127 124 127 122 140 130 135 115 137 136 116 143 124 123 141 117 115 121 117 126 115 137 105 111 130 122 109 119 128 112 142 135 129 155 129 119 117 136 140 124 135 122 119 117 130 130 115 131 125 129 110 118 140 128 131 136 117 109 131 131 135 130 132 132 114 131 127 125 119 133 131 131 122 100 126 166 118 138 141 128 138 139 105 143 118 136 131 110 110 113 124 133 132 89 125 123 135 132 133 143 128 125 116 129 112 144 131 107 135 134 107 127 138 119 132 138 110 134 149 131 127 121 122 130 135 123 125 138 146 119 121 111 112 131 125 123 121 129 115 129 137 144 109 118 132 141 121 113 136 118 111 129 117 110 142 143 130 119 136 118 143 130 135 133 107 124 124 134 137 120 138 134 121 149 117 134 112 120 126 114 134 141 137 121 118 129 116 133 131 133 125 150 102 137 136 122 127 129 125 122 138 123 132 131 126 142 130 132 155 131 132 136 136 146 148 134 115 128 139 123 137 122 132 117 132 122 135 125 127 117 121 123 119 129 118 131 110 114 125 130 118 155 131 127 122 150 131 103 126 124 123 117 136 117 105 131 139 127 137 114 116 119 131 139 131 142 117 123 133 124 140 139 145 126 124 143 140 133 128 149 129 141 143 123 138 133 142 134 126 142 117 135 128 137 110 115 140</counts>
			</dataPoints>
		</scan>
	</xrdMeasurement>
</xrdMeasurements>