File: data/XRD/XG-Sauerstoff/XG-600/W6824-1B_XG_Sauerstoff_600.xrdml
<xrdMeasurements xmlns="http://www.xrdml.com/XRDMeasurement/2.1" xmlns:xsi="http://www.w3.org/2001/XMLSchema-instance" xsi:schemaLocation="http://www.xrdml.com/XRDMeasurement/2.1 http://www.xrdml.com/XRDMeasurement/2.1/XRDMeasurement.xsd" status="Completed">
	<comment>
		<entry>Configuration=Factory configuration, Owner=User-1, Creation date=7/8/2013 4:01:53 PM</entry>
		<entry>Goniometer=PW3050/65 (Theta/2Theta); Minimum step size 2Theta:0.0001; Minimum step size Omega:0.0001</entry>
		<entry>Sample stage=MRD Cradle; Minimum step size Phi:0.01; Minimum step size Chi:0.01; Minimum step size X:0.01; Minimum step size Y:0.01; Minimum step size Z:0.001</entry>
		<entry>Diffractometer system=XPERT-PRO</entry>
		<entry>Measurement program=C:\PANalytical\Data Collector\Programs\Jorrit\2thom\_absolute_2th-om_10-130deg_PIXscan_56min.xrdmp, Identifier={15BCCF57-2807-42BD-B5B9-ECC0B3DC9284}</entry>
		<entry>Batch program=C:\PANalytical\Data Collector\Programs\SimonL\batch4x_2thom_10-130°_z9.1_x0,10,20,30_y0_57min.xrdmp, Identifier={EED9823A-2BEB-424C-9252-345C4EF2834A}</entry>
	</comment>
	<sample type="To be analyzed">
		<id></id>
		<name></name>
		<preparedBy></preparedBy>
	</sample>
	<xrdMeasurement measurementType="Scan" status="Completed" sampleMode="Reflection">
		<comment>
			<entry>_absolute_2th-om_10-130deg_PIXscan_56min</entry>
			<entry>PHD Lower Level = 4.83 (keV), PHD Upper Level = 11.27 (keV)</entry>
		</comment>
		<usedWavelength intended="K-Alpha 1">
			<kAlpha1 unit="Angstrom">1.5405980</kAlpha1>
			<kAlpha2 unit="Angstrom">1.5444260</kAlpha2>
			<kBeta unit="Angstrom">1.3922500</kBeta>
			<ratioKAlpha2KAlpha1>0.5000</ratioKAlpha2KAlpha1>
		</usedWavelength>
		<incidentBeamPath>
			<radius unit="mm">320.00</radius>
			<xRayTube id="1010048" name="Empyrean Cu LFF HR (9430 033 7310x) DK442154">
				<tension unit="kV">40.0</tension>
				<current unit="mA">40.0</current>
				<anodeMaterial>Cu</anodeMaterial>
				<focus type="Line">
					<length unit="mm">12.0</length>
					<width unit="mm">0.4</width>
					<takeOffAngle unit="deg">4.2</takeOffAngle>
				</focus>
			</xRayTube>
			<xRayMirror id="27010001" name="Inc. Beam Cu W/Si (parabolic MRD)" hybrid="false">
				<crystal type="Graded" shape="Parabolic">W/Si</crystal>
				<acceptanceAngle unit="deg">0.800</acceptanceAngle>
				<length unit="mm">60.0</length>
			</xRayMirror>
			<sollerSlit id="21010002" name="Soller slits 0.04 rad.">
				<opening unit="rad">0.0400</opening>
			</sollerSlit>
			<mask id="22030007" name="Fixed mask 2 mm">
				<distanceToSample unit="mm">220.00</distanceToSample>
				<width unit="mm">2.00</width>
			</mask>
			<divergenceSlit id="22010007" name="Fixed slit 1/8°" xsi:type="fixedDivergenceSlitType">
				<distanceToSample unit="mm">220.00</distanceToSample>
				<height unit="mm">0.19</height>
			</divergenceSlit>
		</incidentBeamPath>
		<diffractedBeamPath>
			<radius unit="mm">320.00</radius>
			<sollerSlit id="21010002" name="Soller slits 0.04 rad.">
				<opening unit="rad">0.0400</opening>
			</sollerSlit>
			<receivingSlit id="22010001" name="Fixed slit 4°">
				<height unit="mm">5.88</height>
			</receivingSlit>
			<detector id="7010017" name="PIXcel3D 1x1 detector" xsi:type="areaDetectorType">
				<phd unit="%">
					<lowerLevel>30.0</lowerLevel>
					<upperLevel>70.0</upperLevel>
				</phd>
				<mode>Scanning</mode>
				<activeChannelsEquatorial>255</activeChannelsEquatorial>
				<activeChannelsAxial>255</activeChannelsAxial>
				<pitchEquatorial unit="mm">0.05500</pitchEquatorial>
				<pitchAxial unit="mm">0.05500</pitchAxial>
				<readOutPeriod unit="seconds">0.135</readOutPeriod>
			</detector>
		</diffractedBeamPath>
		<scan appendNumber="0" mode="Continuous" scanAxis="2Theta-Omega" status="Completed">
			<header>
				<startTimeStamp>2024-09-11T21:53:45+02:00</startTimeStamp>
				<endTimeStamp>2024-09-11T22:49:51+02:00</endTimeStamp>
				<author>
					<name>PRO-MRD</name>
				</author>
				<source>
					<applicationSoftware version="6.1b">Data Collector</applicationSoftware>
					<instrumentControlSoftware version="7.0E 20130304">XPERT-PRO</instrumentControlSoftware>
					<instrumentID>0000000011142674</instrumentID>
				</source>
			</header>
			<dataPoints>
				<positions axis="2Theta" unit="deg">
					<startPosition>9.99826193</startPosition>
					<endPosition>129.99755682</endPosition>
				</positions>
				<positions axis="Omega" unit="deg">
					<startPosition>4.99913096</startPosition>
					<endPosition>64.99877841</endPosition>
				</positions>
				<positions axis="Phi" unit="deg">
					<commonPosition>0.00</commonPosition>
				</positions>
				<positions axis="Chi" unit="deg">
					<commonPosition>0.00</commonPosition>
				</positions>
				<positions axis="X" unit="mm">
					<commonPosition>30.00</commonPosition>
				</positions>
				<positions axis="Y" unit="mm">
					<commonPosition>0.00</commonPosition>
				</positions>
				<positions axis="Z" unit="mm">
					<commonPosition>9.100</commonPosition>
				</positions>
				<commonCountingTime unit="seconds">32.895</commonCountingTime>
				<counts 257 226 255 222 260 199 232 218 224 212 222 235 218 214 215 231 220 256 235 256 207 220 271 213 244 224 230 238 233 221 245 229 270 213 268 222 222 233 260 262 210 236 225 262 235 274 239 274 255 256 224 230 257 230 240 242 226 260 266 233 220 241 222 232 217 207 223 216 241 216 237 235 211 236 230 208 247 218 216 231 218 235 199 217 212 207 194 228 191 211 238 224 210 211 207 232 236 198 237 207 216 230 223 208 244 201 222 206 216 210 220 207 210 194 216 220 248 216 218 242 218 182 213 216 216 208 211 201 191 222 235 173 216 213 249 183 208 195 201 204 189 217 220 213 219 214 211 237 209 197 210 197 211 222 207 204 225 233 195 205 197 225 183 215 212 208 231 204 214 240 223 203 197 214 197 198 205 211 198 221 214 211 216 196 206 206 222 220 208 218 188 200 214 226 229 229 238 205 230 177 210 191 194 205 215 191 204 196 213 212 223 188 231 219 192 205 220 190 222 191 213 201 218 205 213 204 240 220 193 213 233 191 213 200 210 216 206 180 216 218 216 224 201 188 199 203 204 203 199 193 181 215 209 200 187 193 224 215 219 222 185 194 227 201 215 206 190 170 188 193 201 201 207 189 201 187 220 228 204 196 238 219 212 193 204 222 198 210 209 188 182 192 219 208 191 192 184 202 192 202 202 191 200 196 188 185 190 194 206 210 197 192 210 208 184 203 184 200 201 219 210 184 197 179 180 207 199 200 194 205 204 187 152 158 200 210 173 201 202 186 201 186 185 186 213 221 185 205 192 211 221 196 189 160 174 195 206 191 185 167 201 182 182 192 190 209 189 190 193 199 213 184 220 169 181 173 169 193 184 179 196 192 173 196 180 177 214 183 187 192 204 183 197 185 184 211 179 171 211 183 210 172 185 210 202 175 198 170 195 198 196 187 180 179 196 176 180 211 191 192 194 185 174 171 186 164 177 186 161 186 170 191 171 188 164 193 182 199 175 171 186 195 173 175 187 177 192 198 198 192 175 187 165 195 192 175 178 176 180 189 180 174 192 168 177 200 187 189 190 168 185 185 192 182 203 195 158 196 159 191 188 176 203 211 192 183 189 175 155 175 178 191 159 154 198 167 185 181 165 206 180 194 181 201 156 197 179 181 186 183 216 182 190 174 181 193 162 202 180 169 175 179 188 182 167 181 176 187 158 181 168 174 151 185 173 184 204 172 181 186 188 187 199 204 181 168 187 184 180 181 190 168 175 184 183 189 194 189 186 154 202 165 189 187 196 169 185 152 161 180 161 206 171 191 181 178 173 194 199 156 155 173 193 171 181 179 194 160 161 173 189 179 170 184 159 161 190 186 175 181 181 187 157 148 171 194 153 177 180 175 165 171 171 153 200 159 170 189 188 150 155 164 167 185 168 176 176 166 160 169 199 165 145 182 169 161 174 179 174 180 150 159 161 187 177 154 155 171 161 177 188 157 169 192 189 181 175 154 177 150 170 159 189 159 152 172 147 176 151 156 195 172 161 173 164 174 169 167 178 155 143 171 172 161 168 182 180 158 185 152 164 159 188 160 186 171 159 153 146 158 175 186 176 181 169 155 175 171 196 182 192 179 178 170 180 167 163 176 171 186 154 173 154 167 157 189 168 149 164 161 167 162 178 174 178 163 164 186 153 168 142 159 165 155 141 160 158 162 143 166 153 175 176 161 163 175 141 150 179 162 144 185 182 151 155 170 188 170 155 186 141 196 161 157 168 145 167 180 189 178 164 175 178 188 174 161 188 165 160 202 183 181 154 161 167 162 176 172 180 184 170 187 168 171 179 171 185 164 162 171 156 141 194 178 175 172 183 166 153 137 165 188 160 175 166 175 182 202 164 170 183 169 160 178 169 149 166 171 156 183 183 157 171 163 162 156 154 183 156 161 166 170 174 154 174 145 179 182 185 175 184 175 177 157 164 167 177 161 151 169 168 170 169 164 160 161 193 167 145 136 167 188 177 159 157 172 187 176 158 167 165 163 186 174 181 148 151 156 174 183 162 170 160 156 186 170 159 179 164 193 168 148 170 170 158 143 167 174 160 163 155 173 166 175 162 170 157 169 169 155 199 152 175 188 193 159 169 160 173 159 184 163 185 177 170 183 185 172 167 164 167 180 177 183 170 174 157 167 169 151 184 173 173 202 195 210 166 158 158 174 205 194 177 190 178 186 180 181 180 183 178 182 193 165 167 192 165 171 173 160 177 171 189 181 174 187 181 192 153 195 184 170 185 143 179 191 159 186 183 170 204 159 202 175 193 165 183 158 191 183 170 188 186 193 181 191 173 164 164 176 179 164 181 180 157 157 156 174 177 170 181 170 195 199 184 153 193 189 186 175 176 162 154 190 196 162 162 203 169 205 195 193 187 184 204 169 165 192 195 210 188 158 182 184 206 183 184 171 203 193 191 174 198 169 174 174 182 174 149 177 185 169 186 183 171 165 179 172 165 191 164 192 186 208 206 180 160 163 186 181 195 185 175 189 175 197 175 171 182 165 184 172 175 165 197 170 185 199 172 180 169 178 199 189 181 188 171 169 197 186 184 199 182 165 203 185 176 169 180 165 183 175 184 190 161 190 203 172 171 178 173 179 179 173 172 179 185 178 176 166 177 174 171 185 184 165 193 181 175 191 190 190 170 182 187 185 176 180 181 165 187 181 206 196 212 166 168 183 164 188 194 184 187 182 164 184 192 167 172 192 194 179 178 194 175 200 189 189 191 169 191 177 160 186 179 171 170 172 176 212 185 195 182 167 179 192 174 181 161 167 179 187 206 191 174 178 209 212 155 182 181 174 145 185 167 172 175 191 168 214 161 147 183 191 169 168 194 172 166 170 186 181 182 194 183 208 193 179 175 189 180 202 194 175 178 200 195 172 199 179 185 202 180 175 168 180 178 179 191 149 210 157 197 180 172 186 183 168 166 163 192 179 180 162 194 188 185 175 167 184 206 179 205 195 165 185 219 200 170 178 183 161 203 162 167 186 192 186 169 170 178 164 199 184 160 177 163 203 172 191 180 167 190 165 176 179 174 188 187 205 184 182 189 179 187 192 189 176 186 179 191 174 187 192 189 175 175 146 177 178 177 180 172 175 192 181 170 181 190 181 197 187 176 174 171 167 167 189 188 200 201 181 206 210 161 164 185 177 187 161 200 167 158 176 188 174 166 177 155 179 186 174 189 182 190 167 161 172 187 189 159 181 156 180 192 180 171 176 166 186 155 166 194 178 170 178 179 176 182 187 153 181 159 184 184 172 184 167 173 168 194 151 179 157 174 169 164 174 162 168 191 173 193 187 172 187 154 179 167 154 180 164 159 168 176 160 196 183 192 182 182 152 196 151 179 165 165 170 170 159 150 148 195 157 169 182 168 189 161 173 167 155 170 170 185 180 173 174 164 143 177 173 159 165 152 167 156 172 158 166 148 158 162 179 166 175 174 172 186 160 180 183 183 168 181 152 152 161 150 166 156 174 163 188 172 148 184 176 163 161 155 170 168 161 170 162 152 155 168 154 170 175 151 163 184 148 153 165 150 155 155 173 177 153 193 166 186 151 184 158 154 161 168 180 159 144 152 182 172 206 140 147 167 180 169 154 159 171 187 168 163 153 137 134 145 164 189 173 166 165 158 157 159 167 168 140 166 181 167 167 151 172 151 169 184 160 182 161 187 176 159 163 163 150 152 157 172 149 162 193 174 149 146 172 134 150 171 181 163 145 169 163 165 180 161 172 169 171 152 190 158 170 175 181 149 167 179 162 164 189 148 159 158 152 151 163 163 171 159 160 151 161 174 164 162 148 149 187 173 161 158 152 177 159 183 136 154 158 148 144 146 141 171 147 147 165 168 150 166 159 157 135 160 140 166 172 133 162 148 176 153 155 154 145 142 160 152 151 161 160 157 174 155 143 155 134 165 138 153 143 145 158 150 157 136 146 155 151 172 146 141 163 160 164 135 140 151 145 173 147 151 149 177 140 170 146 157 152 156 170 152 128 168 160 149 178 168 138 146 144 168 136 160 150 156 144 149 151 164 156 155 145 162 146 146 151 133 136 130 155 149 169 149 158 134 156 147 138 149 158 145 157 161 140 138 140 123 155 151 173 147 118 154 130 148 139 151 161 132 148 140 137 152 163 166 129 146 150 160 146 130 162 161 142 150 136 132 139 142 147 131 137 144 151 166 138 141 188 137 126 149 127 164 128 164 139 153 147 137 148 154 133 160 123 142 154 140 134 143 141 149 147 133 125 167 134 165 165 130 150 137 138 131 144 154 154 146 140 135 161 127 138 142 145 146 132 143 132 125 150 147 163 143 145 127 128 152 146 130 138 149 135 143 153 147 151 116 157 142 123 132 157 141 139 136 116 143 142 144 124 123 130 141 136 123 151 144 123 139 130 145 123 130 165 123 144 127 160 145 159 150 137 165 146 120 136 128 135 128 134 140 146 122 141 125 137 139 149 140 158 144 175 130 130 137 147 138 145 147 146 148 150 129 151 127 139 145 152 132 130 132 120 145 128 161 143 156 139 125 128 144 156 141 144 127 129 143 136 118 134 140 149 141 132 106 114 151 119 140 138 135 129 122 120 138 134 125 114 131 139 156 141 134 127 127 140 134 127 139 142 129 168 126 143 123 118 153 148 137 143 144 136 132 137 125 115 145 127 136 146 126 148 157 152 135 113 147 118 131 138 143 114 134 135 138 109 125 141 160 141 137 146 146 132 127 119 127 147 148 112 146 136 135 118 106 128 109 120 124 161 132 135 131 120 124 131 105 135 148 145 129 133 147 133 134 122 113 104 140 134 126 124 152 159 129 121 138 148 147 119 155 142 122 130 129 113 124 134 126 131 112 138 152 138 135 147 145 128 131 124 147 118 118 147 137 113 130 142 119 130 138 132 131 129 123 121 147 139 116 119 110 125 146 154 120 128 125 99 141 152 131 135 127 147 131 124 119 127 149 141 152 122 135 151 131 117 102 154 101 117 136 140 158 128 104 139 125 123 138 119 126 132 132 133 128 139 131 131 132 135 119 126 128 110 133 127 129 129 122 136 120 125 136 118 129 127 111 111 106 142 126 102 133 108 122 120 120 133 126 126 142 121 135 137 131 151 145 120 120 125 116 136 124 153 118 120 131 125 138 126 122 121 119 144 138 133 134 122 126 128 134 110 118 140 132 127 108 117 137 115 131 117 132 130 113 127 127 117 127 129 126 104 129 134 155 114 118 125 140 124 138 129 128 119 126 120 147 128 138 135 124 135 125 130 119 114 115 111 124 138 119 115 120 119 115 139 152 119 157 129 101 139 130 144 146 124 123 117 136 107 123 126 132 125 126 137 132 112 121 111 127 126 148 144 113 123 109 125 131 122 120 139 136 140 97 122 123 113 122 116 132 101 126 119 133 101 139 119 133 132 123 126 103 118 115 119 121 127 119 104 121 125 120 149 129 121 144 127 118 158 105 121 146 106 137 96 123 114 132 109 119 125 126 129 126 137 116 131 125 127 127 125 122 148 136 115 126 107 143 126 143 120 153 130 125 112 129 130 120 145 108 115 132 122 128 112 110 128 133 135 122 126 127 112 118 106 123 129 108 122 118 138 118 154 123 134 109 118 108 105 123 127 130 134 142 109 138 136 114 127 132 116 117 131 113 106 122 131 151 127 107 112 128 132 116 118 140 106 129 121 125 128 134 118 125 120 115 125 126 121 114 122 126 106 133 133 128 137 150 117 114 122 130 111 127 119 147 113 123 114 113 146 125 142 111 121 141 132 112 116 117 126 121 125 123 127 116 133 126 118 149 111 123 139 118 133 106 121 146 125 141 133 129 129 133 142 119 129 126 105 119 129 138 120 129 113 115 142 117 135 118 111 125 121 131 135 130 117 130 122 123 131 130 105 113 111 128 110 133 130 142 108 133 130 114 142 120 114 134 146 134 114 120 139 121 135 114 143 97 133 135 108 136 112 136 124 129 107 113 111 126 142 130 138 127 104 132 106 122 127 130 110 132 110 143 137 133 131 139 129 128 120 126 115 135 108 137 116 126 126 115 137 137 122 147 136 141 104 122 117 128 132 123 143 122 126 152 136 125 131 130 137 137 139 151 140 126 136 147 120 137 128 133 125 141 167 137 141 136 135 135 143 138 134 146 148 131 136 141 138 117 141 128 141 130 159 141 144 142 132 138 135 143 129 124 122 148 111 107 129 117 124 118 102 116 125 123 127 137 133 131 140 123 123 116 108 117 137 126 134 117 118 135 132 122 102 113 124 114 121 117 114 110 137 112 109 137 141 111 131 119 105 120 134 112 135 122 144 133 98 128 154 128 122 126 114 127 113 144 114 119 114 103 119 140 120 93 101 117 144 134 111 140 135 120 116 139 154 143 130 131 121 135 114 135 121 132 129 134 119 130 99 133 129 123 120 139 105 119 137 118 124 133 112 155 128 117 131 118 104 114 136 127 130 109 124 129 134 116 121 133 113 123 122 116 125 119 138 146 127 115 124 128 119 118 106 117 105 117 135 110 115 103 120 131 120 132 113 110 104 135 115 137 128 148 106 132 137 131 118 113 118 124 126 133 128 130 113 111 119 111 118 126 135 128 117 132 118 127 136 130 134 117 121 123 129 113 128 127 121 92 132 117 113 140 123 135 106 137 120 136 119 113 124 133 123 138 112 113 102 109 109 122 113 142 141 129 116 117 121 126 148 129 125 139 162 125 111 143 130 139 128 122 154 118 110 114 141 142 129 132 128 151 149 110 121 133 132 127 120 127 136 122 134 140 135 132 114 114 126 130 125 128 102 136 118 121 120 118 127 111 119 114 120 107 130 129 129 124 122 136 116 125 120 120 109 123 120 141 126 125 118 131 141 135 120 120 121 134 102 117 131 122 120 113 126 111 134 138 106 137 104 128 121 112 117 135 120 134 127 126 110 117 139 114 125 133 127 137 123 123 131 110 135 112 121 123 142 127 130 128 111 133 146 112 136 121 125 121 112 122 126 152 145 133 108 123 128 115 142 103 103 123 140 144 111 122 122 108 132 122 127 137 90 123 124 120 129 118 105 127 114 135 129 132 123 123 116 131 116 116 135 113 123 129 129 129 137 131 141 114 129 123 114 123 121 110 151 130 138 132 118 114 124 114 126 117 129 121 112 119 101 131 113 137 123 117 148 132 136 132 134 99 153 118 135 122 131 125 109 121 126 119 107 123 147 120 124 118 119 119 119 141 125 132 141 127 129 126 112 120 119 129 109 138 102 153 126 109 136 127 130 126 121 128 118 125 116 114 129 127 140 117 120 121 123 116 123 116 152 127 115 128 105 140 124 134 122 131 128 129 142 116 130 128 118 113 132 126 137 111 123 113 146 139 110 131 125 147 156 125 129 128 116 131 127 132 125 128 130 140 144 108 115 152 135 92 148 124 115 139 119 118 132 120 131 139 129 114 126 142 132 122 143 118 121 121 147 124 127 150 107 110 140 133 114 122 130 143 131 134 129 128 115 126 140 125 142 119 124 143 124 125 133 151 145 137 134 126 137 122 146 127 123 145 122 109 132 127 124 145 111 130 119 128 147 109 137 152 106 111 146 110 149 140 132 114 136 139 117 128 136 143 128 139 151 128 110 136 152 113 143 134 129 141 115 139 116 129 148 128 123 127 118 149 127 136 143 149 131 140 154 138 146 118 127 120 144 136 125 157 154 118 146 142 135 142 142 133 141 137 136 149 130 144 137 166 155 142 135 153 131 140 156 132 135 132 152 126 145 139 137 148 170 161 171 161 135 164 162 150 160 162 151 161 178 169 199 184 174 188 216 196 188 187 230 192 218 232 214 210 217 215 227 225 222 223 244 227 209 211 214 227 229 198 204 206 202 212 184 214 195 154 175 181 184 186 177 172 148 160 148 136 175 158 168 134 162 127 168 154 135 155 139 152 116 160 115 160 141 138 121 154 124 115 105 136 137 139 136 118 122 121 127 145 132 119 118 144 124 123 131 134 108 147 141 117 139 133 127 134 111 107 123 122 135 136 109 118 126 122 116 135 140 150 119 126 109 132 134 141 128 135 148 136 122 140 123 135 142 144 128 125 126 126 118 130 123 122 132 91 113 122 126 107 133 127 127 118 155 121 119 128 120 124 132 135 121 108 127 127 97 118 137 132 124 149 123 119 134 114 120 139 125 128 115 134 105 116 127 131 115 118 133 118 122 104 117 159 131 150 116 132 121 132 120 138 111 107 125 100 101 125 123 132 122 132 125 127 128 136 121 134 150 132 122 114 131 154 152 107 123 126 108 125 111 106 133 110 132 153 122 149 145 132 139 137 128 133 105 147 118 116 128 146 145 142 127 124 125 126 136 138 114 135 123 122 140 120 116 119 124 131 122 139 118 130 132 129 107 142 134 121 116 141 110 125 96 141 123 111 139 128 118 127 111 113 128 113 123 111 143 123 120 110 126 122 118 129 128 115 120 142 113 140 128 127 146 128 146 117 127 132 124 163 125 139 128 129 132 123 121 111 131 126 132 121 137 123 121 109 126 120 122 122 123 111 122 126 146 115 137 108 122 125 110 117 119 123 115 105 132 149 129 133 117 138 108 103 138 135 118 111 115 141 128 118 132 144 152 139 135 125 116 135 129 124 132 104 137 153 150 132 139 121 130 135 114 117 114 97 107 128 109 128 120 132 130 115 126 126 127 127 128 118 124 101 140 124 132 109 122 140 130 112 111 130 134 106 128 129 129 119 124 122 135 130 108 101 132 112 134 131 141 117 124 106 129 109 117 108 125 129 149 111 124 132 131 136 107 116 137 130 122 108 124 123 138 122 108 133 149 120 111 117 118 126 121 122 111 112 136 137 118 127 108 108 124 121 140 124 127 118 127 130 111 117 127 110 133 137 120 113 108 120 135 131 129 120 123 123 133 126 140 140 114 133 111 130 113 125 144 138 114 132 100 103 117 132 117 144 106 118 99 126 144 149 121 131 118 119 136 123 119 154 121 119 123 136 122 120 132 115 119 141 136 135 106 139 136 122 140 109 128 121 129 129 133 121 118 122 130 126 117 126 117 116 132 119 125 125 109 107 134 103 125 135 122 127 128 126 125 140 116 134 138 116 127 121 131 116 123 116 122 123 124 142 134 109 119 123 141 121 109 105 123 130 128 112 127 125 121 143 127 128 126 106 125 119 120 129 105 102 113 122 119 129 121 121 119 118 125 114 133 136 117 113 113 129 127 109 131 123 140 120 120 137 117 93 147 129 120 131 126 115 118 129 119 128 137 107 126 126 135 117 123 125 123 118 112 131 126 119 110 120 131 135 131 142 127 126 133 127 123 109 120 141 125 133 121 121 127 94 133 128 120 130 118 109 134 113 133 127 135 119 136 117 141 132 121 121 118 139 133 125 139 132 135 119 136 134 128 125 107 133 108 124 111 150 124 119 116 106 118 119 134 114 132 115 119 120 111 121 116 105 123 114 111 112 113 131 117 116 129 121 125 134 140 122 118 118 117 140 107 133 119 124 122 121 118 110 123 120 123 117 135 118 121 106 129 125 126 137 137 124 140 116 114 133 113 112 134 129 135 110 131 122 123 122 115 110 116 128 117 111 135 143 111 135 132 134 132 129 118 125 116 118 139 118 124 132 99 139 109 110 120 107 137 130 132 127 124 136 128 122 139 129 128 129 106 134 126 113 123 132 131 118 130 125 107 110 120 132 135 134 125 122 121 122 138 127 120 110 129 114 114 125 123 123 154 104 131 120 131 129 134 119 119 134 124 137 116 112 132 134 117 143 127 126 128 116 141 130 120 112 127 111 135 124 116 130 135 127 129 136 150 119 117 128 124 142 125 110 122 130 121 133 131 118 119 121 133 117 109 132 122 122 147 129 135 113 124 109 122 122 138 121 103 131 122 108 113 123 132 109 124 116 112 129 101 140 122 146 118 136 119 118 124 126 132 131 118 108 117 127 119 131 109 120 111 125 135 118 131 115 127 142 137 123 140 146 126 126 108 114 140 104 106 106 134 121 136 113 111 137 111 123 145 115 144 117 105 111 129 126 115 127 119 106 97 124 146 104 136 121 126 127 126 131 118 131 137 107 134 125 127 118 133 132 114 118 117 95 117 131 122 116 108 123 123 108 121 147 114 108 108 123 119 120 125 127 135 133 116 112 120 124 112 122 139 119 111 123 117 120 128 127 99 119 109 129 117 148 130 118 113 145 111 128 129 138 127 120 139 119 119 138 119 124 132 112 140 122 132 102 115 130 109 110 120 106 146 126 119 141 134 117 122 144 102 122 127 121 113 131 156 139 127 116 98 108 134 124 117 133 122 137 116 105 109 117 142 128 149 119 125 124 146 140 136 134 125 104 120 114 105 132 128 134 111 135 99 114 106 127 125 121 126 120 148 128 127 126 131 111 129 119 135 130 131 143 114 137 122 107 122 121 127 126 135 112 118 127 120 140 133 139 155 143 124 89 129 97 137 113 127 121 148 135 117 125 133 111 130 122 127 118 125 118 142 132 111 144 141 137 121 125 124 123 136 133 120 123 130 132 122 129 141 140 131 109 130 118 123 123 111 125 117 125 123 132 128 131 128 110 107 124 110 112 123 117 124 110 122 122 137 132 135 113 120 135 106 133 139 130 131 126 129 125 123 132 150 124 122 129 134 129 112 120 128 119 132 106 133 131 137 103 121 139 141 136 99 140 132 143 135 108 110 137 135 128 121 131 134 132 116 127 121 118 133 141 125 147 116 109 150 120 128 134 132 131 133 117 130 139 120 134 129 126 122 132 110 139 134 103 124 109 142 128 122 128 132 131 129 124 131 131 119 124 139 122 123 128 124 128 121 129 142 123 123 138 115 119 148 112 116 141 115 139 129 109 139 142 107 129 117 135 112 105 136 123 125 113 131 104 142 112 121 125 140 123 121 118 122 133 136 117 138 126 108 129 137 123 130 121 131 127 118 131 135 142 129 133 130 114 126 127 129 141 128 122 123 118 127 120 121 146 117 113 141 110 135 122 138 119 140 148 138 109 122 114 136 134 152 132 155 136 145 98 123 135 135 106 130 117 137 117 124 126 126 125 125 124 122 118 121 135 130 131 139 147 138 143 132 129 119 134 122 124 151 119 116 134 127 123 123 113 144 124 121 136 103 132 138 107 123 151 134 125 116 126 128 137 140 132 133 139 128 113 131 129 126 117 132 129 123 125 126 144 130 134 103 133 130 121 144 134 143 116 135 133 116 125 115 140 131 131 137 124 121 125 130 115 148 119 158 120 143 127 138 127 135 153 108 134 145 142 150 136 135 119 118 115 125 138 123 123 132 135 136 132 165 112 146 110 141 147 132 131 134 132 138 121 125 138 121 119 121 138 101 119 129 136 155 145 128 127 148 123 140 106 138 108 131 112 126 130 126 142 119 120 153 132 134 145 155 134 125 137 137 124 140 126 127 130 120 124 133 129 134 156 132 144 139 145 128 117 132 140 139 132 125 138 122 145 125 117 140 125 97 121 128 163 141 108 120 120 126 132 149 114 125 130 107 120 112 129 126 124 113 129 135 135 130 126 143 148 134 141 115 131 128 119 122 127 133 145 119 128 129 113 120 120 131 130 127 131 112 110 138 120 116 154 127 148 147 136 135 129 136 114 134 139 123 130 127 121 134 147 135 127 99 125 146 150 134 147 145 146 134 136 136 135 148 139 140 133 120 124 129 128 146 107 130 140 108 126 128 136 105 113 122 125 110 132 128 123 116 137 122 162 135 131 139 136 127 138 127 130 126 125 118 123 122 158 117 143 120 153 125 135 126 108 106 144 124 142 152 119 131 109 147 138 135 144 130 134 131 124 137 116 139 124 144 137 136 124 120 129 119 106 123 131 134 138 156 140 145 142 128 129 131 127 126 158 143 144 132 144 140 123 135 140 150 110 107 134 149 137 145 143 141 120 138 126 100 128 108 114 118 130 107 131 146 148 129 132 137 134 147 154 129 119 140 125 129 129 117 136 109 118 124 119 134 122 123 135 123 133 141 119 146 144 126 147 118 128 133 137 121 131 131 118 129 138 129 142 165 120 125 133 141 115 130 115 131 154 140 138 134 139 142 133 140 139 136 117 124 132 131 127 126 142 149 128 127 136 156 130 96 139 139 126 136 126 141 133 133 141 116 138 122 132 142 139 139 120 136 130 142 134 120 131 141 136 118 145 120 128 107 139 134 135 143 144 128 123 144 125 103 122 133 114 148 135 122 133 138 141 134 127 134 135 128 131 123 126 126 131 106 116 128 132 126 134 150 134 118 139 125 144 118 153 118 127 140 138 113 120 140 163 146 158 137 138 147 146 114 129 157 128 129 120 135 135 148 132 125 136 135 120 129 125 151 121 129 127 137 152 155 134 140 131 146 143 152 129 143 152 111 124 125 139 142 142 130 123 135 130 152 145 117 144 132 147 138 147 124 153 139 137 130 153 142 117 132 120 140 144 143 132 131 125 147 133 115 132 106 135 150 134 134 157 119 132 132 141 154 162 166 148 140 138 136 136 145 126 128 145 151 162 123 122 143 152 134 136 131 135 144 137 144 159 123 131 146 141 150 119 143 144 140 154 150 151 134 127 113 151 147 159 131 136 137 121 137 142 154 131 126 148 134 122 123 125 148 145 151 157 119 146 137 142 136 138 123 141 142 128 131 146 148 140 127 125 143 162 118 125 163 132 124 135 136 114 150 126 123 124 150 133 136 126 130 135 143 151 137 159 112 135 135 133 152 122 118 133 133 137 146 153 148 137 146 130 140 136 153 130 140 127 123 136 131 167 128 147 114 137 142 129 128 133 152 123 129 134 121 137 137 127 135 149 141 140 137 126 145 142 147 145 135 131 143 141 134 130 128 107 135 149 146 114 155 123 123 136 142 128 113 134 137 118 142 134 114 116 144 136 112 145 141 135 124 134 153 132 125 123 129 128 158 138 160 130 136 129 119 113 133 127 143 131 143 136 122 114 137 146 117 138 112 129 158 135 118 147 136 134 121 137 146 150 121 144 140 136 133 142 120 131 137 126 160 136 130 127 139 134 126 128 129 122 134 120 133 142 153 135 131 128 132 138 128 145 119 149 142 140 114 125 131 152 127 127 156 144 142 112 121 119 168 146 150 150 149 129 129 131 122 115 110 134 126 133 123 128 157 139 142 141 122 156 110 149 144 142 132 135 136 148 143 130 127 147 136 162 141 145 134 134 118 128 153 163 129 132 146 135 123 127 126 124 131 145 147 135 125 154 127 122 138 123 120 140 133 140 129 130 135 162 119 155 117 112 137 139 120 128 147 136 138 134 147 143 126 149 114 133 121 151 127 133 139 136 143 140 154 130 134 141 137 132 136 141 137 146 154 146 133 115 126 138 125 140 114 139 126 126 144 125 124 131 115 140 109 150 142 139 122 135 119 132 135 151 128 142 138 117 150 145 130 112 135 139 140 120 139 134 142 138 145 130 121 118 143 141 140 124 131 163 132 179 151 130 126 160 130 134 123 113 143 128 138 126 146 135 123 131 131 142 131 118 139 141 139 147 115 136 139 137 134 137 132 135 141 133 142 128 119 135 137 116 138 159 129 138 129 113 144 124 115 131 151 111 137 129 120 146 124 146 154 133 144 148 141 140 131 111 150 155 154 130 123 143 125 134 147 142 147 141 145 149 151 103 136 128 132 154 126 124 125 137 135 121 138 146 136 129 119 154 151 139 138 131 132 144 119 132 143 122 129 114 124 137 138 113 138 138 141 134 122 125 140 146 124 121 118 124 126 134 142 117 134 130 129 133 128 126 141 140 124 129 141 130 150 142 131 156 131 136 128 123 129 127 130 140 117 142 138 124 137 126 157 142 154 122 141 124 124 155 149 132 136 141 144 126 147 148 146 157 113 147 118 120 126 140 135 106 136 134 141 149 141 117 143 134 128 138 144 137 128 113 145 146 154 112 142 134 147 149 121 135 137 130 147 145 134 138 141 113 122 130 126 125 124 143 138 141 134 115 120 135 136 116 130 122 113 147 129 134 120 120 115 148 146 131 135 143 140 133 134 141 121 123 145 131 131 164 151 135 133 124 153 108 130 129 138 134 130 139 132 144 130 155 107 156 145 141 176 117 136 137 136 137 124 171 151 143 117 125 142 134 148 111 136 141 128 128 141 155 138 139 126 143 135 139 139 151 142 137 142 155 145 157 119 131 135 130 151 127 135 127 118 141 140 120 136 147 135 117 133 131 117 141 137 130 127 130 124 145 146 124 142 144 138 122 152 114 150 126 142 131 130 128 142 144 131 132 143 154 137 135 122 124 140 151 142 147 143 133 115 165 144 126 138 137 141 135 127 136 141 146 125 130 130 128 130 142 134 142 127 140 134 161 128 135 134 122 130 146 145 129 128 136 139 131 145 120 134 132 119 137 133 136 133 118 127 144 139 120 144 123 122 157 139 134 133 152 127 142 131 139 132 120 134 131 141 149 129 138 143 143 126 149 131 151 143 150 136 126 130 134 138 128 153 126 126 148 141 144 142 156 159 152 138 139 129 127 132 129 143 148 136 135 140 149 153 141 136 133 131 120 123 126 138 118 110 137 127 149 127 126 154 123 114 124 135 108 139 124 141 136 140 137 122 138 150 129 133 123 125 124 143 140 145 132 149 115 123 149 122 127 133 130 150 125 136 129 140 159 157 149 141 128 140 137 129 158 123 124 127 140 137 136 128 139 129 153 146 144 160 130 146 134 144 128 154 150 126 117 136 128 135 140 134 122 126 147 130 126 131 142 117 155 138 130 128 121 147 148 123 129 142 131 143 129 137 111 120 153 140 121 134 121 130 142 149 137 119 137 149 161 129 140 135 147 157 122 156 161 134 167 136 125 112 130 140 146 130 130 129 139 159 132 132 143 118 134 120 131 158 126 139 133 137 129 134 158 124 150 139 133 123 146 147 154 124 153 132 146 145 136 144 154 141 144 172 143 139 137 123 151 156 121 131 147 139 131 150 137 153 153 139 130 112 136 130 141 151 145 140 154 146 124 128 121 111 123 130 123 129 121 107 148 140 146 140 143 139 137 117 157 146 123 143 135 167 159 122 155 119 125 133 125 133 130 150 158 150 130 131 143 141 147 129 149 120 156 135 137 153 148 135 139 150 130 150 136 147 140 128 133 144 115 128 123 157 140 127 120 137 138 137 142 146 127 142 125 133 150 143 134 107 132 171 143 149 135 133 136 123 158 137 148 130 154 135 164 144 144 115 130 162 125 142 138 150 126 123 133 149 140 135 138 143 153 139 131 140 145 123 158 135 136 125 132 143 134 127 131 152 150 134 148 139 126 142 143 139 130 127 142 132 132 130 147 141 143 141 151 148 134 132 121 143 134 128 147 126 130 133 159 126 145 135 142 145 142 147 128 132 155 139 147 161 156 141 122 144 137 126 153 146 137 117 134 140 135 157 143 145 126 147 141 143 141 143 142 135 125 132 133 141 122 150 135 131 145 161 143 146 121 144 154 134 155 131 130 133 141 118 136 131 127 153 151 126 131 134 142 140 122 107 135 122 152 148 139 166 138 119 143 144 137 134 145 139 151 110 143 148 141 123 120 129 132 132 149 160 153 148 124 129 136 140 124 133 121 131 130 125 131 136 114 157 141 123 119 142 129 129 139 138 130 149 129 151 144 144 130 150 142 147 147 129 110 135 132 138 131 134 153 142 149 141 124 141 131 142 153 137 135 138 113 135 146 146 155 132 156 137 125 148 139 127 140 144 135 150 143 130 134 157 130 147 134 126 148 132 129 136 147 131 161 126 161 152 137 130 138 138 127 136 128 131 155 124 150 151 130 122 140 127 112 142 135 139 142 148 144 121 112 149 155 123 149 164 161 130 123 136 145 140 113 142 151 150 135 124 134 146 124 144 125 129 152 130 151 135 168 129 151 119 151 161 132 152 148 126 141 119 143 150 148 155 146 146 125 136 139 134 131 133 131 138 143 130 126 146 148 136 118 132 134 145 152 141 134 156 119 144 130 140 138 151 148 145 163 124 131 124 143 145 140 139 126 146 143 138 148 134 149 155 134 132 141 145 138 148 166 133 122 120 125 154 149 130 167 145 137 154 157 127 143 150 149 159 132 130 144 147 136 142 115 147 144 144 129 135 146 132 152 127 145 164 142 143 141 133 133 138 122 137 143 161 121 136 127 142 150 144 150 150 145 146 128 147 137 145 140 154 132 164 125 165 136 140 158 147 134 144 146 133 162 140 142 123 137 138 122 156 136 149 150 155 127 138 149 139 154 146 137 131 135 142 116 146 138 139 137 157 158 133 138 145 143 150 136 131 121 140 141 140 164 162 145 146 119 133 152 123 120 144 129 137 164 147 129 141 140 151 149 157 155 148 144 123 134 155 169 168 128 147 140 147 148 159 154 148 136 127 160 140 142 151 158 151 154 140 146 175 160 162 157 148 170 157 157 151 168 172 173 169 163 161 146 158 152 151 172 153 150 164 155 158 164 115 156 176 152 159 161 172 159 158 140 158 149 140 131 169 151 144 148 163 136 151 147 149 150 156 159 146 144 141 179 136 151 131 160 150 169 172 154 158 148 147 153 145 135 161 133 174 149 144 154 140 143 126 140 148 160 152 152 142 158 131 146 138 161 135 152 159 131 154 139 141 145 155 125 145 141 143 134 140 134 142 164 150 163 153 135 122 158 143 145 167 145 153 136 156 159 138 136 139 129 142 143 131 148 136 129 163 140 142 149 130 134 134 126 122 151 171 122 130 128 140 125 146 138 157 135 136 147 116 144 141 127 154 121 140 132 164 130 131 141 125 145 157 139 134 145 147 126 150 134 112 145 145 138 155 143 135 145 130 137 149 154 141 144 145 142 179 152 150 139 137 117 130 130 127 161 135 138 138 124 164 146 133 132 142 143 126 132 165 141 147 127 129 128 124 138 141 150 138 123 133 139 150 138 137 164 124 134 122 145 165 136 138 145 132 125 145 153 133 137 155 153 144 138 134 142 132 129 147 139 149 128 117 115 136 134 135 130 138 131 138 145 138 125 157 136 150 154 132 148 129 131 136 127 136 118 120 146 139 139 139 136 136 117 158 133 153 125 144 143 153 120 127 121 129 135 139 145 137 132 144 142 134 151 121 125 132 136 145 143 155 132 136 142 133 157 138 122 141 143 136 129 128 150 126 120 128 132 135 160 138 155 134 139 157 167 139 132 140 148 141 134 154 145 136 144 117 143 113 147 122 143 152 153 145 137 144 128 144 147 137 150 135 153 139 142 140 127 125 149 134 120 131 132 136 141 137 140 130 129 156 155 136 114 145 137 122 136 144 151 121 140 155 118 115 130 141 140 134 120 117 143 131 125 153 118 140 135 153 137 129 121 120 138 117 153 123 145 125 120 127 137 128 149 127 120 163 135 118 137 138 149 131 103 128 126 134 136 140 137 136 164 129 137 171 143 122 144 143 125 132 139 131 145 124 126 134 135 137 127 143 141 140 148 112 144 116 128 132 126 142 140 130 126 138 126 140 150 125 144 146 137 118 153 138 147 144 135 132 131 153 142 139 142 139 122 136 129 126 130 135 141 130 138 134 137 120 138 137 140 137 135 133 129 113 157 149 120 128 143 125 144 126 145 131 120 118 163 135 136 169 129 129 133 132 131 131 128 127 129 124 118 149 122 140 141 172 138 140 128 134 145 136 135 122 144 126 114 134 131 148 141 154 157 127 142 109 110 154 153 144 146 116 109 143 155 124 137 128 133 144 127 137 158 125 128 139 144 130 137 122 131 140 147 145 133 154 129 148 128 144 158 137 119 140 105 133 118 135 120 152 120 115 149 151 132 144 150 146 150 121 125 151 129 121 142 126 142 132 149 127 157 132 144 141 126 146 149 132 141 148 128 150 175 136 141 121 139 144 127 127 139 152 143 176 135 133 142 133 138 137 136 118 137 154 132 130 116 136 136 139 138 154 144 119 158 128 147 134 140 134 134 132 143 157 140 144 134 142 127 131 124 122 131 111 133 108 138 132 131 136 154 140 135 142 135 132 129 144 119 152 132 132 117 140 117 121 141 126 134 134 150 119 144 132 129 124 124 153 136 146 152 138 148 131 173 139 121 143 146 120 145 134 160 143 132 153 137 135 142 148 132 140 150 130 133 158 155 142 136 124 147 130 141 146 117 120 143 133 147 149 129 152 142 145 162 136 176 146 129 133 131 145 133 135 127 147 121 128 126 146 140 134 136 137 162 146 126 129 139 142 127 136 125 148 127 136 146 127 131 108 113 128 142 121 136 134 129 143 149 118 138 142 140 147 165 135 118 139 115 155 142 144 145 153 136 140 129 142 136 125 142 147 158 127 130 117 138 134 141 130 137 129 142 121 153 151 133 142 124 141 130 140 129 141 150 147 140 145 153 128 153 118 137 132 140 134 144 138 128 136 135 134 138 122 133 147 138 131 151 165 129 108 162 138 163 117 143 134 131 122 143 123 136 113 154 128 134 144 135 128 125 164 158 128 103 141 137 139 150 131 136 149 133 133 147 110 134 126 125 164 148 149 129 142 144 152 128 140 131 129 134 122 129 115 128 142 130 150 133 122 149 141 138 128 125 137 139 139 135 136 153 149 132 146 139 119 118 137 135 142 147 171 158 152 119 133 145 125 134 143 130 152 137 125 112 152 135 135 134 113 142 148 139 158 116 145 142 130 133 142 135 136 141 135 143 127 140 140 132 141 120 158 133 136 149 160 144 122 151 132 145 137 144 143 146 141 152 152 143 138 160 134 135 130 122 155 129 148 136 131 124 129 147 136 143 158 129 137 142 137 142 145 137 113 121 138 172 119 134 128 153 121 147 127 126 144 129 114 135 129 129 138 133 134 123 132 135 139 147 158 125 145 161 129 162 131 110 124 143 159 128 148 130 149 149 128 127 133 120 131 147 126 138 148 139 133 115 135 157 141 120 143 133 139 124 123 164 136 153 154 133 127 143 125 137 139 128 148 145 143 143 150 134 132 127 149 137 156 133 118 133 134 120 149 120 156 160 118 131 139 147 134 143 164 125 155 151 129 156 118 136 136 132 141 121 129 139 142 145 137 139 132 124 129 134 127 152 148 137 155 145 162 118 116 114 150 118 145 131 131 127 134 165 141 152 136 133 130 111 131 145 128 128 140 135 127 124 144 149 141 132 130 144 126 108 148 153 142 130 132 139 144 145 131 132 125 142 151 119 123 136 130 138 114 131 147 141 147 159 130 126 144 150 128 118 138 140 118 147 138 132 124 134 142 140 124 132 137 134 132 145 159 146 139 144 159 149 130 132 134 144 142 122 110 123 137 127 123 151 144 147 134 136 109 146 155 116 119 131 139 119 161 124 142 130 129 153 135 114 146 130 153 128 119 134 128 126 150 146 135 141 123 143 151 146 140 134 144 133 137 142 107 151 133 145 127 121 149 136 124 132 127 141 126 126 131 146 139 133 156 132 134 139 152 150 143 140 118 126 141 137 113 140 122 143 138 130 127 116 134 157 125 116 141 138 156 143 119 139 166 159 160 143 135 151 132 127 140 138 140 139 134 140 136 127 144 152 133 160 138 131 137 128 158 119 117 132 141 142 135 125 126 132 129 136 116 140 127 124 128 131 134 134 158 142 132 149 133 144 134 138 137 141 137 142 129 136 133 137 148 165 137 150 134 157 124 160 130 130 155 125 133 131 127 130 146 143 138 107 130 125 126 157 159 128 113 123 144 135 133 148 144 138 140 131 144 134 129 137 112 143 142 140 124 143 125 145 126 125 140 135 128 130 129 139 123 138 131 128 144 127 138 136 142 135 138 131 161 123 121 136 142 147 146 133 112 141 146 144 149 137 133 164 144 151 157 147 134 138 110 130 134 150 127 147 133 148 134 132 153 135 147 117 142 121 143 136 119 138 134 144 165 121 133 159 126 116 158 124 131 129 138 130 130 145 111 136 123 165 139 133 127 141 122 139 166 121 120 132 143 110 139 132 134 140 128 134 166 135 147 135 150 129 146 146 138 151 149 150 152 132 133 121 131 132 149 133 132 155 131 144 128 125 120 151 138 120 123 146 153 141 130 147 132 158 135 123 117 123 126 126 156 150 149 125 136 146 143 136 126 140 127 160 126 124 119 119 137 149 132 139 139 131 147 153 160 144 160 152 155 127 136 149 150 126 125 156 135 133 146 140 121 142 138 151 116 134 137 140 135 143 140 126 149 133 145 155 155 153 139 116 154 132 125 157 150 154 124 127 151 146 152 143 134 161 134 155 147 158 151 154 142 144 125 131 147 140 113 148 150 167 127 163 147 144 162 134 137 155 142 124 145 143 155 132 135 140 135 147 151 130 145 121 152 148 149 143 135 116 159 140 130 131 157 137 147 152 142 144 132 143 133 132 154 135 129 143 144 131 139 145 135 156 136 138 136 136 119 130 123 137 134 156 133 117 127 140 150 137 136 173 131 133 138 138 130 121 125 138 134 144 137 120 142 146 156 132 136 149 132 148 130 126 144 136 155 136 141 173 143 117 141 152 139 148 124 158 133 131 128 126 140 138 118 124 140 149 132 113 146 120 137 134 139 141 124 181 124 136 157 148 139 114 139 140 114 126 123 127 123 118 136 142 137 130 144 138 133 127 153 132 129 127 140 153 115 160 151 146 132 141 140 134 134 139 150 162 162 153 135 135 138 142 142 152 121 145 146 116 123 138 151 144 128 130 145 141 148 136 135 135 137 118 133 137 127 137 122 138 139 143 114 119 144 127 138 137 140 142 152 154 156 128 142 147 148 105 134 152 149 147 127 118 133 151 122 156 136 161 144 128 148 147 141 114 130 141 141 161 169 131 109 142 140 141 151 140 108 142 121 150 138 132 134 135 135 139 136 123 125 159 139 146 129 127 143 118 123 124 132 142 146 118 131 129 150 140 119 151 138 135 138 164 140 119 137 124 126 142 150 140 123 149 131 150 139 133 157 133 151 141 126 135 140 149 162 131 124 123 137 135 141 132 135 136 125 151 127 120 145 142 156 123 122 118 135 140 128 127 136 137 124 132 132 126 133 127 154 121 127 137 128 138 126 141 126 130 139 144 159 131 149 128 158 124 138 142 118 149 142 137 128 152 114 130 134 124 126 132 142 123 135 115 147 128 124 143 135 129 133 124 131 138 141 143 151 147 148 132 124 144 135 151 138 140 153 146 147 125 132 146 145 133 139 137 146 131 135 137 142 143 128 136 136 145 112 120 116 134 136 131 140 146 142 141 143 135 157 134 123 151 137 149 134 111 126 127 133 123 132 131 135 159 139 113 116 127 129 122 121 135 144 128 134 154 138 127 130 124 131 112 129 131 147 125 135 126 143 134 128 135 113 150 144 124 120 127 136 148 164 124 126 144 159 141 140 119 143 141 152 129 126 136 121 135 136 146 114 155 123 124 157 122 120 124 122 143 136 153 143 143 142 131 127 137 130 134 135 126 125 135 147 143 132 146 132 138 127 152 130 143 140 118 144 133 153 150 132 122 139 132 136 148 118 133 137 142 137 157 162 143 126 146 146 131 128 135 111 137 149 133 127 140 135 128 137 149 129 144 130 162 120 161 125 142 138 130 144 125 125 134 142 129 134 144 125 133 136 117 128 155 126 150 126 157 129 130 144 117 123 142 129 125 140 157 140 135 155 132 140 132 138 148 129 121 144 134 128 135 137 148 136 139 138 124 130 141 141 129 132 136 171 143 134 144 123 134 120 145 128 149 141 145 144 153 118 123 156 111 121 133 126 132 142 139 127 155 124 135 128 132 132 132 134 162 138 145 133 111 151 121 147 132 133 166 123 125 122 130 134 143 131 143 147 129 132 118 130 142 155 129 136 134 131 138 130 142 132 144 131 133 143 119 140 120 137 142 140 143 120 140 158 140 143 139 144 151 136 144 120 114 144 139 130 126 149 129 139 129 134 136 139 130 148 132 135 145 142 139 158 152 148 114 148 112 134 145 151 149 124 146 143 123 133 141 121 128 136 139 125 135 124 147 141 138 139 128 148 140 145 143 132 116 139 139 124 150 126 129 138 137 107 148 151 121 133 142 162 139 149 157 126 153 134 128 126 131 135 139 123 130 162 138 138 142 136 112 127 110 132 123 130 144 133 138 129 145 120 146 125 133 122 154 127 148 120 127 138 152 142 130 130 147 133 150 133 133 145 145 137 110 129 116 150 145 138 140 136 122 142 133 127 141 145 135 147 158 123 144 130 141 131 140 127 136 124 164 124 133 136 143 158 120 147 133 121 136 126 141 138 145 123 143 119 129 137 140 115 135 115 136 116 154 130 141 121 131 125 129 149 110 140 130 158 132 147 130 138 145 155 135 133 137 152 144 134 134 137 130 130 160 139 130 150 123 142 170 131 138 138 127 129 131 126 144 146 115 141 155 127 142 140 113 136 118 129 131 142 147 147 121 144 124 130 130 136 146 129 148 139 141 122 141 158 136 127 129 135 132 121 137 129 135 143 123 135 138 126 149 130 137 143 122 117 156 149 144 152 147 111 136 126 129 140 119 141 148 143 127 133 127 149 141 153 138 137 144 137 129 143 146 141 137 130 122 128 140 106 152 153 145 130 138 139 137 131 127 123 129 136 135 122 124 142 124 136 128 135 141 122 125 141 143 130 143 131 137 143 133 130 136 127 128 142 125 137 147 142 150 143 147 133 120 133 149 141 132 143 140 122 137 136 148 144 134 119 148 143 158 156 135 120 140 160 149 132 149 141 140 123 146 152 138 120 138 129 138 124 139 128 149 136 164 118 129 135 119 132 140 129 141 116 122 127 133 127 145 118 145 156 141 134 131 142 124 151 122 125 132 129 140 160 127 135 129 127 153 147 134 130 121 124 129 148 129 164 151 145 163 124 124 123 143 128 129 140 147 125 133 122 115 130 137 137 127 151 110 135 137 120 132 130 114 134 123 148 131 139 131 135 129 141 131 130 143 129 101 128 115 146 139 127 136 138 137 122 148 157 136 132 136 129 122 154 128 131 150 134 151 138 136 147 137 117 107 127 120 156 139 143 118 151 132 145 127 139 133 129 128 127 123 142 132 118 108 133 116 146 140 119 131 137 117 132 133 133 117 141 128 131 153 112 133 146 117 132 132 125 139 127 143 127 137 125 134 121 115 116 141 102 131 134 128 131 111 144 139 107 133 152 111 138 132 137 131 143 148 135 115 137 127 135 166 159 133 105 130 137 120 148 131 147 141 125 116 113 119 138 144 155 134 156 127 128 146 138 138 128 133 138 139 129 128 139 127 122 135 128 145 124 133 156 133 131 123 137 144 141 140 126 124 135 124 139 137 137 125 153 139 129 137 126 129 137 128 118 142 127 115 143 146 141 156 141 147 120 117 126 141 141 128 117 142 135 132 124 123 155 135 140 145 124 114 134 135 126 137 142 164 129 143 120 114 127 145 125 138 134 141 134 118 131 147 129 126 142 122 122 134 126 132 127 117 136 143 132 140 153 127 137 135 132 135 136 122 103 138 129 149 125 135 143 140 142 117 124 136 124 140 146 136 146 176 122 136 128 103 149 155 140 162 118 131 120 109 137 133 130 119 141 138 140 124 135 110 128 140 160 149 139 133 146 143 145 115 140 127 145 125 126 144 135 146 134 145 131 141 127 136 131 134 137 131 128 128 130 135 126 154 122 152 133 121 113 127 140 137 140 134 132 106 147 129 107 128 146 138 138 133 132 128 134 154 138 130 131 124 151 138 129 125 127 124 131 140 133 111 130 120 135 136 128 139 132 122 149 118 152 148 127 118 116 120 133 135 137 129 145 130 139 134 128 119 139 143 118 138 151 136 139 134 142 133 133 135 131 119 137 123 143 123 134 122 133 120 144 121 134 122 112 131 141 118 144 132 114 135 113 126 111 118 127 105 124 141 114 129 131 120 132 130 136 127 136 139 128 136 113 114 135 124 122 141 126 139 115 155 106 123 112 139 115 116 131 129 146 123 126 104 150 121 125 132 135 145 135 130 151 133 136 112 136 160 127 140 132 116 141 129 138 127 140 137 131 125 137 101 137 120 146 147 130 139 140 116 114 140 143 123 133 130 144 128 128 148 119 121 115 146 136 118 156 133 141 154 123 144 125 129 150 135 120 109 125 128 137 115 119 134 125 142 132 144 127 127 127 127 138 139 137 134 144 149 131 155 136 148 143 122 118 129 142 140 117 120 153 157 168 130 145 163 149 144 108 129 136 145 130 140 150 144 137 126 129 171 155 126 141 141 145 122 132 158 121 137 137 146 139 142 142 137 123 140 123 128 131 140 133 129 129 130 134 150 138 132 135 125 145 136 139 154 142 134 121 137 157 131 141 153 122 110 129 112 141 131 121 123 127 150 144 122 133 130 120 129 127 131 125 138 107 134 128 126 121 126 145 136 138 117 133 149 138 137 139 160 144 136 129 130 158 140 123 136 124 127 124 135 144 141 122 142 125 120 130 147 134 141 129 138 117 142 133 129 134 118 123 125 126 124 134 136 131 121 130 149 144 122 133 131 126 121 131 129 137 120 133 107 123 130 111 139 128 124 115 126 124 153 123 103 131 135 131 135 117 127 129 130 133 119 135 137 138 142 131 109 124 132 131 119 133 124 110 138 143 113 134 136 126 132 135 117 139 139 143 134 124 128 141 122 140 127 152 137 135 131 118 133 130 104 137 120 113 122 109 154 124 133 135 101 119 144 127 115 118 128 136 120 130 104 114 155 134 115 152 118 136 124 119 147 127 114 126 130 108 144 122 136 147 138 119 128 119 134 130 99 128 137 138 134 118 127 130 130 93 127 148 116 135 136 128 130 124 120 141 127 134 136 121 113 129 128 113 132 134 126 124 141 133 111 130 127 128 127 118 113 136 110 128 135 141 149 123 151 123 124 122 123 121 123 127 130 106 117 124 111 130 149 124 110 123 128 131 144 108 128 125 136 140 126 122 133 145 148 125 107 137 116 124 130 123 109 136 113 146 140 124 128 139 113 116 108 116 135 127 124 136 119 111 146 137 123 138 143 115 130 122 119 135 123 149 104 102 149 142 114 123 109 112 113 134 146 147 110 139 123 123 104 134 157 120 125 120 137 136 148 125 106 116 124 124 127 107 111 115 147 136 122 140 125 111 103 122 147 135 102 131 127 140 126 111 138 135 139 135 138 132 116 125 142 116 112 135 128 126 107 139 119 124 111 114 131 120 122 107 115 112 120 142 131 112 124 107 157 128 130 117 141 112 114 120 113 135 128 138 118 142 119 130 138 136 126 143 118 132 104 123 110 113 95 114 131 138 140 131 126 130 119 136 110 128 139 165 115 137 123 116 151 123 108 122 112 108 110 133 116 133 111 122 122 129 140 136 132 122 121 109 133 112 118 133 122 114 121 138 134 128 134 135 134 109 135 114 146 127 131 115 125 115 133 112 119 120 127 130 124 118 110 110 123 144 113 122 130 128 117 124 133 113 106 130 135 112 128 136 133 139 121 153 110 138 106 125 98 142 103 109 118 131 139 122 124 139 116 121 128 113 146 138 129 120 112 99 119 123 120 121 113 117 120 121 135 132 114 117 145 141 125 126 124 132 110 113 109 122 123 123 119 124 117 116 113 138 113 142 125 130 123 116 118 119 134 134 121 128 119 130 116 128 113 120 108 122 124 117 123 117 107 128 123 123 127 121 123 122 122 121 121 105 105 130 126 129 140 124 138 135 110 125 123 140 117 117 143 115 105 125 108 125 109 119 143 116 129 128 121 115 129 133 118 122 134 138 143 126 113 124 113 156 100 96 106 124 127 115 129 99 135 117 111 124 129 124 124 124 135 109 116 105 146 113 118 110 125 107 106 124 131 134 109 121 123 110 126 121 115 128 127 115 131 122 113 141 119 112 130 126 118 106 108 116 125 132 127 113 130 110 124 117 131 114 121 125 118 140 123 121 145 125 118 106 120 125 126 129 124 140 145 125 119 121 125 121 125 136 119 128 112 120 119 127 107 130 105 110 132 107 137 128 122 129 128 103 118 105 117 126 123 132 126 147 115 109 115 133 119 142 117 115 124 118 95 131 129 115 137 138 128 109 142 145 122 135 106 137 126 135 131 120 120 133 119 137 129 126 116 122 128 120 124 111 140 112 119 135 122 128 144 117 133 124 111 116 117 130 139 111 140 111 112 105 118 114 132 124 130 106 129 125 121 120 122 131 116 105 149 117 129 139 132 119 133 141 118 121 114 117 154 108 129 134 149 127 114 117 137 131 121 129 149 123 111 124 125 133 107 119 107 110 105 135 125 110 116 117 109 135 120 119 105 113 125 105 114 129 114 120 103 142 132 136 133 143 104 132 130 100 116 119 103 112 109 109 130 133 117 121 122 138 138 128 114 117 122 116 123 112 132 128 125 135 114 126 102 130 135 122 133 133 119 106 92 129 103 137 119 131 97 124 127 114 120 112 129 106 110 123 124 119 118 144 126 123 121 123 122 127 112 118 116 123 120 124 126 125 134 109 113 116 121 133 118 102 108 106 127 135 114 139 123 125 132 119 100 132 121 120 130 129 123 124 116 138 135 129 111 122 123 136 117 111 130 118 111 126 129 136 120 144 109 116 118 124 112 125 104 137 151 110 129 128 110 121 125 122 119 118 143 127 130 109 117 126 117 130 107 124 139 123 135 108 135 124 125 134 133 125 143 138 132 121 110 119 106 118 147 131 117 118 119 126 109 127 119 133 140 126 102 110 111 130 138 109 126 131 112 126 126 117 94 123 127 125 107 139 115 102 113 119 125 138 107 139 113 111 140 135 133 119 114 120 118 110 129 124 116 128 110 104 114 119 127 135 129 125 120 112 129 118 116 112 124 99 141 115 118 122 130 116 127 113 121 117 121 129 130 128 107 137 114 130 111 120 117 109 131 124 108 128 117 107 134 110 128 118 113 118 110 139 125 133 117 117 116 120 118 109 116 121 106 120 123 124 138 127 123 137 134 113 120 145 100 103 116 110 123 114 136 115 116 123 116 125 107 115 110 122 128 142 111 108 118 114 121 132 130 113 112 137 121 148 145 104 121 117 132 124 147 115 105 120 115 126 133 132 101 112 130 139 99 125 116 128 114 116 128 117 120 118 116 112 143 114 120 128 119 122 114 127 140 146 120 122 123 124 108 129 137 109 103 124 125 119 143 107 132 139 117 111 99 111 131 111 142 129 124 146 134 123 109 126 119 115 124 130 134 118 126 106 117 118 131 129 116 131 110 125 138 108 118 117 126 127 136 129 118 125 114 132 106 149 90 123 125 133 136 123 106 134 112 124 120 115 121 140 114 118 131 125 125 122 110 116 133 115 125 126 130 114 125 142 124 141 119 122 106 115 97 106 119 113 130 113 125 127 121 119 123 130 115 131 137 124 118 134 121 133 126 118 131 102 109 117 109 133 144 119 124 112</counts>
			</dataPoints>
		</scan>
	</xrdMeasurement>
</xrdMeasurements>