File: data/XRD/XG-Sauerstoff/XG-600/W6821-1B_XG_Sauerstoff_600.xrdml
<xrdMeasurements xmlns="http://www.xrdml.com/XRDMeasurement/2.1" xmlns:xsi="http://www.w3.org/2001/XMLSchema-instance" xsi:schemaLocation="http://www.xrdml.com/XRDMeasurement/2.1 http://www.xrdml.com/XRDMeasurement/2.1/XRDMeasurement.xsd" status="Completed">
	<comment>
		<entry>Configuration=Factory configuration, Owner=User-1, Creation date=7/8/2013 4:01:53 PM</entry>
		<entry>Goniometer=PW3050/65 (Theta/2Theta); Minimum step size 2Theta:0.0001; Minimum step size Omega:0.0001</entry>
		<entry>Sample stage=MRD Cradle; Minimum step size Phi:0.01; Minimum step size Chi:0.01; Minimum step size X:0.01; Minimum step size Y:0.01; Minimum step size Z:0.001</entry>
		<entry>Diffractometer system=XPERT-PRO</entry>
		<entry>Measurement program=C:\PANalytical\Data Collector\Programs\Jorrit\2thom\_absolute_2th-om_10-130deg_PIXscan_56min.xrdmp, Identifier={15BCCF57-2807-42BD-B5B9-ECC0B3DC9284}</entry>
		<entry>Batch program=C:\PANalytical\Data Collector\Programs\SimonL\batch4x_2thom_10-130°_z9.1_x0,10,20,30_y0_57min.xrdmp, Identifier={EED9823A-2BEB-424C-9252-345C4EF2834A}</entry>
	</comment>
	<sample type="To be analyzed">
		<id></id>
		<name></name>
		<preparedBy></preparedBy>
	</sample>
	<xrdMeasurement measurementType="Scan" status="Completed" sampleMode="Reflection">
		<comment>
			<entry>_absolute_2th-om_10-130deg_PIXscan_56min</entry>
			<entry>PHD Lower Level = 4.83 (keV), PHD Upper Level = 11.27 (keV)</entry>
		</comment>
		<usedWavelength intended="K-Alpha 1">
			<kAlpha1 unit="Angstrom">1.5405980</kAlpha1>
			<kAlpha2 unit="Angstrom">1.5444260</kAlpha2>
			<kBeta unit="Angstrom">1.3922500</kBeta>
			<ratioKAlpha2KAlpha1>0.5000</ratioKAlpha2KAlpha1>
		</usedWavelength>
		<incidentBeamPath>
			<radius unit="mm">320.00</radius>
			<xRayTube id="1010048" name="Empyrean Cu LFF HR (9430 033 7310x) DK442154">
				<tension unit="kV">40.0</tension>
				<current unit="mA">40.0</current>
				<anodeMaterial>Cu</anodeMaterial>
				<focus type="Line">
					<length unit="mm">12.0</length>
					<width unit="mm">0.4</width>
					<takeOffAngle unit="deg">4.2</takeOffAngle>
				</focus>
			</xRayTube>
			<xRayMirror id="27010001" name="Inc. Beam Cu W/Si (parabolic MRD)" hybrid="false">
				<crystal type="Graded" shape="Parabolic">W/Si</crystal>
				<acceptanceAngle unit="deg">0.800</acceptanceAngle>
				<length unit="mm">60.0</length>
			</xRayMirror>
			<sollerSlit id="21010002" name="Soller slits 0.04 rad.">
				<opening unit="rad">0.0400</opening>
			</sollerSlit>
			<mask id="22030007" name="Fixed mask 2 mm">
				<distanceToSample unit="mm">220.00</distanceToSample>
				<width unit="mm">2.00</width>
			</mask>
			<divergenceSlit id="22010007" name="Fixed slit 1/8°" xsi:type="fixedDivergenceSlitType">
				<distanceToSample unit="mm">220.00</distanceToSample>
				<height unit="mm">0.19</height>
			</divergenceSlit>
		</incidentBeamPath>
		<diffractedBeamPath>
			<radius unit="mm">320.00</radius>
			<sollerSlit id="21010002" name="Soller slits 0.04 rad.">
				<opening unit="rad">0.0400</opening>
			</sollerSlit>
			<receivingSlit id="22010001" name="Fixed slit 4°">
				<height unit="mm">5.88</height>
			</receivingSlit>
			<detector id="7010017" name="PIXcel3D 1x1 detector" xsi:type="areaDetectorType">
				<phd unit="%">
					<lowerLevel>30.0</lowerLevel>
					<upperLevel>70.0</upperLevel>
				</phd>
				<mode>Scanning</mode>
				<activeChannelsEquatorial>255</activeChannelsEquatorial>
				<activeChannelsAxial>255</activeChannelsAxial>
				<pitchEquatorial unit="mm">0.05500</pitchEquatorial>
				<pitchAxial unit="mm">0.05500</pitchAxial>
				<readOutPeriod unit="seconds">0.135</readOutPeriod>
			</detector>
		</diffractedBeamPath>
		<scan appendNumber="0" mode="Continuous" scanAxis="2Theta-Omega" status="Completed">
			<header>
				<startTimeStamp>2024-09-11T19:03:54+02:00</startTimeStamp>
				<endTimeStamp>2024-09-11T20:00:01+02:00</endTimeStamp>
				<author>
					<name>PRO-MRD</name>
				</author>
				<source>
					<applicationSoftware version="6.1b">Data Collector</applicationSoftware>
					<instrumentControlSoftware version="7.0E 20130304">XPERT-PRO</instrumentControlSoftware>
					<instrumentID>0000000011142674</instrumentID>
				</source>
			</header>
			<dataPoints>
				<positions axis="2Theta" unit="deg">
					<startPosition>9.99826193</startPosition>
					<endPosition>129.99755682</endPosition>
				</positions>
				<positions axis="Omega" unit="deg">
					<startPosition>4.99913096</startPosition>
					<endPosition>64.99877841</endPosition>
				</positions>
				<positions axis="Phi" unit="deg">
					<commonPosition>0.00</commonPosition>
				</positions>
				<positions axis="Chi" unit="deg">
					<commonPosition>0.00</commonPosition>
				</positions>
				<positions axis="X" unit="mm">
					<commonPosition>0.00</commonPosition>
				</positions>
				<positions axis="Y" unit="mm">
					<commonPosition>0.00</commonPosition>
				</positions>
				<positions axis="Z" unit="mm">
					<commonPosition>9.100</commonPosition>
				</positions>
				<commonCountingTime unit="seconds">32.895</commonCountingTime>
				<counts 233 210 216 218 230 207 226 185 193 207 192 206 255 223 216 201 196 217 180 198 219 249 215 218 203 169 180 187 179 197 233 185 217 203 216 208 209 182 183 202 218 214 207 210 203 209 215 199 205 213 211 194 207 220 236 200 204 184 221 172 202 221 209 212 157 182 194 174 209 190 210 186 203 183 179 196 198 206 189 207 191 175 201 200 175 187 183 209 192 207 184 214 204 197 211 200 176 202 205 205 201 183 194 175 216 197 188 169 195 213 219 185 179 215 182 202 195 182 190 207 189 200 203 194 152 185 217 191 167 191 173 201 202 180 204 192 188 172 200 201 187 168 187 175 196 179 196 200 207 198 182 209 203 183 185 219 231 186 190 173 179 171 180 176 186 193 207 195 187 163 199 181 179 182 187 207 185 187 178 163 166 188 193 172 169 188 172 161 181 199 186 170 172 196 184 168 188 192 182 176 160 159 171 166 176 186 198 174 172 178 191 163 188 158 194 192 153 169 186 211 171 170 166 168 153 175 178 169 187 161 171 203 182 172 194 202 180 190 178 194 188 175 166 181 167 147 175 154 184 154 180 184 156 194 172 164 157 190 172 141 181 181 187 184 195 195 196 190 180 173 174 180 180 200 185 184 158 169 190 164 169 174 167 184 160 177 173 189 166 177 150 174 187 174 157 179 162 179 164 171 178 182 188 156 157 167 160 176 164 194 162 174 148 174 189 165 184 180 154 170 165 180 183 166 180 169 163 168 169 168 171 178 174 166 164 151 177 157 161 166 185 164 160 177 164 165 169 169 185 172 176 150 163 179 191 177 172 162 175 172 145 154 152 146 183 171 160 142 176 153 182 182 165 154 157 148 165 169 150 177 163 167 166 154 178 155 162 173 181 175 174 150 177 159 176 165 131 164 161 161 137 177 165 167 155 162 158 176 144 177 174 145 144 146 167 155 153 169 157 194 150 161 156 144 158 171 161 126 175 149 177 158 184 151 171 137 142 162 141 144 144 143 160 174 150 180 137 174 161 141 158 160 144 139 137 152 150 147 168 181 163 160 172 184 168 160 151 159 146 153 170 157 162 173 148 171 163 140 155 153 165 136 155 144 161 150 159 138 147 165 158 158 171 170 156 158 163 150 149 164 174 153 137 145 158 164 155 152 156 160 132 150 151 154 129 155 162 153 146 160 156 160 165 140 154 139 156 153 167 158 160 160 159 163 139 166 169 158 167 157 178 140 139 161 143 161 154 143 159 142 169 163 169 157 148 155 149 128 145 157 151 145 151 154 159 148 153 175 159 188 145 156 151 144 150 153 139 142 163 168 141 145 176 144 144 156 175 129 141 152 136 152 153 174 157 137 173 148 168 155 146 163 165 152 143 193 166 162 145 148 140 155 143 158 164 165 170 161 152 167 138 162 150 162 161 161 168 147 149 140 147 163 141 130 141 149 157 160 144 170 121 162 144 146 156 161 160 147 151 145 145 165 144 128 160 136 150 149 154 139 160 171 154 155 162 139 154 131 148 155 164 162 141 150 120 159 141 137 151 153 150 154 159 145 153 155 142 162 192 150 162 177 155 147 172 172 156 163 165 169 148 147 143 166 135 154 127 143 157 157 142 144 159 150 145 154 146 167 119 146 165 150 165 144 172 135 164 153 162 145 175 163 154 150 152 140 168 188 164 171 136 142 156 151 162 174 170 159 159 161 143 172 168 156 161 138 145 167 151 161 158 143 147 171 159 183 168 156 159 153 155 163 144 190 155 154 149 153 145 160 142 169 163 139 155 151 177 155 156 160 187 162 145 150 156 139 148 156 145 171 168 170 142 163 162 156 151 157 138 146 162 159 175 148 151 138 159 163 150 185 151 159 149 137 147 167 173 145 196 164 148 163 155 163 145 133 174 166 156 186 173 143 148 140 172 175 145 172 178 164 152 169 159 168 162 177 151 160 154 141 149 151 171 171 151 174 159 160 166 170 165 150 188 161 178 147 164 146 171 157 144 138 129 174 136 162 171 166 149 159 175 172 177 156 179 171 167 158 167 171 158 157 173 151 170 171 162 165 163 134 150 166 163 151 158 170 155 162 153 153 165 155 154 173 169 150 159 174 147 157 175 167 186 156 182 190 190 187 154 145 171 189 159 149 176 158 175 132 167 159 164 177 170 163 186 164 147 158 157 183 137 167 165 184 178 141 169 162 179 166 149 179 161 186 182 177 160 181 148 156 185 166 172 156 135 179 172 193 152 146 168 155 165 181 172 179 194 160 166 181 155 177 164 163 147 167 177 155 158 171 156 168 163 168 168 182 158 151 179 164 168 158 171 154 166 160 158 136 154 170 160 170 163 167 174 185 176 175 176 174 164 184 150 151 179 184 176 146 174 170 168 164 165 182 153 153 183 171 157 172 152 173 165 181 167 157 153 159 172 158 150 170 181 136 182 188 160 184 157 148 167 153 172 161 166 156 155 171 148 155 163 161 150 172 150 142 167 189 150 140 154 166 131 169 164 181 175 129 166 155 173 177 166 157 153 186 179 166 158 190 181 168 139 176 164 160 159 169 166 186 166 151 182 182 167 135 174 175 176 164 160 162 191 173 159 166 167 198 172 187 164 171 171 168 181 173 158 161 165 181 160 159 162 167 160 168 176 168 170 160 169 175 167 147 171 151 159 175 166 146 178 153 155 172 168 160 161 151 160 158 176 178 136 163 163 166 169 170 154 194 161 159 174 186 169 162 166 171 149 180 145 137 184 167 177 175 167 167 162 171 180 166 178 152 166 160 180 169 189 172 181 162 180 173 145 173 188 156 171 168 169 160 157 177 160 164 163 177 178 177 162 185 172 165 147 156 196 182 172 186 161 181 158 164 178 168 181 175 189 180 174 176 166 160 168 153 163 179 164 153 167 175 170 157 174 186 174 172 162 164 168 175 170 150 160 183 160 162 181 179 183 164 159 158 167 154 171 160 178 163 195 179 165 171 153 135 168 161 171 146 173 149 182 147 163 149 148 177 150 157 165 168 158 161 164 162 145 188 185 157 158 179 196 175 175 169 182 193 171 191 161 173 152 168 160 163 176 160 200 146 164 155 154 169 154 164 165 177 147 177 151 169 183 165 161 149 165 167 170 156 155 169 159 163 157 158 186 171 167 139 185 160 155 171 159 167 142 165 135 141 169 160 147 163 185 151 154 166 173 163 172 154 171 149 167 158 177 172 140 163 148 148 168 177 147 163 147 148 141 163 159 159 153 151 196 163 188 154 165 170 176 144 177 165 178 159 158 163 161 172 140 166 135 165 164 157 154 150 129 168 170 155 145 171 144 151 167 180 161 157 156 142 146 162 172 148 156 156 166 153 135 147 151 176 161 172 147 158 133 147 161 141 139 170 152 175 156 162 182 171 165 199 137 163 161 139 129 157 147 173 179 158 159 151 152 160 140 141 139 163 165 158 157 158 151 172 121 144 165 169 167 160 161 140 149 170 150 146 175 155 161 157 161 155 152 147 151 155 159 179 154 144 164 144 169 159 149 154 177 158 156 148 151 187 149 154 153 179 140 153 147 164 153 143 170 151 124 156 161 149 159 159 132 172 153 182 146 152 148 146 141 153 130 154 152 159 150 143 153 145 152 137 149 171 145 171 178 125 163 137 143 154 151 187 161 152 161 150 170 152 175 146 158 132 150 140 129 161 148 178 138 172 144 142 132 152 157 171 140 152 167 134 158 157 158 160 155 113 151 153 145 157 137 153 158 165 144 153 130 130 153 144 125 140 147 145 157 153 155 148 126 147 147 132 154 118 150 147 158 162 152 117 170 157 157 169 166 146 143 164 158 144 129 151 155 141 191 151 146 149 137 145 144 163 148 156 153 144 137 153 137 126 135 157 124 137 167 146 158 139 149 137 153 149 127 160 155 137 138 130 157 149 133 131 147 135 160 149 144 161 148 157 147 151 159 162 147 129 150 153 115 146 144 155 162 152 148 139 148 144 157 156 147 149 144 123 136 142 135 154 140 139 136 135 133 160 145 166 142 146 143 133 116 150 146 135 145 165 148 139 144 144 128 150 149 143 153 122 146 133 125 136 167 134 137 131 123 131 124 129 129 130 146 120 128 146 136 130 150 150 138 127 132 138 160 144 144 130 117 127 164 137 128 129 123 141 122 126 136 151 145 142 142 149 137 148 133 122 124 150 150 146 132 153 129 145 144 157 151 130 149 152 137 152 140 124 145 136 134 126 107 143 152 153 141 120 177 139 132 149 134 130 135 145 137 152 150 123 121 152 142 144 141 143 133 162 130 128 148 130 128 126 138 148 143 139 128 144 145 120 129 124 124 126 130 151 140 134 139 140 147 142 135 139 136 126 150 132 129 121 153 139 129 140 140 124 133 159 128 132 114 129 119 112 145 147 135 137 149 147 117 154 144 122 119 131 171 124 164 132 117 116 149 133 137 129 153 135 136 134 147 134 125 137 154 109 152 136 129 153 140 145 146 119 143 166 146 131 141 140 129 144 136 153 139 130 118 132 126 117 150 147 153 113 125 136 140 145 135 115 148 117 128 134 155 143 135 114 145 131 154 141 145 131 105 132 132 144 134 141 129 138 122 105 155 137 130 136 141 151 134 124 146 133 139 138 162 145 139 138 134 127 154 114 137 130 136 143 112 139 136 134 140 139 143 142 122 138 141 128 134 143 137 128 136 138 100 122 124 134 142 129 131 122 148 138 124 130 122 112 149 155 123 140 133 148 149 120 130 128 138 111 113 126 126 141 135 114 121 116 136 146 127 120 118 120 116 145 143 129 134 112 124 153 131 130 128 124 122 129 110 123 143 130 126 133 142 155 117 140 130 128 140 121 146 137 131 131 121 117 114 123 130 122 130 131 132 129 133 143 147 136 137 139 114 131 136 140 148 147 130 133 143 129 114 139 151 130 126 132 135 124 132 126 115 130 122 152 134 135 135 107 135 151 125 126 128 147 136 137 135 134 128 130 145 123 126 142 124 142 155 114 136 144 144 138 125 123 149 120 119 132 123 126 125 127 136 126 120 123 131 141 134 137 116 123 134 143 122 139 120 126 111 117 139 154 102 139 129 136 136 144 136 115 113 122 147 125 141 144 124 127 116 120 138 149 129 129 128 133 138 131 117 128 151 127 155 120 140 115 138 122 136 105 134 114 118 120 140 143 119 123 122 151 131 143 112 126 116 112 96 134 140 127 135 122 142 126 149 131 150 102 142 137 133 113 124 136 121 152 110 104 122 117 139 143 137 154 119 129 120 128 153 142 120 135 126 125 124 141 115 119 129 154 111 133 145 146 142 124 115 138 101 106 111 123 121 139 131 134 119 140 116 129 143 126 112 138 106 105 122 129 106 138 133 118 111 132 130 116 140 128 132 119 108 121 140 135 123 131 114 103 107 145 136 139 113 114 110 135 124 119 108 125 115 115 142 130 126 106 109 123 140 126 146 119 143 118 129 161 128 144 116 118 133 144 113 115 127 130 138 109 107 117 103 129 131 139 148 123 107 120 138 115 125 141 125 114 122 122 127 130 106 137 128 119 118 117 145 131 120 141 107 127 137 125 133 131 143 107 117 117 137 131 120 129 132 106 132 120 137 126 133 121 118 101 134 113 111 133 130 123 110 138 123 106 114 115 112 125 117 104 137 134 119 130 122 132 125 127 126 117 126 134 123 133 123 123 108 132 127 121 112 133 112 120 122 143 139 117 119 124 127 117 132 109 122 120 112 114 103 148 133 144 140 134 128 105 127 116 129 120 123 94 148 138 132 134 129 125 141 115 113 128 111 125 124 118 130 107 125 114 131 134 126 117 123 159 126 129 124 117 121 148 132 112 127 118 112 135 125 120 137 139 104 126 127 135 119 120 139 115 142 126 140 110 120 115 123 147 137 119 113 117 137 111 117 122 163 131 110 127 146 109 123 137 119 121 128 130 110 139 124 130 119 112 126 118 124 141 133 122 145 115 113 120 134 131 129 101 127 125 128 139 125 113 155 146 137 123 121 130 152 114 138 122 125 122 123 141 121 116 124 141 123 134 127 120 136 113 128 116 126 133 148 136 139 124 126 113 143 127 114 146 135 144 133 120 129 129 131 117 110 117 124 111 100 154 119 128 126 122 139 130 132 114 141 139 130 118 133 132 136 136 137 120 123 114 132 118 123 120 122 149 132 110 137 116 112 150 129 151 159 137 124 125 134 135 113 146 144 133 147 138 138 126 123 138 123 115 133 133 132 124 127 112 123 133 112 118 134 123 119 141 114 137 106 128 126 136 121 126 119 130 148 135 121 109 123 133 121 127 123 135 140 104 132 110 116 125 114 142 121 114 123 118 113 121 143 123 120 116 140 124 111 125 118 116 134 138 149 137 134 117 145 132 126 100 119 122 134 132 125 138 125 122 113 114 101 117 119 116 137 112 117 123 106 124 123 130 110 122 135 114 119 116 140 112 124 123 104 134 118 118 125 124 132 98 122 129 127 111 114 125 106 127 118 122 122 106 112 134 119 125 116 117 107 137 121 123 135 118 109 136 110 151 130 117 113 128 114 136 131 120 122 108 124 111 128 101 110 120 122 104 123 124 128 131 131 123 139 102 127 110 131 136 133 124 138 128 121 114 126 148 135 116 121 128 117 120 130 115 135 145 134 122 132 124 115 116 114 119 119 123 121 133 126 118 127 120 120 102 132 103 136 123 122 116 129 126 117 128 126 121 121 125 126 126 110 120 109 122 105 128 127 130 101 110 112 125 111 121 140 137 116 133 147 120 116 129 129 120 115 130 102 134 102 123 145 122 129 124 131 134 112 113 127 126 121 132 144 120 113 125 126 132 116 129 134 116 116 117 129 122 123 143 119 137 126 106 129 118 115 108 132 126 120 100 125 137 103 126 122 130 133 137 119 118 115 121 121 116 116 128 112 119 123 124 126 109 115 135 110 134 138 118 105 121 110 120 127 121 131 120 128 120 120 107 116 124 113 123 120 149 123 138 118 117 125 122 123 142 123 127 117 129 113 128 126 114 123 126 130 155 120 125 120 98 82 114 139 122 124 136 140 113 135 131 114 118 109 134 127 123 119 115 131 135 123 118 124 123 113 113 135 99 150 113 111 122 126 130 129 104 131 118 100 113 132 131 129 117 103 127 111 128 119 138 128 138 137 116 128 121 134 130 127 126 125 131 137 131 87 111 139 105 130 118 126 134 137 115 130 130 134 122 130 113 131 120 129 135 116 116 142 126 111 128 113 135 132 128 106 137 139 130 124 126 123 132 126 123 125 125 147 121 156 110 125 140 131 135 125 120 124 129 134 138 101 113 118 114 127 120 102 137 149 124 119 123 106 122 116 124 124 127 128 130 116 115 119 117 114 105 123 123 114 132 126 128 129 128 143 123 126 126 127 142 126 140 129 128 134 127 114 136 126 134 136 121 138 114 120 139 125 127 137 126 128 123 122 120 123 128 113 100 137 106 136 134 116 119 113 103 151 111 122 133 122 122 118 136 124 124 161 129 132 108 140 114 144 125 112 112 130 123 124 156 140 140 117 148 134 125 131 123 149 129 134 121 138 125 130 127 127 136 146 136 137 145 117 131 140 131 117 142 133 145 131 119 140 115 112 125 152 133 137 142 148 137 119 133 125 110 136 116 132 133 131 111 128 139 131 157 133 133 127 133 151 153 148 116 136 127 132 144 158 122 110 148 148 168 129 118 133 143 151 123 127 145 146 130 134 128 145 159 139 145 148 123 154 136 157 144 134 121 143 155 122 155 162 152 152 163 133 156 138 166 166 146 157 165 157 183 173 163 153 164 188 163 164 146 178 170 178 190 194 215 193 208 205 225 202 227 255 226 233 221 207 217 273 235 263 241 247 255 258 227 261 237 220 223 231 230 237 218 203 209 204 177 186 207 185 201 170 164 195 160 162 184 183 161 157 172 161 151 140 147 157 145 131 164 144 132 147 121 141 136 154 137 154 133 145 157 144 147 127 131 143 118 133 141 111 136 146 133 124 133 136 109 136 166 115 140 136 134 128 116 118 139 150 134 139 118 134 147 126 137 131 129 144 135 124 122 153 137 124 150 113 134 129 122 129 142 134 145 119 141 135 127 120 135 139 136 133 136 126 122 136 119 123 138 114 122 127 127 116 130 137 116 129 125 117 120 136 141 124 93 120 133 116 123 130 137 117 143 138 112 144 126 131 125 127 132 136 137 135 120 120 119 128 126 126 134 111 127 124 127 124 148 120 120 135 140 120 118 147 109 124 150 131 143 124 115 126 110 134 135 131 122 158 96 139 123 117 115 132 131 126 142 141 141 133 123 120 137 127 126 133 142 124 113 110 135 103 116 126 132 144 115 134 138 122 135 123 129 125 118 113 134 123 109 132 126 128 114 140 124 113 124 126 144 126 125 107 115 121 117 137 133 132 135 125 122 142 125 118 126 144 117 152 132 122 122 142 126 132 114 105 112 126 132 142 146 126 107 127 133 155 122 144 135 133 149 113 110 115 118 122 140 131 150 122 117 117 136 134 133 116 121 128 142 129 134 117 129 119 119 126 127 124 126 120 148 149 130 137 129 135 111 141 117 137 129 125 142 133 118 130 152 149 135 91 112 109 138 127 120 141 129 126 142 150 132 110 122 145 139 117 167 131 121 109 123 106 121 123 133 109 138 93 128 155 130 130 135 128 141 132 151 145 129 124 118 141 117 141 131 127 116 138 135 109 128 120 127 142 129 121 127 122 153 131 142 129 113 114 131 118 146 128 146 117 144 110 127 122 132 91 131 132 117 134 149 123 117 96 131 112 122 136 133 130 104 130 116 117 129 121 139 128 139 124 139 125 138 115 154 122 107 121 132 124 138 122 126 116 132 133 120 130 116 116 134 137 127 142 132 141 108 122 117 141 125 117 126 118 119 135 138 123 136 111 124 108 122 136 144 117 134 128 143 129 109 122 152 116 123 128 126 126 137 115 137 117 102 120 116 122 114 123 114 150 135 147 141 114 113 126 125 139 128 120 124 120 114 141 124 116 120 166 141 111 119 123 130 117 116 129 121 113 114 126 148 128 110 129 121 124 143 125 122 107 134 109 127 116 109 136 126 146 131 131 122 130 128 104 126 153 140 93 119 117 132 142 114 124 122 119 122 120 139 134 149 143 120 119 106 134 125 117 121 113 126 122 140 125 141 114 142 102 132 120 126 118 130 114 134 115 124 124 128 144 123 124 138 118 111 114 116 139 133 115 130 141 133 149 144 154 138 141 144 126 134 125 125 146 117 121 114 119 112 128 118 147 150 132 144 128 119 127 104 122 110 112 127 100 109 110 112 133 136 135 136 123 139 128 120 136 148 131 124 116 124 122 122 119 132 127 123 108 142 122 152 119 125 139 114 138 139 127 115 139 127 143 131 148 138 122 123 130 134 124 130 113 127 130 105 122 136 140 118 121 114 128 118 99 103 113 114 122 96 133 106 129 145 130 120 111 118 112 119 119 128 138 131 126 131 133 119 119 118 139 125 126 117 112 130 128 127 118 127 111 105 126 135 160 114 128 135 143 126 116 136 124 118 119 124 124 108 112 127 116 125 128 122 127 135 141 120 102 117 141 125 120 111 119 132 135 110 126 132 115 113 110 139 126 127 125 119 134 129 114 111 128 132 141 114 124 110 121 130 134 133 121 111 126 132 124 137 114 138 124 135 131 122 113 119 120 128 112 124 126 102 134 140 128 117 120 118 126 125 135 125 144 136 114 130 125 134 120 142 122 115 114 118 132 132 103 110 139 112 134 130 119 126 130 134 120 141 111 119 141 133 106 117 114 122 124 138 119 130 131 152 111 107 124 129 137 139 117 121 118 113 138 106 130 123 128 113 121 131 116 126 138 125 129 145 127 115 118 136 121 115 108 108 128 115 131 140 129 112 116 129 133 135 134 121 133 126 131 111 137 129 117 118 131 137 128 124 106 128 115 138 118 116 125 144 128 124 114 123 127 120 133 118 130 135 122 128 120 137 127 160 109 132 134 111 145 105 134 134 113 132 121 138 125 107 141 130 113 159 151 121 132 107 146 118 146 111 144 116 121 134 135 126 142 135 106 110 148 122 129 139 113 114 114 145 119 110 118 150 124 128 121 100 107 140 127 135 134 137 115 142 127 122 144 132 135 120 118 112 125 114 131 128 127 120 124 132 154 132 113 128 143 132 115 119 127 139 134 108 132 142 129 132 145 144 115 134 125 112 113 126 123 106 127 109 125 119 120 115 102 113 136 140 116 110 123 131 135 133 133 144 118 134 113 111 138 128 128 126 121 130 139 113 100 139 113 134 117 142 138 137 120 129 125 104 139 113 137 125 126 119 124 135 124 124 125 101 118 116 133 114 117 112 137 114 116 138 121 115 108 123 109 131 119 145 131 128 131 115 148 148 134 126 111 130 125 130 100 144 114 140 126 104 124 132 125 160 135 120 137 121 139 124 137 148 126 116 111 110 129 130 133 139 126 141 115 142 153 118 131 129 123 123 131 140 133 107 130 118 121 112 136 131 126 115 111 149 148 140 123 127 110 121 122 129 125 112 138 117 133 128 109 110 126 132 112 132 117 138 121 133 136 126 117 119 115 125 136 103 122 122 151 115 133 124 128 133 130 144 124 132 125 143 143 115 107 101 97 125 118 130 133 115 145 119 131 127 133 142 136 106 131 135 145 127 129 146 142 136 126 130 108 124 129 135 126 130 130 124 162 135 134 125 135 112 135 129 149 142 122 143 114 124 126 113 120 147 124 121 138 130 125 105 134 128 105 119 114 135 125 132 118 133 126 100 114 117 124 129 121 123 125 113 140 136 128 138 134 141 139 113 148 111 139 128 113 140 125 122 113 117 126 137 126 135 115 131 137 117 148 146 138 134 130 154 118 142 145 120 128 137 123 119 135 130 105 128 118 126 103 132 138 131 111 124 127 143 110 121 130 117 103 144 123 127 116 154 108 148 121 130 158 114 112 124 131 107 133 127 117 127 114 141 119 127 123 133 99 111 137 136 127 133 142 120 104 129 139 127 115 140 116 140 126 118 116 149 134 123 123 149 154 138 134 140 119 121 119 122 130 138 143 135 130 129 147 121 128 133 131 135 112 131 125 132 127 134 120 131 124 131 125 148 114 136 141 119 148 139 126 122 126 134 135 132 128 141 124 127 119 130 140 115 141 133 115 113 97 118 122 133 130 120 109 115 142 112 129 132 116 116 122 101 128 139 127 145 128 128 125 138 130 119 120 138 127 113 141 122 127 116 130 102 138 120 124 107 151 139 117 98 132 131 130 136 127 110 134 122 125 109 117 141 112 127 118 114 146 113 136 134 123 123 132 133 114 115 131 141 130 149 124 125 119 147 111 121 135 130 139 133 138 119 124 116 106 116 125 98 158 120 134 128 141 129 119 127 112 131 117 123 125 127 138 136 127 118 137 117 120 137 137 121 118 124 139 138 140 125 129 122 129 126 131 123 158 136 132 118 139 156 127 132 141 129 142 132 126 118 111 120 129 133 148 133 133 152 138 131 122 141 137 136 112 118 117 143 150 132 121 113 112 130 124 103 111 119 153 119 133 138 110 113 118 136 137 129 133 118 143 137 129 143 140 140 138 132 124 118 141 125 117 106 143 147 119 131 129 127 136 123 123 147 113 147 129 122 138 117 135 122 123 135 98 125 142 134 153 138 129 139 143 137 131 130 132 128 132 128 120 132 112 134 110 118 149 116 151 151 150 121 150 126 125 126 128 132 132 117 127 133 147 122 132 147 130 118 139 113 110 122 139 139 143 134 135 139 122 142 145 134 123 134 128 120 116 139 137 133 121 116 130 128 132 119 135 145 123 125 140 125 130 160 129 131 138 108 140 141 141 138 126 143 113 117 136 163 127 151 123 141 139 128 136 127 145 138 138 139 120 118 160 128 136 148 132 125 112 131 118 137 134 140 111 102 125 122 136 139 137 138 123 119 138 135 129 148 165 135 112 134 132 128 129 138 126 127 125 162 112 139 125 134 118 133 136 125 112 133 117 146 120 149 126 133 120 122 134 134 122 120 143 150 126 124 139 125 146 120 121 141 122 132 129 149 128 128 123 116 119 122 144 101 132 128 134 127 143 116 125 116 129 135 111 119 114 134 124 138 116 131 126 150 144 118 124 132 137 125 133 116 119 116 157 139 125 141 122 120 157 148 119 111 131 127 134 106 130 129 144 130 128 120 132 116 126 114 126 121 120 130 111 137 150 154 123 129 137 131 126 136 129 123 117 127 147 127 141 134 127 138 149 146 117 142 119 137 135 130 125 135 130 154 143 144 117 140 148 117 142 115 157 125 131 146 134 108 142 122 117 122 104 117 131 147 132 140 134 147 129 136 156 141 112 140 118 136 140 141 147 140 103 144 143 132 127 134 116 135 124 104 141 138 120 146 118 146 148 128 153 116 138 116 157 134 128 148 140 151 120 131 145 125 138 127 150 164 135 118 164 123 130 143 153 143 153 147 128 120 149 131 138 114 163 138 134 152 143 151 125 117 145 149 149 137 135 127 149 139 135 155 142 127 121 145 137 128 156 132 145 131 134 152 124 134 128 148 141 151 125 131 126 126 129 150 124 122 140 124 130 150 121 138 139 134 168 128 128 132 131 133 138 146 126 147 129 136 150 124 152 133 142 128 136 120 133 128 130 119 117 114 127 144 135 150 118 125 143 150 141 147 137 115 130 132 126 153 155 134 131 114 138 158 150 138 152 130 146 144 123 128 136 112 136 116 156 144 126 112 130 119 121 130 131 107 141 110 138 137 141 145 126 126 143 129 138 123 123 152 127 136 119 117 153 121 129 144 122 142 140 123 143 128 120 114 121 127 129 117 123 119 145 121 125 128 132 119 127 124 142 127 124 106 128 153 139 123 114 107 145 110 145 129 142 138 129 135 115 134 124 145 136 145 134 134 136 128 134 127 154 139 132 136 145 114 136 135 127 138 127 129 111 133 123 137 129 128 112 115 129 132 123 134 137 114 131 113 129 131 138 140 111 139 125 116 128 117 106 135 129 152 122 115 118 132 123 129 113 136 133 135 137 136 116 128 140 146 120 128 120 152 124 143 146 141 133 143 138 121 144 138 119 122 135 118 101 121 120 144 122 140 134 136 126 139 111 128 137 133 132 134 117 129 154 146 110 121 115 126 142 118 129 118 130 146 120 107 125 140 129 131 139 120 135 132 150 123 120 141 116 126 138 137 134 111 163 137 149 132 129 134 123 152 137 143 124 139 131 119 145 122 130 139 124 125 140 110 116 133 131 127 108 124 130 124 134 138 126 124 142 126 131 126 124 124 131 127 133 124 148 119 148 131 125 133 138 134 142 135 131 151 132 126 119 135 146 125 133 122 135 112 123 129 132 130 135 133 146 139 127 138 124 115 118 129 128 128 110 138 153 112 128 142 123 152 127 115 124 125 123 119 116 138 129 137 127 128 114 136 132 136 127 119 126 151 118 140 128 141 126 124 149 144 113 143 126 120 123 130 119 140 122 138 133 123 127 147 151 129 120 143 130 129 137 142 132 118 137 129 124 124 134 117 129 125 129 137 107 123 124 124 136 143 129 127 146 139 145 132 144 132 138 137 139 135 131 133 115 136 117 115 148 164 110 151 131 131 116 119 131 130 145 142 140 127 130 154 133 127 124 144 156 131 146 126 121 135 134 127 128 137 133 125 145 133 141 122 122 141 132 111 129 142 133 133 131 133 129 119 113 126 123 112 125 137 133 115 135 151 125 133 109 108 141 140 125 141 142 125 131 124 128 130 131 116 147 133 112 135 141 148 126 131 116 148 126 135 113 145 137 131 157 137 121 136 127 142 115 123 135 121 120 119 124 121 133 131 120 114 135 136 117 149 108 136 129 139 123 125 120 140 130 116 121 153 139 125 114 136 127 120 121 144 144 122 138 120 136 139 126 148 146 124 141 129 118 125 142 121 129 139 126 141 135 135 132 132 111 132 132 140 118 142 134 138 136 124 133 149 122 129 128 97 142 127 152 147 141 122 128 124 143 135 143 107 117 117 119 139 139 136 139 133 112 128 125 120 114 138 125 130 127 152 136 134 120 153 116 143 123 137 134 139 147 128 116 151 131 141 153 128 129 141 136 150 134 124 123 162 132 133 138 133 122 122 118 133 129 149 128 124 125 133 130 142 124 127 137 138 121 120 118 125 139 116 117 122 132 144 118 140 116 149 136 117 116 129 118 124 133 143 136 158 138 134 127 154 133 133 129 122 131 121 114 109 123 123 145 137 119 141 125 127 136 129 117 136 146 121 137 157 129 117 144 127 130 127 153 132 122 128 149 159 128 139 149 148 107 153 139 140 141 121 141 141 133 126 107 128 147 119 134 138 137 125 137 143 134 117 125 139 118 143 128 115 112 130 145 119 145 148 134 138 127 135 146 130 125 126 133 146 155 135 123 132 122 115 149 142 117 142 121 132 126 138 131 131 137 154 135 129 133 131 123 114 149 125 127 130 116 131 131 128 125 140 123 122 128 125 125 135 131 126 129 133 133 129 141 118 141 122 134 137 126 140 140 132 125 156 139 140 120 128 130 148 149 146 122 126 133 149 130 137 141 113 127 135 132 147 128 138 122 123 134 153 120 138 119 131 144 135 127 133 123 160 120 141 131 124 134 152 138 122 149 136 138 120 141 121 145 115 122 142 141 142 135 120 134 123 127 132 126 131 120 121 125 126 125 141 128 121 137 122 130 135 142 108 154 142 163 125 140 139 152 141 116 136 134 125 149 136 139 128 138 136 144 129 130 135 140 123 126 136 130 125 131 118 135 120 123 126 146 130 136 135 128 139 105 135 117 119 139 128 142 124 126 108 134 116 126 128 121 160 134 130 134 133 134 110 140 132 118 136 109 139 120 125 122 128 129 124 109 140 131 146 110 128 125 116 136 115 130 124 157 117 138 124 146 128 116 113 130 126 114 128 140 118 123 110 151 131 95 137 131 123 141 120 118 135 130 130 132 127 118 131 137 132 105 147 116 150 142 134 139 158 134 135 140 143 127 126 147 127 124 142 135 131 138 139 117 140 117 123 122 110 111 133 136 143 129 150 135 128 135 132 135 135 121 115 128 140 131 125 119 111 157 137 121 131 140 142 132 126 137 133 113 116 137 113 137 119 132 126 137 139 160 132 142 119 135 124 137 139 133 135 141 129 129 125 117 120 107 145 138 119 133 145 130 147 113 130 118 157 156 133 128 102 148 130 119 130 119 150 119 118 148 146 122 124 126 146 136 120 115 147 127 137 139 143 124 138 119 112 117 135 130 118 143 114 123 113 129 124 114 136 139 99 124 110 132 142 120 145 134 130 118 126 124 138 136 118 114 121 117 121 123 136 118 129 134 122 122 115 117 140 130 121 123 128 137 130 122 127 139 122 127 134 123 133 118 128 145 141 138 136 112 136 119 120 133 133 129 145 119 104 123 115 132 127 126 149 121 126 109 136 118 124 132 139 122 119 114 121 116 116 126 127 131 135 128 144 136 151 128 119 123 128 115 119 134 137 140 141 130 171 141 126 132 133 120 146 126 133 131 134 138 130 131 143 115 131 116 129 122 127 117 135 119 158 112 159 141 138 116 143 135 142 127 134 135 123 132 131 149 121 125 139 122 127 149 126 134 89 127 129 122 137 136 128 114 126 136 122 125 134 131 143 129 120 135 143 99 131 112 142 120 125 113 137 130 134 114 132 147 143 138 116 132 164 129 134 140 102 132 123 111 122 125 126 144 136 138 112 120 108 126 148 133 133 118 130 104 153 145 132 152 112 125 120 131 137 125 126 135 118 157 128 128 137 152 122 123 116 132 129 118 110 133 143 126 149 131 112 129 129 116 140 130 128 129 115 109 144 124 143 108 138 140 120 126 116 118 122 139 121 135 143 128 131 131 120 135 123 133 127 136 134 126 155 134 124 126 128 137 154 137 142 144 154 131 120 143 120 114 121 112 119 137 149 137 143 124 122 143 140 130 134 150 126 138 127 109 99 131 127 139 135 127 116 119 139 118 113 118 116 130 146 127 118 143 125 124 129 117 144 123 143 117 148 120 133 144 130 120 122 134 139 128 137 142 131 125 106 139 143 145 121 125 115 127 135 116 130 129 121 112 137 107 118 131 135 130 121 143 122 136 142 106 135 120 140 119 120 124 125 139 148 161 124 121 145 143 140 111 143 137 135 129 126 142 132 118 106 112 117 125 142 116 149 137 128 114 111 111 133 120 129 126 117 129 122 136 140 137 115 122 140 138 136 124 122 143 125 115 115 125 135 143 148 130 139 106 138 121 136 129 124 133 127 146 136 153 133 137 115 140 123 129 135 131 123 127 140 152 113 130 148 139 133 141 138 112 134 125 147 129 117 115 127 122 146 152 132 136 136 134 135 128 140 135 144 140 114 129 143 152 136 151 146 132 150 132 133 160 145 122 145 127 165 147 162 125 140 144 140 139 134 140 151 122 157 152 135 153 147 137 145 164 164 137 140 130 150 146 146 135 153 142 160 145 139 170 165 131 142 125 140 132 141 126 137 141 145 127 148 167 140 143 119 136 133 137 147 140 113 125 132 146 123 133 112 127 115 123 149 127 144 145 135 121 133 123 136 119 132 135 139 122 118 143 135 134 128 134 133 128 117 107 97 134 113 128 123 123 140 139 145 130 129 117 119 134 134 123 107 120 143 160 139 129 140 122 139 115 145 119 116 103 119 129 135 127 140 119 121 107 111 138 143 123 109 131 110 113 120 132 104 137 142 98 129 118 141 141 148 112 127 141 117 119 132 124 119 114 128 122 126 126 137 120 135 128 98 141 113 122 120 129 135 115 158 130 124 114 122 150 108 139 141 121 124 120 110 115 128 128 120 119 115 169 133 142 135 126 115 147 133 141 131 142 126 121 118 132 122 121 141 122 138 137 108 131 104 108 124 118 109 132 132 133 123 137 107 108 144 120 121 123 115 124 112 133 141 133 131 137 109 113 127 139 120 111 132 143 137 130 116 142 111 103 119 122 123 126 138 128 145 142 132 115 116 137 144 138 136 159 135 126 109 106 121 136 107 110 157 120 129 142 133 123 125 127 123 131 112 127 155 142 141 120 117 142 116 119 140 119 108 118 130 153 134 121 120 138 134 122 131 141 125 139 118 121 146 106 145 126 117 151 124 123 130 132 119 134 140 116 129 145 122 129 116 129 135 121 101 125 125 126 145 125 134 139 122 136 135 129 132 98 123 102 142 130 132 113 137 150 116 120 108 123 119 118 113 144 130 135 104 134 111 118 142 131 127 134 136 128 121 102 123 105 120 108 110 130 115 129 133 145 111 117 131 125 125 122 118 126 118 126 134 117 114 89 137 122 126 132 124 133 119 142 117 135 124 115 97 125 120 118 126 131 123 127 115 119 146 129 131 93 112 106 125 117 105 103 115 116 130 133 95 108 144 129 117 124 124 112 122 124 145 133 116 128 125 135 131 126 126 103 114 111 131 120 146 127 134 121 138 118 126 137 124 143 132 139 108 129 101 125 108 121 135 130 125 121 136 127 157 155 108 125 131 133 112 143 139 110 151 138 135 105 133 144 121 129 110 124 133 138 115 134 140 127 120 107 134 116 129 146 106 142 136 125 122 110 113 135 136 113 115 116 123 116 138 130 120 124 127 122 112 115 120 116 116 128 114 147 121 124 119 130 132 122 145 121 125 133 116 148 116 115 111 127 130 134 140 120 126 118 124 123 144 138 123 108 115 119 121 124 132 113 112 112 117 137 121 114 118 154 131 143 121 127 131 99 133 116 139 136 117 129 126 137 132 124 119 150 123 104 157 133 124 113 130 144 136 132 138 120 121 121 133 122 122 128 122 110 117 123 135 125 119 141 120 139 123 135 144 114 120 138 128 137 120 114 145 126 95 108 133 117 114 110 104 123 130 103 121 135 138 121 125 128 115 125 129 116 143 140 118 137 121 114 123 129 136 136 118 132 144 126 107 131 120 125 120 136 131 122 135 118 124 126 134 124 134 111 145 134 123 140 162 120 113 105 125 107 126 121 120 118 121 117 147 149 115 133 123 128 120 108 120 139 119 126 124 118 127 126 133 121 131 120 117 125 116 141 131 127 131 149 133 132 107 131 114 143 117 120 145 107 130 132 133 120 153 132 131 131 111 135 133 122 118 143 126 127 128 135 104 133 117 110 139 120 134 127 132 120 111 154 133 130 129 122 121 120 137 126 130 130 135 126 138 149 121 122 152 123 140 111 116 140 117 121 117 101 117 119 130 127 130 131 121 145 137 134 107 122 116 127 154 140 130 124 125 128 139 125 125 127 136 147 104 135 128 115 141 121 122 152 123 106 136 123 139 122 157 138 122 135 118 115 117 130 130 145 119 125 128 119 108 115 120 135 120 147 126 123 138 130 126 124 109 150 122 118 132 141 127 105 131 134 128 153 119 131 112 119 112 124 132 119 128 126 134 110 115 113 120 130 123 143 102 126 134 140 109 122 136 118 147 124 120 154 117 159 115 146 139 123 116 121 132 118 143 130 135 155 129 142 136 118 126 124 120 120 127 126 119 129 159 111 121 114 122 131 126 126 125 146 119 119 123 120 148 113 135 124 141 119 123 130 123 139 132 122 129 114 155 130 135 128 125 125 129 121 114 133 143 123 114 125 130 133 123 125 109 133 137 124 147 123 133 131 147 141 116 125 132 113 121 132 101 119 123 127 135 121 119 148 139 121 114 110 130 123 126 132 132 142 117 131 125 136 126 111 137 147 137 120 124 141 131 119 131 126 134 124 125 116 131 139 129 117 119 132 131 150 135 131 118 126 128 150 140 130 132 137 133 119 138 135 129 116 131 141 105 147 134 135 128 139 121 126 132 119 128 124 130 112 120 106 115 146 122 125 120 133 129 132 132 139 144 130 129 117 128 126 145 121 131 141 112 154 120 105 155 120 132 126 140 123 132 144 127 123 120 120 130 120 111 106 133 130 134 123 128 143 125 127 123 133 123 129 153 129 131 110 125 146 134 123 120 126 137 108 140 123 146 121 130 114 129 126 111 134 143 127 123 109 113 137 120 129 130 114 131 122 143 132 115 141 124 141 127 135 119 115 123 114 129 138 133 128 130 122 103 134 142 130 128 115 122 124 149 140 124 122 134 135 113 130 126 136 138 124 150 129 119 160 130 119 127 137 143 125 132 126 121 121 122 134 127 130 129 143 138 113 111 124 124 129 135 142 126 111 145 110 118 132 110 99 133 112 113 137 108 124 124 119 136 117 129 122 149 132 143 120 127 137 126 140 134 122 135 132 125 132 122 135 118 120 114 134 128 134 128 132 138 119 126 125 121 139 144 115 141 113 146 124 133 137 136 130 137 114 142 134 120 110 126 131 119 138 129 115 137 128 133 114 122 119 119 111 124 121 132 127 119 131 118 153 125 131 104 124 130 155 132 118 120 129 126 112 139 116 150 119 116 146 134 133 139 114 134 114 126 140 131 91 145 146 132 139 129 138 134 142 123 119 111 139 120 136 109 135 131 128 132 125 132 133 130 125 141 127 104 124 141 124 129 135 158 95 139 138 135 123 140 118 140 127 116 130 128 129 126 113 125 126 135 153 131 117 127 115 128 136 134 145 125 129 132 131 107 124 128 119 130 112 130 122 142 122 116 158 123 139 128 132 148 113 127 116 151 122 109 114 115 132 138 144 131 125 122 122 125 111 111 116 133 135 127 131 130 105 112 137 140 124 124 141 143 133 136 127 131 151 137 136 133 117 105 129 120 134 123 145 140 119 145 122 125 122 134 128 113 128 136 127 135 137 124 133 128 118 113 116 119 136 125 136 131 99 137 134 142 128 131 106 135 115 125 127 140 135 133 136 116 121 121 130 141 142 96 151 136 143 124 127 117 119 118 140 122 136 130 122 125 133 125 137 134 129 132 111 142 130 138 133 148 122 124 118 126 120 141 124 117 110 109 136 144 114 131 148 131 142 120 137 137 131 120 142 149 130 124 112 130 140 126 128 129 140 132 102 135 129 133 131 154 121 124 129 125 138 131 144 135 122 127 133 128 151 107 126 130 109 141 130 118 125 117 131 121 134 131 144 137 143 155 136 151 148 148 123 115 145 126 114 136 133 152 135 118 149 147 134 130 133 132 140 125 108 123 137 122 129 136 130 131 106 135 136 130 123 132 123 125 130 123 149 142 114 143 136 153 125 133 129 143 142 100 104 126 137 130 152 135 132 146 117 163 120 147 130 139 149 139 142 128 141 136 146 155 133 138 112 145 115 140 134 137 135 122 134 133 128 142 113 127 131 117 143 131 142 121 148 131 152 133 139 143 133 147 118 122 142 138 120 122 130 131 146 147 140 167 124 140 135 149 134 146 133 135 130 135 131 135 128 130 129 123 135 124 132 128 152 115 127 120 120 149 144 115 127 147 144 117 124 119 129 124 133 141 125 146 121 160 125 120 126 140 147 131 125 165 137 128 147 166 146 125 124 126 151 125 113 125 117 131 144 137 154 122 122 140 143 133 132 115 129 110 146 131 129 119 118 134 137 122 125 135 125 123 136 120 102 126 111 121 124 136 116 109 124 101 117 137 120 141 109 120 127 133 121 124 127 116 126 118 123 121 114 135 127 119 112 124 110 134 120 122 125 135 123 139 141 105 128 131 122 115 118 120 105 134 109 108 130 117 132 121 129 120 136 116 134 117 110 125 122 140 133 137 107 122 133 139 122 131 148 123 132 102 110 127 125 144 141 109 137 125 133 127 130 127 140 126 122 160 143 146 112 146 150 115 134 116 126 109 134 130 128 140 118 110 134 124 118 135 136 118 139 107 128 149 141 114 147 138 107 131 125 143 113 119 107 104 108 109 96 139 114 126 121 158 114 136 110 125 137 133 113 133 150 133 116 127 119 118 110 111 134 134 140 139 140 128 136 130 117 119 120 117 117 126 120 130 123 127 131 126 139 130 131 140 130 132 127 135 144 132 119 130 147 114 128 116 134 121 123 123 131 134 125 109 137 136 127 118 130 133 127 127 148 117 130 112 115 125 127 122 125 126 129 133 128 125 118 102 127 136 134 152 134 127 123 142 109 119 146 129 127 119 122 111 120 132 116 122 135 107 145 131 138 128 128 129 127 118 119 139 123 138 134 129 108 137 121 125 127 129 122 136 105 119 114 144 130 131 140 135 146 126 140 133 126 119 128 135 110 150 121 117 128 130 146 121 104 128 136 110 131 142 112 140 123 137 136 128 144 119 137 147 142 127 155 143 128 105 143 136 143 108 127 122 141 120 129 130 136 133 143 118 123 159 123 126 139 138 146 131 112 132 140 128 104 127 122 149 122 116 131 135 121 105 118 134 112 142 125 149 165 136 137 124 125 144 118 108 131 105 124 121 140 146 131 134 124 128 132 132 124 124 131 120 126 145 140 132 152 108 131 140 126 110 140 134 128 133 126 108 120 119 137 127 120 136 118 107 113 130 105 131 127 119 135 124 129 144 135 125 137 146 144 124 135 142 139 140 151 127 131 130 128 156 154 126 122 128 136 128 137 129 134 131 135 120 143 140 107 130 132 129 129 130 116 121 133 153 140 127 126 119 111 127 123 133 107 143 136 131 129 110 124 128 126 129 118 104 130 126 122 132 134 125 133 145 143 146 135 142 133 135 120 146 130 109 126 127 146 124 106 117 139 147 120 116 122 125 132 117 130 124 117 113 126 126 135 128 137 129 151 147 123 127 108 143 126 108 134 112 144 135 109 130 125 118 132 130 147 155 107 124 129 119 132 130 150 150 131 136 128 133 114 134 122 118 129 109 138 125 149 155 128 117 121 128 128 125 130 126 118 124 112 130 147 119 120 143 122 133 131 121 141 137 125 122 137 127 139 116 133 121 115 113 126 109 124 132 138 124 128 112 136 118 139 155 139 118 122 117 125 134 130 143 121 111 128 115 116 96 127 125 148 133 129 141 117 121 137 119 136 147 130 146 127 136 146 119 113 131 140 118 123 115 116 153 122 111 132 130 143 129 116 150 137 116 120 121 121 129 144 109 133 128 128 109 136 123 140 152 137 123 113 119 122 136 134 135 157 129 133 125 143 122 127 129 133 127 128 135 141 106 150 134 130 141 139 119 129 126 133 113 121 125 145 122 120 122 113 135 141 115 131 136 139 130 136 145 111 134 128 130 129 108 113 123 131 125 135 116 128 142 122 119 113 127 113 128 125 126 125 133 130 118 115 130 139 131 115 134 128 131 125 133 127 118 141 135 122 129 128 114 136 132 149 123 131 141 128 123 129 127 138 137 129 140 129 124 136 115 119 134 146 117 137 132 129 136 134 140 119 119 141 113 137 129 134 140 112 138 158 139 156 109 122 152 128 122 123 134 119 140 140 124 128 130 131 115 142 124 120 131 143 123 135 157 136 137 134 135 123 128 128 118 113 117 117 124 145 134 126 126 126 123 116 111 134 149 108 137 127 103 127 158 160 132 118 145 128 119 115 134 124 145 113 133 117 122 121 159 137 117 131 138 118 110 144 112 108 140 134 124 140 122 135 120 127 132 125 124 128 132 107 113 134 128 139 129 115 144 99 131 140 133 147 137 137 119 108 134 133 134 133 122 130 95 118 143 138 129 149 142 113 128 120 113 126 125 138 117 120 123 118 121 128 132 132 109 123 136 125 110 128 116 124 104 127 115 129 140 131 124 125 139 124 136 114 156 128 121 140 141 148 125 132 125 115 112 137 143 128 103 113 136 111 116 115 142 109 140 132 126 124 122 130 115 136 124 124 120 143 105 129 124 136 121 126 120 129 143 136 120 132 135 122 133 139 117 123 109 129 120 130 137 112 137 119 134 118 140 123 125 130 137 134 123 113 136 135 140 120 116 111 122 146 128 147 138 129 130 125 112 120 123 109 121 116 146 122 127 126 137 115 133 136 117 138 134 143 125 134 145 132 130 134 115 122 139 111 114 130 146 137 111 114 133 137 130 136 130 125 132 148 137 141 117 97 122 126 109 136 134 114 141 147 133 130 124 138 115 135 115 132 125 133 120 129 115 143 118 139 150 138 128 129 129 126 124 127 126 117 144 136 123 125 138 139 123 134 133 130 132 126 130 115 119 127 133 116 135 123 138 124 124 131 127 136 120 137 142 124 104 111 132 126 134 136 113 137 135 114 153 112 146 114 133 133 118 143 126 127 129 116 119 139 123 138 131 110 127 123 120 87 127 114 118 127 115 144 119 122 119 121 123 136 119 122 122 143 117 120 126 134 137 127 131 119 128 124 115 150 142 124 128 105 142 132 134 124 115 111 117 115 132 138 123 134 119 132 125 130 122 137 143 148 130 128 133 125 129 127 142 120 122 132 126 130 126 142 138 139 127 114 115 124 136 112 120 133 125 103 124 147 123 131 131 162 155 104 150 137 119 124 128 120 138 139 142 127 110 148 129 139 129 103 122 137 131 126 139 122 130 138 117 137 136 140 113 141 141 138 137 129 116 125 145 129 123 126 118 104 131 136 143 121 145 135 117 135 119 145 138 125 126 143 119 136 136 136 132 142 145 118 130 128 118 119 141 108 138 142 113 120 129 135 129 117 116 124 120 157 124 143 130 132 126 135 110 139 126 119 129 133 108 123 121 133 132 128 129 133 134 134 151 148 151 136 116 110 138 121 120 140 121 130 142 120 131 124 148 143 125 124 155 137 118 101 117 147 126 124 129 133 131 122 135 125 138 123 139 129 119 131 128 116 132 115 106 138 131 134 130 135 121 138 133 140 115 103 146 121 129 149 137 147 125 120 133 138 133 122 117 117 132 132 123 124 144 115 123 117 121 128 133 133 115 122 148 145 134 124 115 129 130 135 120 134 123 127 141 129 130 125 130 108 122 124 140 126 134 113 123 122 132 107 119 133 130 120 137 112 115 104 139 154 131 123 118 143 119 126 132 123 132 140 134 128 150 146 119 123 122 140 119 148 122 127 115 123 123 138 136 125 136 128 145 136 129 156 117 139 121 132 126 147 155 138 133 141 148 129 129 169 105 148 132 119 139 149 135 142 122 143 121 133 137 132 126 140 141 131 141 143 123 129 117 129 123 138 113 136 153 127 130 117 148 139 152 129 123 148 122 119 143 133 131 133 122 140 148 135 165 155 152 151 131 155 148 109 124 149 129 137 138 129 125 152 128 157 146 149 144 123 131 136 142 137 134 154 152 142 120 154 132 132 145 148 133 139 126 143 172 130 112 134 136 152 138 143 141 139 146 148 115 146 133 161 130 145 149 147 147 145 143 147 183 145 135 164 138 138 144 120 150 131 135 130 134 155 166 172 155 114 131 134 129 135 131 116 166 136 140 148 132 137 121 135 134 145 137 116 133 147 142 142 153 136 126 151 149 158 157 135 146 152 122 128 142 147 144 148 138 139 133 122 148 161 136 123 144 136 129 143 123 127 124 140 143 142 149 136 138 141 134 148 133 145 145 126 136 141 117 134 112 114 150 151 122 140 169 128 126 129 138 138 134 139 154 122 151 143 126 125 130 116 148 127 154 121 118 153 145 119 127 134 125 145 135 138 138 133 124 123 114 136 137 127 109 123 128 137 131 127 135 146 127 157 136 116 132 119 120 155 116 117 115 126 129 112 130 150 138 139 144 121 139 122 116 132 123 138 129 131 112 111 145 119 154 143 138 131 110 116 129 130 139 146 137 111 123 125 152 126 132 122 154 140 130 127 144 116 118 137 131 138 165 132 125 125 142 123 123 136 120 143 133 130 124 148 135 113 144 162 118 148 129 158 137 117 158 148 125 123 141 128 120 137 150 146 133 123 126 108 126 132 120 125 143 142 126 151 144 153 133 126 122 129 150 139 135 119 142 131 147 126 151 117 123 128 124 152 132 125 142 145 147 124 137 126 121 161 126 119 121 130 115 138 121 105 134 148 141 139 137 123 129 148 125 152 127 128 136 127 134 146 129 123 105 117 134 136 149 150 133 120 115 139 138 130 132 115 126 130 128 109 139 128 136 141 120 123 109 157 138 124 123 141 119 128 130 140 133 152 134 129 113 137 136 117 136 139 133 126 123 144 125 120 131 143 134 118 157 104 131 119 142 144 141 135 122 117 111 115 132 110 138 130 142 117 163 141 139 128 119 134 125 154 123 134 133 144 131 137 131 150 135 144 137 129 140 152 134 104 117 112 138 156 147 127 132 118 137 166 123 138 120 133 126 126 145 134 137 155 142 140 108 148 142 124 135 121 135 131 129 132 138 146 146 123 122 138 132 115 113 119 128 131 133 119 147 120 118 144 132 136 132 142 137 144 141 151 142 126 133 127 121 143 146 135 137 125 137 123 131 121 126 148 121 132 127 124 139 127 138 125 117 118 149 125 137 122 123 127 133 123 145 138 127 118 121 146 130 126 145 133 106 113 113 153 127 122 136 126 144 118 114 137 113 125 119 126 140 136 140 121 141 131 115 139 149 146 127 133 134 121 144 133 118 152 123 142 120 113 119 141 131 137 137 132 127 126 148 125 152 142 127 135 136 162 135 128 130 147 113 122 131 136 142 146 150 135 122 139 134 125 112 148 120 126 129 115 125 141 112 116 138 126 137 132 143 125 141 138 160 127 133 161 130 141 137 127 136 147 120 126 129 137 113 129 120 154 125 117 138 128 130 141 143 127 129 131 130 121 161 141 144 107 113 123 123 133 141 116 149 121 123 130 124 126 114 121 144 126 148 134 136 126 107 159 129 129 120 141 132 120 139 130 122 129 133 127 147 109 126 142 137 160 133 135 128 135 128 119 133 122 136 123 109 117 146 134 132 132 111 125 121 131 111 133 122 116 137 133 131 120 128 131 129 125 131 136 127 134 157 122 126 139 141 129 108 139 136 140 146 126 148 146 132 138 120 124 117 135 124 146 106 131 142 110 121 118 150 149 130 142 111 144 114 137 123 137 161 107 133 138 135 153 132 145 135 128 141 122 129 153 139 144 123 134 123 127 136 135 127 131 122 115 137 114 148 128 136 123 137 114 146 115 137 138 136 142 131 138 132 135 139 122 146 137 146 117 131 125 145 137 118 134 126 145 123 139 130 140 127 126 130 128 120 121 142 132 125 128 161 138 128 136 116 111 110 118 141 142 125 144 131 112 118 111 145 139 117 128 101 122 112 123 147 147 124 129 122 135 123 142 112 124 133 139 123 117 130 130 131 116 125 110 124 113 114 129 146 139 138 110 139 122 104 121 114 113 153 117 143 139 143 141 127 126 133 128 126 156 122 119 130 141 131 118 139 96 141 140 124 121 128 134 137 130 129 120 164 148 118 127 130 128 132 129 114 123 120 130 134 142 128 114 119 133 114 124 117 118 120 123 130 119 138 118 128 108 127 119 122 118 119 90 124 122 125 116 119 108 111 121 127 130 148 145 119 117 134 117 134 102 130 121 133 116 135 117 140 136 127 122 127 130 124 113 156 132 125 139 126 148 113 113 110 149 122 123 123 117 111 124 110 130 121 120 120 135 111 145 133 134 152 129 125 123 127 133 106 134 131 111 133 123 117 111 131 125 132 135 116 137 127 130 121 125 118 124 122 134 120 136 135 127 124 129 116 131 110 145 128 136 123 132 122 119 126 136 128 113 163 126 135 113 131 124 125 135 137 112 117 117 110 117 151 105 122 110 147 139 130 106 122 108 134 148 108 90 110 131 124 131 128 130 134 129 130 135 127 137 130 112 135 120 120 132 128 102 142 148 127 137 120 151 131 125 131 137 127 109 121 138 132 134 123 124 131 136 109 107 149 124 121 149 121 124 122 128 131 132 125 141 123 138 108 129 124 150 134 133 116 113 114 141 124 104 138 121 128 128 120 114 129 113 142 113 119 125 97 125 122 116 123 116 132 112 110 128 121 139 145 135 128 132 123 145 127 125 113 129 132 142 127 144 144 113 126 126 131 119 141 131 133 133 118 126 127 133 137 135 127 152 124 119 110 120 127 136 123 122 123 111 151 137 127 132 113 118 130 122 134 128 109 113 122 117 116 115 133 126 128 120 138 97 129 129 128 125 123 138 140 137 124 135 134 138 120 108 120 131 114 125 142 133 142 117 137 131 116 126 136 119 133 122 124 101 156 129 106 144 137 120 112 134 134 131 125 118 129 132 106 139 125 128 158 107 100 121 146 124 147 120 132 128 141 129 112 133 124 127 118 137 121 115 113 118 108 124 103 125 118 139 106 139 110 125 144 138 128 134 133 119 130 125 123 135 117 128 124 125 110 135 116 124 138 127 122 112 122 129 121 129 121 134 134 129 124 120 113 109 118 122 125 119 132 117 144 115 148 128 112 110 127 128 128 144 127 131 107 134 150 124 121 121 125 137 114 131 105 119 146 136 123 120 127 121 116 130 117 117 127 121 118 137 119 130 110 118 118 116 120 132 118 126 120 117 137 118 123 131 131 108 151 117 122 119 113</counts>
			</dataPoints>
		</scan>
	</xrdMeasurement>
</xrdMeasurements>