File: data/XRD/XG-Sauerstoff/XG-600/W6823-1B_XG_Sauerstoff_600.xrdml
<xrdMeasurements xmlns="http://www.xrdml.com/XRDMeasurement/2.1" xmlns:xsi="http://www.w3.org/2001/XMLSchema-instance" xsi:schemaLocation="http://www.xrdml.com/XRDMeasurement/2.1 http://www.xrdml.com/XRDMeasurement/2.1/XRDMeasurement.xsd" status="Completed">
	<comment>
		<entry>Configuration=Factory configuration, Owner=User-1, Creation date=7/8/2013 4:01:53 PM</entry>
		<entry>Goniometer=PW3050/65 (Theta/2Theta); Minimum step size 2Theta:0.0001; Minimum step size Omega:0.0001</entry>
		<entry>Sample stage=MRD Cradle; Minimum step size Phi:0.01; Minimum step size Chi:0.01; Minimum step size X:0.01; Minimum step size Y:0.01; Minimum step size Z:0.001</entry>
		<entry>Diffractometer system=XPERT-PRO</entry>
		<entry>Measurement program=C:\PANalytical\Data Collector\Programs\Jorrit\2thom\_absolute_2th-om_10-130deg_PIXscan_56min.xrdmp, Identifier={15BCCF57-2807-42BD-B5B9-ECC0B3DC9284}</entry>
		<entry>Batch program=C:\PANalytical\Data Collector\Programs\SimonL\batch4x_2thom_10-130°_z9.1_x0,10,20,30_y0_57min.xrdmp, Identifier={EED9823A-2BEB-424C-9252-345C4EF2834A}</entry>
	</comment>
	<sample type="To be analyzed">
		<id></id>
		<name></name>
		<preparedBy></preparedBy>
	</sample>
	<xrdMeasurement measurementType="Scan" status="Completed" sampleMode="Reflection">
		<comment>
			<entry>_absolute_2th-om_10-130deg_PIXscan_56min</entry>
			<entry>PHD Lower Level = 4.83 (keV), PHD Upper Level = 11.27 (keV)</entry>
		</comment>
		<usedWavelength intended="K-Alpha 1">
			<kAlpha1 unit="Angstrom">1.5405980</kAlpha1>
			<kAlpha2 unit="Angstrom">1.5444260</kAlpha2>
			<kBeta unit="Angstrom">1.3922500</kBeta>
			<ratioKAlpha2KAlpha1>0.5000</ratioKAlpha2KAlpha1>
		</usedWavelength>
		<incidentBeamPath>
			<radius unit="mm">320.00</radius>
			<xRayTube id="1010048" name="Empyrean Cu LFF HR (9430 033 7310x) DK442154">
				<tension unit="kV">40.0</tension>
				<current unit="mA">40.0</current>
				<anodeMaterial>Cu</anodeMaterial>
				<focus type="Line">
					<length unit="mm">12.0</length>
					<width unit="mm">0.4</width>
					<takeOffAngle unit="deg">4.2</takeOffAngle>
				</focus>
			</xRayTube>
			<xRayMirror id="27010001" name="Inc. Beam Cu W/Si (parabolic MRD)" hybrid="false">
				<crystal type="Graded" shape="Parabolic">W/Si</crystal>
				<acceptanceAngle unit="deg">0.800</acceptanceAngle>
				<length unit="mm">60.0</length>
			</xRayMirror>
			<sollerSlit id="21010002" name="Soller slits 0.04 rad.">
				<opening unit="rad">0.0400</opening>
			</sollerSlit>
			<mask id="22030007" name="Fixed mask 2 mm">
				<distanceToSample unit="mm">220.00</distanceToSample>
				<width unit="mm">2.00</width>
			</mask>
			<divergenceSlit id="22010007" name="Fixed slit 1/8°" xsi:type="fixedDivergenceSlitType">
				<distanceToSample unit="mm">220.00</distanceToSample>
				<height unit="mm">0.19</height>
			</divergenceSlit>
		</incidentBeamPath>
		<diffractedBeamPath>
			<radius unit="mm">320.00</radius>
			<sollerSlit id="21010002" name="Soller slits 0.04 rad.">
				<opening unit="rad">0.0400</opening>
			</sollerSlit>
			<receivingSlit id="22010001" name="Fixed slit 4°">
				<height unit="mm">5.88</height>
			</receivingSlit>
			<detector id="7010017" name="PIXcel3D 1x1 detector" xsi:type="areaDetectorType">
				<phd unit="%">
					<lowerLevel>30.0</lowerLevel>
					<upperLevel>70.0</upperLevel>
				</phd>
				<mode>Scanning</mode>
				<activeChannelsEquatorial>255</activeChannelsEquatorial>
				<activeChannelsAxial>255</activeChannelsAxial>
				<pitchEquatorial unit="mm">0.05500</pitchEquatorial>
				<pitchAxial unit="mm">0.05500</pitchAxial>
				<readOutPeriod unit="seconds">0.135</readOutPeriod>
			</detector>
		</diffractedBeamPath>
		<scan appendNumber="0" mode="Continuous" scanAxis="2Theta-Omega" status="Completed">
			<header>
				<startTimeStamp>2024-09-11T20:57:08+02:00</startTimeStamp>
				<endTimeStamp>2024-09-11T21:53:14+02:00</endTimeStamp>
				<author>
					<name>PRO-MRD</name>
				</author>
				<source>
					<applicationSoftware version="6.1b">Data Collector</applicationSoftware>
					<instrumentControlSoftware version="7.0E 20130304">XPERT-PRO</instrumentControlSoftware>
					<instrumentID>0000000011142674</instrumentID>
				</source>
			</header>
			<dataPoints>
				<positions axis="2Theta" unit="deg">
					<startPosition>9.99826193</startPosition>
					<endPosition>129.99755682</endPosition>
				</positions>
				<positions axis="Omega" unit="deg">
					<startPosition>4.99913096</startPosition>
					<endPosition>64.99877841</endPosition>
				</positions>
				<positions axis="Phi" unit="deg">
					<commonPosition>0.00</commonPosition>
				</positions>
				<positions axis="Chi" unit="deg">
					<commonPosition>0.00</commonPosition>
				</positions>
				<positions axis="X" unit="mm">
					<commonPosition>20.00</commonPosition>
				</positions>
				<positions axis="Y" unit="mm">
					<commonPosition>0.00</commonPosition>
				</positions>
				<positions axis="Z" unit="mm">
					<commonPosition>9.100</commonPosition>
				</positions>
				<commonCountingTime unit="seconds">32.895</commonCountingTime>
				<counts 201 191 219 183 209 186 225 198 200 195 190 176 211 222 181 185 185 200 212 184 217 200 202 190 201 176 219 188 200 210 177 200 226 183 215 187 167 208 180 215 215 190 184 192 199 203 200 180 229 198 188 181 216 212 215 180 197 198 201 213 203 190 177 189 205 194 194 194 188 207 200 184 210 220 196 203 172 174 194 197 183 202 182 190 165 192 186 194 193 201 178 222 179 192 196 172 191 203 166 204 183 192 189 177 181 203 190 192 186 205 173 196 160 196 186 189 194 210 202 192 181 200 196 181 174 213 211 198 200 201 186 175 193 216 215 184 217 196 215 191 175 174 183 183 203 216 159 199 189 178 207 207 197 171 213 184 202 198 184 195 191 184 180 206 183 146 170 175 177 200 184 207 193 183 155 178 174 184 177 160 151 193 171 194 165 185 161 191 175 180 180 174 182 184 187 189 201 165 186 187 190 156 170 176 193 200 190 172 197 160 191 189 183 178 164 178 200 176 169 181 168 197 169 174 184 159 188 187 180 187 153 183 180 157 187 175 162 215 177 173 154 173 203 173 171 186 167 183 175 189 177 181 169 161 159 203 164 201 188 162 165 157 182 185 189 156 181 185 175 159 162 191 176 169 181 176 185 185 155 188 165 175 171 163 187 178 207 188 166 168 175 180 179 174 171 179 167 176 156 169 182 194 204 164 184 201 198 164 160 144 156 156 187 181 180 183 151 152 175 167 166 145 185 180 168 174 182 171 162 186 166 187 182 188 180 171 185 153 170 180 149 181 185 160 178 159 153 189 178 170 192 182 178 188 194 169 188 171 164 163 180 169 181 164 183 146 161 148 168 149 182 159 180 158 173 154 153 173 184 174 174 176 158 128 166 165 155 169 162 175 156 175 173 161 161 151 164 174 162 157 157 159 155 166 162 182 171 157 161 169 149 167 166 177 205 159 159 150 189 170 150 154 166 177 158 138 188 155 145 175 170 130 155 161 172 175 168 160 164 149 162 180 161 177 163 154 175 161 164 163 152 178 148 171 179 185 146 195 165 176 155 144 159 157 163 172 171 169 173 174 172 160 176 163 175 152 155 143 155 167 152 161 157 156 132 151 160 150 162 179 160 149 168 157 171 153 153 172 163 150 166 160 166 143 185 162 164 179 166 189 179 164 146 159 143 152 164 178 165 154 154 152 160 156 154 178 156 145 160 160 184 163 133 166 170 167 159 163 161 164 176 150 181 176 162 160 161 176 148 169 152 163 172 168 162 153 164 153 186 162 153 176 163 168 166 161 143 152 178 151 157 158 169 165 156 154 153 137 189 177 168 168 158 163 177 184 162 145 150 164 156 167 184 153 177 162 176 181 169 164 155 185 157 182 158 173 158 149 160 172 139 139 150 177 162 159 162 165 170 150 159 161 178 162 153 171 188 180 173 179 174 181 179 160 182 161 152 159 182 154 166 141 153 140 158 157 181 146 168 158 180 156 147 163 159 154 181 158 173 127 167 179 152 160 171 178 171 167 165 166 196 154 155 162 171 183 175 152 158 176 155 173 177 162 166 145 162 164 154 164 177 169 170 175 158 178 181 153 164 168 178 158 181 166 165 169 157 194 194 166 148 143 142 170 181 160 163 161 176 149 175 155 171 159 164 158 165 175 170 152 189 168 188 159 180 164 151 160 158 163 184 168 153 187 153 161 179 158 180 173 173 150 172 178 145 152 161 153 148 163 156 136 157 175 138 162 151 160 182 163 164 181 169 142 168 167 157 162 175 162 173 175 171 159 186 171 160 177 155 162 168 155 157 165 164 180 182 146 169 167 170 181 163 177 148 175 152 172 160 191 149 171 171 168 167 155 171 171 162 173 151 180 167 165 181 167 163 167 194 163 160 173 140 171 157 167 179 173 177 178 166 133 180 165 146 164 175 169 169 173 169 149 155 160 174 173 169 178 163 168 149 176 153 185 161 186 206 149 154 171 161 170 177 166 178 150 151 172 201 180 164 176 147 179 179 179 178 177 201 157 173 164 179 179 147 167 173 171 175 159 164 178 176 161 169 169 168 169 158 171 184 157 175 192 153 173 151 188 162 186 167 145 160 179 181 181 191 198 163 149 183 163 152 155 160 183 169 161 170 151 196 178 154 186 165 174 177 195 187 160 166 164 186 158 179 149 144 153 165 181 168 185 185 175 134 176 166 192 194 171 166 177 177 181 156 167 172 153 160 193 172 175 162 168 160 159 163 135 187 178 179 184 173 187 174 160 156 146 185 190 160 169 154 174 157 159 182 173 175 195 189 165 173 150 170 183 156 169 168 175 155 150 169 188 169 154 174 192 182 156 173 182 144 162 176 175 173 170 160 165 175 177 191 170 163 174 158 168 182 176 186 169 189 146 167 185 185 195 179 156 165 177 167 145 178 173 171 176 185 171 184 160 177 171 188 190 173 157 159 152 170 179 148 175 187 170 134 180 158 138 168 173 146 160 192 171 166 181 166 165 162 159 165 168 163 170 158 169 197 169 166 171 160 182 168 170 165 172 182 187 163 157 167 215 168 160 171 160 183 176 184 175 167 166 174 167 170 169 175 157 188 169 174 168 169 182 169 174 156 169 143 174 170 168 166 181 174 175 175 161 182 166 138 150 190 147 174 171 181 186 173 172 147 183 203 153 171 164 162 158 173 198 155 179 160 180 148 160 173 168 173 205 195 175 163 166 158 174 194 195 168 156 171 138 160 177 194 171 157 179 179 169 172 188 167 150 168 186 167 163 172 182 190 168 175 166 155 175 179 180 166 158 148 172 163 169 160 156 186 176 149 189 179 190 153 168 189 163 165 177 170 165 189 181 171 156 168 175 163 138 179 165 179 165 185 170 169 174 158 177 151 168 171 150 160 184 184 167 194 176 160 164 158 141 170 195 154 190 153 169 168 173 164 168 149 164 156 148 156 177 149 162 162 197 179 170 155 170 161 166 149 175 154 133 165 146 145 145 150 158 171 173 159 163 190 173 167 151 156 150 178 166 160 163 181 169 174 148 175 168 180 147 153 142 174 167 181 164 172 143 153 156 130 179 163 141 165 147 145 153 164 157 131 172 156 164 170 161 134 160 158 167 137 172 149 188 160 159 129 162 155 171 172 195 149 168 181 148 181 167 158 156 157 163 157 166 149 160 137 156 178 172 137 138 153 170 165 150 175 140 149 177 167 177 150 161 177 185 167 133 141 148 164 150 159 137 157 130 153 155 160 155 156 153 185 170 144 162 181 156 144 153 131 153 142 176 148 138 151 154 168 150 113 136 135 163 143 129 146 149 157 143 165 151 165 162 132 182 140 146 158 178 149 133 157 154 151 166 142 154 127 149 155 138 168 130 112 162 152 151 146 138 145 171 130 130 161 134 154 159 141 141 159 151 158 160 140 145 164 155 154 144 164 143 145 137 171 142 142 166 160 146 154 161 142 129 139 129 167 144 165 170 130 153 155 144 135 149 141 161 165 141 148 136 139 135 134 134 159 161 135 136 140 116 145 166 131 151 173 129 148 172 148 137 150 146 147 148 135 158 147 170 138 146 143 146 147 148 166 146 142 141 143 154 136 156 138 133 133 138 168 133 154 158 143 144 137 146 154 153 136 143 144 138 147 161 133 152 145 138 132 150 150 154 129 157 160 151 160 144 138 148 125 129 163 160 136 153 149 141 143 145 151 150 159 144 136 136 150 139 127 114 137 145 148 145 128 147 133 137 148 126 148 124 132 135 147 142 147 149 141 151 139 131 150 138 126 125 134 135 150 143 173 105 145 131 128 131 149 167 131 118 145 138 138 148 149 125 142 158 140 156 125 143 144 147 133 153 129 127 141 148 142 128 127 148 144 135 135 133 150 142 134 133 116 124 159 162 119 131 127 146 145 152 136 133 133 117 145 126 132 140 128 130 124 146 133 138 129 120 129 134 125 134 151 153 138 137 121 120 136 136 120 119 133 143 149 110 121 123 124 139 154 134 125 135 126 145 128 125 116 120 141 140 125 147 139 123 142 141 128 147 128 158 128 125 154 139 140 129 135 130 132 123 141 127 127 139 105 113 132 137 140 125 110 131 125 112 157 133 125 123 136 128 128 126 127 128 142 151 130 139 133 135 166 134 114 134 158 141 138 151 107 137 145 124 152 139 135 139 124 123 145 118 115 142 140 117 119 115 127 143 133 113 107 127 131 127 134 121 122 143 144 141 138 129 140 111 141 116 132 120 120 116 123 135 119 140 129 127 125 136 145 122 113 134 126 133 128 132 124 114 125 127 125 128 138 132 145 111 137 135 134 118 111 128 140 140 137 121 119 117 139 134 125 112 131 138 135 144 117 132 120 107 113 135 128 135 115 120 141 131 110 148 133 130 104 105 128 120 136 125 130 117 140 126 121 129 120 115 111 117 125 107 142 135 107 124 129 135 113 118 117 146 131 111 129 139 108 119 115 118 125 135 146 118 120 125 131 118 108 118 134 133 117 108 144 129 142 103 108 134 123 129 112 103 118 124 116 112 108 143 125 123 118 109 99 120 136 135 113 152 121 122 104 121 125 124 119 133 152 113 122 95 124 117 137 98 119 118 127 125 119 121 128 124 113 110 117 103 130 138 117 120 128 128 114 117 118 119 129 138 128 114 109 107 121 108 113 114 132 113 102 148 125 138 121 112 108 110 108 124 102 108 112 129 119 114 126 123 129 103 123 119 127 111 137 116 125 114 123 98 105 117 125 104 110 116 128 125 120 127 118 125 112 118 130 131 122 100 110 107 113 114 131 98 121 112 119 123 134 119 133 108 104 116 117 120 127 101 116 103 109 110 108 119 118 104 117 124 125 106 123 127 111 113 108 118 110 121 123 120 114 106 109 130 143 125 104 124 107 128 119 100 98 128 104 143 116 103 121 120 118 125 116 130 115 125 113 123 106 119 109 111 103 115 107 127 118 115 114 118 121 117 113 113 120 86 109 104 126 116 108 122 109 109 121 129 122 115 111 113 115 116 116 96 135 118 111 97 97 112 102 115 136 124 111 129 101 108 126 115 120 143 103 111 124 119 104 112 113 115 104 124 111 127 122 117 117 113 123 105 130 94 116 92 118 122 113 101 98 103 112 108 116 138 108 110 125 134 122 113 103 122 118 92 95 92 118 97 118 109 109 125 116 110 112 132 88 98 126 116 108 110 115 112 92 114 117 116 101 97 145 137 115 134 105 112 107 106 120 138 132 98 100 111 105 129 112 102 111 139 100 115 121 117 128 100 118 96 121 123 109 119 104 145 98 111 103 132 105 122 121 117 125 112 127 107 121 126 127 127 88 108 117 120 128 123 112 136 106 109 118 111 111 121 104 116 114 115 105 123 111 116 113 90 101 128 112 135 123 133 116 108 108 127 132 126 118 131 121 109 104 106 135 111 110 124 111 124 129 101 129 108 107 109 125 123 126 112 116 125 99 121 132 91 87 120 130 128 122 109 108 96 129 128 113 115 120 107 112 102 98 124 128 127 99 107 113 100 127 114 104 117 110 118 122 120 124 107 104 124 107 105 117 82 98 120 122 116 104 112 123 128 101 111 99 97 113 109 116 107 105 114 96 139 109 132 128 118 106 123 132 129 114 104 97 100 114 110 105 110 95 137 110 105 108 113 112 99 102 122 98 100 117 93 96 119 124 110 97 122 109 115 115 105 98 112 114 119 116 96 83 119 113 120 137 114 101 112 104 104 105 108 118 99 108 101 92 117 120 115 77 111 110 132 101 84 116 107 106 98 117 109 113 127 117 110 126 127 127 121 118 105 120 120 109 123 110 128 98 116 99 111 116 115 106 96 107 105 109 101 117 132 114 119 103 107 127 115 129 100 119 111 122 116 106 101 122 104 114 123 125 125 100 94 111 126 119 113 122 115 101 116 97 112 112 96 106 97 132 116 121 122 115 122 113 108 94 92 105 119 130 116 106 87 94 111 114 126 115 111 103 117 92 127 120 108 104 108 93 114 104 108 124 114 100 106 91 107 118 105 122 101 112 107 114 124 112 113 109 119 103 112 111 117 100 98 117 125 131 120 104 126 102 118 98 107 108 122 104 122 115 97 130 121 101 104 109 137 98 113 115 116 116 135 116 117 142 108 115 138 113 130 115 108 120 112 106 123 101 119 129 111 117 120 106 124 117 119 100 108 103 108 116 117 116 123 106 122 120 119 111 118 108 116 116 118 126 96 123 116 126 106 116 116 116 117 109 108 119 123 134 125 115 110 132 103 119 105 118 113 104 126 129 119 128 106 111 134 118 119 120 116 119 110 112 97 120 104 120 132 129 110 110 111 103 128 110 117 121 106 111 122 123 123 100 99 118 128 102 123 113 118 100 118 125 136 123 102 126 112 124 128 119 100 122 114 119 101 116 113 104 133 114 127 109 92 125 135 123 116 103 99 117 98 108 100 95 122 131 111 104 107 105 124 110 120 127 123 115 115 111 95 113 121 136 112 105 128 111 111 124 127 137 112 106 109 123 104 91 110 113 109 124 120 97 120 108 101 114 105 121 109 122 99 105 112 126 127 94 125 90 118 136 119 126 118 103 98 123 133 115 115 118 123 122 115 108 108 98 124 109 105 105 93 113 100 99 122 100 127 121 112 109 98 114 126 95 118 95 110 115 121 117 117 114 116 99 107 116 116 111 113 119 90 121 121 123 128 115 112 113 123 105 108 111 120 111 103 100 125 101 120 130 126 98 123 117 117 91 122 111 108 123 98 117 105 125 122 127 125 115 111 116 123 112 114 91 109 113 129 111 112 101 123 117 111 104 108 111 122 94 101 111 124 115 83 115 140 88 124 110 106 105 128 114 131 131 133 127 121 117 110 114 119 122 110 131 123 98 122 124 127 132 110 103 135 123 120 126 118 106 116 129 105 109 118 119 115 130 122 124 114 110 111 131 107 111 130 113 96 125 133 128 122 123 122 117 123 119 111 120 105 118 129 132 112 113 121 101 108 119 138 115 97 108 121 117 132 119 107 113 118 104 113 119 95 107 115 110 97 116 114 105 117 119 110 109 97 124 117 132 135 119 107 97 99 131 137 123 110 117 126 126 117 128 119 108 125 127 109 137 116 119 109 127 120 123 99 109 119 92 102 108 99 107 112 118 100 133 118 105 130 117 129 108 131 119 119 107 118 118 114 136 120 100 139 118 120 91 121 116 105 127 120 114 125 110 103 108 118 142 115 117 118 114 104 117 117 99 128 109 99 102 112 98 114 113 126 119 121 134 120 132 129 129 99 128 131 106 133 125 123 125 113 134 126 121 112 96 123 111 92 111 124 115 133 116 117 117 124 122 124 126 108 131 120 115 121 114 109 101 114 117 126 131 140 129 110 108 114 133 120 101 110 117 123 120 141 127 112 113 137 130 123 144 109 119 123 108 111 140 113 147 128 115 120 132 122 116 112 129 123 128 132 99 106 118 131 131 147 115 102 131 120 104 112 124 134 111 139 128 127 132 114 123 122 132 130 134 104 135 122 114 141 157 125 139 126 117 124 139 132 125 118 135 91 136 128 140 143 150 124 119 132 121 138 119 136 141 142 133 139 133 119 170 125 137 131 131 112 144 140 121 129 122 126 126 119 143 144 117 135 108 123 137 117 130 125 146 136 140 125 131 102 136 139 130 133 135 137 137 137 136 135 89 119 114 124 158 127 139 129 124 107 121 105 128 135 121 133 157 121 141 131 147 120 144 143 121 129 150 129 147 131 130 129 139 143 147 149 140 121 136 137 135 156 142 138 138 128 123 126 153 143 126 132 149 119 141 147 143 146 140 158 135 140 157 129 153 165 162 176 159 162 159 172 164 157 155 182 169 209 163 191 202 214 204 207 222 204 231 217 215 225 189 188 215 211 187 204 187 197 213 206 206 191 189 174 186 190 166 152 153 165 188 179 139 167 166 136 162 183 136 142 149 144 150 133 149 118 138 120 121 158 147 125 133 140 146 111 121 127 166 132 121 129 133 125 135 151 149 113 141 131 133 113 137 127 114 131 129 138 140 141 134 125 133 122 122 121 123 136 119 128 148 147 104 117 123 117 98 126 111 121 120 120 127 120 129 138 116 116 107 107 121 123 124 126 120 128 119 125 126 123 122 131 131 125 139 114 129 116 122 140 116 121 105 132 133 112 114 109 119 106 124 129 134 106 117 142 122 138 141 115 121 121 137 119 119 128 102 132 104 123 117 135 120 123 142 117 124 124 130 117 125 123 117 108 116 110 127 124 111 145 143 119 112 153 127 116 118 137 119 134 119 101 113 127 113 131 126 127 109 120 124 109 123 123 114 117 124 113 120 123 109 149 117 129 100 118 101 120 126 133 135 119 117 126 105 104 127 105 122 127 122 119 127 130 103 117 117 118 129 118 129 113 110 109 121 110 138 118 121 117 116 89 122 134 116 136 115 145 136 104 114 128 127 132 114 137 144 125 107 116 125 121 126 130 134 123 152 111 124 129 119 115 109 122 143 131 125 114 138 126 123 132 130 136 120 117 121 121 124 125 110 133 123 108 129 134 129 94 146 108 122 118 121 119 120 121 113 135 102 114 107 117 119 125 116 117 122 112 112 130 115 120 121 136 104 120 125 122 120 113 121 114 117 134 121 117 111 126 121 110 115 127 126 105 113 118 106 104 136 134 145 126 100 135 127 131 111 116 121 107 127 87 129 124 100 124 117 133 110 119 139 128 122 135 101 131 112 118 131 116 136 106 122 130 106 110 117 136 125 127 127 121 130 120 117 123 129 131 121 120 117 116 114 102 137 126 117 104 125 124 137 120 114 128 118 139 128 126 123 128 115 102 132 126 125 136 98 127 141 119 120 111 126 117 133 106 102 113 121 128 120 117 126 126 112 105 121 125 117 107 114 126 119 120 132 125 106 115 135 118 126 121 113 134 153 101 130 129 133 109 116 122 110 134 138 127 121 130 127 132 115 115 121 127 131 120 128 112 117 121 121 139 117 97 125 118 121 114 128 137 105 141 135 124 126 144 135 113 125 138 111 124 117 136 109 124 135 116 127 136 140 128 101 122 106 118 101 122 127 121 114 120 135 105 132 131 95 123 130 126 132 127 117 128 113 125 117 131 137 118 114 129 109 127 117 124 127 124 128 121 123 140 138 118 135 115 141 115 127 136 127 122 133 145 115 134 119 124 101 126 108 113 128 131 116 129 111 128 109 150 140 106 131 110 106 110 105 116 108 130 129 137 112 129 140 120 92 119 127 103 133 111 127 129 109 110 142 117 101 132 129 135 126 119 127 117 136 126 129 143 110 123 119 109 111 131 127 133 124 131 121 115 139 140 112 120 101 127 131 114 139 120 126 109 130 120 136 144 110 120 133 123 123 136 127 116 137 116 128 117 118 106 138 125 113 124 119 113 152 131 137 138 115 127 124 113 126 122 127 126 134 120 119 123 146 131 131 110 131 124 142 119 126 144 122 127 134 117 126 122 128 115 128 122 130 126 97 114 134 129 134 129 131 109 129 114 145 126 127 120 126 139 127 123 141 103 123 149 116 107 104 130 114 141 143 123 116 135 114 128 114 136 141 128 132 131 120 118 98 104 141 122 122 123 130 129 123 104 125 126 119 131 132 131 116 116 103 149 123 116 127 114 128 130 108 114 127 114 104 129 103 120 104 130 116 137 114 99 135 128 119 148 120 136 120 120 130 124 116 130 121 128 124 137 120 118 104 116 131 148 129 111 129 114 117 144 121 106 144 113 123 111 131 125 133 119 126 133 115 117 126 131 114 118 115 127 113 102 116 118 113 113 126 124 121 134 130 123 115 130 124 110 123 115 110 121 132 120 128 104 98 141 144 127 110 132 107 120 126 109 121 125 116 102 120 122 112 116 124 130 121 123 121 108 122 115 112 134 114 98 130 125 134 117 117 116 113 103 105 113 110 128 116 127 108 101 134 131 103 108 115 105 141 124 130 137 115 130 112 120 122 123 126 132 123 113 120 117 116 145 125 116 102 147 107 136 142 121 116 100 136 142 117 137 137 126 130 125 102 106 128 113 128 137 129 128 122 109 118 118 136 143 113 111 115 103 128 123 147 113 131 116 106 125 97 133 109 129 123 109 131 115 120 106 109 111 129 116 129 131 129 116 147 123 114 115 118 115 113 120 145 105 110 102 115 124 104 114 125 134 131 125 130 135 134 123 122 139 126 132 118 124 124 133 147 104 118 116 121 132 107 135 107 113 128 112 115 118 129 114 112 130 110 112 112 114 129 118 126 127 106 132 109 133 138 138 122 126 107 122 109 129 134 100 111 100 136 122 127 116 132 109 101 105 115 123 117 125 117 106 121 120 110 104 119 124 126 125 102 132 106 129 114 129 123 128 122 115 119 123 139 132 126 114 119 124 118 113 126 126 105 125 122 125 125 131 120 127 127 117 114 116 128 119 127 127 119 145 132 141 127 113 112 140 110 123 131 126 118 125 128 112 115 132 127 126 118 131 117 136 132 129 128 110 134 125 134 130 111 133 117 120 122 134 115 124 119 116 122 148 122 128 132 134 122 145 113 127 132 110 134 131 127 134 133 129 109 112 129 112 121 130 135 119 140 124 138 120 112 141 121 110 152 130 114 106 109 119 129 137 110 114 128 112 114 128 133 128 134 165 126 118 119 132 106 114 118 131 123 131 139 106 131 130 115 115 104 120 115 122 123 124 130 124 125 135 116 113 110 119 128 128 131 123 124 129 117 108 128 136 140 126 120 125 128 128 125 132 155 120 108 126 118 129 114 113 122 120 120 120 128 135 108 122 135 144 134 112 110 112 134 111 120 119 119 123 123 107 113 126 127 128 153 130 103 101 110 112 127 109 145 124 127 127 113 129 120 128 121 122 130 130 121 117 114 114 138 114 116 109 121 127 129 111 106 137 129 137 133 106 132 116 105 127 115 133 108 131 108 107 121 111 110 123 123 119 112 126 133 114 129 121 120 135 120 106 115 121 113 127 110 126 132 114 118 150 116 113 121 116 132 125 124 113 118 102 124 139 127 124 132 113 118 112 144 141 138 141 130 122 134 120 131 114 105 105 117 118 125 145 105 106 135 122 125 128 117 119 134 122 100 139 135 119 116 112 145 123 134 123 123 137 121 121 111 106 132 135 120 125 124 124 103 126 105 111 114 114 119 136 123 108 128 122 130 110 111 116 132 112 122 129 130 122 117 131 99 130 135 145 137 133 121 129 140 129 145 132 114 121 139 116 94 97 110 121 124 110 121 122 112 113 129 134 122 137 126 122 118 133 116 107 105 119 133 125 122 119 120 154 117 120 135 143 118 131 128 138 122 124 127 139 111 117 123 132 116 120 134 109 117 107 126 118 134 110 106 136 141 125 116 126 123 126 124 123 126 127 98 129 109 108 111 117 139 124 126 137 140 123 112 126 127 110 106 138 134 143 134 130 119 122 127 124 111 119 126 134 122 138 116 94 113 128 120 104 138 119 115 127 120 96 123 103 123 113 113 124 119 115 100 125 136 127 109 136 122 111 123 138 112 112 150 127 116 121 124 126 137 136 107 124 129 120 127 147 116 98 103 130 138 123 115 115 123 103 111 121 155 143 147 118 130 115 115 120 122 109 114 136 121 112 120 126 124 134 113 141 128 117 132 104 123 109 123 137 109 118 105 116 108 131 119 116 128 109 120 105 115 145 135 102 122 135 133 140 120 113 93 126 118 116 109 110 118 98 148 112 115 118 131 126 111 105 126 134 118 127 101 113 99 139 124 138 106 119 120 119 96 116 104 130 120 121 128 106 116 129 120 115 121 117 137 121 119 140 117 134 129 132 141 123 124 120 111 114 137 132 140 91 126 131 112 151 133 136 134 107 119 122 124 121 122 124 120 110 122 94 117 108 121 145 139 122 122 135 132 137 123 131 127 125 130 113 135 115 126 142 155 114 143 113 123 115 117 115 114 106 145 115 123 114 113 127 137 168 121 137 128 112 120 128 114 96 119 114 128 131 130 116 140 112 133 115 113 135 113 112 118 148 111 117 133 120 125 118 105 123 141 145 123 122 128 128 131 141 124 112 117 105 146 138 114 135 128 116 105 136 137 116 110 115 99 136 138 108 126 142 128 131 118 115 110 125 124 125 121 122 117 111 92 103 112 126 113 126 107 120 114 136 137 117 127 123 134 133 125 135 106 132 128 136 129 119 117 120 126 117 119 131 127 122 104 114 116 131 110 99 110 113 124 110 128 123 125 116 132 124 114 143 151 138 109 130 145 123 110 114 132 128 112 103 134 129 120 126 114 135 115 107 118 117 116 142 119 116 109 126 130 113 122 112 118 122 138 121 115 114 129 142 107 133 142 102 130 130 104 117 118 113 142 128 115 147 135 106 124 134 127 137 113 124 131 135 136 131 119 128 125 101 129 129 135 135 136 126 127 114 123 119 117 130 122 139 143 135 131 133 117 126 111 129 119 125 114 141 114 126 132 120 125 124 142 135 142 143 113 137 138 124 118 120 125 121 120 132 112 117 117 131 126 141 136 142 122 140 130 136 133 114 131 112 123 122 125 130 120 127 110 106 125 112 130 114 125 105 140 115 115 123 114 112 144 145 127 137 127 138 137 124 135 141 129 133 127 123 142 124 120 139 113 136 127 116 125 117 119 112 132 126 112 131 146 120 119 136 145 129 128 122 138 143 127 119 138 127 116 124 111 118 131 118 119 140 139 142 131 134 118 135 109 122 118 128 124 121 118 111 138 125 144 144 145 123 125 130 122 126 141 97 107 121 139 122 128 130 119 120 125 122 118 132 117 136 116 142 141 141 130 132 122 126 118 108 124 124 139 125 126 117 106 135 125 139 120 134 112 123 123 115 137 105 125 107 125 124 128 107 128 155 130 118 108 123 129 124 88 116 130 133 133 124 153 128 122 113 131 127 123 116 133 141 120 128 115 124 122 128 124 119 122 126 123 127 140 108 114 113 136 129 148 94 119 124 135 111 128 124 120 165 107 119 132 141 136 126 113 144 121 114 125 126 147 103 136 127 128 134 121 115 129 119 114 128 124 121 126 115 115 129 132 108 137 151 127 125 131 115 141 110 132 124 138 99 129 124 128 132 110 127 107 120 115 138 129 131 114 131 130 124 121 113 109 111 131 135 124 124 113 108 128 128 132 119 130 116 118 127 119 137 134 113 127 139 127 111 136 132 101 126 110 119 114 131 124 130 137 122 124 118 115 129 133 136 122 104 142 129 113 130 134 119 124 133 118 125 131 124 96 116 137 125 123 120 113 131 144 99 117 135 122 126 132 114 135 118 142 130 129 125 115 122 136 131 127 122 126 117 126 119 151 111 122 132 124 119 118 126 120 101 131 120 134 111 98 108 119 141 132 115 140 128 107 118 134 133 125 121 127 122 128 123 133 129 113 124 139 128 137 110 134 135 108 140 113 124 90 115 112 136 133 122 126 136 159 108 134 129 121 138 115 145 117 101 131 132 120 151 139 111 139 127 109 111 136 119 124 117 113 138 127 120 108 123 131 127 118 124 122 127 138 127 135 114 140 136 113 117 136 120 137 135 135 119 128 129 122 119 121 116 137 139 131 126 134 116 134 134 142 115 131 113 114 93 122 113 119 105 129 113 123 138 105 107 101 130 128 123 120 123 114 137 124 149 131 112 114 132 126 147 153 139 128 138 133 127 117 112 112 121 116 133 122 112 113 119 133 118 117 116 115 115 114 122 124 126 112 116 93 119 131 124 126 154 129 137 132 118 129 100 130 129 120 105 146 117 122 123 133 124 124 122 128 121 121 127 128 124 141 115 133 134 114 134 128 138 132 125 123 115 119 111 116 122 118 122 108 117 134 131 129 133 145 119 127 129 109 124 123 118 132 128 123 127 149 122 134 119 127 115 93 128 124 115 109 114 120 104 119 127 133 132 127 116 121 118 136 134 121 96 122 113 114 134 114 124 122 123 128 101 129 135 109 118 104 128 108 109 115 122 148 124 133 139 134 115 108 126 132 120 120 123 110 109 115 151 110 117 102 114 128 131 117 127 104 111 114 130 110 127 110 116 113 125 116 133 115 119 124 114 120 115 131 141 128 139 112 111 116 119 119 141 131 116 105 130 107 114 111 111 115 109 132 131 131 98 132 103 107 104 126 135 138 126 119 134 119 125 123 121 112 135 117 125 141 143 105 125 124 132 116 115 101 126 129 125 113 127 106 119 130 116 125 123 130 118 123 117 118 129 121 127 127 109 119 123 120 116 126 112 123 133 123 123 110 135 123 111 113 115 133 110 129 124 112 118 121 117 113 122 133 134 127 124 120 130 123 116 110 123 124 121 116 131 117 119 125 127 125 105 101 122 131 118 115 121 120 123 114 121 136 132 112 125 88 123 112 110 107 128 137 126 135 107 121 131 135 143 110 129 130 128 140 127 119 108 123 115 144 124 110 150 135 128 117 120 97 126 111 122 114 134 123 135 123 134 117 120 112 117 127 115 108 118 137 107 121 122 110 137 115 122 109 119 124 122 111 99 101 122 108 125 136 134 117 140 132 140 126 136 117 144 125 140 126 124 112 123 115 129 133 126 114 118 109 122 107 107 131 128 140 125 117 109 134 118 144 129 123 132 117 129 126 108 124 124 118 107 112 118 149 116 135 112 135 120 139 127 123 117 108 92 114 105 116 125 138 156 118 133 135 126 128 125 120 139 110 117 131 129 139 132 133 155 132 114 124 134 101 117 116 133 133 117 125 116 134 112 126 127 128 125 125 118 127 152 151 114 101 111 111 124 134 140 115 92 124 113 107 146 120 138 121 131 137 131 112 106 114 134 116 120 126 127 125 127 138 157 101 120 133 123 135 118 117 132 128 122 123 136 134 113 122 141 110 149 102 124 125 147 142 139 116 132 130 125 115 123 106 115 123 135 137 111 114 138 101 128 119 149 131 131 121 145 123 110 127 124 111 135 122 115 126 111 131 134 128 100 99 119 115 129 116 109 113 98 121 105 120 118 121 142 142 134 120 135 107 124 117 129 134 145 129 131 104 119 132 119 127 121 139 136 121 121 111 125 123 118 122 119 117 118 141 118 119 127 141 115 112 132 132 117 125 118 123 142 113 114 144 118 114 114 115 121 126 123 126 126 123 116 141 133 121 128 126 112 125 119 117 130 120 127 149 140 128 116 104 127 129 130 108 132 125 122 135 122 137 123 146 116 132 119 127 130 139 138 128 111 126 131 127 120 140 126 116 139 136 138 130 112 124 128 133 114 143 132 135 132 115 124 139 109 125 137 135 115 133 96 119 103 112 125 111 135 135 128 139 123 117 124 130 130 124 105 122 131 133 116 112 126 108 116 122 104 121 140 113 124 117 116 132 141 118 129 104 98 125 128 122 131 121 123 136 135 119 137 113 137 122 123 120 120 132 123 123 140 120 122 125 118 117 129 114 115 111 129 139 130 133 109 129 129 100 131 108 114 124 140 105 119 141 129 111 120 120 118 125 129 130 135 134 101 125 137 107 122 105 138 134 110 110 110 121 115 107 115 133 134 135 121 130 108 131 129 143 138 133 135 114 113 124 119 126 135 130 118 108 124 138 147 138 116 115 128 144 120 127 115 154 140 126 117 136 133 133 109 108 123 113 142 131 128 131 112 124 149 126 139 126 149 129 132 138 128 121 148 137 139 124 140 105 127 111 122 134 125 121 126 115 137 123 127 123 123 117 145 128 132 120 133 123 139 115 136 146 133 116 111 126 134 129 100 143 123 119 134 116 136 136 128 119 127 119 123 143 115 139 122 109 127 126 121 134 104 150 142 131 135 137 121 136 108 119 126 99 142 121 124 122 129 126 139 127 118 113 147 127 118 121 129 134 126 125 143 143 109 137 129 122 126 110 131 98 141 121 112 114 118 123 131 111 115 122 124 108 123 139 132 129 136 138 139 138 127 129 119 120 139 129 130 124 116 120 126 126 119 116 123 138 135 102 140 148 122 148 120 124 120 133 120 118 114 120 124 118 146 134 137 123 152 122 132 145 126 115 133 136 117 134 115 137 109 116 123 107 115 152 121 119 143 121 139 109 134 130 122 123 134 123 124 119 125 111 115 114 118 113 136 110 138 134 148 115 113 130 103 129 139 138 103 144 109 112 119 131 119 144 112 142 124 141 106 134 129 133 121 125 109 112 130 131 135 132 107 121 144 114 108 116 120 107 151 116 122 137 139 109 111 116 146 122 119 116 104 125 122 134 121 116 127 130 135 125 128 131 123 111 127 138 116 127 116 132 136 124 109 118 117 127 125 143 131 110 131 136 112 121 125 119 130 116 121 126 129 131 125 120 122 112 131 135 123 123 122 139 116 116 130 113 145 122 104 141 117 139 141 122 133 122 100 111 128 137 126 126 112 119 151 113 134 125 122 118 133 134 140 134 155 137 141 129 115 128 119 123 120 111 141 125 135 132 118 123 143 150 139 124 119 140 139 159 131 142 123 140 156 133 142 127 125 152 147 147 138 159 121 126 158 116 143 126 157 164 162 145 139 158 151 151 161 138 120 168 143 134 118 157 155 168 137 133 135 142 165 134 142 155 132 123 133 144 139 140 145 144 130 153 137 134 139 122 144 145 147 127 140 136 140 142 131 132 156 133 133 140 114 119 115 143 126 130 123 118 129 131 138 123 144 100 141 124 113 127 128 126 135 111 138 124 113 119 121 132 123 110 122 107 135 153 119 150 152 141 103 153 134 118 132 122 143 129 142 120 124 136 109 117 133 117 133 119 107 121 130 130 114 132 149 130 135 143 114 116 131 131 125 123 113 117 135 113 106 109 116 95 123 127 144 121 126 118 129 130 123 112 147 126 112 115 105 142 119 141 114 118 155 130 147 108 124 126 126 115 122 120 106 100 122 123 124 136 145 132 152 122 110 130 106 115 145 124 132 139 129 140 120 131 115 138 130 117 117 143 144 119 130 124 123 129 131 124 139 122 114 99 148 104 127 144 116 113 146 113 136 132 95 123 116 125 117 138 122 109 118 120 129 122 109 122 143 142 117 119 108 117 125 123 117 119 131 126 120 118 120 129 119 129 140 135 117 112 132 119 116 138 119 123 132 113 129 124 132 101 120 107 99 106 122 102 126 134 104 113 126 111 135 126 123 131 132 135 126 137 136 155 134 122 112 138 129 109 144 141 122 134 106 135 97 129 127 106 129 106 100 111 121 120 118 139 122 120 129 126 132 114 138 126 133 123 121 121 117 106 133 109 134 112 126 130 131 119 137 132 131 136 122 133 154 129 130 115 128 148 114 120 123 114 125 142 120 131 107 108 150 126 125 124 120 119 111 121 137 124 142 133 129 130 127 101 137 125 133 128 125 132 130 111 122 119 128 129 138 118 131 110 113 113 125 110 121 124 116 144 119 132 118 118 129 128 108 138 149 136 109 110 117 113 109 120 105 131 114 141 122 131 135 124 124 133 135 127 103 122 117 107 113 116 116 126 125 117 104 122 113 137 113 132 131 138 145 127 111 135 135 142 102 127 118 126 119 130 126 105 112 128 135 127 135 120 127 122 113 131 129 126 124 130 119 126 115 116 131 120 122 108 107 119 126 110 110 145 132 138 141 139 130 108 126 114 142 125 126 86 125 138 133 118 130 119 107 107 142 134 146 146 113 129 123 116 122 115 134 121 90 113 124 134 134 123 129 116 139 123 116 137 130 138 134 138 124 134 128 121 136 146 128 128 143 119 116 114 126 111 129 100 132 120 160 106 128 133 129 116 125 129 126 119 114 127 137 134 129 144 130 123 127 107 109 130 141 142 113 112 133 98 121 101 119 126 138 102 114 111 109 97 118 122 108 130 112 116 124 120 142 107 129 123 104 135 116 127 128 127 124 125 133 118 133 150 123 119 130 116 138 125 134 129 116 123 121 145 126 125 139 117 106 135 146 139 128 118 123 117 119 115 126 113 123 145 109 131 122 132 121 98 123 116 118 119 138 128 132 111 100 115 142 111 131 136 133 111 119 131 132 113 104 111 109 112 131 102 120 129 112 143 120 138 118 143 119 131 107 132 126 132 133 113 143 117 132 113 106 142 114 113 103 127 163 106 106 114 134 127 133 127 113 140 128 120 133 113 126 112 117 121 115 84 105 116 135 123 114 131 143 147 120 109 111 116 103 127 121 114 128 112 120 148 117 132 123 130 99 114 125 107 107 137 125 127 102 102 108 129 122 141 128 126 125 133 122 112 112 121 102 116 127 117 125 146 131 121 139 132 131 115 135 125 103 119 106 125 106 134 133 120 105 128 103 107 110 130 127 110 144 119 111 117 133 130 122 104 112 131 110 107 121 113 126 147 130 152 115 122 122 161 116 132 123 133 128 136 113 113 103 117 110 141 139 119 115 121 109 114 122 123 117 118 103 108 123 127 111 135 127 115 125 132 120 147 122 128 104 116 121 106 107 116 119 146 106 115 128 132 142 154 129 110 136 116 127 130 143 143 132 127 139 128 128 122 127 134 124 137 130 114 115 128 108 122 117 128 115 134 128 134 125 110 121 109 116 133 123 140 102 113 114 123 119 132 125 111 120 102 127 143 130 141 132 136 137 114 121 132 121 135 143 106 125 119 100 124 133 116 113 116 120 130 113 127 143 126 121 129 122 122 123 132 137 130 103 134 128 136 133 112 132 118 121 99 113 118 120 115 119 134 129 115 119 119 129 135 122 114 111 137 117 106 110 125 143 130 135 117 107 125 107 115 117 116 105 110 126 141 132 131 151 124 117 120 122 128 107 128 135 141 112 145 115 112 118 117 143 117 125 123 141 112 143 122 129 136 110 132 156 120 121 117 118 136 110 115 106 105 123 125 141 128 119 110 128 125 112 122 138 111 134 111 131 139 124 126 123 115 115 120 115 117 124 130 112 124 123 125 143 133 141 115 139 135 125 123 118 132 112 147 131 119 112 127 124 132 100 131 119 132 131 113 121 110 133 106 130 112 127 128 121 134 131 138 114 136 127 120 119 130 133 119 108 122 127 139 123 130 117 135 124 105 151 128 132 130 113 99 137 120 152 126 110 129 105 116 120 138 149 122 139 126 153 126 114 114 152 132 119 115 130 111 123 128 116 140 126 105 105 126 104 135 115 136 129 129 141 128 126 123 126 119 128 128 138 109 111 136 118 141 117 114 94 120 138 120 137 132 120 119 127 123 147 116 115 105 124 131 136 124 118 124 135 110 125 118 125 147 126 138 126 124 143 134 115 113 127 123 117 136 131 109 140 126 140 111 166 118 132 112 127 112 127 117 135 123 133 115 114 105 118 124 120 120 130 121 119 127 100 119 117 119 114 125 120 112 117 133 133 111 138 122 115 124 101 104 136 133 128 112 136 121 138 127 121 116 118 126 125 128 109 113 117 123 122 141 117 113 140 137 112 127 122 131 112 121 103 119 126 104 112 121 103 124 112 133 108 126 102 116 134 131 116 131 126 131 132 120 108 110 126 102 108 123 119 128 115 101 102 110 104 133 133 124 122 127 106 115 115 135 135 105 119 124 133 97 117 134 128 117 120 111 123 135 108 112 136 114 119 137 121 126 133 130 139 112 94 126 98 118 111 113 127 102 126 135 144 117 104 133 107 146 128 132 115 106 122 112 143 123 123 129 108 133 120 127 129 111 130 109 126 134 144 115 111 141 115 125 117 124 136 119 123 123 113 104 116 107 134 131 119 138 107 144 95 113 119 131 117 125 109 113 109 106 112 115 124 127 125 116 139 122 111 122 152 108 133 102 115 102 136 129 116 102 117 120 113 129 112 126 131 123 97 128 123 109 134 108 108 120 121 121 112 138 117 122 128 121 127 129 125 123 117 128 119 110 136 108 106 91 115 124 133 125 119 106 118 105 120 101 95 148 117 128 127 131 122 122 113 116 124 122 114 116 128 113 109 122 124 115 124 113 110 110 113 117 85 120 100 121 117 106 115 112 124 125 133 120 116 122 102 114 87 124 126 115 120 109 93 138 103 147 132 110 97 111 118 122 124 125 109 121 111 109 104 109 130 107 138 114 116 128 124 128 120 119 121 133 129 119 130 125 103 115 107 119 122 129 110 113 102 127 122 108 125 132 121 109 98 116 147 126 127 111 127 121 130 117 115 115 126 144 116 130 128 131 121 110 129 123 119 140 119 119 126 145 123 103 138 145 111 98 128 116 112 138 112 132 130 122 110 119 110 123 114 133 121 106 129 128 135 121 124 116 128 113 106 117 116 109 124 116 139 110 140 126 101 125 119 114 116 114 118 134 122 129 124 98 116 124 110 122 122 115 119 125 105 126 135 128 116 126 112 125 128 110 120 103 126 140 127 125 122 116 112 106 127 125 120 125 129 144 104 129 125 114 129 120 160 109 119 120 131 118 108 135 117 120 131 130 117 108 105 127 116 141 132 131 143 107 111 134 114 120 136 135 115 132 98 131 132 109 123 108 113 118 143 117 94 133 130 130 139 116 124 109 109 120 115 138 122 134 131 118 129 92 128 122 122 123 117 98 128 134 135 131 130 117 116 112 124 124 131 120 96 109 119 112 108 126 120 112 118 115 104 108 126 123 129 120 115 137 122 138 106 118 129 120 109 121 136 133 107 129 148 120 108 106 111 127 106 118 130 117 100 116 110 119 134 101 100 118 126 138 125 96 130 127 129 139 126 122 122 97 122 103 104 120 95 113 115 136 136 115 108 106 125 102 124 122 109 118 93 109 119 111 98 121 121 107 119 112 103 134 120 122 124 101 119 106 128 126 123 119 134 113 109 112 124 127 126 103 123 125 115 122 114 119 119 133 113 114 122 122 136 102 99 129 104 125 122 124 109 108 121 108 130 118 126 117 109 136 118 114 127 120 95 119 115 114 127 121 122 112 119 95 129 117 122 91 117 121 129 116 109 128 100 99 115 112 104 106 113 120 129 129 118 124 129 122 118 124 111 104 121 124 114 103 128 127 112 115 116 113 124 111 147 117 108 118 109 121 122 138 130 102 127 131 122 119 118 121 127 106 97 117 124 126 128 134 117 125 113 108 128 113 137 119 129 113 111 135 124 121 115 115 113 130 126 122 129 124 117 113 123 104 105 116 140 123 105 114 113 115 127 133 117 124 130 123 110 113 118 142 84 112 95 117 103 112 102 126 119 129 106 125 115 110 128 122 124 122 116 101 105 100 100 119 114 117 131 129 141 111 115 115 109 139 134 113 140 107 92 128 122 121 137 133 126 109 110 107 107 130 119 126 114 105 123 120 109 115 120 99 108 122 134 107 99 126 126 105 99 103 127 128 137 124 104 106 114 124 142 114 116 117 102 124 113 101 135 108 113 108 121 125 120 98 103 120 108 99 103 135 119 112 130 111 120 108 113 117 119 130 129 102 124 129 126 93 131 104 114 133 108 122 92 143 115 125 127 113 121 107 123 125 118 128 128 119 125 90 128 111 115 118 101 130 110 99 112 116 111 115 118 127 118 126 121 124 118 122 128 107 96 119 105 110 147 118 107 130 125 113 111 113 119 109 121 122 121 122 125 135 125 96 132 119 130 122 125 125 118 132 120 111 120 121 129 130 117 105 145 105 119 131 112 94 119 110 123 123 123 120 112 110 112 106 120 123 124 119 141 112 115 124 138 113 135 117 120 123 107 118 107 126 115 112 133 108 132 119 112 129 121 129 116 77 118 132 123 120 114 131 96 113 135 126 131 113 111 95 114 107 120 124 137 117 117 112 114 130 135 127 123 119 105 114 125 110 110 116 117 140 116 110 113 100 132 122 124 107 113 115 115 133 130 126 114 133 109 121 116 116 128 127 115 127 116 115 122 123 106 121 118 122 123 124 138 104 136 113 123 124 121 124 117 133 125 114 134 114 130 130 127 116 97 122 92 129 109 119 123 123 101 137 113 123 120 133 115 124 132 116 112 127 111 122 106 102 129 121 117 123 118 133 115 107 115 86 116 102 111 137 117 99 100 120 117 128 100 123 102 119 110 122 123 120 126 126 100 125 116 139 113 122 115 122 109 123 128 122 112 116 119 120 121 122 120 110 109 108 112 132 106 121 131 124 91 126 124 118 144 124 105 122 105 110 113 141 118 135 129 116 149 129 105 119 111 125 137 120 139 135 117 105 108 118 98 110 130 126 122 117 121 134 110 120 125 107 129 116 105 104 132 128 128 114 119 107 103 122 117 112 111 115 136 113 117 104 92 114 128 120 84 117 116 107 103 125 135 104 118 113 133 139 97 121 124 112 127 99 109 107 124 128 127 123 129 107 117 117 107 110 121 125 106 108 130 120 114 109 129 108 98 113 117 129 113 118 127 134 97 143 119 123 102 115 121 118 125 114 114 123 113 117 117 117 118 134 118 117 117 117 136 117 102 109 114 133 117 112 124 108 88 112 117 118 112 109 101 129 112 117 111 105 124 135 121 114 111 102 118 113 109 98 108 105 134 123 121 114 118 126 135 112 129 118 115 97 102 141 104 101 107 109 114 118 98 116 117 126 110 126 116 132 128 105 117 113 131 101 114 112 105 115 119 113 107 96 115 123 119 107 131 120 108 115 129 121 115 113 115 101 122 102 137 113 103 120 128 104 104 123 122 122 118 122 118 139 116 118 124 123 116 122 84 118 116 119 112 118 128 119 129 100 108 140 116 116 104 112 113 121 125 132 101 118 129 111 109 128 131 121 117 134 101 116 139 96 130 122 134 114 134 113 129 114 125 95 129 129 133 117 116 100 113 110 87 113 121 122 103 145 128 109 115 110 100 106 109 136 118 131 104 119 113 115 114 106 138 105 108 135 96 123 97 115 109 120 124 114 92 119 99 101 113 117 113 125 123 97 115 127 128 92 115 96 129 115 118 113 122 113 109 110 122 115 123 121 139 106 110 131 106 125 105 115 139 122 114 122 120 129 102 114 117 107 110 123 105 110 92 124 116 125 99 119 114 122 100 114 109 124 115 118 119 114 115 124 138 117 120 134 117 112 132 116 128 118 104 121 107 126 118 112 109 110 115 126 108 121 128 123 122 111 104 96 119 115 109 107 109 114 108 110 94 132 118 110 110 113 106 102 102 108 109 130 109 113 117 112 138 119 123 122 124 112 107 106 112 127 124 115 125 104 116 107 102 106 111 112 119 123 116 118 124 102 136 107 142 118 107 120 116 130 117 92 117 121 130 112 125 123 92 127 116 99 134 123 114 133 121 127 108 119 99 109 94 111 114 105 114 127 115 114 105 116 95 103 133 108 100 119 129 99 114 108 125 120 110 124 110 116 117 115 110 94 108 137 95 118 100 121 114 134 135 118 126 104 106 106 126 100 115 113 124 108 113 107 128 99 126 117 112 133 118 122 104 108 110 101 111 122 131 119 116 119 136 114 120 108 126 130 98 113 123 107 120 100 115 121 115 103 115 113 107 112 116 114 115 133 129 109 117 129 102 120 112 113 108 117 93 113 129 135 129 112 107 117 113 149 108 113 97 121 116 114 129 122 112 113 117 108 123 100 98 120 79 123 103 109 98 118 135 104 115 124 97 125 122 114 106 92 111 93 119 114 107 109 114 109 122 116 125 119 119 127 103 115 125 118 117 121 131 137 101 113 117 105 131 121 109 133 116 115 113 123 122 108 107 121 113 132 109 118 100 112 114 118 119 107 102 129 116 107 113 103 103 110 103 120 107 117 130 116 113 111 116 106 98 96 132 117 103 92 105 123 119 126 110 126 118 120 106 124 100 118 112 122 127 121 117 114 117 100 120 114 115 104 111 123 103 113 107 113 102 103 121 115 141 111 101 118 89 132 104 118 101 116 128 103 118 128 129 113 125 114 110 110 121 123 107 119 116 107 89 94 115 120 128 117 126 102 113 126 114 101 107 114 110 104 107 112 96 112 126 94 116 118 118 109 109 125 122 115 103 100 120 125 125 116 117 110 119 113 100 123 112 115 122 104 114 103 123 114 117 118 123 120 143 121 108 127 103 107 101 108 120 112 118 124 130 106 104 118 138 125 105 118 126 113 132 115 94 116 126 103 105 106 128 126 119 133 128 133 130 123 128 144 125 114 128 115 111 103 115 131 121 113 119 115 102 127 122 101 118 114 110 114 104 127 117 139 127 132 116 106 123 114 112 114 114 130 109 120 94 124 111 94 119 112 127 119 108 123 122 127 122 134 123 103 109 109 137 122 114 114 126 103 126 123 105 102 107 109 142 107 111 120 144 110 118 111 123 129 125 118 109 120 130 108 121 102 114 130 113 123 130 124 114 116 132 118 111 123 120 129 131 117 128 117 121 130 137 115 113 126 134 109 123 125 119 100 138 127 133 144 129 110 118 112 120 116 107 137 105 129 118 129 115 106 114 133 117 118 120 102 118 132 105 138 141 96 125 128 126 121 108 121 134 135 128 135 144 136 101 119 121 120 116 132 104 109 129 103 123 117 121 126 111 123 94 111 132 91 99 119 112 128 114 108 108 123 125 113 116 117 128 113 130 116 102 109 116 101 130 111 106 110 113 135 115 108 156 124 105 134 125 116 119 129 131 118 123 131 119 137 133 118 115 115 136 114 98 128 104 103 116 95 123 120 124 101 122 106 112 121 111 111 102 113 118 126 117 117 110 142 114 130 118 109 103 109 111 119 129 107 137 127 120 109 130 125 123 118 116 118 117 126 118 130 125 107 103 134 109 119 122 116 110 128 133 120 105 125 139 100 113 91 121 115 136 116 106 106 113 92 96 128 113 123 108 112 100 106 124 128 109 113 112 114 116 109 111 110 109 106 141 110 121 127 98 118 112 110 110 118 122 130 110 114 121 113 111 109 127 122 127 106 120 124 124 120 127 93 119 104 116 123 104 112 115 126 124 106 128 114 116 132 123 109 128 127 122 136 127 123 125 120 121 126 127 114 118 101 112 127 111 97 117 106 101 124 97 114 95 97 96 102 114 108 115 132 119 122 152 116 122 104 105 112 111 109 115 115 116 134 103 126 91 112 127 119 103 112 110 102 107 129 126 111 110 124 119 107 125 127 104 139 132 130 109 119 114 124 125 113 119 109 122 115 115 106 110 132 118 113 115 114 120 124 116 124 108 114 104 122 123 120 109 125 119 126 116 114 116 107 110 95 104 107 112 108 114 113 117 111 109 102 129 112 118 127 105 121 105 103 112 107 109 120 104 119 127 94 95 113 96 116 112 137 124 118 108 116 107 107 113 114 131 113 100 113 105 118 105 105 107 130 128 110 116 127 80 119 113 115 143 91 89 132 110 122 109 132 126 113 131 122 120 102 121 117 112 109 115 111 121 98 130 116 103 111 112 138 120 116 125 115 120 105 111 115 108 93 106 130 125 105 128 114 147 124 109 117 136 118 109 115 100 116 116 111 122 103 112 115 122 110 116 112 126 121 110 109 134 95 124 104 118 115 126 107 117 136 117 123 114 109 118 102 114 116 101 100 87 92 114 109 110 109 113 116 129 98 117 121 115 123 108 126 104 113 99 118 139 121 106 120 130 120 106 125 104 112 108 107 120 126 112 119 127 108 98 124 128 85 107 110 127 104 119 113 105 104 119 122 114 114 120 119 118 107 108 110 136 117 106 117 131 126 104 133 132 119 109 132 117 111 99 112 100 100 102 132 131 111 133 134 123 118 118 123 108 135 120 124 124 111 117 142 151 117 115 115 97 127 108 118 116 117 100 128 119 99 101 118 110 108 114 118 113 134 114 127 117 113 131 104 126 121 135 117 120 132 121 109 109 106 98 113 110 121 106 113 132 100 127 108 102 161 128 98 129 106 104 105 103 101 120 101 122 126 105 95 122 129 113 121 120 117 117 105 105 109 99 115 130 121 110 112 108 122 122 105 104 108 110 118 109 97 112 121 137 126 118 109 92 114 136 122 120 102 115 115 125 129 109 127 137 105 117 105 116 118 118 130 133 128 109 117 109 116 131 125 116 144 109 103 103 107 123 122 95 100 85 104 118 116 116 127 132 105 92 140 140 114 109 122 111 114 90 136 113 119 106 108 113 122 118 111 108 120 122 103 134 100 121 112 132 108 105 111 111 105 116 100 116 119 105 114 113 127 119 124 121 146 131 108 125 117 116 106 100 115 126 109 120 125 118 99 121 111 123 111 124 112 124 122 133 126 95 142 103 120 112 116 136 105 117 108 91 104 126 128 116 118 103 123 113 100 119 126 114 122 114 128 128 112 100 122 98 107 126 121 123 125 109 106 108 101 104 116 134 127 113 111 119 128 122 111 112 110 122 129 116 100 101 111 102 117 109 127 120 129 125 115 119 112 105 105 114 121 116 116 122 105 103 116 103 120 118 110 130 128 119 100 107 111 119 117 120 119 121 112 114 119 95 93 129 103 116 117 95 109 114 102 120 127 131 102 141 112 119 111 111 124 118 136 108 117 118 112 112 120 115 100 114 125 137 126 128 112 126 117 127 126 115 127 132 120 124 100 123 112 97 118 118 122 116 112 115 110 115 130 110 113 116 124 105 112 108 111 105 111 112 141 118 134 124 110 110 110 137 97 128 106 133 125 83 107 109 115 118 128 121 93 117 125 114 122 109 115 127 120 115 127 121 109 114 112 118 101 115 112 144 114 111 122 125 117 115 114 105 108 104 131 124 106 106 95 102 127 109 111 128 124 100 113 120 121 129 129 114 129 119 118 120 123 103 111 107 134 97 112 123 119 122 98 113 106 122 114 112 94 135 115 105 130 130 115 102 122 106 110 108 118 119 94 111 123 92 110 112 128 113 114 102 96 136 137 108 115 128 121 120 100 120 130 132 109 119 112 105 116 127 117 136 112 121 141 111 123 127 131 118 127 109 110 119 108 95 109 110 83 110 122 126 102 118 96 111 138 117 111 108 110 125 107 110 133 120 117 124 113 126 124 121 118 131 117 111 124 141 118 115 125 113 128 124 141 130 119 94 123 105 147 120 115 135 93 115 111 139 135 129 121 125 121 140 104 113 115 100 124 119 120 125 135 131 115 134 107 106 117 96 111 120 107 105 112 106 120 125 113 119 104 125 128 115 132 105 110 113 101 121 123 122 113 108 116 120 125 118 130 122 116 108 115 104 104 130 115 129 137 107 115 97 112 135 110 120 114 128 110 110 117 125 100 110 118 126 100 113 125 96 126 117 102 102 117 126 113 104 105 142 124 114 119 93 112 117 111 91 122 105 119 102 129 117 120 128 112 133 115 115 103 113 123 130 117 130 126 117 125 84 98 121 97 122 122 131 113 102 104 112 115 122 123 128 137 111 128 132 108 117 109 111 129 112 115 110 110 111 104 111 91 114 124 103 98 120 116 109 106 109 118 125 116 103 100 106 116 111 140 118 110 114 115 124 94 102 139 111 108 99 118 110 110 128 108 110 122 105 112 122 127 125 123 128 128 136 117 112 93 113 117 115 106 93 115 107 108 129 127 109 110 95 120 116 124 112 127 104 108 113 114 107 114 122 118 105 101 109 122 106 126 133 116 128 85 137 129 125</counts>
			</dataPoints>
		</scan>
	</xrdMeasurement>
</xrdMeasurements>