File: data/XRD/XG-Sauerstoff/XG-pre/W6821-1B_XG_Sauerstoff_pre.xrdml
<xrdMeasurements xmlns="http://www.xrdml.com/XRDMeasurement/2.1" xmlns:xsi="http://www.w3.org/2001/XMLSchema-instance" xsi:schemaLocation="http://www.xrdml.com/XRDMeasurement/2.1 http://www.xrdml.com/XRDMeasurement/2.1/XRDMeasurement.xsd" status="Completed">
	<comment>
		<entry>Configuration=Factory configuration, Owner=User-1, Creation date=7/8/2013 4:01:53 PM</entry>
		<entry>Goniometer=PW3050/65 (Theta/2Theta); Minimum step size 2Theta:0.0001; Minimum step size Omega:0.0001</entry>
		<entry>Sample stage=MRD Cradle; Minimum step size Phi:0.01; Minimum step size Chi:0.01; Minimum step size X:0.01; Minimum step size Y:0.01; Minimum step size Z:0.001</entry>
		<entry>Diffractometer system=XPERT-PRO</entry>
		<entry>Measurement program=C:\PANalytical\Data Collector\Programs\Jorrit\2thom\_absolute_2th-om_10-130deg_PIXscan_56min.xrdmp, Identifier={15BCCF57-2807-42BD-B5B9-ECC0B3DC9284}</entry>
		<entry>Batch program=C:\PANalytical\Data Collector\Programs\SimonL\batch4x_2thom_10-130°_z9.1_x0,10,20,30_y0_57min.xrdmp, Identifier={EED9823A-2BEB-424C-9252-345C4EF2834A}</entry>
	</comment>
	<sample type="To be analyzed">
		<id></id>
		<name></name>
		<preparedBy></preparedBy>
	</sample>
	<xrdMeasurement measurementType="Scan" status="Completed" sampleMode="Reflection">
		<comment>
			<entry>_absolute_2th-om_10-130deg_PIXscan_56min</entry>
			<entry>PHD Lower Level = 4.83 (keV), PHD Upper Level = 11.27 (keV)</entry>
		</comment>
		<usedWavelength intended="K-Alpha 1">
			<kAlpha1 unit="Angstrom">1.5405980</kAlpha1>
			<kAlpha2 unit="Angstrom">1.5444260</kAlpha2>
			<kBeta unit="Angstrom">1.3922500</kBeta>
			<ratioKAlpha2KAlpha1>0.5000</ratioKAlpha2KAlpha1>
		</usedWavelength>
		<incidentBeamPath>
			<radius unit="mm">320.00</radius>
			<xRayTube id="1010048" name="Empyrean Cu LFF HR (9430 033 7310x) DK442154">
				<tension unit="kV">40.0</tension>
				<current unit="mA">40.0</current>
				<anodeMaterial>Cu</anodeMaterial>
				<focus type="Line">
					<length unit="mm">12.0</length>
					<width unit="mm">0.4</width>
					<takeOffAngle unit="deg">4.2</takeOffAngle>
				</focus>
			</xRayTube>
			<xRayMirror id="27010001" name="Inc. Beam Cu W/Si (parabolic MRD)" hybrid="false">
				<crystal type="Graded" shape="Parabolic">W/Si</crystal>
				<acceptanceAngle unit="deg">0.800</acceptanceAngle>
				<length unit="mm">60.0</length>
			</xRayMirror>
			<sollerSlit id="21010002" name="Soller slits 0.04 rad.">
				<opening unit="rad">0.0400</opening>
			</sollerSlit>
			<mask id="22030007" name="Fixed mask 2 mm">
				<distanceToSample unit="mm">220.00</distanceToSample>
				<width unit="mm">2.00</width>
			</mask>
			<divergenceSlit id="22010007" name="Fixed slit 1/8°" xsi:type="fixedDivergenceSlitType">
				<distanceToSample unit="mm">220.00</distanceToSample>
				<height unit="mm">0.19</height>
			</divergenceSlit>
		</incidentBeamPath>
		<diffractedBeamPath>
			<radius unit="mm">320.00</radius>
			<sollerSlit id="21010002" name="Soller slits 0.04 rad.">
				<opening unit="rad">0.0400</opening>
			</sollerSlit>
			<receivingSlit id="22010001" name="Fixed slit 4°">
				<height unit="mm">5.88</height>
			</receivingSlit>
			<detector id="7010017" name="PIXcel3D 1x1 detector" xsi:type="areaDetectorType">
				<phd unit="%">
					<lowerLevel>30.0</lowerLevel>
					<upperLevel>70.0</upperLevel>
				</phd>
				<mode>Scanning</mode>
				<activeChannelsEquatorial>255</activeChannelsEquatorial>
				<activeChannelsAxial>255</activeChannelsAxial>
				<pitchEquatorial unit="mm">0.05500</pitchEquatorial>
				<pitchAxial unit="mm">0.05500</pitchAxial>
				<readOutPeriod unit="seconds">0.135</readOutPeriod>
			</detector>
		</diffractedBeamPath>
		<scan appendNumber="0" mode="Continuous" scanAxis="2Theta-Omega" status="Completed">
			<header>
				<startTimeStamp>2024-09-10T16:45:20+02:00</startTimeStamp>
				<endTimeStamp>2024-09-10T17:41:23+02:00</endTimeStamp>
				<author>
					<name>PRO-MRD</name>
				</author>
				<source>
					<applicationSoftware version="6.1b">Data Collector</applicationSoftware>
					<instrumentControlSoftware version="7.0E 20130304">XPERT-PRO</instrumentControlSoftware>
					<instrumentID>0000000011142674</instrumentID>
				</source>
			</header>
			<dataPoints>
				<positions axis="2Theta" unit="deg">
					<startPosition>9.99826193</startPosition>
					<endPosition>129.99755682</endPosition>
				</positions>
				<positions axis="Omega" unit="deg">
					<startPosition>4.99913096</startPosition>
					<endPosition>64.99877841</endPosition>
				</positions>
				<positions axis="Phi" unit="deg">
					<commonPosition>0.00</commonPosition>
				</positions>
				<positions axis="Chi" unit="deg">
					<commonPosition>0.00</commonPosition>
				</positions>
				<positions axis="X" unit="mm">
					<commonPosition>0.00</commonPosition>
				</positions>
				<positions axis="Y" unit="mm">
					<commonPosition>0.00</commonPosition>
				</positions>
				<positions axis="Z" unit="mm">
					<commonPosition>9.100</commonPosition>
				</positions>
				<commonCountingTime unit="seconds">32.895</commonCountingTime>
				<counts 241 210 207 208 256 213 224 249 243 243 221 231 230 230 218 211 205 205 221 227 206 206 186 256 205 220 218 230 213 215 218 223 232 229 207 214 202 193 212 181 201 207 239 218 221 223 227 206 217 215 195 184 210 209 224 212 199 234 221 196 213 203 208 227 199 193 225 208 219 189 196 218 218 214 217 188 185 203 204 213 189 193 233 214 237 203 204 208 170 235 189 232 185 224 206 190 207 207 229 224 198 199 221 199 187 218 213 177 205 213 183 209 183 200 201 199 203 232 198 220 201 234 211 192 180 205 225 194 206 200 172 203 200 194 193 202 199 198 205 193 208 215 204 199 208 199 202 207 178 174 198 196 190 221 218 173 202 187 219 222 202 196 190 177 205 201 196 197 190 183 170 202 198 184 242 211 191 190 182 187 174 215 202 223 198 215 208 187 190 202 200 202 194 198 239 194 192 215 200 202 195 181 184 170 163 207 211 217 207 177 187 195 164 189 197 216 192 190 184 187 198 165 205 196 162 208 175 178 192 199 204 199 199 203 203 218 200 209 175 192 206 172 190 193 200 202 185 202 177 157 175 200 185 176 199 198 182 183 187 208 198 201 199 184 190 186 201 174 198 173 195 168 174 166 184 162 204 170 179 159 152 176 182 196 189 178 186 150 162 164 174 196 195 184 165 191 160 182 180 181 186 180 183 187 203 156 188 195 171 173 168 166 193 154 208 167 193 192 196 181 202 173 177 162 162 186 158 156 186 192 165 168 201 177 166 188 162 172 159 183 188 161 176 166 157 181 192 173 166 174 176 159 175 158 207 190 186 172 177 185 197 141 168 173 173 190 176 174 188 202 172 181 181 192 170 179 172 147 194 147 186 172 174 145 155 184 186 162 168 163 171 142 180 169 153 154 164 162 172 177 167 133 156 176 150 151 150 154 156 195 170 174 173 170 149 151 149 164 165 177 172 154 147 166 170 156 171 174 161 151 183 157 184 146 174 174 175 170 146 167 151 168 166 168 170 159 166 146 158 188 165 172 157 160 157 139 184 159 167 171 168 167 150 173 165 162 176 181 180 144 133 132 161 162 129 162 145 180 169 143 157 170 179 183 171 158 174 172 153 170 159 149 166 151 168 148 153 162 144 145 159 152 175 167 159 161 173 158 160 161 171 148 141 150 161 148 151 165 170 146 162 158 175 174 171 152 152 163 152 128 166 143 164 170 167 135 160 144 155 174 174 167 173 172 148 169 168 128 150 155 155 120 158 136 159 153 171 161 149 166 155 175 160 164 165 167 157 155 163 151 142 160 155 148 156 157 155 179 143 158 165 153 155 156 139 169 174 188 152 166 148 132 123 156 158 173 150 148 145 166 142 156 144 148 153 159 155 135 155 141 158 160 142 138 161 140 151 153 152 153 157 146 125 148 159 151 166 148 143 167 155 147 156 132 141 154 157 158 146 165 160 175 162 126 162 172 160 173 167 155 164 136 156 158 145 132 174 144 176 168 167 161 154 166 141 134 162 147 151 146 165 155 148 147 152 153 161 155 176 155 141 155 155 155 159 160 143 158 159 145 133 135 156 136 157 135 129 142 135 138 149 155 175 169 132 150 168 133 158 158 170 156 147 138 132 155 152 147 136 146 159 146 141 146 156 169 159 141 147 160 161 133 167 150 168 167 161 158 158 164 141 143 156 137 186 151 164 166 169 143 140 147 155 131 146 136 151 136 140 172 156 138 145 147 152 148 153 145 152 173 160 169 157 147 141 138 151 143 120 149 169 172 138 131 141 141 161 162 154 151 158 157 172 131 130 174 176 128 164 153 114 167 160 163 145 137 153 162 154 151 151 131 157 175 169 163 135 154 165 155 167 159 157 146 140 146 148 142 144 145 163 154 146 137 150 134 152 141 168 158 169 150 149 173 151 157 143 158 149 183 157 145 144 172 142 142 161 153 152 203 169 159 168 134 144 148 151 150 153 128 153 135 138 156 138 183 159 156 151 156 167 148 137 163 153 140 184 172 148 160 143 140 155 151 170 148 162 173 166 148 160 178 151 152 143 147 144 157 161 166 173 148 160 163 151 139 147 140 176 162 152 143 136 146 174 161 149 139 164 154 153 141 145 158 133 158 153 164 162 177 147 164 134 164 144 173 172 165 171 182 162 165 180 151 145 163 155 152 133 132 184 162 176 153 145 176 176 145 163 160 148 153 126 137 158 145 163 160 147 153 138 157 137 136 159 170 158 161 162 155 167 178 171 152 154 165 142 161 169 183 159 201 182 142 148 171 177 162 131 180 171 165 145 158 156 167 160 175 163 135 161 158 159 152 149 189 155 150 174 158 155 161 154 168 179 184 161 168 153 133 157 171 157 162 131 147 189 147 165 192 145 163 153 140 177 183 164 169 147 167 180 166 161 141 174 171 183 156 158 162 174 163 140 164 158 158 151 155 159 152 171 147 144 167 185 170 160 182 180 156 166 170 145 152 185 138 168 165 172 181 160 163 159 171 170 192 175 161 174 155 169 157 132 171 146 162 175 149 192 191 196 194 186 192 153 163 184 148 180 187 153 165 165 159 151 185 160 179 183 183 150 163 174 179 166 157 164 185 173 163 181 159 172 159 179 155 163 192 159 167 148 175 161 170 163 161 155 144 175 156 162 189 165 145 176 149 176 169 167 166 159 167 165 171 168 166 164 162 181 152 170 173 182 195 178 171 163 172 161 162 161 163 175 174 187 178 168 208 164 144 182 155 186 189 168 173 152 162 197 136 146 135 158 157 162 171 160 194 141 179 148 163 179 168 167 153 172 182 167 173 158 137 151 174 168 151 159 172 160 165 177 163 144 144 182 165 145 160 154 162 158 167 174 174 186 148 159 176 160 171 175 150 186 162 174 181 153 174 161 168 162 192 165 186 194 180 170 186 164 168 150 171 145 164 158 164 180 189 162 160 162 176 190 175 160 164 164 182 166 163 152 159 168 161 172 177 179 171 158 158 159 168 165 185 156 185 164 166 176 164 159 141 142 148 165 163 160 161 156 181 153 175 163 157 131 174 150 159 169 168 156 175 158 160 196 171 157 169 164 164 142 171 150 174 162 173 156 180 159 161 159 162 160 182 184 145 147 155 152 151 168 146 145 160 158 177 129 175 182 155 160 148 153 137 173 163 160 163 152 163 161 163 168 149 146 147 156 157 184 168 180 166 155 180 175 169 167 166 153 185 153 192 154 168 153 150 164 169 174 155 153 170 159 163 164 163 153 155 200 156 175 160 141 155 153 159 163 145 137 152 179 162 151 150 155 155 160 161 135 175 145 168 157 155 144 165 161 136 138 153 159 179 159 149 162 133 166 152 141 178 154 149 158 152 166 197 166 174 120 190 150 142 133 140 151 142 187 146 151 168 160 155 145 163 154 144 144 143 148 156 159 143 150 147 160 144 153 161 151 157 134 157 149 150 141 164 142 161 172 152 173 171 159 137 141 178 156 158 147 137 157 157 149 146 166 158 142 151 153 171 168 122 125 142 141 147 153 147 147 145 138 162 133 138 147 145 131 144 171 149 151 138 137 162 170 143 166 158 153 168 139 156 134 162 134 166 166 157 156 141 164 120 163 155 133 141 136 151 165 166 148 135 126 152 146 143 147 147 128 147 146 137 144 153 127 164 158 165 143 143 159 147 129 158 144 172 160 144 136 161 134 148 158 152 148 155 154 145 133 135 142 153 145 148 141 125 151 145 147 143 152 149 146 143 128 144 153 149 144 149 149 140 164 148 142 135 163 135 156 131 145 129 159 143 151 141 153 140 130 129 151 154 149 158 155 142 143 139 130 147 146 145 139 156 154 154 166 151 142 137 144 140 137 158 158 143 155 131 127 132 143 129 154 136 143 140 150 150 156 116 130 165 139 135 151 144 122 151 141 118 140 154 156 155 141 125 128 129 122 121 143 137 123 147 136 115 139 149 134 139 144 150 130 122 132 142 129 136 133 135 136 134 161 127 127 135 141 134 128 141 122 138 150 155 146 140 132 123 153 142 135 156 136 130 156 115 148 132 123 111 149 147 126 135 134 143 132 145 151 131 139 128 121 123 146 150 125 138 129 144 158 139 129 140 143 133 123 135 135 122 142 139 156 122 147 138 142 155 121 127 157 132 138 153 138 125 140 130 141 143 117 143 141 140 129 134 139 125 150 127 166 138 148 146 136 160 122 133 122 146 149 127 134 125 130 128 150 127 137 135 126 136 121 144 131 135 151 133 120 148 120 120 131 146 133 128 143 125 134 119 142 121 136 119 139 131 120 139 135 156 132 127 119 122 136 134 124 134 134 141 138 144 130 147 129 120 139 143 124 135 125 115 104 139 130 134 152 136 131 133 117 118 151 133 151 124 124 132 122 108 120 124 116 126 138 121 121 128 148 128 120 126 131 116 132 126 138 134 120 144 136 130 118 116 119 133 136 128 146 158 123 131 126 146 123 136 131 119 141 124 141 140 135 125 131 148 111 142 127 122 141 132 124 138 128 130 131 143 121 118 117 141 116 136 131 120 143 126 123 118 121 138 128 132 129 131 132 136 120 127 126 133 137 118 132 131 144 129 127 129 140 118 129 139 109 132 141 127 139 114 118 132 121 133 132 116 116 126 133 111 125 133 130 114 119 137 125 152 109 152 137 129 134 118 129 123 118 129 111 128 129 130 140 135 120 144 133 126 120 126 105 141 137 105 105 109 110 137 125 130 136 119 136 149 126 128 104 134 119 119 133 135 142 120 122 109 124 123 130 115 120 123 124 99 148 122 125 126 118 131 124 128 110 132 131 114 124 138 121 144 146 131 112 105 127 113 139 102 122 113 118 124 137 117 126 106 154 126 159 108 128 123 126 114 119 102 114 122 123 135 119 128 124 114 117 113 117 127 131 132 119 103 129 130 125 113 135 122 118 125 120 110 137 130 125 127 116 109 133 134 126 113 112 132 138 130 125 140 133 137 122 133 121 126 137 120 118 119 120 102 117 118 110 99 121 127 126 119 111 107 116 109 124 118 133 132 128 121 122 146 111 122 124 114 121 118 120 127 139 123 108 111 101 114 111 115 131 130 112 110 127 94 110 128 121 129 119 105 122 114 120 132 128 113 140 131 151 117 120 131 105 125 104 113 115 125 121 143 136 132 127 124 112 135 89 100 116 102 140 126 122 106 118 115 114 111 110 114 138 113 105 137 118 112 128 118 116 86 105 120 120 99 124 120 107 123 115 108 109 147 111 121 111 106 111 98 127 111 126 109 128 132 113 125 117 110 127 117 141 114 115 121 94 121 111 122 107 130 117 110 116 129 104 107 113 117 121 136 123 124 132 147 129 106 117 105 98 99 107 110 111 114 113 121 124 123 111 107 110 119 108 134 119 101 104 123 128 139 112 118 103 113 122 120 126 116 113 120 101 116 120 118 127 133 101 119 110 99 116 119 103 92 125 115 114 123 115 105 124 123 112 117 99 126 133 119 139 123 101 137 121 111 109 104 102 113 117 120 114 117 124 119 134 121 119 121 111 93 102 138 115 118 128 135 112 96 115 124 109 118 105 111 104 133 120 118 116 90 107 113 129 99 112 113 113 109 93 115 104 135 91 112 130 111 96 105 121 116 106 115 105 134 115 105 108 105 96 118 129 124 116 109 102 117 104 108 118 99 124 110 97 125 130 113 114 115 120 114 123 128 134 97 115 97 95 106 125 104 112 120 111 125 103 108 114 118 108 116 109 99 99 111 112 98 116 127 119 106 114 112 131 105 116 112 122 110 127 103 130 86 117 117 103 116 111 111 109 98 111 105 135 122 114 118 105 138 130 122 119 119 125 107 117 132 114 113 117 99 115 116 109 116 103 111 116 114 111 104 119 95 120 104 115 128 119 111 94 117 125 113 97 121 104 138 107 118 125 113 91 105 120 113 120 118 128 109 127 97 127 112 123 123 101 113 108 114 102 118 92 99 114 95 101 129 113 113 100 124 117 120 119 122 107 118 111 127 120 96 133 98 115 126 105 110 119 127 117 121 115 114 108 102 121 109 122 121 127 109 100 108 134 104 118 112 110 105 103 119 129 122 107 109 108 130 107 103 103 129 114 104 111 115 112 111 119 125 112 99 106 114 97 105 100 109 103 107 103 120 116 106 99 114 112 131 114 113 114 105 93 119 107 98 106 135 125 98 111 112 115 104 113 95 103 119 112 112 104 118 106 105 119 112 102 116 124 114 124 101 108 111 128 124 111 112 103 121 116 126 111 98 93 126 119 104 112 111 107 109 105 122 116 112 122 102 97 88 115 100 112 108 96 115 124 107 111 103 101 104 102 126 106 116 127 118 120 110 106 109 118 102 108 97 109 108 113 117 111 106 117 107 114 122 101 116 105 125 117 124 115 99 130 113 116 129 110 119 116 114 110 100 111 110 128 111 115 91 103 97 110 122 103 144 90 102 115 101 117 113 118 113 126 120 111 118 81 124 120 115 106 115 117 116 106 107 118 92 103 98 107 92 122 94 99 131 84 114 107 117 103 113 104 125 109 131 119 105 107 101 108 119 112 116 109 101 98 103 112 119 110 102 96 126 97 141 103 118 111 106 107 108 111 92 128 114 110 97 98 120 140 136 117 120 105 105 113 130 115 103 93 130 96 100 104 105 107 136 123 111 97 103 109 125 118 134 128 117 106 113 99 119 102 109 133 99 117 123 110 109 103 116 99 126 117 125 122 106 115 102 110 115 102 116 118 120 110 119 105 125 102 121 136 132 114 121 111 120 113 101 114 110 109 108 113 115 93 119 115 138 125 109 123 106 121 114 94 109 115 134 105 125 122 109 111 128 114 112 121 125 129 107 119 117 103 133 124 105 114 118 109 87 114 115 107 109 119 91 116 120 131 101 117 117 116 128 123 125 94 117 126 129 110 105 107 103 120 126 135 115 133 114 120 118 118 103 108 90 120 127 105 124 115 108 104 108 93 103 108 114 125 105 115 114 118 103 105 86 88 113 97 112 113 113 130 93 127 108 118 114 114 103 88 129 125 125 117 114 119 122 120 109 114 110 117 117 126 130 123 112 149 107 116 113 120 124 120 120 125 96 108 111 117 95 140 107 120 107 117 115 126 126 122 124 117 111 131 110 107 115 100 131 133 116 123 123 119 114 110 115 110 108 129 122 124 119 120 118 114 116 118 111 117 123 102 105 116 111 128 121 133 131 112 108 126 108 121 100 108 93 119 125 127 117 114 107 95 125 127 100 123 106 139 92 107 113 115 106 117 111 114 131 127 108 125 129 114 119 113 135 103 104 120 139 106 115 111 117 122 110 111 118 128 114 111 110 117 102 122 116 92 114 123 104 125 125 108 108 128 96 115 119 110 106 101 126 121 121 119 116 108 122 137 119 94 123 119 116 135 112 80 119 116 127 120 102 115 119 127 118 134 134 125 121 99 109 129 124 106 121 120 114 110 116 125 134 152 122 128 92 125 107 112 108 129 100 119 118 104 129 96 112 108 117 123 117 128 117 129 118 117 117 130 99 95 106 112 106 123 106 120 109 119 130 115 118 125 102 123 122 126 118 115 121 107 106 100 133 112 122 125 115 115 122 111 120 116 119 118 98 113 103 122 129 122 119 129 122 122 127 101 102 120 126 122 127 132 120 102 121 121 118 118 119 116 116 115 139 105 119 117 121 126 132 113 126 107 123 115 117 111 123 97 104 131 112 123 132 126 130 133 130 126 133 116 115 97 115 139 137 112 128 116 134 124 124 135 136 150 132 135 131 139 133 137 119 139 137 157 155 129 122 161 108 145 131 159 150 134 160 144 140 142 150 175 158 166 163 185 132 184 195 189 189 189 221 212 204 216 230 227 205 217 225 210 214 248 238 238 229 210 205 174 207 195 194 175 214 189 157 185 181 181 155 161 142 157 152 145 165 158 153 126 134 167 145 145 137 142 125 116 144 129 137 147 141 116 133 145 126 129 147 139 139 127 138 134 142 121 117 117 124 117 113 126 110 117 113 105 115 123 144 121 125 119 115 117 104 123 110 126 112 124 126 108 124 122 119 124 121 118 144 109 127 121 122 125 124 109 125 117 116 125 115 124 99 119 118 116 112 118 121 110 117 125 113 121 104 134 112 128 115 110 116 120 124 115 124 119 119 101 111 120 114 121 129 128 123 122 122 112 118 120 138 134 95 113 110 116 98 124 122 91 105 94 104 118 124 123 116 127 112 115 107 111 123 129 116 109 118 97 123 103 108 111 116 96 149 116 118 98 130 129 104 131 118 136 103 126 115 120 102 128 126 120 131 114 121 112 108 127 106 112 109 117 125 110 140 129 117 98 110 114 118 125 123 133 116 104 141 125 131 113 131 127 114 132 122 107 98 102 114 117 93 107 106 100 118 136 102 114 107 96 127 110 104 101 120 115 125 106 106 123 120 125 129 111 107 129 115 112 108 108 115 120 116 112 116 112 109 125 127 137 104 103 96 102 127 126 126 123 110 116 111 121 105 130 113 108 121 125 124 138 112 119 112 124 129 104 129 104 124 111 118 117 113 126 105 125 126 99 116 118 102 131 123 123 110 142 111 117 122 118 122 142 106 119 126 103 101 133 126 99 111 117 115 112 127 111 107 99 115 127 114 107 111 101 111 115 127 106 108 122 123 110 136 116 112 127 121 126 123 134 96 115 121 129 130 119 116 127 115 138 106 116 113 106 96 134 114 129 95 121 103 128 112 120 113 122 121 120 113 107 96 94 129 115 129 122 116 111 116 130 120 118 103 108 110 102 104 104 125 106 116 99 136 111 119 107 132 112 109 113 104 112 89 117 112 131 125 110 103 132 128 107 105 110 109 109 128 113 93 109 100 110 119 114 119 122 110 118 108 115 116 136 113 111 114 116 116 105 100 85 108 103 115 124 130 113 100 111 120 114 115 133 118 141 97 101 130 119 113 94 119 100 111 110 92 120 109 128 122 113 118 123 125 107 100 116 118 131 97 122 111 115 122 107 110 108 98 127 88 105 122 112 139 113 120 110 116 106 99 135 128 118 109 113 97 119 119 126 110 107 105 120 115 125 92 116 81 128 101 115 100 108 121 120 115 119 138 126 117 118 122 104 98 111 106 105 105 119 109 117 115 122 103 113 121 104 107 124 110 137 119 108 106 111 109 119 120 116 111 123 132 100 109 110 119 119 119 126 106 127 104 112 101 103 99 102 122 106 127 119 110 112 123 129 121 118 113 115 105 102 92 126 118 113 117 109 119 99 106 115 136 141 119 111 123 102 109 112 122 109 116 104 126 133 114 111 115 121 124 120 100 103 121 118 94 120 99 105 108 101 119 106 120 110 118 129 109 132 104 120 100 120 105 99 104 138 102 110 112 105 112 105 114 123 100 126 96 128 115 118 111 100 118 114 121 136 127 108 105 111 106 118 107 110 130 127 113 113 94 109 109 110 113 121 107 102 128 118 123 131 128 109 129 104 107 116 117 133 122 113 104 129 129 117 105 108 122 108 113 116 104 107 119 130 106 119 110 112 119 117 121 115 126 115 107 120 123 104 104 113 105 126 128 108 104 118 98 104 128 132 127 115 117 106 118 102 104 133 106 125 97 97 101 122 113 114 137 125 126 113 122 116 98 107 108 109 93 116 112 114 115 98 111 114 132 122 107 111 108 123 128 95 99 126 112 113 123 118 107 123 128 125 125 121 124 95 107 103 124 108 117 121 117 110 101 122 113 114 115 115 121 129 111 116 103 113 132 118 112 109 95 121 125 119 113 114 113 90 113 120 109 126 106 104 112 113 98 130 112 100 92 121 132 95 105 115 104 127 120 118 111 111 124 109 97 96 113 135 107 124 112 117 125 133 103 118 88 96 118 126 147 117 91 139 103 119 117 120 103 96 125 135 110 109 123 107 114 106 135 99 109 95 115 130 105 129 119 112 113 113 94 94 119 135 95 118 109 104 114 102 105 125 105 123 120 114 109 130 100 131 112 106 121 113 123 129 117 93 107 114 124 110 115 118 124 116 105 112 112 122 134 117 101 115 136 120 122 114 108 82 111 121 118 94 104 117 107 127 140 111 104 131 110 98 118 142 107 108 128 98 104 103 114 109 135 122 97 109 103 121 91 115 118 98 131 121 101 140 119 116 108 97 133 91 127 115 105 117 99 115 115 124 90 121 127 118 134 95 129 123 125 134 117 124 94 129 95 114 134 101 128 119 99 109 120 118 132 104 112 112 109 110 115 108 102 109 116 130 120 106 109 122 108 119 124 100 118 117 100 111 94 115 124 154 137 113 118 103 121 121 117 114 125 110 96 115 119 116 123 111 111 114 116 122 106 112 97 111 107 123 103 110 106 126 98 117 122 99 109 114 109 101 120 103 122 113 100 109 103 110 118 102 103 102 114 111 121 106 107 107 128 130 118 129 133 112 98 113 105 127 107 123 121 113 128 123 119 103 129 134 122 132 130 102 122 100 124 106 124 101 95 114 114 118 117 117 119 121 116 109 122 120 105 108 124 121 123 99 118 106 115 116 120 132 113 123 116 125 119 109 101 117 114 112 131 115 135 121 109 119 101 103 114 94 114 108 115 127 113 128 124 105 110 105 119 123 123 117 96 119 117 123 126 112 115 109 120 115 117 111 124 129 125 115 113 111 104 115 102 118 114 108 103 123 117 139 121 123 110 133 124 119 126 112 146 109 127 109 121 123 130 122 115 98 136 120 114 108 92 111 117 100 132 95 115 106 130 114 117 105 108 126 106 120 107 127 125 116 107 126 123 109 126 104 150 119 121 109 100 93 111 102 122 119 99 131 103 117 89 117 114 122 116 115 130 119 109 111 124 128 128 102 109 107 130 115 123 116 117 127 101 110 127 117 107 107 107 119 137 146 126 124 116 130 122 127 114 113 128 112 118 113 101 124 110 140 102 120 126 120 109 106 115 101 108 110 131 92 110 127 113 120 143 126 118 119 109 95 99 129 119 110 122 129 115 119 123 101 101 128 126 118 114 112 101 107 136 109 125 125 140 96 105 118 111 108 121 107 114 113 103 127 112 121 124 110 106 110 107 118 115 122 132 104 101 130 105 106 123 131 130 102 109 112 106 106 136 106 118 118 112 105 121 127 131 128 104 127 107 106 110 110 110 119 116 124 117 131 120 123 112 126 116 95 107 111 113 122 122 100 124 130 142 111 110 114 102 120 102 109 128 125 102 108 115 108 103 115 122 95 118 119 104 117 116 102 129 107 130 124 113 99 105 103 114 124 120 109 110 109 117 113 112 130 101 105 125 111 106 120 119 132 112 126 118 114 110 121 101 104 98 115 121 120 107 112 108 120 113 102 104 127 131 110 112 125 110 110 111 132 109 119 115 121 102 108 120 118 111 127 123 96 113 124 109 107 131 125 115 93 101 100 90 99 124 120 105 111 101 115 114 103 93 125 114 105 121 117 100 98 124 134 107 129 122 105 99 120 116 117 109 127 133 112 105 114 114 124 114 114 109 116 121 127 111 114 114 124 93 115 117 126 131 127 122 103 117 127 123 135 128 122 114 128 106 116 132 103 120 115 128 110 118 122 121 123 106 102 127 113 124 117 131 118 111 121 119 124 120 111 120 106 111 129 98 113 105 125 111 122 119 112 125 115 116 114 117 108 110 130 117 118 112 110 112 108 126 115 108 121 118 122 117 106 113 137 117 108 117 109 116 134 121 119 118 120 127 109 112 106 126 116 110 124 117 118 119 133 119 129 132 123 106 113 99 119 126 105 129 125 135 105 109 140 121 109 121 126 112 108 117 107 127 118 126 106 111 112 101 118 123 108 117 121 115 124 125 119 102 116 127 124 114 118 104 126 112 103 119 107 105 119 130 108 114 110 124 118 112 113 120 111 99 122 124 121 106 119 110 108 109 104 130 110 131 102 109 118 114 116 121 108 115 100 118 140 106 109 133 108 111 121 103 110 113 110 114 136 123 118 111 118 132 126 102 121 108 117 117 117 110 113 114 101 114 114 126 130 97 109 129 137 119 113 118 103 110 90 124 105 107 126 125 118 115 107 128 109 120 115 109 132 118 115 123 128 116 107 118 127 111 131 106 108 112 130 106 100 103 109 119 124 98 120 105 110 99 120 115 105 120 110 125 106 119 112 114 103 114 106 129 99 105 119 120 117 138 107 111 114 112 112 106 111 121 101 112 89 117 111 128 105 105 108 140 110 122 134 103 108 125 110 111 121 109 116 118 117 103 110 124 112 117 126 121 112 109 133 110 112 139 131 119 123 123 94 118 118 116 102 99 139 123 100 113 125 109 115 110 101 106 127 99 112 110 124 124 123 127 100 116 115 122 109 125 103 130 123 108 103 124 130 122 115 134 128 119 129 119 110 106 105 125 120 97 125 125 106 142 114 123 137 102 109 114 128 124 104 121 135 105 113 109 124 135 123 139 129 105 109 105 128 120 138 110 127 120 113 113 129 116 115 111 121 115 130 131 118 123 119 128 124 101 131 116 123 123 121 102 136 145 135 117 110 112 140 109 138 123 132 120 148 131 134 128 115 113 118 131 119 128 138 122 111 89 127 121 105 111 114 131 129 116 129 137 102 128 114 129 106 115 105 114 115 107 132 126 111 108 129 132 127 110 128 134 115 117 124 124 132 113 125 139 132 114 114 130 124 127 93 136 129 133 113 130 127 129 116 98 116 118 120 124 115 104 137 95 128 108 99 125 130 94 123 126 111 128 104 122 126 116 149 114 116 122 124 125 118 103 112 139 114 121 125 119 111 127 105 119 104 116 100 96 102 109 147 116 134 119 98 111 124 94 123 111 108 137 96 113 102 126 112 116 114 124 124 124 112 110 112 125 110 117 119 125 125 98 126 129 140 104 127 103 109 105 143 126 116 105 121 117 122 120 121 121 120 118 87 128 96 116 124 107 119 113 104 109 110 107 128 126 124 118 119 106 113 126 120 119 115 111 93 111 99 117 126 103 111 113 132 102 107 105 108 124 117 108 98 123 130 97 110 107 106 133 119 110 125 135 125 113 93 130 123 110 109 94 97 123 110 138 119 125 111 127 128 105 122 122 130 121 112 93 125 130 120 128 112 130 109 111 132 123 106 128 117 102 130 105 147 110 122 106 121 128 122 121 115 129 127 99 100 130 127 109 95 126 105 101 118 117 123 133 84 117 105 118 102 113 99 110 115 112 127 116 136 124 122 113 139 109 99 122 152 116 126 118 112 119 107 101 96 135 121 113 105 112 118 117 129 106 110 120 121 111 122 114 131 102 101 118 99 131 115 97 105 119 119 104 115 143 107 124 107 124 114 130 118 111 109 132 126 118 123 112 112 121 126 132 105 112 109 114 136 119 110 128 136 105 143 106 115 108 120 110 120 100 114 115 116 119 134 112 98 116 114 109 122 108 102 113 120 124 132 117 97 122 120 113 89 109 112 106 125 97 122 122 121 123 108 113 106 119 132 115 112 128 126 116 116 126 122 107 109 109 134 105 105 114 106 115 117 110 107 112 131 115 110 128 130 120 110 103 117 109 98 129 112 101 108 102 113 115 116 120 135 117 120 121 89 124 115 131 116 121 124 115 112 107 125 112 120 117 127 116 143 112 101 102 103 121 124 125 117 116 114 103 115 116 108 105 116 104 125 112 118 115 124 93 100 111 113 122 104 110 106 142 129 128 113 108 125 111 111 111 104 119 110 104 136 107 103 118 121 102 119 112 113 105 113 109 104 94 115 99 116 109 118 110 118 98 121 132 108 120 114 109 113 113 125 109 105 115 137 133 109 117 104 99 120 117 124 129 122 100 125 85 121 124 95 123 133 116 111 114 119 137 111 129 105 136 117 102 113 110 115 103 119 128 120 119 128 118 101 120 103 113 109 107 129 118 107 103 114 109 120 124 105 103 118 121 117 99 105 119 93 107 128 111 104 101 115 122 119 111 108 116 118 119 112 108 114 118 126 115 109 113 111 117 117 113 110 95 99 117 107 101 105 142 115 100 96 113 89 126 117 114 116 126 118 108 120 108 119 121 109 102 109 109 112 120 114 99 93 110 99 115 119 112 115 105 118 94 108 112 114 101 107 127 109 103 120 90 120 107 119 106 127 106 104 109 98 122 106 104 127 129 132 117 107 114 113 119 124 107 99 120 107 114 105 93 98 127 124 132 106 92 127 106 111 112 129 109 126 112 103 106 107 118 105 113 113 114 129 108 120 119 120 135 117 114 111 94 127 141 127 120 122 106 113 112 96 124 90 118 135 102 102 138 125 100 99 131 110 117 136 99 108 103 113 137 115 125 114 117 114 105 125 112 104 89 110 111 115 103 93 107 132 115 110 105 121 108 110 97 112 120 114 108 123 103 124 114 123 123 118 130 117 103 121 128 111 97 97 103 112 117 120 126 115 120 131 113 101 99 114 124 105 103 118 99 108 103 108 140 126 92 118 113 113 116 111 122 113 110 127 101 121 116 118 121 110 111 119 117 117 113 130 122 118 117 124 123 119 115 111 123 109 115 114 124 103 131 103 94 113 133 129 113 116 126 115 116 99 113 113 125 106 122 112 120 111 114 116 111 128 122 134 100 117 114 121 120 138 88 115 97 121 111 112 106 126 113 104 114 116 108 116 112 109 126 119 116 115 104 121 126 97 120 123 97 129 135 127 111 115 128 115 119 108 112 118 110 105 118 111 94 125 116 114 131 120 108 96 129 117 125 113 109 121 109 138 117 102 112 104 136 106 101 116 116 109 102 125 111 131 123 94 129 114 123 106 113 109 134 105 116 131 105 116 126 127 105 113 120 118 122 104 119 108 112 135 121 120 115 121 96 98 98 105 115 115 135 104 130 104 118 116 131 112 106 113 93 129 136 101 111 116 120 118 123 120 111 121 108 110 124 108 110 119 113 114 109 109 116 133 128 116 97 118 127 92 114 119 105 126 118 131 109 107 108 112 107 120 118 115 112 117 136 112 133 93 99 115 120 118 113 104 116 121 113 112 117 110 108 134 125 109 116 133 114 102 120 129 117 133 118 126 110 108 116 102 111 112 121 105 107 130 109 109 108 119 111 88 126 116 119 135 110 117 123 106 109 121 112 133 112 123 100 96 124 115 122 107 116 135 113 136 88 91 119 105 113 107 108 126 107 113 125 105 115 119 117 117 124 115 136 127 113 117 112 120 98 114 114 105 130 97 115 116 108 107 101 119 112 115 114 112 100 122 110 114 101 113 129 116 119 124 119 104 110 114 100 116 115 120 103 130 120 99 110 108 107 96 113 131 122 121 103 121 96 103 119 113 115 112 117 114 113 125 127 112 133 100 115 123 121 99 124 124 100 112 110 117 110 126 107 106 114 121 108 115 117 123 111 124 120 107 100 106 110 96 109 109 111 103 119 125 109 101 108 123 109 109 113 92 120 107 119 115 123 102 112 114 120 126 125 113 107 109 124 133 100 114 102 109 133 104 109 105 119 131 104 121 114 98 124 106 99 116 121 119 116 108 119 111 114 128 117 105 105 102 98 121 105 113 100 117 116 120 111 118 118 122 105 141 111 112 114 104 101 114 104 106 107 106 116 123 114 110 113 118 119 127 121 111 125 113 130 104 110 98 98 118 95 137 103 106 120 127 114 115 116 118 112 118 111 108 118 120 100 101 131 129 129 98 112 113 124 107 106 121 121 137 104 108 116 123 102 99 122 99 113 114 102 103 117 125 84 119 108 126 96 111 116 122 109 117 98 127 120 102 106 123 129 112 133 97 103 105 116 112 108 107 126 101 127 105 127 109 104 103 121 127 120 122 101 120 120 125 107 99 125 112 116 119 116 117 120 126 111 115 118 132 129 107 104 104 122 94 113 117 93 122 131 119 119 114 129 125 118 120 108 109 108 102 101 109 106 126 121 121 101 108 115 117 112 117 125 95 115 103 120 121 112 116 120 102 84 105 106 108 118 122 115 102 112 112 109 127 111 112 125 107 123 124 108 108 96 102 124 118 93 125 97 107 121 115 102 123 98 116 110 115 98 114 110 110 109 106 114 119 98 116 113 104 104 125 107 108 123 119 96 116 127 128 99 111 92 104 125 112 102 97 110 101 112 93 116 110 103 123 115 123 126 130 112 104 114 117 106 123 127 109 103 104 123 120 125 113 113 109 109 93 112 109 123 113 133 89 117 108 117 116 108 107 109 119 126 120 118 116 112 88 116 117 104 117 100 122 105 105 119 121 111 107 121 101 108 104 113 116 111 116 121 108 115 118 111 120 118 109 110 119 129 117 108 113 130 103 127 105 124 119 115 108 117 104 127 122 121 115 110 101 129 134 93 111 116 126 122 117 88 112 119 122 121 106 105 105 111 124 120 123 113 116 137 118 122 109 111 110 110 127 117 118 105 115 113 131 119 118 127 124 118 107 116 95 102 121 123 120 118 112 128 117 108 124 113 109 121 124 121 133 143 122 128 133 136 120 136 137 150 108 117 117 140 134 145 135 120 142 137 155 128 119 139 147 139 141 133 130 147 140 113 136 124 123 120 125 137 110 135 129 143 118 118 135 130 144 125 116 132 123 107 115 140 116 123 136 121 104 114 118 132 141 109 121 137 130 119 120 119 96 99 114 119 131 129 113 117 116 113 114 113 126 113 122 111 120 119 117 121 132 98 98 113 112 118 100 132 113 125 101 106 118 117 102 114 104 95 132 123 116 122 93 104 105 126 122 130 111 121 121 113 114 111 141 116 114 111 107 130 127 107 110 106 128 103 114 115 112 107 116 101 99 115 119 114 128 128 104 122 108 130 124 102 115 104 102 104 106 105 95 102 119 107 116 111 110 112 91 105 124 124 117 98 129 104 94 106 122 95 105 110 129 113 111 107 119 120 106 91 109 127 105 122 110 108 111 125 118 119 119 126 105 96 106 127 101 117 100 106 108 101 111 121 119 118 110 107 108 108 128 91 122 104 107 116 138 107 124 123 119 100 114 116 103 123 119 120 104 125 105 104 99 97 114 102 121 121 117 106 127 114 101 102 115 116 110 100 127 112 110 132 116 99 131 107 106 104 108 108 106 125 107 107 87 113 124 125 116 121 117 98 115 112 114 118 102 113 106 124 113 97 131 110 117 118 114 106 96 104 128 125 111 112 97 130 118 110 125 112 138 112 103 103 121 120 121 120 124 122 135 97 111 119 96 127 103 118 107 134 96 117 109 121 158 112 123 113 110 108 102 111 108 120 102 133 114 111 123 110 116 117 117 116 129 114 121 109 111 114 126 119 105 115 101 106 102 108 118 115 93 121 113 106 110 118 112 138 113 105 133 129 108 99 96 104 113 115 98 103 129 134 117 109 109 121 103 111 106 102 107 116 121 99 120 133 123 118 139 121 108 120 119 107 121 101 122 110 120 124 116 103 111 116 106 114 103 115 104 119 115 122 133 115 111 104 118 110 123 102 122 104 95 112 107 103 100 107 104 111 108 110 105 106 132 102 117 117 108 118 113 93 122 111 116 103 119 107 99 108 116 89 118 116 106 120 118 89 104 107 114 105 126 124 129 128 114 114 113 99 90 111 130 117 114 107 112 130 108 124 114 122 111 111 107 128 133 106 127 97 91 113 120 123 123 100 102 111 111 114 114 94 97 103 118 97 125 114 119 111 114 101 102 114 105 97 105 107 111 120 98 114 94 130 108 125 116 100 123 133 94 116 120 101 115 118 109 104 118 113 108 107 123 109 111 109 114 114 117 120 118 108 89 125 89 117 121 91 115 115 117 111 142 103 114 100 104 117 118 117 108 137 120 105 119 130 133 92 99 121 104 121 116 97 108 101 109 106 109 108 98 102 131 121 120 105 113 120 116 100 115 112 76 102 111 110 107 142 106 97 109 111 108 122 100 119 116 110 126 108 104 88 122 101 116 129 119 106 114 110 95 103 105 124 128 104 111 125 100 106 109 116 133 120 124 114 106 109 111 119 128 103 122 117 121 101 129 116 99 107 105 122 117 133 136 117 134 124 127 103 115 100 124 112 127 109 133 119 112 106 108 109 124 130 123 114 108 111 104 103 108 101 107 112 125 94 139 116 113 119 104 124 112 128 118 104 103 129 127 127 139 104 117 113 129 109 124 104 118 127 106 98 122 114 134 110 112 112 110 124 119 115 102 104 126 103 107 114 131 123 111 122 142 122 121 116 93 125 127 113 98 103 120 120 115 107 107 102 117 119 121 121 121 105 119 91 120 127 102 113 106 105 120 112 127 120 108 120 108 113 133 106 106 123 110 107 117 104 99 101 131 122 98 79 114 114 113 115 121 116 140 139 116 120 127 129 88 100 127 136 129 134 137 134 100 105 107 107 128 111 117 122 112 112 107 106 126 105 120 116 118 120 85 127 108 113 114 106 106 114 106 113 121 113 123 119 111 120 100 104 104 100 127 114 94 105 109 124 119 99 111 118 115 103 120 108 123 103 103 119 101 114 124 91 139 105 107 105 92 115 116 103 111 131 109 103 113 123 124 119 98 121 125 103 123 125 103 121 134 117 114 103 121 136 97 115 116 132 129 115 111 93 123 108 122 109 103 110 95 111 116 105 77 132 109 99 123 113 101 107 115 105 106 112 108 114 114 128 148 99 102 104 107 109 130 101 100 125 125 108 111 120 104 111 131 116 115 111 95 108 106 106 110 113 99 107 138 122 112 110 130 111 105 132 118 103 119 117 110 99 115 105 132 99 97 103 131 126 138 103 121 109 113 110 111 114 111 130 106 98 100 123 111 127 102 112 97 95 116 119 97 134 104 109 106 95 116 121 93 89 89 110 111 104 120 115 110 112 108 107 117 109 114 105 118 115 102 112 111 124 97 113 115 113 115 113 115 121 125 119 102 114 101 108 126 120 102 102 121 117 105 117 90 123 116 104 127 115 113 117 77 115 107 112 105 111 121 127 126 113 121 105 111 131 119 115 90 104 111 113 102 120 103 122 114 103 128 105 116 110 124 110 139 101 111 113 114 115 127 113 81 104 125 132 134 120 116 96 112 120 103 109 108 97 115 117 120 123 112 130 103 122 127 125 109 95 113 126 128 121 118 120 101 112 126 117 101 104 110 128 113 112 106 109 124 120 104 109 116 101 116 124 120 110 111 113 97 137 116 110 109 136 125 120 122 128 112 124 115 118 108 106 109 112 106 118 109 132 109 112 119 116 121 130 119 110 98 118 127 131 107 141 124 102 117 115 99 115 125 111 126 118 104 126 109 117 111 133 119 128 118 113 99 107 103 128 117 131 117 120 134 101 115 95 124 117 126 134 126 119 115 119 104 103 104 105 121 119 131 120 112 114 91 133 123 117 124 138 121 91 108 125 113 123 129 99 97 116 128 107 110 111 111 118 108 126 116 124 116 127 105 131 130 123 102 99 128 109 109 112 104 110 120 111 127 102 121 115 126 116 114 101 119 106 112 97 109 95 123 126 129 110 110 110 112 102 117 116 132 97 110 126 102 114 108 118 108 97 125 105 108 114 100 129 106 114 110 126 108 104 117 124 104 105 128 102 123 124 114 112 113 98 119 118 114 92 108 112 119 102 108 117 111 123 112 117 107 117 108 115 109 111 114 123 107 115 134 132 146 109 121 101 115 114 117 113 119 107 127 122 121 114 111 98 122 123 107 108 98 88 115 126 128 124 130 129 127 112 125 110 118 116 94 121 94 123 107 113 105 130 120 118 105 114 116 115 114 120 116 99 104 128 103 129 114 129 121 126 118 112 101 106 115 121 105 120 107 115 140 109 126 112 116 123 142 119 106 123 98 114 116 98 94 102 119 118 117 85 119 120 123 113 128 134 97 119 108 112 111 109 108 134 119 141 138 128 101 114 112 114 132 117 107 118 122 110 115 110 112 116 112 115 108 138 111 114 117 100 126 116 110 106 132 121 114 131 108 111 111 131 132 117 122 105 112 108 110 109 134 108 119 105 108 121 134 102 113 109 121 109 117 130 128 115 114 106 108 126 117 112 100 104 95 123 101 97 110 102 109 117 106 123 122 112 97 115 119 117 135 135 119 117 113 132 106 118 101 124 131 112 138 111 100 110 111 135 117 113 121 139 132 111 119 109 109 107 117 98 108 106 98 109 98 106 116 128 124 112 116 120 134 112 137 112 102 135 111 159 108 117 121 132 116 92 120 101 116 114 124 119 129 133 111 113 114 115 125 107 116 113 96 136 136 104 121 113 101 129 118 127 109 124 117 136 138 114 102 118 98 110 108 128 135 111 124 120 110 119 103 122 122 124 107 121 130 120 129 126 125 100 110 111 100 134 120 127 131 133 131 102 136 113 136 122 123 120 135 133 135 121 96 119 124 111 127 134 127 122 123 129 131 120 132 115 115 119 105 131 115 113 121 119 128 128 123 129 114 121 122 131 119 112 111 120 125 107 119 128 107 109 109 121 112 119 109 106 124 121 118 132 100 110 125 110 99 127 106 121 109 142 121 130 127 148 109 118 119 135 134 118 109 126 102 105 109 123 108 135 117 106 126 115 121 126 119 113 116 102 122 130 118 122 117 116 119 111 131 115 117 110 121 105 106 109 119 118 106 103 144 129 117 118 97 108 112 114 109 133 109 120 111 125 147 116 106 114 112 142 136 113 115 102 123 117 128 121 102 115 103 109 107 115 129 127 123 104 108 125 125 109 119 100 120 104 113 127 109 124 98 101 122 138 107 125 114 108 103 113 122 97 112 109 116 116 108 106 109 103 132 97 93 125 112 105 114 101 123 118 121 110 111 129 99 115 104 123 139 94 129 126 117 124 112 127 119 101 124 118 107 113 123 142 126 97 111 102 110 127 92 115 109 112 128 121 102 96 117 99 109 102 116 115 116 123 128 111 109 116 130 132 113 118 126 100 115 114 116 106 123 109 113 102 107 105 128 93 115 109 137 133 125 127 129 131 110 109 108 104 110 111 116 128 124 124 111 100 109 118 119 99 126 101 105 117 136 108 108 97 119 124 132 110 102 105 109 137 109 112 98 116 120 100 105 102 110 132 110 111 113 119 105 113 89 122 123 105 117 92 122 114 108 111 135 127 105 126 127 134 115 112 114 110 109 108 122 123 119 113 118 117 112 97 109 104 122 105 135 121 107 104 103 113 118 110 125 129 131 112 110 124 113 118 122 110 105 127 121 85 115 116 109 106 100 99 106 127 97 126 142 127 116 119 119 118 109 115 115 121 108 103 114 116 125 136 119 132 100 124 103 116 98 116 105 129 108 122 109 121 112 145 114 82 115 111 112 109 129 107 133 110 121 104 112 102 116 106 135 133 103 136 99 118 119 142 106 114 118 136 120 111 123 119 122 116 106 99 125 115 119 136 131 106 106 119 109 106 122 124 105 135 107 110 126 121 111 115 145 118 127 108 103 99 127 113 126 103 80 111 121 131 113 124 121 120 114 122 146 94 119 93 124 109 105 103 104 114 101 128 122 110 124 125 122 128 116 103 118 123 132 111 134 109 106 136 109 126 110 123 113 115 134 101 106 97 124 129 112 116 123 111 120 116 114 110 118 137 101 125 125 123 127 120 112 108 93 121 123 142 107 119 112 102 129 108 118 123 108 124 124 120 142 103 114 117 127 123 116 121 122 115 117 128 116 125 119 103 105 95 116 120 124 108 124 113 106 137 111 103 140 98 118 103 112 121 138 130 129 110 98 107 121 120 134 123 111 115 106 103 133 94 111 121 127 121 111 106 118 132 118 111 123 129 111 119 111 121 129 118 136 109 118 117 101 113 117 111 121 121 108 117 125 124 122 124 98 119 117 109 121 108 127 106 122 98 121 107 106 102 122 120 115 133 123 112 94 121 116 140 120 109 128 114 105 124 110 90 110 105 115 116 108 131 126 118 120 149 113 117 132 126 113 113 118 97 125 119 116 112 107 112 118 127 120 137 122 122 116 130 111 107 110 105 116 127 107 103 107 111 96 102 99 109 120 113 106 111 126 138 104 100 126 120 128 111 109 118 130 92 127 114 104 117 123 115 120 118 111 116 102 107 138 109 117 131 112 94 128 100 103 109 117 106 120 108 100 116 117 98 107 110 98 117 109 114 123 125 98 114 111 118 121 103 128 129 113 121 103 120 108 114 130 123 125 133 117 120 117 127 106 130 111 127 122 128 123 107 131 102 117 120 121 134 109 123 136 111 111 104 101 124 123 115 107 119 125 125 105 119 112 133 101 126 117 112 122 113 130 112 128 103 107 110 126 109 117 125 113 117 120 112 139 117 117 109 103 115 84 99 104 101 108 139 107 110 123 104 120 124 109 122 102 119 109 112 102 110 113 114 100 123 124 122 124 106 108 118 116 108 113 143 126 114 110 139 113 104 114 108 133 118 107 126 116 106 114 128 104 118 114 121 122 94 132 113 120 119 126 110 103 104 95 129 109 131 113 140 103 138 96 127 125 113 118 110 114 110 100 127 112 111 118 137 124 117 97 114 127 133 119 92 106 114 112 124 126 113 125 106 127 110 131 126 117 119 120 110 108 119 110 107 115 120 138 101 108 108 115 119 118 92 101 110 135 115 118 113 120 110 103 137 105 130 115 90 101 109 99 111 123 108 104 125 121 113 112 121 114 122 110 135 101 113 108 95 116 107 114 120 115 122 126 131 97 132 130 113 120 115 110 101 104 104 123 118 108 108 99 115 110 121 99 129 124 98 118 92 128 129 114 115 129 115 111 118 122 117 108 129 99 132 107 91 118 114 94 106 107 120 118 115 98 117 134 99 131 107 93 121 138 133 108 111 94 122 111 124 111 109 113 124 127 109 119 96 122 119 103 96 118 100 115 110 134 123 117 130 91 110 110 126 124 105 122 114 102 95 113 138 111 117 90 104 107 114 138 105 114 128 100 136 135 126 112 96 124 108 108 124 130 113 119 105 122 146 116 119 104 117 112 128 98 89 117 145 101 122 105 127 111 113 100 99 120 103 121 103 112 138 111 111 121 125 116 133 110 121 133 110 146 139 128 108 104 121 115 111 110 120 126 118 123 119 117 107 114 111 107 104 121 118 128 128 97 97 126 121 121 127 112 96 107 127 128 114 113 112 107 94 103 117 118 106 105 111 112 114 115 124 112 117 105 122 111 121 136 131 102 105 127 92 115 155 106 131 124 103 135 112 121 133 130 113 120 114 117 111 106 120 106 111 105 94 114 118 126 120 102 114 116 126 100 108 111 132 126 133 126 125 123 96 122 114 104 130 129 106 97 110 100 117 121 126 89 103 94 113 116 120 111 100 116 120 100 114 139 118 128 105 110 117 127 137 110 98 118 119 90 106 122 100 116 116 89 102 94 111 116 118 116 109 133 115 116 111 115 112 92 110 115 111 132 121 118 115 115 93 137 114 120 112 122 151 126 94 128 114 121 134 112 89 119 112 117 111 118 92 121 115 123 115 105 118 107 115 114 116 118 141 128 109 117 116 120 114 135 107 131 112 95 107 119 93 87 115 109 132 119 100 112 123 104 129 132 118 109 106 125 122 111 124 104 104 107 115 107 102 108 123 142 109 110 102 101 124 139 111 95 120 98 107 99 128 101 128 111 111 130 124 106 100 92 112 131 109 122 121 137 106 127 119 106 113 132 130 125 123 117 98 113 122 114 103 127 134 118 108 107 129 104 106 119 99 100 114 110 98 127 121 118 103 119 107 125 121 94 108 127 117 121 113 105 122 115 109 109 106 115 109 109 119 113 139 100 135 112 131 119 125 125 118 110 105 130 114 121 100 113 116 129 129 112 112 127 99 123 108 122 120 104 112 113 116 107 120 119 126 117 105 124 104 110 128 105 128 116 116 104 122 89 99 122 115 124 121 113 125 130 116 125 126 87 126 122 111 117 107 115 96 125 119 128 129 115 97 114 128 134 115 86 111 131 113 119 122 115 117 109 113 128 123 100 112 114 128 127 115 126 126 117 152 108 125 121 101 95 121 103 115 107 97 109 105 120 101 94 103 109 111 124 106 106 96 136 123 114 109 109 117 121 136 127 126 118 102 123 133 109 90 119 104 129 97 125 130 102 132 119 122 111 122 125 120 99 125 128 109 112 119 106 117 125 109 128 110 106 99 109 132 120 120 122 112 118 114 122 127 109 142 117 117 126 128 129 119 151 112 135 122 109 137 125 108 129 130 117 123 146 116 128 101 120 145 120 138 100 111 113 131 119 123 108 124 105 146 113 117 117 98 125 109 141 107 135 116 117 122 126 138 110 123 134 100 130 109 131 119 122 115 127 129 127 116 126 102 138 136 118 127 116 114 116 139 130 119 116 117 121 139 124 142 115 137 112 119 118 117 116 104 127 114 137 106 133 154 114 113 108 125 139 146 134 129 124 126 145 116 115 110 124 122 129 136 133 121 131 114 120 104 112 137 119 135 125 116 126 131 121 119 111 130 126 122 129 128 134 122 148 122 120 104 123 102 102 119 131 129 125 141 111 136 126 127 132 101 128 91 99 101 108 113 124 112 108 109 114 125 122 124 100 107 122 99 131 119 131 119 110 86 127 118 117 123 109 116 124 122 130 130 114 123 109 140 141 99 113 118 106 123 120 129 115 123 117 115 116 126 114 116 107 124 114 119 106 104 110 122 112 130 114 120 99 126 112 113 116 101 129 123 123 114 118 121 107 142 104 113 121 115 125 113 102 120 105 132 113 114 121 119 140 130 115 130 129 123 112 98 123 110 127 126 121 129 111 110 125 109 110 123 126 124 113 104 113 135 127 96 102 131 127 127 131 147 124 134 137 118 119 116 108 146 115 103 115 110 104 113 116 138 139 140 105 122 112 114 119 114 119 116 112 122 94 121 128 118 125 104 103 130 115 126 140 124 130 129 123 113 111 127 119 128 136 108 115 117 98 96 109 100 106 126 107 127 120 108 109 117 106 113 117 123 105 116 124 108 124 116 117 120 104 96 131 135 123 113 122 113 110 116 115 113 123 119 123 110 134 123 104 133 112 127 111 117 140 110 114 127 108 110 116 114 95 110 132 125 117 116 114 112 115 142 120 112 131 116 125 110 116 111 101 119 122 113 101 112 130 119 122 130 129 102 137 117 119 113 113 113 119 116 110 87 117 108 139 118 122 117 127 114 111 91 111 116 120 150 111 113 128 120 109 117 107 101 118 112 125 113 114 108 125 120 105 108 128 111 111 123 128 110 139 127 111 125 102 133 105 105 91 120 123 127 103 120 120 115 119 126 115 131 102 121 99 127 108 117 133 113 140 101 110 130 118 127 132 119 105 115 120 122 123 137 111 119 124 133 132 127 129 110 124 126 120 104 127 110 98 123 127 110 109 133 110 128 122 104 113 113 116 115 130 95 115 128 121 112 112 119 135 120 138 120 123 129 122 116 134 123 114 117 120 118 127 110 114 116 130 133 109 132 125 108 111 131 111 115 124 113 111 126 101 111 104 101 99 122 132 113 118 136 112 120 110 115 92 117 132 106 111 121 110 114 122 109 125 124 139 147 117 131 124 115 116 126 140 115 117 112 120 121 110 114 121 109 131 125 120 123 98 123 102 126 115 105 116 132 127 117 108 133 118 118 116 106 125 134 118 138 113 127 118 123 146 113 134 123 105 96 101 129 112 113 104 118 112 120 135 103 98 125 128 114 119 126 114 112 107 112 123 115 113 107 109 128 132 107 114 123 116 123 111 134 120 96 128 118 124 112 115 96 103 117 118 113 133 104 115 108 114 118 121 123 109 101 107 131 126 112 110 91 122 124 120 99 111 117 113 130 121 109 138 126 130 134 94 104 122 111 124 123 127 108 92 116 119 98 101 124 121 116 106 112 124 148 111 120 108 119 108 113 127 130 114 110 118 104 104 114 123 123 99 109 101 105 119 128 130 111 100 114 101 129 121 101 109 127 125 123 120 125 111 128 131 108 113 122 112 105 128 113 122 114 114 118 125 133 124 107 112 127 144 146 123 109 110 106 119 118 105 122 113 114 120 137 124 98 121 116 117 138 115 124 105 128 121 115 128 125 132 131 116 117 108 149 115 118 101 141 118 117 113 125 126 125 120 110 106 120 115 135 109 105 134 138 117 101 121 119 103 122 138 91 107 130 121 129 125 108 110 122 120 107 124 116 120 110 124 115 130 109 122 117 126 139 118 118 115 102 100 128 109 111 111 96 108 102 112 111 130 105 103 111 117 111 112 120 104 136 95 118 117 121 104 106 127 114 141 118 103 114 135 122 131 114 114 121 113 100 109 125 122 126 119 123 108 122 118 113 114 116 131 120 112 117 111 120 114 121 141 110 111 125 117 112 114 111 134 112 119 126 124 121 116 108 121 130 116 124 119 118 110 129 134 123 126 126 119 123 119 131 110 113 131 104 133 112 117 128 102 126 111 125 117 114 117 93 135 121 120 118 148 121 112 143 115 109 115 115 119 106 118 115 136 116 132 108 124 119 101 123 141 116 109 122 111 105 120 116 104 124 111 115 117 117 124 119 125 124 137 117 132 109 120 118 119 130 125 123 122 120 121 123 125 111 127 123 122 95 107 108 122 119 113 115 110 123 109 91 146 109 108 117 134 121 121 132 122 112 118 130 99 133 116 135 116 129 124 125 113 119 145 123 125 115 106 136 113 122 121 129 98 120 127 129 114 128 134 125 121 112 113 134 129 111 122 109 110 112 117 130 125 114 117 115 116 144 115 104 88 106 121 115 110 116 117 123 126 110 117 122 123 121 100 130 111 123 111 138 122 122 117 132 125 117 117 118 127 134 118 120 115 109 108 116 131 104 128 104 112 102 106 125 121 125 129 105 105 131 116 125 135 118 127 116 125 126 118 129 143 107 128 120 103 128 119 141 123 123 108 122 118 111 99 122 112 128 96 137 135 105 121 124 123 111 102 123 114 134 115 136 134 123 106 103 108 112 134 115 137 135 127 99 103 104 118 106 114 109 125 127 123 126 108 144 115 123 122 125 132 118 110 131 132 116 117 119 130 130 148 133 116 119 133 116 122 127 132 113 119 134 127 125 112 122 139 116 118 103 93 120 124 106 119 120 108 130 112 104 110 109 119 115 113 120 119 125 128 116 125 112 125 138 119 119 144 128 133 123 114 110 132 112 115 114 121 145 113 128 118 113 111 121 121 126 117 133 117 124 131 125 110 114 129 108 111 122 110 121 120 119 128 131 141 127 133 116 125 112 121 119 128 125 135 122 100 134 125 113 126 125 116 104 106 104 131 128 109 128 109 127 107 132 128 138 123 131 115 140 109 136 136 128 115 129 121 116 93 109 121 129 123 153 133 102 143 131 123 109 125 131 124 138 119 121 125 142 131 122 144 121 138 133 113 100 120 127 118 127 127 123 131 129 117 146 135 140 104 130 96 125 146 116 116 123 132 99 144 118 131 125 121 110 127 120 124 110 107 137 126 111 126 123 112 115 116 123 119 112 112 131 126 106 128 132 120 120 119 131 116 125 109 134 123 105 116 118 134 110 127 127 125 125 118 126 115 108 127 113 114 120 122 119 120 111</counts>
			</dataPoints>
		</scan>
	</xrdMeasurement>
</xrdMeasurements>