File: data/XRD/XG-Sauerstoff/XG-pre/W6822-1B_XG_Sauerstoff_pre.xrdml
<xrdMeasurements xmlns="http://www.xrdml.com/XRDMeasurement/2.1" xmlns:xsi="http://www.w3.org/2001/XMLSchema-instance" xsi:schemaLocation="http://www.xrdml.com/XRDMeasurement/2.1 http://www.xrdml.com/XRDMeasurement/2.1/XRDMeasurement.xsd" status="Completed">
	<comment>
		<entry>Configuration=Factory configuration, Owner=User-1, Creation date=7/8/2013 4:01:53 PM</entry>
		<entry>Goniometer=PW3050/65 (Theta/2Theta); Minimum step size 2Theta:0.0001; Minimum step size Omega:0.0001</entry>
		<entry>Sample stage=MRD Cradle; Minimum step size Phi:0.01; Minimum step size Chi:0.01; Minimum step size X:0.01; Minimum step size Y:0.01; Minimum step size Z:0.001</entry>
		<entry>Diffractometer system=XPERT-PRO</entry>
		<entry>Measurement program=C:\PANalytical\Data Collector\Programs\Jorrit\2thom\_absolute_2th-om_10-130deg_PIXscan_56min.xrdmp, Identifier={15BCCF57-2807-42BD-B5B9-ECC0B3DC9284}</entry>
		<entry>Batch program=C:\PANalytical\Data Collector\Programs\SimonL\batch4x_2thom_10-130°_z9.1_x0,10,20,30_y0_57min.xrdmp, Identifier={EED9823A-2BEB-424C-9252-345C4EF2834A}</entry>
	</comment>
	<sample type="To be analyzed">
		<id></id>
		<name></name>
		<preparedBy></preparedBy>
	</sample>
	<xrdMeasurement measurementType="Scan" status="Completed" sampleMode="Reflection">
		<comment>
			<entry>_absolute_2th-om_10-130deg_PIXscan_56min</entry>
			<entry>PHD Lower Level = 4.83 (keV), PHD Upper Level = 11.27 (keV)</entry>
		</comment>
		<usedWavelength intended="K-Alpha 1">
			<kAlpha1 unit="Angstrom">1.5405980</kAlpha1>
			<kAlpha2 unit="Angstrom">1.5444260</kAlpha2>
			<kBeta unit="Angstrom">1.3922500</kBeta>
			<ratioKAlpha2KAlpha1>0.5000</ratioKAlpha2KAlpha1>
		</usedWavelength>
		<incidentBeamPath>
			<radius unit="mm">320.00</radius>
			<xRayTube id="1010048" name="Empyrean Cu LFF HR (9430 033 7310x) DK442154">
				<tension unit="kV">40.0</tension>
				<current unit="mA">40.0</current>
				<anodeMaterial>Cu</anodeMaterial>
				<focus type="Line">
					<length unit="mm">12.0</length>
					<width unit="mm">0.4</width>
					<takeOffAngle unit="deg">4.2</takeOffAngle>
				</focus>
			</xRayTube>
			<xRayMirror id="27010001" name="Inc. Beam Cu W/Si (parabolic MRD)" hybrid="false">
				<crystal type="Graded" shape="Parabolic">W/Si</crystal>
				<acceptanceAngle unit="deg">0.800</acceptanceAngle>
				<length unit="mm">60.0</length>
			</xRayMirror>
			<sollerSlit id="21010002" name="Soller slits 0.04 rad.">
				<opening unit="rad">0.0400</opening>
			</sollerSlit>
			<mask id="22030007" name="Fixed mask 2 mm">
				<distanceToSample unit="mm">220.00</distanceToSample>
				<width unit="mm">2.00</width>
			</mask>
			<divergenceSlit id="22010007" name="Fixed slit 1/8°" xsi:type="fixedDivergenceSlitType">
				<distanceToSample unit="mm">220.00</distanceToSample>
				<height unit="mm">0.19</height>
			</divergenceSlit>
		</incidentBeamPath>
		<diffractedBeamPath>
			<radius unit="mm">320.00</radius>
			<sollerSlit id="21010002" name="Soller slits 0.04 rad.">
				<opening unit="rad">0.0400</opening>
			</sollerSlit>
			<receivingSlit id="22010001" name="Fixed slit 4°">
				<height unit="mm">5.88</height>
			</receivingSlit>
			<detector id="7010017" name="PIXcel3D 1x1 detector" xsi:type="areaDetectorType">
				<phd unit="%">
					<lowerLevel>30.0</lowerLevel>
					<upperLevel>70.0</upperLevel>
				</phd>
				<mode>Scanning</mode>
				<activeChannelsEquatorial>255</activeChannelsEquatorial>
				<activeChannelsAxial>255</activeChannelsAxial>
				<pitchEquatorial unit="mm">0.05500</pitchEquatorial>
				<pitchAxial unit="mm">0.05500</pitchAxial>
				<readOutPeriod unit="seconds">0.135</readOutPeriod>
			</detector>
		</diffractedBeamPath>
		<scan appendNumber="0" mode="Continuous" scanAxis="2Theta-Omega" status="Completed">
			<header>
				<startTimeStamp>2024-09-10T17:41:54+02:00</startTimeStamp>
				<endTimeStamp>2024-09-10T18:38:00+02:00</endTimeStamp>
				<author>
					<name>PRO-MRD</name>
				</author>
				<source>
					<applicationSoftware version="6.1b">Data Collector</applicationSoftware>
					<instrumentControlSoftware version="7.0E 20130304">XPERT-PRO</instrumentControlSoftware>
					<instrumentID>0000000011142674</instrumentID>
				</source>
			</header>
			<dataPoints>
				<positions axis="2Theta" unit="deg">
					<startPosition>9.99826193</startPosition>
					<endPosition>129.99755682</endPosition>
				</positions>
				<positions axis="Omega" unit="deg">
					<startPosition>4.99913096</startPosition>
					<endPosition>64.99877841</endPosition>
				</positions>
				<positions axis="Phi" unit="deg">
					<commonPosition>0.00</commonPosition>
				</positions>
				<positions axis="Chi" unit="deg">
					<commonPosition>0.00</commonPosition>
				</positions>
				<positions axis="X" unit="mm">
					<commonPosition>10.00</commonPosition>
				</positions>
				<positions axis="Y" unit="mm">
					<commonPosition>0.00</commonPosition>
				</positions>
				<positions axis="Z" unit="mm">
					<commonPosition>9.100</commonPosition>
				</positions>
				<commonCountingTime unit="seconds">32.895</commonCountingTime>
				<counts 204 213 181 227 213 208 186 211 215 206 235 197 215 208 212 206 205 213 212 217 217 225 193 193 236 195 203 210 240 223 224 238 204 221 226 197 223 210 205 219 208 221 214 222 195 235 223 212 222 225 229 228 208 222 217 201 222 214 199 201 206 213 226 175 241 201 247 192 228 208 192 229 189 200 216 183 210 191 205 206 231 190 198 186 210 194 184 232 213 207 216 178 199 193 212 198 188 210 194 188 211 176 210 218 186 177 200 198 191 188 197 221 203 218 193 214 202 207 218 202 208 196 211 193 198 198 189 202 190 196 195 211 180 197 207 223 185 195 224 198 236 192 203 221 217 194 209 195 194 190 231 228 223 209 180 159 199 207 211 180 199 199 197 213 177 213 193 191 190 155 203 167 220 190 212 179 191 197 194 199 189 188 179 203 203 198 182 203 188 205 202 173 207 190 213 198 170 187 198 190 185 191 174 181 194 201 192 198 179 185 184 183 185 185 168 214 191 191 199 193 192 197 165 181 170 180 201 211 189 202 197 180 183 186 187 211 210 202 189 188 184 198 211 180 195 184 177 168 178 204 195 178 181 168 176 175 201 184 194 163 181 213 165 170 200 176 189 200 203 193 205 170 181 206 181 190 172 176 189 199 196 188 182 188 185 178 197 165 186 191 192 158 178 207 194 177 181 164 181 191 171 183 182 194 196 186 182 173 201 179 178 189 173 195 169 167 197 176 181 174 183 168 200 172 162 158 166 180 164 173 160 165 193 166 181 170 202 174 172 184 150 178 147 182 175 170 174 170 174 191 195 158 156 174 159 191 183 181 187 178 174 176 156 183 171 167 166 154 160 170 162 186 181 193 168 160 170 167 154 155 182 157 160 170 193 161 189 158 174 153 172 187 173 180 167 169 150 164 172 159 161 185 189 176 156 156 174 159 157 159 176 182 144 164 175 176 152 151 163 176 170 188 164 158 165 150 139 172 176 157 168 139 160 186 154 160 168 152 168 162 158 162 193 145 157 177 151 153 208 175 161 180 183 148 169 176 163 159 183 186 160 167 162 170 175 157 146 142 165 172 150 179 186 176 160 167 185 176 172 180 153 158 151 170 138 141 166 164 161 169 150 158 166 178 167 173 179 173 176 157 172 158 148 168 171 164 153 163 153 156 166 162 163 155 160 153 152 143 140 158 175 158 157 158 172 161 168 169 147 153 169 168 168 167 157 183 162 160 181 172 148 142 164 164 157 139 137 167 158 187 143 153 144 188 122 145 141 154 162 173 155 177 164 125 151 160 154 157 154 159 150 155 155 157 135 165 174 143 156 171 161 164 139 162 151 153 158 153 164 161 173 171 155 154 135 156 141 156 153 172 171 172 165 153 153 170 129 149 154 143 149 153 146 139 164 172 147 147 155 178 140 166 157 151 150 164 131 140 137 178 159 160 165 160 154 151 163 143 169 140 144 161 157 155 156 148 163 154 142 161 138 155 165 168 150 147 159 171 143 134 168 156 145 167 139 149 173 161 134 125 162 150 152 144 159 138 160 144 155 159 145 145 155 164 146 142 149 145 178 149 152 156 139 137 136 151 159 154 145 145 152 167 152 147 148 162 171 127 152 168 140 144 140 169 172 172 163 147 155 148 165 144 133 143 147 156 156 144 143 131 172 139 130 145 149 190 157 123 153 152 150 142 145 155 141 159 162 154 154 152 132 139 161 146 159 129 147 152 134 143 146 160 154 137 145 148 143 161 154 139 160 150 142 150 159 136 154 150 142 127 144 165 141 166 159 141 143 144 159 141 145 151 143 149 147 139 145 153 135 155 169 153 140 138 151 153 156 141 142 167 129 135 147 142 138 138 157 135 131 143 160 155 146 139 157 150 144 155 157 158 173 151 140 141 141 155 169 155 153 143 146 147 119 150 139 149 139 155 151 144 154 150 136 141 171 154 149 152 170 144 146 147 143 148 161 158 159 153 155 128 151 119 169 171 152 141 137 136 141 156 142 156 168 147 158 148 159 138 157 145 159 157 152 164 183 155 149 151 146 135 136 146 156 146 134 142 153 163 159 165 130 151 164 147 154 124 135 149 172 152 150 154 158 151 135 145 136 149 158 137 170 139 158 172 160 175 156 146 154 135 165 161 141 153 163 159 147 136 158 155 164 140 160 128 133 165 146 159 123 157 148 141 160 161 163 152 144 156 149 138 159 149 155 122 168 153 148 139 149 165 163 159 167 145 162 170 150 164 143 146 161 139 181 151 142 147 151 152 161 152 176 155 145 123 127 163 159 158 165 145 129 150 163 165 168 127 140 142 150 150 150 152 156 154 146 159 180 167 164 153 156 177 180 149 141 139 139 151 152 179 170 140 160 154 157 172 129 179 135 150 135 150 157 133 150 155 135 161 146 175 168 144 154 152 161 163 159 168 172 145 167 173 163 151 169 145 165 140 147 153 168 160 173 167 138 140 134 166 159 158 170 170 156 135 183 148 179 148 174 153 186 157 165 151 149 158 158 154 150 153 167 171 162 140 185 134 153 162 146 147 146 167 163 167 145 152 125 177 175 165 158 148 169 151 159 146 165 171 135 149 173 141 157 174 174 168 156 158 157 178 167 145 160 165 149 161 147 152 154 183 142 188 182 160 166 168 158 156 170 157 171 154 176 181 157 150 166 159 148 140 153 165 170 159 165 151 175 160 162 186 160 155 155 176 181 173 139 160 150 139 177 152 140 144 168 157 168 150 156 159 141 182 161 170 192 173 159 162 167 155 174 145 164 166 160 166 147 151 183 142 151 150 166 163 167 165 135 163 158 170 145 142 127 156 156 186 162 157 168 152 157 169 155 162 185 161 164 151 157 178 148 161 155 156 181 165 156 179 165 164 153 157 141 143 177 159 171 182 147 156 158 138 172 147 146 143 152 167 188 163 126 149 163 160 171 158 153 144 175 142 173 163 156 168 154 160 160 175 144 160 173 170 169 179 148 141 160 166 161 175 194 180 178 173 160 162 182 174 140 135 141 152 169 150 186 157 167 169 151 149 148 158 151 133 144 148 154 172 165 152 167 170 123 160 142 138 161 149 176 155 172 148 142 164 155 151 141 161 168 167 154 143 191 143 156 156 159 159 180 166 134 132 129 141 157 157 171 150 140 145 136 152 149 158 162 160 164 149 142 145 165 142 142 144 142 152 144 150 129 175 158 134 144 149 167 154 151 163 152 129 136 155 141 153 158 144 164 142 152 147 158 163 144 140 144 155 144 161 158 170 158 147 129 159 163 177 147 169 147 147 167 153 153 143 147 175 139 147 148 158 167 153 126 135 187 140 129 177 129 157 157 157 134 145 145 152 145 158 143 135 168 127 158 158 139 119 147 146 142 156 138 162 140 148 131 139 152 159 163 132 141 162 151 132 148 133 151 159 168 147 142 157 146 138 152 133 137 133 145 150 168 146 132 164 133 154 140 159 148 167 177 134 143 139 129 137 146 145 145 112 132 159 164 131 176 147 143 134 124 160 117 134 142 135 151 136 152 124 143 143 143 131 149 125 138 144 166 101 118 134 158 121 136 135 132 132 148 131 146 143 157 128 144 132 131 151 144 143 150 149 153 152 132 132 135 157 155 129 145 155 138 143 142 170 147 146 136 129 145 137 158 155 139 129 163 135 140 157 151 141 136 144 159 149 134 128 131 135 145 132 150 128 120 130 124 116 134 164 146 142 154 146 130 140 143 138 157 152 138 137 151 149 132 144 154 134 152 128 154 153 116 133 124 150 146 125 140 154 128 129 141 132 140 136 138 140 137 151 145 135 150 141 153 146 144 145 144 147 123 135 149 125 137 133 156 129 127 128 119 141 127 153 135 139 123 123 151 133 118 146 119 130 147 133 128 133 145 143 122 109 132 136 134 115 141 123 133 138 132 126 116 110 139 140 117 139 117 133 125 126 125 133 120 140 141 133 122 132 127 153 117 110 160 133 165 117 129 112 139 147 141 125 109 134 133 118 143 140 135 129 119 127 148 133 140 143 124 122 114 135 113 116 135 145 137 147 140 144 134 132 129 119 132 127 121 123 120 114 128 125 138 117 150 135 119 102 114 130 131 146 110 138 128 117 138 109 109 132 139 130 114 130 130 116 122 111 135 119 156 140 114 136 131 124 152 134 144 110 146 110 130 133 130 126 126 122 130 123 135 121 105 132 105 136 116 140 142 133 147 122 132 139 110 115 125 118 118 119 114 127 114 129 130 137 112 120 121 130 149 112 125 138 133 126 107 143 137 127 124 124 116 146 127 148 126 141 110 113 147 124 130 123 140 110 131 113 115 107 115 112 138 129 121 109 113 127 134 123 125 110 123 116 114 115 121 118 128 114 131 138 125 127 128 100 113 101 112 122 96 128 107 123 106 135 126 140 134 111 134 120 135 113 111 124 129 119 138 119 114 136 122 131 114 116 125 96 120 103 127 107 117 122 124 120 117 130 121 102 110 127 114 114 136 135 133 111 118 123 114 114 100 137 101 105 107 120 121 119 118 126 122 126 124 113 120 136 125 132 99 120 108 120 104 139 112 134 110 116 118 119 120 97 109 116 115 105 113 151 105 124 121 94 101 109 103 122 122 114 122 108 115 92 119 114 111 130 120 131 93 135 112 120 119 114 116 115 118 122 117 146 131 114 107 134 115 112 120 96 124 119 120 123 121 139 133 109 120 123 112 109 129 132 134 96 133 122 113 100 104 110 120 106 122 123 117 110 124 121 101 94 118 120 102 105 112 136 131 118 100 93 117 142 121 108 109 104 111 116 106 105 122 122 100 126 123 114 99 112 102 106 124 122 125 113 124 123 116 119 112 112 124 109 118 107 98 97 111 123 111 115 112 124 103 118 114 115 105 97 113 124 130 124 97 99 130 124 96 105 110 114 105 104 113 119 105 126 102 124 113 124 123 114 131 109 112 106 129 112 95 108 110 118 115 109 124 113 123 115 128 100 122 97 108 95 86 119 90 113 101 100 82 127 90 105 126 118 93 98 101 98 95 99 102 117 111 108 115 118 91 105 106 113 121 104 134 108 101 115 121 118 115 124 113 105 122 129 119 107 122 122 129 93 111 98 110 91 130 113 115 113 120 123 113 92 88 117 112 94 103 126 102 125 98 116 127 115 119 112 109 109 123 114 107 113 114 120 126 123 107 110 114 105 121 92 115 102 109 108 121 121 91 111 124 106 118 93 109 107 106 114 114 113 111 101 107 117 135 118 112 110 110 83 102 107 117 115 122 121 122 91 122 93 113 96 89 105 119 122 114 109 111 105 92 129 92 135 108 111 98 93 99 126 99 104 101 109 96 91 105 107 101 124 110 109 96 120 119 103 110 131 109 116 123 97 124 89 105 109 92 102 118 124 102 117 96 100 100 98 100 94 101 114 114 98 89 101 101 107 86 114 127 94 100 103 98 100 109 99 97 121 108 108 96 113 90 108 130 96 113 113 132 117 100 111 110 96 93 112 130 130 115 93 107 114 102 93 117 107 96 111 99 105 116 116 107 93 102 75 99 102 115 102 97 119 104 96 107 113 116 93 96 119 96 97 103 117 102 91 120 91 92 99 117 96 105 97 115 108 105 110 101 105 125 118 122 102 110 112 123 104 104 95 114 91 95 106 111 108 96 93 105 90 119 118 118 102 108 128 103 109 103 97 113 93 95 105 104 110 114 127 123 112 99 102 102 105 94 89 73 86 108 97 109 137 118 115 103 113 106 123 84 97 89 106 99 127 112 106 104 115 107 100 97 110 120 130 102 109 100 123 101 116 108 113 108 96 104 117 109 88 87 101 116 120 135 116 111 95 101 102 112 102 108 107 114 103 127 127 103 91 97 109 106 104 97 101 103 111 105 108 121 107 89 114 104 115 111 105 81 107 108 117 115 95 112 119 112 95 111 99 114 92 101 102 118 100 127 111 94 116 99 122 102 114 102 109 116 95 116 96 86 110 108 103 88 111 102 120 110 105 102 126 94 90 95 95 91 108 104 109 115 98 109 97 95 108 102 107 106 112 107 119 109 104 101 106 101 121 101 110 108 94 93 85 125 111 106 119 100 98 103 114 107 112 84 95 116 94 99 103 95 94 118 117 112 99 119 113 106 93 107 94 111 110 92 100 99 85 112 87 117 104 106 108 111 94 100 96 111 124 86 109 78 100 107 103 93 99 97 107 91 110 104 99 102 105 98 105 127 109 122 108 102 88 110 81 97 93 102 100 118 96 117 112 106 115 93 118 98 98 93 93 95 84 111 102 99 80 98 114 90 111 90 93 94 105 99 99 88 88 106 106 87 97 98 102 109 90 100 98 116 81 102 104 97 91 109 106 108 115 92 113 109 94 102 99 127 97 108 98 127 90 86 94 92 103 84 97 92 87 99 104 113 106 114 95 107 93 105 93 97 114 78 88 91 82 102 105 101 100 110 110 94 93 98 102 95 110 115 94 100 102 89 104 114 121 84 92 110 103 95 97 106 113 97 103 105 99 106 120 112 125 107 106 93 107 99 110 116 113 105 118 113 97 95 99 108 108 108 95 102 119 112 106 93 80 110 96 100 111 99 92 90 95 107 87 112 96 102 92 84 103 101 98 102 96 86 95 116 117 115 117 108 102 106 95 110 94 90 91 96 90 111 92 104 111 104 110 95 97 100 106 110 110 104 103 126 101 93 115 95 107 108 107 119 90 102 101 91 97 101 107 91 93 95 94 92 109 87 98 106 99 112 89 98 86 102 107 102 96 102 118 99 113 101 95 85 98 111 91 121 105 110 111 101 96 111 101 120 105 103 124 90 96 105 120 85 104 100 118 103 110 108 109 99 113 99 99 90 98 89 100 120 119 104 111 106 87 115 101 114 82 107 129 117 100 108 114 115 97 99 122 107 99 97 106 84 95 113 96 87 99 93 104 91 96 113 93 121 111 90 114 99 112 99 112 93 97 95 89 136 122 108 90 116 93 92 119 92 107 114 100 105 98 103 113 126 87 105 103 112 97 118 110 122 116 102 88 113 121 123 94 96 115 83 106 101 112 114 96 102 123 114 121 131 97 102 88 101 100 102 109 83 103 102 100 104 118 83 117 102 108 104 119 100 114 105 105 102 102 110 100 108 118 104 127 109 104 111 96 98 116 99 114 119 109 117 100 93 107 132 95 119 90 108 102 109 110 96 106 113 114 94 87 124 94 102 113 108 110 111 97 115 99 78 102 121 99 121 86 94 100 109 97 87 92 95 140 98 114 81 127 96 118 89 115 87 106 106 100 92 119 103 91 102 115 100 99 114 111 100 101 97 97 114 116 106 101 96 90 99 119 88 116 83 103 117 95 102 98 106 98 85 123 104 110 127 78 96 112 91 112 118 122 121 104 104 127 86 108 116 102 102 107 108 102 121 108 98 114 99 105 97 108 120 98 111 108 91 92 96 97 92 102 99 112 107 108 126 128 108 110 103 101 97 116 103 86 102 97 105 114 97 116 89 103 99 104 94 121 100 100 113 112 115 107 96 109 99 99 94 111 104 113 97 85 114 98 125 113 101 108 104 94 106 118 118 111 97 108 100 97 107 102 120 95 107 110 113 100 106 91 104 101 117 107 88 91 110 106 107 110 119 111 100 102 100 111 100 117 100 98 104 112 108 109 114 103 113 121 114 100 101 93 115 104 98 112 124 112 110 100 115 103 117 115 101 103 110 104 120 115 103 121 112 114 104 110 126 108 106 106 141 103 125 118 107 120 107 105 112 113 129 102 116 122 110 111 113 110 125 129 123 120 136 119 104 125 126 122 136 122 125 127 134 122 136 107 149 128 106 146 139 153 134 140 137 143 143 156 165 150 154 160 185 153 161 162 191 158 153 179 170 188 184 204 164 174 184 194 160 186 172 176 163 137 145 168 152 146 148 168 131 138 144 158 114 130 113 140 143 105 131 135 115 115 134 110 113 124 111 96 113 108 123 112 106 107 111 124 118 103 123 121 114 103 124 113 108 99 118 114 109 137 95 123 108 125 127 102 105 103 99 110 99 105 110 115 110 117 106 101 111 112 110 111 118 95 98 99 100 99 99 128 97 124 99 110 110 101 107 121 103 121 116 117 114 105 105 107 101 93 125 107 111 94 104 97 91 101 99 105 109 96 103 121 115 111 125 115 92 102 110 104 110 104 95 106 87 125 105 113 102 97 104 104 113 102 105 110 77 91 89 107 97 118 99 108 106 104 92 105 100 110 106 115 104 97 123 92 110 91 112 106 89 114 113 90 117 94 96 115 86 100 109 122 100 92 93 111 113 108 93 96 95 94 115 114 112 108 132 102 96 108 104 115 98 87 111 112 116 108 119 104 115 105 91 107 109 118 100 98 97 103 109 97 106 104 93 104 107 109 84 99 117 90 82 104 108 110 103 99 103 102 100 99 120 106 108 105 113 100 94 111 107 90 106 101 140 114 99 99 108 113 103 104 103 77 97 120 117 92 114 99 93 117 110 93 99 106 109 114 111 94 97 120 116 104 97 95 105 105 92 99 103 90 110 73 104 105 113 94 107 103 109 133 95 101 83 99 105 112 96 98 99 111 112 98 101 114 88 104 96 87 108 99 83 112 109 105 108 102 105 85 104 100 103 80 113 98 98 112 121 95 93 103 94 88 78 104 107 101 112 115 89 105 106 96 104 98 101 86 110 113 98 78 103 121 108 91 106 96 102 101 104 97 113 103 92 102 100 124 96 79 95 100 106 106 115 114 85 109 100 97 97 99 104 93 109 93 112 113 100 108 87 105 115 84 93 118 114 99 75 94 98 106 117 103 116 93 101 103 102 106 101 102 109 95 89 124 92 108 98 93 95 121 106 116 104 101 86 88 89 102 97 85 113 112 88 98 113 95 100 82 104 115 109 118 101 109 96 90 99 112 107 114 110 90 92 87 96 99 91 94 115 109 90 105 109 92 99 100 104 120 83 112 94 112 112 106 116 85 97 111 96 98 112 93 98 101 90 99 98 112 91 100 94 99 97 125 98 99 101 102 79 104 106 102 89 107 108 96 94 105 114 86 99 88 91 117 100 108 98 96 103 99 88 101 129 106 102 101 102 102 131 97 85 98 110 126 95 96 93 106 97 92 96 104 96 110 108 112 95 111 97 96 103 87 87 112 110 116 102 87 97 106 89 115 108 103 101 115 89 85 110 114 94 109 97 112 114 91 95 113 93 93 129 91 71 97 100 97 99 95 85 84 102 100 98 98 107 101 108 98 121 101 108 120 97 113 78 111 110 84 119 108 110 97 103 109 109 95 98 98 115 99 97 95 91 106 94 94 96 85 90 97 99 89 107 99 94 102 93 106 98 103 111 106 110 100 94 107 90 85 123 101 94 91 104 86 98 111 101 101 111 100 94 97 125 113 103 88 93 111 105 102 104 107 86 117 99 114 114 114 103 97 99 114 94 97 96 94 122 110 117 100 100 108 110 96 103 89 100 94 100 85 105 130 103 102 100 105 106 107 100 101 89 100 100 96 99 94 105 103 99 97 102 95 103 83 98 117 104 97 118 99 95 104 82 129 112 106 103 112 98 96 94 84 92 104 112 96 95 108 101 113 120 102 107 117 114 98 96 113 99 91 103 105 111 87 88 110 91 91 96 115 90 105 102 116 107 106 104 88 104 108 103 85 128 102 97 101 109 104 86 65 107 109 122 110 102 119 102 123 115 106 98 94 97 88 108 96 85 101 105 98 83 118 95 121 125 115 106 88 119 103 115 112 107 109 94 115 112 99 113 113 107 101 112 115 114 124 110 94 90 102 109 102 108 97 110 116 116 107 107 100 100 102 111 96 111 85 98 90 104 111 95 91 105 99 110 115 113 106 109 101 113 94 86 119 113 110 104 97 94 95 104 119 107 129 125 109 105 120 88 101 96 135 118 105 95 95 109 94 114 89 115 92 103 97 86 98 81 109 113 105 107 107 112 114 127 85 104 104 104 105 114 101 102 95 87 91 100 92 100 111 109 94 90 89 99 101 121 96 88 103 104 107 99 92 109 97 108 113 88 101 89 102 99 96 116 107 110 103 113 116 102 103 97 103 102 103 104 96 109 96 95 115 85 96 112 114 94 104 83 119 108 92 114 123 101 102 109 94 95 114 98 91 101 92 105 98 99 98 95 104 102 95 94 113 99 90 99 106 97 103 106 103 102 100 115 95 115 103 97 97 117 98 98 102 109 105 99 100 109 88 107 111 108 88 94 100 101 87 107 108 104 90 114 100 99 124 97 104 89 90 100 94 106 97 97 100 113 102 96 94 112 116 110 86 113 91 103 93 92 89 117 120 96 96 103 105 103 85 87 103 98 113 103 104 80 90 101 96 107 105 99 117 103 94 121 116 103 99 106 92 94 103 91 97 96 101 107 102 97 119 135 106 111 96 112 81 90 107 96 104 97 108 103 91 105 97 106 101 108 119 108 85 91 108 107 102 97 107 125 106 111 89 80 91 98 103 97 105 93 101 102 87 90 111 94 99 106 102 97 83 112 105 96 122 101 103 119 98 93 105 105 112 107 100 118 101 109 125 106 107 116 89 109 97 114 99 98 118 100 108 96 111 80 103 114 112 98 100 98 109 98 96 101 98 83 102 107 121 100 100 97 94 106 110 110 124 98 93 106 84 86 94 112 79 95 107 84 98 109 105 98 112 83 100 95 117 101 106 103 101 106 105 105 98 83 88 98 112 87 104 98 110 110 110 97 110 99 116 98 78 102 103 92 80 117 122 123 111 113 96 96 98 105 112 92 132 112 97 98 99 108 89 86 89 85 95 93 97 100 93 102 111 94 109 105 98 96 113 107 103 100 88 93 100 107 109 89 101 108 98 96 106 119 98 108 101 101 105 109 107 102 91 98 112 90 100 113 113 108 102 113 113 102 111 99 117 108 103 102 94 93 106 102 94 104 104 112 105 101 110 90 109 106 117 122 104 94 82 100 93 96 104 112 106 94 83 101 92 99 109 112 104 114 95 109 104 101 89 97 96 87 103 109 86 103 104 117 97 98 110 92 113 100 107 89 101 103 102 96 93 84 93 99 97 97 115 121 86 95 105 111 86 105 85 101 106 115 123 102 109 105 99 118 105 105 96 91 107 106 108 110 99 107 104 120 108 80 101 85 118 106 93 98 100 104 94 119 109 106 107 106 92 103 107 91 109 102 119 94 107 106 131 101 123 105 111 116 112 105 108 119 118 112 92 101 97 106 97 97 110 91 104 92 111 103 84 99 108 129 96 102 93 107 115 104 101 105 99 91 99 105 104 98 118 109 99 95 117 112 112 99 131 102 100 113 106 106 93 97 94 103 98 115 94 107 87 114 112 106 92 104 105 125 108 107 98 102 109 112 101 81 112 96 107 90 94 108 86 94 86 105 93 104 119 114 88 95 84 111 108 90 109 97 117 91 80 85 100 78 102 110 98 99 100 108 110 107 115 94 95 98 87 100 104 103 105 111 85 95 93 109 121 106 97 108 87 97 92 99 116 92 104 94 115 100 102 90 100 101 93 94 117 101 90 104 111 113 81 97 90 88 100 97 93 115 108 98 108 123 101 113 116 91 118 99 99 120 95 108 86 102 108 102 127 96 102 109 106 98 111 104 97 127 92 96 91 98 98 108 101 111 95 98 107 95 119 86 112 97 92 92 115 118 89 105 109 118 90 106 81 102 111 111 92 127 109 98 101 102 102 94 100 131 107 94 99 104 92 99 100 94 109 102 89 105 81 106 96 119 101 100 89 105 125 112 109 84 107 120 87 113 124 84 112 97 104 104 101 107 99 107 116 122 122 108 127 80 98 107 107 103 123 110 107 90 106 104 95 121 92 100 83 105 84 94 97 101 101 107 92 108 102 110 105 102 93 106 92 106 114 77 108 107 94 99 95 93 98 101 104 115 107 110 105 123 99 99 86 111 105 93 100 109 105 109 100 108 100 94 92 93 104 89 88 107 110 95 114 96 109 109 130 97 100 111 106 97 102 105 106 109 114 99 93 89 100 87 94 118 104 104 107 95 91 102 106 96 107 96 97 83 95 98 117 93 87 99 95 97 106 88 102 116 90 96 116 93 112 119 77 81 95 92 106 104 115 105 103 103 101 106 109 109 107 109 104 91 119 104 89 113 107 122 106 104 119 97 119 102 95 108 102 84 122 90 100 105 121 86 111 110 110 91 94 116 105 101 111 89 100 110 91 100 110 90 114 96 111 120 91 79 87 103 121 101 100 107 107 107 103 91 102 114 100 116 117 113 122 101 104 111 106 97 116 99 110 88 95 90 92 108 105 103 91 100 116 96 96 97 101 102 92 84 105 119 130 116 129 106 91 105 116 110 92 108 89 124 116 110 115 103 92 101 105 104 106 118 115 99 106 106 100 118 131 105 115 120 115 94 95 130 99 111 82 117 106 102 99 107 109 97 86 100 117 131 115 111 107 118 112 117 107 100 117 95 102 97 117 103 94 102 109 108 111 97 105 130 116 118 128 109 121 112 110 98 125 112 110 125 100 99 101 91 110 95 98 90 92 95 116 112 89 124 94 120 105 129 97 85 115 127 96 92 80 109 110 108 109 107 124 105 113 111 85 106 113 98 116 105 93 111 98 119 108 98 117 106 113 116 104 117 117 119 100 99 124 105 127 107 111 91 90 105 108 115 102 97 109 108 102 120 90 105 102 110 104 126 108 107 96 109 119 116 126 144 120 94 101 102 111 114 117 86 126 114 121 92 100 97 79 109 99 107 104 98 95 118 108 108 114 112 101 116 103 95 96 103 118 114 101 97 116 104 101 124 116 109 98 103 84 130 110 110 121 93 112 114 85 86 93 116 125 95 109 118 112 114 117 115 108 112 94 106 99 105 94 110 93 96 116 116 89 99 102 113 101 111 90 98 92 104 111 108 94 77 104 112 97 110 96 88 97 119 92 88 115 113 101 103 92 94 103 84 102 107 105 103 99 87 96 105 90 116 94 96 113 93 96 101 92 101 99 110 105 104 111 100 120 124 85 98 108 119 89 128 120 100 108 97 96 122 95 98 102 115 111 103 100 102 96 107 107 126 93 103 113 121 97 116 101 100 90 113 108 94 92 95 97 103 122 95 98 83 105 106 108 105 94 93 101 102 106 119 96 109 89 85 79 110 113 98 110 124 118 121 106 98 111 81 111 101 102 115 95 126 107 118 92 103 96 118 108 97 116 119 105 108 101 112 103 94 96 98 100 117 119 111 81 92 106 108 99 101 112 113 130 91 104 114 107 119 101 106 120 107 89 98 99 95 110 129 108 116 98 113 106 104 104 110 131 103 102 105 111 90 139 92 102 114 104 101 112 109 119 104 106 111 99 105 92 88 112 97 93 104 99 81 115 111 111 97 79 102 103 109 91 115 109 102 122 100 101 100 105 86 120 101 99 117 101 127 105 100 89 92 93 112 120 94 96 120 107 99 96 83 110 116 119 102 96 93 132 105 99 97 109 95 102 97 95 99 101 109 116 112 102 105 93 93 114 90 97 126 103 103 97 102 98 100 104 96 103 96 101 93 114 113 104 109 112 103 108 93 92 107 90 115 112 115 109 102 91 96 99 77 106 107 102 117 84 99 80 103 118 112 115 100 114 106 93 106 111 121 102 111 88 92 87 83 104 99 93 106 111 102 116 87 107 93 98 118 104 91 94 104 83 103 87 94 92 90 102 108 100 124 82 105 107 94 102 103 97 85 112 99 107 104 95 106 81 80 94 82 88 107 92 102 113 89 93 110 92 116 104 104 102 92 107 110 88 114 113 118 100 114 86 104 108 97 103 105 109 98 92 109 97 97 104 102 122 106 93 100 118 123 115 84 106 109 86 95 106 100 96 105 120 103 99 125 99 104 93 106 108 111 95 91 114 81 101 112 95 107 112 101 105 91 114 109 93 96 112 106 108 122 91 89 98 99 102 109 92 91 104 100 111 102 99 93 111 96 101 118 100 103 76 107 73 89 97 89 102 110 119 109 105 91 93 83 95 95 101 107 92 93 92 101 105 114 104 90 94 122 89 104 109 115 88 120 92 114 103 106 103 115 91 107 100 97 97 107 94 108 91 91 98 96 89 107 90 114 109 92 112 102 114 125 91 98 90 86 113 121 92 106 113 110 89 101 108 104 89 98 103 89 102 110 103 105 95 96 104 97 92 104 89 103 99 105 116 110 110 111 91 104 97 119 98 107 91 96 97 99 95 121 103 122 87 95 105 121 99 86 116 99 97 131 91 102 85 123 104 106 111 101 117 89 100 90 93 105 122 89 94 84 104 98 93 111 94 127 92 100 105 101 98 115 110 105 104 108 104 107 114 104 88 104 92 91 122 89 102 103 110 103 77 105 88 107 76 110 100 96 122 104 115 123 91 106 130 124 82 108 106 101 94 106 97 73 91 101 100 107 88 107 84 109 88 104 106 103 107 90 95 108 91 103 89 87 96 95 110 102 93 104 104 104 97 103 117 110 86 100 119 102 119 96 106 100 114 91 111 125 114 96 84 83 108 103 81 89 104 107 102 101 111 95 107 109 99 91 101 79 101 95 95 102 90 102 138 114 104 112 114 88 116 107 111 84 108 100 93 101 108 96 96 98 100 96 106 116 106 91 100 107 98 94 99 99 97 109 94 112 112 102 106 107 93 99 98 95 102 100 103 91 114 109 92 107 79 106 108 96 116 84 102 108 90 107 89 107 93 91 80 99 95 96 114 101 107 116 107 89 90 112 94 106 100 107 99 99 111 107 105 99 106 108 122 107 93 126 95 90 114 94 112 94 100 102 106 110 112 95 109 102 94 103 100 104 103 100 106 93 112 107 96 108 108 107 102 95 106 120 111 78 97 106 87 90 112 100 96 111 112 94 101 97 105 103 101 106 106 107 91 107 125 96 119 108 101 98 110 102 116 110 108 91 106 82 93 109 110 111 106 102 103 112 107 106 118 104 97 95 115 118 110 100 86 105 105 96 103 95 104 110 95 104 103 122 84 111 117 101 95 111 118 93 100 102 116 121 96 105 122 104 112 117 89 105 100 111 102 95 128 109 90 112 115 105 108 100 121 87 115 114 99 100 99 101 102 86 94 108 100 96 96 96 89 117 103 96 85 97 96 79 103 103 92 92 99 99 109 89 105 107 114 86 109 93 95 101 92 114 88 96 107 89 88 102 103 90 106 90 102 96 98 102 93 113 104 98 78 93 101 115 108 105 97 95 97 92 104 103 107 109 104 79 111 79 83 105 114 129 104 83 104 105 116 104 86 102 95 95 100 94 103 111 102 110 107 108 106 93 102 98 99 97 111 86 102 108 88 98 109 95 95 111 124 99 103 105 92 116 94 101 93 114 84 103 108 123 84 92 101 86 112 90 99 97 111 117 106 98 85 119 104 96 82 92 102 120 103 107 108 108 113 85 102 114 107 91 98 99 108 94 97 101 90 99 112 93 81 98 111 88 116 93 88 107 106 113 119 118 93 99 104 94 114 126 103 99 86 97 104 107 107 85 115 97 88 82 91 111 108 87 102 113 116 90 103 105 76 103 111 100 109 107 116 95 89 128 92 116 95 80 103 115 87 111 87 102 113 92 90 115 112 87 92 100 105 87 105 102 91 83 96 86 88 97 103 103 106 105 122 92 114 75 131 103 104 87 93 126 118 115 94 109 100 109 95 90 91 111 110 110 93 92 100 88 87 115 110 100 106 100 96 132 80 110 108 100 95 105 96 88 94 104 90 95 104 80 90 103 104 106 110 75 91 87 99 99 104 109 106 96 103 85 94 104 93 91 94 110 115 96 108 98 91 91 97 95 98 100 105 120 109 112 98 97 98 97 96 105 100 97 112 107 89 99 92 106 95 105 112 108 104 103 88 122 104 100 107 96 95 115 98 112 117 94 112 104 101 109 100 109 98 94 105 84 108 112 108 109 90 109 92 111 82 85 106 106 115 101 112 83 114 98 98 81 99 107 108 76 105 101 84 102 109 108 101 91 99 93 99 114 105 92 80 89 103 95 100 92 104 91 101 103 100 93 101 98 99 82 109 98 92 125 96 121 109 96 109 98 76 87 107 92 94 118 90 110 112 113 107 99 82 82 102 109 99 105 93 96 88 108 87 95 93 110 99 108 93 93 114 101 96 109 110 92 121 85 96 103 96 101 92 112 101 85 108 120 108 113 93 115 97 100 107 87 95 102 95 107 85 113 103 90 111 107 113 95 106 90 93 101 95 113 92 100 96 103 108 97 96 99 116 92 97 105 115 91 106 105 100 87 119 97 98 101 87 116 114 103 95 101 98 128 107 111 102 93 104 89 106 80 90 95 106 112 89 102 103 104 110 91 118 102 98 89 103 99 105 98 74 102 109 98 110 106 124 101 96 102 94 109 99 117 102 95 109 105 115 90 113 99 111 101 106 102 107 109 100 108 124 117 114 95 112 112 115 108 126 95 106 105 106 113 97 106 106 112 107 91 117 109 130 119 105 92 109 99 113 101 104 103 132 123 118 114 120 111 106 98 109 103 109 115 114 97 126 100 92 113 125 108 116 123 112 101 122 105 104 131 118 100 96 92 104 111 128 102 115 121 102 104 88 96 116 97 101 119 87 91 124 69 100 91 115 115 104 113 106 105 109 113 90 103 111 102 105 86 115 92 85 101 104 110 107 127 110 136 104 116 90 102 97 97 104 84 114 110 111 105 105 102 90 105 96 111 111 102 111 100 91 116 135 102 91 93 104 108 96 103 95 102 108 124 104 111 105 102 102 97 96 112 116 112 97 86 105 96 100 91 110 88 116 100 105 100 93 97 102 121 101 88 98 100 94 97 110 100 125 104 102 108 90 88 96 103 86 97 94 105 97 103 121 99 83 100 103 104 104 108 92 79 90 92 100 116 88 88 101 92 125 93 95 116 97 94 88 92 125 124 99 100 90 118 99 102 93 112 86 107 91 94 113 84 104 99 105 99 99 89 103 100 103 98 108 101 72 103 92 95 96 103 114 93 99 88 97 86 94 99 108 94 90 92 97 97 88 107 123 113 83 91 105 105 89 91 87 98 111 105 80 91 98 91 90 102 107 98 101 98 95 92 112 98 91 114 99 102 98 104 107 69 89 91 86 90 104 90 99 81 84 90 100 101 90 86 110 116 108 105 110 112 83 91 96 103 108 92 101 94 109 77 106 93 92 84 102 106 98 114 94 87 89 84 93 107 102 92 93 82 106 89 106 102 89 95 114 108 96 98 104 114 97 101 124 71 102 97 84 92 82 98 98 115 87 110 99 96 104 100 104 98 89 101 99 95 92 115 114 96 108 83 102 85 91 94 102 98 96 82 100 112 103 88 95 105 77 116 108 101 95 75 109 99 91 90 120 96 83 103 87 97 91 108 104 96 87 87 109 100 105 87 98 108 91 117 99 95 96 111 99 89 114 97 82 94 89 98 103 98 90 106 110 94 86 87 121 104 91 82 95 90 101 105 102 76 96 89 115 98 78 96 96 88 88 95 87 98 103 88 110 100 83 108 90 87 70 85 128 92 98 95 92 93 118 122 110 98 105 93 79 103 104 98 109 88 106 98 97 101 96 96 93 99 97 111 88 99 115 92 93 114 107 100 97 93 96 81 98 76 75 104 91 116 110 94 84 110 92 94 82 85 82 93 102 92 93 83 101 83 96 82 92 117 86 99 103 114 84 93 93 91 88 95 87 93 103 96 87 83 124 100 91 104 91 117 104 111 81 89 96 113 103 106 84 90 103 112 96 99 88 96 79 78 82 95 76 83 94 86 116 95 109 85 98 92 100 93 87 91 80 80 79 96 94 95 86 84 108 92 91 95 103 103 76 85 101 83 92 93 89 90 99 89 88 98 87 96 83 102 100 90 111 102 103 105 99 98 78 99 103 90 89 90 103 101 102 101 113 94 84 100 91 97 78 94 89 92 95 106 109 101 94 87 97 86 90 89 87 104 102 105 81 85 86 91 105 96 98 88 96 90 101 100 101 86 99 94 105 96 86 98 93 90 91 99 89 99 84 99 78 113 90 86 94 102 106 89 90 94 102 94 87 97 111 99 94 80 95 89 94 94 100 96 83 90 90 88 91 113 91 97 93 85 90 84 98 109 108 116 93 87 91 91 76 80 87 78 88 82 103 88 88 79 86 97 99 98 103 98 98 102 85 96 94 89 88 91 96 88 80 88 83 97 92 80 121 94 97 75 118 99 119 92 96 94 97 102 105 82 85 86 100 89 89 111 87 101 80 101 104 86 87 93 100 98 96 90 93 91 106 87 86 90 96 99 89 92 84 94 92 86 121 106 79 64 105 71 107 110 88 96 104 105 77 94 83 120 95 98 96 119 83 88 118 99 81 85 101 99 107 106 110 80 97 70 96 109 85 88 108 88 89 89 109 96 101 101 88 109 85 111 118 87 89 96 87 98 89 93 100 104 89 85 92 98 99 94 111 117 90 106 110 99 73 96 83 104 93 93 87 93 78 103 98 98 105 104 88 104 90 86 109 83 113 93 102 104 88 97 101 94 96 97 85 74 93 90 81 92 89 94 91 90 91 102 94 102 104 102 95 84 92 88 105 83 100 92 83 76 97 95 93 75 86 91 91 86 98 97 86 100 83 96 100 87 110 94 79 105 102 96 90 105 79 94 99 86 79 98 103 89 89 87 100 106 107 101 95 89 96 82 95 103 88 101 101 92 106 87 85 99 104 90 102 96 108 85 84 82 114 106 103 76 104 110 94 81 108 104 105 103 95 103 87 95 94 86 95 83 90 91 76 103 84 95 89 86 95 105 85 89 95 85 91 100 104 101 89 98 85 83 98 102 97 88 90 87 106 81 95 91 93 94 96 86 86 82 104 76 96 93 80 96 72 94 94 99 92 86 92 83 81 96 111 93 95 82 104 98 85 87 83 76 90 107 87 82 96 87 83 100 75 92 100 84 101 96 102 94 94 100 85 83 99 96 89 88 95 93 100 100 91 76 91 90 92 103 96 73 102 98 90 82 69 82 79 114 90 88 101 96 82 91 89 105 98 99 96 79 95 104 92 82 93 92 115 95 108 86 85 90 117 84 85 85 109 105 88 81 93 98 86 88 97 118 92 111 93 93 90 79 103 79 90 84 80 91 89 98 77 97 89 97 108 82 87 86 107 94 90 88 105 104 80 129 98 110 113 89 95 102 101 107 89 90 97 91 90 103 94 96 90 93 103 89 91 84 111 103 74 84 91 77 104 98 104 100 98 96 90 93 93 97 99 93 95 90 101 85 86 99 92 97 105 91 94 101 86 110 107 100 94 82 120 76 96 92 91 80 94 95 80 92 90 109 86 103 79 93 110 86 77 86 99 90 95 90 89 94 103 94 109 91 124 88 93 105 104 103 88 112 97 107 95 85 115 92 87 97 79 87 87 94 88 81 99 83 89 85 94 120 94 115 100 91 107 86 90 90 93 102 89 102 92 112 98 74 101 99 90 92 101 92 104 90 78 97 102 92 104 96 101 82 103 88 111 93 100 96 102 103 94 80 85 88 92 98 102 111 75 82 96 104 113 88 110 93 99 91 92 85 96 88 104 99 81 86 101 87 83 114 81 109 101 108 82 89 100 93 84 100 96 100 99 88 88 94 88 89 87 82 88 85 87 94 102 109 96 91 86 102 98 97 95 103 82 89 97 92 88 103 117 90 98 96 95 99 115 97 107 95 123 87 89 82 105 91 96 102 93 78 118 89 88 99 116 104 88 90 105 104 91 107 89 97 103 95 109 86 92 94 80 107 100 89 78 105 91 89 84 95 97 104 98 99 90 113 102 83 88 89 100 94 96 96 102 83 100 84 91 120 95 115 94 90 93 80 84 89 86 103 89 93 93 101 89 101 91 85 88 95 87 95 102 87 86 105 102 92 91 102 106 97 91 92 116 108 102 101 90 100 96 90 102 91 91 94 94 119 104 94 90 100 107 86 103 105 101 91 111 109 104 88 88 95 105 105 90 118 99 89 113 95 103 129 104 81 102 101 96 87 90 90 125 88 82 100 90 92 88 88 91 99 100 98 97 96 115 91 88 103 92 110 103 89 88 113 90 106 87 97 90 102 99 95 83 112 95 93 81 118 111 102 82 109 98 87 102 99 108 80 91 103 100 103 91 108 98 99 104 98 99 104 75 89 88 92 106 99 104 88 102 102 118 99 96 97 98 107 100 92 87 78 110 101 93 90 91 112 98 112 98 82 89 122 88 97 76 103 88 90 94 98 115 108 102 84 102 98 79 99 103 97 105 105 93 103 103 82 99 96 90 93 99 110 105 108 103 96 109 98 93 108 100 96 108 98 92 114 89 119 124 99 92 75 101 101 93 83 126 101 102 100 94 100 101 101 94 93 120 82 97 98 80 98 85 87 91 101 94 114 99 104 96 87 91 93 89 84 88 98 100 101 101 112 92 102 105 63 101 97 89 95 103 92 84 102 113 102 99 100 89 96 91 99 98 100 119 84 88 82 102 110 105 99 105 111 105 81 107 94 75 99 94 89 106 100 95 108 88 126 98 88 92 102 91 104 81 103 93 100 110 107 71 98 86 103 103 107 90 104 79 97 109 88 88 109 94 81 102 92 117 90 105 91 90 99 102 104 95 91 96 92 96 92 97 103 92 98 99 93 91 100 91 91 99 100 90 106 91 84 100 98 97 96 81 94 76 99 113 113 89 106 91 109 94 103 126 93 101 87 99 113 92 97 94 95 128 90 97 96 77 113 86 88 95 95 78 98 75 106 80 91 73 93 95 104 95 97 107 88 114 75 89 101 91 83 86 112 86 91 104 96 102 115 84 82 96 88 92 113 106 100 78 102 99 95 76 92 110 94 85 100 92 95 88 84 91 96 92 109 119 97 94 101 100 99 98 92 92 87 79 100 87 100 104 102 96 79 107 99 100 87 101 111 93 90 94 95 98 98 77 102 101 102 108 95 92 97 76 94 93 96 86 103 84 87 110 88 96 99 90 86 93 87 95 87 109 89 102 100 104 84 104 84 85 101 93 95 89 93 106 92 86 95 91 93 89 80 94 99 93 91 92 91 91 102 107 91 105 92 105 99 79 95 84 94 98 90 98 69 84 101 110 78 99 104 106 77 90 109 61 109 101 108 100 99 91 86 99 96 86 90 69 119 102 87 86 102 97 87 108 90 92 100 94 102 103 105 93 86 87 83 104 111 98 91 98 89 100 97 104 99 81 88 85 110 106 106 91 121 107 108 96 98 103 91 92 97 89 96 95 106 102 92 98 113 76 97 111 91 78 110 85 99 101 100 79 96 91 114 92 90 94 100 74 87 94 81 99 97 85 102 92 91 111 76 81 81 108 88 97 91 100 104 114 81 94 88 108 96 105 100 95 106 77 105 101 87 82 95 104 104 103 118 113 99 96 100 105 92 103 80 86 120 115 93 99 91 100 85 74 109 107 89 92 100 97 93 83 90 101 68 88 105 99 121 108 80 94 96 99 90 99 92 95 81 82 94 85 98 89 93 101 90 111 101 104 96 107 107 94 101 102 102 96 87 85 105 107 112 94 115 88 89 84 111 84 105 90 91 98 96 95 91 85 107 91 104 86 107 101 103 118 85 82 112 104 94 88 80 89 105 109 92 124 94 71 97 110 108 84 93 108 110 88 89 84 97 96 88 108 102 92 101 90 118 109 93 91 119 103 97 100 85 98 103 80 109 100 93 97 101 107 80 105 92 93 106 93 97 79 94 107 98 88 98 111 92 111 89 83 104 99 95 100 87 106 113 91 93 84 105 90 94 90 92 92 100 84 86 76 109 105 84 97 84 99 91 99 98 91 94 101 90 97 95 95 106 93 100 87 78 91 101 98 98 99 89 98 104 87 104 93 84 92 102 87 104 95 104 108 101 108 96 98 105 112 96 79 99 101 105 110 96 92 97 84 93 97 114 98 95 106 83 93 110 104 86 91 94 106 110 97 99 104 97 103 78 78 97 101 77 92 110 103 102 97 79 102 91 106 108 93 88 106 94 93 104 102 121 78 94 99 96 80 102 86 105 110 78 83 84 102 108 95 100 92 101 101 96 99 87 83 111 107 102 93 97 102 79 97 104 82 92 104 89 103 107 97 110 112 93 89 102 91 96 97 92 110 91 103 77 100 93 98 81 93 99 86 75 87 96 80 85 89 89 84 96 93 87 92 78 109 99 92 103 108 86 94 96 84 102 96 92 100 113 88 103 95 92 96 95 96 90 76 95 119 83 99 94 93 102 91 98 106 90 98 98 81 88 103 99 93 93 100 100 89 87 104 94 94 105 80 102 104 95 94 100 87 92 91 94 96 98 110 89 111 86 103 105 94 95 80 97 96 104 94 99 115 94 90 109 103 122 84 108 83 103 94 95 93 89 96 103 81 99 100 96 95 89 91 86 93 103 88 87 85 89 97 96 106 90 89 86 103 98 87 94 94 97 99 104 100 105 95 111 100 97 88 88 96 100 86 95 99 94 98 102 99 95 86 92 88 98 79 83 96 102 99 80 79 89 97 92 80 115 90 102 79 87 108 73 84 95 101 94 91 94 98 93 97 97 99 113 104 110 86 92 91 93 93 97 101 119 99 107 92 91 113 96 92 84 99 100 98 98 98 95 105 81 90 99 122 92 91 94 88 92 100 89 100 104 75 93 97 87 98 87 89 88 93 88 85 96 75 93 88 93 118 80 84 91 103 98 92 97 90 118 91 93 102 91 96 87 94 101 109 101 75 97 104 84 84 99 93 95 110 95 98 98 96 95 78 98 112 87 107 85 105 105 87 113 109 90 89 103 103 99 100 93 92 82 102 98 77 93 100 103 101 95 125 87 94 89 92 89 105 110 76 97 89 67 104 115 92 88 98 103 83 96 89 97 126 123 107 106 93 99 90 81 85 108 104 68 96 97 94 105 85 111 97 110 89 83 89 88 85 102 90 102 75 97 94 77 90 107 90 77 101 122 98 92 93 86 95 111 91 129 107 102 93 100 103 104 105 99 93 84 82 100 104 88 107 89 83 99 83 92 92 96 96 104 118 96 102 91 88 92 100 122 93 96 106 86 86 106 90 86 96 82 99 78 84 112 101 99 101 116 97 117 97 110 96 91 107 101 101 88 82 87 84 107 94 96 92 99 84 101 85 97 99 102 99 100 109 101 114 89 111 91 104 92 101 95 109 114 89 92 86 106 98 88 98 107 109 85 99 102 83 83 91 88 84 115 103 90 96 104 86 75 105 92 111 111 108 97 113 88 89 82 96 100 90 100 97 89 100 88 98 106 116 93 92 88 84 85 96 91 89 96 102 100 99 101 95 96 103 83 95 102 92 102 115 87 114 88 87 100 116 96 92 112 90 99 106 84 82 109 88 99 90 94 114 94 102 81 82 105 117 96 100 96 100 95 87 100 80 112 113 105 82 91 105 91 105 91 86 101 103 103 89 96 96 89 90 108 95 91 105 82 97 106 92 97 86 96 88 95 98 99 81 113 98 101 102 85 92 101 86 104 94 97 78 105 88 98 103 91 74 100 92 96 93 108 96 103 89 109 84 102 109 81 90 88 97 107 75 82 89 93 91 90 104 87 89 71 79 93 86 102 110 93 96 88 83 100 98 81 110 105 94 96 110 101 122 86 102 95 103 104 85 108 93 83 102 83 93 95 105 102 104 75 78 92 101 99 102 88 107 99 100 93 100 110 82 86 98 92 102 90 102 80 92 95 103 86 91 97 103 72 82 92 86 83 85 85 112 97 81 82 98 91 100 92 115 86 81 83 86 126 103 90 98 81 110 109 118 95 104 96 91 101 97 97 83 87 91 109 103 93 103 96 117 91 85 81 90 90 83 96 100 101 111 95 92 89 100 101 113 113 98 82 95 82 105 80 104 108 94 78 89 112 89 96 77 113 107 118 84 110 83 83 99 92 80 95 91 76 91 108 86 101 96 108 109 105 89 102 111 97 88 102 124 93 93 84 102 92 91 107 108 107 82 99 108 96 90 89 95 121 98 86 96 89 97 88 97 107 102 90 100 107 100 95 97 94 121 97 88 94 84 105 85 91 93 109 106 93 102 92 116 95 88 105 98 92 92 100 111 92 89 88 115 97 101 106 90 94 100 97 96 106 97 92 85 98 104 117 93 79 99 103 99 105 91 99 87 124 107 109 86 88 109 105 102 114 104 106 102 92 121 118 87 103 101 89 109 98 102 94 79 91 98 110 116 89 104 106 111 85 109 106 97 104 112 126 94 97 102 100 103 114 119 98 107 95 100 99 105 96 95 106 113 113 95 99 99 101 127 113 101 82 92 113 107 104 102 114 103 117 94 92 110 105 98 102 101 106 88 114 112 105 100 103 103 101 118 109 106 90 116 91 91 130 103 104 93 105 106 98 107 86 112 88 92 101 115 123 107 116 97 105 107 85 112 81 104 98 118 98 110 84 89 103 103 85 109 107 104 83 132 108 97 109 86 102 105 107 96 96 108 95 110 100 103 78 81 102 89 102 101 105 113 103 83 93 86 89 102 97 105 97 98 92 90 109 96 109 86 107 103 106 90 93 97 88 92 88 110 84 91 83 107 104 105 93 127 122 88 94 102 87 86 102 89 93 87 103 91 105 88 105 101 100 92 117 92 112 109 100 97 88 95 103 96 100 93 119 109 102 90 125 97 98 113 108 89 98 82 110 104 108 110 87 101 104 94 103 98 95 108 119 101 100 99 95 107 91 104 110 92 100 98 107 98 87 117 91 80 113 90 98 105 117 96 95 102 99 118 93 90 107 106 88 92 92 114 97 83 94 88 101 108 100 97 82 110 118 75 81 107 107 102 109 106 85 96 101 108 90 90 104 112 103 101 102 87 88 80 101 104 99 98 94 102 93 124 94 89 102 99 98 98 110 96 110 104 109 103 105 107 90 116 95 111 96 88 104 106 91 99 97 104 86 107 90 93 85 102 93 104 110 82 106 103 96 94 94 88 98 109 99 90 89 85 87 130 111 96 80 106 109 112 106 104 83 103 95 93 99 99 106 93 107 91 113 90 113 73 86 93 115 93 85 109 103 101 107 99 96 100 112 116 87 97 94 124 92 109 95 94 115 106 88 87 86 109 103 101 104 87 99 120 103 116 101 109 87 104 100 95 109 102 92 112 97 83 106 105 120 114 88 104 103 116 106 82 102 109 111 101 102 114 92 91 81 111 100 92 100 96 112 105 84 90 101 92 98 96 104 93 85 111 103 85 89 105 97 130 102 102 90 117 105 104 100 101 114 95 99 96 100 93 94 92 107 89 96 103 103 77 82 97 91 103 108 93 117 96 103 109 89 101 86 96 103 89 92 109 120 97 120 98 91 104 112 111 101 106 102 116 89 102 110 87 125 106 107 107 108 101 103 106 87 106 99 110 89 103 88 98 98 103 108 98 109 90 104 95 104 107 115 93 83 107 88 116 101 116 83 120 87 100 92 96 114 111 108 106 118 113 92 104 87 97 86 104 101 92 108 101 90 96 91 83 111 103 92 113 105 116 91 91 84 102 80 93 100 103 105 103 92 101 101 105 112 87 101 103 97 109 104 106 100 113 101 103 117 107 93 94 105 88 93 84 109 114 97 94 86 105 88 105 101 102 101 98 100 105 98 97 103 96 80 110 101 96 105 97 107 98 96 103 106 97 120 86 94 106 90 112 93 103 97 115 97 120 88 106 114 96 95 113 92 107 102 104 112 99 88 92 86 110 96 107 93 99 107 95 111 119 93 86 103 93 84 99 113 112 96 98 105 99 104 89 114 99 92 93 113 99 87 92 104 106 121 96 97 111 91 95 102 90 92 104 94 108 79 79 92 84 96 112 87 107 95 95 111 96 102 107 115 103 113 92 97 87 105 77 105 104 107 98 93 104 111 108 95 93 111 113 88 106 84 89 114 117 93 110 103 96 89 82 88 104 93 109 94 109 114 99 107 104 91 100 101 104 107 93 112 92 105 116 83 114 95 93 110 109 98 108 101 99 92 99 119 93 118 114 94 115 116 114 108 100 107 102 84 100 103 95 92 114 106 95 109 84 106 98 91 118 98 99 90 90 97 92 104 85 103 92 94 113 108 100 104 98 85 107 84 102 119 110 87 104 112 103 109 105 108 102 122 115 93 95 99 95 103 121 106 98 95 123 109 108 119 91 114 109 93 102 113 102 106 109 93 127 96 108 103 104 106 107 85 118 99 99 106 98 103 112 103 92 123 114 102 91 94 103 105 107 72 90 108 107 99 90 87 96 108 96 108 100 84 111 89 97 94 92 115 120 105 119 90 103 115 116 97 89 97 101 98 99 117 91 93 100 102 112 97 118 83 101 91 98 94 90 108 101 94 103 103 80 95 106 108 106 94 102 99 110 104 110 95 113 111 119 95 85 111 104 112 116 110 114 117 103 106 104 97 93 103 96 111 107 97 110 102 98 86 113 117 103 102 88 115 109 110 100 113 94 98 107 85 110 93 98 105 106 94 105 108 101 103 97 91 90 83 94 86 104 103 87 85 85 111 109 102 95 98 106 106 92 105 92 104 102 110 101 107 119 89 114 107 102 103 103 110 99 118 93 123 95 107 115 113 109 90 109 109 126 112 120 98 115 95 106 106 112 112 94 86 98 94 104 102 113 124 118 96 115 112 106 103 94 103 100 119 113 89 107 126 121 96 97 120 100 125 100 109 97 113 115 108 97 115 99 111 99 89 106 106 95 103 94 82 98 90 119 103 93 107 117 107 105 103 102 118 99 100 82 80 118 103 92 108 118 106 90 110 106 108 103 88 96 115 90 95 115 113 110 106 83 89 116 103 109 93 110 102 119 106 131 97 120 115 97 103 96 105 118 109 111 123 108 95 95 102 115 105 111 125 95 94 89 110 102 93 104 109 103 126 107 108 104 120 107 112 91 98 115 99 115 104 109 92 83 104 88 93 128 98 97 115 103 105 99 96 90 98 96 92 108 120 98 102 103 90 115 114 85 101 102 110 95 101 98 109 89 130 98 98 106 109 109 79 106 115 101 109 101 102 111 108 93 90 105 88 112 99 119 105 115 104 122 91 95 101 99 99 108 116 78 105 107 107 107 112 107 118 120 82 112 102 97 110 102 119 109 109 117 114 110 116 109 98 101 98 94 99 100 113 130 100 97 128 84 98 123 82 97 106 106 109 108 102 104 103 104 92 111 103 92 99 137 91 85 97 93 110 108 97 89 98 129 107 109 102 85 111 113 103 104 113 115 93 106 115 102 94 92 93 117 91 100 97 108 112 114 96 119 113 109 95 114 97 112 91 104 108 104 103 103 96 113 108 99 97 104 99 106 97 103 99 103 112 104 94 113 117 106 101 105 111 102 85 109 102 96 112 115 119 107 105 107 80 99 102 98 105 112 108 102 92 112 110 109 108 102 106 100 102 118 80 109 125 93 117 110 118 86 124 125 107 121 105 115 112 112 97 112 99 110 117 114 118 115 108 94 104 112 94 98 109 96</counts>
			</dataPoints>
		</scan>
	</xrdMeasurement>
</xrdMeasurements>