File: data/XRD/XG-Sauerstoff/XG-pre/W6824-1B_XG_Sauerstoff_pre.xrdml
<xrdMeasurements xmlns="http://www.xrdml.com/XRDMeasurement/2.1" xmlns:xsi="http://www.w3.org/2001/XMLSchema-instance" xsi:schemaLocation="http://www.xrdml.com/XRDMeasurement/2.1 http://www.xrdml.com/XRDMeasurement/2.1/XRDMeasurement.xsd" status="Completed">
	<comment>
		<entry>Configuration=Factory configuration, Owner=User-1, Creation date=7/8/2013 4:01:53 PM</entry>
		<entry>Goniometer=PW3050/65 (Theta/2Theta); Minimum step size 2Theta:0.0001; Minimum step size Omega:0.0001</entry>
		<entry>Sample stage=MRD Cradle; Minimum step size Phi:0.01; Minimum step size Chi:0.01; Minimum step size X:0.01; Minimum step size Y:0.01; Minimum step size Z:0.001</entry>
		<entry>Diffractometer system=XPERT-PRO</entry>
		<entry>Measurement program=C:\PANalytical\Data Collector\Programs\Jorrit\2thom\_absolute_2th-om_10-130deg_PIXscan_56min.xrdmp, Identifier={15BCCF57-2807-42BD-B5B9-ECC0B3DC9284}</entry>
		<entry>Batch program=C:\PANalytical\Data Collector\Programs\SimonL\batch4x_2thom_10-130°_z9.1_x0,10,20,30_y0_57min.xrdmp, Identifier={EED9823A-2BEB-424C-9252-345C4EF2834A}</entry>
	</comment>
	<sample type="To be analyzed">
		<id></id>
		<name></name>
		<preparedBy></preparedBy>
	</sample>
	<xrdMeasurement measurementType="Scan" status="Completed" sampleMode="Reflection">
		<comment>
			<entry>_absolute_2th-om_10-130deg_PIXscan_56min</entry>
			<entry>PHD Lower Level = 4.83 (keV), PHD Upper Level = 11.27 (keV)</entry>
		</comment>
		<usedWavelength intended="K-Alpha 1">
			<kAlpha1 unit="Angstrom">1.5405980</kAlpha1>
			<kAlpha2 unit="Angstrom">1.5444260</kAlpha2>
			<kBeta unit="Angstrom">1.3922500</kBeta>
			<ratioKAlpha2KAlpha1>0.5000</ratioKAlpha2KAlpha1>
		</usedWavelength>
		<incidentBeamPath>
			<radius unit="mm">320.00</radius>
			<xRayTube id="1010048" name="Empyrean Cu LFF HR (9430 033 7310x) DK442154">
				<tension unit="kV">40.0</tension>
				<current unit="mA">40.0</current>
				<anodeMaterial>Cu</anodeMaterial>
				<focus type="Line">
					<length unit="mm">12.0</length>
					<width unit="mm">0.4</width>
					<takeOffAngle unit="deg">4.2</takeOffAngle>
				</focus>
			</xRayTube>
			<xRayMirror id="27010001" name="Inc. Beam Cu W/Si (parabolic MRD)" hybrid="false">
				<crystal type="Graded" shape="Parabolic">W/Si</crystal>
				<acceptanceAngle unit="deg">0.800</acceptanceAngle>
				<length unit="mm">60.0</length>
			</xRayMirror>
			<sollerSlit id="21010002" name="Soller slits 0.04 rad.">
				<opening unit="rad">0.0400</opening>
			</sollerSlit>
			<mask id="22030007" name="Fixed mask 2 mm">
				<distanceToSample unit="mm">220.00</distanceToSample>
				<width unit="mm">2.00</width>
			</mask>
			<divergenceSlit id="22010007" name="Fixed slit 1/8°" xsi:type="fixedDivergenceSlitType">
				<distanceToSample unit="mm">220.00</distanceToSample>
				<height unit="mm">0.19</height>
			</divergenceSlit>
		</incidentBeamPath>
		<diffractedBeamPath>
			<radius unit="mm">320.00</radius>
			<sollerSlit id="21010002" name="Soller slits 0.04 rad.">
				<opening unit="rad">0.0400</opening>
			</sollerSlit>
			<receivingSlit id="22010001" name="Fixed slit 4°">
				<height unit="mm">5.88</height>
			</receivingSlit>
			<detector id="7010017" name="PIXcel3D 1x1 detector" xsi:type="areaDetectorType">
				<phd unit="%">
					<lowerLevel>30.0</lowerLevel>
					<upperLevel>70.0</upperLevel>
				</phd>
				<mode>Scanning</mode>
				<activeChannelsEquatorial>255</activeChannelsEquatorial>
				<activeChannelsAxial>255</activeChannelsAxial>
				<pitchEquatorial unit="mm">0.05500</pitchEquatorial>
				<pitchAxial unit="mm">0.05500</pitchAxial>
				<readOutPeriod unit="seconds">0.135</readOutPeriod>
			</detector>
		</diffractedBeamPath>
		<scan appendNumber="0" mode="Continuous" scanAxis="2Theta-Omega" status="Completed">
			<header>
				<startTimeStamp>2024-09-10T19:35:07+02:00</startTimeStamp>
				<endTimeStamp>2024-09-10T20:31:13+02:00</endTimeStamp>
				<author>
					<name>PRO-MRD</name>
				</author>
				<source>
					<applicationSoftware version="6.1b">Data Collector</applicationSoftware>
					<instrumentControlSoftware version="7.0E 20130304">XPERT-PRO</instrumentControlSoftware>
					<instrumentID>0000000011142674</instrumentID>
				</source>
			</header>
			<dataPoints>
				<positions axis="2Theta" unit="deg">
					<startPosition>9.99826193</startPosition>
					<endPosition>129.99755682</endPosition>
				</positions>
				<positions axis="Omega" unit="deg">
					<startPosition>4.99913096</startPosition>
					<endPosition>64.99877841</endPosition>
				</positions>
				<positions axis="Phi" unit="deg">
					<commonPosition>0.00</commonPosition>
				</positions>
				<positions axis="Chi" unit="deg">
					<commonPosition>0.00</commonPosition>
				</positions>
				<positions axis="X" unit="mm">
					<commonPosition>30.00</commonPosition>
				</positions>
				<positions axis="Y" unit="mm">
					<commonPosition>0.00</commonPosition>
				</positions>
				<positions axis="Z" unit="mm">
					<commonPosition>9.100</commonPosition>
				</positions>
				<commonCountingTime unit="seconds">32.895</commonCountingTime>
				<counts 216 205 211 236 211 231 233 218 237 214 195 226 207 182 227 188 205 191 236 193 209 207 220 206 192 207 223 181 222 226 208 221 212 219 198 225 217 225 209 218 242 196 195 224 211 238 224 240 201 219 199 210 213 248 193 244 196 232 202 211 223 220 193 206 212 216 181 206 196 224 222 202 215 218 212 191 219 207 226 230 200 202 212 214 202 212 214 215 212 217 237 213 202 221 216 179 204 217 201 231 214 206 179 199 180 179 207 213 193 216 169 199 220 243 224 219 214 199 203 183 189 207 200 198 189 191 207 205 190 214 184 194 207 166 210 207 195 184 204 229 217 226 192 206 188 183 211 202 189 196 197 214 204 187 208 198 216 189 211 223 192 193 220 200 211 198 190 220 192 191 190 220 177 192 203 206 198 193 185 186 188 204 189 204 209 198 208 198 198 174 206 198 230 197 202 196 212 202 188 229 211 179 217 199 193 203 193 206 191 187 187 196 199 200 174 192 196 198 213 201 187 201 206 187 203 196 194 198 180 194 196 192 210 180 204 198 211 191 206 214 184 179 188 209 192 188 188 211 191 193 198 189 198 218 183 189 192 197 192 204 199 172 177 207 196 210 206 208 170 196 172 187 197 187 166 175 160 180 167 185 194 209 178 177 195 178 148 206 190 205 192 171 200 198 201 161 158 180 193 184 187 186 141 184 196 199 180 188 203 184 173 186 191 215 206 174 199 165 193 171 185 180 185 192 182 204 168 172 187 215 179 172 174 197 205 172 194 196 172 199 206 192 181 208 188 205 181 199 192 185 159 191 188 206 175 206 177 178 193 178 183 171 165 181 202 189 197 182 150 178 178 176 182 129 194 174 167 199 179 172 176 184 165 167 168 177 202 193 200 197 207 191 191 200 184 201 188 188 195 181 180 175 193 171 211 180 198 170 178 184 171 167 204 209 178 186 166 183 203 176 179 155 183 186 165 201 172 173 165 179 172 167 184 159 171 189 166 162 174 197 164 172 157 187 190 191 167 192 195 176 180 168 158 185 154 186 186 175 183 192 167 189 172 175 188 179 179 191 158 177 167 165 190 173 169 196 165 176 173 208 171 194 182 206 196 162 180 146 163 196 178 192 170 206 173 170 153 189 164 177 198 180 184 184 192 174 173 170 177 175 186 148 173 194 198 156 176 187 169 184 186 181 151 175 180 157 185 157 188 155 165 186 174 191 162 180 176 175 183 176 178 173 174 162 195 182 167 163 171 197 184 165 171 186 175 165 175 172 181 170 190 195 175 189 188 180 175 189 192 175 161 175 167 168 165 151 175 158 169 156 163 177 174 152 186 160 162 155 162 165 176 159 172 186 179 148 170 164 158 173 143 158 167 166 174 148 150 177 163 168 176 189 169 197 187 184 157 173 165 153 163 170 161 176 149 155 168 177 136 191 157 164 168 171 194 145 184 162 182 174 161 183 170 166 160 180 153 167 164 173 183 173 150 157 170 179 168 176 172 172 151 163 159 154 161 183 170 169 189 192 159 160 166 153 160 150 184 162 192 181 161 152 171 148 190 166 162 167 181 169 165 156 189 183 174 168 168 179 167 136 176 165 183 173 193 198 179 163 183 152 179 152 177 175 159 153 171 149 183 183 161 165 171 171 158 173 183 211 177 178 177 158 174 165 172 168 173 174 173 167 176 171 170 158 165 171 179 167 156 143 155 142 157 189 149 141 180 154 178 150 149 159 174 180 174 189 173 159 163 154 146 162 179 154 141 167 178 174 171 156 171 190 174 182 139 170 175 164 175 188 163 176 194 189 157 174 178 171 151 158 183 168 153 182 163 173 184 169 161 151 166 180 176 156 160 167 148 171 176 166 173 155 177 183 163 173 167 176 178 181 180 171 154 176 166 158 133 174 155 171 156 155 143 187 141 180 190 158 183 172 190 161 170 163 170 178 156 198 158 155 165 148 162 162 182 181 152 143 165 159 149 156 161 162 195 170 187 167 155 170 158 151 175 175 142 163 185 145 160 154 161 159 149 183 173 166 179 174 165 161 174 162 170 167 170 199 172 171 164 159 172 135 170 171 167 169 174 179 169 187 172 157 162 177 169 163 154 152 179 138 183 166 161 181 161 160 162 167 171 146 158 185 147 180 167 170 187 194 182 170 166 189 181 174 175 172 161 166 185 191 179 167 175 166 160 181 165 159 177 150 164 172 189 178 171 197 171 168 172 175 162 175 182 178 148 179 173 188 178 168 195 146 180 142 158 180 172 168 166 173 169 184 178 158 170 165 152 197 178 174 179 151 186 188 161 185 178 173 178 175 170 166 193 187 171 179 160 164 150 186 189 178 172 206 175 177 189 173 165 180 175 176 191 177 179 181 165 182 183 179 157 165 183 169 179 175 182 171 184 179 179 184 156 177 181 188 168 173 184 181 196 189 158 184 194 167 158 196 169 171 179 168 168 187 174 180 182 181 196 171 169 184 138 178 178 165 184 179 161 176 168 174 189 188 165 196 161 179 189 161 173 187 200 168 165 156 198 162 162 168 177 167 161 178 181 185 161 183 166 175 175 161 172 166 180 191 190 171 180 209 166 205 167 175 157 163 159 190 179 196 183 167 172 177 172 188 173 174 191 158 174 165 166 203 187 184 180 166 177 159 203 195 180 189 183 184 184 194 181 196 194 175 197 173 193 176 194 162 184 181 164 167 162 164 176 174 166 200 174 185 191 160 190 176 179 165 157 176 205 156 185 183 163 166 164 184 152 177 214 166 181 196 192 197 169 186 188 199 173 193 170 171 173 167 161 180 202 193 184 193 183 150 178 183 189 167 146 189 186 203 177 159 168 162 180 171 189 195 170 196 169 168 161 178 187 184 189 169 180 183 179 199 170 179 161 177 187 184 177 184 172 175 153 177 173 180 151 150 176 157 182 198 176 156 179 160 170 201 188 149 183 170 160 179 178 142 177 162 191 194 179 161 200 189 193 162 165 193 188 186 181 164 191 202 166 199 166 165 192 208 168 203 169 176 193 152 169 190 166 149 185 192 175 197 181 188 178 178 178 188 174 174 172 214 200 154 181 177 169 195 182 178 167 183 187 182 163 195 175 161 189 188 179 178 176 191 196 182 173 167 153 173 169 167 189 179 182 178 169 172 196 171 204 187 172 186 148 179 185 190 198 164 166 188 189 187 190 180 165 172 143 175 171 181 163 176 155 175 154 151 192 167 185 189 157 188 162 185 190 177 163 178 174 178 176 180 197 164 172 181 173 162 165 167 182 175 176 151 174 178 171 152 167 182 144 166 186 150 172 155 160 153 157 172 170 158 168 194 162 165 175 180 173 163 169 169 153 150 163 168 166 153 171 180 193 165 172 171 168 164 163 184 166 168 197 168 172 159 176 166 163 186 169 175 161 169 159 166 164 160 161 179 154 169 175 139 182 173 161 165 171 183 172 177 165 163 164 168 179 174 176 162 173 161 177 156 188 167 161 152 150 175 160 163 172 169 188 164 159 151 150 151 178 155 181 164 180 164 183 165 144 187 159 163 169 162 140 150 160 191 147 160 164 142 155 170 154 195 151 174 152 157 149 154 150 170 134 167 175 158 155 146 178 150 174 184 162 166 157 168 170 150 161 146 157 162 165 166 171 174 151 147 141 174 151 143 151 160 156 146 167 144 159 133 145 160 144 173 161 171 151 153 150 151 146 162 164 146 184 141 154 166 154 168 162 175 150 157 161 133 161 160 160 128 151 164 147 156 154 150 192 140 171 149 163 152 154 155 164 176 160 166 165 168 169 176 163 157 148 154 171 142 177 154 166 158 163 159 145 152 136 147 163 165 150 156 148 140 168 139 153 155 131 143 169 152 155 163 143 140 140 149 150 156 159 161 134 162 157 149 138 142 157 146 161 147 156 140 152 143 124 141 157 143 141 165 140 154 149 164 145 149 146 170 170 152 158 143 156 153 147 157 150 136 160 122 184 177 164 146 165 149 141 135 123 163 145 177 143 155 175 143 150 159 151 133 134 150 142 142 155 128 150 124 168 133 133 151 157 150 128 128 155 161 146 141 153 168 138 143 150 132 155 144 161 162 141 130 124 151 155 139 143 146 126 126 125 145 153 131 153 138 135 150 159 157 140 132 143 154 153 177 158 140 132 151 139 141 137 134 152 141 152 147 145 148 149 153 163 149 160 146 143 158 134 133 146 153 133 139 128 145 172 142 130 155 133 126 131 133 145 136 129 151 142 146 123 145 142 131 162 124 134 142 134 144 139 146 150 127 144 149 114 138 168 151 143 133 148 152 155 140 135 131 142 147 146 134 154 131 135 145 125 136 145 125 146 128 119 155 161 146 155 142 139 149 146 134 146 144 133 143 165 135 134 134 153 152 129 144 152 131 137 153 141 145 146 141 144 129 116 137 137 139 133 149 136 128 127 132 139 123 152 133 155 140 155 160 132 156 140 161 150 146 145 124 136 131 143 142 120 127 126 146 157 131 146 155 127 132 160 135 128 136 144 132 136 142 134 125 141 127 131 127 148 130 169 128 130 146 130 121 122 123 138 142 146 138 124 126 135 124 131 147 127 149 147 140 109 137 123 114 135 113 136 114 141 137 137 130 133 119 119 141 117 160 141 134 147 149 142 158 118 136 139 127 127 133 131 133 135 135 146 131 145 135 125 153 135 128 124 116 120 145 138 133 119 136 143 136 137 126 136 131 107 120 148 153 130 121 133 136 135 136 136 120 131 139 126 143 147 132 117 120 135 136 118 140 144 139 144 137 125 127 117 122 124 114 140 144 121 126 128 115 130 118 127 142 116 128 122 123 121 125 135 129 144 142 150 117 156 118 120 111 141 121 134 107 126 130 115 134 92 127 134 123 128 120 128 113 125 135 120 137 123 143 138 124 133 111 115 127 145 114 136 122 149 113 150 123 119 125 121 119 129 158 139 133 120 122 117 121 123 116 122 127 125 128 139 127 125 151 122 141 127 135 127 125 152 137 121 124 131 134 131 117 125 125 133 139 151 141 122 116 139 133 122 118 157 117 127 139 115 134 120 133 143 121 134 128 140 118 112 129 144 127 124 136 126 118 125 122 128 121 137 106 103 134 138 118 132 122 113 119 136 116 117 120 145 138 110 125 135 132 116 141 133 122 119 138 126 111 121 137 121 131 109 118 118 130 124 114 110 142 132 124 126 130 151 136 125 118 148 131 139 136 150 143 131 126 128 131 127 114 138 112 127 120 117 118 133 140 122 110 121 129 122 144 137 136 126 133 125 113 116 136 128 131 138 129 131 132 121 125 138 120 122 124 125 138 126 145 135 112 120 113 112 119 134 114 121 119 121 138 116 126 134 128 136 125 127 127 133 128 106 117 123 130 141 101 121 141 136 136 126 123 115 128 145 125 148 119 107 115 112 115 129 120 108 123 108 108 128 130 140 126 119 121 126 123 123 129 136 121 115 142 95 117 131 127 126 112 110 105 122 146 123 138 122 123 116 123 137 128 123 118 113 123 109 134 126 111 116 119 99 108 121 120 112 123 119 126 126 133 119 131 108 111 120 103 127 114 142 126 133 117 142 114 114 113 110 120 138 126 122 112 115 131 114 107 118 105 97 115 131 121 113 110 109 121 103 135 124 138 137 111 110 128 123 122 137 131 110 127 125 147 124 135 132 120 124 126 117 142 128 103 118 120 131 103 117 110 112 116 107 133 96 136 125 132 144 127 131 129 125 129 108 123 130 120 123 121 137 129 118 126 124 111 100 119 139 125 98 105 132 128 128 133 123 119 146 102 121 106 100 135 125 124 138 103 126 108 135 97 107 130 119 115 133 123 132 111 100 118 125 101 98 124 132 122 119 122 125 121 106 106 123 140 126 133 111 134 106 104 117 110 106 122 110 107 109 124 126 112 137 130 119 116 118 112 115 111 114 116 125 105 121 107 127 107 91 126 112 147 140 113 108 131 133 155 135 124 130 103 131 123 122 124 115 132 112 121 120 120 105 132 124 125 124 126 131 124 121 145 107 142 119 114 118 109 121 129 123 124 115 134 117 117 117 129 136 111 125 123 113 118 132 130 115 114 142 118 129 140 118 128 132 119 105 118 135 121 128 132 134 100 115 119 112 117 116 122 145 126 115 123 126 116 109 127 122 97 114 115 117 117 111 104 121 131 123 115 125 117 126 109 103 110 131 134 109 111 114 142 124 107 102 111 99 126 121 122 124 98 104 130 107 136 130 111 117 109 110 127 127 108 107 133 117 120 124 132 136 131 120 119 108 114 120 124 119 130 117 117 105 102 130 120 122 116 121 97 133 114 115 131 118 113 114 124 116 116 115 119 118 127 107 120 130 120 117 121 115 123 118 124 121 92 115 134 134 106 116 141 110 115 106 119 121 108 127 125 105 119 119 119 126 98 127 120 123 142 115 126 101 145 112 136 118 129 127 112 108 121 112 104 135 111 119 117 115 96 105 121 118 130 116 144 136 124 118 145 113 126 123 133 117 112 116 105 120 121 124 107 123 101 116 132 136 121 131 127 116 121 99 103 114 127 117 124 86 119 118 105 140 111 120 136 105 138 121 111 119 127 131 111 120 115 120 117 102 116 140 122 130 111 124 109 126 134 97 128 121 105 106 117 121 127 101 112 113 125 118 132 131 123 126 122 120 128 132 111 115 121 120 124 104 117 129 137 122 115 118 115 114 109 135 116 125 121 132 127 137 112 119 118 111 116 123 117 135 107 120 116 115 124 113 123 114 118 133 115 110 130 129 117 126 124 146 108 114 113 123 112 124 111 99 99 98 128 112 108 134 146 129 129 99 129 137 140 133 126 111 127 123 131 133 130 123 142 116 99 111 115 128 120 141 108 94 128 118 118 118 126 127 136 130 112 132 133 116 121 108 121 120 112 101 124 129 112 118 120 125 126 120 122 139 145 123 107 112 118 122 134 133 122 137 105 95 121 100 107 119 97 114 132 120 133 126 129 113 117 130 141 123 127 130 143 119 113 108 116 108 113 113 122 118 127 110 93 115 129 128 119 138 123 120 128 121 116 126 120 138 118 122 142 117 120 125 107 144 125 119 111 129 116 126 124 136 101 91 136 116 146 125 114 117 136 101 115 112 136 120 104 142 125 110 112 126 122 130 132 112 136 124 116 112 140 138 124 144 126 140 103 129 142 125 117 117 116 114 133 139 122 126 120 127 120 137 118 117 115 136 148 120 114 103 112 125 118 131 120 130 113 111 126 119 147 115 117 133 112 130 126 127 135 131 113 129 133 129 113 109 126 136 121 117 105 131 111 112 124 118 120 124 114 93 121 104 110 115 119 124 140 137 110 107 136 123 126 143 135 128 103 126 113 120 118 122 138 115 131 107 122 133 108 121 113 122 123 116 125 124 126 124 130 134 131 121 123 112 114 112 110 122 106 94 124 129 118 130 135 126 122 129 116 125 95 135 122 121 124 120 112 146 139 109 118 106 127 124 128 122 127 104 107 129 117 128 111 111 138 147 125 128 131 121 123 147 106 125 121 115 140 123 115 114 99 108 129 131 152 122 126 109 120 126 115 136 107 118 109 133 123 119 127 133 118 125 109 121 109 129 138 114 100 103 114 130 116 125 137 139 124 134 155 138 96 119 125 125 113 150 126 118 128 121 110 125 119 111 112 123 112 150 115 127 113 127 130 113 127 115 120 115 123 123 121 120 134 135 124 114 127 123 127 136 131 134 130 155 155 108 137 123 128 140 123 133 135 125 147 148 147 122 123 133 116 135 131 148 155 136 126 134 139 141 137 123 149 144 136 142 140 159 153 158 158 134 136 163 155 189 164 157 184 147 158 180 191 186 179 190 189 200 196 199 201 216 210 210 185 210 165 217 204 235 215 191 196 213 217 247 209 218 194 203 212 204 184 190 192 167 172 166 179 160 168 181 148 125 134 171 146 153 128 159 164 165 138 141 152 118 171 128 119 141 142 139 122 114 132 127 144 125 133 121 129 122 128 129 140 137 125 120 148 121 135 127 118 119 132 134 127 115 126 121 140 126 128 139 114 116 135 111 103 121 122 102 118 115 127 114 113 123 112 129 123 129 142 106 108 123 130 137 117 105 124 118 123 114 124 109 119 125 117 124 122 125 114 108 117 133 110 107 125 118 114 124 114 121 118 114 137 120 131 147 126 127 106 140 138 115 130 123 126 124 122 125 136 128 105 124 131 132 135 157 95 117 116 125 124 98 114 111 140 115 125 125 136 135 113 132 114 131 110 133 131 116 119 102 127 128 138 118 108 115 129 117 102 125 121 123 124 121 134 134 129 120 137 119 128 132 119 121 110 130 131 138 119 133 105 111 120 124 115 108 122 114 118 124 116 118 118 115 123 134 117 127 128 130 124 126 112 104 118 118 123 124 116 130 101 124 129 120 141 122 96 114 136 123 112 135 122 117 116 123 122 133 138 121 128 129 108 122 105 109 120 136 125 116 111 123 116 126 120 119 117 134 116 109 112 109 119 108 108 111 100 119 120 129 125 115 113 110 108 114 113 150 118 131 110 119 133 114 117 117 121 111 126 122 114 137 115 122 105 136 116 119 125 116 125 120 119 106 112 110 112 108 125 110 122 141 108 108 133 112 115 106 120 143 112 107 120 122 121 116 100 130 116 127 116 118 132 122 133 109 139 127 145 121 129 131 115 116 113 117 118 120 124 121 116 99 103 115 111 130 121 142 117 110 118 129 111 119 126 118 124 121 129 123 128 122 107 116 130 108 115 100 155 131 122 123 140 122 122 110 122 114 130 131 131 120 131 120 119 103 127 114 142 128 145 92 95 124 129 127 131 124 131 119 115 129 126 124 114 124 119 132 122 130 108 128 137 112 140 119 113 147 117 143 110 134 135 116 116 107 133 123 114 120 124 117 123 128 129 113 109 114 130 128 127 118 127 132 114 103 119 123 147 120 121 137 124 109 124 115 108 110 125 114 100 124 134 137 114 105 126 129 103 133 138 121 128 124 108 112 123 136 122 125 117 137 113 124 105 115 123 127 129 128 126 121 135 112 116 136 145 129 117 116 106 114 99 109 109 106 130 105 134 111 112 119 113 123 122 124 123 123 108 112 134 126 119 128 131 107 130 117 134 129 121 137 148 132 136 103 143 140 138 120 116 118 111 121 122 127 114 107 138 121 113 132 137 134 106 105 132 126 114 129 126 127 105 120 129 132 106 102 125 92 157 120 116 98 130 116 128 128 112 132 128 135 133 119 142 101 138 108 122 133 108 124 150 127 108 124 106 119 134 121 128 108 115 129 122 125 114 119 100 119 126 134 96 108 103 115 110 108 148 115 120 133 121 138 130 110 123 126 115 109 132 119 117 128 118 122 136 116 116 135 123 125 108 123 115 134 125 122 126 108 132 105 120 124 137 135 122 122 129 131 136 114 124 110 114 126 109 111 136 132 115 115 121 140 127 146 120 110 126 139 126 119 121 130 142 137 127 125 125 129 115 111 122 120 119 105 139 116 91 124 122 118 134 115 131 144 119 127 108 118 120 116 108 120 110 120 121 120 127 127 142 116 118 115 121 121 113 117 132 124 124 111 112 111 121 119 118 127 119 124 121 124 121 132 121 137 130 131 119 113 106 133 110 120 120 109 133 130 103 137 110 94 114 120 121 145 108 140 136 129 117 120 119 121 115 126 134 129 106 121 109 127 130 135 114 111 124 109 116 132 108 113 129 121 118 105 114 123 128 120 142 132 112 122 117 128 132 126 106 135 125 129 108 124 121 122 127 121 117 116 113 123 125 131 114 109 117 119 128 121 108 117 145 129 118 128 107 119 123 115 120 130 105 159 122 113 131 111 102 127 112 132 107 139 131 148 129 117 142 135 146 111 115 124 131 124 105 118 118 124 141 119 125 143 139 132 111 118 121 125 118 117 131 124 122 117 122 129 123 130 124 114 109 123 121 134 122 121 119 116 112 132 125 121 135 112 146 137 128 127 121 127 125 113 117 121 115 131 114 105 123 128 145 129 115 124 130 104 111 156 113 105 122 115 103 126 112 137 116 111 123 127 107 126 120 142 121 115 118 103 129 118 103 122 131 132 111 112 121 107 124 123 130 117 118 128 149 145 132 122 119 111 121 129 116 134 110 114 120 120 122 117 134 110 131 140 116 113 113 122 110 108 126 121 143 100 135 111 113 117 126 119 112 125 131 112 123 107 124 120 111 123 140 115 118 136 136 143 132 112 148 128 116 115 121 137 119 109 119 121 122 144 114 117 122 119 124 110 135 120 124 132 127 142 108 106 136 112 124 126 137 121 125 111 106 135 124 122 140 130 111 119 118 115 142 137 119 138 113 129 137 150 121 119 130 129 137 146 134 116 128 117 115 110 126 121 132 117 118 119 116 131 111 133 126 139 113 126 157 113 143 126 146 136 118 118 160 106 123 110 110 108 122 144 121 108 110 130 110 123 122 124 137 137 126 124 118 129 135 115 144 115 138 119 123 110 131 120 104 131 125 109 125 113 119 120 132 129 123 98 124 111 105 130 120 121 116 126 128 129 130 133 128 142 124 114 127 119 127 102 122 137 116 135 113 135 115 121 108 123 120 118 106 125 104 122 143 110 119 119 117 120 129 126 136 121 121 147 122 120 101 125 133 122 117 139 104 116 124 113 121 129 133 135 136 104 117 136 128 119 116 134 143 123 130 139 147 125 132 119 107 146 118 126 140 117 133 112 129 126 122 128 140 116 123 115 123 122 105 99 105 111 122 123 111 106 130 122 146 113 116 118 124 112 97 123 115 113 136 134 128 107 122 149 129 123 126 132 110 125 112 126 120 120 127 135 134 127 138 150 127 127 131 132 136 142 137 113 121 122 106 106 114 113 114 121 121 125 132 137 143 123 120 121 138 113 133 117 133 120 127 103 130 122 115 128 137 111 118 117 132 104 123 114 126 123 142 110 117 130 122 120 134 145 117 122 122 114 123 119 138 120 128 138 126 126 147 121 106 130 132 148 148 121 121 120 99 121 111 134 134 114 132 122 130 124 156 106 107 118 122 135 120 130 122 130 119 120 134 127 124 107 118 118 122 123 113 120 122 117 143 124 127 127 131 128 137 136 120 125 117 122 115 112 112 125 109 117 139 135 131 115 140 143 126 117 136 140 132 116 119 119 126 118 117 113 135 143 130 118 138 121 93 112 127 126 115 141 101 135 121 134 103 127 132 120 119 119 110 122 117 139 126 124 147 137 123 103 113 130 124 148 112 109 114 116 122 109 111 132 125 108 123 118 127 129 120 115 121 132 120 137 129 130 129 114 133 123 116 132 118 127 148 122 122 113 142 129 123 118 127 124 124 121 118 147 141 120 141 144 120 118 132 140 109 110 130 139 131 133 139 148 123 109 121 131 123 120 117 125 158 135 129 129 130 116 125 136 110 114 132 119 122 126 114 125 128 128 117 123 132 123 132 143 124 133 136 139 132 136 105 124 126 132 136 113 106 116 131 130 114 137 129 128 129 126 112 83 129 132 128 121 125 132 118 142 136 144 129 115 128 159 133 138 122 125 140 108 124 126 108 124 119 132 136 147 139 133 115 129 116 128 129 127 129 126 120 116 114 105 112 129 116 125 121 112 98 135 127 137 123 128 112 144 145 133 112 135 126 126 130 130 112 123 139 111 144 119 125 121 121 140 131 123 141 135 131 132 137 131 126 132 141 130 134 134 131 116 128 115 109 143 122 123 117 133 126 112 127 138 109 139 124 117 114 124 123 132 118 118 140 113 114 117 153 111 128 139 130 121 128 156 114 138 118 131 121 145 132 106 139 130 117 144 103 128 129 112 126 131 130 123 124 140 133 122 121 124 99 137 142 134 129 125 128 138 123 127 123 120 121 136 114 140 135 154 142 104 145 119 132 127 122 142 128 132 141 137 132 124 163 117 133 122 131 113 119 122 134 128 130 116 144 119 136 121 110 132 130 135 132 107 122 114 140 136 136 132 148 145 129 121 139 110 123 122 127 134 124 125 144 130 123 145 122 120 131 134 126 136 152 139 115 126 129 116 120 133 131 137 119 135 95 131 115 118 116 132 117 136 112 140 113 139 140 134 138 126 125 131 133 127 128 133 121 114 114 130 114 133 133 123 142 118 144 132 118 129 144 129 147 158 144 137 123 123 110 122 143 138 130 124 129 123 134 117 132 135 116 129 124 125 150 123 131 136 129 134 115 129 135 114 116 143 117 140 135 143 128 160 123 127 147 136 137 134 122 118 138 129 114 110 117 123 121 135 133 125 136 130 112 135 108 122 110 121 123 154 124 116 136 127 128 119 122 130 123 144 129 126 132 139 129 134 146 130 135 142 134 123 110 125 154 137 118 110 132 121 133 122 126 121 107 143 152 131 123 135 125 138 111 132 120 151 151 121 130 132 149 125 121 108 149 126 134 129 125 141 138 145 155 125 135 149 141 136 139 145 127 111 142 141 123 146 131 142 134 141 130 144 146 144 147 120 150 114 130 149 137 139 127 133 132 128 152 136 152 106 138 145 138 119 128 133 134 136 157 126 137 120 124 122 133 129 125 147 132 139 141 129 106 141 137 147 128 135 142 142 137 127 128 140 126 117 143 121 121 133 127 120 139 108 133 126 151 151 104 112 122 133 119 110 142 138 128 141 127 130 138 127 129 144 146 134 113 122 148 133 117 129 151 129 136 110 138 132 147 131 121 116 146 127 129 117 127 124 142 134 161 125 137 140 149 131 140 141 140 119 118 136 119 133 130 133 140 130 130 114 128 135 122 130 139 115 150 127 128 117 98 120 143 135 138 143 150 146 120 138 128 128 131 141 141 112 123 126 127 110 130 133 119 137 113 122 126 130 125 131 127 129 132 138 135 151 127 128 139 141 122 142 131 124 138 121 147 130 146 145 130 122 112 148 131 125 141 144 133 125 137 122 126 119 126 118 129 120 129 119 125 124 123 129 138 107 136 114 122 116 132 134 113 119 121 131 132 130 156 115 126 111 133 107 128 138 135 117 133 112 139 148 118 136 120 132 137 124 142 140 136 136 134 149 131 125 132 127 122 136 142 136 136 143 141 124 146 136 112 132 137 127 130 125 145 108 134 128 135 137 133 117 117 118 118 128 130 122 133 127 132 128 144 127 135 127 134 127 144 123 132 139 125 131 146 111 122 118 118 143 135 118 123 130 137 149 125 124 120 139 122 123 115 136 136 141 117 135 122 141 130 154 136 113 121 151 133 130 132 147 133 145 136 114 129 133 145 122 112 153 140 122 111 133 141 119 137 122 124 112 140 122 111 121 136 152 149 139 128 132 141 136 132 128 122 128 126 118 119 116 139 129 133 130 122 124 135 121 144 126 116 115 116 141 137 127 113 139 107 126 129 144 128 129 126 139 147 130 127 134 130 141 129 121 127 141 109 121 143 133 120 128 134 126 125 124 123 134 126 117 173 121 120 133 134 123 133 116 122 134 139 136 134 134 122 115 132 133 139 146 127 158 107 130 145 128 129 122 134 120 109 125 119 131 146 135 121 128 123 119 116 138 118 135 132 114 127 127 151 127 136 122 140 129 125 105 130 145 118 104 119 132 116 143 130 105 129 141 133 135 129 117 117 139 136 124 127 132 122 126 148 128 110 138 98 136 134 107 143 129 126 135 138 121 140 141 136 120 136 123 139 137 133 154 119 122 141 141 117 130 119 122 138 149 125 139 126 102 127 109 122 110 126 119 112 135 135 130 140 136 126 134 129 125 128 133 132 133 127 157 137 130 124 131 145 127 113 137 149 132 135 120 135 128 132 130 148 154 112 116 127 120 139 135 127 104 146 136 149 124 129 137 144 127 116 147 117 106 143 117 133 124 124 131 142 130 127 127 114 134 130 135 119 148 137 141 107 111 128 140 124 140 138 142 142 132 131 108 116 125 133 135 129 127 133 133 138 135 124 119 110 122 134 134 127 147 130 131 127 118 154 141 124 120 117 159 138 137 140 124 130 152 117 128 128 107 121 120 133 141 143 139 147 141 119 139 136 123 125 112 144 131 139 122 117 134 147 125 118 106 134 128 126 127 111 146 132 154 130 134 144 123 144 135 136 130 144 148 141 130 126 139 144 117 124 151 108 122 118 103 118 132 122 136 143 116 143 132 119 144 125 142 114 124 136 142 115 122 128 122 127 124 118 139 131 145 140 123 125 120 126 128 127 134 142 116 108 117 119 123 133 143 139 131 123 166 118 122 130 137 100 138 135 131 119 146 116 145 146 120 136 132 116 114 133 118 130 130 142 146 135 127 134 117 136 136 133 129 145 132 137 141 123 128 117 116 137 155 110 140 128 147 127 119 117 134 155 125 139 123 143 132 140 128 142 126 140 147 112 147 115 113 153 141 141 127 144 126 117 141 133 128 132 132 122 121 135 110 152 142 157 121 127 116 134 124 122 144 132 127 122 126 140 125 137 121 130 137 125 145 123 139 112 122 128 125 133 130 126 149 126 124 130 142 149 113 142 111 130 136 124 144 143 122 153 125 115 124 118 125 111 143 146 144 111 131 118 145 137 143 146 134 126 140 131 136 128 127 156 142 130 139 135 129 124 99 122 132 122 134 150 158 133 149 146 110 121 140 150 146 120 121 126 131 135 127 118 140 150 142 116 125 124 147 152 139 142 143 124 127 121 122 110 129 142 133 140 123 138 148 113 144 116 121 122 121 139 130 136 148 132 167 146 118 116 124 109 122 130 110 159 143 141 138 132 124 126 133 143 147 125 136 144 119 135 131 107 123 121 136 144 153 125 132 144 127 142 149 104 114 128 137 152 125 152 142 139 129 118 127 128 114 115 130 120 132 117 131 128 131 141 138 140 127 145 142 119 134 127 138 135 155 134 114 117 130 124 146 144 134 141 111 124 129 151 133 131 117 130 130 125 121 125 139 138 111 143 136 125 127 118 118 129 122 128 143 125 145 134 128 118 113 146 147 142 139 140 124 117 135 140 129 150 144 118 118 111 126 137 142 124 131 135 125 128 119 142 119 138 138 132 122 123 117 131 125 110 119 122 122 118 112 123 136 125 131 117 127 139 136 138 126 124 106 147 127 121 119 121 136 127 139 131 135 130 129 121 120 116 137 119 131 121 122 118 157 134 121 124 137 136 142 125 130 133 132 124 134 116 133 127 139 143 115 136 130 133 113 116 114 112 130 133 136 132 131 122 134 128 127 160 126 153 142 120 112 124 104 110 146 137 133 126 139 140 121 145 129 129 138 117 126 139 161 133 116 112 107 138 140 137 128 148 147 117 138 121 148 123 136 139 118 123 120 124 109 119 109 126 140 116 137 123 140 129 135 141 127 114 129 124 127 148 126 136 111 125 123 119 131 138 125 146 148 142 112 122 117 144 150 136 131 118 136 127 124 140 135 131 142 135 141 126 124 140 127 134 123 99 129 138 156 140 170 139 138 127 129 130 128 147 111 154 138 136 132 134 130 122 151 134 128 131 125 115 147 146 122 143 130 153 121 159 144 128 144 114 159 112 132 125 109 130 126 145 148 158 117 116 135 110 121 136 134 113 150 142 115 125 136 107 131 142 118 145 127 134 132 133 122 119 128 146 123 138 132 126 121 130 126 121 122 138 129 126 105 131 128 126 154 132 131 121 128 123 151 118 135 133 128 143 136 115 135 110 134 126 142 132 124 143 123 106 133 133 148 122 143 121 125 116 140 134 125 144 123 125 143 119 135 102 130 132 147 116 112 121 143 112 128 133 136 118 123 143 133 126 152 132 137 125 132 117 132 124 129 132 148 136 140 121 121 123 137 145 141 118 139 116 118 134 147 126 117 137 115 137 128 127 121 130 150 123 127 138 126 153 132 136 144 135 149 140 122 161 119 134 118 138 142 140 130 112 142 134 129 121 129 122 133 126 111 144 131 126 127 145 143 110 137 119 147 129 137 113 120 140 132 141 116 126 124 129 120 139 171 125 137 129 147 117 122 123 147 130 107 155 136 132 137 119 133 116 144 134 126 147 137 123 129 135 121 136 118 102 124 128 124 131 146 127 137 144 124 160 120 122 146 142 137 152 131 134 113 113 115 141 127 138 128 148 125 135 121 129 122 145 148 139 121 132 117 126 136 123 128 137 122 116 142 138 143 135 146 141 141 135 137 125 124 134 122 121 131 129 136 129 132 137 140 130 118 119 125 130 133 127 130 118 134 144 136 133 131 137 137 156 125 125 144 147 130 121 133 136 139 132 122 151 113 133 117 117 137 133 137 123 104 123 141 126 111 132 149 124 136 145 127 133 123 131 133 150 136 139 129 118 119 133 127 135 114 131 123 147 133 140 129 149 132 159 128 158 122 142 132 127 129 119 121 123 124 131 139 134 139 127 148 133 127 122 123 128 136 140 123 134 133 143 127 132 145 142 128 129 127 128 154 138 147 120 141 140 126 143 179 125 142 141 153 136 155 153 132 135 165 152 137 140 149 149 133 139 129 136 151 154 145 158 135 150 141 132 168 147 174 176 167 158 138 144 155 148 128 131 147 145 163 152 142 172 168 145 148 157 161 150 164 143 138 150 143 144 140 148 161 165 139 150 144 142 128 140 151 127 132 149 150 137 150 127 138 145 128 143 128 158 148 144 139 136 145 127 132 133 142 130 149 126 148 146 133 118 127 138 131 135 132 138 130 126 142 139 138 136 132 142 133 127 130 129 148 129 124 140 132 134 163 147 119 119 157 134 111 133 145 135 124 140 133 127 133 136 154 102 129 138 137 124 140 130 140 106 124 124 140 110 122 130 137 151 116 131 130 128 123 130 156 97 129 124 124 137 126 161 137 117 123 135 130 136 133 149 140 126 118 137 137 131 117 143 113 134 148 115 122 142 151 107 129 127 160 123 126 132 129 119 128 147 114 127 143 136 125 137 144 130 112 105 128 121 136 139 157 145 139 127 119 138 119 141 144 140 124 131 131 132 131 114 133 126 131 129 168 119 144 152 132 118 152 131 128 149 135 151 126 136 143 132 132 136 130 137 120 158 133 127 130 140 112 121 125 137 128 123 111 129 140 134 123 138 130 107 136 149 130 155 136 150 142 142 148 110 140 127 119 124 126 119 119 127 115 135 125 154 152 124 101 107 138 138 125 112 135 149 115 125 125 135 131 142 131 125 128 120 139 130 137 143 107 136 116 122 142 140 127 128 127 141 128 141 144 154 159 127 147 115 137 135 125 142 152 152 128 122 125 126 120 140 142 124 137 128 124 135 121 133 134 125 133 126 140 125 125 141 118 105 139 137 136 133 153 128 138 124 108 139 118 140 138 134 136 146 112 130 130 113 131 143 144 119 140 130 142 129 140 146 135 114 128 136 134 136 129 136 143 140 127 128 118 119 139 124 135 118 112 132 137 116 120 120 144 137 132 135 132 144 125 128 139 142 134 133 131 131 136 119 126 129 149 145 128 130 137 131 146 133 127 129 111 132 121 135 126 126 131 146 121 111 133 118 130 137 141 136 138 133 149 118 139 139 148 125 150 128 123 118 143 137 102 134 125 131 127 145 121 116 120 118 113 144 121 136 125 142 139 123 137 129 139 150 137 120 107 127 127 140 122 131 135 131 128 142 129 143 122 110 132 131 113 131 142 152 137 105 139 158 127 122 108 114 118 162 123 163 122 135 152 126 132 141 133 133 133 138 131 156 118 105 140 116 131 136 158 120 147 104 150 129 131 138 148 119 125 135 119 149 142 142 130 129 116 146 129 137 135 136 122 134 134 130 117 100 113 161 123 113 121 141 121 109 140 130 120 148 142 129 103 158 109 118 118 107 148 145 126 145 111 137 127 123 132 116 145 139 146 117 121 151 116 136 111 127 153 129 116 106 138 117 133 124 148 126 130 118 126 136 141 132 145 130 110 121 130 135 136 136 119 122 128 145 113 125 127 138 128 117 121 134 149 151 127 133 142 108 129 117 132 126 132 117 145 119 131 137 126 139 121 123 130 117 135 138 124 145 136 129 130 107 129 133 136 131 123 132 138 121 135 144 103 125 119 126 133 149 139 147 132 119 120 123 149 120 111 137 146 125 125 128 139 125 120 138 123 132 120 127 118 118 129 150 118 133 148 127 138 156 131 129 129 139 149 129 118 111 140 121 122 124 107 135 142 132 130 117 121 119 137 146 116 144 108 122 118 124 136 142 135 114 124 134 142 136 148 127 126 128 133 128 121 135 139 140 133 132 142 126 123 128 124 111 121 113 137 145 142 146 145 114 116 125 141 151 126 128 148 140 134 131 126 119 129 139 123 134 132 136 139 129 134 128 132 157 134 118 142 128 128 127 108 113 122 115 126 141 87 151 136 143 137 129 138 126 146 140 128 135 138 153 126 117 126 142 132 98 120 137 115 126 114 117 134 135 140 129 130 130 104 122 117 127 114 166 128 125 141 145 127 115 132 138 143 122 125 149 123 106 131 134 146 124 126 116 107 128 129 107 118 145 126 123 124 111 136 119 118 126 131 140 125 120 128 114 144 113 144 118 128 134 110 143 120 135 130 122 126 109 144 145 123 128 138 130 120 113 140 123 128 150 141 125 149 132 138 123 125 127 144 131 132 144 136 124 130 126 114 150 112 153 132 126 132 129 131 124 109 140 127 121 147 129 129 119 133 115 115 135 131 118 144 139 102 141 136 114 109 143 111 131 108 160 143 137 135 132 133 146 117 117 143 112 118 144 149 137 138 119 137 135 133 123 142 126 127 139 126 105 144 120 132 129 111 127 135 146 140 121 131 129 142 118 131 150 140 132 140 117 116 137 127 134 132 131 118 149 130 112 133 127 126 130 116 123 130 127 143 137 134 149 134 132 134 120 128 136 138 126 139 121 125 128 141 130 131 149 149 113 136 132 132 129 108 129 137 155 144 139 118 116 120 132 142 151 143 108 125 148 124 131 118 129 125 137 128 143 113 128 113 129 136 134 114 131 125 136 118 133 112 121 117 127 126 131 124 128 126 136 122 131 132 115 125 135 116 140 129 131 118 129 121 139 133 145 148 137 135 137 129 117 120 115 117 112 124 123 116 132 133 142 143 126 131 138 129 128 134 122 159 116 135 120 129 137 115 123 113 131 125 150 134 122 115 131 134 138 113 125 148 125 104 122 142 121 125 124 122 137 145 113 132 130 153 126 131 128 133 122 142 108 134 114 112 128 131 136 142 141 125 126 124 154 119 118 132 136 137 134 133 116 126 125 133 142 131 124 122 117 117 145 147 143 103 122 133 105 139 134 115 116 126 137 132 125 116 116 141 143 132 141 129 125 112 150 116 127 107 126 122 124 126 130 112 106 116 152 133 114 130 147 122 125 118 127 132 118 126 138 139 109 145 123 143 136 120 134 123 135 122 149 117 152 128 124 135 125 131 130 137 115 141 140 131 117 125 156 128 143 128 145 121 136 116 137 121 118 152 143 133 136 116 130 117 115 145 134 131 136 120 112 144 130 133 121 112 111 129 135 138 132 121 133 147 155 122 139 154 129 104 123 127 140 117 118 134 151 131 117 121 102 146 107 131 138 141 161 155 112 134 132 135 140 130 138 108 107 121 148 119 126 139 123 140 111 128 161 150 129 128 137 146 126 131 154 135 122 131 133 96 124 124 160 140 139 149 134 138 134 130 142 129 129 143 110 114 143 131 126 126 125 111 128 120 112 130 112 141 111 128 125 137 109 127 127 148 132 127 122 143 113 128 123 111 128 119 128 117 131 125 123 125 132 139 124 127 119 133 116 131 128 148 151 139 146 125 137 113 103 117 130 114 125 142 118 134 124 125 107 111 113 149 122 137 130 141 123 127 135 107 138 123 107 118 117 150 134 140 140 116 151 131 117 127 127 127 138 130 140 146 138 106 119 137 161 139 137 136 119 143 128 121 137 127 128 107 135 131 133 123 138 127 114 142 124 153 119 112 133 123 119 134 146 118 115 151 116 138 137 129 115 121 134 121 131 131 128 144 131 123 122 118 120 110 118 126 156 149 130 107 138 137 119 144 129 126 122 129 124 122 127 140 133 132 145 131 135 128 124 141 125 126 143 131 143 141 144 132 130 127 151 123 147 130 134 143 134 110 121 137 128 141 133 122 142 123 131 140 133 132 136 130 134 125 121 141 126 122 116 117 157 133 130 138 156 140 134 114 116 113 138 133 131 126 119 138 140 134 104 122 129 159 136 114 128 138 135 142 128 133 134 118 122 139 130 146 127 150 156 140 124 134 146 131 132 151 159 156 151 144 125 139 127 165 131 151 125 137 138 139 160 151 137 149 142 133 126 137 132 151 153 137 130 154 135 129 141 112 147 132 139 134 151 132 128 130 134 142 144 146 133 129 131 127 144 143 129 153 135 143 140 127 131 135 134 141 119 138 149 133 103 136 121 140 147 124 137 132 120 122 133 135 116 140 134 146 130 135 140 129 135 135 103 142 129 152 122 123 113 142 127 140 137 130 143 128 139 130 140 135 118 128 125 151 119 151 138 147 130 107 129 120 146 136 124 132 128 129 140 129 132 135 118 134 129 130 134 133 114 128 135 133 122 134 134 122 136 132 118 135 116 116 114 148 123 142 151 120 133 144 110 151 137 134 140 148 139 143 118 137 125 118 126 128 128 122 118 135 129 133 113 139 134 148 135 142 116 139 119 148 144 138 135 149 115 108 113 133 139 139 136 126 123 142 117 121 148 121 121 143 134 150 141 135 140 130 135 125 142 130 140 119 132 120 144 130 139 139 140 134 141 133 141 141 138 134 125 108 122 114 97 130 124 142 137 119 119 151 130 154 156 111 141 139 122 125 142 134 126 134 152 132 140 123 123 128 130 109 124 130 119 115 108 133 149 128 131 138 113 136 134 118 113 138 141 132 140 129 132 140 141 126 143 142 127 121 124 138 128 151 139 123 168 140 153 141 137 147 118 124 128 132 141 142 141 116 112 119 139 136 120 144 135 116 126 112 133 148 136 119 158 117 143 150 146 135 130 131 125 144 136 135 127 157 132 127 128 122 118 145 126 153 121 144 129 134 136 140 137 126 130 148 127 130 125 145 123 137 120 119 130 113 122 160 137 116 130 136 133 131 132 140 140 141 135 131 139 136 142 127 115 127 123 142 140 145 127 115 133 137 125 131 139 132 142 136 117 151 134 136 129 125 137 145 144 129 110 128 142 115 131 153 102 97 144 127 129 149 122 137 135 128 127 134 151 131 145 154 100 126 147 132 146 125 135 151 110 119 127 128 131 155 125 138 141 134 132 133 133 115 134 122 128 153 125 135 133 152 148 133 128 117 114 119 117 112 135 131 140 137 113 140 147 157 134 142 111 117 138 101 132 132 123 140 135 135 123 141 121 123 123 133 146 112 146 139 151 142 124 133 134 126 140 145 142 132 149 131 129 121 113 122 121 139 120 144 117 135 145 125 146 126 147 122 143 118 140 108 148 159 134 150 128 128 148 125 133 125 131 110 143 147 136 128 142 147 150 133 128 134 132 128 119 141 118 150 141 125 129 150 143 153 161 121 133 135 125 132 127 130 137 137 134 117 127 155 160 126 144 138 118 143 130 118 126 133 117 132 127 141 127 128 111 145 139 135 154 118 152 138 149 121 133 139 133 115 121 133 159 124 120 158 125 133 133 144 132 147 147 131 129 140 141 136 131 148 142 136 132 125 134 121 126 141 153 131 162 114 143 109 144 119 135 132 136 117 137 113 132 142 138 132 138 144 110 147 141 150 140 137 137 128 136 122 139 143 124 129 149 129 134 132 130 141 126 154 132 136 114 124 150 116 163 139 156 122 125 143 138 129 117 119 145 123 144 120 126 169 149 128 127 138 124 143 129 133 137 139 135 130 146 125 138 125 132 141 137 138 141 126 135 143 145 109 123 131 159 131 144 136 124 114 136 124 139 116 125 150 126 134 150 137 130 117 130 130 120 131 115 123 138 128 127 140 113 141 144 124 149 155 149 127 119 121 132 127 150 147 118 139 143 140 142 134 123 154 152 134 141 126 140 132 128 143 115 125 125 151 137 119 139 141 138 134 133 129 121 142 133 129 123 140 141 161 144 119 128 113 146 123 121 123 130 148 111 134 131 133 127 121 146 158 131 117 115 137 128 146 139 113 136 125 151 149 124 160 150 114 137 116 136 136 129 118 114 142 124 136 123 114 149 142 126 118 129 138 150 113 130 137 142 120 144 152 133 141 131 146 119 144 108 144 156 161 141 129 125 125 153 147 123 121 146 138 137 133 123 138 126 131 124 123 144 104 147 136 151 147 151 137 126 137 136 127 104 114 119 137 143 141 113 123 148 142 133 119 143 127 141 151 119 113 137 137 112 136 148 145 119 137 134 127 149 137 128 136 134 118 140 146 127 120 129 145 131 137 136 123 128 150 142 123 114 143 118 116 140 126 133 128 124 115 150 130 149 123 111 131 155 101 131 133 137 147 137 129 128 129 134 121 132 132 138 126 116 134 134 157 133 110 143 124 134 130 141 164 125 131 123 125 129 139 126 146 122 131 148 133 134 136 120 137 113 149 147 118 151 137 114 148 139 116 141 121 120 133 125 131 129 110 115 124 142 133 106 113 137 139 132 122 140 129 129 119 144 136 143 135 143 146 140 119 116 139 138 131 138 116 135 138 157 126 127 140 117 132 130 124 117 137 112 136 133 150 140 147 149 152 132 104 141 156 111 146 118 131 138 132 128 134 141 139 128 133 129 122 115 132 143 123 107 145 130 131 125 146 123 134 134 139 140 127 120 134 150 138 118 124 108 125 114 139 138 104 131 127 140 134 149 131 130 130 120 135 127 125 114 118 120 133 129 160 123 121 132 137 131 129 125 143 132 145 125 127 138 136 141 128 161 136 123 126 131 129 129 125 123 129 124 132 140 132 144 123 132 131 117 154 117 134 141 138 151 129 130 132 114 131 130 133 127 131 147 111 135 142 133 117 122 108 138 118 145 117 137 131 132 140 141 122 137 115 143 127 148 132 130 146 118 135 143 134 113 135 150 103 147 130 152 138 136 128 125 139 138 100 133 110 114 134 138 110 131 134 126 126 134 130 151 118 137 127 149 94 121 136 149 129 141 143 153 129 140 115 143 142 132 130 106 130 108 127 135 137 139 142 146 136 137 131 142 127 124 147 130 140 151 128 127 135 120 114 134 140 107 165 125 136 119 139 136 140 137 140 140 149 137 132 124 137 142 114 165 132 122 124 153 141 129 126 130 132 123 124 139 138 143 156 126 115 131 154 136 133 144 138 127 120 151 127 128 118 130 110 120 127 142 130 119 129 116 147 142 133 118 126 135 141 137 134 136 142 126 127 133 137 111 123 148 142 146 142 142 122 145 129 137 121 116 117 141 121 125 156 129 143 135 108 129 144 144 147 141 117 136 150 135 154 136 144 138 116 138 127 131 136 140 137 137 123 109 123 127 130 154 123 124 135 111 147 133 139 121 146 135 147 136 133 134 151 120 141 119 142 142 119 161 123 142 129 137 126 139 138 136 141 119 149 157 130 144 137 124 117 138 128 143 144 120 141 153 124 126 150 141 141 156 124 135 124 123 141 120 108 141 128 144 132 149 124 106 126 122 133 111 125 117 147 135 135 119 132 118 128 157 148 111 137 120 128 143 133 126 120 130 145 116 147 140 131 134 144 131 124 151 149 109 125 109 129 154 149 130 120 140 131 137 137 133 164 151 145 113 134 142 136 131 135 116 153 110 132 116 140 119 160 133 127 122 132 142 115 137 133 132 136 140 150 135 151 141 143 125 137 130 132 128 133 129 136 119 137 155 130 138 128 120 131 122 151 123 141 152 150 137 137 137 142 118 140 146 133 133 136 135 130 131 149 130 133 135 130 145 138 139 135 146 130 134 122 127 130 127 129 136 140 149 140 117 134 151 159 133 124 136 140 144 150 133 143 147 150 124 134 106 143 121 158 141 157 148 138 125 151 134 140 132 166 119 141 163 152 128 148 144 146 139 150 121 140 130 151 135 137 144 128 130 127 126 128 121 135 147 138 163 120 115 136 131 128 143 120 141 131 133 130 132 125 119 137 156 130 159 136 143 161 136 118 123 143 128 151 135 139 138 125 122 141 146 120 150 134 132 137 144 136 129 129 160 129 147 138 145 137 141 161 136 150 154 118 150 138 150 129 137 137 149 149 144 128 137 133 141 166 124 159 154 159 152 141 132 134 139 133 150 131 151 145 153 157 139 167 149 157 148 132 138 132 162 128 151 142 149 131 138 157 152 140 147 155 147 160 129 158 129 140 128 145 120 132 135 144 143 131 146 135 154 140 154 148 152 123 148 154 143 151 164 137 132 134 167 142 144 132 146 139 143 121 143 165 144 164 151 128 156 144 136 127 150 151 147 154 127 144 150 147 127 134 153 152 142 132 135 123 138 142 140 149 136 142 129 145 140 155 151 134 127 137 142 133 136 145 140 159 136 144 153 137 133 151 119 141 171 131 143 155 160 132 135 144 155 155 145 163 154 133 149 144 141 131 174 147 127 158 120 152 147 133 140 121 134 120 153 137 141 144 143 134 138 132 125 128 143 134 148 135 126 126 136 149 147 122 144 140 142 142 135 152 134 134 151 134 137 132 134 125 127 118 129 146 122 149 152 129 120 126 131 142 144 133 138 137 120 152 127 124 113 136 146 120 132 177 137 130 131 157 144 142 140 134 124 124 133 124 119 117 144 133 149 134 127 125 142 156 113 142 126 133 118 134 130 138 136 117 134 116 143 136 131 131 103 137 131 129 129 142 129 155 138 129 161 131 127 101 143 136 162 139 143 131 122 129 115 122 145 124 123 121 138 154 130 135 145 133 137 147 124 125 141 143 142 127 128 131 135 133 162 140 142 135 143 128 151 150 142 116 129 133 137 146 136 122 145 131 139 151 118 121 149 141 134 130 139 133 151 126 139 123 146 144 131 159 140 125 104 115 120 131 138 125 129 112 109 130 155 117 138 126 129 148 121 121 126 127 136 157 109 127 130 121 129 134 112 119 124 122 131 145 133 146 141 143 116 139 147 129 143 126 120 145 143 134 136 140 122 150 167 127 163 130 130 134 136 128 117 140 148 144 144 133 132 157 124 143 120 119 130 137 148 152 126 148 135 138 113 127 139 138 132 145 119 140 124 139 141 121 126 141 135 137 128 135 124 149 140 136 145 140 132 136 120 118 134 125 123 140 134 126 135 133 133 143 151 138 127 153 123 134 142 123 144 130 134 110 123 118 139 108 111 142 148 128 127 138 147 150 146 130 127 147 131 128 144 158 106 161 129 145 137 179 122 137 133 139 110 128 140 127 141 134 120 121 129 140 116 132 151 120 117 128 147 143 135 137 145 144 122 107 114 121 123 142 114 137 125 141 118 151 127 151 138 136 126 132 121 102 158 152 126 130 132 133 118 141 139 139 118 135 116 148 152 131 150 136 129 142 165 144 111 144 136 127 122 129 135 119 117 146 134 133 117 120 113 112 134 150 129 131 124 121 114 122 136 149 149 139 133 120 126 120 149 144 142 133 135 119 145 129 122 124 134 142 133 127 140 126 136 132 142 146 167 111 145 123 134 140 148 137 151 148 146 151 127 136 126 125 141 131 133 145 139 127 135 156 139 127 143 146 128 137 139 124 130 141 142 154 151 120 133 125 144 132 128 124 141 152 120 126 128 129 151 148 121 129 128 112 120 142 135 134 122 139 134 141 142 146 135 138 121 125 136 125 122 141 141 120 135 130 125 128 118 154 140 132 153 141 137 134 136 134 130 128 142 119 147 125 123 139 127 142 137 117 145 144 142 126 140 129 150 122 146 141 134 126 135 145 144 135 139 137 144 143 134 131 124 133 130 140 136 141 145 134 103 143 129 125 125 149 125 133 141 144 149 126 132 141 142 132 145 146 147 140 146 136 109 146 138 136 126 123 145 144 138 119 126 156 139 125 111 134 151 129 121 130 119 110 138 132 148 124 121 123 137 129 142 133 140 135 119 116 132 142 114 133 132 119 130 151 122 126 143 151 97 162 133 151 137 104 131 138 132 145 102 127 130 145 118 130 138 133 143 130 128 132 134 133 132 127 111 123 139 151 164 131 114 114 139 124 122 117 126 137 132 147 148 117 142 138 101 133 141 135 134 121 149 144 156 114 127 127 122 125 112 115 136 136 126 146 119 142 125 121 123 129 142 144 139 128 143 133 133 132 126 153 121 121 105 132 139 119 123 143 113 138 124 132 126 140 139 132 132 130 129 135 129 136 131 136 109 141 147 134 125 143 141 116 127 115 143 123 145 132 131 138 122 127 133 147 132 123 121 129 124 134 152 143 141 127 118 124 149 136 126 112 142 132 142 134 133 124 143 126 144 116 108 126 158 130 140 128 140 134 131 130 136 153 144 140 119 132 128 123 128 151 127 129 112 119 111 136 123 111 142 135 135 115 129 122 115 110 143 133 123 137 126 125 132 122 111 111 123 138 161 123 134 133 138 150 145 125 130 143 124 124 119 146 126 115 138 133 123 130 154 118 123 112 124 129 130 131 116 135 128 150 131 110 126 100 141 127 141 125 149 123 126 130 121 137 138 120 145 126 119 121 141 108 145 120 119 133 137 115 130 133 117 147 117 118 123 138 125 131 140 146 147 131 154 129 133 124 128 110 115 132 145 132 129 136 115 128 130 134 123 120 121 121 148 118 127 135 136 140 132 125 148 153 135 130 144 143 134 127 131 136 118 137 138 126 130 128 137 121 123 123 126 143 139 131 144 122 131 113 116 113 120 129 128 120 127 129 129 129 116 121 134 127 126 146 124 115 116 138 134 139 145 127 142 146 132 140 138 140 119 128 125 152 111 132 144 131 135 132 123 134 127 139 122 131 115 137 112 122 135 129 114 115 111 157 110 152 120 130 128 127 131 145 131 126 123 142 146 130 132 150 139 136 124 119 129 132 138 123 124 108 124 115 128 124 126 128 114 161 124 120 120 135 113 129 119 134 120 133 118 123 125 136 135 117 129 132 124 138 130 114 143 122 116 137 108 142 119 108 129 127 126 129 109 112 137 143 138 106 112 125 118 146 137 110 114 128 119 135 109 114 140 123 110 137 126 115 127 130 134 147 128 114 138 130 141 147 127 119 132 113 110 102 119 137 140 134 129 131 130 128 127 141 136 107 118 146 118 124 115 124 148 141 133 130 108 115 113 123 139 151 127 121 125 141 131 147 126 119 137 123 129 121 132 117 134 123 102 144 127 114 111 108 120 129 127 133 126 143 120 117 122 121 143 140 141 134 122 133 128 99 124 133 114 115 140 120 143 108 128 116 145 112 145 121 119 118 138 111 131 119 133 135 120 142 126 132 126 140 132 121 111 137 120 142 136 132 139 120 107 126 123 139 115 130 129 154 124 111 122 122 146 128 133 128 148 150 132 132 126 125 138 128 121 117 128 130 129 128 120 152 106 123 122 145 130 152 118 148 123 115 117 136 107 103 120</counts>
			</dataPoints>
		</scan>
	</xrdMeasurement>
</xrdMeasurements>