File: data/XRD/XG-Sauerstoff/XG-pre/W6823-1B_XG_Sauerstoff_pre.xrdml
<xrdMeasurements xmlns="http://www.xrdml.com/XRDMeasurement/2.1" xmlns:xsi="http://www.w3.org/2001/XMLSchema-instance" xsi:schemaLocation="http://www.xrdml.com/XRDMeasurement/2.1 http://www.xrdml.com/XRDMeasurement/2.1/XRDMeasurement.xsd" status="Completed">
	<comment>
		<entry>Configuration=Factory configuration, Owner=User-1, Creation date=7/8/2013 4:01:53 PM</entry>
		<entry>Goniometer=PW3050/65 (Theta/2Theta); Minimum step size 2Theta:0.0001; Minimum step size Omega:0.0001</entry>
		<entry>Sample stage=MRD Cradle; Minimum step size Phi:0.01; Minimum step size Chi:0.01; Minimum step size X:0.01; Minimum step size Y:0.01; Minimum step size Z:0.001</entry>
		<entry>Diffractometer system=XPERT-PRO</entry>
		<entry>Measurement program=C:\PANalytical\Data Collector\Programs\Jorrit\2thom\_absolute_2th-om_10-130deg_PIXscan_56min.xrdmp, Identifier={15BCCF57-2807-42BD-B5B9-ECC0B3DC9284}</entry>
		<entry>Batch program=C:\PANalytical\Data Collector\Programs\SimonL\batch4x_2thom_10-130°_z9.1_x0,10,20,30_y0_57min.xrdmp, Identifier={EED9823A-2BEB-424C-9252-345C4EF2834A}</entry>
	</comment>
	<sample type="To be analyzed">
		<id></id>
		<name></name>
		<preparedBy></preparedBy>
	</sample>
	<xrdMeasurement measurementType="Scan" status="Completed" sampleMode="Reflection">
		<comment>
			<entry>_absolute_2th-om_10-130deg_PIXscan_56min</entry>
			<entry>PHD Lower Level = 4.83 (keV), PHD Upper Level = 11.27 (keV)</entry>
		</comment>
		<usedWavelength intended="K-Alpha 1">
			<kAlpha1 unit="Angstrom">1.5405980</kAlpha1>
			<kAlpha2 unit="Angstrom">1.5444260</kAlpha2>
			<kBeta unit="Angstrom">1.3922500</kBeta>
			<ratioKAlpha2KAlpha1>0.5000</ratioKAlpha2KAlpha1>
		</usedWavelength>
		<incidentBeamPath>
			<radius unit="mm">320.00</radius>
			<xRayTube id="1010048" name="Empyrean Cu LFF HR (9430 033 7310x) DK442154">
				<tension unit="kV">40.0</tension>
				<current unit="mA">40.0</current>
				<anodeMaterial>Cu</anodeMaterial>
				<focus type="Line">
					<length unit="mm">12.0</length>
					<width unit="mm">0.4</width>
					<takeOffAngle unit="deg">4.2</takeOffAngle>
				</focus>
			</xRayTube>
			<xRayMirror id="27010001" name="Inc. Beam Cu W/Si (parabolic MRD)" hybrid="false">
				<crystal type="Graded" shape="Parabolic">W/Si</crystal>
				<acceptanceAngle unit="deg">0.800</acceptanceAngle>
				<length unit="mm">60.0</length>
			</xRayMirror>
			<sollerSlit id="21010002" name="Soller slits 0.04 rad.">
				<opening unit="rad">0.0400</opening>
			</sollerSlit>
			<mask id="22030007" name="Fixed mask 2 mm">
				<distanceToSample unit="mm">220.00</distanceToSample>
				<width unit="mm">2.00</width>
			</mask>
			<divergenceSlit id="22010007" name="Fixed slit 1/8°" xsi:type="fixedDivergenceSlitType">
				<distanceToSample unit="mm">220.00</distanceToSample>
				<height unit="mm">0.19</height>
			</divergenceSlit>
		</incidentBeamPath>
		<diffractedBeamPath>
			<radius unit="mm">320.00</radius>
			<sollerSlit id="21010002" name="Soller slits 0.04 rad.">
				<opening unit="rad">0.0400</opening>
			</sollerSlit>
			<receivingSlit id="22010001" name="Fixed slit 4°">
				<height unit="mm">5.88</height>
			</receivingSlit>
			<detector id="7010017" name="PIXcel3D 1x1 detector" xsi:type="areaDetectorType">
				<phd unit="%">
					<lowerLevel>30.0</lowerLevel>
					<upperLevel>70.0</upperLevel>
				</phd>
				<mode>Scanning</mode>
				<activeChannelsEquatorial>255</activeChannelsEquatorial>
				<activeChannelsAxial>255</activeChannelsAxial>
				<pitchEquatorial unit="mm">0.05500</pitchEquatorial>
				<pitchAxial unit="mm">0.05500</pitchAxial>
				<readOutPeriod unit="seconds">0.135</readOutPeriod>
			</detector>
		</diffractedBeamPath>
		<scan appendNumber="0" mode="Continuous" scanAxis="2Theta-Omega" status="Completed">
			<header>
				<startTimeStamp>2024-09-10T18:38:30+02:00</startTimeStamp>
				<endTimeStamp>2024-09-10T19:34:36+02:00</endTimeStamp>
				<author>
					<name>PRO-MRD</name>
				</author>
				<source>
					<applicationSoftware version="6.1b">Data Collector</applicationSoftware>
					<instrumentControlSoftware version="7.0E 20130304">XPERT-PRO</instrumentControlSoftware>
					<instrumentID>0000000011142674</instrumentID>
				</source>
			</header>
			<dataPoints>
				<positions axis="2Theta" unit="deg">
					<startPosition>9.99826193</startPosition>
					<endPosition>129.99755682</endPosition>
				</positions>
				<positions axis="Omega" unit="deg">
					<startPosition>4.99913096</startPosition>
					<endPosition>64.99877841</endPosition>
				</positions>
				<positions axis="Phi" unit="deg">
					<commonPosition>0.00</commonPosition>
				</positions>
				<positions axis="Chi" unit="deg">
					<commonPosition>0.00</commonPosition>
				</positions>
				<positions axis="X" unit="mm">
					<commonPosition>20.00</commonPosition>
				</positions>
				<positions axis="Y" unit="mm">
					<commonPosition>0.00</commonPosition>
				</positions>
				<positions axis="Z" unit="mm">
					<commonPosition>9.100</commonPosition>
				</positions>
				<commonCountingTime unit="seconds">32.895</commonCountingTime>
				<counts 191 218 190 199 186 204 217 209 205 213 199 232 203 232 206 180 219 188 202 213 209 193 191 210 197 203 224 223 190 203 199 200 176 192 192 182 202 179 193 190 200 205 190 190 210 206 225 200 200 176 185 199 178 192 230 201 190 188 214 216 201 207 189 185 195 199 201 188 184 183 189 191 199 223 195 186 190 180 208 189 202 175 168 209 215 182 185 174 193 214 203 198 199 190 206 189 208 205 207 177 196 222 203 185 205 188 178 198 206 191 205 168 205 195 187 186 204 181 173 197 198 188 177 187 178 194 198 206 190 201 187 199 184 190 197 208 201 176 173 187 191 208 198 169 159 195 197 188 205 188 201 179 175 189 186 180 174 177 163 200 207 210 205 199 167 208 193 203 198 199 197 182 196 174 197 189 201 187 178 185 190 203 200 191 174 169 215 186 203 185 207 168 188 174 186 194 173 180 188 197 187 186 145 200 171 178 167 206 188 187 220 209 210 191 197 182 186 175 167 176 187 217 176 178 198 183 195 165 210 189 199 216 190 190 194 190 174 182 198 180 182 171 175 169 201 191 188 185 186 176 177 196 167 186 195 178 162 196 180 161 192 187 187 201 184 192 192 177 191 170 182 199 181 186 212 179 176 193 190 178 197 172 192 176 176 157 170 163 163 179 181 176 180 195 172 166 171 181 164 178 193 166 191 159 180 188 191 179 157 166 175 208 188 171 200 170 184 167 160 167 195 196 182 196 210 183 195 178 173 205 187 167 181 148 172 175 189 173 153 171 172 197 196 170 201 187 176 177 164 180 159 192 166 188 163 173 174 188 161 162 205 170 184 178 169 185 146 162 157 174 195 195 158 171 201 173 183 165 197 145 204 182 169 175 180 179 158 183 183 170 155 184 199 192 134 168 174 194 162 166 159 165 184 192 178 154 180 155 154 194 151 199 156 167 189 168 153 152 177 159 203 164 174 192 183 169 162 167 157 192 176 179 167 173 147 155 172 169 189 159 145 199 146 161 163 172 173 191 166 190 178 149 177 182 158 154 156 157 167 172 164 167 153 170 168 155 152 168 156 177 190 173 152 170 170 174 149 194 162 165 154 181 168 167 172 168 178 143 165 161 162 180 189 169 154 187 170 165 187 186 161 172 178 177 157 160 163 172 166 161 154 184 181 162 151 175 176 170 156 152 178 147 166 153 180 165 156 171 189 165 175 161 150 169 167 176 164 186 179 147 178 143 188 145 158 164 162 164 154 173 178 179 180 169 192 156 158 154 169 158 147 181 148 131 164 162 171 183 143 170 179 167 142 180 161 153 188 152 168 169 157 154 158 154 178 147 178 151 176 155 174 185 153 151 152 164 152 154 154 170 165 172 192 138 178 165 167 160 157 161 165 165 143 145 167 155 165 160 170 168 164 135 176 180 162 181 149 172 177 180 146 167 150 158 164 155 160 153 158 152 168 178 180 182 171 171 139 154 143 156 155 158 155 164 160 172 170 134 173 166 151 142 129 168 148 147 161 157 168 142 149 156 158 154 161 159 137 178 149 173 170 176 173 160 178 146 167 175 149 144 185 174 145 144 154 178 166 160 171 154 156 159 181 173 181 189 158 149 151 147 165 152 158 134 169 175 165 140 155 170 153 163 153 164 164 170 143 139 151 165 186 173 141 163 162 168 158 178 169 171 158 147 157 157 162 167 159 196 183 173 166 141 167 177 155 168 184 146 153 168 145 159 169 159 164 169 158 156 170 194 144 158 151 174 162 169 154 159 156 149 198 164 175 160 169 183 152 173 145 153 138 170 178 140 140 160 152 171 151 161 163 159 168 160 135 158 146 161 167 147 176 180 163 150 132 172 172 143 141 174 151 171 158 189 152 168 166 156 144 167 168 156 152 154 148 138 172 173 143 176 168 165 160 148 166 144 138 132 146 152 165 159 161 182 170 151 152 150 157 141 155 142 153 163 160 161 142 162 145 143 168 138 133 173 151 167 176 129 145 148 173 187 155 160 152 142 155 146 148 151 160 154 164 161 160 165 164 133 172 160 153 154 147 157 140 157 156 144 173 171 145 192 151 178 164 149 175 153 148 168 176 170 163 176 143 152 139 149 164 164 174 151 156 168 144 147 157 163 151 172 164 128 169 158 160 160 144 151 153 162 151 162 173 132 149 143 138 156 146 158 160 147 154 150 157 171 160 163 151 155 163 148 159 166 135 145 167 149 158 148 169 164 174 184 159 155 147 152 157 164 171 169 148 162 163 148 126 158 188 167 167 159 154 158 149 167 159 157 146 151 148 152 145 136 158 151 155 180 170 175 151 163 148 143 174 139 165 173 132 180 153 182 159 157 159 187 159 173 167 152 166 152 153 131 159 156 154 128 160 156 174 163 153 166 155 169 148 152 128 156 177 169 164 143 150 157 152 139 153 171 158 149 170 174 158 150 165 177 137 177 156 144 170 180 177 145 153 144 124 166 172 166 161 147 158 146 157 151 143 149 175 171 168 142 162 134 168 156 153 172 149 174 146 161 156 152 149 158 158 161 158 165 159 173 165 126 169 140 150 138 181 145 142 148 145 167 182 154 140 157 162 132 164 180 151 164 150 148 168 156 157 156 172 169 175 154 169 154 139 159 149 164 149 184 136 171 170 163 164 171 167 160 158 160 165 169 186 164 180 153 144 155 194 185 190 173 153 169 159 170 172 156 158 168 147 157 168 153 151 152 163 172 146 156 172 172 136 168 162 172 167 186 154 166 186 174 151 153 189 165 159 165 151 169 193 172 154 171 173 172 161 148 179 176 163 155 148 159 149 139 166 147 161 155 151 167 166 152 166 164 178 167 160 179 183 160 168 140 166 164 172 160 163 159 154 170 152 142 158 166 156 165 160 153 167 162 153 169 156 149 152 146 159 143 174 155 155 140 166 155 158 159 170 148 158 130 171 140 165 158 138 163 163 124 165 168 172 157 165 190 163 160 180 146 158 157 148 153 147 167 154 159 169 165 161 145 156 156 186 173 153 163 154 166 156 162 167 166 148 171 140 148 167 140 130 174 162 170 171 173 167 156 145 132 152 170 179 167 161 174 167 167 186 177 154 165 155 156 163 156 155 148 152 160 170 153 154 147 166 162 140 161 164 157 168 167 165 168 158 150 159 143 162 134 167 150 184 153 175 159 155 159 138 172 154 163 147 158 170 166 171 159 163 145 141 173 157 149 158 155 152 152 156 134 150 163 161 159 151 144 161 166 165 164 158 133 159 170 163 138 158 176 146 147 163 154 144 169 141 157 156 157 147 136 160 149 166 160 156 136 151 161 152 159 166 155 159 142 167 175 138 149 163 150 139 141 153 137 145 137 145 146 154 170 143 141 160 156 166 146 140 150 173 164 152 144 152 133 151 157 160 147 153 151 157 163 131 168 139 155 156 143 161 163 151 151 146 151 167 147 154 158 142 141 159 149 149 144 137 131 144 161 131 133 101 146 151 143 149 146 135 135 149 120 136 149 152 157 143 155 142 157 156 134 160 114 136 151 146 147 121 137 179 154 161 135 161 130 142 135 139 141 146 128 149 173 157 146 131 129 136 146 135 155 149 135 128 160 146 145 155 128 150 153 145 147 145 156 138 122 132 133 117 147 137 145 152 144 153 134 144 136 149 123 162 150 125 144 144 129 165 148 134 138 145 131 152 146 143 137 125 131 126 120 118 127 133 142 144 148 137 151 140 141 138 148 139 152 141 147 129 154 134 147 145 139 141 117 152 135 121 154 146 142 142 115 134 144 128 125 157 133 145 159 134 126 138 139 146 131 162 142 139 157 130 146 129 127 146 146 146 150 156 143 135 134 148 160 145 156 136 138 137 137 153 142 148 122 130 141 130 121 130 137 138 143 145 132 148 130 126 122 134 130 129 131 111 121 138 130 143 141 145 129 123 145 121 142 138 135 135 152 124 107 126 135 133 124 132 142 134 133 132 136 154 166 152 128 143 139 130 151 132 142 113 108 113 129 139 123 113 125 106 132 131 103 130 133 146 135 110 154 133 130 110 130 135 133 133 124 136 129 121 127 146 115 145 135 116 122 130 145 129 152 133 142 126 111 116 122 138 139 115 123 122 103 133 133 131 143 131 119 137 118 144 124 113 124 145 114 121 129 123 107 145 135 126 134 113 136 122 118 114 121 124 127 120 111 149 124 137 121 119 115 124 99 127 118 131 143 147 136 142 116 157 114 131 122 140 112 109 135 123 123 142 116 109 135 130 124 131 132 120 113 114 133 107 146 120 138 122 129 128 103 108 132 130 130 133 121 123 116 120 133 117 118 133 116 138 115 121 126 122 106 131 130 128 104 121 108 123 141 129 139 131 110 136 110 120 119 145 108 116 140 122 130 95 128 140 117 125 114 124 125 106 122 136 95 125 130 113 125 133 131 121 125 115 109 123 123 121 126 112 113 134 113 104 101 122 119 129 111 143 142 106 119 111 112 107 127 119 119 113 112 125 113 125 122 121 122 122 123 131 117 151 129 121 131 112 99 113 116 129 117 127 116 118 116 117 92 131 123 117 128 105 119 130 124 132 135 114 139 123 91 107 125 118 148 127 130 107 113 125 114 105 115 112 118 111 108 131 106 121 121 95 115 118 136 110 110 114 114 116 107 116 112 109 104 125 124 105 121 119 123 119 143 127 115 111 103 115 111 113 119 92 123 140 106 114 118 145 106 129 105 129 122 137 123 106 105 108 103 113 106 87 110 129 114 128 123 123 122 122 120 117 144 123 100 140 117 118 134 110 109 105 118 100 113 107 104 120 104 105 128 96 125 107 117 125 139 127 106 116 112 125 105 104 137 118 104 102 92 131 112 125 117 122 100 121 96 103 113 130 121 117 107 124 105 92 104 104 95 124 117 135 103 109 114 118 114 109 98 146 109 110 93 124 119 119 136 108 96 111 125 123 100 107 121 106 114 111 107 111 101 136 111 126 108 122 108 114 115 111 107 98 123 113 110 123 112 106 97 110 123 124 104 114 109 105 91 97 136 111 108 127 101 115 101 126 119 124 118 112 117 117 109 112 98 103 100 111 110 104 109 140 128 101 103 96 100 102 94 102 111 108 119 129 121 112 122 114 112 112 105 100 118 119 117 109 106 109 95 97 94 119 115 100 109 113 101 101 110 96 117 117 102 113 118 97 94 115 111 99 96 125 116 97 105 121 93 115 126 104 118 112 110 124 109 122 105 119 107 92 124 95 97 99 92 113 105 117 118 103 105 110 109 103 96 121 126 100 121 109 109 116 102 119 104 99 97 114 101 108 97 102 125 104 118 103 109 111 116 133 99 108 123 122 111 118 112 113 125 99 104 116 109 113 88 118 92 119 111 91 110 121 112 107 99 88 117 103 81 107 85 118 97 111 118 105 88 138 91 112 114 96 104 113 120 108 116 109 118 104 98 141 120 97 110 94 115 111 104 97 111 104 109 110 106 100 106 98 115 97 110 101 115 100 112 99 98 110 95 101 122 100 110 114 102 112 120 108 96 107 109 104 114 87 115 120 111 109 92 105 101 112 114 112 112 112 113 113 98 112 98 106 91 104 116 103 110 111 124 114 96 95 102 102 104 93 107 112 90 107 104 122 103 115 99 105 100 114 84 116 90 102 116 96 92 118 107 112 101 102 101 102 104 103 113 109 102 109 93 107 97 103 115 114 113 94 97 89 110 113 112 108 109 104 95 110 110 101 117 110 114 100 94 112 127 95 95 112 99 114 108 112 113 104 115 94 102 112 119 108 113 101 95 90 105 91 99 110 102 96 109 115 102 91 98 103 113 104 104 108 105 121 116 114 103 110 92 116 105 107 100 103 96 100 104 100 104 101 93 91 106 113 105 86 106 86 101 125 111 92 87 91 113 97 91 94 134 112 97 96 105 105 106 103 105 121 86 101 106 106 103 126 97 114 103 125 116 117 98 99 101 105 111 95 112 102 119 116 116 103 100 94 98 94 107 108 110 105 116 97 114 70 92 90 96 120 114 101 116 95 99 116 122 81 79 102 118 101 99 125 103 90 95 102 95 106 96 113 100 98 95 110 104 96 116 113 81 106 87 104 119 110 89 100 103 110 112 90 111 102 101 127 86 111 98 100 123 101 94 99 105 103 98 94 91 115 101 108 99 102 93 104 102 101 86 97 99 110 98 109 105 95 115 110 130 103 106 94 102 106 96 100 85 105 109 105 81 103 80 90 86 105 93 94 94 110 107 100 92 104 116 102 98 108 91 103 109 105 108 92 92 97 102 111 86 101 100 104 95 116 103 125 110 111 111 97 106 123 98 130 111 94 95 109 122 99 111 104 108 108 113 104 82 102 97 93 106 90 92 114 91 91 93 84 99 90 101 115 108 109 118 105 90 89 98 105 104 111 117 101 97 84 108 103 106 105 97 94 92 93 98 110 90 89 111 94 108 100 114 103 88 99 112 91 91 124 100 102 80 106 113 111 94 107 89 114 97 106 113 111 107 102 103 110 114 89 108 96 91 109 88 103 104 107 107 90 97 100 79 92 80 95 107 103 106 100 113 97 96 83 81 99 101 96 82 114 92 86 103 108 115 109 105 123 94 96 117 98 99 95 90 104 97 98 113 125 103 106 95 97 107 89 94 99 103 109 93 107 100 95 104 112 101 82 94 125 97 105 98 87 111 105 105 92 102 114 127 105 104 106 102 93 83 108 116 125 114 98 96 94 87 108 113 94 103 102 101 122 80 114 91 100 112 96 110 127 119 104 130 97 112 102 99 119 110 93 100 105 105 108 109 101 106 102 90 107 108 109 124 98 100 97 74 110 110 95 114 103 107 92 109 103 130 119 85 105 117 98 109 114 96 106 105 112 94 107 90 114 106 107 120 97 90 107 120 117 119 122 111 104 92 93 109 84 103 114 106 122 93 107 115 124 107 99 125 93 105 81 85 101 107 103 121 99 111 104 95 99 100 87 104 108 125 116 101 105 90 96 107 96 104 89 108 94 93 106 113 119 93 91 94 95 125 108 96 105 95 90 82 107 94 94 96 106 103 108 115 106 108 103 100 98 100 121 109 103 132 125 109 109 110 100 102 100 106 108 118 105 108 110 99 109 96 115 88 81 120 102 104 96 96 119 98 114 110 120 88 99 111 105 101 122 103 97 94 104 124 100 110 101 100 105 95 91 97 102 115 121 99 101 111 118 94 96 92 100 116 99 113 97 105 96 114 112 110 98 116 123 105 128 102 112 110 111 84 112 114 95 106 93 110 107 114 124 90 118 91 116 102 110 99 91 115 120 88 93 122 98 130 112 114 92 106 114 99 106 126 110 98 104 103 96 106 114 102 100 103 95 104 85 123 93 104 113 114 96 110 111 91 105 100 109 106 101 90 113 96 114 101 96 98 112 126 112 116 114 107 103 99 121 107 105 109 117 110 110 95 95 93 105 92 107 102 106 122 113 86 119 122 114 104 108 105 106 116 112 106 116 118 120 106 120 126 130 100 129 84 122 103 99 116 114 100 113 120 118 115 108 131 113 116 114 104 108 109 92 119 121 138 96 106 108 112 100 123 127 106 108 121 100 123 95 117 112 120 120 113 125 106 111 115 116 106 118 114 121 107 133 126 141 111 113 96 116 135 126 125 103 108 109 119 108 114 123 134 118 109 97 114 118 122 101 128 127 118 122 122 109 110 109 113 115 118 90 125 122 127 103 125 121 108 102 121 102 127 118 109 138 116 120 100 111 130 123 113 110 117 105 112 131 120 112 127 135 129 109 132 144 129 100 145 127 110 133 123 130 113 124 145 133 141 132 131 127 118 143 129 136 134 137 134 134 158 154 171 146 164 153 164 162 163 144 164 185 209 186 196 174 180 176 189 191 166 202 195 182 179 175 158 204 168 156 135 191 180 170 152 153 167 163 151 162 165 147 129 145 138 123 133 118 120 110 116 146 123 119 121 116 140 115 115 110 114 116 105 124 118 119 112 131 117 100 135 102 119 111 137 113 125 131 109 90 123 112 117 120 105 92 119 132 113 107 114 118 95 93 122 110 107 136 115 103 100 120 104 101 101 145 119 106 106 125 97 86 94 108 124 124 100 107 102 102 118 119 119 100 115 108 123 95 115 114 117 117 101 128 105 105 99 128 110 118 101 96 125 113 115 99 126 88 105 117 89 94 117 100 106 115 88 106 86 103 116 104 119 97 107 136 99 106 97 107 98 93 109 104 94 123 116 97 99 125 127 122 91 112 99 100 115 103 108 107 96 113 105 110 106 91 117 99 101 117 91 118 108 92 113 106 102 97 84 95 100 120 116 106 112 103 107 96 106 118 104 85 101 100 121 102 110 101 116 105 105 105 108 116 91 111 102 88 105 112 109 92 109 119 97 118 104 109 99 111 102 125 109 113 108 122 113 110 86 102 111 109 97 114 121 98 97 124 110 108 90 108 152 130 115 126 104 93 121 116 103 99 99 99 130 107 94 118 100 105 94 110 121 121 107 123 116 98 110 109 99 124 109 111 115 122 99 93 107 109 96 115 138 105 111 105 99 121 117 114 120 125 102 96 112 92 106 103 120 111 112 122 95 115 112 110 103 118 103 107 103 113 92 106 98 104 106 112 114 101 88 95 116 99 116 114 89 105 96 101 114 102 119 103 99 97 106 110 104 114 107 106 100 105 110 92 110 123 106 94 105 117 114 130 112 93 113 118 99 114 124 111 103 100 119 108 103 123 99 108 97 89 114 89 96 110 121 94 108 112 106 98 111 128 113 93 103 115 117 103 107 105 117 98 95 113 94 107 114 108 109 109 122 117 131 97 115 122 126 115 89 91 113 122 107 112 135 111 118 116 106 106 102 102 109 110 102 108 106 125 95 109 100 115 122 107 113 112 118 106 126 114 116 109 119 105 102 98 129 117 101 121 99 110 97 109 104 102 109 120 103 96 100 108 104 106 97 105 109 107 116 111 100 103 114 109 123 113 120 119 112 104 106 110 115 122 113 115 103 101 112 133 122 127 100 113 94 115 95 96 104 112 92 115 111 127 122 93 104 98 116 126 101 109 111 118 119 103 119 95 97 112 111 98 111 124 113 119 84 113 91 101 118 110 131 120 116 128 91 108 104 111 82 107 119 105 100 129 122 112 99 112 113 127 120 112 102 113 96 116 91 105 103 105 102 105 103 102 116 117 108 118 98 100 101 95 101 127 101 111 108 109 88 105 111 102 112 97 103 117 120 110 92 96 121 107 105 110 110 116 114 115 130 109 129 111 95 97 114 96 112 129 108 111 113 133 120 104 105 116 89 123 106 126 123 109 104 102 105 115 100 101 92 122 120 97 102 106 113 103 97 112 97 121 99 97 118 97 111 114 113 138 128 123 121 98 123 101 123 110 102 113 109 99 114 82 110 110 113 120 105 124 122 110 122 128 106 106 106 109 97 104 108 102 111 103 106 131 126 96 99 102 95 114 105 121 111 108 109 95 112 96 102 108 104 105 111 103 119 104 123 124 110 116 117 107 88 107 104 100 99 119 110 111 118 99 126 97 111 93 103 108 123 118 116 111 107 117 132 118 118 105 102 113 125 98 96 106 92 115 109 98 110 99 105 92 106 105 106 98 87 112 99 109 106 108 90 99 112 107 93 109 108 97 97 106 111 123 123 82 127 105 95 115 108 117 115 107 123 89 86 115 107 107 107 120 96 124 110 101 115 100 97 97 123 129 110 112 91 92 109 118 117 100 121 117 100 136 119 99 114 118 116 104 118 99 123 102 108 102 113 100 113 102 101 118 130 100 110 107 103 101 103 97 100 123 111 98 119 104 129 115 119 106 118 115 98 115 98 107 111 118 110 109 122 116 77 112 97 119 113 107 116 116 118 104 121 107 128 107 117 108 103 105 107 115 111 105 112 119 120 120 97 119 121 117 98 105 111 107 131 95 110 123 125 126 113 124 116 123 121 124 114 104 111 110 105 123 93 95 108 108 99 118 118 110 101 105 118 106 110 133 120 115 137 117 113 128 116 123 115 105 105 121 117 88 114 129 81 98 97 103 106 103 117 107 109 98 117 114 98 114 108 119 120 118 125 94 121 111 130 128 127 118 130 116 110 97 97 122 114 114 106 116 111 103 96 92 116 76 96 131 121 122 124 98 97 108 103 109 86 105 120 116 111 99 114 120 118 120 104 143 110 103 115 107 103 107 123 108 110 110 92 113 115 110 116 122 106 109 96 106 115 118 102 92 113 100 95 123 118 101 100 108 130 112 102 120 122 115 112 94 113 130 94 100 109 108 108 102 122 109 109 125 114 109 110 74 98 109 103 117 113 109 106 129 92 119 121 110 95 115 108 109 139 100 116 117 101 123 109 132 108 121 111 120 105 124 116 103 110 121 123 108 105 114 99 120 109 104 97 112 102 96 100 105 128 121 102 86 100 107 114 113 115 105 126 128 98 104 127 96 108 113 110 99 112 102 115 113 107 102 112 119 99 97 104 104 124 114 110 122 109 113 98 127 92 125 124 108 104 115 103 107 127 116 111 108 111 100 112 95 108 90 91 108 97 119 116 116 135 111 106 120 130 120 113 98 103 114 102 101 88 125 109 117 103 138 116 100 115 124 103 113 111 121 103 94 116 96 126 111 126 114 110 92 94 138 138 146 111 97 99 113 118 111 120 116 114 118 106 108 107 98 106 98 129 111 97 113 127 108 87 102 118 112 110 113 109 101 128 132 111 102 129 86 130 114 98 129 124 105 104 96 118 104 130 107 119 100 104 104 109 96 110 116 112 112 105 119 127 103 99 122 107 99 116 98 128 112 102 113 94 116 109 107 113 117 119 114 133 110 103 106 123 122 108 104 107 98 97 106 108 105 117 104 110 105 115 107 120 109 131 123 102 119 117 105 120 111 109 107 100 103 112 116 126 108 114 108 101 114 96 127 103 113 125 128 104 119 91 112 110 109 118 104 104 130 98 121 108 108 106 120 124 100 103 114 104 127 106 104 94 113 112 108 99 111 114 109 104 89 117 128 107 108 101 116 99 92 113 125 100 108 112 102 123 123 100 107 145 98 108 108 98 111 120 109 107 115 132 88 119 93 108 111 108 134 94 114 116 95 108 112 118 122 124 99 108 112 101 118 122 121 99 112 116 93 134 108 133 104 111 111 104 125 124 123 103 105 123 127 79 110 97 113 116 115 107 115 122 120 110 97 121 98 112 120 116 106 139 102 128 117 114 98 115 113 118 104 120 109 118 128 100 108 123 111 116 114 115 116 94 98 108 99 107 112 121 97 131 101 115 109 116 127 108 98 126 112 114 112 108 105 123 134 118 105 101 117 114 108 108 135 117 132 110 117 104 132 124 113 105 117 106 108 112 109 113 121 104 114 88 113 112 112 105 107 105 115 124 106 109 123 104 107 129 112 114 106 114 99 128 96 102 114 98 111 106 110 92 129 107 114 125 113 117 110 96 103 103 111 98 101 108 113 106 108 110 122 114 114 104 124 96 95 98 103 108 105 109 83 123 105 100 111 107 116 137 110 128 109 98 102 102 119 119 102 106 129 111 126 121 124 95 102 132 115 109 102 120 109 126 96 103 111 132 120 114 96 107 114 129 106 114 116 119 116 118 107 98 107 108 98 109 109 126 94 118 113 109 108 115 101 115 98 127 97 116 99 133 120 107 110 112 102 95 104 135 112 90 105 108 108 123 100 101 127 112 127 142 112 102 111 111 117 124 96 96 99 111 109 96 124 113 125 108 91 138 106 118 108 117 115 112 114 102 102 109 125 101 112 99 115 102 116 117 121 97 119 113 115 110 123 109 110 111 91 107 96 96 116 126 108 121 100 115 122 93 118 115 98 106 110 106 126 101 118 113 117 115 122 113 113 121 100 121 131 108 119 118 108 99 122 106 113 117 120 94 110 110 136 114 105 116 118 115 115 113 104 119 126 103 123 116 109 103 110 111 101 110 115 121 112 111 106 125 114 104 134 124 110 135 131 120 101 110 105 98 110 127 119 126 105 96 123 115 111 117 112 117 99 109 122 117 128 124 114 95 112 117 120 107 113 107 80 95 109 112 114 117 113 112 113 107 121 130 112 101 108 123 113 79 126 125 109 101 101 108 113 120 115 124 119 110 88 136 116 125 104 106 128 97 104 116 124 118 138 120 131 111 121 109 115 132 118 122 128 117 118 109 127 114 98 120 100 99 114 117 102 114 130 94 101 102 123 110 125 111 130 109 112 105 97 96 120 114 139 131 121 102 119 129 129 104 127 111 111 124 115 99 121 90 124 112 113 102 113 112 118 126 92 117 122 118 113 116 111 112 115 108 120 122 113 125 123 106 109 111 116 109 105 121 111 111 117 112 121 97 124 108 111 121 114 129 128 115 105 113 104 95 120 116 114 103 118 152 99 116 135 125 108 112 127 118 135 103 117 120 118 115 117 113 103 113 125 98 97 133 98 106 139 109 130 115 132 127 119 121 114 109 127 95 118 126 110 129 112 97 109 114 105 100 140 117 108 125 104 148 130 98 116 126 117 125 107 145 119 124 114 117 120 119 107 129 116 119 122 117 118 116 117 120 119 124 101 122 101 123 121 128 133 108 129 118 143 124 103 124 127 121 96 109 108 104 129 109 119 100 116 125 112 106 115 134 98 112 121 125 99 145 117 118 122 132 111 129 91 126 133 128 101 118 96 111 105 99 116 114 124 122 116 123 117 111 108 110 121 121 148 115 101 134 114 117 108 115 126 124 108 144 114 97 114 122 110 123 128 115 118 111 105 118 103 120 99 106 110 116 109 95 113 122 120 129 110 115 109 115 112 122 95 118 116 129 107 121 101 118 124 102 100 119 117 107 103 117 99 97 117 116 122 98 103 109 110 103 110 93 127 128 113 107 111 110 120 126 122 112 130 122 107 127 94 111 111 114 107 110 111 113 107 116 101 132 113 94 103 112 116 110 106 141 97 100 92 97 123 121 125 107 135 128 117 98 96 125 112 112 110 102 119 105 101 126 107 96 113 122 110 113 107 119 114 101 101 99 114 111 113 119 110 92 98 119 131 106 112 111 119 105 127 107 104 107 123 128 116 97 120 118 117 125 97 103 105 135 121 115 122 112 120 111 123 124 103 119 134 110 123 102 131 100 104 113 89 112 103 103 102 100 118 122 94 95 112 113 139 109 122 109 109 128 101 105 116 129 124 108 123 111 104 113 119 122 115 133 130 108 113 131 121 112 97 114 110 121 109 144 110 110 94 127 113 115 127 130 101 111 111 122 105 124 118 110 107 112 102 116 111 106 111 106 109 117 104 106 110 95 106 104 105 110 125 113 114 102 130 91 137 110 90 128 99 108 92 109 104 111 111 117 103 114 89 114 102 111 113 105 112 118 107 119 114 99 114 130 114 103 110 111 113 116 117 116 112 113 110 110 108 99 123 112 98 141 110 121 110 108 119 97 121 107 116 107 122 102 120 103 116 114 109 103 115 98 124 106 112 108 89 98 110 101 103 117 97 108 114 110 97 112 99 111 110 108 122 111 117 92 119 120 116 95 118 107 103 101 130 152 115 113 118 114 126 109 106 133 120 122 114 109 101 103 114 103 99 116 110 125 136 112 105 90 109 104 106 96 122 116 110 132 120 107 116 112 114 121 118 104 105 108 119 99 119 118 111 118 126 95 120 128 117 90 96 96 114 116 122 100 104 112 120 112 114 126 112 101 124 137 107 117 108 111 92 105 107 108 97 115 91 100 104 102 108 109 117 130 119 107 114 123 110 125 118 117 104 91 127 116 103 91 102 94 102 94 121 106 109 104 90 102 118 138 97 122 103 110 116 102 94 110 123 123 88 109 133 106 100 109 98 108 116 101 108 108 103 96 129 104 118 90 113 94 89 96 133 98 112 103 86 116 97 114 101 135 105 105 118 117 104 108 121 122 107 110 112 92 109 116 96 111 121 108 116 113 106 93 94 107 104 123 112 114 110 94 109 134 121 94 103 102 127 99 117 117 98 100 131 140 97 111 119 112 120 142 120 112 100 107 112 117 122 97 114 102 115 147 108 103 122 130 123 116 126 104 128 89 118 118 101 111 110 103 115 98 137 114 116 106 110 106 113 103 110 122 102 126 119 118 98 103 109 103 119 123 118 113 98 113 97 128 109 109 104 113 103 105 110 99 123 118 120 95 119 106 125 93 126 108 108 114 95 98 96 121 127 117 108 108 99 112 106 110 114 106 107 101 105 109 97 105 102 141 116 122 114 113 135 102 123 108 120 104 105 113 112 87 106 125 111 111 105 93 121 112 130 130 94 138 119 113 116 119 111 89 119 114 108 109 115 117 100 112 112 107 110 102 112 111 96 98 109 137 98 115 112 110 123 122 116 120 112 125 110 116 102 97 96 112 119 114 94 104 108 111 107 107 125 110 104 119 118 103 120 107 90 98 103 115 125 103 127 113 106 100 96 121 126 113 107 131 132 108 101 111 96 120 104 128 129 110 98 96 110 97 125 120 108 95 114 115 111 121 115 135 108 114 124 107 98 110 104 112 97 136 104 108 91 121 105 112 124 114 107 128 96 113 97 114 108 112 115 115 101 104 100 113 127 101 111 108 81 98 118 109 107 121 116 129 116 106 137 125 126 92 108 119 95 110 114 100 118 111 117 102 97 105 137 92 121 110 119 127 111 131 117 108 121 106 90 131 119 101 110 94 104 105 113 120 112 120 105 112 117 117 104 103 99 120 116 123 122 135 111 106 101 121 118 109 108 117 93 106 128 107 119 119 87 103 131 107 118 123 90 110 101 103 120 119 114 108 119 129 120 101 118 113 112 122 113 113 129 138 113 124 122 96 108 108 132 116 117 107 110 94 109 116 102 122 91 116 102 103 122 115 118 116 106 133 105 104 113 113 119 112 104 119 97 77 117 92 111 99 102 100 121 109 101 118 111 103 95 109 104 126 87 115 112 112 92 109 116 118 96 106 105 113 112 126 124 113 108 110 111 101 133 106 99 105 104 109 115 118 117 114 101 130 102 113 110 104 102 117 121 139 110 111 98 124 102 111 109 80 104 132 110 105 106 126 106 108 102 99 111 119 112 115 111 112 113 94 114 102 125 118 91 116 117 114 129 85 110 104 116 118 98 86 124 111 124 117 111 109 108 113 105 114 108 116 126 114 116 108 116 103 114 112 110 112 115 102 114 128 120 115 117 110 118 121 114 130 108 116 134 111 112 118 112 98 116 120 111 114 99 127 138 98 106 122 120 103 110 117 128 110 101 121 96 108 95 111 95 89 115 114 108 117 100 103 102 91 110 117 127 109 139 106 115 109 117 96 125 124 92 103 115 111 112 128 111 116 120 99 110 99 112 90 113 118 120 114 106 120 114 115 104 102 120 116 126 113 111 120 115 109 103 117 119 136 93 107 123 87 101 110 92 123 120 126 116 115 121 130 115 100 106 117 113 115 104 103 122 105 118 111 120 123 130 119 111 102 99 117 105 95 105 135 85 108 112 83 110 109 118 124 104 106 85 124 79 121 118 116 123 108 106 113 115 115 111 156 112 110 110 115 119 106 101 106 116 119 119 103 112 112 106 122 97 112 99 113 111 108 125 115 104 128 118 112 112 93 123 94 115 112 105 95 89 103 102 106 115 103 119 120 92 108 95 102 93 94 108 117 104 108 109 119 98 98 115 110 103 105 104 111 111 108 115 111 115 105 120 109 111 119 109 112 136 109 120 100 112 113 127 107 101 110 117 123 122 103 124 109 111 113 108 111 117 116 100 119 106 105 124 107 120 107 104 109 118 107 91 103 100 113 116 117 108 114 122 110 136 103 110 120 102 115 87 105 128 115 91 114 105 110 108 118 105 77 109 109 98 101 121 102 110 99 111 105 115 116 108 125 105 122 96 120 104 128 110 113 106 127 109 99 123 109 123 109 111 107 99 109 106 112 104 132 119 129 116 98 115 110 105 105 128 105 103 118 119 113 104 125 98 119 107 103 117 127 94 107 128 106 106 109 112 103 116 117 101 114 94 103 112 102 120 122 91 119 128 119 110 120 130 116 119 105 91 110 104 111 89 114 98 114 113 106 142 109 130 113 104 102 127 110 122 114 109 113 99 109 112 112 114 98 111 121 90 121 114 103 112 105 103 119 118 107 106 107 117 110 114 107 97 105 116 104 107 116 127 113 95 112 102 115 113 94 108 92 111 95 102 111 129 96 110 100 126 111 124 103 102 96 112 131 117 125 111 111 91 118 93 116 115 110 126 121 97 110 109 123 103 128 120 135 117 114 113 114 126 128 129 115 126 120 114 138 106 129 121 118 133 111 116 91 119 96 118 112 122 102 112 141 115 111 120 110 120 132 103 94 121 119 120 113 108 121 112 102 98 118 133 125 106 114 112 115 105 111 110 124 148 109 124 116 96 127 115 114 120 120 126 119 121 112 109 111 129 112 124 123 115 94 121 148 124 115 111 125 111 130 124 97 107 118 130 133 105 118 113 121 118 104 127 136 111 108 126 134 136 136 102 133 109 123 127 140 137 117 132 156 132 146 109 109 138 135 133 134 116 109 123 127 138 135 123 136 108 127 122 121 140 121 107 114 105 130 120 139 119 126 114 104 111 121 124 110 108 116 132 114 100 112 103 113 112 109 96 122 114 99 117 100 110 113 129 114 126 116 88 108 106 110 100 112 94 101 126 111 100 102 115 100 116 109 106 114 132 119 117 124 109 118 125 117 109 118 107 96 121 99 107 93 132 110 112 110 104 126 104 112 105 129 97 110 116 119 97 100 111 97 116 108 92 109 94 92 106 99 121 113 118 118 116 124 103 101 97 100 96 114 118 122 92 120 123 119 107 90 107 112 111 112 115 102 104 114 125 107 120 114 109 110 109 117 105 133 112 107 106 101 121 130 114 127 107 98 106 115 98 107 94 96 111 112 119 106 106 110 110 103 111 109 106 109 113 112 98 110 100 118 108 111 127 117 99 103 107 118 124 99 127 117 90 98 105 108 106 130 115 99 106 109 137 107 103 111 114 116 103 95 106 112 105 113 113 116 108 121 105 101 117 114 112 114 104 98 110 112 111 112 101 112 121 99 105 104 113 104 110 116 113 113 109 111 106 96 125 111 106 100 101 106 117 105 121 100 114 107 99 118 109 105 106 98 101 97 102 111 116 109 113 110 103 105 115 104 109 103 111 113 104 104 104 135 94 114 99 101 108 136 114 102 110 123 108 115 111 115 105 114 101 105 115 119 103 101 97 104 82 92 92 90 98 113 108 113 108 123 90 110 97 109 95 112 115 102 103 128 107 115 106 126 117 98 123 133 105 98 110 108 107 100 98 119 123 115 94 106 116 92 109 109 101 121 121 110 100 109 106 102 110 112 100 98 120 116 109 108 98 111 130 100 108 107 107 122 114 108 127 111 95 107 106 113 122 108 112 124 116 119 110 108 115 112 111 108 112 120 108 96 109 86 125 125 118 117 102 106 112 96 101 97 113 107 119 87 94 118 113 123 95 111 119 106 97 95 108 83 103 87 120 113 107 120 115 105 95 126 111 105 95 107 116 119 115 123 126 98 124 118 125 112 100 125 106 115 110 119 117 107 127 132 120 123 116 101 107 116 111 119 107 100 118 91 110 108 108 122 118 118 133 110 119 116 94 101 112 118 106 120 125 116 98 107 139 95 111 104 104 122 116 119 117 110 120 93 115 95 89 103 96 109 105 117 104 106 110 111 131 111 103 101 104 104 104 118 106 118 106 106 106 114 131 116 120 96 93 111 117 102 112 125 109 99 126 108 104 117 117 120 104 107 108 119 100 99 110 108 102 106 121 128 112 113 110 116 107 112 102 116 119 102 105 110 120 128 119 105 96 112 111 120 107 111 110 104 102 107 93 109 97 116 108 123 109 105 113 109 98 102 113 116 110 114 100 100 118 107 103 108 104 113 119 123 109 117 114 113 118 100 101 100 136 120 123 129 118 131 124 98 112 125 117 114 112 115 113 122 118 119 116 106 121 101 115 102 110 118 112 101 127 101 117 105 131 109 109 104 96 107 103 104 111 119 97 100 109 103 113 108 116 117 107 106 103 124 87 134 105 117 112 102 101 124 103 98 98 90 102 114 111 124 140 93 107 121 91 119 111 96 108 115 121 108 113 101 103 112 113 116 115 111 125 109 122 113 128 100 91 121 111 115 108 114 112 119 104 111 122 126 99 107 106 120 137 110 126 100 89 114 120 110 98 128 113 111 98 124 95 139 124 114 103 113 124 108 96 113 117 102 123 116 107 102 106 125 128 124 118 113 101 100 114 114 128 108 131 115 128 104 92 92 132 123 97 105 112 92 117 113 111 111 106 121 116 100 124 116 102 124 111 108 102 126 120 92 90 96 109 110 125 98 134 113 129 138 97 131 106 138 116 109 113 108 93 119 109 104 130 130 100 101 103 113 105 111 128 103 99 123 137 112 115 114 119 112 112 102 109 124 116 107 105 107 102 106 129 114 116 102 100 99 110 105 112 97 100 85 120 120 115 120 98 109 100 99 106 116 99 113 111 130 113 93 93 103 95 116 107 119 94 99 113 127 127 107 105 113 94 103 97 128 131 119 112 102 102 114 110 110 117 111 109 116 102 97 118 99 115 106 121 108 118 100 116 108 92 119 114 99 101 110 122 126 113 105 126 113 118 97 102 112 121 124 111 104 113 90 122 117 103 104 93 103 122 109 83 114 115 102 110 118 104 123 116 111 100 132 113 127 113 120 97 96 113 112 117 95 110 111 87 112 99 133 113 115 112 112 113 95 105 109 109 105 96 119 120 118 99 109 134 122 101 104 124 110 110 105 124 123 127 110 108 115 117 103 130 92 106 96 111 109 101 102 121 120 119 131 118 96 103 107 104 106 105 107 102 113 132 106 113 119 107 104 105 115 108 112 108 119 112 102 117 95 102 120 87 111 102 101 105 121 101 96 127 92 109 119 123 111 111 115 92 134 126 129 104 110 102 107 123 122 117 113 118 106 114 106 121 104 120 110 110 115 103 106 101 120 112 111 111 115 126 105 100 115 99 98 104 99 107 132 94 102 131 120 104 103 100 80 108 101 102 112 123 108 127 101 135 132 103 104 101 107 106 123 107 121 115 128 117 121 99 104 113 124 116 119 110 89 117 116 118 95 117 113 121 116 113 112 119 117 97 108 109 108 98 110 99 123 133 97 115 111 100 97 120 144 117 125 120 122 105 119 108 106 127 123 124 117 116 102 132 102 125 110 116 103 107 108 107 115 133 113 123 104 125 101 128 106 100 116 111 104 109 106 98 122 114 112 96 103 129 123 107 125 105 97 121 107 109 105 107 134 119 104 117 103 100 102 96 122 120 116 128 109 134 90 97 98 95 119 125 108 92 108 112 113 125 118 105 104 102 107 121 116 118 109 99 113 112 141 119 103 123 123 119 121 106 118 116 117 130 132 132 124 103 133 109 120 125 129 125 140 116 113 112 122 117 114 122 131 105 98 107 109 115 81 119 116 111 84 117 101 119 114 111 101 113 111 100 103 100 104 105 115 115 119 95 105 106 105 113 114 95 109 122 129 109 101 122 121 120 100 132 104 106 128 109 109 116 105 121 114 105 113 93 111 96 107 140 113 116 118 101 109 116 130 118 110 110 134 112 123 116 106 98 114 130 121 103 111 105 128 114 111 111 113 114 119 110 134 123 103 115 107 134 112 110 111 131 98 112 126 127 115 82 122 114 114 123 99 107 121 99 96 114 127 121 93 117 101 119 116 98 112 111 121 117 112 141 113 132 130 107 106 116 119 102 106 114 93 98 116 106 133 115 118 132 118 103 104 114 102 99 120 108 109 108 115 123 136 124 109 104 113 112 112 100 112 104 91 117 104 108 119 113 123 127 104 108 127 100 136 125 105 119 119 119 107 114 113 105 119 98 103 118 106 117 122 116 102 124 116 116 113 127 114 112 97 113 117 122 116 111 119 113 113 129 102 116 104 101 110 127 140 92 110 122 122 131 119 125 121 111 111 117 107 107 130 123 110 114 115 119 120 111 122 107 108 108 108 99 108 133 85 114 118 126 126 125 113 114 123 114 119 133 114 130 115 120 120 102 122 112 112 104 109 119 114 99 107 124 121 110 99 108 117 120 122 120 117 88 125 106 109 113 127 116 117 116 121 104 123 121 120 118 117 126 109 131 133 119 135 109 121 97 119 99 113 106 107 123 133 103 123 104 107 125 123 110 114 110 121 129 116 118 103 124 107 128 118 106 120 127 131 109 100 127 136 101 116 128 117 127 112 111 101 114 110 109 136 134 116 119 110 123 135 101 119 126 120 127 126 120 122 119 119 114 133 123 106 130 139 115 115 102 106 120 115 113 133 133 105 123 128 116 103 111 128 125 111 111 133 133 105 118 110 115 101 97 117 124 119 106 112 98 124 104 119 102 115 111 107 124 106 92 138 114 132 118 122 119 120 116 126 115 118 110 102 105 115 125 104 91 125 97 98 116 127 92 119 128 116 107 122 113 118 106 126 130 109 119 113 121 98 109 103 99 118 115 126 109 108 132 115 111 110 123 96 114 96 127 108 111 115 87 112 107 130 94 114 104 108 116 116 120 100 111 134 105 115 119 114 104 102 106 105 120 105 121 134 122 95 111 119 116 111 103 98 100 111 106 130 122 125 119 118 92 114 108 92 105 92 115 112 132 116 89 102 102 122 102 99 122 112 106 95 116 103 119 134 106 131 109 125 119 109 98 107 119 121 121 117 105 145 104 106 90 96 99 114 113 106 98 104 120 91 112 119 110 114 110 115 136 106 122 100 135 118 93 105 115 109 120 98 123 107 122 126 117 132 118 123 112 92 128 99 98 122 108 94 97 127 110 106 116 129 132 100 125 127 122 116 89 124 114 97 115 114 110 113 124 105 104 109 115 111 119 123 95 113 110 111 121 116 108 123 114 136 114 104 114 124 108 113 110 109 128 117 96 118 126 101 132 118 109 127 106 110 96 104 97 116 123 110 114 113 130 118 91 127 102 112 103 132 114 119 112 104 109 109 121 100 123 108 147 101 124 114 92 119 136 109 119 107 126 96 113 117 120 130 111 149 114 115 109 122 103 129 114 111 92 124 117 104 113 116 129 100 104 114 119 131 107 115 109 116 117 109 114 102 110 132 101 103 122 115 96 99 120 121 120 87 111 123 103 114 101 108 106 120 101 138 126 111 103 114 103 125 118 110 115 129 107 129 106 113 121 122 122 99 113 119 107 116 122 105 121 103 101 116 113 126 132 105 124 113 111 108 117 108 108 116 103 127 117 126 113 118 127 115 117 109 107 132 118 118 101 125 105 124 107 90 112 124 107 122 124 103 105 111 121 107 109 103 118 124 100 89 118 115 123 94 119 118 109 112 115 107 107 135 101 107 127 115 95 104 108 131 112 103 115 112 116 112 109 106 123 95 127 95 128 99 111 103 101 127 112 104 102 113 109 117 105 126 122 89 135 112 112 105 115 125 125 119 127 118 113 100 114 102 95 98 113 112 111 120 129 114 108 119 125 108 111 124 98 115 103 100 104 132 118 114 105 128 120 107 101 117 123 109 112 103 104 126 116 116 97 117 103 116 139 113 126 118 120 109 109 120 104 117 134 109 116 115 94 120 112 94 115 119 102 126 114 116 123 109 120 119 103 111 108 115 99 129 109 102 107 107 132 113 87 117 108 103 131 135 115 123 114 112 118 117 129 124 115 114 145 108 93 117 105 123 117 115 104 106 85 119 110 106 106 126 119 117 102 114 100 113 109 100 117 109 115 100 114 132 113 104 133 96 119 116 117 96 112 123 105 106 132 148 101 104 107 121 101 102 118 135 108 117 115 88 125 109 96 114 128 125 127 109 110 104 117 113 102 97 132 103 122 122 114 115 115 105 119 98 102 122 138 110 105 125 111 118 112 122 110 115 115 113 107 107 124 127 112 93 116 140 114 122 111 100 117 100 111 98 119 127 107 125 119 107 111 100 111 119 101 110 117 112 115 100 95 109 110 126 107 101 99 109 111 110 110 107 112 129 116 114 117 101 97 111 105 106 115 116 110 115 105 109 106 110 110 114 113 108 106 116 99 126 101 126 126 112 105 116 122 102 96 113 113 109 117 104 128 107 101 110 126 101 110 114 116 102 110 119 134 116 105 123 92 107 116 124 103 101 127 108 125 121 109 113 119 111 96 119 116 107 121 111 110 112 110 106 105 112 104 131 108 91 141 120 105 129 112 105 115 131 113 117 118 115 110 100 115 89 117 136 111 117 128 109 108 112 110 131 109 113 106 147 123 127 125 103 122 124 114 119 99 136 103 113 102 122 113 113 123 120 103 117 97 112 108 97 107 125 109 124 126 104 131 117 126 105 105 102 106 120 108 113 131 114 111 117 105 112 114 104 105 126 93 109 118 123 123 111 121 107 116 107 125 121 121 103 117 95 101 123 113 111 120 108 87 113 136 104 117 116 108 129 131 101 96 117 111 133 115 127 108 119 103 115 131 96 110 122 117 108 124 114 115 109 99 93 101 98 106 125 137 114 97 113 99 129 122 108 111 116 94 131 107 119 146 125 105 86 99 102 97 119 97 133 111 99 114 100 100 106 111 139 113 111 114 97 93 124 97 122 104 108 98 88 115 103 125 128 103 108 123 103 120 117 104 125 110 102 100 109 107 105 115 125 109 105 102 104 104 102 103 107 120 102 98 108 118 111 106 93 113 126 97 103 101 104 101 105 116 116 108 117 126 97 122 113 110 109 114 113 106 116 104 128 110 116 93 114 114 103 112 129 121 114 105 114 118 116 92 107 97 100 97 100 100 102 111 116 129 115 106 117 122 114 122 116 98 128 110 99 125 114 103 131 128 113 115 94 111 99 97 110 111 118 120 125 97 105 118 116 107 112 100 129 98 108 114 107 97 101 107 113 96 117 108 91 106 98 105 102 114 110 116 111 116 124 107 126 102 118 101 95 105 112 129 108 118 85 105 102 126 116 110 109 114 114 115 108 94 99 122 104 105 121 100 122 97 116 141 110 110 99 118 111 103 116 133 113 131 131 120 102 101 117 120 135 94 117 109 124 125 109 125 99 115 113 117 108 95 112 126 120 96 117 107 111 139 115 102 127 104 121 101 105 110 120 120 109 102 116 107 106 101 94 108 97 86 100 97 102 96 113 110 124 100 95 138 127 90 110 127 107 106 105 126 105 118 109 127 101 115 111 120 112 105 107 117 103 127 111 112 94 92 95 118 112 118 123 118 106 118 126 113 112 107 119 109 97 124 127 116 117 117 123 115 112 97 96 90 103 111 93 126 97 104 119 106 112 104 113 111 105 111 110 100 105 88 107 121 107 116 113 116 105 112 108 102 118 90 125 101 114 109 110 104 119 95 111 108 110 99 133 109 97 109 121 109 115 87 106 110 97 103 112 112 110 131 112 118 114 115 109 125 106 107 109 94 111 120 105 107 117 120 123 121 118 124 109 110 120 121 124 120 104 115 100 113 93 122 136 118 108 117 113 122 107 110 124 109 134 122 110 110 126 114 122 93 119 122 115 123 110 116 105 89 108 106 91 103 104 127 109 96 133 102 118 118 132 110 94 105 131 94 98 100 114 96 114 108 119 104 131 114 115 109 113 107 102 125 114 97 120 102 116 98 108 98 108 108 116 112 134 110 96 118 117 122 104 117 134 117 118 113 122 117 105 105 112 120 101 113 100 127 101 113 101 122 101 116 122 124 98 109 107 108 110 96 108 111 104 116 106 124 126 116 117 120 117 124 114 110 95 131 118 129 109 114 120 108 111 117 124 115 106 103 109 117 117 101 128 120 97 104 96 110 104 124 107 123 121 122 115 108 106 116 92 130 112 102 109 125 110 118 111 108 126 122 106 111 125 116 97 115 91 107 119 98 131 101 133 125 108 111 124 112 119 108 137 126 116 130 129 108 125 131 118 114 114 112 114 97 131 102 113 125 112 106 115 116 107 109 111 138 121 108 113 112 111 125 114 118 118 111 98 130 105 112 117 108 103 114 121 104 94 115 87 120 120 123 114 111 126 106 108 111 133 121 97 107 115 121 120 117 118 111 106 111 107 121 115 107 108 102 104 125 109 126 104 117 108 103 116 112 97 110 115 121 100 116 120 112 120 127 109 105 127 122 114 111 127 105 118 107 119 109 121 130 110 114 117 124 89 94 119 124 117 104 105 102 121 114 129 136 113 126 112 115 151 142 91 133 126 94 120 107 102 108 114 119 130 106 114 128 126 100 109 148 116 126 113 122 126 112 121 111 128 125 123 127 107 119 133 114 119 121 107 122 119 107 104 102 127 110 101 113 113 112 108 132 110 114 107 91 115 102 123 114 111 99 117 122 112 100 112 103 121 107 116 119 131 141 116 124 142 117 134 108 119 110 94 113 125 106 100 112 119 114 100 130 125 115 114 110 110 109 114 128 113 126 131 111 120 131 126 108 110 124 123 110 114 107 114 98 126 101 116 117 114 123 133 115 118 105 104 108 113 98 96 104 111 123 105 106 96 103 131 108 125 117 110 98 130 115 100 121 109 119 117 111 125 128 114 92 109 91 134 122 125 123 107 115 114 124 110 109 99 115 118 125 136 124 125 99 135 114 99 116 117 105 120 134 111 97 119 126 102 99 107 127 106 129 97 117 120 109 110 110 110 118 103 121 107 120 128 105 123 120 117 111 109 125 101 117 113 117 130 115 127 115 99 102 117 106 113 132 100 133 116 115 122 117 109 136 104 99 93 119 131 121 91 96 96 108 100 110 110 106 110 123 101 115 103 97 116 97 125 126 108 100 111 128 122 128 114 95 98 99 88 119 111 103 119 121 133 109 109 109 106 110 99 118 92 116 101 118 116 132 118 100 125 126 103 115 116 109 130 108 103 120 105 110 129 115 111 88 112 107 102 96 102 109 115 106 105 124 101 119 97 105 107 135 105 129 92 105 103 127 119 111 97 94 113 113 110 104 105 114 125 116 124 127 127 108 130 94 106 92 98 96 114 127 99 110 112 108 91 104 111 119 110 130 112 130 99 118 117 114 123 113 139 115 102 105 108 104 119 105 128 115 110 103 101 127 114 94 103 114 110 100 102 98 91 143 96 109 107 90 110 108 110 111 96 118 106 105 111 127 104 103 118 107 112 105 111 90 114 108 110 121 125 102 135 124 116 99 110 120 113 112 102 108 95 115 94 116 116 118 121 109 94 112 113 124 107 121 107 97 113 101 97 102 89 120 102 108 112 100 111 115 97 121 119 122 109 111 101 117 114 107 102 102 106 124 108 106 109 103 122 118 111 129 103 115 104 110 100 94 112 88 135 102 102 115 112 109 110 125 92 103 99 111 113 104 122 118 116 100 104 116 114 88 120 99 100 110 92 127 108 107 133 117 125 115 134 98 113 105 98 92 103 103 115 111 94 116 112 107 107 126 101 117 94 119 88 114 107 110 117 114 105 130 119 120 110 130 98 109 103 130 95 117 122 86 103 122 124 114 124 109 108 111 107 114 114 110 93 92 118 100 121 95 103 113 117 94 106 82 105 93 105 124 101 117 112 112 100 116 111 93 138 100 104 114 109 104 123 94 120 124 97 121 109 107 103 126 110 104 80 111 90 107 108 106 107 121 114 113 101 129 100 101 93 95 110 113 130 105 112 110 104 113 126 110 117 115 113 111 99 96 104 100 121 118 93 110 117 113 104 96 113 110 118 111 118 104 99 98 123 97 127 103 107 105 103 122 115 103 115 114 109 120 105 116 125 103 114 112 96 130 88 108 98 112 109 101 103 107 103 128 102 96 111 120 115 94 121 110 127 100 118 123 97 99 76 108 99 116 94 107 116 96 121 93 95 119 121 95 113 117 104 106 111 113 121 105 114 110 102 96 108 124 123 102 108 128 118 108 119 103 107 101 110 101 105 106 117 98 130 105 120 127 98 106 112 117 113 118 104 106 104 114 122 116 116 101 97 100 104 123 108 123 118 89 114 96 97 110 95 117 109 98 102 116 110 116 100 131 112 95 113 128 106 116 115 111 118 109 105 124 99 102 86 112 110 116 110 131 112 96 127 83 113 101 128 116 114 133 105 95 98 103 114 106 112 113 116 93 94 116 118 112 111 109 119 100 118 104 106 112 106 110 112 102 94 94 106 116 102 100 108 118 94 110 95 121 100 113 116 119 125 104 105 112 108 114 118 113 102 109 93 127 98 95 104 106 111 94 118 104 130 125 111 119 110 102 112 107 108 112 108 94 118 109 111 112 81 108 99 109 109 105 111 116 115 113 123 130 114 106 80 97 102 110 122 103 92 97 118 111 111 108 109 118 92 105 111 103 97 120 119 122 116 115 99 120 120 121 115 105 117 104 109 105 111 101 124 122 118 112 106 103 95 109 99 102 118 119 117 125 123 100 117 115 126 114 100 108 96 123 112 110 113 103 109 118 111 105 102 113 100 112 122 118 116 99 97 121 95 111 110 126 109 118 108 116 116 92 99 119 96 115 110 93 112 100 127 123 99 109 104 110 122 98 106 104 106 115 93 134 117 109 113 129 94 108 121 107 104 122 101 116 108 95 100 110 107 121 128 75 98 122 107 122 113 126 124 113 100 96 114 101 107 102 119 95 110 108 97 109 103 112 116 120 104 108 106 105 102 105 106 92 88 103 87 113 100 103 106 122 109 109 112 97 121 109 95 105 98 125 113 122 99 105 116 118 85 129 109 93 123 116 126 99 117 97 122 108 102 100 113 116 111 106 113 124 130 106 124 107 103 105 104 96 125 98 112 134 130 90 101 115 95 107 112 129 114 108 115 109 128 91 111 111 106 118 123 107 106 96 104 102 111 108 121 122 120 105 122 97 115 97 109 111 115 102 105 99 114 102 111 100 109 111 110 112 101 105 112 103 106 112 111 96 121 109 123 101 103 91 117 105 96 100 93 99 129 111 109 82 110 99 113 113 115 119 103 129 107 126 114 120 123 101 124 104 113 107 110 113 114 123 90 89 110 98 94 97 110 106 129 116 114 105 95 109 107 83 128 133 100 104 114 105 94 107 91 116 108 96 119 111 115 138 110 104 104 99 106 101 92 90 119 114 124 119 112 113 116 104 122 94 110 107 123 99 107 112 101 118 120 114 99 99 107 97 101 117 98 114 118 99 116 105 105 92 90 111 104 122 97 118 121 103 107 111 93 104 129 108 103 112 106 110 110 100 117 110 107 101 124 100 113 110 104 119 100 115 108 110 120 95 102 102 118 128 95 102 98 94 101 97 95 103 93 100 103 97 114 99 104 114 116 102 101 111 98 99 112 111 113 98 108 107 113 113 116 90 115 92 104 118 104 132 112 111 113 125 104 125 100 113 100 96 100 101 111 102 122 117 127 115 106 111 111 112 116 117 104 94 117 114 99 114 113 103 111 106 118 103 86 114 102 100 128 97 114 103 99 104 101 108 109 90 108 112 108 103 113 120 112</counts>
			</dataPoints>
		</scan>
	</xrdMeasurement>
</xrdMeasurements>