File: data/XRD/XG-Sauerstoff/XG-875/W6822-1B_XG_Sauerstoff_875.xrdml
<xrdMeasurements xmlns="http://www.xrdml.com/XRDMeasurement/2.1" xmlns:xsi="http://www.w3.org/2001/XMLSchema-instance" xsi:schemaLocation="http://www.xrdml.com/XRDMeasurement/2.1 http://www.xrdml.com/XRDMeasurement/2.1/XRDMeasurement.xsd" status="Completed">
	<comment>
		<entry>Configuration=Factory configuration, Owner=User-1, Creation date=7/8/2013 4:01:53 PM</entry>
		<entry>Goniometer=PW3050/65 (Theta/2Theta); Minimum step size 2Theta:0.0001; Minimum step size Omega:0.0001</entry>
		<entry>Sample stage=MRD Cradle; Minimum step size Phi:0.01; Minimum step size Chi:0.01; Minimum step size X:0.01; Minimum step size Y:0.01; Minimum step size Z:0.001</entry>
		<entry>Diffractometer system=XPERT-PRO</entry>
		<entry>Measurement program=C:\PANalytical\Data Collector\Programs\Jorrit\2thom\_absolute_2th-om_10-130deg_PIXscan_56min.xrdmp, Identifier={15BCCF57-2807-42BD-B5B9-ECC0B3DC9284}</entry>
		<entry>Batch program=C:\PANalytical\Data Collector\Programs\SimonL\batch4x_2thom_10-130°_z9.1_x0,10,20,30_y0_57min.xrdmp, Identifier={EED9823A-2BEB-424C-9252-345C4EF2834A}</entry>
	</comment>
	<sample type="To be analyzed">
		<id></id>
		<name></name>
		<preparedBy></preparedBy>
	</sample>
	<xrdMeasurement measurementType="Scan" status="Completed" sampleMode="Reflection">
		<comment>
			<entry>_absolute_2th-om_10-130deg_PIXscan_56min</entry>
			<entry>PHD Lower Level = 4.83 (keV), PHD Upper Level = 11.27 (keV)</entry>
		</comment>
		<usedWavelength intended="K-Alpha 1">
			<kAlpha1 unit="Angstrom">1.5405980</kAlpha1>
			<kAlpha2 unit="Angstrom">1.5444260</kAlpha2>
			<kBeta unit="Angstrom">1.3922500</kBeta>
			<ratioKAlpha2KAlpha1>0.5000</ratioKAlpha2KAlpha1>
		</usedWavelength>
		<incidentBeamPath>
			<radius unit="mm">320.00</radius>
			<xRayTube id="1010048" name="Empyrean Cu LFF HR (9430 033 7310x) DK442154">
				<tension unit="kV">40.0</tension>
				<current unit="mA">40.0</current>
				<anodeMaterial>Cu</anodeMaterial>
				<focus type="Line">
					<length unit="mm">12.0</length>
					<width unit="mm">0.4</width>
					<takeOffAngle unit="deg">4.2</takeOffAngle>
				</focus>
			</xRayTube>
			<xRayMirror id="27010001" name="Inc. Beam Cu W/Si (parabolic MRD)" hybrid="false">
				<crystal type="Graded" shape="Parabolic">W/Si</crystal>
				<acceptanceAngle unit="deg">0.800</acceptanceAngle>
				<length unit="mm">60.0</length>
			</xRayMirror>
			<sollerSlit id="21010002" name="Soller slits 0.04 rad.">
				<opening unit="rad">0.0400</opening>
			</sollerSlit>
			<mask id="22030008" name="Fixed mask 4 mm">
				<distanceToSample unit="mm">220.00</distanceToSample>
				<width unit="mm">4.00</width>
			</mask>
			<divergenceSlit id="22010007" name="Fixed slit 1/8°" xsi:type="fixedDivergenceSlitType">
				<distanceToSample unit="mm">220.00</distanceToSample>
				<height unit="mm">0.19</height>
			</divergenceSlit>
		</incidentBeamPath>
		<diffractedBeamPath>
			<radius unit="mm">320.00</radius>
			<sollerSlit id="21010002" name="Soller slits 0.04 rad.">
				<opening unit="rad">0.0400</opening>
			</sollerSlit>
			<receivingSlit id="22010001" name="Fixed slit 4°">
				<height unit="mm">5.88</height>
			</receivingSlit>
			<detector id="7010017" name="PIXcel3D 1x1 detector" xsi:type="areaDetectorType">
				<phd unit="%">
					<lowerLevel>30.0</lowerLevel>
					<upperLevel>70.0</upperLevel>
				</phd>
				<mode>Scanning</mode>
				<activeChannelsEquatorial>255</activeChannelsEquatorial>
				<activeChannelsAxial>255</activeChannelsAxial>
				<pitchEquatorial unit="mm">0.05500</pitchEquatorial>
				<pitchAxial unit="mm">0.05500</pitchAxial>
				<readOutPeriod unit="seconds">0.135</readOutPeriod>
			</detector>
		</diffractedBeamPath>
		<scan appendNumber="0" mode="Continuous" scanAxis="2Theta-Omega" status="Completed">
			<header>
				<startTimeStamp>2024-10-02T15:45:13+02:00</startTimeStamp>
				<endTimeStamp>2024-10-02T16:41:19+02:00</endTimeStamp>
				<author>
					<name>PRO-MRD</name>
				</author>
				<source>
					<applicationSoftware version="6.1b">Data Collector</applicationSoftware>
					<instrumentControlSoftware version="7.0E 20130304">XPERT-PRO</instrumentControlSoftware>
					<instrumentID>0000000011142674</instrumentID>
				</source>
			</header>
			<dataPoints>
				<positions axis="2Theta" unit="deg">
					<startPosition>9.99826193</startPosition>
					<endPosition>129.99755682</endPosition>
				</positions>
				<positions axis="Omega" unit="deg">
					<startPosition>4.99913096</startPosition>
					<endPosition>64.99877841</endPosition>
				</positions>
				<positions axis="Phi" unit="deg">
					<commonPosition>0.00</commonPosition>
				</positions>
				<positions axis="Chi" unit="deg">
					<commonPosition>0.00</commonPosition>
				</positions>
				<positions axis="X" unit="mm">
					<commonPosition>10.00</commonPosition>
				</positions>
				<positions axis="Y" unit="mm">
					<commonPosition>0.00</commonPosition>
				</positions>
				<positions axis="Z" unit="mm">
					<commonPosition>9.100</commonPosition>
				</positions>
				<commonCountingTime unit="seconds">32.895</commonCountingTime>
				<counts 443 448 480 448 478 483 466 458 413 447 458 480 451 461 469 465 442 460 477 405 463 441 431 467 430 487 494 481 526 448 467 454 443 452 435 497 439 456 470 462 468 433 464 402 478 413 465 459 447 487 468 439 455 462 463 451 446 460 449 454 469 450 433 456 467 430 475 450 403 481 452 456 430 455 462 447 445 479 415 413 471 461 439 432 442 485 464 439 432 437 414 430 424 424 480 449 453 431 441 410 455 448 420 411 449 442 427 468 400 402 416 412 431 454 407 497 422 401 401 421 436 421 419 409 440 389 416 416 471 441 424 394 445 404 405 439 388 426 421 441 396 401 419 433 421 436 409 438 386 376 433 440 397 424 480 506 404 406 375 445 430 424 417 469 426 442 385 449 388 405 398 406 420 409 414 404 411 448 401 421 428 392 432 421 392 415 411 409 419 362 418 445 401 406 443 425 393 390 370 402 411 414 399 423 424 419 396 437 416 423 379 396 435 405 408 415 394 393 380 377 397 419 377 415 406 417 403 399 391 438 367 393 416 427 385 401 412 387 419 378 375 421 365 344 396 364 356 372 408 402 406 410 424 384 392 412 398 405 358 366 361 421 394 391 407 374 373 396 387 403 383 363 404 389 356 391 401 408 424 404 363 417 374 400 384 381 408 391 388 373 403 355 427 427 397 383 391 357 369 393 375 380 394 348 384 353 387 397 378 386 373 378 374 392 336 371 389 390 346 359 350 372 366 401 393 410 387 386 361 369 383 375 364 366 354 368 388 351 373 344 364 375 309 358 344 353 351 368 373 338 378 361 390 363 364 353 368 346 374 408 360 378 331 347 344 346 360 378 353 357 323 377 373 367 344 353 373 355 346 361 379 357 368 362 351 375 338 352 364 362 343 351 372 359 362 356 374 345 350 356 392 365 321 399 361 350 340 366 352 317 359 351 375 357 359 310 368 359 346 368 319 341 352 356 327 346 375 365 357 338 335 345 370 342 336 376 349 314 299 351 364 362 386 335 327 370 373 366 360 371 355 367 325 321 337 368 322 323 371 360 320 357 353 336 371 332 336 337 344 326 351 337 338 349 344 337 310 362 355 320 360 313 355 322 339 336 350 362 338 341 318 350 359 333 330 307 361 353 316 337 344 343 367 385 344 334 360 343 370 339 334 348 353 346 354 358 335 357 332 328 335 327 333 320 318 334 354 349 346 346 348 354 326 309 344 313 328 344 309 347 330 325 327 310 324 328 320 318 345 350 336 350 349 366 325 335 350 335 328 303 344 373 330 309 325 365 340 359 357 323 338 328 329 344 355 331 353 359 327 295 323 339 321 322 320 312 346 323 317 293 334 323 332 329 299 335 317 325 334 296 366 332 356 339 297 334 341 355 327 318 289 341 316 351 328 282 318 316 306 318 310 330 343 333 337 306 326 350 334 334 321 284 340 341 328 337 319 308 298 309 365 330 331 310 312 323 330 321 314 345 294 306 319 328 352 325 351 350 323 336 317 340 314 321 307 323 294 328 395 329 292 325 301 330 289 339 348 328 333 346 316 319 295 291 300 340 302 306 316 296 329 329 317 311 318 311 328 303 301 334 285 330 320 310 310 331 315 314 292 316 296 311 327 290 349 307 315 322 337 335 319 336 316 315 330 311 311 339 296 337 339 340 333 332 327 338 315 315 320 324 284 337 291 315 313 355 335 360 337 333 308 324 344 328 315 352 321 331 338 318 308 300 305 340 328 308 352 322 319 308 322 315 291 312 280 346 359 319 299 310 306 305 296 289 349 314 315 349 336 312 312 322 331 339 307 322 316 315 309 307 306 311 349 347 309 332 316 335 357 336 318 326 332 338 289 334 325 294 315 310 310 314 312 314 329 305 336 313 361 312 339 323 298 286 329 316 342 310 332 320 305 312 315 339 369 344 313 310 349 335 302 322 344 330 324 318 358 297 322 332 329 363 326 325 295 298 292 302 323 354 366 305 302 320 338 331 307 334 362 320 343 334 320 314 320 332 315 328 334 325 329 279 312 325 336 320 323 344 322 346 295 346 298 321 343 325 328 347 349 331 337 335 341 360 338 338 315 304 316 292 340 315 328 340 302 344 333 328 322 353 339 368 329 289 320 327 311 314 350 309 303 334 302 323 362 322 330 328 307 323 320 318 344 304 351 320 312 306 330 334 304 345 353 329 334 290 357 353 324 322 327 337 317 312 319 330 310 341 340 343 295 326 336 317 344 321 318 310 347 335 303 337 315 324 340 324 290 331 323 324 334 331 347 338 370 342 367 318 342 376 331 322 329 340 342 344 330 330 323 314 321 334 318 324 347 326 315 346 334 313 318 308 352 310 339 345 323 341 330 347 341 300 281 299 322 331 335 304 292 354 319 354 317 348 340 299 340 312 314 336 318 335 322 326 345 321 351 313 323 305 294 313 346 337 314 329 326 323 329 321 356 316 342 294 327 318 361 349 343 344 352 327 301 335 379 329 353 358 293 327 340 371 325 313 323 340 317 334 300 306 318 359 335 332 378 305 336 307 314 331 351 319 338 337 336 368 341 323 340 325 347 345 325 345 339 354 321 346 315 337 303 367 345 334 338 309 332 344 342 301 343 351 348 316 336 339 332 360 377 327 312 339 353 322 338 315 325 312 337 296 323 321 348 336 346 368 306 383 327 349 323 328 340 315 342 349 308 378 329 314 343 347 369 322 331 305 356 345 317 348 300 337 348 327 338 290 340 326 345 339 349 359 318 358 305 336 317 346 329 325 323 339 334 377 302 323 317 333 351 373 308 325 358 342 335 306 361 320 323 330 312 318 365 349 357 335 343 375 326 352 331 343 315 331 307 332 323 305 316 360 352 344 310 302 344 325 328 328 344 336 349 333 347 329 338 355 341 328 312 364 322 319 350 299 340 311 332 306 283 314 334 328 305 321 318 334 355 329 350 319 340 317 293 342 318 326 351 375 301 383 349 330 326 328 321 346 321 374 311 331 317 365 330 347 325 331 302 332 343 330 337 339 336 304 326 300 361 334 314 337 348 333 344 324 328 351 310 359 311 320 347 337 323 375 345 329 351 319 300 313 312 304 330 341 328 338 318 314 359 342 336 345 326 318 331 321 340 314 304 308 337 351 300 318 351 354 312 336 330 317 301 340 331 327 344 346 358 298 343 342 305 359 300 295 323 350 332 340 317 326 361 308 351 305 330 313 342 321 340 364 297 320 336 322 310 331 328 329 322 324 325 296 290 336 347 330 343 313 326 302 337 335 321 315 315 317 297 312 308 296 330 290 338 288 331 332 323 343 333 306 341 322 306 328 326 321 332 278 326 366 298 356 338 292 295 311 323 338 311 303 308 296 338 316 319 305 299 319 295 311 321 342 325 311 337 305 342 360 338 299 334 296 337 320 308 312 337 307 313 322 330 331 330 329 339 308 290 307 342 306 305 322 315 334 320 317 333 293 323 311 279 313 310 304 339 315 299 302 335 318 289 324 335 306 319 325 281 289 324 289 324 328 299 300 312 292 321 329 316 320 329 318 315 345 337 330 317 318 298 320 307 315 314 309 306 300 308 307 299 288 316 309 289 314 310 299 310 333 306 305 326 334 286 311 306 294 317 321 330 306 308 309 321 313 315 304 271 294 317 279 282 297 333 296 297 279 302 310 301 342 292 322 328 283 273 288 304 307 313 307 313 285 317 310 369 297 278 302 311 292 310 330 259 331 328 315 286 314 306 298 310 310 322 307 315 320 300 292 299 286 294 301 303 288 338 319 309 308 297 292 295 286 308 290 297 310 295 330 275 272 307 320 298 286 294 316 282 298 316 302 290 290 301 259 331 295 351 318 317 315 297 302 345 297 298 297 289 297 291 298 285 285 286 306 297 278 299 301 291 268 296 257 288 300 301 270 302 289 296 305 285 297 295 324 320 290 262 297 277 283 286 277 278 275 288 282 321 282 301 273 317 291 309 310 302 294 317 284 318 306 289 335 301 277 273 326 300 276 280 249 275 288 310 307 301 283 269 296 290 302 277 298 240 311 285 286 304 269 258 317 296 294 275 301 303 304 310 311 264 311 296 278 295 311 308 279 299 305 290 271 293 294 281 291 261 308 297 289 263 257 307 264 283 312 282 275 287 256 285 279 297 309 310 261 308 324 280 282 298 269 275 294 284 273 246 303 278 271 285 294 256 271 289 279 300 279 287 292 296 307 283 279 281 263 269 282 272 280 291 295 284 283 263 274 274 276 293 295 270 296 280 275 292 260 278 260 271 277 288 263 303 295 280 277 294 255 294 283 263 261 263 291 263 292 273 290 277 277 258 272 269 290 281 249 300 281 325 259 279 292 286 298 289 263 270 246 278 266 268 257 249 284 259 279 278 265 259 299 297 296 309 248 284 262 285 236 245 274 245 261 269 285 276 266 280 284 301 261 273 265 275 249 244 278 237 275 257 233 287 268 240 269 265 301 266 290 231 264 278 279 264 256 243 288 263 256 242 257 270 232 277 289 278 285 269 287 268 257 250 269 283 248 263 240 277 285 260 241 284 259 305 274 270 277 277 239 267 271 263 249 279 255 238 282 267 222 274 255 276 280 260 228 234 283 261 260 256 275 281 228 236 260 232 259 268 245 235 281 258 302 239 258 231 282 265 242 281 278 237 261 260 234 282 239 261 242 266 276 260 240 275 258 267 242 239 246 267 245 240 274 248 249 244 260 277 247 294 280 263 291 237 258 264 256 260 278 282 255 257 255 255 292 285 274 234 281 270 242 262 269 263 282 259 286 315 261 256 241 267 239 265 266 260 244 274 243 268 260 243 247 256 265 256 246 228 260 258 283 224 269 272 276 275 278 244 232 285 276 265 267 261 263 269 258 303 236 277 247 259 263 278 260 258 267 266 258 262 278 268 242 272 280 243 287 271 235 273 266 246 266 246 261 249 256 224 259 218 261 260 239 302 231 266 231 272 233 259 249 274 242 235 235 259 240 227 262 273 245 248 241 227 216 227 271 264 243 272 262 243 255 239 274 262 233 234 283 242 279 272 258 215 239 238 259 244 248 244 237 248 249 241 260 237 271 231 240 229 242 248 249 265 270 234 214 270 249 280 243 237 244 255 283 244 247 281 266 262 276 245 273 244 270 257 236 239 236 222 272 229 243 244 229 276 233 269 217 243 259 246 238 255 273 256 269 230 274 245 220 217 255 244 284 247 281 271 261 249 250 287 273 265 279 242 297 257 235 260 230 240 229 249 235 263 261 281 256 225 263 256 216 240 266 261 260 258 228 238 248 257 242 249 235 246 246 257 223 241 265 285 232 257 270 263 237 255 282 268 249 245 229 259 258 241 236 224 266 276 266 245 281 261 268 248 241 228 259 257 237 248 272 238 277 276 267 248 247 277 224 272 227 260 239 280 288 235 237 265 244 259 273 241 242 239 244 238 230 242 261 258 257 279 274 260 223 250 241 262 231 231 230 245 266 249 211 248 223 242 264 248 264 265 258 207 257 241 260 242 229 235 277 267 222 240 242 276 238 221 225 249 263 238 238 277 226 256 265 247 235 265 259 260 281 258 266 237 224 241 265 275 238 272 240 248 241 255 263 265 272 245 248 220 244 250 233 222 239 234 264 278 245 257 259 212 232 238 226 224 269 235 232 239 221 244 237 226 273 270 256 248 274 249 219 236 238 226 264 284 260 276 258 261 227 250 223 243 243 243 259 266 246 234 273 239 243 236 240 248 259 225 240 262 230 213 228 211 215 223 249 237 237 277 296 243 235 243 229 286 228 248 271 240 240 237 258 247 262 264 284 270 261 234 261 239 245 237 272 260 250 269 264 258 249 229 247 233 268 236 272 249 248 264 257 233 285 257 261 266 248 264 244 263 275 210 243 263 276 238 233 220 260 266 244 239 237 230 226 241 235 250 268 255 266 261 232 243 273 224 238 232 270 255 272 272 243 277 242 246 228 261 288 268 247 234 233 260 286 234 258 262 233 243 218 245 267 221 276 228 221 258 210 248 210 264 248 283 259 267 212 264 248 238 222 238 295 232 207 234 266 233 229 248 255 230 239 278 245 245 269 228 287 219 256 257 233 235 280 250 244 247 246 215 226 263 249 216 270 287 278 295 230 246 244 223 257 223 263 247 248 237 266 283 262 266 267 273 247 246 293 228 257 237 283 263 256 259 229 275 256 262 249 267 249 261 285 273 245 262 284 282 261 256 263 273 229 265 222 234 271 244 257 284 266 234 223 218 235 225 265 261 228 270 233 256 242 228 226 232 282 261 262 237 249 228 225 214 269 228 227 256 248 271 225 224 262 238 256 247 238 229 203 270 245 244 244 246 224 232 240 239 219 259 283 256 230 216 235 276 220 238 234 256 249 232 247 214 221 250 244 261 235 227 211 259 239 265 228 224 223 245 294 239 239 267 231 250 234 255 227 229 245 281 259 236 267 236 232 275 275 226 259 217 238 219 222 223 237 239 248 230 241 263 246 268 225 258 237 219 248 226 267 261 239 238 240 246 222 230 246 243 261 233 265 238 245 217 235 232 257 230 284 243 260 270 243 246 243 255 216 259 243 246 203 276 229 246 238 263 236 239 245 263 207 214 228 228 246 259 236 249 243 235 233 255 219 247 260 256 272 263 234 243 244 255 246 230 203 245 227 248 235 271 262 241 212 246 244 246 246 245 269 256 230 232 255 242 206 268 262 260 280 239 234 212 261 257 246 214 218 239 260 223 227 258 226 250 224 224 256 222 268 247 248 246 226 241 230 224 261 266 263 232 259 242 249 261 245 234 217 239 243 232 233 257 243 234 238 271 256 229 249 262 241 237 242 258 223 246 261 225 214 232 250 239 246 232 246 241 263 231 217 240 248 269 265 276 249 225 246 208 250 217 238 265 220 220 231 244 243 239 225 256 269 263 232 208 236 232 240 218 261 241 224 238 236 255 245 229 242 243 240 278 229 263 271 268 218 244 238 225 270 226 258 244 221 274 241 246 259 265 249 235 281 261 207 232 216 231 225 261 228 222 242 261 235 265 233 229 248 223 221 236 219 286 240 237 240 263 241 244 234 289 240 239 233 246 222 256 248 257 248 275 215 258 239 230 229 258 225 280 233 256 248 258 289 228 256 244 247 233 244 261 261 257 271 258 234 280 248 244 218 275 261 255 257 212 236 200 239 213 242 228 224 242 243 259 248 278 224 226 247 245 217 274 256 260 239 266 259 232 261 239 246 235 215 259 223 255 256 218 259 231 258 261 244 257 234 228 245 259 262 216 256 259 235 245 257 200 269 230 216 241 271 228 244 229 222 245 269 215 247 241 258 264 259 229 239 242 271 249 269 266 239 284 223 257 239 264 233 258 225 235 244 235 263 241 237 249 227 226 258 267 249 227 246 283 243 257 275 238 240 259 289 260 237 240 261 273 258 261 258 249 245 242 278 225 220 233 231 262 246 236 275 240 233 243 241 255 237 285 231 244 224 243 256 209 245 232 236 243 260 242 273 241 263 280 235 266 256 266 273 259 235 247 231 266 289 237 245 222 222 260 267 234 269 248 262 276 242 270 295 246 275 229 256 233 229 241 276 261 260 228 260 226 265 256 273 240 283 261 262 230 237 273 280 244 277 265 235 269 247 285 259 265 258 300 273 272 257 281 286 295 258 278 239 229 275 239 290 240 258 245 270 298 279 241 230 272 262 274 245 243 242 266 311 281 259 263 263 255 249 258 246 273 287 293 270 261 294 316 272 286 263 277 257 304 294 310 263 279 276 299 325 283 268 293 289 283 261 294 326 298 294 295 285 291 303 300 318 322 308 308 301 347 328 374 347 324 338 370 374 374 386 369 404 410 390 372 428 441 425 428 436 424 440 438 447 393 410 432 376 446 417 415 390 369 400 409 427 396 396 364 357 381 348 347 317 313 310 320 322 292 287 313 317 298 307 264 322 279 290 244 278 275 262 277 262 298 279 299 258 283 271 287 246 279 292 255 291 279 237 268 258 280 276 281 269 283 258 255 257 261 258 259 243 268 283 246 278 246 276 259 279 264 247 279 250 258 246 255 291 221 244 244 241 248 273 261 256 260 271 261 238 263 268 241 246 248 215 236 220 241 267 290 233 243 267 287 271 272 289 259 233 238 261 231 271 227 265 228 264 262 267 279 268 256 271 245 224 257 263 234 247 280 241 264 268 239 248 255 263 239 267 228 234 275 242 235 249 261 274 248 260 239 262 287 227 273 232 256 233 260 244 222 261 262 263 244 258 243 256 225 240 261 259 239 262 222 247 258 234 259 267 238 225 241 232 271 248 227 274 233 232 230 267 248 258 257 243 241 230 220 240 246 237 247 245 241 264 262 241 210 262 268 268 260 241 282 255 262 260 227 278 262 229 261 245 247 280 249 221 227 270 270 261 233 227 230 242 269 255 275 272 243 283 245 258 261 267 237 246 247 255 255 249 237 272 242 232 270 248 263 218 234 226 275 273 246 255 241 235 257 259 241 265 259 218 229 241 247 256 211 249 258 258 218 245 248 238 246 236 227 248 259 217 255 257 231 230 233 258 294 243 218 234 237 266 246 245 243 243 259 256 223 225 265 246 244 236 241 277 256 246 262 235 233 228 257 260 243 274 271 261 241 228 231 255 264 256 226 283 240 238 231 243 239 264 212 244 248 242 230 225 219 274 232 257 246 262 225 274 218 247 234 271 271 257 246 273 244 263 264 238 258 263 249 256 238 232 257 277 236 266 217 248 258 245 245 232 241 228 260 248 236 246 236 229 278 261 246 272 235 237 281 234 263 232 241 263 258 270 225 262 263 258 218 222 265 247 220 229 240 277 237 225 246 289 238 234 247 232 226 258 248 257 222 256 214 242 229 263 206 244 266 209 235 237 255 245 234 260 231 237 263 237 223 271 278 280 234 239 238 237 273 225 246 262 272 243 237 224 228 249 246 225 259 233 242 232 237 247 272 238 236 261 263 246 258 257 239 270 224 256 264 217 266 270 228 242 241 238 264 229 224 241 265 267 271 270 247 230 233 233 282 227 299 228 258 256 233 258 257 229 284 257 258 248 228 218 270 266 259 256 276 239 226 237 211 233 269 233 226 250 224 258 233 211 245 297 266 226 249 225 218 239 287 229 237 276 242 235 242 234 257 229 281 260 275 245 238 229 229 262 231 233 267 219 243 236 226 227 234 240 266 249 227 244 231 245 250 238 221 212 263 233 244 232 246 230 228 237 237 241 255 235 233 262 223 267 240 242 242 255 268 265 243 256 260 216 221 258 269 231 256 257 245 273 243 250 245 244 265 215 240 235 264 240 238 258 248 246 264 244 233 243 217 266 232 246 217 245 216 249 256 245 242 258 231 238 231 269 265 222 233 219 285 214 229 255 240 233 262 244 232 235 257 246 245 234 266 229 248 237 267 240 242 230 245 266 234 209 209 263 257 267 229 244 243 274 265 203 220 255 248 237 260 267 213 229 263 221 263 238 243 262 241 289 238 233 243 267 261 259 232 213 232 262 262 247 244 245 219 219 262 224 224 238 259 215 249 235 238 240 222 235 229 229 237 233 236 247 269 249 245 224 242 246 228 237 222 245 237 281 226 239 224 240 231 239 226 235 269 233 246 268 228 305 271 234 267 246 247 257 230 263 240 239 235 237 202 245 243 266 240 294 232 265 239 265 231 245 227 240 220 225 249 236 286 258 233 220 229 216 240 225 261 242 243 213 231 255 243 242 282 239 262 236 258 263 290 213 236 236 270 242 234 261 262 260 241 273 263 229 257 269 225 248 245 259 274 267 240 226 310 264 225 255 278 235 272 257 233 269 211 249 235 257 267 275 237 216 241 236 228 259 272 234 231 230 249 240 272 248 238 231 270 234 230 275 239 257 257 247 247 238 236 278 229 256 248 247 212 227 258 226 275 262 230 238 236 243 221 271 249 235 248 238 244 227 269 259 229 231 263 258 256 229 257 281 256 261 282 243 228 278 234 234 285 231 225 240 225 284 255 272 238 247 219 270 268 260 237 285 259 280 264 249 246 230 225 239 260 241 224 257 227 241 235 240 236 233 273 273 259 239 260 231 260 244 236 236 216 245 244 266 241 283 234 257 229 257 243 258 209 245 268 217 248 243 216 280 224 245 223 256 234 301 245 259 245 261 236 231 258 246 275 262 224 227 219 273 259 226 230 241 245 240 235 287 257 243 239 280 261 214 233 276 221 286 226 259 276 273 235 257 217 233 238 238 217 228 218 236 217 224 246 261 241 259 256 258 243 271 240 276 238 245 242 240 214 272 256 228 238 242 270 222 273 246 236 270 271 248 248 245 274 255 268 260 241 234 238 243 234 235 262 250 272 259 221 234 249 247 258 268 266 268 267 255 275 249 267 227 225 280 266 237 257 236 287 239 256 272 276 240 255 259 255 256 242 269 266 262 227 260 240 239 228 247 256 277 282 229 223 236 237 240 246 235 247 269 272 226 266 274 296 210 236 239 255 231 246 234 262 238 283 270 264 267 262 257 232 259 244 244 257 268 241 232 248 237 245 250 262 259 269 255 229 293 262 259 229 231 236 261 246 239 239 273 263 244 229 240 272 258 248 240 242 236 268 235 259 228 249 264 228 230 278 235 265 235 246 240 264 249 255 260 237 223 222 266 255 247 245 237 282 241 246 267 234 237 258 268 234 231 248 250 237 263 240 231 263 230 235 263 279 226 261 263 239 237 278 270 231 244 246 268 232 234 217 263 240 279 223 259 256 265 262 271 274 247 247 296 299 268 229 270 242 240 260 241 244 263 271 260 229 236 244 222 271 262 285 261 257 291 256 255 259 261 268 248 260 232 259 243 218 250 255 267 226 237 227 257 249 245 245 227 229 225 234 264 250 258 273 258 256 281 263 263 243 237 268 278 232 223 270 236 268 241 244 245 265 224 237 247 267 238 260 274 244 235 235 267 268 249 255 242 235 263 241 266 257 257 236 262 261 243 244 239 220 276 232 272 259 248 247 273 258 235 244 242 261 248 273 240 239 246 260 226 237 244 260 261 218 263 256 267 260 257 283 234 287 220 263 246 238 271 231 212 237 222 245 260 270 222 234 269 260 226 259 276 240 273 257 274 265 274 272 237 241 261 262 241 256 233 236 238 275 274 265 225 255 224 263 242 305 224 268 266 261 231 258 224 235 277 266 264 242 235 239 263 269 281 265 228 256 248 234 276 267 241 240 262 246 233 222 233 269 270 222 225 262 236 249 250 263 260 243 240 248 239 257 260 239 275 256 247 235 246 264 263 273 256 264 266 227 238 259 259 236 234 234 234 256 239 263 269 230 240 238 267 240 263 231 256 257 278 239 256 259 230 240 260 289 234 248 263 209 245 256 229 269 228 248 230 257 255 277 281 256 266 220 257 286 235 255 263 238 270 271 237 262 264 245 255 248 260 270 235 257 270 272 247 274 273 262 294 277 235 228 286 246 265 258 256 245 243 220 275 288 264 257 261 259 258 270 256 260 260 219 235 239 241 275 246 292 197 236 283 261 239 230 241 279 213 238 263 259 293 238 238 278 259 234 244 248 279 226 265 262 229 244 258 239 255 258 281 277 260 248 255 258 232 260 235 270 281 259 249 266 247 223 256 279 258 266 231 213 282 250 245 260 239 241 243 232 275 247 249 257 281 263 263 262 244 267 268 267 270 277 272 275 261 257 248 267 220 260 238 282 262 245 231 266 270 235 276 249 278 239 245 255 277 261 274 272 268 280 261 259 245 263 259 282 272 264 225 265 248 281 270 238 234 264 242 222 289 262 270 235 259 248 234 262 269 259 267 260 267 270 259 273 247 232 278 261 244 245 228 261 246 275 270 255 283 277 236 241 230 240 241 271 259 267 238 245 246 259 256 256 211 249 273 223 226 249 257 261 243 257 277 267 257 260 294 259 224 246 265 243 279 263 260 238 233 278 267 269 234 273 223 297 274 279 279 278 244 243 229 243 255 273 245 283 273 279 250 237 244 237 215 238 236 245 268 265 272 270 240 264 267 238 227 265 205 285 222 274 242 274 258 247 265 262 245 256 220 247 280 250 260 288 275 249 244 244 246 268 265 277 271 245 243 242 263 280 263 245 239 283 261 275 284 261 241 273 250 259 278 269 248 273 260 275 235 270 291 261 270 274 247 243 264 242 266 220 228 282 261 277 233 284 267 242 258 277 284 242 244 263 247 267 281 255 270 262 268 249 285 239 243 276 247 295 284 256 237 269 276 283 248 266 281 259 281 256 260 264 284 285 277 231 285 259 257 272 264 262 217 293 245 245 248 247 289 236 277 239 258 248 245 240 272 282 244 273 268 249 278 258 278 258 244 262 270 264 266 269 269 225 246 245 259 255 255 272 248 246 280 237 228 261 243 290 312 243 259 249 262 266 265 264 270 262 269 258 271 278 283 273 272 250 289 270 269 246 267 279 226 245 287 266 248 281 275 279 284 247 275 287 304 294 284 299 259 287 293 260 272 284 311 259 281 282 279 273 288 283 278 262 263 256 265 277 289 272 287 280 288 268 288 247 283 276 277 279 258 249 266 282 270 272 292 273 304 266 264 270 275 245 248 261 262 262 263 279 273 266 302 274 279 266 266 263 246 295 264 267 257 275 275 258 309 284 245 281 294 246 286 258 264 288 240 239 276 274 243 299 273 297 270 249 267 259 267 290 277 259 298 270 262 312 276 233 265 275 277 248 264 247 273 239 227 289 259 269 300 263 225 272 284 260 258 270 287 275 281 273 257 235 235 255 238 290 259 243 274 289 266 290 272 264 246 266 267 276 239 259 290 245 241 233 257 264 277 279 279 261 243 303 283 260 235 294 234 271 270 258 268 266 263 225 255 259 278 248 249 257 255 236 271 255 258 267 249 241 245 265 244 256 282 265 267 297 244 257 228 240 260 265 244 255 259 280 269 286 262 264 272 241 290 223 240 257 272 260 246 269 285 223 240 270 273 264 239 246 245 270 238 245 238 270 241 264 265 299 265 272 247 237 273 294 236 225 280 283 277 266 285 267 243 263 244 290 275 222 220 255 273 265 267 264 247 259 247 279 255 241 263 249 274 228 296 279 249 240 270 236 272 284 282 290 281 276 265 255 262 266 283 255 275 235 280 264 240 263 242 282 272 265 257 248 281 263 276 286 262 250 249 268 245 293 266 238 234 274 287 275 261 248 248 268 287 240 255 256 282 245 248 261 284 268 289 276 284 272 226 273 274 265 224 261 265 265 245 266 281 276 248 267 261 249 267 264 259 236 305 287 260 249 276 279 257 258 268 278 262 238 240 269 256 279 292 241 283 236 256 273 294 270 275 260 288 262 278 263 259 271 264 271 276 283 284 218 255 239 289 225 265 247 277 275 272 249 281 284 278 263 300 269 234 267 227 269 276 247 287 272 235 273 238 257 265 272 303 228 258 255 270 262 249 249 232 286 266 273 275 234 238 276 256 276 275 273 269 244 267 267 231 259 268 273 292 264 260 248 256 284 265 264 277 289 249 289 298 276 259 261 264 292 246 264 245 283 297 247 282 286 283 245 273 275 267 246 292 255 286 271 262 273 310 266 273 302 241 256 286 267 239 280 273 260 263 275 275 272 285 269 278 241 278 285 268 234 270 270 287 261 281 281 249 279 265 285 236 278 244 271 279 299 286 261 262 262 279 248 228 290 277 240 271 239 256 293 241 234 286 264 219 261 284 270 221 268 247 243 271 270 236 247 282 265 296 263 255 268 261 255 265 297 256 286 273 264 233 265 269 307 239 242 264 246 267 235 272 259 286 275 255 225 266 246 297 287 303 261 260 234 266 266 270 240 313 271 290 283 278 284 304 256 265 240 270 281 285 266 276 258 275 263 261 268 260 272 249 267 271 264 258 267 280 243 266 267 257 235 266 266 245 278 265 236 276 271 259 297 222 272 306 283 285 278 288 221 281 259 301 273 262 263 262 241 266 292 302 262 247 283 265 278 267 272 299 219 255 263 280 239 268 263 266 258 267 233 297 285 282 271 245 271 263 290 231 223 274 245 268 284 279 303 263 272 257 263 282 247 293 269 303 259 241 249 269 268 269 257 257 279 265 258 247 284 248 271 290 270 276 250 267 275 245 249 280 294 262 273 270 290 296 268 286 295 255 263 229 245 266 282 267 264 281 239 249 277 258 271 248 287 264 287 289 243 274 293 289 258 261 286 276 267 247 240 260 262 295 242 285 255 296 266 275 259 242 238 277 271 299 261 272 261 283 243 273 273 244 267 272 284 287 270 281 249 258 255 263 245 246 239 279 240 280 258 234 269 276 278 297 256 266 270 241 240 259 273 268 264 224 261 237 270 261 257 264 285 237 238 274 260 256 263 287 248 270 259 260 260 262 262 244 278 272 271 240 266 263 248 275 273 282 272 247 245 272 240 248 268 241 275 269 255 227 260 276 266 244 272 249 261 272 270 244 259 268 233 265 268 244 256 257 247 295 245 282 299 260 241 241 238 264 276 256 294 256 262 239 234 255 266 276 255 279 263 235 289 271 277 265 231 275 290 273 294 246 268 280 296 256 271 258 231 248 266 248 261 264 277 236 256 246 249 246 279 282 234 266 260 287 267 243 223 271 264 278 259 247 245 269 245 239 263 271 244 240 265 276 286 266 264 257 289 239 256 257 267 244 264 233 281 293 259 245 270 276 263 258 276 256 284 285 244 273 285 280 285 239 279 258 270 242 293 232 272 241 243 255 275 265 277 264 228 236 282 268 282 248 300 267 261 259 264 289 234 261 270 267 269 264 262 280 278 263 256 261 275 270 279 261 245 259 231 275 261 258 307 272 263 263 214 273 268 288 262 257 269 276 259 271 249 255 278 227 286 259 276 239 243 263 259 264 280 278 248 276 285 241 257 276 236 289 268 264 247 272 255 262 266 258 228 287 274 241 269 267 236 263 242 292 264 246 225 280 294 249 265 281 246 279 236 265 262 293 260 247 246 248 278 238 256 283 278 275 290 237 257 265 249 272 269 282 270 285 292 242 259 236 273 272 261 268 240 281 290 275 269 245 256 238 271 280 272 261 255 263 248 260 244 241 281 281 247 280 292 274 272 268 276 243 292 275 283 276 231 276 242 265 247 235 272 237 243 275 257 265 267 283 233 229 270 239 261 271 262 263 225 284 267 256 265 277 258 269 272 243 266 284 258 258 261 257 256 226 268 268 266 247 256 266 263 261 272 245 276 248 267 286 238 277 264 310 263 287 272 275 242 270 232 222 257 239 241 247 269 242 231 290 244 269 264 250 268 257 260 283 265 240 258 305 305 273 265 289 273 236 256 248 288 228 263 236 270 243 250 223 256 300 282 267 258 255 248 265 241 248 289 262 277 236 273 287 247 245 255 248 258 269 204 286 243 241 249 255 230 268 236 272 232 237 260 236 277 233 255 258 275 249 237 264 261 238 272 236 241 263 265 248 265 283 242 249 261 249 265 257 284 263 265 266 236 271 271 247 244 281 263 260 264 273 270 316 280 268 273 265 297 290 282 263 259 204 259 271 237 281 269 277 279 246 230 235 248 268 276 262 270 278 286 285 264 247 271 267 277 276 249 278 292 272 266 266 271 259 280 277 267 278 281 265 266 247 271 267 246 228 249 250 273 255 256 259 240 268 273 257 245 248 258 296 272 246 279 250 282 261 235 286 276 235 267 243 245 248 228 262 256 249 273 270 264 250 244 246 228 279 243 300 272 265 258 258 295 284 284 291 227 256 270 241 245 264 271 266 294 237 266 289 256 283 272 288 288 264 295 249 264 260 246 279 285 293 255 267 258 246 273 259 259 265 274 278 267 246 259 277 255 295 268 268 259 238 279 233 242 265 260 283 233 230 269 270 262 261 236 264 229 231 245 247 231 259 230 249 294 270 282 275 243 276 269 259 259 250 257 272 233 258 216 283 268 225 240 260 269 279 263 247 269 248 281 262 286 268 247 246 271 248 278 246 257 286 225 295 261 265 242 242 278 268 280 270 268 230 245 295 244 247 272 245 259 233 274 275 270 274 283 264 278 259 266 223 248 250 269 258 296 231 255 285 270 291 257 267 265 239 284 274 238 246 268 300 242 264 203 280 249 258 292 278 278 243 261 273 238 273 260 287 232 258 307 256 265 286 239 263 255 249 284 238 282 273 282 284 275 242 265 281 316 293 264 244 280 238 229 272 274 243 293 285 278 227 264 278 267 240 274 258 261 266 268 249 266 284 226 267 277 268 280 261 245 271 276 262 280 284 265 247 246 261 282 258 266 247 280 287 260 244 258 255 301 269 256 281 279 261 270 269 268 256 246 290 283 235 237 256 234 276 267 288 249 238 278 244 271 230 260 309 263 307 266 291 284 288 272 272 292 280 259 225 267 269 241 256 302 297 267 269 256 295 255 287 267 269 245 255 280 256 246 271 286 267 292 298 244 237 304 283 262 274 299 305 288 262 265 279 301 294 304 272 322 304 311 281 276 296 305 304 261 311 297 282 314 311 289 332 270 270 296 323 282 273 290 290 280 272 288 306 299 282 262 270 242 277 296 286 265 247 269 268 279 318 294 265 282 276 270 294 267 265 277 274 285 308 297 261 268 298 240 290 304 271 261 281 260 277 261 277 260 241 296 269 272 275 269 282 260 267 263 269 266 262 274 237 263 282 258 235 256 275 274 290 249 274 272 243 259 255 273 260 296 238 283 262 246 236 244 241 245 267 259 246 273 273 249 284 270 219 260 240 268 257 265 248 262 236 272 262 265 302 278 270 259 236 265 262 223 266 247 247 289 232 260 241 277 236 248 247 233 285 247 248 265 244 241 261 261 238 268 246 255 258 247 261 262 270 257 246 262 282 255 261 244 265 281 249 265 246 246 267 249 259 283 267 272 237 240 229 239 272 235 233 260 232 257 269 260 241 267 265 245 240 243 261 285 240 256 231 298 284 220 267 207 257 283 210 259 265 255 269 227 223 299 240 239 240 224 260 268 261 264 261 250 241 247 255 299 235 259 262 255 247 222 243 256 275 264 228 255 244 269 265 277 223 242 277 249 271 248 231 230 236 258 272 241 271 282 259 260 207 273 271 269 279 226 287 230 248 228 282 246 244 244 258 247 279 243 244 239 259 256 241 260 229 275 220 261 243 231 239 256 240 256 248 243 271 245 236 283 230 286 246 271 291 240 255 224 245 268 263 229 245 263 241 230 279 236 243 263 272 245 279 260 231 235 269 260 230 264 270 272 268 257 242 264 265 291 236 264 273 255 268 235 278 242 263 297 242 265 261 245 280 236 283 266 265 258 244 278 238 272 268 294 250 273 277 262 279 243 247 274 241 261 261 238 235 261 244 267 260 232 265 246 231 249 241 236 243 256 243 217 288 234 244 257 237 283 261 227 231 258 283 246 277 227 247 219 265 229 256 238 249 260 259 217 238 243 235 249 262 248 232 223 275 261 268 270 229 262 272 277 217 234 232 266 262 267 248 241 282 258 258 241 259 239 241 290 249 247 276 270 244 240 269 248 236 267 243 262 234 260 237 262 266 279 258 248 234 279 285 277 259 260 259 244 234 256 255 218 269 264 237 247 271 268 243 236 207 250 290 259 271 238 234 268 271 274 264 237 298 246 267 236 238 245 240 256 270 237 273 273 276 248 242 248 264 278 245 231 268 257 275 242 263 273 262 239 255 269 248 245 260 262 265 245 241 258 237 264 270 256 267 262 249 242 240 262 260 271 260 229 244 278 260 245 231 244 246 260 272 256 260 262 259 271 269 275 248 265 248 257 261 233 241 285 211 255 260 261 228 258 249 243 245 264 238 244 267 271 257 276 234 234 243 256 284 239 242 247 244 246 222 228 249 260 247 265 242 259 247 247 262 249 236 241 283 235 255 234 243 275 229 239 258 230 265 235 256 270 235 264 265 256 233 226 245 260 285 258 273 236 245 279 271 219 247 270 262 240 269 245 242 246 246 260 269 247 266 245 273 229 271 285 273 229 274 275 255 259 243 243 234 224 275 264 270 261 246 244 226 239 238 291 272 268 247 269 226 230 273 281 262 257 266 259 243 236 246 279 255 276 233 255 263 235 258 232 248 234 243 245 229 246 263 263 260 235 272 239 231 234 290 234 266 245 229 262 225 240 245 245 260 275 258 239 248 262 277 259 289 286 268 242 275 243 232 249 231 256 256 236 224 239 263 266 248 239 260 235 257 263 279 247 243 274 242 248 243 261 232 268 259 274 271 275 232 245 250 258 241 238 280 259 257 248 266 218 246 249 229 257 238 249 241 240 274 241 265 243 244 281 249 259 240 240 243 235 273 263 259 249 242 262 290 278 299 258 269 274 259 222 225 228 226 246 199 242 297 238 270 278 234 264 239 265 247 226 223 218 262 257 263 246 247 240 234 245 265 234 274 247 240 263 293 271 260 240 244 264 236 258 243 268 242 247 250 264 242 295 263 247 247 233 247 264 282 270 238 268 238 262 273 268 241 255 263 276 262 234 265 262 238 279 275 250 234 237 242 241 264 265 229 264 226 270 247 237 264 237 280 264 262 265 290 263 259 322 279 256 230 262 264 235 240 282 262 249 235 255 260 271 231 236 226 243 275 257 279 284 222 276 275 265 269 267 235 231 255 263 226 242 264 265 233 262 238 280 238 255 267 241 241 242 275 240 244 261 260 259 261 266 292 239 259 294 233 283 238 275 249 240 240 258 248 259 239 242 284 240 244 259 270 268 259 249 268 274 277 249 266 265 242 268 227 229 248 238 247 255 263 280 243 297 268 262 281 249 234 247 246 255 246 287 227 242 249 230 261 249 269 265 255 239 270 239 237 235 238 231 260 234 246 264 268 257 272 248 267 266 242 246 258 260 285 259 248 245 264 269 258 262 266 256 222 303 274 225 256 279 295 242 247 245 276 286 270 266 235 234 281 232 243 265 272 229 297 275 248 242 260 222 255 274 257 262 246 229 217 258 248 228 242 255 270 222 265 264 232 269 243 244 246 261 275 234 257 256 290 272 243 246 262 245 245 256 235 266 263 279 269 242 283 271 263 246 247 279 243 276 243 277 267 243 258 265 266 281 218 259 270 266 261 240 262 238 247 233 275 263 281 277 233 288 250 268 259 261 270 249 266 258 269 258 292 262 236 263 268 292 263 228 265 265 266 240 247 264 248 262 267 249 285 289 265 273 256 224 232 222 267 267 255 245 286 281 259 276 268 228 298 256 287 257 261 255 282 272 302 225 237 263 236 269 242 218 255 266 237 234 268 242 258 267 263 272 256 249 281 219 249 246 265 277 221 238 243 239 241 263 272 241 269 267 261 273 281 228 269 233 265 273 279 258 265 256 274 256 288 229 274 243 286 279 244 225 222 257 245 276 255 267 228 239 255 249 214 269 276 243 261 265 271 260 267 228 247 281 247 259 261 255 271 238 277 266 257 264 274 257 264 239 261 262 242 246 233 270 276 236 257 259 296 256 244 229 282 239 275 261 234 248 289 262 261 267 230 266 264 273 249 260 257 256 268 265 279 267 259 270 237 248 260 261 229 249 258 219 309 273 272 272 273 278 255 242 272 262 255 260 267 266 258 267 247 283 272 243 264 207 261 256 245 227 237 228 231 284 218 257 263 256 263 241 256 263 249 262 268 239 255 244 249 261 260 262 249 257 239 210 275 247 247 258 260 298 246 268 219 239 265 271 256 266 235 265 269 262 244 255 265 318 259 245 259 243 249 262 244 242 248 228 229 227 234 262 263 237 273 268 269 263 267 271 275 262 258 236 221 246 280 238 233 265 276 249 241 285 235 260 272 240 238 234 250 247 273 250 263 246 268 247 271 260 262 264 272 260 256 244 274 261 268 245 263 246 229 267 241 261 276 243 278 286 229 232 264 267 291 267 258 271 231 280 238 278 266 272 272 235 277 262 257 242 243 279 276 258 280 246 262 271 278 260 249 247 247 273 249 264 265 231 242 238 275 261 261 238 245 247 272 276 285 279 291 221 273 272 265 269 236 269 235 278 243 248 221 231 237 269 255 261 245 259 257 240 268 255 274 231 236 236 286 226 259 258 260 226 247 275 264 255 267 276 237 244 299 236 271 256 292 286 261 232 241 245 275 262 262 279 232 237 266 242 241 236 260 243 280 262 282 260 278 274 277 271 237 265 260 248 215 229 239 296 256 248 258 245 250 261 276 293 296 257 279 268 233 272 261 271 249 248 279 279 236 246 244 278 259 275 282 256 267 246 284 279 243 234 267 290 260 271 272 274 277 258 246 241 298 239 269 228 279 225 241 271 272 257 260 269 265 243 232 283 273 279 287 271 289 291 265 272 239 279 274 242 282 268 289 261 281 262 276 249 273 245 286 280 271 274 257 268 242 297 236 277 267 268 274 246 248 285 272 286 292 261 275 249 247 270 239 274 258 300 245 274 272 236 260 234 279 258 279 267 281 262 267 246 276 245 295 237 234 267 231 242 236 248 260 291 263 238 247 276 294 264 235 240 238 285 278 267 239 248 275 249 245 233 260 273 277 232 244 260 240 269 266 240 269 273 285 257 259 262 242 262 292 282 279 276 234 267 297 287 255 223 277 257 243 269 226 270 274 262 269 287 262 241 258 246 267 249 256 272 260 247 231 259 216 282 244 256 234 257 273 266 238 236 280 257 238 247 259 243 265 268 248 232 260 250 267 258 266 259 268 244 225 236 271 233 258 247 261 241 274 247 246 271 257 262 264 265 265 238 278 261 279 256 241 260 272 269 245 249 274 263 248 260 257 261 259 279 266 202 230 264 270 263 267 289 286 264 295 268 240 248 261 259 289 279 277 258 271 283 263 281 269 269 296 263 293 245 227 300 277 247 256 280 302 240 248 260 248 260 268 261 272 262 255 247 274 262 241 238 241 272 270 243 287 217 281 246 221 240 267 269 240 242 274 232 234 285 291 255 247 245 262 245 269 236 280 278 268 260 242 272 238 269 285 249 240 236 266 261 222 256 285 270 286 236 275 274 268 260 293 237 282 275 241 224 233 300 236 292 290 241 243 245 236 258 276 257 247 277 263 262 304 273 258 260 203 229 288 268 262 271 266 268 261 280 266 259 272 263 280 274 243 237 257 236 261 273 264 272 243 276 263 263 264 269 263 243 258 256 281 281 259 255 260 265 226 256 245 269 268 263 298 264 273 266 263 242 280 260 233 255 266 255 289 284 276 290 237 225 265 282 258 286 228 269 275 260 285 241 257 264 287 245 265 256 239 290 268 262 267 257 262 247 276 248 284 280 281 238 263 248 269 235 260 257 273 246 239 240 263 272 245 255 292 275 265 226 230 274 263 268 284 231 272 247 281 220 290 275 248 248 230 273 266 273 270 259 260 255 234 268 274 256 267 275 261 227 274 268 266 278 242 266 237 276 210 245 239 277 234 259 272 243 273 274 263 297 279 273 273 259 266 239 268 262 268 269 231 258 260 239 231 248 247 257 263 240 285 282 233 278 283 262 273 268 244 275 242 258 275 241 263 265 238 255 231 257 262 238 243 263 258 218 258 236 283 242 259 239 270 247 219 225 287 264 279 279 273 290 269 234 248 246 265 273 262 268 265 263 268 278 227 255 255 239 265 267 269 248 272 262 267 231 260 257 235 260 249 227 259 258 234 256 245 287 270 262 281 272 245 234 263 271 283 246 261 299 255 246 246 267 280 289 263 208 271 241 260 244 265 249 227 274 229 216 225 262 260 285 224 249 259 233 273 275 240 285 232 248 250 264 215 285 255 264 257 259 257 233 224 240 267 232 262 265 235 231 261 213 294 240 210 241 209 264 239 269 255 269 269 258 268 262 255 216 245 256 267 256 279 246 249 259 257 243 248 259 259 266 249 257 242 277 239 263 218 255 241 233 219 267 229 243 261 232 275 227 261 262 247 267 281 269 244 244 272 235 268 261 260 248 233 238 233 230 243 271 235 218 248 259 258 250 231 223 249 262 274 285 250 271 275 226 244 238 263 265 243 231 257 278 241 261 232 236 271 265 248 245 256 227 255 240 240 268 262 266 276 233 244 263 245 225 266 266 269 238 242 246 257 273 261 260 257 279 269 258 263 272 249 257 282 249 267 245 263 250 243 237 283 257 234 248 226 243 264 249 234 267 256 273 269 260 260 245 247 249 263 276 242 284 260 280 269 257 258 244 272 267 265 265 267 240 243 257 269 262 249 255 277 282 232 221 238 245 268 217 244 266 262 226 248 299 265 259 255 262 255 266 290 243 243 272 285 282 273 262 237 261 243 246 233 257 249 274 262 278 248 225 243 258 261 256 245 243 258 241 267 255 255 243 295 256 271 258 257 267 249 289 257 246 279 284 256 289 247 263 291 246 241 244 257 270 237 281 227 287 308 263 260 247 282 305 226 255 245 266 258 239 236 286 263 283 239 264 235 245 255 262 286 273 284 260 256 272 244 261 268 265 294 243 244 248 270 267 244 287 249 270 269 264 261 263 258 289 272 267 239 281 237 268 279 232 230 262 264 256 250 263 256 244 265 279 242 304 286 235 272 263 289 264 257 248 255 263 256 287 261 264 278 234 257 268 269 258 258 280 219 273 275 289 277 244 259 274 274 262 296 266 259 279 240 261 255 247 244 270 259 270 270 281 247 263 266 291 244 232 257 228 258 207 240 266 255 248 266 218 249 276 236 264 281 265 271 285 243 233 275 261 257 242 247 282 291 280 248 264 262 257 231 269 286 271 244 235 246 256 261 290 268 261 247 283 261 232 290 247 293 225 267 259 246 262 239 227 277 279 262 249 258 239 268 274 267 274 228 262 250 261 270 247 277 277 282 267 268 243 242 283 220 260 221 259 281 245 248 289 286 267 281 256 281 288 263 271 247 287 288 295 246 293 240 233 233 247 258 255 285 234 289 267 272 275 275 277 262 238 278 295 261 263 280 246 242 273 290 275 265 258 257 259 266 232 249 284 241 264 296 279 271 227 241 290 236 245 249 226 267 259 256 272 238 238 273 262 279 265 248 246 266 269 238 243 238 280 248 270 233 242 276 267 275 274 243 278 262 273 261 259 278 245 277 248 243 280 256 277 248 282 257 266 216 281 245 257 268 242 302 260 240 247 259 283 268 244 263 294 277 240 272 274 244 295 266 301 283 282 247 258 272 272 269 285 246 220 263 242 266 248 272 279 234 248 275 250 242 263 281 276 270 248 238 269 244 249 256 274 264 262 274 242 270 267 249 280 234 287 287 269 260 224 283 290 239 235 260 217 260 283 263 276 235 257 235 248 257 242 280 235 258 283 282 266 235 262 238 259 261 281 238 271 266 255 246 308 237 233 267 262 258 283 277 222 245 274 247 270 274 242 242 273 275 269 230 268 256 264 266 259 300 242 259 289 223 232 248 255 255 267 262 255 258 246 256 257 265 249 271 267 244 259 257 268 295 222 241 276 255 263 289 269 296 274 215 272 276 245 276 229 218 279 263 243 305 246 266 273 282 242 276 258 265 265 230 244 234 264 260 258 241 263 242 291 276 280 273 268 268 256 238 290 244 280 298 226 277 247 266 287 264 273 239 248 256 296 256 278 289 256 255 256 258 285 264 249 238 283 273 258 225 281 267 274 277 258 297 265 278 265 243 247 282 255 270 239 274 228 301 272 270 243 293 258 257 282 270 224 222 278 270 245 229 293 249 273 249 243 256 276 263 263 264 240 257 283 277 264 240 268 270 239 237 308 247 264 283 247 244 257 239 294 245 250 272 283 271 275 249 260 274 245 248 263 257 241 274 262 274 281 240 261 229 263 258 264 297 249 293 238 239 240 280 289 291 276 272 261 263 255 257 264 275 270 234 229 276 268 256 286 256 265 266 272 263 241 278 238 275 265 297 265 274 279 256 289 245 280 247 270 248 268 264 289 239 245 277 281 279 278 261 276 273 239 274 278 270 278 256 237 257 281 266 275 273 262 287 264 257 259 266 271 263 240 257 269 265 293 292 274 263 257 279 263 242 261 293 269 230 257 287 225 281 269 246 275 265 271 248 267 259 240 265 276 263 273 246 283 275 269 275 278 259 264 259 261 260 291 240 246 265 255 257 228 271 260 271 260 255 273 269 288 231 275 267 277 271 255 247 248 276 283 288 289 246 265 280 270 266 290 272 265 269 279 236 273 262 288 294 273 263 279 298 281 267 265 256 283 265 266 286 277 265 285 260 290 289 272 229 287 287 275 263 256 302 244 276 276 275 273 255 279 272 281 273 280 287 286 297 279 286 289 275 267 287 298 299 269 258 284 257 275 296 279 285 276 303 276 283 291 257 278 276 282 303 264 282 246 274 294 256 257 287 293 261 275 249 262 273 281 235 277 244 279 260 307 284 313 299 277 287 284 280 257 295 281 309 290 264 275 237 263 266 257 283 264 270 241 267 269 266 279 241 278 270 242 277 282 270 264 262 269 219 301 266 279 294 280 290 295 290 280 272 276 280 255 275 276 237 288 299 270 263 264 295 283 222 268 287 245 267 275 268 277 234 234 260 277 317 305 274 268 263 306 262 257 238 258 284 260 275 281 243 255 255 267 269 271 277 247 295 286 265 264 278 255 245 260 264 276 273 273 258 262 261 259 273 284 262 268 248 239 261 272 272 266 244 279 285 258 255 280 281 289 275 222 281 255 289 251 259 286 242 230 284 260 284 255 261 273 258 281 249 272 266 237 231 272 232 278 265 281 250 282 274 294 258 265 292 268 260 307 267 273 269 258 280 276 277 250 242 267 258 265 263 256 259 263 267 247 273 302 282 280 291 260 280 259 267 283 250 264 261 274 279 256 237 246 263 267 243 289 279 273 234 266 289 287 272 268 272 291 273 273 239 277 258 269 258 287 270 291 271 255 268 260 264 278 312 272 243 238 265 285 261 262 242 274 266 263 282 258 277 296 264 256 246 273 271 260 292 271 263 227 258 289 273 281 273 244 249 267 257 255 264 234 268 262 267 271 268 277 232 277 250 256 241 243 300 279 256 283 276 276 291 261 259 259 282 256 287 300 271 283 274 281 268 229 263 261 268 268 265 239 285 289 276 244 272 266 279 283 275 241 239 271 270 265 296 267 243 273 278 278 266 282 261 289 258 249 285 269 241 221 256 248 257 255 256 244 225 240 262 240 269 266 262 260 294 273 248 225 258 277 250 280 261 231 260 261 276 267 245 257 245 297 259 277 276 274 241 261 279 259 282 268 247 275 267 259 270 274 280 262 269 282 286 274 269 247 297 268 234 283 266 276 290 266 248 249 268 277 298 263 255 277 229 260 257 239 265 271 268 231 226 239 262 281 272 246 288 273 241 248 264 307 285 270 259 288 269 266 256 270 305 248 250 303 281 274 263 292 264 289 276 279 247 229 261 266 283 258 257 267 277 238 267 291 264 231 272 274 280 255 260 260 262 270 225 273 247 293 270 248 288 249 290 259 265 278 279 300 265 283 265 273 276 266 259 271 278 259 289 264 284 264 261 248 244 299 276 300 236 270 249 249 232 259 275 288 243 274 261 223 242 244 262 243 270 244 293 249 303 270 248 229 291 274 274 214 246 287 261 276 248 271 273 235 263 249 248 247 247 278 264 268 245 268 270 257 291 246 265 273 230 262 236 299 265 271 285 263 248 259 290 278 270 275 237 268 267 257 247 289 262 276 281 246 249 241 264 291 268 259 217 277 265 270 238 237 260 270 232 233 249 281 269 220 262 231 267 297 241 243 269 231 221 283 271 230 271 248 234 296 266 292 281 261 271 262 262 237 286 272 256 292 266 267 301 287 272 288 248 234 266 266 255 286 271 256 258 275 268 274 257 235 257 255 263 255 285 286 260 283 274 293 250 286 224 269 257 282 281 244 277 268 267 238 266 259 264 292 246 264 269 241 234 296 271 245 270 292 278 242 266 267 247 268 282 264 268 285 241 244 239 224 260 244 266 237 274 247 273 305 238 300 273 258 257 274 280 261 280 259 265 263 237 268 270 281 275 230 273 274 261 260 256 221 286 260 275 279 240 244 291 234 255 279 261 257 266 279 283 299 270 244 287 275 235 267 272 265 279 255 283 282 261 257 267 256 261 274 284 264 256 262 280 280 228 271 240 266 268 231 266 238 261 242 262 285 257 275 247 275 228 251 285 270 230 232 283 273 264 278 241 245 263 297 219 246 256 271 267 282 279 265 284 271 273 268 266 273 270 248 284 257 295 268 240 267 304 264 276 248 256 257 236 248 287 258 223 242 246 273 293 259 249 275 260 271 288 308 237 285 238 286 278 305 262 292 300 281 273 292 260 287 282 259 267 284 259 256 290 284 269 236 267 271 248 275 292 261 268 277 259 292 263 264 261 268 256 235 245 244 271 281 284 262 256 268 245 258 255 263 291 288 290 247 258 239 248 267 270 272 298 278 258 244 263 256 306 264 237 271 272 259 234 271 265 258 260 271 257 265 283 288 326 242 294 289 257 266 291 275 278 238 238 257 249 274 289 261 267 294 270 269 267 265 260 262 286 293 273 270 271 276 269 238 257 269 269 270 264 256 259 265 279 277 255 257 268 297 264 236 294 279 244 271 291 292 261 263 281 286 268 255 245 260 273 267 235 283 270 261 274 268 248 288 268 263 260 256 275 271 262 271 282 294 276 237 276 256 268 255 275 262 258 255 229 268 232 268 275 261 260 270 256 283 246 267 246 274 266 278 258 258 249 222 310 287 256 282 282 276 244 271 268 281 271 278 277 275 275 265 273 266 262 267 274 246 242 270 249 245 286 267 281 280 301 255 272 293 288 274 256 282 262 260 239 262 280 273 234 286 263 274 232 266 273 244 245 272 247 250 275 265 290 247 233 275 273 256 243 243 256 289 283 303 294 258 260 278 288 275 270 238 250 290 256 273 291 295 281 310 272 270 240 275 247 260 264 286 262 261 274 298 271 273 278 291 267 290 247 270 245 279 287 279 270 262 276 235 248 275 255 278 283 301 288 273 262 256 262 278 274 264 291 280 279 247 302 299 270 273 295 258 257 280 262 301 241 247 274 269 270 274 257 273 275 297 277 264 309 268 260 274 280 269 284 278 260 279 271 260 301 243 265 278 280 242 276 269 273 274 310 281 262 258 263 270 284 273 274 284 262 271 248 249 300 298 291 268 274 276 270 284 260 299 274 256 274 279 273 307 266 247 272 279 243 278 234 260 244 280 258 276 278 284 283 248 297 259 260 276 238 280 282 286 256 281 292 280 283 267 280 272 288 259 249 271 311 278 269 239 285 271 281 274 258 278 260 299 270 267 274 263 261 295 274 263 267 272 278 248 280 297 280 277 294 274 281 293 293 265 275 279 246 236 259 302 231 269 266 276 292 279 274 281 265 289 284 268 281 273 274 261 246 261 255 244 295 284 291 248 285 245 301 289 258 284 270 255 281 284 266 266 287 279 245 279 303 284 285 285 314 279 273 269 301 268 286 276 271 291 271 258 255</counts>
			</dataPoints>
		</scan>
	</xrdMeasurement>
</xrdMeasurements>