File: data/XRD/XG-Sauerstoff/XG-875/W6823-1B_XG_Sauerstoff_875.xrdml
<xrdMeasurements xmlns="http://www.xrdml.com/XRDMeasurement/2.1" xmlns:xsi="http://www.w3.org/2001/XMLSchema-instance" xsi:schemaLocation="http://www.xrdml.com/XRDMeasurement/2.1 http://www.xrdml.com/XRDMeasurement/2.1/XRDMeasurement.xsd" status="Completed">
	<comment>
		<entry>Configuration=Factory configuration, Owner=User-1, Creation date=7/8/2013 4:01:53 PM</entry>
		<entry>Goniometer=PW3050/65 (Theta/2Theta); Minimum step size 2Theta:0.0001; Minimum step size Omega:0.0001</entry>
		<entry>Sample stage=MRD Cradle; Minimum step size Phi:0.01; Minimum step size Chi:0.01; Minimum step size X:0.01; Minimum step size Y:0.01; Minimum step size Z:0.001</entry>
		<entry>Diffractometer system=XPERT-PRO</entry>
		<entry>Measurement program=C:\PANalytical\Data Collector\Programs\Jorrit\2thom\_absolute_2th-om_10-130deg_PIXscan_56min.xrdmp, Identifier={15BCCF57-2807-42BD-B5B9-ECC0B3DC9284}</entry>
		<entry>Batch program=C:\PANalytical\Data Collector\Programs\SimonL\batch4x_2thom_10-130°_z9.1_x0,10,20,30_y0_57min.xrdmp, Identifier={EED9823A-2BEB-424C-9252-345C4EF2834A}</entry>
	</comment>
	<sample type="To be analyzed">
		<id></id>
		<name></name>
		<preparedBy></preparedBy>
	</sample>
	<xrdMeasurement measurementType="Scan" status="Completed" sampleMode="Reflection">
		<comment>
			<entry>_absolute_2th-om_10-130deg_PIXscan_56min</entry>
			<entry>PHD Lower Level = 4.83 (keV), PHD Upper Level = 11.27 (keV)</entry>
		</comment>
		<usedWavelength intended="K-Alpha 1">
			<kAlpha1 unit="Angstrom">1.5405980</kAlpha1>
			<kAlpha2 unit="Angstrom">1.5444260</kAlpha2>
			<kBeta unit="Angstrom">1.3922500</kBeta>
			<ratioKAlpha2KAlpha1>0.5000</ratioKAlpha2KAlpha1>
		</usedWavelength>
		<incidentBeamPath>
			<radius unit="mm">320.00</radius>
			<xRayTube id="1010048" name="Empyrean Cu LFF HR (9430 033 7310x) DK442154">
				<tension unit="kV">40.0</tension>
				<current unit="mA">40.0</current>
				<anodeMaterial>Cu</anodeMaterial>
				<focus type="Line">
					<length unit="mm">12.0</length>
					<width unit="mm">0.4</width>
					<takeOffAngle unit="deg">4.2</takeOffAngle>
				</focus>
			</xRayTube>
			<xRayMirror id="27010001" name="Inc. Beam Cu W/Si (parabolic MRD)" hybrid="false">
				<crystal type="Graded" shape="Parabolic">W/Si</crystal>
				<acceptanceAngle unit="deg">0.800</acceptanceAngle>
				<length unit="mm">60.0</length>
			</xRayMirror>
			<sollerSlit id="21010002" name="Soller slits 0.04 rad.">
				<opening unit="rad">0.0400</opening>
			</sollerSlit>
			<mask id="22030008" name="Fixed mask 4 mm">
				<distanceToSample unit="mm">220.00</distanceToSample>
				<width unit="mm">4.00</width>
			</mask>
			<divergenceSlit id="22010007" name="Fixed slit 1/8°" xsi:type="fixedDivergenceSlitType">
				<distanceToSample unit="mm">220.00</distanceToSample>
				<height unit="mm">0.19</height>
			</divergenceSlit>
		</incidentBeamPath>
		<diffractedBeamPath>
			<radius unit="mm">320.00</radius>
			<sollerSlit id="21010002" name="Soller slits 0.04 rad.">
				<opening unit="rad">0.0400</opening>
			</sollerSlit>
			<receivingSlit id="22010001" name="Fixed slit 4°">
				<height unit="mm">5.88</height>
			</receivingSlit>
			<detector id="7010017" name="PIXcel3D 1x1 detector" xsi:type="areaDetectorType">
				<phd unit="%">
					<lowerLevel>30.0</lowerLevel>
					<upperLevel>70.0</upperLevel>
				</phd>
				<mode>Scanning</mode>
				<activeChannelsEquatorial>255</activeChannelsEquatorial>
				<activeChannelsAxial>255</activeChannelsAxial>
				<pitchEquatorial unit="mm">0.05500</pitchEquatorial>
				<pitchAxial unit="mm">0.05500</pitchAxial>
				<readOutPeriod unit="seconds">0.135</readOutPeriod>
			</detector>
		</diffractedBeamPath>
		<scan appendNumber="0" mode="Continuous" scanAxis="2Theta-Omega" status="Completed">
			<header>
				<startTimeStamp>2024-10-02T16:41:50+02:00</startTimeStamp>
				<endTimeStamp>2024-10-02T17:37:55+02:00</endTimeStamp>
				<author>
					<name>PRO-MRD</name>
				</author>
				<source>
					<applicationSoftware version="6.1b">Data Collector</applicationSoftware>
					<instrumentControlSoftware version="7.0E 20130304">XPERT-PRO</instrumentControlSoftware>
					<instrumentID>0000000011142674</instrumentID>
				</source>
			</header>
			<dataPoints>
				<positions axis="2Theta" unit="deg">
					<startPosition>9.99826193</startPosition>
					<endPosition>129.99755682</endPosition>
				</positions>
				<positions axis="Omega" unit="deg">
					<startPosition>4.99913096</startPosition>
					<endPosition>64.99877841</endPosition>
				</positions>
				<positions axis="Phi" unit="deg">
					<commonPosition>0.00</commonPosition>
				</positions>
				<positions axis="Chi" unit="deg">
					<commonPosition>0.00</commonPosition>
				</positions>
				<positions axis="X" unit="mm">
					<commonPosition>20.00</commonPosition>
				</positions>
				<positions axis="Y" unit="mm">
					<commonPosition>0.00</commonPosition>
				</positions>
				<positions axis="Z" unit="mm">
					<commonPosition>9.100</commonPosition>
				</positions>
				<commonCountingTime unit="seconds">32.895</commonCountingTime>
				<counts 396 403 355 408 393 387 405 381 377 407 419 407 446 394 447 415 382 385 367 377 406 394 414 379 400 412 372 418 381 398 413 402 438 394 423 402 399 358 397 395 446 393 396 436 384 361 412 425 393 411 360 412 444 401 379 404 366 384 410 401 377 362 394 394 421 370 388 366 358 375 373 361 375 386 390 388 388 346 435 376 392 384 368 388 376 415 391 374 394 359 395 383 397 406 368 358 354 397 424 386 355 380 352 397 370 372 378 354 371 403 407 384 380 390 362 381 362 361 396 380 384 374 386 384 402 400 377 375 395 379 380 394 399 373 357 369 390 333 357 385 391 380 371 326 396 374 411 349 353 386 357 368 398 353 358 329 362 361 366 402 366 398 398 383 324 376 343 376 352 342 370 348 366 338 384 382 348 359 342 381 354 366 410 349 359 334 356 358 327 369 353 343 335 339 386 359 355 372 347 388 407 385 404 410 391 368 358 375 345 334 356 315 311 360 371 375 399 365 339 348 340 352 360 368 381 341 355 398 359 375 312 362 368 371 310 364 336 350 385 343 366 353 340 377 349 363 372 356 364 350 374 364 352 341 321 338 346 370 318 329 360 374 338 349 313 373 338 347 349 351 329 324 350 369 351 374 347 337 352 342 357 323 334 361 347 345 357 346 343 367 328 365 338 352 367 357 317 345 342 354 322 350 335 343 343 308 326 338 335 371 323 332 344 301 338 355 338 371 357 324 345 351 338 336 371 347 317 336 337 333 324 342 349 365 353 293 354 308 321 333 363 305 324 338 366 353 339 336 324 320 322 314 316 316 326 352 334 330 307 335 324 357 311 283 316 364 346 335 344 350 305 320 378 339 337 299 363 290 327 315 287 343 312 333 353 359 330 349 324 324 309 305 341 326 294 313 302 326 324 311 343 288 319 316 291 305 326 336 337 303 301 314 297 322 338 314 312 329 328 346 320 330 285 335 355 304 319 303 306 318 362 334 322 318 317 279 326 325 305 318 300 301 347 321 293 312 293 318 317 305 314 306 310 338 304 323 312 332 285 318 332 309 325 283 308 281 319 312 333 335 323 312 305 344 281 323 287 311 295 317 325 327 276 324 323 320 303 321 280 315 283 328 300 269 290 313 295 316 309 293 310 307 313 298 318 307 342 338 284 319 274 314 315 315 310 314 303 310 304 301 321 293 329 330 319 342 308 309 314 326 302 283 295 297 318 274 299 315 284 288 262 285 300 312 308 301 295 305 310 300 303 282 313 317 316 271 264 305 317 308 286 273 298 299 308 283 322 282 320 298 264 314 290 298 304 319 273 288 310 305 279 303 300 346 300 334 304 305 293 278 310 295 271 302 292 326 280 276 309 270 335 272 283 300 274 300 286 299 282 323 309 315 304 317 314 287 334 273 287 302 260 309 292 287 294 268 268 273 268 287 307 337 266 293 283 288 283 266 304 287 308 287 273 281 296 300 332 248 312 314 295 326 311 292 322 305 295 275 263 297 289 284 316 324 278 280 290 304 299 309 304 293 273 295 284 269 241 272 302 284 299 278 265 301 281 286 279 301 297 273 299 299 272 299 292 301 304 301 283 300 288 283 291 298 283 269 314 287 290 298 302 306 271 274 290 303 316 287 277 294 268 299 276 296 269 304 289 294 262 276 307 312 267 308 305 309 312 282 271 260 276 302 306 300 275 282 278 282 304 276 291 265 294 270 281 313 277 272 282 306 300 285 278 277 278 274 274 294 290 279 258 294 249 295 289 279 271 306 273 291 307 271 263 282 291 293 300 282 287 271 273 269 282 281 270 310 249 284 256 294 273 258 284 283 280 308 295 266 274 289 262 241 273 294 281 296 266 283 277 280 268 267 260 259 304 262 299 277 289 263 280 283 295 274 282 290 262 294 285 296 289 248 272 295 280 289 283 256 263 273 296 267 284 278 290 246 271 266 267 308 278 268 274 293 278 297 273 300 285 327 245 269 260 270 277 314 309 305 261 267 280 288 293 255 263 266 276 246 280 263 274 270 291 299 288 303 306 283 286 287 277 295 261 316 292 276 298 275 288 270 268 291 274 262 278 287 275 276 255 280 255 276 291 280 279 276 291 295 280 242 300 261 271 272 301 272 298 307 272 287 261 267 269 264 263 293 289 284 256 279 290 276 268 283 296 241 269 225 260 286 281 312 280 264 264 296 283 260 271 262 287 290 259 280 243 305 296 293 293 301 274 286 276 261 265 240 270 289 247 268 278 284 281 276 288 296 247 274 269 278 244 279 249 287 281 259 273 256 255 265 268 236 286 281 268 242 258 299 284 289 279 294 262 274 264 244 256 256 306 283 301 265 281 291 258 296 283 272 230 272 286 239 289 284 263 264 246 276 228 277 274 287 302 267 269 290 275 289 281 285 248 275 261 246 315 281 262 269 265 257 265 274 257 281 298 238 242 261 290 273 245 269 256 277 260 301 262 301 238 238 263 296 289 285 263 296 271 288 281 283 284 264 258 273 256 264 281 263 265 243 233 284 293 286 274 294 263 260 272 277 263 274 259 275 280 266 249 262 266 267 272 259 296 272 264 258 277 248 281 264 255 282 247 287 261 245 280 241 287 292 270 272 293 285 255 238 257 297 264 314 263 278 287 248 257 278 267 245 244 261 281 303 264 288 263 302 265 280 260 284 279 258 243 272 258 237 258 259 241 275 269 281 233 261 261 266 284 291 259 309 289 264 257 283 235 299 257 255 274 284 273 264 262 247 273 258 240 293 271 299 293 275 302 278 271 257 262 286 258 276 236 295 277 279 291 283 250 272 298 260 262 261 276 275 299 258 269 258 271 261 286 288 256 278 307 283 249 313 276 250 268 266 292 271 273 245 273 301 268 287 273 273 245 240 234 277 281 290 283 262 269 295 285 249 306 287 262 284 248 272 245 261 274 260 281 246 274 243 248 298 286 267 300 294 271 287 294 293 276 311 244 270 273 278 270 282 280 304 297 249 291 289 275 259 300 286 246 299 270 267 287 294 277 256 295 277 278 291 276 255 296 245 291 294 292 291 269 285 287 290 286 262 259 248 302 281 257 327 265 300 264 287 319 262 277 247 274 280 285 268 309 314 278 294 279 288 264 276 302 287 296 313 301 298 279 273 287 264 288 269 268 272 296 297 310 307 284 295 306 281 295 288 273 269 315 305 319 290 277 289 296 308 311 301 315 296 314 297 293 264 335 264 300 300 283 309 304 308 309 293 299 307 311 289 282 334 306 341 303 294 314 276 308 344 287 304 292 284 295 282 296 333 294 273 275 274 304 306 311 294 322 289 309 294 279 267 274 278 275 304 296 298 293 315 291 293 288 260 300 321 295 280 295 322 298 302 288 332 331 310 300 340 298 274 318 321 295 305 314 297 317 305 307 290 305 274 312 305 289 305 308 296 298 277 270 301 307 279 298 285 274 292 287 282 289 304 285 324 330 280 299 290 288 296 302 269 311 305 330 305 307 331 264 291 298 311 276 310 262 280 289 329 290 266 304 317 300 265 289 308 330 304 299 296 287 289 300 292 311 295 295 291 292 301 319 265 283 304 279 310 292 298 264 282 287 276 328 280 321 268 285 286 302 288 283 309 271 281 282 290 287 296 297 284 317 276 299 290 278 270 290 313 286 283 282 293 280 325 299 302 300 293 299 294 302 274 304 286 293 272 293 293 288 237 302 285 291 332 280 292 320 296 302 291 279 280 314 294 287 287 269 269 289 295 286 283 297 298 276 322 284 280 286 281 288 331 294 279 287 301 290 301 309 297 293 307 277 332 284 246 261 279 289 303 282 275 280 274 316 276 320 277 274 249 281 289 297 293 323 282 278 305 296 289 303 288 297 329 299 304 280 314 261 275 302 283 284 311 273 309 305 311 290 265 275 309 285 298 318 294 320 266 306 290 313 284 315 289 302 283 272 290 293 321 268 261 279 279 323 279 297 310 242 270 291 295 293 289 295 302 307 271 282 295 282 293 279 308 267 290 303 293 290 298 286 274 278 305 312 284 301 298 299 277 297 281 291 274 290 266 267 301 298 290 288 272 279 243 291 294 291 303 273 315 244 273 304 289 272 288 277 303 275 277 295 310 291 287 275 265 306 269 283 303 263 306 279 286 300 282 270 290 283 305 267 267 270 267 272 279 289 294 282 282 297 278 286 289 276 264 262 295 283 265 278 291 277 232 293 297 247 277 288 295 281 269 301 290 262 297 281 275 275 281 273 288 269 293 296 294 267 285 264 287 260 287 293 291 317 274 270 274 297 281 274 275 267 243 281 294 268 296 295 266 307 286 251 268 289 261 261 287 297 306 287 263 269 280 268 263 283 250 277 320 247 275 266 261 249 289 282 292 283 275 301 279 288 255 301 289 248 264 266 228 269 287 279 288 288 292 289 288 258 264 257 262 275 262 291 293 262 286 289 241 269 301 234 267 268 277 331 315 295 261 301 283 274 302 273 276 280 299 282 236 279 285 275 299 280 238 259 269 255 339 271 236 285 276 244 287 260 286 274 282 288 273 289 262 261 263 284 275 262 272 298 278 273 288 265 289 282 321 286 286 294 271 301 281 276 266 284 231 299 301 257 318 292 261 291 259 266 262 289 305 272 258 288 288 278 298 269 269 300 294 292 284 256 262 310 270 277 271 325 298 327 275 290 285 300 290 307 240 320 295 274 257 276 271 273 262 241 235 292 269 286 303 265 287 285 275 273 316 262 289 279 274 267 282 280 305 240 276 258 275 248 273 287 297 307 293 279 291 282 286 242 285 294 294 261 292 279 275 248 302 303 273 293 274 246 273 281 305 300 234 269 272 284 260 245 270 298 279 266 280 280 290 297 269 320 249 249 259 274 279 301 288 281 313 279 271 260 263 279 277 266 297 267 267 270 291 293 273 281 278 269 310 289 277 244 290 269 296 279 277 312 301 318 282 279 276 296 258 278 272 276 267 248 297 270 273 233 300 271 312 269 285 264 307 296 292 276 311 280 281 280 249 278 295 292 280 287 275 308 291 268 294 299 308 297 272 246 309 279 286 296 275 249 284 293 271 311 281 279 284 279 295 269 244 275 257 298 290 277 299 264 276 289 267 273 292 269 295 287 290 273 239 292 290 270 259 259 263 279 272 279 287 229 275 295 259 298 263 302 285 263 275 296 312 314 283 272 291 271 245 267 286 279 300 283 284 287 281 280 268 291 304 290 275 266 230 305 264 298 258 288 265 247 290 275 263 274 258 257 269 274 290 293 288 273 284 262 264 296 272 291 266 276 305 277 275 278 249 278 287 274 295 291 295 279 277 277 256 319 272 282 274 294 264 286 276 296 294 268 261 273 296 295 277 270 293 276 291 267 287 303 267 278 299 263 285 290 299 262 304 273 298 249 286 288 274 270 268 307 270 284 259 279 279 285 247 275 283 282 270 248 278 291 249 278 280 274 268 265 258 309 284 318 263 286 283 247 265 286 292 289 292 262 240 292 294 306 264 296 293 265 289 297 293 273 278 270 303 285 244 281 279 268 297 268 266 268 299 265 269 272 283 259 261 275 258 270 275 283 282 281 248 319 272 298 280 250 278 297 294 279 279 290 272 289 312 313 288 311 333 294 318 290 290 285 296 326 314 319 326 293 259 282 301 282 288 255 272 302 288 273 290 290 289 285 293 282 281 273 288 296 281 320 278 275 262 293 298 284 299 274 293 295 305 280 270 270 287 293 309 278 309 262 263 301 288 307 291 292 304 272 298 293 270 248 294 280 287 301 269 278 301 302 292 310 285 282 299 271 304 261 279 292 297 301 277 324 283 272 322 272 299 314 268 270 288 267 304 293 291 297 287 244 324 301 303 287 321 287 278 304 296 298 291 277 305 310 280 328 318 285 275 271 293 305 344 276 299 285 287 306 305 263 261 318 295 282 300 305 288 309 282 268 264 287 265 273 291 292 296 310 274 300 284 273 298 302 285 302 301 300 248 293 306 317 305 268 319 294 274 306 278 270 284 298 306 309 277 286 313 250 278 287 300 260 280 294 317 300 296 290 273 300 293 283 294 301 276 276 280 272 299 238 270 289 318 302 287 302 271 300 286 244 295 277 290 267 281 244 290 292 270 286 305 284 328 282 279 289 268 291 292 303 269 318 308 301 314 290 257 295 281 283 277 269 264 240 303 283 270 308 271 274 292 289 290 305 236 290 305 272 321 281 306 272 287 302 290 280 309 281 257 300 265 281 280 292 260 274 276 291 305 277 292 332 285 312 285 334 304 309 311 279 297 301 295 279 260 283 319 318 243 302 297 278 283 299 316 257 283 315 270 296 291 294 264 290 295 271 267 287 291 265 255 276 263 298 274 282 298 280 291 269 289 280 297 304 299 269 314 302 289 277 304 279 304 267 307 270 282 258 289 273 268 286 301 289 279 288 291 278 297 321 313 300 295 278 303 309 308 299 275 321 310 286 281 326 268 306 262 303 284 270 288 277 305 307 291 276 288 259 301 287 308 285 289 294 293 309 273 293 322 286 284 290 296 283 291 274 297 273 247 290 313 284 309 302 289 300 285 300 323 275 277 290 286 295 264 335 290 309 306 318 292 303 298 270 287 282 297 300 289 272 284 275 277 267 276 294 297 316 260 314 291 269 321 317 288 273 314 277 272 295 301 277 279 318 304 281 285 268 311 337 311 307 261 275 298 300 272 298 307 292 323 320 311 303 315 315 290 330 291 283 307 302 286 282 278 287 295 312 265 347 299 291 272 307 319 292 276 284 293 320 285 298 297 325 284 314 281 318 285 322 293 303 289 329 316 308 326 283 297 292 336 307 313 331 273 310 323 308 278 307 328 306 306 301 301 311 311 283 323 294 282 281 286 288 313 306 315 310 268 300 313 298 321 314 321 304 315 297 260 305 318 329 329 319 326 290 268 306 323 310 290 299 305 308 321 286 301 299 308 274 288 305 282 322 289 296 324 312 295 329 320 294 331 320 300 306 301 324 312 344 287 261 284 296 279 318 297 294 308 305 300 326 285 326 287 306 341 309 303 337 325 329 333 321 286 281 331 307 316 296 318 317 301 248 316 302 311 306 303 291 299 278 288 292 309 318 318 308 341 291 278 332 279 285 305 300 287 307 276 292 309 287 283 292 280 278 293 316 309 287 305 332 302 306 316 304 309 300 301 344 293 326 317 318 297 317 326 302 282 271 289 267 305 292 310 311 301 288 306 317 330 272 288 327 314 296 290 315 283 290 320 284 278 336 288 302 332 303 291 271 307 314 283 307 280 304 314 297 299 291 283 310 302 323 343 306 295 316 313 327 301 306 296 308 288 293 301 306 306 312 300 300 337 325 288 322 299 315 315 311 286 272 339 306 346 289 293 307 293 312 298 313 304 330 291 322 276 312 299 337 341 309 296 334 321 298 286 329 298 299 335 304 327 313 318 296 312 314 295 316 301 321 304 318 296 313 273 272 332 305 298 293 348 310 315 286 342 354 311 269 286 323 335 349 281 274 311 307 315 288 328 316 322 306 328 295 300 310 302 300 338 323 312 321 355 289 315 343 286 287 308 312 336 317 323 304 316 322 307 317 291 334 325 362 320 328 291 328 331 312 307 332 302 321 319 348 341 337 312 323 289 306 328 309 320 350 332 321 307 350 319 332 318 295 335 361 350 320 339 326 309 330 355 309 354 327 320 324 329 332 303 346 300 327 348 310 314 364 343 341 353 383 360 330 357 341 330 372 367 358 331 334 357 361 354 328 340 360 310 384 357 375 382 343 361 367 383 347 382 389 361 362 390 368 331 374 395 364 382 389 397 398 406 391 414 428 425 451 486 436 421 408 430 442 494 470 444 440 508 502 537 513 518 511 543 553 605 574 577 588 577 588 559 574 581 600 505 544 556 536 523 497 500 471 513 483 490 446 455 433 440 430 415 434 457 425 375 378 381 391 395 369 368 388 380 374 373 346 353 370 399 357 363 335 380 336 347 334 336 357 357 321 333 341 349 340 350 325 351 309 337 324 300 368 342 344 305 323 297 306 349 313 310 298 315 341 328 304 338 300 340 310 334 327 320 338 321 324 330 308 312 335 318 311 326 315 343 311 282 315 335 304 327 313 302 314 311 319 309 382 344 306 347 308 296 286 319 319 319 330 293 368 347 298 320 319 307 312 302 321 341 323 314 306 297 304 296 326 323 334 322 305 321 298 322 320 325 293 310 298 320 313 318 331 297 299 331 310 317 309 310 341 316 330 307 317 335 286 330 311 310 326 289 323 332 326 325 335 323 318 330 285 301 310 325 361 323 322 355 290 323 342 312 306 288 341 301 333 347 314 366 354 343 286 329 310 331 307 342 305 307 318 337 318 317 300 316 320 311 305 337 334 306 322 315 335 347 321 333 306 324 336 329 314 296 298 315 308 313 339 324 367 335 305 349 323 331 356 345 352 336 336 324 342 316 299 319 308 301 313 328 315 299 298 302 320 339 334 317 331 330 357 336 320 346 311 300 308 308 341 348 337 309 308 307 308 313 327 328 359 342 325 331 331 302 298 321 310 308 338 341 359 300 330 322 314 340 358 320 332 317 313 323 307 306 325 329 317 339 300 310 320 342 298 336 329 310 320 323 281 301 300 305 344 302 331 348 339 332 301 327 307 327 372 308 329 310 328 335 333 314 299 307 308 303 328 351 304 326 315 328 316 342 315 337 317 313 318 307 353 343 348 309 338 287 325 268 334 315 286 311 299 344 329 295 311 331 333 310 297 348 338 349 301 342 340 323 319 323 332 311 308 315 304 313 312 322 306 336 347 350 354 327 289 288 318 316 349 305 318 332 327 335 338 321 317 293 335 347 343 321 327 303 315 328 310 345 312 332 321 382 307 332 325 342 340 290 296 353 279 324 340 340 338 320 316 317 314 340 329 323 340 346 331 360 291 343 330 342 341 329 327 299 344 314 321 327 336 320 341 308 342 333 279 308 312 331 336 307 295 317 331 318 307 337 345 303 293 308 319 321 303 329 313 335 328 312 324 299 300 328 308 323 324 336 334 312 323 321 294 312 342 286 373 318 321 322 320 310 318 344 291 342 325 327 330 295 332 316 343 316 322 323 310 334 323 298 321 310 317 345 320 334 295 296 320 337 336 368 334 314 346 309 344 344 349 300 325 340 320 321 344 306 358 309 283 341 340 350 310 305 284 322 302 333 315 305 319 321 341 329 332 296 349 296 318 310 317 345 279 319 283 330 318 336 345 325 339 343 334 340 320 321 323 314 318 335 353 304 346 314 326 346 341 309 320 345 328 301 304 309 333 343 319 325 322 296 313 325 340 319 319 349 372 311 336 312 316 308 319 322 352 297 332 323 349 322 359 324 303 315 306 320 309 317 330 325 319 311 331 315 333 336 293 327 328 321 317 348 340 336 349 333 310 291 317 347 328 343 312 340 303 315 342 331 312 331 329 333 320 335 306 309 330 317 326 309 342 333 325 317 344 332 330 357 307 329 316 323 318 328 363 351 335 339 316 323 308 326 313 322 345 315 319 326 316 316 344 362 305 292 293 299 325 307 356 358 346 323 305 326 326 351 339 323 329 318 343 327 338 308 316 316 350 306 299 337 326 286 357 337 336 360 335 338 295 335 320 308 330 345 315 327 307 328 328 352 335 349 303 338 349 342 340 314 355 315 321 321 318 330 308 308 280 324 327 307 318 338 322 326 344 361 300 346 315 318 311 330 308 348 337 313 333 329 306 293 336 330 373 354 327 341 334 331 318 327 327 319 340 316 316 354 356 344 329 341 318 338 325 355 333 329 338 366 311 334 300 337 380 350 342 348 317 312 313 341 325 353 349 317 322 327 337 338 336 315 290 327 332 333 326 345 346 374 321 318 335 334 313 328 340 349 344 322 301 351 294 335 343 321 316 356 357 332 321 308 287 360 343 353 369 338 331 304 322 331 329 328 323 344 344 333 347 305 366 323 311 333 328 333 346 351 336 326 315 331 354 339 315 327 335 329 358 334 329 311 325 361 320 336 357 335 317 352 330 307 322 305 345 309 333 315 334 332 327 344 336 309 340 349 357 314 327 347 319 348 368 287 329 341 296 315 323 298 334 332 319 304 303 340 333 315 320 359 324 320 380 324 349 329 355 337 352 326 345 311 345 335 301 341 355 333 321 340 341 321 311 321 290 336 343 347 358 352 322 341 349 341 343 308 332 316 331 303 347 321 349 335 338 336 291 320 336 330 341 312 328 337 309 301 335 327 334 339 333 338 335 308 325 333 308 307 307 339 349 343 336 333 336 312 364 337 345 343 323 331 338 321 320 351 316 328 319 318 316 348 338 350 326 364 323 352 313 345 356 344 327 315 381 322 358 323 336 353 334 301 338 291 310 329 311 330 298 337 326 348 319 323 314 304 336 332 328 341 311 362 351 322 327 310 331 338 336 351 335 358 334 333 326 350 318 331 297 331 332 341 316 361 328 333 331 315 348 340 329 335 333 348 311 328 306 364 319 338 324 327 317 336 296 318 288 335 344 331 311 310 299 377 314 299 344 316 318 308 352 345 329 353 335 332 354 393 357 364 341 328 321 353 335 317 316 340 306 343 332 334 343 359 324 325 316 348 306 321 340 331 322 321 302 371 356 357 347 333 334 316 360 326 344 334 340 330 327 332 373 299 347 333 371 355 365 312 308 305 324 329 331 327 331 363 326 339 355 341 313 350 353 337 347 361 369 326 357 348 316 365 367 331 336 323 363 337 339 322 339 372 363 312 333 342 343 322 329 343 350 346 325 341 342 343 338 326 323 332 354 337 330 372 320 324 358 333 340 320 357 334 366 335 306 326 315 357 361 320 353 313 322 320 325 311 370 364 341 348 353 375 333 369 348 338 365 330 333 352 342 337 371 314 325 317 341 333 336 347 369 341 369 328 304 334 346 339 344 353 364 331 340 363 346 337 334 350 333 352 357 319 322 339 358 344 356 311 356 325 345 350 363 339 364 309 348 363 327 345 342 324 337 361 321 352 337 358 328 335 317 345 334 360 354 345 336 344 328 324 360 329 332 361 359 356 305 336 339 329 364 339 347 324 369 334 348 336 368 352 345 381 369 351 309 336 361 339 336 371 336 355 386 367 329 338 349 331 341 343 366 315 351 361 348 338 325 353 383 337 356 356 337 316 357 369 349 289 337 347 320 365 339 363 339 320 345 369 327 367 378 369 362 332 370 399 345 368 333 340 387 326 330 361 360 346 332 347 366 371 327 347 357 334 332 325 359 313 372 354 330 357 345 373 347 332 331 359 357 365 336 363 342 344 328 345 321 352 338 323 374 328 371 335 374 383 330 343 354 376 313 352 358 350 353 340 339 353 360 338 353 321 336 310 340 328 345 336 373 353 353 357 393 354 358 358 346 360 365 360 360 340 343 359 343 335 354 383 334 352 332 362 349 366 357 363 317 347 365 371 351 364 387 383 365 332 374 312 356 344 363 413 316 348 375 382 339 356 337 396 347 340 387 315 340 327 327 351 357 368 341 340 334 346 359 358 355 360 317 347 367 321 372 337 359 371 337 358 337 361 344 345 324 358 368 350 359 348 380 348 343 374 322 354 383 366 374 340 341 331 358 330 341 344 399 358 332 330 390 362 354 334 393 369 363 355 369 365 346 328 359 358 382 332 326 346 362 378 351 358 348 349 385 351 363 336 385 330 374 362 356 379 369 322 353 374 355 387 345 353 346 379 344 326 357 369 374 366 380 345 346 327 326 356 374 391 395 365 365 322 298 349 329 332 337 362 329 340 394 364 345 332 360 358 355 373 398 344 323 355 363 354 364 380 354 333 330 328 347 367 342 350 338 332 416 369 338 357 364 384 370 373 345 358 386 344 359 341 339 346 344 356 380 373 317 350 364 365 357 348 341 348 334 340 334 331 351 337 363 368 361 367 359 350 324 366 318 319 362 342 337 315 326 383 355 387 338 344 364 374 350 392 339 371 333 368 353 335 351 341 335 381 348 372 373 363 385 390 351 375 341 368 360 347 354 352 366 359 383 346 399 357 360 367 356 353 347 357 323 365 346 352 358 392 375 369 373 356 309 357 317 373 349 322 367 338 349 332 341 373 369 406 346 365 351 342 323 352 363 342 369 346 378 381 344 349 362 360 350 344 361 354 323 335 351 345 356 341 341 378 354 334 364 333 339 332 373 355 337 381 384 347 332 377 358 350 364 356 361 370 340 383 373 347 343 399 354 357 339 352 340 374 381 345 321 356 384 363 343 358 353 360 361 393 358 365 344 356 334 364 368 344 355 405 339 349 376 339 353 332 379 362 346 351 325 344 355 345 348 338 339 390 375 347 337 377 342 350 354 383 365 356 394 391 387 376 369 354 353 394 371 358 353 377 372 373 384 354 343 344 373 352 385 370 345 353 357 381 390 345 394 410 399 377 392 390 376 347 348 337 360 373 328 378 404 366 389 351 381 357 372 348 362 408 353 370 386 374 380 360 365 365 389 358 359 362 403 370 395 360 387 370 377 358 384 353 352 403 393 370 383 389 369 391 348 389 402 356 403 367 398 394 382 370 407 398 342 380 395 376 352 362 382 341 382 378 400 362 348 393 375 412 376 380 400 362 385 390 412 359 399 384 417 398 369 358 394 358 349 371 343 384 400 356 354 351 397 319 346 356 345 382 369 349 429 354 378 380 346 380 338 387 350 363 365 353 370 358 385 375 345 356 369 392 385 382 358 409 389 385 369 344 337 348 398 372 366 365 363 363 355 343 370 378 349 338 362 362 361 361 368 349 358 366 376 343 376 370 395 370 355 371 348 358 348 356 308 314 359 370 366 363 333 344 351 362 379 364 363 404 373 372 346 366 357 352 335 366 363 377 374 382 346 379 380 359 350 376 330 373 366 363 380 349 370 342 357 336 391 356 350 382 353 374 376 364 367 370 355 376 395 378 343 359 351 345 376 362 368 364 383 348 371 353 341 381 372 371 370 342 358 355 357 343 354 389 360 348 330 355 367 339 350 332 359 387 336 343 396 389 342 337 348 368 383 372 324 373 378 326 399 361 356 339 385 355 394 362 376 327 369 376 352 326 372 348 395 340 364 349 359 362 348 368 353 352 382 369 381 355 359 344 347 357 365 366 343 360 353 373 369 346 365 388 378 374 394 369 367 355 395 380 356 354 350 373 375 351 344 338 361 367 329 365 377 369 341 373 362 370 352 363 337 371 385 351 374 358 375 379 370 391 401 367 368 359 352 367 367 353 353 381 375 406 371 377 388 392 347 372 366 364 394 379 369 362 359 330 334 376 401 380 338 385 371 389 386 347 370 354 358 349 354 364 361 367 346 368 368 381 343 361 370 345 374 380 371 372 369 370 332 347 353 346 333 345 373 382 384 390 364 370 385 384 331 370 370 371 365 334 339 395 378 368 373 370 409 351 368 359 367 382 341 367 374 339 393 336 354 352 345 353 376 372 389 356 398 346 386 374 383 362 378 323 371 357 369 348 387 379 362 371 351 346 373 386 356 362 332 328 367 362 388 328 365 333 376 373 354 375 338 347 367 352 354 357 386 345 351 367 376 308 307 402 386 348 347 365 373 373 334 331 340 355 355 340 346 389 365 388 334 371 352 354 332 359 371 358 375 381 353 384 359 365 343 377 364 318 358 357 388 334 366 368 364 333 392 366 393 367 346 361 340 362 342 383 389 357 371 343 382 361 343 402 365 367 360 382 345 377 377 322 381 383 368 370 373 385 335 384 364 341 357 364 390 348 339 343 327 353 374 342 345 363 354 388 373 333 382 373 367 336 318 341 344 384 362 363 349 327 342 392 374 353 343 360 380 370 371 338 361 368 374 361 384 344 338 346 359 372 338 369 346 388 387 367 380 402 354 378 389 386 366 389 333 357 390 371 355 333 346 359 360 365 348 364 345 384 369 399 365 372 381 367 363 369 370 350 390 352 378 353 364 368 355 339 370 341 354 368 401 374 355 358 355 383 381 339 325 345 353 415 376 362 386 370 369 349 357 365 392 351 357 371 350 372 346 365 327 398 369 346 395 353 365 358 325 352 360 331 358 366 353 343 329 365 414 359 347 405 372 351 354 359 346 370 397 374 366 334 356 351 385 361 389 378 365 424 371 383 381 360 372 359 345 384 358 382 378 380 363 313 356 364 378 352 384 342 364 408 376 363 358 364 361 387 332 370 354 383 352 344 375 330 315 353 401 382 398 350 374 347 354 389 354 359 363 375 369 385 389 354 370 374 347 378 355 331 358 328 365 356 342 404 396 362 405 356 374 348 384 383 326 378 325 367 382 331 371 330 356 382 365 345 362 336 408 381 385 372 362 371 382 322 347 353 378 360 359 347 405 360 348 357 394 386 337 382 385 333 381 376 400 382 344 347 360 374 381 374 380 365 337 377 385 390 387 348 334 360 384 400 369 345 370 353 344 333 364 356 381 407 380 358 380 412 359 346 336 390 364 392 355 336 359 346 377 345 345 358 379 351 365 371 366 353 378 350 366 347 347 401 347 342 351 409 356 344 337 357 365 377 366 363 365 395 369 391 374 422 370 361 356 378 357 390 326 345 385 365 363 381 386 375 375 361 354 374 339 338 370 356 359 386 342 353 387 363 345 382 389 349 324 346 385 366 373 395 380 363 374 380 364 368 378 367 355 368 370 352 346 360 336 364 358 372 367 335 355 379 332 362 367 380 382 303 346 352 366 365 339 375 365 342 366 381 369 365 347 359 355 365 400 388 302 375 309 332 359 418 386 386 360 337 403 334 333 334 388 359 374 374 359 359 376 360 370 390 347 362 403 362 342 347 371 342 330 362 351 355 336 350 365 360 371 351 358 353 366 352 348 357 382 386 375 377 354 358 364 380 362 382 361 342 364 360 345 360 376 379 342 346 359 352 316 322 346 345 339 350 337 363 338 360 340 357 349 368 344 355 362 390 348 373 416 326 360 362 354 351 328 358 347 327 351 331 366 364 373 362 367 326 365 341 353 363 392 360 383 360 346 368 327 347 367 381 389 341 363 361 381 366 353 347 368 377 329 364 351 341 331 352 364 378 367 355 362 360 348 337 354 368 359 357 384 361 338 391 372 336 385 397 344 354 359 359 359 380 353 339 371 335 359 338 353 376 388 358 329 383 362 385 354 351 375 361 390 380 399 326 405 368 370 357 374 370 396 365 356 382 381 365 366 369 352 351 360 387 353 369 340 379 333 353 410 379 388 327 326 327 403 352 383 383 363 351 393 357 356 357 337 368 376 367 332 360 379 348 379 367 376 372 367 366 367 398 372 366 315 345 352 356 343 372 354 335 338 366 371 376 364 352 371 395 361 386 325 359 355 347 362 355 345 322 376 387 343 360 361 333 365 349 352 365 374 370 378 364 392 348 368 355 367 348 337 361 329 322 350 381 358 372 355 339 366 378 366 377 357 363 361 428 383 333 405 359 345 355 349 351 377 375 351 364 397 364 352 358 358 377 387 385 363 372 350 350 344 360 363 349 380 363 389 364 345 355 395 405 376 374 360 355 346 358 371 364 357 351 387 322 372 372 373 370 360 350 356 361 348 362 400 368 325 412 355 346 352 345 362 352 358 357 353 348 329 370 347 320 361 353 369 334 352 334 335 354 346 372 372 381 389 362 360 347 353 362 373 392 357 342 361 343 366 349 319 361 365 343 328 365 349 374 340 364 352 377 407 358 345 367 365 360 392 367 371 363 366 379 362 363 355 394 365 354 344 344 400 345 352 355 374 364 388 355 336 355 383 365 359 378 371 329 325 375 343 377 403 391 370 359 353 345 366 354 355 379 368 380 358 338 338 380 375 382 373 386 385 345 387 358 333 352 378 332 367 343 367 383 376 370 358 373 364 359 339 408 366 371 357 383 362 395 383 350 360 330 346 403 349 333 329 395 351 335 335 387 353 366 372 393 371 376 366 299 366 368 381 365 332 373 362 350 355 358 332 381 343 358 335 361 334 358 365 350 378 344 339 362 354 369 368 373 356 362 359 385 366 360 350 364 334 382 347 375 365 362 356 392 375 380 354 327 338 339 341 340 355 358 364 395 368 361 368 351 351 354 342 362 364 379 358 351 356 374 364 334 350 369 369 343 370 354 354 342 346 376 382 373 351 355 385 385 359 346 355 371 357 351 352 373 357 378 344 364 330 400 375 354 353 345 359 361 374 380 332 354 380 365 343 381 388 366 375 363 388 331 360 345 361 341 399 358 383 358 380 355 337 358 373 370 339 371 358 363 391 353 392 363 393 377 366 372 367 348 369 365 344 368 390 385 387 348 359 394 363 395 356 361 371 362 355 365 322 371 342 355 374 369 374 352 344 378 404 377 391 341 367 376 386 398 344 354 369 376 389 378 347 365 372 369 376 370 371 387 372 352 373 381 386 392 359 378 367 364 380 388 380 384 392 376 361 382 369 413 367 370 408 376 382 370 367 378 407 428 393 382 402 405 348 380 370 398 422 388 420 400 406 423 383 427 396 384 416 377 407 403 379 414 398 395 393 397 412 391 419 420 415 418 397 410 424 381 390 401 431 405 389 406 415 397 372 375 454 380 382 402 405 360 416 379 387 378 386 404 397 355 345 391 385 371 385 384 378 385 376 369 343 406 393 361 380 342 359 312 372 364 368 384 368 353 341 374 354 372 372 356 313 370 390 351 386 335 347 385 350 385 347 346 339 374 364 312 365 356 370 325 366 354 362 345 366 368 355 337 366 363 362 355 353 350 329 362 364 351 346 320 349 329 339 380 369 344 350 378 379 346 350 357 340 359 361 365 355 355 358 389 363 337 353 331 352 365 360 391 387 368 363 349 387 372 315 323 348 343 344 357 325 367 383 357 347 346 338 373 353 369 353 348 321 368 324 354 313 350 362 367 375 356 371 310 349 380 326 350 372 335 350 371 361 315 356 364 326 366 362 386 357 332 362 352 326 332 347 330 342 343 340 352 376 334 347 350 367 362 335 340 334 377 325 346 322 318 366 358 349 359 351 364 367 319 336 364 312 347 332 316 309 329 348 343 364 340 339 333 346 333 331 380 355 336 328 342 334 330 338 355 332 359 370 367 333 349 353 343 375 364 353 344 339 366 331 339 334 326 328 341 376 333 324 332 325 370 375 339 381 377 365 370 319 340 314 345 321 321 313 331 323 358 329 333 351 359 339 347 300 366 336 354 342 369 349 332 364 355 360 347 350 335 361 357 336 359 343 354 385 357 320 333 411 341 336 357 349 330 315 338 360 355 316 350 331 332 348 346 336 337 336 372 366 340 378 359 334 362 347 347 336 342 357 359 327 336 338 371 334 334 304 346 359 365 355 350 337 367 329 347 325 333 337 352 341 330 370 352 357 322 338 308 351 368 341 392 341 369 366 352 348 338 313 335 340 370 350 336 371 325 327 359 341 375 359 368 356 346 373 316 328 344 346 341 363 313 363 366 332 362 347 366 335 349 336 359 356 320 323 371 352 328 336 309 341 328 344 336 334 346 331 328 364 345 348 351 337 367 339 334 335 316 331 339 329 359 327 326 347 314 381 354 348 374 296 356 328 347 323 364 338 319 323 372 364 350 332 318 356 361 318 336 343 326 315 313 336 351 325 353 368 329 345 351 328 349 337 332 349 321 340 328 348 365 331 340 366 318 338 344 324 345 317 348 363 353 348 343 324 327 347 345 353 359 360 316 375 316 320 346 354 332 350 331 328 373 359 344 334 334 355 347 331 335 310 339 374 349 364 313 359 327 359 311 325 364 353 353 312 349 349 350 338 306 310 323 349 320 341 350 313 341 334 362 370 345 322 333 329 334 363 317 340 341 354 308 361 362 356 337 357 336 356 357 338 336 339 330 345 332 327 340 346 323 360 349 331 352 326 320 340 288 350 345 355 342 324 334 332 329 323 337 330 346 351 352 313 348 378 313 344 321 348 342 343 326 341 360 312 359 336 304 327 346 331 345 326 338 322 313 364 338 368 346 339 313 304 307 307 334 317 337 334 350 312 311 370 363 338 337 318 366 383 346 359 342 320 325 326 299 332 331 329 349 333 321 343 376 314 332 329 326 322 339 331 325 343 357 363 355 303 357 365 320 372 360 354 317 329 364 311 351 335 351 352 312 354 356 318 319 361 348 327 315 349 343 326 367 375 315 337 333 342 362 336 329 324 333 332 333 349 339 356 328 324 339 333 324 318 350 361 333 328 316 334 326 318 317 353 321 381 344 339 352 366 348 342 319 342 324 312 344 337 311 352 348 358 372 347 310 337 320 304 343 323 335 341 325 338 317 305 336 373 320 344 344 309 324 326 290 327 317 328 330 345 359 347 335 314 308 350 328 310 330 349 335 327 318 352 314 311 305 333 342 344 348 333 356 309 347 331 341 342 320 298 314 311 344 336 337 343 298 322 319 366 328 295 352 340 358 341 325 367 333 330 348 321 338 319 345 375 359 306 347 386 342 344 336 347 405 339 341 306 313 339 349 316 322 350 313 347 328 346 319 324 339 367 365 339 345 335 332 349 352 313 335 320 359 335 357 337 347 354 326 339 350 331 332 323 321 310 347 343 338 327 331 320 295 308 331 338 351 344 335 359 325 315 326 361 299 347 341 330 313 318 325 341 347 313 343 331 346 341 339 323 320 351 308 337 301 333 352 328 345 324 368 337 340 326 349 329 330 359 325 334 344 337 334 333 347 329 307 355 344 349 330 301 344 322 339 340 341 348 336 340 337 316 339 319 330 320 305 326 345 342 340 332 314 308 342 341 345 322 316 339 339 352 335 346 320 351 358 338 331 341 330 332 340 342 353 341 349 311 351 319 345 341 350 324 343 350 350 298 323 321 319 334 328 334 320 322 303 342 324 299 328 316 338 306 340 319 326 322 351 330 342 318 301 309 319 317 290 309 326 357 319 332 321 315 330 319 303 352 332 311 345 333 345 335 335 324 330 337 331 324 335 318 297 310 336 303 326 310 340 315 321 340 350 343 319 324 360 352 309 335 345 341 315 310 342 332 312 367 328 335 325 336 332 335 319 331 366 329 335 330 334 314 303 338 325 324 343 303 330 340 343 333 327 349 340 323 306 332 317 319 343 306 338 350 319 329 326 366 336 293 330 314 294 310 332 323 333 363 368 344 335 331 345 331 376 330 338 310 338 363 328 358 332 337 331 309 300 350 346 339 364 348 331 338 330 308 361 341 352 306 327 318 308 332 323 353 357 324 310 299 353 330 350 328 320 339 317 370 316 301 310 336 333 359 357 322 316 358 306 349 323 349 351 335 328 317 304 338 316 339 347 328 335 336 331 323 351 308 309 322 346 327 331 312 332 332 318 330 333 353 326 340 307 317 348 292 328 295 306 324 323 326 347 306 296 337 317 330 328 324 322 346 321 314 307 313 357 349 342 322 345 360 327 296 317 341 325 309 309 328 308 351 302 306 307 336 299 326 345 317 377 342 341 338 339 328 342 341 338 339 327 315 319 318 325 319 359 355 320 331 322 324 355 322 295 315 330 305 333 331 345 275 339 319 355 318 342 331 314 367 322 321 318 349 335 309 313 319 302 302 321 355 324 321 298 298 305 312 363 303 278 327 331 317 325 288 323 310 318 313 341 374 331 346 339 309 351 364 337 316 338 355 334 328 357 344 320 314 354 331 313 299 327 308 325 342 343 329 301 308 369 338 319 369 311 334 307 346 319 364 320 330 300 342 360 301 338 342 304 351 353 306 316 333 331 367 304 354 330 343 343 333 323 315 334 328 341 348 324 343 352 338 321 333 303 281 337 364 318 338 320 349 320 325 333 291 315 339 339 315 348 343 329 343 309 337 351 361 374 316 303 310 311 316 343 343 353 304 301 325 314 327 344 311 305 340 345 315 322 325 348 319 334 340 319 365 287 363 325 343 342 343 312 327 328 321 345 316 340 261 302 336 309 324 293 319 341 347 343 331 302 336 308 345 333 313 319 347 309 301 329 310 339 306 319 351 335 320 323 320 323 293 315 315 306 309 319 350 313 344 328 298 336 327 349 303 299 336 310 323 280 344 284 319 337 306 331 331 321 305 323 349 348 317 334 288 331 320 335 323 321 302 361 321 334 352 340 309 332 331 315 295 320 323 325 327 315 345 343 282 304 341 338 322 320 321 323 316 342 325 334 326 337 339 296 314 312 300 330 324 304 314 305 317 341 313 334 360 322 304 326 312 349 321 320 347 337 324 357 325 335 335 308 359 317 311 347 340 330 308 336 321 350 338 292 315 342 347 358 362 355 299 379 362 316 346 372 326 320 334 316 339 336 348 302 368 351 321 314 338 351 336 356 336 366 351 338 297 334 348 353 326 314 327 322 317 346 332 343 328 344 346 343 332 333 324 346 335 349 325 359 317 324 320 330 321 326 300 308 313 328 287 333 298 330 304 332 301 316 319 337 322 298 307 336 326 324 334 312 326 342 316 305 320 319 318 296 343 310 344 319 336 307 323 334 336 328 307 299 330 329 306 322 304 314 304 319 347 297 309 306 337 298 295 338 332 291 317 324 296 308 313 295 314 327 321 355 321 334 330 290 314 319 306 293 312 325 331 327 285 306 300 296 323 327 295 299 335 328 344 344 322 310 298 344 342 321 329 291 308 300 302 332 322 323 295 325 322 333 322 275 338 323 328 296 349 325 312 365 294 335 309 334 320 328 307 280 317 308 337 314 341 304 285 303 331 312 294 339 293 305 332 306 319 335 296 312 284 322 334 308 312 303 376 287 341 344 336 342 310 313 322 316 319 290 330 327 280 314 326 314 299 316 301 316 279 300 294 309 327 358 343 351 334 322 307 319 317 289 331 270 311 301 314 325 295 318 282 273 309 311 306 314 303 324 309 339 313 288 308 300 308 340 321 298 311 325 300 286 343 311 303 297 334 308 306 301 342 311 321 330 327 328 308 307 298 312 340 340 331 317 338 354 313 329 306 306 289 318 329 315 299 298 312 315 310 288 295 345 273 351 315 298 311 311 367 333 285 290 351 367 331 302 309 316 308 338 316 331 305 326 321 303 309 322 312 332 322 322 309 325 337 319 300 332 316 317 309 350 309 319 317 322 285 311 341 311 337 303 301 304 320 335 305 287 338 321 308 309 331 312 290 292 336 341 315 326 300 320 307 311 323 304 315 334 300 320 304 341 304 293 331 291 316 298 310 330 331 312 325 330 289 286 314 277 308 329 307 289 307 323 293 297 300 315 314 315 316 290 329 311 301 323 294 295 342 319 323 304 308 307 307 316 330 299 335 319 310 319 308 312 321 334 320 334 303 318 312 326 317 350 341 322 321 305 312 306 280 307 321 268 304 348 318 341 311 288 309 316 300 327 323 308 314 286 315 318 309 304 334 314 332 328 326 314 325 312 307 330 303 323 309 284 302 326 297 293 339 306 302 269 344 298 337 314 295 301 278 307 291 295 303 311 323 305 328 283 358 300 300 322 292 309 320 324 295 347 325 290 315 311 333 293 299 304 321 295 290 316 308 337 293 296 292 325 279 289 306 329 293 305 334 317 318 305 322 316 318 336 333 328 321 314 304 282 319 312 318 307 291 350 301 319 313 301 294 323 333 315 297 330 337 295 296 321 333 354 301 303 321 279 296 326 284 301 344 297 307 324 342 292 321 303 321 304 302 325 334 311 313 274 306 288 294 312 290 297 330 313 304 301 327 326 293 297 278 318 336 318 332 319 307 288 281 293 289 319 287 306 338 301 332 296 275 297 343 330 302 313 282 276 272 327 323 333 321 310 321 308 280 262 285 330 306 295 317 332 286 294 296 326 315 321 286 296 292 287 289 337 315 309 307 309 306 316 298 301 299 297 309 311 316 284 310 299 327 304 317 300 316 326 265 297 307 324 313 290 337 315 315 289 332 302 315 327 330 305 282 321 309 313 310 324 296 328 278 310 340 281 313 282 298 310 314 325 305 299 313 302 303 276 312 325 310 319 340 324 326 318 325 326 289 313 329 313 334 324 307 304 319 312 314 322 283 326 330 278 305 316 309 330 312 312 306 332 297 294 302 315 320 274 291 320 305 302 307 298 264 284 315 265 309 286 316 337 277 313 271 295 310 309 310 326 297 291 289 310 308 305 305 271 301 290 273 290 330 321 303 296 312 282 319 330 309 312 315 298 291 332 298 301 317 284 333 297 280 313 302 308 336 311 330 313 302 354 295 331 306 322 316 309 327 298 308 332 303 310 279 292 288 302 311 324 301 312 312 327 318 304 307 293 319 308 329 314 309 286 316 274 308 322 300 297 310 313 311 287 286 305 306 296 316 308 283 315 284 320 303 318 295 296 352 326 295 297 319 304 311 298 291 305 325 303 340 312 300 335 276 310 319 313 316 309 300 327 313 290 309 288 303 282 307 295 334 289 286 306 300 274 328 312 308 279 291 320 343 328 336 311 295 306 338 333 317 288 290 302 307 310 337 313 257 322 312 287 317 344 290 316 320 302 299 337 282 301 312 330 305 312 320 291 302 313 334 306 322 304 292 291 297 323 297 335 292 322 286 335 285 296 278 299 295 326 324 300 298 289 276 285 309 283 291 303 317 305 322 294 326 316 317 318 286 292 305 272 292 320 294 313 284 301 303 299 317 291 334 290 313 307 274 303 334 302 306 323 287 288 304 312 321 350 259 297 287 322 304 326 324 301 303 304 301 312 310 275 290 296 294 295 332 275 316 295 317 295 320 291 299 361 344 277 337 294 296 310 312 304 302 289 331 298 298 322 287 293 309 290 305 316 361 303 295 285 337 304 319 303 309 316 324 303 295 340 293 296 310 299 307 312 312 272 300 326 278 314 347 315 287 287 322 329 325 292 298 279 320 293 294 352 287 306 311 325 292 303 319 316 286 308 277 294 301 312 272 301 313 306 298 309 280 301 296 314 305 272 293 308 334 298 306 304 307 297 307 286 309 289 308 313 280 351 323 312 312 295 296 281 296 298 311 317 287 299 310 318 316 306 287 301 302 302 305 303 319 312 297 306 307 302 300 271 285 306 291 290 293 298 323 297 270 319 330 301 289 304 312 311 271 281 285 296 306 296 300 283 287 331 338 299 300 327 308 281 303 324 286 322 296 282 326 297 283 291 322 296 299 298 287 282 338 303 314 278 301 293 289 297 329 313 298 299 298 289 310 296 282 322 288 290 302 311 321 312 303 292 297 294 300 305 308 337 262 299 329 298 280 306 303 324 299 298 294 281 301 285 325 277 294 296 317 310 329 285 314 311 314 321 303 303 287 295 279 295 313 288 304 321 316 282 289 301 269 311 300 306 295 331 296 301 311 320 287 269 312 284 303 313 295 296 287 296 328 302 332 285 280 297 302 307 323 304 320 278 296 302 315 282 310 310 299 289 304 302 284 315 287 305 297 277 288 291 302 277 286 278 294 310 322 291 331 260 295 280 311 268 309 332 279 332 280 319 291 290 294 291 312 331 297 297 307 313 296 294 293 264 292 275 278 327 304 296 317 292 298 311 283 277 292 283 317 297 322 244 302 307 319 304 283 285 301 336 296 309 314 284 298 282 296 331 312 324 295 291 266 278 286 282 273 269 276 327 282 321 297 269 270 300 315 277 291 303 311 294 318 276 268 326 272 296 295 271 293 277 309 287 294 298 285 310 302 285 315 313 318 309 300 332 293 292 293 283 285 310 267 316 301 300 303 273 329 310 300 315 288 287 338 314 300 319 270 287 309 295 279 319 310 300 336 281 313 319 306 311 273 325 277 305 306 319 282 287 268 322 317 284 308 326 325 316 301 323 306 341 299 322 311 309 300 313 315 282 319 324 314 303 305 292 305 293 285 304 290 297 301 278 284 307 321 316 313 346 272 296 303 295 310 317 291 294 313 321 320 302 258 331 280 310 321 293 334 322 305 289 315 313 317 288 286 300 308 314 316 285 307 258 293 289 330 263 310 283 279 280 308 289 306 306 275 292 295 289 310 304 296 317 303 295 316 300 290 294 329 335 318 304 285 313 306 289 325 341 321 299 291 326 320 272 289 276 301 301 309 281 310 289 324 283 338 286 348 292 330 316 287 300 306 332 334 346 309 308 303 278 303 309 341 305 304 332 335 334 283 315 283 316 302 282 301 301 313 282 303 339 314 305 303 335 287 299 287 312 353 307 289 337 292 328 302 317 277 334 311 291 322 299 294 302 301 290 298 300 286 327 336 299 330 312 337 276 313 331 299 327 325 295 301 295 308 324 314 306 322 308 296 345 334 308 294 333 293 332 294 288 279 304 362 292 338 332 320 310 327 339 329 356 337 301 304 331 355 326 336 287 311 334 339 289 320 324 324 310 327 345 309 330 330 321 312 308 302 321 321 300 314 338 317 323 319 319 303 343 300 325 317 351 331 312 306 316 307 321 323 333 319 331 287 302 279 324 305 327 315 312 331 301 303 351 330 298 308 301 314 313 299 305 298 270 290 271 301 329 304 306 326 343 335 339 303 331 316 299 331 296 290 302 353 284 272 310 289 320 297 310 299 292 313 326 290 307 316 311 304 291 325 326 296 301 353 305 312 308 298 341 266 281 309 287 330 322 320 311 286 313 322 306 311 303 314 285 351 301 308 307 329 309 345 338 310 321 321 312 319 285 304 329 325 306 302 326 310 309 331 291 282 287 316 325 327 262 259 279 298 307 311 289 315 302 297 315 304 286 294 301 300 300 296 302 309 310 322 292 295 314 275 298 313 282 295 304 310 302 293 310 332 316 275 291 326 322 300 274 318 340 301 293 323 342 305 307 296 276 304 311 296 308 285 274 289 316 311 290 283 309 284 327 291 317 301 286 314 320 265 298 305 288 338 287 295 270 301 287 346 323 306 317 288 287 309 279 295 305 289 297 312 318 308 298 296 289 282 311 313 290 310 274 301 308 281 266 307 297 293 305 303 299 308 307 302 312 305 298 261 275 339 294 294 315 323 284 288 292 280 308 319 322 315 277 324 305 305 279 309 292 300 296 313 305 302 301 330 303 286 303 284 335 304 319 318 292 283 298 324 298 309 299 320 314 289 303 301 280 270 319 346 255 317 291 299 310 310 287 294 286 316 320 335 276 261 334 310 292 332 324 306 306 292 323 318 314 317 289 288 306 287 302 291 312 319 315 305 286 298 325 319 310 299 310 305 321 312 319 302 245 293 269 314 302 314 292 305 297 317 329 276 296 315 311 327 304 309 306 311 293 286 306 316 321 317 292 282 311 332 310 309 309 327 311 300 306 310 270 320 318 347 280 316 300 312 307 310 296 318 303 310 289 280 283 299 287 283 327 296 283 291 282 278 310 298 290 308 310 286 304 305 299 298 308 283 297 299 274 287 324 279 330 286 337 338 304 291 298 341 331 304 327 290 305 279 315 300 309 268 331 308 327 307 287 311 323 296 295 313 284 311 305 269 278 349 289 283 294 322 278 317 317 289 290 316 305 301 289 323 267 278 280 311 282 309 309 310 294 295 303 298 280 286 277 260 291 313 332 301 311 302 282 317 315 309 301 320 283 302 320 306 298 293 276 294 324 303 302 316 303 307 267 305 279 283 308 331 297 342 292 289 285 275 310 301 299 332 309 287 280 282 318 289 297 319 286 292 309 334 325 276 343 320 336 283 289 267 327 324 331 281 288 331 303 340 314 312 303 288 329 337 288 322 320 288 269 295 287 289 312 285 265 291 308 303 297 273 301 311 270 320 281 331 282 276 304 312 272 316 314 296 281 301 313 262 276 282 273 299 300 310 307 312 296 316 271 307 290 318 292 306 314 297 341 280 291 309 291 281 278 287 304 307 298 308 293 305 315 322 305 323 296 294 335 309 288 311 292 304 306 337 313 323 276 282 275 302 301 304 330 281 313 304 273 278 337 292 285 320 314 305 295 293 281 304 288 290 282 273 303 307 310 289 317 316 319 292 280 302 314 304 309 308 286 274 291 303 319 335 303 302 314 300 302 328 297 286 321 298 290 304 293 286 293 299 316 289 277 299 297 272 298 331 321 325 321 309 307 321 284 291 302 307 316 289 329 302 308 307 301 287 298 273 329 292 296 277 300 296 264 273 305 287 312 310 341 325 300 289 272 300 285 330 287 327 288 326 316 307 310 315 290 288 264 328 336 303 290 294 273 308 286 276 314 311 330 273 301 313 284 302 296 329 299 301 329 317 314 267 292 308 341 317 323 297 317 285 291 336 320 282 287 281 321 308 258 293 292 306 330 301 287 315 261 305 302 271 287 302 283 302 275 293 325 303 285 328 283 325 307 313 303 316 291 270 281 280 338 283 316 332 325 300 275 310 314 308 293 309 305 307 294 296 287 306 294 308 333 266 290 292 304 329 322 308 283 282 319 270 323 321 295 331 302 296 310 347 313 329 295 264 285 305 281 304 291 277 325 294 282 302 306 296 289 276 298 306 321 314 281 288 280 285 316 308 313 306 296 307 301 315 287 307 286 327 293 321 296 303 299 284 293 296 302 299 280 300 296 296 279 273 283 297 284 290 269 288 295 283 357 298 282 289 297 305 316 314 326 315 303 304 331 300 292 281 289 296 317 307 287 307 281 303 275 307 311 305 299 247 283 282 269 291 316 321 305 315 299 313 295 282 299 276 299 298 292 311 286 321 310 284 289 288 321 311 296 322 297 298 319 286 298 291 257 266 310 294 303 310 293 289 282 322 302 275 309 309 330 314 308 295 309 325 313 287 298 304 291 317 267 286 284 318 296 306 266 310 246 290 279 281 275 272 295 255 277 313 283 279 316 283 307 289 313 305 291 306 300 305 284 326 300 293 293 299 309 290 287 302 283 280 274 315 271 307 285 294 297 300 319 323 310 335 280 310 287 294 301 275 313 306 303 285 280 288 307 331 269 301 319 305 279 271 270 296 315 283 298 325 280 300 327 313 302 307 334 257 276 282 271 338 288 297 284 264 312 306 274 337 307 290 295 275 328 307 285 291 299 271 284 296 286 296 322 324 321 300 276 293 281 290 291 312 277 303 282 311 298 264 299 310 315 279 292 281 274 296 246 318 303 285 288 325 310 300 312 327 314 284 295 267 274 308 321 293 308 311 305 323 328 274 280 266 312 302 296 321 312 283 279 303 310 297 264 285 336 283 318 281 287 324 299 292 286 301 308 291 280 303 323 304 307 276 324 314 308 312 262 285 294 296 321 277 308 265 313 300 298 290 311 289 276 310 302 316 284 319 258 310 278 317 314 302 295 288 286 273 294 293 277 324 300 295 304 326 300 324 308 291 330 301 321 273 292 274 310 294 319 300 276 255 297 312 316 268 303 282 305 298 290 311 312 307 276 287 313 273 292 327 286 302 323 303 321 320 266 309 330 289 293 321 294 286 318 276 280 287 322 287 309 320 295 276 322 300 303 319 274 305 296 287 289 288 285 289 295 309 307 288 316 311 319 312 303 261 294 305 320 282 296 293 270 316 296 312 301 344 292 281 289 300 284 300 317 292 304 346 290 268 305</counts>
			</dataPoints>
		</scan>
	</xrdMeasurement>
</xrdMeasurements>