File: data/XRD/XG-Sauerstoff/XG-875/W6824-1B_XG_Sauerstoff_875.xrdml
<xrdMeasurements xmlns="http://www.xrdml.com/XRDMeasurement/2.1" xmlns:xsi="http://www.w3.org/2001/XMLSchema-instance" xsi:schemaLocation="http://www.xrdml.com/XRDMeasurement/2.1 http://www.xrdml.com/XRDMeasurement/2.1/XRDMeasurement.xsd" status="Completed">
	<comment>
		<entry>Configuration=Factory configuration, Owner=User-1, Creation date=7/8/2013 4:01:53 PM</entry>
		<entry>Goniometer=PW3050/65 (Theta/2Theta); Minimum step size 2Theta:0.0001; Minimum step size Omega:0.0001</entry>
		<entry>Sample stage=MRD Cradle; Minimum step size Phi:0.01; Minimum step size Chi:0.01; Minimum step size X:0.01; Minimum step size Y:0.01; Minimum step size Z:0.001</entry>
		<entry>Diffractometer system=XPERT-PRO</entry>
		<entry>Measurement program=C:\PANalytical\Data Collector\Programs\Jorrit\2thom\_absolute_2th-om_10-130deg_PIXscan_56min.xrdmp, Identifier={15BCCF57-2807-42BD-B5B9-ECC0B3DC9284}</entry>
		<entry>Batch program=C:\PANalytical\Data Collector\Programs\SimonL\batch4x_2thom_10-130°_z9.1_x0,10,20,30_y0_57min.xrdmp, Identifier={EED9823A-2BEB-424C-9252-345C4EF2834A}</entry>
	</comment>
	<sample type="To be analyzed">
		<id></id>
		<name></name>
		<preparedBy></preparedBy>
	</sample>
	<xrdMeasurement measurementType="Scan" status="Completed" sampleMode="Reflection">
		<comment>
			<entry>_absolute_2th-om_10-130deg_PIXscan_56min</entry>
			<entry>PHD Lower Level = 4.83 (keV), PHD Upper Level = 11.27 (keV)</entry>
		</comment>
		<usedWavelength intended="K-Alpha 1">
			<kAlpha1 unit="Angstrom">1.5405980</kAlpha1>
			<kAlpha2 unit="Angstrom">1.5444260</kAlpha2>
			<kBeta unit="Angstrom">1.3922500</kBeta>
			<ratioKAlpha2KAlpha1>0.5000</ratioKAlpha2KAlpha1>
		</usedWavelength>
		<incidentBeamPath>
			<radius unit="mm">320.00</radius>
			<xRayTube id="1010048" name="Empyrean Cu LFF HR (9430 033 7310x) DK442154">
				<tension unit="kV">40.0</tension>
				<current unit="mA">40.0</current>
				<anodeMaterial>Cu</anodeMaterial>
				<focus type="Line">
					<length unit="mm">12.0</length>
					<width unit="mm">0.4</width>
					<takeOffAngle unit="deg">4.2</takeOffAngle>
				</focus>
			</xRayTube>
			<xRayMirror id="27010001" name="Inc. Beam Cu W/Si (parabolic MRD)" hybrid="false">
				<crystal type="Graded" shape="Parabolic">W/Si</crystal>
				<acceptanceAngle unit="deg">0.800</acceptanceAngle>
				<length unit="mm">60.0</length>
			</xRayMirror>
			<sollerSlit id="21010002" name="Soller slits 0.04 rad.">
				<opening unit="rad">0.0400</opening>
			</sollerSlit>
			<mask id="22030008" name="Fixed mask 4 mm">
				<distanceToSample unit="mm">220.00</distanceToSample>
				<width unit="mm">4.00</width>
			</mask>
			<divergenceSlit id="22010007" name="Fixed slit 1/8°" xsi:type="fixedDivergenceSlitType">
				<distanceToSample unit="mm">220.00</distanceToSample>
				<height unit="mm">0.19</height>
			</divergenceSlit>
		</incidentBeamPath>
		<diffractedBeamPath>
			<radius unit="mm">320.00</radius>
			<sollerSlit id="21010002" name="Soller slits 0.04 rad.">
				<opening unit="rad">0.0400</opening>
			</sollerSlit>
			<receivingSlit id="22010001" name="Fixed slit 4°">
				<height unit="mm">5.88</height>
			</receivingSlit>
			<detector id="7010017" name="PIXcel3D 1x1 detector" xsi:type="areaDetectorType">
				<phd unit="%">
					<lowerLevel>30.0</lowerLevel>
					<upperLevel>70.0</upperLevel>
				</phd>
				<mode>Scanning</mode>
				<activeChannelsEquatorial>255</activeChannelsEquatorial>
				<activeChannelsAxial>255</activeChannelsAxial>
				<pitchEquatorial unit="mm">0.05500</pitchEquatorial>
				<pitchAxial unit="mm">0.05500</pitchAxial>
				<readOutPeriod unit="seconds">0.135</readOutPeriod>
			</detector>
		</diffractedBeamPath>
		<scan appendNumber="0" mode="Continuous" scanAxis="2Theta-Omega" status="Completed">
			<header>
				<startTimeStamp>2024-10-02T17:38:26+02:00</startTimeStamp>
				<endTimeStamp>2024-10-02T18:34:32+02:00</endTimeStamp>
				<author>
					<name>PRO-MRD</name>
				</author>
				<source>
					<applicationSoftware version="6.1b">Data Collector</applicationSoftware>
					<instrumentControlSoftware version="7.0E 20130304">XPERT-PRO</instrumentControlSoftware>
					<instrumentID>0000000011142674</instrumentID>
				</source>
			</header>
			<dataPoints>
				<positions axis="2Theta" unit="deg">
					<startPosition>9.99826193</startPosition>
					<endPosition>129.99755682</endPosition>
				</positions>
				<positions axis="Omega" unit="deg">
					<startPosition>4.99913096</startPosition>
					<endPosition>64.99877841</endPosition>
				</positions>
				<positions axis="Phi" unit="deg">
					<commonPosition>0.00</commonPosition>
				</positions>
				<positions axis="Chi" unit="deg">
					<commonPosition>0.00</commonPosition>
				</positions>
				<positions axis="X" unit="mm">
					<commonPosition>30.00</commonPosition>
				</positions>
				<positions axis="Y" unit="mm">
					<commonPosition>0.00</commonPosition>
				</positions>
				<positions axis="Z" unit="mm">
					<commonPosition>9.100</commonPosition>
				</positions>
				<commonCountingTime unit="seconds">32.895</commonCountingTime>
				<counts 428 433 437 458 444 419 447 441 481 438 452 441 404 427 402 452 457 421 423 416 439 440 444 453 415 442 417 438 390 438 435 414 413 423 412 388 452 429 406 422 394 418 453 433 430 437 441 408 435 405 419 410 446 463 409 432 451 433 435 438 440 462 417 394 430 458 438 424 420 433 480 414 462 425 408 414 426 392 424 447 456 429 416 442 462 466 417 474 389 438 412 452 426 459 439 434 415 418 389 384 406 431 407 425 387 426 418 401 391 407 429 397 370 417 407 393 428 392 466 410 403 398 431 434 373 404 445 403 433 423 409 443 448 405 426 397 416 421 404 421 428 381 395 420 410 451 435 429 419 411 408 402 375 411 404 389 395 390 441 433 412 395 402 421 385 422 413 450 381 381 440 406 388 406 411 405 411 414 388 414 410 425 404 401 413 403 435 386 382 411 397 392 422 410 405 415 377 424 374 442 397 433 421 419 378 386 418 367 413 413 395 407 436 368 379 387 387 373 367 386 391 354 387 387 385 390 397 390 372 403 372 390 407 392 393 401 354 417 402 383 395 405 417 348 355 393 428 381 388 396 365 450 397 360 388 427 388 420 405 386 360 373 411 375 359 378 363 377 411 375 375 389 347 381 354 372 349 372 362 394 379 398 382 385 362 396 392 407 378 353 394 378 362 383 403 374 362 364 367 376 373 404 366 392 383 351 378 369 362 385 357 374 364 380 346 370 352 387 386 390 342 378 369 385 353 406 394 380 398 413 410 394 384 351 386 417 373 346 347 390 412 375 378 357 360 382 373 346 391 389 375 349 375 352 366 344 358 369 359 378 382 364 372 365 378 335 363 368 367 353 378 338 348 355 337 360 389 361 364 328 357 369 357 391 372 401 351 328 355 356 371 347 356 368 350 363 342 353 298 361 359 350 330 378 314 381 370 331 358 343 361 339 356 365 369 373 325 379 341 374 356 368 344 378 359 360 363 351 356 378 390 336 293 360 383 359 362 345 340 375 354 329 368 323 380 368 359 372 340 290 343 335 340 340 344 339 369 366 359 321 307 338 370 306 327 346 337 331 357 341 344 343 319 355 366 338 335 316 368 321 348 320 358 317 358 328 335 345 349 342 364 333 347 347 326 317 338 339 340 344 366 319 324 305 338 333 329 343 328 318 331 342 298 337 334 326 346 326 395 357 340 316 347 319 321 324 355 335 299 324 340 335 349 322 344 324 312 309 327 339 274 342 341 327 306 320 337 312 362 311 339 322 302 286 351 299 329 334 317 326 348 328 344 308 325 323 308 325 328 321 330 305 302 328 320 355 351 335 329 316 349 308 292 317 316 324 306 316 306 337 327 341 330 326 319 318 319 343 297 321 330 306 322 313 310 296 352 305 329 317 328 333 361 337 311 340 319 306 305 321 346 301 314 341 343 289 382 327 300 292 317 345 288 360 309 294 313 326 341 301 299 345 330 293 319 294 289 326 321 313 301 333 346 308 317 302 318 318 337 307 318 307 298 306 325 320 319 304 368 291 307 346 291 318 289 275 301 309 336 308 322 356 350 316 327 304 290 301 312 302 318 312 295 331 331 327 332 338 288 304 339 314 318 325 324 305 337 306 317 326 300 322 294 288 328 305 335 324 318 318 324 321 315 305 327 320 317 324 306 315 327 303 312 309 289 335 327 302 305 284 325 297 317 339 306 333 332 307 321 330 323 310 312 289 311 314 310 311 327 338 329 290 326 297 300 292 324 288 311 289 306 309 359 314 304 300 326 299 330 323 316 341 289 301 299 359 321 301 293 299 295 280 306 310 315 316 311 308 337 316 318 304 295 295 316 333 323 280 314 333 294 309 346 332 329 317 325 316 319 325 317 292 292 284 282 302 313 333 323 282 293 298 281 320 341 285 311 305 290 282 283 283 330 317 308 303 335 321 328 314 295 327 298 307 306 329 318 312 299 321 309 304 315 332 324 291 315 332 288 347 331 313 332 321 304 309 307 301 345 307 319 314 299 305 286 297 325 289 292 332 353 299 306 337 302 314 290 311 318 332 291 304 303 315 320 325 325 332 315 325 323 341 320 296 314 314 317 348 346 273 303 325 309 326 321 299 338 298 269 283 309 327 327 295 336 337 321 311 322 305 294 336 327 334 307 326 294 340 313 306 307 314 289 318 321 309 337 317 350 321 303 309 296 299 312 288 321 301 338 346 312 293 324 318 305 334 364 294 325 330 300 313 288 311 328 306 324 284 340 335 328 300 299 309 319 321 318 331 340 340 317 353 328 290 327 300 326 326 317 299 294 343 284 338 327 340 305 297 318 344 333 321 323 300 348 324 299 338 303 322 336 319 315 367 319 314 330 298 331 298 311 330 326 323 350 324 310 295 305 320 304 332 296 315 290 335 322 318 317 298 321 332 297 338 341 330 302 317 324 327 339 361 322 324 318 366 328 336 355 284 309 304 324 345 325 346 315 281 322 318 334 299 286 327 342 306 355 313 309 322 327 334 321 331 293 354 323 312 339 318 303 331 310 291 335 323 326 307 312 351 336 319 349 316 304 371 342 326 312 324 301 354 341 327 322 351 318 337 337 310 325 323 329 327 338 309 354 305 339 324 354 306 295 330 323 286 295 325 325 366 326 357 356 332 318 322 353 323 345 287 332 326 330 345 325 346 309 340 346 326 342 314 312 325 334 321 314 307 339 373 315 355 285 326 350 332 317 292 285 289 350 330 352 344 332 331 305 299 296 344 365 327 319 354 328 307 320 332 350 320 369 297 349 309 292 368 354 307 338 334 342 334 336 339 349 337 320 358 334 350 302 318 326 328 345 328 351 304 361 342 323 309 310 331 326 368 268 346 357 325 307 342 332 322 329 318 354 344 309 288 352 344 326 352 311 366 307 338 332 333 331 332 336 306 313 352 330 359 335 339 317 332 327 331 332 304 335 318 309 306 319 358 370 359 336 351 329 331 309 344 378 308 361 332 329 341 339 317 333 327 312 326 310 328 327 343 344 323 321 347 323 360 304 339 320 304 299 348 358 334 336 339 320 341 341 321 337 302 333 325 345 319 350 330 309 281 337 335 349 340 302 332 300 326 326 327 343 327 321 344 303 337 332 325 315 292 325 325 331 322 325 301 320 340 299 342 331 341 351 336 311 308 325 318 317 318 308 355 324 330 320 314 368 351 323 322 318 330 342 349 371 332 319 327 308 321 335 337 320 333 318 319 311 349 334 298 295 327 324 302 296 323 329 331 298 304 313 307 332 346 311 348 337 306 321 294 322 310 327 322 311 317 306 314 312 294 360 314 319 309 321 325 304 316 357 324 314 318 334 312 317 298 309 313 310 280 284 322 319 315 294 326 295 315 324 325 309 319 316 346 304 344 341 287 321 321 288 320 322 321 318 321 304 303 297 302 357 306 301 339 321 311 308 314 307 341 306 309 282 307 308 316 312 338 304 315 297 311 327 313 331 329 317 304 320 319 308 316 285 327 300 314 331 287 331 314 307 305 326 328 318 297 332 304 323 323 327 320 306 306 324 277 291 286 333 329 298 311 322 306 288 334 311 325 299 322 303 328 303 343 309 334 330 333 298 319 304 321 315 323 311 291 329 316 275 309 318 302 329 309 316 302 314 311 326 285 348 333 303 290 290 321 287 304 330 306 314 330 293 309 305 338 296 302 293 293 303 324 294 323 300 304 274 311 339 324 281 285 306 307 279 291 301 304 283 299 292 303 269 306 316 292 294 284 307 295 360 322 312 304 288 326 300 302 310 338 327 296 325 306 283 315 296 311 294 264 298 324 256 310 334 258 267 301 264 304 284 317 338 309 294 263 305 282 305 304 301 298 294 310 286 296 311 273 290 259 267 315 304 309 281 289 284 296 272 273 302 308 274 277 284 290 278 301 298 295 306 295 265 277 307 301 287 279 280 299 315 266 308 305 280 283 306 286 306 313 304 286 276 316 286 294 317 321 316 286 312 286 293 291 286 296 278 256 276 307 294 264 278 277 298 270 299 280 301 309 289 316 305 281 308 269 306 275 290 258 300 311 283 259 293 280 280 279 260 307 304 267 283 287 268 277 258 258 259 290 258 306 243 227 271 266 321 277 286 249 264 291 293 264 297 294 281 288 293 282 301 311 280 315 265 282 279 243 293 257 288 272 286 279 292 272 263 299 315 297 294 288 272 263 281 277 303 297 296 270 270 281 289 257 287 275 241 248 280 303 286 286 265 288 283 275 307 274 297 258 264 272 271 276 293 271 263 241 281 290 277 288 284 235 313 275 318 257 274 262 263 289 279 270 268 256 303 248 297 247 235 280 284 329 306 274 269 228 281 290 265 307 274 255 282 295 289 262 295 303 277 278 277 248 243 259 276 294 279 264 268 285 246 247 272 262 290 273 277 272 243 269 299 268 292 264 277 266 241 273 243 280 279 259 297 273 261 292 268 269 284 276 257 277 249 256 241 269 278 311 278 268 226 262 232 263 240 255 290 274 249 240 263 290 275 305 258 237 284 244 268 245 277 268 276 263 280 268 256 235 244 275 228 291 259 243 281 282 264 261 269 291 288 276 290 232 290 246 246 285 280 268 295 269 290 231 239 244 290 265 277 291 284 276 294 261 301 250 269 256 262 262 231 275 268 271 268 248 258 281 242 235 264 273 241 274 287 280 280 279 270 270 273 281 273 243 280 218 248 266 269 250 260 272 268 246 279 287 276 297 267 272 279 271 260 225 261 245 268 271 239 262 275 257 257 302 255 287 248 276 269 281 241 278 290 266 271 267 279 298 246 294 271 242 244 242 246 279 284 275 229 247 260 258 285 248 255 293 275 274 257 237 221 274 273 239 267 263 294 240 294 279 256 264 274 248 282 271 275 223 276 244 309 282 274 269 248 264 282 234 265 270 286 275 265 286 266 249 281 282 278 260 272 263 267 261 240 293 244 248 272 263 227 246 258 268 310 236 259 263 302 255 270 271 260 256 265 237 282 243 241 275 261 268 262 229 268 278 269 267 260 242 257 246 296 258 271 287 258 250 266 239 265 230 240 255 260 279 214 269 245 255 258 255 274 241 273 274 230 246 234 248 271 280 248 264 255 238 272 265 208 275 237 248 280 247 267 217 243 228 273 261 256 261 262 260 273 261 272 261 243 241 281 258 234 274 270 261 264 241 214 273 268 271 260 270 262 242 255 255 250 280 239 262 264 232 286 259 256 276 257 267 248 270 244 272 262 216 234 257 282 236 280 260 265 239 262 256 255 307 248 288 249 234 263 273 271 230 240 234 244 239 283 266 278 263 232 274 288 229 263 237 215 239 239 279 237 234 248 277 225 290 250 243 281 242 216 271 264 291 265 272 276 258 261 268 266 261 282 265 258 262 270 283 271 241 275 236 240 264 247 239 237 250 268 262 283 278 304 247 263 243 271 258 282 249 238 226 263 244 272 256 248 249 279 281 258 261 275 239 261 275 276 247 269 258 290 256 258 261 244 233 261 243 267 262 244 273 241 255 273 239 274 242 244 258 258 262 238 246 236 260 255 266 229 257 275 234 277 268 267 236 268 242 241 266 243 298 258 261 245 245 226 275 225 233 276 239 237 262 287 237 258 248 261 274 266 281 276 259 246 246 219 241 267 258 235 247 247 265 284 240 256 241 255 221 258 261 259 250 277 286 257 288 285 248 243 259 231 278 265 257 264 261 241 286 246 261 260 240 255 237 288 248 304 232 244 232 273 231 249 285 247 215 270 278 236 281 263 268 263 247 218 223 257 225 274 238 247 267 242 241 245 262 273 247 218 245 277 239 247 244 244 245 272 233 260 249 249 221 231 233 236 263 267 257 228 268 255 243 239 257 260 224 255 269 248 286 256 260 268 261 268 249 242 261 328 247 237 268 249 238 238 247 262 237 274 255 216 241 281 269 267 234 257 245 250 232 265 272 242 265 271 263 227 242 245 207 242 236 270 257 249 246 249 257 264 259 244 261 247 270 259 257 256 241 265 260 267 245 246 235 263 266 229 244 289 246 272 243 277 271 298 247 235 289 248 249 285 257 243 214 256 244 271 279 232 247 248 266 291 242 245 224 247 270 246 234 247 248 279 276 272 241 288 264 249 244 245 271 240 245 260 259 227 249 246 278 281 245 280 258 262 273 246 279 286 264 274 307 267 264 298 298 291 274 267 267 274 307 277 300 288 245 275 262 289 273 267 271 268 256 247 263 231 266 240 259 229 287 227 271 275 259 258 239 258 241 264 257 271 248 244 241 256 239 261 265 279 216 212 231 219 262 247 246 237 248 233 221 270 241 234 284 229 249 257 234 227 269 268 263 246 208 236 225 230 211 238 231 258 221 238 273 267 235 216 245 279 249 248 217 230 250 243 214 279 236 242 245 259 242 231 245 227 236 263 233 246 245 245 228 261 265 219 237 248 242 221 239 248 224 236 268 241 237 262 229 286 246 227 209 230 259 242 261 217 259 223 224 247 274 244 225 244 205 230 270 264 225 237 260 214 237 234 234 244 245 244 238 222 272 230 264 241 256 227 258 259 237 257 271 236 249 250 249 278 271 275 263 241 225 259 236 247 241 267 226 239 213 270 245 228 291 235 261 222 231 232 240 248 218 239 235 270 248 221 248 230 242 236 262 225 224 267 241 241 241 267 274 222 263 236 245 227 238 223 247 245 267 235 235 223 238 235 237 221 235 231 247 247 227 273 209 259 275 233 266 269 231 220 240 225 223 244 259 236 229 299 240 242 216 221 245 226 247 215 226 248 248 232 248 226 267 211 240 247 257 227 261 226 233 263 262 232 239 268 234 245 248 239 231 250 242 289 243 264 239 249 261 238 268 230 235 255 241 247 260 223 262 231 248 250 273 236 258 260 239 259 297 257 241 258 259 268 228 248 236 261 263 256 237 238 229 234 243 255 248 262 225 255 240 233 276 269 244 249 244 244 260 230 262 257 243 237 230 266 246 236 269 244 249 260 263 226 270 264 246 218 227 222 233 243 210 230 261 247 266 262 238 260 269 279 271 259 238 236 266 235 217 240 243 286 235 245 243 219 214 225 236 268 268 256 282 245 246 259 245 265 245 265 214 240 247 245 283 231 271 261 225 269 255 234 230 257 244 229 260 249 267 216 259 248 234 270 267 226 250 239 239 272 264 256 258 263 277 281 232 228 263 249 238 274 228 258 238 227 249 246 258 259 263 281 246 234 207 277 241 249 240 285 213 257 277 283 260 274 248 250 235 246 221 270 224 270 224 258 264 242 272 229 273 275 279 240 229 234 203 264 233 258 281 280 261 246 265 277 238 256 255 261 228 244 261 249 260 243 284 247 229 216 255 260 268 228 245 241 243 231 236 244 230 244 248 282 242 236 256 260 273 237 263 288 259 266 267 241 256 248 247 245 236 266 249 283 260 268 262 264 233 244 261 231 247 244 288 270 235 240 261 258 260 258 235 249 266 282 258 274 262 255 248 278 259 249 248 269 265 242 261 241 238 257 271 217 278 282 249 236 247 235 271 249 267 238 276 266 269 266 245 290 258 247 240 255 275 227 246 216 269 301 318 263 259 271 230 269 272 306 265 261 267 298 261 276 248 236 230 248 247 267 323 287 273 279 272 269 262 286 302 241 258 262 285 301 274 245 263 270 259 276 284 241 273 276 284 306 263 290 256 264 241 248 267 255 278 292 293 247 235 302 264 276 288 282 286 272 277 277 280 276 277 264 262 237 284 282 271 264 280 287 288 291 296 288 286 296 306 315 295 292 289 280 309 302 285 301 301 287 311 303 280 289 309 305 310 286 298 295 283 335 322 353 324 356 326 375 333 317 345 387 346 333 371 344 373 376 422 412 411 412 434 412 419 464 401 477 419 473 454 449 436 410 392 445 399 429 432 387 385 438 421 405 389 396 409 378 386 339 375 357 357 350 320 314 350 350 317 311 322 306 322 348 330 290 302 303 317 284 276 288 275 291 290 301 315 315 271 300 283 284 276 281 318 304 291 279 284 274 245 282 269 286 279 272 299 279 287 264 280 234 264 238 255 257 285 250 267 290 271 266 304 269 265 279 261 248 290 289 275 267 262 267 297 243 281 242 266 235 277 268 260 286 261 264 278 244 270 266 278 259 236 257 303 250 265 269 250 246 240 265 222 297 237 238 268 296 269 265 263 287 241 250 274 266 240 275 282 269 291 257 272 232 245 259 273 288 274 278 267 248 270 275 262 263 278 263 258 255 295 266 240 267 264 300 231 246 250 260 261 262 242 289 286 247 277 269 287 247 214 272 310 265 286 260 239 261 244 212 300 256 270 283 283 244 257 273 231 235 269 259 276 261 247 249 290 260 259 242 255 274 259 270 281 211 289 294 257 286 258 287 270 263 242 288 264 245 283 257 279 267 259 242 267 255 246 271 266 269 279 305 261 262 281 260 266 266 259 277 264 279 282 274 260 289 264 248 284 275 261 260 238 256 256 241 242 243 242 279 235 268 268 291 286 284 279 296 256 269 270 255 242 266 259 271 241 271 241 246 231 262 269 289 230 273 247 281 277 247 238 270 238 264 241 281 263 262 265 257 246 262 280 256 235 273 272 277 235 269 283 262 275 303 243 260 285 259 267 264 294 276 239 242 266 269 285 294 303 289 257 277 292 238 285 228 258 259 247 264 293 264 279 277 260 278 248 277 297 274 267 244 279 259 247 249 237 256 259 278 280 270 283 282 246 261 276 293 261 244 265 244 265 271 298 243 267 238 237 244 263 293 274 264 271 261 227 266 259 286 271 284 258 274 274 292 291 266 258 314 281 270 235 266 247 265 298 242 266 297 287 287 290 269 304 271 268 278 229 247 274 268 287 263 261 245 241 265 245 279 273 259 271 289 262 269 292 274 265 288 260 241 266 258 266 250 268 304 269 295 266 242 256 269 237 246 266 259 267 276 242 274 223 233 259 266 264 255 279 265 242 270 247 290 284 259 263 264 293 262 264 271 306 295 235 247 275 283 256 294 272 281 243 270 255 286 243 297 265 295 247 250 240 273 283 255 286 273 281 301 285 247 283 266 293 264 265 257 292 290 248 280 265 295 285 289 275 247 275 258 266 273 228 249 249 289 256 288 258 263 225 286 267 247 279 268 262 246 245 268 256 301 264 300 239 265 274 256 281 249 264 305 233 262 240 267 235 239 246 256 264 270 222 289 263 301 282 236 277 268 234 282 283 228 259 271 273 274 304 269 262 215 276 314 286 270 258 265 277 267 267 271 255 294 244 272 304 239 234 288 285 278 227 263 264 256 277 230 256 267 240 260 260 261 270 246 231 260 247 279 305 267 260 278 207 236 240 266 233 241 267 277 290 284 258 255 241 271 255 272 280 293 305 279 287 275 238 261 275 289 264 261 233 258 242 281 229 246 262 258 269 283 242 273 287 245 232 284 296 269 259 259 276 288 243 277 255 279 265 261 241 248 257 230 272 249 275 243 296 262 271 247 274 278 266 238 247 249 255 276 234 293 266 242 266 281 280 260 272 296 262 247 258 243 259 290 284 242 238 246 297 281 291 271 295 272 275 277 279 290 292 277 255 279 268 279 299 257 298 287 270 244 262 269 237 274 262 279 263 285 234 278 276 259 255 264 277 292 305 292 256 275 272 289 259 257 262 260 234 278 280 246 235 279 278 274 303 268 257 229 289 265 277 263 228 239 266 272 265 234 256 288 289 238 258 264 290 239 269 268 270 230 268 277 247 267 275 267 242 265 241 259 278 248 287 279 276 275 281 281 255 248 284 279 284 258 273 267 264 277 244 287 234 255 266 258 265 255 234 297 291 259 270 284 262 277 263 274 273 270 285 280 295 290 239 248 275 273 262 276 226 264 292 248 284 267 294 292 293 270 273 259 244 280 246 264 261 271 292 268 248 272 264 269 274 267 294 279 237 266 248 280 264 266 261 270 271 283 294 249 281 259 259 272 307 257 283 292 225 270 238 262 273 237 242 257 260 275 260 294 264 261 270 232 300 258 293 275 266 261 272 265 261 290 264 255 271 263 247 239 273 227 285 264 286 280 295 277 287 277 291 269 234 248 269 247 264 270 261 230 258 263 269 285 273 269 279 259 245 245 261 270 259 271 269 230 278 263 262 279 269 260 268 245 248 227 244 262 285 248 267 235 272 292 242 256 286 271 240 268 288 273 221 287 262 239 268 256 278 278 246 284 263 271 259 270 280 258 241 262 259 291 275 276 260 236 262 239 256 263 279 247 313 295 266 247 284 260 260 268 261 274 280 282 228 279 244 276 246 276 293 263 256 264 243 249 288 271 272 276 272 288 276 283 266 260 287 269 262 247 267 248 233 289 265 235 257 303 279 269 270 288 268 283 243 299 290 260 248 259 255 264 268 260 263 280 267 242 281 244 272 246 268 272 242 244 290 239 242 273 247 296 264 283 262 265 279 289 266 274 271 233 260 294 242 273 275 265 284 262 280 264 258 258 268 298 305 290 243 270 266 236 281 276 290 272 239 245 294 280 263 283 299 279 262 285 276 270 296 296 278 284 271 267 249 259 299 288 282 275 310 266 248 233 264 300 265 298 244 236 237 258 273 236 259 249 281 249 232 243 280 268 285 274 245 261 224 271 237 278 242 255 258 264 244 294 272 287 266 255 279 280 269 277 277 310 303 257 276 263 260 259 278 269 292 291 234 262 297 298 283 278 294 260 276 267 230 299 266 273 242 277 273 273 246 279 266 265 288 263 285 272 282 275 275 265 280 292 307 257 249 275 256 258 260 292 280 259 309 276 225 247 271 236 286 262 227 266 262 262 304 241 283 293 286 284 240 250 267 267 277 264 245 258 294 281 280 291 274 291 287 258 262 265 304 244 270 263 264 268 260 291 261 286 262 289 269 276 266 282 284 267 262 297 272 304 274 277 272 303 277 286 288 273 238 237 318 247 279 274 286 287 290 276 274 282 286 248 256 293 299 265 262 291 270 246 226 290 258 261 264 259 271 238 263 269 268 277 281 261 237 231 282 264 263 278 287 245 260 264 264 262 244 235 292 281 295 309 276 270 290 261 270 282 271 300 305 262 266 299 261 265 269 305 267 288 269 246 281 284 277 288 276 284 293 284 282 281 285 266 309 285 296 238 283 271 259 284 279 276 273 241 256 269 242 267 287 296 280 298 280 279 290 313 269 272 271 268 288 262 274 278 300 265 305 286 266 281 291 261 293 288 273 286 280 294 308 255 275 293 280 271 291 285 294 275 283 277 269 256 272 265 300 280 286 261 266 306 318 302 288 298 295 277 281 284 310 287 318 271 285 286 286 265 271 250 284 305 308 261 271 283 264 258 272 300 265 274 279 285 275 317 305 280 286 292 259 276 283 283 298 274 260 266 288 291 274 292 272 280 286 280 285 288 268 281 270 277 243 262 247 291 302 270 291 279 273 266 272 247 291 263 284 284 286 280 300 320 275 319 275 260 275 255 315 274 247 286 297 287 283 283 271 289 289 278 286 308 285 241 259 269 280 258 275 296 268 262 288 242 301 302 285 236 248 267 245 270 261 247 282 280 295 294 283 276 270 289 285 291 275 279 280 273 275 286 285 217 262 285 268 245 271 285 308 260 275 284 287 271 264 274 276 289 262 272 259 266 307 273 287 296 245 258 243 265 276 269 281 294 274 285 247 275 281 278 274 292 273 266 264 274 296 273 277 294 283 258 278 288 289 241 267 268 275 294 261 261 309 266 265 288 276 256 246 288 282 315 294 284 264 262 246 288 305 273 265 296 296 264 283 296 259 270 250 260 294 292 267 266 266 289 303 297 267 283 259 273 233 237 287 277 266 287 274 243 318 268 282 298 262 296 257 306 286 288 259 283 286 282 295 299 286 270 257 269 260 277 286 288 274 282 264 286 262 271 263 312 298 287 273 298 269 300 237 248 262 300 273 241 271 276 290 298 281 308 300 272 258 288 282 277 317 296 249 242 289 305 258 282 287 290 261 279 274 287 282 294 273 266 265 247 300 275 306 265 242 256 304 278 281 271 297 281 287 293 303 286 268 282 281 289 285 291 277 297 278 274 289 263 290 259 298 263 296 284 297 293 294 285 276 321 294 283 265 267 295 302 291 267 257 277 258 297 301 291 270 272 272 298 265 266 292 262 273 260 261 267 284 283 242 291 286 283 271 258 282 255 245 243 243 301 284 271 248 280 321 280 258 262 299 295 266 229 237 282 275 281 245 302 267 304 258 296 262 282 316 259 296 278 272 266 258 282 262 271 282 311 282 259 298 274 266 277 264 247 281 269 276 270 268 278 289 286 289 299 289 279 278 297 344 293 279 297 287 278 306 271 288 283 289 272 261 285 269 307 292 285 274 275 285 290 310 231 261 262 274 309 234 311 315 317 297 309 288 265 274 317 287 278 292 289 317 299 248 309 263 236 262 283 285 292 307 270 273 284 291 271 309 292 281 324 300 291 282 270 274 307 287 288 272 284 324 292 270 266 266 307 296 296 299 293 263 258 291 286 310 264 287 286 288 286 332 286 318 287 310 296 289 280 300 287 317 315 260 328 308 318 290 265 259 285 249 284 297 293 293 279 286 270 276 297 290 302 288 308 299 295 312 301 302 297 296 287 278 264 311 281 288 279 309 304 284 288 284 321 279 281 295 282 288 296 305 293 239 295 283 297 308 289 291 302 286 292 291 303 312 313 288 279 265 286 300 285 279 268 284 312 259 286 263 293 296 301 266 268 278 258 283 286 272 266 286 284 293 276 281 257 277 227 259 245 237 281 301 282 280 345 255 289 273 284 261 299 257 276 280 276 292 273 259 271 288 281 259 255 285 281 263 278 283 274 331 250 333 305 276 294 277 286 284 278 293 313 264 288 270 280 268 266 266 281 291 248 294 248 281 277 308 283 289 297 281 247 284 261 312 292 287 285 269 288 277 281 295 294 287 285 287 276 265 283 275 269 277 280 294 238 278 295 303 285 257 270 265 287 257 275 281 241 291 284 283 274 248 288 266 283 268 312 290 275 268 331 243 271 270 269 246 294 290 294 260 291 286 290 291 259 263 265 308 260 283 296 293 262 268 269 265 259 282 295 288 293 319 276 266 256 291 284 280 293 314 265 295 316 280 258 274 304 268 295 304 277 255 275 283 270 282 264 283 283 291 261 305 263 279 300 302 267 286 290 262 260 292 288 288 292 282 279 247 238 250 278 281 277 285 284 242 302 248 298 299 264 262 285 287 284 285 263 285 262 280 292 282 295 307 297 270 310 279 309 306 268 291 294 301 271 294 261 257 282 288 290 248 249 284 261 289 324 298 303 274 274 287 288 305 296 274 285 281 288 257 272 307 269 284 289 276 294 281 293 303 299 276 276 268 292 277 288 271 250 285 288 240 273 272 308 292 275 286 297 276 279 268 313 263 255 290 288 264 295 294 261 278 297 259 249 263 273 276 247 247 276 296 258 257 277 271 245 290 329 294 265 274 307 264 289 293 266 245 279 284 273 280 287 298 287 268 244 259 286 263 289 285 288 285 265 272 231 277 289 298 264 273 263 284 271 293 292 269 270 295 283 294 300 263 261 277 325 306 285 270 266 265 286 303 257 280 292 271 281 275 272 271 276 285 262 296 277 266 285 273 278 316 287 290 278 306 241 289 237 301 277 250 293 257 275 302 227 291 277 238 281 247 278 261 287 294 301 288 286 290 288 297 285 282 260 278 282 277 274 317 268 250 280 256 232 258 242 259 293 301 313 308 278 279 236 279 272 286 291 292 278 299 272 282 293 287 279 285 297 272 243 309 268 262 305 271 275 274 300 261 278 274 271 292 262 295 317 256 296 292 248 285 303 279 278 292 261 282 285 281 266 266 299 247 271 288 290 261 273 297 245 289 293 299 277 250 289 279 292 298 277 276 273 294 274 316 299 267 285 302 284 255 286 276 275 287 294 284 283 273 270 240 268 283 284 276 291 286 272 245 293 294 294 290 297 281 261 275 271 274 250 283 281 279 281 291 272 284 299 290 272 271 278 266 277 278 309 267 283 263 287 276 291 293 292 303 243 268 318 272 264 290 281 283 270 293 316 279 262 266 277 263 305 279 283 306 265 270 301 262 275 277 257 305 275 271 285 295 274 273 262 264 307 229 276 264 263 264 297 286 280 294 282 267 276 278 287 272 285 293 278 274 261 298 282 247 274 282 282 294 286 308 259 266 296 299 282 262 297 291 301 262 276 246 257 270 290 273 276 262 268 293 280 285 272 299 274 292 262 293 246 288 290 301 261 268 292 288 280 284 287 284 300 297 243 282 265 241 274 295 289 293 268 280 290 266 262 266 273 312 228 305 294 284 299 265 286 249 260 312 305 266 297 303 266 306 284 263 304 293 240 268 233 287 273 274 268 292 255 266 250 271 273 286 285 302 281 287 307 289 272 236 291 274 284 277 280 281 255 284 307 277 311 284 276 271 297 272 275 284 280 229 269 268 272 305 296 260 288 300 313 271 274 285 265 264 283 284 287 310 317 276 304 273 291 289 266 300 268 275 293 282 276 293 266 294 271 279 302 278 290 298 306 306 290 269 273 270 295 281 271 288 288 303 270 269 265 265 288 290 261 303 285 286 295 285 267 276 318 266 240 297 275 271 271 294 240 294 289 284 264 270 296 294 287 278 296 296 298 279 263 277 268 287 280 297 276 245 266 281 293 284 267 288 294 271 274 316 255 279 281 297 291 282 272 263 278 286 305 310 290 283 284 295 280 283 296 284 288 263 289 281 325 286 284 284 281 286 276 309 272 270 297 279 287 293 257 245 282 272 289 269 271 305 261 272 261 238 273 264 280 264 248 242 270 288 300 301 284 275 286 278 258 298 284 273 271 276 272 284 312 240 265 287 263 317 257 293 297 271 277 272 302 271 262 285 307 292 257 294 271 292 296 267 270 274 320 281 280 292 273 279 302 302 290 240 283 290 296 280 315 280 294 295 308 273 290 275 320 267 292 279 284 310 261 283 325 279 231 305 270 242 315 273 321 262 261 292 293 280 272 264 314 307 270 286 287 275 294 259 295 271 270 267 295 268 282 258 279 287 235 288 303 299 286 265 285 276 295 283 257 266 283 317 262 271 296 288 321 275 279 297 278 265 284 289 258 268 282 305 243 280 291 290 262 263 288 296 300 274 271 265 306 285 248 250 257 305 300 286 277 289 276 239 276 313 280 269 272 265 308 297 288 276 269 299 298 285 292 287 278 287 272 270 257 277 264 232 270 294 294 287 290 272 282 276 255 292 320 249 297 284 314 272 309 278 279 285 258 309 305 271 310 321 290 283 230 277 279 265 266 290 302 284 265 277 278 273 274 282 286 296 270 277 259 273 287 278 285 275 271 340 277 238 292 257 284 286 289 282 261 298 273 299 302 288 275 302 274 268 263 292 245 311 266 278 246 305 285 278 303 312 293 284 292 266 279 298 285 278 292 312 288 303 309 311 275 280 245 285 278 281 263 287 258 266 275 285 292 264 302 280 277 299 269 268 299 250 280 290 287 280 259 267 293 283 280 281 293 295 280 273 294 290 289 278 298 296 289 274 247 293 260 277 287 263 244 267 286 278 272 282 277 275 265 268 273 290 308 304 294 275 283 268 270 288 273 292 277 255 265 274 267 275 308 266 311 258 274 293 259 255 294 277 279 262 285 297 259 281 256 279 275 300 298 303 275 277 279 311 286 281 298 276 266 264 267 238 270 291 266 308 288 276 240 271 293 295 241 265 292 284 298 295 282 285 280 269 257 275 287 245 294 288 283 264 301 288 311 265 303 297 312 281 284 298 291 283 288 292 266 242 261 274 291 281 292 240 326 295 281 272 265 275 258 291 269 301 267 295 282 288 292 268 287 270 286 285 291 280 277 303 284 258 272 287 304 249 275 258 290 276 284 272 285 279 277 280 283 297 266 294 286 279 309 272 278 271 290 305 272 265 263 281 305 262 273 316 299 243 288 283 293 292 285 269 289 237 263 302 275 283 263 288 271 263 285 276 285 284 284 274 296 270 301 281 291 302 304 319 275 308 266 264 267 261 306 294 278 275 280 274 281 265 266 246 276 309 283 288 265 264 284 291 298 284 275 279 266 272 286 256 305 261 288 274 281 282 281 267 263 256 263 287 258 270 279 277 300 267 267 300 288 266 256 245 263 300 295 273 272 286 279 272 250 301 245 274 310 290 304 313 314 265 284 318 305 289 296 271 287 268 283 281 243 299 276 275 308 291 283 299 301 284 295 259 304 273 281 263 279 278 275 300 267 294 285 293 265 293 284 308 303 307 312 281 284 301 278 309 293 280 280 309 283 290 298 301 306 274 320 275 285 267 291 290 284 270 270 278 309 287 296 280 299 326 274 295 301 292 285 300 266 300 285 277 291 287 306 310 279 287 298 308 257 266 323 287 301 301 308 294 273 272 338 312 335 292 275 278 294 275 299 301 311 318 337 281 321 296 303 279 305 310 339 311 317 299 336 335 321 311 329 318 332 301 347 261 301 316 329 337 343 301 322 333 316 298 331 337 303 342 312 332 346 311 348 322 292 300 328 333 317 303 306 302 350 294 335 289 305 291 314 314 306 298 301 295 279 329 301 316 283 238 308 311 282 308 296 301 324 299 283 287 293 303 267 260 314 290 292 270 313 259 277 298 273 275 295 258 293 304 281 276 316 267 293 256 279 312 287 331 304 286 284 283 290 299 289 264 290 281 300 297 282 282 291 255 268 288 311 233 300 273 291 275 296 284 302 311 310 288 292 275 281 273 278 301 289 282 299 239 283 290 280 293 268 285 274 302 302 264 307 282 307 294 296 280 297 313 269 288 295 292 313 285 284 283 279 299 256 329 263 277 269 264 292 287 290 279 265 290 265 271 266 269 280 270 281 282 281 261 293 279 302 291 279 273 274 280 276 306 258 301 280 286 274 277 275 279 268 281 259 268 305 297 276 276 279 292 317 292 294 269 283 244 270 279 302 308 279 299 286 275 274 269 286 295 285 272 268 299 233 261 284 236 286 263 291 271 316 248 297 271 284 279 288 312 282 280 294 268 293 302 265 275 259 284 287 296 287 298 261 281 268 273 269 257 308 255 293 278 266 291 285 288 266 274 283 259 268 279 290 304 250 290 281 284 283 298 311 288 303 269 270 314 332 271 316 263 271 255 285 275 278 279 246 300 283 268 277 268 294 250 289 286 292 289 277 260 260 266 279 299 313 312 277 265 283 298 303 266 267 283 333 248 281 276 291 300 288 281 288 279 272 300 238 293 301 274 267 279 274 303 289 298 289 312 262 257 267 268 304 284 284 316 274 266 277 279 294 304 286 267 276 295 291 306 257 286 286 276 284 291 294 281 283 289 284 294 280 303 279 263 274 294 257 266 286 277 283 280 294 270 314 288 242 272 257 269 290 268 285 291 269 289 281 288 277 287 270 277 278 285 290 293 273 265 302 296 273 311 306 271 315 273 271 294 270 288 264 270 248 285 291 294 262 324 281 264 262 285 284 320 255 273 272 265 276 276 242 301 289 289 267 312 288 258 304 285 297 280 276 266 267 290 275 312 238 301 270 284 262 288 296 268 263 232 279 283 296 285 276 265 274 267 285 292 309 278 293 274 274 270 270 282 262 284 284 286 301 286 304 276 279 291 296 258 297 255 292 272 280 288 276 283 285 271 264 295 294 245 275 299 268 284 311 282 289 266 260 292 275 287 276 304 293 302 306 263 279 260 280 296 283 317 250 302 245 304 290 285 266 267 271 268 279 297 283 260 310 273 283 294 270 286 285 302 275 269 289 265 282 272 305 275 300 257 282 288 292 242 289 271 286 306 282 284 283 276 264 300 288 282 279 294 306 290 286 290 259 290 268 307 267 300 288 248 264 295 282 286 266 287 284 264 297 266 284 291 309 279 305 268 302 302 281 321 300 261 326 290 292 301 274 272 266 277 271 287 294 292 285 282 240 242 291 260 293 295 263 280 294 313 272 285 308 304 264 279 284 275 241 298 266 298 303 273 279 260 286 258 276 278 286 296 286 280 281 296 265 284 258 318 268 282 268 303 292 267 269 281 306 293 282 295 295 271 299 266 292 257 292 301 292 281 303 263 281 260 278 305 277 278 283 274 306 287 298 271 288 277 333 284 268 295 290 256 289 293 308 298 279 285 279 297 268 264 292 292 258 285 284 289 275 304 295 310 292 276 292 280 316 256 291 288 302 299 266 290 262 278 286 276 281 260 271 294 295 283 274 309 308 312 275 287 270 265 286 321 279 302 283 334 301 296 281 284 299 292 298 305 318 285 303 274 302 288 285 270 288 288 304 276 259 255 277 265 287 264 304 294 291 292 314 303 289 294 287 258 311 331 296 268 296 279 320 243 301 279 295 299 272 308 262 286 334 301 283 271 304 297 283 257 306 330 283 319 279 304 276 278 336 304 316 293 286 281 281 282 285 281 290 272 269 281 321 304 294 268 282 274 246 315 310 272 287 273 278 289 281 292 272 275 289 308 267 263 313 291 311 278 262 269 293 300 306 265 260 286 293 249 281 266 309 297 302 299 274 318 284 303 275 264 271 312 277 275 287 280 277 306 266 292 279 261 290 290 272 274 266 299 294 289 276 267 274 241 278 276 271 316 296 282 306 266 260 265 243 291 268 278 280 274 300 310 269 282 270 284 305 284 280 271 262 325 295 301 285 277 264 329 278 270 294 296 277 247 292 269 294 292 304 291 293 288 288 294 235 306 262 283 290 309 293 292 260 307 318 282 300 268 297 288 309 281 286 296 280 294 273 294 270 279 282 289 321 242 274 295 303 295 265 303 265 304 257 272 282 277 295 289 299 288 282 286 304 308 290 313 257 293 275 267 280 273 263 284 302 260 270 280 259 294 263 289 297 287 280 276 288 285 285 318 297 281 315 277 303 294 295 285 285 322 284 305 292 289 299 291 288 281 274 290 285 279 304 309 247 307 290 310 287 277 281 304 286 309 302 288 282 273 279 247 287 273 280 312 265 244 285 283 256 284 278 275 236 262 233 287 312 281 298 274 268 298 282 293 315 303 304 282 296 285 281 280 290 293 305 280 287 297 340 266 279 322 283 278 264 277 278 257 287 282 286 287 274 247 263 282 311 283 299 316 285 266 286 291 274 287 266 286 310 306 290 288 315 284 285 281 242 308 280 290 267 284 301 294 297 291 263 271 278 288 291 292 294 284 291 291 282 282 281 261 264 313 296 296 269 277 265 260 273 280 275 287 267 266 282 294 290 317 299 285 304 287 267 286 290 275 281 289 272 273 321 277 308 268 268 272 284 283 260 282 297 290 268 281 265 317 312 271 275 292 267 296 279 300 271 271 261 304 301 287 278 283 247 275 289 299 310 292 292 263 275 283 234 281 260 307 285 264 279 273 297 259 270 311 270 277 304 269 314 291 261 242 291 286 264 309 291 268 278 274 281 280 274 295 270 295 247 311 277 296 295 256 270 248 275 268 283 304 263 269 324 301 279 293 268 284 277 281 295 278 300 267 269 275 272 261 264 300 273 276 283 273 276 283 306 283 300 244 297 247 246 270 296 265 280 292 232 297 270 282 283 313 271 298 287 284 273 282 274 256 290 263 282 299 242 278 286 293 261 283 272 274 296 287 302 302 283 291 285 278 277 315 265 286 278 278 273 244 272 265 271 263 243 281 288 248 242 264 259 256 283 265 295 265 274 274 297 267 278 276 266 297 274 279 286 264 242 284 291 276 260 278 277 280 258 293 265 246 280 261 283 315 296 265 273 263 265 243 248 260 287 273 290 278 298 271 300 243 239 285 274 274 243 275 298 302 319 255 247 269 309 272 259 264 298 307 281 303 307 279 265 280 270 258 275 290 270 248 247 293 295 270 263 292 289 271 289 249 275 274 276 281 283 264 270 258 284 303 288 289 266 271 273 264 270 273 283 258 262 286 267 271 277 295 250 270 269 281 247 283 286 278 290 280 279 263 305 325 317 267 258 262 268 258 285 241 286 275 239 282 272 268 308 270 295 266 259 260 256 247 274 245 279 271 282 278 288 266 292 281 277 302 259 277 268 278 287 267 291 265 286 284 259 255 263 286 265 262 297 291 268 281 291 300 290 290 287 286 267 287 271 307 279 287 278 309 287 277 272 282 292 306 274 258 268 276 259 281 277 264 300 262 280 290 293 292 287 284 263 242 290 270 297 270 244 320 275 293 309 318 268 270 302 284 279 306 286 302 297 259 299 305 295 276 290 276 299 249 314 281 269 266 258 264 281 292 279 308 286 300 264 320 288 286 295 306 275 301 312 291 291 279 259 300 308 303 279 288 309 265 320 300 281 287 263 270 293 274 313 274 302 262 291 301 286 248 273 309 296 286 289 302 321 297 280 294 291 279 289 295 263 266 262 294 308 290 273 279 257 262 292 279 260 268 299 300 272 300 261 282 282 280 257 305 308 313 271 277 270 286 285 276 298 278 272 259 290 300 286 262 267 271 280 319 257 302 286 286 289 275 263 266 234 283 281 294 249 285 284 307 237 256 282 295 296 262 292 287 263 297 268 264 248 281 279 270 256 261 267 245 277 245 276 324 302 287 247 315 275 271 286 265 287 260 278 279 263 267 307 300 285 281 316 266 283 265 301 281 320 283 250 275 276 287 294 255 260 244 277 274 249 294 307 290 293 277 277 274 285 286 256 283 267 264 291 282 308 287 272 286 268 282 313 282 276 273 299 280 297 269 272 300 286 272 293 305 266 278 274 294 276 261 278 272 278 314 244 295 305 282 277 291 307 267 295 316 284 273 287 302 284 263 276 303 293 285 310 314 280 284 313 249 283 292 291 263 296 289 271 264 295 296 261 284 289 280 264 305 289 272 285 294 263 285 312 279 288 281 277 300 264 257 259 293 304 289 256 285 264 259 261 285 291 266 248 284 311 284 276 320 282 288 273 311 260 247 287 281 264 279 284 301 279 274 275 246 276 289 273 288 281 275 262 296 267 258 293 268 263 288 259 291 292 276 262 291 315 278 276 265 259 264 317 249 312 289 309 296 309 291 263 255 257 285 288 285 277 313 297 278 305 299 297 261 282 284 296 289 291 276 292 270 265 288 282 265 266 281 285 270 284 273 266 273 284 267 288 268 268 296 271 300 247 265 283 257 256 279 293 286 287 271 274 256 312 261 282 298 289 266 279 263 316 269 285 306 293 270 304 281 296 300 289 276 293 287 302 281 283 261 294 291 271 282 294 281 277 269 288 276 269 269 266 240 295 283 301 297 276 266 278 299 286 273 278 284 273 248 256 268 299 290 286 274 280 315 287 276 292 277 298 284 285 271 268 231 286 293 294 268 293 284 246 276 286 328 304 300 297 269 283 273 280 285 284 280 283 285 288 282 264 284 298 286 275 317 287 280 290 271 282 246 282 272 275 266 292 262 280 275 272 273 302 289 249 265 245 281 246 284 285 268 290 275 277 285 271 306 263 296 292 273 259 267 274 282 276 288 295 293 290 279 279 292 272 291 275 289 280 273 304 288 268 273 292 292 273 289 286 273 303 303 283 304 268 316 286 256 244 286 295 273 258 273 276 300 278 292 265 279 272 290 285 287 286 315 273 264 291 236 316 295 287 295 271 267 285 268 259 298 289 274 270 312 260 264 293 290 273 297 267 257 279 282 293 307 270 294 258 292 290 279 290 297 271 291 296 279 275 283 292 297 284 292 240 282 283 284 312 276 299 275 276 274 297 263 307 283 286 277 284 293 284 298 268 279 292 267 278 265 295 297 289 277 269 270 259 272 288 290 316 279 271 271 287 269 257 296 257 292 303 267 276 310 292 293 278 256 265 238 277 304 295 258 278 291 258 292 287 291 266 297 271 273 265 273 302 277 297 299 294 271 258 263 300 298 292 274 255 321 261 291 256 257 302 290 264 268 317 290 265 277 308 292 286 266 279 292 272 268 267 304 316 278 273 300 265 301 277 301 280 276 280 267 247 279 272 312 288 298 285 307 290 294 266 237 299 276 273 272 275 300 271 309 281 274 288 306 276 277 280 298 285 245 304 279 271 289 290 281 287 311 261 263 265 281 298 271 303 278 303 291 313 269 276 296 279 307 300 288 283 285 273 285 287 265 297 297 314 262 328 269 280 274 294 285 294 275 291 270 276 290 296 292 305 296 267 277 266 288 286 284 261 283 292 247 248 267 266 311 280 275 282 290 271 289 291 319 298 268 289 292 296 263 298 296 283 273 276 300 292 314 291 291 292 274 264 295 304 286 298 297 311 287 313 265 278 295 288 271 289 288 296 290 291 271 290 301 259 273 270 291 273 278 292 257 316 288 244 284 288 257 310 296 270 279 290 277 303 283 273 304 285 318 311 276 299 286 292 262 279 290 286 290 274 312 266 297 263 275 298 282 281 271 267 286 270 286 305 292 271 294 340 331 271 278 267 295 249 288 286 302 326 284 283 305 266 259 292 290 286 314 278 298 302 305 250 284 300 291 296 263 294 272 298 235 319 307 307 290 312 311 292 317 313 319 262 277 298 273 282 300 285 273 308 316 245 288 310 260 304 285 307 286 279 279 284 277 259 263 296 302 290 255 288 304 263 286 263 288 278 282 285 314 269 258 272 293 245 277 282 277 271 265 308 298 268 276 283 287 291 278 287 266 278 309 271 276 277 265 329 290 286 272 264 261 289 283 282 285 302 317 289 289 268 279 294 307 293 280 293 292 293 286 263 309 283 268 275 273 271 279 264 290 276 308 308 277 270 285 296 302 238 272 293 274 300 277 288 271 285 284 277 263 286 295 293 289 281 275 270 279 260 305 293 266 249 276 291 298 329 273 331 277 304 299 277 297 275 290 292 266 288 281 273 274 297 277 289 279 313 287 295 324 308 296 270 301 283 273 271 276 286 277 318 271 278 289 306 299 284 314 301 282 289 284 302 296 306 277 297 308 303 287 272 269 296 276 306 275 279 262 273 271 278 295 267 280 284 271 303 293 276 300 309 287 264 277 236 241 313 324 298 305 291 291 299 294 272 322 255 315 293 285 284 277 249 261 295 285 311 286 275 297 273 309 282 268 303 276 283 305 297 309 288 282 268 264 293 277 269 291 278 279 303 304 283 296 295 292 263 269 307 255 291 266 276 294 273 273 273 272 278 299 280 284 286 294 268 290 303 284 284 294 311 288 290 281 271 282 293 286 286 293 262 266 286 264 317 264 284 260 286 271 328 281 308 291 275 259 290 266 283 315 268 279 318 298 312 270 296 283 246 257 287 282 284 241 300 274 276 270 260 294 279 270 327 268 277 271 284 296 248 257 276 272 309 274 285 281 271 298 331 296 263 277 266 259 285 241 271 282 298 281 300 244 298 293 259 280 284 287 283 288 293 350 293 270 268 309 291 313 271 303 291 268 286 274 272 289 234 259 267 286 263 264 295 240 280 312 273 288 309 295 271 269 286 304 269 247 275 285 264 277 267 307 269 287 309 266 263 263 289 286 338 259 275 292 290 334 268 275 268 309 268 303 279 275 295 303 290 291 321 317 268 290 287 262 290 274 299 317 291 292 282 284 287 275 264 307 258 312 296 314 264 303 285 291 266 270 262 304 301 281 261 262 293 273 255 277 287 288 272 288 272 278 275 287 282 323 279 273 270 313 289 290 285 322 279 311 280 270 307 287 260 306 247 269 285 265 275 290 277 281 296 302 294 261 292 309 285 300 284 302 308 319 277 295 308 278 323 300 279 312 245 238 289 272 298 286 324 301 270 286 323 298 269 282 292 291 312 278 302 281 297 303 226 275 263 290 279 291 281 303 319 267 282 274 312 293 263 292 291 309 290 265 284 288 298 260 282 289 267 306 260 280 293 298 258 279 274 287 273 284 269 256 284 264 300 283 260 304 264 288 301 236 301 266 290 269 294 278 269 249 304 327 308 288 249 287 246 303 277 247 314 302 292 294 287 281 302 261 275 276 279 291 297 328 281 283 283 250 317 248 266 279 293 263 268 314 295 293 310 298 317 348 293 291 284 264 289 260 307 293 247 293 300 301 288 289 282 285 267 318 269 302 287 303 319 293 262 270 290 286 309 290 274 308 262 293 317 285 293 297 282 316 282 294 285 275 277 274 318 295 287 274 269 309 269 273 282 301 281 294 283 271 285 306 263 314 302 317 294 306 321 264 269 301 301 306 274 288 317 313 292 271 282 312 265 328 307 309 319 296 284 282 278 308 308 311 302 286 336 280 311 333 268 312 245 293 314 287 264 309 302 333 308 300 263 281 296 320 277 307 287 301 282 309 319 310 292 287 286 308 286 332 312 301 294 294 267 284 309 287 289 297 294 303 307 286 312 288 282 303 277 304 319 313 318 341 271 314 291 321 304 293 339 270 294 291 283 335 277 296 316 303 276 308 283 325 289 294 299 273 309 249 255 286 270 313 296 288 300 314 286 269 297 314 286 322 269 303 300 295 301 268 283 273 244 301 278 293 274 276 308 301 282 240 273 256 287 265 300 294 260 307 290 258 295 262 261 277 303 269 288 300 277 290 263 279 285 303 314 290 273 284 301 291 289 267 334 279 293 307 292 270 280 272 290 284 266 271 303 268 247 310 285 273 297 245 285 279 295 278 268 263 295 298 299 309 303 287 312 293 299 277 297 299 279 283 280 282 279 329 280 264 294 296 280 279 301 271 307 305 317 273 269 274 266 270 318 262 276 295 270 264 314 273 291 260 279 300 296 256 320 295 267 277 278 262 281 273 300 258 280 266 268 287 302 277 265 304 280 262 270 281 284 272 291 292 282 307 275 293 312 262 289 307 293 274 278 305 277 276 291 288 271 294 267 302 265 275 293 276 272 278 276 301 272 308 271 306 244 313 262 263 287 286 268 303 274 289 287 275 244 307 284 277 244 263 329 270 311 282 288 279 278 295 302 279 313 270 269 302 281 286 287 272 281 294 271 275 288 267 293 288 265 291 265 268 280 301 290 257 277 320 267 295 256 297 277 282 279 305 281 291 281 266 266 276 281 283 249 267 289 287 287 281 271 290 294 290 291 310 260 277 267 302 257 311 293 283 283 258 291 280 292 282 282 294 258 271 297 299 279 283 272 294 269 275 297 302 282 262 291 282 283 279 331 278 247 307 274 273 278 279 282 292 309 279 277 268 284 270 246 274 296 286 250 302 292 281 294 250 294 278 268 289 283 282 279 267 297 326 286 303 307 262 271 256 267 258 272 258 283 282 273 256 299 282 265 298 291 291 281 259 268 295 294 293 315 284 308 275 304 296 291 304 294 260 294 281 269 296 273 297 281 306 303 282 267 283 275 292 305 308 264 259 299 286 276 276 277 281 290 280 296 299 298 244 281 266 272 290 261 293 298 273 318 280 291 277 293 280 304 283 266 259 272 273 279 288 278 295 266 264 292 257 269 275 248 300 287 232 241 279 287 277 297 268 268 256 290 291 286 289 311 283 266 278 264 222 280 255 308 310 306 301 296 308 270 295 278 295 297 280 287 255 287 282 294 286 277 275 275 295 257 316 261 289 307 271 246 298 269 277 256 285 284 280 327 281 313 321 280 244 314 289 304 303 277 281 291 262 318 320 296 307 320 295 309 292 293 263 262 247 310 261 283 283 269 289 307 286 296 287 260 282 259 285 286 294 289 267 269 273 276 269 302 245 303 298 256 279 298 307 280 291 317 291 283 294 301 285 284 304 299 309 277 291 282 300 294 291 303 297 285 306 278 305 309 271 285 281 328 306 263 276 282 255 262 311 311 318 268 269 301 295 284 291 272 306 300 291 320 320 301 287 282 291 286 324 309 299 296 261 270 287 299 309 297 297 295 247 271 281 289 292 296 287 308 292 319 241 281 273 286 291 294 289 300 312 280 307 293 278 283 273 296 326 333 279 305 285 270 287 304 306 268 288 285 290 275 292 290 298 279 287 309 270 281 293 301 278 263 276 288 283 295 343 281 286 258 281 279 301 277 297 304 308 270 281 307 264 281 308 263 312 295 295 305 306 264 291 288 273 258 287 291 288 295 340 284 299 283 310 297 259 250 311 274 275 282 263 294 295 315 270 295 309 290 256 310 295 282 296 280 301 289 280 303 288 293 296 302 293 291 310 287 304 282 292 294 316 266 263 262 287 302 308 276 282 314 303 280 284 287 318 290 294 294 299 301 287 310 288 266 288 273 255 286 297 276 330 307 269 293 285 298 298 259 264 302 295 274 263 261 273 315 296 301 289 274 242 289 280 307 301 287 294 313 248 285 261 304 276 305 284 269 275 279 285 261 262 285 289 246 265 277 296 311 289 250 267 315 302 304 279 271 298 279 306 307 291 288 267 277 278 298 313 286 307 264 280 267 276 290 288 279 269 284 273 245 305 285 300 310 309 277 280 309 280 259 259 276 240 285 290 283 281 301 308 286 270 296 281 308 243 308 297 284 302 285 255 291 293 279 268 249 284 291 267 310 283 297 319 295 305 274 283 269 279 284 241 246 289 308 293 285 262 284 278 279 267 315 260 304 274 305 289 278 285 268 291 277 305 279 278 287 280 263 313 274 265 283 280 303 243 283 283 270 288 302 301 291 321 289 293 256 298 271 291 270 264 314 301 268 265 295 281 342 276 315 264 299 313 247 272 266 306 308 280 282 268 273 301 283 256 290 289 276 268 285 262 278 271 302 293 288 287 263 284 263 250 304 299 272 299 302 298 284 271 308 281 277 294 266 294 269 280 279 288 283 285 295 268 258 291 296 276 309 249 264 277 265 298 294 259 272 297 264 290 259 271 281 278 284 248 289 268 273 292 296 281 291 258 306 240 265 320 276 293 277 291 272 271 271 291 277 271 269 284 275 293 295 277 299 297 316 297 246 298 301 288 287 302 303 268 267 271 277 303 240 263 259 295 279 248 272 265 300 276 294 268 238 244 274 286 264 261 270 269 294 273 266 283 300 268 286 270 259 304 267 265 248 270 269 290 294 282 289 290 308 268 274 260 266 280 258 283 263 267 276 302 256 249 301 294 285 299 278 307 315 284 284 282 266 287 270 256 270 243 273 289 257 291 292 291 269 260 286 305 282 256 270 283 281 282 247 293 262 267 277 261 279 256 305 260 297 269 281 230 269 283 277 238 283 288 290 306 301 286 265 271 248 268 248 301 274 268 272 231 281 269 263 269 285 267 283 277 289 265 274 262 279 264 264 279 285 261 289 283 273 289 262 281 289 316 259 262 280 266 286 308 270 304 287 259 290 284 273 268 278 261 262 244 282 306 267 280 264 298 275 264 272 267 262 293 273 294 277 266 294 274 262 287 280 273 275 287 291 311 281 258 269 282 295 292 290 277 283 296 280 258 248 294 290 301 289 271 287 299 275 272 260 276 293 273 282 265 257 262 278 292 258 270 273 283 288 274 285 256 296 282 302 249 278 289 284 266 302 294 286 288 286 279 284 261 273 293 264 274 263 278 293 293 283 285 255 260 260 291 294 310</counts>
			</dataPoints>
		</scan>
	</xrdMeasurement>
</xrdMeasurements>