File: data/XRD/XG-Sauerstoff/XG-875/W6821-1B_XG_Sauerstoff_875.xrdml
<xrdMeasurements xmlns="http://www.xrdml.com/XRDMeasurement/2.1" xmlns:xsi="http://www.w3.org/2001/XMLSchema-instance" xsi:schemaLocation="http://www.xrdml.com/XRDMeasurement/2.1 http://www.xrdml.com/XRDMeasurement/2.1/XRDMeasurement.xsd" status="Completed">
	<comment>
		<entry>Configuration=Factory configuration, Owner=User-1, Creation date=7/8/2013 4:01:53 PM</entry>
		<entry>Goniometer=PW3050/65 (Theta/2Theta); Minimum step size 2Theta:0.0001; Minimum step size Omega:0.0001</entry>
		<entry>Sample stage=MRD Cradle; Minimum step size Phi:0.01; Minimum step size Chi:0.01; Minimum step size X:0.01; Minimum step size Y:0.01; Minimum step size Z:0.001</entry>
		<entry>Diffractometer system=XPERT-PRO</entry>
		<entry>Measurement program=C:\PANalytical\Data Collector\Programs\Jorrit\2thom\_absolute_2th-om_10-130deg_PIXscan_56min.xrdmp, Identifier={15BCCF57-2807-42BD-B5B9-ECC0B3DC9284}</entry>
		<entry>Batch program=C:\PANalytical\Data Collector\Programs\SimonL\batch4x_2thom_10-130°_z9.1_x0,10,20,30_y0_57min.xrdmp, Identifier={EED9823A-2BEB-424C-9252-345C4EF2834A}</entry>
	</comment>
	<sample type="To be analyzed">
		<id></id>
		<name></name>
		<preparedBy></preparedBy>
	</sample>
	<xrdMeasurement measurementType="Scan" status="Completed" sampleMode="Reflection">
		<comment>
			<entry>_absolute_2th-om_10-130deg_PIXscan_56min</entry>
			<entry>PHD Lower Level = 4.83 (keV), PHD Upper Level = 11.27 (keV)</entry>
		</comment>
		<usedWavelength intended="K-Alpha 1">
			<kAlpha1 unit="Angstrom">1.5405980</kAlpha1>
			<kAlpha2 unit="Angstrom">1.5444260</kAlpha2>
			<kBeta unit="Angstrom">1.3922500</kBeta>
			<ratioKAlpha2KAlpha1>0.5000</ratioKAlpha2KAlpha1>
		</usedWavelength>
		<incidentBeamPath>
			<radius unit="mm">320.00</radius>
			<xRayTube id="1010048" name="Empyrean Cu LFF HR (9430 033 7310x) DK442154">
				<tension unit="kV">40.0</tension>
				<current unit="mA">40.0</current>
				<anodeMaterial>Cu</anodeMaterial>
				<focus type="Line">
					<length unit="mm">12.0</length>
					<width unit="mm">0.4</width>
					<takeOffAngle unit="deg">4.2</takeOffAngle>
				</focus>
			</xRayTube>
			<xRayMirror id="27010001" name="Inc. Beam Cu W/Si (parabolic MRD)" hybrid="false">
				<crystal type="Graded" shape="Parabolic">W/Si</crystal>
				<acceptanceAngle unit="deg">0.800</acceptanceAngle>
				<length unit="mm">60.0</length>
			</xRayMirror>
			<sollerSlit id="21010002" name="Soller slits 0.04 rad.">
				<opening unit="rad">0.0400</opening>
			</sollerSlit>
			<mask id="22030008" name="Fixed mask 4 mm">
				<distanceToSample unit="mm">220.00</distanceToSample>
				<width unit="mm">4.00</width>
			</mask>
			<divergenceSlit id="22010007" name="Fixed slit 1/8°" xsi:type="fixedDivergenceSlitType">
				<distanceToSample unit="mm">220.00</distanceToSample>
				<height unit="mm">0.19</height>
			</divergenceSlit>
		</incidentBeamPath>
		<diffractedBeamPath>
			<radius unit="mm">320.00</radius>
			<sollerSlit id="21010002" name="Soller slits 0.04 rad.">
				<opening unit="rad">0.0400</opening>
			</sollerSlit>
			<receivingSlit id="22010001" name="Fixed slit 4°">
				<height unit="mm">5.88</height>
			</receivingSlit>
			<detector id="7010017" name="PIXcel3D 1x1 detector" xsi:type="areaDetectorType">
				<phd unit="%">
					<lowerLevel>30.0</lowerLevel>
					<upperLevel>70.0</upperLevel>
				</phd>
				<mode>Scanning</mode>
				<activeChannelsEquatorial>255</activeChannelsEquatorial>
				<activeChannelsAxial>255</activeChannelsAxial>
				<pitchEquatorial unit="mm">0.05500</pitchEquatorial>
				<pitchAxial unit="mm">0.05500</pitchAxial>
				<readOutPeriod unit="seconds">0.135</readOutPeriod>
			</detector>
		</diffractedBeamPath>
		<scan appendNumber="0" mode="Continuous" scanAxis="2Theta-Omega" status="Completed">
			<header>
				<startTimeStamp>2024-10-02T14:48:38+02:00</startTimeStamp>
				<endTimeStamp>2024-10-02T15:44:42+02:00</endTimeStamp>
				<author>
					<name>PRO-MRD</name>
				</author>
				<source>
					<applicationSoftware version="6.1b">Data Collector</applicationSoftware>
					<instrumentControlSoftware version="7.0E 20130304">XPERT-PRO</instrumentControlSoftware>
					<instrumentID>0000000011142674</instrumentID>
				</source>
			</header>
			<dataPoints>
				<positions axis="2Theta" unit="deg">
					<startPosition>9.99826193</startPosition>
					<endPosition>129.99755682</endPosition>
				</positions>
				<positions axis="Omega" unit="deg">
					<startPosition>4.99913096</startPosition>
					<endPosition>64.99877841</endPosition>
				</positions>
				<positions axis="Phi" unit="deg">
					<commonPosition>0.00</commonPosition>
				</positions>
				<positions axis="Chi" unit="deg">
					<commonPosition>0.00</commonPosition>
				</positions>
				<positions axis="X" unit="mm">
					<commonPosition>0.00</commonPosition>
				</positions>
				<positions axis="Y" unit="mm">
					<commonPosition>0.00</commonPosition>
				</positions>
				<positions axis="Z" unit="mm">
					<commonPosition>9.100</commonPosition>
				</positions>
				<commonCountingTime unit="seconds">32.895</commonCountingTime>
				<counts 430 445 434 417 418 455 432 418 410 418 436 423 393 404 402 435 440 425 381 442 410 408 439 403 432 430 443 415 427 437 425 414 404 443 412 432 402 407 396 412 412 429 396 425 411 425 418 457 401 401 404 385 387 417 459 397 404 385 421 369 410 412 429 440 427 381 407 396 410 397 419 423 435 424 426 400 382 428 407 390 412 377 443 426 380 406 390 389 408 403 414 388 404 403 430 406 394 427 401 408 409 400 397 421 388 410 428 423 429 394 405 420 431 407 359 409 443 380 365 386 417 420 397 399 410 411 402 405 357 407 386 391 406 396 379 389 431 420 386 378 370 410 439 390 372 402 394 360 369 368 342 467 395 398 389 394 421 357 402 392 420 359 372 372 383 384 401 371 379 390 372 346 395 422 392 408 396 378 375 371 399 367 427 369 376 380 378 359 387 431 406 367 344 402 348 385 371 381 377 381 411 381 396 374 362 377 345 377 389 376 390 363 384 358 365 384 347 402 376 390 374 333 364 397 354 367 373 376 383 383 370 392 351 362 384 397 384 348 371 373 381 385 354 348 363 369 385 377 354 350 380 355 349 354 372 359 354 370 373 348 358 382 316 352 379 359 349 368 346 333 388 342 346 368 332 367 357 370 344 343 377 343 339 381 334 349 343 386 390 345 352 351 394 374 334 358 337 387 391 363 381 348 367 358 362 365 315 357 356 362 367 333 362 346 350 343 342 348 351 334 325 359 348 346 359 350 327 356 333 373 356 342 314 324 324 392 307 386 336 320 339 346 360 320 307 386 358 369 333 367 358 347 352 376 333 381 342 335 348 326 338 325 370 372 381 334 339 342 335 327 364 360 349 342 335 353 338 359 340 313 320 323 324 311 334 348 356 334 282 354 314 312 359 305 344 348 344 332 353 349 363 339 336 330 323 349 363 332 336 324 352 345 342 350 329 329 325 343 343 344 310 330 344 374 341 353 315 355 356 323 329 318 319 342 338 314 310 296 305 342 356 363 314 365 303 346 311 325 320 335 343 342 344 315 335 344 301 283 323 296 330 310 342 338 323 327 318 347 347 303 301 320 316 289 337 364 313 325 291 352 361 343 350 335 331 327 340 337 300 326 326 271 329 317 309 317 342 331 319 301 342 315 305 351 336 337 312 334 338 301 310 320 303 301 348 324 321 327 333 311 296 334 334 337 354 332 327 309 316 336 323 326 326 322 324 351 292 306 319 339 308 308 326 317 325 340 306 304 329 303 308 333 300 354 304 342 314 309 291 307 283 326 305 326 323 309 307 311 329 296 320 322 333 349 320 301 322 293 312 330 364 275 311 309 311 301 291 332 319 297 310 310 315 318 339 317 316 308 298 286 311 315 304 336 336 276 290 271 282 303 302 322 303 303 313 305 281 303 318 336 342 282 302 283 344 328 323 286 332 332 319 301 323 326 299 332 304 340 339 282 306 298 306 309 297 331 297 311 327 304 304 321 296 296 295 301 331 315 313 322 331 314 329 307 321 303 289 297 289 322 317 310 353 300 315 336 294 324 287 304 319 296 286 277 313 299 294 329 304 308 339 294 306 314 335 313 292 317 286 259 303 321 278 332 311 290 312 323 320 301 284 331 312 293 311 309 310 318 330 348 287 316 346 323 309 302 312 319 275 311 317 335 308 326 309 303 325 328 314 318 327 336 281 323 326 314 302 321 305 286 286 313 306 330 290 288 321 337 295 308 334 307 343 280 291 315 339 307 286 273 303 275 281 289 292 290 338 336 309 294 318 292 311 314 283 318 311 315 285 292 287 305 302 326 309 307 317 305 329 303 316 352 291 334 305 285 317 314 310 327 317 309 270 345 315 314 302 322 288 315 322 313 311 305 299 305 322 307 303 306 305 313 303 326 304 304 288 289 317 322 318 305 322 300 319 299 304 308 304 283 337 280 331 337 307 333 336 323 309 324 277 310 309 328 299 306 323 347 299 286 314 286 303 279 310 303 336 347 318 331 332 321 308 316 312 342 298 324 285 329 298 314 326 340 326 324 304 326 327 290 323 331 314 288 290 332 319 298 294 297 342 341 331 316 299 318 269 311 293 307 326 328 328 337 338 297 297 335 328 342 304 330 312 334 343 286 349 298 337 349 332 316 316 335 317 336 323 310 341 302 315 337 308 341 312 314 359 334 325 328 338 322 267 315 307 279 285 336 325 334 334 316 293 326 331 351 323 350 321 324 339 311 311 338 326 325 296 316 322 323 327 315 322 316 340 296 297 315 307 324 362 294 306 319 343 361 312 313 313 290 309 299 348 327 322 301 287 327 298 325 317 328 357 325 320 302 306 333 332 318 306 349 348 322 336 348 324 355 298 320 330 319 354 348 339 307 337 354 334 355 292 292 288 328 330 310 329 351 342 319 342 332 312 315 358 322 343 317 347 316 320 323 318 302 297 361 314 305 345 323 330 317 308 300 364 351 330 323 317 335 369 346 332 338 342 357 353 345 308 355 336 315 357 318 339 375 332 338 314 355 314 332 339 342 288 327 340 347 345 324 309 334 342 366 382 329 348 347 325 321 342 354 342 327 350 309 351 336 317 333 353 285 338 376 321 289 331 300 321 335 307 365 321 355 339 330 359 344 331 344 365 326 328 346 309 330 335 320 353 333 355 320 347 335 334 351 353 341 347 335 337 357 337 331 327 339 322 347 343 346 316 344 365 321 354 327 347 295 344 348 322 359 350 318 327 327 344 339 333 338 379 330 348 336 323 323 299 344 350 340 345 330 332 303 343 324 338 345 319 332 353 321 323 320 331 329 359 347 329 346 309 327 310 364 332 362 345 351 346 357 351 317 316 321 335 355 362 307 316 331 313 364 343 311 351 322 322 303 340 344 369 329 358 352 345 321 365 331 371 358 335 302 364 343 338 321 365 361 331 317 320 319 346 357 324 364 335 345 354 356 368 308 322 342 388 325 329 298 346 358 353 322 348 349 303 298 332 341 356 335 359 337 331 357 355 358 331 318 358 375 337 317 334 339 350 310 313 348 303 333 324 323 320 332 330 324 321 355 348 318 355 308 319 323 324 340 331 331 340 329 348 332 312 333 394 298 342 327 342 311 332 337 308 311 323 339 315 331 347 286 347 320 344 343 314 319 340 321 351 346 285 346 320 329 366 331 380 361 331 382 311 310 319 369 318 348 329 339 336 327 309 347 320 340 352 337 335 333 347 333 339 337 330 317 302 352 339 330 333 317 350 378 333 334 321 309 361 341 339 361 369 320 329 334 352 337 344 320 334 317 353 355 339 303 341 328 318 336 332 354 368 317 321 353 311 352 315 304 324 342 308 344 329 325 312 332 325 303 352 350 337 347 334 307 324 329 349 327 342 311 336 336 335 278 308 341 301 301 285 297 322 302 344 325 327 333 303 338 326 309 348 332 339 331 300 315 331 316 306 333 345 351 338 321 311 302 327 323 338 326 297 332 304 307 330 304 300 347 326 310 339 316 284 304 332 321 314 307 315 344 307 321 319 320 332 337 305 309 328 313 342 323 317 346 334 312 297 358 354 301 342 332 299 325 340 292 311 300 327 310 322 315 325 303 317 334 299 322 319 305 336 326 279 340 330 317 308 334 289 320 298 300 313 310 339 324 320 315 339 306 321 330 309 323 305 288 294 315 295 302 316 286 288 321 322 269 333 305 323 292 295 309 309 289 308 309 296 301 306 334 336 272 323 328 289 280 291 334 293 338 306 318 290 288 278 313 282 328 332 314 309 314 320 301 321 296 297 294 307 294 303 314 282 288 301 330 283 315 320 343 293 295 292 274 294 298 302 323 294 288 304 284 306 293 288 312 321 313 312 310 299 305 337 303 298 286 301 284 308 303 304 295 299 293 270 280 290 296 295 336 306 303 287 283 294 277 306 322 292 280 284 264 312 257 305 303 328 302 314 306 263 320 315 289 343 317 329 281 304 288 317 303 275 290 300 286 331 300 313 291 287 308 338 298 281 309 311 293 325 300 280 295 310 307 296 283 311 297 290 304 296 305 271 304 257 292 336 305 278 312 286 298 335 300 285 295 285 310 305 335 318 289 290 299 324 293 270 288 300 281 291 286 278 286 284 305 290 275 319 294 298 280 284 280 285 262 296 333 299 299 301 301 290 291 281 295 311 303 293 328 290 279 280 292 303 305 273 281 284 289 346 317 265 293 289 273 315 291 289 313 272 298 287 267 318 283 297 308 313 300 277 292 246 298 304 295 281 314 297 276 289 278 308 294 278 308 298 278 314 276 264 316 255 270 319 298 288 296 294 270 291 318 298 280 288 271 290 269 294 276 296 248 249 287 284 287 297 276 283 300 280 313 283 301 297 256 272 288 292 268 275 292 289 273 262 282 295 249 309 271 283 296 262 257 259 314 275 264 284 276 279 260 287 299 289 283 280 270 286 275 291 284 281 313 276 281 275 288 265 264 286 291 289 257 290 291 305 270 277 265 266 281 241 303 290 267 309 295 259 283 261 289 248 243 314 263 255 262 277 295 270 286 292 297 277 285 292 276 285 283 274 267 265 232 280 292 282 274 292 260 262 298 264 300 309 278 261 257 272 246 277 269 287 275 264 288 257 261 282 278 315 274 285 223 310 270 316 291 264 255 278 265 289 279 262 293 300 260 274 301 292 299 284 248 298 297 287 315 266 276 312 284 281 282 295 284 297 249 292 255 269 280 276 255 246 279 249 316 299 260 265 258 275 285 279 286 271 291 270 269 266 278 273 314 281 304 269 240 282 279 273 279 278 266 255 280 311 286 230 248 270 269 284 283 260 319 266 282 264 307 244 265 259 277 291 245 287 305 262 281 274 277 258 279 271 258 246 258 278 265 300 287 292 274 260 266 287 249 280 272 278 280 292 275 249 302 295 284 257 274 259 300 274 296 275 272 239 262 261 299 283 264 268 241 276 283 298 233 297 259 259 275 273 259 256 226 264 260 294 262 309 275 221 265 264 290 296 284 245 282 290 264 247 269 274 274 266 259 277 258 298 244 257 262 271 280 279 248 269 260 280 275 277 245 274 288 278 263 300 228 263 307 271 298 224 269 276 278 310 279 281 267 277 282 247 280 238 255 301 234 288 291 267 247 240 263 270 280 272 245 255 294 278 273 247 292 299 247 242 239 267 259 273 257 295 243 291 257 275 278 262 260 262 241 260 267 291 256 263 257 278 230 234 275 284 277 269 275 266 262 299 267 278 275 243 271 288 234 295 233 281 258 243 277 263 289 267 294 243 261 242 281 278 296 275 273 219 223 248 234 260 237 245 246 268 233 279 293 276 272 290 243 303 274 262 303 287 261 258 272 282 267 270 287 277 244 237 269 293 259 278 273 241 268 245 263 267 258 269 278 277 248 249 255 264 286 268 266 261 244 282 280 238 233 233 268 268 258 233 244 245 248 258 268 233 284 259 276 261 285 258 279 263 241 260 273 260 243 275 234 265 258 245 237 238 249 234 241 259 255 234 258 223 289 296 233 237 293 269 232 237 257 266 276 231 257 240 279 263 244 250 273 275 270 271 265 231 239 237 255 263 268 277 246 267 243 277 256 256 249 237 256 269 289 266 247 246 237 240 271 272 270 271 247 272 269 265 271 238 250 268 235 232 263 287 274 231 230 229 267 243 292 211 263 238 234 286 243 269 238 258 266 259 244 235 257 230 249 235 279 230 267 265 228 244 239 229 268 271 232 240 258 217 270 243 248 259 268 260 272 256 256 272 237 263 258 255 260 247 260 244 246 270 266 263 262 259 267 261 278 243 246 271 235 261 226 267 234 265 261 230 256 236 273 260 264 255 247 245 244 258 231 248 256 230 265 264 233 261 247 281 262 258 241 271 256 236 263 255 249 256 243 237 255 236 247 265 273 241 260 265 279 262 262 258 236 264 294 255 245 256 259 275 264 236 242 260 274 247 236 265 259 281 243 301 276 228 226 243 264 225 265 256 214 245 238 262 256 241 283 270 273 280 265 275 300 281 228 235 245 216 234 264 244 259 236 269 255 259 239 264 262 230 218 258 279 260 262 241 269 226 257 270 256 248 219 256 246 276 262 207 219 243 248 240 238 241 277 256 260 257 247 293 228 261 273 242 238 280 264 285 271 262 270 241 259 269 237 288 263 261 264 259 256 262 249 249 243 261 293 238 280 262 273 288 278 282 279 278 286 260 261 234 278 255 250 283 239 256 271 256 289 246 244 217 278 247 233 292 222 242 239 270 261 259 234 269 221 263 246 275 247 262 231 256 263 267 226 239 269 277 235 263 278 257 248 239 261 233 225 250 279 244 262 245 265 280 233 247 238 278 241 248 239 197 236 266 229 285 260 257 241 248 231 267 265 233 248 255 241 220 244 240 237 242 269 215 231 239 221 246 241 234 257 257 264 258 248 237 259 259 266 232 246 256 268 212 219 242 242 258 262 239 261 247 273 228 230 247 228 229 243 249 240 264 248 261 245 255 245 261 248 237 264 258 234 212 227 242 236 283 214 260 235 271 264 257 265 269 238 222 258 247 262 255 233 237 232 279 255 272 238 240 261 266 266 250 234 245 241 271 268 243 232 272 230 274 255 243 236 242 240 248 244 258 231 286 248 259 258 246 270 234 263 233 241 241 244 276 248 237 241 258 246 236 234 228 264 238 264 243 250 223 240 261 237 244 229 261 266 257 227 237 272 220 282 243 268 241 239 246 249 232 261 268 215 283 244 248 256 265 272 269 245 255 260 264 232 234 241 268 264 233 261 260 212 245 236 234 237 230 240 236 265 221 278 257 270 248 235 215 235 242 235 242 244 246 270 270 249 268 235 259 247 244 244 243 265 244 264 266 241 218 259 267 261 228 271 272 250 274 269 250 271 233 245 248 289 255 232 265 249 213 255 222 232 247 234 229 249 233 243 231 236 265 241 244 255 275 261 225 224 243 247 263 237 246 243 223 229 247 261 247 237 208 256 230 238 226 239 241 241 214 248 266 235 228 226 242 263 257 247 248 262 245 262 240 242 237 237 237 234 263 266 256 243 237 244 234 265 248 241 247 236 228 241 256 242 220 261 242 226 226 242 239 231 228 236 246 274 248 265 260 248 268 260 235 258 221 274 242 227 269 236 268 280 261 266 263 232 222 255 260 233 285 231 270 256 283 241 233 239 255 248 290 259 256 279 233 257 239 278 244 260 239 272 233 274 247 277 239 233 243 242 246 281 264 240 248 249 240 283 248 236 270 255 243 276 260 259 237 227 229 240 240 262 220 238 250 247 277 249 244 290 240 205 223 248 230 257 241 235 226 238 250 262 262 271 273 260 280 275 261 267 259 255 240 243 256 248 246 242 260 263 215 262 238 233 291 284 258 270 239 268 258 277 231 258 247 237 236 249 277 238 258 229 241 247 241 249 277 244 262 255 257 264 258 268 273 272 256 249 238 279 268 259 268 303 268 237 245 270 242 249 245 224 255 270 256 259 260 266 260 242 248 265 235 269 285 283 271 245 270 257 262 236 270 279 260 268 243 282 274 260 272 265 240 270 259 272 267 216 259 232 286 256 278 270 248 283 267 259 227 258 269 272 281 260 276 232 287 273 256 284 299 282 255 277 261 269 260 256 264 260 289 276 262 275 284 294 298 274 286 239 239 284 264 241 300 288 260 260 289 243 268 262 305 264 300 269 267 292 269 281 273 307 292 248 304 265 283 291 250 274 281 297 274 289 283 290 294 283 284 300 262 278 271 282 297 292 287 281 285 274 282 282 273 281 303 302 313 250 271 328 289 309 312 334 312 315 324 328 287 318 315 312 338 353 373 339 318 336 387 319 319 362 358 337 377 400 403 417 421 440 435 406 479 456 464 439 474 501 486 488 513 488 450 502 467 475 481 482 473 454 425 429 417 424 415 369 453 375 390 405 385 363 346 342 330 339 381 296 341 325 311 296 282 339 310 303 311 291 310 301 286 303 271 297 315 277 297 293 282 307 286 247 282 282 275 272 289 281 266 280 326 267 286 263 274 283 261 296 289 290 284 268 269 305 292 278 269 282 280 276 294 270 262 270 292 266 300 274 261 284 271 249 263 290 260 263 278 237 260 269 255 269 269 261 276 263 275 264 261 301 263 268 248 263 239 260 299 277 272 267 279 255 267 236 255 283 271 278 248 255 259 246 239 241 263 243 304 283 288 272 259 266 243 240 275 273 260 247 278 268 271 263 238 279 240 266 278 250 264 298 248 233 289 240 268 277 247 240 249 270 263 263 260 232 283 301 243 249 255 303 248 270 258 216 261 265 236 260 281 259 278 285 266 247 228 232 266 232 236 295 255 257 297 288 242 269 284 257 247 273 284 229 289 262 273 278 278 266 230 294 234 280 257 281 286 264 264 263 248 242 257 275 255 274 255 225 275 248 255 268 264 249 219 268 262 241 268 270 280 241 247 241 226 261 245 238 255 236 279 230 266 274 221 271 293 267 240 269 236 247 242 246 263 247 245 275 270 248 250 264 245 220 273 292 242 248 262 236 260 246 261 275 240 256 259 220 257 238 247 238 258 236 248 262 240 242 274 281 250 245 249 238 264 241 246 240 239 241 261 257 278 241 269 288 236 272 267 272 271 261 272 256 279 241 228 272 250 280 244 235 258 293 248 248 244 218 268 259 242 240 266 242 266 297 299 248 230 248 279 247 255 246 293 257 281 245 260 266 279 238 238 284 264 239 241 269 294 266 279 284 283 234 267 280 274 283 242 262 242 241 257 270 274 239 281 234 262 275 259 261 285 281 263 257 257 232 240 265 273 250 260 284 227 273 261 234 234 280 233 257 266 291 243 297 250 246 266 269 261 264 277 286 246 247 257 234 264 271 273 272 258 239 289 242 230 255 262 261 268 265 245 267 282 245 232 265 260 229 241 228 268 257 226 257 270 278 263 270 275 264 259 237 244 246 237 226 269 261 277 267 223 272 233 257 225 263 228 256 236 257 264 259 250 247 283 249 265 267 270 241 235 239 266 240 272 232 279 256 239 255 241 296 247 261 225 274 246 266 213 257 266 236 233 256 248 246 244 240 271 290 261 244 267 257 217 250 263 232 261 277 238 275 256 259 243 248 217 264 222 292 229 280 257 310 264 243 269 272 276 226 272 241 243 246 248 260 246 256 244 237 256 232 241 220 222 286 260 248 235 242 248 288 233 261 236 261 229 234 267 278 247 266 244 285 256 240 255 273 217 247 248 282 256 229 255 284 246 234 240 242 248 222 258 258 262 246 267 247 260 250 262 217 259 278 268 268 243 259 233 304 279 237 238 275 275 229 264 273 248 260 265 235 255 246 235 243 274 271 276 300 263 269 278 244 272 271 241 225 276 291 259 270 234 267 256 264 221 267 258 231 273 264 271 277 264 248 263 243 283 244 247 282 277 267 272 212 245 272 242 241 255 217 263 258 294 264 226 266 249 263 229 269 247 248 259 265 249 232 305 239 247 247 234 230 255 277 258 244 277 247 277 281 296 238 282 237 245 237 246 230 229 230 236 248 234 265 267 223 246 261 265 274 272 229 257 224 249 249 243 275 259 280 229 248 258 223 243 232 263 232 256 260 255 235 273 264 259 232 249 283 258 260 244 275 248 246 246 233 255 248 266 250 268 277 265 230 230 229 248 273 264 263 230 275 247 247 266 257 281 240 271 268 267 259 261 281 222 245 258 245 269 262 225 271 270 271 261 263 219 235 237 281 247 256 257 273 245 263 234 280 223 233 267 256 280 258 244 287 270 238 258 286 235 259 233 247 250 263 268 248 233 270 264 262 241 256 281 268 226 210 245 236 284 264 276 283 247 275 224 261 295 270 267 297 269 258 275 235 247 255 238 270 286 227 267 231 274 240 245 245 242 270 235 279 272 227 217 257 238 236 235 245 274 245 274 247 294 280 281 233 247 262 262 258 246 228 246 255 291 236 243 265 267 244 283 286 270 293 255 231 220 229 266 245 260 245 285 214 243 264 292 272 273 269 271 245 282 240 247 243 243 261 244 250 240 263 248 277 268 260 236 256 248 258 255 281 272 225 270 246 242 239 281 262 269 261 231 256 271 265 244 245 209 240 238 237 285 266 242 234 239 263 249 242 268 279 264 241 247 218 278 295 265 268 263 257 230 281 263 234 259 267 228 279 276 270 257 266 272 235 243 277 270 279 287 236 260 271 276 238 270 247 241 273 274 245 232 270 271 261 256 260 226 260 284 260 265 280 267 250 247 248 262 276 257 262 233 240 284 255 228 236 239 248 257 239 300 234 243 262 243 284 240 248 229 231 279 276 278 256 246 261 279 270 266 288 278 248 242 236 287 260 282 241 268 274 257 244 240 291 245 271 256 256 274 233 266 257 238 260 264 247 285 258 217 271 242 260 237 256 249 283 256 273 246 222 284 221 239 271 229 231 217 245 266 259 242 237 229 258 295 270 259 258 246 245 306 236 263 255 271 247 229 279 228 270 246 268 243 256 263 245 255 280 250 278 214 236 246 266 263 228 232 227 231 247 262 264 283 275 256 284 239 262 277 245 248 268 270 261 220 246 221 259 262 273 243 269 256 242 255 273 261 240 244 272 256 238 286 266 240 245 279 250 258 229 273 237 262 292 279 262 259 265 231 264 227 255 234 266 247 284 257 247 262 279 270 219 274 259 222 272 274 255 243 239 281 256 237 260 282 244 239 234 257 311 266 244 250 271 274 265 212 262 255 274 226 234 255 261 257 238 256 279 243 260 270 241 237 277 264 230 276 281 255 272 268 274 243 262 232 266 269 244 260 238 239 259 262 239 240 255 271 266 235 236 245 229 263 269 237 246 278 272 256 245 275 272 258 272 238 258 244 258 246 267 245 238 242 262 278 280 259 261 263 271 247 233 261 245 241 261 243 282 274 256 265 243 242 264 228 264 238 248 246 247 279 249 259 276 214 224 240 227 277 250 233 237 266 241 269 259 231 269 260 235 262 279 227 286 267 219 256 259 231 228 256 270 248 248 272 260 271 257 257 273 239 250 265 262 241 263 255 246 237 276 288 266 263 240 278 224 234 237 249 228 240 256 265 270 220 264 269 265 234 246 226 269 245 255 282 247 233 264 274 233 274 262 230 270 264 227 271 246 246 256 240 256 265 262 255 243 264 260 241 256 239 243 262 270 256 263 243 259 246 256 239 264 261 245 240 270 232 285 237 244 241 267 262 262 225 242 274 283 245 260 260 232 223 240 240 244 261 299 293 237 296 221 219 227 239 269 238 258 231 260 291 237 276 268 269 260 255 264 247 255 238 234 234 243 233 203 250 250 248 277 257 276 267 279 266 274 259 258 229 240 255 266 276 273 233 237 272 219 229 249 246 236 241 244 246 262 230 267 264 228 246 263 267 271 278 222 210 234 218 267 237 225 230 236 289 262 296 236 260 266 248 233 227 242 219 247 258 268 250 241 268 257 236 256 239 234 259 241 275 271 256 260 255 216 240 241 243 240 282 261 269 277 278 255 282 233 226 245 229 243 265 277 274 274 227 235 276 266 246 293 263 241 248 287 248 240 247 250 209 270 247 219 248 235 247 234 276 244 249 258 256 216 255 258 274 287 227 246 262 212 233 249 249 262 263 242 231 243 288 289 260 241 266 277 222 255 271 267 243 262 256 239 238 261 234 263 243 233 263 226 256 264 240 225 255 258 221 261 238 258 270 225 257 245 265 236 265 267 265 271 246 239 232 269 248 270 244 232 295 258 240 267 233 240 249 226 243 256 211 265 256 266 248 282 257 240 265 268 268 291 239 261 261 250 275 239 247 290 255 236 267 260 256 236 276 259 274 235 248 278 264 257 270 256 238 255 243 249 279 293 234 244 263 292 259 231 263 248 235 289 264 242 220 249 288 282 267 219 247 290 265 261 281 265 280 255 287 230 274 282 228 246 258 237 247 268 257 244 247 259 231 289 248 272 245 235 227 230 260 238 258 242 266 235 236 224 255 274 274 273 256 244 247 276 256 249 267 226 274 238 265 230 276 277 224 244 211 243 237 229 220 265 245 238 236 257 237 234 273 245 274 245 246 244 271 242 266 267 247 265 255 267 268 256 257 272 277 239 278 247 243 264 249 277 245 242 241 272 240 298 220 264 245 255 267 260 228 240 240 248 240 300 269 265 275 243 248 243 274 242 264 239 239 266 279 269 264 300 244 246 255 266 285 267 267 248 232 244 217 298 273 270 281 229 268 260 256 244 260 287 270 249 270 275 246 234 308 290 276 244 227 250 264 271 258 241 233 249 231 245 267 292 269 205 276 258 272 271 232 256 218 257 283 272 279 247 248 256 263 255 256 277 226 277 266 295 268 283 269 264 230 249 319 237 281 250 292 262 239 248 255 267 259 278 285 293 297 282 243 262 280 248 271 279 257 261 211 283 245 247 265 275 285 268 241 286 275 260 289 280 265 258 281 282 288 266 260 272 288 266 236 270 269 282 292 247 297 280 278 279 276 287 270 294 308 267 244 264 271 240 260 281 267 274 263 263 258 259 291 283 285 284 272 268 287 256 261 277 293 309 258 285 261 274 285 287 263 248 282 276 270 262 229 288 303 235 243 281 265 292 271 282 247 239 290 259 260 264 274 257 262 246 249 284 264 256 279 270 286 243 282 276 234 240 279 302 247 242 272 256 273 275 264 258 274 234 255 271 255 239 271 269 262 268 277 276 263 278 295 247 291 267 238 247 270 283 255 257 278 266 261 248 247 261 232 259 275 259 304 273 229 239 271 266 234 264 257 256 241 262 245 264 225 269 281 276 236 280 260 270 263 239 246 266 279 280 250 241 273 271 284 278 267 232 260 243 247 281 245 257 257 256 239 248 242 247 269 280 242 256 256 273 221 245 271 234 270 274 263 265 247 246 260 263 281 272 286 235 248 287 293 246 298 250 261 261 257 268 283 269 260 278 268 264 286 287 282 241 261 256 260 249 231 272 284 237 266 283 268 239 308 247 275 247 265 259 264 255 255 228 274 268 274 267 268 277 255 245 230 239 290 260 293 288 262 279 223 288 262 261 260 298 270 243 267 256 265 273 239 283 240 235 265 273 250 277 272 257 244 250 277 278 278 230 275 250 245 263 292 289 286 255 288 279 266 268 262 262 288 276 300 229 263 266 256 258 268 267 271 288 234 258 247 274 276 285 225 257 241 244 271 239 267 266 267 263 274 284 236 262 307 248 241 281 221 270 294 249 264 246 264 263 250 239 245 240 237 278 282 228 233 283 266 263 238 236 233 286 240 238 268 302 256 275 245 238 230 247 281 271 243 246 228 273 267 249 231 243 285 257 286 283 237 247 274 236 257 239 277 259 261 227 267 265 296 240 248 267 266 240 273 290 244 247 272 257 236 269 216 241 259 249 264 262 247 265 268 258 262 243 265 247 265 261 236 263 272 273 278 255 295 285 274 231 279 264 263 256 245 242 280 279 262 284 264 260 285 265 240 285 249 262 262 288 276 260 284 235 238 244 282 295 256 281 262 235 243 246 270 300 248 263 238 243 241 266 256 248 221 265 257 232 265 249 262 296 266 283 262 285 259 274 279 271 236 287 245 287 282 262 256 265 297 234 247 271 272 235 312 269 258 233 283 274 249 278 276 238 258 256 267 250 276 242 237 272 255 292 296 249 281 257 257 273 243 262 264 248 257 242 266 295 282 266 261 239 248 263 264 265 248 287 317 249 275 282 279 229 288 285 263 245 269 263 261 231 296 266 248 285 245 276 246 307 304 243 261 238 246 231 246 279 255 264 279 277 274 281 266 241 281 249 258 270 248 274 281 231 287 283 265 247 276 278 256 271 274 270 268 273 258 267 237 248 288 270 310 261 299 262 283 278 246 296 273 278 268 245 277 297 260 289 264 220 242 267 266 243 236 266 283 256 242 256 250 262 279 278 297 263 247 260 250 293 255 274 260 267 261 281 281 230 249 262 279 273 262 249 267 260 289 276 273 273 274 292 273 265 256 276 258 257 278 244 257 236 290 267 269 262 256 261 275 259 281 275 248 257 285 270 275 279 269 277 270 287 227 302 245 244 235 262 273 244 241 287 283 263 249 258 257 249 256 242 273 271 264 279 256 256 237 259 264 268 275 301 272 291 290 264 261 275 271 274 236 257 261 264 259 261 261 278 282 282 264 291 279 289 269 261 264 272 269 310 248 238 269 226 269 286 272 271 245 236 258 293 245 271 261 272 267 284 268 272 268 292 272 245 267 276 266 258 272 261 244 294 257 240 257 231 272 265 228 266 287 291 232 221 275 262 291 287 299 279 270 278 245 246 283 261 256 276 278 276 268 249 261 281 281 238 256 278 244 236 242 271 269 273 256 261 260 272 234 247 244 264 285 281 289 224 258 290 249 260 261 290 304 276 258 274 266 274 284 270 281 287 236 269 264 267 256 294 239 274 279 263 270 268 274 257 283 282 269 273 269 236 273 269 271 242 263 290 230 267 276 283 281 260 274 261 249 263 247 266 255 255 264 261 274 281 268 250 279 279 262 263 299 257 293 271 265 269 236 277 244 240 274 245 263 264 275 270 266 295 243 291 238 243 275 272 257 273 265 241 282 271 302 264 282 287 278 218 229 265 257 235 264 273 248 248 264 245 289 288 285 258 269 257 272 247 265 289 258 307 275 271 277 284 283 281 304 249 274 287 269 273 275 273 289 270 271 293 270 269 267 230 224 274 244 280 244 255 266 267 270 261 292 275 263 244 272 269 281 263 291 261 278 266 290 273 244 264 273 276 261 247 281 283 256 269 266 268 237 286 281 272 264 264 233 283 263 271 246 237 259 235 264 271 230 247 274 261 256 247 232 273 289 271 264 263 259 310 282 262 300 298 257 286 261 270 291 281 243 275 217 238 299 268 257 277 274 265 275 230 272 292 263 258 248 266 268 296 229 279 303 255 264 287 268 244 250 232 261 273 275 260 249 278 234 275 284 307 241 271 282 271 275 283 257 288 268 265 280 249 257 243 261 280 276 267 245 278 280 277 281 275 268 262 283 263 285 244 257 282 261 246 270 271 274 258 227 266 275 261 274 243 262 276 259 270 299 247 307 255 285 278 248 258 257 270 262 303 276 270 285 250 259 276 260 263 271 257 280 268 263 262 235 268 276 281 246 264 283 286 263 238 284 232 260 265 222 290 284 271 274 281 255 307 300 291 257 303 282 257 269 287 247 266 240 235 281 214 276 249 275 278 268 295 237 276 263 249 272 295 261 257 219 243 234 275 277 279 263 272 277 257 263 286 281 278 257 288 248 272 248 238 263 272 256 256 289 261 243 239 248 284 268 255 267 276 247 280 268 260 261 243 276 278 266 266 255 264 272 256 289 260 276 245 285 235 282 238 288 248 272 244 268 270 237 244 258 271 269 277 282 229 280 256 274 280 281 249 264 247 237 255 276 269 257 259 284 280 235 283 284 264 286 245 268 277 261 271 262 267 263 265 275 276 248 283 236 266 257 263 261 268 264 246 221 262 226 274 276 288 248 271 238 279 261 263 267 255 247 268 265 273 297 250 258 267 247 264 257 276 250 265 278 272 259 272 259 263 226 260 284 236 224 267 256 283 256 280 289 268 320 248 260 266 247 263 269 299 256 274 288 261 266 282 257 282 255 266 269 233 276 266 275 264 248 263 292 237 283 277 260 257 262 266 229 267 240 299 265 279 280 262 293 280 236 291 274 272 236 314 236 258 274 279 257 264 249 248 273 257 262 249 270 257 284 285 228 260 259 265 276 261 248 272 280 265 261 261 270 245 291 263 277 256 255 255 263 234 260 302 235 265 222 245 263 255 258 275 275 263 282 241 257 238 263 273 234 278 276 290 267 268 278 270 286 258 294 266 284 262 284 281 300 205 258 271 267 255 258 262 255 270 248 248 274 237 271 248 264 285 285 265 262 299 274 270 284 263 264 265 268 270 284 291 281 242 261 287 266 277 258 246 228 276 260 260 248 233 278 259 296 264 244 292 266 300 281 220 273 286 260 273 267 255 264 238 261 247 224 259 236 271 237 293 263 298 277 275 265 289 255 259 257 275 266 275 275 255 250 259 290 276 269 235 293 286 263 277 276 268 279 274 277 274 259 272 234 279 266 292 259 283 278 229 244 255 285 232 245 277 293 266 312 249 274 264 272 274 271 283 281 281 275 247 244 249 247 289 241 276 241 278 268 269 286 286 245 260 288 287 263 267 270 240 271 250 277 269 261 264 266 262 286 278 256 267 246 236 297 240 287 241 296 286 298 250 250 279 290 277 265 264 231 244 275 277 277 267 299 277 276 267 243 257 276 246 265 284 273 259 265 269 241 243 264 260 235 295 274 292 318 256 272 271 246 284 293 294 268 273 310 248 268 289 320 242 280 271 278 279 306 307 278 290 283 269 273 261 285 323 265 288 278 286 275 262 301 270 291 306 285 303 290 298 311 282 300 329 301 288 290 303 274 291 303 289 265 336 298 324 304 328 308 321 283 291 297 314 332 319 312 296 287 326 299 285 323 282 286 306 281 295 305 301 281 273 323 300 302 301 271 317 274 304 259 287 317 315 306 278 315 289 305 285 282 291 264 288 302 324 267 285 272 240 281 278 250 277 282 296 247 281 295 274 265 269 279 274 283 283 270 243 312 239 283 258 246 262 269 263 270 277 239 297 285 277 267 272 249 259 271 264 292 259 255 268 273 274 268 293 295 261 245 272 272 225 266 264 282 261 270 281 292 236 266 227 260 239 301 305 249 260 278 306 287 277 281 257 257 248 282 236 266 239 265 245 264 259 265 285 231 261 258 242 255 278 275 248 250 276 266 237 269 263 237 274 267 236 276 247 273 276 257 268 268 277 274 271 236 289 241 270 228 262 267 234 292 265 255 292 245 244 276 256 266 279 245 246 234 269 246 277 221 256 272 261 274 272 279 269 241 244 288 288 264 232 262 243 249 227 267 232 272 282 263 238 235 281 301 211 247 263 267 272 288 279 247 260 269 268 275 241 264 248 228 235 258 272 284 245 261 277 273 274 279 237 243 240 263 265 268 271 256 258 256 257 247 262 232 275 262 274 272 242 263 261 258 315 265 259 238 245 283 287 281 231 280 258 258 255 263 220 271 296 268 245 240 239 227 237 255 267 257 265 233 257 265 273 265 266 274 246 272 258 248 236 267 265 247 261 225 281 278 245 271 261 248 279 279 269 263 246 263 245 249 261 220 244 231 266 227 243 279 269 284 270 246 263 236 248 274 219 280 231 286 256 274 260 280 267 240 295 258 260 245 227 248 260 268 280 238 229 248 217 257 250 271 242 212 260 266 243 266 232 225 228 263 256 241 240 243 264 258 264 239 244 256 273 261 258 237 229 269 243 281 247 232 243 264 296 237 227 245 244 219 240 238 240 259 258 240 215 266 297 239 243 234 242 259 260 227 258 256 235 284 247 272 261 237 256 269 222 237 247 277 282 244 223 247 275 237 245 265 261 257 260 282 268 243 275 249 228 237 283 271 263 259 261 239 238 278 235 278 245 234 250 270 235 282 246 247 278 247 260 247 258 284 236 295 241 229 270 212 248 264 238 246 209 268 248 223 245 262 244 245 242 241 246 243 270 239 243 222 229 238 296 256 279 238 288 259 236 238 221 218 244 232 256 236 268 267 232 256 243 236 216 273 255 248 267 228 279 249 268 261 275 243 255 270 235 233 257 241 230 256 238 270 271 226 257 264 259 276 240 228 276 274 271 239 215 285 245 232 220 264 264 277 216 266 263 234 234 245 264 223 262 259 240 260 222 221 226 245 243 265 233 263 224 249 278 241 228 282 265 271 241 235 243 229 271 242 272 273 240 271 233 233 231 244 272 248 262 247 275 241 246 236 233 244 239 243 245 247 236 267 244 262 262 234 255 263 236 222 264 255 241 262 233 256 266 249 234 242 257 266 268 245 255 236 245 256 246 272 236 255 247 239 229 244 244 248 247 249 264 258 257 238 273 240 291 274 249 233 256 257 267 237 232 223 240 262 262 230 278 238 218 260 266 259 242 257 281 258 263 255 257 272 267 226 233 262 231 242 255 233 235 266 228 238 248 273 246 248 259 238 260 241 258 267 222 269 263 256 263 235 241 242 242 239 255 257 259 240 263 266 259 265 257 267 217 256 245 267 270 222 265 242 272 247 242 230 229 248 255 260 248 264 270 261 243 232 227 283 243 274 268 244 240 255 261 234 267 243 261 245 239 235 269 259 237 243 268 287 268 259 257 255 269 228 247 255 259 265 263 248 248 247 240 262 255 248 265 221 258 245 250 222 263 248 239 272 244 255 257 228 265 245 267 267 235 236 242 290 277 238 270 255 258 233 240 232 215 271 264 267 259 273 248 266 226 241 247 272 264 258 245 237 233 246 258 247 273 240 271 240 269 271 240 266 257 265 245 228 242 237 223 281 242 234 266 267 231 264 248 259 239 242 277 246 249 264 245 266 249 260 260 217 221 260 283 245 224 290 237 240 268 241 262 280 260 275 225 257 269 278 279 270 247 242 280 269 240 272 244 262 258 255 249 248 284 235 267 263 241 276 240 237 270 257 275 259 292 247 268 276 249 231 282 265 246 234 291 245 246 285 249 246 258 270 244 271 249 277 278 267 246 225 259 247 260 261 265 271 237 260 267 268 240 271 285 232 249 215 248 221 282 247 255 242 219 287 270 260 276 229 247 284 234 224 260 265 246 224 266 247 247 259 247 261 249 268 274 227 259 231 240 275 224 218 248 270 257 228 269 276 220 201 290 243 247 274 286 278 262 240 259 244 263 248 284 256 238 260 268 238 219 238 233 285 264 261 260 248 260 240 273 258 231 276 240 246 283 271 257 219 283 213 258 232 231 265 276 256 227 290 269 263 279 277 240 236 268 267 233 246 242 244 273 272 262 242 294 255 260 236 277 255 279 232 244 260 275 300 278 264 243 266 226 301 279 277 269 282 265 269 224 256 257 262 249 276 266 247 279 283 249 258 272 239 292 261 260 261 263 287 247 258 248 255 246 258 256 293 235 238 256 280 249 268 249 259 255 240 249 268 235 260 242 271 259 260 206 269 261 244 262 272 277 276 246 250 248 258 228 265 223 277 212 231 262 230 279 240 240 277 271 246 259 276 286 269 248 288 264 258 258 277 246 275 235 275 270 255 270 269 246 288 260 234 225 282 249 266 271 240 240 261 294 248 243 258 268 248 244 269 240 231 239 221 260 255 249 260 270 262 291 247 273 264 263 270 213 270 298 271 277 260 241 280 240 265 260 256 281 244 237 263 261 227 286 244 243 245 270 257 227 270 240 234 260 247 236 268 263 312 303 269 255 255 222 262 240 259 273 264 241 264 258 247 295 265 280 232 259 273 260 243 267 266 246 266 280 257 276 269 278 262 270 250 237 264 238 258 276 257 255 241 243 261 237 277 256 278 283 257 233 266 278 241 289 268 263 272 240 266 256 245 242 256 219 277 260 279 242 232 225 243 274 262 239 268 258 259 295 258 259 265 278 235 245 279 242 262 246 272 234 249 274 269 225 283 256 292 248 264 279 243 225 275 258 224 274 224 280 272 269 284 239 233 243 245 283 274 248 243 271 257 248 270 255 266 269 273 275 242 284 229 239 265 233 264 265 245 246 238 215 249 244 232 233 231 231 256 231 267 235 272 258 246 247 270 289 246 261 284 264 258 256 255 266 250 258 266 256 258 310 266 269 235 250 263 280 273 258 257 266 277 269 266 226 232 230 276 274 272 236 227 232 267 218 218 262 271 283 261 273 233 242 266 258 270 248 269 250 266 257 260 272 260 244 255 259 270 267 276 261 230 265 264 279 243 283 245 264 249 235 272 271 285 265 261 260 241 233 267 224 271 238 265 277 261 257 237 298 226 275 270 243 266 249 288 273 275 248 272 270 269 287 256 269 270 238 247 277 285 244 282 242 231 216 263 279 259 270 250 257 300 249 262 231 287 287 230 287 239 241 241 231 241 281 256 238 227 265 284 272 270 261 235 247 277 296 269 256 256 263 269 287 277 242 259 282 244 280 238 244 258 279 220 245 257 290 243 285 239 234 261 289 270 257 292 290 287 280 265 259 273 233 265 256 264 239 274 275 257 272 256 280 242 225 284 273 266 286 238 295 249 247 273 234 243 256 267 310 261 264 287 258 262 276 243 276 258 268 261 284 248 256 259 275 282 278 293 264 256 268 260 242 239 233 248 246 301 259 256 273 255 256 268 269 276 270 276 291 278 281 262 290 260 257 273 273 270 289 262 268 264 270 286 279 279 284 281 247 276 248 276 278 256 331 258 282 246 248 270 271 256 256 311 239 256 273 270 232 257 257 258 285 261 277 281 236 257 294 281 263 245 247 262 266 262 265 270 262 283 272 266 267 276 299 267 295 286 256 264 265 275 278 272 281 244 274 247 256 276 258 283 243 270 277 291 274 256 272 281 272 256 246 277 274 289 270 247 289 243 259 236 245 295 288 241 257 276 265 244 279 304 257 241 260 245 288 256 264 262 318 245 242 263 262 247 279 217 297 271 238 246 264 267 282 260 244 266 247 278 263 285 261 275 318 276 238 263 234 247 245 237 247 248 263 258 265 272 240 235 295 231 238 281 275 224 261 264 264 261 270 288 274 240 287 264 263 285 259 241 264 233 266 265 260 302 277 270 280 266 237 266 266 284 268 264 269 261 238 271 275 285 256 283 264 263 242 276 260 257 246 283 269 283 272 263 287 273 262 247 248 247 274 272 270 282 238 260 246 256 235 244 281 290 242 247 275 279 248 238 263 267 267 272 261 264 227 269 287 282 261 278 295 295 227 247 278 246 267 265 263 243 286 258 271 269 269 259 278 238 280 272 243 244 249 261 297 264 240 259 274 278 260 269 265 249 248 261 255 255 240 249 270 269 256 272 242 260 246 260 245 250 255 259 250 282 275 281 302 304 257 255 272 262 271 281 270 245 227 243 258 311 236 239 278 248 297 272 239 228 263 256 270 261 278 257 256 243 238 230 237 255 240 241 263 243 267 269 255 273 259 233 273 236 235 271 260 275 279 300 230 290 241 279 243 237 258 272 248 295 261 258 237 259 276 283 239 261 255 294 271 264 301 291 266 295 262 255 260 264 296 243 237 283 278 256 280 287 294 245 243 312 274 245 284 258 268 290 243 245 268 244 260 257 259 282 248 269 264 260 255 272 267 228 261 268 267 243 268 246 266 228 255 265 239 256 280 256 266 271 280 266 217 232 283 244 277 242 277 242 244 275 245 256 244 285 257 208 284 263 248 281 272 242 241 276 267 260 240 283 267 267 270 283 274 258 270 259 271 255 234 275 272 266 267 291 273 212 244 264 262 270 261 263 258 269 271 265 235 237 248 241 223 257 260 210 300 283 287 268 271 214 245 255 242 256 288 257 267 245 273 265 256 260 265 260 273 290 229 262 241 245 245 249 244 234 259 261 235 266 264 240 281 244 268 280 218 264 281 240 261 258 257 244 250 277 276 241 241 264 264 278 246 278 255 271 248 267 264 266 281 270 262 275 268 255 262 239 258 269 290 274 261 242 237 250 211 271 270 279 265 271 276 278 249 255 262 285 261 271 270 264 270 247 248 222 267 265 281 266 232 263 268 240 266 258 260 277 264 286 264 280 260 246 286 258 264 258 234 238 265 257 256 258 255 274 287 226 278 206 245 285 242 235 287 259 275 276 240 255 245 255 245 265 284 270 260 279 246 302 261 259 262 262 259 237 274 260 274 241 247 241 262 241 268 247 277 255 271 261 279 264 263 248 286 246 282 245 260 232 235 270 196 283 271 289 270 225 288 260 250 242 259 269 271 226 282 244 275 242 261 276 268 243 246 279 257 268 267 249 241 268 296 248 261 271 292 250 247 272 256 260 245 262 245 243 249 246 217 283 225 259 246 258 259 245 273 259 239 293 244 270 256 241 259 242 303 256 276 245 271 234 270 246 259 242 241 263 261 281 228 249 263 247 220 264 249 269 288 272 248 238 269 242 277 263 259 265 259 263 287 257 268 269 231 248 297 255 284 283 284 262 241 265 273 247 256 271 281 271 240 273 272 275 269 260 257 242 277 261 241 255 300 240 279 248 255 285 259 245 241 240 237 233 255 241 267 245 241 248 274 232 226 226 275 267 245 248 247 262 225 244 271 263 284 266 259 247 219 248 258 271 259 249 264 257 284 276 273 265 228 246 258 259 249 291 275 284 234 263 283 267 269 239 249 291 274 260 261 265 298 263 261 258 268 265 280 276 248 294 270 263 290 278 263 258 262 276 265 242 241 271 269 258 228 261 243 256 271 262 274 259 258 239 281 279 256 261 243 263 281 242 277 256 292 276 236 242 276 271 267 239 268 264 279 258 297 244 262 268 262 258 257 268 266 235 281 271 219 269 284 279 236 267 266 274 236 282 248 238 266 256 271 272 279 284 260 243 277 244 267 248 293 296 255 270 302 257 262 244 278 255 280 268 261 298 266 265 260 256 269 287 263 268 314 248 259 272 271 269 230 260 278 274 243 238 260 289 296 288 256 265 214 249 278 265 287 276 236 230 278 271 247 263 292 273 300 256 242 261 269 257 273 285 262 239 263 244 249 267 236 242 299 239 267 261 280 283 263 261 277 284 262 260 248 239 268 273 243 264 256 285 274 294 282 264 257 262 257 290 287 274 230 240 261 255 255 275 258 237 262 292 244 268 247 261 263 244 243 300 299 269 249 258 298 273 276 227 244 248 256 263 208 276 271 236 261 270 291 289 262 240 249 259 258 245 240 234 283 256 272 286 247 279 259 258 265 275 275 281 271 281 277 248 277 279 218 237 263 245 250 273 261 288 264 222 268 257 277 266 276 249 266 290 264 268 289 287 262 265 265 261 248 270 269 278 259 273 246 260 279 269 228 240 237 261 243 267 237 270 247 246 250 263 262 243 263 232 241 273 245 244 268 266 256 266 244 256 229 255 257 236 275 232 243 266 261 245 257 257 264 228 247 272 263 271 261 271 259 239 247 256 225 264 267 257 270 276 267 262 274 259 267 258 263 266 241 262 274 247 211 287 270 284 262 290 248 269 270 244 276 238 260 241 272 264 274 232 248 287 256 284 257 226 268 259 232 283 287 292 257 224 302 240 256 234 298 263 259 226 259 233 245 271 258 276 267 232 292 256 261 214 280 279 287 235 310 244 244 275 264 256 272 240 255 271 257 272 217 234 244 264 274 259 269 263 234 238 279 237 283 288 284 226 262 270 295 247 249 228 244 271 256 231 248 261 242 245 295 288 258 248 260 270 247 256 242 248 247 238 247 279 247 257 243 262 259 236 261 259 268 247 238 275 234 269 263 230 240 265 289 236 264 235 280 219 236 271 257 233 262 241 268 229 261 223 244 273 264 286 239 249 257 212 280 241 276 257 259 277 269 259 242 236 241 258 263 222 262 229 229 272 267 230 240 242 243 268 240 244 287 236 247 266 222 245 265 234 269 289 259 262 235 266 235 245 242 250 273 272 274 246 246 241 259 257 236 278 256 268 263 234 279 287 264 241 266 271 256 247 261 243 295 292 249 218 268 290 249 263 257 275 235 259 264 307 259 268 246 269 269 258 243 266 279 242 270 268 260 259 249 286 258 258 241 263 234 246 242 274 246 236 248 234 267 281 220 245 263 258 261 299 268 273 276 269 242 267 292 272 280 262 278 278 263 248 259 262 278 256 263 267 260 263 285 235 259 239 249 245 295 258 243 282 247 242 244 242 260 267 259 266 259 256 244 261 260 241 246 248 263 268 237 259 265 247 290 277 271 279 266 283 276 258 224 261 248 277 248 270 230 241 258 239 255 280 243 300 273 277 247 238 255 232 224 247 257 259 274 260 292 247 256 261 220 243 275 269 275 268 291 272 248 268 273 277 256 269 265 241 286 278 241 225 257 235 265 238 275 285 244 247 258 243 240 259 282 237 286 235 278 296 289 290 298 274 215 263 248 278 276 261 266 281 228 222 256 264 267 258 285 233 267 268 241 278 276 234 261 278 302 275 242 272 280 265 226 243 265 272 266 283 266 266 275 258 246 255 281 249 275 277 245 264 238 271 220 281 247 272 271 278 277 285 247 263 248 269 289 275 287 271 294 277 294 282 269 272 270 276 297 279 258 313 240 279 286 277 285 287 289 259 313 256 272 249 277 311 276 284 288 275 245 312 259 294 255 306 284 283 285 290 276 285 274 305 258 261 257 262 295 258 259 228 293 266 277 268 255 313 280 289 304 266 272 259 266 282 272 279 296 286 249 265 280 289 298 265 284 276 287 292 258 284 276 275 292 303 291 278 272 263 269 304 267 282 266 265 298 291 293 285 301 286 294 260 296 264 296 271 294 266 278 290 273 282 270 257 244 302 285 274 313 287 282 288 289 256 298 280 306 296 277 244 268 274 250 275 274 259 280 282 300 286 244 282 279 294 289 255 274 278 283 276 296 281 283 261 258 264 273 246 298 275 290 267 301 256 288 243 276 277 287 277 257 268 257 266 278 229 257 290 287 288 298 244 292 275 261 304 240 290 240 282 264 268 250 280 271 277 285 248 257 285 280 266 261 297 255 269 247 256 296 258 284 243 295 273 312 275 280 259 263 260 281 260 298 265 246 244 245 277 249 293 255 256 268 265 274 273 260 281 261 290 256 258 230 272 267 262 258 255 264 261 278 314 292 279 269 280 264 260 272 265 238 259 249 278 234 279 265 258 261 269 282 292 284 243 273 271 276 244 256 259 271 260 243 289 277 276 222 297 257 256 261 280 281 296 243 297 258 230 288 272 303 276 244 235 281 248 234 278 263 272 265 244 277 269 282 257 270 227 271 247 283 292 283 266 264 241 277 264 263 284 285 294 245 264 267 246 272 298 249 257 269 268 265 287 240 258 308 260 256 299 284 249 285 266 271 294 268 246 286 261 247 231 267 269 293 273 263 275 234 262 306 248 267 297 276 234 275 274 278 249 243 270 270 262 265 268 260 281 280 230 272 275 267 248 235 257 264 234 244 258 242 275 264 239 249 259 271 308 302 258 272 266 238 243 243 259 303 234 265 235 285 282 263 264 278 243 286 265 264 275 241 243 246 261 261 298 264 245 228 278 238 290 244 243 273 295 264 264 282 261 272 269 282 286 285 279 268 270 283 274 238 227 287 242 268 257 285 235 246 262 240 235 283 286 286 228 218 267 276 289 260 275 234 245 242 268 276 266 233 279 260 273 285 256 261 263 248 256 259 277 257 243 249 274 275 300 248 273 278 256 241 295 262 223 238 268 221 280 280 270 255 268 263 274 263 272 276 294 304 238 245 266 259 256 244 261 265 236 238 288 276 299 265 289 266 292 248 230 259 259 273 244 276 284 278 218 303 267 233 287 260 243 259 261 265 275 249 265 257 274 241 274 302 287 260 279 256 275 277 273 274 266 258 258 279 244 270 290 258 267 257 273 278 273 268 304 287 250 278 280 278 278 305 281 242 281 272 276 256 285 269 278 258 281 279 247 285 278 265 265 294 239 268 275 278 246 271 294 263 249 228 262 265 279 267 264 291 255 267 286 259 257 273 289 242 294 284 276 284 266 256 275 273 264 247 275 260 262 258 279 268 261 289 248 259 246 256 270 272 255 243 236 287 243 248 256 264 248 265 264 271 235 295 279 228 238 236 270 267 281 259 264 261 241 248 269 284 250 248 291 270 295 245 266 274 292 288 226 259 295 263 274 300 259 262 256 285 276 249 260 243 277 261 281 307 265 281 261 264 288 267 262 277 268 299 272 249 280 267 264 261 277 285 305 246 269 279 268 247 273 292 286 283 275 285 290 243 256 244 235 265 264 268 233 255 286 303 242 297 255 294 266 265 241 264 244 273 255 248 267 282 239 256 262 285 250 260 267 258 274 265 291 247 239 275 264 273 245 290 245 255 296 258 246 270 264 294 259 259 259 279 249 268 258 232 306 277 275 278 256 245 247 261 256 263 272 289 294 239 256 238 258 266 248 279 244 229 228 229 279 260 233 232 249 233 257 272 247 239 273 286 263 247 260 261 267 272 300 262 260 266 270 274 286 262 261 238 290 258 259 235 261 255 242 261 263 243 246 249 266 273 267 277 273 247 268 269 239 281 289 265 263 260 255 279 246 247 263 261 293 258 234 258 237 255 275 269 257 244 240 222 239 231 230 239 262 249 275 246 279 263 278 262 244 265 265 235 273 242 290 274 261 263 243 281 318 240 231 257 258 292 248 256 270 286 286 284 256 247 257 237 249 262 266 265 274 278 262 287 302 268 276 258 269 281 255 236 263 248 242 273 265 261 274 235 269 235 261 261 311 277 269 269 221 258 262 261 244 258 267 269 282 250 265 300 284 266 261 263 247 274 246 268 242 263 265 269 256 268 298 235 237 264 262 262 284 266 246 277 243 265 279 280 272 270 256 259 257 277 262 263 267 282 264 229 247 272 233 279 249 266 255 260 261 248 248 241 264 257 274 278 245 249 281 278 286 298 248 270 240 228 259 264 302 247 281 276 243 260 256 226 282 270 262 266 245 297 245 281 238 228 290 239 283 241 234 262 261 243 228 265 222 275 288 247 262 276 232 231 268 263 265 267 296 272 266 231 274 256 239 261 264 270 256 259 294 268 284 267 260 279 244 265 242 255 240 287 268 275 286 269 257 281 283 264 249 246 257 246 267 256 224 266 246 247 269 217 262 261 259 282 248 236 236 277 278 261 232 261 218 238 267 264 265 239 263 284 285 249 232 266 265 262 246 244 274 256 255 235 255 278 261 256 259 267 280 278 277 272 272 246 268 275 272 228 240 260 269 234 275 266 277 289 258 237 274 235 273 282 250 246 235 246 290 260 279 228 244 269 262 235 238 268 262 272 264 283 240 260 269 278 257 234 261 260 277 240 267 272 265 269 256 232 275 241 286 257 274 272 291 275 233 262 256 260 273 278 279 214 242 232 260 255 276 273 255 240 274 265 278 263 236 269 261 283 281 288 262 277 242 264 268 275 248 298 233 267 260 275 265 256 264 272 264 291 272 241 242 268 236 233 229 279 261 256 229 255 302 247 268 289 232 275 247 282 243 275 282 267 271 245 255 257 240 229 255 240 279 264 231 238 269 247 288 272 247 244 257 275 264 269 244 270 273 269 274 262 292 282 249 225 258 273 277 278 278 283 268 227 256 267 257 312 243 263 276 291 269 257 220 269 291 234 273 279 257 288 237 268 233 291 282 242 260 239 280 220 242 271 271 278 258 284 245 258 279 248 275 267 279 247 285 268 284 291 272 249 281 248 240 277 246 277 243 243 288 284 260 242 243 272 238 261 256 282 271 279 263 250 257 273 289 239 280 275 287 302 274 262 281 277 245 266 257 272 270 232 264 298 259 264 272 233 261 257 248 244 242 276 240 269 264 261 245 296 268 280 264 246 266 263 237 267 295 281 305 283 274 274 294 260 237 270</counts>
			</dataPoints>
		</scan>
	</xrdMeasurement>
</xrdMeasurements>