File: data/XRD/_misc/glass.xrdml
<xrdMeasurements xmlns="http://www.xrdml.com/XRDMeasurement/2.1" xmlns:xsi="http://www.w3.org/2001/XMLSchema-instance" xsi:schemaLocation="http://www.xrdml.com/XRDMeasurement/2.1 http://www.xrdml.com/XRDMeasurement/2.1/XRDMeasurement.xsd" status="Completed">
	<comment>
		<entry>Configuration=Factory configuration, Owner=User-1, Creation date=7/8/2013 4:01:53 PM</entry>
		<entry>Goniometer=PW3050/65 (Theta/2Theta); Minimum step size 2Theta:0.0001; Minimum step size Omega:0.0001</entry>
		<entry>Sample stage=MRD Cradle; Minimum step size Phi:0.01; Minimum step size Chi:0.01; Minimum step size X:0.01; Minimum step size Y:0.01; Minimum step size Z:0.001</entry>
		<entry>Diffractometer system=XPERT-PRO</entry>
		<entry>Measurement program=C:\PANalytical\Data Collector\Programs\Jorrit\2thom\_absolute_2th-om_10-130deg_PIXscan_56min.xrdmp, Identifier={15BCCF57-2807-42BD-B5B9-ECC0B3DC9284}</entry>
		<entry>Batch program=C:\PANalytical\Data Collector\Programs\SimonL\batch6x_2thom_10-130°_z9.1_x0,10,20,30_y20,40_57min - Kopie.xrdmp, Identifier={8874E540-C3F4-4307-831A-CD55F073CDCD}</entry>
	</comment>
	<sample type="To be analyzed">
		<id></id>
		<name></name>
		<preparedBy></preparedBy>
	</sample>
	<xrdMeasurement measurementType="Scan" status="Completed" sampleMode="Reflection">
		<comment>
			<entry>_absolute_2th-om_10-130deg_PIXscan_56min</entry>
			<entry>PHD Lower Level = 4.83 (keV), PHD Upper Level = 11.27 (keV)</entry>
		</comment>
		<usedWavelength intended="K-Alpha 1">
			<kAlpha1 unit="Angstrom">1.5405980</kAlpha1>
			<kAlpha2 unit="Angstrom">1.5444260</kAlpha2>
			<kBeta unit="Angstrom">1.3922500</kBeta>
			<ratioKAlpha2KAlpha1>0.5000</ratioKAlpha2KAlpha1>
		</usedWavelength>
		<incidentBeamPath>
			<radius unit="mm">320.00</radius>
			<xRayTube id="1010048" name="Empyrean Cu LFF HR (9430 033 7310x) DK442154">
				<tension unit="kV">40.0</tension>
				<current unit="mA">40.0</current>
				<anodeMaterial>Cu</anodeMaterial>
				<focus type="Line">
					<length unit="mm">12.0</length>
					<width unit="mm">0.4</width>
					<takeOffAngle unit="deg">4.2</takeOffAngle>
				</focus>
			</xRayTube>
			<xRayMirror id="27010001" name="Inc. Beam Cu W/Si (parabolic MRD)" hybrid="false">
				<crystal type="Graded" shape="Parabolic">W/Si</crystal>
				<acceptanceAngle unit="deg">0.800</acceptanceAngle>
				<length unit="mm">60.0</length>
			</xRayMirror>
			<sollerSlit id="21010002" name="Soller slits 0.04 rad.">
				<opening unit="rad">0.0400</opening>
			</sollerSlit>
			<mask id="22030007" name="Fixed mask 2 mm">
				<distanceToSample unit="mm">220.00</distanceToSample>
				<width unit="mm">2.00</width>
			</mask>
			<divergenceSlit id="22010007" name="Fixed slit 1/8°" xsi:type="fixedDivergenceSlitType">
				<distanceToSample unit="mm">220.00</distanceToSample>
				<height unit="mm">0.19</height>
			</divergenceSlit>
		</incidentBeamPath>
		<diffractedBeamPath>
			<radius unit="mm">320.00</radius>
			<sollerSlit id="21010002" name="Soller slits 0.04 rad.">
				<opening unit="rad">0.0400</opening>
			</sollerSlit>
			<receivingSlit id="22010001" name="Fixed slit 4°">
				<height unit="mm">5.88</height>
			</receivingSlit>
			<detector id="7010017" name="PIXcel3D 1x1 detector" xsi:type="areaDetectorType">
				<phd unit="%">
					<lowerLevel>30.0</lowerLevel>
					<upperLevel>70.0</upperLevel>
				</phd>
				<mode>Scanning</mode>
				<activeChannelsEquatorial>255</activeChannelsEquatorial>
				<activeChannelsAxial>255</activeChannelsAxial>
				<pitchEquatorial unit="mm">0.05500</pitchEquatorial>
				<pitchAxial unit="mm">0.05500</pitchAxial>
				<readOutPeriod unit="seconds">0.135</readOutPeriod>
			</detector>
		</diffractedBeamPath>
		<scan appendNumber="0" mode="Continuous" scanAxis="2Theta-Omega" status="Completed">
			<header>
				<startTimeStamp>2024-10-25T23:51:14+02:00</startTimeStamp>
				<endTimeStamp>2024-10-26T00:47:20+02:00</endTimeStamp>
				<author>
					<name>PRO-MRD</name>
				</author>
				<source>
					<applicationSoftware version="6.1b">Data Collector</applicationSoftware>
					<instrumentControlSoftware version="7.0E 20130304">XPERT-PRO</instrumentControlSoftware>
					<instrumentID>0000000011142674</instrumentID>
				</source>
			</header>
			<dataPoints>
				<positions axis="2Theta" unit="deg">
					<startPosition>9.99826193</startPosition>
					<endPosition>129.99755682</endPosition>
				</positions>
				<positions axis="Omega" unit="deg">
					<startPosition>4.99913096</startPosition>
					<endPosition>64.99877841</endPosition>
				</positions>
				<positions axis="Phi" unit="deg">
					<commonPosition>0.00</commonPosition>
				</positions>
				<positions axis="Chi" unit="deg">
					<commonPosition>0.00</commonPosition>
				</positions>
				<positions axis="X" unit="mm">
					<commonPosition>0.00</commonPosition>
				</positions>
				<positions axis="Y" unit="mm">
					<commonPosition>-20.00</commonPosition>
				</positions>
				<positions axis="Z" unit="mm">
					<commonPosition>9.100</commonPosition>
				</positions>
				<commonCountingTime unit="seconds">32.895</commonCountingTime>
				<counts 410 386 384 372 341 398 386 411 392 443 382 377 379 381 379 360 383 405 384 377 414 367 385 375 384 347 386 373 409 426 356 395 374 377 394 378 372 386 374 401 376 380 392 374 379 381 402 378 375 408 352 378 352 411 377 391 366 341 385 380 370 375 386 393 379 374 359 399 412 394 372 404 421 387 393 393 379 370 386 363 373 361 402 353 374 365 380 383 370 358 356 361 378 389 376 413 409 358 347 383 361 404 386 380 374 346 378 358 337 378 391 361 358 367 367 402 348 372 375 358 365 341 406 388 359 351 379 373 383 362 359 379 328 366 358 372 378 419 393 352 340 372 357 357 387 359 417 367 369 378 363 376 338 389 368 354 358 371 387 374 367 373 360 354 375 384 368 379 389 411 362 372 345 325 392 370 375 383 376 393 356 367 400 375 318 372 366 388 355 356 332 389 370 361 354 373 384 355 360 360 370 363 363 368 370 378 365 329 385 370 403 385 354 392 377 354 381 359 333 350 359 374 348 350 343 383 406 364 406 365 353 369 391 357 365 349 385 385 374 346 350 407 312 350 365 394 347 367 369 345 370 352 376 345 354 360 390 376 399 367 306 369 362 375 353 330 366 379 377 357 343 337 371 388 319 365 356 399 380 351 339 370 385 350 365 357 363 342 370 363 363 376 373 325 374 367 377 358 349 326 343 368 325 357 390 392 383 362 320 350 335 349 351 398 344 353 350 377 376 367 365 323 349 356 340 362 339 332 343 370 349 378 365 364 349 322 318 299 367 367 358 381 352 328 354 378 350 355 366 346 372 391 340 330 362 338 347 344 345 378 307 314 388 371 360 340 347 334 341 354 335 338 348 336 368 349 348 313 360 371 364 350 354 305 340 338 333 348 387 382 358 366 392 331 365 349 341 324 388 336 345 363 352 357 341 337 397 319 347 297 382 325 358 345 348 359 376 345 392 345 355 345 385 375 391 358 357 360 320 328 389 348 372 381 391 344 355 321 329 340 373 370 344 336 349 340 362 375 356 334 393 375 331 312 356 371 318 341 308 316 382 345 318 365 370 338 350 321 330 366 324 373 358 347 338 355 340 319 307 330 336 322 382 354 318 347 374 356 351 341 353 369 346 319 340 342 334 358 339 343 330 336 338 336 338 331 311 335 361 361 329 337 347 330 371 344 334 338 359 340 376 363 363 345 374 357 372 340 361 364 354 312 347 350 320 346 386 345 341 324 364 326 389 334 311 340 351 313 356 338 319 340 310 346 325 360 374 365 347 370 340 330 328 371 334 352 329 342 371 349 342 336 324 293 373 358 364 334 359 350 341 372 350 335 350 339 355 342 342 332 317 371 355 356 325 358 338 339 367 353 363 339 360 346 365 342 383 367 339 365 302 322 337 354 360 360 308 312 361 347 337 347 347 340 364 345 367 337 334 340 326 333 355 348 319 347 366 342 342 326 330 334 369 363 344 407 350 335 363 317 341 352 313 337 307 318 338 320 348 390 345 372 343 352 305 340 341 338 356 304 348 337 349 367 316 355 370 335 366 362 353 337 353 355 306 357 354 318 345 311 345 371 344 349 356 355 300 320 336 332 314 371 346 316 362 338 351 360 335 328 345 351 375 383 319 366 313 355 340 359 359 392 347 339 340 324 348 336 353 370 316 368 332 326 324 330 327 351 337 347 333 344 358 355 336 363 374 370 335 342 306 356 330 329 388 331 353 351 309 350 320 319 341 356 321 366 368 362 358 322 363 373 354 355 334 355 356 365 373 386 340 349 388 356 370 344 384 378 374 368 352 360 364 388 363 342 354 339 383 354 338 351 352 373 324 364 351 335 379 330 365 316 322 306 323 358 384 347 365 346 312 338 339 366 334 346 327 330 352 333 326 338 319 349 334 331 353 341 339 337 341 360 337 357 341 353 326 326 367 351 333 340 336 348 346 295 370 349 318 331 315 342 366 364 337 331 321 318 351 357 364 345 337 366 354 328 358 332 340 344 361 372 359 335 351 329 364 332 370 345 364 355 363 339 336 319 344 356 338 318 369 362 348 339 350 314 331 360 339 348 363 353 349 368 383 331 355 355 329 359 339 347 374 332 361 324 329 335 348 360 375 373 345 330 363 333 337 376 345 359 366 365 357 372 347 364 344 365 323 383 374 337 338 310 329 348 370 357 346 351 394 370 387 380 332 329 405 405 350 359 367 344 347 347 323 347 358 320 348 327 381 342 343 350 352 343 370 351 321 349 377 365 329 354 364 339 338 376 365 349 340 373 338 379 374 342 372 357 329 376 362 336 327 314 330 361 315 404 354 327 360 325 362 370 378 388 353 390 374 341 333 345 343 337 369 364 364 355 395 369 347 325 357 371 387 370 331 364 388 395 350 378 351 329 353 325 335 359 365 353 316 348 347 354 360 346 381 372 328 321 324 380 361 347 366 357 388 373 365 339 392 371 351 386 347 361 353 365 385 384 403 371 348 389 386 326 370 391 385 336 368 363 375 383 351 364 323 406 330 379 370 342 364 378 386 342 356 334 367 350 353 325 344 371 343 377 331 370 409 374 378 382 390 367 394 369 371 353 356 372 357 393 379 363 350 377 349 401 388 352 345 351 370 361 330 377 340 389 377 409 374 379 356 347 373 359 357 358 374 337 392 346 368 383 363 379 364 351 370 382 364 344 393 379 362 397 378 347 336 369 336 352 425 352 382 367 363 376 419 352 378 334 388 371 349 386 348 331 411 364 330 361 345 378 362 366 331 344 389 380 388 359 366 380 364 366 395 388 384 392 393 350 370 389 326 361 381 388 401 375 351 361 389 359 401 390 370 371 390 366 345 395 415 358 379 353 391 367 374 373 332 331 384 374 384 366 363 389 356 351 338 404 366 394 374 374 389 394 337 328 374 356 353 358 369 347 369 349 339 367 381 395 373 365 409 332 374 388 406 381 358 358 373 365 372 362 393 383 407 383 373 354 315 344 396 365 302 354 364 376 338 363 354 376 346 356 389 360 349 367 395 364 348 368 384 359 369 358 349 377 334 387 366 361 354 350 360 352 386 390 358 354 353 361 362 368 363 347 377 328 381 368 347 346 377 354 352 320 345 357 363 365 352 370 336 355 342 365 369 358 354 385 340 369 349 385 337 340 340 348 369 367 343 336 344 378 372 354 392 333 352 381 365 381 379 356 337 345 364 360 367 352 357 333 356 331 368 324 342 356 340 373 336 335 375 339 323 332 312 344 344 318 345 336 350 362 346 350 351 346 372 339 344 354 345 339 353 347 339 334 331 394 343 356 361 368 355 354 374 366 349 391 326 328 374 361 342 327 358 327 371 315 342 309 389 335 322 375 347 340 332 334 337 337 349 318 334 360 329 353 339 359 330 322 334 310 336 340 298 327 347 346 323 348 354 355 343 347 343 370 358 334 348 345 343 341 360 329 307 327 333 333 329 348 334 357 356 338 356 334 338 324 344 341 352 336 344 353 356 315 311 347 313 320 354 310 368 306 343 324 333 343 373 348 309 334 337 351 354 363 353 314 336 318 361 339 315 313 323 300 342 336 342 324 302 346 337 343 306 329 365 334 323 337 358 318 325 316 331 310 325 342 338 321 325 337 341 321 306 347 311 328 329 344 362 333 341 296 373 325 337 348 293 326 353 366 317 318 351 316 345 307 323 329 331 364 317 333 349 333 297 362 310 381 289 342 353 330 324 324 311 338 338 306 308 332 328 313 328 308 327 318 310 344 311 335 323 337 325 309 300 322 328 320 334 331 328 306 298 345 314 311 345 341 315 337 299 321 341 356 334 330 334 303 319 341 339 353 311 312 313 314 328 317 326 312 321 342 330 277 306 346 300 318 319 354 322 338 315 328 318 289 324 331 305 318 288 319 326 340 288 292 309 295 347 307 289 317 306 299 330 352 323 349 329 335 316 326 311 313 336 317 318 296 294 313 283 336 329 335 298 310 302 339 327 299 322 279 306 265 291 315 340 321 282 325 297 337 301 278 348 339 317 288 288 307 288 302 318 270 300 310 372 283 326 319 328 287 317 312 336 329 283 291 291 328 338 308 299 314 309 323 327 306 297 330 323 298 276 314 288 345 347 311 299 275 289 309 292 334 325 324 325 299 331 322 306 285 308 283 294 302 307 317 329 313 310 300 306 292 292 306 291 297 312 331 294 325 281 329 298 273 342 279 354 322 325 300 310 292 343 301 329 302 321 299 320 306 313 310 288 315 291 300 311 288 295 290 321 361 317 319 294 297 292 300 306 277 299 323 302 322 263 284 300 290 286 314 278 301 295 282 297 317 287 309 306 286 310 268 293 279 307 261 319 302 277 291 307 298 280 285 261 283 303 273 291 276 286 276 287 293 314 281 296 284 296 295 294 259 314 304 281 303 296 265 259 299 294 316 296 300 274 295 317 313 322 300 283 262 284 263 293 302 267 285 301 291 270 308 273 296 239 296 297 304 294 300 307 309 278 284 306 294 275 291 283 283 286 296 255 309 271 296 304 285 277 296 284 299 264 301 278 295 283 290 302 299 301 274 301 278 276 274 299 272 290 285 316 268 306 311 299 277 282 311 306 283 288 303 301 296 295 312 291 275 280 291 269 275 284 267 308 295 283 317 276 275 273 286 310 309 290 279 304 290 295 300 277 286 272 292 274 320 284 295 299 272 269 310 269 293 274 269 272 249 299 299 294 250 307 296 273 278 309 290 276 292 288 240 271 274 308 299 279 289 276 294 303 273 270 291 291 291 295 262 302 284 282 282 318 271 271 303 330 309 310 286 257 298 295 294 291 267 268 272 295 274 307 266 276 300 269 289 277 279 287 273 266 296 275 270 279 246 258 341 277 269 300 289 262 283 286 270 287 283 311 294 288 287 275 270 324 271 247 275 306 284 303 258 301 285 281 287 295 241 258 265 275 288 284 295 271 283 262 315 276 304 291 258 227 299 296 275 279 273 303 284 294 299 293 302 290 257 261 262 261 269 272 262 290 277 307 243 284 288 271 285 270 287 277 281 262 263 271 271 275 272 258 300 262 296 281 279 300 279 295 287 256 238 287 294 309 301 259 291 279 290 270 289 285 268 273 297 236 273 273 286 309 262 274 288 262 296 270 299 292 274 288 269 255 284 270 269 274 290 298 297 281 280 317 286 296 273 236 284 244 238 278 295 278 272 275 255 262 275 270 288 263 273 264 247 247 283 312 264 296 284 275 246 268 263 275 238 249 286 270 243 287 258 269 263 258 276 278 270 245 290 250 277 271 271 234 284 258 296 276 283 261 278 271 271 303 259 239 246 287 269 255 288 279 262 288 310 266 292 278 236 277 258 273 270 276 289 260 267 285 286 248 244 255 269 281 282 304 278 278 273 292 262 299 298 277 307 257 250 246 268 297 263 281 241 267 258 270 271 273 266 274 264 250 273 275 308 264 255 258 266 276 259 258 270 260 273 283 277 256 273 272 266 295 296 276 237 242 257 250 246 299 269 269 296 238 282 285 267 269 262 267 271 271 266 260 269 276 270 288 274 213 256 277 288 259 287 280 264 263 302 279 267 273 240 269 303 270 247 261 288 259 283 225 297 264 274 275 246 245 283 281 286 269 284 286 288 216 290 276 266 240 273 259 278 273 259 271 293 270 261 287 307 255 276 255 275 288 258 269 255 245 295 248 272 242 275 245 269 282 281 260 249 271 273 272 303 266 270 235 284 267 214 245 283 306 258 239 278 249 281 249 255 245 267 297 237 272 286 283 271 258 295 265 289 287 288 269 261 245 292 275 261 255 281 255 273 243 265 212 263 259 245 267 277 267 265 238 268 229 275 270 285 284 235 266 246 240 220 307 271 269 289 244 307 273 257 263 248 300 261 269 240 266 258 258 270 259 270 283 275 276 250 270 237 269 257 260 240 297 241 256 247 269 249 275 276 235 237 284 224 286 296 259 268 283 241 244 256 259 256 259 273 230 270 275 260 243 256 273 258 271 255 267 249 264 267 255 267 264 290 281 256 255 279 273 241 285 260 248 262 249 261 276 236 226 276 271 264 271 293 294 292 265 241 234 248 278 271 262 268 284 269 234 240 237 219 290 260 270 258 298 263 278 241 284 262 244 268 261 298 259 260 268 258 270 273 257 277 270 260 268 272 261 244 249 228 285 264 290 245 264 262 269 257 239 266 273 258 289 280 259 275 261 234 250 239 265 269 260 263 268 248 242 274 276 258 220 234 260 266 268 262 258 248 235 274 239 245 265 266 218 226 248 257 263 286 221 246 292 256 256 241 269 238 246 302 250 232 235 265 262 294 270 223 249 238 230 240 275 273 265 259 265 267 236 208 299 259 275 247 271 273 232 248 271 278 294 279 226 223 227 278 271 256 262 269 239 303 246 224 250 241 257 247 273 246 265 269 236 287 270 240 231 261 241 286 273 269 271 221 278 271 258 249 281 250 260 241 264 273 283 244 265 248 234 237 256 299 248 269 273 269 313 255 262 247 279 260 280 256 267 237 279 278 266 283 248 265 249 245 236 293 278 278 245 241 294 257 238 248 257 270 264 227 285 282 242 243 235 231 257 277 256 259 258 242 262 238 270 267 280 259 273 243 285 272 280 231 272 277 245 262 260 247 261 240 243 281 289 249 266 263 257 266 245 280 221 264 261 280 237 270 242 267 277 261 238 238 265 235 282 263 270 257 257 260 281 267 269 249 278 222 288 258 269 241 247 275 288 255 278 234 275 267 279 232 265 286 268 264 262 267 256 247 267 267 276 275 259 259 277 262 245 257 258 273 275 279 268 244 262 244 256 268 284 273 248 249 257 257 268 274 292 292 276 259 247 260 229 265 229 243 268 248 266 262 266 257 287 260 231 272 247 262 272 277 281 223 297 258 263 267 237 287 248 281 239 280 265 266 265 225 285 271 288 239 248 268 269 279 273 243 260 258 232 280 260 239 242 236 278 259 276 272 261 257 271 236 270 239 273 261 280 242 257 258 273 245 257 246 265 231 286 256 216 271 261 269 270 277 263 248 272 278 287 238 240 267 271 235 232 259 261 249 268 260 290 267 282 242 289 255 245 257 247 248 248 244 250 245 287 234 267 243 258 261 265 250 290 273 283 259 250 237 228 245 261 234 249 299 255 235 272 240 239 239 276 265 274 285 281 241 228 243 283 281 262 272 239 303 280 242 231 248 241 277 295 264 266 263 224 281 255 244 288 257 271 244 247 258 267 266 260 271 272 271 246 261 272 260 257 263 239 277 265 275 263 279 281 232 225 260 276 266 286 244 298 260 269 255 217 265 255 276 261 267 248 234 289 245 259 264 228 282 261 256 291 279 281 271 248 258 270 236 266 266 260 297 264 272 263 241 296 295 288 275 304 258 281 273 278 241 280 269 276 273 276 271 280 268 248 288 244 279 272 248 284 300 272 275 258 282 255 297 281 264 277 285 269 261 289 267 274 273 256 256 233 276 275 246 267 245 275 283 287 265 262 265 283 276 269 276 269 271 246 270 255 248 276 273 283 272 250 319 265 262 294 263 258 242 262 269 263 246 270 265 270 272 288 259 277 273 242 275 303 264 268 269 260 291 261 270 295 267 291 281 268 229 272 260 274 258 281 258 279 278 287 264 243 262 283 283 295 298 277 284 258 260 277 284 294 307 263 290 243 263 308 275 303 286 284 296 267 290 283 270 294 325 274 301 289 297 268 308 292 242 268 276 291 303 300 302 338 282 272 299 299 325 294 296 299 277 265 336 303 306 317 301 284 329 297 283 329 311 322 329 306 340 315 361 320 321 329 331 328 337 334 343 361 343 333 367 388 371 379 378 360 374 446 392 418 412 423 446 441 455 492 466 472 497 500 498 501 496 492 525 536 528 549 559 507 559 518 548 518 468 498 498 457 482 473 445 440 450 425 420 439 422 439 402 399 395 335 315 349 322 331 344 348 302 341 322 302 312 291 304 337 327 284 327 308 281 261 311 291 296 302 300 278 288 313 270 256 297 294 310 277 307 283 296 307 283 281 266 290 273 311 275 308 280 281 247 279 279 268 242 292 294 263 301 266 293 268 292 270 288 269 259 263 283 302 277 284 258 272 257 292 274 281 277 279 281 288 279 269 232 266 264 292 270 267 296 269 290 295 286 288 285 269 280 273 280 248 269 289 287 255 264 276 266 278 231 255 260 277 283 227 303 277 300 241 262 303 268 292 273 258 259 274 273 286 293 280 256 246 250 290 262 246 273 267 248 249 286 270 260 260 278 257 228 238 285 271 274 219 246 265 247 242 277 276 273 282 272 273 268 291 237 279 249 296 234 265 250 291 276 263 283 281 247 244 258 297 248 291 306 276 266 247 258 256 248 299 276 272 287 255 284 289 281 278 288 296 240 300 258 285 258 264 278 278 241 282 238 268 258 266 285 238 248 270 276 303 274 260 292 277 284 280 268 268 247 258 266 260 263 273 265 241 277 280 263 266 279 264 264 285 281 249 248 271 272 292 237 269 264 268 302 260 261 285 271 289 259 267 263 272 264 257 274 263 260 259 271 286 262 241 247 276 269 249 240 276 270 283 231 259 247 273 259 274 292 286 278 284 299 279 247 259 277 289 261 292 257 282 262 244 274 283 277 281 235 297 274 263 262 264 260 258 248 257 256 283 257 230 293 281 295 283 248 292 273 267 270 283 289 283 276 243 266 277 267 257 279 286 283 246 285 277 264 237 228 278 323 255 239 258 270 242 231 302 266 272 239 289 247 237 286 246 242 269 235 284 260 268 291 267 269 262 280 240 225 270 242 292 285 274 271 267 265 245 280 261 284 275 259 265 282 278 265 270 279 256 275 259 262 267 238 243 248 269 245 262 284 238 269 259 256 264 270 281 264 260 270 267 283 266 246 285 228 267 238 287 263 263 274 261 283 289 286 265 265 279 245 261 315 280 264 255 265 271 246 239 268 267 270 265 282 276 232 271 263 289 250 265 304 277 247 238 259 262 270 278 259 267 249 283 264 255 266 287 246 258 247 241 274 233 305 299 256 267 257 256 263 281 237 302 310 259 276 240 271 291 224 246 265 270 274 263 223 271 237 259 279 270 268 274 261 279 244 303 269 277 281 243 291 260 261 272 275 263 244 277 262 262 284 258 257 249 235 242 279 267 266 288 256 261 241 255 266 298 286 289 260 257 266 222 243 273 280 256 267 259 268 258 259 220 276 255 249 296 273 255 247 245 261 259 278 271 283 245 233 278 228 245 257 233 270 284 258 266 260 245 302 270 259 270 272 267 291 232 284 255 233 274 264 245 219 267 282 240 277 258 256 259 235 284 228 284 286 268 257 257 275 265 255 279 257 237 272 241 271 282 277 282 261 241 264 235 270 248 294 256 240 255 255 263 246 262 269 248 279 270 290 268 281 237 243 260 244 263 266 240 246 267 278 260 235 276 230 283 265 235 294 281 241 274 242 220 261 240 284 248 262 244 271 291 266 293 270 294 257 227 245 291 242 301 293 256 261 248 295 258 247 272 272 249 275 260 276 274 237 266 245 246 224 281 272 241 228 272 233 257 273 281 243 260 278 240 313 259 234 228 263 273 265 262 271 298 228 276 238 304 274 241 261 291 281 258 234 277 301 256 237 246 270 240 262 283 246 275 246 277 265 285 236 239 218 232 266 287 270 258 282 231 244 262 270 282 270 223 258 276 257 275 298 243 249 305 263 250 244 249 267 259 264 234 256 265 258 265 244 226 281 234 241 269 234 288 274 287 275 269 246 280 255 260 275 236 232 289 220 237 256 273 240 246 267 259 243 255 257 240 240 244 242 258 248 265 257 264 258 256 270 231 260 272 262 294 282 248 278 241 292 213 284 276 259 263 264 241 270 258 272 249 244 283 258 283 258 271 272 300 266 239 305 274 277 272 242 265 255 263 283 246 265 247 237 270 226 268 286 271 269 219 293 233 274 264 267 241 230 281 240 273 249 239 269 248 262 259 235 276 249 266 265 257 237 238 247 233 238 240 248 260 233 264 241 245 261 244 261 270 300 255 248 227 247 239 289 220 240 255 272 264 237 221 244 244 245 281 302 277 237 241 255 275 236 263 273 276 263 256 237 287 270 264 255 257 240 277 250 218 247 270 257 244 272 246 244 233 255 257 276 240 239 239 261 239 270 232 267 235 282 297 260 278 265 234 247 271 259 233 243 255 264 230 298 260 250 261 249 279 229 275 239 260 243 280 255 283 293 244 241 248 232 290 261 266 231 256 256 248 272 285 267 274 264 272 236 273 230 241 258 248 260 256 223 241 225 235 249 244 225 269 258 237 265 236 264 265 268 275 243 257 240 285 224 274 247 280 269 287 261 239 260 262 273 259 286 266 284 262 225 265 272 269 225 265 264 250 263 239 284 221 270 223 298 241 246 276 271 249 246 260 308 268 269 287 286 277 228 273 258 263 243 271 275 257 270 267 264 260 291 241 238 263 250 261 282 236 268 257 263 241 264 227 224 270 227 273 268 216 276 238 265 217 262 243 259 260 256 256 233 202 257 267 266 244 237 224 236 266 230 276 270 222 292 280 271 260 240 229 277 275 241 255 267 288 257 249 229 226 218 228 272 273 242 256 259 237 301 271 264 226 238 213 273 227 246 256 260 286 239 271 236 272 262 279 266 241 263 244 240 273 266 262 269 260 273 290 229 246 261 259 276 291 266 291 267 238 273 282 240 262 266 275 266 188 240 260 238 278 236 259 243 267 255 245 235 247 271 227 233 243 276 250 278 266 268 282 247 249 276 261 275 271 259 255 263 244 236 264 266 242 244 241 279 244 237 218 233 285 242 246 229 264 273 234 281 282 244 256 245 265 245 244 263 258 264 257 244 280 245 284 234 238 259 244 246 299 243 265 273 245 225 276 263 305 255 273 228 260 260 258 281 261 243 243 226 267 241 260 256 239 262 274 237 268 277 240 257 262 264 279 256 220 245 291 282 271 259 274 265 266 245 236 272 274 243 238 247 264 293 271 259 275 295 212 249 287 272 232 285 264 273 245 266 222 228 248 245 257 255 255 258 233 230 264 250 242 283 244 264 249 273 284 245 259 232 239 258 236 240 284 240 271 244 249 259 241 264 239 241 275 273 284 245 274 235 263 232 278 232 278 259 232 239 258 249 267 242 271 268 236 275 249 247 255 247 257 244 268 271 248 240 263 263 276 246 273 223 259 250 274 257 262 245 271 257 272 257 263 255 270 227 243 242 246 217 250 242 255 267 298 258 282 248 255 288 279 278 278 237 269 222 243 239 272 288 242 275 266 256 268 261 272 266 279 239 261 274 267 259 244 232 250 268 246 275 273 266 271 238 274 266 272 274 240 263 269 281 269 272 239 275 243 282 262 276 282 269 275 270 243 294 243 268 267 232 249 248 243 225 266 249 239 263 267 248 267 265 279 295 270 287 241 300 258 271 272 260 270 239 247 274 245 265 280 279 298 280 240 257 225 264 285 276 261 232 230 284 260 267 282 245 289 292 276 239 292 241 279 264 262 268 255 271 256 272 255 276 234 273 269 228 243 249 261 271 249 239 256 297 281 234 248 262 242 270 260 263 258 237 239 270 248 273 237 229 257 270 231 250 269 231 263 266 265 285 274 241 263 266 256 259 240 290 241 263 264 295 286 275 265 290 248 258 246 286 267 267 263 262 270 265 259 249 247 269 260 286 267 268 240 260 243 288 301 238 249 245 284 279 241 265 258 237 258 248 271 238 292 267 261 256 272 231 235 246 277 257 238 255 271 273 240 262 262 237 279 275 258 268 272 297 270 273 272 243 258 236 240 278 267 243 296 278 266 236 265 268 236 232 241 276 276 283 242 280 273 258 281 278 278 236 269 271 266 232 262 263 236 266 278 268 249 248 262 275 272 223 237 258 260 292 277 287 287 289 244 241 269 300 288 284 282 255 224 279 247 229 248 237 266 273 281 281 239 274 233 302 290 242 260 277 247 273 262 282 256 244 287 279 244 276 231 232 211 267 282 246 245 264 275 244 267 269 272 259 269 243 237 281 267 279 273 299 241 281 269 248 260 295 275 235 272 270 280 256 269 281 267 275 274 312 246 282 282 263 272 236 260 269 244 271 282 263 283 259 310 238 289 284 262 273 290 255 285 264 266 237 263 258 277 274 268 273 255 281 284 242 259 266 283 257 241 301 246 237 274 275 293 299 264 278 274 264 275 285 258 240 267 249 293 264 249 269 242 257 260 292 266 256 273 263 258 269 245 290 283 292 226 265 263 287 245 267 287 242 268 268 227 267 314 289 239 319 278 304 258 308 273 272 284 269 258 246 247 248 273 282 270 276 241 291 267 266 247 265 267 235 217 273 277 225 282 268 280 287 241 317 259 286 258 262 255 256 291 263 284 268 269 274 267 240 272 278 280 244 283 259 255 276 275 275 241 240 290 285 286 288 296 284 292 246 257 291 274 264 262 258 280 291 271 257 260 265 255 295 271 281 265 249 273 268 274 284 303 244 278 281 285 297 301 264 285 269 298 315 269 284 289 294 260 264 267 265 301 292 296 266 275 304 269 280 261 280 275 275 273 240 284 268 249 292 240 265 235 276 295 276 291 290 286 261 292 241 272 288 250 269 289 274 303 290 264 239 246 264 205 257 274 306 263 246 241 287 269 263 256 293 278 246 257 275 260 261 262 262 266 262 290 272 274 296 271 289 290 282 267 260 286 300 270 246 261 246 273 246 285 284 281 270 269 244 272 240 303 281 268 262 280 242 230 263 240 274 262 255 278 281 249 255 261 264 285 262 262 260 244 278 288 266 235 285 304 269 273 238 263 292 283 272 273 256 286 267 239 286 283 294 242 275 242 277 288 280 247 228 266 275 233 279 255 266 261 242 289 245 236 245 265 273 244 269 245 264 278 288 259 287 281 249 267 276 288 274 258 256 260 283 278 274 239 265 274 297 273 262 281 276 260 284 275 264 257 227 271 279 241 277 283 297 263 294 266 246 266 267 264 248 264 278 264 283 287 261 281 239 280 244 271 264 277 257 281 236 259 231 258 271 256 248 247 266 264 266 249 233 283 259 268 259 284 249 248 262 266 275 300 290 270 262 303 249 247 256 268 262 267 256 266 266 255 266 281 247 299 256 289 246 267 260 296 256 224 264 281 303 264 255 243 288 247 261 278 227 248 248 310 256 287 242 283 271 242 263 285 279 249 228 299 257 267 281 265 272 284 276 268 242 269 233 268 267 288 275 273 285 260 292 261 299 265 231 276 265 230 296 266 257 284 249 278 275 235 258 280 243 264 286 299 248 285 266 261 275 277 273 285 258 241 263 277 243 279 261 272 268 263 241 299 249 265 242 255 236 260 297 258 264 244 244 268 265 260 274 269 269 256 257 279 272 271 318 278 281 297 268 258 275 259 247 266 264 270 291 261 261 232 278 261 225 266 282 289 270 290 281 257 256 262 270 260 256 300 266 285 281 244 261 264 257 239 269 278 285 264 264 270 303 244 265 239 258 258 295 226 287 279 273 245 289 269 273 260 241 255 261 278 279 242 271 277 280 263 235 292 283 285 273 248 272 266 292 264 244 299 279 275 271 247 264 258 228 272 274 240 271 266 256 271 289 283 295 235 250 244 290 244 255 288 280 268 293 270 277 267 245 301 278 258 265 274 268 256 269 220 236 273 264 224 293 249 284 268 261 290 292 234 262 269 275 260 261 285 280 276 282 286 275 274 269 280 266 257 257 255 243 269 242 244 228 247 265 268 240 270 272 281 283 268 257 279 267 261 262 285 260 280 282 259 257 260 238 266 285 255 274 262 305 270 268 238 284 282 245 262 269 257 239 261 285 256 285 268 236 289 267 233 263 263 258 246 259 266 277 267 264 236 261 268 267 261 249 284 259 268 270 279 271 257 265 247 256 292 280 286 280 259 256 263 264 235 255 272 264 277 257 282 263 277 256 258 228 268 259 277 288 268 263 259 278 281 284 300 242 266 261 262 257 297 267 229 261 255 259 279 286 280 285 287 261 258 238 240 255 244 284 276 236 236 230 278 256 255 255 223 264 279 270 256 245 258 259 264 263 221 265 278 259 266 238 285 269 268 256 246 241 267 255 283 265 243 269 237 278 263 260 267 277 271 249 276 255 227 274 237 236 270 244 236 257 221 270 247 249 283 270 255 259 278 267 231 270 273 262 264 274 293 281 263 225 267 267 266 267 278 223 273 285 291 275 266 257 273 261 273 268 234 269 241 280 282 260 269 241 268 263 258 246 242 257 262 275 273 258 271 289 265 244 243 246 264 268 271 278 260 256 264 280 284 279 280 286 279 244 249 262 259 243 249 236 302 281 266 268 255 274 222 267 249 247 276 281 264 280 249 261 263 248 242 273 279 274 280 298 279 274 226 274 264 263 265 258 266 243 269 256 279 269 285 268 258 242 286 280 246 258 258 247 263 283 289 257 245 281 263 270 268 244 235 290 265 246 247 242 227 291 268 291 260 237 259 311 276 286 258 290 287 292 288 274 246 235 248 263 247 234 310 226 301 240 269 237 249 284 280 242 292 282 259 264 282 268 281 286 247 264 261 250 277 277 265 277 266 239 275 258 278 263 267 229 265 247 285 259 255 258 240 237 297 277 278 266 271 274 265 282 230 290 273 255 276 243 298 223 274 267 257 268 277 242 236 262 274 245 259 262 247 282 257 267 313 246 278 284 286 256 282 256 234 282 274 283 237 275 271 286 272 259 260 279 261 260 268 256 271 262 278 259 277 240 256 247 263 311 279 239 247 283 289 276 256 278 286 294 256 262 259 266 270 278 257 258 250 248 276 242 286 264 246 242 270 282 262 272 256 266 282 262 259 272 271 284 266 263 255 238 223 237 222 276 280 263 283 245 287 246 236 257 261 241 246 246 266 256 276 225 233 266 282 270 244 260 289 280 283 261 261 289 287 264 241 276 274 233 284 272 274 248 238 256 277 234 247 262 272 283 288 302 259 255 297 249 265 245 292 257 261 262 257 274 257 265 267 266 259 248 280 264 260 279 233 255 279 271 265 260 255 300 269 272 265 273 267 247 285 267 259 249 223 270 275 260 257 262 282 272 274 288 234 262 235 286 271 276 281 262 278 286 274 256 243 257 238 267 244 223 257 265 268 264 292 248 266 246 236 245 262 263 270 280 235 274 257 285 265 268 249 312 262 260 233 297 269 264 243 262 256 260 256 236 270 242 245 256 273 262 234 266 268 270 277 285 268 246 261 265 259 242 255 240 294 291 306 240 273 235 242 264 243 282 280 264 270 275 272 231 271 278 244 246 260 261 296 285 267 287 240 270 292 250 284 266 247 262 283 268 255 261 258 288 240 235 257 288 259 278 233 242 258 245 274 269 288 237 266 269 246 265 262 286 236 261 266 244 256 282 288 263 271 272 247 237 231 287 240 281 234 242 256 270 262 261 267 259 269 271 273 263 235 268 258 239 289 274 242 243 241 267 248 279 297 246 228 241 264 258 263 273 244 277 255 243 281 281 261 265 257 266 244 278 258 256 247 246 271 272 279 257 289 238 269 216 246 242 261 244 257 242 264 224 271 261 259 263 266 270 229 267 270 247 234 284 283 270 274 287 242 227 284 257 246 260 259 278 269 264 241 264 244 247 238 268 266 255 263 231 261 237 237 262 215 267 255 274 246 248 250 247 268 286 246 241 272 282 260 270 233 273 247 278 264 261 266 265 260 227 273 260 243 227 276 271 245 241 277 278 261 231 256 246 247 238 265 266 263 241 230 275 274 260 268 255 248 236 267 295 241 241 246 277 228 255 255 248 264 275 266 261 275 250 279 256 245 283 268 224 249 243 241 250 249 284 261 238 288 308 250 244 228 276 292 244 258 225 243 282 264 245 261 261 239 263 236 274 270 256 241 303 241 231 273 289 240 230 277 274 278 244 272 290 267 293 257 266 257 264 280 255 289 275 245 263 270 249 283 266 269 275 265 260 232 246 247 283 231 278 232 235 267 228 248 256 299 274 260 233 262 259 291 250 257 273 274 231 283 258 234 256 246 257 241 271 245 262 274 274 236 249 263 250 263 242 247 244 258 269 233 242 266 243 291 249 299 277 266 241 277 240 293 263 258 245 230 273 291 264 260 263 246 272 244 246 294 277 278 271 274 243 248 274 264 271 273 265 246 278 274 255 301 262 285 277 258 264 256 271 221 238 238 247 242 277 274 267 260 243 256 284 267 275 234 287 238 270 276 246 266 266 281 250 249 286 279 248 242 266 298 229 247 243 266 285 247 260 275 262 264 243 288 289 307 285 286 262 282 261 264 264 249 265 248 275 241 238 249 238 275 263 275 267 275 273 263 245 272 274 265 257 282 271 279 281 287 284 271 271 273 287 280 255 280 309 259 273 282 310 278 261 255 285 219 290 277 294 261 275 283 265 273 280 292 300 291 301 258 286 233 294 271 271 284 329 290 294 289 294 298 284 319 291 312 299 296 288 301 292 308 294 289 321 285 273 310 317 297 283 314 306 314 322 297 297 247 328 309 307 323 276 282 271 263 280 318 301 276 270 279 287 291 284 295 291 260 290 263 298 288 302 273 288 287 268 246 248 323 289 266 278 264 274 287 272 299 265 277 289 296 266 291 284 272 275 277 256 280 274 270 232 244 277 249 236 239 285 281 256 278 258 270 281 276 255 281 283 272 287 269 239 294 277 277 234 267 287 235 262 259 245 262 258 269 273 259 267 280 269 286 270 303 278 242 247 285 244 265 270 283 259 255 245 273 290 245 259 280 268 242 241 276 281 280 236 226 269 248 228 236 260 270 268 246 272 237 273 282 256 250 262 269 274 290 263 219 267 265 273 271 260 262 259 258 246 258 293 273 236 264 282 250 247 265 249 249 208 279 231 281 232 263 278 248 239 262 238 227 268 282 241 255 282 295 228 278 280 250 275 284 260 283 281 269 250 258 291 273 289 255 268 235 273 286 234 283 276 245 277 268 268 245 290 218 210 258 262 230 267 277 266 247 265 264 240 249 249 259 239 259 282 278 265 268 282 260 264 263 264 227 277 266 248 248 220 248 260 233 285 263 260 270 287 262 221 238 264 260 242 272 279 223 274 235 236 226 272 221 271 270 264 282 275 247 243 276 272 267 247 235 273 268 263 276 210 255 247 225 250 287 269 284 258 241 249 243 256 266 246 269 271 248 258 272 240 238 264 257 256 243 262 274 239 256 259 259 261 264 231 231 263 238 237 279 265 268 266 260 261 261 243 234 264 234 294 249 256 240 232 232 241 277 244 236 258 266 267 240 238 258 277 247 249 262 246 272 248 235 276 276 236 248 256 264 244 258 244 262 265 285 270 276 257 242 285 260 275 269 238 265 257 264 267 261 293 261 245 243 267 231 276 277 262 241 250 244 255 260 273 232 258 245 259 264 258 264 225 255 247 260 271 261 276 274 256 245 267 277 240 280 231 271 264 267 241 273 264 229 246 227 226 262 241 265 273 227 241 216 260 267 264 261 272 248 234 256 239 260 272 283 243 242 255 245 244 259 248 243 256 274 243 236 235 234 261 257 241 261 260 296 271 263 213 245 275 271 278 276 242 212 219 230 270 262 257 265 243 248 248 275 259 224 241 235 237 243 257 225 268 261 231 238 263 264 213 259 259 258 263 241 245 263 249 268 247 249 236 236 223 261 232 255 257 264 267 228 264 231 248 281 255 238 260 233 259 256 270 258 255 240 248 240 247 245 261 281 244 240 203 286 255 262 243 249 232 275 289 268 243 266 275 240 216 248 233 237 260 235 244 249 266 242 248 262 227 230 278 264 277 232 280 256 247 229 268 266 243 224 227 248 242 259 230 235 276 240 228 279 224 278 264 261 267 230 250 243 236 263 245 249 263 238 246 256 242 271 263 230 247 257 236 262 258 240 265 246 275 242 243 244 255 236 259 257 274 276 274 258 246 269 263 243 221 242 279 237 231 233 257 228 244 262 233 237 260 256 238 246 238 227 259 248 238 259 256 286 258 234 248 243 227 245 257 264 235 275 258 269 243 258 270 235 261 241 241 240 234 257 237 272 260 230 248 260 249 261 261 277 256 265 225 260 249 241 256 222 231 247 217 259 269 227 264 238 221 266 258 234 256 260 234 256 243 276 259 247 239 243 247 269 217 237 266 233 282 255 244 273 214 271 263 286 273 286 246 264 258 266 242 261 241 262 246 263 258 261 256 266 258 226 277 255 231 273 263 248 266 277 248 237 256 263 236 256 283 221 257 269 275 259 263 260 261 234 236 229 260 259 255 250 229 225 270 241 255 226 264 261 235 270 263 246 248 245 230 274 265 278 261 246 215 241 269 267 233 245 264 246 244 280 255 241 236 257 248 279 268 208 267 275 223 220 225 233 238 262 261 262 269 270 267 227 272 266 231 237 274 248 275 262 242 275 217 225 230 239 245 264 275 225 235 243 262 247 258 273 256 222 279 263 281 262 232 267 258 269 280 221 246 281 278 259 243 241 261 256 267 272 246 238 258 263 237 281 244 247 265 279 245 245 262 261 262 239 267 233 274 230 264 255 242 218 242 259 242 263 259 243 237 257 243 260 210 256 232 300 272 241 268 258 265 244 219 230 294 249 265 276 260 231 258 270 277 265 233 236 231 241 258 239 234 260 268 241 269 258 262 281 226 245 226 274 234 280 241 238 287 214 249 265 247 256 269 264 269 264 266 282 227 256 293 256 248 262 301 273 234 270 240 238 232 230 242 257 282 240 255 224 274 263 236 235 259 245 263 261 263 267 243 255 269 266 241 246 228 235 257 247 249 262 235 236 256 258 257 244 256 249 257 257 246 273 292 271 234 248 278 278 250 280 223 229 256 240 257 240 274 272 276 267 256 239 266 247 228 274 285 245 273 274 265 262 269 232 220 272 278 232 259 227 219 275 276 248 240 277 241 215 278 273 240 279 283 269 258 231 249 285 238 275 245 276 257 261 244 283 266 245 231 258 240 240 242 244 246 312 263 273 275 262 258 244 255 226 242 279 224 286 262 267 271 245 232 262 243 225 241 264 266 271 222 236 229 257 246 293 239 257 240 228 281 267 256 265 240 277 255 274 259 230 241 227 267 264 241 273 268 246 279 239 271 264 245 248 269 227 247 243 264 284 259 284 255 247 223 256 248 224 238 249 261 266 277 261 248 271 220 246 243 237 257 269 237 231 246 242 238 256 241 225 264 241 214 241 244 220 244 262 262 265 229 245 249 244 273 278 239 250 280 245 226 249 241 259 267 248 235 237 244 242 284 235 244 259 267 226 240 261 258 240 233 240 232 257 265 219 259 225 265 260 233 245 264 265 238 271 267 246 245 247 246 220 276 231 268 224 260 233 239 257 258 266 217 257 230 260 268 239 235 286 246 232 220 230 228 288 268 262 223 236 264 268 235 263 239 271 235 219 246 247 248 258 270 260 277 255 243 261 265 223 219 243 236 267 261 262 282 267 230 238 262 242 276 265 262 244 259 265 247 266 241 260 271 258 244 245 268 237 260 255 259 235 230 240 259 244 234 262 281 282 243 290 276 267 243 222 255 236 266 241 260 235 245 256 227 230 250 256 276 239 298 242 282 242 249 246 256 273 263 228 238 261 237 242 222 260 260 256 247 291 280 237 233 243 239 235 264 265 241 234 255 225 258 263 271 261 248 262 257 255 267 250 222 239 259 264 272 271 242 262 222 278 249 239 222 226 242 240 263 257 222 270 248 264 245 264 229 235 247 279 231 266 264 248 255 271 248 230 227 274 233 269 245 228 222 256 237 234 263 245 258 240 242 292 287 246 246 257 246 279 255 245 238 271 224 248 239 260 278 263 232 260 257 256 235 274 266 240 290 237 246 236 229 273 242 257 281 245 246 257 273 264 255 245 259 247 265 257 248 275 261 269 272 261 275 258 281 258 266 226 227 273 264 249 238 266 232 276 233 271 248 276 225 265 243 296 242 275 227 247 263 278 256 265 262 269 260 269 269 281 283 230 245 232 262 246 285 281 257 271 264 286 225 231 269 240 244 246 261 248 264 244 284 275 260 218 248 246 258 294 243 286 274 224 245 257 238 264 267 263 256 257 261 275 237 244 268 249 263 256 241 241 275 242 260 280 241 240 259 230 267 230 239 225 274 219 246 246 240 240 234 261 271 245 269 246 271 270 291 267 270 255 241 235 247 258 237 219 238 280 271 257 269 222 268 260 237 248 232 296 260 260 226 274 291 289 246 282 245 264 305 296 300 246 229 249 248 263 256 270 280 258 284 278 283 304 258 281 268 279 283 262 265 268 269 268 267 278 283 284 265 257 255 249 277 258 261 288 275 246 270 243 294 258 288 287 255 259 284 260 245 257 273 240 277 255 255 240 272 282 272 270 269 271 244 248 271 272 276 267 265 264 276 248 255 260 289 256 230 256 231 272 247 248 237 277 246 257 260 265 237 261 255 272 247 250 273 233 272 267 280 266 237 243 271 281 287 246 286 264 274 261 241 233 242 271 258 266 255 271 241 256 243 271 262 273 223 257 275 266 246 274 256 262 284 279 213 280 240 224 260 217 274 240 268 274 247 269 259 261 267 262 250 243 280 231 264 260 260 224 234 234 238 237 230 239 271 249 286 237 295 260 256 243 274 256 231 260 249 267 221 245 241 234 231 271 271 222 264 273 261 240 240 227 278 228 241 257 266 261 232 243 227 236 277 244 240 226 218 255 240 237 257 244 217 255 246 256 250 257 257 227 259 260 239 229 259 244 242 289 223 240 262 238 272 218 248 235 259 239 272 261 274 234 256 267 234 241 242 241 246 276 249 230 221 268 247 291 266 250 245 248 278 262 231 271 245 238 273 227 250 233 248 240 244 239 264 207 264 246 265 243 260 271 238 287 269 273 244 238 255 280 257 230 282 263 265 244 287 263 236 224 259 286 233 260 249 227 248 249 245 240 267 260 233 229 256 268 248 280 233 266 278 283 272 220 272 227 239 230 235 259 261 246 233 241 273 232 283 241 259 212 257 262 228 248 211 230 227 262 269 245 229 239 259 242 262 260 266 229 266 244 245 238 241 260 227 236 258 244 230 230 265 287 264 283 243 242 266 274 242 221 217 268 225 262 248 270 232 268 275 261 247 239 226 242 243 233 283 266 238 264 255 232 222 257 265 258 270 263 274 264 221 270 211 308 244 273 248 246 239 209 271 238 246 258 228 256 232 248 233 224 224 236 272 242 227 257 259 234 256 238 239 271 265 234 241 269 257 260 218 246 258 245 235 216 240 248 267 229 287 249 249 243 223 277 262 264 235 247 270 231 264 269 215 229 235 273 234 235 260 237 263 232 256 271 269 244 226 239 224 240 247 244 258 240 239 227 246 264 250 228 272 260 207 244 232 268 267 267 242 247 240 241 263 227 257 239 256 229 223 237 230 287 260 218 238 227 263 261 241 258 258 241 247 232 276 264 219 280 242 229 258 246 233 233 232 258 244 240 290 269 239 270 246 219 230 269 243 263 255 245 212 236 268 267 273 241 233 280 218 279 241 269 257 259 263 237 213 238 217 259 245 270 246 213 255 266 237 279 269 248 272 217 237 249 241 268 269 263 244 238 240 242 255 265 263 245 230 274 256 272 263 289 260 261 245 237 241 266 246 268 236 272 272 255 291 260 230 240 280 244 224 261 246 244 238 264 256 244 248 256 256 241 246 266 248 262 268 276 278 234 270 298 268 259 277 267 243 237 230 272 263 265 247 242 247 260 265 259 236 295 271 244 259 202 244 261 263 275 269 273 269 278 235 237 261 275 255 248 255 257 271 238 226 255 279 236 259 237 209 256 242 275 209 271 273 258 265 260 238 245 269 242 240 258 261 290 269 269 238 232 239 259 235 233 256 232 239 246 265 246 261 260 248 255 241 229 267 238 259 225 244 227 285 247 243 255 273 278 264 281 242 265 301 261 263 271 230 236 263 269 260 225 225 232 235 259 259 228 240 261 238 274 264 276 285 275 244 276 241 270 261 287 280 248 273 275 268 264 280 246 264 232 259 232 269 258 229 216 281 257 300 243 259 239 277 278 236 241 239 247 269 262 283 240 279 238 257 276 258 226 240 276 259 223 274 250 249 277 246 268 245 249 235 261 240 230 264 261 273 278 270 243 277 280 230 296 245 275 249 258 269 275 255 268 259 226 256 247 237 265 255 275 259 238 257 268 236 274 283 264 265 246 259 232 268 244 281 274 250 279 249 242 258 257 241 263 264 272 261 283 248 262 246 247 233 250 222 276 224 264 247 271 266 246 292 265 241 244 230 241 268 245 275 273 280 287 261 281 222 265 260 262 255 272 246 224 257 216 266 275 246 259 262 238 246 236 283 244 244 271 245 248 263 259 249 258 240 238 290 280 242 269 237 261 255 271 243 274 218 295 248 247 236 274 255 234 288 255 285 228 267 245 265 275 229 232 300 246 301 238 263 261 260 244 233 263 266 261 237 247 293 255 260 232 223 235 258 226 239 263 248 244 272 231 248 224 249 267 245 266 260 259 244 247 243 249 273 259 279 236 246 221 225 264 215 255 222 260 275 267 227 222 248 247 259 232 242 303 214 261 265 309 246 277 267 279 228 257 224 240 288 263 244 230 280 271 239 282 267 238 263 267 282 272 272 256 274 267 267 220 242 277 248 241 227 274 258 265 296 243 244 234 244 275 256 225 269 240 279 265 271 275 266 230 262 269 257 276 283 260 262 256 248 270 227 275 244 249 247 267 245 262 241 234 234 233 245 247 244 248 267 299 237 265 249 265 255 269 234 284 274 244 256 237 246 216 277 248 243 243 244 233 288 259 242 229 232 282 268 258 246 288 263 278 280 240 247 290 272 281 263 239 241 266 250 238 274 262 274 245 260 280 237 242 260 242 265 245 239 262 258 264 262 256 276 242 266 279 282 276 249 235 274 259 234 237 238 269 268 260 241 263 261 273 260 239 260 277 234 275 261 257 265 277 248 258 242 248 268 264 267 259 243 242 264 247 275 224 259 268 287 243 290 237 248 283 284 290 287 239 240 258 237 241 248 243 258 245 268 269 320 265 256 268 276 249 285 267 225 264 229 277 264 247 275 246 259 247 281 242 243 290 276 277 240 274 260 239 273 271 289 238 248 274 242 255 265 217 258 274 245 261 267 270 220 238 241 264 240 282 226 241 285 261 267 233 244 269 243 255 257 277 263 284 255 279 241 281 263 265 268 259 241 237 232 245 259 271 262 282 226 269 247 245 279 266 236 267 265 244 236 268 262 256 246 269 265 265 258 273 260 235 243 248 248 246 298 243 224 258 246 275 235 262 262 244 245 259 279 257 283 260 224 248 282 265 255 258 277 243 246 248 232 216 236 238 226 266 280 245 246 258 284 236 273 248 243 245 265 235 243 224 262 244 237 246 261 260 274 226 268 237 262 250 260 244 273 264 267 265 265 261 263 245 257 234 215 257 246 286 218 269 265 286 258 271 234 280 255 260 220 245 248 248 274 223 260 270 244 260 267 266 259 223 242 221 258 275 232 238 268 290 249 263 246 261 297 262 280 265 273 242 232 274 240 262 268 241 243 226 238 229 266 229 284 264 250 244 248 249 245 257 271 237 221 266 266 282 258 245 256 232 217 266 249 242 265 235 230 263 259 266 231 236 211 248 273 234 261 247 231 256 233 259 276 257 262 278 269 227 226 271 256 231 266 236 225 226 219 247 275 255 256 246 248 246 231 268 259 239 275 239 300 267 264 214 225 237 243 235 258 249 287 242 239 246 279 245 260 261 265 249 260 258 266 249 268 257 227 234 261 241 227 266 279 234 246 265 228 267 241 233 247 256 291 260 218 256 255 267 256 265 284 280 245 257 242 240 259 255 258 266 245 259 241 289 243 236 285 266 244 248 281 247 240 243 250 268 257 274 238 266 268 227 246 258 238 280 237 224 266 302 238 230 282 228 247 261 267 263 242 245 273 249 255 267 273 242 239 240 266 249 273 245 246 304 249 270 267 239 280 290 283 264 264 266 257 273 264 266 280 283 249 274 234 272 265 265 263 255 259 289 262 275 258 257 268 288 232 284 260 244 260 261 267 270 258 262 267 268 255 295 280 247 241 265 257 243 291 238 274 269 243 289 264 227 270 260 269 259 257 235 269 245 237 268 223 289 257 263 268 290 285 287 267 266 274 256 262 305 284 290 255 303 273 267 279 267 327 290 307 245 307 271 261 262 283 263 283 294 256 284 280 284 267 279 271 282 263 297 281 295 284 256 267 282 306 274 289 266 243 283 261 279 263 281 281 281 286 288 268 273 277 266 261 265 277 264 241 258 265 268 290 300 265 279 292 263 285 294 261 290 250 280 257 273 288 248 288 304 262 287 246 246 260 263 299 267 289 235 293 313 261 271 291 279 264 265 246 241 269 247 305 261 295 264 258 246 262 241 260 242 277 270 248 262 248 276 258 245 255 265 295 264 257 275 258 288 298 268 238 256 263 239 273 274 276 285 257 279 239 262 240 260 258 248 271 235 246 237 266 291 264 270 269 272 293 240 263 275 257 266 261 231 286 265 273 239 242 259 288 283 247 249 243 261 266 279 267 260 293 259 249 271 247 244 237 294 247 245 243 257 270 258 264 270 276 235 258 238 230 272 238 267 243 273 257 234 248 238 264 237 248 265 234 280 248 275 256 270 260 239 242 281 280 248 236 230 259 242 250 265 245 235 281 278 250 276 239 234 266 265 239 258 232 283 266 244 267 237 237 275 247 261 243 229 230 245 277 276 278 255 257 219 243 261 235 237 268 245 245 268 245 255 246 273 280 231 267 280 244 265 243 231 226 273 260 279 259 255 246 259 239 271 242 216 281 285 273 246 231 264 222 224 237 242 277 258 263 242 271 263 220 272 265 259 246 234 289 243 223 246 227 233 276 248 240 246 286 243 245 273 264 237 261 259 240 240 235 260 246 244 295 262 276 210 229 235 232 238 246 225 273 248 245 269 280 265 246 259 222 270 238 231 255 239 259 270 233 274 263 263 232 241 249 270 245 270 265 268 255 268 255 236 247 239 258 238 250 261 222 277 238 249 261 262 265 257 237 238 233 212 260 237 259 255 242 247 249 249 289 273 240 249 243 290 275 249 223 243 240 205 276 262 275 247 257 245 285 273 241 260 235 309 219 239 239 245 278 238 270 234 243 249 246 281 255 276 267 263 231 270 248 247 258 249 248 274 241 239 267 261 264 240 281 239 236 239 257 211 261 255 275 242 288 247 218 265 233 238 245 245 274 275 267 244 291 248 270 266 243 220 257 226 226 289 258 271 240 279 218 256 270 282 273 293 246 266 250 268 271 259 264 266 250 224 256 243 243 285 234 307 273 237 262 265 247 265 246 281 267 261 262 269 241 247 271 243 275 222 228 276 257 224 247 235 260 240 246 241 264 224 289 261 236 246 235 235 239 293 224 249 217 243 258 259 274 242 269 278 270 272 285 243 272 259 245 241 258 239 230 245 268 285 238 256 272 255 255 264 263 237 274 269 272 272 215 219 262 295 255 257 295 283 276 222 258 294 259 257 285 275 259 249 221 226 272 231 240 263 263 279 265 286 230 245 282 260 262 273 240 276 234 271 274 270 258 278 270 256 257 255 256 255 264 247 261 305 262 272 275 259 264 257 266 278 247 273 286 261 229 258 279 258 282 250 294 250 255 273 290 262 275 247 232 266 240 271 294 247 268 241 248 235 236 256 248 283 266 242 237 248 271 265 240 281 271 264 236 230 259 293 263 266 271 265 240 276 235 285 228 237 258 241 266 281 271 218 286 258 245 267 263 246 267 255 259 271 278 265 258 275 237 280 243 248 246 259 258 237 247 234 271 250 234 291 274 283 281 255 235 280 263 242 309 267 272 267 268 233 282 279 261 288 249 263 239 290 257 265 242 284 270 242 274 258 265 256 233 250 248 288 273 261 276 259 241 276 270 204 256 280 271 240 261 246 231 277 289 248 257 274 289 267 273 248 285 255 244 282 278 256 236 260 257 245 257 262 255 271 278 285 293 280 247 255 258 281 255 262 273 271 236 299 268 267 264 279 248 281 236 264 281 255 255 240 290 292 255 259 284 221 256 258 272 260 263 264 267 235 279 261 238 256 243 272 277 262 299 229 230 246 242 248 280 234 219 256 244 267 282 266 263 232 267 248 265 284 264 275 237 266 241 273 234 247 234 270 232 259 249 267 248 246 258 285 279 240 260 256 284 250 245 239 259 270 248 238 271 239 243 245 268 264 278 263 272 275 271 233 290 298 268 276 278 246 265 249 239 272 246 275 240 261 272 260 237 263 249 227 288 267 277 257 246 270 277 248 265 248 278 256 307 275 260 259 232 249 261 258 271 269 246 245 224 249 264 255 236 267 270 277 219 263 272 263 238 244 248 264 258 269 312 266 275 275 248 284 276 244 311 244 222 233 260 270 247 248 235 244 292 279 277 281 261 265 275 269 284 236 241 269 239 261 265 228 266 277 244 262 269 262 232 226 296 241 284 239 264 269 272 261 265 261 228 299 284 261 262 276 245 233 245 239 274 271 230 245 269 244 260 235 258 249 272 232 258 271 267 229 274 256 235 266 242 246 265 278 283 261 258 267 259 258 238 241 261 219 232 275 272 237 291 275 266 237 236 261 266 263 268 261 284 233 261 257 268 292 255 268 233 240 235 276 262 275 259 263 248 263 241 258 240 262 245 266 267 283 272 264 240 244 233 249 243 257 266 260 222 232 264 257 255 275 274 267 255 256 256 244 203 274 249 258 277 236 246 232 241 262 274 265 243 221 260 255 275 275 232 303 282 236 269 237 284 230 239 269 276 250 273 237 279 225 257 225 238 279 249 225 238 269 262 267 263 258 227 240 267 261 259 248 232 268 270 241 257 275 234 243 244 244 288 266 248 248 230 241 264 282 244 266 227 262 261 263 234 278 280 246 277 247 270 258 268 246 256 217 237 258 286 282 259 248 255 261 264 288 223 245 272 276 266 273 244 261 241 249 261 286 276 257 239 273 249 241 237 262 260 244 264 237 293 246 279 273 269 266 246 309 259 261 248 258 218 261 247 262 231 241 264 255 283 263 244 308 290 273 248 236 239 273 260 259 270 287 277 273 249 259 237 244 263 234 234 260 266 272 275 266 249 221 272 268 262 243 259 247 281 228 258 258 264 258 285 234 281 272 241 247 244 266 265 238 259 279 242 236 241 285 275 275 214 262 265 266 284 258 280 284 280 267 273 241 272 268 265 255 241 274 287 273 266 298 261 241 278 256 257 258 274 267 238 249 273 290 263 261 279 263 267 246 273 269 264 259 265 245 268 262 290 264 259 295 243 248 269 245 260 240 242 245 269 240 216 291 246 271 282 224 288 232 260 242 236 249 264 264 276 255 239 247 260 245 269 269 271 279 279 269 259 262 270 272 260 260 247 249 264 262 264 233 263 269 260</counts>
			</dataPoints>
		</scan>
	</xrdMeasurement>
</xrdMeasurements>