File: data/XRD/_misc/sampleholder.xrdml
<xrdMeasurements xmlns="http://www.xrdml.com/XRDMeasurement/2.1" xmlns:xsi="http://www.w3.org/2001/XMLSchema-instance" xsi:schemaLocation="http://www.xrdml.com/XRDMeasurement/2.1 http://www.xrdml.com/XRDMeasurement/2.1/XRDMeasurement.xsd" status="Completed">
	<comment>
		<entry>Configuration=Factory configuration, Owner=User-1, Creation date=7/8/2013 4:01:53 PM</entry>
		<entry>Goniometer=PW3050/65 (Theta/2Theta); Minimum step size 2Theta:0.0001; Minimum step size Omega:0.0001</entry>
		<entry>Sample stage=MRD Cradle; Minimum step size Phi:0.01; Minimum step size Chi:0.01; Minimum step size X:0.01; Minimum step size Y:0.01; Minimum step size Z:0.001</entry>
		<entry>Diffractometer system=XPERT-PRO</entry>
		<entry>Measurement program=C:\PANalytical\Data Collector\Programs\Jorrit\2thom\_absolute_2th-om_10-130deg_PIXscan_56min.xrdmp, Identifier={15BCCF57-2807-42BD-B5B9-ECC0B3DC9284}</entry>
		<entry>Batch program=C:\PANalytical\Data Collector\Programs\SimonL\batch1x_2thom_10-130°_z9.1_x0_y0_57min.xrdmp, Identifier={37E1D15C-4BC3-4D9E-A700-45BC264E77A4}</entry>
	</comment>
	<sample type="To be analyzed">
		<id></id>
		<name></name>
		<preparedBy></preparedBy>
	</sample>
	<xrdMeasurement measurementType="Scan" status="Completed" sampleMode="Reflection">
		<comment>
			<entry>_absolute_2th-om_10-130deg_PIXscan_56min</entry>
			<entry>PHD Lower Level = 4.83 (keV), PHD Upper Level = 11.27 (keV)</entry>
		</comment>
		<usedWavelength intended="K-Alpha 1">
			<kAlpha1 unit="Angstrom">1.5405980</kAlpha1>
			<kAlpha2 unit="Angstrom">1.5444260</kAlpha2>
			<kBeta unit="Angstrom">1.3922500</kBeta>
			<ratioKAlpha2KAlpha1>0.5000</ratioKAlpha2KAlpha1>
		</usedWavelength>
		<incidentBeamPath>
			<radius unit="mm">320.00</radius>
			<xRayTube id="1010048" name="Empyrean Cu LFF HR (9430 033 7310x) DK442154">
				<tension unit="kV">40.0</tension>
				<current unit="mA">40.0</current>
				<anodeMaterial>Cu</anodeMaterial>
				<focus type="Line">
					<length unit="mm">12.0</length>
					<width unit="mm">0.4</width>
					<takeOffAngle unit="deg">4.2</takeOffAngle>
				</focus>
			</xRayTube>
			<xRayMirror id="27010001" name="Inc. Beam Cu W/Si (parabolic MRD)" hybrid="false">
				<crystal type="Graded" shape="Parabolic">W/Si</crystal>
				<acceptanceAngle unit="deg">0.800</acceptanceAngle>
				<length unit="mm">60.0</length>
			</xRayMirror>
			<sollerSlit id="21010002" name="Soller slits 0.04 rad.">
				<opening unit="rad">0.0400</opening>
			</sollerSlit>
			<mask id="22030007" name="Fixed mask 2 mm">
				<distanceToSample unit="mm">220.00</distanceToSample>
				<width unit="mm">2.00</width>
			</mask>
			<divergenceSlit id="22010007" name="Fixed slit 1/8°" xsi:type="fixedDivergenceSlitType">
				<distanceToSample unit="mm">220.00</distanceToSample>
				<height unit="mm">0.19</height>
			</divergenceSlit>
		</incidentBeamPath>
		<diffractedBeamPath>
			<radius unit="mm">320.00</radius>
			<sollerSlit id="21010002" name="Soller slits 0.04 rad.">
				<opening unit="rad">0.0400</opening>
			</sollerSlit>
			<receivingSlit id="22010001" name="Fixed slit 4°">
				<height unit="mm">5.88</height>
			</receivingSlit>
			<detector id="7010017" name="PIXcel3D 1x1 detector" xsi:type="areaDetectorType">
				<phd unit="%">
					<lowerLevel>30.0</lowerLevel>
					<upperLevel>70.0</upperLevel>
				</phd>
				<mode>Scanning</mode>
				<activeChannelsEquatorial>255</activeChannelsEquatorial>
				<activeChannelsAxial>255</activeChannelsAxial>
				<pitchEquatorial unit="mm">0.05500</pitchEquatorial>
				<pitchAxial unit="mm">0.05500</pitchAxial>
				<readOutPeriod unit="seconds">0.135</readOutPeriod>
			</detector>
		</diffractedBeamPath>
		<scan appendNumber="0" mode="Continuous" scanAxis="2Theta-Omega" status="Completed">
			<header>
				<startTimeStamp>2024-09-11T09:22:50+02:00</startTimeStamp>
				<endTimeStamp>2024-09-11T10:18:54+02:00</endTimeStamp>
				<author>
					<name>PRO-MRD</name>
				</author>
				<source>
					<applicationSoftware version="6.1b">Data Collector</applicationSoftware>
					<instrumentControlSoftware version="7.0E 20130304">XPERT-PRO</instrumentControlSoftware>
					<instrumentID>0000000011142674</instrumentID>
				</source>
			</header>
			<dataPoints>
				<positions axis="2Theta" unit="deg">
					<startPosition>9.99826193</startPosition>
					<endPosition>129.99755682</endPosition>
				</positions>
				<positions axis="Omega" unit="deg">
					<startPosition>4.99913096</startPosition>
					<endPosition>64.99877841</endPosition>
				</positions>
				<positions axis="Phi" unit="deg">
					<commonPosition>0.00</commonPosition>
				</positions>
				<positions axis="Chi" unit="deg">
					<commonPosition>0.00</commonPosition>
				</positions>
				<positions axis="X" unit="mm">
					<commonPosition>0.00</commonPosition>
				</positions>
				<positions axis="Y" unit="mm">
					<commonPosition>0.00</commonPosition>
				</positions>
				<positions axis="Z" unit="mm">
					<commonPosition>9.100</commonPosition>
				</positions>
				<commonCountingTime unit="seconds">32.895</commonCountingTime>
				<counts 256 303 239 237 272 270 258 299 288 261 243 257 245 264 286 264 263 249 245 281 238 228 261 256 269 240 244 273 280 259 236 283 234 239 278 257 289 258 270 260 259 273 265 231 269 250 267 266 261 280 264 267 287 243 246 279 265 273 243 235 291 279 256 255 292 285 243 279 233 237 266 296 262 242 238 268 210 256 245 222 223 282 244 282 260 265 265 277 276 256 261 235 246 256 240 233 247 300 245 268 266 263 255 219 217 263 235 279 245 258 248 261 258 238 267 249 261 264 275 259 275 244 244 261 236 245 257 278 256 269 242 289 263 233 277 234 241 244 221 278 260 258 274 273 234 224 224 275 204 264 272 237 232 265 242 258 249 226 213 244 227 239 226 247 234 228 261 262 236 230 264 264 262 248 231 257 261 214 222 261 217 235 260 260 217 242 248 226 233 272 240 213 245 212 236 244 234 232 218 225 236 232 229 207 225 237 295 279 225 197 220 265 224 229 242 236 222 261 264 236 244 242 228 260 264 278 237 236 255 247 237 255 230 234 234 239 240 233 231 234 259 242 219 240 264 221 237 248 235 249 222 236 231 256 246 256 227 234 238 220 216 205 209 231 247 210 241 220 217 238 202 241 219 216 240 236 258 225 266 245 208 247 243 227 270 219 225 244 228 232 259 219 234 224 257 235 232 233 237 227 231 202 217 234 269 260 237 223 245 240 222 215 214 276 231 214 264 214 220 207 213 235 224 210 200 208 222 213 226 230 219 234 228 238 246 222 206 221 203 226 218 216 242 218 221 228 206 221 231 235 232 216 207 226 202 216 262 223 228 207 224 204 213 222 213 217 213 198 218 229 230 221 237 230 234 195 235 185 226 214 226 191 206 208 219 227 210 231 242 217 207 211 216 229 198 202 218 223 224 241 240 229 215 210 218 196 229 219 227 219 229 218 212 208 207 223 217 207 219 214 233 219 210 215 228 207 219 205 194 188 218 214 195 215 212 227 219 202 235 210 208 213 212 226 240 201 206 211 209 224 244 245 246 235 192 224 210 220 213 206 191 209 201 205 197 188 239 226 205 203 195 211 212 212 217 186 221 233 198 212 212 234 196 219 196 225 227 219 186 220 234 212 216 212 213 189 216 216 212 218 182 194 200 208 223 218 204 218 183 225 212 229 211 229 215 224 225 201 179 227 225 210 227 210 203 215 203 213 219 221 234 221 219 211 198 205 213 207 233 208 199 203 228 222 206 208 212 210 229 210 178 223 229 211 226 223 200 216 229 188 221 223 191 216 206 213 217 216 202 197 215 197 194 201 208 199 173 221 198 205 215 178 231 216 204 191 185 218 223 202 193 195 225 216 212 210 226 202 212 196 192 212 209 192 183 196 188 218 196 195 213 206 204 191 216 195 218 186 219 196 218 205 228 195 232 198 212 229 208 217 210 206 211 213 218 212 207 212 227 193 197 206 226 213 232 174 219 217 201 207 188 202 204 181 190 226 240 181 211 210 214 214 226 200 226 201 184 187 189 208 204 175 195 198 198 191 191 205 215 186 192 196 212 219 211 186 193 204 211 204 207 221 216 219 215 206 198 215 211 225 201 201 164 194 217 188 208 197 202 215 194 175 198 229 227 215 188 204 207 199 228 174 229 213 219 192 218 200 204 212 225 191 180 201 192 210 210 212 207 224 222 202 220 191 200 205 202 221 198 212 199 206 218 217 200 186 215 204 196 183 222 178 210 233 205 193 204 213 197 206 211 215 174 210 200 201 186 190 245 231 208 198 195 205 212 185 196 245 206 195 188 224 209 195 218 209 213 186 208 191 208 196 224 213 209 198 221 187 181 192 197 226 198 172 201 185 189 192 217 201 186 211 184 199 238 208 186 195 232 184 212 201 189 200 196 216 206 196 176 187 208 204 198 204 223 211 204 170 204 185 185 197 203 205 215 196 193 205 208 210 211 205 195 199 216 197 198 242 220 192 183 197 205 192 193 194 209 209 193 197 198 195 205 195 201 210 196 193 207 203 199 202 210 207 217 197 185 209 195 187 186 211 204 196 194 221 195 205 199 216 203 209 210 181 199 189 219 176 223 201 204 177 212 193 198 173 173 224 210 183 193 187 202 216 196 226 180 193 190 196 177 183 203 193 229 190 193 215 201 199 223 221 198 207 174 200 188 227 181 184 208 180 179 216 214 214 175 211 194 193 202 175 175 203 205 214 205 201 197 171 178 199 196 187 226 213 210 216 211 196 212 202 204 172 200 182 199 182 174 208 181 222 199 199 200 185 209 206 215 194 205 241 198 178 189 206 194 188 190 191 204 200 184 203 192 189 187 171 168 213 206 159 224 201 219 184 193 194 215 195 213 195 182 210 193 203 202 191 221 214 209 189 188 187 208 208 181 199 196 217 201 199 223 229 200 202 204 204 181 188 224 200 208 208 226 198 188 214 198 207 204 190 208 223 194 191 232 194 213 186 219 188 213 214 204 215 184 190 195 201 189 196 205 212 210 206 213 194 181 230 200 197 220 208 205 183 219 184 203 213 201 219 190 217 200 214 184 190 210 221 199 200 206 200 219 184 209 162 208 173 198 225 178 211 203 201 209 218 184 188 180 209 215 196 212 212 186 204 204 208 187 236 210 204 215 215 192 206 215 182 207 217 187 197 181 214 193 220 199 210 199 184 207 188 193 220 211 197 207 205 204 212 209 199 200 201 176 188 197 192 204 181 230 204 172 209 205 205 201 184 184 206 203 198 227 226 197 226 225 182 188 208 222 191 188 178 225 225 191 191 227 165 210 189 230 188 198 209 210 201 188 221 184 175 204 205 203 216 197 193 229 205 218 200 203 204 187 208 206 184 190 195 201 213 220 209 217 229 194 210 173 202 190 201 198 201 202 191 193 227 193 201 205 198 194 212 189 192 186 213 206 218 183 188 189 210 205 205 219 193 200 191 186 200 214 208 216 213 224 198 215 202 216 217 197 170 181 190 205 199 201 240 206 202 218 216 190 197 208 214 180 171 180 198 196 207 223 202 206 193 209 213 186 217 223 187 207 186 217 186 219 201 195 198 192 196 210 215 236 194 205 202 203 219 218 209 210 207 219 228 201 200 193 170 198 209 198 220 191 221 206 202 197 192 182 205 210 210 209 168 217 199 188 200 211 195 185 217 203 180 191 196 186 205 209 186 197 209 239 208 197 197 215 213 215 196 219 216 210 194 176 182 211 212 200 215 205 188 198 206 191 208 174 213 192 205 197 196 209 217 217 212 219 219 209 220 185 206 180 199 218 226 219 200 209 204 212 208 219 192 200 224 214 202 194 226 210 198 208 222 181 197 208 230 208 210 199 255 209 192 196 195 187 212 188 216 220 219 182 192 202 196 216 210 221 189 214 211 234 203 177 216 216 214 202 200 195 197 206 221 237 196 204 177 186 191 207 216 194 221 205 197 204 224 207 194 210 222 232 206 208 213 192 200 202 212 218 164 212 192 221 231 207 198 217 211 206 193 178 204 221 234 213 218 214 218 190 213 227 211 205 228 207 238 226 198 212 197 214 199 215 214 185 190 220 229 231 215 220 230 209 232 222 217 196 223 170 205 209 228 199 235 241 227 196 241 237 200 225 225 216 239 203 206 207 217 201 210 226 196 232 200 230 219 195 255 223 183 235 204 223 217 238 209 191 201 204 206 201 205 194 219 206 217 221 196 222 220 230 226 220 235 207 225 210 204 230 204 227 198 209 209 228 221 220 214 194 206 212 203 239 204 205 221 225 221 217 195 193 195 216 210 197 247 218 204 245 215 206 206 245 207 220 200 199 237 197 226 209 241 229 229 195 209 218 206 229 212 213 216 229 213 227 229 194 200 203 235 206 203 212 209 227 215 212 224 226 224 217 208 218 231 191 219 192 225 201 217 205 241 225 218 236 224 214 222 234 217 199 194 244 206 222 201 231 204 232 215 245 233 226 203 239 256 216 220 210 221 218 216 205 231 205 205 234 213 207 225 203 230 229 214 224 234 215 215 233 238 209 225 201 214 238 223 233 214 227 225 215 220 226 237 228 222 179 202 213 217 232 201 240 203 225 225 209 199 216 248 213 224 211 202 238 244 220 247 245 235 222 220 235 222 220 199 228 211 229 230 208 214 245 231 228 225 218 209 226 240 202 236 215 227 226 215 194 206 196 247 236 221 245 242 255 228 211 265 246 227 210 232 218 230 214 236 236 255 204 274 235 214 221 225 223 243 215 239 220 222 228 206 216 225 226 223 242 217 209 236 222 215 195 217 239 211 244 213 202 223 219 255 228 230 228 224 237 238 219 238 256 221 219 222 210 216 257 219 229 211 221 235 224 219 214 215 229 231 223 233 201 243 255 209 216 282 225 222 230 233 228 190 222 232 213 239 219 223 248 214 235 243 239 233 248 223 226 219 212 229 258 235 237 218 219 242 227 231 246 237 212 208 226 227 207 242 222 212 256 243 273 219 244 231 248 244 205 215 241 196 259 222 219 226 244 230 239 224 234 221 232 241 212 215 239 242 271 230 236 222 232 257 224 230 230 241 224 231 215 230 244 219 237 234 219 214 225 228 199 222 242 230 234 216 217 210 230 215 231 232 265 230 230 217 246 243 227 219 275 235 239 248 243 201 236 259 245 234 236 214 227 247 232 238 260 213 258 229 217 239 212 219 232 272 262 241 247 261 230 238 235 240 235 270 234 231 248 245 269 242 261 219 220 226 237 241 236 265 255 223 249 275 230 197 268 241 213 265 238 212 255 226 197 236 256 249 217 262 233 239 227 226 236 196 277 266 231 234 248 219 256 244 237 229 228 214 233 223 227 238 218 241 216 220 221 257 223 269 229 230 217 237 268 227 212 230 276 244 240 259 232 259 260 230 227 223 258 232 268 237 256 223 224 257 227 218 247 220 258 243 248 245 200 217 231 197 230 238 249 240 221 277 247 190 240 208 230 261 230 242 246 249 223 244 277 245 231 227 220 250 244 217 218 233 244 256 219 225 263 232 230 300 237 276 266 293 223 234 223 238 242 255 274 221 257 200 224 267 215 282 268 239 234 243 242 227 239 262 230 275 233 258 268 231 248 274 268 229 238 232 224 234 261 235 223 259 249 236 243 233 246 247 230 263 226 230 258 231 223 246 248 249 220 271 248 239 239 278 230 248 231 260 227 272 241 226 228 231 247 246 238 257 221 246 225 245 255 268 249 255 246 268 240 268 265 259 234 234 267 262 227 260 258 216 212 267 272 266 243 237 245 256 225 247 260 255 215 268 242 235 245 224 280 232 214 246 223 271 261 240 211 247 269 241 269 265 240 245 269 224 261 282 275 256 245 241 268 283 270 249 236 284 249 260 248 257 259 244 275 261 231 278 240 245 276 255 241 244 256 234 227 237 269 246 244 247 243 260 246 271 226 229 233 234 261 259 230 257 235 273 228 275 237 246 260 220 281 260 234 248 288 234 226 217 240 241 225 244 273 243 225 285 249 256 230 243 281 268 266 263 241 285 267 243 236 234 236 267 258 242 276 246 217 264 259 245 276 236 256 269 264 276 255 240 240 260 249 249 222 273 261 291 222 238 268 278 268 249 289 236 271 233 240 261 249 238 237 212 241 241 249 246 243 270 282 240 256 266 237 274 264 227 235 266 244 247 246 268 249 261 260 248 249 248 264 248 278 265 236 246 247 271 283 259 266 266 246 263 273 262 227 240 255 257 234 269 229 227 276 243 273 226 259 270 249 241 239 260 246 287 226 259 242 268 275 262 282 262 265 257 288 266 296 237 264 237 266 270 276 262 264 243 304 235 267 243 263 265 257 250 259 269 226 256 250 280 267 271 249 266 246 277 281 256 270 255 277 220 248 238 245 247 258 228 239 248 238 233 232 204 229 273 226 229 273 267 235 231 274 263 247 225 276 270 276 256 278 286 239 216 275 238 271 259 261 259 282 248 233 256 237 228 247 233 263 262 269 272 266 255 260 302 283 245 282 263 283 227 274 224 246 245 262 268 247 259 280 269 257 267 278 272 277 258 244 243 240 285 281 263 291 267 242 271 247 267 256 265 248 237 239 245 277 248 263 259 280 265 265 260 267 260 278 274 235 276 257 265 264 256 250 238 261 282 266 263 257 258 240 262 238 281 240 234 278 259 246 309 281 247 285 261 283 263 270 268 233 285 258 296 282 250 235 277 269 286 278 241 229 265 258 235 275 283 285 243 273 265 227 267 262 232 248 255 265 272 267 247 248 260 262 299 264 268 265 284 276 257 258 270 264 264 306 273 264 268 277 277 279 264 265 297 243 267 258 282 264 250 242 278 275 250 257 243 277 240 287 270 225 311 270 272 225 260 287 282 237 240 255 247 275 246 245 266 291 228 237 265 261 275 260 282 243 284 297 258 277 280 236 278 275 249 271 268 263 259 260 224 255 272 262 263 285 278 242 276 272 255 261 263 243 261 269 250 266 261 240 281 271 269 264 279 267 231 289 246 275 284 280 261 271 244 257 291 234 274 281 262 298 288 240 262 278 247 296 274 277 271 263 295 261 268 249 263 275 271 256 292 282 281 255 261 246 221 277 233 262 275 246 235 292 265 248 258 268 287 283 264 229 268 262 288 248 259 238 285 278 282 305 268 267 291 264 236 291 241 299 274 266 264 266 298 275 222 279 247 242 272 240 247 316 285 287 287 273 262 295 255 283 246 280 278 239 270 270 286 271 265 245 300 273 271 238 286 281 256 321 265 259 261 311 286 269 243 307 238 273 279 282 269 292 267 266 267 246 278 298 255 286 283 287 279 297 308 272 263 296 265 278 271 247 267 265 280 284 306 257 307 269 267 272 255 262 275 270 267 266 281 269 299 275 291 277 256 271 272 255 281 249 264 296 283 270 286 262 281 262 273 298 255 276 267 263 263 237 287 282 247 275 293 266 274 256 282 268 297 277 306 306 231 305 303 287 269 261 302 261 259 307 263 248 270 277 281 270 246 298 277 286 275 236 279 268 294 261 279 296 276 259 268 269 307 258 264 289 275 284 257 249 219 288 257 277 302 269 316 276 280 304 294 276 309 292 283 285 273 271 281 282 297 264 281 279 313 255 282 301 270 299 269 283 264 308 282 300 282 297 260 276 261 290 281 304 297 295 277 291 286 255 260 271 249 321 275 270 270 278 281 289 294 267 282 300 267 274 262 287 289 270 327 285 287 282 311 281 297 270 295 292 286 306 293 260 235 299 274 279 294 259 288 279 266 289 279 307 255 261 277 277 283 270 274 297 296 283 277 293 273 266 285 300 273 264 292 290 270 294 255 286 258 289 310 258 250 291 307 289 297 286 310 278 294 282 281 290 307 274 301 281 281 283 278 272 289 285 297 294 295 298 275 282 292 274 302 280 265 287 301 299 287 263 335 312 299 289 296 276 282 262 312 264 326 274 312 270 294 296 301 287 336 322 321 294 282 244 289 295 299 294 300 246 307 265 283 316 299 288 272 275 297 284 275 273 272 281 301 265 306 289 300 300 273 292 286 300 301 287 287 308 286 266 294 311 275 305 301 329 287 291 306 291 309 294 303 311 315 288 258 259 282 286 291 269 257 286 315 323 316 288 311 282 310 280 307 302 303 273 303 321 291 275 294 307 276 320 303 336 328 305 297 298 267 310 287 329 312 311 307 302 305 332 278 319 284 315 303 271 302 315 314 296 319 341 322 297 315 315 299 344 305 337 321 332 305 312 338 329 321 306 329 364 306 337 314 349 342 319 312 304 312 345 344 347 318 381 366 361 324 325 388 369 304 369 386 371 343 372 369 395 407 382 405 372 413 408 419 445 412 472 432 445 500 434 500 529 537 531 490 569 557 598 607 589 579 552 601 589 633 608 586 638 582 590 546 567 592 545 532 530 518 485 490 495 454 426 431 449 441 430 416 374 394 389 394 387 361 364 338 356 388 338 354 353 342 357 337 328 341 325 328 355 335 299 342 308 338 354 333 313 294 359 326 327 328 298 308 316 344 305 348 302 274 294 307 319 319 340 313 289 278 305 297 318 310 306 282 341 294 262 320 307 306 331 298 301 287 317 306 297 292 288 302 285 335 305 290 327 288 283 308 297 310 293 307 322 325 284 307 309 293 298 275 272 276 278 294 283 316 299 273 264 300 299 312 269 326 290 297 319 283 289 283 283 301 312 279 314 272 283 302 301 323 328 293 295 318 331 280 281 303 276 297 284 310 296 285 287 306 288 283 277 292 277 303 304 297 277 319 273 298 322 274 313 305 283 293 302 301 303 298 279 304 279 322 290 297 288 318 285 288 258 317 303 287 273 276 311 284 301 335 289 282 273 297 304 312 285 266 266 307 282 280 293 277 293 304 282 308 301 329 306 303 288 324 294 263 291 288 302 278 286 277 336 289 273 307 308 268 288 313 289 282 301 276 291 304 318 313 307 299 322 279 291 286 311 285 291 313 301 316 314 304 325 306 316 297 295 314 278 275 313 335 294 297 299 316 322 305 298 333 301 286 299 320 338 303 307 293 263 298 308 289 332 302 305 285 307 313 316 311 277 272 262 297 285 274 292 311 287 295 307 319 296 305 311 304 302 279 282 291 321 281 314 268 315 287 319 328 312 298 320 315 291 292 296 279 299 308 278 313 302 296 304 281 306 290 313 298 321 326 323 284 284 292 305 298 310 303 284 311 331 315 295 299 325 322 304 311 290 291 287 292 278 314 331 310 293 302 291 289 303 278 293 314 285 294 294 312 310 314 283 315 289 334 294 313 309 315 285 330 308 296 346 295 276 315 317 318 304 289 339 260 315 288 324 314 314 322 283 315 296 309 279 314 300 326 309 299 284 337 273 295 324 268 265 319 334 311 309 312 286 320 320 314 303 289 303 296 340 287 299 300 297 284 300 299 287 293 319 304 301 301 301 297 285 273 299 316 304 306 310 295 304 315 278 326 305 296 296 325 319 305 282 297 311 305 299 318 287 303 278 286 323 313 263 277 326 316 290 318 319 300 325 326 297 330 345 327 284 308 326 297 321 319 283 287 312 325 307 269 302 279 267 311 326 319 283 299 273 296 316 299 304 295 322 294 298 313 322 316 280 299 294 305 316 300 300 311 293 311 308 316 290 291 285 322 286 322 304 298 329 308 304 304 268 292 275 296 314 317 282 296 300 304 292 297 275 279 284 289 328 315 332 293 290 316 291 298 299 280 302 285 292 348 315 311 326 283 295 303 293 294 280 279 334 273 281 283 299 333 331 313 297 335 290 280 307 318 291 320 311 317 292 302 332 296 293 325 328 312 325 293 298 301 296 307 301 293 275 247 298 325 302 318 280 301 297 329 338 293 344 292 329 280 279 336 269 313 310 326 329 309 327 330 288 325 298 308 322 350 285 302 311 303 306 307 305 301 293 291 314 304 296 333 297 312 310 294 320 290 263 324 313 323 274 330 323 320 310 326 324 327 321 291 283 322 305 347 293 286 311 296 288 291 298 302 302 320 309 303 307 305 301 321 290 313 291 305 321 277 317 330 324 318 316 287 300 304 319 312 318 331 313 321 299 288 306 302 283 303 299 285 320 297 300 323 271 297 277 289 294 305 303 328 309 315 318 337 320 323 320 329 311 329 291 306 318 339 304 308 330 290 345 314 307 314 338 298 286 325 315 281 307 318 332 311 312 329 306 295 305 304 337 293 303 307 340 314 324 289 317 321 333 315 324 306 297 291 304 284 304 331 324 334 268 285 317 291 317 298 331 309 345 310 332 313 325 340 335 297 296 305 299 318 313 310 315 326 320 307 280 296 315 345 317 315 336 333 290 290 299 343 342 327 357 309 304 320 324 328 302 303 302 290 313 354 306 315 314 327 316 301 298 345 345 337 323 340 331 341 298 289 315 311 316 307 306 304 314 371 325 299 335 310 297 310 319 341 297 319 323 351 331 283 307 347 308 306 314 346 323 307 287 331 334 350 328 334 297 302 327 337 323 312 323 284 306 317 302 319 303 321 300 295 341 312 314 315 330 317 363 291 311 297 326 288 316 309 298 332 284 306 339 281 311 308 312 314 322 312 296 316 321 294 321 332 305 338 319 280 325 326 341 308 314 299 331 332 308 314 287 296 334 313 322 335 276 314 308 328 303 300 321 316 299 354 299 289 330 301 281 339 311 310 269 309 304 301 302 303 307 315 334 344 300 316 320 312 328 326 331 325 314 304 288 288 289 357 336 328 316 297 329 295 313 310 268 306 317 354 334 326 344 321 340 312 343 290 311 301 293 330 333 331 296 304 296 304 288 328 323 322 284 300 330 311 314 312 312 295 326 335 308 330 319 344 327 300 325 331 292 311 311 340 321 288 338 331 326 275 311 314 334 306 314 279 313 313 329 321 331 309 322 297 297 280 327 331 316 321 281 308 310 342 340 305 331 327 337 330 333 311 321 352 342 330 344 312 348 327 299 363 304 319 318 280 294 333 333 310 329 335 315 314 316 296 315 327 322 306 298 326 312 336 308 323 318 329 325 311 324 310 336 333 310 311 327 347 329 288 321 329 343 329 314 310 325 325 325 327 295 313 314 318 335 333 309 314 322 295 307 307 287 309 288 316 340 336 324 335 282 303 301 325 343 307 337 335 321 309 323 332 331 322 322 306 315 350 332 330 327 356 281 296 331 295 296 322 320 300 334 314 337 313 341 301 357 349 302 338 321 292 319 300 308 316 342 321 330 322 283 296 319 313 312 311 311 290 338 331 333 312 359 295 319 340 320 329 329 325 316 303 313 308 294 308 317 343 340 322 305 329 354 345 316 335 342 335 324 337 308 321 323 334 370 330 351 301 302 326 330 318 308 321 318 320 322 324 324 345 331 335 342 327 350 277 325 341 324 297 312 324 315 336 312 330 354 309 299 319 324 318 324 321 363 307 329 316 323 324 326 326 290 328 318 360 332 329 315 330 334 346 316 318 347 332 315 321 309 326 368 326 328 317 333 350 328 352 288 329 303 330 317 343 286 324 286 312 345 285 308 323 296 289 317 335 323 331 318 320 329 314 329 331 337 305 313 326 297 351 316 313 330 311 336 326 334 350 317 297 330 321 329 336 314 311 275 299 296 329 347 319 345 281 351 305 306 294 347 327 316 329 320 334 320 322 325 293 300 310 344 343 327 365 317 315 338 333 311 287 304 313 320 327 310 307 329 300 325 333 311 304 303 328 353 320 289 346 336 321 318 295 329 315 318 326 312 336 329 340 319 336 334 337 362 330 342 345 344 340 343 306 344 313 351 332 343 310 315 291 328 317 314 322 320 352 318 324 328 323 323 342 304 349 330 325 317 327 326 338 327 287 330 337 347 323 334 353 297 315 331 321 356 287 347 315 347 312 364 352 304 303 310 311 326 373 305 340 348 289 306 348 337 332 299 290 318 320 331 358 328 310 347 312 304 301 312 331 337 302 320 311 330 293 326 325 339 331 353 333 331 313 314 341 320 318 316 339 277 310 286 331 357 349 318 314 328 373 326 323 308 324 329 337 321 335 301 312 334 316 338 283 311 340 334 302 307 275 337 314 331 316 308 308 305 316 325 344 295 321 312 320 346 338 330 322 346 325 313 299 319 315 299 301 289 348 308 331 309 326 337 297 322 297 340 314 307 332 357 317 344 319 305 306 339 319 330 328 307 334 329 346 348 330 357 343 338 334 346 295 330 333 331 288 330 304 330 344 310 313 315 312 310 317 349 333 305 318 319 316 330 318 358 324 310 315 379 342 318 315 312 310 332 332 325 336 347 319 331 334 361 323 341 339 309 317 335 330 329 316 302 326 314 306 302 330 340 303 355 336 309 335 359 310 349 298 330 316 316 325 317 322 338 309 316 363 323 321 322 309 328 334 288 315 332 353 322 322 304 288 297 343 331 358 355 304 355 325 312 330 358 333 336 339 323 291 373 346 326 331 339 309 300 328 314 318 351 352 285 327 340 318 294 316 302 306 336 321 316 334 298 331 330 335 317 333 336 359 322 322 340 322 339 318 337 338 330 307 329 355 323 310 318 350 372 365 327 344 299 327 327 307 323 310 345 334 345 319 337 353 366 335 342 344 322 326 336 303 305 316 315 314 337 345 352 332 324 338 353 329 316 327 309 317 304 340 318 317 360 313 354 340 325 311 317 326 342 332 319 348 342 329 328 310 348 300 344 315 346 357 294 324 328 335 309 324 356 327 325 348 317 304 346 307 315 351 308 311 336 305 358 337 324 322 310 332 336 357 286 319 344 339 315 330 338 344 304 359 351 330 319 319 318 340 357 334 306 340 331 354 353 331 356 319 312 334 347 384 320 315 354 349 368 362 364 335 321 324 315 314 338 361 311 340 341 339 310 360 341 325 341 390 324 301 345 353 360 335 332 354 356 338 348 316 350 333 357 337 341 334 355 344 332 362 331 329 350 355 322 329 353 365 356 360 358 335 343 342 316 338 339 339 351 340 365 357 349 384 356 346 366 346 370 367 381 342 357 352 356 369 372 361 345 342 418 392 354 359 398 370 353 383 377 400 374 342 405 390 352 345 341 340 348 370 377 385 370 362 336 326 376 344 349 377 363 346 360 359 404 349 336 393 347 358 373 331 344 339 368 349 352 356 336 342 338 359 370 352 315 352 353 333 351 372 355 324 324 351 340 335 346 339 375 321 322 304 346 376 344 374 324 366 350 301 325 349 319 345 380 322 339 314 339 336 333 324 312 351 324 338 336 330 338 324 349 338 316 334 316 343 310 316 338 359 323 304 316 342 353 319 361 329 327 317 365 329 324 362 301 330 358 319 346 349 331 327 313 355 336 345 326 352 374 321 312 312 316 337 359 321 361 326 332 358 333 346 338 344 334 299 365 343 318 304 336 319 338 374 331 347 331 328 358 316 308 309 352 326 341 347 349 336 352 329 360 328 330 328 364 344 342 368 303 324 318 343 336 317 312 311 323 350 344 337 346 340 386 320 338 355 356 292 360 320 316 329 312 286 344 347 334 306 308 362 325 285 303 332 357 345 336 294 337 381 314 313 326 330 314 336 331 335 348 307 308 326 335 327 329 352 328 350 325 349 371 350 301 344 319 321 334 322 329 324 339 344 316 348 328 327 309 326 308 297 301 282 360 329 321 355 346 347 340 334 345 319 331 331 292 335 336 324 338 332 320 359 326 326 383 330 325 335 343 329 333 317 332 329 344 344 320 319 325 321 306 289 309 317 355 318 337 336 293 324 330 340 303 331 343 328 318 291 333 320 342 323 351 351 353 340 342 332 327 316 351 329 336 354 322 291 346 345 341 321 323 330 300 306 324 330 345 306 301 362 355 325 334 346 336 340 304 333 327 315 310 318 312 315 331 285 329 371 331 334 319 332 350 304 343 329 335 323 321 315 352 308 331 318 323 308 329 320 311 323 340 305 318 331 313 380 327 335 349 306 321 313 349 328 324 333 322 315 339 347 331 340 342 361 324 316 355 324 306 366 299 307 327 308 362 303 314 329 327 350 320 351 330 340 347 291 333 346 317 326 338 328 350 307 342 350 318 358 338 347 320 383 318 368 348 314 340 317 363 330 346 330 337 328 318 332 337 306 346 325 305 326 337 353 307 322 361 318 339 354 339 371 325 307 345 326 325 351 318 328 344 346 328 318 336 355 337 343 321 315 282 327 314 315 327 354 351 331 311 323 335 316 319 322 346 333 340 332 291 317 291 348 334 364 334 329 341 315 343 364 330 339 315 332 317 318 340 325 354 312 332 342 364 363 328 382 350 323 316 337 351 352 302 324 360 336 348 293 328 349 326 338 358 337 327 334 349 333 361 333 311 331 360 329 332 327 305 292 334 310 315 340 324 345 274 311 361 321 322 301 329 348 342 322 308 349 349 330 339 324 338 334 291 343 337 346 326 323 332 341 329 313 350 380 318 320 323 342 362 303 329 350 370 346 346 354 331 358 352 327 338 330 322 341 347 341 328 324 328 335 328 347 330 319 345 320 322 335 351 346 313 342 320 343 319 367 300 325 326 337 304 340 340 310 322 309 337 367 356 326 327 356 342 328 356 331 337 340 360 338 318 315 325 334 314 344 359 340 350 327 323 332 317 333 335 327 307 334 329 332 323 336 344 305 373 356 356 329 353 345 348 375 328 323 313 338 337 344 347 321 354 348 369 354 330 356 330 323 353 356 324 352 341 343 343 347 381 318 355 324 303 312 316 360 354 340 360 350 370 351 358 334 364 332 350 314 339 390 318 321 315 384 342 341 357 335 342 361 370 357 313 357 354 359 312 324 342 292 305 335 303 348 352 316 352 346 330 329 336 366 341 337 354 359 362 352 362 346 339 329 330 347 327 328 327 349 324 356 293 381 360 338 337 351 354 324 321 343 307 342 380 353 337 316 333 337 318 360 336 327 372 361 348 361 339 345 343 337 326 332 349 345 366 347 327 368 385 350 374 347 356 341 367 316 351 370 348 326 332 360 314 342 320 342 343 357 350 318 326 354 384 320 321 370 339 326 389 344 370 318 349 369 360 333 322 359 339 345 325 331 340 341 314 358 347 353 347 360 361 344 339 368 333 372 324 358 337 347 334 373 394 355 341 343 336 354 332 363 361 345 335 345 329 324 359 351 352 343 375 323 339 359 368 343 347 346 345 325 351 320 384 343 335 403 345 337 343 367 352 318 346 320 331 311 369 323 361 334 370 362 342 357 343 332 338 368 310 348 340 361 330 326 322 362 353 343 333 339 363 315 379 337 327 365 348 322 330 318 330 339 334 357 353 325 390 369 347 324 307 355 354 368 332 323 372 360 354 356 300 326 329 332 354 364 353 315 318 354 364 400 333 372 340 358 362 361 345 331 340 373 368 361 305 342 340 345 332 354 332 336 364 336 326 321 350 353 361 382 377 319 348 334 340 365 365 393 344 343 361 344 366 361 332 342 329 316 367 362 321 327 355 358 370 333 357 356 357 362 319 351 340 331 356 363 355 352 332 367 348 376 343 362 363 336 356 363 378 356 341 331 344 343 359 383 331 329 332 365 333 362 354 328 374 350 307 332 333 381 356 346 373 338 341 336 331 303 329 343 354 381 369 358 364 376 351 355 358 361 353 333 321 351 335 336 359 338 373 336 359 340 386 329 326 346 377 320 352 353 332 338 352 364 329 336 314 337 332 325 352 383 336 340 350 336 349 306 330 329 335 330 360 315 345 333 337 349 340 363 340 342 366 350 329 335 372 364 380 362 353 359 360 370 355 353 317 362 391 329 322 342 363 349 368 357 343 339 380 366 341 347 336 394 375 321 324 350 353 335 356 342 380 326 347 380 345 383 337 323 339 350 380 322 333 339 332 348 381 352 316 336 345 331 360 317 320 340 344 340 333 340 337 349 343 346 365 347 367 352 334 370 348 348 326 341 308 354 346 308 361 387 350 338 339 358 345 341 373 342 339 380 346 343 351 314 368 329 329 378 374 312 348 345 390 359 372 392 318 358 343 346 328 373 404 387 324 391 336 348 321 360 327 406 320 390 372 375 345 365 364 360 378 334 338 320 369 346 359 368 394 325 324 348 330 333 338 348 349 348 344 327 334 358 352 338 358 391 330 370 380 347 375 337 358 372 338 357 364 368 358 363 321 357 312 353 309 367 370 370 328 332 338 381 328 326 353 337 350 376 347 353 339 360 345 358 332 346 371 350 364 362 339 335 356 329 349 356 340 327 332 350 326 324 359 340 346 371 356 342 355 370 382 361 335 345 355 323 360 343 362 331 348 360 355 350 324 340 307 314 320 342 314 362 352 366 350 324 332 343 339 366 355 349 346 345 332 322 329 341 325 345 362 384 378 302 338 377 351 310 364 359 318 366 397 323 346 347 372 335 351 348 369 327 354 348 397 350 347 361 324 339 356 358 357 332 342 343 363 384 331 382 315 344 369 349 304 369 319 357 346 335 311 369 320 377 346 317 338 361 336 323 320 386 365 338 389 319 382 346 333 387 348 362 373 346 347 346 342 386 332 337 353 346 315 332 350 332 325 349 320 338 332 325 345 366 350 344 332 338 344 362 355 360 354 363 285 333 351 365 346 356 338 327 347 364 338 362 349 346 330 367 353 342 376 334 342 350 353 384 370 335 377 334 349 356 348 338 332 349 343 329 291 335 321 328 392 347 385 352 367 340 339 323 357 333 355 334 345 338 342 377 344 325 352 330 344 377 345 368 336 367 326 318 361 393 361 342 320 358 365 311 349 339 351 335 360 325 366 382 320 355 384 318 345 381 355 358 363 348 353 340 367 349 338 316 340 367 326 344 330 386 331 391 386 327 368 382 406 328 352 333 360 348 363 328 368 403 375 325 355 366 355 358 367 360 357 319 358 352 370 367 379 345 416 378 352 355 349 373 357 357 358 360 397 363 366 350 361 374 371 377 356 371 382 369 398 350 360 387 366 373 376 331 331 373 357 368 405 350 374 366 385 388 428 384 368 389 446 393 410 399 395 396 393 441 401 449 434 376 395 384 422 407 426 408 418 369 389 398 391 392 393 383 406 414 378 381 391 406 404 398 384 405 382 392 398 391 413 395 396 402 375 411 373 379 380 395 380 386 410 373 390 343 400 352 352 347 390 351 392 341 378 349 349 341 360 379 351 351 323 371 351 314 364 351 381 350 387 375 338 359 378 364 365 346 363 363 380 335 343 353 353 356 330 347 372 327 374 344 334 361 363 359 352 316 357 323 351 346 368 357 355 339 361 370 371 364 371 380 366 330 365 350 356 342 355 323 320 353 374 334 347 357 347 320 337 371 357 364 349 356 337 341 293 345 317 363 339 347 332 368 356 337 358 360 333 366 362 348 351 334 345 342 361 336 380 344 334 329 356 346 359 344 358 371 334 356 338 356 367 363 354 348 353 367 360 343 344 315 370 357 334 351 365 338 362 365 368 346 321 348 335 348 358 359 355 326 345 391 327 324 359 352 337 393 356 360 348 353 365 370 340 367 360 315 350 309 376 343 356 360 352 348 307 351 318 371 372 363 335 365 335 359 319 317 338 391 381 357 370 380 342 366 332 328 357 347 363 332 388 345 359 352 367 347 311 345 389 351 345 327 345 318 352 321 315 342 355 355 351 347 361 330 364 356 381 329 319 376 344 370 341 340 349 374 361 348 352 363 330 323 335 344 382 364 354 349 356 401 376 336 339 381 337 372 324 348 317 337 347 350 354 375 338 352 379 336 357 353 351 371 344 324 358 373 351 364 351 369 349 363 322 369 335 351 341 371 331 331 341 338 351 366 369 325 339 340 348 337 377 354 333 366 320 368 325 342 334 345 366 365 360 341 378 368 344 335 361 339 321 356 344 334 343 328 349 355 348 334 330 346 310 315 364 324 353 368 361 361 374 365 339 385 357 330 358 320 341 359 376 370 342 316 392 406 332 360 311 349 372 348 397 358 344 313 360 335 331 344 338 317 315 371 353 351 337 329 335 349 379 387 321 381 340 319 373 352 324 345 365 362 307 322 329 340 336 354 330 350 337 389 367 325 354 379 349 347 392 344 365 360 364 374 363 340 365 350 386 332 348 360 353 368 395 350 350 367 348 368 364 368 343 348 340 344 294 323 323 369 380 322 348 360 345 370 357 351 354 367 341 328 355 343 360 349 358 374 366 357 346 365 341 338 358 350 348 348 330 352 373 375 367 341 344 293 346 350 353 349 363 334 356 334 348 349 343 368 325 372 327 376 358 348 369 378 372 314 347 363 350 343 330 323 363 334 377 303 383 336 345 338 349 339 366 341 329 373 336 378 350 355 350 312 319 304 340 360 356 354 359 343 344 366 356 334 335 323 379 387 337 342 386 342 356 350 320 333 335 357 326 343 365 337 309 332 346 355 369 348 365 323 367 363 334 352 359 346 356 350 399 382 324 366 339 355 327 326 349 328 363 353 362 397 348 310 364 356 349 368 340 369 350 357 353 388 353 355 343 359 350 360 329 350 365 339 356 364 363 354 335 328 343 307 319 341 376 335 341 352 333 346 357 358 344 359 364 375 374 330 355 361 336 337 348 336 350 330 356 326 367 357 357 345 359 340 364 314 368 313 363 289 352 356 356 392 340 307 338 368 357 370 372 362 343 328 334 350 323 347 361 365 373 328 344 333 317 358 348 349 348 344 371 331 357 349 349 335 336 354 349 354 363 331 364 338 340 353 374 342 340 361 372 344 336 362 343 395 358 341 344 376 339 333 366 352 353 347 340 341 360 362 349 367 343 352 366 391 374 350 341 340 353 339 332 366 359 369 356 366 349 356 332 321 348 369 333 335 334 331 365 374 373 340 370 348 298 383 343 339 352 360 324 349 318 401 325 328 323 358 370 342 369 343 355 357 353 352 379 363 374 333 367 341 362 377 329 329 352 373 341 361 381 343 393 381 380 366 339 370 334 372 369 351 331 346 342 366 337 363 371 359 336 351 340 358 344 358 343 338 370 360 347 399 332 344 330 346 330 376 327 320 355 355 357 311 349 379 366 323 325 333 382 358 361 337 380 356 349 350 327 365 315 354 347 342 346 342 319 393 344 341 346 363 353 330 363 369 349 379 354 354 355 384 315 332 397 327 346 357 343 353 342 358 402 349 358 352 379 336 315 382 372 387 362 355 343 373 388 379 358 347 376 352 310 351 331 340 360 342 363 354 333 368 406 328 362 336 363 354 370 353 357 369 384 380 338 365 354 378 355 346 302 346 346 373 351 389 338 348 386 375 382 343 307 355 349 368 333 336 380 343 362 368 340 381 396 354 337 364 344 373 357 373 343 357 379 346 364 388 389 324 366 372 363 372 349 359 379 349 358 325 363 332 383 360 321 348 355 358 379 341 340 339 348 364 337 332 351 329 337 334 349 369 374 354 338 360 333 368 362 359 365 330 373 354 356 364 311 373 398 393 362 384 351 351 340 370 348 331 334 352 383 368 376 379 350 358 392 352 362 358 346 389 372 378 334 355 345 381 360 368 354 323 372 363 355 355 337 372 349 370 351 345 377 389 339 369 344 347 362 333 348 351 319 348 372 405 362 329 332 361 327 357 345 374 382 334 367 373 344 343 362 372 370 391 381 385 369 349 325 348 368 366 351 365 373 364 334 350 349 366 358 306 375 341 341 378 379 322 369 366 344 371 386 347 349 375 344 361 356 337 355 366 332 375 343 359 373 381 335 380 365 365 373 377 346 331 327 322 383 356 358 338 374 363 402 390 358 313 353 365 353 361 348 345 376 370 368 383 309 379 342 364 351 343 372 324 371 327 338 363 353 386 356 342 336 386 356 372 362 355 331 362 366 347 398 384 321 358 347 348 360 344 392 365 342 339 394 348 372 368 354 354 344 321 369 364 336 376 356 378 384 338 311 337 390 387 367 335 379 384 340 408 352 360 379 353 351 348 325 351 373 356 365 317 368 313 336 351 349 379 366 384 383 372 358 356 324 346 368 368 339 346 384 376 351 377 385 348 358 323 367 335 317 381 350 371 360 346 329 338 376 400 385 339 353 359 350 362 356 378 329 373 351 342 353 372 335 353 363 364 336 353 345 347 363 354 348 345 360 366 352 354 344 372 391 350 362 342 358 350 342 339 339 377 334 350 339 355 353 389 347 351 371 405 350 386 367 357 345 360 398 323 349 343 351 355 362 352 391 359 330 366 353 392 386 357 344 360 361 357 365 348 368 340 350 338 359 362 377 361 365 361 358 358 374 330 371 361 369 347 372 366 385 316 335 354 366 369 358 301 392 375 359 371 364 388 336 373 374 369 377 335 377 375 350 339 357 367 335 350 355 376 331 300 386 400 361 393 345 387 335 375 369 325 364 336 335 348 370 363 378 343 385 380 371 363 346 355 351 377 350 393 368 343 352 380 358 336 333 333 337 373 345 365 361 382 359 360 364 346 383 321 360 374 373 368 315 359 350 356 349 337 376 339 371 363 381 346 377 334 343 359 386 342 369 359 368 340 369 366 343 329 373 389 388 358 335 352 375 376 375 352 345 344 359 355 354 295 362 354 374 382 385 385 384 335 345 362 358 386 358 374 366 374 363 317 331 342 375 373 412 373 333 399 364 359 342 352 392 357 373 345 388 395 334 350 361 373 360 343 334 351 356 352 358 362 368 369 372 359 387 362 369 356 376 374 358 363 383 364 332 340 376 332 367 347 370 351 374 364 402 348 365 371 374 306 363 321 357 392 355 364 367 361 361 332 385 366 417 388 381 379 351 360 359 344 371 352 384 346 376 367 400 385 361 335 385 404 374 370 359 391 360 392 405 384 399 378 372 362 366 350 382 396 392 385 410 392 378 394 376 422 368 372 391 364 401 376 385 372 381 330 397 364 363 369 366 367 394 408 359 383 399 347 374 399 362 371 361 404 369 387 374 404 388 378 371 368 385 370 391 353 373 407 361 363 384 354 378 369 362 385 374 364 365 382 383 347 361 329 340 364 380 384 337 374 338 389 369 366 351 371 386 363 355 364 368 350 323 380 341 386 369 347 363 335 321 332 362 351 359 381 335 368 381 412 330 350 342 386 374 349 383 379 365 358 361 355 345 376 362 319 368 378 362 376 353 371 373 362 346 354 368 378 359 328 356 381 342 373 351 367 342 378 358 374 365 344 342 383 346 348 372 347 371 363 400 353 366 359 362 369 349 347 341 342 312 351 352 386 353 338 357 361 370 369 357 367 367 376 367 334 378 385 354 354 407 362 325 338 357 341 377 356 369 374 341 325 330 361 349 344 356 357 367 358 373 347 376 348 307 355 363 382 374 362 333 376 343 326 356 361 342 389 360 329 356 362 366 386 352 347 371 346 375 370 366 407 360 369 378 363 344 340 395 341 383 347 354 393 360 355 338 351 384 343 369 324 367 314 371 368 387 356 389 373 375 353 354 388 368 356 348 369 386 365 384 358 357 358 358 383 361 391 393 352 353 347 358 367 370 346 344 339 379 343 361 359 378 370 374 358 372 373 346 365 371 380 375 346 339 364 386 359 367 346 353 370 379 352 393 365 356 335 368 368 316 342 368 356 386 365 380 337 358 340 343 359 362 342 358 367 341 375 352 376 356 360 335 359 338 340 353 372 350 357 389 383 366 352 352 358 369 319 356 356 335 373 355 374 366 339 337 360 367 383 348 362 369 390 346 340 351 356 372 347 399 343 376 328 349 324 349 331 389 374 352 382 321 377 375 344 355 387 381 413 352 373 361 344 346 372 366 390 361 379 357 374 351 371 372 344 368 354 370 338 349 345 360 350 367 354 325 352 348 363 344 378 347 386 385 359 362 346 376 342 360 320 358 354 346 345 354 358 333 336 361 367 332 331 323 337 349 346 363 360 337 365 364 339 332 336 371 332 334 363 364 351 348 335 347 379 309 362 357 331 345 370 364 364 357 362 377 374 363 371 351 367 367 367 363 346 366 362 353 321 342 365 368 364 347 382 382 353 340 375 353 373 352 354 360 398 399 352 335 386 344 385 330 349 366 375 344 394 393 346 348 363 377 346 343 360 342 373 333 362 383 360 386 332 364 354 363 342 337 352 319 382 354 376 359 354 329 347 378 390 356 393 335 363 354 387 352 359 347 356 355 329 361 366 368 338 388 375 388 374 349 342 361 323 390 342 318 384 330 384 343 301 342 378 359 360 370 324 332 357 364 351 342 364 358 336 321 348 382 353 347 384 341 335 313 347 374 364 335 357 329 349 355 342 382 336 367 341 332 351 340 330 340 376 364 370 381 332 340 348 326 355 327 382 371 343 365 337 385 358 313 347 346 350 345 359 345 338 327 367 376 349 352 356 324 371 365 366 338 351 380 334 378 336 357 359 361 350 357 347 324 342 341 329 358 334 360 348 343 354 349 350 334 341 395 338 366 362 339 364 366 364 349 357 337 348 351 391 375 355 347 321 369 350 339 332 352 332 347 400 349 365 326 364 380 362 340 356 378 358 355 332 361 335 374 326 364 363 321 359 381 364 370 377 335 358 345 344 346 327 322 348 363 374 323 333 349 340 357 346 371 337 374 340 355 365 362 322 371 351 367 345 326 334 341 355 335 351 365 342 390 374 362 355 341 394 362 371 391 352 374 292 307 358 327 356 323 324 342 337 353 377 353 363 376 319 361 359 360 320 302 326 332 376 362 381 361 350 338 347 355 325 380 353 346 352 351 324 343 361 324 337 374 334 381 362 315 420 351 358 349 371 324 384 329 381 351 309 340 359 365 358 346 358 348 362 334 344 385 351 342 367 331 342 366 341 372 347 346 362 347 391 361 335 362 343 368 337 364 318 368 374 368 396 389 364 336 346 345 391 378 332 349 367 371 382 369 358 334 353 361 377 363 323 368 351 354 363 374 349 388 365 346 375 349 378 355 340 362 340 351 357 391 367 375 396 362 358 362 366 352 343 399 364 369 364 362 351 363 364 335 401 375 326 377 357 347 372 357 390 361 377 334 323 379 334 382 354 325 347 349 354 336 399 316 377 366 346 357 385 372 363 352 353 346 386 363 335 398 347 392 325 380 369 346 342 331 348 342 376 341 355 354 358 358 349 366 390 361 379 331 353 370 346 367 340 349 336 344 358 376 391 384 352 337 351 371 370 364 349 377 340 350 336 364 361 361 344 380 369 355 411 358 352 365 355 354 348 378 341 338 338 339 339 365 376 370 352 375 348 339 380 346 385 355 362 395 340 379 360 368 371 371 365 325 364 335 374 348 359 369 362 373 350 385 384 345 351 377 365 398 370 363 349 369 365 369 342 359 333 377 362 344 371 347 369 387 368 356 350 380 360 384 353 362 349 362 360 372 355 364 372 381 373 371 346 370 347 369 351 352 355 342 351 388 365 374 351 391 380 325 362 370 362 367 357 341 342 340 378 364 364 348 363 398 374 368 365 372 384 382 363 351 372 352 323 366 326 325 345 378 374 301 367 366 370 357 368 336 347 377 331 362 346 357 330 338 369 344 369 357 361 359 321 349 341 350 355 355 337 351 352 371 359 351 363 376 366 365 374 331 337 348 370 356 376 324 357 365 372 356 352 397 325 349 337 380 358 400 346 371 357 378 400 368 360 358 363 375 366 361 347 380 360 373 357 350 367 354 397 369 375 364 369 360 333 387 389 368 340 355 359 351 399 340 380 355 368 364 344 380 350 355 357 362 344 381 404 338 360 401 323 363 338 343 405 362 385 360 361 378 393 363 368 380 387 366 381 380 335 356 350 357 349 372 352 332 358 365 375 388 355 377 339 335 340 352 364 356 385 375 352 370 319 347 372 375 361 376 352 363 369 336 344 368 382 362 377 389 378 365 391 378 413 358 374 379 343 398 375 385 359 358 374 340 341 336 365 354 390 380 320 330 323 334 372 332 389 353 347 340 366 347 361 363 354 365 374 337 340 359 405 364 361 335 356 357 358 369 381 359 381 371 353 385 343 348 389 355 357 371 351 340 338 374 383 361 349 387 362 364 395 380 354 364 378 381 342 371 357 392 359 342 391 366 386 390 332 387 411 378 380 392 352 376 386 360 363 342 372 328 353 390 374 374 393 378 364 357 360 368 384 378 376 373 371 361 334 391 376 360 383 376 378 387 375 381 364 366 330 338 336 389 325 341 390 360 358 369 350 370 375 336 331 364 348 381 347 365 356 377 370 385 382 348 378 399 372 327 372 340 405 369 356 335 388 353 347 370 341 354 333 333 328 347 324 339 369 364 386 364 373 363 363 355 344 365 395 354 341 367 374 365 380 350 362 377 366 340 367 361 387 362 376 349 361 330 363 358 379 359 371 333 357 342 407 348 331 364 359 397 344 394 355 351 349 363 353 379 381 336 376 359 333 343 374 354 371 363 366 373 362 366 380 371 340 370 378 346 367 373 372 384 354 352 385 350 353 364 407 345 391 372 358 345 373 342 360 376 371 339 362 387 345 381 392 405 383 349 376 365 338 367 360 405 370 366 389 342 390 404 351 371 338 363 368 384 378 361 365 374 388 353 360 330 350 358 390 406 386 334 383 375 359 361 363 370 390 384 354 382 348 381 395 358 393 384 381 352 356 377 385 349 372 354 370 351 359 335 373 385 375 365 385 386 347 375 378 410 375 385 377 379 364 411 333 398 375 378 378 357 342 411 374 368 413 361 367 407 368 360 375 391 400 407 424 344 379 359 380 416 414 396 370 366 406 388 401 358 378 383 365 359 372 367 367 385 402 413 364 398 374 395 355 394 391 409 399 406 356 345 415 375 404 383 401 363 366 412 363 383 360 360 398 378 414 396 369 405 388 400 405 370 394 375 388 372 412 391 401 400 387 371 370 350 411 390 391 403 402 422 397 371 396 364 380 407 400 385 374 350 363 397 402 411 396 361 387 401 420 408 424 370 394 382 405 389 362 378 358 420 392 367 357 372 364 388 396 358 385 365 372 386 386 375 351 382 392 343 372 387 373 369 371 417 366 372 398 408 378 385 390 397 387 388 398 395 365 387 379 352 387 369 330 372 363 366 351 400 386 374 404 389 407 339 385 380 361 384 352 314 358 375 353 383 379 384 377 387 354 369 387 384 339 375 343 363 394 331 378 370 386 366 375 362 370 374 386 363 362 370 402 399 348 386 374 381 385 372 366 384 368 363 394 365 378 337 364 385 387 355 378 385 346 366 368 366 372 362 388 336 365 364 349 381 355 356 358 365 372 381 410 385 315 360 366 358 378 391 339 364 376 362 362 342 391 376 369 396 393 384 338 357 383 381 361 360 357 367 348 357 364 344 392 349 362 370 385 354 373 359 347 381 379 391 370 365 337 385 347 333 382 380 386 367 374 357 380 369 357 399 387 369 361 395 350 364 371 365 384 356 352 378 385 350 358 407 393 370 369 363 377 382 357 365 373 350 352 383 370 362 355 358 385 359 359 336 384 384 346 378 366 373 348 377 360 376 385 338 374 347 361 383 374 367 355 375 374 363 366 366 337 381 327 394 389 366 362 372 404 378 372 406 339 400 324 364 329 351 364 372 353 368 367 350 372 395 386 344 421 377 373 363 405 392 390 375 341 337 381 382 356 345 316 343 342 322 343 379 369 375 365 357 382 368 322 369 354 356 345 383 360 357 315 357 347 356 394 362 373 345 404 394 381 379 351 370 358 377 355 383 353 375 419 363 366 377 345 361 368 357 368 376 356 368 349 371 359 352 367 364 378 353 348 347 343 362 374 388 355 338 382 382 385 383 422 383 350 372 373 349 345 333 354 341 376 391 348 366 348 358 362 355 337 341 322 368 367 361 341 370 336 357 360 361 360 345 358 349 372 376 389 352 345 359 361 381 341 360 342 350 381 353 341 365 363 410 397 357 374 334 381 368 360 344 360 344 363 373 360 363 342 393 359 352 382 356 387 371 358 367 365 327 363 349 374 381 366 357 364 352 355 363 344 380 341 361 342 360 352 362 382 373 366 395 351 397 376 370 369 368 370 370 360 344 358 328 369 371 380 365 357 318 396 352 355 350 362 354 347 351 352 339 402 357 358 374 366 362 359 362 379 395 358 388 361 354 377 403 353 355 373 355 353 372 409 358 359 364 367 343 370 387 400 348 376 354 378 346 372 341 392 369 394 378 340 350 325 344 388 371 355 366 356 364 362 378 365 365 390 377 358 376 375 408 362 386 377 364 341 329 393 383 381 354 358 419 378 362 367 357 399 391 377 353 378 370 346 346 384 364 352 373 395 344 418 354 371 376 377 372 352 386 347 347 375 368 337 389 418 345 372 367 358 347 371 353 372 369 365 376 367 391 392 344 386 382 328 338 354 365 373 371 370 372 330 342 390 364 345 389 374 332 367 351 348 352 324 376 364 355 360 365 353 356 358 369 376 343 384 356 382 353 366 356 331 358 368 353 380 360 351 408 359 362 405 341 363 382 359 339 356 381 357 379 373 378 357 364 392 382 394 369 349 390 362 376 370 361 356 361 365 358 348 378 356 343 345 365 411 360 344 372 379 354 362 388 377 363 357 350 355 390 381 360 363 333 374 394 359 379 356 360 359 351 364 319 353 359 413 404 384 372 388 388 388 363 371 352 341 394 342 387 377 354 367 345 362 390 399 383 360 359 361 386 357 333 327 366 354 409 380 389 361 392 384 397 373 393 348 349 367 345 377 350 360 381 346 353 374 388 398 337 319 369 396 358 352 369 384 367 373 385 347 362 365 383 348 378 369 373 372 368 392 386 345 356 336 396 374 382 352 372 351 369 360 348 339 350 357 376 397 354 323 394 367 384 337 370 355 349 435 375 345 337 382 380 370 395 348 344 358 401 368 375 363 356 357 362 386 369 377 404 335 387 373 347 378 374 376 334 315 351 361 343 366 384 356 365 362 328 385 398 350 375 350 379 358 379 387 363 360 396 362 350 364 389 377 362 357 344 330 373 351 374 352 377 344 375 362 358 390 367 368 389 361 417 414 357 339 355 361 405 397 386 365 395 365 353 388 336 349 357 359 365 356 372 411 371 388 362 372 387 353 367 391 362 350 382 374 350 390 346 341 353 383 374 355 381 376 363 388 317 360 319 382 372 343 371 345 361 348 385 362 354 381 376 348 383 383 396 363 360 370 374 354 357 381 371 346 353 390 358 360 379 376 383 407 355 397 370 354 394 361 388 353 381 369 351 386 366 344 374 374 361 366 357 397 381 367 365 378 366 364 336 351 348 384 379 382 357 343 404 354 414 348 381 357 371 346 390 373 370 390 410 387 358 366 374 369 394 370 373 338 356 389 345 389 363 340 350 394 362 375 364 399 341 382 338 355 333 382 396 363 356 358 340 366 369 406 343 360 418 389 328 367 391 356 366 356 343 336 372 368 381 398 383 408 344 344 362 361 335 379 364 382 367 335 375 353 363 391 359 344 361 347 370 361 358 370 329 372 401 401 355 379 351 369 389 367 397 377 394 353 390 364 413 338 390 373 339 397 373 353 385 346 354 331 360 353 388 362 339 403 362 376 374 373 361 346 351 347 386 361 356 393 370 360 344 375 344 369 372 346 393 350 363 408 376 400 353 398 375 352 382 362 371 365 379 347 353 366 340 355 360 354 349 364 362 353 402 332 384 352 390 366 371 346 369 362 357 360 374 356 350 398 426 367 352 354 374 339 387 371 388 383 368 354 369 365 398 368 350 365 372 364 341 392 389 378 343 347 366 388 359 355 384 387 353 428 373 381 370 325 371 362 373 344 352 381 368 386 397 360 390 364 366 396 367 363 372 354 353 349 372 362 355 386 338 370 356 373 376 344 343 386 380 398 387 389 382 370 361 354 384 350 360 371 366 361 358 361 370 346 381 349 368 354 379 363 361 363 353 387 357 391 366 371 376 382 389 362 369 384 391 375 374 356 387 354 387 340 333 338 344 365 382 353 390 342 363 377 359 383 354 329 349 341 365 358 359 359 370 370 357 349 375 357 386 374 335 378 358 345 361 366 362 384 360 337 349 396 386 405 361 390 387 416 362 366 359 424 374 339 408 362 401 371</counts>
			</dataPoints>
		</scan>
	</xrdMeasurement>
</xrdMeasurements>