File: data/XRD/_misc/SampleHolder_absolute_2th-om_10-130deg_PIXscan_17min_1.xrdml
<xrdMeasurements xmlns="http://www.xrdml.com/XRDMeasurement/2.1" xmlns:xsi="http://www.w3.org/2001/XMLSchema-instance" xsi:schemaLocation="http://www.xrdml.com/XRDMeasurement/2.1 http://www.xrdml.com/XRDMeasurement/2.1/XRDMeasurement.xsd" status="Completed">
	<comment>
		<entry>Configuration=Factory configuration, Owner=User-1, Creation date=7/8/2013 4:01:53 PM</entry>
		<entry>Goniometer=PW3050/65 (Theta/2Theta); Minimum step size 2Theta:0.0001; Minimum step size Omega:0.0001</entry>
		<entry>Sample stage=MRD Cradle; Minimum step size Phi:0.01; Minimum step size Chi:0.01; Minimum step size X:0.01; Minimum step size Y:0.01; Minimum step size Z:0.001</entry>
		<entry>Diffractometer system=XPERT-PRO</entry>
		<entry>Measurement program=C:\PANalytical\Data Collector\Programs\Clemens\2theta-omega\_absolute_2th-om_10-130deg_PIXscan_17min.xrdmp, Identifier={9BCB2CD6-D60F-4B79-81CB-4704B13CA475}</entry>
	</comment>
	<sample type="To be analyzed">
		<id></id>
		<name></name>
		<preparedBy></preparedBy>
	</sample>
	<xrdMeasurement measurementType="Scan" status="Completed" sampleMode="Reflection">
		<comment>
			<entry>2theta-omega 10-130 deg PIXscan 17min</entry>
			<entry>PHD Lower Level = 4.83 (keV), PHD Upper Level = 11.27 (keV)</entry>
		</comment>
		<usedWavelength intended="K-Alpha 1">
			<kAlpha1 unit="Angstrom">1.5405980</kAlpha1>
			<kAlpha2 unit="Angstrom">1.5444260</kAlpha2>
			<kBeta unit="Angstrom">1.3922500</kBeta>
			<ratioKAlpha2KAlpha1>0.5000</ratioKAlpha2KAlpha1>
		</usedWavelength>
		<incidentBeamPath>
			<radius unit="mm">320.00</radius>
			<xRayTube id="1010048" name="Empyrean Cu LFF HR (9430 033 7310x) DK442154">
				<tension unit="kV">40.0</tension>
				<current unit="mA">40.0</current>
				<anodeMaterial>Cu</anodeMaterial>
				<focus type="Line">
					<length unit="mm">12.0</length>
					<width unit="mm">0.4</width>
					<takeOffAngle unit="deg">4.2</takeOffAngle>
				</focus>
			</xRayTube>
			<xRayMirror id="27010001" name="Inc. Beam Cu W/Si (parabolic MRD)" hybrid="false">
				<crystal type="Graded" shape="Parabolic">W/Si</crystal>
				<acceptanceAngle unit="deg">0.800</acceptanceAngle>
				<length unit="mm">60.0</length>
			</xRayMirror>
			<sollerSlit id="21010002" name="Soller slits 0.04 rad.">
				<opening unit="rad">0.0400</opening>
			</sollerSlit>
			<mask id="22030007" name="Fixed mask 2 mm">
				<distanceToSample unit="mm">220.00</distanceToSample>
				<width unit="mm">2.00</width>
			</mask>
			<divergenceSlit id="22010007" name="Fixed slit 1/8°" xsi:type="fixedDivergenceSlitType">
				<distanceToSample unit="mm">220.00</distanceToSample>
				<height unit="mm">0.19</height>
			</divergenceSlit>
		</incidentBeamPath>
		<diffractedBeamPath>
			<radius unit="mm">320.00</radius>
			<sollerSlit id="21010002" name="Soller slits 0.04 rad.">
				<opening unit="rad">0.0400</opening>
			</sollerSlit>
			<receivingSlit id="22010001" name="Fixed slit 4°">
				<height unit="mm">5.88</height>
			</receivingSlit>
			<detector id="7010017" name="PIXcel3D 1x1 detector" xsi:type="areaDetectorType">
				<phd unit="%">
					<lowerLevel>30.0</lowerLevel>
					<upperLevel>70.0</upperLevel>
				</phd>
				<mode>Scanning</mode>
				<activeChannelsEquatorial>255</activeChannelsEquatorial>
				<activeChannelsAxial>255</activeChannelsAxial>
				<pitchEquatorial unit="mm">0.05500</pitchEquatorial>
				<pitchAxial unit="mm">0.05500</pitchAxial>
				<readOutPeriod unit="seconds">0.040</readOutPeriod>
			</detector>
		</diffractedBeamPath>
		<scan appendNumber="0" mode="Continuous" scanAxis="2Theta-Omega" status="Completed">
			<header>
				<startTimeStamp>2024-08-05T14:16:56+02:00</startTimeStamp>
				<endTimeStamp>2024-08-05T14:33:39+02:00</endTimeStamp>
				<author>
					<name>PRO-MRD</name>
				</author>
				<source>
					<applicationSoftware version="6.1b">Data Collector</applicationSoftware>
					<instrumentControlSoftware version="7.0E 20130304">XPERT-PRO</instrumentControlSoftware>
					<instrumentID>0000000011142674</instrumentID>
				</source>
			</header>
			<dataPoints>
				<positions axis="2Theta" unit="deg">
					<startPosition>10.00346193</startPosition>
					<endPosition>129.99783297</endPosition>
				</positions>
				<positions axis="Omega" unit="deg">
					<startPosition>5.00173097</startPosition>
					<endPosition>64.99891648</endPosition>
				</positions>
				<positions axis="Phi" unit="deg">
					<commonPosition>0.00</commonPosition>
				</positions>
				<positions axis="Chi" unit="deg">
					<commonPosition>0.00</commonPosition>
				</positions>
				<positions axis="X" unit="mm">
					<commonPosition>-30.00</commonPosition>
				</positions>
				<positions axis="Y" unit="mm">
					<commonPosition>0.00</commonPosition>
				</positions>
				<positions axis="Z" unit="mm">
					<commonPosition>9.100</commonPosition>
				</positions>
				<commonCountingTime unit="seconds">8.670</commonCountingTime>
				<counts 76 78 65 70 85 78 71 76 90 73 82 101 71 85 77 82 87 66 78 73 80 71 81 90 79 72 114 70 89 86 98 79 65 77 63 91 83 75 81 83 70 68 63 87 69 75 80 85 81 77 75 80 79 69 65 80 71 77 82 64 92 74 81 59 63 77 80 69 84 90 75 81 70 72 79 75 74 64 80 79 70 69 75 67 91 87 79 75 71 81 74 80 88 78 69 68 76 83 84 69 80 79 69 79 57 62 76 75 84 76 62 76 74 68 65 78 89 68 70 89 69 75 79 75 66 80 68 72 71 79 81 81 70 72 82 83 77 66 73 66 61 64 67 66 74 67 78 103 74 72 85 68 56 59 77 92 69 83 63 46 64 67 79 61 52 63 72 58 72 77 86 84 70 67 83 74 71 101 63 68 77 70 67 57 86 87 79 63 69 61 53 73 59 68 65 58 71 63 71 61 80 73 62 69 89 89 69 72 77 66 64 79 71 73 80 74 58 60 76 68 73 70 65 71 69 64 65 64 75 66 82 62 89 58 78 75 73 64 69 80 77 70 86 64 54 67 65 75 72 61 70 78 65 62 78 63 62 75 80 69 67 46 84 63 61 61 77 90 90 71 77 70 75 60 74 84 90 66 69 64 66 60 69 57 79 67 63 59 68 58 78 71 84 70 56 74 55 59 73 65 71 60 58 71 61 74 80 63 62 69 65 69 66 78 62 73 62 71 72 68 65 61 65 76 79 75 86 72 65 67 84 66 75 65 73 75 64 79 77 68 61 65 55 67 70 65 72 60 79 74 63 49 63 79 51 67 61 70 62 67 71 59 61 56 66 50 60 82 55 63 60 70 66 58 61 58 63 60 72 63 67 75 58 69 65 70 62 70 77 78 65 71 55 62 83 75 52 61 59 61 64 66 69 61 71 64 56 56 68 63 60 69 71 63 87 56 63 64 59 58 58 73 68 60 58 56 63 63 52 65 60 63 61 56 47 69 69 66 59 45 68 65 77 71 56 52 67 59 58 63 66 58 65 68 64 71 63 64 52 60 58 56 74 72 66 62 78 67 58 58 55 45 61 55 59 51 50 68 61 47 62 49 66 68 76 73 56 50 65 65 58 75 76 61 68 64 51 63 64 64 55 51 58 63 68 62 66 69 59 60 65 69 61 63 54 55 62 58 76 61 63 65 85 51 51 67 53 57 59 56 69 78 52 60 57 68 55 53 75 62 47 53 72 63 59 55 54 66 69 73 65 56 56 56 45 71 50 59 51 57 68 54 50 67 67 67 53 65 59 66 74 67 73 55 61 59 49 60 51 68 72 51 63 60 55 48 66 72 58 51 64 67 62 54 62 50 50 55 66 57 64 61 66 54 61 64 79 51 64 56 60 59 68 51 65 49 67 53 62 72 64 61 70 63 66 54 62 53 46 55 55 60 57 68 61 65 54 66 52 61 59 71 45 62 64 48 54 69 66 72 57 60 52 45 65 51 72 62 51 69 58 61 54 51 70 53 65 51 51 59 50 62 56 51 55 65 63 57 64 34 54 48 60 55 42 75 47 54 50 60 59 66 63 52 61 58 66 54 69 61 61 60 60 66 55 56 48 72 62 58 65 54 69 50 55 72 59 60 54 46 56 66 60 53 67 60 64 54 49 60 55 51 47 55 70 52 51 56 62 49 64 62 55 55 47 60 53 48 57 66 56 65 54 48 61 63 64 65 49 65 54 47 48 62 43 55 61 60 51 61 53 59 63 58 64 60 76 43 72 49 64 61 65 45 55 35 70 57 58 44 50 58 65 51 55 62 68 60 51 58 44 65 56 56 56 57 54 57 63 56 63 50 51 53 58 46 46 55 52 51 54 49 56 50 64 57 50 60 63 51 69 59 49 66 64 52 51 61 52 42 62 51 65 66 65 55 53 66 43 54 59 66 63 61 43 61 54 63 48 49 66 42 56 50 51 45 54 56 46 62 52 67 53 46 63 55 50 52 53 55 80 51 50 48 68 55 44 45 52 59 64 62 59 60 68 62 52 64 51 46 49 57 75 49 49 50 60 54 57 46 73 52 51 53 56 46 55 75 52 56 61 52 66 48 72 64 57 61 61 53 46 73 50 64 52 52 37 47 59 42 51 54 55 49 59 48 40 52 66 57 66 51 78 45 63 51 52 48 53 50 52 65 49 53 65 54 45 53 66 63 58 68 48 43 60 58 64 50 58 53 62 56 56 62 56 45 50 50 50 43 51 61 54 50 41 47 59 58 70 54 56 46 48 57 57 50 51 51 47 61 57 43 45 61 41 61 60 58 54 44 56 46 55 54 68 57 61 61 43 49 55 66 60 49 46 46 42 50 62 61 54 57 44 56 39 60 62 52 46 61 61 50 50 52 53 49 48 52 44 59 50 47 59 50 50 45 50 43 54 63 48 48 48 52 55 50 51 67 39 66 57 44 54 47 54 56 52 44 55 43 64 75 53 60 51 52 52 52 66 55 50 74 50 51 51 63 59 53 60 56 54 47 61 55 66 59 63 47 57 61 60 53 50 57 57 49 53 59 50 44 69 53 48 47 54 50 62 54 57 57 40 62 46 58 53 62 61 47 49 58 57 59 60 51 59 61 55 56 59 67 55 39 73 50 40 48 58 52 62 53 54 68 37 56 49 59 47 44 51 53 54 58 55 60 48 58 58 55 54 39 55 59 64 53 48 46 50 47 50 40 38 47 46 56 55 54 59 66 56 63 39 54 45 79 51 57 50 43 57 49 55 62 41 67 61 42 48 49 59 58 51 51 47 53 48 41 56 49 62 65 63 51 61 51 52 67 65 62 47 49 52 60 70 51 56 45 60 54 62 52 53 52 53 60 52 43 50 52 41 48 58 43 53 63 51 55 43 66 55 64 51 54 49 50 66 54 56 51 62 48 67 56 51 42 58 46 56 53 47 64 60 55 68 53 67 39 41 55 51 56 53 48 52 43 48 54 48 62 52 57 54 55 40 53 53 58 45 60 49 52 62 44 47 59 47 47 49 53 65 50 63 44 44 42 64 51 45 52 54 50 45 58 44 58 52 56 58 46 76 62 57 55 63 64 64 37 64 51 55 56 53 51 46 43 51 56 47 41 60 46 60 57 58 48 69 46 51 42 48 53 54 48 51 51 57 50 57 48 49 50 48 41 52 49 63 40 49 43 49 39 48 41 67 61 58 40 56 42 42 52 37 42 48 50 56 48 61 56 54 53 51 57 46 41 48 61 46 59 57 55 41 55 53 62 55 50 48 55 54 56 50 56 61 56 45 55 43 55 55 56 65 42 54 61 51 49 49 52 56 59 47 56 48 55 57 53 50 64 42 46 37 57 61 70 35 49 59 43 46 41 58 43 38 53 50 61 53 51 53 47 43 44 60 37 56 39 51 52 50 51 47 50 44 61 49 45 48 50 56 52 55 57 64 52 68 54 60 43 58 54 48 52 65 43 48 47 52 42 49 43 48 47 59 47 46 60 49 43 53 51 54 58 62 54 54 65 61 48 53 47 45 69 40 67 38 61 49 63 55 56 66 49 52 49 56 56 51 50 64 49 50 51 55 44 57 56 62 64 54 51 54 57 54 46 58 51 50 49 37 52 42 50 52 49 59 45 41 51 50 46 54 50 45 57 42 53 62 52 53 49 52 59 46 53 43 49 51 45 60 61 59 35 52 63 49 49 43 43 64 52 59 43 45 46 48 52 52 40 65 59 55 59 54 63 59 56 50 58 68 50 57 41 50 56 46 41 54 59 69 54 63 50 54 50 40 51 45 50 64 59 64 62 59 50 52 53 58 45 50 57 67 48 36 40 49 45 59 50 43 46 50 58 40 49 63 38 53 47 47 45 47 62 41 47 56 48 47 54 47 58 56 39 53 39 60 65 52 64 66 48 42 48 62 49 56 50 55 61 46 51 56 63 50 60 46 41 47 52 45 47 55 56 38 59 46 49 49 47 53 61 62 62 48 57 47 66 49 58 64 57 49 45 50 53 51 59 51 51 56 51 63 71 63 61 57 49 40 57 43 55 55 56 53 46 61 41 53 55 46 60 52 47 48 34 47 52 48 52 33 49 53 57 49 35 55 38 53 41 55 55 61 69 44 44 57 63 55 48 61 52 48 55 55 53 50 59 42 55 60 56 55 55 50 63 46 43 60 66 60 47 45 54 48 51 58 48 59 60 48 44 56 46 45 36 44 55 54 56 47 50 51 41 47 62 57 53 55 54 55 64 48 65 41 55 58 59 57 57 47 51 48 63 46 75 46 54 43 60 52 60 42 52 55 64 63 45 55 56 59 44 64 52 65 41 50 56 43 52 53 65 52 58 57 47 45 58 51 57 52 57 57 55 55 44 62 60 52 59 52 60 56 50 57 64 56 53 56 51 54 52 63 56 59 47 48 61 53 64 61 47 43 70 57 59 57 43 57 62 64 50 72 64 57 49 53 64 61 59 63 50 63 53 59 63 54 54 49 52 58 60 48 46 56 59 53 45 66 48 54 61 49 53 50 62 45 51 55 47 38 58 53 55 54 41 59 45 66 72 60 61 45 60 58 56 55 69 55 59 64 63 54 51 54 55 48 52 65 58 62 61 55 46 52 51 59 54 54 59 62 64 46 47 57 58 52 42 59 54 65 49 70 53 43 70 54 53 60 49 47 57 53 59 61 38 49 45 52 58 69 60 62 63 69 48 63 65 46 54 56 48 62 63 55 63 47 59 68 59 61 70 66 55 56 58 67 54 44 53 61 57 50 59 51 60 47 57 49 52 60 54 62 56 65 44 52 63 56 71 60 70 54 44 56 50 48 53 54 58 46 63 79 38 59 52 55 49 50 64 65 62 50 66 53 56 51 55 51 52 69 48 56 68 61 55 54 57 62 51 58 56 60 66 57 36 56 56 48 48 46 58 51 59 59 61 53 55 56 55 47 69 53 65 60 63 61 55 64 51 64 61 53 47 55 51 52 54 56 67 58 62 55 57 57 51 53 54 62 54 50 53 62 47 63 50 52 43 64 58 58 60 63 66 63 59 53 53 51 55 75 62 49 49 62 51 57 57 62 57 42 62 54 61 57 54 63 63 53 57 42 54 59 61 52 48 62 60 56 58 57 64 59 55 56 48 63 66 66 52 61 58 67 49 49 72 51 45 65 56 53 52 70 67 66 52 74 55 44 75 45 58 56 56 54 64 66 48 45 55 62 56 62 61 69 69 64 45 46 79 57 57 61 55 55 67 65 56 50 60 44 47 60 60 62 59 69 54 53 60 60 57 68 64 64 50 52 57 64 48 55 52 60 74 44 66 66 36 55 60 57 68 62 54 40 42 65 51 53 41 62 57 71 49 64 51 50 49 56 50 49 58 68 64 56 70 60 68 68 57 65 55 53 56 49 58 47 55 61 63 66 54 58 59 64 44 58 46 42 69 60 50 63 61 54 63 54 45 59 53 60 54 75 67 66 61 42 51 75 58 70 73 57 49 59 73 58 62 64 72 45 53 53 62 59 48 42 52 53 50 54 58 60 47 63 57 67 65 68 58 64 57 61 53 49 47 55 63 60 67 62 54 58 72 59 69 57 59 60 52 61 46 53 50 63 50 50 66 62 49 54 63 56 62 50 62 60 59 61 61 40 63 61 50 62 55 49 80 67 51 53 63 72 48 73 53 62 74 49 43 72 48 58 61 68 63 52 59 59 55 65 64 58 64 59 66 78 59 65 56 83 63 66 60 54 57 56 61 49 53 64 57 63 52 48 70 56 68 67 71 66 57 68 47 67 50 64 71 63 61 63 60 71 59 54 55 59 49 59 59 65 75 59 62 68 62 52 67 70 47 51 61 59 53 56 63 58 55 59 55 57 67 63 63 58 75 51 71 58 48 66 51 57 58 53 62 62 57 64 83 68 68 54 71 80 60 57 70 83 60 55 60 69 64 61 50 81 54 58 78 54 55 65 58 61 54 73 58 63 48 47 71 65 70 55 55 59 55 59 68 74 64 72 56 53 77 56 64 61 64 57 62 64 66 67 54 48 67 63 68 62 70 68 72 67 53 70 56 63 51 65 62 65 49 65 71 70 62 61 67 63 78 60 70 55 64 73 68 74 83 64 75 69 68 60 68 66 59 62 72 70 73 55 72 69 72 49 56 69 58 56 59 71 58 52 67 75 71 86 57 83 60 61 58 70 59 55 63 59 63 64 70 60 77 54 71 72 66 58 63 60 73 71 80 62 63 79 63 65 62 65 69 60 62 81 66 52 60 52 49 64 60 63 58 70 68 72 56 76 65 61 68 61 53 55 56 65 64 75 57 70 64 73 67 71 80 66 48 75 68 70 51 75 62 67 77 68 63 65 73 47 71 61 68 66 71 77 51 81 70 59 65 66 63 70 89 59 85 81 71 62 57 68 62 60 60 57 74 62 80 68 58 62 59 71 66 75 64 60 66 64 77 68 54 67 70 66 54 63 71 59 68 69 64 59 78 70 75 72 68 69 39 58 73 78 65 69 68 63 67 61 68 69 72 74 79 59 60 71 57 71 67 69 73 63 66 66 58 58 59 84 59 58 59 68 67 57 65 63 61 63 64 70 72 64 70 65 65 66 73 78 57 71 72 62 62 61 76 62 72 78 71 66 67 69 49 69 82 59 66 65 75 60 64 63 81 80 77 73 58 75 62 56 63 69 61 76 69 72 60 65 72 66 53 50 71 60 72 71 64 81 67 63 84 82 74 49 73 65 69 61 70 72 66 75 70 62 65 54 60 70 55 66 69 62 52 64 67 82 64 65 76 81 65 60 71 65 60 83 60 68 71 65 67 55 68 89 61 68 69 77 79 75 72 62 66 74 70 67 68 66 72 78 82 57 58 80 62 66 88 64 59 66 60 66 63 75 71 69 59 58 62 72 74 60 56 65 61 72 85 77 82 66 62 83 83 62 62 63 77 63 71 71 81 63 75 74 57 62 62 80 72 62 60 68 78 72 73 82 60 90 69 74 64 61 73 70 71 71 78 71 72 63 83 57 81 55 70 49 63 78 67 64 66 73 59 81 64 79 72 79 61 63 72 68 64 69 89 49 73 56 55 64 64 66 86 81 86 66 74 79 48 66 76 90 76 69 72 59 76 66 78 68 78 64 67 59 74 77 71 64 73 69 70 66 67 76 66 54 75 69 75 75 59 75 68 62 65 52 79 55 70 71 66 65 66 88 73 68 81 67 47 77 65 59 71 58 68 69 62 69 68 62 78 63 58 74 77 65 79 79 55 74 67 87 68 74 61 85 58 60 71 74 88 72 69 69 72 78 58 75 75 87 75 77 65 63 71 70 72 76 78 94 72 61 76 64 67 78 58 76 70 85 66 67 67 78 70 66 71 73 69 72 68 60 73 58 56 73 77 63 60 59 75 59 80 70 69 63 64 64 62 69 77 62 72 78 71 52 60 67 90 70 71 71 71 73 64 65 53 57 69 73 85 78 74 61 66 63 60 69 92 59 74 74 62 82 72 83 62 53 71 73 70 86 63 79 64 62 68 69 84 73 83 80 81 83 72 76 67 85 61 61 69 88 86 79 67 71 78 80 88 74 59 88 58 58 76 67 93 63 66 52 63 71 63 65 74 70 70 58 80 55 68 75 62 82 69 93 72 66 84 79 90 80 64 66 65 89 76 73 73 68 76 66 85 81 73 75 78 99 77 70 83 71 78 86 79 80 95 93 67 69 63 78 86 73 75 86 75 84 81 79 65 72 88 96 76 94 65 85 83 86 97 71 85 96 75 88 84 107 97 100 103 105 101 93 86 97 98 97 107 95 83 122 96 105 100 106 129 106 100 112 108 119 137 138 126 148 138 137 139 154 133 157 161 171 168 155 169 143 165 145 148 126 159 142 141 136 121 128 139 126 121 135 130 130 117 103 115 104 99 107 109 114 104 103 89 106 83 98 84 102 84 92 87 86 94 101 86 77 76 102 66 80 68 73 75 85 66 81 77 76 82 87 65 70 76 80 84 84 70 78 81 67 71 88 70 71 94 88 77 77 81 85 80 79 76 67 69 85 66 83 68 77 79 75 80 76 86 69 66 80 68 81 67 79 85 65 74 71 66 77 75 93 82 96 55 62 60 65 83 84 77 96 79 70 74 84 92 91 77 80 72 63 81 66 82 64 79 72 64 73 80 67 70 77 65 80 74 88 74 69 70 69 91 73 83 69 84 91 64 69 84 74 74 70 80 69 69 76 53 73 66 73 87 73 64 80 83 79 64 99 74 71 83 75 73 76 74 65 77 78 83 79 68 72 64 60 80 62 69 67 54 69 63 85 74 68 80 73 76 70 70 60 74 71 66 78 80 72 83 80 84 78 76 55 60 68 87 71 66 78 67 79 85 69 77 64 79 74 71 65 77 69 95 75 76 71 76 81 58 81 71 93 83 75 60 67 77 88 70 79 76 91 83 80 77 78 83 69 79 71 92 67 78 73 95 74 65 83 66 90 73 93 88 72 78 78 78 58 70 88 66 90 70 84 94 58 77 82 80 71 77 71 75 70 57 56 54 90 78 82 88 69 65 76 79 79 84 79 77 76 72 72 74 84 65 60 73 67 75 70 66 64 73 90 71 83 76 71 93 86 91 88 71 91 73 81 62 69 89 71 77 82 61 84 80 68 72 68 94 89 66 72 78 67 66 87 68 84 62 78 70 88 82 90 84 76 87 74 80 71 80 69 96 76 87 73 78 90 79 85 86 71 67 75 88 92 82 78 82 83 89 73 77 67 78 65 81 78 80 75 82 78 90 71 57 82 62 75 88 67 75 66 66 77 91 80 74 77 81 61 94 73 76 83 76 72 68 81 84 82 82 59 90 72 72 68 83 81 74 77 67 58 80 85 101 67 70 88 94 88 79 74 71 79 63 95 79 84 84 79 70 62 65 88 77 86 70 75 82 77 66 62 64 79 89 71 81 86 81 78 82 72 72 72 73 75 69 83 73 75 71 87 69 73 77 80 82 70 63 81 71 85 77 69 68 84 78 76 93 80 75 83 73 66 83 68 70 79 71 74 83 81 69 91 90 71 75 74 70 72 65 88 79 69 63 84 85 70 79 78 61 92 85 75 85 67 80 88 80 82 95 69 86 72 95 71 67 78 89 89 65 80 79 78 91 79 72 69 90 71 74 73 72 91 73 76 85 92 85 70 65 79 65 89 74 72 81 84 73 70 91 66 74 81 81 80 70 86 80 78 73 75 83 103 83 82 80 95 73 81 69 88 83 67 69 72 88 81 72 82 80 68 60 80 69 70 70 68 73 52 79 88 71 74 75 74 89 76 76 77 68 83 80 74 70 107 87 98 73 74 72 72 82 76 64 80 87 106 83 91 75 70 89 79 80 65 86 75 77 70 60 65 73 65 75 102 81 84 91 75 84 68 78 75 87 88 85 82 82 63 78 73 79 88 90 85 81 96 72 85 81 84 78 83 75 78 82 56 73 73 86 94 83 82 78 76 68 78 73 96 77 85 75 69 83 79 76 90 73 78 76 70 79 70 72 82 83 87 86 88 74 74 69 81 75 66 96 69 81 76 83 90 79 86 84 85 69 86 80 83 80 73 79 90 66 74 75 79 100 71 62 96 73 69 85 81 73 76 76 72 63 84 92 90 68 70 93 76 81 81 82 77 73 72 88 69 79 79 87 75 77 85 79 65 78 92 81 74 75 75 89 60 71 91 68 80 101 78 69 83 92 77 99 75 86 74 88 77 69 78 73 63 90 86 80 85 81 87 80 79 94 73 81 81 72 86 73 85 79 88 80 98 76 89 75 93 88 86 87 104 70 81 83 80 69 90 71 83 67 88 93 88 93 79 79 76 60 85 74 68 83 84 86 63 76 89 77 73 73 77 88 89 69 73 89 99 84 86 77 80 97 82 101 76 79 99 88 86 87 76 87 98 88 92 82 97 70 85 88 67 77 69 86 83 76 80 84 78 91 94 69 81 88 77 93 74 84 82 95 86 79 81 73 71 83 95 85 87 80 76 81 84 84 76 86 87 75 74 81 85 93 78 78 70 78 89 83 84 79 76 71 70 77 71 78 71 84 88 69 79 90 76 73 77 73 80 82 80 92 89 73 73 67 86 85 91 80 85 73 89 82 79 75 92 86 83 75 88 85 79 89 99 69 67 80 87 74 60 85 78 81 80 70 89 89 93 81 73 75 92 80 90 74 85 74 73 93 90 92 72 82 67 86 69 74 91 75 75 88 83 97 65 78 79 83 79 86 92 81 78 76 95 82 73 81 73 75 86 73 78 72 72 82 77 70 84 73 71 74 79 89 94 78 66 81 86 74 84 86 91 87 94 92 76 65 72 82 69 76 81 88 87 86 85 89 69 88 74 77 82 89 78 84 79 74 77 99 88 86 71 82 79 72 71 82 89 86 94 83 83 69 86 86 86 84 92 83 87 82 80 84 82 79 84 75 69 66 73 79 83 88 82 80 76 78 83 73 76 84 82 81 88 78 75 82 82 102 78 66 86 80 91 93 76 83 89 71 71 76 72 84 101 80 75 75 63 93 66 77 80 72 80 101 86 79 89 99 79 83 81 83 98 73 73 84 69 76 75 88 82 84 77 87 98 85 88 70 79 95 83 81 83 84 70 76 77 80 72 85 75 90 80 88 97 95 88 80 98 79 85 82 79 84 83 74 82 86 90 82 71 85 86 91 77 85 82 74 80 69 80 88 76 92 91 82 85 92 84 69 91 89 58 77 81 92 86 91 83 81 88 84 71 89 71 95 97 84 82 63 88 79 91 94 79 86 95 80 84 83 87 73 100 77 84 78 95 95 93 86 68 73 89 89 93 77 77 91 94 61 92 87 78 94 91 85 75 73 77 89 78 80 74 63 80 72 94 89 82 84 68 94 81 77 101 92 87 67 65 81 77 93 86 70 102 78 76 71 90 93 95 94 64 77 73 73 96 63 82 83 89 81 95 74 72 81 79 99 92 74 92 89 78 74 67 95 88 76 84 88 94 79 75 91 72 85 82 76 96 78 85 89 99 85 81 77 105 86 82 84 87 81 90 90 90 87 87 87 85 93 78 90 84 84 91 99 82 94 82 98 77 65 98 78 91 84 70 73 68 72 63 89 77 70 98 81 88 72 88 64 75 96 71 81 81 65 93 77 89 74 86 84 91 83 91 102 87 82 75 84 97 69 96 97 68 78 75 91 94 88 83 93 89 74 90 81 84 78 63 91 87 73 73 84 80 68 91 83 75 75 96 86 76 82 91 87 98 71 103 85 94 89 69 87 79 93 88 89 90 88 103 78 84 93 95 90 80 93 79 78 84 86 96 76 95 94 80 88 83 94 70 107 84 88 69 97 106 101 86 89 84 81 79 108 74 82 80 84 90 94 90 94 77 90 85 99 89 94 105 92 91 62 107 95 87 92 85 89 80 82 87 78 108 73 80 86 82 83 83 89 70 108 82 80 102 91 94 75 92 85 94 81 90 77 79 87 78 106 81 104 67 86 91 110 99 86 101 89 81 79 84 93 94 86 86 78 88 98 96 91 81 79 93 91 80 99 96 88 65 94 77 94 90 81 82 89 85 103 96 93 80 73 77 96 84 90 91 77 86 90 69 89 87 80 97 77 95 87 88 90 103 91 79 91 88 98 96 85 80 90 96 67 93 98 94 66 95 83 91 90 81 75 108 97 71 90 75 87 100 85 78 87 97 94 84 83 94 94 77 83 90 85 69 91 90 103 86 92 102 81 95 105 75 82 98 93 97 68 86 88 80 81 94 85 81 90 75 99 91 95 99 97 91 88 76 80 89 86 79 79 88 93 94 101 108 81 91 64 80 93 84 92 97 87 103 84 93 63 84 77 89 79 104 94 87 91 75 93 97 96 82 85 111 91 99 94 92 87 83 92 108 103 99 105 92 96 89 94 97 90 81 70 99 88 77 104 92 90 93 99 84 72 107 94 98 97 89 96 86 108 66 88 101 89 91 83 86 82 83 90 90 76 97 85 102 91 100 93 87 75 87 103 88 95 75 93 96 90 79 80 76 104 93 95 82 90 73 81 95 85 77 85 83 89 103 89 106 87 94 81 83 78 74 94 107 91 90 86 81 78 99 95 86 92 77 93 92 90 81 85 87 85 98 109 87 81 96 78 81 77 91 87 94 106 87 75 79 80 87 95 102 81 106 89 92 84 66 88 85 74 89 94 74 85 94 68 78 85 83 84 93 104 82 92 90 106 78 85 85 91 94 96 92 108 99 68 68 90 103 98 104 92 105 74 100 97 90 80 88 78 88 87 100 93 88 83 72 81 95 84 96 94 104 80 98 71 73 83 96 92 91 89 84 77 81 80 104 85 77 87 92 88 89 92 93 87 104 87 86 102 80 93 88 92 82 86 85 79 109 84 93 79 93 72 72 87 100 80 76 75 86 95 84 102 75 85 110 78 103 86 98 111 94 94 85 71 84 86 80 87 89 91 86 83 86 93 92 81 83 136 95 95 100 101 79 100 87 97 106 88 105 101 103 94 94 107 85 88 89 106 90 94 99 93 100 88 97 96 94 93 104 95 104 95 106 82 113 100 91 88 95 114 105 88 91 106 84 82 103 100 123 100 97 96 82 94 92 90 94 95 80 93 101 76 108 96 104 90 92 104 85 87 91 75 97 85 93 85 102 97 79 80 101 90 93 91 113 87 79 86 84 86 89 100 94 88 90 87 89 82 97 98 98 90 69 98 77 87 82 89 84 86 90 81 94 93 98 90 98 90 88 119 79 107 88 83 74 79 93 90 79 91 77 83 107 88 97 98 79 93 85 93 71 73 87 80 71 103 90 76 90 102 85 84 125 86 117 103 92 79 112 102 83 98 87 84 92 84 93 89 98 95 99 84 82 101 94 85 87 96 84 89 74 93 106 79 106 87 89 97 68 91 84 94 86 95 90 83 104 81 98 81 95 96 87 77 88 84 91 92 72 90 98 99 91 100 93 86 90 101 94 92 89 98 85 86 86 81 92 106 94 84 100 82 100 87 91 77 96 104 101 90 87 86 77 99 88 85 94 85 85 100 99 88 74 80 87 95 107 88 108 105 82 83 89 100 101 91 88 93 90 96 65 98 90 94 74 92 81 88 89 84 81 100 101 89 112 93 98 84 92 91 80 103 97 89 82 97 81 105 77 103 93 112 77 82 102 92 101 92 87 86 111 105 79 96 80 86 99 84 101 90 93 98 81 93 86 80 90 101 124 97 92 99 98 79 90 86 100 86 90 104 98 99 90 100 98 94 94 96 94 95 91 91 78 93 91 83 103 91 96 84 85 90 80 100 97 91 83 74 89 95 92 77 86 79 109 84 95 87 97 92 80 113 72 109 88 83 87 82 78 74 96 97 83 66 81 80 95 87 101 111 75 104 99 103 121 95 90 70 83 92 93 88 80 95 95 92 90 95 85 93 118 97 79 100 84 97 113 76 93 85 101 89 101 98 80 82 80 85 89 97 86 82 84 95 113 86 77 81 89 85 89 100 93 101 102 105 103 85 81 103 82 98 102 87 111 87 95 101 93 101 91 80 96 101 107 85 103 90 93 106 81 87 89 117 84 90 77 77 107 83 95 92 90 87 118 98 101 100 104 89 83 84 83 76 88 97 98 78 90 63 83 112 107 86 122 102 88 99 95 105 89 93 97 76 110 95 110 86 84 101 87 86 103 85 98 89 112 101 104 110 84 96 81 82 108 85 82 92 117 94 96 107 86 77 99 90 121 100 100 87 97 93 73 104 75 89 77 104 86 100 108 78 91 101 94 99 101 94 87 89 104 105 82 88 96 90 97 100 75 109 95 85 111 89 107 87 87 98 73 109 90 84 87 89 92 82 88 83 89 100 88 104 89 91 86 87 94 106 85 93 95 93 84 86 79 85 93 80 107 87 90 106 89 92 90 99 81 94 100 108 96 95 82 99 106 107 118 88 83 85 92 103 101 100 85 86 109 89 85 87 90 88 99 81 96 103 110 105 92 90 68 91 90 87 100 95 83 104 98 96 102 94 91 93 102 98 88 97 97 91 99 77 81 104 100 100 122 82 78 80 98 92 92 84 115 111 93 88 102 92 92 85 89 93 102 89 84 83 105 97 82 105 90 103 97 66 85 105 109 104 103 81 107 95 103 82 80 96 76 95 108 111 105 92 88 87 87 86 85 86 86 75 92 90 105 86 79 71 81 92 107 84 89 94 87 77 91 73 108 96 89 94 102 107 91 75 93 96 96 80 102 89 100 114 97 92 110 97 93 97 90 76 95 82 111 103 92 89 102 111 95 87 81 96 78 97 99 103 99 94 106 99 93 99 99 81 77 90 86 85 107 90 84 110 82 91 102 86 86 83 96 113 82 109 111 98 106 110 81 98 109 89 65 93 95 85 87 86 107 103 99 83 94 90 77 113 94 102 84 77 95 87 94 102 86 98 104 101 89 91 95 72 104 112 75 91 90 115 105 87 101 94 88 86 73 97 83 89 82 106 90 85 88 95 80 90 99 103 91 85 80 93 101 89 114 99 88 93 101 101 77 87 92 101 102 95 105 99 85 85 97 87 84 103 102 103 91 98 100 98 97 106 80 94 108 89 98 90 78 87 94 100 91 84 76 70 94 90 80 89 84 107 87 88 83 106 102 100 83 103 87 94 79 87 97 104 96 95 80 96 120 120 81 98 95 92 88 80 82 87 88 83 88 105 95 85 88 113 97 92 93 96 88 92 109 79 90 99 90 105 90 87 94 75 94 99 114 83 83 85 89 85 119 94 101 103 109 99 104 100 95 97 94 97 88 107 101 98 80 102 80 116 103 89 98 91 88 75 87 98 78 105 106 94 86 95 88 87 107 99 93 107 94 98 95 102 116 87 87 82 108 101 111 104 71 93 107 111 94 94 98 110 87 92 82 93 116 98 78 96 89 96 90 97 88 84 79 105 99 98 86 88 111 93 87 82 83 98 86 102 86 80 101 103 101 81 97 85 96 92 96 112 98 103 97 89 99 77 113 104 100 92 71 92 98 94 98 94 99 91 87 76 94 105 97 99 81 107 104 98 90 81 89 92 85 81 98 83 82 95 96 100 100 91 92 90 118 105 103 85 92 97 107 89 102 93 75 99 85 97 95 92 111 88 98 81 90 106 79 106 99 109 98 98 93 98 93 90 92 102 111 91 89 87 93 112 92 88 120 95 97 86 104 109 98 100 106 106 65 88 109 102 89 93 94 97 119 73 95 87 101 93 88 97 81 98 85 88 101 96 88 81 89 98 99 81 86 95 83 85 91 91 97 82 105 87 76 76 95 84 110 104 99 102 89 100 82 87 107 101 92 100 95 100 103 92 110 95 104 86 90 93 105 94 93 90 91 86 104 98 119 89 78 94 89 108 98 99 102 100 85 96 91 91 95 104 88 88 89 102 94 85 113 107 95 96 84 103 92 77 97 98 103 99 92 92 94 100 88 106 82 116 98 74 114 106 97 87 95 98 102 110 88 81 97 89 82 106 112 101 89 100 77 92 115 101 91 84 84 100 112 100 100 102 114 88 82 105 101 90 113 109 94 96 112 80 85 103 85 85 101 100 92 101 88 93 107 105 88 97 91 113 99 76 83 100 81 101 108 102 83 100 104 100 75 102 92 84 84 103 117 101 90 98 105 107 98 95 97 71 79 119 105 82 95 105 89 85 86 101 100 112 79 106 94 86 103 72 97 106 113 112 88 84 97 86 92 103 98 116 104 98 84 90 80 106 84 92 88 94 79 94 90 88 85 94 103 93 71 89 89 104 108 83 87 96 107 84 103 102 78 95 98 79 86 88 85 95 75 81 94 88 79 107 81 83 103 96 103 87 80 92 99 115 100 94 93 105 99 106 104 100 89 88 95 103 87 83 96 86 97 88 89 113 98 94 75 95 103 106 93 98 111 80 96 78 86 101 118 105 110 102 107 95 98 108 93 90 90 77 99 96 90 102 99 97 65 80 99 99 94 106 93 89 111 100 104 82 94 108 92 92 108 89 85 73 103 90 87 95 98 95 101 90 97 98 85 110 81 81 92 118 96 88 90 104 99 100 85 115 92 84 93 90 97 92 96 89 128 96 99 80 108 94 95 97 102 97 107 90 89 110 87 113 100 98 104 96 94 81 81 111 102 98 117 94 89 105 95 97 98 129 102 83 111 93 94 85 98 104 99 98 103 99 110 110 103 81 93 90 92 108 102 103 81 100 90 96 88 102 100 93 110 106 105 96 122 89 108 97 104 86 105 109 100 93 102 101 89 101 104 103 100 108 94 91 106 96 101 87 96 85 100 94 90 102 122 95 91 89 102 108 93 92 89 97 114 95 96 114 100 93 81 107 87 105 97 85 129 112 90 110 120 120 82 106 93 90 114 118 97 85 100 112 105 98 98 121 97 115 102 93 118 105 103 107 106 122 112 115 97 109 114 112 105 113 114 92 108 109 124 108 101 127 105 102 104 103 116 96 115 104 125 105 105 104 102 95 123 105 107 121 106 115 123 106 97 116 116 113 117 100 112 103 125 106 122 104 103 96 88 104 94 107 104 115 98 134 118 106 97 107 111 95 112 113 96 118 116 114 102 109 114 108 97 100 96 98 103 110 96 101 87 92 99 111 86 103 112 104 105 89 105 98 114 98 93 96 113 94 85 91 86 104 116 95 97 107 93 89 93 92 108 96 81 84 104 95 109 113 92 107 100 103 92 86 120 107 109 90 113 103 100 109 92 106 126 86 81 85 123 108 97 88 89 116 102 97 91 98 90 87 85 103 93 65 94 88 101 94 94 79 92 100 109 109 125 116 92 93 93 89 90 87 94 98 103 113 109 100 95 91 103 108 109 102 104 103 91 100 90 98 92 105 98 94 92 79 113 101 95 101 108 89 97 101 101 101 91 104 112 77 83 94 94 106 114 100 112 98 95 102 86 88 68 103 98 96 87 113 77 85 90 106 81 124 90 101 102 95 105 106 88 92 86 110 112 82 87 113 98 108 85 90 96 90 82 91 104 113 101 108 111 106 106 102 99 100 98 90 106 103 99 101 101 106 117 87 101 91 98 102 91 97 86 91 103 89 87 107 73 100 108 95 95 87 105 96 93 96 121 96 91 93 122 98 111 97 106 102 95 95 117 83 93 83 115 105 94 88 104 116 93 103 102 90 87 112 86 89 109 98 101 116 104 89 84 118 113 91 82 87 96 99 91 124 94 105 85 84 89 110 114 83 103 89 100 89 94 112 105 112 100 95 99 104 100 83 109 111 101 92 98 93 108 100 94 102 94 99 98 124 85 89 93 93 100 91 92 104 89 124 101 118 110 103 77 109 97 114 106 88 96 95 99 103 92 88 105 116 110 91 89 100 98 98 92 96 80 85 102 98 88 127 102 79 107 93 108 89 115 104 90 104 99 102 107 107 102 107 102 89 116 93 78 88 109 90 95 90 100 101 108 93 116 94 111 105 103 107 103 100 93 87 97 106 100 93 115 92 106 111 104 94 114 104 86 87 114 98 107 87 98 110 123 95 98 100 93 97 98 86 87 104 87 88 104 107 90 110 112 95 96 86 98 103 102 104 101 97 98 98 102 92 98 88 94 104 104 96 105 101 106 103 100 112 102 111 100 104 90 100 83 100 108 93 86 99 87 96 112 98 91 99 95 100 96 110 86 100 98 82 91 100 70 90 97 91 121 95 106 105 85 94 98 116 87 107 102 91 88 86 91 102 102 123 93 103 102 92 87 85 107 120 89 93 98 94 104 103 99 95 94 108 99 115 88 97 88 106 101 87 102 89 121 118 95 112 112 86 93 102 108 107 105 88 84 99 131 88 123 111 96 80 92 80 98 100 105 86 112 91 84 113 100 105 92 101 87 82 109 107 90 100 107 113 87 109 99 95 99 95 127 105 88 113 92 101 83 75 96 100 105 97 95 99 99 100 83 107 107 90 119 103 94 109 87 106 111 91 124 104 85 91 112 114 110 96 76 81 97 94 88 106 83 102 81 82 94 91 93 107 81 95 108 101 102 93 95 106 105 86 109 97 123 101 87 97 96 117 97 110 89 116 94 98 100 123 87 114 93 113 92 103 102 109 108 108 107 105 86 112 103 98 90 111 87 101 76 100 88 93 102 129 97 90 109 95 87 114 109 112 101 83 99 88 115 117 96 94 97 101 97 96 115 115 113 100 92 96 105 88 106 104 106 108 96 92 109 97 92 91 92 106 82 95 112 92 102 103 105 71 95 109 95 97 93 99 94 92 110 98 106 104 116 108 88 93 92 110 107 101 91 98 101 126 106 99 104 98 88 117 102 94 107 107 103 105 101 85 106 109 99 93 103 107 97 115 90 99 102 103 102 112 109 109 95 117 128 110 74 89 111 104 112 86 93 104 82 114 110 109 108 105 107 96 78 92 115 112 111 104 93 103 90 95 79 88 117 102 101 119 116 105 100 114 96 93 87 92 109 97 75 90 109 98 95 107 108 111 94 87 99 97 113 111 87 106 96 131 93 96 96 101 84 92 91 103 99 80 116 99 95 93 99 90 101 88 105 94 93 100 104 86 112 85 98 107 110 98 120 85 111 120 100 98 117 104 97 92 85 114 105 98 107 92 78 96 98 129 100 119 101 97 86 120 118 108 77 88 103 94 100 78 118 105 101 121 109 92 103 104 112 94 85 108 92 87 107 102 111 101 88 92 122 95 102 92 110 106 100 90 114 126 101 99 100 85 101 113 108 104 111 109 77 97 103 95 95 81 97 111 89 98 88 97 105 109 109 102 98 94 99 108 102 101 112 115 95 100 92 117 100 111 127 115 106 116 85 94 102 94 99 98 79 78 85 92 108 101 90 97 107 110 84 111 106 121 92 106 104 121 88 108 110 104 110 96 101 95 106 104 107 105 113 113 97 96 93 102 81 94 91 100 93 105 92 119 94 107 118 86 98 94 93 89 97 91 113 105 107 104 94 98 108 98 85 105 93 80 94 94 85 98 101 104 98 98 79 105 105 87 92 98 115 113 92 85 92 99 80 96 101 116 119 103 126 100 110 101 96 104 87 93 94 94 88 119 102 100 103 109 92 85 96 89 98 90 97 89 114 90 100 93 105 128 96 106 98 90 95 101 90 92 91 90 110 98 87 88 95 97 100 111 111 104 91 90 103 91 113 89 102 114 115 105 95 109 112 99 91 109 101 102 114 103 102 116 104 95 92 108 96 97 97 106 90 107 106 99 95 89 96 109 113 93 99 84 96 106 111 95 95 95 101 94 87 101 89 115 90 94 84 98 110 109 101 96 89 85 123 80 91 111 94 109 101 101 112 91 87 109 99 98 115 83 96 96 97 98 102 96 102 98 91 92 116 88 115 92 123 96 93 110 109 101 84 94 110 82 98 103 96 115 105 98 105 91 99 97 79 100 87 92 104 94 111 92 100 97 112 108 81 95 101 106 109 94 91 99 85 114 101 105 104 94 108 108 103 92 101 95 93 84 99 98 103 114 100 123 107 91 102 98 101 96 98 122 101 107 84 85 113 93 95 92 102 92 92 99 114 116 102 106 91 119 115 104 91 106 102 94 120 100 103 107 108 102 102 95 94 106 103 111 109 108 90 103 98 116 99 104 98 102 97 113 84 81 101 94 110 98 107 103 93 100 109 89 109 107 86 99 104 83 107 94 94 87 103 92 108 101 117 107 99 95 88 87 108 97 115 101 98 99 90 97 103 81 84 96 112 101 117 101 91 110 104 102 88 123 112 91 94 112 94 101 81 95 93 89 90 94 87 92 106 116 112 123 101 106 99 99 84 91 109 108 97 104 103 101 88 97 99 111 93 98 92 104 98 97 108 96 99 98 88 109 77 83 86 108 108 112 105 100 97 97 98 104 112 107 87 85 100 101 104 104 98 96 98 107 121 95 91 103 87 78 87 110 106 116 117 96 97 122 119 101 105 88 110 107 103 89 112 93 108 94 117 110 99 115 91 109 92 90 102 106 105 102 88 110 91 107 100 106 98 110 85 86 104 102 124 124 99 107 90 108 105 96 99 108 102 125 105 113 100 97 114 88 109 95 112 98 75 90 98 104 76 116 96 103 93 102 101 110 99 115 101 112 118 89 116 104 101 105 105 115 107 123 95 94 94 115 106 103 98 115 104 108 112 100 103 111 81 96 99 108 95 91 115 112 100 94 105 109 106 94 93 93 90 126 94 80 109 101 115 115 81 121 106 98 108 89 104 84 90 94 113 97 107 102 116 109 119 110 104 104 100 96 116 100 120 101 102 91 92 116 97 116 95 107 120 108 105 99 84 84 113 96 118 94 126 109 103 97 113 98 106 94 86 91 126 94 99 109 110 105 119 116 101 98 98 108 107 117 117 108 115 91 110 81 112 96 106 97 99 110 109 110 99 104 100 103 102 114 95 99 120 102 104 118 100 96 83 113 90 103 90 106 94 101 111 122 106 115 115 83 114 104 96 87 110 102 107 98 96 84 106 101 105 109 115 106 109 99 129 106 97 108 105 103 89 93 94 112 94 100 96 91 94 107 91 80 106 116 104 104 104 103 88 103 91 78 96 103 94 101 99 137 106 92 119 107 100 80 91 115 97 115 107 94 108 93 91 92 95 86 84 131 110 99 101 94 102 84 104 91 108 99 111 109 108 96 112 107 86 101 103 118 100 88 104 95 117 90 100 109 105 98 111 122 86 125 109 102 110 117 80 105 98 103 112 97 97 111 88 96 98 107 104 96 112 106 118 90 113 98 105 100 103 94 96 107 114 96 114 109 118 118 98 104 95 95 103 103 83 102 114 94 102 119 101 105 111 110 100 124 87 91 119 97 91 91 97 84 99 85 108 95 90 117 119 89 96 87 92 108 112 84 117 114 110 114 102 91 103 106 111 94 111 92 106 102 110 95 100 117 95 92 97 105 105 108 103 104 96 116 113 106 110 92 108 97 113 80 101 81 103 98 108 94 112 123 92 109 91 100 100 118 137 105 106 112 90 100 91 108 83 118 96 106 108 89 105 95 112 94 85 106 85 74 96 106 105 89 88 97 91 98 113 93 92 104 110 96 102 114 87 120 92 87 91 95 79 88 101 95 93 98 95 95 95 86 99 94 109 101 113 99 100 99 92 97 109 95 102 103 107 88 112 99 95 91 94 102 95 100 122 106 91 99 82 88 117 101 108 106 108 88 89 92 87 107 104 82 90 93 94 105 100 93 100 101 105 93 97 110 96 101 91 97 90 105 100 106 101 112 110 106 104 84 104 86 96 88 105 99 97 93 95 104 97 112 113 106 104 96 102 94 97 91 115 114 103 97 111 115 105 115 122 101 105 97 93 97 103 116 105 94 126 103 96 109 90 87 106 99 99 109 103 113 102 102 103 111 85 112 92 105 91 92 91 108 93 93 118 107 109 102 98 119 103 103 84 98 89 101 90 92 92 113 119 94 99 102 116 100 114 113 101 109 102 97 98 98 115 112 91 105 103 104 93 96 115 106 91 101 122 90 103 99 85 104 102 98 108 102 80 92 104 97 114 95 75 100 97 106 110 107 92 116 93 101 86 95 92 115 97 90 96 86 101 92 91 96 97 117 102 107 93 103 95 126 85 115 100 112 98 94 98 115 107 92 84 106 95 120 99 96 93 115 86 116 112 108 90 116 106 91 102 99 87 107 98 74 118 97 95 103 97 84 118 100 88 112 107 106 90 112 98 103 103 110 89 90 106 91 106 100 99 78 115 108 117 105 124 103 87 85 102 110 113 105 85 126 88 83 104 110 97 94 100 118 101 114 99 97 88 88 109 86 102 86 97 87 92 82 100 83 107 98 93 93 109 88 101 83 97 82 91 109 96 99 77 108 110 92 114 91 97 96 95 103 99 100 114 91 94 96 91 98 85 89 114 113 106 105 101 102 100 85 105 122 120 97 96 92 88 102 115 101 106 95 100 89 99 108 100 100 113 114 86 102 91 104 107 101 84 99 98 114 111 95 95 90 89 82 98 102 93 91 110 110 104 103 118 96 94 90 113 98 95 96 81 97 96 94 94 115 97 94 117 98 86 111 93 103 97 100 88 86 94 109 92 95 95 94 89 90 108 90 95 92 98 80 107 95 104 98 93 105 80 112 96 90 97 91 83 104 100 96 90 85 96 89 102 91 102 87 78 91 103 104 114 107 103 103 99 108 82 114 104 106 95 103 108 97 100 101 88 109 89 102 96 97 99 102 114 113 90 106 102 95 99 79 96 110 100 99 103 82 106 105 105 118 116 96 104 87 116 98 90 94 106 106 105 88 96 107 95 105 86 105 98 97 92 91 100 96 92 109 111 108 111 99 107 88 111 97 108 95 98 92 114 99 107 82 91 100 96 119 106 93 112 95 95 106 117 94 90 93 91 92 94 106 106 112 121 107 101 87 96 113 111 101 116 93 111 96 100 88 95 108 92 103 86 113 100 104 120 93 91 90 110 107 100 108 114 109 98 101 111 105 111 101 119 97 105 101 99 105 107 98 76 97 101 95 90 95 109 115 108 100 94 108 103 102 114 113 113 109 110 95 99 100 99 94 108 102 111 90 91 103 106 105 91 103 106 119 105 103 101 93 95 95 101 103 109 107 112 104 100 108 99 93 96 129 102 87 100 110 91 102 91 113 92 120 100 105 88 102 115 100 107 102 95 107 83 101 120 113 100 99 100 113 89 88 85 106 92 103 99 107 101 105 93 107 95 112 97 106 108 98 107 104 120 91 99 122 98 111 121 107 97 122 111 87 117 90 106 97 96 108 98 110 91 112 87 112 98 105 103 101 94 96 118 99 101 111 102 98 103 99 93 104 92 117 118 145 110 92 99 114 109 81 105 88 100 103 113 120 113 101 98 95 100 84 107 105 99 102 95 100 99 82 102 109 106 107 101 111 99 109 107 112 106 99 104 109 104 104 93 125 106 109 121 111 95 102 84 82 108 95 99 95 103 82 101 100 116 102 102 127 100 99 96 107 110 97 105 103 111 106 106 101 91 108 100 106 89 107 104 101 116 100 88 100 105 89 101 105 105 100 99 85 106 94 95 103 96 96 103 102 110 120 115 105 101 111 90 104 106 104 100 100 104 120 82 112 92 114 98 97 102 112 97 101 113 85 101 111 100 101 119 108 95 89 85 119 120 91 109 94 106 91 97 109 93 106 96 109 79 93 93 88 112 118 93 112 94 118 106 111 116 120 105 109 90 98 102 109 92 119 91 114 111 109 102 106 101 99 97 108 93 96 102 110 108 106 101 108 113 104 104 123 108 90 97 113 96 101 98 97 100 111 96 101 111 102 97 89 101 106 95 96 93 113 93 120 93 91 108 110 101 93 94 98 96 117 98 98 96 99 89 102 99 95 110 105 88 91 103 109 119 95 104 94 90 100 91 110 115 90 87 91 95 101 89 114 91 106 100 114 101 117 87 87 106 110 100 119 91 113 101 95 95 88 109 107 94 103 96 100 112 91 107 90 120 102 105 101 97 111 113 86 93 110 99 99 99 99 111 108 109 109 100 103 98 99 104 98 82 99 93 90 97 111 112 103 104 109 84 95 121 99 108 96 108 100 112 96 100 82 110 106 99 104 105 105 95 91 105 100 103 89 93 100 91 97 116 98 95 116 118 104 101 112 106 115 115 92 97 97 106 99 105 101 114 98 101 109 94 100 113 103 85 116 104 104 121 107 91 107 111 114 86 90 100 94 116 108 110 108 82 122 114 100 116 102 94 93 99 110 122 104 104 112 89 100 87 102 91 97 112 104 107 99 106 85 106 113 116 109 109 109 108 103 97 113 105 115 99 97 114 78 113 116 109 91 92 128 95 93 101 99 92 107 104 106 110 111 95 97 96 95 102 115 104 108 111 111 87 113 106 94 93 88 115 85 92 113 89 95 100 99 99 83 113 109 109 103 95 100 98 115 96 99 118 84 112 110 106 104 89 98 112 95 136 100 100 110 101 122 102 89 85 112 116 107 99 92 116 105 112 134 92 106 100 112 113 109 97 106 111 109 113 106 114 111 111 97 105 103 125 118 105 107 105 101 105 101 107 103 117 103 118 104 102 136 119 101 96 125 103 107 88 113 107 98 93 102 109 102 92 120 92 108 96 114 116 105 113 110 90 102 112 109 91 112 98 99 102 111 101 87 117 109 88 92 116 98 121 107 94 98 107 120 108 109 122 113 100 121 114 111 107 114 97 105 100 123 125 119 110 120 111 101 99 108 111 104 127 103 111 100 95 99 121 126 115 103 96 106 124 104 108 113 114 87 88 111 117 99 116 105 120 131 109 103 104 98 79 121 106 102 128 106 119 97 132 109 108 120 118 98 105 125 95 109 108 94 110 106 95 105 122 121 103 110 115 118 107 120 106 107 103 127 89 116 92 103 106 111 127 102 118 133 116 109 117 116 101 106 122 113 123 116 112 106 88 118 98 77 105 113 110 110 102 103 117 142 106 99 103 105 95 121 104 99 99 97 107 106 87 108 112 112 108 115 87 102 117 93 92 121 113 100 117 117 104 98 86 86 117 110 103 84 116 106 101 105 103 115 109 95 120 109 115 117 120 102 100 100 97 109 97 104 112 104 94 114 109 101 116 97 116 109 112 111 130 103 114 103 105 103 115 98 119 90 121 89 111 95 102 96 94 106 104 110 100 109 121 89 109 100 102 111 106 98 112 101 94 105 91 100 86 103 101 125 114 109 119 102 93 114 120 112 127 102 104 109 103 103 97 101 98 96 128 106 120 99 108 92 108 102 100 114 107 109 104 111 112 94 103 104 107 96 111 104 110 118 109 98 107 97 116 92 109 106 125 94 104 105 94 92 108 99 97 99 117 98 98 102 99 100 81 120 102 93 93 123 115 84 98 110 95 91 99 93 93 102 111 93 103 91 98 109 110 89 123 102 95 108 100 94 109 111 103 102 94 100 105 95 129 92 88 113 105 95 97 90 98 84 115 78 96 117 85 108 100 104 91 103 87 120 99 120 91 116 86 118 104 117 110 86 107 86 102 104 103 118 100 109 114 96 99 98 115 106 102 93 96 110 89 108 94 98 77 93 114 117 116 103 105 100 106 130 121 101 99 105 97 101 114 94 93 105 108 98 111 135 79 99 112 98 90 98 112 85 82 92 102 96 98 92 116 98 97 115 109 102 108 103 93 118 87 124 91 105 122 116 94 103 84 104 105 119 121 98 107 122 103 102 97 101 90 98 101 104 102 105 96 93 111 114 91 112 95 99 90 100 103 106 114 107 112 116 96 117 97 112 86 94 100 99 101 86 111 100 115 101 107 133 92 100 122 100 113 98 99 100 102 86 87 109 104 95 117 117 118 112 97 105 117 94 102 108 106 98 96 101 96 114 108 87 92 104 96 115 100 114 117 108 88 123 103 116 98 100 101 101 100 100 101 94 119 107 110 93 97 108 117 123 107 101 97 108 88 103 109 114 119 95 118 112 101 85 117 127 118 118 87 99 112 100 123 112 100 93 96 95 103 87 93 105 106 101 87 120 115 109 121 128 118 90 114 89 119 97 104 106 107 83 90 113 112 101 90 99 86 110 103 88 97 88 110 101 92 108 94 102 112 86 91 95 93 109 100 105 99 85 102 115 96 104 97 97 85 102 116 119 120 102 103 116 97 110 94 108 102 105 90 113 88 112 95 101 120 106 115 85 96 104 97 87 98 119 101 121 101 93 110 116 104 136 106 105 100 87 102 91 126 111 107 109 107 116 95 113 103 105 114 109 122 91 97 108 115 116 113 119 109 100 100 102 88 84 121 111 117 122 95 82 106 93 95 135 106 102 90 107 109 97 121 104 85 104 100 90 94 104 105 94 122 112 115 99 108 121 112 94 104 100 92 97 89 115 104 93 102 108 116 88 98 78 106 110 94 108 111 96 104 113 99 89 112 123 120 109 131 111 123 98 93 116 112 101 111 89 101 111 90 102 91 119 127 106 87 105 101 104 107 119 106 115 103 96 89 104 123 96 108 108 106 100 99 112 101 96 96 102 107 92 102 103 100 92 93 107 100 102 99 88 85 116 86 99 100 94 114 82 122 82 115 86 108 109 104 87 133 104 111 119 107 100 130 109 93 111 113 109 118 108 101 87 103 113 100 115 86 104 93 119 95 125 111 112 94 110 85 103 93 114 93 91 101 117 117 119 128 101 112 96 105 94 117 110 122 102 94 95 127 101 97 105 102 92 95 104 102 114 104 98 84 92 97 100 109 115 107 88 111 90 95 101 105 110 97 87 90 103 112 120 111 90 112 103 91 107 101 94 122 107 106 109 120 102 107 100 106 97 109 96 121 95 122 82 95 119 110 89 106 100 111 110 110 107 124 98 107 102 104 105 112 103 85 96 115 118 119 115 102 117 113 139 99 96 122 114 108 89 108 96 109 102 107 98 86 105 97 104 114 107 125 96 99 100 100 117 109 97 94 113 118 101 120 99 90 91 111 101 109 96 105 101 111 90 87 119 115 99 111 118 111 135 104 120 109 110 112 117 99 84 98 116 91 94 99 113 141 103 103 109 93 100 113 99 96 111 121 102 103 87 109 106 115 101 106 111 100 104 93 113 106 109 102 104 112 110 99 110 95 108 113 95 108 92 94 93 114 102 117 100 107 105 102 102 87 130 101 116 100 97 122 99 101 113 107 106 101 72 102 101 112 84 89 116 93 109 101 130 114 120 98 103 103 99 121 107 91 109 109 111 100 73 117 104 116 105 87 127 127 111 113 91 110 96 112 89 94 116 98 115 87 104 105 93 103 98 105 111 119 95 102 94 104 97 98 112 108 113 92 86 111 95 94 88 103 93 91 122 138 102 91 115 87 121 89 99 95 78 99 97 115 108 94 106 87 132 99 103 96 108 110 83 95 100 91 87 110 97 99 110 103 88 108 87 93 110 112 89 100 89 104 103 89 101 116 102 98 111 115 118 102 106 105 96 102 101 111 100 96 87 103 113 116 97 112 108 100 111 110 103 98 98 124 81 116 104 89 96 77 106 128 105 100 96 107 86 98 101 106 80 113 118 98 88 106 95 113 121 113 103 106 129 108 100 101 96 107 124 116 107 107 105 105 89 109 111 89 96 100 104 104 119 109 115 98 124 85 110 115 114 103 111 104 103 107 97 104 92 108 110 92 119 99 135 84 101 94 102 105 103 93 104 99 108 99 100 94 114 93 114 89 96 81 107 83 109 112 104 103 132 94 106 116 115 113 94 104 103 113 102 103 101 89 114 91 103 108 95 97 121 92 112 108 118 116 88 97 93 101 96 114 114 85 103 91 90 108 109 105 101 83 90 98 97 95 116 99 120 104 123 122 117 95 112 102 92 108 121 82 113 103 123 88 117 98 112 111 102 99 100 109 112 85 100 115 89 98 93 100 120 105 96 113 106 95 106 98 107 76 113 102 102 98 102 102 94 95 113 106 122 106 103 110 96 99 111 87 85 96 102 95 136</counts>
			</dataPoints>
		</scan>
	</xrdMeasurement>
</xrdMeasurements>