File: data/XRD/_misc/target.xrdml
<xrdMeasurements xmlns="http://www.xrdml.com/XRDMeasurement/2.1" xmlns:xsi="http://www.w3.org/2001/XMLSchema-instance" xsi:schemaLocation="http://www.xrdml.com/XRDMeasurement/2.1 http://www.xrdml.com/XRDMeasurement/2.1/XRDMeasurement.xsd" status="Completed">
	<comment>
		<entry>Configuration=Factory configuration, Owner=User-1, Creation date=7/8/2013 4:01:53 PM</entry>
		<entry>Goniometer=PW3050/65 (Theta/2Theta); Minimum step size 2Theta:0.0001; Minimum step size Omega:0.0001</entry>
		<entry>Sample stage=MRD Cradle; Minimum step size Phi:0.01; Minimum step size Chi:0.01; Minimum step size X:0.01; Minimum step size Y:0.01; Minimum step size Z:0.001</entry>
		<entry>Diffractometer system=XPERT-PRO</entry>
		<entry>Measurement program=Manual, Owner=User-1, Creation date=1/26/2024 8:28:26 AM</entry>
	</comment>
	<sample type="To be analyzed">
		<id></id>
		<name></name>
		<preparedBy></preparedBy>
	</sample>
	<xrdMeasurement measurementType="Scan" status="Completed" sampleMode="Reflection">
		<comment>
			<entry>PHD Lower Level = 4.83 (keV), PHD Upper Level = 11.27 (keV)</entry>
		</comment>
		<usedWavelength intended="K-Alpha 1">
			<kAlpha1 unit="Angstrom">1.5405980</kAlpha1>
			<kAlpha2 unit="Angstrom">1.5444260</kAlpha2>
			<kBeta unit="Angstrom">1.3922500</kBeta>
			<ratioKAlpha2KAlpha1>0.5000</ratioKAlpha2KAlpha1>
		</usedWavelength>
		<incidentBeamPath>
			<radius unit="mm">320.00</radius>
			<xRayTube id="1010048" name="Empyrean Cu LFF HR (9430 033 7310x) DK423709">
				<tension unit="kV">40.0</tension>
				<current unit="mA">40.0</current>
				<anodeMaterial>Cu</anodeMaterial>
				<focus type="Line">
					<length unit="mm">12.0</length>
					<width unit="mm">0.4</width>
					<takeOffAngle unit="deg">4.2</takeOffAngle>
				</focus>
			</xRayTube>
			<xRayMirror id="27010001" name="Inc. Beam Cu W/Si (parabolic MRD)" hybrid="false">
				<crystal type="Graded" shape="Parabolic">W/Si</crystal>
				<acceptanceAngle unit="deg">0.800</acceptanceAngle>
				<length unit="mm">60.0</length>
			</xRayMirror>
			<sollerSlit id="21010002" name="Soller slits 0.04 rad.">
				<opening unit="rad">0.0400</opening>
			</sollerSlit>
			<mask id="22030007" name="Fixed mask 2 mm">
				<distanceToSample unit="mm">220.00</distanceToSample>
				<width unit="mm">2.00</width>
			</mask>
			<divergenceSlit id="22010007" name="Fixed slit 1/8°" xsi:type="fixedDivergenceSlitType">
				<distanceToSample unit="mm">220.00</distanceToSample>
				<height unit="mm">0.19</height>
			</divergenceSlit>
		</incidentBeamPath>
		<diffractedBeamPath>
			<radius unit="mm">320.00</radius>
			<sollerSlit id="21010002" name="Soller slits 0.04 rad.">
				<opening unit="rad">0.0400</opening>
			</sollerSlit>
			<receivingSlit id="22010001" name="Fixed slit 4°">
				<height unit="mm">5.88</height>
			</receivingSlit>
			<detector id="7010017" name="PIXcel3D 1x1 detector" xsi:type="areaDetectorType">
				<phd unit="%">
					<lowerLevel>30.0</lowerLevel>
					<upperLevel>70.0</upperLevel>
				</phd>
				<mode>Scanning</mode>
				<activeChannelsEquatorial>255</activeChannelsEquatorial>
				<activeChannelsAxial>255</activeChannelsAxial>
				<pitchEquatorial unit="mm">0.05500</pitchEquatorial>
				<pitchAxial unit="mm">0.05500</pitchAxial>
				<readOutPeriod unit="seconds">0.135</readOutPeriod>
			</detector>
		</diffractedBeamPath>
		<scan appendNumber="0" mode="Continuous" scanAxis="2Theta-Omega" status="Completed">
			<header>
				<startTimeStamp>2024-01-26T08:32:06+01:00</startTimeStamp>
				<endTimeStamp>2024-01-26T12:16:08+01:00</endTimeStamp>
				<author>
					<name>PRO-MRD</name>
				</author>
				<source>
					<applicationSoftware version="6.1b">Data Collector</applicationSoftware>
					<instrumentControlSoftware version="7.0E 20130304">XPERT-PRO</instrumentControlSoftware>
					<instrumentID>0000000011142674</instrumentID>
				</source>
			</header>
			<scanAxisCenter>
				<position axis="2Theta" unit="deg">70.0000</position>
				<position axis="Omega" unit="deg">35.0000</position>
			</scanAxisCenter>
			<reflection>
				<hkl>
					<h>0</h>
					<k>0</k>
					<l>0</l>
				</hkl>
			</reflection>
			<dataPoints>
				<positions axis="2Theta" unit="deg">
					<startPosition>10.00051548</startPosition>
					<endPosition>129.99981038</endPosition>
				</positions>
				<positions axis="Omega" unit="deg">
					<startPosition>5.00025774</startPosition>
					<endPosition>64.99990519</endPosition>
				</positions>
				<positions axis="Phi" unit="deg">
					<commonPosition>0.00</commonPosition>
				</positions>
				<positions axis="Chi" unit="deg">
					<commonPosition>0.00</commonPosition>
				</positions>
				<positions axis="X" unit="mm">
					<commonPosition>0.00</commonPosition>
				</positions>
				<positions axis="Y" unit="mm">
					<commonPosition>0.00</commonPosition>
				</positions>
				<positions axis="Z" unit="mm">
					<commonPosition>6.500</commonPosition>
				</positions>
				<commonCountingTime unit="seconds">32.895</commonCountingTime>
				<counts 158 140 135 141 136 145 165 131 139 124 161 141 143 142 146 141 152 121 142 147 134 123 149 131 146 160 158 144 129 124 136 144 144 169 144 139 149 143 148 135 128 136 148 129 165 147 129 134 130 128 151 133 132 130 133 146 112 119 148 163 141 134 158 142 131 154 132 128 143 149 129 129 159 157 143 124 124 139 144 161 153 112 137 132 164 150 115 142 142 147 135 139 126 131 142 119 163 146 139 150 146 135 133 139 157 128 158 124 136 152 156 128 136 140 138 150 142 126 143 133 132 141 142 149 152 130 139 124 149 128 145 149 142 147 128 150 127 164 153 122 145 147 132 144 139 152 152 149 133 132 153 131 141 162 167 139 131 162 123 140 143 130 107 153 128 119 150 123 162 137 141 129 119 142 137 140 163 158 137 138 132 156 125 146 142 147 136 147 137 131 148 135 149 131 126 126 156 151 134 135 148 122 131 156 150 135 152 140 167 141 149 168 136 130 128 149 151 132 144 148 150 156 128 138 168 140 134 139 142 134 139 127 134 156 134 145 166 140 143 132 157 117 150 127 156 155 149 157 146 147 163 159 131 159 138 156 148 151 147 135 165 148 147 167 143 146 146 150 151 120 139 146 134 144 158 135 139 131 152 139 121 144 158 126 167 145 149 136 160 133 127 134 147 124 131 147 127 159 139 161 146 138 148 135 128 142 111 133 124 140 134 139 133 138 147 136 148 127 133 158 148 137 146 135 117 151 130 161 135 162 156 140 154 140 148 141 140 131 144 167 128 171 150 130 145 142 143 136 141 149 132 140 148 142 142 167 143 147 150 116 145 139 145 154 151 131 148 126 148 150 128 144 138 148 145 152 145 133 143 137 122 122 139 153 154 138 155 151 138 143 137 152 120 146 158 150 153 115 151 162 142 119 129 135 117 162 151 147 130 146 147 130 153 133 123 133 126 125 147 131 117 179 140 123 132 150 149 134 117 153 131 148 110 169 146 135 132 131 145 128 125 147 130 133 139 157 148 122 111 141 139 130 116 138 145 157 120 128 148 144 137 145 135 156 127 141 139 122 138 150 152 115 133 140 135 141 113 150 135 136 131 133 138 128 127 147 152 150 133 133 146 136 140 134 120 159 127 137 138 138 137 123 152 151 134 136 131 143 149 149 135 120 126 131 122 128 131 122 140 131 117 139 125 146 144 116 138 141 127 137 135 143 138 121 150 153 119 159 152 155 147 147 135 146 116 126 137 148 114 143 150 154 146 148 143 135 148 145 150 137 123 123 117 123 132 134 128 154 148 117 127 138 129 123 132 140 138 146 130 113 142 135 135 130 134 134 137 137 133 132 142 117 124 136 135 133 132 134 121 139 139 146 120 130 151 141 133 137 131 124 121 148 154 135 152 136 145 129 128 143 133 113 145 124 150 123 136 134 137 110 150 139 136 137 145 152 134 163 141 152 114 147 130 138 139 143 147 149 131 139 164 147 144 115 147 137 160 149 157 138 125 135 136 136 126 139 129 133 124 152 146 139 116 129 131 126 149 138 143 127 148 148 137 141 138 118 120 155 136 113 143 149 132 149 140 119 147 133 127 125 146 136 126 142 145 151 126 126 126 127 124 156 150 147 136 133 120 144 148 148 146 125 128 144 157 141 118 139 136 136 126 142 142 126 136 144 121 150 140 136 145 128 148 126 122 148 122 130 158 136 148 142 134 138 149 127 132 120 156 148 111 146 150 139 143 155 141 137 128 138 122 145 141 161 130 130 153 145 138 137 113 136 122 132 134 121 130 127 145 144 149 130 136 158 129 140 112 122 117 108 129 150 131 129 132 138 131 137 128 126 130 138 122 138 143 125 125 123 114 138 122 143 137 168 126 150 147 128 149 128 124 122 134 152 133 125 127 143 158 123 118 138 136 112 140 140 135 119 124 132 135 124 120 146 139 142 145 127 116 136 132 139 124 125 135 137 121 127 156 142 125 120 116 158 132 135 119 139 137 138 132 119 130 144 136 145 142 141 138 140 126 143 114 149 134 127 133 116 145 134 129 124 132 123 137 119 135 134 138 124 115 141 131 123 129 151 135 135 117 134 145 141 133 153 111 125 132 134 145 139 141 130 131 154 138 133 137 144 109 119 137 142 128 142 141 140 147 126 152 154 163 122 117 139 120 145 147 120 140 137 136 145 142 146 129 119 136 118 137 128 125 122 134 121 111 139 128 118 151 151 130 129 126 146 131 144 122 139 129 140 129 134 114 147 145 125 141 137 114 119 131 133 142 128 136 119 138 111 127 139 137 135 128 132 140 135 108 133 134 124 137 135 147 123 146 132 116 140 129 125 144 140 124 129 133 121 150 141 129 129 123 130 151 132 136 121 128 115 128 122 142 146 135 139 140 147 134 129 125 115 134 120 128 133 139 121 120 117 119 121 123 137 133 125 150 127 138 108 152 143 147 136 116 146 136 122 135 136 133 122 118 144 136 130 121 115 113 145 141 128 131 128 138 124 133 122 128 125 129 133 147 113 152 149 136 148 120 120 127 125 159 122 139 146 135 118 118 159 139 150 138 133 130 143 136 150 111 147 135 133 131 129 146 113 125 127 109 123 125 128 139 113 150 137 151 138 121 121 117 132 132 138 136 126 138 122 130 145 137 140 141 148 129 119 122 136 133 128 144 138 144 134 119 121 142 134 131 136 127 131 122 140 127 148 142 129 132 129 123 134 122 159 147 112 125 120 149 122 145 124 140 149 142 139 143 117 139 130 144 122 123 122 152 117 136 131 126 141 113 139 134 139 148 131 132 123 132 145 130 141 132 155 121 140 124 136 114 158 133 123 146 128 114 147 128 126 123 138 129 138 139 133 129 141 134 137 136 119 136 130 118 145 134 144 146 121 105 144 120 149 139 113 101 147 133 115 143 136 149 128 117 131 123 113 130 122 155 132 152 133 135 144 122 117 151 119 146 137 140 139 134 128 116 123 122 137 115 138 135 119 111 123 132 111 108 109 140 132 145 130 135 143 113 154 112 139 116 119 130 103 133 146 147 132 103 134 126 130 125 134 119 115 141 120 131 140 117 140 134 112 117 149 131 139 139 128 123 124 139 124 142 123 115 118 118 123 131 126 124 120 130 133 120 135 135 143 112 108 124 140 136 153 111 129 145 115 137 124 119 151 120 140 134 144 135 120 117 129 143 118 145 122 123 122 137 149 121 122 137 140 138 121 128 109 128 91 140 129 124 137 124 146 141 148 121 131 125 150 139 124 130 125 129 155 139 128 124 132 139 130 146 131 124 100 113 149 125 115 142 130 116 155 129 140 126 112 148 126 150 128 147 112 125 136 161 127 121 147 119 115 141 114 167 127 123 129 118 131 114 133 132 96 114 136 132 137 122 132 145 130 135 105 115 125 143 145 164 132 141 101 147 128 118 131 120 143 110 134 129 139 132 137 125 148 121 119 124 147 136 122 137 143 119 123 143 124 125 131 129 118 146 127 122 126 109 109 120 120 134 133 109 131 136 115 127 116 128 140 141 119 122 131 139 132 127 128 125 121 136 119 117 142 108 122 150 133 122 143 119 132 118 127 124 128 118 129 105 111 128 105 120 115 147 125 127 116 143 133 146 144 124 129 120 140 145 121 123 138 126 132 133 122 121 110 117 124 123 113 129 117 112 137 120 125 114 125 111 122 129 122 106 121 136 123 128 114 120 117 146 136 146 125 114 132 124 124 146 120 130 116 116 111 116 133 129 127 104 108 139 116 120 129 131 125 134 135 130 127 113 131 130 131 137 130 111 134 113 121 125 132 126 110 134 129 123 131 122 96 121 125 125 124 116 118 124 118 157 129 133 139 126 116 111 124 129 136 122 122 120 126 111 113 124 112 139 124 133 141 123 132 106 124 137 139 135 127 135 132 125 127 132 129 104 125 141 132 123 111 112 111 133 137 131 132 133 134 132 120 114 130 127 134 107 116 117 117 124 124 130 135 110 115 136 120 117 120 128 111 121 116 125 122 125 120 137 143 154 136 141 121 118 118 135 119 135 138 130 126 125 117 117 124 129 124 125 106 128 133 132 126 102 126 111 134 107 123 120 118 123 106 140 126 150 115 123 127 122 133 143 116 115 131 117 119 92 142 115 138 123 123 133 121 133 135 130 127 110 116 119 119 124 120 122 116 127 125 134 114 126 117 109 131 126 108 134 117 129 126 124 118 117 114 116 114 106 132 123 115 115 136 105 139 119 125 130 140 115 117 134 118 132 141 127 121 112 123 126 131 112 129 127 95 140 96 120 121 105 133 101 127 129 142 104 124 106 132 125 119 142 123 129 139 112 123 126 136 121 117 130 146 104 128 129 123 145 129 121 133 132 125 133 127 129 122 111 117 142 105 116 120 130 116 117 112 100 136 124 130 128 114 140 132 118 122 122 126 133 115 117 112 112 125 100 92 116 121 127 124 126 121 117 126 128 125 120 123 118 112 137 128 107 132 140 119 142 130 123 127 124 154 117 137 119 134 128 136 135 102 127 122 140 109 108 119 117 139 132 121 128 108 123 122 144 124 132 122 122 106 125 101 136 108 108 115 125 114 121 126 116 116 120 114 116 125 121 120 98 122 126 106 116 135 126 106 138 111 106 106 115 97 114 132 120 134 137 141 132 127 108 128 121 117 125 131 107 122 110 122 124 115 116 111 141 133 119 127 138 122 137 114 115 119 122 126 112 113 123 122 154 127 132 133 128 124 126 116 131 122 112 103 120 137 137 128 131 126 141 132 106 115 132 134 127 130 124 127 136 113 132 119 123 129 106 123 125 112 124 130 132 117 114 102 132 126 136 127 104 110 113 118 133 120 140 121 117 118 118 119 141 129 118 117 112 124 142 121 87 107 123 115 121 124 125 113 145 136 129 107 113 125 120 120 137 121 122 134 127 127 91 114 125 117 116 124 106 119 105 121 94 130 129 113 109 115 137 124 113 129 140 120 110 116 132 127 128 129 121 123 123 123 131 109 98 118 128 133 128 137 131 135 126 108 111 119 136 110 111 105 129 116 97 133 131 101 130 124 120 130 103 119 126 125 128 134 115 134 126 103 120 120 100 124 109 107 123 123 160 107 136 112 133 127 134 112 132 117 128 124 134 112 111 121 138 113 105 109 110 139 121 129 136 123 118 133 126 139 134 111 118 118 127 115 122 114 106 142 127 131 109 137 122 135 110 121 136 122 132 133 105 132 128 127 126 100 132 149 104 105 119 109 138 136 116 127 126 115 112 152 113 128 126 141 118 108 126 111 117 115 114 107 108 133 124 140 110 113 112 129 113 123 119 126 105 119 93 123 118 114 107 124 136 115 121 100 112 127 101 124 129 124 119 125 121 107 148 132 116 114 116 127 149 114 116 117 128 140 131 124 123 113 100 138 122 146 101 128 116 130 128 136 110 104 112 121 108 142 111 120 124 121 110 103 130 136 141 120 127 117 112 105 137 103 117 114 111 121 120 113 122 121 121 114 103 122 116 122 105 116 126 128 125 93 122 121 116 138 140 106 133 120 129 117 121 105 101 125 136 116 125 107 119 98 123 123 108 126 142 114 126 125 112 120 121 128 133 98 126 126 127 120 116 90 119 129 129 115 129 115 113 102 99 118 110 107 121 104 132 101 111 117 114 127 120 126 149 118 138 130 122 123 125 117 121 129 132 149 124 117 115 135 108 118 126 141 114 113 135 111 120 121 120 104 120 132 97 133 135 103 117 123 128 128 135 122 129 128 129 141 124 136 118 107 143 136 145 116 119 129 127 144 106 123 144 124 137 119 118 122 118 145 136 132 149 123 140 123 147 130 139 123 139 135 146 142 140 127 138 138 151 135 139 123 153 125 105 149 122 127 142 153 152 125 125 127 122 149 142 127 140 135 128 112 132 126 115 139 104 145 153 162 119 131 150 136 121 119 107 125 123 97 111 137 119 116 133 121 128 149 130 124 152 135 141 131 106 142 137 112 121 121 142 150 123 138 119 125 127 129 132 125 123 136 135 122 121 125 127 144 141 140 129 158 138 139 137 131 120 134 147 163 159 161 146 166 172 147 179 193 209 200 259 274 297 326 383 406 549 520 671 658 638 629 623 549 515 520 482 461 472 452 469 406 355 323 297 271 227 188 212 171 189 173 158 163 158 142 146 125 125 150 114 139 126 135 132 126 137 128 127 110 117 141 122 141 117 134 131 137 118 138 122 134 127 122 132 128 141 107 127 134 130 108 127 113 117 116 115 131 138 112 127 116 112 120 120 139 110 109 128 136 109 118 120 127 123 119 110 126 139 130 120 127 130 128 116 141 115 124 113 110 113 138 120 132 124 108 129 126 115 118 100 131 112 118 126 149 130 120 125 108 114 111 135 132 118 107 117 129 130 140 107 136 122 108 105 122 146 125 140 135 101 103 136 138 116 139 119 103 135 139 127 125 133 132 108 125 137 119 116 137 131 113 124 107 128 132 108 115 140 106 125 114 123 124 107 130 128 144 121 132 140 120 128 132 142 124 108 133 122 120 147 115 129 123 113 130 123 135 134 153 111 137 137 132 154 142 151 135 118 133 146 144 117 165 135 145 145 137 118 144 146 120 135 132 159 117 135 128 139 146 140 123 114 124 119 113 120 124 130 142 151 124 124 132 116 118 131 132 122 116 143 115 130 111 134 129 120 121 139 130 126 115 118 100 108 118 123 127 136 118 116 105 134 112 121 137 128 126 113 135 130 113 125 111 128 131 119 129 113 128 115 124 131 110 97 119 131 99 116 135 119 125 118 112 111 113 118 111 105 114 106 127 129 111 130 100 110 130 119 133 125 110 116 108 105 128 122 139 130 118 123 128 153 119 140 130 131 128 113 124 127 110 115 131 144 117 123 121 117 116 110 112 119 127 126 117 127 115 128 110 114 115 128 120 115 125 116 135 128 116 120 130 104 130 123 106 115 128 110 130 138 138 111 137 123 97 108 113 107 112 131 129 121 117 115 120 117 121 115 129 109 110 121 122 118 130 117 120 124 118 110 94 131 118 132 118 110 114 118 134 149 123 132 124 117 129 119 112 121 130 120 121 146 122 120 112 108 140 115 132 123 118 145 136 143 124 130 131 140 125 124 118 141 106 127 111 123 110 127 126 129 120 118 128 104 109 123 114 113 127 120 138 112 109 115 132 116 109 129 111 125 117 93 119 139 123 135 116 121 117 115 109 105 111 124 124 118 113 129 113 126 122 146 124 124 115 110 118 135 130 104 97 114 133 137 128 122 109 117 131 131 124 135 103 97 102 150 134 120 127 117 120 112 107 127 92 128 130 115 132 97 128 107 122 119 115 114 111 135 96 110 138 120 106 127 125 127 119 125 117 118 130 114 143 133 142 118 128 158 123 145 147 167 146 150 162 164 162 162 179 183 200 200 223 235 238 282 306 309 329 360 367 383 448 507 533 528 507 531 643 676 663 692 737 700 682 721 711 678 710 655 646 608 644 600 544 520 491 497 508 436 415 388 379 343 326 294 312 262 268 232 212 205 209 213 189 190 201 176 149 168 175 167 135 159 154 139 120 127 135 144 140 126 119 110 146 152 120 129 132 125 111 128 129 126 151 112 117 133 145 121 128 106 128 123 113 119 103 119 108 112 114 116 130 128 120 107 105 133 117 113 125 120 136 132 110 109 107 104 112 114 104 117 112 107 116 129 120 135 125 114 111 116 117 135 129 116 117 125 147 126 118 114 111 138 120 99 122 128 106 100 119 116 104 112 137 116 103 109 136 100 119 123 103 125 110 99 128 140 109 106 124 115 118 116 108 106 132 144 105 132 114 116 125 129 119 123 107 108 88 120 118 106 134 110 100 105 115 110 124 116 105 141 107 110 123 117 117 127 127 117 128 122 126 117 117 105 131 115 128 140 123 122 107 106 128 121 116 122 116 126 108 116 98 133 116 112 125 131 109 128 128 130 116 128 146 104 108 136 110 112 126 97 125 112 122 124 112 112 124 102 121 131 118 109 118 94 134 110 129 105 111 104 115 134 112 107 131 113 117 99 131 111 127 128 111 124 124 105 119 135 118 122 127 110 104 127 138 112 132 135 131 133 123 110 106 100 132 116 119 123 132 105 105 134 119 113 117 90 111 125 131 113 117 108 112 119 121 137 110 124 90 119 108 103 118 117 122 98 91 96 126 116 117 138 113 126 99 106 108 120 126 124 125 112 130 124 115 97 114 106 124 106 121 94 109 98 113 145 106 123 110 129 127 120 108 113 108 113 108 142 104 116 101 122 105 91 98 98 121 107 122 105 107 125 106 122 100 106 117 120 122 126 120 134 108 111 117 110 113 117 107 121 99 122 124 111 110 114 108 102 119 132 126 113 107 107 116 138 132 121 123 105 120 123 124 101 124 110 111 107 113 139 113 106 124 118 109 127 120 120 133 110 138 110 124 118 101 100 106 129 103 116 109 111 101 120 108 119 109 134 119 125 123 102 95 117 121 123 118 118 110 88 118 113 103 111 126 115 121 113 131 111 137 124 120 127 115 121 113 111 125 112 99 135 99 118 123 122 133 113 109 127 132 114 128 141 120 127 132 110 89 95 106 112 115 124 119 109 111 124 123 107 106 116 116 137 111 129 98 105 102 137 110 147 118 113 114 112 120 103 111 108 121 132 117 130 110 104 112 115 109 120 125 131 110 114 107 113 121 118 109 106 114 111 99 128 129 106 120 144 130 110 134 111 116 111 138 125 116 115 125 123 127 126 133 122 103 109 125 118 116 107 114 127 112 104 105 101 115 126 101 115 115 122 110 112 111 106 111 118 117 123 116 97 113 124 101 87 138 114 116 117 118 128 99 98 115 120 126 116 122 99 112 127 121 129 134 121 117 109 98 114 115 123 129 119 110 110 109 92 106 126 95 136 113 120 122 123 106 107 110 94 127 125 112 107 118 121 112 126 109 109 127 117 115 133 127 119 114 136 119 127 127 115 120 125 106 127 118 122 111 107 110 111 114 116 112 119 117 127 128 108 138 101 111 103 109 137 111 107 125 110 122 121 131 112 129 112 118 111 110 121 88 122 112 119 129 107 114 94 116 126 119 103 132 138 112 105 120 130 121 132 107 110 100 108 96 140 132 119 103 103 96 120 148 114 113 122 137 119 123 127 130 131 129 118 113 113 117 112 124 110 109 122 98 110 108 138 133 130 101 107 121 124 89 121 125 110 125 110 91 107 119 117 104 117 122 103 114 100 136 114 120 113 122 110 117 130 97 121 116 112 127 106 112 124 112 106 92 105 104 116 122 94 87 108 112 132 106 112 132 131 132 117 109 129 104 115 100 138 87 107 117 101 122 109 126 107 114 116 120 105 108 105 117 121 113 113 124 119 113 122 129 88 112 117 99 113 119 124 122 114 96 105 119 102 105 120 123 117 116 94 113 99 125 117 120 125 105 123 104 129 101 121 122 125 116 110 134 119 112 114 102 122 126 106 113 100 123 94 108 122 108 102 102 106 121 123 110 122 115 103 110 124 95 98 103 117 122 115 108 106 101 116 118 114 125 122 102 95 93 125 119 110 133 125 122 112 129 115 115 97 122 104 110 115 111 107 107 111 138 110 120 124 119 115 118 121 113 118 96 86 118 111 136 133 129 101 144 118 130 110 110 123 108 109 117 119 123 107 105 111 122 108 120 129 133 120 122 111 103 124 118 119 125 126 96 99 101 99 109 121 119 116 117 88 122 109 127 121 122 94 107 110 94 107 106 118 119 116 116 125 90 124 116 127 93 117 111 114 114 122 136 128 112 125 144 114 104 122 115 122 136 112 107 116 144 115 118 118 106 121 106 121 109 115 118 106 118 108 105 106 124 119 109 126 137 110 127 109 105 130 136 104 116 114 142 107 110 109 135 132 109 89 114 107 113 105 114 115 99 121 121 91 109 110 92 132 104 108 125 119 140 124 113 117 114 147 98 134 118 113 94 122 128 108 97 122 125 107 116 122 103 110 111 108 126 103 109 111 110 122 122 106 127 127 97 104 107 104 124 118 112 116 109 123 115 104 134 130 128 109 108 126 133 125 119 115 128 117 110 121 107 134 112 126 122 107 121 125 106 124 119 131 119 104 130 103 126 94 136 128 94 118 132 118 105 112 113 116 135 131 112 101 108 124 108 117 122 129 115 110 137 108 96 111 123 111 123 107 103 110 107 112 133 133 108 137 133 129 110 117 119 115 119 125 112 115 120 109 111 124 119 111 123 134 97 103 116 108 115 110 124 113 125 123 123 115 118 102 128 123 125 113 125 116 106 122 137 102 111 123 123 118 120 103 136 95 123 108 112 113 120 124 127 117 122 131 151 126 121 122 125 110 144 105 141 105 119 120 111 114 117 128 115 127 104 132 110 114 124 108 134 103 131 105 122 119 116 128 121 104 109 121 129 130 106 104 131 105 110 122 113 116 107 128 111 103 108 118 130 113 134 129 110 116 126 122 117 94 140 133 122 116 104 102 139 125 116 131 101 113 128 110 100 106 123 126 108 116 123 113 127 126 119 130 103 117 118 103 110 112 92 110 117 149 139 113 120 128 110 88 120 110 118 119 113 129 119 129 106 123 108 116 110 127 94 86 128 104 113 134 116 102 131 98 99 120 102 129 98 113 112 110 112 111 116 106 109 125 132 130 116 117 123 131 113 112 108 120 124 115 110 109 129 107 108 121 111 117 108 104 111 118 124 121 115 111 117 103 126 102 114 127 113 115 113 117 120 122 96 108 110 99 107 110 104 119 124 118 126 103 110 124 113 107 112 113 105 98 99 91 107 125 131 121 114 115 112 113 113 103 125 121 105 117 103 122 116 124 107 117 107 139 108 115 97 118 96 99 109 112 110 110 115 119 102 109 112 103 112 123 125 101 117 117 135 127 102 127 120 115 108 117 117 114 95 105 117 95 117 121 94 123 111 101 109 107 129 113 105 106 137 116 116 91 102 109 103 114 109 102 120 108 117 113 115 105 121 107 132 122 113 129 110 107 115 124 109 113 102 116 121 123 106 120 123 110 114 110 118 122 137 112 129 106 131 110 115 110 118 124 124 114 131 126 96 127 109 106 127 108 110 108 110 131 104 113 110 99 111 127 119 133 124 103 134 126 116 131 107 137 115 106 138 92 114 128 103 125 131 136 107 121 116 126 106 114 107 122 120 118 107 132 110 114 115 105 122 126 119 127 120 108 108 102 129 118 111 117 124 133 110 127 139 125 118 122 121 125 96 140 116 133 111 110 110 110 137 134 123 115 126 130 120 115 131 121 114 105 108 117 117 127 130 114 118 122 111 120 108 120 117 123 122 121 121 126 104 121 119 111 130 116 138 110 111 113 119 114 124 120 130 93 122 105 100 130 127 125 145 117 108 108 108 132 101 138 91 123 101 115 112 126 110 136 113 106 124 113 108 123 113 130 137 93 139 143 112 110 115 131 123 123 121 123 101 123 105 123 124 115 101 131 88 110 120 140 125 104 126 107 111 110 127 127 104 111 97 113 97 114 129 135 101 115 131 114 108 108 124 124 101 108 111 134 123 121 134 115 126 108 102 140 104 122 107 93 109 125 113 106 117 124 128 124 117 128 120 119 121 132 103 115 111 116 107 103 132 131 105 105 124 117 118 124 136 102 126 145 130 128 110 109 114 119 125 109 121 121 109 104 108 108 124 133 118 140 116 109 115 116 127 114 113 134 123 119 104 99 132 110 120 128 121 141 122 114 119 118 130 117 132 115 141 133 122 133 118 136 123 130 117 134 118 132 144 112 124 124 121 126 140 130 152 126 145 137 129 151 149 159 139 152 139 142 167 155 169 152 179 188 187 207 190 202 228 241 235 270 249 292 332 346 351 343 381 364 382 335 372 347 316 355 352 357 340 327 342 317 312 330 296 315 284 285 289 263 275 268 256 239 244 217 220 209 194 188 185 159 149 163 163 140 148 122 138 149 159 124 136 155 138 133 127 130 101 133 135 138 131 138 133 103 126 123 119 134 111 127 139 129 103 123 128 119 129 118 110 149 124 124 108 118 129 121 107 141 132 112 130 118 108 126 128 132 118 90 115 124 129 111 117 134 115 117 104 121 101 102 138 119 121 116 140 131 113 125 121 128 112 138 113 124 133 111 123 122 133 147 113 127 133 111 122 123 133 138 135 122 108 134 97 118 117 124 127 102 114 115 113 101 113 117 114 108 118 132 113 114 153 118 111 102 119 113 124 138 113 116 109 119 127 132 120 122 120 122 119 129 109 103 117 123 119 112 114 114 118 111 125 114 110 124 99 115 138 104 103 118 123 125 124 99 132 139 110 93 110 129 107 102 122 116 125 111 125 98 98 111 121 111 128 121 107 126 122 124 123 118 118 119 116 125 131 125 129 128 107 103 106 123 105 89 111 108 137 117 102 119 103 143 116 117 108 136 117 124 111 120 102 113 111 121 117 100 132 109 113 132 113 121 112 115 128 114 97 126 118 120 111 124 107 114 108 118 119 130 114 95 108 95 129 114 108 125 117 95 119 141 126 104 125 104 120 110 121 122 129 108 107 123 120 120 104 123 102 117 116 111 115 115 123 95 123 125 104 102 121 102 128 128 117 108 117 125 102 110 117 117 99 100 120 95 120 107 124 115 128 106 124 127 111 110 94 112 112 104 131 121 114 98 121 106 123 113 132 133 106 128 128 107 110 122 108 110 144 119 118 101 109 106 123 126 118 117 106 106 111 118 106 119 111 112 119 117 103 125 125 124 106 106 101 122 114 141 97 121 107 118 117 104 108 123 126 129 130 110 114 124 118 120 114 115 118 138 107 133 132 116 122 106 121 111 136 115 127 107 113 133 115 123 120 123 107 112 123 94 111 120 130 103 122 115 118 122 111 129 107 127 118 110 122 127 118 108 109 135 115 140 119 118 113 111 116 105 109 118 107 139 132 120 112 132 105 115 111 101 110 115 116 114 94 132 130 116 102 119 133 128 117 111 127 109 120 111 90 111 116 113 123 130 124 108 111 135 149 101 128 118 105 119 125 117 122 108 123 127 118 142 144 119 114 126 119 100 125 130 111 117 133 101 117 119 101 114 95 107 112 108 124 118 122 93 134 105 115 115 97 131 118 117 122 117 130 104 108 112 123 135 116 144 111 127 112 131 116 109 121 131 113 137 110 110 125 129 114 115 125 111 110 106 124 123 116 121 97 105 115 125 122 112 91 126 113 117 138 104 124 117 110 118 115 121 119 127 101 132 137 123 127 103 113 118 120 111 120 145 119 104 122 121 117 113 114 117 105 106 132 111 112 144 124 127 122 123 100 107 142 120 115 120 119 123 102 116 125 103 103 109 105 117 129 109 117 127 108 97 119 123 113 121 118 126 110 138 119 105 113 125 108 116 101 122 129 121 137 122 96 90 125 133 113 117 121 116 129 123 133 115 118 126 95 132 122 115 119 105 126 114 122 119 118 110 111 116 110 114 111 118 111 138 105 134 123 114 129 119 108 129 115 106 108 109 128 122 114 109 109 124 110 157 106 112 122 136 133 115 110 115 108 110 105 96 149 108 133 114 109 122 126 117 108 114 115 115 113 118 137 100 118 131 107 114 136 98 104 118 118 113 108 125 111 104 100 114 114 126 106 131 101 109 142 123 124 107 127 122 117 96 131 121 116 104 103 121 122 111 116 116 114 99 142 108 118 133 131 117 113 112 128 135 110 126 117 123 115 101 108 100 112 122 117 98 116 126 100 112 126 133 118 110 140 122 105 106 109 130 112 118 122 107 110 119 123 103 132 105 99 122 117 106 111 126 129 117 122 121 104 131 112 117 121 108 114 117 101 109 107 118 147 131 123 114 113 133 119 106 130 106 112 131 99 94 127 125 124 138 130 110 91 116 104 107 113 122 106 133 118 126 109 109 96 121 129 131 109 126 117 119 112 113 100 121 115 102 127 125 131 129 105 99 100 106 105 131 120 116 109 114 107 128 129 114 126 119 119 113 108 119 133 124 106 140 122 116 124 121 102 121 109 115 110 118 135 117 105 105 106 115 116 137 131 109 112 122 118 121 130 114 115 125 104 105 118 103 101 116 128 103 137 97 115 120 141 132 100 122 113 105 127 108 115 101 120 107 118 103 121 117 137 116 95 96 120 111 120 123 113 139 113 126 113 130 114 129 101 119 102 119 116 118 118 121 124 128 130 116 128 118 121 124 118 97 99 115 116 124 123 130 107 135 122 93 125 114 118 116 110 114 125 112 102 106 131 115 114 103 112 104 134 131 138 108 120 121 123 98 104 125 117 114 119 108 109 121 107 107 108 115 140 137 109 116 126 121 115 128 114 137 119 116 120 119 126 121 120 125 119 118 119 135 110 127 98 118 117 131 112 117 100 139 119 103 132 119 118 116 118 124 114 131 145 116 106 108 128 128 116 119 128 122 135 108 128 94 94 118 139 122 107 115 121 106 107 95 113 113 124 107 112 120 111 113 136 137 122 118 123 133 95 116 115 132 124 99 119 113 128 121 106 117 117 92 112 148 114 125 146 132 127 127 126 130 127 118 109 130 101 116 107 107 110 106 116 105 131 109 115 120 85 97 113 118 126 111 122 116 119 136 108 121 121 118 143 119 119 120 110 115 146 144 122 145 142 160 140 114 156 147 149 150 142 154 158 161 133 177 157 144 176 162 192 150 170 157 186 188 191 191 165 177 174 173 160 194 158 160 165 175 184 167 165 151 145 153 165 162 169 150 153 143 157 156 155 155 129 137 154 151 142 139 146 135 148 141 130 152 111 129 129 136 125 111 138 124 116 136 112 118 120 134 112 124 124 99 135 118 123 109 127 126 105 139 130 112 128 119 121 127 118 116 113 134 131 130 125 117 123 143 131 132 118 136 114 124 116 118 119 92 118 114 114 117 113 128 98 106 110 107 147 116 95 122 102 122 122 110 98 127 112 107 99 120 96 120 103 112 111 133 97 122 121 103 121 127 137 113 114 118 115 115 125 121 127 129 118 120 117 123 110 119 126 144 123 122 128 127 113 93 111 123 117 110 113 102 104 103 114 113 111 89 111 129 130 125 106 100 128 116 120 131 124 108 110 123 101 108 101 108 125 103 105 120 107 113 114 116 101 120 104 107 120 118 107 123 119 121 109 113 118 106 115 120 122 127 138 126 126 116 123 108 108 135 110 119 131 124 121 97 124 118 120 107 107 122 97 108 113 123 148 109 115 112 127 109 130 118 111 117 114 111 116 108 117 117 108 129 125 117 104 108 109 102 117 105 133 148 126 111 115 140 127 118 115 118 115 110 118 123 131 107 137 128 112 103 115 99 113 117 110 115 104 131 130 122 121 112 117 105 109 133 129 113 119 103 115 124 132 96 98 112 118 124 123 129 125 119 117 111 126 105 92 118 111 122 128 111 120 108 120 122 104 114 116 118 128 99 115 95 134 123 113 123 130 124 121 117 112 108 91 144 115 116 102 102 107 111 130 131 126 114 112 119 129 112 122 121 107 117 115 134 113 107 129 120 128 114 129 125 138 140 109 132 133 118 115 114 128 146 148 151 146 159 158 160 177 197 213 193 183 178 195 197 173 182 203 177 158 161 172 170 144 155 146 141 158 159 158 153 159 155 161 177 172 175 162 160 140 158 152 143 173 134 153 151 129 125 137 111 148 137 102 101 132 113 109 132 119 116 121 114 118 100 129 108 119 129 136 109 111 134 130 114 134 127 127 109 134 120 125 140 96 133 102 116 126 114 115 115 130 123 113 101 93 107 116 119 126 122 127 114 124 114 100 107 110 101 115 133 111 102 123 115 125 103 107 100 117 124 140 130 98 138 114 107 119 148 125 120 103 115 117 117 123 138 97 105 126 130 107 102 122 120 120 122 129 122 114 107 101 107 110 126 104 125 119 130 111 99 123 93 113 128 138 112 118 117 125 115 112 115 122 108 141 97 111 122 130 123 128 136 127 119 123 109 116 128 113 113 116 111 103 121 111 120 135 133 100 99 114 112 125 135 113 109 117 114 131 112 119 108 96 113 127 123 113 129 121 133 127 117 106 121 110 120 108 120 116 118 110 112 114 136 120 120 140 105 147 103 118 122 116 132 109 102 113 102 111 106 117 106 102 114 124 122 116 126 116 123 135 128 114 113 116 121 108 121 105 134 123 134 117 106 106 119 126 107 126 124 105 122 102 119 104 118 117 123 115 134 120 120 128 102 127 117 131 122 132 119 108 114 120 107 112 125 116 109 117 105 107 127 110 121 118 95 125 143 138 129 127 109 112 115 126 102 140 94 122 113 127 134 119 119 129 104 125 133 126 127 115 106 133 112 119 121 117 111 136 113 126 125 106 117 125 113 121 117 117 101 139 104 110 121 113 119 123 99 120 129 104 113 114 100 106 118 105 126 108 128 114 114 125 114 110 93 119 125 117 120 124 113 116 122 113 89 117 142 109 129 124 113 119 123 112 109 121 140 97 123 125 116 129 122 108 138 132 128 128 120 125 131 121 107 98 111 105 104 116 119 116 109 103 108 111 110 105 120 117 119 120 101 124 110 111 115 109 142 125 117 122 115 125 110 107 120 132 103 119 135 114 101 113 117 124 136 133 105 143 125 116 103 116 104 112 106 110 104 127 101 127 117 100 108 112 104 103 107 107 135 102 106 107 133 132 135 93 131 115 109 126 123 121 119 128 107 111 102 101 129 130 137 132 128 108 116 104 106 109 115 106 133 125 106 103 108 104 116 118 100 135 130 112 121 130 104 110 104 121 104 124 131 123 96 131 121 117 109 102 120 106 129 124 106 129 109 108 93 109 123 113 123 126 123 138 120 126 123 128 125 105 114 112 132 134 119 111 106 135 110 130 125 119 130 140 98 127 119 102 121 120 136 108 101 120 121 118 120 112 124 117 157 116 106 104 120 125 132 112 102 106 113 112 112 125 137 114 116 115 116 120 100 103 116 114 112 118 123 123 117 134 100 116 124 131 115 117 115 113 106 115 134 123 116 135 122 131 111 117 121 128 108 139 142 137 104 129 113 101 111 116 107 118 106 104 97 120 118 114 114 128 115 119 112 115 106 98 123 107 148 112 117 133 116 127 98 140 94 123 121 114 124 118 113 120 119 100 118 93 113 118 129 112 115 104 124 124 111 117 107 125 101 100 122 129 97 119 113 98 126 115 114 116 122 123 115 93 111 116 121 107 121 119 125 120 128 126 118 120 99 117 124 144 128 109 124 112 120 116 123 109 101 138 114 135 124 127 133 116 118 121 123 121 130 119 134 113 119 107 137 113 108 135 109 122 114 112 116 109 113 93 132 127 113 136 119 110 98 114 117 102 124 121 117 108 123 123 130 133 111 108 106 103 115 132 104 113 125 103 92 124 108 133 120 119 121 114 107 127 116 104 134 123 125 109 119 119 116 120 133 111 112 123 105 126 140 121 122 109 115 125 99 129 108 122 103 105 139 113 125 130 143 110 111 120 100 119 120 131 101 120 123 107 107 99 115 118 105 117 129 105 111 114 108 123 123 147 121 109 108 106 132 109 145 104 115 116 126 129 129 118 114 137 117 109 110 110 126 123 124 107 102 113 112 134 113 122 122 122 110 126 106 100 118 98 109 110 115 136 134 120 105 121 123 117 134 105 121 97 102 127 130 117 127 101 126 125 134 111 121 121 104 132 133 123 115 124 104 120 114 112 118 123 128 119 117 116 118 131 131 132 106 103 107 102 120 100 98 119 114 102 120 113 120 121 127 112 124 116 114 100 113 104 96 120 126 107 132 122 138 113 130 111 120 115 123 128 110 131 109 95 108 124 118 119 101 131 129 120 117 127 122 123 133 122 104 129 113 130 138 122 100 128 122 102 110 100 133 119 134 107 110 127 111 98 124 118 112 112 103 112 117 113 137 122 127 128 115 100 134 116 119 119 132 137 116 122 120 126 116 141 117 115 112 123 121 123 122 125 127 136 122 108 111 113 125 122 103 120 114 111 126 130 118 114 107 132 90 117 133 126 102 111 109 122 126 114 124 118 129 117 101 146 110 123 140 110 129 84 118 99 117 86 100 133 117 129 117 107 122 105 118 128 111 116 105 97 99 120 127 106 105 132 128 115 143 112 119 130 131 107 143 124 129 114 114 104 105 109 119 122 121 126 107 128 128 90 116 108 122 120 108 120 126 109 111 140 128 130 136 117 129 111 116 119 138 128 110 112 123 119 116 109 107 125 121 105 113 116 125 140 104 103 102 112 108 115 97 107 108 107 111 118 112 105 97 128 124 114 119 119 106 123 118 132 130 122 127 116 124 125 133 124 108 118 129 102 125 141 118 132 126 133 118 122 120 130 127 106 92 126 98 120 101 108 144 114 120 122 107 136 127 106 127 127 118 108 117 125 137 111 124 118 105 114 118 112 134 118 120 130 121 118 114 124 116 105 132 135 95 105 130 123 118 124 130 124 109 130 128 121 121 130 96 122 128 125 95 128 137 149 111 123 132 113 112 135 126 124 123 111 117 109 109 94 106 120 99 82 130 135 98 111 113 124 118 106 118 114 125 86 117 128 121 116 124 100 120 125 119 109 115 125 112 104 141 114 95 115 129 129 108 106 129 125 107 132 104 125 117 119 121 116 111 109 126 105 132 103 111 98 128 107 113 130 109 129 127 125 129 104 104 131 113 125 116 115 145 105 131 111 112 99 124 98 94 102 113 127 116 133 121 123 109 136 99 119 119 128 122 109 110 126 127 118 125 118 132 113 122 104 129 126 105 126 109 112 116 134 108 137 120 111 119 101 108 119 111 125 121 82 116 109 99 120 99 123 103 125 101 113 113 120 96 116 102 113 123 135 124 111 123 113 129 110 112 111 114 95 107 114 131 107 131 131 111 118 111 131 112 126 115 119 146 136 129 113 116 119 125 128 110 112 123 104 129 135 117 140 123 125 116 114 124 120 108 112 118 119 121 143 116 126 107 128 125 115 123 122 135 110 104 116 149 109 140 132 131 121 125 104 139 131 117 130 106 116 127 127 115 109 125 108 146 118 124 109 127 135 119 124 130 142 134 137 147 123 151 149 143 115 127 124 137 141 148 136 129 123 129 134 131 151 149 143 147 130 134 106 130 166 126 137 119 117 125 133 127 129 130 135 119 135 125 128 124 136 126 121 140 116 119 131 135 155 133 129 110 108 119 109 122 133 121 121 129 110 153 154 126 115 126 129 131 131 137 143 142 121 125 128 124 135 116 122 113 117 139 114 123 113 115 112 111 131 113 120 103 143 103 133 109 124 114 140 137 107 127 127 119 120 129 115 118 117 122 126 97 114 124 126 132 116 112 116 118 114 116 128 127 106 111 115 132 117 115 119 116 125 121 121 121 114 112 128 131 134 104 115 107 127 125 122 122 135 110 122 124 117 80 137 108 131 131 127 108 111 119 121 119 114 119 111 113 106 127 106 121 117 119 128 120 99 116 128 109 135 115 118 117 106 121 110 122 110 112 127 111 122 125 134 123 134 109 132 109 125 112 122 128 136 141 112 107 107 127 111 113 104 130 128 127 121 128 117 117 135 117 115 110 120 113 119 128 136 107 124 125 133 120 130 112 109 117 114 120 121 105 100 118 129 124 122 125 124 121 120 97 122 107 124 119 118 110 128 122 115 97 91 99 119 106 105 107 120 127 116 133 128 132 122 105 107 130 106 134 122 121 109 103 119 110 118 122 126 102 108 116 112 101 117 115 113 97 122 117 111 134 115 122 114 110 131 134 121 111 103 101 131 115 117 126 124 120 117 105 134 135 121 114 120 103 126 124 126 136 89 119 127 114 117 117 141 128 127 117 117 132 136 115 124 107 123 120 122 118 127 114 96 105 118 116 130 131 119 127 113 120 124 125 113 99 134 114 115 115 122 132 112 147 112 127 104 109 123 141 126 112 101 107 108 114 112 111 97 112 126 127 108 114 96 106 121 143 124 116 107 124 112 133 122 110 127 118 117 107 122 115 121 125 95 121 127 107 115 120 109 134 122 121 121 97 135 113 122 113 115 120 114 117 85 114 109 123 109 137 105 107 104 109 133 117 111 112 102 125 121 100 132 134 99 119 136 140 143 122 103 131 120 127 116 115 123 101 103 116 116 122 115 119 110 115 123 121 104 112 118 102 104 123 137 116 118 117 117 126 114 126 129 113 129 111 127 118 111 134 140 115 119 128 121 129 119 124 129 140 110 125 120 112 112 119 116 124 104 113 135 125 115 127 120 147 116 114 111 99 97 105 119 141 102 123 98 138 120 147 118 131 116 132 121 109 114 129 124 117 134 109 129 115 124 93 121 110 130 124 126 123 123 118 140 111 127 109 118 125 104 126 115 118 108 112 109 122 125 125 130 125 135 113 122 127 112 119 116 135 140 140 113 110 125 125 121 121 114 117 108 133 119 116 138 113 102 123 120 121 125 126 105 134 139 126 83 111 122 116 108 146 119 111 114 138 116 118 120 121 122 136 120 121 111 106 123 103 119 113 117 119 116 124 124 128 119 117 131 105 121 113 112 106 104 111 105 136 115 127 132 109 120 115 139 113 111 126 120 110 114 124 105 113 117 125 120 136 119 95 111 126 107 107 112 137 131 115 112 135 116 115 109 125 89 117 115 110 113 135 111 118 107 115 121 111 96 113 137 124 105 144 123 106 113 99 129 120 125 119 97 123 128 113 132 137 134 131 106 118 110 107 118 111 115 125 121 115 127 133 149 113 115 129 117 125 90 112 127 103 110 118 113 117 121 116 108 110 119 104 107 124 107 118 117 120 131 108 110 125 141 134 107 127 123 115 114 111 111 122 117 118 115 130 131 127 100 109 120 126 131 99 113 121 125 112 117 115 112 122 126 129 124 122 119 107 120 119 123 113 119 117 127 116 135 132 115 109 123 136 108 105 144 118 118 134 125 115 110 116 143 134 118 124 123 103 118 118 115 143 108 118 127 114 99 131 102 111 102 129 87 144 113 130 127 104 115 147 131 118 113 110 140 116 119 152 123 115 121 131 106 123 120 122 122 108 112 121 128 120 103 125 122 117 123 118 127 119 123 118 115 119 122 111 112 112 123 126 122 106 106 118 118 133 109 108 106 125 120 106 127 114 124 146 125 112 100 89 114 120 134 116 134 117 125 115 107 135 128 132 123 133 122 122 128 122 125 116 111 130 118 114 119 114 123 129 112 115 129 129 121 139 106 123 126 122 108 101 139 123 112 97 113 97 117 116 132 113 111 119 114 116 139 113 115 128 119 125 113 123 138 115 133 123 144 105 99 100 112 122 127 125 123 134 112 139 123 128 121 137 113 121 119 115 102 133 118 127 120 119 120 119 113 106 113 123 108 133 108 108 111 120 113 126 107 133 107 116 130 128 125 124 124 120 122 126 124 146 120 113 100 128 127 131 104 116 118 126 133 116 114 123 115 109 120 122 118 120 124 109 116 116 129 112 125 115 114 98 127 128 110 138 125 108 113 125 121 124 123 109 101 108 104 123 125 122 123 125 128 125 105 120 109 135 120 111 101 105 112 126 126 113 144 109 124 116 107 112 127 139 117 122 124 128 126 106 127 110 105 118 131 131 117 111 134 127 120 128 126 119 120 127 110 118 140 123 125 120 128 124 129 131 127 115 107 122 131 137 129 108 127 139 126 110 134 130 133 114 126 112 148 126 133 156 137 151 141 140 122 163 153 121 114 156 117 135 142 156 140 157 131 146 152 155 138 159 149 131 127 130 152 140 142 125 139 153 136 139 139 141 129 115 133 133 152 131 151 109 129 134 131 149 114 141 142 131 126 134 144 130 139 118 133 134 142 126 127 122 133 136 138 135 135 130 107 130 115 131 110 121 133 137 123 109 93 116 128 143 133 118 128 110 130 134 93 107 120 130 108 119 124 129 103 141 122 149 130 120 105 99 123 118 120 122 122 113 127 148 107 138 127 103 111 128 119 135 116 119 133 103 115 118 115 110 137 116 133 109 136 124 110 101 139 135 139 116 115 111 120 105 111 118 119 113 118 118 147 118 129 130 116 107 140 117 130 123 119 103 116 113 112 123 124 122 132 120 114 126 104 112 128 113 113 126 116 124 110 131 128 111 116 123 121 122 140 132 120 109 143 96 147 118 114 126 115 122 136 130 124 122 110 140 134 132 137 107 129 109 131 127 127 121 131 109 122 123 130 124 121 116 117 110 118 130 140 111 123 105 106 141 120 127 118 114 118 119 146 133 117 116 131 120 113 103 128 112 113 140 125 106 125 118 114 141 120 119 124 119 108 128 123 112 116 114 92 135 115 121 111 125 121 106 116 106 97 140 123 115 128 133 119 127 123 128 111 102 127 108 100 118 131 116 128 115 114 149 119 115 116 100 117 119 117 121 133 129 117 129 119 125 136 132 126 104 105 127 127 117 111 117 117 113 130 129 124 127 102 100 118 112 128 135 137 127 129 133 112 103 126 119 116 120 122 113 132 117 115 117 140 129 124 135 123 140 120 132 131 142 141 107 135 119 125 124 137 143 144 169 144 107 143 122 143 150 117 135 131 134 126 146 156 129 131 125 173 134 133 145 130 121 159 141 124 168 129 145 151 143 138 165 144 166 170 137 155 148 145 149 156 168 147 168 158 163 149 149 161 178 190 173 149 155 160 137 165 147 140 150 152 144 147 145 132 127 150 158 160 139 163 146 135 150 130 133 153 154 147 139 150 152 146 149 146 108 141 145 136 142 134 135 147 145 114 145 134 140 152 142 111 154 144 128 152 126 144 119 115 152 121 120 126 137 108 134 123 117 111 115 109 123 131 137 117 112 124 127 143 130 137 125 115 144 121 117 125 128 109 102 110 140 113 139 143 123 110 131 117 137 119 113 120 116 117 139 134 118 121 115 103 102 117 118 115 130 120 129 122 133 139 93 129 117 121 115 129 111 113 129 112 124 107 116 102 128 114 126 118 117 112 98 124 100 139 121 106 112 125 117 119 103 145 107 123 110 115 112 117 103 111 126 118 117 133 132 113 127 135 118 126 124 104 122 118 93 131 108 107 119 126 101 109 120 122 107 130 113 134 103 109 107 135 109 110 115 116 132 113 99 141 112 117 117 116 135 124 144 121 115 119 103 121 108 106 114 132 98 134 116 117 107 116 94 115 131 99 118 123 105 99 124 113 106 115 120 97 120 122 110 102 109 127 117 107 115 107 120 117 130 122 104 115 123 116 131 112 98 125 100 126 124 116 126 113 112 131 110 109 104 123 107 148 109 120 115 119 115 122 122 118 124 122 117 130 120 142 127 130 109 111 105 129 120 127 104 114 111 105 105 132 109 110 117 117 116 132 110 112 124 114 118 124 106 114 109 117 138 115 119 146 110 121 112 107 99 121 118 114 107 102 123 126 106 131 119 128 114 117 128 110 115 108 117 120 118 105 133 116 117 108 107 107 127 118 136 113 109 108 115 102 108 119 107 115 124 128 119 121 111 120 100 115 125 130 105 113 108 102 114 106 140 125 125 121 113 104 130 117 116 127 112 115 111 112 107 118 125 125 127 109 121 122 130 125 124 118 111 120 130 98 142 133 108 104 112 113 108 120 112 124 111 111 110 110 110 108 121 107 114 115 105 117 123 99 110 108 112 124 124 113 126 113 111 112 118 140 95 114 139 119 123 124 98 116 120 122 117 152 110 120 136 111 118 123 108 132 126 129 139 117 109 123 113 120 106 128 107 107 129 135 108 122 113 110 124 124 121 139 131 118 97 112 151 122 127 122 110 117 116 114 119 117 133 122 127 125 106 116 103 123 104 117 132 130 113 114 106 115 122 128 107 123 121 113 117 118 142 121 117 112 116 122 119 122 115 119 118 121 121 114 126 116 123 114 115 109 133 121 132 107 100 129 124 118 120 113 116 114 105 116 111 103 108 120 112 113 105 116 110 145 133 117 123 98 120 109 112 122 107 125 117 118 94 113 122 90 124 120 106 123 133 112 124 124 109 115 131 125 131 123 115 115 121 110 122 141 121 123 120 116 120 132 117 112 109 114 127 109 133 118 107 141 111 126 109 108 109 114 98 107 128 122 108 110 121 122 123 130 126 116 120 123 132 112 124 115 124 131 122 126 102 131 110 125 118 126 124 107 111 117 125 121 117 100 107 129 123 121 136 119 110 112 116 130 103 130 108 122 114 124 129 123 123 114 109 115 124 108 124 115 107 122 113 123 120 110 125 121 137 108 118 128 112 137 121 127 116 114 110 128 104 118 100 148 122 117 131 112 132 116 103 117 124 104 112 120 113 131 121 112 105 116 105 140 128 118 129 129 114 127 102 131 116 99 107 100 123 104 116 126 120 127 109 111 117 147 133 123 119 116 118 133 123 137 136 118 137 113 130 116 91 104 121 127 108 101 137 127 121 100 116 138 136 119 104 118 105 121 115 120 119 115 123 119 111 138 122 124 116 112 137 123 122 135 108 120 132 122 122 125 131 116 111 129 108 125 116 109 130 99 131 116 100 108 106 121 118 109 105 115 133 137 116 101 95 125 121 105 117 128 115 117 110 120 130 111 127 129 144 118 111 125 115 121 107 140 126 124 129 123 129 116 114 107 110 128 118 130 124 91 121 125 140 130 98 120 129 108 127 114 138 115 123 112 115 119 108 143 123 129 115 114 122 110 104 102 135 117 121 132 91 115 121 94 120 107 122 114 120 96 120 125 104 125 106 110 109 114 112 120 95 111 113 107 126 124 124 107 124 140 123 123 115 124 118 130 113 114 108 121 122 114 127 122 141 135 111 93 104 119 102 116 118 111 137 139 111 141 121 100 101 131 118 128 127 109 99 128 106 121 101 119 114 140 145 124 125 111 119 123 130 122 131 138 127 129 108 142 124 107 136 128 101 124 115 102 117 131 122 113 122 126 111 129 106 107 123 111 121 113 118 120 130 123 127 112 110 118 130 94 103 107 124 100 102 115 134 110 133 125 110 117 120 108 138 112 127 130 126 118 126 127 131 119 133 106 118 109 126 121 131 99 134 102 118 111 97 124 107 129 124 107 129 88 111 110 121 125 96 137 120 132 112 116 111 122 128 128 106 107 114 133 143 122 108 137 130 124 119 140 119 128 102 100 106 136 96 106 125 113 127 94 114 106 122 122 135 113 118 140 133 120 118 149 121 141 123 142 133 122 115 124 132 108 105 130 117 106 126 127 109 112 111 126 109 134 134 115 126 116 105 139 105 128 141 118 97 120 101 114 113 103 116 113 115 116 127 127 103 127 123 112 137 116 118 101 131 122 122 126 143 104 110 113 138 113 125 103 125 120 131 128 143 131 116 132 110 126 119 132 93 127 117 112 131 118 127 111 121 119 123 111 119 127 109 115 120 104 103 114 133 108 134 110 132 120 122 146 139 131 138 103 132 128 117 127 135 123 123 129 134 93 127 121 98 125 122 115 108 118 120 124 118 121 127 124 139 127 118 120 104 111 123 127 124 115 137 106 133 118 132 125 123 105 142 104 131 125 134 118 125 122 119 121 122 142 137 121 138 126 147 109 129 105 118 121 100 158 118 121 112 126 137 114 118 137 137 114 112 121 119 124 106 114 108 149 140 116 108 110 113 122 128 122 108 125 133 129 107 122 119 137 108 136 131 114 109 129 117 120 107 140 125 123 121 126 145 117 143 114 123 115 141 130 142 136 126 126 137 119 126 134 125 134 117 124 130 144 117 112 129 127 129 122 102 109 112 159 131 105 125 101 128 128 128 121 123 132 111 105 118 120 114 129 114 129 114 135 130 131 125 123 129 119 116 130 126 116 108 117 116 122 125 129 129 116 129 134 126 123 115 111 104 103 120 128 136 118 116 116 135 120 145 130 107 127 118 131 127 135 111 109 125 120 140 144 132 115 124 128 130 125 97 113 129 107 111 126 135 128 112 104 114 123 123 136 123 112 133 129 130 115 102 100 109 123 105 132 107 127 147 137 113 116 123 123 136 109 108 122 106 129 121 122 125 108 112 111 119 115 129 140 138 90 113 140 111 130 104 118 123 129 114 110 118 125 116 111 118 113 120 120 131 120 131 131 135 104 137 132 106 110 109 121 125 141 137 111 134 121 119 109 125 135 119 124 122 125 113 102 104 107 113 139 113 135 122 124 128 130 115 122 104 122 123 126 131 128 130 129 120 113 119 120 130 133 108 133 131 121 132 130 132 116 126 150 116 106 118 120 120 104 146 123 124 118 136 126 123 115 126 129 117 124 121 117 106 127 123 134 113 115 123 114 124 116 144 107 117 119 99 133 119 128 122 116 111 123 125 122 123 112 122 135 141 118 112 111 124 125 125 118 131 112 119 125 106 118 124 123 135 124 115 120 123 117 115 136 128 112 113 111 118 111 128 135 116 143 128 129 111 132 100 128 122 111 141 136 109 121 132 122 137 121 135 120 130 117 114 142 115 136 158 146 118 123 133 133 124 135 134 123 130 136 125 143 127 131 155 134 153 130 119 114 135 129 141 140 138 155 151 127 156 127 137 149 150 131 140 163 150 139 158 156 122 154 168 147 165 154 140 164 163 151 143 150 159 148 140 140 138 157 150 141 167 166 162 148 150 147 145 150 133 161 145 144 135 145 151 129 138 145 164 153 126 144 146 133 140 154 160 149 143 143 152 145 157 126 134 126 147 132 147 157 143 147 130 147 128 146 127 169 132 130 156 159 137 150 128 159 136 111 114 139 137 142 143 141 120 135 125 160 142 134 132 141 141 136 134 132 138 132 122 123 143 117 153 121 112 119 130 138 144 131 142 109 133 137 121 132 131 136 102 115 139 137 128 147 120 135 140 119 124 117 128 141 129 104 140 130 128 145 117 125 120 127 105 115 131 120 108 120 122 133 126 103 118 122 138 114 129 118 120 115 118 120 128 118 128 121 110 102 138 135 117 117 124 130 151 124 105 113 117 127 102 102 112 121 131 109 108 109 110 127 123 125 122 123 118 115 125 120 111 120 132 128 120 122 120 120 123 130 111 123 113 105 115 114 113 120 123 134 149 114 136 108 133 112 117 105 133 122 123 122 113 134 126 130 135 134 133 121 113 118 122 130 115 128 130 131 124 116 124 126 124 128 106 125 128 128 116 119 115 116 131 121 102 134 116 120 113 118 102 115 114 119 120 123 109 122 113 95 101 126 122 139 142 114 142 113 124 115 111 107 126 128 113 120 104 110 114 140 115 122 123 125 104 127 134 107 119 124 123 128 130 130 108 109 128 110 131 128 140 110 113 108 111 112 113 112 121 137 125 112 121 115 99 126 117 118 124 119 120 101 132 110 111 115 130 120 134 103 116 110 119 144 115 132 121 113 116 121 115 128 146 116 132 120 131 128 138 133 126 119 103 107 109 119 117 118 117 136 112 116 116 146 126 97 125 140 139 120 103 139 118 123 106 116 110 134 111 108 125 101 111 130 123 101 140 130 123 135 119 106 107 121 114 123 113 92 127 115 133 121 121 118 129 113 120 121</counts>
			</dataPoints>
		</scan>
	</xrdMeasurement>
</xrdMeasurements>