File: data/XRD/_misc/W6822-1D_600°C_1h_absolute_2th-om_10-130deg_PIXscan_20min_1.xrdml
<xrdMeasurements xmlns="http://www.xrdml.com/XRDMeasurement/2.1" xmlns:xsi="http://www.w3.org/2001/XMLSchema-instance" xsi:schemaLocation="http://www.xrdml.com/XRDMeasurement/2.1 http://www.xrdml.com/XRDMeasurement/2.1/XRDMeasurement.xsd" status="Completed">
	<comment>
		<entry>Configuration=Factory configuration, Owner=User-1, Creation date=7/8/2013 4:01:53 PM</entry>
		<entry>Goniometer=PW3050/65 (Theta/2Theta); Minimum step size 2Theta:0.0001; Minimum step size Omega:0.0001</entry>
		<entry>Sample stage=MRD Cradle; Minimum step size Phi:0.01; Minimum step size Chi:0.01; Minimum step size X:0.01; Minimum step size Y:0.01; Minimum step size Z:0.001</entry>
		<entry>Diffractometer system=XPERT-PRO</entry>
		<entry>Measurement program=C:\PANalytical\Data Collector\Programs\Jorrit\2thom\_absolute_2th-om_10-130deg_PIXscan_20min.xrdmp, Identifier={3DBA8D3C-DF21-4D25-BD76-C00789461246}</entry>
	</comment>
	<sample type="To be analyzed">
		<id></id>
		<name></name>
		<preparedBy></preparedBy>
	</sample>
	<xrdMeasurement measurementType="Scan" status="Completed" sampleMode="Reflection">
		<comment>
			<entry>2theta-omega 10-130 deg PIXscan 17min</entry>
			<entry>PHD Lower Level = 4.83 (keV), PHD Upper Level = 11.27 (keV)</entry>
		</comment>
		<usedWavelength intended="K-Alpha 1">
			<kAlpha1 unit="Angstrom">1.5405980</kAlpha1>
			<kAlpha2 unit="Angstrom">1.5444260</kAlpha2>
			<kBeta unit="Angstrom">1.3922500</kBeta>
			<ratioKAlpha2KAlpha1>0.5000</ratioKAlpha2KAlpha1>
		</usedWavelength>
		<incidentBeamPath>
			<radius unit="mm">320.00</radius>
			<xRayTube id="1010048" name="Empyrean Cu LFF HR (9430 033 7310x) DK442154">
				<tension unit="kV">40.0</tension>
				<current unit="mA">40.0</current>
				<anodeMaterial>Cu</anodeMaterial>
				<focus type="Line">
					<length unit="mm">12.0</length>
					<width unit="mm">0.4</width>
					<takeOffAngle unit="deg">4.2</takeOffAngle>
				</focus>
			</xRayTube>
			<xRayMirror id="27010001" name="Inc. Beam Cu W/Si (parabolic MRD)" hybrid="false">
				<crystal type="Graded" shape="Parabolic">W/Si</crystal>
				<acceptanceAngle unit="deg">0.800</acceptanceAngle>
				<length unit="mm">60.0</length>
			</xRayMirror>
			<sollerSlit id="21010002" name="Soller slits 0.04 rad.">
				<opening unit="rad">0.0400</opening>
			</sollerSlit>
			<mask id="22030007" name="Fixed mask 2 mm">
				<distanceToSample unit="mm">220.00</distanceToSample>
				<width unit="mm">2.00</width>
			</mask>
			<divergenceSlit id="22010007" name="Fixed slit 1/8°" xsi:type="fixedDivergenceSlitType">
				<distanceToSample unit="mm">220.00</distanceToSample>
				<height unit="mm">0.19</height>
			</divergenceSlit>
		</incidentBeamPath>
		<diffractedBeamPath>
			<radius unit="mm">320.00</radius>
			<sollerSlit id="21010002" name="Soller slits 0.04 rad.">
				<opening unit="rad">0.0400</opening>
			</sollerSlit>
			<receivingSlit id="22010001" name="Fixed slit 4°">
				<height unit="mm">5.88</height>
			</receivingSlit>
			<detector id="7010017" name="PIXcel3D 1x1 detector" xsi:type="areaDetectorType">
				<phd unit="%">
					<lowerLevel>30.0</lowerLevel>
					<upperLevel>70.0</upperLevel>
				</phd>
				<mode>Scanning</mode>
				<activeChannelsEquatorial>255</activeChannelsEquatorial>
				<activeChannelsAxial>255</activeChannelsAxial>
				<pitchEquatorial unit="mm">0.05500</pitchEquatorial>
				<pitchAxial unit="mm">0.05500</pitchAxial>
				<readOutPeriod unit="seconds">0.045</readOutPeriod>
			</detector>
		</diffractedBeamPath>
		<scan appendNumber="0" mode="Continuous" scanAxis="2Theta-Omega" status="Completed">
			<header>
				<startTimeStamp>2024-08-05T13:56:45+02:00</startTimeStamp>
				<endTimeStamp>2024-08-05T14:15:32+02:00</endTimeStamp>
				<author>
					<name>PRO-MRD</name>
				</author>
				<source>
					<applicationSoftware version="6.1b">Data Collector</applicationSoftware>
					<instrumentControlSoftware version="7.0E 20130304">XPERT-PRO</instrumentControlSoftware>
					<instrumentID>0000000011142674</instrumentID>
				</source>
			</header>
			<dataPoints>
				<positions axis="2Theta" unit="deg">
					<startPosition>10.00346193</startPosition>
					<endPosition>129.99783297</endPosition>
				</positions>
				<positions axis="Omega" unit="deg">
					<startPosition>5.00173097</startPosition>
					<endPosition>64.99891648</endPosition>
				</positions>
				<positions axis="Phi" unit="deg">
					<commonPosition>0.00</commonPosition>
				</positions>
				<positions axis="Chi" unit="deg">
					<commonPosition>0.00</commonPosition>
				</positions>
				<positions axis="X" unit="mm">
					<commonPosition>0.00</commonPosition>
				</positions>
				<positions axis="Y" unit="mm">
					<commonPosition>0.00</commonPosition>
				</positions>
				<positions axis="Z" unit="mm">
					<commonPosition>9.100</commonPosition>
				</positions>
				<commonCountingTime unit="seconds">9.945</commonCountingTime>
				<counts 85 80 60 69 82 69 75 86 83 78 89 73 81 70 75 81 91 86 76 85 74 72 85 79 93 78 73 66 74 68 67 81 89 86 80 66 57 74 84 63 72 81 87 66 61 80 70 80 81 80 74 86 70 76 71 71 78 76 80 74 72 62 61 61 85 85 75 56 62 84 74 69 80 69 81 71 73 71 70 72 91 70 57 87 79 73 68 64 82 73 73 74 82 78 74 82 66 81 74 75 66 79 74 66 73 59 73 77 72 83 61 56 66 70 74 74 89 79 86 51 75 81 80 87 79 72 77 86 88 74 61 95 80 81 63 63 72 78 89 62 84 78 75 84 63 85 72 71 68 69 78 72 65 65 81 76 90 81 86 81 62 76 80 70 74 76 58 62 58 77 86 88 75 76 57 79 79 67 80 66 73 64 79 71 63 79 83 82 80 78 86 71 74 56 71 59 78 93 73 84 63 64 66 64 79 64 72 63 58 68 74 80 84 65 65 73 79 75 71 55 76 50 64 76 63 42 74 64 65 65 69 70 62 58 72 76 68 60 69 69 69 59 61 63 76 66 61 72 82 72 60 66 67 72 76 71 68 63 66 71 73 58 61 60 65 75 63 59 66 61 72 80 65 64 52 70 71 59 64 70 79 72 74 59 63 85 70 69 57 54 81 61 76 68 61 51 66 62 76 60 84 65 63 63 75 57 75 73 62 66 62 57 49 79 76 69 63 64 65 70 71 75 68 69 77 76 59 64 61 78 60 69 56 68 72 58 74 69 82 73 65 66 59 69 65 78 69 51 70 68 50 71 75 60 78 68 62 71 59 76 60 69 61 65 90 61 75 71 57 63 62 60 53 41 60 63 56 53 80 71 62 67 64 69 75 53 57 59 75 63 59 64 69 66 85 63 71 62 52 80 63 75 64 56 63 62 56 61 58 65 44 66 64 55 58 56 54 78 58 56 50 78 53 47 60 62 80 58 54 57 64 55 55 56 72 66 54 48 63 68 49 69 65 54 61 59 56 74 64 78 59 67 63 64 44 64 57 59 52 63 62 57 54 54 61 65 68 52 66 68 67 61 75 59 49 75 59 57 60 56 65 67 61 91 81 56 62 59 57 68 63 50 63 54 53 45 54 80 62 56 55 63 52 69 69 75 74 63 62 69 55 63 62 55 71 65 62 62 55 70 50 60 75 65 58 70 60 61 63 69 65 71 58 73 62 71 53 51 63 62 54 65 59 72 54 72 49 49 45 54 58 55 70 55 63 60 58 54 69 62 73 60 77 78 64 53 54 56 67 54 63 58 65 61 58 51 55 49 64 63 59 56 67 71 71 66 53 61 66 64 63 50 51 61 60 59 54 49 58 58 54 59 59 74 67 74 46 63 53 49 62 55 63 59 57 53 51 68 63 76 51 44 48 73 43 68 45 63 57 55 62 56 62 46 57 58 64 84 53 58 54 52 50 59 56 51 57 66 60 50 60 60 66 56 57 66 70 58 50 49 64 64 48 78 70 49 62 54 60 66 51 64 62 64 61 46 66 62 52 52 59 69 50 50 61 57 66 53 44 64 64 58 45 62 43 68 52 80 54 53 64 66 59 58 59 60 56 62 54 60 66 63 57 69 66 68 56 54 53 44 70 55 60 36 49 61 52 47 56 55 73 55 64 59 58 59 59 55 59 55 71 57 58 54 63 58 59 54 35 51 43 52 70 37 66 58 55 51 71 49 68 53 62 58 55 49 49 57 62 75 57 50 50 48 59 54 54 64 57 56 76 65 48 50 69 55 47 71 65 52 54 63 71 53 59 60 58 50 59 51 50 62 62 52 62 53 58 58 60 64 55 51 53 59 67 57 58 58 55 58 62 57 61 56 57 49 71 49 60 47 65 65 57 59 65 70 56 56 60 52 57 57 64 72 60 69 62 66 50 52 61 57 76 68 63 58 66 80 54 63 70 65 53 52 62 57 73 71 65 48 68 64 65 51 66 54 49 73 61 46 48 56 44 71 60 50 63 50 62 56 75 70 49 56 71 41 49 62 51 64 68 68 73 58 54 69 60 60 63 58 53 53 54 67 62 49 65 66 67 73 59 72 56 67 65 55 53 63 58 53 65 47 71 65 58 64 67 72 53 68 70 65 47 59 61 66 53 57 75 76 55 65 62 63 64 62 75 67 72 62 61 76 54 56 53 57 46 59 51 68 61 62 55 59 69 53 54 48 66 48 54 55 71 62 50 63 46 63 61 51 69 63 63 51 54 50 76 57 68 69 92 55 59 69 63 51 54 65 47 57 64 69 47 66 68 63 55 53 52 56 60 62 56 66 56 76 51 68 64 62 61 65 54 59 54 63 54 73 53 55 59 68 51 66 81 50 58 56 71 49 64 72 79 73 67 77 59 62 62 61 62 44 56 64 82 72 50 68 53 74 51 59 55 70 70 63 77 53 66 60 66 41 51 59 60 58 80 68 70 79 74 62 66 72 65 70 69 73 57 52 63 68 63 51 63 52 74 71 65 54 67 74 63 60 62 64 61 48 60 51 49 77 61 55 72 63 53 59 63 69 47 63 67 58 64 49 70 71 49 59 61 48 55 65 70 63 67 62 67 76 57 52 63 73 74 36 43 70 53 58 64 60 73 52 71 64 57 77 63 62 51 67 75 61 70 60 66 68 62 64 60 55 68 61 55 65 66 76 85 63 66 66 77 68 58 59 57 53 51 73 69 81 59 49 63 69 66 57 68 63 53 55 76 52 61 62 55 51 58 55 64 52 55 69 58 65 59 76 51 53 53 64 59 62 62 67 54 58 69 81 48 63 59 48 71 68 69 52 53 47 67 71 65 70 59 65 61 50 57 63 76 50 54 68 69 66 67 67 52 83 67 74 59 60 62 59 69 63 60 52 78 44 63 63 54 56 64 69 69 63 67 49 67 50 56 50 60 55 56 59 60 65 60 62 63 56 69 58 58 75 55 53 79 60 60 72 51 59 78 63 59 66 71 67 59 65 68 61 62 66 62 60 63 55 59 69 49 74 61 80 61 55 51 65 57 71 66 67 59 59 50 59 73 67 56 67 61 69 69 75 51 53 64 53 67 66 72 69 58 60 69 56 57 70 62 72 67 50 74 73 60 62 58 47 57 72 67 58 60 55 64 71 62 70 69 61 63 53 57 80 55 64 64 71 70 62 54 77 58 59 50 48 66 68 57 73 56 53 64 68 63 55 58 56 67 55 63 61 67 68 56 62 64 57 66 67 67 73 67 59 58 72 56 56 53 63 63 66 52 57 55 47 52 67 65 52 55 60 49 65 59 63 62 49 54 64 62 54 51 52 56 63 59 64 79 65 53 52 56 48 61 56 44 57 53 60 56 54 49 63 60 57 64 52 66 60 72 46 70 51 48 66 68 63 47 57 45 59 49 57 57 54 55 61 64 67 63 60 61 64 66 63 70 71 66 62 55 76 60 47 53 63 59 50 78 78 56 50 56 61 63 52 56 53 64 62 68 63 57 59 53 54 60 69 61 52 50 65 60 58 50 53 51 63 69 57 70 61 59 55 66 54 69 50 57 66 42 64 60 46 62 66 68 53 62 56 43 60 76 51 53 57 62 65 45 65 61 65 60 53 68 61 55 56 55 65 74 51 63 49 65 61 62 38 66 57 50 62 59 54 66 55 69 50 60 58 58 49 71 68 56 50 45 55 68 53 52 63 58 72 66 62 54 61 69 57 72 60 76 48 58 49 49 56 52 70 51 49 56 81 59 52 51 50 55 59 53 58 60 61 61 60 62 62 60 53 56 56 76 44 61 54 51 61 54 71 47 52 55 65 66 58 59 58 58 54 49 39 43 59 73 54 55 49 47 43 51 63 68 54 71 60 60 65 64 56 57 51 56 51 60 55 61 64 57 74 59 68 50 46 56 59 47 58 68 56 58 69 70 63 70 54 49 50 46 52 68 70 64 54 68 52 54 55 50 52 58 61 62 61 62 56 59 77 50 55 56 64 61 50 54 60 45 63 63 72 54 53 53 60 65 67 63 53 48 62 46 62 54 63 55 58 79 49 59 34 47 57 51 63 49 67 63 48 54 57 70 61 46 57 45 46 54 45 58 51 62 46 65 46 63 56 55 64 49 50 67 71 62 52 57 53 55 52 60 53 76 54 57 46 62 61 65 62 59 54 54 66 62 59 49 55 54 50 51 53 55 66 46 48 61 50 58 50 54 73 67 57 62 60 73 52 60 58 57 54 53 47 45 61 55 66 51 47 48 46 50 55 42 50 62 46 60 51 69 53 54 58 54 50 58 69 66 49 64 58 52 49 65 56 59 67 52 59 52 70 59 52 48 57 54 76 67 49 48 56 44 44 56 63 50 65 53 54 61 58 63 48 61 54 60 74 49 59 48 55 56 47 54 56 50 47 58 52 58 49 52 55 52 62 55 54 63 50 53 52 55 50 53 48 44 51 56 51 61 49 59 49 62 53 50 55 79 46 65 52 55 43 45 62 48 46 64 50 59 64 56 46 53 71 54 61 61 50 66 43 53 52 54 48 52 61 50 45 40 48 74 55 47 53 56 54 47 57 56 67 59 49 53 46 63 60 57 49 57 50 49 54 55 60 61 66 65 60 40 49 51 47 65 42 56 51 59 39 51 41 40 67 56 50 58 65 46 60 59 48 53 40 55 55 48 53 57 58 62 52 36 57 51 67 53 52 58 46 61 52 51 52 61 48 54 58 62 55 55 57 52 51 63 56 48 64 54 53 49 54 50 53 52 52 56 48 45 60 45 54 58 54 63 58 51 63 56 46 43 54 41 60 50 58 43 49 62 55 40 62 54 53 39 55 58 52 66 44 45 39 54 59 48 56 51 38 48 58 51 62 58 56 53 55 61 47 45 56 55 70 63 53 65 58 61 49 59 56 64 58 53 43 53 49 60 39 46 58 45 62 48 60 49 49 46 58 39 45 56 65 58 56 52 59 54 43 51 64 60 52 41 53 61 51 56 46 48 51 47 46 50 57 45 61 44 66 50 51 51 49 50 56 49 71 60 59 47 44 42 57 58 47 51 44 67 55 48 52 38 37 50 64 46 58 55 67 51 39 50 62 64 44 54 56 57 49 55 55 46 54 51 48 54 61 53 36 60 65 44 48 61 49 59 63 60 59 55 51 48 50 47 57 40 52 61 56 68 51 52 45 59 50 57 36 60 47 49 57 62 40 44 51 39 53 61 48 57 42 55 46 60 64 65 69 58 55 54 48 51 64 49 55 48 49 54 64 46 49 50 61 45 55 40 51 64 47 51 50 46 55 44 47 35 50 52 47 44 41 46 52 67 61 56 58 54 50 54 56 54 57 61 50 55 61 49 45 42 56 58 51 58 68 54 57 67 56 52 51 50 43 48 53 52 57 51 65 44 46 56 60 58 55 40 55 48 48 54 51 54 49 60 46 53 57 62 47 48 50 67 54 48 54 55 57 52 48 59 55 47 59 42 49 55 46 56 61 57 57 76 43 54 50 35 47 49 53 49 65 51 58 38 45 56 56 50 51 45 43 58 55 48 70 52 52 33 44 49 57 46 60 55 48 65 52 55 47 53 67 62 47 67 55 43 61 55 43 49 59 54 54 53 51 58 65 58 50 55 51 42 67 44 56 61 55 55 59 53 48 35 58 53 48 42 64 80 45 45 47 47 46 60 43 48 58 50 61 58 47 54 55 44 46 64 45 39 52 35 55 56 56 54 64 46 56 69 47 62 46 48 58 42 48 54 50 46 50 55 53 55 55 62 60 52 51 63 55 55 67 58 68 45 56 62 56 60 44 50 60 52 46 62 56 60 54 45 42 46 54 67 37 51 44 59 56 58 57 51 57 49 62 63 53 49 55 45 69 59 62 51 58 52 58 49 64 52 54 56 48 56 45 46 44 49 51 63 49 47 57 42 51 64 48 56 39 52 49 64 42 50 44 54 71 65 69 68 52 58 59 61 55 55 54 38 53 60 42 57 57 47 53 45 55 44 71 49 59 50 58 71 63 58 42 51 50 40 62 56 46 56 66 58 56 47 56 52 54 64 61 58 64 55 47 50 57 59 48 53 54 54 58 40 53 51 49 53 66 55 38 58 53 54 41 41 52 42 53 51 50 52 47 46 64 45 49 54 53 45 45 48 53 41 44 40 53 41 51 61 50 60 60 52 66 54 43 65 60 55 49 59 58 54 52 50 59 43 52 36 58 48 56 42 37 46 48 61 50 47 54 48 61 58 43 53 47 58 59 39 56 52 47 59 44 63 66 62 54 50 58 35 53 76 35 54 45 49 52 47 56 47 58 51 42 56 51 41 54 58 56 54 64 52 61 55 54 38 46 48 60 49 66 50 48 61 55 54 49 49 50 51 50 46 60 58 59 49 64 55 50 53 53 67 47 45 58 40 64 63 63 53 46 55 50 49 60 45 41 67 58 64 49 56 56 52 55 56 38 54 47 62 54 50 47 53 52 55 49 53 49 58 50 55 50 44 56 51 52 41 53 53 67 47 51 55 56 66 57 44 70 57 62 47 51 61 45 57 58 63 52 46 56 49 44 54 53 50 55 66 38 72 66 51 60 58 62 57 53 62 45 60 53 61 57 40 56 56 73 39 45 35 60 63 67 57 60 59 46 47 60 46 56 48 56 53 47 54 51 58 59 65 73 51 64 58 50 50 51 59 42 68 53 60 51 50 57 62 50 50 46 48 49 60 62 61 57 49 75 48 60 55 49 47 59 64 58 39 57 52 60 56 64 62 40 60 47 57 59 47 51 58 49 61 43 47 66 44 53 49 63 59 44 62 52 58 51 55 53 66 44 59 65 48 53 43 48 58 52 60 58 55 54 70 48 50 59 49 61 56 50 54 61 69 57 44 51 49 53 43 51 45 55 49 49 58 51 65 60 50 57 48 50 61 63 49 58 50 50 60 62 35 44 43 52 68 64 54 50 54 64 57 50 54 46 57 54 55 50 61 45 59 48 54 55 55 49 51 50 48 48 47 44 56 53 51 55 46 41 78 49 64 43 58 49 51 44 38 51 52 57 60 48 48 51 56 54 61 47 50 46 60 47 45 67 59 62 56 57 67 63 66 49 50 59 48 53 67 47 50 45 45 46 58 67 59 62 57 67 65 55 47 56 40 57 51 54 63 58 59 52 63 51 63 56 61 49 55 41 61 61 66 64 64 61 62 57 58 51 69 47 51 51 52 63 45 53 56 53 47 46 61 53 52 49 52 56 59 66 55 56 56 51 47 50 53 64 57 56 57 62 51 66 60 47 66 52 52 59 66 52 45 58 52 51 42 46 55 55 54 51 50 55 48 41 56 47 48 52 54 47 67 56 62 60 55 51 59 53 63 59 72 61 57 59 47 40 54 47 62 67 61 49 59 49 55 55 57 52 45 71 45 60 52 57 66 54 50 47 44 61 64 50 52 74 52 59 48 68 64 45 46 40 48 52 45 52 64 64 56 49 42 66 60 73 54 63 58 57 52 49 61 54 55 53 55 49 45 51 63 79 50 66 61 55 62 70 41 50 53 56 50 66 66 34 55 60 52 59 48 40 48 61 66 52 48 62 55 79 52 50 54 68 68 63 60 60 67 69 54 45 51 54 74 56 50 61 49 53 54 65 47 62 55 54 62 54 50 63 47 56 68 52 67 74 58 49 55 65 55 60 56 52 68 69 53 63 57 60 63 57 55 63 61 55 62 57 61 50 57 54 69 51 64 58 73 57 69 55 58 66 75 67 61 56 73 70 61 79 60 64 43 72 51 71 55 52 68 77 66 74 67 68 76 61 88 70 77 76 89 59 84 85 92 77 90 84 106 79 98 88 95 111 95 106 116 103 107 112 105 105 124 122 101 124 111 98 102 98 90 102 104 92 104 88 79 98 89 87 82 74 73 102 84 65 78 75 85 79 63 76 80 74 73 66 73 61 71 69 68 60 61 82 63 59 53 70 61 72 71 52 77 54 44 68 49 60 48 71 72 59 69 67 70 44 51 63 60 47 65 55 55 71 69 58 59 68 57 62 66 63 58 46 57 62 51 58 71 53 50 64 50 47 52 69 54 50 59 62 55 66 49 62 48 64 63 53 59 39 53 57 57 62 65 49 46 54 59 58 58 60 55 56 59 50 53 47 44 54 61 51 64 51 60 56 57 45 45 62 56 57 56 57 51 63 37 55 59 54 72 60 58 47 65 65 54 56 64 68 62 58 52 47 57 65 69 47 40 62 49 52 53 61 50 55 60 66 60 51 46 61 73 52 67 59 66 50 53 59 64 62 58 53 49 54 41 55 52 58 49 49 65 57 68 74 40 58 49 49 57 43 40 57 55 44 68 59 50 50 49 59 64 47 42 52 69 69 69 61 57 62 47 63 63 70 58 53 47 55 53 47 69 54 57 52 70 54 66 53 58 52 52 71 53 56 60 48 64 65 62 50 65 43 53 58 55 57 51 63 48 56 64 59 56 62 53 61 41 57 65 65 51 54 69 60 49 65 57 58 55 52 43 58 56 70 56 54 55 61 60 51 59 58 58 59 50 48 61 57 45 64 53 60 55 70 62 48 55 47 53 48 58 48 57 49 59 81 58 64 43 55 62 47 46 66 54 62 59 59 58 51 55 58 62 52 52 50 55 53 40 57 54 62 51 55 57 68 63 51 53 61 55 47 54 47 44 47 63 51 67 62 61 54 66 63 62 50 49 59 58 53 59 51 57 45 45 57 55 55 59 67 60 63 63 54 48 55 63 54 56 48 58 42 44 61 59 70 66 51 62 46 62 44 68 66 51 54 43 53 58 51 45 59 56 49 48 52 62 53 60 53 52 75 58 59 60 47 48 68 71 56 62 63 56 68 57 65 47 59 64 47 59 73 57 50 62 44 45 65 55 65 57 57 56 61 60 51 47 52 54 60 57 48 57 62 78 43 49 65 49 67 57 54 56 50 59 44 50 65 56 62 64 62 66 54 54 65 63 36 51 65 64 67 38 64 59 56 53 54 63 54 57 62 48 75 57 49 59 55 60 54 68 51 46 69 51 73 65 72 54 45 50 66 50 54 50 55 65 69 56 50 56 64 48 64 65 62 53 65 57 56 59 61 55 59 42 50 62 57 63 44 55 69 60 63 55 72 61 43 64 51 53 53 57 68 52 57 49 53 69 59 55 69 64 47 55 50 58 63 65 37 62 54 52 60 55 56 58 54 67 50 58 68 45 71 69 56 56 53 53 62 59 62 55 65 63 45 56 54 57 65 75 51 35 47 64 80 57 56 64 63 49 46 59 55 56 55 53 57 46 59 46 67 53 57 65 61 69 65 68 64 64 56 55 65 64 52 52 51 58 72 67 48 51 68 56 58 61 54 51 62 77 57 62 54 51 55 60 63 48 58 60 63 57 70 49 55 55 61 60 50 70 58 44 57 76 62 56 49 50 60 69 64 55 65 73 55 59 47 72 62 65 52 55 47 65 48 72 56 63 59 75 47 62 67 47 61 44 62 56 65 47 58 63 64 62 51 55 55 64 52 69 59 53 56 55 58 60 46 66 56 49 52 58 58 55 74 57 64 55 62 55 59 59 67 50 53 59 72 67 54 47 50 60 49 62 59 58 76 56 66 53 63 63 61 51 56 55 65 60 57 51 57 60 60 75 51 59 48 45 56 56 53 66 66 68 48 51 45 51 44 49 54 64 57 42 67 66 64 60 60 58 53 68 52 66 45 52 58 51 48 62 57 52 70 73 59 53 39 49 75 67 67 59 54 60 57 55 68 54 55 48 53 58 60 72 66 57 65 60 58 60 51 57 71 50 70 50 66 52 49 65 66 69 58 55 55 53 63 70 55 59 55 43 57 76 66 61 65 79 59 57 71 60 52 69 58 60 62 66 51 55 56 59 68 37 49 62 48 53 47 53 72 59 51 50 53 56 61 55 63 63 47 66 58 43 60 62 48 80 53 72 62 53 56 58 57 68 63 57 71 66 79 60 62 61 57 61 51 58 48 50 54 53 62 69 55 60 48 62 64 48 81 75 64 60 50 62 69 76 54 53 67 66 56 63 68 60 54 53 61 52 65 62 45 61 62 73 60 53 51 51 68 76 76 46 51 64 70 44 49 42 49 45 66 54 61 65 67 59 61 53 60 65 62 60 54 49 54 63 70 58 52 48 48 61 55 61 67 56 58 69 55 44 59 79 58 63 60 74 59 62 68 54 64 76 72 62 65 53 65 57 65 70 66 67 63 53 61 50 60 63 58 64 59 65 60 58 52 43 67 61 49 56 52 44 56 74 58 65 57 54 71 57 52 64 59 62 71 68 69 54 57 42 58 57 62 55 60 72 55 55 54 60 45 53 72 61 55 51 70 59 56 49 43 51 52 54 74 54 57 67 60 75 45 67 54 61 58 66 76 56 56 63 70 69 68 57 53 49 66 52 63 60 47 54 62 56 55 66 62 51 72 48 51 56 61 71 62 68 55 55 48 50 50 57 61 52 61 52 58 51 72 59 63 74 68 56 51 54 63 72 59 71 63 60 57 56 70 45 46 70 68 68 54 66 53 58 78 52 60 50 53 75 68 66 62 68 58 59 78 65 51 60 58 58 69 76 44 62 60 63 65 64 49 54 61 59 63 58 50 43 64 66 64 54 59 52 49 58 58 60 66 60 63 59 73 56 52 74 67 65 75 50 65 61 75 68 57 56 50 62 52 61 62 63 69 63 64 64 55 58 53 61 65 62 57 56 65 73 50 51 56 62 41 57 56 58 62 56 46 60 61 62 68 66 53 80 64 55 57 52 73 50 72 50 62 54 58 73 63 63 62 55 68 65 71 51 63 71 61 61 42 60 63 54 62 62 48 57 60 59 71 51 53 61 53 61 66 63 46 65 52 60 63 63 64 71 62 65 67 71 58 66 57 53 55 66 53 45 59 55 56 60 61 64 61 54 73 69 58 68 74 68 45 68 79 55 58 74 69 54 54 55 69 55 56 73 64 52 76 56 60 73 48 65 64 52 64 83 55 53 60 61 54 49 57 54 72 61 61 68 58 61 64 59 78 54 73 58 61 65 57 54 52 61 40 53 77 59 69 69 58 58 59 62 66 68 67 66 66 68 56 62 58 55 52 64 77 61 53 63 63 70 62 57 73 64 54 58 56 59 62 57 59 58 56 57 67 59 71 66 62 53 65 67 57 55 50 43 66 55 60 55 60 71 58 56 55 54 49 62 66 53 49 59 50 57 70 68 65 60 48 65 61 60 54 69 55 53 64 59 66 60 64 56 70 57 68 53 70 53 59 67 59 60 67 69 65 64 72 57 68 54 62 59 57 51 53 62 67 56 77 61 60 48 66 64 56 65 74 69 66 70 58 51 59 70 57 56 75 55 59 74 60 62 66 52 47 60 55 55 57 54 67 47 47 47 68 69 62 61 51 67 68 79 58 47 62 65 70 48 58 55 73 69 65 45 57 64 69 55 69 40 55 61 49 62 59 50 48 56 67 58 62 50 65 44 53 54 63 45 69 63 62 56 53 72 57 85 69 58 54 44 63 57 82 57 66 61 61 59 64 53 52 64 85 44 52 58 51 56 68 61 53 65 67 60 70 64 56 71 58 52 68 58 39 60 63 60 58 59 63 66 50 65 63 59 66 51 56 65 74 69 68 62 70 56 70 51 70 63 64 77 71 66 69 50 62 49 62 68 69 55 60 64 68 59 67 56 56 56 60 69 78 59 58 55 51 49 50 79 56 60 55 71 76 58 56 55 71 70 48 69 62 66 59 66 68 61 72 51 60 51 66 50 47 57 58 74 59 64 60 51 75 63 62 51 63 65 82 74 67 65 58 63 63 56 55 72 73 77 75 70 54 55 70 60 61 68 66 67 66 61 52 63 62 57 61 54 51 65 69 52 57 56 71 75 79 74 71 54 74 52 58 60 65 49 63 64 63 69 66 52 59 74 63 47 49 68 57 58 51 54 45 63 52 60 57 60 63 73 62 60 70 63 68 54 63 69 72 61 66 64 77 53 66 78 68 71 69 60 56 52 68 69 57 55 51 54 62 63 65 64 52 62 63 64 61 59 67 53 64 77 66 55 58 47 55 53 59 51 55 77 62 60 62 72 71 55 58 80 69 73 67 70 53 50 51 68 54 60 42 62 68 50 72 58 50 73 75 60 53 61 55 62 65 86 68 61 74 51 65 57 49 63 66 68 60 55 64 69 71 81 62 64 60 59 60 69 56 47 66 66 59 73 68 59 56 66 70 59 71 68 59 60 71 67 51 63 72 54 60 56 69 77 81 59 82 52 63 62 63 76 62 68 79 61 69 57 61 69 56 78 59 71 67 62 70 45 65 69 54 71 63 72 61 61 58 64 56 83 70 83 59 58 69 67 70 58 64 67 71 64 68 59 68 63 60 62 74 73 60 61 63 66 73 67 79 76 60 56 58 44 66 70 75 79 60 57 68 63 59 60 75 55 72 54 59 62 84 60 73 59 79 81 68 75 57 63 66 81 67 82 67 76 64 70 61 92 55 76 74 65 61 63 51 66 61 74 47 71 61 61 61 60 72 73 68 52 66 61 69 58 66 77 75 58 54 62 63 72 60 60 68 61 69 74 63 67 61 68 67 71 59 60 60 64 64 57 61 62 62 70 68 57 49 60 74 66 60 51 62 60 57 55 57 69 79 65 65 64 50 56 71 59 62 73 53 57 58 71 60 65 69 54 70 71 59 61 61 67 70 77 57 63 60 65 69 72 62 59 69 54 61 57 57 49 77 67 78 70 79 64 72 74 69 59 73 67 68 81 72 61 65 64 53 64 77 77 69 54 59 74 65 65 58 69 64 57 62 50 56 71 72 52 75 64 65 70 51 57 51 61 61 63 69 54 55 70 71 71 60 58 63 59 68 61 85 72 59 61 54 60 79 67 62 65 52 73 48 48 65 62 65 80 57 56 71 69 54 66 64 63 79 79 68 53 51 69 72 69 72 76 58 67 66 68 56 52 69 57 63 66 65 67 67 70 68 73 63 68 64 80 76 59 60 64 60 52 74 66 71 63 75 72 62 50 59 65 60 63 61 62 58 61 67 74 61 59 69 70 78 76 71 68 70 58 52 72 60 62 52 67 64 62 63 67 51 61 58 55 76 72 70 77 69 61 56 76 51 63 78 65 80 63 80 67 66 70 76 55 63 69 57 56 50 49 59 59 67 59 57 73 55 53 54 65 84 65 60 59 72 63 71 69 62 61 48 71 62 65 60 72 60 66 56 67 64 59 71 63 71 77 67 67 79 57 60 56 57 64 70 57 71 55 64 51 64 74 72 70 60 73 68 67 71 60 58 61 88 49 66 58 48 72 64 77 50 67 51 65 58 62 64 71 73 78 55 61 60 61 54 62 69 73 60 70 50 64 65 63 60 71 54 71 54 73 52 50 56 73 60 63 52 63 77 68 49 70 72 48 67 66 73 69 53 59 78 59 60 71 53 74 69 63 56 61 62 83 49 67 71 67 57 63 57 62 59 70 70 56 60 71 57 53 68 67 50 71 55 66 67 59 65 59 60 55 60 70 57 63 72 67 81 73 58 61 64 60 43 56 52 61 76 54 74 59 56 61 55 79 69 63 49 69 63 56 65 76 71 73 54 61 64 68 63 75 45 73 58 60 58 52 64 54 80 68 67 70 67 63 54 78 78 59 70 55 70 61 58 75 52 61 57 58 67 69 65 56 77 79 66 55 70 62 59 70 64 64 55 56 65 58 67 59 67 68 56 77 67 66 75 56 62 61 73 62 65 64 67 61 55 54 61 73 53 61 64 59 51 74 64 68 61 66 64 64 54 66 70 55 81 62 63 77 64 55 57 71 65 51 61 56 68 56 48 54 71 68 57 70 63 72 68 64 67 48 72 71 60 68 58 83 64 68 66 48 66 73 66 61 59 73 64 72 48 63 73 70 79 61 62 61 78 79 61 55 65 65 73 66 64 55 65 73 64 64 74 59 66 61 61 69 64 62 62 48 58 64 60 69 78 50 60 78 63 55 74 61 65 68 69 51 56 55 73 54 65 63 57 78 54 69 58 69 66 66 60 59 64 59 83 53 66 67 73 64 80 75 72 66 56 62 67 51 57 70 66 53 64 59 67 68 62 54 55 62 77 80 50 66 62 58 63 63 59 65 56 63 54 43 52 61 54 62 73 68 51 65 60 65 75 60 66 64 59 69 59 67 57 57 79 60 58 60 72 52 64 48 71 38 68 52 60 58 62 70 76 74 57 64 72 76 63 71 62 66 72 69 77 66 76 53 62 66 63 77 66 67 77 63 75 68 70 48 72 57 65 68 58 52 65 62 66 67 61 60 65 72 57 72 59 65 70 78 76 67 69 64 65 61 63 81 54 67 60 57 59 53 56 67 70 69 50 68 65 59 76 70 66 62 54 66 63 59 78 65 73 43 50 61 47 65 64 49 64 68 60 56 61 67 64 59 61 73 83 61 68 52 61 69 52 67 62 69 65 74 73 54 48 53 63 52 59 50 61 59 57 87 55 71 60 76 66 68 74 60 70 72 73 61 63 61 64 69 65 58 63 63 67 62 75 69 60 54 65 60 68 60 53 72 66 63 74 59 52 77 63 68 54 60 53 71 69 66 68 80 82 63 61 57 85 71 75 80 65 59 60 56 53 61 68 67 73 66 76 67 55 66 71 69 48 63 66 73 63 56 72 73 50 64 81 72 64 44 59 43 72 76 63 69 62 55 72 69 65 64 59 50 90 59 73 62 57 57 71 62 65 71 54 64 59 53 54 52 55 62 61 72 56 72 68 72 66 78 59 78 75 55 52 62 85 57 76 60 69 68 64 53 58 50 81 64 72 58 63 61 67 62 66 61 63 57 83 61 75 71 79 66 66 56 68 80 70 57 64 69 60 61 61 50 64 64 69 69 57 67 71 66 72 55 52 58 51 60 58 76 53 56 57 69 60 58 71 74 72 57 70 45 69 59 61 62 88 61 71 53 54 81 57 74 80 86 56 64 80 70 57 71 58 69 75 69 63 70 67 53 76 57 68 59 43 62 60 59 65 72 62 69 67 55 60 67 77 55 69 59 59 61 60 60 76 57 64 82 69 71 64 63 66 63 81 62 74 68 61 71 78 67 68 49 65 59 60 59 59 65 65 57 69 78 74 69 70 58 70 67 70 71 65 56 58 72 62 73 73 75 63 62 63 56 70 63 85 75 56 63 72 67 60 75 66 57 58 66 68 76 73 77 61 57 71 67 60 61 51 62 70 51 64 66 63 81 78 64 69 67 58 60 61 68 61 70 67 80 48 62 70 71 56 64 55 49 68 71 51 57 73 70 80 74 70 66 72 60 73 51 61 64 51 62 62 68 53 67 55 65 52 60 64 60 54 59 62 61 72 77 56 56 62 61 52 71 82 54 49 66 66 61 63 60 62 59 70 57 59 55 53 64 62 61 60 55 63 67 59 58 66 61 67 75 65 64 69 65 50 70 54 68 65 61 64 57 54 63 54 61 71 78 65 64 56 63 69 61 56 66 51 64 69 66 48 57 56 78 70 75 68 60 72 62 80 66 58 61 66 59 54 51 53 72 61 65 71 71 60 74 74 68 47 64 61 64 67 69 54 68 72 73 62 55 62 71 68 63 71 57 74 49 83 47 63 72 68 67 60 69 60 57 50 81 69 74 66 60 65 64 56 51 74 69 51 67 61 67 51 63 60 76 66 88 64 66 68 54 48 61 67 51 60 57 59 70 62 68 49 54 65 68 58 69 72 66 63 58 58 58 68 51 80 53 76 81 65 55 65 57 60 66 77 68 57 72 70 64 71 65 54 60 71 53 60 59 67 63 57 68 47 57 63 67 55 56 64 52 63 68 65 76 75 56 70 72 55 59 65 78 53 67 70 53 64 54 77 68 58 66 57 54 57 85 66 70 75 61 72 56 64 47 66 59 66 60 55 65 53 64 70 64 64 53 64 57 62 61 74 64 54 78 69 74 61 60 60 65 55 50 67 69 64 60 66 62 60 50 68 68 66 66 77 63 88 66 75 66 55 72 71 60 69 80 68 65 55 71 60 51 58 61 60 65 79 64 66 78 64 58 58 62 62 70 82 73 65 64 64 62 57 48 61 79 63 66 73 64 57 59 65 61 61 81 65 60 62 66 60 64 71 69 48 55 64 78 57 69 57 73 76 63 68 76 60 68 78 57 62 75 53 70 68 61 62 75 43 66 63 69 66 65 71 61 74 74 65 73 69 68 70 65 85 59 57 83 62 55 65 57 55 74 65 73 60 70 50 74 73 63 62 64 64 68 68 74 61 80 67 67 79 61 61 52 71 60 77 63 63 72 59 69 77 78 56 71 67 64 60 85 80 68 73 68 73 69 72 68 72 73 82 78 74 67 78 50 69 75 62 71 71 77 77 66 71 70 73 74 78 68 74 57 58 64 80 63 77 63 65 61 77 72 62 67 68 74 68 74 71 64 63 71 68 85 72 81 74 71 70 63 71 86 67 59 83 80 71 77 55 74 60 75 65 71 81 79 54 73 77 69 76 88 67 64 62 69 83 69 72 75 63 70 80 74 66 57 62 60 80 64 71 68 65 74 69 60 76 60 82 74 49 69 79 61 73 54 84 65 61 68 67 63 72 70 84 42 45 48 68 59 65 66 67 68 52 77 73 68 70 79 69 48 61 57 48 64 75 69 74 81 62 50 60 60 81 71 62 71 70 63 79 68 66 63 61 67 64 46 66 62 65 63 68 76 49 70 62 66 75 66 62 56 63 63 74 67 68 64 57 66 68 91 74 63 60 56 61 63 69 73 60 62 65 66 58 67 67 56 72 60 62 58 56 59 68 54 79 59 67 64 66 70 53 66 67 49 59 76 65 70 66 53 46 59 60 63 53 60 53 78 71 61 77 54 56 69 63 59 65 55 55 72 56 66 68 56 68 65 57 56 61 40 58 69 56 64 74 47 72 66 56 73 70 80 72 61 76 56 63 59 47 53 68 71 74 59 72 74 48 62 65 57 64 64 65 58 68 72 75 58 60 74 75 66 68 70 69 66 53 65 65 71 81 60 57 86 62 73 56 64 67 62 67 47 72 82 58 59 62 71 72 69 57 79 63 68 63 71 67 68 64 61 74 58 66 66 56 59 56 68 45 50 64 70 72 55 65 61 44 63 72 52 63 72 54 76 59 56 70 70 48 60 69 74 66 66 65 65 70 69 59 50 64 59 74 70 56 73 60 69 70 85 46 50 62 62 63 72 53 77 58 60 65 73 55 61 75 52 65 54 72 69 60 63 67 65 54 73 69 65 69 63 56 75 81 66 60 79 74 57 47 61 72 70 66 54 51 73 69 63 80 60 61 74 60 57 60 60 56 73 76 51 61 54 72 72 55 62 67 56 67 58 61 52 64 49 52 56 54 65 71 57 59 53 48 58 65 73 81 53 70 59 71 58 61 62 64 74 59 65 57 82 53 61 66 59 60 69 59 76 58 69 63 54 56 57 61 56 61 68 63 63 67 55 86 64 44 67 54 66 76 63 57 65 70 66 50 62 60 77 49 65 68 62 58 67 69 79 64 71 63 62 75 51 64 62 54 60 64 79 64 66 60 55 53 62 68 69 76 73 67 75 62 76 46 50 78 65 64 63 73 56 59 46 53 53 65 58 58 68 68 46 61 54 67 65 79 57 62 56 72 68 54 74 70 75 61 57 59 70 49 58 62 71 44 59 47 59 70 58 58 44 66 71 47 67 56 67 49 56 60 74 50 66 80 57 63 63 66 57 57 56 55 79 48 59 65 59 72 70 56 73 52 64 61 66 53 45 61 60 57 71 66 53 75 69 66 66 55 43 67 63 58 68 59 72 70 75 50 71 64 45 54 67 69 67 52 52 86 63 73 62 59 76 67 58 75 58 69 62 55 62 75 59 56 63 74 66 57 73 72 71 70 69 62 66 70 69 61 64 48 65 49 48 49 64 55 61 65 66 54 54 71 56 69 57 62 60 57 76 70 51 59 57 57 68 50 69 54 58 57 64 62 60 61 70 66 55 59 69 67 49 64 68 71 55 67 64 60 66 64 64 67 62 67 56 49 72 55 62 71 60 62 58 69 72 60 60 62 63 53 61 58 61 64 60 71 61 60 50 56 81 52 68 71 62 62 61 61 62 64 49 68 61 68 55 51 59 71 62 62 44 52 61 57 46 57 61 64 71 59 64 62 58 66 63 63 56 57 68 74 74 57 63 67 56 62 59 61 61 76 63 68 64 58 61 64 69 65 60 76 70 56 76 52 56 51 57 54 75 60 60 52 52 62 48 65 67 44 43 65 56 61 72 56 68 82 66 64 57 45 63 60 76 68 63 63 56 64 69 70 64 68 66 51 64 79 62 56 67 67 68 70 81 54 65 63 79 69 69 73 63 77 58 61 66 55 59 75 72 70 53 58 58 69 65 62 49 53 59 66 68 58 54 60 62 57 65 67 59 67 53 50 74 62 48 56 78 56 56 56 60 78 71 54 69 68 57 53 64 61 76 56 55 60 59 79 52 72 46 79 59 68 60 59 64 50 49 72 64 60 51 65 65 62 60 55 65 78 71 76 59 67 71 68 60 64 51 69 65 59 67 63 72 48 60 70 57 63 72 63 68 59 56 72 64 66 73 72 62 78 64 60 49 72 60 57 53 52 66 70 65 78 51 57 40 76 72 66 52 73 64 58 64 64 43 48 73 60 69 65 51 76 58 57 60 59 61 68 59 64 57 65 49 54 58 58 90 49 58 65 62 61 59 70 59 52 47 62 51 50 69 57 54 74 60 63 65 64 63 52 64 72 54 61 81 51 62 57 64 58 65 50 66 60 58 71 67 65 72 72 73 56 67 59 69 71 47 68 58 64 63 71 77 46 67 55 75 64 73 73 66 61 67 64 74 62 73 71 74 64 61 62 80 57 67 62 63 78 61 56 60 73 42 71 64 57 49 81 59 72 68 64 67 59 67 64 58 55 59 50 64 56 56 63 63 64 62 62 70 61 69 53 59 54 59 68 59 61 71 64 64 54 71 50 58 66 50 69 61 65 61 58 69 73 42 73 57 58 70 55 63 62 59 46 72 68 73 62 57 48 66 69 58 55 45 55 59 79 53 68 64 54 55 59 61 50 60 64 52 62 62 64 68 75 55 78 58 56 56 70 72 65 70 62 72 57 59 65 76 54 72 61 40 71 66 66 52 72 71 61 75 72 63 63 73 66 72 62 68 58 64 56 79 66 65 66 72 66 61 60 73 49 57 60 56 62 63 58 50 62 58 54 79 58 59 59 55 76 65 59 69 59 53 69 74 53 76 80 74 60 67 70 46 68 64 72 58 59 58 62 69 68 80 57 46 69 58 68 67 57 79 56 52 57 63 65 72 60 74 54 67 60 57 66 69 50 61 66 66 62 73 65 56 54 77 56 78 53 54 57 63 72 56 57 63 75 57 64 57 56 56 56 62 68 58 74 55 63 63 61 61 60 65 59 61 70 72 64 70 70 68 50 64 57 54 65 67 70 75 64 66 64 60 53 54 70 50 74 62 66 40 58 63 59 70 64 65 50 64 59 53 74 66 66 56 69 70 54 54 63 72 58 62 62 69 55 53 54 78 81 61 68 72 74 61 59 57 49 63 52 57 70 69 63 61 58 68 72 52 46 61 64 69 67 75 61 70 54 52 58 66 63 71 79 65 69 65 58 66 77 67 80 63 60 73 60 56 53 64 72 67 53 59 53 60 56 63 76 62 71 55 43 58 56 60 78 61 55 65 63 60 67 69 62 62 65 67 58 56 62 63 62 81 51 62 68 63 78 50 59 50 67 57 56 61 67 69 84 58 72 61 48 63 62 56 73 56 66 61 51 62 63 78 58 49 77 69 55 76 70 48 54 46 50 59 68 68 72 74 63 63 66 50 62 61 61 58 56 56 47 64 61 59 61 57 63 80 65 54 67 65 53 93 53 71 68 56 69 53 73 78 72 72 72 53 67 60 68 63 76 53 59 57 60 64 55 65 67 84 64 66 58 52 71 66 65 67 59 75 59 60 43 60 68 59 73 60 68 69 57 56 60 72 53 72 69 54 64 53 60 74 59 63 60 64 59 55 60 59 61 46 63 62 71 65 64 59 53 64 70 56 56 67 56 81 63 59 59 64 68 63 70 65 39 56 66 51 55 79 73 67 49 65 58 78 55 72 58 57 60 57 57 63 50 67 77 78 62 55 65 80 66 51 63 67 66 75 71 59 65 68 61 67 54 70 53 59 75 49 77 57 64 50 64 66 50 56 81 53 68 72 61 59 71 62 64 70 61 65 55 68 61 60 53 59 54 57 63 69 58 63 64 58 59 61 62 65 52 68 56 64 64 62 62 66 71 74 78 60 66 66 61 75 51 62 70 65 72 72 49 60 69 86 59 53 71 60 65 49 69 57 59 55 68 61 57 60 62 66 60 50 53 64 63 70 69 79 59 71 53 48 53 74 63 64 65 61 74 62 48 58 64 59 74 56 68 72 84 64 51 65 65 58 73 72 66 72 60 61 58 63 61 65 60 63 68 66 67 64 61 49 55 74 68 59 82 58 51 44 54 64 55 50 64 64 63 48 58 61 60 62 61 63 70 64 78 59 62 54 64 66 62 69 70 56 59 58 66 70 74 70 74 68 64 61 69 69 71 68 49 58 73 51 50 67 69 75 73 62 62 56 77 54 74 60 67 52 69 63 55 54 70 70 63 63 54 59 42 80 57 66 75 61 63 75 82 52 56 68 68 62 64 52 66 57 73 57 60 62 49 58 62 53 64 63 60 56 60 64 60 70 51 60 83 59 67 57 64 66 78 59 68 81 56 64 68 54 80 60 65 63 54 59 63 70 70 62 57 61 54 61 58 75 65 60 73 67 46 71 57 75 65 59 70 69 48 57 59 59 61 61 65 75 56 59 48 52 67 80 66 63 73 64 81 55 66 65 62 58 57 64 53 64 52 64 69 66 72 64 65 65 68 74 56 66 58 68 56 55 61 69 62 65 68 66 53 64 56 68 55 57 63 52 59 61 64 61 59 65 45 60 68 80 77 44 75 55 56 68 73 59 65 73 57 57 62 70 49 72 66 60 58 61 59 74 50 52 63 52 69 58 62 65 62 61 66 49 52 54 59 72 51 48 65 67 74 56 67 60 52 67 66 59 76 65 58 69 56 56 59 67 59 75 63 77 68 68 59 68 69 57 61 65 63 46 59 68 73 64 52 51 63 56 64 54 70 65 75 61 78 77 67 63 73 60 57 65 65 52 72 64 72 54 66 61 55 55 81 60 60 63 77 65 58 50 53 63 57 60 67 63 65 55 58 59 71 69 78 70 49 64 58 73 54 64 68 69 75 72 64 62 78 73 59 64 64 82 56 66 53 52 59 68 52 65 70 66 65 50 49 60 63 72 61 66 52 45 67 92 60 58 61 57 58 65 64 71 70 58 77 60 63 64 60 54 65 78 65 59 70 72 61 50 58 58 72 63 74 68 60 65 68 70 61 55 79 72 68 65 68 74 53 71 72 72 70 66 69 66 66 69 61 67 73 60 71 53 67 69 71 59 59 71 61 70 56 55 53 65 66 61 60 62 63 60 53 61 66 65 71 67 64 59 73 78 71 77 60 73 56 62 71 64 73 69 62 66 57 57 52 54 44 54 68 67 79 68 62 55 53 68 56 61 65 66 57 61 59 68 63 61 61 68 56 72 53 60 69 57 63 74 72 63 59 57 55 56 50 60 57 58 65 54 55 59 60 61 76 62 58 62 59 73 60 62 67 53 74 57 62 55 63 57 62 51 61 63 60 65 67 67 52 68 73 70 64 60 64 63 62 56 75 73 60 57 70 66 53 70 63 70 73 58 67 67 64 59 61 69 66 49 56 62 79 58 61 52 88 60 50 49 65 56 66 66 59 55 56 74 59 60 75 70 69 59 62 45 45 72 50 61 53 67 52 61 70 78 59 55 70 61 55 79 64 66 58 62 73 56 67 62 59 63 55 59 67 57 60 51 72 54 68 66 65 52 56 67 73 65 65 64 66 57 57 53 66 53 65 41 56 52 65 57 82 53 59 52 49 56 71 55 62 53 59 53 67 54 55 61 58 63 64 72 66 72 53 63 61 78 58 61 72 52 70 58 61 60 41 71 65 69 72 67 59 59 56 48 66 59 57 59 57 74 52 61 70 77 56 67 55 56 75 46 54 58 52 69 51 49 56 68 65 78 63 60 70 63 48 55 64 72 65 51 58 60 61 73 49 67 65 64 46 64 74 65 75 61 76 53 66 65 84 68 58 61 64 69 72 62 57 51 78 63 57 64 62 68 58 71 63 49 68 64 54 61 65 51 65 76 66 60 60 67 63 62 50 48 69 61 58 68 70 64 62 56 53 57 62 60 56 64 62 71 77 63 58 60 72 57 68 69 59 65 57 74 73 84 63 57 72 65 40 64 52 65 56 66 66 67 58 45 57 72 66 68 66 60 66 62 73 62 67 62 66 61 62 60 64 53 66 56 70 69 56 53 64 71 51 52 63 56 73 57 63 59 69 68 76 60 58 57 74 74 72 68 68 50 63 66 72 75 63 72 72 69 67 57 61 72 54 73 61 56 65 62 69 69 95 71 61 62 64 59 58 57 63 60 72 75 55 59 60 62 71 68 67 62 57 55 68 72 70 54 67 75 50 67 67 61 68 65 55 63 54 73 50 73 57 61 67 64 82 48 77 76 51 54 57 64 60 67 69 58 60 56 63 58 62 60 69 70 53 70 68 75 51 58 46 59 69 62 74 60 58 64 68 69 65 55 57 59 58 55 56 56 85 62 64 57 63 63 63 55 58 60 57 61 83 56 66 62 72 65 53 56 63 70 73 73 59 60 62 55 67 64 59 63 61 71 62 47 68 68 56 66 60 61 62 62 66 51 61 57 54 68 61 54 68 64 67 66 62 77 54 64 71 65 68 60 57 67 59 69 54 65 60 61 74 58 46 61 76 58 56 67 67 53 56 65 60 54 65 65 59 63 60 49 58 64 80 66 64 60 64 63 66 71 58 63 47 56 56 62 57 63 64 57 65 65 54 61 70 76 80 47 67 73 69 68 60 73 58 64 43 79 57 75 56 58 60 64 62 56 67 58 70 59 61 79 54 79 70 65 62 44 56 65 60 73 55 68 61 59 66 62 60 78 52 72 59 61 60 61 66 65 70 61 66 52 66 60 61 64 60 70 49 49 61 54 51 70 62 70 57 63 59 53 53 63 77 68 54 53 57 65 61 60 53 67 83 49 68 48 51 59 58 56 63 52 68 51 69 61 51 59 50 68 53 48 55 68 71 66 68 82 62 67 54 66 62 69 61 59 70 58 73 70 56 76 54 64 57 69 52 78 66 65 68 59 58 60 71 59 65 54 75 63 82 64 70 84 71 61 68 64 64 53 62 64 62 65 70 66 78 75 56 52 67 58 59 55 62 66 56 76 72 69 80 54 69 79 59 47 55 50 57 62 71 64 58 70 55 69 58 62 53 62 70 74 67 65 63 58 66 53 54 59 62 64 68 80 75 45 67 62 74 52 40 54 69 57 62 52 78 39 71 62 66 67 65 74 71 67 60 55 92 58 58 72 73 59 61 50 59 68 56 65 63 65 55 61 61 54 48 62 66 53 61 62 68 75 52 72 45 57 63 64 59 65 66 61 75 70 75 60 70 55 73 67 60 64 67 53 63 61 72 58 57 76 82 59 68 67 61 68 51 66 74 72 62 69 62 74 75 59 68 70 56 66 69 67 73 64 65 68 74 58 54 72 62 68 56 57 72 75 60 55 64 50 72 77 64 57 62 73 61 63 50 75 62 71 61 48 68 66 80 76 57 48 67 67 61 72 61 71 82 64 74 57 63 56 74 63 66 70 62 62 54 55 47 61 72 67 68 72 50 63 60 69 65 61 63 56 72 72 61 68 76 67 86 61 60 56 59 67 76 71 68 72 67 60 65 61 61 70 59 72 67 67 55 46 58 59 74 74 61 67 62 62 69 66 69 63 44 54 73 64 69 52 70 82 72 63 67 74 55 67 72 75 62 94 65 67 60 62 68 59 80 77 75 77 66 72 63 68 77 72 69 65 62 68 79 53 58 45 86 63 67 64 64 61 65 72 71 62 70 63 73 65 62 84 84 66 69 64 67 62 80 69 60 58 76 74 64 75 69 72 73 74 67 83 67 77 58 58 69 64 56 71 52 58 59 67 72 68 66 79 65 76 62 65 70 66 70 61 78 65 74 80 61 55 65 64 70 64 65 66 69 73 52 76 60 73 75 73 60 62 54 61 74 67 65 70 75 68 64 91 78 75 85 73 85 65 85 76 65 61 64 62 79 70 76 72 80 59 61 59 83 57 65 67 61 66 68 71 50 66 64 77 81 75 63 70 48 65 76 65 58 70 78 63 56 65 74 59 79 56 44 60 69 54 63 57 61 66 75 66 62 71 79 58 70 67 69 73 81 76 67 63 74 61 64 70 72 74 61 68 62 64 64 73 49 62 64 74 71 66 51 56 75 48 70 75 74 65 72 71 50 63 82 70 61 61 63 58 66 59 66 57 63 48 74 61 63 65 69 59 63 71 62 60 60 75 75 66 72 64 56 58 67 66 64 66 63 58 73 54 72 53 62 70 60 63 48 57 70 69 69 63 59 76 67 64 68 77 64 77 68 66 62 69 73 72 61 57 55 69 60 62 68 61 60 80 67 77 64 73 73 68 75 72 68 60 54 49 61 56 84 73 64 57 63 57 65 50 65 47 71 52 64 56 67 69 62 64 64 85 59 73 72 53 74 81 63 68 68 66 53 69 56 69 67 72 55 59 81 60 68 60 61 64 63 83 79 59 65 68 63 68 56 51 72 61 54 62 54 52 81 55 63 82 90 66 64 67 68 72 61 70 68 86 70 61 78 66 64 64 92 71 75 64 61 57 64 64 52 77 67 70 66 55 77 67 78 66 62 60 60 73 61 63 52 65 60 65 74 63 53 75 57 61 59 63 78 70 51 68 68 61 49 81 57 72 82 55 75 58 77 61 65 62 70 70 53 69 60 53 58 65 66 64 61 66 51 73 78 73 66 61 70 69 74 64 63 65 65 68 58 52 68 65 65 59 61 57 71 64 58 59 77 51 66 61 65 74 53 56 68 68 59 74 63 90 66 65 68 63 68 74 57 62 81 70 65 63 64 60 78 65 56 68 66 67 64 83 66 64 71 46 75 60 62 67 60 65 61 65 71 68 73 47 56 61 65 62 59 49 62 60 69 66 64 59 59 70 68 57 80 62 65 57 51 56 57 71 67 72 44 71 55 65 60 64 52 62 62 76 67 84 68 57 45 64 72 74 51 56 75 75 73 75 62 56 70 60 70 60 64 74 52 61 73 63 65 72 72 65 68 68 75 71 55 64 65 62 65 66 59 58 69 65 63 53 54 61 59 62 65 66 55 60 60 62 60 69 72 40 68 72 60 65 62 60 57 70 76 59 66 72 76 57 58 61 51 63 52 64 55 72 66 54 57 54 61 62 63 66 70 70 59 58 69 68 73 50 62 69 69 74 69 60 73 61 63 63 67 65 65 53 60 61 54 69 65 80 67 43 61 60 64 60 84 68 60 60 68 62 57 64 52 71 70 70 64 67 67 61 72 60 64 74 80 62 65 67 72 69 58 65 68 57 62 75 66 62 52 59 64 58 55 73 55 68 55 72 54 65 71 68 68 62 65 78 65 65 50 66 63 51 56 59 63 65 77 66 81 46 80 73 66 59 73 78 60 86 65 71 60 59 53 67 60 65 63 60 57 60 66 43 59 66 64 75 70 73 70 63 53 67 45 54 68 72 60 68 68 65 68 56 50 79 72 47 49 67 73 71 58 67 64 58 54 57 71 69 63 54 65 57 55 54 52 64 54 72 85 57 57 70 63 76 54 55 62 58 63 76 72 63 77 63 42 53 63 68 59 77 79 74 75 71 58 69 68 81 64 68 71 51 42 70 68 70 65 73 72 61 53 69 59 64 73 81 69 60 53 69 62 70 68 60 79 76 52 83 61 71 78 73 69 79 61 53 69 59 59 61 57 87 76 65 61 69 48 61 58 66 72 63 68 65 62 53 59 61 59 61 78 76 67 76 76 65 71 56 70 57 71 70 57 66 65 55 61 69 61 54 63 74 66 78 67 56 70 61 68 59 73 66 43 55 68 61 59 64 72 57 65 61 63 62 64 67 64 58 62 49 65 65 77 58 57 54 58 74 56 59 58 66 73 62 75 66 85 82 70 59 60 59 64 65 70 66 80 57 65 60 53 62 78 46 65 66 54 59 70 71 61 58 73 73 70 74 60 72 72 57 64 59 55 62 57 62 63 46 65 73 77 68 65 55 61 73 83 68 74 65 75 47 70 77 53 73 66 73 65 75 60 54 51 68 55 64 66 74 78 63 64 67 68 65 74 71 54 54 63 69 66 74 62 67 54 76 62 61 76 59 74 62 67 86 53 58 65 62 59 71 73 70 66 51 56 62 57 63 72 70 55 67 55 62 66 58 57 70 61 64 55 57 74 73 73 67 66 65 69 70 56 66 51 76 53 65 67 72 70 70 67 70 62 79 76 61 54 59 75 60 63 65 63 52 70 70 73 61 40 62 80 77 61 89 70 70 59 79 66 60 83 71 71 64 78 73 72 76 64 45 78 71 83 70 65 69 57 59 62 71 78 64 65 60 66 63 67 67 67 68 76 62 73 66 65 54 71 61 54 68 73 55 65 64 66 56 46 57 64 57 53 58 69 55 79 61 52 66 59 71 57 68 63 66 57 77 70 55 85 55 64 67 62 75 55 75 42 68 71 61 48 74 60 64 73 75 62 67 69 62 52 72 65 63 67 68 67 55 60 68 73 61 72 66 72 60 59 63 60 81 55 58 61 61 63 55 62 49 66 63 55 68 50 75 62 54 70 49 79 65 59 70 65 72 53 66 69 68 69 73 62 71 52 52 73 58 64 79 60 76 65 60 56 62 71 67 62 60 69 62 56 56 72 61 72 66 55 70 59 64 69 63 80 78 61 80 66 60 72 63 55 77 70 60 65 63 63 63 78 75 73 70 63 65 57 79 65 70 73 70 52 70 76 64 57 72 80 61 65 63 56 63 77 76 54 65 71 52 66 60 47 60 68 50 46 83 57 52 63 56 67 66 69 67 87 54 69 77 62 69 86 69 56 72 55 60 48 70 66 62 76 59 69 91 63 63 67 54 64 59 69 51 72 57 70 63 40 66 68 71 61 68 60 58 65 84 76 62 71 39 65 66 71 76 62 52 81 69 86 74 49 57 70 66 69 61 75 55 78 70 81 66 63 72 61 60 77 68 63 73 73 67 65 74 67 52 50 78 57 58 69 60 67 73 45 71 65 59 84 57 56 62 69 64 55 65 64</counts>
			</dataPoints>
		</scan>
	</xrdMeasurement>
</xrdMeasurements>