File: data/XRD/_misc/W6922-1D_600°C_3h_absolute_2th-om_10-130deg_PIXscan_56min.xrdml
<xrdMeasurements xmlns="http://www.xrdml.com/XRDMeasurement/2.1" xmlns:xsi="http://www.w3.org/2001/XMLSchema-instance" xsi:schemaLocation="http://www.xrdml.com/XRDMeasurement/2.1 http://www.xrdml.com/XRDMeasurement/2.1/XRDMeasurement.xsd" status="Completed">
	<comment>
		<entry>Configuration=Factory configuration, Owner=User-1, Creation date=7/8/2013 4:01:53 PM</entry>
		<entry>Goniometer=PW3050/65 (Theta/2Theta); Minimum step size 2Theta:0.0001; Minimum step size Omega:0.0001</entry>
		<entry>Sample stage=MRD Cradle; Minimum step size Phi:0.01; Minimum step size Chi:0.01; Minimum step size X:0.01; Minimum step size Y:0.01; Minimum step size Z:0.001</entry>
		<entry>Diffractometer system=XPERT-PRO</entry>
		<entry>Measurement program=C:\PANalytical\Data Collector\Programs\Jorrit\2thom\_absolute_2th-om_10-130deg_PIXscan_56min.xrdmp, Identifier={15BCCF57-2807-42BD-B5B9-ECC0B3DC9284}</entry>
		<entry>Batch program=C:\PANalytical\Data Collector\Programs\SimonL\batch1x_2thom_10-130°_z9.1_x0y0_57min.xrdmp, Identifier={AA3B4683-C0E0-423D-A045-92923806D7B5}</entry>
	</comment>
	<sample type="To be analyzed">
		<id></id>
		<name></name>
		<preparedBy></preparedBy>
	</sample>
	<xrdMeasurement measurementType="Scan" status="Completed" sampleMode="Reflection">
		<comment>
			<entry>_absolute_2th-om_10-130deg_PIXscan_56min</entry>
			<entry>PHD Lower Level = 4.83 (keV), PHD Upper Level = 11.27 (keV)</entry>
		</comment>
		<usedWavelength intended="K-Alpha 1">
			<kAlpha1 unit="Angstrom">1.5405980</kAlpha1>
			<kAlpha2 unit="Angstrom">1.5444260</kAlpha2>
			<kBeta unit="Angstrom">1.3922500</kBeta>
			<ratioKAlpha2KAlpha1>0.5000</ratioKAlpha2KAlpha1>
		</usedWavelength>
		<incidentBeamPath>
			<radius unit="mm">320.00</radius>
			<xRayTube id="1010048" name="Empyrean Cu LFF HR (9430 033 7310x) DK442154">
				<tension unit="kV">40.0</tension>
				<current unit="mA">40.0</current>
				<anodeMaterial>Cu</anodeMaterial>
				<focus type="Line">
					<length unit="mm">12.0</length>
					<width unit="mm">0.4</width>
					<takeOffAngle unit="deg">4.2</takeOffAngle>
				</focus>
			</xRayTube>
			<xRayMirror id="27010001" name="Inc. Beam Cu W/Si (parabolic MRD)" hybrid="false">
				<crystal type="Graded" shape="Parabolic">W/Si</crystal>
				<acceptanceAngle unit="deg">0.800</acceptanceAngle>
				<length unit="mm">60.0</length>
			</xRayMirror>
			<sollerSlit id="21010002" name="Soller slits 0.04 rad.">
				<opening unit="rad">0.0400</opening>
			</sollerSlit>
			<mask id="22030007" name="Fixed mask 2 mm">
				<distanceToSample unit="mm">220.00</distanceToSample>
				<width unit="mm">2.00</width>
			</mask>
			<divergenceSlit id="22010007" name="Fixed slit 1/8°" xsi:type="fixedDivergenceSlitType">
				<distanceToSample unit="mm">220.00</distanceToSample>
				<height unit="mm">0.19</height>
			</divergenceSlit>
		</incidentBeamPath>
		<diffractedBeamPath>
			<radius unit="mm">320.00</radius>
			<sollerSlit id="21010002" name="Soller slits 0.04 rad.">
				<opening unit="rad">0.0400</opening>
			</sollerSlit>
			<receivingSlit id="22010001" name="Fixed slit 4°">
				<height unit="mm">5.88</height>
			</receivingSlit>
			<detector id="7010017" name="PIXcel3D 1x1 detector" xsi:type="areaDetectorType">
				<phd unit="%">
					<lowerLevel>30.0</lowerLevel>
					<upperLevel>70.0</upperLevel>
				</phd>
				<mode>Scanning</mode>
				<activeChannelsEquatorial>255</activeChannelsEquatorial>
				<activeChannelsAxial>255</activeChannelsAxial>
				<pitchEquatorial unit="mm">0.05500</pitchEquatorial>
				<pitchAxial unit="mm">0.05500</pitchAxial>
				<readOutPeriod unit="seconds">0.135</readOutPeriod>
			</detector>
		</diffractedBeamPath>
		<scan appendNumber="0" mode="Continuous" scanAxis="2Theta-Omega" status="Completed">
			<header>
				<startTimeStamp>2024-08-15T14:58:30+02:00</startTimeStamp>
				<endTimeStamp>2024-08-15T15:54:36+02:00</endTimeStamp>
				<author>
					<name>PRO-MRD</name>
				</author>
				<source>
					<applicationSoftware version="6.1b">Data Collector</applicationSoftware>
					<instrumentControlSoftware version="7.0E 20130304">XPERT-PRO</instrumentControlSoftware>
					<instrumentID>0000000011142674</instrumentID>
				</source>
			</header>
			<dataPoints>
				<positions axis="2Theta" unit="deg">
					<startPosition>9.99826193</startPosition>
					<endPosition>129.99755682</endPosition>
				</positions>
				<positions axis="Omega" unit="deg">
					<startPosition>4.99913096</startPosition>
					<endPosition>64.99877841</endPosition>
				</positions>
				<positions axis="Phi" unit="deg">
					<commonPosition>0.00</commonPosition>
				</positions>
				<positions axis="Chi" unit="deg">
					<commonPosition>0.00</commonPosition>
				</positions>
				<positions axis="X" unit="mm">
					<commonPosition>0.00</commonPosition>
				</positions>
				<positions axis="Y" unit="mm">
					<commonPosition>0.00</commonPosition>
				</positions>
				<positions axis="Z" unit="mm">
					<commonPosition>9.100</commonPosition>
				</positions>
				<commonCountingTime unit="seconds">32.895</commonCountingTime>
				<counts 233 218 257 227 250 196 256 242 226 261 256 261 242 219 228 248 256 229 218 240 242 231 203 227 227 243 264 237 226 262 219 225 255 217 230 242 227 227 247 227 211 231 211 233 206 243 207 237 255 256 223 242 245 197 248 218 244 214 212 201 227 238 230 237 232 259 206 218 234 240 230 232 212 216 260 217 241 196 243 219 234 250 220 246 225 197 216 208 225 214 243 265 243 216 198 198 200 232 260 240 234 216 202 205 223 206 204 225 220 181 217 209 205 231 205 234 233 227 217 200 226 197 230 260 233 239 206 236 214 241 230 215 216 245 217 241 187 230 198 214 199 226 215 213 232 201 226 210 222 219 198 236 231 217 243 218 231 220 234 227 236 225 213 213 229 206 201 214 243 224 205 195 204 189 239 202 208 214 208 222 232 227 209 202 229 222 207 219 210 241 197 197 202 229 207 214 203 223 226 191 178 212 203 223 193 203 229 188 226 219 215 236 165 226 213 221 227 196 216 206 226 217 191 193 204 213 214 209 183 212 205 237 192 213 174 191 183 218 198 220 210 207 219 191 201 203 210 203 192 214 181 186 202 206 210 196 212 199 183 211 171 213 214 200 197 208 220 181 213 198 186 224 207 205 193 198 206 191 194 189 184 175 197 192 192 234 214 218 206 220 209 186 182 232 201 195 180 213 189 193 196 209 191 193 200 206 214 217 171 216 183 223 191 205 193 197 173 204 219 210 195 202 212 195 208 212 189 189 193 196 205 157 206 202 193 198 196 195 215 184 185 181 207 173 190 217 177 189 200 179 182 180 190 178 203 212 198 190 205 219 168 204 193 179 171 207 205 218 171 185 192 183 192 186 177 178 183 200 174 204 168 186 181 184 194 188 207 169 185 168 199 163 195 197 191 183 197 182 207 188 180 190 182 168 175 182 174 194 167 180 217 181 186 177 182 188 194 195 176 177 193 184 192 184 168 181 179 198 199 176 162 173 198 182 193 182 173 184 182 172 173 178 174 209 203 158 196 179 152 182 179 195 205 169 182 177 175 196 203 174 205 182 186 165 180 192 169 185 187 189 161 172 176 180 186 193 168 195 194 183 194 189 165 196 206 178 160 153 189 175 165 158 174 194 173 192 193 178 166 203 163 155 188 187 217 160 174 171 165 180 203 164 164 176 173 180 149 163 176 181 174 179 197 189 181 178 170 156 156 158 185 189 168 168 202 180 187 191 189 166 204 168 186 174 172 174 172 167 196 160 204 170 189 154 169 184 171 181 167 183 180 160 165 204 196 202 166 154 188 170 188 183 175 183 176 150 192 170 166 173 168 171 173 179 190 182 145 178 154 153 185 194 184 167 185 176 162 177 189 196 196 181 178 190 161 175 152 172 186 159 168 161 164 173 199 190 171 159 179 167 165 204 181 184 161 187 169 177 198 158 175 200 159 192 180 151 151 174 180 173 168 157 149 175 197 179 200 170 161 198 176 203 161 185 153 170 180 186 185 193 188 190 171 166 182 170 202 168 167 177 185 194 157 178 172 155 163 177 155 174 181 186 190 172 172 183 182 191 170 186 177 172 175 173 151 161 169 176 188 165 155 186 180 164 155 174 156 162 187 158 177 186 164 184 171 171 176 162 166 170 168 197 161 178 162 180 188 178 171 185 178 173 156 178 208 190 182 169 170 178 178 181 168 176 193 187 190 169 186 191 166 165 164 175 171 212 196 198 161 203 181 193 196 192 179 173 154 177 165 161 199 169 175 191 179 182 194 165 177 175 193 168 183 190 174 182 161 202 178 176 158 158 158 200 170 190 179 188 175 168 165 156 176 174 185 194 192 179 166 172 161 193 144 190 195 182 154 146 201 175 177 182 172 173 156 162 148 171 183 177 172 192 173 185 170 197 182 186 185 189 176 184 180 174 170 172 214 180 168 171 196 205 210 207 192 166 180 179 150 188 170 187 186 195 170 177 171 188 158 174 215 171 170 174 180 168 196 178 192 181 159 170 192 161 184 205 206 178 171 170 188 152 149 176 161 166 163 174 191 189 164 179 191 176 177 168 166 174 193 192 176 154 170 181 174 166 196 164 158 178 178 180 193 196 168 176 193 204 167 176 186 174 189 188 180 174 159 172 198 164 174 211 173 165 174 214 176 176 172 182 170 210 189 177 170 197 200 157 179 168 192 164 166 181 173 179 172 162 196 183 193 172 172 177 178 180 183 198 173 169 181 190 196 171 190 177 192 194 174 193 178 178 175 183 155 195 170 193 182 172 171 177 195 173 187 189 170 164 184 176 185 179 192 189 171 174 172 166 199 174 179 172 185 171 198 172 148 187 188 155 182 181 179 186 176 173 160 196 211 167 201 160 158 161 176 200 179 198 200 188 184 183 205 189 177 186 180 171 167 195 169 177 193 198 189 204 197 197 190 167 191 190 167 177 190 169 188 180 177 191 210 193 188 188 204 169 189 172 196 207 172 193 185 179 220 187 181 198 166 187 208 168 187 203 150 172 181 190 176 186 205 168 196 191 206 180 188 190 225 178 177 190 179 181 163 186 196 187 177 173 193 198 177 177 200 188 174 197 198 187 157 173 181 168 191 186 183 197 174 164 193 200 206 178 196 196 196 192 222 200 195 181 174 191 177 175 190 177 196 203 199 195 202 202 213 191 188 196 170 174 181 212 208 184 179 189 179 197 207 169 192 172 175 179 167 206 157 192 195 181 201 187 173 166 226 203 192 180 185 191 184 185 183 183 204 225 183 191 200 190 187 181 195 194 199 158 178 174 224 205 203 220 198 175 174 184 178 184 185 189 171 190 178 199 186 210 188 179 198 173 165 179 207 164 183 220 199 178 196 169 191 158 195 164 204 174 206 203 163 165 162 182 195 183 197 177 182 209 185 187 219 198 195 203 183 189 190 197 180 194 187 184 212 152 204 181 187 194 199 196 215 197 189 174 188 193 173 194 183 159 198 190 149 198 182 176 174 184 168 183 187 166 154 178 184 185 195 180 217 209 194 182 201 189 162 188 175 178 168 172 156 193 151 166 167 166 198 184 205 188 162 171 176 192 193 183 195 182 176 211 181 176 196 185 185 202 157 179 202 173 187 185 178 182 169 182 185 181 188 188 170 163 203 186 184 184 176 168 207 185 179 177 176 181 181 205 195 186 177 161 164 156 196 176 179 162 200 152 186 188 155 199 206 183 196 181 181 180 188 196 179 199 205 178 177 167 199 179 179 172 159 165 205 191 189 185 168 182 174 203 153 184 176 156 170 197 199 172 186 209 171 201 181 194 190 178 182 184 199 183 164 165 171 174 173 164 180 195 185 158 186 175 189 162 166 196 166 186 165 186 179 167 193 162 188 166 174 194 172 176 210 184 190 192 175 186 181 172 180 164 172 151 182 197 192 189 174 180 199 190 202 169 165 161 154 156 185 164 192 167 177 183 181 178 179 165 170 152 169 191 180 178 188 182 186 169 184 162 179 172 182 180 169 178 188 179 170 181 174 195 189 175 182 171 154 173 170 166 162 174 172 176 180 141 178 168 163 183 198 164 191 184 176 196 153 182 174 168 142 167 176 179 168 170 198 174 170 195 197 170 169 163 188 155 173 195 168 144 169 155 156 183 179 161 158 184 165 179 173 175 182 173 176 172 179 174 178 191 165 159 172 162 141 166 162 182 184 194 182 185 149 164 170 181 189 174 170 166 176 176 179 166 174 160 194 148 194 185 165 161 145 168 157 178 185 171 180 184 157 157 172 158 175 195 152 179 176 178 166 172 173 186 172 161 172 163 189 167 170 170 169 169 164 163 191 149 177 173 154 181 155 155 176 183 170 163 173 155 177 164 152 178 159 164 144 148 181 170 156 173 178 170 166 186 170 169 192 197 147 171 168 151 137 162 179 195 157 171 148 169 156 164 166 165 171 171 158 164 181 159 155 156 179 180 169 142 184 166 196 174 173 164 175 147 188 182 162 194 137 161 148 161 178 178 156 177 163 169 182 172 181 167 188 161 162 147 167 166 150 158 148 171 181 156 157 164 155 141 160 185 150 152 158 175 153 153 174 150 147 158 166 181 166 178 159 161 170 169 163 156 189 172 194 171 163 177 167 156 157 151 147 159 161 168 153 178 151 163 157 143 132 171 143 161 178 136 171 166 172 174 165 185 171 168 159 167 149 168 158 136 175 151 158 148 185 152 143 158 146 171 161 161 171 135 164 138 178 179 148 167 162 153 152 136 167 145 164 161 151 128 169 144 144 161 144 159 169 161 147 149 183 160 166 149 162 158 159 200 157 140 181 165 172 160 153 154 177 125 156 152 138 134 147 169 137 165 126 139 175 145 168 185 161 179 158 176 140 151 165 152 170 137 173 166 145 154 142 191 158 146 151 149 153 158 169 155 146 144 175 156 168 155 146 151 167 164 163 148 162 174 152 167 159 155 168 153 144 149 129 161 144 157 159 141 159 159 177 139 174 156 137 123 160 170 161 168 162 181 135 181 173 141 163 149 160 157 177 154 141 179 153 171 149 163 144 160 154 176 195 160 141 145 149 151 134 154 149 162 167 152 138 134 167 141 169 163 148 139 152 188 152 151 167 174 135 158 159 165 166 144 169 160 169 155 160 156 162 158 158 164 143 163 164 146 165 165 155 156 163 151 161 136 145 161 163 171 160 149 172 144 161 149 159 156 166 156 168 141 138 172 162 134 148 142 155 165 141 151 168 162 144 142 161 145 178 158 151 146 161 135 162 154 154 146 163 149 163 164 152 147 133 134 158 179 151 145 158 153 166 137 143 145 136 162 159 136 156 131 165 142 151 150 152 146 155 162 128 135 161 135 157 171 156 156 128 136 161 158 151 158 164 145 151 173 148 169 155 150 132 163 172 151 152 142 149 151 132 129 145 159 159 141 158 169 183 159 177 147 140 153 141 168 160 150 158 157 180 165 144 153 188 142 179 153 158 166 148 177 157 148 146 150 154 156 153 153 153 145 161 164 189 145 145 161 161 177 158 149 150 147 145 153 152 168 150 147 140 146 137 164 157 135 132 161 157 163 135 121 153 157 139 164 146 154 143 143 137 150 141 126 147 176 119 131 170 127 153 153 158 162 181 172 187 145 142 148 145 164 148 160 148 149 159 160 173 153 157 163 154 151 147 131 152 136 155 160 158 131 150 147 141 138 142 154 143 134 163 142 157 161 157 156 132 146 139 156 155 167 190 142 154 173 149 149 151 156 154 157 145 150 146 148 146 147 145 162 157 148 158 139 167 168 157 154 146 161 160 163 160 161 167 143 145 154 151 153 166 161 176 154 190 130 154 159 169 174 153 170 158 146 170 138 133 151 163 158 139 146 145 164 163 160 181 157 150 151 143 155 149 141 145 167 136 141 165 137 148 132 147 149 141 165 106 169 133 141 144 154 141 177 152 167 145 135 139 173 157 147 136 156 168 169 125 157 157 155 164 124 163 152 147 146 137 149 157 158 155 151 155 145 139 141 165 158 138 130 156 162 171 148 167 161 144 164 146 164 141 161 156 137 142 145 139 150 132 152 159 131 154 172 157 166 136 157 148 161 150 158 168 164 165 158 149 154 177 148 174 161 167 121 159 142 169 146 140 149 139 139 162 147 150 160 166 158 149 169 155 162 194 140 160 171 134 125 150 142 150 139 169 179 158 144 145 150 160 154 162 134 163 174 150 154 145 166 146 141 182 157 156 138 147 161 137 156 165 141 157 138 142 168 143 149 147 156 158 133 163 161 155 176 149 157 165 135 169 146 144 148 171 143 163 157 145 155 143 143 155 165 158 167 154 156 170 146 139 163 168 148 127 163 142 144 154 166 147 139 148 160 144 150 148 150 130 181 166 164 139 124 145 158 173 132 147 142 139 153 163 144 149 154 188 152 146 153 163 152 140 164 138 135 170 163 155 151 159 131 160 154 156 132 173 147 151 168 142 149 166 163 177 123 147 139 165 152 158 155 154 154 169 157 136 153 148 162 137 152 149 153 141 148 154 156 162 142 158 140 147 164 141 166 154 176 167 166 159 163 154 160 155 159 157 176 183 156 140 154 173 143 141 133 163 148 171 153 138 142 154 138 170 148 139 152 162 155 167 159 156 164 139 161 175 143 160 169 166 145 182 145 167 152 164 155 169 144 154 188 167 179 163 146 168 134 160 167 154 159 166 187 153 151 180 165 164 170 159 155 163 153 158 170 184 158 147 149 162 157 172 164 153 148 144 165 137 155 181 164 161 153 141 166 129 144 165 145 175 150 158 153 146 126 160 156 161 159 145 146 148 165 163 152 153 138 157 166 158 160 157 147 149 165 151 134 138 158 171 157 175 175 146 162 156 155 167 148 150 161 168 183 144 136 144 160 164 145 183 145 164 157 180 163 172 145 148 144 151 153 162 138 169 148 165 182 173 170 152 158 164 148 156 163 170 136 149 153 163 155 133 153 158 156 160 161 137 137 157 152 155 165 148 165 162 161 146 152 158 151 150 145 147 154 169 161 171 160 164 127 135 167 167 150 151 151 140 154 153 126 154 145 141 166 152 153 145 141 148 122 173 149 170 165 149 132 156 156 147 144 141 156 178 156 154 177 152 149 164 163 174 152 157 148 154 163 146 162 143 144 165 127 159 150 162 178 127 154 153 163 166 162 157 162 131 150 149 136 168 148 143 163 155 155 161 156 152 158 176 159 153 143 166 157 155 135 163 176 176 170 142 148 161 160 153 152 165 154 153 154 164 160 166 160 152 151 146 155 165 160 152 159 140 141 143 170 139 154 160 171 147 156 123 128 158 153 148 135 176 164 137 158 161 137 169 137 161 168 131 164 156 141 167 145 156 162 150 143 159 157 139 150 138 162 174 148 152 159 163 157 156 139 175 148 140 159 146 141 148 145 169 146 133 151 154 157 142 142 151 156 160 146 145 134 175 154 140 151 160 144 142 162 158 161 166 151 172 158 154 150 171 148 172 170 152 158 138 154 155 159 131 132 144 182 162 149 148 157 157 166 168 161 171 160 136 165 169 162 176 146 172 166 169 139 157 157 144 147 147 187 161 153 168 165 152 159 145 159 158 150 143 135 148 172 164 155 179 154 143 155 151 149 177 183 136 156 168 146 167 155 151 161 151 171 157 162 152 178 167 157 153 175 145 154 137 139 183 194 146 172 167 149 153 152 142 170 143 159 134 157 163 147 147 152 142 195 162 148 137 183 155 166 165 177 152 162 154 150 144 178 180 163 158 161 164 130 146 153 150 166 153 145 166 179 150 141 165 164 166 155 167 152 160 168 158 150 160 161 179 176 145 166 156 142 163 154 183 158 175 170 166 146 154 149 135 142 161 167 169 165 163 152 173 146 155 136 146 144 161 153 155 153 146 147 145 175 163 176 154 150 156 168 162 142 128 179 157 160 182 165 155 170 164 184 167 178 152 143 162 157 153 158 152 165 172 141 182 167 167 178 153 156 146 152 171 176 164 156 184 171 149 159 153 156 157 176 173 164 157 160 180 172 165 167 155 156 168 151 168 145 134 158 176 160 144 172 153 168 165 174 158 157 176 171 174 173 175 174 149 163 153 179 152 155 153 158 146 152 174 180 176 145 167 163 164 165 180 175 162 157 153 168 149 163 174 138 183 154 175 169 203 166 176 173 167 177 165 159 175 195 175 164 175 184 176 197 174 168 178 174 181 169 160 173 195 175 170 176 166 198 177 195 210 168 180 199 175 175 161 187 178 185 202 176 191 183 220 170 167 166 168 181 183 181 184 178 184 198 188 201 187 177 193 188 190 199 184 236 188 182 193 260 207 185 193 203 214 230 224 238 231 258 246 245 228 259 233 243 262 313 311 328 290 326 282 334 335 334 368 375 311 326 315 299 326 330 296 308 301 277 261 291 265 269 255 245 249 224 255 241 225 239 282 216 212 197 189 207 181 205 203 199 210 190 179 186 191 203 165 171 161 162 180 200 166 171 181 177 177 172 166 177 159 158 151 172 177 161 159 158 172 187 153 170 158 167 158 158 140 157 175 186 178 165 158 155 154 177 147 169 151 154 141 199 178 186 173 193 170 171 175 167 150 187 138 177 159 149 141 151 167 147 168 169 160 178 174 140 170 159 168 151 157 162 195 139 151 153 155 181 165 170 173 155 161 166 176 182 157 168 154 131 166 172 183 169 182 140 178 152 168 148 173 169 168 167 164 164 145 172 142 189 174 180 154 159 145 161 180 160 153 154 174 159 147 164 168 152 168 179 153 193 156 151 151 170 173 158 162 154 160 170 173 172 192 152 175 182 144 167 164 151 150 147 167 170 151 166 184 186 166 172 142 189 147 161 174 153 155 179 151 153 175 160 148 177 169 153 160 176 182 165 160 165 156 174 175 170 178 177 160 169 165 157 158 171 180 190 148 159 147 158 171 158 166 149 154 146 180 146 188 151 182 153 170 176 158 162 166 186 159 163 163 167 162 152 166 174 156 165 147 173 157 179 171 168 163 178 150 170 151 171 163 155 176 171 182 164 172 173 148 176 159 168 156 179 168 163 167 166 165 158 182 155 163 159 166 164 188 154 164 158 154 168 169 159 166 194 162 134 166 165 167 165 158 169 158 157 192 146 155 175 161 175 147 176 154 181 151 184 166 160 180 164 167 159 177 156 155 157 154 163 159 182 163 188 162 180 193 166 170 153 162 166 158 158 177 173 169 170 180 169 142 178 177 165 164 161 158 163 167 182 132 159 161 168 161 157 151 162 154 153 153 162 157 139 172 179 146 167 159 178 181 152 164 162 137 140 166 161 149 161 178 174 164 160 172 153 156 166 157 134 179 176 166 170 162 163 162 167 170 176 182 161 175 141 154 166 178 162 160 180 170 188 133 166 182 162 150 160 159 160 158 170 163 183 140 188 157 160 166 152 184 162 191 162 177 161 163 153 159 179 172 158 165 164 152 168 160 169 163 178 185 159 185 157 147 158 180 168 172 154 166 176 177 168 164 144 177 162 180 168 181 181 158 160 164 152 165 135 177 180 150 151 158 158 153 154 148 164 151 163 164 165 178 180 190 156 155 147 165 171 172 151 158 162 143 163 164 173 145 131 169 166 161 157 169 157 168 145 143 152 165 162 162 168 146 172 162 152 170 152 163 138 175 165 169 158 147 151 139 141 152 182 153 164 160 172 169 149 160 167 178 150 153 170 165 173 185 153 180 162 176 167 168 183 193 162 173 164 149 166 176 155 148 148 157 165 166 154 173 160 194 161 166 165 168 163 160 182 148 163 149 145 162 186 159 136 148 144 177 153 149 197 170 167 146 156 173 186 174 163 172 159 149 167 165 156 148 171 147 168 190 167 158 149 142 158 156 169 143 176 159 171 160 164 179 178 157 164 169 169 158 160 153 185 159 161 158 188 166 167 172 158 155 161 174 166 156 168 173 160 152 172 155 143 150 154 153 164 178 155 201 160 162 168 169 192 194 161 163 167 173 156 162 183 159 159 154 174 170 148 163 172 153 163 174 164 168 168 171 156 168 176 158 166 145 191 164 172 147 177 173 159 162 156 166 181 156 180 171 168 186 154 139 161 190 163 163 141 166 157 177 188 168 159 155 167 151 155 161 179 147 154 159 170 148 162 162 160 167 150 146 174 172 152 153 168 183 162 145 168 174 146 153 154 151 167 146 159 144 169 164 157 185 164 160 181 173 162 157 138 192 144 157 165 153 165 148 182 153 159 160 158 173 171 163 184 190 161 155 179 175 175 174 167 170 167 155 169 153 177 146 155 140 161 163 148 190 191 155 155 158 176 148 153 154 167 165 164 148 170 179 190 166 173 159 159 164 131 167 151 157 138 161 180 173 158 137 150 159 180 173 152 147 151 184 172 169 144 153 164 159 183 174 161 139 200 165 189 175 153 166 161 151 190 155 179 169 162 169 158 170 150 166 177 154 139 152 161 151 157 146 167 146 166 154 168 162 182 159 162 165 182 162 176 165 165 150 144 168 168 165 172 164 170 135 149 191 149 157 147 169 183 174 185 149 163 168 168 158 171 147 177 198 161 162 172 158 154 157 166 174 174 165 145 154 198 160 171 143 176 173 140 160 175 192 152 163 179 170 175 151 163 180 182 149 197 172 153 152 158 153 137 155 149 174 140 161 168 181 175 148 157 155 159 157 157 160 176 165 151 141 166 156 160 174 152 152 167 154 177 160 136 164 167 173 168 148 177 156 171 166 170 171 166 154 163 149 153 168 153 156 175 189 167 184 139 175 172 152 187 184 160 157 168 192 171 171 178 145 170 157 143 150 191 149 157 149 176 165 163 172 158 162 148 147 170 161 167 156 181 166 168 177 158 158 166 165 184 146 160 150 180 149 176 177 172 184 156 175 162 192 156 168 153 198 152 160 197 194 157 142 177 155 144 189 166 197 152 156 155 151 177 162 178 167 171 165 158 174 190 190 174 180 185 190 173 183 150 128 164 141 172 183 155 174 145 147 162 172 173 167 192 185 156 152 169 162 145 150 170 154 171 162 159 149 175 146 130 176 166 164 159 175 172 171 160 174 186 175 170 186 145 135 208 178 149 172 159 162 163 174 171 166 189 166 164 166 138 166 144 145 173 169 150 170 156 181 154 161 187 178 155 186 171 152 175 175 159 172 143 174 186 139 165 156 170 191 155 171 166 182 161 165 176 160 180 176 174 167 153 166 162 164 164 161 184 146 175 183 169 156 191 166 148 157 147 143 190 155 160 173 170 164 154 140 165 154 141 154 156 183 172 160 172 159 144 163 150 141 187 157 157 154 162 152 166 169 157 158 187 191 202 184 178 149 180 170 166 164 147 168 182 146 159 169 160 197 167 151 175 164 204 148 139 162 178 186 156 162 162 156 167 160 159 169 158 168 154 180 154 170 193 176 149 173 182 188 170 165 160 172 161 163 154 173 143 184 181 172 187 168 172 179 177 192 175 173 164 157 163 140 185 158 151 178 176 173 177 181 177 165 156 144 162 174 159 193 181 165 185 166 174 157 167 158 176 155 171 171 182 158 196 168 159 160 180 173 158 157 156 159 149 152 172 158 140 151 138 177 173 166 164 164 168 170 158 195 158 135 154 174 180 173 152 163 171 165 161 155 164 143 162 170 175 195 153 179 155 178 138 175 184 168 160 155 182 171 159 159 157 177 178 164 165 133 162 175 181 177 158 164 178 159 167 175 173 149 142 164 174 143 169 167 182 181 176 165 183 169 196 157 164 190 141 175 165 188 166 150 164 164 179 176 162 139 165 163 177 149 178 176 153 165 178 151 167 167 190 154 174 171 202 170 144 202 155 152 154 170 150 200 152 152 160 187 164 161 177 139 155 153 139 201 152 157 151 174 174 180 146 164 157 154 165 170 147 175 198 159 191 159 170 143 172 177 172 160 157 144 142 174 153 139 189 164 159 144 154 162 136 177 149 171 165 185 160 166 181 151 164 155 170 151 169 152 159 152 162 182 182 186 132 181 161 135 181 168 180 181 165 169 154 171 174 138 162 136 171 170 181 172 183 177 149 144 155 162 170 159 170 163 165 174 159 185 154 155 166 171 168 179 160 176 181 179 164 152 171 171 167 165 187 172 169 169 148 178 167 173 149 172 172 180 158 166 153 170 183 164 171 180 154 166 185 186 189 167 204 173 170 181 158 158 167 151 172 164 165 172 174 180 182 150 149 167 158 161 175 170 175 149 175 169 169 157 142 171 159 147 160 177 159 156 163 161 167 188 204 177 152 170 175 153 140 174 167 177 147 160 149 154 152 166 157 177 162 155 177 180 171 175 180 173 172 191 175 170 163 186 164 170 162 162 188 169 149 162 163 164 180 169 165 184 181 189 159 163 150 152 184 157 161 167 178 165 191 153 186 170 178 164 154 195 180 168 187 167 156 150 182 146 139 159 168 206 172 153 144 164 161 175 148 171 162 159 165 194 164 171 178 196 170 182 186 174 177 168 149 186 159 160 177 183 159 195 150 169 172 179 129 176 162 169 166 177 149 176 159 156 167 172 163 171 165 178 133 142 176 185 155 188 166 184 180 174 164 152 186 167 176 187 179 145 179 143 184 165 161 169 150 148 157 173 151 172 176 155 158 176 178 166 180 162 149 187 175 155 147 167 173 157 174 182 162 162 149 163 170 161 175 173 196 148 168 158 164 167 177 177 177 173 177 181 160 161 189 177 158 168 148 151 168 199 172 149 196 163 180 156 167 183 166 173 174 149 170 185 162 191 168 159 152 172 168 163 172 162 161 181 169 180 189 172 164 154 156 173 164 184 186 192 169 164 177 174 167 163 158 171 163 186 153 181 173 183 183 175 159 189 171 174 165 165 170 188 145 170 171 165 144 173 195 167 190 143 187 174 158 163 191 186 161 190 176 167 170 163 201 189 179 165 161 166 161 158 160 172 168 209 179 150 166 181 188 192 168 168 189 194 175 184 179 177 201 188 189 184 181 186 206 205 181 164 180 160 190 202 205 167 177 174 213 166 154 192 179 197 192 194 191 189 181 196 139 188 193 170 207 177 197 179 211 169 190 203 184 179 204 202 193 186 186 195 208 182 191 194 201 170 168 166 195 186 194 194 196 172 182 160 189 185 176 188 160 175 183 187 183 174 179 185 156 164 183 172 185 179 202 161 165 159 150 156 167 193 164 166 166 176 176 185 167 186 197 161 195 176 162 144 179 167 197 177 168 181 166 178 148 182 162 175 156 191 189 182 168 177 176 189 158 161 181 183 164 167 169 192 174 160 190 161 173 185 174 182 163 177 178 166 175 157 175 180 169 174 184 152 190 180 184 177 162 179 177 165 187 215 177 175 166 179 147 165 182 169 164 162 193 179 187 169 191 174 191 159 195 167 183 156 184 172 180 160 174 153 169 175 191 159 196 166 171 194 166 165 148 155 167 168 186 171 188 176 179 196 166 142 181 157 189 181 173 174 183 187 190 186 186 171 172 193 183 176 196 196 184 160 185 166 188 170 160 169 184 187 168 168 174 163 164 171 171 167 153 174 178 189 179 175 192 183 173 179 167 153 164 172 170 181 182 192 186 163 171 167 191 153 143 167 174 175 179 147 174 172 155 155 188 157 156 178 155 192 178 175 192 172 172 177 172 170 170 167 159 158 173 154 174 191 159 178 172 207 183 159 176 171 153 176 165 184 164 151 179 160 168 160 177 171 182 175 181 171 173 171 164 156 169 176 170 179 180 176 177 179 172 174 183 157 170 177 177 177 157 177 171 158 157 177 169 153 175 175 176 173 166 167 175 155 175 185 174 173 163 166 193 174 176 134 174 156 151 166 150 184 158 191 175 180 180 179 159 177 157 190 168 194 169 180 171 155 174 164 202 176 182 155 192 177 177 189 166 153 144 180 152 148 176 171 162 178 160 194 167 184 168 174 153 169 175 204 156 174 195 160 176 168 161 167 172 166 181 190 173 174 168 152 162 160 159 176 174 156 181 181 175 176 200 168 170 187 161 180 164 165 180 183 180 171 186 178 176 178 159 203 166 164 181 158 164 189 162 169 165 174 194 136 187 176 194 176 160 156 169 175 170 169 187 177 171 175 190 175 181 148 149 162 172 168 172 141 183 160 178 193 165 160 160 144 168 181 160 175 169 193 181 171 172 137 171 170 153 181 175 156 174 172 176 152 175 165 151 159 151 162 179 193 160 175 175 161 158 168 157 170 161 162 171 186 168 183 168 176 147 159 164 210 166 160 170 180 179 174 198 145 168 154 162 170 169 162 179 180 181 181 190 159 179 168 171 167 160 151 174 160 174 161 162 174 153 159 168 195 153 184 187 171 177 194 177 162 173 157 176 156 181 146 160 161 152 174 175 183 171 197 152 153 159 185 169 168 167 180 175 180 171 175 163 167 186 147 171 169 182 168 160 175 153 142 176 168 158 183 165 169 176 180 161 159 156 173 170 158 171 179 159 199 159 175 183 178 191 176 171 190 153 169 151 154 182 133 150 155 168 183 203 162 162 159 171 158 161 166 169 157 178 187 141 165 156 176 157 170 148 176 191 172 174 175 185 155 189 172 183 200 161 163 186 171 154 176 178 172 160 171 161 159 160 181 150 150 172 172 176 156 173 148 144 173 163 154 156 171 171 172 167 177 163 186 163 170 178 173 156 142 156 163 181 160 174 157 182 180 178 176 163 175 171 165 170 163 152 174 156 169 149 177 155 182 172 168 154 153 177 178 163 177 199 198 160 161 169 171 184 166 179 191 186 188 148 171 180 171 165 164 191 164 188 175 180 176 156 159 173 147 164 179 182 191 156 158 162 182 161 194 173 169 180 173 159 185 168 185 161 170 182 178 169 159 145 167 189 171 190 156 180 183 121 167 191 162 167 160 146 169 180 180 179 149 189 197 153 175 170 173 172 170 174 159 171 149 173 172 160 141 154 194 156 156 182 177 154 180 201 191 169 174 184 164 153 165 188 154 176 163 156 177 182 199 158 174 190 176 164 184 161 161 166 153 169 178 168 179 174 156 170 175 173 178 155 142 165 179 174 176 150 170 163 184 160 168 143 164 179 165 185 147 188 161 159 169 193 130 186 164 162 167 153 195 188 147 171 149 163 180 207 164 184 172 181 165 192 199 185 159 161 182 193 173 180 177 177 134 179 185 158 176 188 189 182 187 182 144 170 179 173 164 162 171 166 200 191 181 176 168 182 180 183 178 190 168 161 175 159 151 150 198 186 158 165 167 172 152 153 169 169 164 178 174 200 173 173 165 178 170 203 181 178 205 199 163 171 151 154 166 196 180 197 169 175 154 172 169 173 173 204 146 168 172 173 159 155 161 176 170 161 175 165 166 169 172 152 136 165 167 162 180 152 190 171 172 179 181 162 161 187 174 162 160 185 174 179 157 186 147 169 184 182 187 160 163 158 177 189 158 149 151 162 171 180 196 193 190 148 183 183 170 183 165 187 182 167 194 164 177 177 161 177 140 171 168 165 169 158 188 178 173 176 165 181 163 181 188 164 147 171 184 187 188 193 167 179 180 155 181 162 167 154 145 170 189 152 178 182 175 149 178 164 166 197 181 186 185 203 148 159 164 155 186 161 179 172 167 175 146 166 147 160 166 160 178 167 175 166 178 179 176 176 174 179 165 149 198 161 167 179 192 178 153 178 177 171 187 180 175 166 181 161 170 174 168 185 179 137 175 183 163 166 191 181 160 153 152 148 169 181 180 185 172 154 168 158 170 177 180 181 178 165 154 185 172 171 176 180 160 174 181 179 182 171 152 163 172 169 170 149 178 164 171 174 184 148 157 158 193 179 165 182 160 164 187 172 152 181 179 194 180 171 154 187 167 184 163 156 172 177 183 181 172 160 157 165 169 175 170 163 167 163 155 174 175 158 184 150 165 174 169 181 165 158 177 135 180 162 160 176 176 175 179 165 171 187 175 174 171 173 167 160 161 167 160 154 186 166 159 178 177 175 172 196 165 180 167 172 166 181 168 185 163 180 176 152 163 193 172 162 142 175 167 169 172 160 169 154 156 161 177 170 178 169 154 164 174 182 167 158 153 163 172 166 149 183 179 154 183 199 168 183 164 148 157 150 201 168 182 191 170 160 162 183 177 161 167 174 152 148 181 181 171 178 172 170 195 162 177 169 163 173 181 161 165 182 179 161 161 147 150 170 178 172 173 164 182 182 152 167 185 147 175 155 173 184 185 161 187 193 177 165 161 178 174 192 179 187 175 171 177 174 180 183 189 153 182 184 178 179 159 154 156 165 148 164 164 190 196 165 164 167 170 181 181 172 168 170 161 160 164 154 161 161 156 166 171 172 173 182 200 190 185 169 151 172 161 167 194 178 184 161 184 165 171 161 178 175 183 152 165 177 169 138 175 176 180 165 186 180 165 168 164 150 183 168 192 170 180 153 165 182 174 173 177 171 159 154 166 165 171 137 157 163 167 168 201 172 179 178 159 175 158 165 189 170 185 161 156 199 186 160 158 159 164 188 177 178 163 166 181 172 151 148 174 171 159 171 176 184 184 161 154 191 165 180 181 175 203 173 150 204 187 166 157 145 185 170 169 169 172 162 159 175 181 178 161 157 171 169 154 180 158 167 177 161 158 150 155 164 179 160 174 195 168 168 169 218 150 170 160 170 171 175 173 184 190 145 181 178 154 153 167 181 157 157 178 170 168 166 186 191 166 170 163 181 163 176 180 167 158 172 179 167 176 166 183 172 177 161 169 165 166 179 180 148 175 183 165 165 171 145 178 168 180 182 159 176 171 170 175 187 162 164 164 175 144 170 180 184 170 185 172 166 151 160 163 183 172 166 159 174 150 190 174 149 170 167 188 166 178 153 183 155 172 181 178 185 190 167 185 174 171 165 173 193 147 184 188 198 181 162 179 179 173 181 168 184 160 186 148 166 170 186 194 161 213 211 176 158 187 190 198 213 184 171 196 160 193 169 191 193 199 180 200 197 186 193 189 180 193 191 200 205 186 194 184 188 197 195 205 212 183 200 191 195 214 184 210 183 187 174 211 166 209 194 179 170 183 192 173 177 175 185 159 170 197 173 177 212 165 171 183 206 163 196 176 199 203 187 176 195 180 181 179 163 181 173 175 181 178 184 166 160 177 175 191 188 158 185 183 175 152 169 190 163 183 201 175 160 158 186 184 179 172 182 166 188 179 168 167 173 154 181 174 173 160 180 182 145 213 159 146 177 152 184 175 176 183 177 180 179 150 181 200 174 178 162 182 143 175 156 175 153 164 171 160 166 180 158 160 181 175 157 161 189 170 154 166 177 181 196 163 150 158 180 193 169 186 170 193 175 175 170 153 172 183 148 180 176 167 177 184 168 177 158 181 172 169 157 157 164 197 175 159 165 159 164 156 157 171 149 152 158 156 184 177 149 160 160 169 175 163 182 191 186 189 161 159 172 173 146 173 173 137 173 184 171 167 151 137 178 166 144 175 156 166 167 157 162 152 168 166 178 174 159 166 183 183 170 184 175 163 159 152 165 177 196 174 187 211 162 183 163 196 166 166 170 173 179 166 166 191 154 168 185 191 172 169 174 156 174 185 172 143 165 169 160 167 188 160 183 167 176 148 171 141 175 170 174 152 156 190 165 168 163 173 167 179 186 182 193 180 154 187 172 166 155 165 157 172 197 180 189 173 181 162 171 164 177 151 151 176 166 169 154 173 173 171 160 157 170 166 178 175 191 171 155 191 180 171 180 161 163 180 189 143 182 187 172 166 184 188 163 189 156 190 159 176 154 179 180 165 159 148 158 177 173 192 175 184 188 162 173 165 167 177 156 175 174 167 185 169 161 180 186 158 181 170 171 185 172 187 179 172 175 151 173 185 162 167 174 148 182 156 161 161 167 182 168 191 184 180 191 209 180 162 163 143 162 160 175 158 167 164 169 167 196 160 165 165 163 173 165 169 173 163 158 178 164 175 158 180 177 169 177 162 178 169 154 163 184 159 182 181 147 169 159 165 137 175 166 153 177 179 174 171 195 151 171 168 178 164 154 159 171 162 181 161 171 176 173 174 178 165 144 183 155 175 180 197 171 159 152 167 166 167 163 170 189 163 153 143 162 184 172 159 179 150 197 182 184 179 170 155 165 178 182 150 170 167 188 171 169 160 158 168 156 189 159 144 147 175 166 181 176 189 202 175 163 177 196 196 185 149 180 190 165 153 170 163 162 187 171 169 184 165 160 157 176 146 161 164 170 172 167 169 180 162 173 176 174 186 180 163 182 165 164 175 170 164 156 168 187 179 189 191 173 164 160 187 176 159 166 172 184 167 164 196 172 128 155 167 167 149 146 157 177 170 192 175 173 176 159 160 196 158 154 150 154 188 151 155 166 191 142 168 193 175 167 164 160 178 159 156 153 164 165 168 177 168 163 168 168 155 160 153 152 167 184 158 153 184 160 167 171 161 186 171 177 175 171 174 187 171 166 158 194 180 162 159 177 167 174 164 178 153 173 158 164 200 177 142 164 190 157 152 157 185 146 166 163 147 172 178 157 161 148 149 164 180 154 176 176 190 178 152 173 156 181 165 148 166 166 182 174 171 148 182 184 175 175 187 169 158 164 187 193 195 165 168 172 183 173 179 165 180 147 177 152 173 157 173 164 192 142 144 143 150 177 192 167 156 160 169 192 186 169 171 171 173 179 165 152 182 182 177 168 179 156 156 188 175 152 164 137 180 175 172 159 172 170 175 176 164 193 191 168 176 168 166 189 158 179 159 192 167 162 154 181 177 166 165 164 179 175 173 169 191 172 177 178 186 167 169 155 178 173 171 159 198 187 182 177 176 152 164 163 178 160 165 170 178 174 165 190 157 173 179 161 187 166 157 186 146 189 187 163 170 183 172 152 191 161 158 142 192 194 175 152 162 168 169 162 181 160 198 156 192 162 168 188 170 171 172 184 153 177 203 177 154 164 188 191 170 163 177 193 198 157 158 140 168 165 170 185 163 178 172 189 169 173 173 201 159 162 181 158 158 170 195 159 148 187 173 176 151 169 167 178 177 168 153 161 182 162 165 163 176 168 159 169 186 179 184 150 197 157 193 174 173 152 155 160 174 154 163 167 176 181 178 177 167 190 181 164 172 198 174 154 176 164 185 170 183 161 188 171 179 159 166 166 148 166 160 163 167 177 177 153 154 168 193 190 168 179 188 174 184 182 169 154 168 140 162 157 181 153 156 170 163 171 159 191 175 183 184 175 197 169 186 181 178 169 162 153 170 163 172 174 175 160 174 181 195 189 172 186 174 173 144 147 170 160 200 170 150 173 167 176 173 152 183 169 182 176 188 185 164 180 149 197 176 176 170 185 158 181 159 159 173 193 188 170 166 188 134 194 176 166 169 158 177 180 141 195 168 179 185 167 138 148 176 163 158 186 159 166 164 185 164 168 159 197 173 163 170 183 174 169 184 173 178 174 156 159 193 164 161 149 188 183 182 153 161 167 160 167 175 162 180 172 165 153 153 177 175 178 147 162 172 160 176 138 158 169 177 177 172 143 169 174 161 178 157 180 161 168 169 166 157 144 157 182 173 158 162 167 184 173 156 152 161 170 171 179 156 151 153 175 174 185 165 195 185 165 158 196 164 165 134 180 185 166 178 196 141 149 174 160 161 193 182 171 182 168 166 167 157 176 148 155 167 163 191 163 154 168 163 188 188 143 173 182 177 169 178 182 181 162 168 169 142 158 181 169 158 164 142 169 178 184 176 170 139 157 158 168 186 163 175 162 165 194 180 214 165 168 177 152 155 159 174 186 171 170 182 164 182 179 184 161 171 158 183 169 173 162 169 194 164 158 185 181 164 188 175 178 191 166 177 193 158 175 183 161 167 164 150 175 152 168 191 184 176 175 165 188 191 167 166 158 197 167 178 175 159 180 179 191 173 149 175 149 200 179 180 175 161 141 169 179 166 155 168 165 160 171 178 183 165 188 175 151 165 197 161 148 179 149 175 158 152 151 181 171 182 181 164 176 154 173 189 159 162 181 153 160 199 156 164 174 170 169 196 195 166 144 187 158 144 180 188 185 188 162 170 173 194 171 183 153 178 170 171 186 145 181 192 165 178 167 162 163 189 154 169 166 165 179 159 170 159 186 177 170 172 176 173 145 182 184 170 150 173 169 160 215 164 167 189 190 199 166 174 179 195 170 175 172 172 168 153 171 186 176 176 170 150 161 158 177 168 171 161 169 164 163 202 172 176 163 164 161 160 186 169 184 177 170 173 197 174 173 179 182 175 200 152 193 158 167 177 187 163 161 144 161 152 150 158 144 156 167 154 166 162 165 170 187 164 180 184 173 156 193 166 210 184 183 181 175 194 190 168 166 153 163 184 197 178 201 158 179 143 168 160 154 153 164 169 171 180 191 154 158 164 186 183 170 159 189 175 197 187 173 178 151 189 187 170 174 173 195 166 157 185 178 144 169 185 177 144 167 173 152 173 166 152 165 179 145 185 153 171 171 183 178 165 148 183 161 180 156 186 148 159 178 194 163 166 176 158 164 161 184 154 179 182 157 182 181 172 167 170 169 180 185 173 171 185 190 154 175 188 167 188 179 160 175 163 162 173 196 172 164 170 163 176 190 163 169 168 174 159 154 180 169 166 156 183 188 167 173 153 185 180 153 169 184 183 154 164 176 153 174 191 177 177 167 152 190 190 178 150 198 179 183 166 196 171 181 151 171 178 150 175 177 163 158 176 179 195 172 173 176 181 150 182 182 194 189 176 169 173 158 185 175 163 196 195 190 199 195 186 173 197 175 183 194 200 166 151 171 156 201 175 180 183 183 180 194 183 189 169 177 163 165 173 169 177 181 163 177 179 180 176 203 179 183 162 180 177 173 149 161 162 169 187 184 170 159 158 169 174 162 188 186 187 187 163 186 178 176 173 160 173 192 168 181 168 164 171 169 204 157 173 194 173 168 178 184 195 172 153 143 149 173 183 167 179 182 166 169 167 156 172 166 158 184 163 188 157 172 171 169 168 154 172 184 164 149 172 185 159 180 182 185 195 162 139 188 163 166 174 179 156 163 156 171 180 170 184 185 161 175 136 195 158 168 155 175 171 181 147 147 158 167 182 183 169 180 148 189 173 170 162 162 163 175 168 183 191 149 169 190 171 154 168 169 161 185 151 173 165 184 159 171 178 173 181 178 162 165 160 173 153 173 178 187 164 178 181 176 178 169 152 189 163 174 172 194 192 192 156 186 191 177 161 166 170 196 177 167 172 168 172 185 151 180 180 172 163 163 162 180 188 159 179 172 146 178 149 162 198 159 186 168 151 176 171 182 186 159 168 176 159 175 171 186 184 183 180 177 166 188 165 175 169 163 169 159 177 169 179 210 203 167 181 147 192 172 181 179 192 191 174 154 174 181 157 175 168 187 189 168 153 163 149 166 160 163 166 182 166 178 178 180 164 161 167 170 184 175 171 184 156 168 166 197 152 149 149 170 170 183 164 193 195 194 173 176 157 163 177 170 164 187 184 158 182 165 182 193 154 163 178 161 180 192 177 175 181 189 169 199 159 171 169 170 174 162 185 173 186 178 171 167 148 185 148 181 172 143 149 157 163 192 179 197 171 193 170 156 174 157 154 166 161 157 153 156 187 151 168 167 152 146 151 157 179 172 166 168 139 148 172 161 163 175 164 181 190 165 162 156 177 153 165 182 157 162 184 167 192 165 159 189 163 165 172 156 140 171 175 151 163 150 179 156 185 177 144 166 160 162 149 180 158 174 170 161 179 178 181 168 158 165 181 174 156 167 203 168 193 148 171 166 164 148 160 180 161 174 163 163 169 152 165 180 170 167 189 168 154 175 169 184 172 167 168 174 184 174 164 174 171 164 165 193 158 189 167 159 184 177 158 177 185 197 154 183 185 165 144 185 210 169 174 171 169 155 166 157 165 164 175 143 170 187 171 185 186 167 149 175 185 158 166 156 162 168 174 191 173 156 175 146 168 190 177 149 169 169 176 171 168 159 179 183 165 142 160 164 173 156 198 168 157 166 181 150 154 193 164 174 179 145 156 160 188 163 164 170 186 167 174 163 198 168 154 187 144 165 157 172 177 177 169 178 184 190 172 181 164 164 171 150 166 180 164 136 162 173 161 183 176 196 176 156 183 184 153 160 184 164 183 173 177 155 161 194 162 178 141 158 170 162 162 175 190 176 184 159 214 188 169 164 171 170 181 187 180 162 179 165 149 191 198 162 171 178 168 188 166 150 178 171 169 173 140 175 167 149 174 163 153 173 163 179 181 196 160 163 166 157 168 164 155 165 163 187 158 162 148 161 163 173 154 168 197 168 181 161 187 182 160 161 153 176 166 140 165 166 181 183 193 158 161 150 184 175 174 179 190 163 189 161 174 190 179 165 158 171 161 136 173 172 173 164 175 152 195 186 160 156 172 179 156 165 180 167 149 183 167 176 169 173 176 166 174 169 176 158 182 169 160 157 162 165 153 174 158 183 157 167 176 174 160 146 184 173 189 167 163 172 182 167 163 180 157 164 188 167 160 162 178 166 154 174 181 169 179 175 170 176 155 171 173 161 174 167 203 175 185 195 172 164 166 157 174 156 171 167 188 175 181 169 194 152 192 184 180 175 174 190 194 160 177 183 188 178 156 199 173 178 175 160 178 171 176 168 152 148 162 164 170 173 160 171 154 177 185 162 194 165 173 174 169 174 171 166 149 196 168 172 154 153 162 165 174 172 208 164 190 160 181 170 166 163 175 183 159 172 170 163 152 148 180 176 169 174 165 221 170 166 187 166 175 165 179 175 184 180 174 181 161 160 186 176 185 144 147 171 166 167 177 174 182 185 175 199 211 162 167 154 166 159 148 136 157 180 151 167 182 148 176 153 159 162 170 191 192 173 164 161 159 172 186 171 183 178 170 191 160 179 156 188 174 199 175 185 152 162 192 171 160 179 150 144 166 172 167 160 156 165 177 167 160 161 157 165 168 158 175 189 167 168 174 184 147 162 189 145 143 170 199 180 179 173 169 166 177 172 170 180 152 161 165 197 161 173 177 155 160 176 193 166 166 181 137 169 189 173 175 153 142 169 177 174 162 172 169 177 192 169 150 149 159 153 160 186 156 161 168 168 161 187 179 158 168 179 180 191 174 176 152 169 171 172 153 148 170 189 173 182 166 152 164 161 173 184 172 176 164 171 164 164 150 150 148 162 154 136 160 178 187 176 151 189 168 169 167 168 148 164 172 168 197 153 157 160 188 144 176 178 174 167 164 168 171 173 149 185 165 131 163 174 182 163 153 176 169 182 171 173 158 163 173 171 171 159 170 173 165 157 155 176 173 183 191 147 153 148 173 184 157 161 154 155 182 181 168 152 194 168 169 168 173 184 168 164 164 149 175 199 152 160 181 159 164 158 137 161 154 181 144 165 145 145 157 169 164 178 181 166 181 179 183 157 149 173 181 156 157 155 143 176 166 172 182 175 141 165 147 171 182 185 155 157 176 153 199 173 166 154 156 183 162 181 151 170 167 174 151 153 172 169 171 188 173 162 165 173 188 187 164 171 191 163 162 158 167 135 164 180 167 162 158 157 151 159 171 148 159 169 152 190 144 178 184 160 167 175 183 157 156 170 156 160 165 178 145 163 137 159 153 177 158 154 175 164 158 156 143 159 172 160 165 178 154 172 166 185 176 147 175 185 160 149 169 180 157 181 170 167 156 181 139 153 159 178 186 143 164 156 168 198 148 153 186 146 175 151 184 143 180 163 188 152 154 163 154 158 167 175 138 175 162 175 162 151 153 194 153 164 168 182 175 175 162 153 181 148 170 164 151 151 156 159 165 174 166 152 169 171 176 170 153 172 158 176 155 172 156 179 148 159 164 163 152 158 152 168 184 178 150 166 167 174 175 183 171 174 173 170 151 157 165 163 177 195 176 185 170 149 184 163 162 154 167 171 172 185 166 158 173 154 184 163 155 160 161 165 175 181 161 157 161 185 163 161 174 151 156 170 176 180 148 171 183 196 175 191 173 167 158 145 157 176 187 178 171 182 187 145 140 165 155 170 168 164 192 151 154 150 141 155 161 169 171 178 162 172 142 161 166 159 154 157 184 182 168 173 158 175 170 171 140 179 180 166 170 160 157 158 158 142 160 139 169 163 181 134 189 156 182 163 137 163 151 152 150 167 158 161 166 167 172 174 159 172 174 179 172 188 162 163 172 181 169 171 168 195 188 175 182 157 157 179 187 153 169 181 192 201 169 161 180 175 180 174 165 142 181 190 182 168 165 162 161 177 157 198 160 194 171 168 143 173 179 160 177 162 159 195 147 157 160 182 170 154 157 182 165 193 169 172 162 156 184 169 146 168 163 173 173 177 182 195 199 172 163 156 161 175 173 157 169 169 169 193 168 192 182 170 166 172 179 146 167 181 177 168 148 175 153 166 162 169 179 172 186 168 182 175 182 174 191 194 201 154 158 168 188 150 180 149 167 150 192 168 161 152 164 185 188 154 172 168 169 173 170 182 162 187 170 173 179 177 185 182 144 166 193 176 185 183 169 155 183 198 154 180 163 178 175 157 173 179 195 198 155 173 180 184 172 202 161 138 150 157 178 190 170 175 189 186 168 168 168 200 190 177 183 161 164 170 155 175 210 160 166 181 184 170 173 159 171 197 186 157 173 164 188 195 168 194 179 159 184 190 208 180 190 183 170 174 190 192 181 176 162 195 164 162 160 159 204 202 198 181 175 175 184 179 153 179 186 179 196 161 189 177 180 194 186 184 195 181 183 170 185 188 208 188 172 164 189 183 183 202 182 175 176 174 209 193 186 179 217 187 182 197 196 175 191 197 186 180 186 176 144 165 160 166 157 192 180 184 181 178 176 185 161 157 187 184 185 170 174 190 168 199 195 202 154 183 188 160 214 173 198 181 186 178 172 200 169 174 182 202 179 183 180 158 176 157 197 166 185 197 172 177 189 200 177 173 186 178 178 171 172 193 172 172 152 160 182 179 175 154 169 178 151 184 197 188 184 174 175 167 145 146 181 191 161 173 178 190 169 147 173 188 157 183 154 172 164 166 176 191 172 184 172 176 183 175 174 166 174 176 168 201 199 178 166 156 153 167 167 166 174 167 172 153 186 170 174 175 153 186 150 171 171 177 159 174 138 152 150 184 191 175 170 187 166 180 179 165 183 176 189 172 169 181 165 155 161 169 178 142 158 162 163 166 176 158 171 173 181 164 176 166 158 147 172 156 178 182 174 171 191 186 183 176 153 176 171 173 166 178 176 158 184 173 175 191 168 170 159 181 174 186 182 166 169 172 172 145 172 179 197 170 178 154 172 160 194 165 182 139 164 195 166 181 178 168 164 188 201 173 183 179 156 173 144 195 155 161 182 153 159 178 167 202 163 179 191 183 178 166 192 177 167 153 190 155 199 168 149 157 152 170 165 165 184 157 180 145 172 165 172 160 195 165 156 151 152 171 166 206 176 186 166 167 155 160 176 161 157 181 166 188 169 182 170 170 161 176 168 165 172 188 163 150 183 165 152 170 166 163 179 164 168 183 193 188 159 196 156 163 165 175 170 173 169 156 166 189 175 174 198 150 153 183 163 173 160 154 161 182 157 173 212 160 188 168 188 163 197 191 177 159 179 165 159 160 153 163 194 177 165 182 186 155 157 184 154 199 160 184 170 180 175 174 154 158 187 174 179 203 183 168 158 159 190 161 173 180 182 180 155 165 162 189 173 153 167 167 168 183 162 182 185 189 174 187 194 195 170 169 189 162 161 180 175 153 162 148 176 179 165 159 167 174 173 166 174 158 160 168 181 174 178 172 189 193 169 169 181 172 172 156 179 193 171 174 171 169 157 155 147 167 179 159 166 198 184 176 194 178 173 166 159 169 173 164 164 182 170 188 193 137 182 184 187 158 135 168 176 171 150 169 174 158 169 161 177 180 177 165 165 185 155 174 159 192 166 172 160 195 149 160 174 188 178 162 158 172 180 160 183 185 189 178 166 168 172 182 166 165 159 191 161 176 189 167 177 142 185 181 163 173 180 153 173 191 200 175 166 155 193 169 176 167 178 165 179 161 163 172 172 154 161 175 167 158 171 152 200 175 174 155 162 167 173 189 167 175 165 147 183 164 174 170 204 171 149 169 173 178 145 179 172 160 167 178 154 169 173 166 171 157 158 154 177 173 169 164 171 187 188 153 175 192 164 169 166 187 164 174 190 178 183 143 165 150 158 170 161 169 190 174 149 175 166 166 161 164 180 174 169 171 188 159 176 169 190 169 155 166 195 195 156 173 161 150 188 194 179 176 171 160 175 167 144 178 155 185 149 162 178 165 187 166 171 168 168 152 185 144 176 188 149 152 176 162 173 171 167 157 158 177 151 148 184 165 176 179 179 166 168 176 157 161 153 147 174 150 171 191 175 185 170 152 169 182 163 170 172 185 176 160 166 154 157 180 174 179 150 186 193 151 181 180 174 160 170 183 188 185 174 171 166 174 181 187 171 158 175 157 177 189 160 156 149 163 175 165 167 190 189 162 169 183 181 190 167 189 173 167 202 166 176 172 176 159 174 181 164 164 163 161 180 177 172 156 163 186 153 174 139 174 176 169 172 185 170 169 188 174 159 169 160 170 175 176 166 176 169 152 185 149 168 169 196 162 157 173 207 165 185 175 195 168 167 155 164 164 159 169 174 172 194 170 167 179 150 160 154 170 172 179 197 162 165 179 164 173 176 182 145 176 187 171 165 174 173 168 152 180 204 175 158 158 193 173 161 191 174 180 173 152 182 182 174 168 177 182 172 157 167 162 194 177 161 176 129 160 184 160 161 150 182 177 189 176 149 172 168 173 191 151 179 179 174 184 177 193 186 162 157 180 186 168 148 180 166 175 184 173 192 164 165 160 183 159 167 182 179 170 188 183 153 190 157 167 186 164 168 153 190 187 165 164 187 177 173 145 129 180 163 157 183 169 179 144 152 175 176 164 182 167 167 137 178 174 154 167 167 166 148 146 166 168 162 171 175 196 187 177 156 175 155 182 154 163 174 181 172 156 160 168 175 177 145 176 176 175 189 158 167 171 173 168 162 158 160 185 169 164 169 172 170 181 168 174 160 171 173 164 171 145 168 175 180 167 206 153 156 162 157 157 192 165 169 181 158 194 175 181 160 162 168 204 165 202 188 176 162 170 158 180 165 200 185 167 182 167 192 178 174 158 185 171 165 176 187 198 159 163 170 172 162 175 183 184 174 188 162 159 157 169 181 138 178 162 175 196 182 168 197 199 182 194 192 199 185 158 168 183 178 172 212 181 169 161 161 163 180 189 179 165 158 179 175 192 195 164 167 169 183 166 157 171 179 170 173 181 170 177 185 172 160 178 164 164 165 195 173 176 182 166 152 152 167 169 207 161 176 181 174 150 193 179 178 173 163 189 173 183 186 173 177 171 173 180 178 169 168 181 155 164 199 182 188 193 168 199 170 153 191 194 190 170 171 152 181 181 160 165 159 170 189 169 175 181 159 188 173 172 169 158 188 182 190 174 180 173 186 197 163 198 184 175 150 169 191 175 167 157 161 167 180 186 184 162 186 169 187 166 174 179 161 173 172 174 171 161 167 172 198 162 168 167 159 181 164 165 177 188 179 180 154 164 188 199 179 174 173 169 178 157 192 170 166 184 171 182 166 174 156 164 176 178 184 168 183 174 198 205 153 170 181 186 169 175 179 168 180 174 197 181 168 188 164 173 181 164 173 178 181 190 179 159 187 161 189 183 154 183 172 159 194 174 182 175 198 160 182 179 170 157 176 168 168 192 175 162 165 179 162 172 179 185 202 162 171 159 166 171 166 194 164 158 167 175 191 186 186 172 173 155 146 186 170 181 178 165 178 182 180 176 166 176 161 180 184 180 153 164 182 188 169 167 172 182 164 153 158 167 202 171 193 141 147 168 192 173 173 155 173 162 162 186 159 178 179 171 158 155</counts>
			</dataPoints>
		</scan>
	</xrdMeasurement>
</xrdMeasurements>