File: data/XRD/_misc/W6922-1D_600°C_1h_absolute_2th-om_10-130deg_PIXscan_56min_1.xrdml
<xrdMeasurements xmlns="http://www.xrdml.com/XRDMeasurement/2.1" xmlns:xsi="http://www.w3.org/2001/XMLSchema-instance" xsi:schemaLocation="http://www.xrdml.com/XRDMeasurement/2.1 http://www.xrdml.com/XRDMeasurement/2.1/XRDMeasurement.xsd" status="Completed">
	<comment>
		<entry>Configuration=Factory configuration, Owner=User-1, Creation date=7/8/2013 4:01:53 PM</entry>
		<entry>Goniometer=PW3050/65 (Theta/2Theta); Minimum step size 2Theta:0.0001; Minimum step size Omega:0.0001</entry>
		<entry>Sample stage=MRD Cradle; Minimum step size Phi:0.01; Minimum step size Chi:0.01; Minimum step size X:0.01; Minimum step size Y:0.01; Minimum step size Z:0.001</entry>
		<entry>Diffractometer system=XPERT-PRO</entry>
		<entry>Measurement program=C:\PANalytical\Data Collector\Programs\Jorrit\2thom\_absolute_2th-om_10-130deg_PIXscan_56min.xrdmp, Identifier={15BCCF57-2807-42BD-B5B9-ECC0B3DC9284}</entry>
	</comment>
	<sample type="To be analyzed">
		<id></id>
		<name></name>
		<preparedBy></preparedBy>
	</sample>
	<xrdMeasurement measurementType="Scan" status="Completed" sampleMode="Reflection">
		<comment>
			<entry>_absolute_2th-om_10-130deg_PIXscan_56min</entry>
			<entry>PHD Lower Level = 4.83 (keV), PHD Upper Level = 11.27 (keV)</entry>
		</comment>
		<usedWavelength intended="K-Alpha 1">
			<kAlpha1 unit="Angstrom">1.5405980</kAlpha1>
			<kAlpha2 unit="Angstrom">1.5444260</kAlpha2>
			<kBeta unit="Angstrom">1.3922500</kBeta>
			<ratioKAlpha2KAlpha1>0.5000</ratioKAlpha2KAlpha1>
		</usedWavelength>
		<incidentBeamPath>
			<radius unit="mm">320.00</radius>
			<xRayTube id="1010048" name="Empyrean Cu LFF HR (9430 033 7310x) DK442154">
				<tension unit="kV">40.0</tension>
				<current unit="mA">40.0</current>
				<anodeMaterial>Cu</anodeMaterial>
				<focus type="Line">
					<length unit="mm">12.0</length>
					<width unit="mm">0.4</width>
					<takeOffAngle unit="deg">4.2</takeOffAngle>
				</focus>
			</xRayTube>
			<xRayMirror id="27010001" name="Inc. Beam Cu W/Si (parabolic MRD)" hybrid="false">
				<crystal type="Graded" shape="Parabolic">W/Si</crystal>
				<acceptanceAngle unit="deg">0.800</acceptanceAngle>
				<length unit="mm">60.0</length>
			</xRayMirror>
			<sollerSlit id="21010002" name="Soller slits 0.04 rad.">
				<opening unit="rad">0.0400</opening>
			</sollerSlit>
			<mask id="22030007" name="Fixed mask 2 mm">
				<distanceToSample unit="mm">220.00</distanceToSample>
				<width unit="mm">2.00</width>
			</mask>
			<divergenceSlit id="22010007" name="Fixed slit 1/8°" xsi:type="fixedDivergenceSlitType">
				<distanceToSample unit="mm">220.00</distanceToSample>
				<height unit="mm">0.19</height>
			</divergenceSlit>
		</incidentBeamPath>
		<diffractedBeamPath>
			<radius unit="mm">320.00</radius>
			<sollerSlit id="21010002" name="Soller slits 0.04 rad.">
				<opening unit="rad">0.0400</opening>
			</sollerSlit>
			<receivingSlit id="22010001" name="Fixed slit 4°">
				<height unit="mm">5.88</height>
			</receivingSlit>
			<detector id="7010017" name="PIXcel3D 1x1 detector" xsi:type="areaDetectorType">
				<phd unit="%">
					<lowerLevel>30.0</lowerLevel>
					<upperLevel>70.0</upperLevel>
				</phd>
				<mode>Scanning</mode>
				<activeChannelsEquatorial>255</activeChannelsEquatorial>
				<activeChannelsAxial>255</activeChannelsAxial>
				<pitchEquatorial unit="mm">0.05500</pitchEquatorial>
				<pitchAxial unit="mm">0.05500</pitchAxial>
				<readOutPeriod unit="seconds">0.135</readOutPeriod>
			</detector>
		</diffractedBeamPath>
		<scan appendNumber="0" mode="Continuous" scanAxis="2Theta-Omega" status="Completed">
			<header>
				<startTimeStamp>2024-08-05T14:45:47+02:00</startTimeStamp>
				<endTimeStamp>2024-08-05T15:41:51+02:00</endTimeStamp>
				<author>
					<name>PRO-MRD</name>
				</author>
				<source>
					<applicationSoftware version="6.1b">Data Collector</applicationSoftware>
					<instrumentControlSoftware version="7.0E 20130304">XPERT-PRO</instrumentControlSoftware>
					<instrumentID>0000000011142674</instrumentID>
				</source>
			</header>
			<dataPoints>
				<positions axis="2Theta" unit="deg">
					<startPosition>9.99826193</startPosition>
					<endPosition>129.99755682</endPosition>
				</positions>
				<positions axis="Omega" unit="deg">
					<startPosition>4.99913096</startPosition>
					<endPosition>64.99877841</endPosition>
				</positions>
				<positions axis="Phi" unit="deg">
					<commonPosition>0.00</commonPosition>
				</positions>
				<positions axis="Chi" unit="deg">
					<commonPosition>0.00</commonPosition>
				</positions>
				<positions axis="X" unit="mm">
					<commonPosition>0.00</commonPosition>
				</positions>
				<positions axis="Y" unit="mm">
					<commonPosition>0.00</commonPosition>
				</positions>
				<positions axis="Z" unit="mm">
					<commonPosition>9.300</commonPosition>
				</positions>
				<commonCountingTime unit="seconds">32.895</commonCountingTime>
				<counts 244 250 227 247 233 264 245 248 231 215 243 248 263 244 233 218 239 234 224 248 264 268 232 206 244 229 247 279 214 249 232 244 236 239 195 225 224 225 240 231 226 239 219 230 247 241 200 230 257 215 227 217 220 234 247 246 240 234 229 239 242 261 248 257 256 222 244 214 223 230 261 242 237 234 205 248 257 241 223 230 228 227 226 221 222 247 228 219 258 222 217 245 239 212 218 227 256 233 188 195 241 198 231 217 255 220 244 226 223 224 189 230 232 230 243 258 226 218 232 246 222 226 212 216 232 241 205 214 233 239 217 243 218 234 264 256 195 236 255 233 209 236 217 211 228 231 222 224 246 218 214 215 232 215 241 228 225 209 203 219 236 268 224 222 218 212 224 228 257 210 224 215 225 195 202 207 227 209 225 207 206 224 212 242 196 199 220 224 239 225 221 249 227 210 226 264 226 211 232 204 202 216 222 223 220 217 218 230 223 232 205 191 193 224 210 229 219 229 200 207 215 224 230 211 211 199 195 201 226 206 261 216 226 215 213 256 230 206 239 213 220 227 233 259 216 207 241 200 224 216 204 197 230 197 218 228 215 236 212 234 215 203 227 212 209 212 247 205 205 213 216 208 195 242 245 208 238 207 218 183 205 218 200 220 190 209 213 213 220 186 183 234 209 205 227 227 195 222 217 207 203 199 227 212 194 225 225 197 208 235 216 217 220 193 201 202 214 194 193 203 213 237 208 210 198 187 222 203 225 204 190 200 217 226 201 216 221 208 204 198 209 222 195 192 220 202 211 214 200 217 207 231 194 185 201 186 186 221 257 201 189 208 231 212 184 211 194 222 235 222 212 223 197 201 220 211 200 206 214 224 208 208 232 236 231 193 202 218 220 193 223 190 211 222 206 211 190 199 203 188 231 215 205 208 178 199 224 199 194 191 226 186 203 195 221 186 189 188 190 222 182 204 198 181 206 210 240 197 197 191 188 210 187 214 187 210 193 189 194 204 237 194 193 171 183 183 204 197 199 216 207 207 201 202 183 175 177 200 220 217 210 176 224 211 209 185 195 204 207 202 185 194 212 188 178 211 201 196 182 177 162 209 197 201 200 198 204 202 190 205 230 195 215 181 193 211 226 198 186 209 223 196 198 204 195 205 191 183 180 184 204 215 187 196 188 170 205 195 165 208 195 186 225 222 177 186 195 221 194 212 194 200 179 198 189 220 193 193 209 210 191 206 203 215 191 200 180 172 190 213 188 230 176 212 182 192 162 196 201 176 198 203 200 193 203 189 192 183 189 196 200 226 210 188 183 186 208 206 177 218 209 182 196 192 179 197 204 205 218 202 203 188 194 182 195 197 215 179 228 207 192 216 190 205 204 206 221 176 208 180 202 205 194 220 208 213 181 226 200 182 200 200 210 203 181 217 198 203 223 198 209 206 177 178 199 205 215 200 200 208 204 183 193 189 215 194 227 228 176 194 223 187 200 212 192 200 201 204 213 234 196 204 180 186 224 212 187 225 197 190 182 211 206 216 185 168 194 211 219 203 206 201 222 216 226 216 208 194 205 172 186 194 182 180 194 198 208 211 204 169 192 215 207 203 170 202 189 216 204 210 205 208 216 195 207 220 206 208 191 215 214 199 239 212 210 221 212 194 207 221 214 210 197 209 237 246 215 185 220 243 206 212 222 215 200 259 205 203 215 218 192 218 209 210 202 221 230 196 208 229 219 217 222 207 202 222 226 177 207 212 196 212 175 217 182 220 203 213 199 199 212 179 203 199 219 216 241 198 241 233 221 176 197 225 204 233 205 218 206 218 213 222 205 197 225 208 212 212 211 180 205 197 212 202 206 199 206 227 199 220 226 207 215 192 189 214 206 211 237 208 230 195 207 174 231 223 232 193 190 196 203 208 259 234 217 219 222 189 194 204 180 196 196 208 195 226 222 209 200 208 241 189 227 209 210 210 236 197 208 208 210 248 224 194 220 213 243 199 211 212 214 216 221 215 243 237 230 221 224 207 217 202 218 186 215 217 188 207 202 210 203 231 214 219 211 213 236 220 210 208 207 196 201 241 227 219 186 225 208 239 193 221 201 213 213 199 208 225 218 211 224 229 230 218 223 223 233 200 211 215 215 230 218 222 205 211 209 202 214 241 238 190 215 203 206 240 228 206 201 225 199 231 227 212 239 217 239 244 201 239 215 230 214 211 201 227 221 233 203 220 228 204 208 222 213 244 209 223 243 232 206 198 214 227 210 226 195 241 201 193 206 212 215 196 205 204 241 225 190 198 242 246 221 196 238 187 219 204 209 201 231 195 182 205 225 234 231 198 221 200 221 211 194 223 194 222 230 208 204 191 206 209 225 234 210 199 201 210 225 217 235 200 205 200 234 231 230 228 225 199 232 233 225 193 234 217 231 229 255 181 216 215 199 224 218 200 202 205 224 221 228 225 224 209 210 212 216 241 211 211 197 187 217 223 198 220 225 200 230 227 240 219 205 221 202 217 196 246 226 224 213 208 201 212 206 204 218 216 225 198 210 223 228 202 202 238 206 224 209 228 234 237 213 238 207 206 230 243 213 226 220 196 215 238 209 218 222 240 208 204 199 211 245 209 221 192 211 211 210 204 221 237 220 201 228 212 221 216 240 261 194 235 235 241 198 207 234 215 209 222 207 250 186 186 195 226 215 213 244 219 238 192 197 236 221 186 203 228 201 216 214 207 190 211 215 185 209 226 204 222 210 214 199 230 205 224 227 225 220 246 222 209 236 196 209 204 226 183 206 223 211 230 216 207 241 216 219 212 216 219 217 218 200 184 199 177 203 222 212 243 206 192 221 187 221 199 227 203 220 205 241 215 222 219 194 194 232 188 210 201 202 234 223 168 238 216 203 186 192 226 219 199 194 199 201 224 225 202 220 209 220 231 188 217 227 183 198 215 240 195 215 211 180 240 230 231 236 214 208 218 209 216 220 225 214 218 202 201 197 221 219 213 219 216 218 236 230 206 200 218 184 220 217 213 238 205 203 210 228 236 200 214 210 220 233 225 207 214 221 220 207 220 231 195 227 227 220 213 197 215 225 192 225 243 224 205 236 212 228 214 226 215 235 178 226 194 222 208 204 204 174 229 212 205 214 187 199 185 211 193 217 220 212 210 200 224 204 213 224 194 188 212 184 208 203 207 188 179 209 227 211 195 198 189 200 223 200 196 216 193 209 224 184 209 221 199 215 195 221 215 220 203 211 201 225 186 200 188 207 193 185 208 207 202 207 214 207 188 204 200 196 207 211 212 180 228 200 191 231 199 193 204 225 198 204 195 187 198 220 214 221 225 203 219 216 230 186 200 204 194 182 191 190 214 226 193 193 206 216 202 209 213 221 191 207 222 185 218 212 203 208 215 204 195 227 195 174 209 174 200 198 228 217 204 209 202 195 194 198 188 191 230 183 196 178 193 213 227 192 218 229 207 200 211 214 191 205 194 193 186 199 198 207 220 206 200 207 226 210 201 187 175 194 203 210 217 195 195 181 222 190 205 187 187 180 217 219 197 186 195 182 192 174 180 198 216 187 195 205 224 180 193 212 211 226 218 197 192 207 189 192 193 212 212 168 196 191 224 199 193 190 208 204 190 191 193 194 185 217 204 197 202 203 184 193 210 201 197 219 190 176 194 184 180 203 220 214 179 184 186 190 182 189 216 199 204 224 212 209 210 198 186 189 196 180 186 215 210 199 207 197 203 180 199 198 163 216 219 197 195 204 198 207 194 168 193 201 193 214 195 202 208 203 200 200 208 186 199 203 199 208 198 200 205 232 227 188 192 194 213 188 183 197 192 174 182 206 184 181 183 173 199 196 193 180 212 191 205 193 210 203 207 213 184 194 200 214 201 191 170 189 202 219 206 186 197 207 210 203 197 195 186 213 187 207 189 187 180 221 200 183 191 227 181 187 195 198 217 203 187 191 175 175 192 194 198 173 181 178 191 191 199 193 206 197 190 197 194 186 200 209 210 192 172 189 190 190 189 195 197 183 189 192 190 170 192 178 174 221 221 190 192 192 188 166 204 173 196 195 168 179 185 205 196 210 174 174 192 184 190 205 196 187 184 205 199 200 175 186 186 223 200 182 201 181 201 189 197 176 214 182 173 199 203 168 192 210 170 194 195 208 160 207 173 194 195 173 205 179 201 193 175 157 176 173 181 213 203 182 195 198 208 196 160 190 194 193 178 203 190 174 201 170 202 188 207 183 165 174 205 176 169 174 217 184 177 203 193 196 204 203 166 215 185 198 187 173 189 171 173 184 205 190 183 202 195 196 194 188 203 176 156 175 172 169 181 194 194 177 189 177 162 181 169 174 190 184 202 175 198 209 211 163 197 162 183 171 198 172 184 168 190 153 187 165 186 191 199 201 207 207 159 176 158 166 191 183 214 188 197 189 184 185 190 168 168 174 179 205 199 179 187 193 195 185 179 184 176 182 197 211 176 189 192 197 189 165 180 176 191 201 169 158 186 144 171 176 160 180 173 197 191 166 183 187 202 190 161 189 187 218 193 172 182 166 200 195 183 188 192 180 179 174 174 170 186 208 178 178 165 181 185 193 184 201 196 183 173 165 184 178 183 196 180 178 172 161 171 188 183 184 180 183 184 171 188 149 173 175 179 197 151 187 205 189 192 165 149 176 191 182 209 188 158 181 176 183 176 194 177 191 181 168 180 167 179 180 187 198 182 205 180 165 180 167 165 181 160 183 194 182 169 180 184 205 191 152 170 174 194 158 181 182 176 196 167 152 185 202 203 190 183 186 184 180 178 183 175 181 177 168 170 187 160 179 193 163 173 176 165 169 187 172 210 190 181 180 148 205 148 169 164 164 186 191 191 170 163 161 178 178 183 188 178 197 176 183 178 204 183 177 181 189 168 172 203 163 176 172 200 195 167 155 197 173 196 162 160 173 186 187 181 160 185 155 186 154 159 180 170 186 190 168 155 170 185 199 189 176 156 175 168 191 177 174 173 178 188 190 183 162 163 167 165 176 186 166 176 181 177 159 170 176 162 197 199 202 181 178 188 190 185 186 210 209 198 153 175 181 201 153 156 191 173 164 200 177 164 163 178 169 162 171 186 179 190 187 183 159 180 194 177 177 192 190 187 170 165 200 199 170 166 189 191 179 201 181 152 190 172 192 164 171 165 197 167 173 172 172 173 148 195 169 190 184 182 164 185 155 167 195 166 177 192 181 197 175 205 164 187 167 178 201 179 176 187 174 187 168 190 198 180 195 177 164 179 196 179 216 198 190 156 170 186 170 185 168 180 182 206 169 191 187 181 194 160 151 184 167 177 169 168 186 182 168 176 186 192 147 178 171 166 189 171 178 166 165 185 171 202 199 197 187 158 168 164 167 153 187 182 157 194 180 193 173 171 166 190 194 174 186 173 171 158 166 197 160 159 156 189 189 161 181 161 181 179 167 173 197 211 166 195 185 178 201 172 172 169 203 182 180 195 166 167 193 173 203 196 181 155 172 162 187 183 179 186 183 169 183 195 153 181 177 170 169 180 169 162 192 176 176 171 188 188 153 162 159 188 160 188 182 183 167 204 174 169 176 195 172 154 174 182 173 154 169 188 191 181 171 191 193 200 197 183 158 186 176 179 199 182 185 207 172 188 178 162 179 179 185 175 189 178 172 180 206 184 178 177 183 167 167 190 184 174 196 167 194 172 164 189 167 195 175 158 156 183 186 159 202 204 187 173 202 158 154 186 188 211 175 194 175 190 181 184 177 180 182 154 174 179 172 170 188 153 189 186 164 192 187 188 186 171 204 183 198 171 170 184 185 191 175 198 172 175 168 181 183 188 155 168 177 179 184 178 216 182 173 178 186 166 172 184 169 176 170 181 184 156 164 151 174 187 170 188 188 188 166 178 181 185 181 188 170 188 198 197 187 183 181 181 163 160 162 167 204 182 176 180 176 176 198 197 189 192 207 177 142 165 181 176 182 170 191 199 182 182 174 175 170 200 179 189 157 184 195 161 188 193 201 158 197 192 190 181 192 190 163 191 189 160 192 200 160 182 153 192 184 177 183 162 197 161 185 171 169 176 185 170 195 212 150 194 198 202 164 176 171 180 181 168 171 184 160 176 196 206 177 185 158 173 192 184 161 167 194 162 165 185 185 141 184 184 184 175 165 183 180 177 206 181 186 180 198 210 191 174 167 155 186 184 175 174 196 154 172 185 170 173 168 169 170 175 161 189 192 165 188 180 179 180 166 190 174 155 198 189 189 178 186 192 169 168 183 163 178 176 189 183 179 175 158 192 173 170 164 183 181 171 144 167 181 173 186 167 155 153 167 148 196 164 180 171 159 191 168 183 171 178 175 190 170 193 188 181 161 183 165 175 159 171 185 154 163 180 175 175 185 180 177 191 199 173 175 177 203 192 192 189 181 183 194 192 174 174 170 176 181 162 192 159 205 163 191 162 152 185 157 175 194 170 206 207 168 184 171 166 195 145 185 185 186 188 165 171 193 171 207 166 192 191 178 183 162 211 203 177 164 182 188 177 182 180 183 183 172 182 169 195 177 192 158 161 199 184 195 190 190 161 185 153 190 170 172 182 193 176 174 188 166 161 184 184 200 194 165 174 171 168 172 185 168 190 171 171 197 171 185 161 179 195 176 208 179 183 176 198 174 192 174 193 156 182 201 196 166 174 195 183 179 176 164 172 177 168 166 182 190 166 188 187 178 174 189 165 188 193 194 184 196 205 167 193 185 197 186 175 169 172 175 188 195 172 186 187 194 195 182 197 181 179 176 206 187 182 189 199 177 186 197 203 181 212 194 179 194 194 188 173 194 207 191 177 228 192 202 185 183 168 177 187 165 179 191 177 172 166 202 198 180 197 196 199 192 182 188 177 183 177 189 188 179 183 179 188 201 196 181 196 174 188 171 166 204 177 164 195 176 142 169 180 187 219 186 201 167 199 180 176 206 202 177 164 179 201 220 200 188 187 205 174 201 188 198 207 188 205 184 189 191 196 185 183 199 185 166 170 187 171 191 199 186 172 187 195 175 211 185 178 190 182 209 190 190 186 187 200 169 181 189 173 189 202 186 180 201 182 209 154 191 173 162 200 192 168 196 215 177 168 179 197 164 197 164 188 205 166 180 171 184 181 201 187 194 178 181 214 178 169 199 185 199 183 207 175 187 197 211 199 189 173 192 181 184 174 185 185 194 177 181 198 178 218 214 195 167 202 178 179 201 172 203 190 194 196 178 198 175 183 219 185 187 188 190 210 185 188 200 198 167 185 166 197 194 166 198 182 207 191 180 178 175 218 205 173 166 179 186 182 207 179 191 208 182 199 198 190 174 184 177 194 202 207 211 173 180 180 202 178 204 161 207 215 185 181 190 185 183 190 190 176 186 194 201 201 176 178 189 192 181 185 192 168 184 184 175 182 177 225 163 191 163 199 204 204 189 159 193 194 198 208 182 183 187 178 183 189 160 194 188 176 190 197 180 190 176 190 208 199 202 187 194 191 199 172 189 162 179 204 191 193 169 192 174 179 198 207 194 191 192 191 222 201 165 166 172 184 197 192 201 178 174 198 193 196 204 196 190 201 198 147 177 186 199 168 181 185 226 204 186 199 203 177 162 158 176 179 181 211 182 188 206 207 163 202 181 196 210 197 187 192 180 173 209 188 152 207 206 198 217 172 219 211 239 216 196 206 206 213 209 199 216 219 229 203 190 194 183 224 210 221 204 202 204 193 235 222 222 222 218 221 214 207 228 219 221 227 199 216 212 219 228 213 213 264 229 227 250 239 215 255 209 213 259 223 245 260 257 295 280 256 261 284 293 281 296 308 318 312 309 333 313 364 339 350 368 364 423 372 328 373 392 393 395 394 383 376 403 365 367 352 391 342 336 342 376 322 340 329 286 314 286 313 268 292 275 277 266 286 272 268 239 255 211 220 228 248 203 222 199 224 212 231 223 222 224 203 198 222 218 173 207 167 235 214 211 210 207 197 224 215 206 201 211 199 210 192 177 202 223 207 213 212 172 210 213 177 184 210 186 206 214 204 224 208 185 206 163 220 205 188 170 193 184 196 183 223 177 184 203 189 206 176 186 193 194 206 181 198 208 180 194 193 203 208 213 209 207 197 226 194 212 194 216 202 171 183 183 188 191 193 168 194 217 216 209 206 199 200 196 209 183 199 207 209 200 203 210 193 196 224 195 196 173 190 191 204 190 192 217 198 222 209 213 177 194 206 170 203 210 204 188 182 207 185 180 204 196 198 220 180 190 186 182 219 192 185 189 196 185 193 204 242 188 186 195 192 165 208 198 179 196 223 217 161 229 201 189 208 184 197 183 192 211 195 172 182 204 182 207 164 201 201 194 171 177 198 186 175 207 186 184 217 180 199 180 182 224 191 205 192 198 204 177 191 191 182 170 166 191 197 173 206 197 184 180 160 198 203 223 179 200 206 202 164 198 184 209 199 182 175 194 173 197 198 184 211 190 171 182 190 191 192 176 206 194 198 201 177 189 190 207 204 227 168 192 198 184 177 213 199 200 193 200 198 208 197 181 197 183 215 215 206 211 196 191 200 200 204 191 177 198 189 185 197 208 180 199 181 190 201 221 189 183 186 184 199 201 202 184 216 190 194 191 159 192 198 223 197 197 204 212 195 202 206 174 202 213 177 193 200 199 194 195 176 227 217 226 210 214 197 176 203 164 199 188 190 204 204 209 220 229 197 187 204 202 187 196 189 209 186 212 178 208 232 190 179 201 174 199 201 222 211 225 176 209 209 216 178 205 181 197 215 180 207 203 218 193 204 202 202 177 191 182 212 190 196 193 206 200 199 205 211 187 198 189 211 178 212 195 177 185 198 192 184 172 192 220 211 184 181 201 177 197 193 206 185 210 199 190 210 205 192 197 171 197 182 175 181 211 200 214 202 195 186 180 195 206 197 173 170 190 197 192 183 200 206 189 208 212 179 187 219 186 197 192 202 206 187 192 196 214 188 195 182 197 195 182 223 189 202 188 198 172 191 220 202 221 189 202 205 190 202 191 188 208 213 181 200 196 214 202 217 190 173 182 176 213 174 194 208 175 193 190 196 210 195 196 187 198 191 196 207 210 204 216 195 207 214 193 182 182 191 197 204 213 193 187 185 186 230 175 174 195 185 204 218 210 200 187 192 203 181 193 193 183 181 197 211 199 205 202 209 172 204 204 183 209 191 192 220 192 188 180 196 189 183 191 196 187 229 212 188 198 191 202 194 210 176 190 201 185 219 199 204 208 213 188 180 202 196 189 192 209 206 211 198 198 181 178 205 189 187 200 171 180 174 187 202 220 216 187 221 178 204 189 186 187 189 210 211 216 194 193 176 187 222 185 180 160 204 194 194 194 215 185 199 199 238 215 178 202 227 202 203 200 192 192 202 191 208 195 217 188 196 195 189 193 191 194 189 211 202 189 195 208 179 205 177 207 183 186 193 217 199 191 200 205 190 209 202 208 178 218 192 211 222 206 179 187 184 196 197 203 182 193 167 191 220 196 181 219 197 193 186 205 193 232 202 192 180 217 193 198 207 185 200 208 203 205 190 218 185 209 204 214 214 180 228 187 217 211 217 197 173 192 201 207 213 204 199 202 205 192 209 209 184 198 207 215 189 212 208 189 200 207 209 209 217 175 162 186 223 219 202 214 191 199 173 182 212 177 208 189 180 174 200 177 214 189 222 200 203 225 182 181 173 199 189 210 212 166 200 216 190 198 187 220 216 195 209 197 190 203 232 183 202 190 178 186 204 214 206 206 209 204 167 215 200 186 199 189 164 184 189 179 189 191 156 198 207 194 207 156 194 188 223 180 203 175 224 204 206 225 195 204 224 193 205 220 192 189 186 215 196 196 179 213 223 191 175 222 180 199 179 190 207 175 179 191 201 196 175 209 203 169 226 194 181 203 194 199 166 199 191 200 199 181 192 190 188 216 219 215 193 169 198 196 200 188 218 190 182 191 220 188 199 171 173 182 186 192 160 204 204 194 185 176 206 198 177 172 167 178 193 196 206 185 200 192 186 181 210 194 211 187 217 179 224 192 186 190 193 196 187 184 218 213 211 184 202 194 231 176 204 180 198 183 198 200 199 208 180 209 217 182 183 188 216 187 220 159 178 188 226 218 191 194 198 208 193 192 198 187 218 194 180 222 213 195 203 180 200 189 199 175 182 195 162 209 199 170 195 193 202 191 220 210 203 185 207 199 200 181 179 198 194 210 216 202 211 199 216 210 204 209 211 194 171 184 181 201 198 163 218 204 171 224 206 176 194 212 217 206 191 211 202 200 179 205 200 214 207 212 179 211 216 219 210 174 167 206 201 186 210 187 213 181 203 215 202 215 187 203 203 192 198 213 196 176 176 189 201 202 207 200 200 179 179 185 175 197 204 202 189 214 202 203 186 213 188 200 193 184 211 201 228 191 222 201 199 202 187 204 210 190 189 184 172 207 177 203 202 202 195 196 177 202 198 209 209 202 197 200 189 204 171 202 194 195 197 201 211 194 202 173 212 198 200 188 218 201 171 217 207 197 184 189 195 185 205 216 160 177 185 196 206 203 204 198 196 199 180 172 213 206 196 197 209 188 212 209 209 190 188 194 185 175 178 193 216 189 188 177 194 215 202 203 189 197 175 189 201 203 178 202 202 194 207 190 186 228 205 177 186 182 202 204 201 212 176 185 200 187 205 196 204 210 212 203 208 179 195 195 194 211 183 181 171 206 203 190 217 183 193 186 179 219 202 180 199 188 183 193 218 196 204 192 195 205 193 203 159 179 202 193 202 180 203 193 198 178 212 192 189 213 188 212 190 173 186 204 205 195 190 179 201 210 206 191 169 199 205 210 211 186 202 199 191 217 220 237 192 195 219 215 198 183 201 192 208 174 220 197 201 202 183 196 186 188 192 239 185 200 200 189 185 170 187 224 172 195 207 200 193 179 175 198 200 225 208 208 174 200 187 207 207 198 212 203 208 211 166 190 180 209 227 195 184 193 229 190 197 217 204 200 193 190 192 194 195 196 198 189 192 192 189 185 181 190 182 220 195 195 190 170 194 188 220 204 202 184 224 198 213 197 174 188 207 199 189 191 196 194 183 196 188 203 208 164 202 186 191 169 186 173 202 201 187 194 219 194 202 190 197 176 197 191 184 213 184 204 203 207 182 190 200 207 191 210 199 206 220 187 194 180 199 176 214 185 187 190 213 197 205 212 208 206 182 190 210 213 206 192 200 222 195 189 187 185 211 195 197 210 212 194 196 203 209 206 190 189 230 187 196 200 198 224 193 176 229 191 201 207 191 219 198 202 182 211 194 205 203 185 214 204 188 168 203 200 219 222 212 193 208 214 217 204 213 200 182 184 197 203 214 191 189 180 180 206 204 186 210 209 195 189 184 180 181 210 192 210 209 198 198 187 205 191 202 177 202 180 209 202 198 210 189 212 196 201 223 190 188 192 197 203 200 210 193 237 225 246 201 185 193 186 202 221 204 212 187 193 196 222 204 193 201 194 188 221 188 208 220 170 169 211 199 182 210 194 205 203 247 196 202 197 186 221 203 222 195 177 228 198 199 194 201 205 204 200 216 204 181 193 191 202 183 188 212 203 200 219 187 213 199 181 213 205 175 214 178 202 199 183 198 219 201 204 193 204 185 230 192 192 224 214 205 206 214 211 194 202 225 191 183 208 207 195 223 196 201 209 206 214 182 207 193 189 213 198 219 206 206 208 208 197 201 212 201 214 198 197 207 223 193 202 215 222 190 208 201 221 208 184 192 208 212 192 211 176 221 204 209 194 205 192 211 201 207 195 213 212 210 205 226 208 191 229 190 191 207 218 203 218 204 194 206 203 196 235 220 208 210 193 200 178 224 205 219 211 213 190 200 201 206 222 217 220 191 221 181 199 231 184 212 187 194 202 202 202 184 215 208 220 195 193 196 193 191 231 201 186 207 220 215 197 182 193 200 213 207 224 217 201 183 206 194 201 213 215 196 190 238 219 229 161 172 234 232 172 215 214 211 207 196 204 206 198 180 189 204 205 210 190 187 183 195 190 207 210 234 190 208 188 224 186 206 201 213 205 220 180 210 203 187 204 217 215 212 207 218 193 200 201 209 193 189 193 215 193 213 194 206 218 201 169 213 195 221 203 197 191 207 211 221 201 216 194 220 200 198 206 214 172 209 204 205 213 201 208 220 184 211 192 192 222 183 186 208 232 200 201 199 201 190 193 203 204 210 207 198 221 205 204 203 226 192 204 197 201 236 213 196 210 184 190 196 208 211 218 206 206 212 225 191 227 197 190 229 205 216 204 220 215 200 181 207 213 227 177 200 207 218 193 226 197 223 188 225 224 179 225 197 183 215 185 211 210 198 207 199 207 202 236 195 202 198 201 241 188 187 192 231 211 208 215 197 244 213 196 212 196 236 210 222 218 224 219 227 228 205 183 198 219 221 221 213 198 214 219 237 231 228 203 227 191 242 224 224 192 203 222 233 258 203 220 218 211 217 232 228 203 182 218 200 233 231 201 202 226 234 223 219 223 200 192 195 227 224 227 202 216 238 225 217 230 229 219 217 203 215 218 208 227 212 198 217 169 205 226 180 198 219 235 190 201 201 195 234 205 234 196 189 194 209 217 189 207 204 200 177 195 232 240 214 186 184 227 199 209 209 215 185 202 210 186 194 192 199 200 211 221 230 206 180 210 206 201 213 228 199 204 193 200 201 216 194 234 195 191 225 202 192 191 176 200 196 223 203 186 204 197 225 224 208 219 221 220 178 196 182 209 207 213 220 206 197 184 205 187 209 203 232 195 215 206 211 199 195 203 203 177 223 198 202 196 207 214 205 202 203 176 209 214 194 192 203 198 215 194 191 218 209 181 178 195 232 194 194 192 166 191 219 218 193 208 211 212 203 215 193 204 198 218 200 218 190 214 186 193 231 197 174 188 196 213 218 220 216 185 205 216 200 207 188 167 222 204 202 203 198 176 223 203 201 211 211 227 204 214 197 233 184 190 219 193 202 200 209 228 203 204 195 194 216 201 215 181 203 192 187 187 192 186 204 204 202 193 193 192 201 177 188 189 202 198 213 220 219 210 165 186 212 196 200 214 212 224 213 178 165 201 200 212 219 205 225 219 218 182 233 196 203 190 223 179 193 200 193 224 181 211 175 200 165 223 207 214 204 224 183 193 165 195 198 202 193 225 220 196 203 210 234 206 210 190 196 214 201 196 207 186 215 201 231 177 202 209 232 197 199 200 198 216 208 182 183 177 220 202 212 215 194 195 214 189 212 209 207 217 203 222 209 204 192 210 190 205 214 220 186 203 199 197 187 212 218 178 198 189 183 223 206 203 208 216 206 180 205 192 204 203 203 208 208 218 202 189 211 194 207 214 195 202 214 191 218 191 207 214 206 199 189 185 194 211 212 207 193 206 194 219 175 212 215 181 196 196 206 224 231 192 212 198 181 209 191 212 211 198 183 190 189 174 212 185 217 200 200 205 200 196 197 193 196 190 201 204 192 195 196 201 190 196 207 175 202 211 192 196 188 188 206 224 200 208 201 177 209 211 189 195 234 176 202 179 220 205 200 196 197 213 219 190 212 214 187 202 233 209 202 199 200 215 206 197 176 215 196 215 197 197 173 181 184 203 205 194 198 186 195 184 206 213 206 193 194 211 225 197 202 187 198 216 185 231 192 206 181 221 180 212 202 219 192 196 207 192 208 201 197 186 213 206 193 187 213 198 185 196 230 203 202 205 199 196 220 181 176 218 210 203 190 193 171 240 219 201 203 205 191 202 194 189 209 185 201 220 211 207 211 213 174 228 215 227 183 191 208 215 194 203 200 193 209 200 179 176 186 181 199 206 178 218 185 200 205 198 189 226 194 196 206 179 171 205 192 204 199 189 213 198 202 209 190 199 177 187 178 215 201 194 197 213 201 202 183 178 181 176 183 192 203 205 182 210 176 197 207 194 157 196 203 189 208 203 190 202 185 194 194 183 195 199 196 202 195 186 223 207 190 181 190 187 202 181 209 207 199 189 207 181 191 206 210 227 207 185 207 173 189 208 193 192 189 165 204 202 204 207 196 195 224 199 181 209 191 203 205 159 184 221 201 211 192 206 197 165 202 196 199 200 200 190 177 192 177 176 190 201 187 194 225 185 211 217 178 197 216 193 191 181 189 194 186 202 206 206 187 202 199 214 199 211 195 202 197 192 215 192 189 190 180 214 219 218 209 198 228 173 180 193 219 197 235 203 189 205 200 202 207 209 192 191 197 191 195 180 188 163 197 203 190 181 199 201 222 207 179 193 191 186 195 200 194 167 186 222 213 196 200 212 201 211 187 189 200 218 212 184 228 200 195 189 183 214 193 192 212 187 215 174 211 192 221 225 185 195 204 199 214 181 194 206 196 208 212 192 202 171 181 217 186 194 179 199 190 205 215 192 203 191 194 199 180 203 181 187 187 203 183 180 189 174 183 190 216 194 206 197 191 204 193 208 202 202 217 203 212 206 200 192 205 189 178 201 203 202 190 207 213 204 197 209 202 193 194 223 198 199 198 224 199 199 176 182 201 215 180 223 212 197 220 193 195 183 200 196 206 200 230 191 208 208 207 211 191 199 206 174 215 181 211 204 200 205 193 207 216 194 207 199 221 193 194 186 189 233 177 173 172 210 198 207 198 224 200 190 215 199 189 197 178 182 188 204 200 172 203 209 206 194 203 209 209 203 182 214 188 205 209 209 205 206 186 205 194 202 212 228 187 203 177 203 178 178 217 189 178 208 200 179 209 219 192 206 199 188 171 210 202 198 208 188 191 202 188 200 195 209 187 179 194 190 200 166 187 200 216 202 208 194 201 207 179 191 233 200 183 199 201 186 192 199 199 182 178 202 211 183 176 196 192 209 178 230 216 210 225 186 192 209 189 204 214 197 183 212 195 202 209 219 223 228 215 208 176 220 201 206 209 215 191 197 207 196 189 173 212 220 179 188 192 204 171 194 218 208 230 201 206 166 208 200 197 211 220 196 190 204 198 195 198 206 220 198 198 186 189 212 200 183 206 199 203 194 209 167 193 202 203 186 200 189 184 214 188 162 196 168 217 192 202 178 205 194 204 174 195 193 218 208 201 175 220 194 177 193 185 186 201 187 189 184 192 208 195 250 194 169 189 198 189 198 221 210 207 192 183 194 184 178 199 176 197 174 203 202 188 196 172 192 217 194 185 218 199 188 191 181 201 222 226 203 203 178 202 205 206 190 206 200 201 155 201 226 189 203 182 188 209 194 182 174 195 196 206 186 193 201 200 224 218 206 205 201 184 232 195 183 177 209 209 176 204 210 194 208 197 185 192 206 180 200 216 201 176 201 197 175 198 204 187 179 208 206 192 211 201 196 225 196 194 205 198 178 181 206 212 174 222 192 185 205 195 189 184 210 203 211 174 202 217 215 194 212 199 220 211 189 222 206 225 195 183 190 196 186 176 180 192 198 201 209 189 171 205 160 210 205 193 169 199 190 194 215 191 215 211 186 185 206 193 189 212 193 213 203 210 210 199 193 208 200 200 184 214 218 234 229 226 186 171 190 199 215 194 197 205 196 176 209 193 189 214 207 207 206 209 208 216 204 200 219 193 191 195 243 218 196 180 198 183 192 176 193 220 218 190 215 187 208 194 216 185 210 205 177 229 191 209 187 225 202 200 193 185 220 214 222 211 202 222 190 169 198 195 186 218 211 215 203 213 198 182 208 206 172 185 175 196 211 229 190 201 197 190 210 219 206 209 216 191 188 207 201 198 194 209 177 205 198 200 202 185 207 201 195 190 186 184 177 192 206 208 207 225 191 202 205 204 201 185 199 193 217 185 199 213 201 201 210 226 198 230 212 188 224 198 197 206 216 192 212 190 187 197 185 211 205 204 199 193 191 197 218 192 179 198 211 194 192 182 204 206 206 180 213 185 223 195 190 225 186 202 209 197 218 205 187 188 210 204 184 191 203 202 167 178 189 222 202 195 211 212 201 188 211 198 198 220 194 198 209 216 191 185 200 186 182 246 204 220 202 197 208 217 207 219 206 188 219 218 211 209 184 178 208 209 207 198 204 210 177 193 212 174 206 203 194 219 200 208 183 216 227 215 218 187 198 203 208 207 166 195 196 193 210 206 193 196 203 200 196 186 198 205 213 167 202 190 228 224 186 217 192 193 223 208 228 197 194 217 203 201 198 194 199 227 181 220 197 176 191 222 215 227 199 196 194 214 195 203 198 215 196 211 215 209 207 195 209 215 221 219 209 207 181 204 196 216 213 198 209 195 227 220 211 217 210 204 211 213 202 203 232 206 195 211 223 202 207 211 204 203 211 227 185 184 200 198 221 208 205 210 202 192 215 238 207 211 197 239 214 213 195 218 224 213 222 168 215 201 267 202 218 223 247 258 219 204 245 221 211 225 228 220 236 248 248 208 231 238 213 224 227 249 231 243 239 208 237 231 227 215 234 234 225 276 224 230 222 243 239 227 240 229 215 227 214 243 238 233 232 218 210 203 246 208 232 234 233 229 220 228 237 205 213 204 239 211 205 217 241 223 235 200 192 223 231 218 208 222 239 213 210 201 211 212 221 200 236 210 203 206 209 223 211 232 223 198 227 195 207 192 191 177 224 191 219 200 211 188 192 226 219 192 223 204 196 206 218 189 203 208 180 231 223 189 197 207 183 195 196 215 208 204 198 211 201 193 216 206 187 199 196 208 181 192 194 190 195 193 194 212 212 191 176 197 183 194 183 208 194 207 203 228 213 228 222 216 220 180 232 199 180 184 203 215 162 214 211 198 188 196 193 188 193 192 211 205 200 193 219 196 209 215 192 217 205 188 213 195 198 193 181 188 212 198 198 211 198 195 197 213 181 220 221 201 243 184 198 217 212 201 209 191 219 198 211 212 190 181 206 199 226 209 217 194 207 221 197 189 203 178 196 205 221 206 193 188 204 179 193 189 210 192 208 175 201 213 204 198 195 229 189 177 219 210 192 204 191 198 205 183 184 221 206 208 202 213 199 194 216 215 212 198 212 222 180 205 194 213 212 214 191 234 221 206 201 219 187 204 200 196 208 220 195 194 216 213 233 210 186 213 197 204 186 204 194 202 238 189 185 233 217 216 208 227 196 203 214 203 202 205 191 200 203 207 198 193 207 203 204 205 182 205 179 207 195 204 212 195 197 238 182 224 199 174 208 217 200 215 213 217 215 204 205 207 204 232 184 196 209 206 228 204 209 183 188 208 202 180 214 182 182 225 198 188 178 225 181 206 189 179 197 232 184 214 211 177 210 194 199 198 191 188 197 195 222 193 199 192 206 205 205 188 218 205 211 189 216 182 204 174 203 205 210 202 185 186 177 202 177 162 194 193 238 220 185 191 189 208 227 184 197 185 193 203 203 211 203 202 205 218 222 197 196 224 200 175 211 216 194 198 199 222 200 208 185 207 196 210 199 213 198 191 190 209 216 195 213 198 210 214 197 166 200 190 214 203 173 191 223 197 219 222 198 190 228 184 214 215 200 196 196 200 187 199 202 224 182 205 184 172 207 195 207 214 204 195 210 207 231 182 173 173 192 211 167 216 189 219 210 200 234 194 189 206 209 209 198 193 200 241 200 212 218 202 195 209 191 227 200 169 206 206 204 201 187 188 202 216 221 208 181 196 231 207 173 186 203 212 215 224 201 198 194 195 201 198 238 195 218 208 204 172 194 189 219 214 207 200 194 196 196 190 224 169 192 232 175 194 223 200 224 241 188 213 227 208 215 195 209 202 214 222 221 196 218 173 210 192 220 200 212 188 216 208 202 226 198 207 213 194 205 196 199 189 186 183 186 203 224 163 210 189 210 199 202 182 194 188 202 209 210 228 187 207 223 204 224 197 180 197 203 209 226 183 196 205 209 201 221 195 209 213 201 214 194 201 200 195 197 196 203 181 206 199 200 205 192 188 200 191 212 226 201 180 203 229 216 198 203 223 199 217 185 198 197 218 216 201 203 219 217 213 216 188 187 194 212 190 229 170 182 220 210 183 212 211 176 203 226 182 199 209 191 200 208 201 201 209 199 224 206 201 209 186 206 203 199 198 187 200 192 212 229 208 230 191 224 204 185 215 188 201 193 203 174 230 177 197 211 209 200 203 194 201 210 186 199 185 209 208 217 201 203 190 207 190 215 209 204 218 222 203 216 221 190 222 212 220 214 195 211 223 199 199 201 216 220 198 195 198 218 198 193 208 204 194 196 196 210 193 203 210 192 200 191 199 212 222 211 210 191 180 194 166 191 226 201 216 202 204 210 212 195 214 238 197 168 197 192 225 212 236 204 194 220 189 182 206 202 202 227 206 193 183 198 195 202 201 167 226 211 199 189 188 206 190 224 184 228 178 193 213 197 199 177 188 203 217 226 180 187 199 205 185 198 196 207 211 200 221 215 210 210 205 211 198 195 197 202 210 210 191 196 243 227 218 191 182 201 199 203 197 209 208 214 199 197 238 208 199 202 184 200 209 215 199 208 203 201 219 216 200 203 215 211 208 190 188 208 222 196 197 221 211 194 208 206 204 202 192 243 195 188 210 201 194 201 211 191 184 214 214 221 213 196 189 219 228 198 231 212 191 191 197 181 203 209 208 214 214 186 230 208 221 205 209 202 179 182 200 215 171 218 191 187 209 199 227 191 208 228 187 194 218 218 224 181 188 201 235 200 184 214 193 213 177 186 188 205 200 227 194 225 225 191 226 190 197 221 213 202 228 186 215 229 211 227 197 174 204 208 208 237 189 217 194 192 210 201 212 167 208 207 204 207 221 205 215 203 192 239 217 191 221 201 213 199 232 221 222 200 202 195 228 206 192 208 194 199 199 193 205 198 193 212 210 194 189 191 192 193 195 202 215 240 211 181 194 166 205 217 193 234 160 198 205 187 200 207 197 200 219 219 209 194 208 208 181 221 207 206 234 214 195 189 198 198 192 204 211 192 204 217 181 172 215 202 222 201 194 199 216 213 186 196 224 208 232 222 200 219 204 212 205 210 188 201 191 204 185 185 197 221 205 211 237 207 194 215 214 181 190 212 217 192 189 206 201 182 202 182 216 187 213 212 213 195 179 204 210 220 195 211 199 194 188 219 190 217 171 195 194 208 199 191 190 191 203 209 235 205 192 204 203 194 195 192 198 197 209 206 211 223 213 219 226 224 175 203 214 213 189 191 220 197 182 215 224 215 204 218 189 227 196 194 172 196 227 213 190 194 199 222 198 188 192 204 198 203 209 190 209 222 205 203 203 201 183 205 222 198 212 220 243 191 206 205 206 193 178 201 216 197 226 202 194 182 212 197 216 216 200 201 211 209 198 198 201 197 228 216 198 199 197 187 217 223 210 216 190 190 200 189 183 190 193 215 191 206 227 176 192 210 215 174 209 208 184 191 200 195 191 212 202 165 195 199 211 200 211 198 243 205 199 201 192 187 203 216 205 200 220 179 206 195 200 225 198 195 207 211 222 222 197 243 205 197 193 203 182 193 224 189 187 216 198 211 202 193 209 205 217 199 199 219 228 210 193 205 212 207 208 181 210 202 193 185 204 194 199 197 180 199 186 217 225 190 186 224 189 168 185 219 192 209 190 230 196 224 211 189 198 194 192 196 211 208 204 185 214 196 204 238 227 210 227 184 192 208 194 205 190 198 217 197 204 225 182 204 196 187 197 210 215 213 213 189 208 220 189 222 180 192 206 186 196 207 218 244 219 184 187 212 219 203 207 196 209 211 201 208 192 230 224 192 196 207 197 192 190 214 202 187 210 192 210 201 204 203 189 193 196 207 214 199 199 205 217 196 213 217 212 197 212 209 199 238 222 211 187 198 217 222 217 204 191 217 213 218 238 194 210 174 210 209 213 224 201 221 217 193 199 213 183 225 214 224 201 197 222 206 207 179 211 212 212 213 195 176 207 259 183 230 193 208 194 214 214 192 224 199 199 193 182 200 223 193 176 183 189 214 204 188 217 199 224 219 198 199 203 186 212 198 233 197 209 199 207 211 199 189 198 216 181 195 197 174 217 188 202 215 216 222 195 227 239 192 193 215 202 190 175 224 197 210 198 217 202 195 204 242 212 182 188 193 208 212 212 219 196 204 201 221 200 250 206 180 211 217 223 225 227 211 210 206 231 168 220 204 209 215 199 193 198 222 188 207 226 197 237 218 242 211 203 240 207 220 177 188 201 219 221 168 241 238 214 237 244 193 213 185 206 213 217 207 242 206 191 210 232 212 225 214 209 256 211 216 215 198 209 224 216 208 233 206 211 196 209 205 221 206 219 204 234 207 221 210 220 210 236 241 226 227 262 247 212 211 223 213 215 214 211 213 236 211 214 195 218 205 219 205 186 213 175 209 231 198 237 223 183 198 208 219 191 221 186 218 207 250 226 217 212 195 202 236 202 233 206 219 209 205 200 204 195 202 214 217 217 195 195 208 225 202 180 205 212 200 206 225 210 215 194 181 203 212 218 212 226 219 229 227 196 225 178 192 223 199 237 225 201 192 221 219 208 197 199 212 204 204 216 219 184 232 192 224 209 225 218 218 229 209 202 185 206 200 200 221 204 181 216 207 217 217 188 195 203 196 208 223 200 195 223 203 188 193 191 224 219 226 199 219 177 256 204 213 230 214 245 203 223 219 221 191 213 207 206 206 176 243 211 198 200 194 194 198 211 228 205 208 216 208 182 236 198 205 196 199 202 185 186 232 194 215 213 211 201 200 213 209 202 198 237 209 207 194 226 229 233 197 195 216 233 219 220 209 242 196 219 208 205 202 196 223 200 199 209 195 212 207 218 197 195 204 186 207 213 186 217 205 187 206 219 224 221 170 198 204 198 182 197 208 231 214 206 216 214 173 177 197 232 203 187 206 214 210 212 197 195 211 222 169 226 182 230 197 210 217 189 182 218 217 221 213 211 206 206 215 214 196 192 195 196 208 234 217 220 206 233 193 233 202 204 202 200 213 238 221 216 205 197 194 199 195 199 246 213 203 187 208 184 211 201 184 196 181 246 200 234 222 210 204 237 195 204 206 223 198 206 200 214 224 196 189 211 213 203 225 217 216 189 222 207 195 205 181 216 229 194 208 183 176 224 220 199 235 206 229 203 221 192 227 205 206 220 202 199 205 191 191 229 211 203 202 214 244 227 249 219 202 198 193 226 235 216 239 191 211 210 184 214 213 204 216 209 227 196 207 214 213 204 196 228 210 227 212 189 209 218 216 223 212 216 235 214 195 202 209 241 201 221 223 196 209 223 199 201 219 221 234 211 188 228 210 221 205 206 221 212 186 218 207 219 209 197 196 186 186 209 229 211 204 205 207 204 199 191 208 196 194 208 193 183 199 213 200 183 216 214 229 223 202 191 181 223 208 218 232 209 210 208 181 188 217 212 224 217 215 188 194 200 212 209 224 189 196 180 228 218 201 204 213 195 196 186 219 199 179 227 221 197 219 229 188 206 207 220 205 209 198 218 219 200 232 203 223 199 224 224 235 223 223 204 196 222 219 221 234 203 199 170 176 214 177 230 241 204 202 192 240 208 211 195 215 223 217 196 201 212 221 189 231 201 197 195 216 179 206 217 206 199 224 221 232 223 197 217 203 191 208 220 205 210 214 193 205 199 208 215 211 199 209 226 218 225 196 206 215 196 222 197 184 226 193 204 202 200 214 186 194 171 180 229 189 201 222 204 239 228 214 233 200 209 232 210 241 203 198 215 202 220 214 204 199 193 224 215 204 240 237 217 207 201 196 230 193 204 210 217 190 211 191 191 207 217 195 208 191 237 219 200 212 237 194 199 214 214 201 215 182 240 213 261 190 216 188 214 204 216 190 237 200 209 202 187 186 226 217 203 203 176 220 212 228 196 215 214 208 218 214 207 200 199 207 183 222 196 197 221 220 182 216 218 217 224 194 215 200 194 214 231 204 217 239 210 208 215 217 202 208 204 198 214 190 186 202 200 197 227 210 214 230 214 229 211 202 189 229 197 221 203 185 238 244 194 174 224 228 227 201 207 192 203 191 228 223 201 204 222 231 215 202 201 216 200 204 199 211 199 220 217 199 206 192 215 215 219 184 210 209 202 192 228 221 225 219 233 205 209 200 188 213 189 196 181 210 192 200 219 182 200 185 238 221 193 220 206 179 192 192 185 203 225 217 221 209 205 241 215 219 210 222 246 232 217 216 201 218 214 192 217 211 225 200 195 216 239 198 194 223 204 224 221 217 224 212 198 230 195 205 224 196 202 213 223 216 182 201 245 227 201 206 177 191 220 219 203 215 222 204 223 216 243 182 213 183 214 210 191 199 222 214 191 196 231 200 236 228 181 227 227 191 223 208 207 226 214 193 215 231 216 183 214 214 195 216 193 216 220 214 201 201 228 206 234 203 231 223 198 217 228 214 256 224 219 241 190 210 171 233 188 210 195 214 217 238 223 203 211 198 231 215 197 189 201 223 177 219 212 193 203 189 216 178 214 209 214 198 203 184 224 226 214 195 188 195 225 183 219 222 220 229 220 239 209 180 181 198 219 227 200 194 206 215 199 223 211 167 219 181 194 205 209 192 206 241 214 197 210 210 215 244 183 221 215 214 226 196 212 201 221 226 205 207 217 210 185 204 187 211 204 205 212 167 200 225 197 224 221 201 188 223 225 211 208 167 203 201 231 193 193 203 213 175 208 225 231 212 170 191 225 208 219 193 225 209 205 217 199 247 220 220 204 203 212 221 186 228 215 208 209 192 195 201 217 223 216 231 189 197 197 255 212 233 169 204 232 184 212 258 189 200 220 186 224 197 234 200 204 207 219 238 187 232 196 188 214 214 233 201 246 225 185 222 205 185 177 214 196 210 208 239 210 239 224 199 223 229 192 192 213 218 211 199 193 192 213 218 194 197 200 187 187 237 211 177 202 205 212 213 195 189 222 231 229 204 196 212 210 229 214 188 219 197 194 212 217 226 176 206 213 187 217 208 223 183 207 218 215 212 216 193 198 198 222 204 201 192 202 228 189 234 202 186 224 203 223 198 212 188 215 195 218 232 226 192 201 198 193 204 217 202 196 196 222 221 211 194 193 226 208 214 214 205 214 194 208 193 216 197 237 224 190 206 200 233 204 215 216 209 205 219 203 200 207 210 245 200 203 194 221 207 219 209 221 205 198 221 192 190 201 231 226 212 216 229 186 217 212 197 224 196 218 208 212 211 230 226 214 205 199 218 204 172 205 204 224 222 210 209 208 201 230 202 198 217 223 232 197 185 201 207 212 213 235 232 229 183 197 204 227 230 202 195 192 206 183 210 237 213 212 219 235 221 227 209 221 227 204 205 200 225 201 216 201 230 190 225 206 196 217 176 225 191 218 208 214 202 216 187 202 211 215 201 191 214 237 217 220 194 209 198 201 205 208 212 205 222 209 218 214 196 199 196 201 204 210 201 213 222 195 210 221 232 224 191 219 219 220 194 239 222 196 202 227 196 203 193 216 215 222 204 227 224 208 205 212 216 205 220 214 210 215 215 209 222 215 232 216 231 207 200 181 226 210 193 241 214 214 218 219 235 231 188 169 211 224 214 221 204 201 239 184 212 233 205 214 184 224 224 229 244 205 195 223 200 215 218 219 203 233 203 220 209 228 221 231 216 217 200 228 202 215 234 216 220 211 236 206 210 201 226 242 230 225 197 185 208 209 209 222 207 221 231 204 216 219 217 201 205 192 224 202 210 238 215 211 197 237 201 213 223 214 236 213 213 218 213 211 200 205 204 213 209 217 209 214 211 207 229 216 215 202 218 205 232 209 210 227 236 207 207 204 224 214 206 224 193 195 229 223 188 222 226 188 219 219 211 189 220 203 202 215 221 220 224 194 215 217 209 281 199 197 204 211 206 204 215 223 204 210 227 211 215 197 191 199 223 206 196 200 234 215 211 199 232 212 210 214 195 200 228 209 218 226 187 233 231 212 221 217 205 217 217 228 198 207 203 203 229 199 180 234 207 193 222 224 199 218 212 217 208 182 214 217 224 209 228 226 220 209 207 200 240 202 201 197 226 223 218 234 196 260 207 231 235 239 215 198 208 220 214 238 207 220 213 190 235 216 212 235 209 241 244 209 216 226 236 206 224 217 207 207 201 198 229 197 217 249 237 214 231 231 220 213 244 213 218 203 221 229 222 212 242 233 233 228 219 212 237 227 227 242 223 228 216 210 217 231 236 241 238 243 217 218 224 238 214 232 230 243 227 246 212 231 207 242 228 230 217 241 259 230 238 237 200 208 226 224 211 205 221 215 240 236 192 237 214 245 242 212 199 217 235 231 220 242 235 232 212 213 205 235 210 264 247 235 221 232 228 218 212 210 231 222 229 205 209 226 200 194 255 215 203 195 246 217 232 216 225 248 211 231 218 218 230 207 180 205 184 236 212 189 208 211 211 219 188 198 236 225 231 221 226 218 220 201 226 229 204 244 211 238 205 188 212 223 226 212 216 205 207 219 221 222 223 193 224 213 219 219 191 198 206 217 212 193 209 219 210 215 217 194 210 201 195 231 222 224 215 209 223 198 218 227 210 227 239 215 216 212 221 240 219 221 219 214 184 215 233 232 238 221 208 224 222 209 255 232 234 208 255 206 230 211 205 227 223 180 201 192 217 208 227 206 234 219 215 204 210 214 223 205 212 243 218 215 203 224 187 223 204 214 217 223 191 219 211 216 223 223 228 214 207 216 225 219 190 192 193 199 217 208 193 214 199 215 216 208 217 225 232 263 219 211 240 228 214 233 194 218 231 210 230 220 225 196 240 203 205 225 210 207 190 216 207 220 205 243 215 218 187 214 233 205 194 244 229 224 211 236 199 218 236 222 180 216 211 213 190 222 229 231 257 221 235 203 214 229 222 215 219 214 227 184 205 203 244 234 211 238 219 208 223 212 215 203 178 235 200 196 209 230 195 179 209 235 208 191 196 235 194 222 179 227 222 226 190 206 200 222 215 198 235 198 221 204 192 224 215 227 215 213 216 201 230 214 206 219 208 216 175 228 222 224 207 204 225 204 207 190 218 221 208 181 197 205 215 183 235 220 208 215 225 218 215 197 222 223 198 233 206 210 267 215 216 223 216 211 222 213 211 220 210 198 221 202 238 189 192 223 210 195 195 189 229 182 204 200 211 205 241 214 204 224 196 183 218 208 210 225 210 184 211 235 221 206 205 193 230 216 190 214 214 199 225 199 208 215 230 215 231 192 193 217 213 221 208 189 197 198 218 175 217 221 220 198 205 200 227 184 226 200 207 213 215 220 189 203 207 234 218 201 207 218 184 188 194 216 228 213 197 188 206 204 210 207 185 198 204 224 219 240 226 207 215 223 207 205 192 238 233 217 233 199 203 210 189 215 188 222 207 198 198 198 194 216 205 222 204 214 217 260 194 222 215 212 212 199 186 233 195 197 210 212 233 226 236 221 208 195 172 202 212 215 181 217 200 203 204 188 195 218 219 183 197 217 202 198 192 186 213 218 187 200 179 197 225 186 217 219 199 222 212 212 232 214 204 220 219 207 202 212 198 202 203 207 199 200 213 198 189 201 230 220 244 203 220 181 199 227 200 205 223 195 224 201 203 182 189 220 232 203 203 217 184 199 213 218 189 213 197 196 187 194 217 208 215 211 205 198 189 220 213 194 207 193 204 208 225 209 223 205 213 204 240 200 210 231 203 229 205 199 219 204 216 236 199 208 214 219 209 172 214 210 206 193 235 209 181 209 215 223 225 180 211 199 210 221 189 220 212 178 211 218 217 214 225 228 239 211 225 201 202 217 210 232 204 191 204 205 198 234 208 208 216 234 207 211 218 231 198 203 216 221 221 192 208 196 192 214 177 201 215 220 189 228 212 191 225 199 205 207 222 185 198 229 204 211 204 203 200 226 198 223 200 183 192 213 222 220 205 190 227 201 206 225 211 224 228 200 209 191 226 214 229 188 192 209 210 246 184 186 215 203 206 207 212 228 221 194 191 208 198 218 204 211 198 213 200 199 235 195 210 210 197 199 215 208 201 206 198 209 216 200 199 200 225 224 200 206 211 220 199 221 215 205 229 210 236 250 201 207 212 198 219 223 188 213 227 201 196 213 219 198 241 222 215 211 193 207 219 207 211 215 214 200 218 212 206 210 213 198 203 234 206 235 209 221 210 197 201 230 210 226 228 206 235 231 223 202 196 234 204 202 221 205 215 189 249 183 228 207 233 216 218 245 214 222 225 216 216 183 214 179 207 214 194 218 197 218 194 201 204 184 193 206 205 202 215 197 221 189 224 195 219 201 229 182 190 234 213 198 227 218 198 229 213 216 154 204 219 196 216 206 183 236 215 213 241 216 191 223 198 205 214 209 196 227 226 200 240 208 244 220 220 211 228 220 215 206 209 204 212 210 192 207 221 193 236 210 215 189 191 200 203 208 243 208 195 188 226 222 216 217 201 176 200 216 223 229 193 221 215 222 221 238 207 190 232 218 204 190 226 220 213 224 203 209 231 205 212 205 208 206 197 214 188 216 204 215 220 193 210 192 182 178 208 205 202 228 207 215 216 212 222 235 232 221 206 189 188 192 211 213 235 173 233 210 199 229 204 223 217 203 202 189 201 213 212 186 200 195 195 188 237 201 211 214 217 210 212 218 257 214 215 233 185 215 214 188 234 204 205 201 209 184 213 193 183 189 207 228 197 214 209 201 210 196 204 179 200 205 206 180 201 195 203 194 181 207 236 211 215 218 240 208 207 200 204 207 217 206 213 235 215 216 202 193 210 212 194 205 225 215 197 216 228 225 193 208 224 227 216 207 196 214 207 205 215 202 181 189 222 208 214 225 219 220 191 223 195 224 208 191 208 182 203 213 208 194 187 222 216 218 207 200 203 200 200 192 224 188 226 172 206 209 223 201 234 195 228 197 187 215 201 189 202 214 226 202 216 206 204 221 180 185 219 207 216 186 221 202 191 206 212 199 200 210 205 215 220 233 210 205 165 199 212 194 174 214 210 233 203 193 208 210 214 203 255 219 219 222 223 214 198 210 196 198 218 226 245 217 213 234 194 203 195 234 208 193 212 231 201 221 233 220 212 199 222 198 198 218 246 211 182 208 217 201 203 198 195 181 212 198 240 238 191 220 192 182 200 204 213 194 221 217 231 191 188 223 186 245 189 202 220 196 223 240 236 203 199 208 212 221 215 215 183 205 213 186 206 219 209 195 190 184 192 218 221 222 202 211 200 223 183 218 215 215 205 219 199 218 184 204 220 206 228 184 215 221 208 187 206 189 237 209 206 191 195 264 228 205 217 189 228 212 194 196 215 192 182 191 201 229 191 225 234 196 195 212 245 196 223 207 187 193 198 196 219 199 209 212 228 215 216 197 215 201 184 189 184 204 213 200 224 222 222 219 211 237 192 218</counts>
			</dataPoints>
		</scan>
	</xrdMeasurement>
</xrdMeasurements>