File: data/XRD/XG-Vakuum/XG-750/W6824-1C_XG_Vakuum_750.xrdml
<xrdMeasurements xmlns="http://www.xrdml.com/XRDMeasurement/2.1" xmlns:xsi="http://www.w3.org/2001/XMLSchema-instance" xsi:schemaLocation="http://www.xrdml.com/XRDMeasurement/2.1 http://www.xrdml.com/XRDMeasurement/2.1/XRDMeasurement.xsd" status="Completed">
	<comment>
		<entry>Configuration=Factory configuration, Owner=User-1, Creation date=7/8/2013 4:01:53 PM</entry>
		<entry>Goniometer=PW3050/65 (Theta/2Theta); Minimum step size 2Theta:0.0001; Minimum step size Omega:0.0001</entry>
		<entry>Sample stage=MRD Cradle; Minimum step size Phi:0.01; Minimum step size Chi:0.01; Minimum step size X:0.01; Minimum step size Y:0.01; Minimum step size Z:0.001</entry>
		<entry>Diffractometer system=XPERT-PRO</entry>
		<entry>Measurement program=C:\PANalytical\Data Collector\Programs\Jorrit\2thom\_absolute_2th-om_10-130deg_PIXscan_56min.xrdmp, Identifier={15BCCF57-2807-42BD-B5B9-ECC0B3DC9284}</entry>
		<entry>Batch program=C:\PANalytical\Data Collector\Programs\SimonL\batch6x_2thom_10-130°_z9.1_x0,10,20,30_y20,40_57min - Kopie.xrdmp, Identifier={6B3EF4D3-441D-47FD-9EA5-077D311040EA}</entry>
	</comment>
	<sample type="To be analyzed">
		<id></id>
		<name></name>
		<preparedBy></preparedBy>
	</sample>
	<xrdMeasurement measurementType="Scan" status="Completed" sampleMode="Reflection">
		<comment>
			<entry>_absolute_2th-om_10-130deg_PIXscan_56min</entry>
			<entry>PHD Lower Level = 4.83 (keV), PHD Upper Level = 11.27 (keV)</entry>
		</comment>
		<usedWavelength intended="K-Alpha 1">
			<kAlpha1 unit="Angstrom">1.5405980</kAlpha1>
			<kAlpha2 unit="Angstrom">1.5444260</kAlpha2>
			<kBeta unit="Angstrom">1.3922500</kBeta>
			<ratioKAlpha2KAlpha1>0.5000</ratioKAlpha2KAlpha1>
		</usedWavelength>
		<incidentBeamPath>
			<radius unit="mm">320.00</radius>
			<xRayTube id="1010048" name="Empyrean Cu LFF HR (9430 033 7310x) DK442154">
				<tension unit="kV">40.0</tension>
				<current unit="mA">40.0</current>
				<anodeMaterial>Cu</anodeMaterial>
				<focus type="Line">
					<length unit="mm">12.0</length>
					<width unit="mm">0.4</width>
					<takeOffAngle unit="deg">4.2</takeOffAngle>
				</focus>
			</xRayTube>
			<xRayMirror id="27010001" name="Inc. Beam Cu W/Si (parabolic MRD)" hybrid="false">
				<crystal type="Graded" shape="Parabolic">W/Si</crystal>
				<acceptanceAngle unit="deg">0.800</acceptanceAngle>
				<length unit="mm">60.0</length>
			</xRayMirror>
			<sollerSlit id="21010002" name="Soller slits 0.04 rad.">
				<opening unit="rad">0.0400</opening>
			</sollerSlit>
			<mask id="22030008" name="Fixed mask 4 mm">
				<distanceToSample unit="mm">220.00</distanceToSample>
				<width unit="mm">4.00</width>
			</mask>
			<divergenceSlit id="22010011" name="Fixed slit 1/32°" xsi:type="fixedDivergenceSlitType">
				<distanceToSample unit="mm">220.00</distanceToSample>
				<height unit="mm">0.05</height>
			</divergenceSlit>
		</incidentBeamPath>
		<diffractedBeamPath>
			<radius unit="mm">320.00</radius>
			<sollerSlit id="21010002" name="Soller slits 0.04 rad.">
				<opening unit="rad">0.0400</opening>
			</sollerSlit>
			<receivingSlit id="22010001" name="Fixed slit 4°">
				<height unit="mm">5.88</height>
			</receivingSlit>
			<detector id="7010017" name="PIXcel3D 1x1 detector" xsi:type="areaDetectorType">
				<phd unit="%">
					<lowerLevel>30.0</lowerLevel>
					<upperLevel>70.0</upperLevel>
				</phd>
				<mode>Scanning</mode>
				<activeChannelsEquatorial>255</activeChannelsEquatorial>
				<activeChannelsAxial>255</activeChannelsAxial>
				<pitchEquatorial unit="mm">0.05500</pitchEquatorial>
				<pitchAxial unit="mm">0.05500</pitchAxial>
				<readOutPeriod unit="seconds">0.135</readOutPeriod>
			</detector>
		</diffractedBeamPath>
		<scan appendNumber="0" mode="Continuous" scanAxis="2Theta-Omega" status="Completed">
			<header>
				<startTimeStamp>2024-10-11T19:15:27+02:00</startTimeStamp>
				<endTimeStamp>2024-10-11T20:11:33+02:00</endTimeStamp>
				<author>
					<name>PRO-MRD</name>
				</author>
				<source>
					<applicationSoftware version="6.1b">Data Collector</applicationSoftware>
					<instrumentControlSoftware version="7.0E 20130304">XPERT-PRO</instrumentControlSoftware>
					<instrumentID>0000000011142674</instrumentID>
				</source>
			</header>
			<dataPoints>
				<positions axis="2Theta" unit="deg">
					<startPosition>9.99826193</startPosition>
					<endPosition>129.99755682</endPosition>
				</positions>
				<positions axis="Omega" unit="deg">
					<startPosition>4.99913096</startPosition>
					<endPosition>64.99877841</endPosition>
				</positions>
				<positions axis="Phi" unit="deg">
					<commonPosition>0.00</commonPosition>
				</positions>
				<positions axis="Chi" unit="deg">
					<commonPosition>0.00</commonPosition>
				</positions>
				<positions axis="X" unit="mm">
					<commonPosition>30.00</commonPosition>
				</positions>
				<positions axis="Y" unit="mm">
					<commonPosition>0.00</commonPosition>
				</positions>
				<positions axis="Z" unit="mm">
					<commonPosition>9.100</commonPosition>
				</positions>
				<commonCountingTime unit="seconds">32.895</commonCountingTime>
				<counts 384 405 440 441 401 428 422 431 426 433 410 408 432 386 427 409 446 401 407 387 389 453 438 396 397 420 442 418 422 424 433 394 427 425 423 430 420 417 412 395 426 435 377 387 415 403 419 391 440 423 448 436 408 417 470 441 393 362 437 425 418 417 404 440 402 460 399 393 426 422 433 417 422 431 407 439 393 379 431 374 396 457 419 399 425 379 407 408 422 440 426 400 402 407 427 406 419 391 385 393 414 386 407 394 390 416 414 386 447 398 399 353 422 396 457 448 435 420 387 399 405 392 427 381 410 457 426 379 393 401 405 385 387 410 404 409 411 417 352 370 402 397 421 359 383 381 404 408 390 389 391 392 371 426 361 387 389 402 382 423 396 377 382 409 400 404 397 409 386 390 407 362 421 390 376 364 361 374 374 399 366 377 346 390 371 374 381 389 384 382 377 383 386 381 397 386 373 410 389 363 391 400 405 372 392 356 414 357 360 422 397 377 370 403 386 390 387 362 378 430 395 369 332 378 363 354 389 353 346 398 370 361 350 403 409 372 369 380 426 356 349 332 383 374 359 386 395 369 384 366 419 351 387 350 364 355 348 369 369 382 393 359 357 363 387 382 381 346 338 347 352 351 439 349 365 354 350 388 405 388 361 367 375 395 372 384 381 390 374 365 371 341 396 377 352 370 371 331 398 364 358 315 368 372 396 375 361 389 381 350 347 388 339 376 381 331 344 333 366 356 377 368 365 375 375 379 328 362 334 388 354 373 344 382 358 334 356 355 351 344 329 343 392 386 350 335 326 362 376 386 341 371 338 358 348 360 355 353 334 348 351 367 376 334 343 394 327 338 361 316 349 336 325 342 353 354 347 320 323 365 314 332 360 334 363 340 336 363 327 347 371 347 347 347 357 342 383 356 330 310 334 317 346 350 329 316 334 332 339 376 336 335 329 332 339 343 314 355 361 305 360 323 333 343 344 322 339 357 324 319 329 310 320 362 326 315 340 321 315 340 321 379 341 340 314 344 323 344 356 322 348 361 308 336 318 333 275 327 323 312 331 339 310 352 323 313 311 311 344 339 357 326 322 345 358 329 319 343 349 354 344 282 357 322 328 344 290 310 306 350 337 322 322 337 340 352 307 310 331 346 349 318 322 331 309 317 332 344 329 326 327 353 342 311 287 352 315 327 341 330 311 343 327 338 308 320 316 335 306 333 318 328 321 304 327 326 340 329 310 302 312 336 319 342 343 314 324 336 344 340 309 313 319 292 324 292 339 316 323 327 331 305 327 324 364 291 348 313 275 319 307 307 325 314 300 341 307 273 320 301 300 331 346 322 316 316 291 322 337 345 272 333 318 336 301 307 314 327 317 307 326 320 322 310 294 307 289 316 316 293 309 323 327 311 286 327 315 327 303 313 276 317 326 349 330 311 323 309 301 322 288 311 301 328 317 312 308 328 324 317 309 327 322 307 296 342 319 327 277 314 293 320 338 303 300 329 325 315 319 267 319 298 361 337 303 343 279 310 337 287 286 299 303 311 310 291 302 294 338 316 304 329 322 313 322 316 338 350 328 280 312 293 317 315 309 307 306 330 343 302 324 319 308 318 285 291 290 331 314 327 295 276 303 297 324 301 301 304 301 322 333 301 301 280 310 295 316 297 299 327 304 320 318 324 289 324 285 280 298 314 316 289 307 278 289 314 318 281 322 307 288 298 299 318 308 303 319 267 304 337 331 289 291 303 333 309 331 339 310 323 317 270 334 301 324 315 318 294 303 307 333 305 296 292 291 284 297 297 293 346 327 348 318 299 305 299 273 281 314 314 313 290 310 314 315 307 314 303 333 322 283 308 289 327 303 317 296 295 321 271 316 330 299 307 325 302 288 323 278 299 303 301 289 311 275 320 302 309 309 304 306 316 302 339 349 312 312 332 297 297 308 308 291 315 326 304 344 294 334 314 332 333 320 296 316 307 314 319 328 286 334 327 331 320 318 297 319 306 333 330 315 291 313 324 283 289 302 302 294 302 317 336 321 295 302 300 342 291 317 314 276 340 301 310 287 323 329 310 314 319 266 279 292 314 301 305 307 319 278 300 309 353 340 307 298 305 315 317 293 280 308 341 292 328 325 334 315 304 346 305 304 308 292 303 318 315 316 313 287 297 297 326 279 327 329 343 336 336 335 314 316 303 332 319 304 298 326 355 316 304 332 289 341 300 325 299 332 303 313 298 304 270 342 337 311 327 320 296 324 286 310 323 339 291 291 305 308 328 305 321 302 341 302 315 283 321 277 302 313 296 286 303 295 297 318 327 280 334 281 283 332 309 304 314 327 310 370 313 329 292 339 346 340 340 278 329 311 322 291 303 297 298 330 305 352 301 257 323 328 340 319 313 327 316 283 309 319 335 302 331 310 318 286 302 314 311 352 318 318 299 342 350 318 335 319 342 336 312 328 339 348 327 324 294 321 324 314 307 305 325 309 300 320 335 323 311 282 302 318 327 332 353 309 298 336 335 275 315 326 355 344 314 339 324 305 300 296 300 315 294 325 322 320 311 321 329 333 323 320 311 329 317 320 309 328 323 338 310 330 353 316 301 285 331 317 313 313 360 322 308 302 295 304 327 338 344 347 353 285 334 333 274 277 331 330 314 351 327 310 320 320 340 340 340 310 304 328 332 328 353 306 308 272 317 284 313 351 320 310 303 330 324 317 336 309 304 341 342 284 324 355 312 356 324 330 291 338 306 322 306 316 322 342 335 356 332 307 306 300 344 311 340 316 295 324 352 291 359 305 316 337 335 351 348 313 343 330 318 328 317 315 301 316 309 320 302 315 322 315 330 359 342 309 306 305 332 329 313 333 323 329 317 354 321 341 322 320 317 321 321 292 318 307 296 324 322 318 327 298 329 320 320 319 294 328 333 321 296 318 323 326 286 311 305 324 343 280 294 305 339 312 308 304 318 347 278 310 298 328 317 319 327 294 324 286 343 309 305 334 321 331 305 342 322 302 326 307 299 337 303 308 326 299 320 320 310 314 341 327 338 347 309 339 322 339 292 308 287 294 282 335 343 333 317 311 291 311 316 295 323 302 323 350 319 332 281 325 307 289 309 365 324 309 325 283 301 328 323 337 339 334 345 293 325 338 306 344 300 320 289 314 333 346 351 304 333 335 329 333 280 309 290 311 329 296 317 312 295 317 336 307 312 303 320 292 318 313 301 314 300 297 320 288 302 304 297 319 318 297 327 331 372 317 296 314 284 313 342 317 271 340 334 316 334 320 338 286 340 303 333 288 308 298 297 319 327 327 308 290 293 301 324 323 311 317 308 309 294 322 296 295 305 300 323 313 281 316 296 308 306 298 265 293 297 303 323 288 305 311 316 291 297 301 309 305 276 323 301 295 315 323 308 314 302 310 300 292 296 308 324 323 273 318 299 308 281 279 308 324 301 303 328 315 292 322 290 325 262 327 287 328 308 296 261 300 294 306 319 298 282 316 303 317 294 283 310 286 306 301 299 285 277 290 330 280 299 302 290 316 290 269 323 308 301 285 303 326 310 313 296 277 279 283 280 292 317 295 274 306 290 314 304 299 284 281 290 308 294 308 291 300 266 283 287 296 291 281 289 295 307 260 273 301 288 291 307 294 246 287 306 288 276 284 310 323 275 311 283 273 299 300 227 289 304 282 279 281 240 288 294 288 308 287 291 303 291 308 274 303 282 271 285 301 291 240 284 291 284 323 292 280 296 289 256 249 265 249 291 286 358 308 280 258 272 279 270 290 299 337 268 269 275 298 287 278 267 294 288 316 287 311 275 244 311 295 305 249 263 294 290 248 279 310 311 249 277 271 275 236 238 273 291 273 290 262 264 259 298 269 279 289 263 302 274 294 238 285 291 277 300 299 271 284 264 286 276 307 260 247 269 289 275 291 277 289 272 276 281 272 311 239 266 292 248 272 292 297 260 271 270 292 235 264 256 277 286 280 277 279 272 288 242 293 237 274 280 246 246 314 247 263 269 270 293 244 269 293 247 249 247 255 277 241 284 255 279 283 264 283 266 260 266 270 266 261 273 274 263 293 249 240 282 277 269 249 258 225 284 291 292 273 293 250 234 247 280 267 234 258 273 248 279 273 290 238 237 279 256 290 233 225 278 267 277 245 259 286 263 283 259 281 277 279 240 244 278 261 244 271 248 224 244 239 264 239 271 276 267 238 249 240 246 276 247 256 242 267 282 225 256 243 264 245 257 265 247 249 237 264 260 268 238 268 275 232 278 246 256 262 270 220 231 267 259 235 273 270 240 256 257 245 243 215 239 260 228 279 258 257 243 242 230 258 221 231 278 235 237 257 227 243 233 279 236 230 232 228 249 262 278 233 224 268 245 264 264 227 249 257 199 260 261 266 264 268 248 240 256 246 230 213 249 258 256 245 218 264 240 265 277 288 223 258 245 258 220 219 268 219 237 244 226 227 246 245 219 239 243 226 232 217 256 224 240 229 261 262 261 227 228 225 231 265 233 242 262 259 237 235 234 243 264 237 247 235 235 233 273 229 220 233 239 256 272 269 206 236 242 242 264 258 231 227 208 218 246 247 237 239 238 259 237 250 232 269 228 219 235 238 234 263 248 250 217 231 249 226 233 264 258 238 215 235 232 258 246 230 215 236 220 219 208 242 219 246 242 227 210 229 231 228 229 255 235 265 234 235 250 239 244 261 234 216 203 229 197 235 225 256 224 223 224 234 233 242 263 246 210 222 231 239 226 236 257 236 234 229 255 272 236 266 243 240 230 237 250 216 243 220 227 241 228 233 230 241 229 219 246 213 229 227 233 245 223 227 235 221 217 213 244 220 235 248 260 237 232 231 238 198 270 242 222 228 226 248 258 219 232 214 240 225 229 189 238 223 228 264 233 231 211 234 237 224 245 226 227 234 235 260 266 247 259 233 220 232 257 245 217 221 239 230 222 219 239 200 214 211 221 270 222 207 216 234 260 215 238 233 236 219 206 206 205 207 247 238 239 205 259 256 200 214 225 233 201 229 214 243 223 202 238 236 214 237 243 234 239 228 210 228 231 231 238 227 212 244 214 211 224 229 216 200 237 232 224 203 198 227 200 255 234 258 226 241 225 211 212 248 262 215 227 244 216 259 212 224 239 226 223 213 218 238 219 238 234 235 216 233 210 219 209 233 238 228 185 230 238 231 228 222 185 216 227 231 238 233 197 226 220 242 200 227 237 237 261 221 226 218 249 236 226 229 245 222 236 219 244 228 214 238 234 237 227 245 238 240 235 215 230 227 217 238 223 231 236 225 215 225 209 214 217 243 219 219 209 208 219 216 212 210 224 218 209 229 221 240 232 223 218 222 223 224 217 225 217 222 223 189 204 220 238 189 212 190 199 205 208 226 269 241 255 226 209 227 222 212 213 224 207 217 232 220 222 216 200 214 255 232 205 232 215 192 222 209 232 227 231 208 219 236 221 218 186 230 212 222 220 224 239 259 232 222 222 241 230 212 236 217 208 219 200 195 199 203 223 202 219 241 241 206 231 202 232 216 223 236 212 224 214 226 207 226 204 235 191 225 210 257 229 201 216 238 190 249 218 218 216 206 221 208 223 215 220 221 238 212 243 213 219 217 216 215 208 205 224 210 203 210 203 235 197 207 217 225 212 217 223 224 222 200 204 217 225 222 193 220 244 208 238 212 219 196 182 216 206 201 196 201 237 229 216 193 195 241 247 241 220 244 210 221 198 212 192 191 222 214 216 192 219 228 221 240 222 230 227 216 218 209 213 210 211 202 205 228 191 210 206 202 206 209 210 227 205 210 225 216 202 201 246 201 236 204 209 238 226 224 197 210 231 208 220 205 193 213 225 214 213 230 217 218 220 204 210 211 212 217 211 207 218 214 221 223 224 223 221 230 183 208 232 232 236 242 206 239 215 214 219 219 224 204 231 197 199 223 196 204 204 248 232 186 203 219 235 215 213 218 206 215 209 211 220 198 212 200 220 216 188 236 203 218 190 235 198 248 195 227 212 223 229 214 207 225 219 205 221 212 204 235 189 206 206 233 227 202 207 216 197 217 226 240 197 208 207 218 238 220 224 200 231 224 211 225 193 213 219 217 230 216 207 206 209 217 239 204 224 182 204 234 228 212 220 227 210 242 204 231 238 229 219 234 212 200 231 223 219 216 206 225 197 183 195 215 212 224 208 229 193 226 200 206 207 202 202 220 233 216 226 197 207 214 223 209 207 221 226 208 208 231 218 223 220 205 213 193 222 212 230 203 259 203 200 218 203 218 226 203 221 210 219 207 220 206 198 238 206 207 200 208 240 202 196 226 194 200 206 208 239 234 204 199 207 227 216 217 214 241 211 201 236 213 198 212 202 240 241 268 211 212 210 205 225 211 216 212 226 223 212 184 231 240 214 193 208 197 219 238 226 229 190 190 200 199 212 207 235 215 226 227 216 205 233 202 185 240 222 233 206 223 235 193 216 215 200 215 212 209 226 236 209 211 213 199 204 216 247 226 228 223 216 228 217 185 223 215 240 209 187 220 219 212 204 210 231 241 217 222 190 230 214 229 195 229 205 236 199 242 198 207 225 233 219 211 216 227 215 211 188 185 212 225 207 223 220 213 223 225 205 215 224 232 219 209 204 192 205 227 220 242 213 192 211 210 204 217 208 199 232 224 256 197 216 206 189 212 215 200 196 189 213 198 223 217 224 202 189 206 220 223 208 195 198 201 205 198 213 188 208 218 210 208 224 221 213 201 189 203 198 212 220 226 227 212 213 226 210 231 209 224 227 228 208 219 217 195 198 211 233 200 215 217 256 217 236 257 220 219 204 214 203 222 217 214 203 211 191 202 221 227 193 227 209 240 212 241 211 215 203 227 232 229 225 248 231 215 190 238 225 232 189 221 214 209 194 208 241 202 177 210 220 234 188 198 200 223 217 207 224 218 214 197 212 217 238 215 208 194 201 195 211 212 224 195 206 220 208 211 222 227 235 198 229 208 202 218 219 219 224 210 215 200 204 211 208 220 202 209 218 197 243 230 225 233 206 215 218 195 209 196 200 198 201 210 217 194 196 224 211 198 188 205 245 208 197 189 194 225 216 232 233 218 186 225 186 215 206 193 183 214 211 172 207 203 226 220 216 208 202 188 229 193 201 178 213 188 217 192 237 203 214 204 241 207 207 220 211 184 230 206 215 205 190 196 226 175 189 210 205 208 209 232 229 226 210 231 224 202 214 218 188 224 197 204 206 230 211 207 186 222 190 197 227 231 211 187 195 210 198 226 206 210 235 242 202 229 207 209 197 206 230 214 227 221 224 202 215 197 227 230 205 209 211 213 211 227 231 233 223 216 189 229 209 214 208 211 174 232 231 221 215 206 207 208 204 213 220 194 224 210 239 216 190 227 219 191 230 219 209 207 241 205 194 197 191 198 201 220 210 223 219 211 220 220 249 225 219 223 213 225 207 192 207 208 220 202 203 227 220 211 212 217 219 210 221 218 213 204 216 199 224 230 213 202 243 241 225 225 221 221 209 233 217 205 223 256 264 247 257 237 261 240 223 225 194 210 222 214 223 196 245 211 209 204 224 225 216 235 215 220 232 213 220 206 226 242 229 225 216 217 215 219 224 246 240 217 211 228 188 223 208 210 222 228 242 236 216 227 186 236 229 224 219 223 231 240 205 239 223 244 237 234 223 191 238 221 214 237 229 241 227 244 239 236 214 222 267 259 234 229 266 238 215 231 214 268 243 226 285 268 238 267 237 237 226 237 243 257 243 278 267 275 224 249 282 223 242 272 267 261 273 290 282 303 298 273 294 281 286 350 308 294 325 314 333 313 326 334 344 378 367 331 369 427 381 383 385 384 404 397 382 406 381 386 389 386 391 398 334 377 356 359 360 343 351 324 312 317 290 294 275 243 293 279 281 246 269 244 249 232 260 266 233 260 244 282 248 238 229 234 229 248 265 223 226 239 246 213 249 227 255 243 214 206 245 228 222 259 227 229 227 239 237 212 238 211 245 202 192 248 228 208 236 214 221 246 255 220 237 234 228 226 236 212 241 226 225 255 190 218 213 209 221 217 185 220 201 222 209 245 199 245 223 244 212 227 216 223 197 206 205 233 190 226 238 218 195 219 210 213 230 224 224 198 224 219 209 244 211 213 195 196 213 239 196 255 214 241 205 245 239 242 240 223 220 220 229 199 208 200 221 216 202 210 210 205 213 205 238 224 232 235 216 197 210 210 239 206 209 209 230 198 222 212 210 213 218 227 220 242 232 223 208 243 244 190 195 193 191 216 228 207 225 209 210 222 236 213 217 205 227 197 214 207 213 225 219 209 226 216 231 224 225 211 193 221 212 208 231 210 209 210 245 224 235 200 216 194 241 233 227 232 207 223 221 205 222 238 220 256 226 203 194 212 226 246 185 189 195 214 216 214 228 214 257 208 219 230 211 242 255 204 243 222 231 231 229 225 211 239 216 204 207 214 210 232 205 237 227 230 207 242 219 217 241 217 228 224 213 201 207 223 246 213 245 226 231 213 219 195 228 212 204 230 213 217 212 219 220 233 234 220 218 203 235 222 208 229 225 239 235 228 224 232 216 228 228 241 219 216 196 210 215 212 223 195 211 205 210 255 197 221 249 194 239 237 207 202 220 206 216 212 203 233 204 219 223 207 214 208 228 220 199 212 194 207 211 215 197 226 217 209 183 228 219 216 228 211 226 207 203 230 205 184 206 227 249 225 211 208 222 225 223 225 223 211 207 191 197 214 239 199 209 209 184 220 241 213 219 207 211 216 191 206 226 216 217 222 207 201 217 228 212 224 218 218 220 226 257 219 231 244 227 206 229 201 213 245 218 208 220 219 200 235 222 196 191 236 203 243 217 211 214 194 237 210 221 217 264 209 227 230 241 207 208 225 216 216 245 225 221 229 224 219 209 201 203 204 213 189 221 196 222 213 195 209 220 223 214 215 204 216 197 238 231 209 205 225 228 203 214 205 193 181 241 237 222 211 190 226 219 187 210 196 230 220 205 195 224 230 208 235 215 213 230 213 219 219 229 209 207 176 238 218 255 220 203 196 225 242 232 223 208 209 201 212 215 217 215 213 239 211 228 228 233 213 215 206 260 203 232 204 222 211 186 221 227 206 213 226 199 221 223 257 222 181 218 216 233 214 229 209 201 209 241 214 218 232 184 246 222 192 230 204 210 233 192 235 198 229 220 227 228 226 228 221 192 225 234 201 223 229 232 201 217 217 220 206 207 233 200 178 188 222 199 244 196 212 227 234 206 207 221 223 202 223 183 196 214 199 218 207 208 203 258 217 223 218 219 219 248 219 266 212 220 239 226 200 212 225 213 214 193 204 229 233 201 228 208 202 209 209 249 194 231 212 214 214 236 201 232 208 233 195 257 214 194 206 217 213 213 221 226 234 206 183 208 214 203 234 228 233 210 202 209 210 235 213 215 211 209 213 206 211 239 216 227 213 220 202 214 220 223 210 208 206 204 233 223 222 224 226 210 228 205 242 218 219 234 244 225 207 218 221 228 221 207 214 223 230 221 226 226 216 226 218 217 203 199 212 223 221 227 202 220 219 227 221 219 232 229 181 219 201 235 190 220 222 239 257 239 209 191 231 226 224 213 230 197 189 221 192 212 234 205 218 210 200 227 210 216 218 229 223 194 191 207 209 211 224 222 212 222 227 207 217 200 206 222 223 224 223 223 229 215 239 213 187 215 228 238 195 229 206 210 202 213 226 212 247 204 191 206 191 232 217 238 216 218 198 234 195 205 241 204 222 242 231 224 214 264 202 214 197 232 229 217 214 216 232 234 212 205 217 199 211 220 205 223 217 232 217 212 213 217 212 227 197 204 232 227 220 205 210 227 222 208 217 225 246 208 233 207 230 214 239 189 235 229 215 233 235 222 205 230 232 230 224 223 219 230 212 231 204 243 245 200 216 225 230 222 195 233 265 200 221 209 241 214 216 237 232 224 219 213 209 210 182 234 237 227 208 224 225 230 203 271 241 232 222 205 213 231 220 211 228 221 235 211 226 208 218 224 231 224 233 209 217 262 247 205 217 216 203 258 207 202 221 232 238 248 240 188 246 186 240 219 215 236 235 235 232 211 224 227 243 237 228 202 216 217 182 222 221 214 214 208 230 222 212 242 214 231 196 224 188 213 224 214 231 224 215 238 199 212 198 215 209 230 235 210 205 212 197 228 210 203 210 208 214 205 220 225 204 198 213 237 194 225 242 231 179 188 219 232 229 228 239 200 189 223 231 245 207 226 233 210 223 218 205 216 224 215 226 191 216 197 199 205 215 208 223 210 229 232 202 226 232 209 216 209 231 222 191 246 219 210 205 228 206 221 210 235 219 212 207 213 218 206 224 210 224 227 225 195 225 210 216 227 219 230 198 244 211 207 263 218 209 238 246 211 202 210 220 273 188 237 214 214 221 226 237 221 215 224 220 233 235 237 248 217 239 214 208 218 222 211 199 201 200 223 225 224 220 232 214 203 223 208 229 210 230 222 226 238 214 193 232 203 227 201 205 223 190 218 222 201 198 200 226 185 205 227 264 234 214 202 209 223 240 233 229 219 232 233 243 257 224 212 225 235 237 227 219 230 226 206 228 209 212 213 230 219 186 236 219 212 221 207 230 220 210 227 213 237 212 206 235 213 222 210 230 223 263 212 195 207 224 233 233 185 203 210 228 232 242 214 214 234 232 223 241 222 206 221 210 221 239 231 247 203 220 231 239 214 208 211 205 220 221 242 244 188 239 230 223 238 219 227 240 243 212 201 208 232 237 239 217 238 223 257 222 189 243 225 202 227 231 195 221 228 217 249 212 222 198 227 209 210 225 233 236 193 236 228 240 247 219 246 222 222 202 215 233 243 227 224 189 215 231 228 247 216 244 221 212 235 212 232 226 202 246 200 202 232 212 233 212 226 211 213 200 208 234 222 227 224 249 231 236 228 213 219 234 233 234 205 227 225 240 242 225 228 200 224 241 216 226 244 216 241 210 237 240 204 220 246 212 231 217 229 201 222 223 227 221 249 217 226 218 209 229 246 217 223 257 249 242 224 241 229 208 214 220 209 236 236 203 235 215 227 205 206 236 243 240 222 208 215 225 232 213 217 214 229 242 230 228 219 214 246 221 243 217 223 234 225 217 245 234 224 232 225 226 204 267 228 219 227 218 214 230 231 240 236 220 239 220 228 232 217 216 223 189 195 239 219 219 203 215 241 263 206 227 242 214 196 224 223 244 228 230 203 241 264 219 262 246 236 242 209 204 235 218 226 221 233 208 235 234 188 219 230 249 230 225 220 230 227 221 223 221 221 222 263 210 237 192 239 230 225 215 230 212 238 187 217 244 201 222 249 255 220 238 233 222 212 211 199 245 227 257 218 230 245 208 208 229 235 221 226 221 235 219 231 226 221 256 229 202 189 214 213 212 232 234 222 196 275 206 246 216 227 270 217 204 216 229 221 198 248 218 206 228 211 246 201 226 220 222 228 225 236 230 216 226 255 209 197 220 241 235 224 193 250 227 230 218 232 238 211 240 221 234 198 230 210 230 260 228 232 238 238 225 233 236 260 246 229 205 203 215 220 227 245 209 233 227 234 249 218 243 238 220 212 247 247 227 212 215 217 216 218 226 218 237 247 222 234 240 232 247 267 259 203 197 229 245 226 201 234 222 240 240 231 231 231 234 234 224 217 227 240 242 233 233 239 265 225 215 222 260 205 236 240 229 236 268 247 225 227 246 219 228 216 232 237 220 261 227 234 256 231 260 220 244 240 230 227 248 237 247 248 259 227 260 222 237 246 234 229 240 237 206 218 255 240 232 233 234 238 242 224 236 219 237 214 233 209 237 270 236 220 239 242 230 229 239 243 239 260 237 228 259 225 249 239 207 238 247 209 244 227 219 249 229 227 258 240 261 244 210 220 233 270 232 247 231 268 236 228 235 238 230 248 247 241 220 243 235 243 241 232 247 234 277 247 255 270 233 246 218 230 228 237 237 237 222 257 242 229 256 255 265 233 242 229 245 230 215 257 218 263 247 202 239 237 245 237 246 225 235 217 221 279 241 201 246 226 219 203 238 214 240 240 245 201 226 210 232 224 222 232 219 224 227 226 236 255 236 219 236 205 220 185 228 241 227 232 224 215 218 246 233 218 244 206 249 270 208 265 219 249 220 230 234 242 218 235 233 234 283 221 242 244 243 224 228 229 227 222 245 258 258 213 245 265 227 218 212 236 214 236 268 240 237 248 242 247 215 233 247 225 243 232 268 231 224 207 226 271 267 259 247 232 232 215 244 225 264 231 218 216 271 215 256 258 207 235 216 259 210 242 242 221 234 223 242 219 215 226 230 227 234 229 239 233 241 248 237 219 245 235 243 224 256 234 256 213 221 214 210 198 235 205 220 225 262 261 236 228 232 235 236 238 240 232 234 247 246 214 257 225 232 229 230 209 209 244 224 280 267 218 258 243 231 236 259 250 255 224 228 226 245 245 244 245 233 241 268 245 262 269 262 233 248 247 237 263 245 238 232 233 238 234 242 240 222 216 256 262 266 220 242 238 236 245 220 230 267 241 220 263 258 261 225 268 265 244 233 241 239 244 256 231 268 228 235 238 224 261 259 214 229 232 212 240 202 255 248 222 257 208 218 221 220 218 257 224 249 232 242 235 217 242 237 245 223 205 235 241 241 216 266 259 199 233 257 239 229 239 227 240 224 229 206 223 224 247 222 250 238 211 216 216 261 240 216 218 224 218 214 267 216 247 231 261 241 262 281 245 229 215 240 220 238 243 233 225 197 222 239 237 238 203 229 203 232 231 230 248 215 245 227 215 214 237 221 231 243 234 266 243 246 218 246 225 238 245 245 213 260 236 216 202 234 237 222 222 220 242 250 250 214 255 255 235 234 203 242 230 255 248 220 222 193 260 232 264 255 243 240 236 238 256 229 265 229 220 242 230 218 218 235 257 216 227 238 247 245 231 209 220 220 239 225 231 217 228 243 217 259 247 243 238 230 225 225 241 231 221 258 249 256 240 216 237 243 216 249 220 260 239 231 255 227 238 262 243 226 235 227 218 246 229 222 248 223 200 245 231 224 261 248 219 215 241 259 237 224 236 226 272 238 236 212 239 273 225 234 237 229 242 233 245 236 228 215 211 222 214 235 255 235 223 258 215 244 208 240 241 233 258 225 212 257 233 256 257 206 215 255 268 225 244 260 242 273 230 236 241 234 249 273 293 262 238 217 267 241 233 231 238 255 242 217 214 240 275 268 241 196 235 232 235 233 258 225 205 233 218 241 197 231 231 243 249 243 248 240 265 219 241 230 240 217 249 214 262 260 244 268 245 232 237 246 236 222 262 243 239 243 261 237 226 226 208 225 271 230 242 275 270 232 243 256 268 240 248 245 279 242 224 232 218 220 272 234 206 264 229 209 248 216 238 208 243 243 225 221 245 229 245 239 234 222 260 242 230 261 238 221 244 228 244 240 257 248 245 264 220 209 261 232 225 210 226 243 239 279 241 240 237 232 226 265 264 226 243 261 242 273 236 239 260 232 278 269 259 238 228 230 220 214 230 214 230 248 246 267 224 215 221 213 223 239 220 227 242 272 224 264 240 232 264 265 234 247 227 236 231 226 243 217 217 255 270 269 213 238 260 233 210 243 247 256 241 255 237 279 205 262 241 224 219 223 231 260 228 230 263 230 258 238 233 285 227 202 242 218 220 237 260 234 228 255 259 244 267 262 233 241 236 226 246 247 223 260 255 236 238 246 216 248 197 263 219 228 242 240 225 238 234 241 230 223 219 226 245 224 215 265 230 238 233 225 230 218 219 218 212 249 222 223 235 234 256 220 244 227 246 250 235 218 264 229 230 229 218 239 239 225 231 226 271 208 234 247 263 231 217 236 249 221 261 267 239 247 238 234 221 238 227 247 201 260 235 234 243 256 243 242 220 223 239 238 255 229 243 238 231 250 241 218 231 233 247 272 247 237 244 249 214 256 250 229 271 224 243 250 240 221 242 259 238 243 223 256 246 244 246 247 224 219 228 263 241 236 216 241 238 239 278 244 206 218 220 223 284 211 226 262 267 223 217 237 207 204 220 223 273 209 238 233 246 232 235 248 219 238 239 227 217 247 220 217 230 211 230 244 236 212 256 219 224 234 234 245 233 227 255 238 230 274 235 225 232 238 245 244 259 258 231 227 220 228 233 204 247 229 255 242 210 255 217 219 230 239 238 214 221 243 256 237 232 257 224 227 228 250 249 241 244 226 230 263 212 245 229 236 219 240 243 240 237 255 239 217 236 216 236 222 255 233 216 232 261 276 230 224 246 242 232 255 222 260 232 248 229 258 238 223 261 241 229 233 243 244 222 238 227 211 235 221 244 222 240 221 234 225 232 227 227 224 230 225 243 238 243 255 234 229 238 258 257 229 236 238 241 236 226 226 214 248 228 269 248 229 246 272 246 200 221 238 217 248 232 236 235 238 227 208 266 246 236 245 225 214 234 240 206 222 275 227 220 240 250 213 215 246 248 223 217 207 235 242 231 259 233 230 244 219 231 232 247 263 249 222 237 258 268 248 214 242 257 230 231 244 259 240 223 239 218 235 209 268 242 237 243 226 259 205 245 236 239 221 228 255 240 238 230 278 246 231 232 231 235 207 218 244 213 270 266 264 241 244 226 222 256 241 207 223 248 209 229 218 237 257 229 247 267 214 244 220 250 261 279 218 246 231 229 265 246 213 225 211 236 234 259 233 272 211 219 243 256 256 227 238 219 227 247 232 248 246 233 225 268 249 281 245 231 258 234 284 222 228 228 271 244 224 208 222 282 245 282 246 248 243 244 231 229 237 225 224 239 219 229 219 245 221 244 232 268 242 237 244 259 260 236 256 264 212 236 223 260 236 220 224 213 237 236 219 225 232 226 231 231 225 241 236 242 233 244 224 212 217 230 267 259 230 224 239 211 229 219 239 205 248 231 235 233 250 236 208 228 228 226 260 233 211 207 220 216 270 231 239 235 210 241 217 250 230 206 209 249 255 206 221 227 255 259 264 217 232 230 237 226 229 246 225 227 243 215 227 231 227 246 216 235 264 260 236 216 271 258 249 267 278 218 218 244 245 189 241 242 240 270 241 259 225 275 242 202 228 246 215 259 234 229 222 228 230 227 232 216 204 220 243 245 257 217 246 249 206 242 242 227 235 242 242 233 214 235 265 208 257 249 235 247 215 247 217 269 214 220 238 222 211 224 264 235 233 234 224 226 243 226 245 246 239 227 233 271 245 244 239 224 232 238 266 231 229 244 224 221 224 268 231 242 216 233 237 257 242 247 269 216 263 238 210 247 219 239 240 239 232 220 231 248 223 256 238 239 221 223 227 218 255 226 227 231 241 203 269 235 245 229 258 260 226 222 244 258 248 234 213 236 242 244 275 248 261 199 233 249 230 267 241 224 228 244 257 238 265 286 221 232 233 267 247 241 242 264 235 245 292 247 226 269 241 206 206 246 216 241 241 233 246 226 228 249 230 236 235 239 256 231 227 257 222 228 243 231 222 263 258 217 229 258 255 249 225 225 240 272 246 267 227 247 247 238 243 244 233 243 226 257 227 234 258 237 213 247 215 234 231 225 243 243 230 243 239 258 231 282 273 265 228 233 213 227 240 255 237 244 238 288 212 235 213 221 230 237 246 224 221 238 238 239 241 271 208 213 229 238 237 256 236 203 236 229 258 267 259 210 239 259 248 241 217 256 264 246 248 232 257 263 239 240 221 225 235 239 249 237 238 241 244 224 230 244 231 219 237 245 239 244 242 260 239 246 240 227 220 270 247 244 260 226 245 255 226 238 236 233 231 260 216 241 243 244 213 243 259 222 257 222 217 267 260 228 246 256 234 237 239 259 209 269 248 226 223 258 237 249 221 233 220 233 208 240 232 248 232 224 225 240 231 245 232 244 241 197 206 233 256 239 227 280 231 246 247 240 217 226 277 227 241 264 233 270 231 268 219 238 233 230 271 229 235 247 255 247 247 235 238 249 258 312 238 220 245 234 246 206 225 269 243 237 240 273 238 237 210 242 236 256 247 206 228 263 231 227 262 215 236 223 240 256 234 235 233 221 235 235 235 238 246 236 223 233 230 248 239 233 264 256 235 242 226 236 239 242 245 217 229 226 237 278 255 235 255 260 240 240 245 226 249 197 229 265 241 248 228 244 244 218 242 235 246 210 228 241 219 249 231 230 218 256 223 247 236 263 234 250 237 247 230 221 248 265 286 226 226 218 257 244 271 243 240 241 236 235 207 240 259 228 241 223 240 266 264 258 237 241 258 269 247 263 266 233 263 233 238 236 224 262 267 259 257 262 228 226 233 255 264 248 243 240 233 271 276 217 222 268 271 222 257 258 236 283 236 264 280 279 234 273 287 239 277 262 280 297 274 266 267 255 289 260 289 262 245 238 271 247 278 223 290 260 295 258 262 256 265 268 265 259 263 283 248 284 248 275 280 244 280 259 269 245 263 273 258 259 264 265 224 241 264 231 270 275 244 247 273 245 242 249 273 279 233 225 236 238 259 238 260 294 237 236 255 240 245 250 203 275 245 260 240 263 269 249 258 246 237 229 271 210 249 243 260 226 226 235 238 241 238 259 261 262 218 242 232 259 262 197 267 247 239 255 220 265 248 231 243 243 236 237 245 259 240 230 233 231 231 224 237 234 247 228 269 236 210 256 237 236 262 257 258 263 201 240 230 216 246 211 211 238 227 224 221 220 267 246 222 244 230 224 266 240 242 235 263 239 261 219 255 242 224 211 241 261 226 248 243 211 245 231 231 210 224 206 239 225 237 226 239 207 209 237 225 256 262 244 248 241 230 239 246 236 231 229 217 259 228 243 247 212 255 207 243 255 246 241 242 233 228 269 232 223 216 241 231 204 247 229 240 242 258 237 222 214 231 248 218 262 235 268 233 265 258 273 211 217 217 230 219 272 202 264 264 228 248 275 267 223 236 231 247 224 221 226 245 263 237 228 247 248 218 229 243 265 248 234 200 228 256 218 209 212 282 233 234 243 221 240 203 257 238 229 220 247 225 248 236 209 245 248 227 218 230 230 232 241 258 212 218 231 275 229 273 246 221 258 241 237 261 245 239 235 266 266 216 215 243 230 215 228 218 262 249 236 280 246 263 256 220 245 236 235 230 238 222 216 239 257 239 264 228 214 235 242 236 270 275 235 244 234 246 236 259 213 246 232 236 236 242 246 222 244 232 245 232 229 244 235 233 269 206 234 226 197 246 242 238 227 230 221 236 240 245 213 236 224 216 234 220 223 264 262 235 233 239 233 228 214 268 247 236 231 234 218 235 230 227 226 260 245 239 246 231 258 259 212 233 227 217 233 220 241 220 260 250 242 245 231 227 260 228 225 211 241 218 259 203 216 248 217 226 228 242 237 232 229 225 243 256 262 244 204 229 225 243 243 225 261 248 241 226 204 204 234 226 260 241 216 209 255 240 216 233 231 214 238 227 232 237 248 223 240 229 223 230 270 237 200 210 227 238 266 220 227 225 261 222 234 210 236 237 215 239 246 249 206 234 247 213 258 217 213 224 233 237 226 236 221 227 227 229 226 227 238 230 228 267 258 257 202 236 220 262 238 235 231 237 217 214 214 239 224 209 236 221 238 242 231 237 256 229 230 257 218 221 249 225 241 247 230 223 240 226 233 230 224 223 218 250 266 230 235 249 225 241 259 260 239 239 228 227 245 213 272 214 230 224 209 222 237 237 248 216 222 206 220 261 231 245 237 240 217 248 222 248 248 233 222 229 261 236 226 240 276 224 255 213 212 247 226 255 233 227 247 277 227 223 225 235 232 221 233 258 228 255 218 244 231 219 227 222 206 215 222 237 236 225 233 245 226 230 242 234 228 231 237 237 223 214 214 229 239 263 234 232 227 262 230 224 229 232 238 210 245 222 236 224 207 233 235 247 241 258 226 208 229 223 235 234 212 266 232 214 240 270 218 264 243 214 230 221 199 224 257 248 276 240 210 263 243 231 247 260 248 234 261 266 230 222 259 239 212 265 229 238 217 234 249 221 250 228 213 214 238 218 208 246 246 226 224 241 231 234 221 214 235 219 225 219 259 235 249 223 255 238 234 204 221 216 232 236 213 262 235 216 240 207 242 225 223 219 224 240 227 219 238 221 217 257 232 217 227 243 225 221 262 231 219 243 223 230 238 275 212 237 247 248 248 231 240 223 243 219 262 243 232 229 256 238 228 242 222 233 219 227 268 221 280 215 239 210 246 242 243 216 236 224 246 234 244 228 248 245 271 278 256 224 240 228 237 219 209 222 239 227 212 191 235 213 239 256 231 242 212 258 230 242 217 220 239 205 229 241 234 219 234 246 230 242 238 224 212 246 259 220 240 243 208 209 233 242 190 216 214 210 198 220 237 218 241 216 221 261 227 233 244 238 225 266 215 225 230 260 217 233 216 229 269 202 227 248 261 215 226 235 260 214 247 228 230 226 230 213 258 240 224 246 236 237 230 237 232 243 249 219 229 221 220 232 235 242 230 233 227 231 220 239 239 240 268 229 245 217 267 203 235 246 232 237 259 230 232 229 238 249 215 212 221 239 250 247 238 248 223 257 220 217 255 244 210 232 239 260 247 230 238 233 242 228 232 231 262 211 210 230 233 238 259 273 249 229 225 222 194 211 244 228 213 223 243 224 229 233 243 222 259 242 223 219 243 207 237 238 260 229 222 197 215 222 230 221 223 266 261 235 219 200 243 227 243 255 227 225 229 233 229 239 220 247 247 237 219 225 239 221 220 242 225 217 232 262 239 208 226 237 228 219 209 233 221 197 236 192 220 222 231 219 225 237 258 255 242 248 200 242 233 249 211 245 259 215 239 225 234 221 226 212 232 269 226 265 243 222 224 211 229 222 230 220 216 227 204 284 191 218 228 257 261 264 220 232 233 233 227 239 224 209 269 260 215 239 234 232 208 244 221 213 241 222 241 247 237 223 242 202 237 232 241 216 237 226 233 195 248 230 231 260 224 210 232 223 247 199 218 229 238 242 235 218 255 235 224 235 225 257 245 240 217 244 212 267 217 233 240 258 225 216 250 233 241 231 211 222 219 257 220 236 217 227 223 249 259 205 216 222 220 240 234 231 217 258 239 262 272 226 221 224 239 239 237 215 225 200 249 204 240 205 282 229 242 224 260 203 236 231 200 210 267 217 224 232 263 235 274 249 224 214 248 232 232 221 227 233 201 225 241 232 242 245 229 205 218 257 233 236 222 237 233 243 214 246 225 232 227 221 218 227 207 248 228 241 227 262 225 249 223 231 245 255 216 233 230 247 239 219 223 233 250 244 264 238 236 256 233 212 212 231 214 221 218 249 215 238 219 268 229 221 230 263 232 245 230 255 275 240 255 237 232 220 230 226 221 215 215 275 217 210 230 230 223 239 226 227 244 216 221 223 219 229 248 228 246 246 236 270 213 226 230 205 267 232 232 231 262 228 262 247 244 231 241 219 239 223 204 222 231 257 256 221 258 250 241 249 221 209 268 231 240 216 265 234 211 255 218 226 238 223 238 245 257 230 220 238 260 273 236 225 226 225 221 228 203 227 217 230 229 222 257 216 234 224 260 216 256 224 200 224 233 248 226 213 271 236 246 231 237 240 248 236 218 236 232 268 222 237 241 236 230 228 228 230 262 212 226 205 219 218 241 216 241 222 224 236 259 257 234 267 225 235 242 238 243 231 228 234 245 243 202 242 223 224 237 243 226 250 199 265 244 244 207 228 245 227 240 264 226 259 224 232 217 222 237 255 230 247 247 225 225 224 231 216 220 233 231 221 234 215 264 214 240 231 237 257 225 222 276 267 240 226 223 228 214 245 219 238 227 244 237 264 239 223 259 229 214 225 230 212 242 235 244 262 245 201 235 236 239 247 236 231 238 198 221 271 223 233 209 224 256 238 233 242 243 261 229 212 258 229 237 224 222 232 223 232 213 233 242 218 245 247 212 233 261 274 231 228 224 221 211 227 262 248 246 206 243 231 239 226 213 245 233 256 258 236 232 239 220 216 239 245 259 250 233 241 234 215 237 219 223 204 228 258 229 270 231 223 241 221 243 236 233 221 210 234 225 229 226 261 225 238 218 237 260 222 259 220 215 231 257 241 214 216 231 246 233 240 258 233 246 262 244 232 255 241 226 244 269 224 207 232 220 224 223 244 248 255 221 244 267 284 224 237 273 242 220 247 269 259 232 231 257 247 222 256 266 256 220 222 236 225 270 243 235 238 244 255 240 266 240 271 258 267 263 224 219 264 243 241 232 208 240 215 256 256 267 247 221 233 224 223 222 237 278 236 262 233 235 259 238 237 237 226 246 235 226 223 267 220 246 229 241 233 237 246 256 247 224 241 261 236 233 250 244 240 248 256 257 270 220 229 263 232 236 235 242 230 235 220 217 265 223 234 263 239 248 259 265 268 220 232 259 238 240 225 249 246 236 230 265 238 221 204 256 243 223 230 219 222 231 257 264 228 210 246 204 228 271 249 212 232 234 259 270 233 214 212 207 228 247 229 256 260 241 230 237 257 221 231 218 197 271 273 233 255 235 199 214 257 224 219 228 223 245 222 243 257 243 243 197 219 220 271 255 236 227 261 208 272 226 238 240 225 264 231 218 228 248 228 245 212 233 239 217 238 223 245 234 246 203 233 203 268 234 232 215 238 245 211 260 233 239 223 248 269 217 221 259 224 265 261 240 266 235 240 203 243 249 239 232 186 218 241 249 237 243 246 242 220 274 229 204 219 231 236 246 198 265 239 214 233 226 237 225 244 246 217 220 233 238 242 228 237 241 222 233 256 240 244 234 223 233 226 227 224 225 260 236 255 235 262 213 220 258 250 237 214 263 228 257 225 246 215 228 246 237 223 267 198 247 204 278 229 255 232 230 233 265 259 248 261 247 234 207 227 231 215 231 229 225 238 265 236 222 242 226 239 255 220 234 241 271 243 216 234 212 237 232 228 238 256 258 258 261 229 237 257 200 238 221 219 281 240 218 245 219 224 268 214 271 244 224 240 261 234 219 237 246 243 244 241 228 255 223 229 222 234 216 230 260 238 265 241 235 235 240 225 238 257 238 256 275 231 241 242 243 207 269 257 231 249 226 264 224 190 228 259 245 246 256 240 238 262 262 225 261 260 215 218 244 225 249 245 222 228 272 261 232 214 227 210 217 258 231 240 240 227 223 269 218 199 242 248 266 257 239 230 228 220 241 203 247 238 242 231 217 256 237 247 259 235 242 244 229 240 216 259 216 231 213 221 265 245 249 237 233 236 282 267 226 223 225 277 225 274 224 244 239 242 242 267 248 242 264 258 242 236 231 269 236 232 216 222 230 243 237 233 233 287 229 261 230 246 208 219 232 248 235 236 229 230 230 226 257 235 229 241 238 263 228 266 248 222 227 237 220 208 239 232 229 223 234 218 243 228 215 246 224 242 238 245 223 221 247 226 221 248 221 235 217 237 250 233 216 238 238 261 248 250 256 244 220 215 245 257 235 223 249 220 219 239 255 226 238 239 247 230 208 259 230 244 236 223 242 256 226 244 262 224 261 279 191 255 259 257 228 224 228 256 232 222 257 260 249 234 257 229 225 226 260 245 246 275 226 232 202 227 247 258 221 257 246 237 225 255 227 237 230 238 294 215 274 228 239 256 258 222 230 255 219 247 247 239 246 247 237 223 261 262 245 221 243 225 229 228 232 232 263 215 233 237 224 232 238 236 256 248 259 189 239 231 235 240 241 233 245 240 249 244 241 246 248 233 235 201 205 225 245 205 246 247 239 243 261 236 237 245 239 231 227 195 256 243 226 242 238 232 237 227 236 222 244 260 234 257 264 240 226 268 261 226 217 231 245 248 239 235 244 225 242 255 236 225 249 257 271 199 233 236 246 244 224 247 241 238 255 237 219 221 236 229 242 212 235 217 231 244 206 234 255 222 237 229 232 240 225 230 239 263 239 234 260 258 202 224 234 229 227 244 219 227 238 229 250 228 212 220 233 212 228 235 213 224 236 232 225 240 206 234 245 242 229 227 216 217 204 231 235 214 222 227 233 248 237 218 246 217 231 227 241 246 228 239 231 261 234 228 243 241 248 227 219 217 236 259 231 257 231 244 211 236 237 210 227 257 256 241 233 237 235 213 231 223 236 231 243 226 257 244 247 201 201 230 228 236 218 240 242 234 241 266 266 230 232 220 216 260 238 231 241 206 236 209 221 229 256 237 245 217 231 225 235 263 233 238 236 211 236 263 238 264 245 198 231 242 233 246 255 242 277 246 248 236 234 221 260 189 244 240 250 227 270 241 246 230 247 214 239 201 220 238 226 199 248 247 245 227 246 239 263 246 239 220 223 219 246 241 219 246 231 255 227 229 266 240 231 273 208 239 226 271 255 220 216 255 238 242 234 246 269 237 230 227 213 235 231 229 227 243 234 259 286 221 239 236 236 229 232 235 220 236 249 210 233 221 209 246 222 237 238 217 243 200 233 229 232 236 220 260 239 265 224 257 233 265 228 246 230 232 207 214 234 220 244 207 260 212 216 244 261 237 233 216 225 244 270 226 237 224 241 209 223 238 236 226 257 199 266 255 240 256 235 246 230 233 243 221 232 239 238 231 238 231 236 224 261 233 241 243 263 225 274 206 210 256 219 244 242 266 235 220 234 230 256 234 207 250 231 223 216 214 228 264 227 267 258 243 238 246 249 280 242 260 231 228 239 250 228 255 239 256 255 258 265 231 255 240 255 234 242 234 225 261 256 261 270 228 238 227 260 237 240 255 241 212 263 224 281 226 241 241 267 236 255 224 223 248 256 238 233 218 231 229 246 256 244 266 257 239 255 233 275 222 259 235 249 245 234 241 237 242 224 243 265 206 235 244 236 265 266 227 226 255 243 248 237 248 231 257 230 250 238 228 259 290 220 268 228 233 216 227 242 231 267 246 250 244 228 237 218 255 241 222 230 232 238 227 235 268 256 263 224 241 264 239 248 218 246 239 220 259 239 264 239 234 229 257 222 224 233 246 247 259 221 241 269 271 224 247 263 231 229 248 268 244 211 206 240 237 258 230 246 224 243 224 228 233 224 248 267 245 219 245 262 218 243 233 243 259 243 244 247 238 237 212 229 210 221 258 239 214 275 220 225 210 226 214 227 242 239 212 248 245 231 248 258 220 225 239 244 230 215 234 242 235 236 234 249 262 218 271 239 231 249 231 243 247 229 224 247 256 269 234 231 222 244 273 261 238 246 260 258 234 233 260 209 266 244 267 225 245 230 225 239 259 240 260 235 245 234 219 256 239 227 218 267 222 247 216 214 237 222 258 248 256 258 259 235 258 258 256 229 234 237 249 214 274 223 249 239 237 245 225 229 227 225 211 246 235 230 222 224 218 224 228 262 242 216 245 232 225 234 231 227 263 240 235 261 243 232 238 238 227 228 214 248 269 245 240 232 262 247 210 242 225 241 267 274 230 222 217 237 242 225 220 239 215 248 259 227 238 257 236 236 261 224 255 234 202 235 241 218 229 234 236 250 237 223 256 223 225 231 230 263 236 235 230 231 243 257 249 243 217 211 241 231 230 241 242 243 239 237 267 245 237 227 239 238 237 225 275 229 231 228 265 207 255 224 245 218 223 233 239 249 243 257 242 226 241 250 238 267 235 206 270 234 229 232 232 260 224 240 224 249 237 243 248 220 220 227 228 223 237 233 257 237 228 261 264 247 235 233 231 249 219 242 245 248 229 260 233 238 259 243 236 216 229 244 224 240 238 272 256 236 220 215 245 215 215 259 213 233 276 229 214 231 234 229 222 224 249 250 214 245 212 229 260 246 236 234 225 211 216 213 270 248 236 265 202 217 272 229 244 238 240 231 273 234 245 233 234 272 233 231 243 270 257 235 237 243 260 221 235 242 227 255 259 247 233 214 229 242 217 246 237 225 257 272 234 243 204 238 213 233 240 218 256 265 236 244 211 217 235 212 233 241 246 249 216 247 242 237 228 230 269 257 234 223 216 249 228 257 233 230 269 258 227 235 241 226 236 271 208 236 281 235 239 239 266 264 249 269 244 221 230 246 257 267 263 200 235 215 256 239 209 248 245 255 246 222 247 270 259 248 239 291 247 229 268 237 228 255 243 249 224 232 261 297 239 219 270 271 264 240 237 273 249 263 248 280 245 221 262 257 255 270 243 278 249 221 269 259 255 261 220 257 240 250 259 250 249 259 247 229 274 268 268 245 242 241 246 221 264 291 242 239 214 220 246 206 255 289 243 223 232 265 269 232 256 227 223 248 220 259 248 249 223 241 229 268 243 234 243 247 287 258 258 219 288 221 231 233 245 280 279 260 211 244 241 228 296 227 222 220 240 233 214 236 226 256 248 220 237 240 217 223 270 265 261 232 242 231 247 226 260 262 276 262 227 249 234 227 230 257 239 248 257 236 256 225 236 230 230 229 256 259 206 217 229 231 281 239 235 227 232 270 245 234 226 265 229 234 270 223 224 256 232 242 220 234 239 241 214 247 233 217 259 256 249 232 241 234 223 242 232 248 233 221 226 226 260 207 261 241 243 219 247 245 264 248 230 259 228 221 210 239 255 277 257 278 225 237 257 225 264 219 247 248 220 238 226 244 243 236 229 255 239 240 236 236 228 241 266 229 205 242 223 225 255 261 237 220 215 263 238 236 229 211 237 255 226 225 232 222 231 236 230 245 248 260 286 228 261 237 241 242 238 240 230 234 243 238 219 274 246 234 232 240 264 239 228 265 226 238 260 227 228 230 260 236 255 212 237 228 228 231 232 231 243 255 234 237 229 204 225 246 215 247 244 222 237 247 242 242 246 247 244 256 276 271 246 267 219 255 233 263 236 228 247 221 229 248 266 257 256 236 244 258 261 233 230 267 260 211 245 246 256 258 213 273 232 207 237 243 227 255 221 228 209 224 227 228 238 239 262 233 229 244 257 228 260 241 220 264 234 231 230 256 256 274 246 230 234 213 216 219 265 241 241 235 266 265 218 243 228 221 241 236 193 264 234 255 236 204 233 257 225 246 238 219 223 248 258 244 238 248 248 262 257 265 263 246 261 226 210 263 262 231 241 234 236 239 234 240 259 245 223 260 224 232 245 237 233 234 235 214 244 235 259 270 242 241 268 235 245 259 273 242 241 243 237 225 232 223 218 198 232 234 212 230 284 214 246 217 237 243 240 239 221 232 226 229 227 223 270 226 243 259 228 241 218 260 233 225 248 217 238 282 234 248 230 228 243 213 271 228 222 220 197 247 237 242 249 212 224 262 256 228 217 227 242 256 256 263 272 259 259 247 226 261 217 259 245 237 206 215 214 224 206 243 240 240 240 236 269 266 195 249 220 239 240 236 229 228 223 230 242 240 248 233 230 239 244 211 250 244 260 232 244 270 248 261 211 221 237 236 246 233 265 241 234 255 249 257 227 264 248 239 213 211 244 236 228 225 273 227 248 226 217 205 229 268 230 238 246 214 245 218 221 240 244 232 223 233 229 265 235 241 268 243 220 225 231 225 263 221 236 240 224 257 225 257 230 273 229 256 256 240 241 236 218 247 255 235 261 229 245 232 271 233 241 215 220 239 269 261 225 246 211 230 224 240 240 244 242 240 212 241 243 214 246 261 242 235 229 244 218 233 226 230 218 243 245 220 244 229 238 220 207 234 256 228 225 233 236 234 221 230 241 266 225 210 247 211 212 257 216 241 239 232 221 232 262 230 248 222 220 263 273 228 227 226 235 213 222 216 266 243 217 271 223 223 245 249 255 236 241 214 283 250 249 228 232 202 222 238 265 266 219 231 257 242 206 204 224 215 225 229 223 247 261 216 211 222 279 243 226 219 232 233 202 274 247 263 232 234 220 259 241 234 249 233 237 240 241 246 232 231 207 248 262 245 207 220 227 242 228 257 224 258 220 242 228 229 228 226 240 263 228 230 263 215 215 228 234 244 236 249 224 279 222 230 236 261 246 256 227 260 238 230 255 236 258 225 231 249 210 244 232 243 228 235 242 215 235 216 216 226 227 235 215 235 256 228 230 238 223 226 241 226 237 227 234 228 258 226 244 235 231 263 248 224 219 219 226 263 246 239 220 218 246 231 237 208 246 265 208 206 262 198 243 260 228 236 220 236 226 237 260 237 256 225 241 214 224 240 225 236 266 228 235 232 216 219 230 222 220 212 241 264 283 226 224 234 231 221 216 255 233 262 263 213 217 238 220 209 219 245 222 232 241 250 240 240 281 239 205 231 217 238 211 249 238 242 265 229 214 221 210 229 224 215 222 272 243 267 220 255 209 229 195 237 229 244 227 242 249 222 239 268 217 237 229 248 213 255 204 215 248 236 224 263 233 229 228 247 225 231 239 220 271 220 237 245 243 235 240 244 246 222 234 258 226 240 267 228 228 219 235 256 229 232 244 212 242 221 247 217 189 273 230 218 217 228 238 258 268 239 223 246 225 229 218 230 238 225 257 231 229 232 231 283 260 238 261 240 247 231 247 249 211 244 203 223 243 245 200 272 263 236 220 236 224 228 231 221 229 227 234 231 241 235 241 224 228 228 240 201 238 228 222 224 220 249 223 246 235 225 211 243 261 209 223 240 228 218 267 261 247 212 225 234 247 240 233 209 217 248 255 224 207 257 233 246 237 233 243 271 236 238 247 229 257 236 212 226 227 221 229 213 221 238 240 238 217 232 207 234 232 216 279 232 238 248 239 224 246 248 211 239 219 245 244 238 245 247 242 232 244 218 236 216 236 213 231 229 273 228 236 229 235 225 206 239 233 230 245 242 230 215 221 231 204 201 240 219 234 199 230 244 256 245 255 213 286 202 248 259 218 246 202 221 227 226 215 206 236 234 214 219 235 235 232 237 245 222 233 223 195 216 249 236 250 245 229 244 226 233 238 232 266 227 230 224 232 196 268 265 214 199 222 220 238 226 222 223 229 241 262 222 211 232 222 237 230 208 242 229 259 218 225 222 234 245 255 222 247 269 224 246 229 217 248 260 230 214 225 234 230 256 217 210 246 232 215 247 232 234 227 215 212 240 222 258 225 214 221 250 229 243 258 255 240 255 215 206 243 231 238 224 242 270 262 233 236 244 221 210 238 235 239 224 220 246 256 236 240 245 240 237 238 207 248 272 224 231 239 261 234 239 214 218 242 232 260 245 222 240 229 218 259 217 216 250 245 192 210 249 229 208 219 216 228 248 212 227 239 256 238 234 240 259 233 191 237 256 247 222 232 205 228 236 244 237 261 209 239 234 227 255 223 217 255 243 230 227 231 256 235 240 247 231 226 219 245 220 225 208 226 224 223 240 228 210 246 221 255 227 246 243 210 231 234 266 224 240 248 216 245 208 235 256 227 245</counts>
			</dataPoints>
		</scan>
	</xrdMeasurement>
</xrdMeasurements>