File: data/XRD/XG-Vakuum/XG-750/W6821-1C_XG_Vakuum_750.xrdml
<xrdMeasurements xmlns="http://www.xrdml.com/XRDMeasurement/2.1" xmlns:xsi="http://www.w3.org/2001/XMLSchema-instance" xsi:schemaLocation="http://www.xrdml.com/XRDMeasurement/2.1 http://www.xrdml.com/XRDMeasurement/2.1/XRDMeasurement.xsd" status="Completed">
	<comment>
		<entry>Configuration=Factory configuration, Owner=User-1, Creation date=7/8/2013 4:01:53 PM</entry>
		<entry>Goniometer=PW3050/65 (Theta/2Theta); Minimum step size 2Theta:0.0001; Minimum step size Omega:0.0001</entry>
		<entry>Sample stage=MRD Cradle; Minimum step size Phi:0.01; Minimum step size Chi:0.01; Minimum step size X:0.01; Minimum step size Y:0.01; Minimum step size Z:0.001</entry>
		<entry>Diffractometer system=XPERT-PRO</entry>
		<entry>Measurement program=C:\PANalytical\Data Collector\Programs\Jorrit\2thom\_absolute_2th-om_10-130deg_PIXscan_56min.xrdmp, Identifier={15BCCF57-2807-42BD-B5B9-ECC0B3DC9284}</entry>
		<entry>Batch program=C:\PANalytical\Data Collector\Programs\SimonL\batch6x_2thom_10-130°_z9.1_x0,10,20,30_y20,40_57min - Kopie.xrdmp, Identifier={6B3EF4D3-441D-47FD-9EA5-077D311040EA}</entry>
	</comment>
	<sample type="To be analyzed">
		<id></id>
		<name></name>
		<preparedBy></preparedBy>
	</sample>
	<xrdMeasurement measurementType="Scan" status="Completed" sampleMode="Reflection">
		<comment>
			<entry>_absolute_2th-om_10-130deg_PIXscan_56min</entry>
			<entry>PHD Lower Level = 4.83 (keV), PHD Upper Level = 11.27 (keV)</entry>
		</comment>
		<usedWavelength intended="K-Alpha 1">
			<kAlpha1 unit="Angstrom">1.5405980</kAlpha1>
			<kAlpha2 unit="Angstrom">1.5444260</kAlpha2>
			<kBeta unit="Angstrom">1.3922500</kBeta>
			<ratioKAlpha2KAlpha1>0.5000</ratioKAlpha2KAlpha1>
		</usedWavelength>
		<incidentBeamPath>
			<radius unit="mm">320.00</radius>
			<xRayTube id="1010048" name="Empyrean Cu LFF HR (9430 033 7310x) DK442154">
				<tension unit="kV">40.0</tension>
				<current unit="mA">40.0</current>
				<anodeMaterial>Cu</anodeMaterial>
				<focus type="Line">
					<length unit="mm">12.0</length>
					<width unit="mm">0.4</width>
					<takeOffAngle unit="deg">4.2</takeOffAngle>
				</focus>
			</xRayTube>
			<xRayMirror id="27010001" name="Inc. Beam Cu W/Si (parabolic MRD)" hybrid="false">
				<crystal type="Graded" shape="Parabolic">W/Si</crystal>
				<acceptanceAngle unit="deg">0.800</acceptanceAngle>
				<length unit="mm">60.0</length>
			</xRayMirror>
			<sollerSlit id="21010002" name="Soller slits 0.04 rad.">
				<opening unit="rad">0.0400</opening>
			</sollerSlit>
			<mask id="22030008" name="Fixed mask 4 mm">
				<distanceToSample unit="mm">220.00</distanceToSample>
				<width unit="mm">4.00</width>
			</mask>
			<divergenceSlit id="22010011" name="Fixed slit 1/32°" xsi:type="fixedDivergenceSlitType">
				<distanceToSample unit="mm">220.00</distanceToSample>
				<height unit="mm">0.05</height>
			</divergenceSlit>
		</incidentBeamPath>
		<diffractedBeamPath>
			<radius unit="mm">320.00</radius>
			<sollerSlit id="21010002" name="Soller slits 0.04 rad.">
				<opening unit="rad">0.0400</opening>
			</sollerSlit>
			<receivingSlit id="22010001" name="Fixed slit 4°">
				<height unit="mm">5.88</height>
			</receivingSlit>
			<detector id="7010017" name="PIXcel3D 1x1 detector" xsi:type="areaDetectorType">
				<phd unit="%">
					<lowerLevel>30.0</lowerLevel>
					<upperLevel>70.0</upperLevel>
				</phd>
				<mode>Scanning</mode>
				<activeChannelsEquatorial>255</activeChannelsEquatorial>
				<activeChannelsAxial>255</activeChannelsAxial>
				<pitchEquatorial unit="mm">0.05500</pitchEquatorial>
				<pitchAxial unit="mm">0.05500</pitchAxial>
				<readOutPeriod unit="seconds">0.135</readOutPeriod>
			</detector>
		</diffractedBeamPath>
		<scan appendNumber="0" mode="Continuous" scanAxis="2Theta-Omega" status="Completed">
			<header>
				<startTimeStamp>2024-10-11T16:25:38+02:00</startTimeStamp>
				<endTimeStamp>2024-10-11T17:21:43+02:00</endTimeStamp>
				<author>
					<name>PRO-MRD</name>
				</author>
				<source>
					<applicationSoftware version="6.1b">Data Collector</applicationSoftware>
					<instrumentControlSoftware version="7.0E 20130304">XPERT-PRO</instrumentControlSoftware>
					<instrumentID>0000000011142674</instrumentID>
				</source>
			</header>
			<dataPoints>
				<positions axis="2Theta" unit="deg">
					<startPosition>9.99826193</startPosition>
					<endPosition>129.99755682</endPosition>
				</positions>
				<positions axis="Omega" unit="deg">
					<startPosition>4.99913096</startPosition>
					<endPosition>64.99877841</endPosition>
				</positions>
				<positions axis="Phi" unit="deg">
					<commonPosition>0.00</commonPosition>
				</positions>
				<positions axis="Chi" unit="deg">
					<commonPosition>0.00</commonPosition>
				</positions>
				<positions axis="X" unit="mm">
					<commonPosition>0.00</commonPosition>
				</positions>
				<positions axis="Y" unit="mm">
					<commonPosition>0.00</commonPosition>
				</positions>
				<positions axis="Z" unit="mm">
					<commonPosition>9.100</commonPosition>
				</positions>
				<commonCountingTime unit="seconds">32.895</commonCountingTime>
				<counts 459 446 474 450 457 451 462 489 493 421 467 407 497 430 458 457 484 452 438 439 428 462 483 434 443 490 447 437 480 427 478 432 484 440 429 435 465 467 426 463 451 474 452 457 477 425 473 420 426 442 415 426 456 447 463 447 421 461 476 448 479 444 456 439 418 389 460 423 410 473 437 427 440 407 420 404 427 434 466 434 409 417 410 429 445 416 412 433 422 426 444 426 453 435 406 445 404 388 470 404 436 421 430 401 448 420 400 404 407 443 421 425 416 441 408 389 422 465 403 448 423 449 403 431 409 374 391 424 454 400 412 441 414 411 418 475 386 404 403 418 418 421 391 408 454 431 391 417 390 420 413 402 409 430 443 394 406 412 404 407 410 422 427 408 431 430 419 415 380 372 405 371 434 400 408 386 380 381 392 392 411 437 385 428 386 397 397 403 391 394 423 407 398 426 389 374 442 419 399 394 412 393 430 402 412 389 380 372 416 406 407 383 381 419 372 423 429 411 382 411 372 370 406 391 396 353 412 387 356 405 340 401 404 413 374 362 411 430 411 381 397 380 370 382 374 385 411 356 400 336 405 413 360 384 403 361 347 399 385 366 380 395 394 393 404 377 411 370 335 399 396 427 374 386 380 377 407 382 359 358 395 382 369 397 421 394 374 372 367 346 388 370 389 411 335 368 370 345 359 370 389 361 362 359 358 346 383 381 363 370 337 350 357 326 369 393 365 358 347 390 373 424 373 342 384 355 393 361 378 369 377 358 371 385 338 356 353 345 354 368 336 350 354 389 393 372 340 400 357 359 375 365 356 363 370 357 348 369 367 364 351 336 379 371 382 372 356 345 362 354 388 349 347 355 348 351 324 344 348 343 364 384 365 359 397 381 361 356 365 365 351 387 344 372 370 323 364 349 373 357 341 340 362 358 364 329 356 374 340 368 360 346 383 357 345 373 357 357 381 334 315 340 332 354 320 359 359 354 361 334 336 347 381 294 340 347 357 358 327 323 345 335 341 313 363 339 353 354 320 348 326 353 375 350 341 323 334 331 323 340 352 330 364 325 353 354 330 296 354 365 353 320 309 350 327 325 342 347 336 325 344 360 348 326 289 348 320 358 350 334 346 360 338 334 329 383 326 351 314 362 323 373 296 342 359 331 352 298 323 341 315 307 316 342 311 342 362 292 281 333 301 358 318 343 325 316 344 324 323 376 326 329 357 312 311 311 315 330 325 294 316 335 306 343 305 311 327 306 321 309 334 299 337 320 312 315 312 331 280 339 300 311 342 348 311 316 344 329 299 327 321 305 369 312 303 313 283 359 314 342 333 316 340 336 327 328 359 327 356 324 358 299 320 308 318 315 347 294 306 289 321 302 310 347 327 315 285 336 290 333 333 326 308 329 309 307 310 307 298 322 309 316 302 326 299 297 325 336 311 310 337 325 308 309 347 339 292 313 286 314 299 338 305 285 327 283 327 305 321 343 304 308 314 324 322 297 324 326 318 317 308 338 311 323 315 315 305 293 363 311 322 331 308 305 304 342 316 335 272 305 311 331 334 299 338 318 321 345 365 327 329 346 318 329 324 331 329 316 328 336 321 307 349 325 337 328 318 320 291 317 316 340 297 337 329 314 338 292 307 304 302 328 321 342 320 305 308 331 360 323 317 306 311 319 314 295 302 338 340 323 319 327 319 288 296 285 324 337 307 275 300 312 320 289 296 339 302 311 312 333 329 334 328 331 302 302 297 313 332 346 292 323 335 312 326 350 328 306 306 305 306 306 337 338 280 309 284 321 315 365 330 345 307 319 302 292 338 299 311 323 296 337 300 332 310 315 345 304 302 308 314 350 289 311 321 328 292 318 283 280 341 308 325 317 322 296 321 299 287 339 342 301 297 326 331 292 296 330 326 309 308 347 350 337 304 330 334 319 334 333 273 322 330 329 322 314 332 351 312 347 313 332 330 322 297 295 310 347 308 320 321 322 323 363 319 309 324 331 300 325 310 309 371 330 320 331 310 339 342 318 353 333 319 301 344 319 314 310 322 330 329 359 302 338 317 319 323 302 341 333 316 321 345 352 331 330 323 323 313 298 318 298 329 328 314 296 310 328 312 364 327 327 338 299 343 344 301 324 321 322 352 335 328 354 329 343 370 296 327 333 331 340 312 350 349 351 340 327 307 341 330 345 363 322 328 330 322 319 295 284 342 314 328 329 319 331 359 338 315 348 346 331 320 299 311 342 318 322 315 337 331 359 326 304 356 324 309 362 350 320 352 336 377 332 335 353 303 341 328 349 356 326 351 313 354 344 327 329 323 325 321 308 317 313 330 321 366 338 328 362 315 336 342 311 341 331 338 320 327 320 330 322 325 318 334 320 349 327 360 323 339 355 326 329 356 335 335 337 313 311 343 364 318 291 364 353 346 312 349 348 342 354 349 340 360 372 335 364 346 363 324 356 325 359 337 351 316 344 308 381 339 354 360 329 321 321 345 333 314 330 354 339 375 343 368 349 394 336 346 347 327 325 348 370 349 306 348 335 336 375 319 345 332 328 365 334 342 328 349 329 340 357 332 356 328 340 339 353 374 335 350 367 389 319 331 369 362 347 346 338 331 377 335 303 340 362 406 362 378 360 373 343 337 329 341 343 387 352 321 328 333 368 327 353 351 348 346 357 390 356 368 352 352 347 361 344 363 364 376 320 310 349 331 333 343 340 344 351 353 325 366 322 340 326 357 347 339 350 381 330 352 381 375 333 343 345 356 349 347 347 328 311 348 371 313 344 365 364 360 331 361 360 364 344 355 351 368 343 364 360 370 363 342 346 353 365 359 351 319 368 369 386 385 347 345 314 377 371 346 333 340 351 370 375 360 348 326 359 350 365 322 322 348 351 359 332 341 319 342 364 366 317 357 353 326 327 378 313 375 350 364 357 356 378 371 347 355 346 374 365 343 342 353 365 358 359 374 342 333 361 355 361 350 333 355 365 310 372 341 378 346 355 349 361 358 341 367 350 346 336 340 357 345 359 355 344 349 330 320 361 373 315 347 362 364 344 326 341 362 361 338 311 362 352 328 330 365 321 338 320 336 343 372 356 319 329 361 336 291 328 346 316 325 329 342 359 309 338 356 378 329 333 306 328 325 357 375 339 341 354 334 334 341 304 347 342 347 317 317 333 371 341 344 325 338 333 331 362 347 350 342 371 321 340 351 336 313 345 343 353 340 378 332 356 330 375 347 381 309 345 354 318 346 360 342 327 315 368 341 340 351 361 343 308 314 312 334 332 382 358 372 342 339 338 304 330 345 315 304 358 340 346 338 336 328 392 342 376 320 354 317 356 342 311 311 345 313 327 308 338 364 335 321 341 323 311 317 330 326 338 376 341 328 299 345 317 351 354 348 322 333 315 338 360 317 344 317 346 353 319 339 353 368 321 327 348 355 294 311 347 360 333 318 316 346 325 325 308 325 323 343 327 342 361 326 346 333 345 329 341 324 332 364 351 342 312 321 352 321 301 336 302 306 333 350 305 347 331 356 324 337 329 308 329 323 347 347 337 343 290 296 326 341 353 314 327 343 313 319 319 323 301 313 347 345 315 311 313 315 332 297 332 338 338 345 322 341 303 352 318 329 304 313 316 297 330 313 328 308 335 353 311 324 320 295 330 309 323 336 363 345 336 314 333 285 295 316 347 319 319 312 313 308 315 344 303 342 298 325 326 333 318 327 314 316 343 317 324 335 336 330 350 315 322 329 315 301 290 345 329 349 291 292 320 328 318 362 325 317 367 358 317 305 312 261 357 315 326 310 311 321 278 340 318 297 323 318 287 346 323 316 333 312 313 336 326 279 327 307 322 336 286 353 317 299 318 304 288 319 298 297 310 289 325 317 312 299 312 302 304 328 328 325 316 321 338 322 305 303 269 314 305 290 304 287 325 315 306 315 293 290 305 297 297 304 322 312 308 309 287 319 301 331 301 332 332 358 271 304 312 311 326 282 314 315 318 342 309 297 303 303 300 314 281 307 303 308 300 294 303 333 295 348 330 306 332 327 280 318 282 298 300 294 289 294 303 315 297 316 297 290 326 319 288 324 318 275 316 333 290 350 303 301 306 323 315 298 290 310 331 270 309 310 330 315 328 270 310 325 286 310 315 302 304 312 300 292 299 315 318 272 309 324 313 356 299 316 312 328 311 334 315 303 307 308 260 263 303 275 343 295 270 308 283 326 292 313 296 323 292 297 319 323 307 318 303 313 328 266 267 321 330 299 282 284 297 270 281 304 294 301 306 281 297 345 291 282 282 311 302 308 310 288 292 273 241 308 299 316 316 291 285 280 299 312 297 327 294 273 282 290 307 307 300 282 304 319 296 260 304 311 283 264 292 344 301 303 289 306 282 330 278 289 283 266 282 279 274 299 298 308 300 283 322 277 296 334 292 297 313 305 269 280 290 290 301 288 272 287 290 283 281 309 313 265 283 263 297 283 270 264 260 302 301 293 298 300 333 310 281 307 288 283 289 316 291 291 291 282 319 289 294 283 285 319 296 299 314 292 278 317 273 294 287 290 308 297 320 284 304 283 296 295 321 281 308 289 292 295 286 319 268 274 271 287 274 295 292 310 287 276 258 282 313 291 249 324 312 273 311 272 282 263 286 281 288 294 277 290 311 284 299 286 292 287 313 289 249 285 344 336 275 311 265 276 289 288 270 300 297 245 304 283 305 311 290 318 306 289 259 272 288 264 279 263 297 270 286 311 287 268 227 244 288 285 289 279 297 300 271 280 316 277 280 303 284 270 288 277 313 306 306 300 276 286 283 276 295 284 272 274 315 266 285 290 274 307 302 273 297 263 276 296 272 296 281 300 271 298 280 285 281 256 286 280 282 262 279 302 288 270 289 262 274 317 286 303 285 250 303 302 279 266 299 291 306 294 304 287 277 270 278 261 246 273 283 291 288 296 293 255 273 277 285 312 274 292 256 272 233 321 263 291 276 272 291 278 293 267 283 288 302 261 280 229 292 270 256 301 265 307 244 268 316 285 264 217 271 269 305 257 308 298 282 281 294 242 265 277 298 271 286 283 291 239 233 293 296 266 289 279 292 264 314 264 293 258 281 271 265 283 303 268 243 236 286 297 246 279 250 269 298 263 308 295 282 287 297 276 278 263 284 285 267 268 284 278 304 294 259 277 273 283 286 295 283 290 304 292 288 272 280 286 303 256 325 275 269 279 258 282 270 283 280 263 275 287 277 283 278 269 291 262 284 307 235 270 241 267 267 294 284 271 277 287 257 293 261 276 292 295 275 272 273 286 274 270 263 257 259 281 296 279 276 290 287 286 257 272 245 262 272 306 279 263 282 283 278 275 283 288 278 265 279 260 294 262 257 271 308 285 279 264 266 256 263 247 312 265 273 275 290 271 288 274 249 243 299 262 296 275 250 289 297 245 273 283 276 278 284 269 244 246 290 282 256 261 292 281 280 304 257 240 272 283 285 248 291 275 272 269 245 286 245 282 286 268 278 265 299 272 278 274 277 241 277 271 243 294 240 311 292 268 300 277 313 241 287 285 291 258 265 265 300 239 266 249 261 301 291 282 248 257 263 287 264 286 293 278 266 267 284 282 255 285 239 275 288 262 290 257 266 248 258 300 264 268 285 257 283 277 241 261 249 272 270 277 271 291 280 276 292 273 281 292 255 261 264 282 263 261 241 270 272 249 278 276 277 271 292 278 255 278 269 277 226 259 270 266 288 246 265 296 292 277 243 245 309 256 282 289 257 280 291 274 290 281 270 275 287 259 268 229 289 267 263 242 280 295 269 294 265 240 256 277 267 302 272 277 244 264 314 267 290 291 259 291 282 257 289 272 244 268 269 244 299 272 300 281 301 281 283 261 263 267 283 292 291 245 287 294 261 249 260 287 272 260 240 286 264 264 268 282 286 239 243 280 265 223 274 270 271 258 258 274 262 276 263 270 268 285 300 269 257 270 284 264 262 266 286 277 225 266 278 280 275 268 272 271 259 248 280 231 278 287 297 241 236 261 295 260 263 256 271 249 276 243 264 278 266 238 286 303 280 287 273 281 270 272 223 263 261 276 268 261 263 258 248 256 275 280 247 256 269 290 240 266 281 269 255 269 277 302 259 264 241 278 275 262 300 267 277 258 244 291 268 236 273 276 293 273 247 272 241 259 249 259 259 270 240 265 247 292 260 256 262 257 276 270 303 289 263 287 249 290 260 294 279 233 263 243 283 284 270 273 256 270 247 247 279 223 255 260 228 274 271 235 290 264 243 238 276 235 237 264 250 288 269 237 255 299 272 286 262 234 274 249 249 293 282 280 285 242 237 263 308 276 247 243 263 258 296 256 240 284 232 286 249 283 273 247 271 247 235 281 259 236 245 242 212 243 266 297 265 240 255 263 275 248 281 267 239 280 278 265 278 247 256 279 270 242 250 240 256 275 255 245 260 289 264 263 293 265 256 283 265 273 264 249 308 270 289 268 279 249 261 290 248 245 287 263 241 255 276 274 277 247 299 275 263 225 264 278 263 244 244 259 240 257 242 242 265 261 257 224 262 256 235 256 277 264 296 256 310 260 231 246 272 249 247 267 238 241 267 244 273 271 285 262 287 294 270 283 274 283 249 257 281 270 282 256 248 286 230 270 276 263 263 276 264 259 267 236 296 240 273 264 267 246 243 301 243 287 270 249 249 234 258 257 267 277 285 246 249 236 259 277 246 275 256 270 264 247 241 278 282 247 262 263 268 291 249 265 282 238 279 292 265 264 277 295 275 245 267 236 276 288 267 285 294 281 230 262 284 248 284 269 241 223 271 288 259 288 290 266 256 284 289 263 243 285 260 279 281 239 269 294 247 293 267 242 285 259 232 266 262 260 264 261 248 220 273 259 235 260 271 262 248 273 264 266 245 237 235 229 241 271 257 259 212 255 257 260 286 235 278 264 264 270 297 248 274 272 292 237 245 280 280 229 259 265 259 295 280 234 230 262 244 268 275 264 288 260 262 269 279 287 271 266 292 263 263 267 213 316 260 245 288 264 271 274 288 244 282 279 284 272 293 299 262 239 260 263 258 271 286 270 270 294 257 260 285 265 248 243 266 274 266 264 277 256 279 287 267 275 284 267 276 245 273 243 271 279 243 283 276 242 235 245 262 301 277 255 246 289 275 281 286 246 273 263 274 242 246 272 275 260 272 278 263 262 295 308 248 275 290 258 286 275 280 268 288 308 295 269 275 291 282 280 236 283 283 282 279 278 296 280 288 278 284 275 273 232 264 294 257 228 279 263 288 287 259 271 298 240 267 275 285 291 290 258 258 302 271 273 236 283 269 284 249 273 310 255 262 283 283 282 301 275 286 285 280 285 295 273 245 278 260 285 271 247 282 269 231 258 280 304 289 278 245 262 276 260 234 294 257 297 270 266 271 278 247 267 273 250 299 303 277 291 243 266 257 263 287 271 286 265 243 304 285 273 281 271 246 261 278 287 285 238 283 255 315 316 268 271 261 318 296 282 284 272 301 297 301 302 284 296 304 328 282 329 309 282 289 324 278 325 301 293 350 293 313 298 297 285 273 291 313 310 298 308 280 290 284 316 285 285 304 311 267 319 293 314 277 275 296 303 304 281 263 305 296 249 267 263 284 282 306 272 287 265 295 273 264 267 241 282 284 319 294 315 282 288 310 314 327 272 286 311 304 323 301 324 284 291 311 295 322 314 280 317 278 282 271 296 286 329 304 305 273 328 275 309 323 300 304 302 336 289 300 320 314 338 290 363 345 328 318 316 320 350 342 348 378 345 334 366 360 343 368 371 391 383 406 378 387 386 405 465 432 439 439 447 466 470 486 475 472 522 497 501 536 511 501 549 509 517 518 512 510 520 501 500 494 496 478 482 456 472 387 424 417 436 390 396 395 387 349 367 363 362 393 369 374 360 350 339 360 331 333 350 303 308 355 335 350 301 289 317 328 338 318 286 300 308 294 355 283 312 298 301 331 294 321 281 309 262 303 280 302 275 281 310 302 274 293 320 277 294 268 295 326 280 283 303 283 312 284 328 308 287 288 275 292 281 306 295 290 290 288 271 259 299 288 293 296 297 288 281 290 282 269 321 278 288 292 291 289 288 303 314 319 269 272 277 283 302 271 269 265 320 298 272 293 296 278 270 278 268 271 312 303 272 285 307 297 296 282 300 294 300 302 290 282 239 276 319 249 293 246 293 265 281 257 284 297 287 271 243 279 262 278 247 267 321 301 285 289 307 304 313 281 297 290 270 239 284 268 284 324 319 278 290 298 273 281 286 278 276 266 249 292 269 297 275 275 276 290 307 276 260 299 305 274 264 298 235 271 299 283 274 277 266 303 288 295 274 298 274 292 308 239 272 269 243 292 285 260 264 271 310 272 259 285 315 306 299 277 289 284 280 303 284 324 291 265 292 238 295 289 271 271 273 270 283 243 258 245 239 281 238 274 320 275 242 277 267 330 260 279 257 272 264 259 308 291 265 278 273 292 286 279 273 284 276 245 297 299 271 281 231 269 295 265 274 280 266 284 285 284 258 288 277 293 276 289 284 244 278 274 297 267 270 278 294 288 257 316 271 265 298 284 271 296 260 270 275 316 237 281 272 283 270 279 280 297 257 291 265 256 262 291 277 262 258 271 308 255 309 247 279 268 321 271 286 311 288 268 274 274 263 266 258 273 272 258 272 284 266 279 305 300 266 285 270 282 296 272 302 267 288 283 285 278 264 309 286 269 293 270 300 292 230 256 264 279 290 270 288 275 279 296 271 315 266 290 277 307 277 285 255 276 281 259 268 306 245 282 280 282 269 285 294 273 283 276 298 286 294 299 296 271 277 292 273 308 277 280 279 270 247 277 284 249 305 272 292 288 287 248 243 262 267 281 295 278 291 287 294 282 255 290 322 268 271 287 303 305 277 262 261 288 274 293 272 262 297 262 295 274 287 307 289 307 276 258 282 271 276 261 278 278 273 294 275 306 242 294 281 279 259 300 271 288 262 267 325 280 283 285 257 295 272 270 265 267 271 277 272 272 270 286 275 266 290 270 285 267 261 262 268 286 272 261 266 294 259 267 292 259 279 256 238 276 274 276 259 266 239 247 290 261 279 270 255 262 263 277 237 294 292 285 299 244 273 285 296 313 308 264 269 293 278 280 278 288 275 284 237 284 263 285 255 268 267 287 287 265 292 282 283 290 269 255 293 294 273 297 274 273 275 271 291 263 286 258 268 291 298 280 262 275 265 300 264 296 274 279 257 292 265 308 293 258 278 269 294 274 238 289 289 285 306 305 293 265 282 257 282 288 271 284 274 237 270 293 276 259 280 256 264 302 261 297 302 286 270 276 279 272 264 295 250 268 282 263 249 260 269 255 282 274 277 280 286 289 281 244 290 288 299 290 259 277 293 290 262 293 264 281 310 280 274 285 275 244 266 306 248 263 279 271 271 327 234 249 258 262 301 264 276 292 291 284 278 281 259 266 285 267 269 276 265 241 282 292 262 281 242 257 272 250 269 304 281 306 239 278 288 320 264 290 269 296 317 239 261 302 298 297 277 267 292 275 286 293 287 275 289 329 280 259 297 290 241 289 272 316 263 271 278 311 244 288 302 319 296 280 268 285 266 262 290 273 312 272 307 273 281 263 261 258 261 266 264 283 296 269 268 266 286 259 288 259 277 257 275 294 283 266 296 272 304 297 317 331 257 288 264 295 329 278 274 238 301 272 283 286 255 326 280 282 280 296 288 246 294 284 263 291 301 273 304 274 274 267 312 266 284 263 271 299 300 243 242 272 268 284 282 295 283 290 294 269 300 291 301 280 293 257 248 281 315 280 266 289 292 277 277 284 257 299 259 270 245 282 288 274 257 244 270 258 285 281 276 259 275 265 306 288 267 259 285 281 292 303 257 266 269 280 283 247 294 262 280 283 277 279 270 301 285 239 275 294 262 264 243 277 303 257 267 244 248 284 293 270 285 265 285 249 311 270 276 275 295 279 246 277 306 273 283 269 297 282 284 255 291 285 265 273 255 269 275 244 283 264 305 278 275 234 275 268 277 293 300 270 247 290 317 259 230 284 247 290 260 297 277 293 260 271 268 279 293 268 276 290 256 285 311 311 275 249 257 281 303 283 289 287 291 303 304 272 270 312 286 290 302 248 285 274 305 282 280 307 280 284 261 283 298 258 246 281 283 259 282 274 284 291 291 283 293 321 285 299 295 279 274 274 280 278 247 276 302 286 287 281 287 274 262 267 291 260 276 287 326 298 309 311 250 272 295 267 291 286 267 277 294 269 297 249 289 281 261 293 302 287 283 260 280 269 307 274 294 273 273 317 294 277 269 282 274 266 298 248 279 272 280 270 309 315 255 278 279 274 258 316 301 307 287 244 298 280 303 284 295 269 278 274 301 271 289 275 307 277 284 295 287 282 274 270 304 256 298 272 273 291 303 298 290 284 308 264 283 268 291 286 246 318 282 332 282 258 262 316 326 284 282 268 264 289 282 277 294 289 275 275 278 307 276 306 296 280 260 307 296 278 276 259 263 305 301 304 283 275 277 270 292 279 293 296 310 262 260 285 303 319 295 278 273 277 288 285 311 291 281 319 274 288 262 308 292 278 284 290 270 296 299 275 301 284 270 283 249 264 256 272 257 324 256 265 236 281 297 276 272 280 275 289 290 287 283 290 276 293 267 305 275 281 275 278 275 291 295 274 271 292 286 336 236 312 304 260 275 297 291 285 267 276 283 272 286 258 283 256 298 290 267 288 298 272 260 280 261 276 259 276 271 263 299 269 293 274 258 282 276 298 283 263 256 311 240 280 291 301 273 278 290 278 264 297 278 262 263 316 306 261 295 268 288 276 272 255 299 278 297 277 305 245 266 300 281 246 297 267 266 303 272 247 288 280 264 319 309 258 282 277 247 285 289 293 289 309 301 294 261 270 272 277 324 282 274 296 269 279 277 303 278 283 296 314 307 294 295 279 289 277 271 303 273 257 264 256 281 299 279 280 290 297 293 284 265 298 316 288 280 281 271 281 309 295 298 283 286 305 293 290 321 295 262 281 291 299 292 263 302 247 304 297 297 269 284 271 315 272 280 265 284 275 283 282 275 271 293 294 296 288 255 291 272 273 259 286 244 298 249 258 311 284 281 285 291 276 283 305 295 295 330 284 286 301 287 271 283 283 279 292 246 293 272 290 287 266 295 274 280 306 281 274 276 291 290 299 274 293 295 264 295 282 304 263 287 273 288 279 324 301 313 295 324 278 308 283 274 293 273 277 282 255 296 305 301 274 277 314 290 269 296 273 277 271 269 273 317 274 288 316 244 258 305 311 307 286 285 297 295 274 281 267 268 313 277 303 284 268 265 284 291 298 268 267 293 297 278 272 283 282 301 295 274 304 270 298 275 268 289 299 320 297 276 288 255 305 324 284 282 281 245 268 273 266 280 285 287 263 283 274 291 263 269 299 274 296 248 248 274 319 249 273 278 298 293 280 280 275 288 311 280 297 275 243 279 313 290 307 258 265 295 267 307 231 279 262 280 255 282 319 307 292 276 270 278 283 278 292 268 306 256 282 296 298 270 313 264 288 244 279 269 282 275 293 277 282 291 248 260 285 302 279 282 300 294 298 287 275 299 291 282 283 286 289 274 271 265 277 291 289 267 266 312 266 246 286 260 282 293 296 281 283 274 260 302 286 292 248 297 293 302 262 286 286 266 275 266 276 295 239 278 288 313 287 266 298 258 300 270 301 308 268 288 286 301 298 265 301 288 278 275 291 306 291 304 284 298 295 284 272 260 269 264 297 301 287 269 290 293 314 283 290 283 255 285 265 246 288 290 291 277 289 307 269 316 284 278 302 266 288 292 276 240 284 259 262 276 308 280 288 293 270 301 289 265 295 274 305 274 312 287 267 286 269 244 284 282 337 278 288 267 291 273 292 273 292 289 270 296 283 277 292 249 275 284 304 299 289 284 287 262 276 267 282 296 288 278 316 257 284 265 296 299 306 240 312 273 282 274 297 290 283 276 310 306 281 260 281 272 288 283 283 297 283 305 305 296 281 276 264 301 263 286 306 269 259 284 276 263 264 260 296 267 277 300 274 280 309 285 265 295 270 303 308 288 277 271 292 240 302 249 294 290 315 301 305 298 267 289 311 263 296 274 303 287 275 278 299 278 284 276 259 301 271 291 274 280 300 270 259 272 276 277 290 306 300 263 283 291 281 290 278 274 296 268 295 290 280 302 283 292 285 297 269 281 300 295 297 237 262 298 255 309 275 287 291 281 279 286 255 285 295 256 284 268 296 287 285 291 277 288 284 300 269 269 309 292 273 303 255 289 308 295 291 288 267 307 275 295 307 318 262 316 309 307 296 287 279 260 243 278 287 302 275 315 283 278 301 284 293 294 278 290 299 315 317 284 273 288 310 279 321 307 305 308 269 301 273 286 304 288 336 308 305 310 316 290 312 312 320 292 299 330 290 333 294 289 321 277 299 318 282 320 327 310 309 316 297 297 307 316 350 335 305 306 299 321 295 290 313 294 296 303 280 299 285 315 287 300 283 274 314 271 319 271 289 293 303 284 291 289 285 273 315 286 307 309 265 260 293 260 304 305 309 263 290 270 268 282 297 274 282 289 277 303 278 286 300 282 308 281 310 291 311 255 285 308 278 280 292 289 290 282 256 270 307 272 294 291 286 286 257 285 282 300 280 293 264 291 297 287 297 292 272 300 263 258 290 279 293 288 271 290 296 300 285 292 300 305 275 262 258 297 238 279 291 306 310 300 274 260 282 308 305 272 284 294 273 277 293 291 308 310 249 291 295 276 336 301 299 277 249 269 277 288 236 274 269 272 278 268 231 320 266 261 282 291 272 282 289 277 270 299 311 312 278 298 281 274 291 283 301 287 289 294 300 282 291 260 290 289 275 270 291 288 267 286 267 297 261 273 309 260 297 296 288 273 283 308 258 297 301 267 274 294 285 308 276 283 288 271 277 310 300 298 269 303 269 312 295 255 268 291 284 272 289 293 268 268 273 280 279 275 324 267 257 273 305 259 285 294 294 279 279 287 270 293 270 272 274 268 277 305 277 279 299 259 279 232 297 284 290 282 282 273 294 264 278 249 291 306 264 283 247 282 258 257 319 284 259 256 264 269 268 263 271 279 265 308 270 261 276 301 265 287 264 299 287 288 285 287 305 263 247 282 272 284 278 287 283 276 278 288 249 263 308 298 277 301 302 271 331 265 243 268 285 279 304 262 301 317 294 303 263 278 301 270 293 299 293 334 292 271 283 285 280 301 296 295 270 282 274 277 265 297 273 297 288 296 280 302 275 301 290 279 264 272 281 272 269 291 283 287 278 280 278 282 276 289 297 265 290 279 247 267 280 283 274 286 297 259 287 265 260 286 316 276 289 277 302 278 283 294 287 272 230 287 271 272 279 294 302 262 267 240 289 270 248 281 266 308 294 273 300 285 267 272 290 265 279 268 291 292 297 309 298 280 322 264 279 285 280 314 291 296 268 273 307 278 272 287 300 315 250 245 271 288 307 294 297 307 297 309 287 250 287 280 269 296 247 272 261 263 276 294 292 257 278 297 268 285 248 281 291 276 257 288 305 289 285 300 273 277 274 295 258 282 282 276 284 292 272 228 268 291 238 238 280 265 277 284 296 293 258 272 283 269 256 278 275 267 297 298 242 279 247 284 267 277 297 309 314 310 241 278 280 313 270 280 317 306 260 222 293 282 287 292 296 308 284 298 315 281 270 321 291 314 305 293 289 293 282 269 282 303 310 292 292 311 283 245 231 249 279 292 296 278 286 292 311 286 279 262 276 277 241 286 271 294 301 282 279 281 295 263 279 286 287 294 267 330 289 256 263 301 302 265 279 245 272 289 245 296 288 292 282 296 294 267 309 270 281 292 302 337 288 259 269 283 233 272 262 299 303 305 289 285 302 278 275 262 301 263 292 290 270 309 294 280 283 261 281 304 277 300 296 284 285 287 277 259 293 273 281 247 269 288 281 319 271 244 250 270 283 264 296 276 293 285 287 281 277 295 273 274 295 292 324 302 294 305 277 273 283 290 295 298 262 280 280 305 293 259 285 294 299 282 310 263 246 284 273 273 286 290 286 283 286 314 307 300 263 287 278 271 270 306 302 269 288 288 296 279 283 283 274 275 249 294 286 295 278 305 292 274 281 265 256 320 292 289 272 244 292 290 272 274 293 265 275 294 258 307 269 250 257 265 300 279 289 262 279 271 265 291 255 290 243 286 277 269 308 291 298 265 291 285 284 285 278 268 301 295 288 314 304 273 287 278 295 235 280 278 294 313 290 266 234 298 285 278 276 272 242 298 279 296 292 315 279 269 296 282 285 272 295 298 300 260 293 291 270 303 274 306 308 267 268 278 263 279 283 326 289 279 274 272 272 301 273 293 280 284 263 263 255 266 294 266 267 276 291 280 277 289 298 278 318 304 285 277 294 266 288 292 299 298 266 297 276 299 306 243 257 300 293 284 287 271 263 274 274 285 306 292 290 276 286 306 299 265 256 255 275 307 265 275 286 276 281 266 265 284 301 293 297 290 272 311 317 286 279 247 313 276 309 279 309 303 282 276 322 262 275 294 278 295 277 287 261 288 283 293 276 258 294 297 267 280 276 285 289 294 284 284 301 271 274 261 280 300 283 241 296 294 278 278 262 268 270 268 321 297 294 242 275 269 243 286 260 248 284 310 301 278 285 291 302 267 314 273 309 286 310 266 295 274 277 286 286 282 293 268 298 278 263 289 283 310 272 304 285 282 268 326 284 287 273 244 258 342 243 275 292 279 293 247 306 288 281 284 318 243 324 269 283 288 285 264 292 293 299 279 274 290 288 319 296 276 282 250 284 268 273 303 277 264 276 262 284 305 284 276 309 290 281 286 289 273 267 266 319 273 301 277 289 255 267 276 259 263 318 250 278 245 274 278 273 250 291 267 282 280 284 297 289 275 265 278 263 293 284 288 264 261 286 292 306 280 277 282 262 302 282 278 288 299 276 302 285 256 234 305 261 261 262 256 287 303 284 267 294 286 286 259 283 277 267 276 274 294 278 277 267 273 298 302 280 267 271 280 292 271 294 289 276 297 290 265 277 276 287 281 274 278 301 279 285 272 233 286 260 271 307 276 298 301 325 257 312 285 272 274 285 293 270 283 315 304 278 271 277 244 294 293 293 277 265 282 298 264 283 275 310 259 269 323 276 285 248 265 262 270 301 271 294 301 298 275 298 276 271 268 268 300 261 262 300 281 283 286 316 277 288 282 270 292 291 284 267 285 300 294 249 271 271 292 269 255 285 258 267 298 285 243 281 256 263 272 294 290 284 297 278 241 278 268 307 302 282 289 304 298 282 255 255 243 257 244 325 258 258 300 288 278 316 297 285 314 290 278 295 295 281 260 247 256 284 271 291 255 242 272 291 283 280 264 287 280 272 270 264 282 267 287 285 298 270 265 263 249 301 288 281 276 263 300 265 283 290 289 240 243 276 256 247 256 279 273 271 293 258 257 299 271 317 260 270 305 297 286 267 255 278 265 273 281 284 259 264 291 286 285 255 311 241 238 285 300 263 268 301 249 272 293 273 267 279 278 267 258 295 288 279 285 307 301 299 264 288 274 274 301 271 263 283 259 273 269 305 286 240 270 284 255 318 295 275 269 283 256 275 285 280 271 273 311 290 261 293 279 296 280 292 281 288 309 286 292 279 267 298 306 287 259 280 290 296 271 262 278 266 292 307 293 308 282 273 300 287 288 309 284 315 314 264 269 271 303 279 260 280 306 299 266 299 274 297 271 293 274 290 274 270 289 276 261 278 299 270 243 272 257 269 267 309 297 281 282 266 290 287 247 244 274 239 287 283 306 279 264 273 288 282 272 262 279 297 285 280 292 302 292 267 281 277 270 273 263 283 271 324 249 284 272 261 292 307 289 293 307 287 268 300 261 300 297 282 298 307 287 276 302 292 308 324 276 255 307 292 270 298 282 285 279 296 285 289 266 256 268 277 270 290 266 284 306 273 243 261 323 268 255 277 287 316 271 274 282 276 277 304 288 247 305 283 282 297 297 294 243 264 280 264 292 290 284 292 294 280 289 264 269 298 303 290 320 267 299 284 265 283 282 268 275 265 239 239 288 243 299 284 274 300 274 292 282 278 276 294 277 288 295 296 281 274 280 280 308 295 271 299 303 274 283 301 269 263 273 289 303 312 277 255 297 273 323 292 273 282 261 312 260 278 286 303 260 306 276 288 301 274 299 292 284 292 283 290 278 300 273 280 277 295 308 281 282 284 296 309 282 294 296 295 297 279 277 276 273 318 302 293 280 307 290 310 302 278 293 291 274 289 290 279 311 318 265 293 293 318 302 315 301 294 318 278 316 304 306 296 295 278 319 305 300 312 317 317 341 315 295 310 318 314 342 315 315 323 319 309 308 326 300 311 310 290 350 368 316 311 313 322 320 331 303 343 316 328 345 318 339 359 349 325 320 317 305 310 311 313 321 327 330 314 306 310 305 312 283 327 291 273 296 348 275 302 300 285 276 298 276 309 279 299 315 297 303 305 319 281 275 279 286 275 297 293 295 287 297 248 280 279 231 306 286 293 289 275 256 271 294 294 299 271 291 265 324 275 260 289 275 270 301 279 297 275 280 294 268 266 309 285 272 296 276 280 283 301 284 288 296 282 322 280 235 259 269 293 300 274 278 246 284 282 304 331 277 307 262 286 250 268 277 270 291 301 280 301 277 295 261 245 264 282 256 293 271 286 305 246 266 270 266 296 282 273 282 240 299 273 282 246 276 311 294 280 269 270 235 283 289 260 265 274 286 278 278 273 290 258 261 274 271 268 280 268 294 284 309 279 277 301 265 259 255 279 263 243 273 277 272 304 260 315 271 273 270 286 248 315 277 291 261 307 273 263 229 303 281 281 282 261 285 287 278 262 297 277 300 278 290 319 265 235 275 278 283 267 268 295 282 248 285 292 285 278 300 281 273 279 265 304 266 288 271 282 296 287 315 250 289 309 274 299 264 270 267 275 263 264 292 269 274 282 304 322 268 270 270 288 278 267 292 266 285 279 292 296 262 289 273 280 241 294 303 289 318 287 288 286 299 275 270 262 290 282 286 248 270 236 282 270 289 273 236 274 293 293 259 299 269 271 263 277 271 283 256 290 287 309 280 289 275 246 287 257 265 285 256 273 263 261 280 283 267 291 279 291 261 270 327 269 289 283 284 267 297 310 272 287 294 292 289 269 283 259 280 258 280 281 274 296 284 291 297 263 288 287 275 287 280 285 284 306 270 293 264 302 265 299 262 296 289 270 308 293 264 284 271 335 324 312 255 286 257 277 287 269 246 245 264 247 290 297 274 284 282 292 280 274 307 298 276 279 295 267 280 280 279 282 260 273 281 260 264 295 278 289 285 248 271 261 305 263 265 261 314 297 282 300 301 278 278 257 327 308 289 296 265 298 285 277 263 275 293 290 255 278 307 269 285 271 286 275 272 267 262 282 261 284 259 272 235 257 280 290 241 267 286 301 259 282 304 277 280 274 240 298 275 297 320 262 263 256 239 263 287 308 249 306 283 259 263 296 272 287 260 266 307 271 293 269 258 293 284 287 248 285 280 275 269 271 291 262 281 290 277 267 272 273 288 273 298 297 274 265 275 306 296 275 298 291 304 283 306 263 313 261 272 264 284 257 327 290 270 275 264 296 280 282 276 270 285 295 287 312 263 272 264 269 282 230 287 279 298 240 274 287 284 262 280 255 256 280 273 256 285 268 301 269 257 292 284 275 291 259 283 279 268 296 313 281 261 313 293 265 293 315 270 272 283 313 267 293 273 293 289 243 292 248 272 279 262 313 269 313 286 300 273 273 325 271 228 264 275 278 275 279 246 308 256 269 296 267 261 276 291 255 303 289 272 262 263 288 312 263 249 282 302 275 274 256 282 287 293 282 285 249 273 281 250 280 256 263 275 308 287 261 249 281 244 272 291 270 256 271 290 266 298 291 283 288 301 290 287 292 281 296 292 261 294 298 282 306 286 286 269 267 306 302 264 247 274 293 287 311 239 262 300 277 275 296 282 281 296 258 314 244 274 263 269 291 258 259 293 269 291 297 269 288 298 292 237 295 270 272 274 285 292 282 295 297 261 292 280 276 271 268 279 281 279 287 311 277 275 267 300 307 315 264 310 287 270 281 263 277 260 288 266 273 279 292 267 259 285 300 290 274 292 285 271 294 297 321 269 282 260 284 273 291 288 279 255 268 285 270 294 259 296 266 270 318 274 284 299 247 298 262 262 282 268 298 270 286 278 297 293 280 271 267 297 226 298 297 281 283 279 265 290 292 247 263 283 265 278 242 280 273 270 274 280 271 285 260 246 276 293 279 288 298 248 288 265 290 275 272 274 283 302 303 259 308 295 290 294 265 274 280 284 308 262 284 277 285 269 276 269 302 306 288 297 279 279 277 269 247 285 262 307 227 279 282 294 275 307 295 268 268 289 249 271 296 281 291 255 262 296 244 272 265 288 322 233 273 270 287 289 290 266 270 311 267 316 267 263 329 269 296 273 247 298 264 287 286 287 298 272 245 272 274 263 271 290 296 281 288 286 279 278 283 300 292 287 308 266 287 271 277 274 308 301 266 272 286 259 289 321 298 267 281 314 287 294 278 232 261 271 298 264 276 284 255 270 269 299 281 285 250 308 264 295 291 245 312 282 258 293 271 303 290 305 293 279 297 297 290 257 266 278 283 283 282 263 282 249 245 245 276 270 289 268 237 283 265 285 282 303 280 295 279 277 274 280 267 260 244 288 293 266 284 294 270 265 283 273 281 290 328 277 269 259 265 311 258 247 269 232 268 268 274 276 288 275 315 295 277 259 249 273 306 278 280 275 273 265 264 271 276 255 256 266 264 247 268 268 268 261 262 284 285 298 243 289 292 266 245 313 284 244 289 258 261 294 282 268 265 256 271 285 294 243 281 283 316 283 262 270 288 260 243 292 271 287 257 292 261 277 278 293 283 259 259 268 276 249 299 234 278 238 295 281 269 267 277 264 262 271 284 299 281 283 290 288 281 302 264 258 255 278 263 275 271 268 248 272 282 284 287 275 275 279 272 242 292 277 274 266 284 284 264 267 223 273 259 284 283 301 263 270 278 245 267 240 271 266 272 335 268 294 270 273 284 272 268 240 259 281 268 273 283 276 244 265 268 289 280 262 284 259 284 248 274 261 303 278 297 258 291 290 270 268 295 247 299 264 281 260 249 288 272 268 246 287 244 280 256 249 292 266 269 255 299 296 245 264 280 272 258 297 290 239 274 278 287 269 255 277 307 261 263 288 262 289 287 268 247 298 268 279 278 279 295 273 280 305 276 285 243 244 284 312 279 299 268 277 273 296 294 288 299 293 266 259 292 275 278 266 284 300 285 283 270 299 271 259 261 271 272 298 269 287 239 258 260 281 272 299 283 237 274 248 275 257 248 277 287 271 243 293 331 287 265 267 275 283 262 267 257 243 259 261 280 274 299 274 270 287 287 258 269 293 241 282 276 260 274 295 271 285 287 281 274 304 291 264 279 265 288 272 320 296 279 266 286 283 256 244 270 264 305 256 293 258 297 283 248 296 230 255 272 275 271 278 262 279 249 294 273 270 232 301 264 274 293 277 306 259 285 286 261 280 303 279 282 288 274 300 261 257 261 266 279 287 292 277 298 295 265 244 289 256 262 285 281 210 288 279 266 250 257 265 248 277 258 248 276 284 285 263 259 260 307 271 259 289 257 283 320 282 261 277 279 277 291 300 232 261 285 288 271 273 261 287 263 298 267 275 285 297 297 289 312 287 302 258 281 285 296 338 277 260 245 288 293 280 324 261 277 246 261 279 288 242 237 277 270 291 270 305 222 250 315 269 298 287 264 289 280 295 293 299 290 277 281 242 301 310 261 292 274 270 280 312 246 275 234 255 260 268 248 273 286 266 257 293 295 292 245 268 264 287 304 276 294 300 284 265 295 270 260 240 300 245 286 305 311 255 249 269 255 279 287 261 258 276 256 277 249 273 272 288 304 259 316 262 280 247 262 260 286 243 291 278 278 271 264 293 296 289 292 309 265 283 259 307 272 279 264 272 281 263 270 265 249 294 293 282 259 269 292 290 269 277 283 279 297 268 283 297 285 268 279 271 282 271 281 280 290 273 261 280 275 332 278 313 287 279 279 284 293 263 285 281 301 290 290 259 276 307 308 263 278 283 265 264 273 294 266 276 270 266 311 299 306 255 288 278 282 256 283 307 316 283 308 280 269 262 295 309 247 293 278 285 271 288 292 288 299 280 276 280 296 288 283 281 283 280 286 271 285 293 268 292 266 235 276 297 278 277 274 284 290 284 262 269 284 309 236 306 303 294 269 285 260 277 262 257 271 258 260 296 247 271 259 269 283 267 257 277 285 287 286 285 299 270 282 268 271 284 271 272 288 256 283 283 293 248 265 283 265 269 271 280 255 301 266 256 263 264 277 302 267 260 276 268 245 278 257 275 264 268 266 282 257 272 262 278 283 269 278 247 272 243 269 255 241 256 289 270 270 266 261 278 282 270 295 248 262 273 266 297 283 262 247 265 268 273 267 303 282 278 272 247 271 277 257 268 278 243 282 303 287 270 287 280 276 257 278 258 266 257 303 237 244 265 223 258 244 302 268 296 273 242 236 238 263 275 262 277 279 282 280 280 283 275 268 271 261 279 291 285 271 257 270 272 291 248 287 282 277 267 246 280 240 265 249 292 277 295 279 276 266 285 281 281 287 291 289 246 278 280 276 298 272 258 263 272 295 278 256 246 261 291 300 276 238 268 272 287 240 272 265 301 267 293 288 242 277 294 257 256 275 281 232 283 276 242 274 285 239 268 261 282 262 267 261 281 271 249 275 265 316 296 246 244 277 267 266 267 285 240 261 277 238 270 284 269 271 259 285 278 276 249 265 280 275 274 245 267 258 288 287 278 276 263 298 241 275 282 283 280 281 290 282 275 248 267 265 277 285 283 244 247 240 261 264 302 301 285 284 250 289 278 259 295 292 287 270 259 288 284 261 258 261 284 291 283 256 305 270 277 278 264 273 263 281 266 289 294 300 321 257 258 248 267 247 248 248 281 277 294 284 291 262 239 291 240 250 275 280 267 277 264 286 273 260 285 266 279 270 293 279 300 236 268 302 242 248 277 279 285 258 266 260 249 263 268 238 281 257 271 278 275 275 287 245 261 249 265 295 269 235 274 241 247 296 264 265 290 292 239 280 256 260 276 284 271 261 272 283 272 266 262 290 290 258 277 290 276 275 281 262 303 266 276 276 257 298 279 270 281 283 240 245 281 296 287 296 284 292 268 274 285 277 282 266 274 277 262 297 304 270 294 292 297 249 280 249 314 277 286 266 276 273 265 273 278 295 267 248 268 291 295 290 278 262 256 303 283 276 273 271 275 293 239 266 292 264 272 281 310 290 243 295 268 279 242 259 286 238 292 279 273 273 279 262 297 294 297 259 327 277 285 278 275 256 279 276 259 282 232 278 277 285 275 280 258 281 259 291 296 285 276 293 269 287 245 299 247 281 265 273 244 289 269 287 280 289 292 280 278 300 273 256 263 281 265 299 246 266 276 289 306 260 271 286 295 266 294 267 277 304 286 300 265 267 285 284 271 271 275 288 273 288 283 294 265 264 282 257 260 277 269 315 274 312 259 285 241 273 277 265 250 281 311 282 287 293 277 286 227 294 310 301 291 269 265 281 273 275 299 278 261 317 282 288 269 289 270 301 255 285 267 277 279 302 286 279 278 285 301 275 289 272 263 298 292 282 287 249 289 297 297 264 241 297 307 285 274 263 286 257 285 288 280 258 288 274 273 295 296 289 274 273 245 309 297 293 293 289 330 275 289 299 302 258 289 270 298 245 300 315 283 285 272 263 278 284 268 268 241 276 292 266 281 303 268 267 239 291 289 282 301 264 288 301 321 270 271 293 278 303 287 259 293 282 294 300 297 292 270 296 273 249 291 257 290 279 279 299 284 289 276 258 286 274 298 298 278 271 271 327 272 301 317 305 275 317 270 283 292 260 286 273 263 297 293 279 297 261 289 264 306 294 238 291 271 293 273 249 302 263 281 288 267 303 259 267 267 283 279 295 297 276 280 281 274 284 275 267 299 284 304 297 273 267 273 284 275 295 292 267 261 277 282 258 288 255 282 278 270 294 299 282 288 286 281 260 282 288 301 278 280 291 263 313 290 277 288 246 292 310 257 304 263 264 268 305 284 267 272 308 269 291 290 304 281 290 276 279 332 287 278 281 274 282 259 260 285 260 288 275 284 264 246 273 266 257 280 267 259 302 290 270 289 288 295 285 275 286 306 260 246 282 291 284 271 275 302 259 297 246 269 275 299 270 280 273 269 255 274 242 272 279 261 265 277 278 294 243 292 294 285 292 265 266 280 299 294 256 300 304 282 280 280 257 272 265 331 291 279 262 286 262 291 273 291 268 326 292 271 271 301 280 299 285 292 263 273 290 264 264 270 289 273 264 237 268 281 287 283 291 297 281 279 265 274 288 287 305 278 287 274 274 299 257 314 284 260 249 285 261 289 284 286 310 263 278 262 290 285 274 276 249 274 271 300 268 269 291 267 275 295 295 279 277 259 312 276 261 281 317 281 298 284 297 232 255 273 274 324 267 259 269 281 305 279 260 301 257 304 282 288 264 261 279 264 322 286 311 289 276 267 295 295 297 311 302 289 290 298 290 272 287 271 306 288 273 293 289 282 279 265 297 238 259 260 290 278 285 296 246 278 276 310 246 277 278 275 256 295 266 301 281 296 288 281 280 271 295 288 300 282 282 284 295 312 318 276 273 274 283 282 288 273 271 287 314 279 277 270 266 250 297 296 302 299 326 272 307 277 300 272 288 260 262 238 282 280 270 261 297 260 272 288 282 240 300 311 274 262 282 278 282 268 242 295 292 312 261 278 262 287 288 272 287 281 289 293 298 299 263 295 273 301 261 292 261 293 278 284 290 299 280 292 308 274 278 275 300 296 265 261 291 302 310 291 334 250 267 303 277 282 291 266 303 293 269 266 307 261 304 276 311 284 302 275 278 294 270 297 265 295 283 266 285 259 268 305 247 279 262 281 296 298 286 266 292 278 264 288 290 293 300 281 273 270 267 282 275 282 298 272 296 283 282 314 286 308 270 304 259 303 272 280 288 311 282 290 327 286 288 280 269 271 277 284 293 296 267 264 261 294 300 280 277 275 270 289 273 312 261 298 286 265 301 245 259 274 302 303 261 299 290 296 239 302 301 275 295 278 266 292 279 294 263 315 296 273 302 310 267 296 317 277 274 284 294 259 259 289 305 297 281 298 281 278 298 266 268 263 307 279 306 268 275 282 294 311 292 294 279 290 250 256 300 248 281 273 316 303 248 257 277 282 283 296 276 274 302 281 259 287 276 279 286 308 266 289 280 288 314 299 283 313 273 287 303 294 258 291 272 313 285 292 287 297 239 255 293 278 276 290 277 281 271 276 249 247 285 268 308 235 295 305 283 298 299 279 286 270 256 300 268 270 288 266 295 294 299 304 291 273 300 269 294 247 291 287 249 267 313 268 310 296 264 328 258 284 301 271 280 274 319 289 282 276 285 287 274 311 296 288 242 263 293 297 317 269 266 295 297 292 276 324 266 275 294 279 311 235 284 283 250 261 270 276 266 274 287 287 268 298 286 285 294 302 281 298 244 295 274 311 313 279 308 302 260 279 279 273 293 273 298 274 274 295 303 288 291 303 289 306 267 279 301 308 293 304 277 310 272 259 256 262 294 272 269 267 281 288 314 272 297 297 297 317 277 277 282 283 291 280 274 284 303 280 272 309 287 274 320 257 294 317 301 302 273 231 301 255 255 256 272 262 305 246 274 271 289 257 284 294 285 279 283 295 264 294 309 303 299 256 296 288 272 271 298 266 282 325 284 285 282 294 303 300 278 303 270 303 296 271 284 285 295 276 308 324 281 275 278 267 306 281 276 289 285 293 324 291 304 280 332 288 256 296 267 300 280 287 289 292 282 310 288 277 298 303 302 278 301 288 292 287 286 267 239 280 288 290 262 313 306 302 292 296 321 273 263 280 247 315 291 283 329 290 304 290 291 293 299 259 295 292 289 278 305 312 304 283 279 318 284 283 319 281 305 291 276 334 278 258 329 299 302 307 311 290 305 291 332 275 303 303 286 271 282 303 318 302 296 294 300 279 285 291 338 283 300 328 283 318 288 300 291 313 319 318 299 280 272 296 288 288 292 283 319 308 287 291 292 293 310 274 283 322 325 295 291 309 273 308 304 296 278 276 297 299 265 270 305 280 288 257 294 288 273 261 278 298 331 298 303 307 291 271 306 303 270 288 307 304 271 281 309 292 290 243 291 295 293 258 247 283 276 300 279 286 269 248 275 277 268 298 294 270 287 304 296 314 281 337 295 278 275 277 256 287 304 266 281 273 295 276 300 320 301 268 297 274 280 268 271 262 318 281 299 282 276 284 264 273 301 295 281 271 285 235 268 292 246 310 283 295 277 260 264 271 274 305 271 299 285 272 265 272 281 299 312 262 263 285 246 269 317 260 283 281 276 270 278 268 280 300 259 263 271 285 249 283 283 290 274 315 305 276 300 264 260 283 280 291 289 277 287 274 277 309 287 293 306 307 287 258 256 287 308 301 295 271 287 292 281 297 241 269 267 260 275 278 278 265 296 273 307 276 297 290 243 301 263 273 266 278 288 292 291 287 271 280 265 290 271 273 294 282 281 328 280 279 272 249 295 279 270 283 295 289 257 284 304 255 232 265 245 291 268 279 304 301 281 285 298 303 281 273 270 270 286 301 270 273 321 275 261 247 303 280 270 267 275 309 268 267 294 260 287 247 255 282 305 297 260 299 283 281 288 270 284 294 279 287 293 270 278 270 233 288 266 331 285 292 279 277 315 268 294 302 294 291 312 288 285 262 264 261 270 282 275 278 299 272 277 301 249 291 301 297 237 259 270 280 257 304 274 294 289 247 274 271 272 304 288 305 264 301 278 282 313 320 272 297 277 276 243 296 260 282 272 302 255 306 276 287 294 282 281 286 275 246 268 267 268 287 281 285 255 302 257 271 243 272 263 255 284 282 274 248 283 291 273 261 300 258 279 290 296 300 299 305 290 258 280 283 280 306 284 273 298 293 270 302 267 256 240 290 281 264 286 290 260 274 273 279 272 272 289 265 290 275 274 305 266 289 249 280 262 265 260 256 302 293 301 268 238 225 232 296 304 273 259 286 280 269 297 283 264 290 292 257 275 282 275 281 290 288 291 272 279 285 288 303 289 261 269 239 297 299 276 301 272 275 244 280 313 298 247 301 263 308 259 292 248 287 280 305 273 326 336 292 281 284 259 284 279 270 276 293 239 290 265 289 273 279 313 293 301 308 279 259 267 263 247 309 272 288 279 288 272 280 266 306 285 307 280 300 293 314 269 265 285 258 276 258 259 280 288 281 286 271 281 306 304 256 277 271 268 312 270 291 271 278 264 322 279 290 288 295 258 268 290 303 272 267 276 283 280 264 284 271 296 266 278 293 311 298 246 246 277 262 277 290 266 306 266 277 297 266 269 296 287 302 286 273 307 277 280 290 289 281 265 287 268 281 284 293 276 269 288 287 288 270 271 300 266 259 295 278 291 281 294 299 281 261 269 291 274 273 284 271 294 298 289 285 307 303 285 282 318 275 230 271 287 264 277 280 278 281 299 275 279 261 274 288 298 283 256 235 274 262 277 287 292 280 271 285 219 288 280 298 299 276 279 293 294 296 286 247 278 293 245 295 319 271 280 279 282 273 272 303 304 299 271 311 277 289 293 270 300 288 307 296 272 274 275 281 262 268 278 279 284 319 272 273 307 282 238 295 275 290 235 264 279 276 270 284 310 308 272 281 275 270 287 240 287 289 276 284 305 294 290 279 291 291 280 282 281 260 284 317 286 297 259 284 296 319 277 289 272 271 293 300 312 299 289 305 282 300 293 293 291 278 302 242 303 313 292 318 293 265 309 272 287 281 246 300 268 294 298 272 315 291 267 295 273 264 280 258 297 249 268 285 303 278 256 298 302 306 273 269 281 289 292 279 238 250 267 281 264 314 263 264 302 293 291 322 239 308 308 280 273 269 292 273 291 256 263 269 308 283 278 277 316 258 295 275 275 265 267 298 271 293 282 298 275 287 269 262 278 302 288 282 287 294 296 284 275 296 275 274 268 290 294 269 280 279 309 276 274 297 284 272 309 277 266 229 313 272 279 241 312 278 259 279 265 277 268 280 287 289 321 294 256 303 293 261 267 305 323 262 273 287 284 305 296 263 274 314 302 276 288 286 297 278 283 282 299 294 291 305 283 282 280 292 286 278 293 270 300 287 288 290 293 302 278 269 300 297 287 309 310 307 266 266 287 281 286 273 262 265 258 271 287 291 298 279 302 282 274 288 269 292 281 286 261 269 289 258 277 290 301 265 274 278 277 278 289 315 274 324 296 298 295 286 290 271 260 303 276 287 266 271 274 305 273 293 270 296 285 289 285 298 235 261 271 289 313 272 279 299 288 306 291 290 292 279 279 273 271 276 296 296 282 265 315 286 307 287 291 246 267 291 275 299 293 274 276 285 270 307 271 262 263 275 301 316 270 273 299 241 292 267 295 288 327 312 278 272 256 280 289 283 264 283 283 266 272 299 286 276 246 314 285 248 312 293 268 259 306 326 320 293 302 314 316 278 284 298 304 276 297 259 296 295 314 287 281 276 289 286 300 265 290 281 270 298 274 284 280 275 274 292 311 283 282 278 250 272 298 340 281 278 279 308 288 313 292 299 292 275 348 292 271 267 297 314 307 287 274 277 267 295 312 303 294 310 261 273 282 269 274 285 341 245 296 297 313 280 314 331 287 276 279 282 280 301 284 302 282 309 286 265 296 274 300 295 294 282 287 303 296 286 324 272 269 287 308 295 302 296 241 265 299 313 291 319 282 256 272 278 309 292 290 311 264 267 283 275 292 296 240 258 287 264 288 260 299 267 293 292 299 299 286 293 265 273 294 278 284 296 305 296 265 317 269 298 274 316 292 282 278 265 260 303 309 272 279 293 270 294 276 300 304 304 300 304 274 284 282 268 303 295 294 282 302 292 259 295 294 267 288 312 289 292 287 283 306 277 304 263 266 288 275 294 301 283 277 294 275 261 305 275 277 289 272 292 310 322 302 276 303 275 294 293 306 268 279 266 288 273 261 312 275 272 297 311 279 299 266 300 309 286 287 282 288 287 257 271 308 301 300 291 287 247 288 297 280 277 281 293 263 273 296 250 287 307 297 289 283 249 269 292 300 277 277 317 304 287 272 269 299 277 293 287 263 260 304 311 285</counts>
			</dataPoints>
		</scan>
	</xrdMeasurement>
</xrdMeasurements>