File: data/XRD/XG-Vakuum/XG-750/W6823-1C_XG_Vakuum_750.xrdml
<xrdMeasurements xmlns="http://www.xrdml.com/XRDMeasurement/2.1" xmlns:xsi="http://www.w3.org/2001/XMLSchema-instance" xsi:schemaLocation="http://www.xrdml.com/XRDMeasurement/2.1 http://www.xrdml.com/XRDMeasurement/2.1/XRDMeasurement.xsd" status="Completed">
	<comment>
		<entry>Configuration=Factory configuration, Owner=User-1, Creation date=7/8/2013 4:01:53 PM</entry>
		<entry>Goniometer=PW3050/65 (Theta/2Theta); Minimum step size 2Theta:0.0001; Minimum step size Omega:0.0001</entry>
		<entry>Sample stage=MRD Cradle; Minimum step size Phi:0.01; Minimum step size Chi:0.01; Minimum step size X:0.01; Minimum step size Y:0.01; Minimum step size Z:0.001</entry>
		<entry>Diffractometer system=XPERT-PRO</entry>
		<entry>Measurement program=C:\PANalytical\Data Collector\Programs\Jorrit\2thom\_absolute_2th-om_10-130deg_PIXscan_56min.xrdmp, Identifier={15BCCF57-2807-42BD-B5B9-ECC0B3DC9284}</entry>
		<entry>Batch program=C:\PANalytical\Data Collector\Programs\SimonL\batch6x_2thom_10-130°_z9.1_x0,10,20,30_y20,40_57min - Kopie.xrdmp, Identifier={6B3EF4D3-441D-47FD-9EA5-077D311040EA}</entry>
	</comment>
	<sample type="To be analyzed">
		<id></id>
		<name></name>
		<preparedBy></preparedBy>
	</sample>
	<xrdMeasurement measurementType="Scan" status="Completed" sampleMode="Reflection">
		<comment>
			<entry>_absolute_2th-om_10-130deg_PIXscan_56min</entry>
			<entry>PHD Lower Level = 4.83 (keV), PHD Upper Level = 11.27 (keV)</entry>
		</comment>
		<usedWavelength intended="K-Alpha 1">
			<kAlpha1 unit="Angstrom">1.5405980</kAlpha1>
			<kAlpha2 unit="Angstrom">1.5444260</kAlpha2>
			<kBeta unit="Angstrom">1.3922500</kBeta>
			<ratioKAlpha2KAlpha1>0.5000</ratioKAlpha2KAlpha1>
		</usedWavelength>
		<incidentBeamPath>
			<radius unit="mm">320.00</radius>
			<xRayTube id="1010048" name="Empyrean Cu LFF HR (9430 033 7310x) DK442154">
				<tension unit="kV">40.0</tension>
				<current unit="mA">40.0</current>
				<anodeMaterial>Cu</anodeMaterial>
				<focus type="Line">
					<length unit="mm">12.0</length>
					<width unit="mm">0.4</width>
					<takeOffAngle unit="deg">4.2</takeOffAngle>
				</focus>
			</xRayTube>
			<xRayMirror id="27010001" name="Inc. Beam Cu W/Si (parabolic MRD)" hybrid="false">
				<crystal type="Graded" shape="Parabolic">W/Si</crystal>
				<acceptanceAngle unit="deg">0.800</acceptanceAngle>
				<length unit="mm">60.0</length>
			</xRayMirror>
			<sollerSlit id="21010002" name="Soller slits 0.04 rad.">
				<opening unit="rad">0.0400</opening>
			</sollerSlit>
			<mask id="22030008" name="Fixed mask 4 mm">
				<distanceToSample unit="mm">220.00</distanceToSample>
				<width unit="mm">4.00</width>
			</mask>
			<divergenceSlit id="22010011" name="Fixed slit 1/32°" xsi:type="fixedDivergenceSlitType">
				<distanceToSample unit="mm">220.00</distanceToSample>
				<height unit="mm">0.05</height>
			</divergenceSlit>
		</incidentBeamPath>
		<diffractedBeamPath>
			<radius unit="mm">320.00</radius>
			<sollerSlit id="21010002" name="Soller slits 0.04 rad.">
				<opening unit="rad">0.0400</opening>
			</sollerSlit>
			<receivingSlit id="22010001" name="Fixed slit 4°">
				<height unit="mm">5.88</height>
			</receivingSlit>
			<detector id="7010017" name="PIXcel3D 1x1 detector" xsi:type="areaDetectorType">
				<phd unit="%">
					<lowerLevel>30.0</lowerLevel>
					<upperLevel>70.0</upperLevel>
				</phd>
				<mode>Scanning</mode>
				<activeChannelsEquatorial>255</activeChannelsEquatorial>
				<activeChannelsAxial>255</activeChannelsAxial>
				<pitchEquatorial unit="mm">0.05500</pitchEquatorial>
				<pitchAxial unit="mm">0.05500</pitchAxial>
				<readOutPeriod unit="seconds">0.135</readOutPeriod>
			</detector>
		</diffractedBeamPath>
		<scan appendNumber="0" mode="Continuous" scanAxis="2Theta-Omega" status="Completed">
			<header>
				<startTimeStamp>2024-10-11T18:18:50+02:00</startTimeStamp>
				<endTimeStamp>2024-10-11T19:14:56+02:00</endTimeStamp>
				<author>
					<name>PRO-MRD</name>
				</author>
				<source>
					<applicationSoftware version="6.1b">Data Collector</applicationSoftware>
					<instrumentControlSoftware version="7.0E 20130304">XPERT-PRO</instrumentControlSoftware>
					<instrumentID>0000000011142674</instrumentID>
				</source>
			</header>
			<dataPoints>
				<positions axis="2Theta" unit="deg">
					<startPosition>9.99826193</startPosition>
					<endPosition>129.99755682</endPosition>
				</positions>
				<positions axis="Omega" unit="deg">
					<startPosition>4.99913096</startPosition>
					<endPosition>64.99877841</endPosition>
				</positions>
				<positions axis="Phi" unit="deg">
					<commonPosition>0.00</commonPosition>
				</positions>
				<positions axis="Chi" unit="deg">
					<commonPosition>0.00</commonPosition>
				</positions>
				<positions axis="X" unit="mm">
					<commonPosition>20.00</commonPosition>
				</positions>
				<positions axis="Y" unit="mm">
					<commonPosition>0.00</commonPosition>
				</positions>
				<positions axis="Z" unit="mm">
					<commonPosition>9.100</commonPosition>
				</positions>
				<commonCountingTime unit="seconds">32.895</commonCountingTime>
				<counts 358 402 370 368 407 381 357 375 371 381 376 385 365 353 404 357 376 370 370 367 372 347 379 368 373 393 367 355 372 400 377 359 385 394 390 382 374 374 412 364 414 387 419 371 382 365 387 359 392 379 378 380 392 380 408 358 403 372 393 352 382 381 375 351 376 387 382 366 357 355 368 346 353 378 357 371 357 391 388 380 409 342 365 356 350 347 336 364 349 380 385 353 343 351 351 349 356 352 335 347 364 354 348 358 352 366 362 371 369 333 338 332 350 384 331 342 366 329 381 377 335 353 374 346 347 320 380 324 346 353 330 333 312 373 358 341 341 337 359 359 346 333 314 345 336 352 330 347 349 346 342 328 341 316 373 321 350 336 348 314 350 379 321 349 338 358 347 340 349 341 344 326 363 329 304 316 369 327 341 322 335 353 350 317 316 338 356 344 349 351 327 315 335 353 327 299 325 333 365 332 333 322 340 324 317 292 329 315 296 298 362 317 319 343 332 311 337 328 333 313 309 332 356 346 301 320 310 342 313 366 330 331 288 332 323 299 331 330 340 339 323 295 325 314 344 322 296 326 317 319 319 313 331 320 321 298 336 317 334 342 345 318 332 335 322 312 318 301 294 308 344 338 304 302 323 314 313 344 351 315 298 331 318 327 330 311 336 318 335 310 318 320 342 310 316 325 335 318 340 309 341 331 320 316 318 283 341 309 288 299 291 308 308 316 302 307 305 307 301 295 304 281 265 301 291 293 300 310 295 273 313 335 312 295 304 347 280 289 313 315 303 313 303 325 327 318 306 280 282 324 279 308 272 296 272 291 290 274 297 292 274 306 274 268 315 286 305 302 312 303 319 291 338 322 289 295 307 304 255 298 297 325 292 328 325 302 287 305 313 291 308 282 287 278 311 273 274 265 276 315 264 307 311 298 292 286 301 297 308 327 277 260 279 278 310 283 289 286 300 273 310 267 305 294 281 300 273 277 259 257 249 269 258 245 275 296 270 267 304 288 280 272 283 290 274 277 275 294 268 244 278 316 290 261 292 262 279 259 247 288 273 314 272 275 268 299 301 210 256 256 280 261 248 278 306 245 265 275 279 290 272 289 281 277 284 297 286 247 266 292 242 265 275 281 282 288 281 271 268 287 292 273 282 289 267 272 288 241 262 291 299 310 306 266 303 277 281 276 260 291 274 249 279 272 285 276 245 281 263 231 263 286 259 259 266 262 289 276 279 263 243 269 244 241 257 270 271 267 265 274 262 295 284 280 264 264 244 249 277 267 266 265 269 246 266 265 278 282 289 278 241 271 276 239 286 258 273 235 275 281 262 296 241 264 276 257 292 283 249 263 292 237 230 262 241 276 246 282 272 283 264 257 258 259 245 242 260 242 257 277 240 287 242 283 264 256 261 285 236 240 277 241 236 230 266 249 247 262 259 266 237 265 269 262 270 248 235 273 236 244 229 226 261 277 230 241 263 246 237 274 233 277 240 272 244 234 241 265 246 289 270 256 255 282 267 249 277 248 247 264 255 258 262 229 259 286 209 249 248 239 225 261 265 235 259 259 242 228 272 263 249 249 236 244 266 248 223 237 239 262 267 262 243 247 248 264 263 245 248 258 222 261 272 210 227 265 234 225 245 260 242 241 247 230 257 279 259 219 220 243 229 248 267 219 259 262 248 225 264 257 216 258 243 221 242 240 241 240 235 242 236 242 238 217 247 248 267 278 255 242 230 237 241 235 239 259 229 230 228 263 244 258 258 218 229 236 245 230 241 229 200 231 260 241 222 258 239 245 218 237 247 258 243 248 231 227 244 229 261 244 234 240 255 241 231 237 248 231 272 232 235 199 214 217 240 246 258 243 243 228 220 235 237 234 247 271 228 243 240 227 250 230 262 233 247 227 237 255 246 255 215 225 249 222 235 227 221 231 242 247 216 224 230 265 218 230 234 238 221 259 211 242 244 218 230 226 245 236 226 223 227 235 218 228 232 240 245 230 228 227 217 236 233 233 220 257 227 229 245 220 213 234 246 229 240 264 232 255 197 229 239 243 226 213 235 206 229 249 223 224 255 248 249 249 256 244 217 266 239 236 230 261 241 272 239 224 236 255 236 244 228 247 255 231 227 242 205 242 270 228 204 265 234 229 225 237 244 230 242 233 228 243 268 238 228 197 246 224 220 258 270 242 256 217 236 247 230 277 239 235 214 219 230 228 239 210 237 247 239 211 265 258 231 227 229 249 217 241 227 268 248 231 208 233 237 255 218 234 232 250 261 268 212 234 238 232 232 213 233 228 223 230 257 223 239 234 223 221 247 234 261 259 233 228 262 230 246 246 237 219 274 256 258 204 223 229 222 260 263 224 277 226 215 242 227 267 241 201 236 246 227 241 228 233 237 240 225 266 237 228 249 218 276 230 270 255 247 216 222 226 222 229 238 243 247 238 245 247 258 235 217 245 227 262 226 231 238 267 256 230 236 261 259 255 225 221 223 247 242 207 240 224 215 238 243 236 225 260 241 221 242 226 232 246 250 232 229 263 235 257 239 265 273 230 243 229 269 278 276 225 235 259 230 241 217 237 248 214 247 257 258 248 258 232 244 258 238 265 220 261 257 258 268 238 214 279 259 245 214 269 236 246 274 235 256 228 282 255 237 265 268 230 265 216 235 247 233 242 248 260 241 240 217 270 271 261 264 249 274 240 239 238 230 247 263 227 275 243 272 260 238 257 271 263 265 258 223 222 265 224 218 240 229 236 228 245 270 237 229 233 232 247 270 241 259 244 261 237 286 260 256 236 256 241 235 226 233 230 230 259 261 243 219 214 268 244 233 271 225 236 241 244 236 268 238 244 264 238 280 247 233 243 225 236 276 269 244 256 237 223 267 283 218 234 245 277 257 246 248 279 286 240 260 255 244 240 219 260 278 248 234 233 262 268 258 286 244 245 231 271 227 273 233 270 283 244 240 273 259 224 238 235 250 272 248 211 285 240 218 263 273 244 276 256 245 248 255 255 267 237 209 284 288 247 255 247 263 261 244 259 223 269 257 261 244 245 248 244 248 241 277 238 242 221 270 258 260 240 245 223 255 275 224 273 235 264 266 296 284 230 236 267 247 257 219 259 247 271 235 245 245 262 258 237 261 279 233 238 241 266 295 256 241 247 235 237 261 273 240 257 268 262 300 266 259 275 245 244 268 220 270 261 235 229 243 250 242 263 245 245 289 264 272 283 271 236 275 265 280 234 264 239 264 263 273 243 248 270 234 244 276 264 257 259 260 238 258 238 267 262 261 275 255 222 249 236 237 240 255 249 281 229 232 264 260 240 239 277 265 261 244 260 261 260 242 257 258 229 246 245 260 267 255 258 261 249 220 233 266 233 260 259 236 243 284 266 245 241 243 225 249 256 225 263 268 263 250 244 268 268 290 262 248 243 234 244 246 234 248 268 263 259 255 259 236 228 270 234 264 245 257 228 238 219 248 238 244 237 263 272 227 236 276 236 270 277 225 227 273 238 240 229 268 255 234 242 267 249 267 259 257 247 227 261 264 230 233 261 246 223 256 231 239 265 248 239 233 208 241 242 220 234 246 242 240 260 250 226 245 247 238 228 221 255 214 244 249 249 242 234 244 260 231 229 226 235 223 233 216 262 262 223 244 222 259 272 223 243 272 247 264 248 258 263 241 275 246 229 219 213 265 212 249 212 243 228 233 272 209 234 242 249 263 226 249 221 210 224 235 218 219 238 241 255 234 245 246 219 192 260 276 233 263 271 230 264 249 218 244 235 248 273 229 243 247 217 264 255 232 232 244 255 216 215 240 232 208 223 235 264 233 262 229 219 224 225 231 208 227 248 217 248 223 229 255 229 225 244 220 233 244 246 214 211 219 255 229 242 215 245 240 286 279 233 217 210 245 244 242 255 224 259 255 237 230 233 234 219 219 247 223 223 248 240 223 236 250 243 204 228 249 228 207 235 233 259 228 217 262 258 238 238 220 238 224 255 231 212 230 230 226 223 184 243 237 221 206 244 235 250 196 231 205 230 246 230 212 209 217 225 257 202 263 239 207 224 229 207 232 230 224 218 243 239 257 236 226 209 212 271 198 231 245 266 230 232 230 264 210 191 260 249 229 248 241 221 243 214 235 229 229 210 261 224 233 256 214 243 229 206 233 235 221 226 258 250 217 275 226 255 244 208 231 257 244 217 213 235 231 224 236 246 260 246 229 226 241 230 237 225 206 221 228 248 223 242 235 219 249 209 231 232 239 220 233 213 234 234 220 243 235 233 205 233 224 256 227 233 226 218 242 233 234 239 205 216 250 216 248 222 241 223 230 214 219 245 258 211 224 221 228 232 217 221 221 238 228 226 211 236 223 226 244 220 204 225 227 226 228 209 226 245 231 244 220 232 227 216 273 213 230 222 256 243 228 234 212 228 229 210 257 237 219 231 204 228 213 256 234 223 225 222 215 217 218 232 225 230 197 226 221 222 216 208 230 233 257 215 216 207 217 218 212 219 219 228 222 258 190 209 206 224 229 219 222 214 231 259 212 224 204 212 218 207 217 196 226 207 230 194 258 235 224 235 210 258 227 229 248 232 224 223 222 222 183 244 219 213 227 266 226 216 212 211 212 223 245 210 229 210 235 204 215 214 180 224 208 198 212 203 239 209 215 240 224 216 225 220 226 237 211 222 216 217 206 231 235 231 237 249 204 234 243 221 207 219 228 246 214 234 226 205 212 229 210 195 226 213 227 228 213 225 218 242 232 232 247 232 201 214 220 224 243 232 235 219 209 238 218 192 219 240 220 210 224 234 214 211 216 204 214 208 216 218 223 215 211 236 239 221 186 197 208 203 226 230 200 215 199 200 204 215 201 205 218 227 224 190 219 264 230 214 212 232 205 214 198 212 232 236 193 201 227 206 187 235 210 205 223 234 207 215 208 224 188 206 212 219 215 216 227 203 194 210 212 195 202 210 250 188 231 213 223 222 218 197 205 223 231 212 214 237 231 224 218 197 216 237 230 224 208 198 238 223 208 206 189 195 202 226 212 238 205 212 222 230 200 209 209 219 229 223 206 246 216 194 259 221 196 242 229 175 213 230 228 222 189 234 221 212 215 217 186 206 230 225 262 228 211 215 207 227 242 231 212 190 215 247 198 206 219 217 233 204 203 237 222 222 202 226 225 224 230 245 199 238 220 216 217 248 224 236 216 199 213 248 214 216 207 219 241 234 211 219 240 206 224 217 227 205 241 212 201 230 227 242 193 200 232 220 198 190 231 227 220 229 211 209 236 234 198 219 200 242 237 243 228 219 219 220 221 191 245 222 224 210 244 229 222 195 213 218 205 213 206 232 228 235 213 215 220 223 237 192 248 241 226 258 215 216 230 203 224 237 208 221 197 215 227 225 228 223 209 231 226 241 236 221 232 233 229 220 234 236 212 227 270 186 231 231 204 213 227 191 236 216 198 204 209 228 257 259 228 208 227 238 212 221 198 231 200 221 232 225 229 217 206 210 222 192 271 231 202 232 216 238 223 224 217 207 216 204 228 233 236 226 207 212 236 222 259 263 212 223 222 231 258 231 218 233 249 232 228 217 211 223 220 213 199 218 214 213 197 228 220 257 250 232 234 236 225 207 214 221 221 248 261 242 226 224 231 198 221 204 221 208 235 229 226 229 266 221 222 210 220 212 217 223 243 245 203 242 216 205 195 248 211 237 226 228 245 220 229 242 226 246 240 209 207 229 231 246 233 243 208 230 215 206 197 260 215 201 258 242 217 215 208 245 228 223 242 266 240 202 220 203 216 225 227 204 220 229 247 226 234 230 214 244 239 238 228 221 197 240 247 236 213 210 228 241 205 248 236 207 229 236 196 233 214 227 212 246 200 220 225 241 235 238 256 211 221 236 226 221 231 241 234 203 234 224 214 217 211 223 262 245 237 235 233 216 203 211 220 215 234 230 222 211 225 229 191 224 226 233 220 243 203 209 242 209 194 220 218 223 212 300 205 232 259 235 232 216 228 210 202 236 206 218 204 220 233 238 225 227 209 230 208 222 206 204 224 224 221 208 211 247 242 213 224 235 240 255 238 233 224 245 224 228 210 265 235 224 214 205 245 237 229 227 216 213 236 237 237 205 214 220 234 214 244 223 230 250 211 199 227 246 220 195 241 208 201 222 230 223 212 223 229 230 220 227 222 227 218 229 225 224 240 259 258 194 257 233 235 204 255 202 243 232 223 234 235 236 219 232 231 230 231 246 231 224 240 219 219 227 216 235 228 240 232 212 228 236 239 244 208 244 229 246 260 223 237 233 219 277 204 226 233 234 234 212 256 231 243 250 233 250 259 259 248 235 264 271 235 232 227 285 248 272 294 262 269 273 306 272 281 294 311 282 329 294 336 341 358 367 368 451 389 477 566 628 749 834 1067 1347 1530 1887 2133 2302 2339 2215 2109 1917 1722 1648 1573 1518 1571 1507 1518 1338 1228 1136 987 850 739 626 566 486 435 433 405 412 376 353 348 287 319 303 309 262 292 298 280 288 284 237 246 271 248 282 290 230 231 239 248 212 240 228 244 243 249 234 270 246 211 220 209 234 228 222 223 239 235 234 209 211 249 241 231 216 210 230 223 262 230 223 225 239 224 207 229 228 225 210 224 235 204 241 217 232 220 232 217 208 234 225 248 211 227 237 246 226 221 244 232 257 232 223 255 255 246 219 204 209 218 225 225 227 226 214 243 241 237 202 238 199 227 230 243 224 238 197 206 223 229 216 213 233 244 256 224 228 231 230 224 225 238 221 210 242 232 204 207 233 222 216 228 218 215 227 218 225 234 207 219 228 228 216 195 229 220 221 195 223 225 234 218 248 238 199 205 236 219 242 240 272 222 226 235 185 279 245 231 221 227 220 210 267 238 242 232 223 238 242 215 209 235 199 234 227 218 217 241 232 218 234 235 229 225 226 233 257 201 257 206 235 249 202 221 213 230 242 248 248 191 231 223 216 233 231 235 222 269 248 226 243 232 226 215 237 228 264 240 224 224 216 220 236 233 216 236 267 241 249 223 209 230 225 231 240 239 233 220 218 209 241 255 219 229 227 246 198 235 228 222 223 212 233 228 235 244 232 225 222 239 228 212 237 233 212 230 200 241 227 217 236 213 218 244 260 229 245 235 221 216 232 243 223 200 244 280 247 234 239 231 224 218 213 224 255 219 226 246 219 249 234 228 249 256 233 264 225 222 198 228 222 262 234 243 266 216 258 240 222 231 211 275 233 222 255 265 237 241 224 218 281 222 245 230 246 249 256 231 242 240 217 234 262 215 197 220 231 243 228 256 226 259 222 222 248 244 243 205 215 231 261 219 282 246 245 245 237 231 225 215 227 231 224 242 242 227 210 206 248 220 243 239 227 257 265 271 236 217 221 230 222 231 239 255 238 225 259 216 239 231 230 249 228 273 201 263 221 235 249 231 189 222 265 260 225 225 234 221 223 280 233 234 199 245 210 235 212 218 236 220 249 231 234 269 235 216 210 234 258 231 231 234 207 225 230 240 218 247 265 241 212 228 217 237 248 247 246 218 267 247 235 221 265 262 222 210 244 227 272 234 222 240 236 241 224 239 266 256 246 249 239 268 238 255 229 244 249 223 240 231 226 267 230 242 270 233 229 222 248 219 255 240 270 267 232 262 288 258 236 240 272 240 276 246 258 266 276 256 257 236 260 266 301 282 255 274 240 268 265 274 240 259 267 283 280 262 279 269 292 273 269 283 304 274 293 304 281 268 285 291 290 278 269 316 287 294 275 296 272 301 326 304 263 286 324 334 304 343 339 314 319 328 332 336 350 355 359 434 406 439 447 472 455 559 523 588 634 652 742 758 826 876 853 781 804 807 723 807 770 808 753 762 771 734 713 664 650 656 597 553 507 540 486 522 458 431 460 429 382 408 421 370 348 416 347 320 347 331 357 314 332 325 296 293 296 277 293 304 282 297 296 273 267 280 306 274 267 306 278 278 256 272 255 290 245 268 260 267 232 256 257 270 278 260 273 255 235 256 242 237 249 241 238 277 262 245 236 217 289 237 238 244 233 263 227 237 230 243 236 258 249 208 213 287 255 249 206 216 223 244 247 257 239 231 255 229 210 262 258 233 224 255 274 249 249 255 242 228 226 233 238 217 234 240 261 226 261 258 239 237 228 216 238 266 263 243 243 249 224 224 214 238 246 241 219 236 265 263 237 229 223 215 257 224 243 246 217 240 205 236 229 221 230 248 232 210 200 234 237 230 244 267 246 223 243 238 246 241 223 222 234 228 226 241 230 206 215 246 217 261 237 204 230 242 230 240 215 219 229 259 218 261 241 216 212 227 247 244 265 231 231 249 239 260 245 260 260 244 233 231 256 240 258 227 242 211 234 236 241 222 247 235 235 239 235 237 260 256 226 268 236 231 224 249 218 222 248 233 248 232 228 223 222 235 210 239 233 235 261 211 225 229 213 249 204 224 235 239 238 191 232 233 265 265 218 272 273 250 233 241 246 236 257 245 244 244 219 239 288 243 241 241 223 270 240 223 282 241 223 238 223 238 227 236 264 228 212 216 244 228 236 243 230 271 236 235 233 230 263 263 227 214 265 225 237 231 243 228 241 266 223 214 261 246 207 219 233 249 236 233 240 237 242 244 222 238 231 260 263 263 246 222 241 236 260 257 227 279 226 267 232 197 257 261 218 238 255 249 256 229 237 234 234 222 255 237 242 228 256 245 262 240 282 227 250 242 258 227 239 216 238 240 245 243 265 229 258 272 258 235 255 218 250 229 255 249 236 236 237 236 244 263 270 239 237 235 245 262 235 241 262 213 235 239 223 267 244 201 239 255 233 225 256 263 267 235 232 219 246 256 259 238 232 220 271 238 236 262 215 244 243 269 228 208 239 263 243 206 259 273 239 248 233 265 237 255 215 238 235 229 248 241 259 258 239 241 242 272 221 259 198 258 240 231 224 240 238 237 238 260 243 227 270 237 228 236 261 241 258 239 258 275 221 257 273 248 235 244 258 248 246 257 241 242 222 237 269 286 249 274 247 262 272 226 263 246 233 234 241 256 227 255 256 279 236 221 242 226 245 244 227 230 228 245 229 245 272 243 257 256 247 239 249 244 224 275 240 257 243 233 224 227 278 226 237 243 281 281 239 268 266 248 230 260 245 271 263 249 239 235 230 259 246 256 273 240 217 263 220 238 255 285 248 257 262 272 237 265 294 282 258 243 275 236 244 230 282 256 260 235 243 240 240 264 245 231 217 240 260 247 228 248 255 227 267 255 234 248 234 248 261 257 233 272 260 276 257 239 236 260 237 260 268 263 263 282 234 216 244 261 239 233 236 267 247 275 274 277 269 257 220 263 245 259 221 237 245 256 263 218 258 258 245 245 238 243 258 263 270 229 273 247 244 220 255 292 256 266 267 256 274 232 242 264 222 263 224 233 258 223 261 243 261 237 248 258 265 256 235 241 276 257 243 241 224 264 242 271 238 266 244 256 238 263 240 242 245 258 239 261 262 282 223 247 240 242 264 266 214 226 241 241 264 241 209 240 278 256 233 272 271 261 257 266 249 282 260 228 258 235 250 258 262 264 273 266 242 245 269 258 225 234 238 260 239 269 246 262 245 257 238 277 244 282 240 246 277 215 224 240 272 232 264 276 267 242 266 242 259 242 266 222 277 293 260 248 247 240 236 223 242 223 258 241 255 241 297 261 268 232 239 241 264 248 248 269 237 228 227 227 264 257 264 256 230 263 236 257 244 271 277 271 259 263 265 280 262 282 238 243 255 228 268 249 231 238 266 232 261 237 243 257 265 259 233 245 226 232 271 238 259 267 240 279 238 287 222 228 236 241 267 260 220 241 262 263 258 285 246 263 263 229 277 282 241 279 248 297 231 258 263 273 263 237 273 202 237 263 260 270 265 264 244 261 242 274 238 265 261 232 229 235 257 266 289 266 284 260 248 264 226 249 225 235 247 241 233 250 271 259 244 244 226 241 286 238 288 293 272 256 283 247 247 259 231 255 255 229 222 261 268 276 262 257 279 277 249 258 269 269 274 237 223 259 235 241 280 249 239 257 267 279 236 274 288 258 243 234 265 247 238 216 244 247 270 263 232 257 256 282 228 232 247 259 240 235 258 269 271 243 269 220 271 277 238 275 231 257 242 245 247 267 229 280 246 236 243 271 235 223 240 248 293 240 273 248 227 261 244 240 242 257 274 272 256 287 267 268 249 263 240 235 219 228 258 267 246 270 257 248 271 250 281 267 262 246 278 239 268 241 268 243 227 230 245 286 244 264 226 237 255 275 270 272 247 265 276 232 236 279 244 279 258 279 284 286 268 241 246 242 264 243 258 239 284 246 233 229 281 274 238 242 273 247 255 286 236 233 232 255 264 277 262 267 258 257 261 241 258 276 244 259 288 237 279 246 267 255 266 240 235 271 236 240 230 259 231 235 257 269 230 239 280 261 248 241 247 270 259 267 258 262 277 260 236 217 261 224 248 264 269 271 265 247 268 238 248 232 266 275 258 274 280 248 240 246 259 275 269 282 262 255 259 250 245 244 279 232 220 268 284 285 220 236 258 274 232 290 284 292 244 266 227 248 275 262 245 246 238 264 249 255 256 263 267 244 249 247 272 239 266 236 236 265 269 265 283 242 277 272 239 240 272 250 268 280 245 249 246 256 266 244 273 245 212 303 260 273 280 243 273 233 255 289 272 261 278 297 262 268 281 266 289 240 266 267 274 238 246 258 275 238 274 269 272 256 266 258 275 241 239 227 273 276 238 259 265 236 238 267 260 255 270 273 265 272 237 263 261 239 247 244 258 266 259 268 280 244 255 241 247 268 277 265 293 262 273 259 276 238 258 271 281 274 295 238 283 227 293 259 268 286 241 265 247 288 284 256 280 283 259 207 268 230 245 273 246 243 255 237 267 259 275 297 259 279 238 259 279 264 297 257 281 279 259 244 275 237 262 270 266 245 284 301 237 247 278 286 294 279 267 256 263 291 293 269 242 285 290 284 277 267 258 257 235 269 270 270 287 272 263 281 257 285 271 260 269 245 268 256 259 273 282 274 261 247 284 291 274 257 247 278 273 281 284 273 227 244 250 268 255 263 267 258 257 306 243 246 244 243 248 263 270 274 277 214 283 289 266 277 291 295 255 259 274 280 270 247 265 260 260 248 279 264 267 266 243 272 290 289 269 226 259 240 289 272 243 236 244 301 239 241 259 222 270 277 233 292 275 273 296 242 259 269 270 280 279 266 276 263 284 258 245 257 262 277 265 278 260 265 270 255 287 262 232 277 262 258 295 246 260 300 261 279 284 264 300 220 268 255 245 258 282 280 264 255 259 276 221 246 247 292 275 260 289 257 291 281 292 286 235 248 226 247 246 261 247 294 262 285 257 308 274 294 248 283 273 255 270 292 278 273 237 264 279 289 263 235 273 248 269 246 265 313 292 268 231 259 255 264 289 264 271 278 268 232 291 247 247 274 243 241 243 270 259 278 228 274 258 268 267 285 270 273 263 267 240 292 272 235 274 270 278 266 248 290 266 286 284 268 282 248 240 286 268 231 278 244 240 259 265 271 268 239 276 275 259 287 275 260 266 255 235 276 275 282 256 287 269 294 260 262 275 283 274 270 279 255 268 283 267 234 282 276 298 292 241 266 272 249 256 272 244 240 262 282 266 272 267 266 232 276 264 275 263 248 286 236 250 284 267 286 282 257 259 244 267 246 273 282 270 265 272 284 260 283 257 272 242 277 242 256 276 268 302 265 270 264 272 272 276 269 279 248 245 224 257 259 264 239 233 260 256 243 265 256 255 260 274 250 268 260 272 247 245 275 268 268 297 260 246 267 275 261 269 289 237 273 286 271 276 255 273 266 249 275 261 270 273 267 287 294 293 263 269 239 282 265 270 287 244 239 264 292 260 289 266 232 246 264 243 260 260 279 237 261 241 243 266 241 270 249 282 283 276 271 271 284 266 269 286 273 265 272 256 278 277 291 282 288 267 274 267 225 267 239 297 249 265 267 294 260 279 292 282 263 271 263 278 286 263 241 285 261 279 282 246 259 287 249 263 261 255 259 290 274 273 263 280 236 262 266 259 282 272 287 297 276 283 280 281 261 286 235 287 270 256 258 309 282 299 260 281 244 279 292 276 311 279 240 266 276 265 255 278 245 269 271 295 277 246 244 243 285 264 265 276 278 265 244 243 285 304 290 256 285 250 299 284 264 264 278 260 287 262 281 240 262 272 247 276 279 276 275 273 292 288 261 280 263 266 278 294 282 261 267 257 279 269 260 283 313 260 288 300 256 273 303 245 315 301 268 267 295 288 289 262 295 277 308 278 300 294 321 269 306 285 308 255 250 306 317 288 265 278 301 287 304 288 278 302 275 260 276 311 316 302 290 323 331 290 313 301 313 318 310 327 351 366 341 388 366 357 393 427 400 392 419 373 456 423 401 403 369 369 385 387 361 386 377 369 393 408 364 361 396 369 387 375 335 359 363 359 322 378 336 304 316 331 293 318 286 323 330 291 311 284 298 301 313 296 297 284 306 293 313 303 270 281 285 288 300 284 282 285 283 301 291 298 288 299 242 288 250 312 278 270 270 308 303 283 295 293 304 278 281 288 305 289 288 292 283 297 268 275 322 295 282 298 259 282 264 276 276 256 270 249 292 268 273 276 280 258 259 229 264 275 305 270 286 256 268 276 261 304 285 259 243 291 292 256 297 300 286 325 282 310 263 244 261 302 280 264 292 288 272 230 284 290 243 264 282 240 260 282 266 291 273 304 250 279 260 266 281 261 239 307 281 302 273 284 299 235 291 295 261 280 273 259 313 286 288 258 241 294 249 295 314 305 259 290 300 270 277 271 260 269 269 263 237 287 284 289 275 282 270 230 280 298 306 287 272 321 300 276 319 286 286 301 262 247 229 263 270 274 302 258 296 281 260 259 262 250 280 293 305 246 274 265 255 313 280 285 265 266 263 285 278 247 276 292 306 298 268 274 276 297 299 291 265 284 265 284 250 269 303 283 287 292 285 264 268 270 282 282 286 256 276 315 272 279 267 266 290 290 293 280 244 279 272 270 242 292 309 265 274 259 267 296 293 231 287 287 278 291 306 283 261 248 259 285 280 247 289 240 256 268 296 298 311 261 247 270 319 276 269 266 275 271 244 287 301 292 270 275 258 284 282 303 302 267 264 282 280 301 272 286 279 286 285 245 296 275 290 286 267 276 277 244 255 277 301 269 258 291 275 276 250 271 241 279 282 272 257 260 285 280 275 286 285 227 262 275 300 297 248 258 286 274 277 275 282 267 287 256 241 274 296 266 280 278 273 302 267 312 288 273 276 289 256 238 288 295 243 270 288 261 273 299 278 279 270 279 280 241 267 275 264 270 260 295 240 294 277 306 269 289 270 270 296 294 269 282 268 283 292 287 287 262 306 270 267 281 263 245 259 276 275 280 279 288 296 280 262 299 283 303 280 276 265 282 275 287 281 263 256 308 274 283 284 270 298 281 270 286 267 284 286 270 255 265 280 276 283 260 246 267 303 240 265 262 300 278 269 285 287 287 282 285 282 263 285 299 292 284 295 300 260 283 291 292 283 297 276 280 256 317 242 299 278 309 289 275 259 265 263 306 301 284 289 294 262 278 276 278 300 276 284 260 295 289 255 294 311 277 295 288 286 304 288 246 270 273 278 286 266 289 296 297 323 259 295 290 273 287 261 287 307 261 294 288 298 243 278 282 272 236 247 266 242 257 275 312 228 279 298 278 282 284 282 295 268 290 261 270 287 288 266 267 299 303 276 267 294 269 256 299 268 275 244 298 265 270 278 266 260 284 288 295 284 316 302 283 270 269 266 274 279 299 293 274 274 298 305 270 287 260 287 271 276 312 285 286 307 308 270 249 304 259 285 283 292 275 280 290 310 299 276 300 243 295 281 300 278 266 274 257 268 280 302 259 292 268 274 306 284 275 280 264 281 298 257 268 266 289 285 298 262 273 261 230 286 264 263 278 308 280 312 299 268 278 261 283 240 295 284 286 274 288 291 268 247 238 261 275 282 259 279 299 262 293 266 313 290 277 267 308 256 273 267 265 277 288 290 265 290 272 293 285 268 266 263 285 259 272 263 261 288 282 285 309 287 284 291 273 277 265 263 288 302 276 245 266 292 277 290 283 296 288 302 285 278 275 272 277 285 279 269 286 291 237 268 275 301 270 269 285 294 286 249 284 289 268 303 316 294 293 275 303 270 260 300 311 301 300 263 295 283 273 259 261 276 307 284 289 272 261 274 293 302 273 250 272 268 247 292 241 276 271 299 297 294 275 292 278 319 298 275 267 289 273 287 302 305 287 262 264 260 273 277 286 273 232 289 291 292 236 268 285 241 274 269 277 273 263 289 266 265 304 270 287 286 285 283 290 271 285 238 270 295 243 264 302 279 286 283 279 294 284 292 280 277 283 299 271 288 272 305 278 271 259 292 263 272 279 298 234 310 274 248 267 285 258 291 283 278 288 317 306 302 304 269 307 286 257 261 268 255 271 271 259 270 269 282 273 289 282 276 272 274 242 309 282 246 293 284 275 266 257 302 264 265 248 259 303 281 282 248 286 291 280 263 270 289 256 289 259 287 275 277 286 291 275 290 275 295 295 242 239 287 258 294 259 262 244 280 292 289 280 292 278 309 280 289 294 262 287 278 290 255 322 261 263 269 272 279 267 264 283 275 261 291 273 293 262 279 289 278 273 290 274 272 287 263 258 249 298 285 272 280 285 265 309 279 275 269 271 279 286 261 283 261 276 286 247 279 265 269 271 299 276 300 280 316 279 263 291 289 275 249 291 278 292 256 284 290 262 292 296 286 287 278 238 282 289 273 259 304 291 288 287 271 255 307 272 255 295 299 282 255 281 257 288 269 284 310 248 259 262 282 259 287 294 266 260 316 273 268 292 285 260 273 267 278 280 276 292 290 261 259 264 258 238 273 306 283 283 276 277 282 224 279 299 247 275 293 264 257 275 276 280 275 264 267 292 270 270 294 268 268 295 301 255 280 280 293 258 283 277 270 264 248 300 269 286 291 282 281 289 278 268 284 308 293 285 235 286 257 280 275 274 266 278 278 285 304 273 288 268 281 302 271 282 291 273 288 255 281 247 294 292 266 276 299 262 271 263 282 304 293 284 262 270 313 292 262 273 286 271 278 285 267 279 283 276 271 263 275 305 284 301 281 257 267 294 275 288 283 276 283 304 298 312 246 271 255 309 276 255 293 264 297 293 263 293 267 284 308 274 298 307 269 290 275 303 285 292 296 294 284 291 281 290 297 289 270 287 279 279 294 273 276 291 296 310 298 278 300 309 319 281 295 317 298 301 303 331 333 346 322 311 314 319 325 348 383 361 357 376 355 378 355 369 417 397 393 400 364 383 380 395 402 394 356 346 357 325 355 375 328 355 327 379 370 345 369 334 351 371 358 343 332 372 331 331 310 326 348 316 308 302 307 306 308 311 305 311 299 314 295 286 298 297 306 319 275 298 268 263 266 273 293 269 274 296 284 279 314 242 301 315 280 292 309 246 265 295 279 273 284 295 296 285 258 263 306 278 298 282 280 300 291 267 270 285 270 264 259 287 272 272 294 278 312 281 283 312 288 245 297 259 294 241 290 300 299 273 267 280 273 256 256 279 267 297 240 282 272 274 262 303 281 260 310 284 304 310 277 287 243 280 293 275 310 248 278 260 282 270 285 306 262 295 257 265 273 250 260 308 304 279 284 293 276 287 299 278 301 260 290 241 281 305 286 248 240 276 261 304 293 269 279 278 260 268 284 259 308 293 262 277 227 249 277 262 298 282 300 295 257 258 281 275 268 285 275 266 275 291 303 293 291 273 245 279 260 268 289 289 273 248 284 296 282 286 263 280 270 305 297 275 238 281 277 288 281 264 278 272 298 312 277 289 281 289 281 233 268 300 284 246 280 292 287 296 278 259 292 267 306 284 279 247 260 278 289 256 309 288 287 288 248 278 283 314 280 268 280 279 246 296 278 290 290 293 298 265 260 273 294 292 291 272 265 276 282 274 274 277 292 261 269 272 319 289 294 297 246 291 298 234 269 288 255 285 280 275 314 302 304 270 279 250 267 297 286 267 275 276 280 274 259 283 277 299 283 260 244 291 291 272 285 255 279 262 246 284 312 250 303 286 291 286 285 256 250 279 294 282 294 244 267 290 276 327 299 321 283 301 311 295 308 292 256 277 287 278 298 232 286 274 297 285 298 303 281 262 266 238 268 281 291 287 281 293 245 264 300 272 313 274 303 299 302 301 309 266 300 312 289 331 277 288 282 343 294 294 297 325 353 323 325 368 321 339 334 335 325 361 354 333 357 301 324 327 318 301 302 324 281 310 306 313 316 327 324 330 328 315 327 311 330 337 301 341 318 325 321 305 320 336 328 322 319 312 342 323 340 323 313 312 323 337 320 315 325 319 347 339 286 332 346 315 320 327 306 332 329 310 315 345 335 338 307 331 285 302 280 343 294 326 315 277 326 316 306 290 318 321 284 326 311 315 298 274 317 276 285 268 297 275 270 321 295 268 313 273 291 318 310 297 303 300 258 303 270 311 271 295 264 303 274 266 307 299 280 303 325 295 276 299 294 277 324 297 308 281 286 277 285 285 288 269 259 292 298 286 286 292 292 271 311 295 270 246 297 257 280 280 264 274 240 245 276 276 256 277 290 238 273 305 249 271 283 301 311 276 266 265 283 297 293 271 270 293 247 289 293 267 298 275 284 285 269 269 258 247 280 273 273 264 277 263 266 283 258 270 279 292 271 265 280 266 299 288 271 308 277 255 264 235 275 234 270 288 279 281 283 267 277 287 302 302 285 273 306 275 282 298 294 256 283 299 294 268 273 283 287 271 278 296 260 270 257 293 285 272 287 257 272 288 264 260 247 286 266 273 280 238 255 242 274 282 288 266 286 287 305 297 282 269 293 287 300 257 269 313 262 249 285 297 275 263 259 296 271 271 272 273 259 272 255 271 271 287 273 266 293 277 267 275 271 295 286 300 279 302 284 255 275 269 279 267 261 262 267 289 283 264 276 264 237 298 282 271 256 280 320 290 281 297 275 283 292 286 296 273 234 273 285 261 291 245 280 297 282 279 286 280 310 273 298 284 291 298 299 283 267 287 271 282 287 318 248 278 263 244 256 287 285 268 257 247 299 271 279 284 299 257 285 266 292 290 303 260 292 269 284 270 263 249 291 288 288 238 278 266 269 286 297 275 265 230 279 260 261 257 297 285 274 260 297 275 297 266 281 267 278 269 269 299 308 260 293 278 313 290 249 275 270 268 284 267 301 255 266 268 247 296 274 261 280 271 260 290 285 290 257 278 263 277 286 275 291 264 290 260 261 272 261 280 248 272 277 291 228 291 241 243 285 269 257 263 269 309 264 292 293 279 289 270 274 286 248 280 297 245 274 277 274 255 315 279 249 289 286 296 262 278 293 273 291 309 284 288 257 274 272 289 288 295 270 291 247 243 267 268 243 284 272 312 333 288 271 266 283 290 283 284 291 274 275 283 289 300 274 263 275 280 284 274 274 287 271 282 274 308 276 288 261 272 246 243 277 274 272 296 259 274 286 273 258 263 257 242 262 269 269 275 239 290 260 277 271 280 246 239 268 284 288 273 256 286 259 269 275 265 278 279 320 264 279 266 306 294 278 257 284 313 269 276 334 273 284 264 292 279 281 273 261 256 266 262 275 278 279 268 272 281 273 269 272 270 262 293 274 284 249 277 263 271 281 276 288 258 272 245 272 275 267 272 285 288 257 274 291 278 242 284 274 218 284 289 265 276 292 273 271 291 237 266 257 263 262 285 282 295 269 274 293 285 273 293 256 296 267 294 272 272 293 280 277 271 281 272 282 259 244 266 295 271 290 267 294 281 283 308 255 249 299 312 243 286 284 290 284 306 294 263 310 243 261 258 285 267 264 263 293 287 303 267 268 299 276 287 278 234 279 280 291 248 277 275 272 260 279 256 297 281 295 270 267 267 256 277 272 305 278 256 290 266 288 273 270 283 267 286 284 281 273 288 259 281 290 265 277 267 270 261 307 285 280 268 284 282 273 284 264 276 296 324 269 284 269 286 277 281 256 280 268 246 277 261 293 284 270 268 264 275 283 267 281 283 275 291 245 256 268 276 274 308 271 283 273 288 292 279 271 304 264 256 288 264 257 243 296 281 275 245 260 274 291 272 264 247 294 296 239 299 263 273 282 288 299 275 308 291 287 273 283 302 260 248 287 268 265 268 270 265 274 291 274 269 266 249 278 264 267 270 266 278 298 276 240 290 292 277 288 282 265 261 275 298 268 298 260 286 262 268 262 274 298 284 302 260 260 292 244 268 258 287 256 265 261 280 303 317 284 278 285 265 280 270 239 289 299 243 274 280 294 291 295 270 274 292 272 275 287 296 271 258 293 294 271 273 288 258 266 283 304 271 319 279 299 268 281 302 295 292 246 247 278 284 262 245 276 273 269 256 275 275 281 256 310 265 258 309 264 312 260 296 276 273 283 283 255 278 293 261 269 257 269 241 255 266 281 268 257 267 278 278 267 256 244 248 270 293 283 274 288 297 271 266 266 299 277 292 249 276 296 315 279 255 269 267 307 290 268 314 305 245 259 249 278 283 271 274 286 258 307 285 311 259 299 268 264 273 232 282 281 284 281 256 270 281 288 286 260 278 301 283 277 264 261 248 273 281 293 280 262 257 298 284 255 278 295 279 266 242 287 256 271 292 275 265 281 292 268 268 317 305 294 279 255 258 279 274 300 283 304 248 257 299 241 262 265 256 284 262 249 249 244 271 279 249 302 274 256 295 255 255 274 261 261 267 264 262 244 275 258 264 279 284 289 293 288 317 285 281 282 262 246 267 281 262 264 295 257 274 309 259 305 271 255 290 270 270 271 233 275 278 280 264 265 265 259 290 260 246 264 243 273 259 248 283 289 277 288 234 260 270 287 294 283 265 301 264 300 285 285 247 275 273 291 273 258 260 266 272 279 290 269 272 262 234 279 289 261 268 276 291 275 266 275 296 270 262 279 257 274 260 271 315 283 301 283 257 249 259 259 240 280 291 261 273 243 266 269 282 265 236 282 271 273 262 249 311 260 250 272 272 279 259 279 268 295 279 283 281 260 244 281 274 265 258 264 261 282 292 274 245 273 260 246 255 272 289 269 269 270 257 263 296 236 243 289 260 273 261 245 284 260 256 267 268 263 265 273 245 292 293 268 246 274 262 290 249 287 257 248 291 273 284 270 265 257 250 284 302 279 295 247 273 285 221 281 285 298 267 287 250 274 294 272 274 237 273 277 298 255 278 290 270 278 262 237 261 257 275 263 288 272 269 276 240 271 268 288 272 249 282 271 299 277 267 249 282 232 284 263 270 296 275 273 260 249 238 259 294 220 284 259 272 279 282 260 260 280 255 278 276 255 263 263 279 258 261 256 284 284 283 267 275 269 276 269 262 275 266 280 231 247 278 248 278 275 268 296 274 240 264 249 238 273 268 281 277 229 280 255 269 267 242 267 294 290 238 268 286 286 244 249 273 255 267 242 286 289 297 264 248 263 299 279 241 300 281 287 284 258 281 300 275 264 235 291 239 282 300 262 285 272 278 292 259 292 259 284 272 282 264 270 266 283 245 288 283 248 281 263 297 317 258 279 297 273 257 276 274 285 280 315 236 272 282 287 274 261 269 278 285 255 275 286 238 263 292 257 297 258 290 260 222 273 270 269 301 246 262 275 277 308 286 270 301 284 264 255 315 291 282 257 277 270 286 292 291 288 266 262 268 256 290 272 277 238 238 266 238 259 271 274 286 266 268 286 289 261 284 297 278 293 267 271 299 276 298 324 264 270 292 269 291 262 273 285 265 263 279 285 290 249 259 256 285 261 285 304 261 287 279 296 255 261 285 284 279 290 295 286 269 267 256 272 282 277 330 288 271 288 283 274 290 290 296 279 276 305 256 271 277 286 286 261 262 296 261 297 235 279 286 297 273 234 257 290 292 273 290 302 277 274 268 268 300 286 307 289 293 286 291 318 289 284 303 340 314 264 276 296 298 320 314 311 280 278 302 298 279 307 278 265 282 264 272 282 277 279 286 311 290 276 296 286 321 294 321 261 330 279 272 288 287 270 300 266 331 278 306 296 280 283 272 295 300 290 310 302 242 275 293 289 300 277 286 308 288 300 289 290 297 297 287 269 282 284 293 287 307 285 280 301 305 324 300 302 316 325 314 332 296 278 276 271 287 291 294 266 309 286 298 298 271 297 291 310 312 290 259 302 299 289 280 276 280 299 298 279 301 286 293 305 279 276 287 296 297 296 319 281 288 298 314 303 277 297 279 281 281 309 245 303 280 283 260 309 268 271 309 288 264 280 283 283 287 278 285 269 271 291 279 293 244 284 283 277 239 305 275 275 270 316 265 286 309 269 263 266 291 294 323 302 282 269 286 292 292 289 290 291 317 280 286 318 268 304 293 292 246 279 314 282 289 273 245 291 274 266 302 295 293 296 310 297 279 273 311 294 305 278 281 305 287 302 283 299 260 260 280 274 265 280 272 290 275 276 292 272 266 270 282 287 263 260 291 292 274 265 272 294 285 328 281 284 261 302 282 320 275 291 293 312 318 264 308 300 281 282 306 272 279 265 312 291 265 285 265 317 270 282 287 277 268 275 302 239 266 303 234 276 248 264 309 290 265 272 300 288 316 301 302 279 304 303 306 260 287 287 265 272 289 247 236 314 277 315 280 284 289 291 265 262 266 275 272 261 266 303 297 278 259 283 277 298 279 302 298 287 241 280 297 271 288 298 268 260 268 288 298 268 278 297 270 312 283 268 281 264 280 294 277 289 262 261 305 281 266 264 256 267 266 256 255 291 271 268 277 260 290 232 285 296 260 246 276 290 277 280 285 278 287 275 259 274 262 281 247 281 299 249 238 278 263 269 298 288 297 312 263 286 301 261 257 281 292 263 265 285 247 289 287 278 284 277 309 278 267 267 265 284 295 273 286 280 270 291 276 280 256 273 278 269 270 289 281 271 305 292 265 267 272 291 265 281 258 268 291 261 248 269 247 287 295 279 259 308 274 279 249 244 237 238 293 280 281 288 259 273 266 301 266 280 266 266 300 302 299 290 271 276 285 281 246 342 275 279 294 281 304 278 274 240 276 273 247 265 308 236 271 288 279 257 263 290 297 289 271 284 278 290 275 291 297 275 290 257 270 280 274 265 258 306 262 278 266 288 298 291 278 274 303 274 283 281 280 280 277 292 276 261 275 271 241 283 283 312 282 281 319 270 269 292 240 288 319 247 273 262 284 265 258 313 294 272 287 285 280 284 248 283 285 302 268 286 275 277 277 286 242 299 288 286 277 314 262 262 278 284 283 282 298 269 280 323 303 283 330 307 296 243 297 281 300 296 287 281 258 292 267 287 281 282 261 301 287 293 271 280 317 296 271 265 274 290 319 266 245 308 289 275 287 282 273 293 301 283 268 283 270 263 277 281 312 285 268 295 278 298 295 271 275 304 263 259 308 245 249 304 296 298 271 280 287 281 295 270 271 283 274 278 281 288 295 294 277 293 291 330 256 284 303 275 319 314 302 270 289 302 276 292 275 267 274 278 279 308 297 297 273 276 298 282 293 262 257 292 305 282 305 309 264 302 264 297 246 260 277 281 274 260 276 257 250 278 263 268 284 270 285 294 312 307 293 295 265 255 302 271 283 302 296 274 295 280 296 261 290 293 294 285 273 318 287 274 298 298 292 301 290 289 286 280 286 339 307 305 267 308 270 292 266 271 274 273 314 300 264 315 273 296 272 284 276 300 267 281 281 283 291 290 247 281 288 312 303 255 271 272 286 261 262 282 281 283 233 296 296 296 281 280 266 248 232 269 267 296 270 263 287 264 265 281 303 283 263 266 285 287 260 297 291 320 320 303 294 312 301 283 288 271 271 292 263 296 274 278 264 281 282 290 289 309 281 316 322 300 264 295 307 272 274 284 279 280 280 315 314 291 288 289 292 276 276 263 311 319 308 244 258 305 277 299 273 314 276 260 281 314 280 285 299 301 285 291 330 286 281 285 262 298 297 274 282 286 263 293 285 276 270 296 280 276 272 270 301 276 280 275 272 291 283 307 289 277 269 281 270 257 286 248 268 289 289 275 275 283 266 327 308 276 277 302 258 281 261 315 295 295 292 275 260 278 277 259 278 276 308 307 271 309 268 265 315 291 249 282 302 277 266 287 272 281 271 287 273 292 262 301 279 277 236 249 286 277 264 245 289 285 290 286 261 289 295 267 314 311 298 290 267 300 288 311 259 260 271 279 294 282 300 272 288 311 286 264 311 281 277 311 282 284 301 306 278 285 282 288 281 283 272 264 271 282 283 294 290 302 266 292 283 272 291 258 286 292 327 315 274 287 318 319 291 315 271 275 259 291 269 258 288 263 257 264 277 269 310 268 281 306 290 262 290 286 259 279 283 288 295 271 262 285 279 298 290 312 267 282 264 268 269 273 293 263 273 278 277 272 268 272 275 257 266 245 293 271 259 292 226 281 284 296 260 281 270 266 285 255 290 301 299 294 267 282 301 315 270 280 295 301 282 280 270 288 299 292 248 293 271 266 279 275 222 281 283 279 283 265 281 280 271 291 244 279 270 236 288 271 282 266 290 295 283 270 283 273 268 266 284 277 288 277 293 285 312 277 244 295 299 260 258 299 276 301 278 258 264 266 280 287 243 276 292 282 259 293 279 297 291 276 292 301 276 292 270 296 297 282 249 272 245 285 242 277 294 289 271 286 274 280 272 282 256 281 282 246 289 277 279 243 274 279 268 274 277 272 259 266 292 266 298 285 259 301 295 262 275 297 278 290 297 259 269 282 296 242 299 322 318 305 305 284 278 278 328 287 283 319 307 278 307 290 330 306 280 297 312 308 272 294 309 309 288 309 324 323 301 304 310 325 290 296 282 286 295 284 319 285 269 301 294 299 304 299 300 318 270 286 335 263 304 273 309 270 284 297 293 304 311 285 287 290 276 275 294 277 286 310 283 307 274 297 296 298 281 270 294 263 310 306 266 272 276 295 285 303 287 271 290 282 238 258 271 290 309 285 257 265 273 266 296 249 275 286 277 249 285 293 277 290 275 283 283 239 282 272 286 284 294 261 262 279 270 301 237 287 291 268 288 282 289 280 282 286 279 268 282 246 279 302 273 277 274 294 247 272 290 245 284 303 247 259 240 271 258 278 274 291 263 280 287 277 266 273 278 310 265 265 278 258 268 277 264 307 260 310 255 281 249 266 264 265 261 274 259 265 267 294 266 263 273 268 255 270 291 297 261 290 282 262 281 283 302 256 288 272 281 245 271 289 274 310 237 269 281 249 270 297 274 271 273 265 276 276 271 279 281 302 280 280 280 293 287 274 268 281 297 261 257 286 304 270 306 297 268 279 263 247 261 284 266 303 293 287 267 272 241 302 298 266 287 288 255 264 280 245 290 275 267 272 255 267 262 244 298 286 294 282 246 286 287 257 256 256 280 282 284 282 237 281 282 278 285 240 297 303 279 263 293 268 285 296 280 273 295 276 246 263 299 283 243 276 275 289 300 286 310 262 293 264 286 314 283 305 274 291 264 261 284 283 295 283 278 287 272 268 229 270 271 303 303 256 277 266 265 256 282 259 284 263 299 290 293 287 279 267 281 295 302 272 274 262 278 312 302 261 287 241 269 313 288 317 291 262 255 296 240 273 270 229 296 298 266 248 280 309 314 299 285 292 309 288 261 263 291 258 287 267 284 278 283 272 276 294 245 292 246 290 287 293 288 292 283 312 284 280 290 276 277 275 278 282 263 312 294 304 303 291 276 263 294 299 278 257 278 296 309 271 279 280 292 295 319 298 300 288 318 305 307 297 295 298 267 283 270 276 298 281 301 308 293 304 304 313 312 292 295 303 296 294 304 293 325 277 325 284 298 322 316 300 329 314 308 301 354 302 292 285 331 307 294 287 326 326 310 272 309 352 306 320 315 314 297 331 302 313 296 315 293 331 313 314 328 324 297 299 316 297 294 312 274 301 261 301 293 316 303 305 297 290 275 315 305 278 294 315 307 313 314 289 316 289 307 303 305 312 305 304 285 293 279 278 282 282 309 269 281 327 290 277 289 297 293 299 298 315 283 302 321 291 305 324 287 274 288 311 283 276 331 316 275 331 304 296 310 340 276 302 301 275 287 286 302 287 295 276 308 283 278 317 318 271 306 269 300 274 293 290 302 298 309 325 306 269 285 299 299 321 310 291 301 291 269 308 302 304 293 258 298 301 290 275 292 293 264 294 315 327 299 308 318 312 308 286 284 280 312 301 301 309 313 278 292 293 277 301 297 274 291 289 295 306 295 290 268 301 316 272 293 262 243 282 275 301 274 279 317 286 281 301 310 296 307 291 294 284 275 278 273 302 279 295 286 304 275 278 313 263 303 301 281 277 291 258 276 290 307 286 241 313 282 287 279 293 276 304 297 272 324 280 285 297 289 266 293 258 342 325 291 283 277 306 311 266 308 302 313 287 299 304 258 319 243 290 280 272 290 287 299 287 290 299 318 280 293 271 285 278 291 286 266 292 288 269 270 273 313 257 276 278 308 238 277 304 307 271 257 319 275 275 313 302 282 315 276 276 228 244 293 286 272 289 300 269 305 281 310 266 286 297 277 261 287 301 271 287 273 261 273 297 273 276 290 267 274 267 311 272 281 294 273 260 244 276 245 270 259 286 266 258 269 265 232 279 281 262 296 287 286 271 283 263 294 290 276 295 256 276 283 295 284 300 270 279 262 277 274 281 280 283 258 273 258 273 297 267 256 262 273 271 288 259 267 286 259 283 291 305 278 263 294 273 303 267 297 282 265 236 262 287 277 295 259 267 276 285 276 266 286 280 295 307 246 260 239 291 299 270 262 274 230 280 290 296 264 286 294 261 312 295 241 259 275 279 311 283 258 310 292 303 286 281 275 272 301 294 281 289 295 284 263 287 280 271 250 299 295 280 278 288 309 287 293 277 282 271 264 258 238 274 276 256 280 266 269 270 273 287 292 267 267 283 293 279 255 264 279 243 280 279 276 249 283 278 302 257 283 269 241 291 260 271 296 297 262 297 276 269 281 246 301 255 278 268 304 307 249 288 280 301 264 262 249 263 296 267 257 268 283 273 269 269 301 256 289 296 300 298 265 277 279 242 277 285 267 285 280 245 257 281 287 301 263 303 292 297 273 289 278 275 290 260 282 277 259 276 271 290 303 278 257 281 268 287 297 244 291 281 280 270 309 273 301 280 245 260 297 309 283 284 229 250 261 280 280 290 288 279 268 282 285 264 284 268 266 265 247 298 293 265 274 293 281 270 264 289 289 264 275 268 289 282 299 278 286 281 261 247 278 279 270 299 297 303 300 295 268 297 287 306 266 307 284 285 265 246 272 274 279 291 280 277 266 301 288 267 283 264 269 268 278 304 294 257 267 307 266 302 284 280 287 279 268 274 267 293 296 306 274 291 257 233 267 309 276 286 285 275 291 276 267 282 297 277 275 265 247 294 260 274 305 272 291 290 287 270 270 264 288 234 281 261 262 280 277 294 285 300 230 255 285 289 283 272 295 274 293 280 287 281 292 263 249 296 271 284 306 286 278 284 277 299 274 269 255 263 285 282 284 273 289 276 291 264 289 270 303 292 269 285 247 275 269 258 276 266 294 282 261 279 272 275 270 296 288 278 281 307 301 272 289 288 310 311 258 293 288 265 287 278 278 272 261 288 272 285 265 304 296 282 245 281 294 278 285 262 247 267 295 299 292 313 275 293 289 285 288 315 303 263 288 282 271 308 311 277 261 280 287 272 297 284 267 304 267 306 303 278 273 292 259 295 283 273 298 288 284 278 273 266 273 243 286 268 265 256 286 276 241 260 269 260 313 248 283 293 249 278 274 291 263 245 286 307 258 303 239 306 270 283 258 291 281 292 290 280 270 258 289 287 280 260 270 285 284 306 307 249 320 283 283 302 279 278 325 291 302 279 262 264 273 259 271 288 244 278 293 265 283 290 238 266 295 281 274 242 321 271 280 297 255 284 291 281 262 297 296 294 233 274 293 281 292 293 255 269 279 259 270 265 283 278 275 294 264 288 282 278 258 294 272 258 283 274 297 277 273 296 304 319 282 303 284 278 281 273 265 296 298 267 301 262 271 273 266 267 283 272 280 267 265 263 308 274 273 249 274 269 278 310 281 283 261 311 284 266 276 274 271 283 281 266 262 274 293 238 260 276 255 266 300 291 280 267 266 256 265 261 285 266 288 236 271 268 302 265 285 283 262 246 325 290 280 280 262 272 280 276 266 271 246 258 291 293 275 288 264 278 247 274 315 270 260 283 269 278 280 249 287 281 279 274 261 273 258 279 281 301 302 280 282 268 241 279 301 268 284 290 240 297 269 263 283 282 286 288 271 276 279 263 277 259 274 275 292 293 297 256 275 268 301 285 274 269 284 297 259 282 274 291 287 269 275 263 276 289 265 304 290 270 327 249 277 292 281 279 278 274 284 271 294 266 249 294 306 284 270 274 286 258 270 268 285 250 295 278 289 249 281 273 280 304 286 286 305 268 272 239 272 283 282 265 263 268 292 289 260 290 285 286 267 301 266 288 280 261 257 289 292 273 308 268 299 274 280 277 262 287 277 276 280 282 270 293 220 307 292 279 297 259 278 267 271 288 282 288 283 303 272 284 286 301 288 266 265 275 270 259 292 270 259 273 239 262 303 241 298 302 280 282 281 274 279 250 272 261 283 286 272 283 288 263 297 306 283 304 284 279 290 295 302 271 277 304 302 264 273 259 275 293 281 284 294 287 257 282 280 298 292 298 301 274 276 287 273 275 269 284 280 302 275 290 271 301 273 314 280 300 274 295 283 278 258 276 282 284 284 258 275 272 289 288 275 278 298 296 281 281 256 259 257 260 286 292 312 258 288 293 288 286 268 274 283 286 324 289 270 275 272 282 269 294 326 293 301 279 294 258 274 260 263 277 255 288 276 281 284 291 300 286 259 279 278 264 285 310 283 259 262 266 272 265 284 292 285 296 288 277 281 275 268 287 318 279 323 316 286 286 296 285 269 246 276 287 259 250 258 282 296 297 248 292 278 279 269 272 281 246 281 280 278 327 284 288 275 278 273 276 263 278 273 304 228 283 276 293 284 291 271 278 225 267 294 283 280 282 281 273 308 288 286 247 267 285 294 315 283 292 288 299 278 280 302 286 257 298 269 281 287 302 256 258 316 293 312 294 293 312 259 287 274 297 267 277 291 316 248 284 328 280 300 284 290 258 295 284 288 271 291 302 246 286 271 298 312 287 257 257 272 268 278 317 287 269 271 261 248 287 312 281 260 278 297</counts>
			</dataPoints>
		</scan>
	</xrdMeasurement>
</xrdMeasurements>