File: data/XRD/XG-Vakuum/XG-750/W6822-1C_XG_Vakuum_750.xrdml
<xrdMeasurements xmlns="http://www.xrdml.com/XRDMeasurement/2.1" xmlns:xsi="http://www.w3.org/2001/XMLSchema-instance" xsi:schemaLocation="http://www.xrdml.com/XRDMeasurement/2.1 http://www.xrdml.com/XRDMeasurement/2.1/XRDMeasurement.xsd" status="Completed">
	<comment>
		<entry>Configuration=Factory configuration, Owner=User-1, Creation date=7/8/2013 4:01:53 PM</entry>
		<entry>Goniometer=PW3050/65 (Theta/2Theta); Minimum step size 2Theta:0.0001; Minimum step size Omega:0.0001</entry>
		<entry>Sample stage=MRD Cradle; Minimum step size Phi:0.01; Minimum step size Chi:0.01; Minimum step size X:0.01; Minimum step size Y:0.01; Minimum step size Z:0.001</entry>
		<entry>Diffractometer system=XPERT-PRO</entry>
		<entry>Measurement program=C:\PANalytical\Data Collector\Programs\Jorrit\2thom\_absolute_2th-om_10-130deg_PIXscan_56min.xrdmp, Identifier={15BCCF57-2807-42BD-B5B9-ECC0B3DC9284}</entry>
		<entry>Batch program=C:\PANalytical\Data Collector\Programs\SimonL\batch6x_2thom_10-130°_z9.1_x0,10,20,30_y20,40_57min - Kopie.xrdmp, Identifier={6B3EF4D3-441D-47FD-9EA5-077D311040EA}</entry>
	</comment>
	<sample type="To be analyzed">
		<id></id>
		<name></name>
		<preparedBy></preparedBy>
	</sample>
	<xrdMeasurement measurementType="Scan" status="Completed" sampleMode="Reflection">
		<comment>
			<entry>_absolute_2th-om_10-130deg_PIXscan_56min</entry>
			<entry>PHD Lower Level = 4.83 (keV), PHD Upper Level = 11.27 (keV)</entry>
		</comment>
		<usedWavelength intended="K-Alpha 1">
			<kAlpha1 unit="Angstrom">1.5405980</kAlpha1>
			<kAlpha2 unit="Angstrom">1.5444260</kAlpha2>
			<kBeta unit="Angstrom">1.3922500</kBeta>
			<ratioKAlpha2KAlpha1>0.5000</ratioKAlpha2KAlpha1>
		</usedWavelength>
		<incidentBeamPath>
			<radius unit="mm">320.00</radius>
			<xRayTube id="1010048" name="Empyrean Cu LFF HR (9430 033 7310x) DK442154">
				<tension unit="kV">40.0</tension>
				<current unit="mA">40.0</current>
				<anodeMaterial>Cu</anodeMaterial>
				<focus type="Line">
					<length unit="mm">12.0</length>
					<width unit="mm">0.4</width>
					<takeOffAngle unit="deg">4.2</takeOffAngle>
				</focus>
			</xRayTube>
			<xRayMirror id="27010001" name="Inc. Beam Cu W/Si (parabolic MRD)" hybrid="false">
				<crystal type="Graded" shape="Parabolic">W/Si</crystal>
				<acceptanceAngle unit="deg">0.800</acceptanceAngle>
				<length unit="mm">60.0</length>
			</xRayMirror>
			<sollerSlit id="21010002" name="Soller slits 0.04 rad.">
				<opening unit="rad">0.0400</opening>
			</sollerSlit>
			<mask id="22030008" name="Fixed mask 4 mm">
				<distanceToSample unit="mm">220.00</distanceToSample>
				<width unit="mm">4.00</width>
			</mask>
			<divergenceSlit id="22010011" name="Fixed slit 1/32°" xsi:type="fixedDivergenceSlitType">
				<distanceToSample unit="mm">220.00</distanceToSample>
				<height unit="mm">0.05</height>
			</divergenceSlit>
		</incidentBeamPath>
		<diffractedBeamPath>
			<radius unit="mm">320.00</radius>
			<sollerSlit id="21010002" name="Soller slits 0.04 rad.">
				<opening unit="rad">0.0400</opening>
			</sollerSlit>
			<receivingSlit id="22010001" name="Fixed slit 4°">
				<height unit="mm">5.88</height>
			</receivingSlit>
			<detector id="7010017" name="PIXcel3D 1x1 detector" xsi:type="areaDetectorType">
				<phd unit="%">
					<lowerLevel>30.0</lowerLevel>
					<upperLevel>70.0</upperLevel>
				</phd>
				<mode>Scanning</mode>
				<activeChannelsEquatorial>255</activeChannelsEquatorial>
				<activeChannelsAxial>255</activeChannelsAxial>
				<pitchEquatorial unit="mm">0.05500</pitchEquatorial>
				<pitchAxial unit="mm">0.05500</pitchAxial>
				<readOutPeriod unit="seconds">0.135</readOutPeriod>
			</detector>
		</diffractedBeamPath>
		<scan appendNumber="0" mode="Continuous" scanAxis="2Theta-Omega" status="Completed">
			<header>
				<startTimeStamp>2024-10-11T17:22:13+02:00</startTimeStamp>
				<endTimeStamp>2024-10-11T18:18:19+02:00</endTimeStamp>
				<author>
					<name>PRO-MRD</name>
				</author>
				<source>
					<applicationSoftware version="6.1b">Data Collector</applicationSoftware>
					<instrumentControlSoftware version="7.0E 20130304">XPERT-PRO</instrumentControlSoftware>
					<instrumentID>0000000011142674</instrumentID>
				</source>
			</header>
			<dataPoints>
				<positions axis="2Theta" unit="deg">
					<startPosition>9.99826193</startPosition>
					<endPosition>129.99755682</endPosition>
				</positions>
				<positions axis="Omega" unit="deg">
					<startPosition>4.99913096</startPosition>
					<endPosition>64.99877841</endPosition>
				</positions>
				<positions axis="Phi" unit="deg">
					<commonPosition>0.00</commonPosition>
				</positions>
				<positions axis="Chi" unit="deg">
					<commonPosition>0.00</commonPosition>
				</positions>
				<positions axis="X" unit="mm">
					<commonPosition>10.00</commonPosition>
				</positions>
				<positions axis="Y" unit="mm">
					<commonPosition>0.00</commonPosition>
				</positions>
				<positions axis="Z" unit="mm">
					<commonPosition>9.100</commonPosition>
				</positions>
				<commonCountingTime unit="seconds">32.895</commonCountingTime>
				<counts 420 403 420 440 432 417 439 410 451 441 416 431 416 390 426 454 428 450 440 438 448 430 465 399 426 414 408 430 435 462 464 448 399 425 433 422 470 447 419 407 445 434 458 451 478 432 439 449 430 459 457 470 462 445 439 455 468 493 411 447 414 414 432 452 444 413 472 447 444 410 430 422 436 416 414 483 457 444 428 431 417 430 454 420 363 416 417 407 433 417 390 393 436 400 408 433 412 428 410 405 424 426 430 365 439 413 394 423 400 409 424 406 421 421 425 413 372 402 407 407 431 427 435 417 438 419 430 409 412 422 381 405 404 460 420 425 399 416 433 421 402 402 365 411 411 395 408 389 419 408 419 404 407 371 381 352 375 407 394 400 396 403 413 396 412 375 433 442 421 439 390 416 373 387 396 374 377 342 383 415 388 405 391 407 398 397 394 388 386 374 365 401 399 393 393 416 404 377 428 366 443 382 426 369 379 382 384 369 422 387 404 383 395 397 383 375 374 411 378 381 378 365 369 417 406 365 390 399 372 376 389 392 392 386 387 418 377 365 363 377 383 397 377 350 411 372 381 399 390 373 380 352 398 372 409 361 363 379 372 351 399 395 412 392 375 367 394 376 383 414 384 379 374 350 398 408 387 383 362 396 352 368 379 380 379 337 361 363 359 358 375 362 347 345 389 384 346 393 353 370 380 390 384 387 357 377 380 340 375 349 366 385 366 372 386 383 386 377 361 349 341 384 368 369 371 365 389 375 388 378 373 407 346 367 377 375 308 317 356 384 373 382 362 396 377 357 335 334 349 386 338 362 377 348 381 348 344 344 348 354 354 362 367 351 360 353 375 336 360 356 333 343 362 360 381 356 370 346 374 330 355 371 378 349 357 319 338 352 357 343 348 398 351 340 334 357 350 366 392 329 350 383 356 333 321 367 325 408 385 333 355 313 359 350 346 356 362 353 363 346 377 383 368 355 356 320 333 356 327 324 349 319 364 339 345 354 308 328 338 351 356 334 339 341 314 369 332 343 357 333 328 341 316 347 350 320 316 366 354 351 349 327 363 357 333 328 319 342 388 354 388 359 332 365 344 319 333 375 383 335 334 328 343 341 317 317 347 346 337 350 376 328 329 320 345 354 343 315 298 358 334 366 361 315 344 339 345 320 317 328 309 360 307 365 334 328 319 341 335 377 336 336 317 353 334 328 308 370 332 358 326 351 327 314 304 353 343 305 319 351 352 375 359 339 351 329 312 333 349 345 362 328 326 334 296 349 306 328 318 335 328 289 358 357 340 346 330 351 296 347 321 346 328 321 341 323 307 322 334 324 334 296 327 326 309 331 350 329 319 323 314 307 344 344 322 290 325 313 364 322 313 317 345 336 330 341 334 339 316 346 316 330 309 339 306 346 339 305 342 321 324 306 351 344 338 310 329 316 292 338 328 275 347 331 329 339 320 307 310 315 311 324 308 317 332 303 308 288 327 333 321 317 319 298 312 325 300 315 324 310 313 343 344 306 339 328 309 325 330 292 266 341 300 312 339 317 350 302 320 335 342 305 320 301 350 312 335 346 333 337 325 316 312 339 283 312 327 311 319 320 293 313 331 299 357 305 330 312 299 327 279 319 297 296 343 318 303 332 330 313 336 290 293 321 320 284 303 312 332 346 325 308 317 330 333 305 313 331 309 291 325 285 316 302 326 317 317 277 315 340 330 292 303 334 307 292 315 295 310 332 309 354 325 323 298 333 292 313 345 346 279 316 339 339 317 342 322 317 324 292 294 338 317 329 333 339 306 336 291 340 285 332 304 315 321 319 337 315 328 308 311 313 333 332 318 340 316 317 325 284 334 317 343 341 294 324 320 298 349 327 353 322 329 306 304 335 335 344 335 317 348 286 323 326 312 305 311 345 335 318 295 318 316 305 315 326 321 319 350 322 313 304 285 331 313 348 320 319 310 338 336 334 336 333 326 330 315 304 305 328 289 285 286 290 294 325 309 314 331 377 316 345 318 317 315 352 306 314 317 296 318 309 352 299 327 316 340 343 296 312 360 306 336 319 303 334 315 350 304 340 303 333 331 343 307 330 352 338 339 298 313 323 327 284 311 331 335 305 311 354 307 302 342 326 339 315 310 330 312 338 350 318 322 361 335 349 346 320 325 317 315 356 320 309 329 311 328 346 311 331 341 327 353 317 325 346 351 326 327 331 326 324 316 306 296 301 316 316 302 314 320 334 329 328 302 356 341 339 323 321 314 312 317 291 308 291 342 336 315 325 340 297 311 323 335 313 296 353 320 327 314 304 330 325 346 311 311 338 318 324 344 330 333 340 341 335 315 337 346 359 323 346 334 339 327 326 367 341 360 331 360 311 321 338 331 310 325 355 351 325 343 347 336 339 333 327 364 323 305 319 329 312 325 316 333 363 357 347 298 345 313 325 331 335 311 347 338 354 328 324 310 339 301 333 340 326 339 352 317 318 336 295 350 327 300 356 373 356 294 353 335 320 354 327 322 302 359 339 326 337 318 303 333 360 356 323 339 325 352 343 357 331 324 339 326 349 326 323 356 327 297 356 324 319 330 337 350 312 337 299 350 327 322 367 321 321 334 326 310 321 317 337 337 335 354 333 339 336 325 314 351 333 341 353 342 344 320 343 351 324 308 312 335 344 297 333 349 327 344 312 346 335 334 380 351 280 349 304 345 331 348 347 335 333 342 306 355 304 320 359 359 342 317 340 330 358 344 343 318 329 346 340 368 341 313 355 318 335 339 350 331 354 357 336 302 366 348 345 314 316 315 348 332 370 362 330 320 348 337 349 327 319 323 325 340 333 324 314 342 351 332 359 336 350 330 305 325 315 313 359 320 309 313 328 306 338 337 308 330 318 330 312 281 313 351 344 339 303 350 346 338 324 306 335 355 341 352 332 334 378 341 353 312 345 347 314 365 323 350 341 321 365 336 311 324 334 330 324 349 303 310 331 347 299 350 331 306 316 355 329 327 302 337 297 313 346 329 307 344 307 384 363 301 332 314 315 306 351 376 320 358 344 341 353 311 340 346 346 348 336 312 312 338 330 343 320 313 340 355 322 296 320 308 348 309 304 383 315 355 321 311 342 326 334 314 311 319 319 303 327 295 286 333 304 356 293 327 342 339 334 333 330 334 340 305 302 326 323 329 320 324 296 356 340 329 323 290 319 331 366 314 293 317 322 320 350 338 321 308 318 311 311 314 314 314 326 325 300 312 320 337 316 333 335 309 338 299 309 299 363 282 327 319 278 308 357 339 323 302 322 294 338 325 365 315 294 361 338 334 331 321 283 324 331 325 293 316 329 327 307 319 324 321 292 318 321 324 336 347 289 341 334 365 310 332 311 332 295 305 308 321 327 312 312 328 328 351 297 314 318 322 325 317 331 343 321 302 313 320 296 294 322 337 286 322 353 351 327 314 290 295 321 323 366 325 307 321 330 341 305 308 318 315 294 321 339 304 302 307 291 314 301 306 319 334 314 309 282 297 327 323 321 304 299 305 306 338 312 300 283 313 279 302 314 312 308 324 325 323 310 274 306 311 270 299 272 284 319 327 328 298 259 337 289 307 287 299 301 280 305 314 304 274 303 284 308 302 280 298 321 310 307 286 290 277 288 320 309 308 334 301 303 324 316 301 300 300 326 265 286 306 364 326 289 312 293 306 318 290 280 285 283 262 298 319 328 295 312 278 311 286 309 297 281 275 301 275 278 280 298 259 280 292 261 350 298 283 300 281 316 272 302 265 308 313 293 321 298 295 312 330 286 298 296 280 309 301 284 311 279 341 300 319 282 314 302 316 293 279 297 323 288 291 306 308 299 306 306 267 286 292 277 285 285 298 282 270 310 301 291 262 278 262 300 310 283 272 311 277 284 265 267 287 283 281 286 272 308 293 292 296 278 299 271 287 287 278 279 288 307 279 258 267 306 303 280 317 260 272 292 285 269 291 278 280 257 279 315 250 293 294 272 281 282 306 291 297 310 286 287 286 262 309 294 276 277 242 275 292 292 262 266 271 278 265 281 306 294 262 283 273 277 287 286 289 269 288 301 258 281 281 273 265 270 267 310 295 284 293 259 295 289 282 317 290 318 281 318 249 279 271 289 274 305 293 261 270 281 238 273 286 288 308 276 269 299 273 275 283 272 257 248 246 280 272 272 286 306 278 289 265 274 300 278 264 271 262 284 273 277 300 258 263 328 238 255 277 282 263 299 268 272 268 260 240 276 255 264 265 256 262 249 296 259 300 243 275 286 247 257 272 278 258 259 257 306 239 269 243 274 247 271 283 248 255 261 269 283 271 282 262 244 275 278 278 237 256 274 224 247 277 246 238 241 243 267 237 268 256 232 237 259 263 242 271 262 268 277 263 261 287 274 295 284 245 235 288 271 272 297 259 258 257 283 259 281 273 266 247 274 249 293 235 235 268 246 286 261 262 279 282 265 264 265 269 265 259 234 245 277 297 265 247 246 291 247 255 285 280 232 256 244 267 276 245 241 240 275 267 283 229 230 238 232 261 248 245 259 289 263 261 268 255 245 258 235 243 278 272 248 256 244 269 226 230 237 235 274 238 242 284 274 216 226 245 274 276 235 272 255 258 283 239 246 267 270 265 240 266 227 258 296 259 211 258 246 257 267 234 238 262 282 231 232 269 209 225 264 202 232 274 242 256 244 217 255 243 217 266 273 242 249 257 263 224 265 235 242 261 279 263 245 256 282 234 260 220 249 220 274 240 220 223 268 207 248 263 237 255 242 240 247 225 257 239 227 224 271 240 260 245 262 234 256 220 219 260 234 258 232 220 244 229 248 262 248 236 240 230 213 223 241 246 282 240 239 266 230 242 236 243 232 219 255 259 219 240 261 226 249 228 238 243 257 236 241 257 238 245 242 258 265 255 244 228 247 234 223 226 273 233 250 257 248 214 236 256 241 255 242 228 231 242 213 223 239 225 238 231 213 233 244 205 230 248 221 231 243 242 232 229 248 240 242 226 242 257 214 242 232 233 215 256 243 285 220 230 225 245 257 217 225 257 238 220 227 269 205 235 238 239 261 223 223 268 257 241 233 239 232 256 234 220 246 206 228 212 257 240 222 192 217 243 226 243 218 227 223 250 237 235 233 217 243 248 231 270 243 249 242 244 234 221 260 236 212 233 228 232 233 240 228 240 236 238 215 226 239 233 231 232 232 242 210 224 247 232 234 235 242 212 198 222 223 223 234 234 257 228 230 239 247 229 212 239 257 256 231 233 228 203 216 234 233 241 214 195 221 225 199 223 258 232 226 208 234 232 239 238 232 274 227 225 236 220 227 211 258 243 218 240 264 211 209 256 240 231 189 233 223 240 208 220 226 235 216 214 235 235 235 213 214 233 218 211 224 218 204 223 227 236 193 216 228 228 238 229 237 240 228 223 224 211 207 221 235 264 248 247 214 223 234 209 212 237 224 224 228 226 207 210 202 228 222 257 204 257 218 233 219 231 228 217 236 267 206 247 215 244 243 207 209 211 245 222 209 229 207 242 219 245 210 216 231 218 256 222 245 228 224 220 245 178 230 259 231 226 225 230 207 214 245 229 219 247 199 237 235 214 222 205 221 218 203 274 216 208 262 236 232 247 216 185 222 239 203 237 224 220 204 197 202 222 217 230 219 238 228 242 216 219 227 217 214 222 224 178 206 202 212 225 203 230 221 205 201 227 219 214 233 218 187 235 240 226 205 196 222 217 206 197 220 229 222 215 224 238 218 263 205 223 216 233 212 246 218 203 211 234 223 227 204 234 218 215 202 264 202 202 212 206 237 210 239 231 228 192 209 236 240 207 226 207 207 228 270 222 222 214 226 214 239 226 222 207 216 232 232 230 220 241 238 215 240 239 210 244 216 204 220 218 214 207 214 226 228 216 237 225 203 207 196 235 228 206 211 234 243 210 231 234 196 212 205 213 229 266 219 229 210 222 232 194 219 223 208 230 226 217 213 238 237 235 198 231 237 246 219 229 226 206 232 218 200 213 217 227 202 208 192 235 231 199 188 215 207 230 191 209 220 243 217 226 222 226 218 245 199 242 199 249 237 200 238 238 195 211 231 226 215 193 211 227 216 210 212 227 212 201 205 215 200 208 190 189 214 190 216 203 203 208 214 209 226 200 199 229 223 212 222 232 224 224 227 220 204 238 221 219 228 230 225 225 240 189 219 207 222 231 247 234 215 221 230 208 223 213 212 190 257 225 239 207 222 263 219 214 190 215 191 221 222 207 213 264 233 216 202 207 217 207 230 215 216 193 171 247 240 195 224 215 231 214 210 221 199 203 241 221 219 224 200 222 235 223 264 221 223 220 239 237 213 225 225 212 229 229 213 225 199 214 187 207 219 200 196 200 221 225 225 214 208 198 215 194 193 222 201 232 200 236 199 226 230 225 215 220 182 203 210 213 219 216 217 211 206 239 258 220 216 222 213 216 198 230 201 245 217 218 230 194 217 208 240 265 246 222 221 220 219 223 197 229 216 221 221 204 208 226 215 196 189 229 220 218 222 235 224 204 232 225 190 212 246 220 215 198 210 218 212 222 197 192 219 218 268 225 203 187 216 205 218 210 211 232 191 218 255 219 210 218 205 203 217 223 205 226 231 223 199 221 212 207 230 208 240 208 200 219 204 200 207 237 199 209 208 226 200 228 204 222 232 204 193 197 229 216 211 211 205 210 233 236 211 216 200 234 203 213 264 209 235 187 227 255 213 209 227 198 204 193 228 213 224 230 221 225 225 219 216 244 215 231 200 228 215 237 210 211 223 199 249 208 193 209 220 220 246 215 211 213 224 221 217 225 219 224 216 206 202 229 206 213 215 202 217 220 214 223 211 239 218 219 223 258 206 193 208 247 220 228 240 193 198 182 198 206 207 244 221 228 222 258 216 209 219 233 204 222 219 222 208 232 215 235 210 242 226 222 233 208 204 228 232 220 229 232 206 211 236 200 226 228 234 212 221 213 220 210 225 224 194 208 215 212 214 204 209 221 227 218 191 211 181 227 222 204 224 217 196 212 201 245 226 193 233 201 211 232 195 176 221 211 220 198 232 200 207 206 218 222 231 199 205 221 210 200 209 211 202 223 212 219 235 215 222 220 214 221 221 188 222 209 229 221 237 217 196 218 216 199 217 226 232 216 221 223 228 189 199 255 223 248 199 222 195 228 225 211 211 222 213 228 240 233 243 240 207 211 199 228 220 232 238 240 221 226 235 226 222 208 215 207 209 227 213 216 242 213 209 246 196 231 210 213 191 240 217 214 225 242 209 216 231 221 192 239 229 220 232 204 230 198 221 202 218 208 220 237 211 244 222 182 199 219 236 219 232 212 194 208 255 226 237 216 219 237 236 243 255 241 190 222 200 198 215 248 216 247 203 212 231 203 239 227 210 215 213 225 243 219 213 232 234 188 205 241 227 217 215 198 232 238 240 194 216 239 235 222 229 185 255 214 239 223 228 202 241 216 221 222 220 215 213 202 213 230 232 221 217 189 242 233 230 229 244 218 229 206 224 243 264 244 224 238 259 221 261 216 230 230 223 245 218 223 257 246 234 214 231 238 201 246 211 214 248 233 265 230 235 204 224 208 202 217 234 205 225 221 228 222 223 245 218 218 250 214 214 221 250 247 224 218 236 214 218 242 238 231 211 244 244 266 268 256 230 201 240 248 257 219 203 241 221 217 240 219 214 255 255 232 235 216 236 260 256 235 246 244 270 270 243 263 225 261 262 265 244 236 257 233 268 270 241 223 240 280 260 297 228 288 279 283 283 246 224 285 298 307 278 330 299 283 281 298 308 335 290 320 310 314 319 331 340 368 357 367 342 366 376 374 406 411 402 401 373 348 363 364 371 396 338 375 339 373 363 329 334 318 352 315 303 322 316 284 265 278 292 282 268 261 294 270 282 261 240 243 245 260 260 262 260 223 255 255 248 209 231 220 266 211 239 238 235 223 229 208 228 206 228 258 226 217 257 261 231 216 287 249 231 243 226 211 233 212 219 236 220 225 244 232 229 228 224 208 202 216 225 244 238 212 217 221 234 238 227 217 261 227 207 219 239 202 230 260 232 233 217 234 225 242 233 209 237 247 228 207 227 214 220 220 215 231 229 208 248 208 198 216 189 234 219 237 194 195 215 218 234 209 217 209 214 183 198 227 228 213 250 185 228 211 242 212 244 204 205 231 195 228 222 210 220 200 210 214 219 207 231 201 233 217 217 241 219 199 219 215 215 218 224 205 235 199 233 214 195 233 221 218 215 209 192 224 201 220 221 222 226 229 242 224 200 234 198 237 239 232 212 219 213 205 211 190 236 231 228 224 226 216 219 218 249 221 215 224 210 244 222 225 198 226 199 238 177 232 234 206 196 221 223 237 230 235 219 203 215 235 219 214 219 211 210 221 237 238 219 227 213 195 208 219 226 214 221 224 221 194 202 212 232 206 216 203 235 236 219 225 222 226 243 215 222 225 215 216 223 211 205 221 211 208 221 209 199 221 248 224 240 230 219 212 231 196 211 226 217 193 210 258 208 225 203 210 193 204 212 223 198 195 218 187 215 229 236 226 234 192 227 200 211 234 206 213 190 213 227 231 208 203 227 190 220 201 220 228 189 210 202 216 234 204 208 229 227 217 236 216 217 257 224 239 200 225 177 193 208 209 219 231 217 203 220 220 224 220 224 211 210 222 194 209 215 202 203 199 244 204 213 214 241 227 200 205 189 241 188 202 199 207 206 232 205 222 203 227 222 242 215 228 222 223 208 211 217 208 220 243 205 197 206 235 222 235 194 212 229 209 216 213 205 242 225 226 207 207 215 233 233 212 233 223 209 199 219 210 230 206 215 213 214 234 215 212 219 218 201 177 246 219 206 220 231 220 217 225 210 201 209 208 206 216 219 214 227 246 231 212 233 207 222 236 207 228 242 227 211 219 193 231 230 241 199 211 222 192 194 208 230 217 218 239 227 220 196 207 234 226 226 222 218 216 193 226 196 217 195 235 224 204 215 227 233 207 181 207 221 221 218 203 223 213 216 222 210 206 179 218 223 200 175 194 211 203 243 230 210 240 199 239 213 205 216 215 223 196 228 205 198 204 218 223 202 221 211 220 219 233 199 201 197 228 221 226 223 204 213 227 185 223 223 223 219 223 235 209 216 201 247 230 206 191 209 234 215 244 195 210 176 207 212 232 197 213 232 221 212 247 192 204 198 199 226 241 222 232 224 223 209 228 219 230 226 212 236 216 231 209 200 216 203 242 209 224 193 245 239 227 218 213 235 217 222 229 205 218 207 201 231 202 211 210 245 231 193 228 199 197 218 218 199 249 223 213 240 232 219 195 243 230 242 228 209 234 210 208 232 232 211 219 247 216 190 199 215 199 187 225 230 224 226 226 229 216 216 207 205 232 190 219 219 216 219 229 231 235 225 229 242 232 219 217 191 200 199 204 212 212 218 239 216 211 202 215 226 208 215 204 171 216 261 210 187 203 198 215 223 197 218 222 230 190 240 214 199 213 200 192 231 247 221 202 241 205 217 218 224 226 195 222 208 209 234 212 231 241 220 222 224 217 220 222 201 235 220 219 216 230 232 218 243 234 219 229 222 230 219 218 228 205 203 190 218 221 198 221 230 240 216 216 258 213 215 216 188 199 264 213 223 228 207 249 218 223 236 229 200 205 196 213 201 196 183 213 187 214 207 259 187 234 226 210 202 195 194 233 220 238 222 205 221 212 221 212 227 221 195 190 230 245 212 214 220 215 211 231 236 209 225 211 204 244 233 203 202 219 204 203 194 214 208 189 197 233 227 221 190 219 210 230 211 188 221 222 210 214 208 229 208 216 229 221 216 213 225 226 220 210 194 230 243 207 227 200 221 197 229 210 215 202 225 246 216 236 207 228 205 209 191 221 239 225 210 239 224 227 199 213 205 203 203 210 206 193 217 230 208 215 229 216 211 220 215 205 208 215 223 214 220 203 200 211 222 223 225 193 224 234 230 228 201 221 233 215 201 198 210 200 227 221 200 258 209 215 173 215 218 225 219 221 210 259 205 234 216 199 209 211 203 197 206 224 209 209 225 218 227 213 225 223 226 207 260 223 214 215 215 237 212 214 220 222 183 201 212 207 222 209 197 257 216 207 199 241 210 216 206 240 216 232 221 231 195 205 235 217 205 249 198 199 228 226 216 217 217 198 234 202 221 212 212 206 201 217 206 208 239 220 230 217 202 236 200 211 227 228 214 225 213 219 217 221 205 216 198 199 225 210 213 200 209 222 224 226 221 234 200 239 205 210 216 216 223 219 195 179 193 200 210 183 204 207 212 222 229 204 193 222 210 176 189 234 216 223 198 212 201 232 223 232 226 228 189 199 222 233 204 202 211 226 207 234 196 210 210 234 214 203 212 211 216 226 194 217 211 215 200 215 215 233 205 203 213 213 236 238 218 258 199 209 226 184 229 199 223 199 208 199 231 220 224 204 206 201 196 222 216 186 214 217 229 230 231 226 212 225 206 203 205 208 226 225 222 218 204 220 240 187 213 211 211 191 196 199 247 243 200 233 217 217 196 208 227 208 222 203 206 212 212 232 206 219 217 228 210 223 217 204 204 222 233 200 224 199 201 237 224 207 211 193 216 233 229 215 206 208 175 219 228 224 180 213 222 213 208 219 245 208 220 230 220 218 205 191 201 226 219 182 194 232 204 206 243 188 210 197 215 186 194 225 239 195 204 205 218 229 203 184 217 214 221 226 198 204 217 216 205 237 205 265 204 209 208 198 222 207 221 233 190 203 223 238 196 230 205 200 210 227 228 235 228 249 212 195 224 197 206 207 214 266 207 211 218 195 218 228 230 221 225 220 191 215 215 197 221 218 234 190 205 216 237 241 222 207 214 180 220 196 206 214 202 199 228 208 218 208 208 221 217 196 217 216 211 202 210 231 234 244 225 219 219 223 211 198 238 186 212 221 245 198 221 219 241 236 240 203 228 246 222 241 194 182 205 218 230 231 199 214 215 264 211 217 195 212 225 213 239 205 193 226 237 204 221 201 236 245 195 212 227 214 247 213 220 226 229 187 232 210 208 233 206 256 215 236 232 206 213 215 227 229 220 222 225 212 214 222 212 218 224 206 209 203 227 233 236 212 228 203 194 216 195 187 223 197 223 243 230 222 229 222 238 208 205 233 207 233 215 199 185 212 230 202 215 209 200 220 238 224 228 240 227 217 176 234 195 221 221 210 187 215 214 199 228 197 235 205 222 231 218 196 194 217 199 230 209 193 217 222 246 221 223 217 224 212 212 208 183 223 206 223 204 212 237 240 226 213 187 202 214 204 203 210 210 212 235 213 211 195 222 198 209 193 204 201 213 213 224 199 196 236 224 220 241 189 218 258 206 200 232 205 235 209 229 208 185 219 214 212 208 214 235 226 248 234 234 244 206 208 238 228 209 241 213 201 210 220 232 201 204 199 224 193 210 204 231 202 209 233 222 216 223 196 228 216 218 214 205 276 217 200 224 212 213 229 224 220 239 236 218 271 212 214 239 204 225 238 192 220 221 215 243 248 272 258 209 216 206 180 248 234 211 185 207 209 209 231 217 243 213 230 227 204 184 234 204 233 213 221 220 200 244 233 227 224 240 230 225 229 183 229 231 228 225 210 244 197 262 213 217 262 243 213 211 212 201 230 225 202 204 219 237 233 245 215 203 220 213 232 206 208 261 219 225 232 230 204 240 210 218 258 222 218 237 233 235 227 205 214 221 230 213 256 210 177 211 227 239 215 197 209 217 207 192 199 214 219 246 229 213 235 228 211 206 214 214 187 226 218 222 255 213 209 225 215 263 217 210 227 211 225 248 203 218 201 214 221 228 194 204 204 196 227 180 213 213 217 206 216 224 216 215 203 256 269 229 206 220 227 220 220 225 207 238 220 188 232 209 211 231 194 219 213 226 202 231 257 229 225 240 189 235 248 233 227 246 244 234 240 234 245 217 224 202 228 262 215 229 234 244 223 218 232 237 235 223 216 238 230 204 233 197 197 200 199 214 189 237 214 218 226 233 228 233 217 231 239 211 227 238 243 214 235 211 206 231 195 221 220 228 197 256 238 249 214 202 217 214 257 233 214 222 223 205 214 199 198 216 203 211 247 217 202 203 186 236 228 229 211 196 197 237 216 209 233 209 233 205 210 202 179 211 207 210 221 222 219 216 223 211 219 216 216 209 238 203 206 200 204 223 211 235 223 215 245 240 222 198 222 203 200 257 194 231 235 211 220 184 196 206 234 217 205 236 210 217 249 204 223 219 199 230 211 204 195 192 219 201 218 212 231 216 225 218 218 225 227 223 212 215 220 240 203 228 227 221 222 219 203 228 203 225 219 218 191 246 206 216 219 213 210 217 218 206 201 184 220 223 209 218 256 225 202 239 238 226 227 234 226 229 208 207 220 246 221 256 235 240 225 223 261 212 236 232 221 214 240 237 231 259 220 206 235 246 234 217 232 237 240 233 236 233 265 244 224 236 241 210 224 234 204 227 226 241 233 223 216 245 230 240 216 208 218 228 217 235 229 215 212 224 213 217 218 225 235 220 225 227 237 228 233 229 241 238 223 223 222 226 204 214 216 221 229 245 220 228 208 234 227 211 207 232 240 227 235 227 229 240 220 214 226 216 214 222 264 226 226 211 207 245 207 207 229 219 218 194 226 195 205 228 184 186 226 220 187 206 244 198 194 233 218 226 243 239 222 223 205 211 212 215 215 219 238 226 224 199 223 224 206 241 233 240 195 218 230 235 207 220 227 231 220 212 248 220 203 231 216 206 221 208 203 206 236 203 221 208 240 217 207 204 215 244 192 229 197 219 193 209 227 225 199 242 213 209 202 207 211 224 200 229 210 225 218 208 230 204 233 200 220 232 214 188 196 214 214 204 200 209 235 204 229 218 216 240 181 225 211 221 234 233 196 265 213 214 213 206 201 184 224 208 217 213 198 238 197 206 246 217 211 198 225 223 214 204 220 244 226 193 188 222 223 234 215 204 207 228 216 237 190 208 222 207 214 202 213 270 213 212 231 204 203 204 214 228 226 222 239 203 241 238 213 220 240 228 204 188 221 219 211 211 218 223 207 213 222 225 240 237 215 228 217 224 217 226 209 237 223 238 195 240 227 227 233 209 206 202 222 219 228 192 205 203 218 212 214 214 214 229 209 189 193 222 271 226 223 215 230 220 211 231 199 185 247 221 205 220 263 213 185 225 223 214 226 201 239 222 244 215 206 207 239 228 229 214 219 204 235 188 195 228 216 229 221 205 227 234 237 196 203 211 214 232 238 185 237 247 213 207 220 256 187 257 210 236 218 206 234 205 207 198 214 240 232 226 259 216 227 220 219 223 229 226 190 211 219 213 208 260 231 222 214 219 211 210 226 234 215 225 240 214 234 240 199 202 248 214 204 230 225 204 240 230 240 215 201 231 215 227 245 202 220 223 235 227 198 199 195 235 222 210 192 226 220 218 221 231 222 219 221 219 213 233 210 206 211 209 223 207 192 237 215 226 212 225 229 203 238 226 209 233 231 217 222 222 234 231 217 214 221 207 241 214 213 213 226 201 206 219 230 193 215 221 234 241 234 212 225 229 216 228 227 198 216 225 222 205 215 169 206 235 199 210 222 206 239 212 238 239 210 207 227 244 219 211 218 206 219 207 223 191 182 221 212 222 230 222 205 231 222 213 205 203 237 237 221 223 192 202 197 225 207 203 258 225 220 222 211 223 242 244 198 203 232 222 241 235 233 213 229 201 216 192 206 220 213 218 196 208 205 219 213 243 203 227 179 233 227 216 222 246 204 193 232 203 229 216 234 198 224 209 244 203 241 231 206 238 199 224 206 211 215 234 226 238 220 212 206 196 215 215 207 244 209 257 219 221 204 225 213 205 206 235 212 215 186 221 208 225 218 213 225 238 203 222 201 206 237 221 189 210 202 209 199 247 226 234 188 227 206 225 223 243 227 212 209 224 216 188 218 194 208 227 216 224 212 220 201 221 223 190 200 210 207 212 217 199 220 205 195 206 202 218 230 203 227 184 229 209 222 227 185 212 213 200 244 218 224 206 213 234 201 211 221 194 213 222 216 226 241 210 220 225 241 223 214 223 210 201 182 224 219 222 218 202 218 215 218 226 192 188 205 212 215 210 223 223 187 210 219 205 193 214 234 225 210 215 238 217 199 198 218 215 210 208 203 236 223 205 246 199 210 222 197 233 238 198 211 185 226 198 221 205 217 210 236 225 201 205 235 239 216 220 213 201 259 220 210 209 209 231 243 200 238 219 199 219 199 236 195 235 212 239 218 188 225 212 203 214 231 218 207 206 210 204 227 203 219 240 206 231 225 228 225 223 236 194 223 206 226 238 211 214 212 219 221 231 214 192 218 231 214 221 236 214 241 203 201 239 208 222 232 219 215 236 208 233 213 193 214 189 216 216 225 204 210 255 231 227 201 223 201 193 217 212 194 194 215 203 217 213 225 216 211 214 218 193 222 203 214 215 221 211 201 214 203 212 226 194 225 196 205 237 200 203 211 201 223 200 213 212 222 197 210 199 226 203 223 249 201 219 208 246 221 210 224 234 209 214 217 212 219 233 205 222 196 212 234 201 214 222 219 196 236 225 206 216 229 203 235 235 227 191 237 200 202 223 207 240 207 221 223 203 224 210 207 194 241 189 199 207 210 218 199 208 210 210 228 234 225 223 210 214 210 217 223 248 237 231 231 230 220 238 217 221 227 212 210 223 215 217 227 225 231 209 212 218 209 225 216 236 210 200 215 211 219 217 228 229 247 215 215 244 222 209 191 184 212 222 205 229 231 215 255 198 211 259 198 198 220 234 205 216 270 224 223 226 217 197 194 203 221 205 245 217 212 208 240 198 202 216 243 223 241 225 232 198 216 216 207 204 210 221 227 204 213 205 210 213 223 205 186 219 229 208 212 231 207 207 226 206 222 217 199 211 194 217 207 225 219 220 206 230 237 216 209 231 231 217 204 228 210 199 196 210 225 205 204 211 213 244 220 238 209 229 206 212 230 215 216 214 230 210 196 228 201 222 206 227 228 220 212 228 210 228 244 204 202 193 195 237 200 212 218 199 220 210 188 198 212 214 222 174 235 199 197 224 235 232 225 222 223 228 211 219 196 209 232 213 218 223 197 206 198 205 216 221 224 215 213 217 231 227 210 209 238 216 216 243 230 209 233 192 200 199 221 196 228 211 232 235 196 211 216 184 189 226 212 223 207 198 208 208 232 223 203 200 219 206 217 217 217 210 220 227 220 228 204 247 186 204 197 208 198 209 220 219 208 218 209 225 197 185 218 200 171 214 216 205 194 219 217 226 204 214 226 219 214 247 230 214 188 221 230 205 214 232 206 227 218 215 196 228 208 216 210 165 210 234 210 240 191 208 228 187 243 215 199 224 220 217 240 241 201 221 234 225 184 220 207 197 194 190 217 239 223 208 239 219 206 217 197 202 204 200 199 189 216 189 224 208 212 226 222 228 205 181 186 218 190 206 179 222 197 223 194 204 191 202 215 225 223 226 184 196 202 195 207 216 211 205 199 206 222 199 204 219 205 211 222 205 225 220 225 199 224 210 203 199 223 211 203 204 225 189 217 238 211 202 223 201 199 227 190 237 228 204 185 218 224 200 220 222 219 238 228 207 210 221 196 165 197 203 221 211 219 204 225 205 211 239 203 232 208 242 180 217 208 213 218 190 211 195 213 227 241 183 185 205 202 202 231 226 204 215 203 217 218 219 215 186 216 201 203 214 218 191 196 233 203 182 198 220 217 205 210 223 229 209 226 235 205 223 186 176 196 225 204 178 224 219 189 205 187 206 197 204 217 191 206 214 212 216 206 202 216 197 204 219 234 201 206 211 195 220 202 205 214 209 172 191 194 182 212 231 206 229 199 204 191 198 228 215 203 227 228 210 196 214 175 199 189 222 239 205 221 229 211 202 207 214 232 196 210 185 229 194 237 195 207 194 199 214 200 207 223 198 196 227 239 206 194 221 226 214 212 236 205 176 203 207 221 226 223 201 205 214 210 232 203 178 214 222 213 221 228 213 180 186 189 225 228 222 197 226 183 200 211 214 164 209 194 186 225 197 190 186 192 207 199 201 196 216 220 208 209 191 195 172 210 180 222 206 217 207 229 206 211 204 195 217 180 183 230 244 188 231 212 207 204 193 218 202 210 210 210 183 233 208 209 218 218 213 189 205 207 215 204 212 218 198 209 201 209 215 206 235 227 181 245 227 223 232 189 210 196 202 209 206 216 215 203 214 206 187 230 219 212 213 235 236 209 203 230 219 229 185 208 195 205 199 213 206 242 191 230 219 199 213 242 210 213 212 210 218 222 208 212 221 182 248 256 220 222 194 204 213 247 232 229 241 209 197 248 261 222 219 212 238 238 202 227 221 226 246 237 225 215 219 244 265 240 247 246 232 233 240 233 236 258 260 258 238 219 239 232 235 233 218 239 216 199 228 221 204 249 226 224 257 245 210 237 235 236 210 211 218 238 229 205 243 228 231 214 202 200 232 238 220 256 224 219 204 229 202 227 228 217 210 218 215 211 245 204 210 239 218 219 204 217 177 219 216 184 204 238 227 233 207 190 224 213 210 209 221 217 186 197 210 197 203 196 189 191 189 198 226 206 185 198 200 220 194 193 188 198 198 205 234 190 215 209 210 185 188 223 207 217 202 229 203 198 193 230 196 212 203 194 196 193 218 209 214 215 189 205 207 227 198 206 190 203 194 228 205 190 181 207 210 221 215 202 183 227 197 207 204 209 211 190 210 210 198 191 199 203 233 197 205 207 239 208 182 204 198 233 184 189 192 206 233 198 187 186 230 186 200 193 200 223 221 189 199 184 222 210 205 177 185 191 195 188 224 188 194 199 182 214 200 198 234 186 208 218 203 219 194 202 213 205 184 231 210 184 201 208 205 199 211 217 198 212 202 201 201 197 206 211 218 205 184 172 203 204 214 199 193 207 214 185 201 224 205 238 195 182 202 209 218 208 204 217 194 176 183 185 214 179 192 201 189 208 203 188 214 183 205 213 176 191 209 209 208 205 207 179 177 196 198 204 201 219 198 199 208 192 195 203 202 206 202 208 178 198 178 195 197 206 204 194 230 189 192 199 182 191 195 178 223 193 188 170 205 187 217 219 193 181 177 199 227 208 192 219 203 193 194 195 194 190 180 205 204 200 192 178 175 192 193 199 209 202 191 190 194 218 192 198 184 208 164 204 210 191 183 198 176 203 197 203 187 215 197 181 200 170 177 180 195 189 216 200 195 196 214 232 173 221 189 170 210 208 219 204 219 201 193 221 189 206 211 183 195 211 202 197 213 212 201 199 213 192 183 195 184 196 167 211 177 194 212 171 203 186 199 176 187 208 189 197 189 185 182 209 214 201 179 187 177 193 185 200 212 204 201 212 190 195 201 190 207 194 200 202 196 197 167 175 206 210 210 209 188 207 210 213 198 189 201 169 195 200 192 209 178 192 179 227 200 193 186 200 197 215 206 198 205 195 190 202 211 195 224 207 192 185 200 195 204 185 196 193 200 210 203 183 193 195 191 191 186 203 212 222 185 188 217 196 179 206 199 203 215 184 200 212 169 202 193 185 193 187 196 199 190 189 200 195 202 184 172 206 209 195 213 195 191 217 194 214 217 186 205 190 215 216 219 176 207 182 184 179 220 182 212 206 210 195 177 190 208 216 200 193 218 193 233 205 201 202 202 199 217 200 191 203 218 212 190 194 187 234 193 235 190 190 217 177 179 209 178 188 184 199 192 194 228 192 198 195 199 219 223 197 191 186 182 212 201 214 199 175 214 219 210 190 200 193 210 203 208 193 205 185 211 177 212 173 222 213 201 189 184 222 204 205 208 212 193 201 189 179 180 201 203 220 204 204 191 198 199 224 183 206 210 212 217 199 205 203 186 203 204 200 168 188 206 207 217 197 188 197 208 189 208 183 203 187 190 207 180 204 201 185 196 186 182 202 175 203 188 189 179 201 196 217 187 194 197 182 212 202 184 189 209 184 205 172 210 191 207 189 196 192 211 179 194 184 186 178 188 183 216 200 199 176 195 205 175 174 179 170 198 199 181 203 215 181 194 207 188 197 188 194 167 193 199 195 201 177 176 220 220 185 208 194 195 197 176 178 184 189 171 204 196 177 178 188 195 192 183 209 173 197 218 181 206 203 222 174 207 212 200 193 171 184 193 175 193 177 200 197 174 180 185 208 203 178 184 182 190 176 166 157 187 194 196 201 194 179 174 193 191 198 202 213 205 197 209 199 212 183 217 197 210 191 191 204 202 219 213 181 177 166 198 176 214 192 174 196 205 207 172 180 200 211 193 194 199 204 175 188 202 204 183 219 206 193 181 203 183 194 207 190 205 185 185 190 162 197 194 202 196 203 179 203 185 216 198 197 172 189 170 204 202 214 184 202 211 214 210 185 196 192 194 194 197 207 199 201 186 171 178 170 191 183 170 198 203 193 200 201 199 174 179 208 200 190 192 204 195 196 205 215 208 209 210 203 217 195 192 184 176 205 182 219 178 193 182 182 209 193 195 198 204 176 195 202 176 182 214 204 194 170 175 194 185 218 202 211 180 211 188 198 186 219 219 204 182 187 197 208 206 208 194 183 190 200 209 184 227 201 186 203 189 220 174 167 187 194 209 208 181 210 178 215 213 181 233 182 196 198 211 208 171 196 225 208 186 180 188 184 200 177 181 194 178 202 210 198 170 195 201 197 197 206 202 191 185 196 200 198 194 190 173 173 177 205 184 170 193 205 197 198 178 192 191 175 192 198 199 202 215 203 193 181 217 192 179 203 179 180 196 212 165 199 191 201 220 178 184 218 199 194 202 195 179 186 177 177 198 206 213 196 181 173 223 217 201 213 195 191 205 181 201 191 175 180 225 204 191 212 193 194 190 207 221 196 202 219 199 189 224 180 176 192 219 175 204 191 183 201 211 206 204 174 187 204 173 186 181 199 199 179 189 185 169 211 190 193 174 208 207 182 186 199 186 184 193 205 196 220 190 203 204 191 179 192 220 191 172 194 201 202 229 197 187 209 182 200 195 202 175 213 199 154 205 215 207 223 166 209 194 208 197 207 193 179 201 191 197 168 202 214 176 196 205 196 192 203 202 192 197 212 219 199 201 174 199 214 178 190 193 206 190 192 192 195 184 236 209 224 194 220 212 200 194 181 228 207 187 182 178 188 183 214 199 210 191 201 190 193 197 196 183 203 182 202 216 203 215 192 186 203 178 226 217 181 214 192 188 209 210 192 211 186 184 174 197 187 186 206 186 188 220 188 206 212 201 177 221 202 205 207 235 205 198 203 182 200 188 210 194 206 179 188 185 190 218 172 190 211 202 216 175 214 170 198 186 213 184 189 200 218 185 196 185 201 193 184 209 174 212 193 200 211 199 199 227 178 217 181 183 194 184 188 180 193 188 188 191 201 210 206 196 168 185 194 203 203 178 184 204 193 207 214 203 220 186 198 202 188 201 187 185 178 203 175 180 179 206 197 177 184 179 178 205 211 189 192 196 205 203 211 199 199 202 191 191 197 212 197 194 207 216 169 169 205 208 171 203 194 180 217 230 190 190 208 191 191 208 173 210 203 186 200 200 187 198 205 175 202 186 190 197 219 200 200 168 173 205 184 234 181 190 193 182 198 178 211 192 180 213 175 191 201 195 183 213 206 187 204 211 209 210 181 186 198 213 200 186 191 210 214 182 178 213 186 193 181 163 201 170 183 169 201 195 179 207 209 175 190 179 184 196 218 205 187 203 184 187 178 187 203 212 187 197 209 180 179 188 224 201 216 194 203 203 195 178 201 195 188 209 198 176 205 211 206 197 200 187 196 160 183 164 207 211 192 200 211 191 207 186 212 206 216 201 203 219 203 208 167 196 189 179 175 188 195 162 205 169 163 184 191 202 201 180 187 221 225 189 213 190 201 193 183 174 209 184 228 160 216 169 169 185 200 190 226 188 172 200 184 206 199 201 199 193 175 189 191 221 208 188 185 185 180 193 173 193 212 217 218 193 193 206 206 200 200 196 199 210 222 200 203 184 181 180 183 187 189 210 187 179 189 219 194 200 214 177 215 204 193 211 173 229 188 211 188 221 204 205 209 191 194 214 223 209 223 204 192 213 201 215 205 193 176 227 236 205 201 205 205 219 196 200 190 201 233 205 214 184 232 210 241 237 224 227 199 205 213 222 215 200 204 199 214 207 222 228 196 234 201 197 201 216 192 226 195 216 179 208 221 191 222 212 184 195 196 205 193 193 230 189 218 195 206 173 211 215 212 188 200 200 203 220 198 197 202 207 192 211 208 222 219 205 234 190 235 199 197 204 216 207 222 200 209 199 207 185 210 189 216 209 186 209 208 202 214 195 211 193 209 203 201 221 171 170 202 181 178 222 203 212 191 194 216 185 179 215 177 207 185 184 194 208 203 211 169 176 195 215 217 190 190 177 204 199 186 195 215 207 192 202 175 171 202 215 223 187 200 194 205 208 187 191 199 180 209 228 205 208 188 221 181 192 180 200 207 212 186 215 208 199 210 203 201 199 186 210 210 218 203 203 202 220 217 216 188 198 204 218 219 221 191 217 246 207 200 218 179 221 204 199 178 201 203 168 211 178 205 190 222 203 199 193 219 197 206 217 201 198 206 217 198 177 171 213 200 218 212 171 184 196 216 221 218 207 207 214 197 216 208 200 187 233 209 208 193 231 187 204 194 206 197 218 198 187 215 204 175 183 186 205 234 231 192 205 200 205 192 186 177 190 191 183 202 184 187 204 208 233 196 224 226 206 171 194 177 208 198 201 203 200 181 204 190 190 184 202 203 202 186 197 194 210 210 188 215 207 205 200 209 187 206 199 191 202 183 186 193 202 202 196 195 212 191 209 212 212 192 187 217 224 190 189 222 208 218 220 203 211 193 224 201 213 206 201 174 203 223 227 191 200 168 198 213 211 183 178 207 206 201 177 200 202 203 228 216 197 201 219 202 188 180 197 205 200 185 199 186 214 181 207 192 214 212 192 210 229 186 191 225 218 199 206 194 222 191 212 194 209 199 208 209 204 200 202 211 192 239 196 191 205 200 204 217 221 202 190 223 223 221 202 187 191 199 202 183 171 169 199 215 223 198 204 182 202 163 188 224 224 187 198 195 163 209 194 194 189 207 193 156 221 189 178 193 191 204 219 210 212 200 194 197 205 196 203 200 193 213 199 216 196 211 192 200 203 191 227 208 209 221 177 194 207 188 212 187 197 210 186 200 163 177 190 196 206 192 202 202 198 184 220 161 195 210 204 207 204 219 186 216 204 180 229 204 227 210 203 191 191 201 190 192 195 205 207 212 197 232 182 211 232 201 180 228 192 200 199 189 219 201 203 201 190 201 188 186 182 222 203 186 199 228 199 189 183 195 209 218 188 185 173 196 224 192 176 192 217 190 187 182 185 184 223 211 196 198 215 187 213 217 186 222 220 182 189 187 200 202 228 212 234 226 190 191 173 212 198 190 214 203 194 182 191 212 192 191 185 213 169 211 195 195 209 203 215 202 195 200 218 211 212 191 197 197 214 239 201 215 190 206 205 201 194 194 201 208 229 211 192 208 192 176 197 198 215 207 203 208 190 203 216 191 205 189 181 216 196 216 217 208 187 196 192 213 220 211 203 200 216 179 186 188 228 193 183 202 182 196 198 196 211 199 204 179 223 203 195 227 199 241 183 203 197 184 190 185 206 197 207 239 201 216 198 221 192 212 199 210 185 212 226 212 210 223 192 200 154 207 205 186 199 189 196 220 195 213 183 233 203 203 173 205 188 180 213 185 194 215 199 198 211 175 188 196 206 223 186 189 221 213 181 200 202 192 192 188 213 181 196 198 194 195 202 191 206 194 204 171 194 210 195 197 207 202 191 232 191 204 209 222 225 234 225 177 193 226 187 192 201 193 194 194 198 187 211 194 188 179 200 183 195 196 199 216 207 186 200 200 190 176 186 211 215 196 182 175 190 225 181 199 210 206 224 190 194 196 187 207 199 169 180 185 227 217 194 200 214 215 214 185 184 211 196 197 195 196 200 191 199 211 206 229 203 213 181 203 184 218 194 210 211 183 212 209 187 184 193 207 205 177 197 191 207 200 198 186 183 203 168 224 199 213 204 206 177 212 180 175 201 206 191 223 207 187 187 214 209 200 209 204 190 216 226 184 189 178 200 214 200 203 216 195 175 182 194 167 196 213 198 204 210 213 214 216 173 198 185 184 203 199 171 199 162 193 206 191 198 182 183 188 240 211 187 206 200 210 232 208 205 195 222 203 212 207 192 196 189 218 189 191 222 194 199 204 225 195 191 208 184 187 204 213 214 196 191 233 208 214 209 184 192 197 196 195 201 196 211 219 154 210 211 211 194 194 216 191 218 202 177 182 196 222 209 206 230 196 177 195 188 233 195 193 205 162 172 223 192 195 207 185 220 173 193 221 190 214 203 185 196 177 210 222 188 183 204 201 194 216 174 216 222 199 200 195 195 197 167 213 196 213 205 218 221 194 203 198 224 190 228 236 209 193 221 197 211 196 188 178 178 215 172 199 195 222 225 188 197 184 207 201 175 232 209 209 174 193 179 183 192 202 204 204 186 199 213 215 189 226 209 201 211 224 211 206 204 177 238 224 213 204 189 197 209 200 182 198 185 227 216 197 203 193 183 206 206 182 183 232 216 219 189 211 202 170 207 209 197 189 206 202 198 198 215 230 207 177 186 187 207 222 202 198 215 207 222 210 204 203 201 184 193 212 204 214 177 204 204 191 181 208 219 213 204 212 224 213 209 207 206 233 200 219 205 210 192 223 203 229 246 213 203 204 206 219 206 222 179 206 225 199 198 200 211 224 216 238 226 202 205 197 199 209 209 199 190 215 218 191 213 208 220 199 223 217 196 190 221 208 198 205 181 209 221 222 222 205 208 197 195 187 228 212 229 194 197 228 220 205 182 190 209 217 219 196 170 215 219 211 200 206 199 193 220 198 209 193 220 219 215 212 200 197 204 193 187 202 196 196 185 204 229 207 197 194 193 194 208 216 193 226 228 190 175 203 199 197 217 218 198 200 198 196 194 216 199 175 188 210 223 190 194 222 192 205 217 224 220 203 221 212 213 206 202 186 214 214 183 213 223 185 203 179 223 199 209 214 213 207 217 217 181 187 198 218 224 196 214 198 207 200 211 217 219 188 220 221 211 186 208 200 211 221 213 205 198 202 194 190 203 212 201 188 203 185 211 206 215 218 201 225 193 233 179 188 219 192 211 199 202 160 215 203 233 196 190 178 200 194 224 219 204 216 183 211 195 204 220 212 228 228 180 222 195 222 190 204 219 201 205 197 182 192 204 178 207 197 224 197 201 188 210 206 207 168 201 199 206 180 194 228 175 176 230 222 200 221 184 212 194 214 211 208 209 193 194 183 199 190 188 187 172 203 202 226 213 167 166 190 200 208 207 218 222 191 195 222 189 218 200 197 189 184 213 235 203 196 222 210 187 192 192 204 193 187 215 198 220 211 204 202 197 207 195 212 213 208 199 175 202 209 197 220 169 208 189 221 202 190 218 171 200 218 218 200 199 192 190 214 213 208 190 218 217 191 211 223 198 192 199 199 205 199 212 210 215 190 217 197 226 182 174 181 223 205 186 203 196 192 197 180 208 189 192 183 186 184 184 184 197 200 214 230 191 206 212 205 192 211 214 182 210 175 209 212 192 210 212 205 211 198 196 199 216 210 220 189 185 213 197 203 240 220 199 173 179 214 196 233 205 197 175 214 190 185 217 200 206 194 215 213 179 197 197 182 210 198 202 222 212 190 190 193 216 190 195 168 165 185 199 196 182 223 211 198 210 197 194 207 223 199 209 204 200 226 219 206 195 217 204 239 216 195 194 193 198 218 206 231 201 200 179 192 209 214 220 193 201 194 188 183 230 205 190 198 198 222 214 196 199 212 182 192 201 208 217 220 211 220 199 183 210 213 196 211 212 203 213 205 224 190 208 203 237 190 195 190 215 200 194 198 195 201 199 201 197 191 220 220 184 229 218 207 193 189 223 218 192 182 188 190 267 224 203 201 214 231 208 217 226 192 210 222 213 176 186 198 212 259 220 206 215 208 223 226 241 195 214 206 238 220 192 221 201 224 238 221 209 205 226 212 211 215 215 186 221 214 222 205 229 190 225 224 231 200 199 215 240 195 199 246 211 226 180 213 233 220 218 227 200 219 229 221 242 209 183 208 208 204 187 200 202 186 172 199 220 209 211 217 201 227 234 195 195 234 207 230 215 197 196 189 207 209 205 191 193 216 213 231 183 204 180 227 212 219 205 204 205 206 215 216 201 221 197 205 205 205 225 236 216 208 195 219 235 209 207 197 229 197 222 201 201 235 228 209 208 199 223 207 191 185 220 197 197 211 190 210 190 195 196 203 197 184 206 183 220 212 195 221 213 201 202 193 218 202 213 195 191 190 194 190 206 210 197 235 210 210 205 208 201 217 197 185 187 196 206 214 200 229 198 210 208 201 203 222 197 206 204 218 186 200 228 199 196 204 188 203 193 188 173 201 188 212 207 200 223 204 227 202 186 194 210 223 203 192 203 196 197 198 181 201 226 216 221 207 221 173 216 208 232 188 221 178 210 216 216 209 184 209 195 214 211 189 205 184 229 193 197 203 204 185 206 213 188 197 212 192 192 213 203 205 200 201 216 195 190 219 231 206 188 201 190 172 211 187 178 190 174 182 206 226 222 217 200 200 196 184 204 203 196 207 213 208 212 204 242 222 183 185 206 223 192 182 212 202 200 194 210 199 213 202 188 191 223 171 205 202 199 181 201 204 174 193 183 205 195 196 196 186 182 187 230 213 181 209 218 199 215 213 225 166 203 219 196 223 214 204 202 205 226 238 184 189 211 222 175 185 205 221 204 199 206 199 200 194 171 192 192 178 195 167 205 208 210 199 207 200 193 204 195 197 194 190 181 197 186 187 209 222 185 192 178 180 211 192 212 192 209 183 182 198 218 166 211 213 206 217 195 204 221 189 199 183 185 209 225 196 215 190 173 192 177 205 212 242 205 201 211 174 199 192 202 185 188 207 212 221 199 173 172 199 210 202 230 215 209 181 168 175 205 187 216 196 192 214 229 203 189 202 192 203 184 217 228 228 210 195 186 230 191 191 200 224 231 200 201 187 214 223 214 209 181 196 175 198 185 229 230 197 211 201 183 195 190 188 213 213 199 211 195 222 181 170 199 209 196 225 208 211 199 188 206 211 190 205 217 202 189 204 205 189 221 213 226 216 189 196 218 189 206 211 191 193 207 201 201 221 183 197 177 185 189 197 199 174 207 206 177 191 221 214 188 220 208 210 204 199 215 190 189 216 177 200 210 201 207 193 202 206 187 183 167 219 199 197 198 225 204 203 172 216 199 190 218 238 206 196 205 228 212 233 170 199 195 212 207 202 193 173 208 223 232 224 214 200 209 203 222 174 199 200 207 182 183 194 202 197 186 193 202 194 216 203 223 192 217 229 194 202 212 192 185 199 178 205 206 216 214 193 220 178 182 175 179 206 200 195 186 222 198 206 189 201 194 216 213 187 200 213 211 213 193 194 205 193 187 209 193 209 205 187 207 185 197 189 210 209 238 185 211 193 213 222 191 193 211 219 189 227 195 213 178 211 188 191 217 208 195 212 209 173 220 212 166 183 228 209 224 193 200 213 195 201 213 216 211 211 234 225 192 178 202 193 210 193 191 208 193 232 202 217 214 202 224 219 195 202 194 200 169 218 209 186 171 195 212 209 174 207 200 182 199 186 207 209 184 219 210 209 217 197 220 212 189 194 185 185 206 201 183 200 198 226 213 197 159 217 212 195 219 195 191 196 202 222 192 190 240 231 193 209 204 191 197 211 195 225 196 184 196 187 229 216 220 202 200 204 189 182 204 185 189 208 189 235 193 195 214 231 195 197 223 196 219 185 231 229 211 217 205 205 210 219 204 212 207 204 218 186 207 185 195 218 198 190 194 241 187 212 198 180 203 188 212 220 200 221 232 183 203 212 219 202 183 201 177 171 204 219 229 196 191 193 187 201 218 223 221 192 199 209 195 196 208 188 198 173 196 165 216 209 182 212 201 191 190 206 173 208 196 214 216 191 198 186 204 236 212 205 197 209 223 201 238 198 213 216 184 207 237 196 212 200 188 222 197 201 190 195 220 194 202 194 190 192 187 206 218 212 221 188 200 214 192 210 204 222 206 219 199 193 202 200 206 224 192 208 196 187 225 212 199 204 189 225 192 193 202 192 191 218 188 208 210 225 190 202 201 206 176 198 179 200 201 186 200 218 185 191 222 221 200 216 195 191 198 203 192 206 186 218 211 199 201 215 199 218 204 234 193 208 181 179 191 191 204 209 246 208 219 221 211 220 190 205 221 196 218 178 194 190 201 177 205 196 220 205 207 197 195 224 183 204 186 206 182 179 192 204 215 202 203 192 185 201 197 203 185 227 193 219 197 189 227 212 219 206 192 180 215 212 197 211 204 212 202 210 194 198 212 174 219 214 208 193 208 226 229 236 235 221 177 237 236 211 190 189 222 186 228 200 214 216 221 225 206 176 209 186 209 242 221 193 211 211 204 213 194 221 233 183 196 226 210 179 216 212 214 221 202 192 199 207 213 204 217 209 210 208 213 204 225 221 189 184 237 219 192 197 199 198 210 181 212 215 209 222 198 220 189 219 222 217 201 231 205 222 179 212 234 198 194 193 212 225 198 201 245 223 216 187 197 236 192 217 213 176 215 206 202 232 200 193 206 197 199 205 225 211 202 207 217 205 208 228 237 195 217 213 228 220 203 207 196 210 209 197 210 203 186 194 212 193 194 220 206 202 223 205 195 213 213 212 233 212 221 207 191 196 219 177 228 218 207 214 164 184 210 213 233 204 213 193 217 214 223 190 222 189 197 237 186 228 245 174 207 239 225 225 214 218 220 212 190 219 188 211 209 190 195 205 193 214 203 210 256 224 202 184 216 215 224 204 199 194 202 208 223 205 227 201 197 206 219 217 185 219 205 206 211 209 234 220 185 197 231 199 202 225 230 207 213 202 218 221 213 204 187 188 175 249 217 192 222 224 226 213 200 209 198 233 199 201 232 219 208 202 224 181 219 242 189 179 218 233 198 208 218 223 200 213 199 204 215 199 217 237 212 202 209 216 204 207 207 200 212 203 236 182 229 214 204 185 190 207 206 223 192 193 218 174 223 214 195 215 206 207 201 205 197 207 215 204 221 230 239 238 216 192 206 214 217 222 205 228 205 217 202 223 204 204 203 195 184 217 210 214 208 204 216 225 184 201 186 201 206 216 229 198 233 225 226 223 217 192 198 188 216</counts>
			</dataPoints>
		</scan>
	</xrdMeasurement>
</xrdMeasurements>