File: data/XRD/XG-Luft/XG-pre/W6823-1D_XG_Luft_pre.xrdml
<xrdMeasurements xmlns="http://www.xrdml.com/XRDMeasurement/2.1" xmlns:xsi="http://www.w3.org/2001/XMLSchema-instance" xsi:schemaLocation="http://www.xrdml.com/XRDMeasurement/2.1 http://www.xrdml.com/XRDMeasurement/2.1/XRDMeasurement.xsd" status="Completed">
	<comment>
		<entry>Configuration=Factory configuration, Owner=User-1, Creation date=7/8/2013 4:01:53 PM</entry>
		<entry>Goniometer=PW3050/65 (Theta/2Theta); Minimum step size 2Theta:0.0001; Minimum step size Omega:0.0001</entry>
		<entry>Sample stage=MRD Cradle; Minimum step size Phi:0.01; Minimum step size Chi:0.01; Minimum step size X:0.01; Minimum step size Y:0.01; Minimum step size Z:0.001</entry>
		<entry>Diffractometer system=XPERT-PRO</entry>
		<entry>Measurement program=C:\PANalytical\Data Collector\Programs\Jorrit\2thom\_absolute_2th-om_10-130deg_PIXscan_56min.xrdmp, Identifier={15BCCF57-2807-42BD-B5B9-ECC0B3DC9284}</entry>
		<entry>Batch program=C:\PANalytical\Data Collector\Programs\SimonL\batch7x_2thom_10-130°_z9.1_x0,10,20,30_y10,20,30_57min.xrdmp, Identifier={089D96B1-A01D-49FF-BCB5-EEA9DFC9CC78}</entry>
	</comment>
	<sample type="To be analyzed">
		<id></id>
		<name></name>
		<preparedBy></preparedBy>
	</sample>
	<xrdMeasurement measurementType="Scan" status="Completed" sampleMode="Reflection">
		<comment>
			<entry>_absolute_2th-om_10-130deg_PIXscan_56min</entry>
			<entry>PHD Lower Level = 4.83 (keV), PHD Upper Level = 11.27 (keV)</entry>
		</comment>
		<usedWavelength intended="K-Alpha 1">
			<kAlpha1 unit="Angstrom">1.5405980</kAlpha1>
			<kAlpha2 unit="Angstrom">1.5444260</kAlpha2>
			<kBeta unit="Angstrom">1.3922500</kBeta>
			<ratioKAlpha2KAlpha1>0.5000</ratioKAlpha2KAlpha1>
		</usedWavelength>
		<incidentBeamPath>
			<radius unit="mm">320.00</radius>
			<xRayTube id="1010048" name="Empyrean Cu LFF HR (9430 033 7310x) DK442154">
				<tension unit="kV">40.0</tension>
				<current unit="mA">40.0</current>
				<anodeMaterial>Cu</anodeMaterial>
				<focus type="Line">
					<length unit="mm">12.0</length>
					<width unit="mm">0.4</width>
					<takeOffAngle unit="deg">4.2</takeOffAngle>
				</focus>
			</xRayTube>
			<xRayMirror id="27010001" name="Inc. Beam Cu W/Si (parabolic MRD)" hybrid="false">
				<crystal type="Graded" shape="Parabolic">W/Si</crystal>
				<acceptanceAngle unit="deg">0.800</acceptanceAngle>
				<length unit="mm">60.0</length>
			</xRayMirror>
			<sollerSlit id="21010002" name="Soller slits 0.04 rad.">
				<opening unit="rad">0.0400</opening>
			</sollerSlit>
			<mask id="22030008" name="Fixed mask 4 mm">
				<distanceToSample unit="mm">220.00</distanceToSample>
				<width unit="mm">4.00</width>
			</mask>
			<divergenceSlit id="22010011" name="Fixed slit 1/32°" xsi:type="fixedDivergenceSlitType">
				<distanceToSample unit="mm">220.00</distanceToSample>
				<height unit="mm">0.05</height>
			</divergenceSlit>
		</incidentBeamPath>
		<diffractedBeamPath>
			<radius unit="mm">320.00</radius>
			<sollerSlit id="21010002" name="Soller slits 0.04 rad.">
				<opening unit="rad">0.0400</opening>
			</sollerSlit>
			<receivingSlit id="22010001" name="Fixed slit 4°">
				<height unit="mm">5.88</height>
			</receivingSlit>
			<detector id="7010017" name="PIXcel3D 1x1 detector" xsi:type="areaDetectorType">
				<phd unit="%">
					<lowerLevel>30.0</lowerLevel>
					<upperLevel>70.0</upperLevel>
				</phd>
				<mode>Scanning</mode>
				<activeChannelsEquatorial>255</activeChannelsEquatorial>
				<activeChannelsAxial>255</activeChannelsAxial>
				<pitchEquatorial unit="mm">0.05500</pitchEquatorial>
				<pitchAxial unit="mm">0.05500</pitchAxial>
				<readOutPeriod unit="seconds">0.135</readOutPeriod>
			</detector>
		</diffractedBeamPath>
		<scan appendNumber="0" mode="Continuous" scanAxis="2Theta-Omega" status="Completed">
			<header>
				<startTimeStamp>2024-10-21T22:21:25+02:00</startTimeStamp>
				<endTimeStamp>2024-10-21T23:17:31+02:00</endTimeStamp>
				<author>
					<name>PRO-MRD</name>
				</author>
				<source>
					<applicationSoftware version="6.1b">Data Collector</applicationSoftware>
					<instrumentControlSoftware version="7.0E 20130304">XPERT-PRO</instrumentControlSoftware>
					<instrumentID>0000000011142674</instrumentID>
				</source>
			</header>
			<dataPoints>
				<positions axis="2Theta" unit="deg">
					<startPosition>9.99826193</startPosition>
					<endPosition>129.99755682</endPosition>
				</positions>
				<positions axis="Omega" unit="deg">
					<startPosition>4.99913096</startPosition>
					<endPosition>64.99877841</endPosition>
				</positions>
				<positions axis="Phi" unit="deg">
					<commonPosition>0.00</commonPosition>
				</positions>
				<positions axis="Chi" unit="deg">
					<commonPosition>0.00</commonPosition>
				</positions>
				<positions axis="X" unit="mm">
					<commonPosition>20.00</commonPosition>
				</positions>
				<positions axis="Y" unit="mm">
					<commonPosition>0.00</commonPosition>
				</positions>
				<positions axis="Z" unit="mm">
					<commonPosition>9.100</commonPosition>
				</positions>
				<commonCountingTime unit="seconds">32.895</commonCountingTime>
				<counts 66 72 73 79 90 64 97 60 70 77 76 75 79 80 67 71 74 67 63 75 94 64 84 65 77 82 74 73 63 76 73 81 80 88 73 83 78 66 73 69 67 68 76 77 54 78 63 70 94 69 78 77 69 90 80 75 70 82 88 91 72 72 66 64 66 91 73 64 70 60 69 78 63 72 86 78 96 76 81 64 87 86 67 60 73 73 75 69 88 72 64 65 74 86 70 84 102 84 64 70 77 67 68 71 71 67 71 63 81 72 63 69 68 85 63 81 57 60 62 73 70 69 65 74 67 79 69 79 70 70 60 72 75 80 65 67 57 68 75 70 63 74 80 63 72 64 78 81 77 76 58 95 74 74 52 58 73 67 75 57 57 82 68 61 78 77 70 74 73 69 77 65 77 84 76 63 68 85 71 68 68 66 68 47 50 72 88 70 55 76 76 71 71 79 54 67 72 73 81 67 73 50 56 48 65 78 62 86 67 67 62 79 51 80 64 67 74 72 66 64 71 76 77 62 59 67 73 69 73 61 62 71 65 58 69 59 60 71 76 64 60 65 66 67 75 79 66 73 65 58 64 60 71 74 58 74 58 64 60 67 64 66 66 64 59 56 61 78 62 69 65 61 46 49 73 78 62 75 83 60 62 65 62 62 77 81 53 57 58 71 60 78 56 82 52 54 69 69 65 63 59 54 62 73 57 64 79 58 75 77 57 47 61 70 66 64 65 61 57 74 73 48 58 76 65 69 63 54 72 55 67 70 59 68 59 69 64 71 70 61 68 72 66 65 63 63 68 65 67 52 63 56 66 71 51 47 68 48 68 62 52 76 58 78 61 70 62 60 67 56 70 61 77 53 54 62 56 67 62 63 57 57 57 80 64 62 45 65 51 58 56 67 70 61 60 58 72 55 66 52 75 69 76 69 54 61 54 60 52 68 47 60 73 65 77 62 65 65 68 44 49 57 48 58 63 55 58 60 59 73 60 40 71 62 51 61 62 59 56 61 59 59 53 71 52 59 62 52 59 56 63 59 64 57 53 69 63 69 51 52 76 52 53 49 51 61 65 64 60 63 56 53 68 62 49 50 55 46 55 62 62 78 61 54 53 52 62 61 56 43 63 63 65 60 50 48 54 60 53 48 60 55 50 55 48 83 35 68 65 45 69 62 66 54 50 62 67 77 60 58 63 63 58 60 62 51 58 64 56 42 54 51 53 54 51 48 59 55 52 45 51 47 68 72 64 59 49 62 68 58 49 58 52 52 54 66 49 63 52 51 57 73 52 57 68 52 69 48 72 64 61 54 62 46 57 54 54 54 57 56 46 49 57 56 67 70 60 61 50 66 55 70 59 56 66 57 55 58 54 65 66 51 58 50 55 57 55 65 55 50 77 51 52 44 65 55 52 52 67 50 66 39 50 51 50 60 49 56 54 54 63 55 49 54 57 58 55 51 63 71 55 58 49 68 50 60 51 57 61 55 56 58 62 75 57 56 61 57 63 73 49 40 62 63 56 57 45 46 46 47 60 46 50 72 60 57 46 61 57 58 56 51 50 50 53 57 47 53 59 61 59 57 58 55 68 41 59 59 45 60 48 62 61 60 50 52 55 46 46 69 55 52 56 63 60 59 61 51 69 66 54 54 47 58 57 61 64 53 68 54 46 65 56 52 48 48 47 56 60 61 59 51 39 61 62 57 55 48 40 52 58 59 56 55 63 54 53 53 62 60 55 46 53 63 47 54 46 45 61 51 60 61 54 70 52 61 53 46 50 53 42 45 69 61 46 59 55 51 70 55 59 72 55 57 67 52 64 60 55 56 53 44 74 42 66 57 53 42 54 35 64 52 61 52 62 53 50 39 55 56 43 51 51 44 49 47 61 75 57 58 55 60 49 56 45 49 59 58 53 53 57 48 53 59 58 44 60 62 51 54 44 50 40 46 53 69 52 56 60 60 59 52 62 49 63 57 64 52 47 58 45 49 57 50 59 46 65 57 51 50 55 46 63 53 64 59 49 54 58 46 61 56 55 56 44 61 50 45 57 49 59 47 43 53 53 53 54 56 54 49 56 43 49 51 67 58 59 64 54 60 50 71 51 50 56 56 45 68 49 59 51 59 47 54 58 62 41 48 46 58 54 67 64 47 65 55 47 57 44 63 62 50 56 60 64 63 53 59 58 60 64 63 53 58 53 45 65 50 36 70 56 64 64 55 49 49 57 61 45 63 45 62 72 53 52 65 64 49 54 56 51 60 61 68 76 71 66 52 56 48 71 50 61 49 68 46 61 52 49 54 50 60 42 64 46 53 58 58 59 58 48 70 69 54 56 53 58 55 67 41 57 68 66 59 55 41 48 63 50 65 66 65 58 61 57 66 67 60 66 64 49 53 53 52 68 55 57 56 53 56 56 66 58 53 64 69 49 75 49 59 64 53 67 56 66 44 55 62 56 59 59 59 55 61 61 48 57 53 64 57 57 54 61 48 51 60 46 56 63 62 74 63 58 61 62 62 54 60 52 50 50 57 59 70 50 53 58 60 62 49 64 58 57 62 62 70 77 49 53 55 68 56 74 71 75 61 48 50 67 61 63 44 73 58 64 59 67 40 56 54 67 60 76 62 66 53 50 49 50 52 56 71 53 52 54 73 52 71 59 51 64 62 59 52 52 71 59 59 51 68 61 62 60 60 69 75 53 49 63 47 49 65 72 61 84 54 54 68 73 61 50 67 67 57 69 64 55 65 67 68 65 59 54 63 59 60 67 57 58 62 56 57 48 72 64 61 46 51 69 44 70 54 48 66 64 64 67 59 65 59 57 55 59 58 57 60 54 62 70 60 65 63 57 64 59 51 55 57 58 53 56 48 48 58 64 59 72 69 62 63 55 65 59 60 59 54 51 62 49 63 50 60 49 51 62 49 57 59 70 62 64 52 65 60 54 66 78 58 61 62 60 72 65 64 64 78 62 74 64 68 66 62 59 68 64 65 65 55 58 68 61 50 70 61 66 55 74 59 63 61 60 55 58 62 69 61 56 58 67 45 63 59 52 58 58 64 74 76 55 73 76 61 42 64 63 60 62 68 54 61 55 63 54 67 53 63 60 69 51 57 50 55 50 63 60 55 51 56 52 70 56 60 57 55 63 64 67 67 59 67 62 60 58 59 62 64 58 48 59 53 62 50 64 53 62 55 62 70 57 65 53 61 59 66 64 57 65 56 59 61 61 73 63 65 49 61 48 58 65 42 49 59 56 63 60 59 69 73 45 52 61 51 56 50 54 48 49 47 53 61 49 54 57 37 49 59 62 58 60 56 63 55 58 48 54 51 53 50 58 55 52 48 53 44 61 49 53 52 52 71 66 50 61 53 52 48 63 47 43 70 44 74 56 55 65 49 51 60 54 60 53 58 55 60 48 58 60 41 52 58 43 43 65 46 44 50 57 61 68 42 56 51 55 55 52 54 53 44 55 49 54 57 55 56 65 51 59 48 70 56 51 47 37 59 56 46 47 59 56 54 49 50 50 52 61 51 51 55 42 46 50 53 47 55 55 54 49 62 58 49 51 54 69 48 63 64 63 59 56 70 61 44 57 49 52 52 54 51 51 37 44 54 45 43 44 65 59 38 55 42 46 52 42 62 52 48 52 41 51 59 41 60 43 46 54 50 55 45 48 61 40 66 55 54 42 48 52 56 49 43 55 61 45 53 45 63 53 51 51 39 48 56 50 54 40 45 68 52 55 62 38 49 46 58 52 61 54 54 48 59 44 41 43 40 58 61 51 52 48 52 58 46 44 51 52 44 45 49 50 57 39 45 57 55 40 39 36 53 52 51 59 45 53 57 52 50 42 41 52 47 45 49 50 47 34 50 65 41 44 39 42 40 46 43 46 48 47 37 47 58 42 41 41 61 56 62 45 44 46 45 40 48 38 52 56 34 56 56 52 63 54 39 52 44 45 48 52 40 52 54 43 47 41 49 53 42 49 62 40 30 49 52 46 39 39 52 48 52 49 46 43 54 50 49 65 45 54 45 47 48 42 49 58 53 44 36 47 61 47 38 31 65 43 47 47 48 51 59 53 50 47 54 53 44 47 47 45 40 56 45 44 40 41 45 51 57 44 45 53 39 46 48 51 49 45 47 46 49 41 51 39 47 63 44 38 42 50 45 41 44 49 48 52 41 60 45 50 56 41 46 49 46 46 48 45 55 50 53 42 67 39 55 49 50 51 44 50 42 56 30 53 40 45 51 54 50 48 42 38 43 47 54 41 39 47 38 48 48 47 40 47 50 37 48 50 49 52 52 45 41 46 36 44 48 55 42 49 40 39 50 53 36 51 51 52 41 46 54 50 41 51 48 55 41 48 47 43 40 40 36 39 37 42 39 39 48 41 44 52 55 43 51 40 45 34 37 43 48 45 43 42 55 55 43 48 36 44 48 34 46 39 41 50 36 46 37 45 38 43 44 56 45 43 48 46 47 36 59 45 47 51 34 36 47 53 46 49 57 48 35 39 25 48 38 52 35 58 41 42 32 42 42 38 42 44 54 39 46 47 36 44 54 46 44 49 56 39 42 40 40 58 52 39 56 57 38 36 46 44 29 49 34 40 50 46 41 31 40 52 48 48 45 44 46 41 39 61 46 42 40 40 42 30 49 29 41 38 42 33 33 35 48 47 59 38 45 39 53 42 39 43 47 52 51 50 38 39 46 39 36 48 46 42 32 39 54 47 55 31 54 45 52 44 37 51 25 48 43 43 44 45 37 55 47 34 39 46 46 34 26 43 52 38 44 49 42 47 33 46 39 48 38 50 48 37 46 36 51 41 45 47 42 42 39 40 43 43 23 35 33 31 33 36 43 38 37 36 40 38 51 41 43 44 51 50 36 43 42 50 47 42 40 47 34 43 43 43 49 31 44 45 28 43 53 34 30 32 41 34 32 52 54 41 42 44 30 26 30 43 36 52 42 38 39 38 38 37 37 54 48 44 49 35 41 40 47 45 50 41 39 43 47 45 39 42 40 45 43 36 41 41 39 34 37 43 41 53 46 58 37 45 32 41 32 28 34 53 36 45 42 51 40 46 41 40 49 40 53 41 41 48 34 44 55 46 49 45 35 44 43 44 36 48 38 31 41 44 33 35 36 38 48 37 37 48 43 36 36 43 49 33 43 36 42 41 38 38 38 49 44 33 37 33 47 42 37 48 40 44 26 42 32 50 49 44 45 40 48 37 38 45 41 40 47 45 36 49 39 36 46 34 29 48 44 39 54 28 38 43 30 51 39 47 39 33 43 51 41 36 34 39 48 41 44 40 25 43 43 37 43 38 55 42 34 45 37 37 42 39 43 34 36 48 34 40 47 33 34 37 44 35 42 39 36 31 33 43 45 30 33 34 38 39 32 43 41 46 36 45 39 42 44 45 33 39 48 33 36 45 36 45 32 37 43 30 40 43 35 35 32 37 32 54 39 31 48 36 38 38 41 41 44 44 43 33 38 27 38 32 49 34 45 25 35 18 40 29 30 45 48 44 42 42 36 29 48 33 36 35 33 30 38 41 52 29 42 51 25 36 49 38 38 36 44 34 31 38 40 40 32 49 42 39 38 51 31 38 48 40 34 27 39 36 39 43 52 45 45 50 42 35 41 28 40 36 36 34 37 23 51 43 36 24 47 29 31 50 48 37 27 46 30 38 35 44 27 43 40 37 32 46 42 35 45 40 34 53 38 38 41 27 43 47 30 36 50 37 57 50 28 38 43 41 44 39 27 36 37 32 35 41 34 42 44 33 37 46 40 34 35 34 38 43 35 49 37 39 36 44 32 32 49 42 37 42 40 34 43 30 44 42 42 37 39 38 46 33 35 38 47 37 37 30 35 41 40 43 34 49 43 52 34 38 40 32 48 44 47 42 35 29 39 41 39 33 39 54 46 44 32 39 36 30 37 37 36 40 39 42 51 37 40 36 32 34 32 45 31 43 44 30 36 31 33 42 39 44 45 43 42 39 33 37 29 37 29 40 35 45 37 42 38 29 36 44 46 38 47 35 28 38 34 41 42 35 46 47 39 35 28 37 37 33 41 37 35 33 41 43 42 49 37 45 34 35 27 38 32 33 32 39 34 38 40 41 37 25 32 39 34 36 28 41 34 42 39 28 45 36 39 33 28 36 32 39 32 31 34 47 41 39 34 31 32 35 38 37 36 31 32 42 36 34 31 47 33 40 42 40 37 34 59 41 34 38 40 33 33 40 42 47 38 36 31 42 29 32 24 44 38 42 39 43 36 33 24 31 33 29 31 43 35 35 38 39 33 34 30 38 31 45 41 46 30 32 35 39 34 40 31 39 46 39 45 33 30 34 34 33 44 40 36 36 29 39 48 41 23 34 40 34 62 36 51 45 42 40 39 42 49 35 35 27 32 35 42 35 27 47 45 33 32 28 37 40 33 59 38 28 37 33 37 29 42 27 45 53 37 44 38 51 22 32 37 33 34 35 25 39 40 41 42 47 36 37 50 46 30 39 41 44 38 40 39 36 25 40 43 41 34 34 32 41 42 38 40 38 28 28 39 45 34 43 35 36 38 38 48 39 41 38 30 32 36 42 37 33 38 45 34 36 43 31 36 56 36 32 30 31 28 45 33 35 38 34 23 33 37 38 36 25 32 38 39 39 40 37 37 39 25 36 31 45 33 33 38 40 42 25 38 47 37 37 40 40 33 45 44 44 37 42 31 44 27 46 39 42 30 48 38 26 47 43 26 34 38 38 35 40 50 32 40 39 30 31 36 28 29 43 39 35 45 30 33 42 44 37 50 43 48 33 25 33 36 37 48 48 28 41 42 34 30 44 37 41 38 30 36 32 32 40 36 36 32 42 46 46 43 32 26 44 26 21 33 29 39 22 31 30 32 45 47 33 37 50 41 40 40 37 34 47 39 34 27 34 44 38 38 33 39 35 44 40 53 40 47 40 36 28 33 43 38 32 35 42 45 44 30 39 35 41 39 37 49 39 29 36 25 36 35 43 36 46 37 42 33 45 41 37 35 39 47 33 42 30 36 45 30 43 38 38 45 52 52 46 41 47 42 35 35 44 40 46 34 32 31 45 41 48 35 41 32 37 41 22 34 45 43 41 38 45 33 35 31 34 37 32 42 31 38 25 42 35 31 46 37 36 34 42 26 40 39 36 36 37 31 32 41 37 36 38 39 37 41 32 38 34 47 38 44 41 38 33 30 40 27 49 41 36 41 47 33 34 34 34 44 44 38 43 40 44 37 36 50 44 31 34 44 42 40 31 34 56 45 48 39 41 42 31 34 46 36 32 33 40 43 38 43 32 39 29 27 25 46 47 46 43 46 33 32 44 46 33 31 26 37 40 44 29 56 42 29 44 51 46 35 43 50 42 34 34 45 38 36 34 43 34 43 38 42 30 43 33 43 41 45 37 34 46 39 35 40 45 50 44 37 37 45 32 34 35 46 36 50 38 45 36 25 32 43 36 44 44 39 40 39 44 44 36 43 45 44 40 41 35 41 50 38 31 33 34 41 29 53 36 38 42 50 36 59 41 45 48 44 50 42 29 59 43 48 50 40 27 39 33 39 35 40 48 46 42 40 39 48 30 29 37 44 39 36 51 32 38 39 33 32 38 42 40 40 40 48 44 53 45 49 34 37 51 49 36 61 34 39 41 43 38 50 47 38 38 36 39 39 47 51 28 40 53 34 33 47 47 37 44 45 52 37 38 39 36 51 42 45 41 50 39 45 46 47 48 38 56 40 47 45 52 34 43 53 60 38 45 44 52 52 55 41 48 47 44 46 53 58 51 45 56 66 57 45 55 54 69 48 49 62 48 45 53 67 51 55 65 63 60 76 77 63 79 82 74 72 68 61 71 69 78 93 66 77 67 69 59 77 63 57 67 59 60 68 60 66 53 59 60 57 50 56 57 48 53 49 38 47 63 48 41 42 37 49 38 43 49 40 39 48 51 40 40 31 45 46 32 33 46 49 37 55 41 41 45 44 41 38 38 31 48 39 26 49 46 44 33 30 50 28 60 53 41 32 42 37 49 39 43 59 44 45 43 38 31 51 48 49 38 46 34 42 42 38 49 45 38 43 48 42 40 42 38 54 32 44 55 31 50 51 51 37 39 34 46 29 35 46 55 43 41 47 49 43 45 50 50 38 37 47 46 53 39 35 36 57 39 37 39 39 30 46 44 33 44 43 56 46 53 34 36 42 42 44 48 40 36 50 34 41 45 42 31 44 38 48 31 37 43 27 53 36 38 46 48 44 44 36 47 47 42 37 35 41 39 50 40 51 34 42 34 42 48 46 39 51 34 49 34 55 42 49 30 42 43 44 26 38 40 42 24 52 35 30 43 45 34 41 43 35 45 41 39 45 44 52 36 36 34 41 43 46 36 47 31 46 36 36 34 46 24 52 37 44 44 44 36 36 46 50 36 28 35 39 65 40 29 34 35 47 42 46 35 37 33 43 33 53 43 42 33 42 53 34 41 46 46 45 35 49 47 44 44 44 35 45 54 40 45 57 37 41 37 42 57 40 31 46 38 44 50 34 41 39 30 42 42 38 44 40 33 41 43 42 49 40 34 44 31 42 36 47 58 29 40 37 38 32 29 31 35 39 47 44 34 45 39 30 42 46 36 40 38 48 44 41 40 37 41 30 37 48 34 36 42 47 36 46 39 36 45 47 52 42 42 36 45 44 32 38 43 30 43 38 25 35 43 37 50 43 34 40 43 42 51 43 39 42 50 48 56 45 46 41 31 49 56 39 43 36 36 38 35 47 54 42 36 38 43 37 42 41 48 35 52 43 38 36 40 46 40 50 49 36 42 48 37 44 44 49 35 22 38 43 41 59 50 53 42 42 35 43 49 52 37 36 36 36 44 61 43 43 36 43 41 26 40 41 47 38 53 40 43 49 42 36 42 42 45 39 41 35 46 39 32 47 37 47 36 53 54 35 51 35 47 39 46 35 43 36 36 59 38 42 43 43 52 38 47 46 46 42 51 40 42 31 42 52 44 41 33 30 50 48 36 28 39 43 43 40 37 48 47 42 42 46 35 32 39 46 41 38 39 36 51 38 35 44 46 43 41 45 42 40 50 42 49 31 43 43 34 46 34 34 36 41 44 60 35 47 28 48 41 40 42 33 30 43 45 35 44 38 39 38 53 40 50 40 35 47 31 39 56 42 40 42 34 36 41 40 49 54 28 47 38 43 40 42 34 42 45 51 46 45 29 45 37 49 46 40 42 42 48 35 40 34 40 34 31 33 60 36 41 45 45 46 35 52 47 45 43 34 30 39 26 42 47 38 42 49 37 36 41 50 35 36 38 39 46 36 40 51 36 39 41 43 43 55 43 35 49 34 40 53 55 36 48 46 35 44 46 38 29 33 33 48 49 39 43 31 67 29 42 47 34 40 38 39 36 42 41 38 45 44 42 36 48 42 31 41 46 35 35 40 42 36 32 31 45 27 33 43 35 30 41 36 35 38 41 46 52 37 42 39 49 42 47 27 36 41 36 35 44 42 36 30 44 32 32 43 42 33 33 31 42 47 39 44 31 36 34 37 44 40 41 51 25 31 38 37 34 46 29 49 40 41 58 36 43 44 36 48 23 48 36 38 44 39 47 51 38 45 45 39 46 45 45 33 40 49 36 41 42 47 38 45 34 34 47 30 45 53 33 44 41 39 43 55 36 47 35 40 38 33 40 40 45 53 42 39 31 31 37 36 31 49 30 33 35 50 47 38 49 38 46 43 47 43 37 41 38 49 37 36 39 42 51 35 43 27 27 39 37 58 30 42 49 44 38 53 46 52 51 31 39 31 35 35 47 36 49 50 36 29 48 39 38 37 42 41 43 44 31 27 43 41 50 42 59 32 51 46 41 38 43 42 34 36 30 36 31 45 41 43 46 46 34 39 49 31 31 43 45 39 38 36 32 28 45 37 52 34 41 37 39 31 33 40 37 39 38 38 39 39 38 41 37 35 48 30 34 41 34 35 49 41 41 39 51 47 36 43 44 38 36 37 43 47 39 38 35 42 47 51 35 39 42 36 42 39 39 42 30 42 55 41 32 42 37 38 56 38 42 47 41 40 40 43 42 40 46 37 39 38 48 36 40 48 53 46 37 35 53 35 51 49 47 43 31 35 38 42 34 38 37 40 38 41 41 51 40 44 40 31 46 41 30 38 35 48 38 39 50 38 39 40 41 42 33 37 47 48 40 48 29 45 39 40 43 44 47 53 25 36 33 28 45 46 37 63 44 43 42 42 46 44 48 36 45 44 37 36 51 31 42 37 47 37 37 44 42 44 41 49 44 33 41 35 36 46 28 31 39 36 42 31 38 38 57 43 45 60 38 43 45 37 49 31 32 56 46 31 49 43 41 46 53 51 44 48 41 47 41 42 39 42 40 32 38 47 36 47 43 42 36 39 36 35 47 47 41 41 39 41 37 37 49 43 48 29 33 54 55 34 39 40 46 46 44 38 40 43 49 34 54 37 46 36 40 46 39 42 43 43 32 47 42 52 36 48 40 47 37 41 57 49 44 38 56 42 42 41 43 51 38 44 43 49 43 44 38 41 33 52 47 47 42 39 50 46 37 48 57 36 35 50 34 49 43 35 33 39 41 38 35 44 43 47 45 45 42 45 54 41 38 53 45 36 48 40 47 37 42 39 41 30 32 35 51 49 42 32 48 33 40 40 46 42 49 42 42 33 32 52 47 46 49 50 35 32 36 37 48 45 48 39 47 40 50 38 38 45 47 42 35 30 47 46 35 45 42 42 39 33 45 59 45 38 49 39 34 41 39 39 50 38 45 52 45 50 44 47 51 56 42 41 38 40 43 48 33 46 41 46 44 40 38 35 52 44 51 47 49 41 47 36 28 46 38 37 41 55 54 41 41 39 37 46 39 39 39 36 40 47 42 46 34 42 35 41 39 37 59 37 32 40 38 36 33 45 33 38 35 52 37 39 50 39 36 46 46 51 43 42 35 36 41 50 36 31 47 42 48 36 40 45 34 43 38 47 42 52 36 42 46 36 50 35 44 36 49 35 59 35 50 46 47 40 44 46 39 49 35 43 35 47 33 37 38 46 41 41 41 34 44 50 49 46 50 30 40 44 39 37 44 46 42 41 25 36 41 38 44 46 43 39 40 44 46 39 41 37 42 53 40 38 57 39 44 32 28 39 46 41 43 67 38 40 44 45 43 35 44 54 33 48 45 46 41 32 34 38 49 50 38 44 40 40 45 32 47 37 42 48 44 49 41 41 49 47 46 43 51 38 46 41 47 31 59 49 34 41 29 39 38 47 46 48 53 35 41 47 48 47 44 42 31 47 34 34 41 50 35 46 40 45 41 23 35 45 49 39 39 39 39 42 38 31 42 41 52 43 37 44 44 38 39 39 34 35 41 42 37 33 38 36 41 39 35 35 49 28 51 37 36 47 49 48 44 44 49 48 32 37 45 32 35 35 46 47 50 38 43 43 44 40 37 30 44 41 41 40 45 40 33 40 41 44 45 37 41 34 42 36 34 39 38 44 43 53 41 40 48 50 47 31 46 56 41 52 46 29 35 32 32 40 45 40 41 38 42 39 35 41 45 36 44 47 40 27 39 48 48 38 51 49 36 50 49 50 40 41 47 45 40 52 30 35 44 41 42 46 40 42 42 35 34 39 49 47 39 45 42 36 34 47 55 41 31 35 38 32 35 44 49 27 46 46 54 36 46 44 49 55 38 39 32 41 52 47 41 49 42 31 33 48 50 58 41 38 47 45 33 46 40 49 38 42 45 32 44 29 51 40 31 50 56 54 50 47 42 43 46 40 43 51 31 42 43 55 37 43 56 50 50 48 46 42 34 42 40 56 46 40 38 52 38 38 56 51 40 55 41 49 49 45 42 36 35 41 37 58 44 40 41 36 29 38 35 41 41 43 33 44 50 40 56 44 36 57 37 33 44 40 39 49 45 41 44 33 37 29 36 37 46 39 36 38 37 40 40 40 34 38 51 42 46 29 34 45 37 46 31 44 39 36 48 43 40 44 39 48 49 32 50 34 53 46 48 37 41 50 44 39 49 42 52 39 33 38 39 33 47 44 40 29 48 38 46 37 35 44 39 44 48 42 48 43 44 46 50 44 60 49 41 53 44 49 34 34 50 56 43 58 59 39 48 36 60 36 38 50 44 31 33 40 44 41 50 49 47 42 42 46 46 42 43 41 40 36 47 61 43 42 43 35 40 33 47 41 43 53 33 41 48 35 49 38 35 36 43 31 29 42 46 45 54 47 46 42 37 48 50 53 47 40 45 35 39 38 54 40 41 44 39 55 45 22 58 49 51 48 41 50 45 40 47 37 38 47 36 52 48 46 38 48 41 52 47 39 35 44 42 44 43 48 43 45 37 40 38 38 33 35 34 59 56 48 37 49 30 46 46 36 38 46 41 62 53 41 57 41 48 36 52 39 48 40 31 46 56 31 37 53 43 47 55 56 37 50 54 52 52 46 39 42 40 37 40 47 48 49 42 43 59 46 49 35 42 54 41 41 30 46 39 42 48 50 52 67 45 53 59 61 51 44 47 43 40 48 42 39 44 30 40 44 36 41 48 40 34 40 44 62 51 48 44 44 40 47 48 49 59 45 29 38 45 46 37 43 40 52 53 52 45 48 48 47 39 49 45 47 54 50 47 45 42 40 44 44 54 53 41 35 44 26 59 49 47 37 46 43 47 42 45 46 44 45 47 47 48 48 55 40 44 27 49 49 51 41 51 47 41 42 43 43 35 49 54 53 44 41 45 43 45 47 48 44 47 54 43 51 50 39 46 44 43 34 48 57 36 51 30 39 56 53 35 42 51 58 46 32 50 41 50 47 47 42 45 40 53 39 40 39 29 41 34 40 52 47 60 39 44 48 53 35 32 45 28 60 40 51 40 39 46 50 51 42 38 41 41 41 41 50 60 51 45 43 41 28 47 42 40 44 48 40 41 58 33 36 45 66 42 29 58 45 44 47 41 48 52 46 29 38 36 37 46 49 50 45 45 45 59 51 37 41 53 46 42 35 44 48 43 41 52 45 44 48 46 48 42 51 42 53 37 38 43 49 47 48 46 40 32 61 43 46 47 53 37 45 46 41 47 42 37 43 45 33 41 55 29 43 32 44 35 40 39 58 34 48 40 36 37 42 35 38 44 41 49 27 39 36 38 41 48 40 35 45 42 45 45 31 42 41 42 42 33 41 48 38 47 47 44 48 49 49 42 40 44 51 54 43 42 38 38 47 43 41 35 49 39 49 45 56 49 45 35 42 38 40 40 36 39 45 42 46 45 43 51 38 42 41 37 46 59 59 47 48 44 43 51 51 47 39 56 56 42 42 49 55 39 58 43 44 31 37 52 49 48 36 46 39 33 47 29 34 33 48 45 55 46 33 42 41 46 56 41 55 48 42 43 46 40 47 47 50 37 52 46 43 46 47 38 45 42 37 33 44 32 33 48 39 46 42 45 51 45 43 55 49 35 58 44 49 40 38 45 40 48 43 55 43 47 52 46 47 36 44 44 43 49 35 41 48 46 34 46 46 61 40 46 37 39 31 51 43 57 40 44 55 38 48 51 48 47 49 41 40 49 36 57 41 46 48 48 43 44 35 49 44 41 44 45 51 52 47 47 37 37 36 30 42 54 47 35 47 47 40 37 41 45 57 48 33 58 45 44 58 52 47 47 35 49 56 40 47 45 44 45 44 45 24 42 50 34 44 42 39 44 64 45 44 50 50 59 41 39 45 40 43 47 39 44 39 51 38 37 45 37 38 39 47 40 48 37 53 40 33 45 29 37 36 37 33 47 40 39 54 40 50 43 46 45 38 37 39 43 45 42 35 47 44 45 50 38 45 54 48 56 47 47 54 42 37 51 39 38 42 37 33 45 42 59 42 37 42 49 49 48 48 31 44 34 49 34 58 33 52 48 48 27 56 35 49 42 51 52 40 44 49 47 43 30 38 53 39 48 52 40 51 37 40 35 39 45 44 33 49 35 51 40 52 37 54 47 57 36 47 41 48 58 50 47 45 33 47 46 60 38 54 40 39 32 47 59 45 40 47 50 43 45 43 43 54 36 41 47 57 38 32 37 43 43 34 50 36 47 44 40 45 47 33 49 49 40 51 36 47 38 44 47 47 40 43 37 52 44 41 51 37 43 39 52 39 41 36 36 48 47 51 50 32 33 48 41 42 65 54 34 48 48 40 47 48 52 33 58 26 35 53 38 55 35 46 38 47 39 38 43 49 51 44 44 37 58 54 38 45 40 38 38 47 37 47 42 43 47 33 44 46 37 43 53 45 36 42 35 50 39 40 60 39 36 41 32 41 38 30 30 35 50 49 38 36 47 44 43 37 45 31 29 45 49 33 41 35 38 42 47 46 40 35 36 43 38 43 57 48 57 44 37 41 47 41 51 40 34 43 33 41 45 36 42 49 44 57 36 39 51 49 43 35 46 42 47 45 43 52 29 39 36 44 40 37 53 43 43 54 36 50 49 39 46 37 42 43 37 29 39 55 38 41 36 45 45 42 47 50 47 47 45 44 39 37 30 42 43 45 63 42 39 49 47 50 46 47 30 43 54 37 48 43 43 49 44 44 36 50 40 40 46 42 49 41 38 33 45 46 46 44 35 39 53 45 43 28 32 39 40 45 51 57 41 53 48 40 37 42 42 46 37 44 55 37 42 41 43 32 45 45 40 47 36 34 49 54 34 41 50 48 37 43 46 33 50 39 35 46 51 38 34 51 37 45 43 36 39 34 39 54 37 50 26 39 28 47 42 42 39 55 44 33 43 38 41 43 36 41 53 44 40 45 50 42 41 42 42 38 39 38 55 39 51 42 45 41 30 41 55 40 39 38 44 42 37 41 50 43 46 57 36 50 49 41 49 52 57 43 47 46 52 53 44 47 39 58 51 47 42 36 42 46 35 28 46 41 55 41 52 40 39 42 46 50 44 44 52 39 50 29 42 36 53 33 47 49 43 40 40 46 40 44 47 42 42 50 41 50 35 37 48 50 47 52 48 40 34 48 34 56 48 43 36 44 31 38 34 49 34 41 47 36 38 46 34 43 40 42 39 37 39 39 36 37 47 37 40 37 46 47 46 38 45 46 42 42 44 46 45 30 48 39 46 38 45 45 38 36 40 42 46 45 49 38 43 45 35 44 50 42 46 50 40 48 46 40 44 41 41 56 36 42 50 48 39 44 52 53 42 44 46 37 39 49 39 34 34 39 39 37 40 42 42 39 53 37 38 46 37 40 58 42 39 36 47 37 40 44 50 46 40 47 37 41 43 34 38 53 57 42 41 48 51 31 46 24 46 45 39 46 45 56 37 36 53 36 45 38 35 51 41 57 44 43 51 51 37 51 38 34 34 48 51 41 38 44 46 43 37 51 49 49 43 47 36 41 31 41 45 32 46 33 48 30 50 45 44 44 40 44 33 36 55 43 36 56 46 38 47 36 45 39 42 45 46 54 44 38 41 45 50 43 40 38 55 37 51 46 32 35 27 35 50 37 35 43 37 49 42 43 36 51 32 53 39 48 43 33 47 43 43 31 45 51 44 40 35 43 46 45 39 31 47 42 48 42 43 45 47 45 54 32 35 50 42 59 49 40 44 44 48 30 34 47 26 56 38 43 46 36 40 43 42 47 49 30 45 40 53 48 34 36 46 49 45 53 47 41 29 36 39 44 57 46 44 46 52 37 38 48 41 44 29 52 52 37 39 48 44 35 53 45 37 55 51 41 47 38 42 42 51 34 42 43 41 39 41 38 38 48 35 47 48 39 47 39 46 40 40 46 41 43 41 33 42 41 46 43 42 37 46 41 37 40 49 47 40 51 39 43 44 46 48 39 45 40 37 31 34 46 48 44 50 50 36 51 45 48 39 52 50 40 51 38 45 36 31 50 55 30 43 39 42 34 45 40 40 56 33 45 38 41 51 38 43 42 51 42 48 46 44 28 54 41 52 37 40 50 49 44 47 40 50 47 46 54 40 38 37 36 36 45 36 52 51 36 39 30 40 39 46 51 43 30 42 33 44 45 39 58 47 41 40 48 36 42 40 47 38 49 53 49 46 48 44 40 32 40 43 44 52 27 44 49 47 41 43 44 38 41 50 37 45 49 48 48 38 56 31 33 43 35 43 43 38 25 38 41 51 44 31 40 46 47 28 32 35 41 42 30 33 30 41 45 45 43 37 39 39 49 65 48 54 44 50 43 41 37 37 47 53 32 39 46 49 50 37 44 35 45 46 44 56 49 45 40 45 46 46 46 39 50 41 39 39 48 49 36 50 30 40 44 41 46 32 29 46 44 49 52 49 38 46 47 44 59 44 42 40 44 46 45 33 52 38 35 44 49 48 46 50 52 50 49 37 51 34 53 37 39 49 37 53 53 36 51 48 36 43 39 49 38 33 46 45 41 48 43 46 58 49 55 49 49 51 36 49 48 52 51 42 38 50 45 50 48 43 49 44 39 50 44 51 49 46 49 48 54 51 64 47 44 43 45 41 55 54 36 42 43 58 59 47 57 56 42 50 53 51 35 44 36 47 50 56 58 37 50 50 43 43 47 57 56 45 63 44 55 51 57 47 41 50 50 43 47 43 40 57 43 37 58 32 38 40 39 36 42 50 36 38 44 46 50 57 44 47 43 36 50 43 40 45 36 30 35 34 44 48 42 46 40 36 52 49 37 40 41 47 36 43 33 51 32 30 41 42 30 45 64 47 41 47 44 42 45 55 51 41 53 42 41 45 40 45 39 44 42 53 41 31 31 48 46 34 47 41 53 37 54 38 35 54 41 43 52 66 44 41 32 49 42 53 45 41 43 38 41 38 49 40 38 35 44 42 44 50 46 42 53 34 44 46 44 32 38 37 43 44 34 38 41 46 34 45 34 36 49 42 41 40 33 51 36 53 55 48 40 54 48 44 35 37 39 39 40 48 46 52 31 40 53 41 35 51 38 42 56 49 32 38 41 42 41 49 54 48 48 54 34 49 46 46 49 29 40 47 41 37 43 41 43 36 38 43 39 48 51 44 34 37 43 34 38 43 38 40 45 42 31 47 34 46 39 38 45 45 35 35 33 38 30 39 41 48 60 51 37 29 41 48 44 49 43 41 50 47 48 46 47 44 37 39 47 44 35 38 39 42 56 46 43 45 51 45 54 43 48 48 50 51 47 52 38 46 40 46 35 50 43 35 39 45 33 40 45 41 35 32 42 48 39 49 48 37 42 30 41 55 50 42 42 46 41 41 40 37 45 46 38 40 52 36 41 42 38 46 58 44 49 54 45 38 33 36 37 30 40 37 27 51 40 40 34 45 44 44 47 59 35 44 47 35 39 44 45 40 45 51 45 43 49 53 33 43 40 37 51 51 45 47 40 31 42 42 39 40 42 48 31 49 41 46 45 40 33 39 49 45 50 35 55 42 37 45 61 47 44 37 36 44 65 44 35 39 51 47 38 57 27 44 56 41 43 52 45 54 51 39 43 40 41 50 43 43 52 46 45 40 40 37 40 38 40 38 37 44 42 53 34 45 35 44 52 40 55 42 46 51 34 52 39 53 45 57 30 44 43 37 64 51 37 40 45 47 51 45 36 35 30 59 48 39 42 38 47 44 42 31 45 34 40 47 44 32 32 43 42 37 42 47 45 31 44 47 44 42 48 43 44 48 39 34 43 57 32 30 35 45 37 50 50 47 45 31 54 51 39 56 30 45 43 44 38 35 42 41 41 39 38 42 29 56 47 27 52 36 56 41 43 47 42 37 36 39 50 39 39 33 38 35 44 52 45 30 40 37 41 66 32 47 42 27 42 48 36 39 33 50 41 48 49 47 51 38 47 41 33 38 44 45 42 51 53 44 36 47 44 49 43 43 41 49 40 35 38 34 42 32 46 37 51 42 39 42 37 34 38 47 45 39 40 42 33 53 61 47 35 46 41 43 43 46 44 53 42 43 33 29 42 50 39 46 43 38 41 41 39 29 34 40 41 41 33 43 36 46 43 43 53 42 33 30 39 43 36 32 38 40 34 34 46 31 40 43 32 37 41 34 52 40 44 47 50 34 36 45 47 44 53 40 38 34 44 42 43 48 42 30 42 49 47 36 34 46 52 41 47 37 38 34 46 41 39 33 42 43 42 42 44 33 29 30 48 32 48 33 46 41 41 49 55 55 50 41 41 39 46 33 27 46 43 35 38 43 41 40 35 45 29 48 45 42 43 51 36 41 49 44 35 33 34 31 43 33 49 54 40 41 40 50 38 53 48 47 47 40 32 43 51 48 35 43 39 44 33 31 47 46 50 33 34 37 37 34 40 32 45 34 48 48 51 34 37 46 37 41 32 34 39 31 41 35 39 37 32 54 34 39 35 47 40 35 34 40 47 38 44 42 40 51 31 44 43 43 32 34 42 37 42 38 49 41 41 30 55 32 26 43 31 39 49 42 41 38 58 43 43 42 49 51 38 45 52 45 49 38 42 39 43 45 49 45 47 32 32 44 58 41 31 51 43 35 40 42 39 43 50 33 42 33 41 52 37 41 51 35 24 44 51 48 41 34 48 33 36 43 42 26 37 40 37 37 47 44 45 54 48 36 49 40 42 29 35 36 37 45 38 41 30 28 48 32 38 46 47 46 42 39 51 43 46 40 55 40 38 41 44 41 43 45 48 35 51 40 40 33 45 35 51 41 39 48 38 39 52 39 46 40 39 34 45 34 49 46 32 47 35 46 45 37 42 41 43 41 41 45 37 42 43 42 46 55 42 48 41 47 45 45 47 50 39 42 54 41 43 35 52 45 38 51 40 38 41 48 42 42 36 41 47 46 52 30 33 31 52 42 32 42 43 45 35 32 42 35 41 38 41 34 49 35 32 47 48 37 46 40 44 39 59 41 43 51 38 37 29 39 51 37 50 44 40 36 45 44 44 42 30 44 51 40 47 50 51 54 38 35 32 42 39 45 50 39 34 43 43 38 44 46 35 43 41 49 48 41 34 43 38 49 39 34 32 31 40 55 35 31 37 40 45 59 53 45 49 55 45 39 34 34 47 47 53 35 38 43 39 41 44 55 44 39 41 47 48 37 47 45 44 40 44 45 50 32 33 39 41 27 40 35 48 49 48 52 37 45 55 45 38 43 56 36 33 29 38 48 37 36 57 41 39 44 33 40 47 42 51 43 44 39 34 43 37 38 28 47 33 34 45 40 31 37 33 43 39 50 29 36 32 36 39 43 31 47 44 40 41 41 43 53 46 42 41 38 36 37 35 42 40 42 35 47 42 35 40 46 49 44 50 33 42 50 36 50 39 44 44 43 40 33 46 39 46 38 49 41 40 47 44 37 37 33 48 49 38 53 39 33 40 38 57 43 33 45 48 39 41 42 45 44 29 28 29 29 59 44 54 36 41 55 40 39 37 35 48 53 52 40 51 35 39 45 48 46 47 40 43 38 33 40 39 43 39 39 43 54 37 44 42 38 30 36 51 55 39 42 35 35 41 53 22 47 35 33 47 38 41 40 30 44 41 37 52 37 37 42 47 40 43 36 39 47 38 30 32 32 36 53 50 42 48 38 46 30 39 53 51 29 41 41 45 37 30 48 40 44 44 52 35 32 44 44 40 37 43 37 37 30 45 61 30 51 45 59 36 36 47 31 40 51 41 44 47 48 38 40 33 42 44 36 46 38 43 39 40 49 40 40 39 35 33 43 52 34 45 22 38 40 41 42 39 49 40 39 34 44 46 44 45 47 46 47 46 44 35 48 38 45 40 37 37 40 44 48 52 42 41 37 42 39 49 33 51 42 35 40 48 51 43 42 38 44 37 44 40 39 49 30 43 35 40 46 35 44 47 47 43 40 51 31 38 37 36 44 46 41 38 43 35 42 50 34 45 44 37 31 34 35 40 43 38 49 35 48 38 43 44 42 43 28 33 42 42 40 46 39 32 51 23 40 49 42 37 40 45 40 49 39 26 35 45 41 54 40 30 43 39 39 40 32 43 33 52 42 46 38 36 45 34 40 36 44 49 38 38 50 41 48 41 45 37 45 41 38 35 44 46 38 38 40 46 37 40 30 34 46 30 39 42 41 42 47 33 41 46 42 37 49 40 53 40 44 42 34 42 32 43 36 48 34 26 53 46 45 49 42 45 45 59 31 32 36 36 35 43 40 33 30 40 38 40 52 44 33 46 52 44 39 41 44 41 40 39 54 53 46 35 53 53 40 41 43 41 46 41 48 33 46 33 53 41 45 44 44 56 41 45 40 45 42 50 47 49 47 49 44 31 49 29 45 33 42 35 56 47 39 51 54 49 49 41 54 38 48 31 42 38 42 52 44 43 51 43 51 42 50 42 41 54 38 56 44 45 34 37 41 40 38 31 30 51 43 47 41 53 41 55 43 47 48 36 41 38 60 53 41 44 42 43 40 34 39 48 52 46 51 44 41 37 33 46 50 41 49 41 46 43 39 36 37 45 48 48 34 31 46 33 53 46 44 37 47 40 50 43 32 46 37 37 42 34 47 38 42 40 40 50 44 38 37 44 31 41 48 42 38 35 46 49 54 49 38 46 53 35 54 39 50 36 52 46 39 54 32 36 34 36 39 45 37 55 45 47 36 36 31 42 42 45 44 34 50 41 49 46 40 41 47 40 42 45 42 36 47 42 40 40 40 38 43 39 37 37 41 38 53 36 49 35 38 47 55 32 38 52 35 51 39 42 46 35 39 60 37 44 38 28 44 49 43 51 40 36 42 46 36 50 48 41 44 52 41 40 55 40 26 34 58 44 43 55 42 53 52 49 41 45 45 33 42 41 37 36 32 32 34 42 44 47 45 39 41 43 49 48 48 51 36 44 39 41 48 34 41 37 35 36 52 41 47 52 46 39 57 36 33 42 40 42 33 55 49 37 48 47 38 47 41 36 47 42 33 35 49 55 38 47 49 45 49 45 42 43 37 49 43 43 42 60 32 37 40 38 44 40 30 34 52 47 46 31 32 40 51 46 44 48 42 35 48 50 39 35 40 38 38 33 38 37 38 37 38 40 47 48 40 42 42 37 50 35 43 44 37 56 54 33 43 51 43 40 37 38 43 36 51 25 41 32 37 43 46 39 39 27 40 36 45 36 42 44 40 37 41 49 34 37 49 34 41 42 47 44 43 34 35 35 47 39 49 43 39 34 38 30 53 36 39 42 35 35 38 33 35 51 32 44 39 65 41 47 48 35 33 38 45 40 32 33 52 34 37 51 39 40 44 49 42 43 36 43 53 33 35 45 45 45 35 36 44 49 42 39 46 44 52 45 35 40 45 40 37 40 40 43 40 38 36 36 39 44 44 50 45 35 35 41 51 38 31 39 46 41 44 36 41 45 46 40 45 47 39 28 47 42 42 45 42 50 42 47 41 40 49 40 32 48 34 29 47 47 45 44 31 40 41 29 33 48 38 43 44 41 41 41 38 45 40 48 45 39 55 43 42 42 46 41 50 37 40 49 38 49 47 45 40 39 48 42 50 46 34 43 39 47 39 46 44 31 37 41 44 37 37 40 33 40 61 48 44 33 39 37 37 42 38 28 50 49 33 46 41 40 31 45 45 39 36 33 42 46 37 45 49 36 39 37 46 41 40 35 51 42 30 42 38 56 38 32 50 42 38 48 55 31 58 38 59 25 42 45 47 32 36 38 38 40 39 40 43 37 37 44 43 45 45 37 37 28 47 32 46 40 55 43 53 33 37 39 47 36 30 41 38 35 50 33 39 30 37 43 42 42 33 29 39 47 42 46 42 43 33 45 38 51 44 33 36 37 38 43 32 35 42 32 46 39 49 43 41 34 37 41 35 55 37 43 31 49 44 32 33 33 33 39 40 54 61 43 43 31 41 41 44 37 40 54 31 37 43 51 40 37 48 44 37 32 34 46 33 44 48 43 50 43 39 38 51 41 51 33 28 41 43 37 42 42 43 44 37 44 49 37 44 35 46 44 50 45 40 35 37 43 43 46 30 45 45 33 42 44 35 41 36 45 36 34 40 43 46 43 43 40 51 36 49 34 43 47 36 43 39 35 43 36 46 44 36 44 36 37 46 48 40 41 42 43 44 45 48 41 50 51 41 36 45 34 51 42 43 40 43 51 45 37 55 35 47 45 39 39 36 43 32 35 47 37 41 44 32 36 48 42 38 54 37 36 42 37 38 45 44 49 38 38 32 46 47 45 41 45 44 41 38 54 36 45 53 36 40 36 38 50 34 40 27 38 33 44 39 45 50 40 32 46 35 45 50 37 37 55 38 20 39 51 36 32 38 46 44 41 36 33 28 48 39 47 42 39 45 49 29 47 40 40 45 46 34 54 38 39 50 33 51 36 34 46 44 44 38 41 50 54 43 46 47 51 35 46 40 51 37 36 51 46 42 38 61 38 43 44 51 41 39 40 54 24 42 31 39 36 57 45 39 31 38 38 37 48 45 40 39 36 47 42 34 34 42 52 39 43 45 46 41 44 42 45 44 29 38 37 47 39 44 37 42 52 47 39 42 42 38 26 45 41 48 30 48 40 41 30 48 35 43 32 46 46 44 29 40 52 43 43 42 45 47 39 41 32 40 42 44 31 43 54 56 52 33 26 49 32 48 48 44 38 51 52 47 41 39 47 39 39 37 42 48 44 39 48 38 46 45 36 34 43 37 40 47 37 40 39 45 45 45 45 33 41 43 46 49 45 27 48 50 43 39 52 35 38 35 42 46 32 36 44 30 39 37 33 41 35 46 35 40 49 46 38 46 32 46 50 39 44 35 31 48 49 35 41 31 42 42 56 57 39 30 56 57 43 41 42 28 43 34 45 45 39 41 32 45 40 45 41 29 44 44 53 32 49 33 35 29 51 40 39 38 46 38 37 41 36 36 38 34 35 33 40 44 52 31 47 54 55 50 39 44 42 44 51 46 47 36 40 41 46 34 38 55 58 37 30 32 38 47 40 27 40 52 52 46 40 41 49 41 43 44 38 42 34 45 36 35 40 40 31 45 45 43 27 36 47 40 43 45 31 42 37 46 42 31 36 35 39 36 33 48 33 38 41 38 44 37 47 26 33 31 29 47 42 51 45 51 40 34 49 36 34 36 49 42 42 54 44 45 48 53 39 45 44 43 36 38 32 38 44 43 43 34 52 31 34 51 43 44 27 40 34 54 28 43 45 45 45 33 51 41 46 33 38 45 47 46 31 40 50 40 37 43 46 49 47 39 43 49 35 35 43 39 49 37 43 47 44 46 40 29 50 35 41 37 46 41 37 31 28 36 50 37 42 35 55 48 57 37 44 33 43 42 31 50 51 31 42 47 42 33 33 34 48 56 34 39 51 44 39 43 42 48 62 35 37 36 56 53 36 37 57 40 42 39 48 33 41 51 58 36 53 38 45 42 40 34 44 32 52 49 49 31 48 37 33 54 49 39 55 39 36 41 40 53 36 46 39 53 40 41 42 47 33 38 42 37 46 47 45 36 39 38 45 35 44 41 36 49 43 49 48 37 39 44 43 39 37 32 47 45 47 47 37 43 38 46 39 53 37 47 44 37 36 56 39 47 47 34 36 25 45 39 34 37 48 43 44 36 46 43 36 43 34 38 29 48 38 36 56 30 33 41 39 47 39 44 26 34 39 54 35 42 38 47 42 38 33 48 42 43 40 46 40 41 40 42 42 34 41 39 50 45 46 50 46 41 62 43 40 35 36 37 52 31 31 46 33 41 39 44 39 38 50 47 46 42 41 38 44 42 57 41 34 51 36 46 42 44 38 41 40 38 46 53 51 29 42 39 36 44 42 34 42 48 35 39 49 39 46 34 51 43 31 37 42 39 43 36 38 45 42 45 53 41 41 35 47 35 40 43 44 39 30 45 29 28 36 42 40 42 33 43 43 33 40 47 36 45 29 42 40 35 50 35 33 44 41 46 40 38 45 50 35 37 44 48 43 58 35 49 38 39 49 38 41 39 41 37 47 43 41 36 52 39 42 31 50 46 42 36 49 38 45 35 50 39 36 44 30 50 54 39 32 37 37 43 40 48 54 32 35 51 36 40 46 40 44 48 31 39 37 38 52 36 40 43 46 32 37 36 41 42 35 43 42 33 43 43 35 46 38 49 32 34 35 34 49 28 43 47 39 45 37 54 36 52 44 50 36 31 42 43 44 51 35 42 38 35 48 50 45 32 51 50 42 41 47 48 49 50 38 40 41 39 41 50 42 47 36 44 40 53 56 46 51 43 42 40 44 57 47 55 39 51 40 38 51 45 35 50 34 53 45 42 40 41 36 48 43 46 36 40 54 45 40 56 48 41 35 50 40 43 49 52 46 54 50 32 40 44 42 40 47 36 51 48 39 48 45 52 44 50 31 28 51 45 46 30 48 44 50 40 30 39 45 40 51 48 57 43 40 45 43 42 34 44 42 45 30 34 48 34 46 41 41 38 50 44 43 49 34 41 46 36 33 45 39 39 51 49 51 40 39 44 40 41 38 31 42 44 37 50 50 33 46 50 52 46 44 44 45 28 33 33 48 34 38 35 48 40 29 38 33 46 45 39 43 42 32 30 40 37 33 52 31 58 41 40 44 42 37 57 50 31 39 49 30 50 37 41 46 44 42 42 40 35 44 45 47 43 48 42 56 40 33 38 54 40 53 50 39 47 35 51 41 38 33 47 39 42 40 46 30 43 49 40 50 38 36 53 37 29 33 40 36 37 43 39 39 29 42 45 45 36 36 49 39 42 41 51 39 39 44 50 48 51 43 39 35 41 31 50 32 37 36 34 59 54 27 35 45 36 41 41 43 48 65 41 30 43 43 31 30 38 41 49 35 37 40 54 41 46 37 33 30 47 41 41 34 39 40 50 40 43 50 41 42 39 41 44 37 35 42 33 36 41 51 39 36 36 48 40 47 52 42 40 47 45 37 52 47 43 50 37 31 41 53 41 40 43 46 47 44 53 41 46 43 42 29 45 49 48 46 33 40 36 38 40 44 44 38 39 41 39 29 42 47 29 47 41 45 36 31 44 49 40 45 36 42 34 50 35 45 38 34 34 54 31 39 33 33 47 42 56 43 34 45 30 50 38 38 43 45 46 36 38 39 54 38 35 34 44 51 40 38 40 50 51 36 46 46 44 37 31 48 39 49 33 48 40 38 43 47 47 59 47 49 36 44 45 40 46 47 44 36 39 39 45 51 42 38 41 43 34 48 37 37 33 38 44 40 34 33 44 34 46 45 50 46 47 46 36 32 44 35 28 48 55 48 50 46 45 38 39 37 52 41 53 31 38 45 43 33 52 43 44 51 54 55 39 27 33 38 38 34 40 44 48 48 54 33 44 47 40 36 33 35 42 41 40 43 35 50 39 38 30 43 41 40 52 50 63 51 50 47 40 27 53 42 54 48 48 50 37 50 44 38 39 42 61 32 43 36 45 44 49 49 32 43 39 33 53 40 38 48 43 38 38 31 39 41 43 33 45 43 49 37 55 43 39 50 45 50 43 37 40 58 32 51 34 28 35 39 45 50 42 40 42 21 34 46 51 47 34 36 49 38 47 38 41 37 38 46 45 43 48 34 44 44 33 36 44 36 42 40 42 46 31 36 36 34 41 47 43 40 38 36 38 46 38 41 38 45 49 41 39 36 41 35 56 33 46 42 40 51 49 39 33 46 36 43 43 44 51 43 35 46 34 40 47 39 39 47 42 37 47 53 41 33 36 43 51 34 44 38 49 51 43 31 38 33 46 48 42 38 40 38 45 38 42 34 41 40 57 50 37 47 33 45 42 38 34 43 38 51 50 35 41 39 33 50 48 37 47 46 55 52 45 44 40 41 55 46 45 48 50 54 54 50 34 38 59 22 42 36 37 48 40 43 40 47 33 42 25 40 46 34 37 47 45 45 35 46 43 31 37 51 36 45 42 47 49 39 41 51 58 34 38 30 31 51 53 45 43 36 48 63 42 48 43 38 39 31 48 32 33 37 33 45 50 42 43 55 56 28 32 38 39 47 58 46 56 45 40 52 48 45 39 44 44 42 42 49 33 40 41 36 37 38 40 43 42 34 45 49 33 40 27 44 41 46 32 46 48 37 49 41 24 40 55 33 34 38 33 37 38 43 34 43 44 32 53 46 45 34 39 56 48 43 41 53 40 42 43 45 50 42 38 46 39 28 32 46 36 43 32 44 41 38 44 54 35 38 44 43 31 26 31 46 53 34 38 37 31 43 41 54 41 42 52 39 31 45 39 46 39 50 44 41 39 43 49 41 54 46 45 39 47 43 39 43 43 44 45 41 41 47 48 35 49 50 46 46 36 36 48 41 53 45 45 35 49 54 35 43 45 53 32 34 48 44 51 52 53 36 44 57 51 43 30 42 35 54 45 41 49 43 44 45 27 33 44 43 47 53 51 30 47 40 49 34 49 43 40 68 34 49 42 41 41 39 41 48 41 45 38 59 38 35 44 54 46 43 40 46 32 39 34 38 39 46 37 44 33 36 37 50 59 37 49 57 42 51 30 32 51 34 55 41 57 27 54 51 43 41 51 44 41 31 49 43 47 38 44 50 38 24 49 37 38 35 42 43 46 38 44 38 33 42 33 42 52 40 39 45 46 35 42 27 53 35 46 55 38 38 43 34 36 44 48 41 31 46 38 39 52 41 35 37 50 41 34 40 42 43 45 46 51 46 47 38 44 51 46 27 39 45 47 46 44 44 47 46 45 40 46 38 52 46 43 52 50 41 43 48 28 46 32 47 40 40 35 43 56 40 45 29 46 54 39 38 34 48 37 42 39 35 34 38 35 38 46 39 41 37 41 50 29 44 39 41 50 28 30 48 36 40 46 34 44 30 30 45 38 44 41 33 40 53 38 52 46 47 40 46 27 44 37 38 48 43 53 34 33 48 36 37 54 38 42 53 33 43 42 42 38 38 41 39 46 37 37 46 33 48 44 27 44 48 47 39 43 39 42 27 37 37 29 33 46 51 33 42 42 48 39 47 37 44 52 36 32 37 51 33 30 31 36 43 45 28 59 34 40 39 40 39 42 44 37 35 46 37 30 50 40 31 39 39 40 51 40 39 45 52 39 43 49 32 28 36 33 36 23 54 55 46 36 48 36 50 50 35 47 44 27 38 58 47 36 40 34 34 34 53 44 31 36 38 42 35 43 49 38 41 47 30 35 51 38 35 48 46 38 38 44 47 36 45 38 35 42 46 48 37 38 52 32 45 49 35 33 27 42 46 52 29 47 48 33 45 50 34 31 43 32 49 37 41 32 43 40 39 36 40 43 46 40 43 42 44 45 38 49 41 36 44 31 45 41 40 39 52 43 50 38 33 37 37 45 48 39 44 49 38 52 43 33 52 49 55 38 37 43 52 46 36 51 52 40 42 34 43 30 40 45 35 46 46 54 50 54 46 45 38 38 46 35 28 40 41 40 43 44 43 42 29 45 49 32 49 34 32 35 38</counts>
			</dataPoints>
		</scan>
	</xrdMeasurement>
</xrdMeasurements>