File: data/XRD/XG-Luft/XG-pre/W6821-1D_XG_Luft_pre.xrdml
<xrdMeasurements xmlns="http://www.xrdml.com/XRDMeasurement/2.1" xmlns:xsi="http://www.w3.org/2001/XMLSchema-instance" xsi:schemaLocation="http://www.xrdml.com/XRDMeasurement/2.1 http://www.xrdml.com/XRDMeasurement/2.1/XRDMeasurement.xsd" status="Completed">
	<comment>
		<entry>Configuration=Factory configuration, Owner=User-1, Creation date=7/8/2013 4:01:53 PM</entry>
		<entry>Goniometer=PW3050/65 (Theta/2Theta); Minimum step size 2Theta:0.0001; Minimum step size Omega:0.0001</entry>
		<entry>Sample stage=MRD Cradle; Minimum step size Phi:0.01; Minimum step size Chi:0.01; Minimum step size X:0.01; Minimum step size Y:0.01; Minimum step size Z:0.001</entry>
		<entry>Diffractometer system=XPERT-PRO</entry>
		<entry>Measurement program=C:\PANalytical\Data Collector\Programs\Jorrit\2thom\_absolute_2th-om_10-130deg_PIXscan_56min.xrdmp, Identifier={15BCCF57-2807-42BD-B5B9-ECC0B3DC9284}</entry>
		<entry>Batch program=C:\PANalytical\Data Collector\Programs\SimonL\batch7x_2thom_10-130°_z9.1_x0,10,20,30_y10,20,30_57min.xrdmp, Identifier={089D96B1-A01D-49FF-BCB5-EEA9DFC9CC78}</entry>
	</comment>
	<sample type="To be analyzed">
		<id></id>
		<name></name>
		<preparedBy></preparedBy>
	</sample>
	<xrdMeasurement measurementType="Scan" status="Completed" sampleMode="Reflection">
		<comment>
			<entry>_absolute_2th-om_10-130deg_PIXscan_56min</entry>
			<entry>PHD Lower Level = 4.83 (keV), PHD Upper Level = 11.27 (keV)</entry>
		</comment>
		<usedWavelength intended="K-Alpha 1">
			<kAlpha1 unit="Angstrom">1.5405980</kAlpha1>
			<kAlpha2 unit="Angstrom">1.5444260</kAlpha2>
			<kBeta unit="Angstrom">1.3922500</kBeta>
			<ratioKAlpha2KAlpha1>0.5000</ratioKAlpha2KAlpha1>
		</usedWavelength>
		<incidentBeamPath>
			<radius unit="mm">320.00</radius>
			<xRayTube id="1010048" name="Empyrean Cu LFF HR (9430 033 7310x) DK442154">
				<tension unit="kV">40.0</tension>
				<current unit="mA">40.0</current>
				<anodeMaterial>Cu</anodeMaterial>
				<focus type="Line">
					<length unit="mm">12.0</length>
					<width unit="mm">0.4</width>
					<takeOffAngle unit="deg">4.2</takeOffAngle>
				</focus>
			</xRayTube>
			<xRayMirror id="27010001" name="Inc. Beam Cu W/Si (parabolic MRD)" hybrid="false">
				<crystal type="Graded" shape="Parabolic">W/Si</crystal>
				<acceptanceAngle unit="deg">0.800</acceptanceAngle>
				<length unit="mm">60.0</length>
			</xRayMirror>
			<sollerSlit id="21010002" name="Soller slits 0.04 rad.">
				<opening unit="rad">0.0400</opening>
			</sollerSlit>
			<mask id="22030008" name="Fixed mask 4 mm">
				<distanceToSample unit="mm">220.00</distanceToSample>
				<width unit="mm">4.00</width>
			</mask>
			<divergenceSlit id="22010011" name="Fixed slit 1/32°" xsi:type="fixedDivergenceSlitType">
				<distanceToSample unit="mm">220.00</distanceToSample>
				<height unit="mm">0.05</height>
			</divergenceSlit>
		</incidentBeamPath>
		<diffractedBeamPath>
			<radius unit="mm">320.00</radius>
			<sollerSlit id="21010002" name="Soller slits 0.04 rad.">
				<opening unit="rad">0.0400</opening>
			</sollerSlit>
			<receivingSlit id="22010001" name="Fixed slit 4°">
				<height unit="mm">5.88</height>
			</receivingSlit>
			<detector id="7010017" name="PIXcel3D 1x1 detector" xsi:type="areaDetectorType">
				<phd unit="%">
					<lowerLevel>30.0</lowerLevel>
					<upperLevel>70.0</upperLevel>
				</phd>
				<mode>Scanning</mode>
				<activeChannelsEquatorial>255</activeChannelsEquatorial>
				<activeChannelsAxial>255</activeChannelsAxial>
				<pitchEquatorial unit="mm">0.05500</pitchEquatorial>
				<pitchAxial unit="mm">0.05500</pitchAxial>
				<readOutPeriod unit="seconds">0.135</readOutPeriod>
			</detector>
		</diffractedBeamPath>
		<scan appendNumber="0" mode="Continuous" scanAxis="2Theta-Omega" status="Completed">
			<header>
				<startTimeStamp>2024-10-21T20:28:12+02:00</startTimeStamp>
				<endTimeStamp>2024-10-21T21:24:18+02:00</endTimeStamp>
				<author>
					<name>PRO-MRD</name>
				</author>
				<source>
					<applicationSoftware version="6.1b">Data Collector</applicationSoftware>
					<instrumentControlSoftware version="7.0E 20130304">XPERT-PRO</instrumentControlSoftware>
					<instrumentID>0000000011142674</instrumentID>
				</source>
			</header>
			<dataPoints>
				<positions axis="2Theta" unit="deg">
					<startPosition>9.99826193</startPosition>
					<endPosition>129.99755682</endPosition>
				</positions>
				<positions axis="Omega" unit="deg">
					<startPosition>4.99913096</startPosition>
					<endPosition>64.99877841</endPosition>
				</positions>
				<positions axis="Phi" unit="deg">
					<commonPosition>0.00</commonPosition>
				</positions>
				<positions axis="Chi" unit="deg">
					<commonPosition>0.00</commonPosition>
				</positions>
				<positions axis="X" unit="mm">
					<commonPosition>0.00</commonPosition>
				</positions>
				<positions axis="Y" unit="mm">
					<commonPosition>0.00</commonPosition>
				</positions>
				<positions axis="Z" unit="mm">
					<commonPosition>9.100</commonPosition>
				</positions>
				<commonCountingTime unit="seconds">32.895</commonCountingTime>
				<counts 88 81 95 83 91 100 88 98 90 96 91 96 90 98 102 93 94 92 104 102 70 95 74 92 81 99 85 75 75 82 89 82 77 93 78 82 76 79 98 92 86 91 76 86 84 84 77 90 84 84 81 80 82 86 88 80 99 83 84 78 81 75 84 101 67 95 86 66 68 70 69 85 79 101 70 74 76 71 90 87 68 95 83 90 84 83 96 80 80 78 90 82 94 83 76 90 73 83 70 90 86 83 93 80 86 96 85 80 73 78 79 70 74 86 82 89 105 84 77 89 71 78 90 76 59 99 85 82 103 78 82 79 83 88 77 112 96 88 79 80 74 67 88 73 87 73 108 80 83 82 94 76 83 89 74 62 77 83 70 81 98 71 75 71 62 84 76 91 80 87 81 73 79 76 63 85 81 76 86 89 85 95 79 90 70 80 68 74 65 81 73 79 58 71 81 86 82 81 96 80 72 73 87 83 97 83 61 74 85 71 73 81 78 94 86 87 67 82 67 84 92 80 67 75 86 75 76 68 79 75 83 82 69 76 59 82 76 75 79 57 75 68 76 72 77 65 79 72 75 79 71 68 76 87 77 83 79 78 72 89 69 57 64 85 74 79 51 71 87 82 73 88 59 71 68 83 68 76 74 75 86 76 71 69 72 59 70 68 68 79 62 65 77 71 69 69 71 65 67 73 69 78 77 61 68 84 60 76 75 73 72 65 67 82 67 69 79 71 85 76 54 72 66 60 80 67 74 63 83 72 69 70 67 71 65 70 76 78 62 79 72 73 69 62 75 55 56 71 83 59 74 84 61 70 81 79 73 55 69 77 58 76 73 70 64 66 51 58 57 74 52 62 63 79 71 70 75 76 73 56 61 68 70 68 77 61 81 73 61 63 72 62 71 72 92 70 67 70 73 81 61 72 64 59 75 53 60 76 69 69 62 74 52 51 67 75 62 74 64 56 65 69 60 79 67 60 73 65 61 69 60 84 67 69 62 60 72 42 52 59 60 70 65 64 71 71 78 59 69 75 41 55 67 63 60 64 66 50 56 58 66 43 71 68 54 60 70 49 69 78 77 64 64 61 65 62 64 56 64 71 59 67 60 51 59 63 53 56 62 61 57 72 64 64 61 70 65 67 70 76 63 81 61 70 64 50 47 64 57 56 65 58 62 49 63 52 55 65 55 61 65 66 68 57 60 54 64 67 56 59 58 51 63 51 71 66 64 65 61 49 68 64 58 60 63 54 75 67 50 79 46 70 69 65 60 68 50 61 55 53 65 57 58 69 59 65 55 71 70 61 50 64 58 55 51 69 64 65 67 72 67 64 69 57 58 56 65 60 72 53 56 61 65 45 59 53 57 66 68 59 65 70 58 64 61 50 62 49 64 71 62 61 64 67 51 71 60 62 62 68 61 63 62 68 62 57 64 60 53 82 55 58 65 57 49 55 68 73 60 59 57 59 62 71 61 59 64 77 56 53 69 52 78 63 53 55 54 64 53 60 74 64 65 64 58 52 76 49 60 41 57 64 57 56 57 64 62 57 59 61 60 71 63 48 56 57 62 55 61 69 65 80 66 62 60 66 37 49 56 55 48 72 66 63 58 56 59 62 51 66 51 51 64 63 60 66 62 55 41 62 56 53 57 64 67 67 53 51 59 41 63 75 65 52 45 60 49 62 70 59 58 70 67 55 48 53 54 42 71 51 59 52 54 62 63 78 72 72 66 42 53 57 73 58 55 74 58 57 49 58 52 71 51 47 59 57 69 62 64 53 58 66 47 77 48 64 48 60 48 50 59 58 67 73 66 63 70 58 51 65 71 45 50 51 62 52 58 54 61 63 54 49 59 55 65 62 62 55 55 60 61 58 41 62 57 70 50 59 56 68 50 66 54 73 54 51 46 59 57 63 50 66 57 56 58 79 72 59 48 75 51 61 66 56 57 67 40 58 64 55 57 76 77 57 54 51 64 55 80 60 55 61 57 56 66 61 51 56 74 60 59 72 60 68 72 64 54 48 62 70 55 59 62 62 42 61 59 52 62 55 52 55 59 43 77 78 58 50 66 58 69 52 56 64 66 57 48 61 56 56 72 69 66 67 57 65 48 58 68 58 60 48 58 55 50 56 60 70 60 56 71 65 46 53 63 59 61 67 58 48 53 60 56 54 43 59 62 67 45 60 53 53 45 53 49 60 66 49 55 53 67 64 62 58 62 58 60 46 56 56 57 61 47 74 58 61 63 71 57 69 58 48 69 54 74 42 69 58 69 54 68 43 70 61 55 65 79 51 66 47 61 53 56 56 64 66 70 66 70 62 67 45 61 55 54 53 46 63 55 65 66 61 58 60 60 65 64 47 71 48 69 43 50 60 70 72 71 57 56 56 51 65 65 60 55 59 59 61 49 67 63 45 61 53 56 58 71 58 61 54 60 72 51 61 58 72 73 55 55 52 54 58 53 54 63 62 62 72 57 67 55 58 80 64 61 66 70 58 71 68 67 72 64 63 71 62 64 67 71 59 59 52 50 60 56 68 58 57 50 69 68 72 66 46 62 54 72 52 61 67 57 52 66 59 67 77 52 68 68 60 65 63 82 62 70 66 55 74 59 58 68 67 54 66 60 55 56 60 55 68 60 71 60 84 76 55 65 78 51 71 54 63 81 59 57 70 65 73 61 60 63 56 57 52 70 59 53 68 53 50 60 58 49 60 75 58 61 67 70 57 58 70 68 62 62 71 67 57 71 54 58 61 67 61 63 75 54 61 67 69 65 74 71 66 65 71 58 54 74 70 42 59 76 73 54 74 79 53 71 47 73 68 67 54 57 52 85 90 69 61 59 53 48 79 57 65 53 50 78 51 70 49 51 58 65 67 54 64 67 76 73 59 88 61 67 49 60 65 74 61 58 78 70 58 54 68 67 61 64 64 62 69 55 66 57 64 66 58 63 55 73 66 65 69 67 73 56 60 67 59 60 63 74 68 67 71 61 80 65 70 44 57 62 51 60 61 66 60 64 74 59 64 52 55 67 63 67 60 62 72 63 61 73 67 55 53 48 71 68 60 65 67 63 74 58 66 62 73 60 66 66 71 64 71 69 69 71 52 63 63 65 57 64 56 51 63 69 56 63 64 62 62 68 58 68 62 58 73 65 59 68 69 60 75 57 73 61 52 71 65 66 54 67 68 50 49 65 66 59 57 57 68 72 62 51 54 64 58 45 67 58 63 64 65 65 65 55 66 75 71 69 68 65 69 63 72 50 75 54 84 53 56 65 58 55 57 60 61 60 54 63 59 70 56 59 60 56 61 56 56 56 68 55 65 59 55 68 58 70 58 41 47 63 54 49 52 64 47 59 62 54 57 55 47 45 57 63 66 62 48 62 66 49 50 83 73 64 62 53 56 67 63 75 64 65 71 69 72 63 69 59 69 55 61 61 61 63 67 57 72 73 66 56 65 52 53 65 67 58 66 61 58 69 54 58 69 64 67 57 67 59 62 60 61 64 65 53 54 59 49 73 64 42 68 70 51 71 64 63 54 58 68 59 55 62 53 57 78 64 75 63 63 56 51 71 64 67 50 63 68 66 56 63 60 52 55 62 69 68 72 45 58 62 57 50 68 56 59 61 54 66 53 69 69 60 58 51 69 68 66 56 65 60 71 73 70 66 66 53 51 59 52 53 54 52 56 64 57 51 56 66 50 59 47 52 58 54 59 70 64 60 50 52 57 58 53 60 62 61 50 65 68 69 55 54 53 63 63 60 64 71 60 63 68 48 46 49 51 60 62 57 52 56 37 66 59 60 56 65 58 60 55 40 67 56 66 60 51 64 61 67 46 56 61 66 65 65 63 58 64 51 62 63 50 47 60 60 62 58 63 47 56 50 60 60 62 58 45 54 52 34 58 42 59 63 53 58 59 60 68 65 47 70 44 56 44 42 50 62 55 52 65 53 65 57 71 51 47 65 50 63 64 59 67 58 48 61 62 50 58 49 50 63 61 43 58 63 65 67 53 60 53 58 49 51 59 71 72 65 62 62 52 58 57 54 55 52 55 50 59 60 43 50 41 57 58 56 60 60 56 48 60 63 62 54 62 54 55 63 42 44 69 48 64 56 49 51 46 53 53 53 59 47 47 59 61 74 51 62 39 57 59 46 51 54 55 73 37 48 57 52 62 59 46 58 52 49 56 59 66 39 53 52 55 51 54 57 45 57 43 63 61 56 66 39 61 56 62 56 61 56 60 66 51 68 47 53 59 44 46 50 45 67 49 50 70 60 61 70 59 50 57 51 47 50 64 52 56 56 55 72 64 48 46 50 46 45 55 50 54 50 57 59 59 56 64 49 54 64 52 41 65 52 49 48 57 69 63 56 43 61 51 51 56 40 51 66 50 48 52 46 51 50 44 57 48 50 61 51 63 41 55 41 47 44 59 56 54 62 58 57 61 59 57 46 60 60 51 49 44 56 60 61 46 60 56 48 62 52 45 46 60 49 68 44 50 55 55 60 65 57 55 59 62 43 55 58 50 50 51 56 48 42 57 54 59 37 51 56 63 47 45 59 56 62 53 47 46 55 50 54 54 51 53 54 65 49 55 66 63 54 41 40 53 48 48 64 59 50 45 54 49 50 66 51 72 62 45 55 42 43 53 41 46 57 52 42 52 45 44 41 42 58 53 44 48 44 58 62 57 44 55 52 62 60 61 52 57 55 54 61 62 40 56 51 48 49 55 52 55 45 45 56 48 38 53 54 50 54 61 58 40 53 60 59 48 60 47 46 56 46 50 60 44 47 41 63 56 56 50 44 56 48 52 49 61 39 47 60 55 53 44 56 53 64 48 52 43 48 55 45 50 60 64 47 58 62 54 58 49 58 49 50 47 46 54 45 49 53 58 51 47 63 59 55 48 53 49 66 55 38 45 51 53 57 65 36 40 51 56 50 47 49 60 42 53 49 60 52 34 63 58 58 49 48 42 50 62 48 63 54 38 59 55 76 57 54 50 63 54 49 59 68 46 35 48 69 54 53 51 42 46 51 55 56 53 58 67 58 52 56 54 46 51 46 50 50 57 58 43 54 65 40 30 49 43 69 52 48 56 54 39 37 61 66 53 53 54 58 51 51 46 42 50 47 49 47 44 64 56 52 46 59 55 73 67 47 61 66 54 50 42 40 42 48 34 54 48 55 51 56 50 37 50 50 54 59 54 42 50 56 55 43 59 59 44 41 40 36 62 55 61 51 48 48 52 47 51 49 56 55 41 51 49 69 61 39 51 52 37 47 58 72 55 49 52 56 50 47 48 43 54 42 59 49 56 41 55 52 50 51 39 51 53 39 57 42 49 54 51 49 54 44 40 50 58 37 43 41 61 54 64 53 48 46 45 53 42 39 56 71 36 37 63 53 50 34 48 62 48 32 58 55 39 55 53 54 59 49 59 52 54 56 52 52 52 60 51 46 51 53 55 43 58 54 46 52 56 62 54 44 57 48 53 62 50 56 45 46 50 50 44 38 53 60 49 43 46 64 48 41 68 41 46 46 55 54 54 46 53 59 42 51 47 67 60 61 52 43 57 45 57 42 48 48 60 61 57 53 52 56 45 56 49 43 41 43 56 56 39 44 55 50 52 49 33 53 65 52 37 45 50 60 57 54 51 45 48 60 50 47 46 56 46 48 57 52 51 56 50 57 50 67 50 52 46 64 62 46 56 59 44 37 50 62 50 50 55 44 48 56 44 46 56 54 47 47 53 39 60 47 51 51 52 43 51 48 45 39 51 47 46 51 48 52 60 68 52 43 40 51 55 48 68 49 71 50 41 52 45 57 48 56 60 46 51 59 57 49 61 61 52 51 50 57 45 34 48 61 54 39 63 52 42 49 53 48 49 38 53 39 48 32 52 57 43 42 57 59 36 42 65 55 44 49 54 50 54 52 52 40 40 47 47 59 51 37 44 61 45 38 50 50 55 64 50 48 43 65 46 55 42 49 55 54 44 43 52 40 49 51 49 48 45 38 49 48 48 50 46 53 40 43 40 44 53 52 48 52 42 60 41 51 58 53 50 46 55 54 44 49 50 39 41 61 47 47 53 57 60 49 44 43 55 33 37 56 46 61 40 54 44 47 45 48 54 46 50 57 62 41 43 43 57 45 53 45 44 59 48 50 47 48 54 45 51 47 46 46 39 71 55 52 49 57 54 58 45 59 47 50 44 52 57 50 53 44 40 45 37 53 53 48 56 52 55 50 51 41 41 45 54 56 40 43 59 41 42 40 44 49 48 45 74 49 56 46 56 61 53 38 46 49 52 47 59 36 51 53 50 49 51 50 54 55 58 52 47 51 56 46 43 43 49 60 50 45 63 59 41 52 34 55 52 50 56 53 35 53 66 46 58 44 44 53 41 63 52 49 61 53 43 52 46 52 42 44 61 40 55 53 47 50 51 49 36 50 48 50 50 38 53 47 46 50 45 58 54 49 50 47 48 46 46 52 35 45 57 47 49 55 53 52 41 40 39 43 40 49 58 53 47 58 46 50 48 56 56 44 56 40 58 44 46 44 47 50 47 52 47 51 41 52 52 47 56 56 50 48 58 51 50 45 35 39 58 50 54 55 55 58 49 60 36 52 49 44 40 52 42 44 57 59 53 49 44 49 54 43 36 52 46 49 60 32 51 55 52 57 61 56 40 47 40 59 49 39 50 51 51 37 49 51 49 57 51 46 58 44 59 47 51 48 50 45 53 49 48 45 55 43 44 46 30 71 59 54 36 47 55 61 54 58 51 60 50 43 52 61 55 46 41 56 45 52 59 42 36 56 56 51 38 65 46 41 58 51 53 56 37 45 43 45 66 57 54 50 46 57 55 42 58 40 54 58 41 57 56 63 46 44 45 54 51 40 39 49 44 59 49 53 53 46 58 56 38 49 54 41 46 53 51 50 43 41 44 51 61 53 48 53 41 60 39 55 56 40 51 42 55 54 46 47 43 46 50 56 49 62 55 50 60 54 55 45 57 52 55 36 48 50 53 53 52 37 44 51 60 42 50 56 52 46 48 55 48 44 63 49 40 39 61 60 45 53 44 44 71 56 52 39 48 52 40 56 57 52 54 47 60 44 47 63 42 63 47 43 62 62 47 49 44 49 62 54 56 51 51 53 51 56 55 48 58 58 53 48 53 41 62 52 50 45 43 61 54 48 50 55 58 49 43 52 46 52 39 41 53 50 49 48 54 62 63 43 41 46 49 54 58 48 54 57 58 42 65 45 52 48 52 51 42 70 46 64 57 51 60 52 55 64 52 54 47 47 47 60 61 50 62 63 51 59 53 65 55 40 40 50 54 47 53 45 48 42 52 53 51 55 54 46 43 57 47 66 51 46 47 54 36 51 53 50 44 52 42 50 61 45 46 55 52 48 55 44 57 49 61 46 48 53 53 39 65 52 56 44 46 52 44 48 54 65 56 55 51 47 50 63 38 52 57 44 48 49 55 52 53 40 50 52 50 52 58 64 39 46 56 60 53 61 48 59 49 58 54 48 63 40 46 58 55 45 56 41 54 58 50 50 43 56 64 43 50 57 58 44 52 48 55 49 43 42 51 42 51 53 44 67 56 49 54 55 48 45 52 43 54 63 48 65 57 55 48 54 44 59 64 77 63 39 53 49 47 45 61 51 61 44 51 60 58 51 60 64 46 48 52 53 57 54 54 51 57 78 60 55 42 49 56 63 47 61 60 57 62 50 48 48 53 60 59 53 57 66 55 62 61 61 45 64 48 50 62 54 64 63 68 55 73 64 62 73 60 63 51 72 55 62 66 78 58 58 61 61 76 69 62 81 63 76 74 77 88 78 70 76 87 68 85 88 88 91 97 77 96 91 85 110 109 110 104 115 88 104 107 107 111 91 112 89 84 98 92 92 94 105 93 81 90 81 77 66 78 72 77 63 69 78 92 79 75 66 62 73 58 59 51 60 68 57 61 67 75 52 59 58 60 59 46 61 56 61 58 52 59 47 59 54 66 61 51 56 66 66 51 54 49 65 52 48 52 49 57 45 56 47 52 45 61 53 60 67 42 48 58 57 50 61 51 71 54 42 60 68 46 51 48 56 46 55 45 56 48 46 57 44 54 46 58 58 50 56 71 48 61 51 67 43 57 61 53 61 45 53 46 59 44 64 63 68 47 59 55 54 47 51 53 47 50 48 59 53 55 45 58 57 48 49 47 59 50 44 50 53 54 54 66 57 71 58 64 52 53 55 63 58 61 62 55 46 56 55 57 65 56 54 58 56 69 40 61 51 53 50 48 56 49 55 59 49 43 53 53 42 54 60 47 55 45 55 58 47 63 57 49 49 49 67 60 55 58 49 53 47 57 49 60 69 43 50 60 44 57 59 50 59 60 59 53 63 42 43 48 51 57 68 44 45 42 54 64 56 57 59 66 58 64 45 52 68 43 54 40 68 50 58 60 57 59 54 54 47 60 39 52 33 61 57 54 49 67 40 56 48 56 54 56 58 64 60 52 58 54 45 49 58 61 59 55 55 45 54 45 47 48 45 62 63 34 57 65 50 48 63 58 31 63 45 36 43 50 55 61 54 55 54 62 58 62 42 58 60 48 45 55 54 48 49 52 54 61 48 57 59 32 56 44 45 49 58 51 58 55 45 49 52 55 56 57 52 50 71 63 58 45 60 62 51 43 60 48 56 44 52 48 45 64 55 47 49 51 58 60 47 46 54 50 52 49 58 58 55 61 48 33 35 53 43 47 44 52 56 63 59 64 42 55 55 62 49 53 51 47 49 53 41 52 44 49 49 52 40 59 53 58 58 46 36 64 50 39 65 61 53 40 47 44 57 47 51 61 51 37 56 45 59 51 44 42 46 41 60 52 45 53 46 56 45 49 57 54 46 63 50 51 48 55 47 43 57 43 46 67 60 62 59 52 39 61 56 55 43 49 44 58 61 49 45 50 66 52 54 57 52 57 61 39 63 61 33 54 48 53 64 51 53 50 50 63 52 64 54 42 54 49 50 50 46 55 51 41 61 53 45 56 60 67 44 52 40 57 45 62 47 64 50 36 52 62 50 41 40 51 53 54 56 38 57 51 42 53 42 49 53 50 57 44 55 40 53 47 54 70 39 50 57 50 43 46 59 63 58 48 63 57 50 63 54 42 52 56 53 55 57 57 48 45 39 65 44 54 44 56 38 50 69 42 62 54 55 49 59 57 36 52 54 46 54 45 46 49 54 53 45 58 50 64 55 52 49 45 45 39 51 44 50 50 48 51 45 48 49 42 46 62 49 49 45 55 46 68 59 47 60 52 47 55 47 53 49 52 54 56 60 45 48 48 39 39 48 48 58 58 61 43 51 45 39 43 57 46 49 55 49 52 40 61 56 48 57 39 48 62 57 60 56 49 52 49 50 42 64 46 58 47 45 50 53 47 51 46 64 39 52 55 55 46 50 69 51 62 43 66 57 51 50 48 47 48 51 52 49 36 55 51 46 53 54 56 62 53 46 44 55 43 55 44 38 65 42 59 45 50 47 58 67 38 49 54 45 49 41 58 56 55 52 51 62 52 59 59 43 50 55 51 61 47 52 64 46 48 56 54 53 41 55 41 61 44 45 44 52 41 52 46 42 70 44 48 40 59 51 47 61 53 40 46 47 50 57 43 52 49 56 52 40 46 58 51 48 38 54 45 62 62 51 54 52 47 54 60 58 57 49 46 52 66 52 49 44 47 35 32 47 53 47 40 45 61 48 63 43 61 42 56 53 65 54 51 48 56 51 58 48 47 52 45 67 40 27 51 45 46 60 43 36 59 44 48 61 51 46 49 66 39 57 55 45 62 49 51 48 60 57 59 54 56 63 51 59 47 47 62 45 51 42 49 43 50 51 52 44 50 51 44 39 45 45 65 46 53 46 47 43 41 52 54 62 47 53 45 51 44 69 50 50 52 50 50 53 51 66 49 52 36 47 47 43 53 48 49 27 60 51 57 64 64 55 49 57 56 60 65 51 54 45 43 45 53 48 64 55 47 45 57 48 59 53 47 46 62 55 52 56 51 64 58 53 57 51 52 43 40 48 58 47 41 50 44 43 47 48 64 54 43 51 48 40 55 49 67 41 53 46 47 53 66 61 60 61 52 55 53 48 53 42 53 55 64 48 44 46 55 54 49 52 53 56 57 57 53 36 54 44 50 49 61 47 59 52 56 44 49 47 55 49 48 56 56 60 62 58 55 66 55 56 49 58 46 45 45 50 48 51 54 65 55 43 50 61 53 48 61 50 52 61 60 59 42 63 59 67 51 54 46 47 62 56 53 48 55 50 43 50 38 58 53 52 48 65 54 41 55 50 55 53 47 54 55 46 55 46 51 48 50 57 61 51 54 48 39 44 54 59 61 57 59 52 43 47 52 42 59 45 50 54 43 53 49 53 51 47 34 47 39 50 51 43 42 56 45 51 52 52 64 46 50 55 37 36 53 52 50 46 44 49 55 60 47 48 46 61 57 48 48 50 47 55 49 54 54 50 52 52 52 46 44 53 49 47 48 66 43 55 68 59 45 47 54 47 67 61 43 45 52 40 41 52 51 45 54 47 51 54 42 56 44 41 51 50 58 62 46 52 49 54 57 53 55 49 54 49 56 43 45 46 64 64 56 66 41 59 57 53 42 49 52 62 56 46 51 37 59 42 46 50 45 52 55 47 54 61 67 50 53 54 45 44 50 56 51 44 60 46 59 50 41 45 48 41 49 53 48 43 54 52 47 40 53 53 51 49 58 54 67 44 50 52 49 43 51 51 56 48 51 54 56 59 50 41 61 60 36 67 45 56 60 58 40 51 45 51 58 60 62 53 48 44 49 47 55 42 56 63 60 59 52 48 49 60 40 60 56 60 58 37 51 52 60 44 54 50 49 48 45 33 55 46 42 52 59 46 43 59 58 49 38 53 64 50 45 56 53 48 60 41 52 51 53 51 53 46 67 53 48 47 54 46 56 74 54 59 49 63 34 40 38 58 64 48 56 52 57 61 56 64 50 48 48 39 48 59 44 53 39 56 46 58 44 61 53 42 49 52 54 46 48 39 56 49 41 63 54 43 54 48 51 51 55 59 76 66 56 52 34 51 39 54 42 57 50 51 50 49 55 41 54 64 51 45 47 51 58 56 54 58 61 37 44 63 55 61 56 44 51 54 50 53 52 57 56 55 51 60 54 56 53 56 58 52 50 60 47 54 50 48 48 48 58 56 47 45 42 52 55 52 49 54 43 51 56 47 60 73 38 66 45 46 57 48 59 35 58 43 39 59 49 51 55 46 49 54 40 50 53 41 60 41 50 46 49 60 50 39 57 50 63 53 39 51 63 55 50 50 44 59 45 53 46 52 49 48 55 65 48 54 42 58 43 64 35 59 42 55 52 41 56 56 63 52 49 59 60 50 49 56 63 39 53 55 49 56 62 58 52 55 50 57 71 49 51 53 54 64 43 55 47 51 45 57 47 57 42 54 46 55 59 42 47 48 48 57 56 48 42 44 58 55 38 49 42 55 58 59 59 43 55 45 46 54 43 51 44 53 39 50 59 59 50 44 41 54 38 39 39 51 54 58 46 48 54 45 56 54 38 45 64 50 32 53 35 45 46 48 47 43 43 61 49 49 46 43 44 56 47 54 47 56 74 60 58 47 54 56 49 47 54 52 59 53 50 46 46 59 56 63 57 43 55 40 54 54 72 53 52 55 58 48 54 60 55 55 41 54 41 49 49 59 41 72 53 52 48 59 62 54 57 66 45 57 59 58 52 53 46 44 57 45 53 45 46 45 41 51 48 44 56 46 66 65 46 66 45 63 62 51 48 60 72 58 59 63 56 55 57 60 54 50 64 57 53 45 54 59 44 53 47 52 51 53 63 59 51 42 48 51 55 58 49 59 64 44 49 49 42 48 52 51 53 58 62 45 57 48 43 53 63 38 52 40 49 52 48 52 51 56 50 52 45 48 57 54 44 59 59 44 54 58 36 58 46 50 46 70 53 46 45 60 61 46 66 46 51 50 65 52 51 55 46 49 51 53 56 61 56 49 61 48 53 67 43 51 59 45 51 55 51 47 63 55 57 53 67 48 56 56 44 65 58 52 48 46 42 48 52 51 59 62 51 59 63 57 43 49 69 67 72 47 55 54 45 61 46 53 50 47 36 56 56 41 40 37 51 47 49 55 62 53 54 49 44 52 46 36 55 69 54 53 53 55 53 56 55 49 47 47 52 51 50 52 49 44 55 58 55 52 48 50 49 81 52 70 50 57 54 47 47 59 49 55 54 63 50 54 60 58 59 49 41 55 57 60 58 54 55 61 40 57 53 54 44 56 55 59 62 58 41 41 59 63 43 55 67 54 55 47 54 54 49 36 58 61 46 58 70 51 41 47 62 49 62 65 57 54 53 57 51 62 53 52 66 53 56 48 58 46 48 48 50 49 55 56 47 46 44 51 62 50 43 52 65 58 65 45 44 52 53 50 66 51 51 51 46 58 58 47 49 44 54 43 57 54 60 59 56 58 65 55 52 57 43 52 56 59 58 50 37 52 54 46 57 68 53 60 59 54 53 37 58 61 44 57 54 56 48 58 49 62 61 41 62 57 68 58 52 59 56 55 61 63 51 46 51 57 59 46 66 53 46 53 49 43 60 57 52 57 52 59 48 55 44 64 64 53 54 52 56 51 56 56 47 55 45 37 49 50 43 50 62 53 51 55 51 61 50 46 54 58 55 49 61 58 54 52 57 49 65 41 57 33 56 66 58 42 49 48 41 51 64 43 72 48 48 50 68 52 54 35 49 44 53 69 44 52 56 57 57 58 40 62 58 46 47 53 55 46 51 58 42 55 59 57 49 44 53 46 71 55 59 68 43 54 59 45 42 48 49 48 52 49 44 46 62 49 58 57 44 52 61 60 59 40 51 52 55 51 65 53 65 56 62 61 53 48 59 57 48 50 54 58 43 43 49 43 40 55 40 55 60 57 40 47 40 54 57 36 54 58 48 47 58 62 54 56 48 62 34 56 52 53 55 50 40 50 59 67 50 51 62 53 51 66 61 65 62 54 58 51 48 53 52 44 55 57 37 51 46 58 43 46 55 37 53 51 48 52 54 55 50 56 30 53 57 39 63 48 42 44 53 33 54 35 53 50 47 62 62 42 40 51 54 63 48 64 52 47 36 57 53 47 57 47 51 51 41 50 51 55 48 58 52 48 63 55 48 58 69 48 60 54 47 57 43 52 57 55 46 51 51 59 56 54 52 51 44 54 69 55 68 53 57 41 49 41 56 55 66 42 47 56 46 50 45 50 58 46 57 51 48 49 62 65 49 50 62 53 46 38 57 52 59 56 53 48 53 43 49 49 54 58 58 49 66 54 49 71 57 60 50 52 47 45 49 53 56 51 51 38 57 48 54 47 42 49 48 44 53 56 49 44 56 40 49 39 54 64 51 54 48 40 51 56 53 46 37 53 55 45 56 51 53 66 52 60 51 36 51 69 44 60 58 52 53 57 59 42 51 55 59 47 37 54 37 49 47 50 53 45 59 46 63 59 43 48 64 57 58 44 59 53 47 45 50 64 45 53 64 65 47 62 49 55 53 50 60 59 46 47 51 54 43 47 56 50 44 53 59 65 54 52 56 47 49 49 47 57 55 47 53 54 44 49 72 45 59 65 40 62 43 50 51 47 60 46 66 57 47 46 43 49 61 43 45 53 53 56 54 56 54 56 48 55 62 70 40 49 46 54 41 40 53 54 51 50 53 56 60 53 50 54 43 48 48 59 45 59 44 53 51 56 52 48 50 58 46 59 55 58 51 56 66 49 57 50 54 54 63 48 50 53 49 62 48 50 50 66 56 49 46 44 59 42 46 44 45 44 50 47 54 50 64 44 65 52 64 55 44 58 49 60 51 40 45 50 63 59 61 49 52 55 62 37 60 42 49 50 46 60 57 55 43 41 62 43 47 48 52 57 57 50 50 65 62 50 64 38 49 58 49 45 38 50 58 62 40 44 61 63 47 49 46 50 54 48 60 58 63 53 48 51 37 61 47 47 40 51 42 46 58 50 50 51 53 58 46 46 51 56 54 56 57 51 57 61 57 55 46 43 36 65 53 52 52 53 51 50 56 48 53 68 43 50 41 54 52 49 50 43 62 66 54 57 52 51 49 42 57 73 34 67 67 49 69 50 58 63 65 63 54 40 56 54 45 67 49 62 56 54 55 53 60 40 63 58 60 54 48 43 46 52 50 59 48 56 46 56 59 55 45 50 55 52 56 52 56 56 63 49 43 48 57 62 55 49 57 52 51 62 53 61 73 57 40 55 53 43 54 46 48 56 41 47 59 42 51 52 46 50 57 52 50 59 60 52 49 39 51 51 52 46 48 44 48 55 53 51 47 54 56 53 42 60 40 55 49 40 45 45 46 62 57 48 42 60 45 53 33 54 63 66 60 56 44 59 38 58 62 46 60 61 61 49 47 50 46 53 51 53 48 56 64 47 56 44 58 54 48 68 50 68 65 54 57 49 56 44 56 63 51 55 67 48 40 42 47 53 63 49 60 61 55 51 41 52 42 56 51 58 59 54 57 53 46 52 54 48 50 38 52 66 43 60 43 41 49 58 55 48 60 54 54 53 64 53 59 55 48 47 49 34 53 48 38 47 57 57 50 60 61 54 49 55 60 49 50 51 46 62 48 52 55 53 53 52 44 65 54 41 54 58 60 45 57 55 51 47 45 50 52 58 45 60 56 50 44 59 54 47 45 45 57 50 61 29 53 58 61 60 53 50 59 61 65 57 52 47 46 46 42 46 55 64 64 55 36 56 44 42 70 63 60 49 54 63 52 55 54 47 63 48 50 56 61 55 64 53 49 49 40 37 47 42 53 65 57 65 49 48 66 42 46 46 46 62 40 45 46 54 55 57 59 54 46 60 55 61 55 47 52 47 59 47 49 62 54 50 61 58 42 58 50 57 53 54 63 40 57 61 53 65 58 50 46 56 50 57 46 53 54 56 58 48 43 43 42 48 49 45 44 60 52 55 65 59 46 50 54 47 45 57 53 37 59 58 47 50 61 61 42 57 59 62 51 53 57 41 48 56 47 46 45 53 62 48 66 45 66 61 54 55 36 58 49 50 63 42 52 49 46 54 55 52 41 51 60 61 67 52 56 40 59 46 52 48 64 63 52 58 58 48 53 52 50 55 57 48 40 44 49 53 66 45 54 58 49 41 57 47 48 54 49 52 51 44 54 42 61 50 56 47 57 52 37 46 75 51 70 58 61 49 35 56 58 46 49 45 57 45 49 51 38 59 49 50 41 53 62 64 67 57 61 57 57 50 46 50 53 63 53 59 39 55 59 62 56 64 67 56 58 48 44 47 59 53 42 58 54 54 52 62 54 58 52 42 46 49 46 49 44 54 48 41 59 49 51 50 63 67 51 53 41 51 55 53 55 50 46 52 52 52 60 48 59 53 56 41 60 50 47 54 46 50 38 59 60 51 59 48 51 60 47 58 60 48 50 56 48 65 60 65 52 66 47 52 51 42 50 42 58 63 45 42 48 48 56 67 48 57 47 47 46 41 44 61 61 52 62 49 57 56 45 45 47 59 67 55 46 70 55 46 52 59 52 52 54 52 52 51 47 47 60 57 55 55 53 64 62 56 47 42 40 46 56 49 55 54 54 68 58 48 64 76 43 45 66 57 58 42 55 51 48 53 59 44 57 39 56 49 64 49 59 47 52 51 56 50 48 59 52 41 51 51 43 56 55 50 53 50 46 50 56 61 51 46 41 47 52 51 64 52 59 49 57 52 53 42 49 53 48 52 49 45 61 72 62 51 55 41 67 42 58 56 57 60 46 60 58 43 45 50 60 50 56 50 49 54 44 58 54 50 57 58 57 59 51 46 54 34 58 42 49 65 47 49 66 42 45 47 63 61 46 50 55 40 39 46 53 57 44 60 59 45 60 61 60 54 55 59 51 56 56 53 49 46 51 57 67 57 62 44 58 54 46 57 67 60 41 55 54 50 55 65 45 47 51 54 48 51 65 44 65 51 44 46 42 48 61 52 63 46 60 48 54 56 58 59 68 46 58 55 48 50 49 42 66 56 59 61 43 49 47 50 64 39 69 39 41 52 39 35 47 60 50 50 54 52 52 48 60 45 49 52 44 46 71 56 56 54 59 57 64 55 55 51 54 51 56 61 59 64 45 45 54 44 44 61 64 47 46 65 60 58 48 45 62 60 51 58 58 48 48 54 57 59 49 33 55 45 48 50 56 53 67 49 53 57 58 59 57 59 54 58 45 55 51 39 47 57 60 46 44 49 58 48 57 46 44 65 73 50 46 60 53 59 60 65 46 49 63 37 65 38 43 51 48 44 64 47 65 62 60 43 55 56 60 55 56 52 66 59 48 55 54 43 57 56 59 53 56 50 50 57 48 56 58 51 55 56 56 55 65 44 74 60 72 54 68 57 70 72 57 60 64 54 68 67 58 57 63 55 82 71 58 61 66 69 57 53 71 45 60 62 63 55 68 62 59 55 60 59 64 54 50 44 62 53 51 60 49 58 59 66 49 51 53 63 57 55 64 49 60 57 65 63 62 55 46 49 55 56 64 60 58 59 70 64 53 62 50 52 57 58 64 63 46 43 52 43 53 55 48 63 69 59 52 58 57 49 64 47 42 62 49 56 47 48 57 52 54 58 55 50 57 49 44 53 43 51 52 50 47 55 44 34 58 51 60 37 50 56 47 57 56 48 47 55 54 43 44 49 47 58 55 46 53 49 52 65 51 47 42 37 67 62 58 51 63 38 56 64 54 45 57 55 67 48 38 60 75 44 55 58 53 57 44 44 55 51 62 44 48 52 84 43 34 51 39 47 44 57 49 50 51 46 52 47 54 46 55 50 54 38 68 56 66 49 50 56 53 54 44 55 46 52 63 48 55 55 56 53 48 45 47 58 47 54 49 52 40 51 56 40 58 53 41 59 38 57 55 50 54 45 42 64 55 70 55 32 62 55 56 47 61 39 60 53 56 58 59 56 64 50 59 49 48 48 53 40 47 56 47 64 47 43 57 47 51 46 51 57 57 46 44 62 68 42 54 55 51 58 45 52 53 46 49 46 55 68 54 50 48 60 46 40 60 51 57 61 58 50 53 38 43 46 55 45 59 40 63 58 58 57 39 49 52 44 61 51 38 44 42 56 51 54 56 57 47 61 57 47 56 33 38 48 46 61 49 51 46 53 47 52 51 50 61 46 48 55 42 33 55 69 69 51 45 61 51 48 54 44 44 45 56 49 63 54 55 39 44 48 59 57 54 60 55 55 59 39 46 52 44 61 54 66 42 48 56 60 44 59 54 56 51 38 54 36 46 36 51 60 54 54 49 52 43 59 67 57 63 45 57 46 53 53 58 47 53 50 42 57 45 58 51 43 58 48 46 52 45 53 50 54 46 51 62 43 54 47 69 48 50 60 43 55 54 48 49 46 45 52 44 48 53 56 48 50 45 51 55 58 57 43 61 55 54 50 64 55 49 55 43 44 47 55 53 49 56 44 37 50 47 43 60 40 56 53 53 49 41 49 57 39 49 46 58 51 46 56 62 56 46 65 52 49 70 57 37 32 48 46 40 44 46 49 53 58 53 52 57 56 48 47 37 49 59 48 52 56 51 56 48 50 55 58 52 61 47 51 52 55 59 58 50 49 46 47 54 40 40 47 54 44 60 70 38 61 45 41 51 50 56 58 43 51 55 51 47 44 38 63 69 43 47 61 55 43 69 67 55 60 44 59 55 50 46 55 60 53 45 52 50 59 56 48 54 55 51 66 47 41 54 41 38 48 56 61 45 50 55 53 64 64 59 42 51 56 63 56 58 53 48 45 46 51 48 46 51 52 42 53 71 66 43 45 53 61 61 59 38 57 57 48 49 65 48 68 56 48 60 66 51 55 50 44 56 59 46 48 55 57 54 58 42 56 53 58 47 48 50 48 44 45 48 56 34 43 50 53 45 42 56 44 49 69 60 47 59 44 34 69 52 57 57 52 54 57 51 48 58 53 44 53 48 57 53 46 37 50 53 56 51 49 54 46 50 54 50 33 47 46 53 38 63 46 48 57 60 57 56 57 51 44 45 48 48 64 61 66 48 56 52 63 53 46 44 70 55 56 45 38 46 55 55 46 45 56 42 45 53 55 52 52 45 59 52 52 48 44 54 52 47 63 46 53 50 42 52 47 53 54 51 60 57 51 45 58 47 52 39 51 45 45 47 51 50 49 50 53 45 42 60 40 51 64 57 65 53 49 52 53 48 55 44 47 55 52 52 34 54 55 57 57 48 42 49 46 53 49 50 50 55 68 54 60 52 61 50 58 47 43 53 65 53 49 59 47 59 66 34 53 48 62 53 52 48 59 37 49 48 56 61 52 48 54 55 41 44 53 63 59 52 55 48 51 55 52 47 41 38 42 45 52 66 42 52 36 68 52 43 44 59 52 40 50 53 48 52 51 41 53 57 62 50 47 51 58 51 58 41 36 58 41 47 38 50 48 48 51 62 46 49 45 55 50 58 47 57 61 51 64 51 56 61 51 54 46 63 47 59 48 53 49 53 48 37 43 40 43 51 64 36 45 47 50 58 56 60 57 66 46 46 49 52 54 43 56 46 45 47 53 47 63 43 43 52 46 44 50 41 52 56 45 47 55 44 49 55 55 57 55 54 51 45 42 59 63 58 56 59 39 56 50 50 45 46 61 58 51 48 55 57 51 49 44 46 53 50 60 59 58 50 48 58 53 42 51 41 41 50 62 57 65 51 53 48 58 51 62 57 50 58 57 46 54 54 40 51 46 55 54 51 36 60 50 53 56 62 52 54 59 50 51 53 51 57 52 60 56 47 48 54 50 57 57 54 52 56 52 50 55 51 62 54 51 49 53 37 46 50 58 57 59 68 63 43 43 38 49 45 53 47 37 49 45 51 55 56 53 49 59 60 53 61 59 62 35 51 68 59 53 57 51 50 51 44 47 44 54 48 57 55 60 64 53 49 54 54 58 46 55 33 56 32 54 56 50 33 58 55 60 52 62 49 54 49 64 43 45 62 41 50 48 56 41 51 54 46 53 52 59 68 44 53 49 59 50 58 55 45 50 37 61 55 55 48 50 49 66 48 45 36 54 55 44 48 53 47 43 49 55 64 39 51 49 54 50 58 62 49 57 72 47 59 55 46 55 70 64 46 54 50 46 54 59 59 50 52 32 56 55 53 54 46 59 49 43 50 47 50 48 60 51 53 34 46 41 59 59 44 53 54 52 43 57 54 51 41 53 46 39 42 45 73 56 42 59 45 53 44 47 54 55 52 58 59 44 45 55 63 67 48 52 33 43 45 57 50 51 57 37 41 51 58 55 57 47 56 55 63 55 66 52 53 47 47 54 47 67 52 63 59 48 52 51 52 54 45 60 56 49 59 42 53 46 60 56 57 54 53 47 57 47 45 44 36 52 45 62 56 52 52 61 48 54 48 59 55 55 60 56 38 40 55 60 41 53 42 57 49 53 59 63 45 42 44 52 59 44 62 50 39 47 59 39 51 50 57 56 56 50 47 68 45 54 56 48 68 49 46 60 49 56 38 63 60 59 52 53 56 56 52 44 47 59 47 51 44 50 46 41 54 44 54 41 42 42 56 67 53 52 45 55 46 40 46 50 41 67 62 50 53 51 52 47 53 55 62 50 45 44 52 54 49 44 71 66 44 70 62 63 53 53 61 54 54 48 48 43 45 60 50 49 53 60 51 56 53 55 59 55 42 52 49 53 38 40 51 43 59 53 51 46 46 43 50 51 53 41 54 55 66 51 43 40 63 46 51 57 54 51 49 56 57 60 59 59 62 59 45 63 49 46 45 47 43 57 60 49 49 52 54 60 61 55 58 51 40 47 39 54 57 53 50 38 51 42 45 61 50 66 50 51 46 53 39 55 50 47 57 46 65 43 56 49 54 45 63 49 58 58 55 53 42 52 47 51 53 46 57 50 47 46 49 58 56 66 44 46 48 39 48 52 59 54 53 43 47 52 54 51 56 54 59 47 53 54 47 60 57 54 46 46 49 58 51 48 58 48 47 40 55 64 50 46 47 47 58 56 51 41 52 56 44 53 42 51 59 45 54 47 61 50 56 69 63 52 48 48 59 44 60 53 45 59 51 42 44 57 32 56 44 59 55 69 51 56 47 63 50 50 43 45 33 52 46 57 60 55 61 45 63 63 59 50 73 59 53 51 71 58 40 43 47 54 54 61 42 52 57 62 49 55 42 45 46 50 47 59 73 46 66 49 44 65 62 65 57 58 64 53 48 42 54 52 43 44 54 54 65 52 47 64 64 69 56 51 65 48 55 58 52 58 54 53 63 66 57 52 47 57 50 50 46 57 59 55 62 57 47 56 49 50 53 49 61 50 57 67 56 57 60 44 53 49 57 50 43 51 48 40 45 52 48 48 50 60 52 72 60 45 56 57 45 59 71 69 54 53 37 40 52 45 50 61 53 48 51 66 57 50 72 47 45 55 38 54 52 64 39 63 69 41 69 59 53 73 47 57 54 48 66 41 51 50 63 48 53 57 50 61 55 45 44 49 45 42 41 61 58 53 47 42 55 46 49 49 46 60 69 49 49 45 44 58 52 63 61 61 61 59 53 48 44 47 54 57 51 37 40 38 51 50 61 53 42 54 53 50 51 63 49 49 47 51 55 39 48 58 48 43 50 47 47 57 61 51 52 56 71 47 56 64 48 65 64 59 59 43 55 62 64 48 46 59 51 52 67 49 59 56 43 47 42 51 48 53 48 54 53 67 69 60 59 41 54 52 62 54 50 58 46 46 46 67 57 48 43 56 58 41 52 49 51 65 51 59 49 57 48 56 52 53 53 43 67 49 54 55 53 46 46 55 53 68 54 61 48 52 52 55 52 55 44 43 62 55 49 59 61 56 49 61 48 42 58 51 47 50 52 50 57 50 53 53 49 68 59 51 52 46 47 60 53 52 44 51 52 36 55 50 52 48 48 57 64 56 56 50 49 68 44 42 53 47 53 42 52 52 46 47 55 54 50 42 51 56 45 46 48 41 50 38 59 40 56 48 54 51 40 45 64 58 57 56 50 58 62 45 51 40 62 49 58 62 42 48 54 60 45 46 45 46 51 75 52 55 55 63 56 59 70 60 58 54 44 54 60 55 42 41 46 47 46 56 52 49 41 47 40 58 58 68 49 57 57 48 55 51 62 44 55 35 56 49 51 63 53 55 43 59 62 59 44 56 53 54 50 57 46 49 51 51 62 63 59 50 58 55 42 47 44 48 59 53 49 57 54 53 49 55 53 37 58 38 59 49 69 41 54 52 43 49 47 61 54 49 56 53 59 64 48 47 53 60 59 57 64 56 47 48 49 65 50 38 53 50 54 60 51 50 62 54 51 52 51 48 62 47 41 58 42 47 38 69 56 57 47 48 47 45 52 51 57 63 48 55 57 47 45 54 46 52 42 55 60 50 50 64 52 44 54 47 62 50 61 45 47 53 41 57 49 45 46 41 52 47 57 56 48 43 50 52 66 51 72 53 58 58 47 46 50 55 58 48 66 48 60 53 55 53 39 60 44 37 52 58 45 46 54 52 66 53 57 61 57 40 56 46 42 45 53 57 59 46 58 52 43 51 58 60 46 47 51 41 41 47 58 68 59 51 51 62 38 58 44 53 40 50 50 55 55 48 47 53 54 55 44 70 58 61 49 33 46 52 39 50 48 49 54 44 50 49 47 57 47 48 55 43 47 52 56 47 55 52 50 39 55 45 38 49 54 53 51 55 48 52 46 49 42 54 43 50 46 42 42 58 42 63 43 59 42 65 61 57 44 50 41 60 51 50 45 51 45 52 45 48 45 51 62 59 41 52 56 59 47 55 60 51 73 57 56 49 44 42 52 56 69 66 47 49 52 59 48 57 40 54 60 50 58 60 56 44 48 61 43 54 53 58 45 38 46 51 47 57 47 46 37 57 63 52 55 55 51 49 50 53 50 60 44 39 38 55 59 57 50 51 58 57 56 59 69 44 55 47 51 46 43 46 64 49 51 42 49 46 59 60 53 59 51 57 48 55 52 49 58 55 44 53 52 49 40 51 54 56 52 50 53 50 36 62 49 47 59 55 40 35 52 49 60 49 48 46 50 52 50 43 49 33 47 62 47 51 62 55 60 60 73 57 48 61 44 52 53 43 49 57 45 55 63 52 52 54 43 49 53 57 67 38 43 54 64 50 56 47 52 48 51 53 59 50 56 44 48 41 55 43 59 46 39 57 47 53 38 36 49 58 45 46 57 61 44 55 46 50 49 54 44 60 40 46 49 44 53 59 58 60 54 40 53 54 39 51 38 68 60 55 53 52 44 54 51 77 48 55 49 43 46 62 47 50 40 58 63 56 46 66 58 63 46 48 46 53 61 61 50 42 44 57 64 39 56 66 65 41 50 48 49 47 46 59 60 57 56 57 47 59 50 69 46 43 57 37 42 45 66 43 58 47 40 56 42 61 40 61 63 51 54 61 54 58 64 68 47 62 56 46 39 55 55 55 51 66 52 53 48 46 61 48 35 50 41 36 51 49 47 63 50 41 43 50 39 42 45 48 59 51 53 54 58 58 48 56 59 58 43 56 57 49 40 57 56 55 47 54 46 65 46 60 52 48 51 55 49 55 55 48 42 72 31 49 59 61 60 49 47 40 40 56 71 49 67 56 55 46 50 49 53 71 63 50 73 48 43 49 54 49 39 49 44 57 58 58 41 47 50 45 39 47 56 42 49 49 46 59 49 44 44 57 62 60 48 61 48 59 57 53 37 46 54 40 67 52 57 60 56 45 51 69 61 79 50 50 48 55 64 47 54 51 57 46 46 69 66 55 50 57 57 50 66 52 63 45 45 63 50 57 54 47 55 45 59 52 55 49 60 56 51 60 35 59 48 47 53 42 41 54 38 48 59 62 50 50 43 41 50 61 51 51 60 53 46 51 51 60 48 42 36 40 54 49 51 59 58 69 51 63 61 57 48 52 52 48 60 54 55 59 50 50 53 56 54 57 57 53 56 59 42 59 49 38 61 49 54 46 59 51 37 47 46 53 50 43 58 66 50 66 46 47 47 51 48 53 65 48 53 56 66 51 58 47 32 61 55 59 47 56 52 49 37 38 51 56 45 49 52 56 52 49 58 54 51 65 49 55 60 53 53 51 52 48 44 62 47 60 43 37 62 54 45 62 45 58 51 56 54 46 49 40 54 51 57 50 61 53 63 59 58 58 45 49 64 49 43 56 47 58 50 57 53 59 52 62 58 44 46 49 62 58 45 52 55 48 42 61 44 58 58 55 69 64 56 62 64 53 57 59 54 54 62 65 56 54 36 56 58 52 62 41 46 54 60 58 54 43 54 44 41 53 47 44 43 53 51 48 55 56 53 58 45 54 51 60 58 58 59 54 51 48 41 51 61 50 44 47 52 53 63 64 51 53 56 58 52 43 49 62 39 64 54 55 61 78 43 57 54 55 59 49 49 64 47 45 58 46 62 47 66 50 47 61 42 49 56 59 64 57 67 63 49 46 41 50 58 54 60 50 49 58 52 51 47 57 41 52 44 54 61 47 50 46 47 51 54 34 62 65 57 50 53 46 52 47 42 35 49 62 42 52 66 50 51 49 51 40 45 68 54 50 62 53 44 38 52 52 58 58 62 67 55 50 56 56 45 58 48 45 54 39 43 46 59 52 63 55 46 53 59 49 48 50 62 42 47 50 50 54 59 51 47 45 51 57 47 49 46 41 54 58 53 58 48 56 58 46 58 62 60 60 59 47 55 51 50 60 42 50 70 56 48 57 46 63 42 62 55 63 47 51 47 58 53 50 59 54 55 46 48 48 44 50 53 55 52 61 42 46 57 44 58 61 51 46 59 55 53 48 49 46 66 62 54 50 51 65 56 52 53 56 59 49 58 50 59 44 43 46 62 54 56 46 46 51 58 39 49 56 51 48 65 59 50 52 52 53 57 45 52 54 56 53 59 58 50 51 52 55 53 51 57 58 50 46 53 53 50 46 55 48 60 56 55 51 51 52 65 61 56 52 52 57 46 54 44 53 49 70 55 51 52 60 60 63 51 48 52 35 48 55 58 37 49 62 53 56 46 50 51 58 64 50 45 68 45 66 45 49 51 46 54 53 52 53 45 49 56 48 56 45 52 44 45 66 64 54 57 62 55 48 50 62 65 54 61 60 61 50 51 55 43 64 46 50 55 44 55 62 54 59 75 50 55 74 57 55 54 44 48 53 48 63 53 51 64 54 51 50 60 58 62 58 53 62 58 51 46 56 41 62 58 78 53 59 57 47 52 58 48 67 47 57 51 54 50 73 56 53 57 39 67 54 50 65 56 45 68 45 49 38 50 72 46 44 59 58 56 49 57 50 53 63 46 61 55 56 52 64 49 58 59 49 58 72 56 63 58 46 53 47 71 39 64 62 54 58 62 60 55 54 49 59 55 50 58 56 50 56 45 39 66 56 45 54 55 49 64 44 42 59 50 54 65 48 52 56 51 38 52 45 51 56 38 42 62 47 43 52 48 57 62 50 58 48 62 56 53 67 50 50 51 40 75 58 50 62 49 46 60 37 52 56 52 60 62 60 53 45 55 59 35 53 43 46 59 56 40 44 66 62 48 50 50 62 56 53 58 58 56 56 63 44 52 50 60 57 47 47 51 50 64 50 40 47 42 60 46 52 53 46 61 59 59 57 50 41 53 60 50 58 44 68 52 45 48 51 53 52 67 58 55 47 63 48 55 46 47 55 56 55 63 48 47 56 49 52 52 53 47 59 57 40 52 49 49 34 52 48 59 50 56 63 52 43 49 59 58 50 57 52 52 52 50 47 44 42 56 59 45 58 49 64 53 51 47 44 51 38 53 39 57 54 57 60 50 51 40 42 67 63 57 51 64 46 48 63 54 42 47 50 47 51 53 40 49 52 51 56 60 58 51 57 47 59 57 32 49 47 45 44 58 50 55 55 47 45 48 51 55 52 52 52 57 52 66 51 39 50 52 53 53 64 53 58 58 52 51 51 51 61 66 47 47 43 38 48 46 38 59 55 62 48 45 57 53 54 55 62 70 62 68 41 43 75 56 50 44 54 53 39 50 51 58 46 62 55 53 58 58 67 36 66 46 54 54 45 43 56 59 66 62 39 57 57 61 56 51 46 52 54 50 64 52 61 46 54 45 47 53 51 49 47 59 50 54 53 50 57 52 68 54 47 52 58 50 45 55 62 50 46 51 49 58 59 57 48 55 60 52 59 57 50 61 35 39 50 43 57 57 57 58 44 51 41 58 52 54 52 56 61 41 57 59 66 44 55 54 45 40 58 67 63 52 43 57 54 52 51 57 45 44 51 53 55 52 56 65 51 60 54 53 47 41 55 45 50 44 49 74 54 58 34 60 47 58 56 42 57 42 40 63 60 49 49 48 63 51 59 61 63 52 65 40 52 50 47 44 47 55 53 59 50 52 59 54 47 53 59 47 56 45 57 79 47 51 65 48 48 42 67 51 50 45 50 55 47 37 53 59 52 51 58 59 57 64 59 52 42 46 56 42 60 53 46 60 45 44 61 43 61 53 51 53 46 52 52 55 52 62 43 50 54 71 60 56 52 51 69 55 47 61 55 47 57 57 40 59 67 54 52 44 63 47 66 43 63 53 40 55 43 54 51 52 49 66 52 68 59 61 50 60 52 48 60 54 59 60 50 55 44 49 69 58 36 46 57 40 41 45 58 60 46 49 36 43 48 45 62 60 51 46 34 52 44 48 59 53 54 58 45 48 59 48 49 54 54 45 52 49 52 53 53 51 45 51 49 44 50 56 53 49 65 47 49 57 59 50 56 50 54 60 61 51 51 48 46 55 53 60 59 52 53 52 55 47 59 51 57 52 49 52 53 57 40 38 35 53 60 51 71 44 51 55 52 44 55 55 60 47 44 55 55 56 42 53 54 52 48 47 50 57 50 39 54 43 45 57 54 55 47 36 57 50 49 55 59 53 66 46 60 47 51 52 44 38 44 42 57 63 49 42 40 48 51 48 50 49 55 59 58 48 62 59 52 50 56 73 57 55 62 48 60 58 56 52 55 46 60 59 59 55 48 49 33 56 54 50 68 45 54 55 40 55 49 59 40 61 54 59 57 63 48 66 47 65 49 46 48 59 56 68 56 58 53 54 51 49 60 65 48 49 41 64 40 47 47 48 55 51 53 60 36 56 48 54 48 59 57 67 59 65 49 73 56 53 56 55 64 48 57 54 56 55 44 45 57 54 53 51 41 49 49 48 50 54 54 40 49 54 57 51 45 59 47 43 56 47 52 45 57 52 57 50 58 45 63 63 60 42 53 64 41 61 59 63 71 60 68 53 56 46 47 65 61 58 51 58 64 58 53 59 57 47 58 48 36 70 51 50 63 62 44 68 38 53 55 57 64 55 61 51 50 48 47 53 50 60 51 61 57 50 56 59 50 56 51 53 45 49 46 51 48 50 52 57 61 54 46 52 58 40 46 42 57 69 60 56 50 51 51 53 51 44 56 52 57 48 54 44 46 53 59 48 56 50 50 56 45 43 49 57 52 63 50 53 64 61 55 55 50 48 50 65 55 56 46 42 54 51 45 60 54 70 51 53 58 34 54 53 49 45 49 51 53 49 44 56 49 63 46 51 50 56 49 51 52 55 57 52 55 47 61 55 60 46 54 56 46 38 59 53 65 57 61 47 47 48 46 73 69 55 54 51 59 35 58 55 44 54 58 57 48 56 66 50 49 53 51 49 41 48 55 50 55 55 54 55 48 62 64 57 44 44 48 48 49 54 39 59 48 54 46 55 44 55 57 48 49 52 51 47 48 51 52 52 52 53 61 49 51 54 48 60 44 66 52 41 45 51 54 47 45 61 40 51 59 52 43 61 54 46 49 41 48 65 46 53 46 51 53 57 46 47 56 71 50 59 53 54 57 58 53 46 45 55 55 48 47 49 62 45 48 47 43 64 58 52 55 63 51 37 53 43 52 57 68 56 52 49 57 58 56 53 45 63 54 46 44 47 52 65 51 51 63 44 52 59 51 46 61 60 49 47 37 54 55 44 43 49 47 55 41 51 44 48 47 53 47 57 53 49 59 45 54 41 70 41 49 46 45 51 53 57 50 51 33 41 50 44 55 56 52 47 49 56 52 51 56 58 45 47 53 55 42 64 62 58 46 55 58 54 57 46 57 51 37 46 34 52 56 53 48 57 50 58 53 45 61 65 56 44 40 49 57 53 69 60 52 54 51 48 59 57 55 43 43 38 59 61 45 57 57 54 69 46 41 38 50 48 47 54 48 48 43 52 56 57 57 48 59 41 47 37 54 49 54 62 58 52 39 54 58 53 48 66 36 49 68 55 49 63 58 54 37 51 55 52 52 62 55 45 49 43 70 43 58 59</counts>
			</dataPoints>
		</scan>
	</xrdMeasurement>
</xrdMeasurements>