File: data/XRD/XG-Luft/XG-pre/W6824-1D_XG_Luft_pre.xrdml
<xrdMeasurements xmlns="http://www.xrdml.com/XRDMeasurement/2.1" xmlns:xsi="http://www.w3.org/2001/XMLSchema-instance" xsi:schemaLocation="http://www.xrdml.com/XRDMeasurement/2.1 http://www.xrdml.com/XRDMeasurement/2.1/XRDMeasurement.xsd" status="Completed">
	<comment>
		<entry>Configuration=Factory configuration, Owner=User-1, Creation date=7/8/2013 4:01:53 PM</entry>
		<entry>Goniometer=PW3050/65 (Theta/2Theta); Minimum step size 2Theta:0.0001; Minimum step size Omega:0.0001</entry>
		<entry>Sample stage=MRD Cradle; Minimum step size Phi:0.01; Minimum step size Chi:0.01; Minimum step size X:0.01; Minimum step size Y:0.01; Minimum step size Z:0.001</entry>
		<entry>Diffractometer system=XPERT-PRO</entry>
		<entry>Measurement program=C:\PANalytical\Data Collector\Programs\Jorrit\2thom\_absolute_2th-om_10-130deg_PIXscan_56min.xrdmp, Identifier={15BCCF57-2807-42BD-B5B9-ECC0B3DC9284}</entry>
		<entry>Batch program=C:\PANalytical\Data Collector\Programs\SimonL\batch7x_2thom_10-130°_z9.1_x0,10,20,30_y10,20,30_57min.xrdmp, Identifier={089D96B1-A01D-49FF-BCB5-EEA9DFC9CC78}</entry>
	</comment>
	<sample type="To be analyzed">
		<id></id>
		<name></name>
		<preparedBy></preparedBy>
	</sample>
	<xrdMeasurement measurementType="Scan" status="Completed" sampleMode="Reflection">
		<comment>
			<entry>_absolute_2th-om_10-130deg_PIXscan_56min</entry>
			<entry>PHD Lower Level = 4.83 (keV), PHD Upper Level = 11.27 (keV)</entry>
		</comment>
		<usedWavelength intended="K-Alpha 1">
			<kAlpha1 unit="Angstrom">1.5405980</kAlpha1>
			<kAlpha2 unit="Angstrom">1.5444260</kAlpha2>
			<kBeta unit="Angstrom">1.3922500</kBeta>
			<ratioKAlpha2KAlpha1>0.5000</ratioKAlpha2KAlpha1>
		</usedWavelength>
		<incidentBeamPath>
			<radius unit="mm">320.00</radius>
			<xRayTube id="1010048" name="Empyrean Cu LFF HR (9430 033 7310x) DK442154">
				<tension unit="kV">40.0</tension>
				<current unit="mA">40.0</current>
				<anodeMaterial>Cu</anodeMaterial>
				<focus type="Line">
					<length unit="mm">12.0</length>
					<width unit="mm">0.4</width>
					<takeOffAngle unit="deg">4.2</takeOffAngle>
				</focus>
			</xRayTube>
			<xRayMirror id="27010001" name="Inc. Beam Cu W/Si (parabolic MRD)" hybrid="false">
				<crystal type="Graded" shape="Parabolic">W/Si</crystal>
				<acceptanceAngle unit="deg">0.800</acceptanceAngle>
				<length unit="mm">60.0</length>
			</xRayMirror>
			<sollerSlit id="21010002" name="Soller slits 0.04 rad.">
				<opening unit="rad">0.0400</opening>
			</sollerSlit>
			<mask id="22030008" name="Fixed mask 4 mm">
				<distanceToSample unit="mm">220.00</distanceToSample>
				<width unit="mm">4.00</width>
			</mask>
			<divergenceSlit id="22010011" name="Fixed slit 1/32°" xsi:type="fixedDivergenceSlitType">
				<distanceToSample unit="mm">220.00</distanceToSample>
				<height unit="mm">0.05</height>
			</divergenceSlit>
		</incidentBeamPath>
		<diffractedBeamPath>
			<radius unit="mm">320.00</radius>
			<sollerSlit id="21010002" name="Soller slits 0.04 rad.">
				<opening unit="rad">0.0400</opening>
			</sollerSlit>
			<receivingSlit id="22010001" name="Fixed slit 4°">
				<height unit="mm">5.88</height>
			</receivingSlit>
			<detector id="7010017" name="PIXcel3D 1x1 detector" xsi:type="areaDetectorType">
				<phd unit="%">
					<lowerLevel>30.0</lowerLevel>
					<upperLevel>70.0</upperLevel>
				</phd>
				<mode>Scanning</mode>
				<activeChannelsEquatorial>255</activeChannelsEquatorial>
				<activeChannelsAxial>255</activeChannelsAxial>
				<pitchEquatorial unit="mm">0.05500</pitchEquatorial>
				<pitchAxial unit="mm">0.05500</pitchAxial>
				<readOutPeriod unit="seconds">0.135</readOutPeriod>
			</detector>
		</diffractedBeamPath>
		<scan appendNumber="0" mode="Continuous" scanAxis="2Theta-Omega" status="Completed">
			<header>
				<startTimeStamp>2024-10-21T23:18:02+02:00</startTimeStamp>
				<endTimeStamp>2024-10-22T00:14:08+02:00</endTimeStamp>
				<author>
					<name>PRO-MRD</name>
				</author>
				<source>
					<applicationSoftware version="6.1b">Data Collector</applicationSoftware>
					<instrumentControlSoftware version="7.0E 20130304">XPERT-PRO</instrumentControlSoftware>
					<instrumentID>0000000011142674</instrumentID>
				</source>
			</header>
			<dataPoints>
				<positions axis="2Theta" unit="deg">
					<startPosition>9.99826193</startPosition>
					<endPosition>129.99755682</endPosition>
				</positions>
				<positions axis="Omega" unit="deg">
					<startPosition>4.99913096</startPosition>
					<endPosition>64.99877841</endPosition>
				</positions>
				<positions axis="Phi" unit="deg">
					<commonPosition>0.00</commonPosition>
				</positions>
				<positions axis="Chi" unit="deg">
					<commonPosition>0.00</commonPosition>
				</positions>
				<positions axis="X" unit="mm">
					<commonPosition>30.00</commonPosition>
				</positions>
				<positions axis="Y" unit="mm">
					<commonPosition>0.00</commonPosition>
				</positions>
				<positions axis="Z" unit="mm">
					<commonPosition>9.100</commonPosition>
				</positions>
				<commonCountingTime unit="seconds">32.895</commonCountingTime>
				<counts 95 68 84 84 95 76 99 72 65 69 83 80 78 86 73 88 81 81 76 78 79 80 86 81 91 73 71 80 84 79 68 81 83 68 72 97 82 69 77 84 73 73 68 84 78 94 81 80 97 102 76 83 74 77 77 83 67 75 89 95 82 57 81 81 74 80 89 84 84 79 89 84 91 72 70 84 66 75 91 73 87 79 69 82 83 82 86 73 72 73 82 78 78 84 72 81 74 76 61 61 74 82 74 77 78 89 75 72 81 72 81 61 86 78 79 96 68 82 69 72 92 92 84 75 66 85 77 74 77 70 59 78 82 78 87 80 69 80 68 67 76 86 74 71 72 80 83 76 72 65 74 68 60 70 67 74 77 79 83 57 79 98 76 64 94 67 76 72 80 84 84 69 68 66 88 83 82 76 82 79 72 57 75 61 72 71 77 78 77 70 82 72 75 81 76 62 65 71 69 75 64 74 65 75 66 71 63 85 80 66 67 70 74 67 88 67 88 65 61 63 68 66 76 83 57 79 69 62 62 68 70 73 62 68 53 75 58 67 68 60 81 70 69 74 55 66 71 71 79 65 64 76 70 61 69 67 86 71 75 66 65 58 65 78 74 83 58 78 86 69 74 77 64 68 69 76 75 61 71 75 73 62 78 62 54 78 78 68 66 63 56 62 63 62 70 65 85 65 77 63 61 84 58 65 78 73 67 64 85 58 66 69 81 74 68 64 67 53 71 80 63 74 63 68 59 79 59 62 65 53 63 74 66 71 74 59 73 78 57 66 52 54 74 88 66 71 61 63 67 57 64 60 58 69 62 49 48 56 66 68 76 53 61 71 63 49 64 69 67 79 67 59 65 67 68 69 48 72 55 76 55 59 58 54 59 77 75 50 67 79 70 72 75 52 58 79 40 61 79 68 74 57 61 67 59 68 66 67 80 61 49 60 55 84 55 57 55 53 59 76 61 37 73 56 70 51 55 56 71 63 74 70 59 64 75 50 67 74 60 72 61 69 58 60 60 51 62 62 71 65 74 55 72 57 62 60 65 80 63 58 63 76 68 69 70 61 62 72 52 58 46 69 62 56 53 86 59 61 78 53 60 69 53 60 54 62 60 59 64 68 60 66 50 64 58 73 50 56 62 45 63 68 58 72 65 59 67 65 56 72 65 71 53 54 80 71 67 69 68 60 55 71 56 73 55 62 63 66 61 61 73 61 55 63 59 59 51 71 62 78 54 55 72 82 59 41 52 57 73 66 59 55 69 56 74 49 34 57 49 63 71 50 58 59 62 54 57 75 49 55 60 56 59 53 64 57 65 55 57 43 50 70 46 49 61 64 61 57 54 62 69 54 54 55 57 51 64 67 65 65 56 50 63 59 74 61 78 54 64 69 63 58 58 68 67 67 51 68 74 68 66 62 56 59 50 48 59 53 58 66 56 55 57 62 57 65 56 64 57 66 61 46 61 62 56 49 56 62 60 51 53 51 62 58 46 70 58 60 44 60 64 55 64 70 65 56 52 56 49 54 56 61 54 79 67 60 66 58 52 49 52 59 63 72 52 48 77 59 60 59 54 63 53 64 66 50 53 58 60 61 43 53 63 58 45 57 47 61 62 49 70 48 63 52 49 71 76 57 44 63 66 60 63 59 55 37 63 50 61 53 58 57 61 63 80 55 59 53 51 72 49 53 44 51 54 40 50 61 65 54 51 67 64 50 53 63 69 56 46 64 67 62 59 62 49 60 50 64 59 48 59 51 53 48 58 54 61 63 57 58 59 55 64 54 62 54 54 54 58 60 60 73 59 78 53 61 59 56 54 78 55 57 57 51 58 59 75 59 58 73 62 58 54 55 55 48 58 57 47 58 61 52 67 59 71 55 73 52 66 51 53 67 62 56 45 69 75 61 53 61 57 51 58 49 67 47 60 74 52 43 50 53 53 51 57 49 52 49 51 63 52 67 53 51 57 61 53 48 62 46 55 52 53 60 66 63 65 81 63 59 75 63 56 50 58 64 48 69 58 54 53 50 54 63 65 62 69 67 50 65 40 65 59 55 64 58 52 54 65 57 58 60 56 61 66 62 63 69 51 54 61 54 62 69 46 54 58 53 49 47 65 61 66 47 67 69 62 58 57 53 67 53 62 61 48 56 59 63 64 66 54 57 53 56 68 50 66 66 47 53 52 55 60 70 59 54 62 76 62 51 43 58 68 62 54 55 58 59 55 58 56 60 53 55 48 61 57 56 58 57 67 57 53 59 60 50 59 61 55 62 55 73 61 56 51 65 60 64 61 75 50 56 62 45 66 59 64 55 52 61 58 49 53 72 65 50 56 58 55 65 78 61 55 59 64 59 48 65 59 55 49 75 56 66 65 71 54 47 64 48 44 72 64 58 51 48 51 53 51 67 41 70 53 67 79 53 45 45 55 62 50 67 55 57 59 45 55 62 65 46 65 52 57 49 54 60 66 67 63 67 46 49 56 62 74 67 47 51 65 65 55 57 69 48 62 60 66 67 64 59 64 64 53 64 57 54 51 54 58 65 61 45 45 72 65 67 63 50 62 74 59 52 63 61 67 60 52 60 51 64 72 49 40 70 62 65 50 57 64 50 55 53 53 56 63 52 50 42 59 58 60 64 58 57 49 68 65 49 57 55 68 63 59 60 46 59 62 61 62 53 46 81 63 71 63 67 55 41 77 60 58 53 52 60 59 51 64 62 54 58 64 63 66 59 58 69 66 60 63 58 59 58 59 64 63 50 56 55 57 44 65 59 58 54 56 64 43 55 51 57 61 47 55 61 61 50 57 47 63 47 55 51 67 66 62 46 59 62 64 70 52 63 69 52 56 62 64 58 58 47 50 52 65 56 49 64 57 39 63 55 63 59 63 54 68 55 58 61 69 66 59 60 49 69 46 56 64 56 65 67 60 55 56 61 64 49 54 63 53 54 53 51 55 60 52 67 63 71 66 53 50 63 62 57 59 60 51 58 52 55 68 52 48 55 58 61 67 54 58 70 61 73 64 49 65 53 60 54 83 70 55 53 54 71 53 58 64 58 52 51 49 54 67 66 69 51 73 71 59 58 48 60 54 57 59 60 42 52 65 62 49 54 53 52 69 61 62 54 62 63 41 71 52 60 64 52 66 63 58 72 58 58 56 53 54 50 67 55 44 72 63 74 57 61 73 64 55 69 57 59 62 70 49 53 61 45 58 68 54 67 64 51 73 60 57 36 59 61 52 59 60 61 70 65 44 54 69 55 61 59 59 46 47 52 58 67 48 56 43 58 53 57 69 72 60 67 63 64 51 73 47 47 62 59 65 64 51 61 53 54 49 59 53 43 51 50 53 59 44 67 51 60 61 59 46 57 50 56 53 55 55 65 53 66 56 63 52 61 68 55 49 67 54 47 67 60 61 57 59 49 63 71 56 55 62 58 66 48 59 53 57 48 56 49 56 68 60 53 52 46 52 62 63 60 47 67 64 54 51 58 58 65 58 55 57 52 56 58 52 73 69 44 56 60 60 56 54 59 67 58 47 64 56 62 44 51 54 38 43 64 55 62 59 56 65 49 58 55 57 51 65 50 63 57 59 60 61 62 64 61 49 62 53 67 54 67 52 49 60 53 48 58 61 54 62 49 52 50 53 59 59 46 52 50 53 54 43 67 53 56 62 60 49 54 50 54 64 61 56 52 51 50 47 59 50 42 51 51 57 46 56 52 57 53 57 56 55 45 63 64 43 66 47 53 42 51 48 52 56 62 51 56 46 51 47 39 58 48 41 47 49 57 60 51 48 53 59 61 39 57 66 53 42 64 48 51 50 39 46 54 49 46 44 52 62 45 58 56 58 59 42 61 55 51 50 56 55 47 62 45 46 54 43 63 51 54 55 68 36 46 52 66 58 42 54 46 52 41 54 46 49 47 54 56 49 50 47 53 48 57 54 46 52 42 50 54 50 50 52 36 56 54 55 45 46 51 66 60 49 50 55 58 38 59 49 44 52 58 44 56 47 57 52 55 42 36 50 57 53 41 55 40 59 41 53 56 49 54 55 53 37 48 52 53 68 45 47 41 56 57 43 52 55 56 48 53 53 55 59 38 48 42 52 43 50 58 51 54 65 51 55 56 50 45 51 53 41 40 68 40 67 43 44 43 45 47 54 59 33 50 43 46 57 40 49 48 50 44 45 55 53 59 47 52 48 44 37 49 51 48 46 49 42 57 55 44 50 56 49 56 32 36 54 55 56 42 38 41 58 41 50 42 45 46 55 48 38 48 43 39 40 42 44 38 51 46 38 43 46 33 53 68 40 59 39 41 61 56 61 54 50 39 53 46 60 49 52 56 40 60 50 40 46 46 61 53 50 51 39 40 52 46 53 47 53 43 54 47 38 62 44 34 53 48 42 56 47 54 54 52 49 52 53 53 44 57 53 56 54 51 37 41 47 52 44 50 46 47 58 57 47 53 57 42 51 52 51 43 45 49 45 50 55 53 57 49 43 68 30 37 52 33 37 43 52 48 46 57 42 52 33 41 47 60 34 50 36 45 50 48 35 55 47 49 57 49 49 39 49 58 52 47 38 55 42 49 39 51 38 46 49 44 40 56 49 47 44 37 58 39 35 55 43 41 53 59 46 37 50 43 45 45 48 43 42 46 43 37 57 49 54 49 48 45 41 45 45 49 41 59 39 43 48 52 44 48 48 55 53 40 55 38 48 60 49 44 45 40 43 42 45 33 57 32 48 62 41 46 41 58 52 37 44 55 41 46 36 46 39 38 52 58 49 43 46 43 56 62 51 39 54 35 45 54 50 42 29 53 43 44 49 46 57 41 45 45 41 46 51 39 38 49 43 54 55 41 49 63 44 51 51 49 44 49 53 43 41 49 38 40 34 43 46 50 50 50 44 46 51 43 30 37 43 44 36 49 45 50 41 36 48 38 47 33 40 55 47 39 39 38 38 43 57 48 51 55 42 43 37 34 40 52 47 49 42 48 53 61 44 51 53 51 51 46 35 37 48 46 54 43 44 53 44 41 51 49 38 50 47 50 49 43 39 51 41 38 42 46 50 39 46 39 45 44 35 46 37 48 50 58 58 39 46 48 48 50 42 49 43 52 39 61 45 42 42 43 44 43 58 46 48 40 43 47 49 46 55 47 47 48 44 51 40 47 51 43 50 53 44 46 42 38 39 47 45 47 39 53 40 36 35 50 46 45 42 35 47 36 36 48 37 57 47 58 33 51 52 50 49 51 43 48 49 41 49 40 46 52 49 49 37 53 64 50 50 47 50 48 52 44 52 42 37 35 35 43 50 40 39 40 31 37 35 51 49 33 49 43 47 38 50 37 33 41 48 37 44 47 60 47 36 48 47 57 41 41 44 51 46 37 44 35 40 45 48 51 49 48 47 46 45 51 44 63 40 52 43 46 57 39 40 34 56 47 43 55 48 46 42 45 34 45 45 49 45 36 39 49 49 44 51 38 40 43 50 42 41 45 46 42 49 41 31 30 39 42 40 26 44 42 40 52 43 38 40 40 56 55 52 32 46 44 41 42 51 46 42 40 40 52 42 53 47 42 42 39 31 49 54 37 39 31 42 47 39 48 34 54 57 50 36 48 43 43 44 48 48 47 39 36 48 46 47 48 55 50 46 47 42 40 52 48 41 41 47 41 49 46 51 56 34 40 43 51 53 58 49 41 42 26 45 56 46 42 37 46 48 43 55 50 35 48 43 31 39 44 40 49 37 39 41 39 57 41 47 32 46 53 48 49 49 36 48 50 48 49 50 37 45 48 46 34 44 51 48 43 49 49 44 39 54 41 44 48 52 51 44 40 34 36 49 38 46 42 46 49 47 43 38 49 46 43 47 43 50 37 48 50 52 40 45 38 42 47 43 34 49 42 57 58 43 41 42 42 45 34 45 57 52 44 38 35 36 46 43 47 53 43 40 44 45 34 48 56 40 39 36 45 48 43 45 41 45 34 59 48 53 44 57 41 48 39 52 32 37 35 31 50 48 54 38 39 39 42 46 52 53 42 50 48 57 44 50 38 34 57 49 36 56 54 41 40 52 54 26 45 40 34 53 41 47 44 64 49 43 43 43 36 50 50 31 36 41 44 46 41 37 41 50 53 41 39 42 41 43 39 33 58 38 48 47 45 34 41 42 50 50 38 38 52 48 39 45 42 42 38 36 34 42 43 34 37 38 63 35 45 42 53 41 38 45 37 36 39 44 49 44 39 39 39 51 38 41 46 44 57 41 39 45 44 50 46 45 37 49 42 45 42 37 40 49 36 41 52 47 42 43 44 38 37 53 37 51 32 37 44 38 37 29 41 37 43 45 36 39 54 43 52 41 40 49 33 46 46 42 34 44 51 50 42 47 46 42 36 42 42 41 37 40 47 42 50 31 51 35 58 36 27 37 36 39 47 35 46 51 43 42 45 51 44 38 54 34 40 44 32 55 46 44 49 54 43 38 55 38 46 40 33 33 50 47 37 36 47 52 35 47 37 44 42 43 39 36 57 38 37 34 42 49 35 52 42 40 36 50 52 41 54 44 48 42 47 35 44 43 40 54 39 48 53 48 37 46 53 55 40 42 45 48 37 37 46 45 51 54 36 46 42 54 46 37 34 49 46 41 52 46 38 41 43 46 40 36 45 49 43 45 51 48 54 42 43 51 40 49 50 46 34 40 36 47 52 39 55 40 39 45 35 49 49 43 35 47 45 44 45 39 41 38 47 42 37 45 47 45 52 46 32 52 42 40 44 37 42 49 40 38 50 44 45 42 47 52 29 38 44 47 47 47 38 48 48 44 34 36 59 40 34 50 51 44 37 55 25 49 39 47 43 51 51 40 48 38 54 36 43 29 38 39 35 60 37 54 41 33 46 48 55 45 44 41 33 47 45 36 52 34 52 35 41 46 33 45 54 51 46 43 45 41 58 64 37 52 48 47 44 35 39 46 46 46 40 43 46 50 49 50 49 29 52 48 41 45 36 30 34 42 36 53 42 51 39 64 49 36 48 35 29 41 44 46 48 43 39 46 50 36 51 38 57 45 61 49 57 47 48 58 43 41 44 53 32 41 31 39 45 41 47 42 49 54 39 54 46 42 47 45 38 37 44 37 52 41 39 30 30 43 39 41 44 54 34 38 42 41 50 47 43 33 56 48 40 31 46 46 50 47 44 45 44 35 49 41 40 46 42 27 58 52 53 51 38 51 40 43 43 36 43 48 43 45 36 37 53 41 35 39 50 51 46 64 41 43 53 47 39 53 48 47 42 54 44 49 60 42 38 44 55 49 41 45 36 46 50 44 48 51 46 47 36 38 50 42 52 39 55 47 50 50 42 44 46 45 42 57 51 37 47 36 30 41 40 38 51 47 44 35 45 50 31 55 43 53 46 42 40 42 32 45 44 48 45 44 45 38 44 40 40 44 36 37 40 49 51 41 50 37 42 56 39 45 52 57 35 48 43 43 47 50 30 43 35 42 39 34 42 56 41 46 41 53 51 59 52 48 47 49 46 42 37 39 52 52 41 48 57 47 41 41 50 51 38 36 49 50 57 41 37 50 47 33 54 53 40 43 34 54 52 48 42 39 36 36 54 46 44 39 48 45 32 59 52 54 46 40 42 40 47 55 45 40 41 39 49 38 44 47 42 55 38 40 47 54 37 43 44 46 45 49 44 52 38 39 43 48 51 51 54 36 59 58 58 50 60 50 52 51 51 58 48 42 44 46 50 46 40 40 47 51 43 54 45 46 60 63 45 58 58 49 56 43 66 47 59 41 43 64 50 50 47 48 55 65 44 54 40 42 55 61 60 51 52 61 54 69 68 56 51 54 60 68 48 73 76 65 72 61 73 62 80 61 87 79 65 85 92 83 64 76 88 84 83 78 84 63 87 83 76 56 73 56 77 65 72 59 62 59 53 66 64 54 59 66 61 51 72 62 60 43 45 47 53 52 57 50 48 41 52 47 50 41 49 35 42 45 53 44 64 53 40 37 56 48 56 39 48 55 47 40 37 47 43 49 50 48 54 49 56 45 50 49 49 41 40 37 54 49 40 44 50 51 45 34 48 43 42 40 49 52 52 51 52 48 54 51 56 42 52 43 48 36 45 51 42 40 41 48 48 40 54 39 51 43 37 53 52 45 51 52 45 51 57 37 47 42 52 32 58 38 48 45 44 56 51 39 47 36 45 46 36 50 53 47 47 56 44 42 40 45 43 33 47 57 37 49 33 48 47 37 44 53 42 57 50 48 37 51 47 44 48 26 44 52 35 46 60 33 38 37 35 37 57 50 43 40 39 35 42 44 47 52 48 50 48 44 42 32 55 37 40 47 35 58 36 50 43 51 35 52 50 45 37 48 48 38 50 46 51 46 41 40 38 43 48 40 42 57 40 51 38 42 48 45 44 44 41 46 34 47 48 36 49 56 45 49 57 38 57 45 47 43 42 38 32 58 32 34 39 45 42 46 45 41 49 45 53 55 33 44 33 52 39 44 43 43 43 47 38 39 44 59 37 44 47 43 44 35 40 54 46 48 40 55 53 46 49 41 48 59 61 33 37 60 54 42 50 32 51 34 50 43 47 41 47 38 43 47 63 44 55 36 49 44 50 46 48 54 42 48 51 50 40 42 36 53 46 49 52 41 48 42 45 38 48 48 44 52 45 35 38 43 47 52 39 44 39 52 38 40 57 35 37 48 34 39 50 46 39 51 36 44 49 37 48 52 37 34 41 63 44 50 35 43 44 49 44 41 51 58 36 35 43 36 42 48 48 46 47 51 52 37 47 42 37 48 62 33 51 36 46 52 43 51 50 44 37 45 40 44 42 39 52 44 47 48 54 47 46 45 42 49 35 41 50 65 52 41 40 47 52 46 53 43 44 51 52 46 56 53 44 49 49 34 41 46 45 52 52 59 31 40 48 35 46 54 39 40 57 46 52 45 66 47 49 44 37 46 46 34 42 52 42 58 46 35 54 52 46 51 41 48 52 49 55 46 49 38 41 36 43 42 43 47 45 48 44 45 39 42 50 41 36 46 33 53 38 50 55 45 50 42 48 55 46 50 29 48 53 57 44 56 38 43 52 59 39 37 41 37 48 38 54 53 53 44 52 46 38 37 49 49 47 42 55 43 55 46 52 42 45 42 55 58 39 57 40 47 48 47 52 40 43 33 39 54 40 46 39 55 43 51 55 59 46 37 66 46 45 36 50 43 34 49 49 53 41 43 63 46 46 48 53 32 45 41 57 44 54 48 58 37 43 45 49 48 54 45 33 44 38 49 34 51 39 23 29 35 41 38 38 49 55 41 43 56 48 50 48 46 43 41 52 50 49 41 46 49 59 33 40 41 39 42 52 52 45 37 46 37 28 51 41 47 43 42 49 52 43 41 51 40 40 43 41 58 34 33 48 53 33 45 45 47 54 50 39 49 51 29 47 45 47 53 38 53 48 50 49 46 46 55 45 43 57 46 52 37 53 46 46 52 37 42 36 61 46 47 41 51 38 40 52 50 29 46 56 43 57 50 43 35 57 44 53 44 38 40 48 41 49 41 39 50 49 52 42 50 43 34 42 44 46 33 55 33 45 43 51 42 55 49 47 52 48 44 42 48 49 51 61 39 38 41 44 60 48 51 37 53 46 55 48 45 42 40 50 40 55 46 38 52 48 39 43 40 39 39 35 48 43 42 47 44 46 55 44 42 50 32 47 39 42 41 50 43 41 44 38 55 41 49 41 52 53 56 46 43 53 53 36 54 40 43 51 55 48 42 47 45 41 56 43 41 41 50 39 48 48 42 43 44 46 42 49 48 41 47 47 39 55 46 50 42 33 52 57 54 45 45 49 36 43 50 35 37 60 41 43 44 52 52 52 55 55 41 39 37 41 38 48 44 48 50 49 55 65 49 42 40 58 48 50 45 43 40 52 35 38 60 57 48 43 48 39 43 60 54 45 50 46 42 45 49 58 38 49 44 39 40 39 46 49 42 47 43 51 43 45 48 38 42 32 40 57 40 34 40 40 44 53 42 48 32 46 50 43 34 50 38 44 38 36 37 47 55 46 52 49 47 39 45 45 37 53 40 49 45 36 43 44 52 48 44 49 45 49 41 61 43 57 60 46 49 43 36 51 59 53 41 53 38 53 43 50 45 43 54 39 49 56 51 46 41 41 47 42 49 48 40 47 44 29 45 57 48 54 39 40 45 46 44 39 40 47 44 49 46 42 49 50 41 49 41 45 36 35 42 47 45 48 47 50 64 52 42 52 42 53 49 46 48 49 39 51 48 52 40 43 51 46 45 49 45 56 61 49 52 42 53 35 44 55 53 45 48 50 37 42 45 40 49 40 44 42 59 60 39 42 42 49 40 48 49 44 49 46 52 60 43 42 57 46 53 38 52 46 54 52 46 42 45 51 52 50 31 33 37 57 56 42 54 42 46 44 48 52 50 53 43 45 50 51 48 39 50 43 56 47 48 44 46 49 40 52 53 58 36 46 40 40 42 45 51 38 49 45 60 50 34 51 37 43 46 49 46 50 45 45 51 45 44 42 55 45 44 43 44 35 47 49 43 55 33 55 38 46 54 34 56 44 35 55 51 41 42 44 48 54 31 45 39 49 48 52 48 37 52 68 51 42 50 46 33 42 65 53 52 48 48 51 38 53 59 33 39 51 49 54 35 45 44 53 46 49 57 46 35 41 51 38 53 40 37 38 55 49 45 50 54 41 47 47 47 41 47 47 49 46 50 43 44 50 50 50 29 50 47 46 57 47 38 52 48 50 44 47 43 49 41 43 42 40 49 55 41 34 56 49 42 43 50 47 50 59 48 51 45 45 36 48 36 51 50 53 42 60 46 53 45 55 54 50 46 49 53 49 37 57 49 41 40 41 42 51 45 49 49 42 47 39 41 55 41 44 40 47 56 37 45 40 42 55 41 30 52 45 51 40 40 46 48 51 45 37 42 42 43 46 49 52 46 46 57 50 47 53 53 48 41 57 38 57 48 45 56 45 41 40 54 49 42 45 44 46 50 47 47 35 48 50 49 46 47 53 38 45 49 51 44 44 47 45 52 47 45 53 51 60 61 51 52 36 51 51 48 35 38 48 52 39 45 37 51 55 53 50 45 53 45 40 45 48 50 50 49 41 40 33 45 58 58 51 55 45 44 48 49 52 36 46 41 39 54 47 54 39 36 51 53 35 43 44 46 46 50 52 51 51 37 44 56 37 55 38 68 37 52 50 56 55 54 40 49 37 43 48 40 46 35 42 49 57 45 55 30 51 54 48 44 42 49 46 55 71 30 53 48 47 42 37 62 39 55 55 37 42 54 45 48 51 41 50 57 52 56 47 43 43 56 43 42 45 64 46 58 62 48 49 46 42 43 38 42 42 45 43 43 48 50 39 46 48 53 67 68 51 44 39 47 53 55 50 43 54 42 48 58 55 46 51 39 49 62 41 49 46 42 56 38 52 40 38 48 63 52 35 47 53 42 50 43 50 50 40 54 55 49 32 39 40 57 51 53 53 46 43 43 45 59 44 47 48 39 59 47 45 46 54 51 65 48 50 49 41 31 35 59 55 45 56 51 43 39 57 50 70 44 51 56 46 65 34 47 44 41 45 46 56 56 55 48 52 48 50 68 38 58 38 42 53 53 36 40 47 38 50 38 46 51 52 46 43 64 46 41 47 59 45 42 40 45 55 47 40 54 42 46 41 47 48 54 45 37 37 56 51 36 51 52 33 55 53 45 40 52 58 53 62 44 54 45 51 44 49 51 48 50 44 59 67 59 58 45 52 49 41 43 47 51 58 50 47 46 50 47 45 57 50 42 58 59 37 40 54 43 59 46 48 53 50 45 50 44 50 50 47 56 41 48 50 56 48 60 33 44 55 48 54 54 56 37 55 46 45 43 53 44 55 60 52 45 46 42 47 44 42 45 59 53 49 38 51 47 55 52 49 52 42 39 54 60 63 56 44 50 54 45 48 48 57 52 49 47 48 39 42 34 44 46 47 40 44 63 49 60 58 55 48 53 45 40 43 53 46 48 55 62 42 41 43 48 43 53 50 43 52 59 38 51 43 59 45 57 66 52 54 42 43 50 51 38 49 58 61 41 55 51 59 49 50 51 48 47 52 43 49 36 55 41 44 52 53 44 49 47 49 48 56 49 55 49 40 55 53 52 54 65 45 36 54 45 48 52 55 54 48 47 46 47 60 50 47 41 38 40 51 47 59 44 53 47 42 55 62 49 55 54 43 48 63 51 48 45 56 55 44 52 45 54 47 70 54 42 44 38 49 48 58 48 41 54 63 60 42 40 50 49 44 49 55 48 51 55 52 53 57 34 46 35 45 48 37 37 50 51 50 39 48 35 50 55 45 57 40 44 46 52 47 39 61 54 51 49 43 43 52 57 52 63 47 48 55 41 45 50 63 42 44 58 51 46 48 51 43 52 46 51 49 52 51 49 56 56 68 50 61 59 48 46 55 49 39 42 52 59 63 56 55 55 45 45 64 45 42 41 38 47 47 43 45 64 47 55 48 58 48 55 62 41 61 54 56 53 51 51 57 46 49 60 56 57 58 64 55 59 62 59 55 46 57 52 64 59 48 43 48 55 47 60 42 50 50 54 48 56 48 53 61 50 37 44 57 51 51 50 58 69 46 57 57 51 52 40 33 59 51 49 51 43 53 43 34 58 50 41 41 59 50 55 37 47 34 71 47 40 45 51 59 54 50 55 56 51 59 57 66 57 49 49 48 60 49 53 44 55 54 51 47 54 47 47 42 48 48 57 51 42 52 48 40 50 54 44 47 41 43 43 48 42 59 37 53 48 55 34 56 52 57 59 57 42 57 41 45 37 58 48 58 36 39 52 50 59 50 49 42 45 44 44 47 47 47 51 67 53 46 44 47 50 45 53 49 58 42 50 57 43 42 36 41 49 58 62 48 50 52 61 45 43 48 44 47 62 46 43 35 71 44 58 48 44 45 51 52 43 43 54 49 43 51 40 43 42 55 52 32 61 37 62 44 44 46 45 52 50 51 45 52 46 41 53 62 50 38 44 51 57 43 52 44 47 43 85 47 44 52 60 48 40 51 55 28 37 59 45 46 49 52 49 54 53 48 39 66 51 57 53 54 62 50 44 44 50 42 66 45 52 48 45 57 57 54 58 45 45 52 48 45 53 45 44 40 56 51 40 44 40 50 53 43 59 38 51 48 61 42 57 50 38 57 50 58 59 51 49 55 35 42 59 43 41 53 35 53 52 45 56 53 52 55 50 53 48 58 46 53 54 49 51 61 51 58 50 43 63 50 43 65 52 56 51 56 43 37 51 39 57 44 56 61 43 43 52 42 55 38 55 44 57 45 52 60 56 63 44 34 47 44 57 38 53 45 50 36 41 51 56 59 52 48 44 45 42 55 53 45 51 40 52 58 41 52 59 53 50 45 63 49 43 61 45 69 47 42 58 44 54 65 42 45 51 51 41 40 46 47 57 54 56 62 46 52 59 53 47 49 42 44 42 55 59 47 63 65 50 46 44 46 53 64 49 43 55 45 66 51 52 43 46 50 50 57 47 51 43 55 60 56 65 50 41 59 54 43 50 55 43 48 60 46 41 42 42 45 49 53 53 44 51 37 57 49 55 59 44 47 51 40 44 54 45 55 48 56 53 45 45 54 41 62 53 49 51 43 43 57 47 55 64 43 53 46 34 52 52 63 51 55 40 65 44 42 56 71 53 41 47 36 48 45 60 38 53 47 55 58 44 50 56 41 49 43 40 48 41 44 42 48 60 50 45 61 53 53 38 77 41 51 48 55 38 52 57 60 52 44 54 55 43 55 47 63 37 43 41 46 53 63 32 38 48 51 50 51 46 53 51 50 64 45 52 47 45 59 48 56 48 51 38 53 54 49 41 50 54 53 58 50 58 56 45 53 48 48 45 55 52 40 46 37 44 53 53 48 33 54 42 46 49 46 41 52 66 49 60 51 56 44 51 58 40 50 54 53 47 48 57 47 54 46 53 44 52 52 54 45 43 55 52 36 47 48 58 52 56 48 48 62 38 70 47 47 45 57 50 49 50 41 49 44 63 61 63 49 54 42 41 51 61 47 43 59 41 45 44 58 48 41 49 54 39 40 54 57 51 60 61 45 44 53 36 55 42 39 43 56 49 52 57 50 57 74 48 50 68 48 60 49 46 64 46 58 42 53 55 56 50 51 59 41 53 49 45 49 46 43 53 57 50 44 55 56 52 44 44 60 32 44 59 57 42 55 42 40 62 45 46 46 42 58 47 55 63 43 64 50 51 55 48 47 45 44 45 57 48 56 54 49 47 52 54 60 51 53 51 53 54 47 46 51 66 53 57 52 38 42 51 49 59 39 44 40 49 64 51 47 65 49 60 64 37 53 55 59 45 55 37 54 33 49 55 62 48 49 58 55 44 58 47 58 55 52 51 59 62 50 45 55 48 51 43 46 39 44 53 47 47 62 56 42 60 55 49 39 37 61 48 42 49 48 61 54 59 52 40 54 38 61 51 53 60 59 63 55 60 39 44 54 56 54 48 40 34 46 54 50 54 51 52 64 57 44 64 43 40 41 47 44 60 53 59 48 53 61 54 53 45 42 45 51 41 49 48 53 52 45 55 55 44 48 51 49 60 49 58 40 43 51 46 53 55 46 47 50 48 50 56 46 51 43 61 48 41 57 52 51 48 51 54 34 46 44 47 48 48 47 51 50 60 47 63 62 50 42 56 42 50 60 55 39 55 38 36 57 44 45 65 52 57 51 46 42 47 50 45 53 53 44 38 51 64 58 50 56 50 59 44 46 48 51 43 62 55 54 48 52 41 48 46 41 49 53 60 68 49 53 39 54 52 37 38 56 48 50 38 42 50 54 59 44 55 65 52 38 57 50 56 51 53 52 56 39 57 48 51 45 47 48 49 61 59 67 68 51 54 58 58 52 39 60 49 44 57 44 46 44 54 60 48 37 49 55 48 53 58 48 55 37 49 47 43 39 42 45 36 58 56 61 55 45 53 41 38 43 53 54 43 48 46 46 43 50 40 48 52 49 57 53 42 52 57 47 70 45 48 42 57 45 61 45 45 43 51 51 51 56 44 55 51 53 40 60 51 52 51 65 47 42 54 37 55 47 54 70 46 54 42 66 50 57 51 37 65 59 48 54 53 46 55 52 44 42 50 55 67 59 58 44 66 49 40 59 52 37 58 67 33 50 61 36 51 55 57 57 45 47 49 47 57 51 59 40 44 45 56 68 40 57 55 42 46 55 57 52 62 55 53 56 47 45 42 48 39 51 55 48 55 48 63 36 47 45 56 53 50 59 48 62 53 51 43 55 45 33 60 52 52 58 46 50 44 49 54 46 52 60 53 51 61 56 58 51 50 36 45 62 57 59 62 41 57 59 51 51 50 44 56 41 43 45 47 51 40 54 54 42 61 51 67 40 42 44 54 61 42 51 52 63 59 47 42 50 58 39 42 45 58 52 47 54 59 46 37 41 43 63 48 57 49 40 57 63 40 34 51 47 47 42 44 51 51 48 48 34 63 49 46 40 35 52 44 46 62 57 42 57 53 48 47 61 50 41 42 45 43 49 57 42 41 45 56 46 59 50 50 51 58 43 52 39 51 34 38 46 43 59 39 47 50 45 50 58 49 43 59 45 49 56 51 55 54 48 46 44 69 41 48 54 40 49 55 46 57 62 60 53 49 50 46 55 51 44 50 52 59 49 62 39 50 53 54 71 60 47 48 57 38 46 61 54 58 54 44 51 64 49 53 53 56 62 52 56 45 49 48 52 57 45 49 53 39 53 51 52 57 50 49 55 43 50 65 50 46 56 39 52 53 60 46 27 52 53 43 63 46 50 56 60 49 47 50 47 61 49 59 45 50 49 48 48 60 49 38 62 56 45 51 39 47 48 61 42 58 43 55 56 66 42 56 65 49 55 42 41 49 52 48 51 53 43 45 43 54 59 51 47 52 56 51 48 40 48 43 52 56 48 46 41 40 48 40 55 48 48 61 49 42 53 52 55 44 44 44 47 47 44 51 46 56 49 44 50 56 44 32 42 41 41 48 40 44 47 51 52 51 59 39 38 57 60 44 56 64 41 60 62 52 47 48 51 58 51 46 54 50 52 43 61 55 57 51 54 39 52 41 50 40 49 62 47 40 43 45 41 60 39 49 68 53 46 54 52 49 67 55 61 50 64 45 57 54 42 52 45 55 38 39 57 65 47 45 51 51 55 47 48 58 47 52 45 62 52 52 61 51 63 63 49 56 43 45 57 56 50 45 56 56 46 56 53 58 43 46 44 58 46 57 51 46 51 47 50 55 51 49 60 41 32 50 55 45 56 46 55 65 51 53 60 46 36 61 52 48 39 45 41 38 54 54 45 56 39 59 55 52 49 61 51 49 45 52 65 55 46 49 36 51 61 57 43 50 43 63 54 42 53 58 40 64 52 55 62 45 62 51 56 81 70 46 63 54 61 52 55 63 49 66 47 57 63 56 62 59 38 62 45 51 67 58 54 65 49 55 63 66 53 63 61 51 60 36 58 62 47 58 57 52 47 66 67 56 46 62 58 44 57 48 51 56 43 55 46 61 56 48 51 66 51 49 55 52 51 40 64 48 51 50 52 56 60 53 59 54 53 48 72 35 49 52 37 61 38 44 56 54 49 63 62 78 43 45 50 48 46 39 61 57 51 45 48 56 56 45 51 63 47 46 55 50 53 49 38 45 57 55 59 40 47 46 44 47 52 52 48 48 47 63 57 59 46 49 55 42 55 38 38 52 52 44 43 51 44 58 50 55 41 52 50 61 51 51 49 44 48 49 62 54 58 46 58 52 57 58 45 43 52 36 59 51 55 65 52 52 47 49 41 44 52 37 66 50 80 40 45 55 52 35 55 40 53 49 46 41 61 45 50 49 64 56 44 51 63 59 50 50 51 52 58 54 46 68 54 42 58 45 50 68 66 43 38 44 57 46 41 62 68 41 50 55 52 49 39 58 59 47 56 60 50 57 57 50 68 46 45 52 47 55 54 42 52 49 47 50 47 53 41 58 56 51 47 64 35 33 44 46 58 58 46 51 48 42 61 45 66 40 50 51 53 56 58 46 55 43 48 52 52 51 55 66 56 44 47 46 30 51 47 61 56 41 51 49 51 59 51 44 47 47 49 55 37 50 49 54 53 47 59 45 47 51 46 56 49 60 45 43 52 55 45 45 51 43 65 49 40 47 60 52 48 40 52 42 45 36 36 41 49 56 57 45 47 40 58 53 44 52 41 39 50 45 46 39 42 46 40 54 63 56 57 47 58 39 49 64 57 45 49 41 55 49 39 50 42 44 55 55 40 64 44 42 46 45 37 54 52 51 55 32 39 50 53 46 45 58 40 55 50 50 43 58 55 65 53 53 50 48 42 49 56 54 53 60 54 50 56 48 57 46 54 44 50 52 43 47 56 38 58 53 48 39 48 53 46 58 49 49 47 50 49 52 35 57 41 52 44 53 48 56 51 47 46 58 62 43 59 51 55 47 52 55 51 46 56 45 47 44 51 50 48 63 40 40 38 45 44 51 50 51 43 52 56 63 54 47 58 53 45 46 34 47 62 45 51 59 54 49 46 54 50 50 48 58 48 58 48 59 43 57 42 38 52 67 49 56 40 47 38 48 53 40 47 50 41 49 47 51 42 40 48 45 44 36 57 44 45 42 57 56 48 59 33 44 57 44 55 52 53 55 39 51 48 40 42 55 44 36 48 51 56 49 52 43 55 47 58 47 62 60 50 57 54 57 42 52 53 42 47 49 65 47 51 59 54 36 55 43 46 39 56 40 50 46 40 56 50 45 61 44 57 51 47 44 50 45 54 63 51 51 47 40 64 50 46 49 59 50 53 65 47 55 56 60 43 64 47 43 44 46 36 39 38 40 44 49 51 50 53 50 49 61 34 58 43 52 37 49 53 51 47 48 38 38 49 56 25 50 50 49 40 48 43 42 41 49 64 47 64 46 55 58 40 51 42 47 71 50 66 54 48 41 53 60 44 46 55 62 61 52 48 58 47 43 42 47 32 57 50 50 51 51 47 49 42 51 60 38 55 57 52 66 62 47 54 54 59 42 36 56 51 42 59 38 47 39 61 53 40 39 38 37 53 56 54 56 53 46 53 54 56 47 58 50 50 54 51 58 64 59 60 58 60 50 54 54 58 57 46 43 59 50 53 55 53 43 53 48 48 50 46 57 38 50 45 39 42 43 47 40 44 36 47 53 39 53 49 44 56 34 58 48 49 49 59 53 49 57 61 59 44 51 46 45 60 48 53 52 47 59 45 47 46 60 46 69 55 54 45 46 38 51 53 51 61 53 50 52 50 48 52 47 53 59 48 71 47 59 54 52 45 42 58 52 56 55 47 40 59 57 47 28 48 50 37 49 49 60 60 61 68 48 47 42 47 60 51 55 45 58 40 42 47 60 42 61 54 51 44 47 57 48 55 48 61 48 59 46 46 46 48 53 53 45 42 57 45 45 59 55 42 59 35 44 40 48 65 49 45 49 48 51 63 46 49 65 47 52 48 46 48 47 55 57 47 46 55 54 49 41 41 46 53 53 54 38 43 50 46 43 51 42 40 45 52 40 40 45 49 48 52 57 43 45 52 43 57 60 49 53 42 31 47 41 59 43 55 50 44 58 38 54 50 51 49 50 48 60 44 50 52 39 39 62 54 39 45 45 51 51 58 58 42 50 60 34 48 37 52 52 47 36 43 48 56 65 53 62 44 44 38 47 52 42 48 45 47 45 48 46 41 42 37 35 41 55 49 52 44 57 42 33 51 59 51 44 55 55 56 44 45 57 54 53 58 48 34 49 41 45 56 49 47 48 48 52 55 36 45 59 51 42 57 51 49 49 64 47 51 46 44 52 59 48 54 41 42 59 54 47 52 43 54 32 49 49 37 55 46 56 51 34 49 60 37 39 46 43 47 55 41 57 56 48 52 36 36 54 52 48 55 50 48 36 56 52 48 44 54 61 52 59 44 41 46 41 42 62 54 53 59 53 44 47 50 37 38 43 54 42 47 51 45 44 54 53 51 52 52 40 50 50 50 43 48 66 57 47 69 44 53 46 37 48 54 53 49 59 58 62 43 39 47 46 49 54 40 39 59 61 43 49 53 59 52 35 51 53 39 49 51 42 50 43 40 42 51 47 46 45 40 50 43 49 52 57 41 48 71 51 55 54 52 46 52 53 47 44 51 55 62 41 45 50 41 55 46 52 43 53 46 54 46 57 55 61 62 56 50 52 45 45 57 45 50 38 59 50 55 51 51 45 53 55 50 55 45 41 60 43 53 44 47 39 48 50 52 45 48 62 51 53 49 54 46 50 30 51 36 53 44 45 52 37 64 50 50 51 61 54 53 58 39 55 48 58 48 52 49 65 48 52 44 62 48 52 41 46 48 46 36 37 54 45 39 36 47 47 42 60 63 46 62 47 48 52 51 52 56 41 48 40 63 60 59 44 45 48 54 54 54 37 45 46 55 41 53 49 55 41 44 40 46 52 52 53 41 43 41 50 43 55 47 52 47 43 42 50 56 58 48 61 47 49 63 51 50 58 46 51 48 37 41 40 46 59 59 51 42 50 53 45 59 68 55 57 53 50 41 49 54 42 58 52 54 41 42 51 41 49 44 58 44 64 37 51 51 46 55 62 62 47 48 46 58 47 77 39 42 59 39 61 45 41 57 52 53 43 61 50 47 56 53 46 47 48 47 62 64 52 60 43 47 43 68 50 46 42 46 50 53 56 40 38 46 38 59 56 43 50 43 50 45 41 51 56 42 61 51 50 47 68 58 53 44 43 53 50 54 53 53 45 42 45 49 47 49 46 38 44 63 55 50 50 38 51 60 56 46 38 45 48 38 45 46 47 52 40 52 45 47 49 48 49 43 55 49 56 45 41 55 53 57 41 47 51 45 54 52 54 54 69 49 54 51 60 65 58 45 43 50 44 51 58 39 51 53 63 44 51 58 53 54 61 48 38 58 45 49 51 50 57 52 54 41 43 50 47 52 46 46 51 48 39 48 54 51 66 43 56 42 42 43 46 47 46 44 54 53 56 49 56 51 38 31 48 50 51 47 56 66 46 49 38 49 46 53 63 64 40 44 61 47 46 57 58 46 51 54 53 46 46 56 47 56 51 54 57 55 52 36 42 56 48 64 45 39 60 46 49 54 56 49 55 56 36 36 50 47 51 64 56 49 44 43 49 44 58 51 63 46 51 51 43 59 55 55 45 43 46 59 56 51 52 58 51 55 53 46 54 61 60 62 54 43 58 54 45 39 66 50 56 55 53 40 55 38 57 46 55 49 62 43 46 57 53 44 52 46 47 64 59 57 59 54 40 56 38 44 66 59 50 55 44 39 39 61 49 64 45 55 44 51 58 44 54 52 61 60 43 42 51 43 51 44 41 65 55 42 51 54 49 54 51 59 64 51 53 43 59 49 59 50 37 57 47 58 45 45 42 52 49 53 56 46 46 50 41 61 56 66 37 59 45 47 48 55 47 45 56 57 43 51 41 43 53 52 58 44 45 41 60 47 53 53 56 51 51 49 36 54 59 44 47 52 52 34 48 57 52 46 49 59 55 53 57 45 55 58 53 40 49 56 47 52 47 55 34 61 55 57 41 57 47 59 41 51 58 56 53 55 44 58 54 55 64 54 52 53 44 46 32 43 43 51 43 55 48 48 38 63 52 56 57 41 65 48 50 53 58 44 50 62 43 33 52 46 41 50 42 67 47 53 37 44 46 48 54 45 49 52 62 42 43 54 48 48 42 45 50 43 54 60 47 41 47 57 52 60 50 34 48 37 50 55 39 53 51 52 50 49 38 54 56 56 50 54 56 52 54 48 55 59 53 44 54 36 64 42 57 45 63 57 42 46 57 42 42 62 56 61 54 40 47 45 66 48 54 41 55 55 56 37 56 61 51 68 49 57 60 60 52 61 41 53 51 46 52 45 46 50 46 52 46 62 46 58 44 61 47 46 48 41 43 57 47 47 56 52 65 54 51 54 35 58 49 49 59 40 52 38 31 49 47 55 48 50 57 44 45 55 46 44 63 53 52 55 44 50 56 42 52 47 52 46 47 55 35 53 46 54 52 53 56 67 51 58 40 42 62 59 48 63 53 49 51 45 48 43 46 55 55 55 49 41 48 44 52 44 44 51 34 58 48 37 38 70 49 50 46 37 54 60 45 55 57 57 52 42 40 48 55 46 47 46 45 51 53 42 48 58 47 49 43 58 51 51 54 59 51 55 58 50 54 54 51 52 44 49 46 46 41 39 36 40 48 54 47 47 52 49 37 45 64 45 56 44 52 54 52 50 49 54 45 42 39 43 53 49 53 41 55 47 35 44 44 52 50 53 52 63 47 47 57 47 46 56 46 52 45 48 56 58 48 44 56 63 50 55 47 57 57 58 50 45 63 52 49 53 44 63 55 40 52 46 61 55 53 59 46 61 44 44 52 58 51 57 62 47 42 48 46 45 50 56 47 41 58 47 56 66 44 47 42 47 51 41 50 36 46 53 56 49 52 51 53 52 42 47 59 42 42 46 50 48 40 38 43 48 45 50 52 47 56 50 39 44 43 62 51 54 53 56 55 57 48 41 46 55 49 52 43 41 49 70 58 59 52 43 58 48 38 60 39 48 54 54 50 63 41 54 43 53 46 51 63 45 63 60 51 49 57 60 50 56 47 59 49 59 50 48 56 47 55 49 67 47 50 64 42 47 60 44 50 59 59 36 57 45 38 58 46 49 47 61 37 52 56 41 51 49 55 46 34 50 37 39 47 51 49 44 48 67 57 62 65 65 57 45 44 48 56 55 48 62 43 54 41 47 52 46 53 43 47 46 45 40 43 45 46 44 54 39 51 51 45 47 50 37 59 44 45 47 51 46 61 54 41 52 40 40 59 52 48 58 57 55 61 60 44 51 44 34 49 72 51 43 47 46 65 49 51 52 59 59 56 53 46 41 48 47 54 45 53 45 38 45 38 54 57 48 74 53 49 51 59 62 61 50 46 53 53 47 43 49 46 51 49 41 51 49 49 45 47 41 45 39 51 46 56 40 42 57 55 37 44 43 56 45 46 37 50 35 46 56 59 40 42 39 47 55 67 44 49 61 47 55 58 44 42 52 36 43 55 57 52 44 57 48 54 37 51 47 41 52 63 42 41 54 53 55 43 57 42 50 46 40 50 52 44 49 47 43 40 43 51 50 61 42 47 38 48 57 41 53 41 53 72 55 53 32 74 48 42 49 61 67 54 43 41 43 38 72 43 53 42 48 62 47 43 51 62 40 44 66 71 48 56 63 52 45 51 50 55 52 50 46 63 54 57 58 41 48 44 48 50 44 46 39 53 55 55 54 53 48 30 55 55 52 64 60 59 56 53 55 33 56 41 46 65 59 60 50 54 58 42 44 55 55 46 46 45 36 52 43 51 56 46 41 47 58 61 68 44 47 53 40 45 51 54 48 54 40 48 49 40 43 66 50 46 45 45 48 50 54 44 58 45 55 44 39 45 52 46 55 40 47 51 50 46 43 50 43 51 47 40 47 47 37 53 50 55 53 42 53 42 39 29 52 61 59 45 60 47 51 45 47 53 52 48 56 41 48 49 51 29 51 50 50 58 48 68 63 47 55 45 42 46 51 47 67 60 46 47 45 55 43 62 42 58 47 36 37 49 45 54 52 55 42 55 52 43 49 46 54 51 44 47 51 49 50 47 45 49 39 50 40 53 43 62 62 49 36 56 48 60 52 41 53 57 45 46 45 48 51 42 47 56 52 49 42 53 43 49 45 56 50 44 49 48 46 44 51 57 53 55 50 45 46 60 50 31 55 62 51 52 61 49 48 49 45 42 42 42 54 58 43 49 42 58 48 55 42 47 44 57 54 47 61 42 59 49 44 47 50 46 57 39 45 36 43 64 35 46 47 53 47 60 44 45 46 62 41 56 51 40 47 55 55 39 49 37 50 41 42 53 39 51 53 40 60 48 46 61 52 58 58 42 54 39 49 47 63 55 46 52 47 53 47 35 48 50 47 51 39 46 45 45 47 42 44 52 50 40 51 50 48 53 45 50 55 58 47 57 49 54 50 57 45 54 46 36 45 42 42 39 65 60 53 59 53 57 48 62 48 50 51 53 42 48 52 45 53 44 51 45 42 45 70 53 51 43 55 41 40 60 50 43 51 46 53 39 60 53 52 47 46 45 47 53 39 32 60 39 45 60 69 42 55 61 57 45 58 34 48 39 42 53 53 50 46 45 50 47 43 60 52 55 56 48 47 47 42 44 50 57 54 58 54 53 45 44 38 50 51 43 53 61 54 52 45 52 48 58 42 37 49 47 55 46 40 47 65 57 46 63 46 50 44 48 50 56 47 38 53 51 47 32 48 52 37 43 41 43 46 37 65 49 52 47 49 48 40 58 45 69 46 64 39 51 56 50 52 52 50 53 53 49 50 58 47 57 52 48 50 50 33 49 51 58 50 40 51 46 52 57 43 46 49 54 62 47 51 50 51 44 49 43 54 46 45 57 59 58 61 53 47 57 57 52 59 49 62 45 46 37 59 47 57 44 47 48 38 52 42 41 55 58 58 45 52 54 49 54 43 54 44 46 62 30 53 50 48 56 38 44 47 59 50 50 63 59 51 49 56 50 54 53 35 49 45 39 44 51 54 64 51 50 48 43 54 61 50 41 41 39 49 45 46 48 51 45 47 53 53 51 54 48 71 58 54 53 48 50 46 47 54 65 53 55 47 56 43 56 50 48 56 54 42 43 44 55 50 45 55 59 36 54 57 35 55 42 46 50 50 40 53 55 53 51 57 38 52 43 52 48 51 41 49 51 59 48 48 49 46 48 55 50 45 56 53 40 51 45 50 68 59 46 48 44 50 52 44 51 63 43 48 52 57 63 37 59 38 48 48 56 54 46 46 63 50 50 40 49 48 53 55 44 43 52 55 48 46 51 50 64 52 57 56 59 59 56 57 60 50 47 45 44 54 63 59 36 48 50 46 53 48 61 43 46 54 45 56 41 44 37 42 61 45 47 55 45 58 56 43 55 52 42 47 60 54 55 60 50 47 46 72 58 64 58 54 43 58 38 56 68 44 49 37 42 34 59 40 52 53 60 46 61 57 58 59 46 54 57 54 52 50 47 43 61 50 50 66 57 53 55 50 58 56 60 52 70 54 52 52 53 47 64 54 59 59 54 41 45 57 42 42 49 53 57 52 53 50 48 66 60 52 36 50 39 50 45 45 51 38 51 39 54 49 58 59 52 46 54 47 41 55 49 45 46 58 51 59 46 51 40 58 62 48 35 48 66 54 71 45 53 53 42 53 60 59 55 63 56 43 45 46 65 57 54 54 54 59 49 49 56 42 41 58 51 43 59 65 43 54 45 42 44 50 40 54 54 62 49 49 48 56 56 46 50 55 50 47 43 50 59 50 55 59 60 54 48 37 57 41 64 48 54 46 45 57 51 48 51 39 45 45 45 61 50 54 55 52 63 58 57 44 41 47 54 50 48 43 47 49 48 49 52 55 51 51 42 57 38 49 62 42 53 47 53 52 49 46 52 56 49 52 45 48 55 42 52 63 53 58 43 52 50 56 50 62 53 63 45 50 57 53 44 51 35 46 50 58 50 51 49 47 53 50 53 50 58 49 51 57 60 53 59 56 40 51 39 62 50 49 54 50 56 47 42 46 51 50 39 47 51 52 52 38 56 50 52 53 52 52 52 57 57 49 53 49 53 48 36 56 50 48 51 46 48 44 42 51 61 59 49 53 52 50 52 43 50 58 58 49 42 42 54 44 45 49 56 51 49 35 48 43 51 51 41 42 48 44 53 47 49 43 46 46 47 44 48 50 38 52 55 49 51 57 43 45 48 48 64 54 43 50 47 43 49 50 59 45 48 54 44 53 52 60 47 50 50 48 47 59 57 47 55 69 49 52 62 59 56 52 47 53 40 40 51 50 49 50 48 47 55 50 40 54 53 60 56 46 38 54 41 43 51 44 50 50 41 57 57 45 49 54 56 48 58 47 47 57 40 43 60 52 63 43 61 38 44 52 35 57 53 43 52 45 50 58 51 46 41 40 54 59 48 56 46 48 51 55 55 45 60 47 51 48 33 51 52 36 53 44 51 46 46 56 67 47 57 49 49 55 42 54 47 35 49 56 53 51 43 46 53 50 36 44 42 52 53 52 43 57 50 45 51 60 51 52 42 58 49 49 47 46 46 40 44 45 48 40 49 47 48 47 47 49 46 43 55 42 44 46 44 41 47 40 43 42 57 49 58 45 53 54 59 40 43 48 45 59 56 66 48 44 52 48 57 48 46 44 57 51 49 52 39 52 46 54 59 38 67 54 45 47 58 43 54 50 48 44 49 62 52 53 52 44 42 54 49 47 50 43 43 59 55 49 46 40 48 51 54 48 59 44 57 50 57 50 42 58 42 49 56 55 44 49 46 53 40 49 50 40 40 62 50 51 69 45 54 50 49 51 57 53 47 39 52 38 47 55 44 52 43 45 64 54 50 48 47 42 38 40 45 42 48 42 43 60 46 45 51 44 53 44 54 46 46 42 66 46 48 54 59 53 56 44 50 40 48 51 42 50 43 49 47 57 47 50 61 38 52 48 53 60 44 50 57 49 44 43 53 51 56 51 50 59 68 41 41 57 49 49 61 59 47 54 45 57 45 49 51 49 67 57 64 39 42 54 52 52 46 53 56 43 56 46 62 53 60 46 67 56 55 53 44 60 55 59 54 52 44 59 46 46 53 44 47 57 55 54 38 51 43 40 73 59 40 44 47 50 50 51 49 52 50 56 48 59 28 49 53 47 50 45 45 43 50 60 49 35 56 56 36 58 66 45 38 49 54 54 46 39 42 52 49 54 37 49 51 48 56 40 55 52 52 55 56 56 55 45 43 44 60 44 46 48 48 54 58 54 47 41 42 54 57 46 49 50 58 52 64 56 60 49 51 42 48 49 42 48 40 63 56 47 49 53 40 55 42 46 53 58 49 53 40 51 46 65 41 46 50 46 56 37 47 65 50 52 64 54 54 36 62 50 73 46 42 40 43 46 36 46 50 49 71 47 53 53 59 52 52 51 40 49 38 52 56 49 49 59 45 48 53 45 58 34 44 49 57 52 55 45 46 53 53 51 58 45 54 51 50 47 53 43 53 70 48 58 47 60 62 47 48 45 57 49 51 61 48 58 52 56 46 47 50 45 60 47 52 50 48 64 46 58 55 54 50 44 48 34 39 53 35 45 52 46 58 46 69 61 45 35 45 48 59 52 57 65 49 47 53 40 43 56 37 60 52 43 60 51 43 49 59 45 47 48 49 55 50 36 42 62 47 52 61 54 58 53 54 53 39 45 51 47 56 44 42 53 46 50 41 55 66 46 56 55 53 51 63 45 65 53 54 55 38 67 50 55 41 46 51 43 53 57 48 38 46 54 49 43 52 45 52 49 49 48 50 39 48 58 43 50 41 53 44 52 50 58 51 50 48 62 45 54 42 48 41 50 56 48 48 45 28 56 50 62 51 48 51 50 50 52 66 51 57 46 45 38 56 50 54 56 42 44 46 48 53 53 35 56 60 51 69 52 63 39 43 57 47 56 52 37 40 60 51 57 59 43 60 66 52 64 65 41 54 56 55 48 60 52 55 46 70 59 56 51 48 42 43 46 53 46 48 53 58 50 47 56 58 41 57 47 49 69 46 47 45 48 47 39 47 49 40 45 41 39 48 47 47 49 54 57 58 54 37 55 49 42 63 46 59 60 50 58 49 36 66 42 40 48 60 46 54 48 64 47 63 43 49 48 53 58 53 42 36 59 55 57 51 49 39 55 40 56 68 66 60 52 51 56 55 49 39 47 49 52 50 54 46 50 51 49 56 47 57 42 53 49 48 45 51 45 45 61 46 51 53 41 55 45 57 61 46 34 57 54 46 42 41 50 36 49 45 44 53 38 51 43 51 59 48 53 56 49 53 42 57 54 43 55 55 43 50 51 60 54 57 41 64 37 58 45 51 54 54 47 49 61 42 55 57 38 46 57 58 53 44 60 41 57 57 54 54 48 48 68 47 52 45 56 47 53 43 38 59 46 35 57 55 57 51 41 71 51 59 37 48 54 52 46 51 58 52 47 51 52 46 40 37 61 52 44 44 58 43 49 43 48 48 42 38 50 43 51 51 46 52 46 61 47 41 56 52 54 57 54 50 40 46 45 49 51 37 50 56 58 51 46 55 48 51 52 44 46 38 43 39 54 48 37 42 52 53 47 48 62 45 56 57 50 49 51 55 55 53 45 45 49 61 56 52 54 41 49 57 41 49 62 50 52 57 45 50 51 41 39 41 61 43 55 43 52 57 42 37 53 48 61 49 50 54 42 39 49 40 54 31 34 55 49 37 63 41 57 51 41</counts>
			</dataPoints>
		</scan>
	</xrdMeasurement>
</xrdMeasurements>