File: data/XRD/GIXRD/sample_holder.xrdml
<xrdMeasurements xmlns="http://www.xrdml.com/XRDMeasurement/2.1" xmlns:xsi="http://www.w3.org/2001/XMLSchema-instance" xsi:schemaLocation="http://www.xrdml.com/XRDMeasurement/2.1 http://www.xrdml.com/XRDMeasurement/2.1/XRDMeasurement.xsd" status="Completed">
	<comment>
		<entry>Configuration=Factory configuration, Owner=User-1, Creation date=7/8/2013 4:01:53 PM</entry>
		<entry>Goniometer=PW3050/65 (Theta/2Theta); Minimum step size 2Theta:0.0001; Minimum step size Omega:0.0001</entry>
		<entry>Sample stage=MRD Cradle; Minimum step size Phi:0.01; Minimum step size Chi:0.01; Minimum step size X:0.01; Minimum step size Y:0.01; Minimum step size Z:0.001</entry>
		<entry>Diffractometer system=XPERT-PRO</entry>
		<entry>Measurement program=C:\PANalytical\Data Collector\Programs\Sofie\GIXRD_om_fest-2deg_2theta-10deg-80deg_40s.xrdmp, Identifier={5D08F084-E282-4D09-BA8B-67D165D754DE}</entry>
	</comment>
	<sample type="To be analyzed">
		<id></id>
		<name></name>
		<preparedBy></preparedBy>
	</sample>
	<xrdMeasurement measurementType="Scan" status="Completed" sampleMode="Reflection">
		<comment>
			<entry>PHD Lower Level = 4.83 (keV), PHD Upper Level = 11.27 (keV)</entry>
		</comment>
		<usedWavelength intended="K-Alpha 1">
			<kAlpha1 unit="Angstrom">1.5405980</kAlpha1>
			<kAlpha2 unit="Angstrom">1.5444260</kAlpha2>
			<kBeta unit="Angstrom">1.3922500</kBeta>
			<ratioKAlpha2KAlpha1>0.5000</ratioKAlpha2KAlpha1>
		</usedWavelength>
		<incidentBeamPath>
			<radius unit="mm">320.00</radius>
			<xRayTube id="1010048" name="Empyrean Cu LFF HR (9430 033 7310x) DK442154">
				<tension unit="kV">40.0</tension>
				<current unit="mA">40.0</current>
				<anodeMaterial>Cu</anodeMaterial>
				<focus type="Line">
					<length unit="mm">12.0</length>
					<width unit="mm">0.4</width>
					<takeOffAngle unit="deg">4.2</takeOffAngle>
				</focus>
			</xRayTube>
			<xRayMirror id="27010001" name="Inc. Beam Cu W/Si (parabolic MRD)" hybrid="false">
				<crystal type="Graded" shape="Parabolic">W/Si</crystal>
				<acceptanceAngle unit="deg">0.800</acceptanceAngle>
				<length unit="mm">60.0</length>
			</xRayMirror>
			<sollerSlit id="21010002" name="Soller slits 0.04 rad.">
				<opening unit="rad">0.0400</opening>
			</sollerSlit>
			<mask id="22030008" name="Fixed mask 4 mm">
				<distanceToSample unit="mm">220.00</distanceToSample>
				<width unit="mm">4.00</width>
			</mask>
			<divergenceSlit id="22010011" name="Fixed slit 1/32°" xsi:type="fixedDivergenceSlitType">
				<distanceToSample unit="mm">220.00</distanceToSample>
				<height unit="mm">0.05</height>
			</divergenceSlit>
		</incidentBeamPath>
		<diffractedBeamPath>
			<radius unit="mm">320.00</radius>
			<sollerSlit id="21010002" name="Soller slits 0.04 rad.">
				<opening unit="rad">0.0400</opening>
			</sollerSlit>
			<receivingSlit id="22010001" name="Fixed slit 4°">
				<height unit="mm">5.88</height>
			</receivingSlit>
			<detector id="7010017" name="PIXcel3D 1x1 detector" xsi:type="areaDetectorType">
				<phd unit="%">
					<lowerLevel>30.0</lowerLevel>
					<upperLevel>70.0</upperLevel>
				</phd>
				<mode>Scanning</mode>
				<activeChannelsEquatorial>255</activeChannelsEquatorial>
				<activeChannelsAxial>255</activeChannelsAxial>
				<pitchEquatorial unit="mm">0.05500</pitchEquatorial>
				<pitchAxial unit="mm">0.05500</pitchAxial>
				<readOutPeriod unit="seconds">0.155</readOutPeriod>
			</detector>
		</diffractedBeamPath>
		<scan appendNumber="0" mode="Continuous" scanAxis="2Theta" status="Completed">
			<header>
				<startTimeStamp>2024-10-18T14:08:16+02:00</startTimeStamp>
				<endTimeStamp>2024-10-18T14:46:23+02:00</endTimeStamp>
				<author>
					<name>PRO-MRD</name>
				</author>
				<source>
					<applicationSoftware version="6.1b">Data Collector</applicationSoftware>
					<instrumentControlSoftware version="7.0E 20130304">XPERT-PRO</instrumentControlSoftware>
					<instrumentID>0000000011142674</instrumentID>
				</source>
			</header>
			<dataPoints>
				<positions axis="2Theta" unit="deg">
					<startPosition>10.00246193</startPosition>
					<endPosition>79.99507515</endPosition>
				</positions>
				<positions axis="Omega" unit="deg">
					<commonPosition>2.0000</commonPosition>
				</positions>
				<positions axis="Phi" unit="deg">
					<commonPosition>0.00</commonPosition>
				</positions>
				<positions axis="Chi" unit="deg">
					<commonPosition>0.00</commonPosition>
				</positions>
				<positions axis="X" unit="mm">
					<commonPosition>0.00</commonPosition>
				</positions>
				<positions axis="Y" unit="mm">
					<commonPosition>0.00</commonPosition>
				</positions>
				<positions axis="Z" unit="mm">
					<commonPosition>9.100</commonPosition>
				</positions>
				<commonCountingTime unit="seconds">37.995</commonCountingTime>
				<counts 328 301 313 306 310 322 303 265 297 307 292 333 303 292 307 287 308 323 299 306 319 288 320 303 309 319 311 353 322 308 304 309 305 304 289 322 317 336 307 295 302 287 305 233 320 328 322 307 327 298 316 330 317 320 306 320 286 294 308 290 268 305 292 295 285 300 333 315 326 303 298 310 325 293 329 300 249 318 297 316 299 301 288 302 323 311 288 298 284 300 312 318 325 322 319 320 315 306 288 298 302 279 311 273 313 287 315 292 302 294 310 304 301 309 312 300 317 327 299 326 302 322 315 343 332 270 281 291 304 321 293 327 322 312 280 316 325 302 297 326 305 312 293 293 278 313 328 323 292 311 308 276 319 333 325 297 293 293 315 302 317 335 311 280 280 326 332 320 275 279 300 287 315 317 295 306 289 316 327 320 271 283 318 277 274 307 335 305 320 298 301 296 304 321 313 290 290 291 301 296 304 294 270 322 325 302 290 304 303 312 285 285 328 320 269 353 293 283 295 324 282 296 280 294 307 267 307 274 313 328 304 298 334 270 289 284 300 296 279 281 315 311 318 320 300 293 306 310 299 299 303 297 280 329 328 312 289 308 315 282 262 309 329 290 293 307 264 292 288 315 274 276 304 303 268 303 315 308 298 290 309 305 311 314 287 301 327 278 297 318 295 290 277 310 277 299 305 283 264 271 272 281 278 287 276 296 302 314 283 272 299 272 314 298 285 295 330 321 314 278 307 291 314 275 307 277 304 273 311 268 284 275 283 307 299 301 327 273 314 304 275 288 307 288 267 331 298 306 329 311 280 312 311 290 286 317 285 333 261 312 305 306 298 283 275 333 259 265 301 309 292 274 306 293 291 323 328 310 274 288 294 286 289 286 286 293 287 290 286 322 298 293 314 273 316 273 277 317 294 275 262 309 269 295 282 298 286 290 312 272 257 302 296 303 297 274 324 318 325 296 247 295 300 273 295 300 281 295 257 296 288 295 279 296 287 263 284 271 302 307 275 272 282 290 305 306 275 288 297 287 289 285 281 272 261 275 255 268 286 295 273 294 285 312 268 257 324 322 296 283 282 303 305 270 272 282 287 267 257 279 266 289 317 286 265 282 302 295 275 286 243 301 274 306 286 297 270 263 300 272 270 280 300 302 307 272 273 284 298 289 293 296 284 250 264 290 293 308 305 277 271 286 277 292 292 277 289 286 304 272 296 274 295 279 294 271 284 273 285 285 264 298 293 308 249 289 280 279 287 294 287 288 255 268 284 269 239 305 319 289 310 285 285 278 292 275 262 312 282 289 286 287 270 295 288 281 299 293 275 291 265 293 286 285 289 297 328 281 282 281 263 281 298 280 289 284 263 304 314 283 301 300 261 288 284 285 257 280 270 291 290 292 267 311 294 286 331 288 266 276 290 270 283 306 268 277 307 285 325 287 289 249 296 264 278 297 294 246 291 273 273 259 289 236 293 270 273 298 282 301 285 289 263 269 281 287 265 263 275 305 260 283 282 274 300 288 285 281 290 278 278 297 270 255 315 290 278 291 272 294 301 299 245 282 236 261 301 291 292 277 319 289 289 267 277 287 267 311 306 306 248 250 282 291 285 274 318 289 270 284 281 301 275 307 250 235 259 288 249 260 272 288 265 268 294 268 279 263 296 288 267 255 281 279 295 260 292 269 315 241 288 292 248 276 291 293 292 282 256 273 262 272 279 303 276 261 267 273 262 263 305 296 329 296 257 288 295 260 308 292 289 258 277 268 245 295 288 280 294 281 287 278 259 260 271 272 274 246 309 239 315 283 291 276 235 281 227 255 284 260 266 276 306 279 249 266 276 294 295 229 270 277 279 274 267 291 248 275 280 267 260 318 300 289 287 268 247 295 274 244 268 267 256 283 271 296 269 284 260 277 328 296 281 281 255 297 268 308 306 261 262 276 283 283 273 256 255 264 296 284 281 272 275 284 243 285 289 299 279 272 262 267 282 287 277 267 249 266 244 272 272 269 262 249 262 280 280 247 262 283 279 264 286 256 296 272 256 268 304 287 299 315 267 268 262 291 264 285 243 228 290 260 283 281 268 292 292 265 277 278 283 295 262 273 277 275 305 273 276 269 267 276 304 267 296 297 261 295 287 277 272 260 273 246 278 277 276 276 301 280 275 263 280 239 257 262 274 274 244 282 270 240 261 276 262 276 300 235 237 281 246 294 282 265 240 270 263 280 274 271 268 274 263 274 282 267 272 278 287 300 248 248 220 267 279 256 244 278 274 276 310 258 294 279 289 247 245 261 283 236 258 278 266 257 256 250 272 248 276 255 258 268 269 267 262 262 244 262 237 296 290 292 236 275 246 244 282 280 262 274 250 247 273 305 237 259 268 258 264 279 256 230 239 243 237 247 276 298 242 269 242 273 246 284 281 264 282 268 262 257 250 275 266 256 267 256 255 264 239 245 271 259 262 284 284 239 270 247 273 256 265 256 263 236 279 287 282 239 269 239 285 280 305 276 264 240 277 246 264 249 294 262 278 255 226 234 264 300 280 288 262 268 236 289 242 273 271 266 259 294 283 264 247 240 284 233 257 275 233 249 235 285 257 266 272 281 287 276 247 260 277 273 286 282 276 299 272 241 259 260 268 249 261 293 267 244 287 288 239 288 271 268 242 256 271 248 239 244 273 260 249 257 273 282 238 236 219 261 241 240 223 266 275 286 270 264 265 273 244 315 229 277 260 281 268 278 272 257 257 264 242 242 303 277 261 232 295 232 265 225 281 297 255 261 285 311 246 242 236 247 265 261 250 262 257 274 267 237 244 265 274 272 263 261 278 260 238 266 270 278 212 260 273 242 262 263 262 286 292 247 286 235 288 234 238 276 269 257 266 241 294 244 277 238 244 234 214 281 278 246 237 258 262 227 241 240 243 242 270 225 266 240 243 274 267 242 271 258 274 278 271 293 244 269 289 277 244 267 262 282 270 256 287 265 265 260 258 278 245 279 282 275 223 283 275 264 277 290 285 266 267 274 267 256 266 246 292 249 245 235 243 237 226 248 247 287 248 279 266 239 270 211 243 275 260 244 257 268 245 245 243 257 269 248 270 243 271 294 257 247 243 268 274 245 258 246 248 256 261 266 242 265 241 273 276 227 263 250 238 241 262 237 238 263 272 243 257 278 216 265 255 223 208 222 239 243 221 242 247 268 274 237 291 259 264 227 263 269 270 246 237 223 247 249 247 269 248 255 262 264 275 258 278 266 246 282 238 263 248 274 248 272 235 267 287 240 261 240 271 273 263 258 247 233 269 245 241 249 261 277 224 240 235 244 238 230 213 285 232 237 235 270 214 245 260 272 268 275 279 242 277 255 268 260 262 237 227 266 266 262 279 242 262 245 301 240 221 263 255 260 290 240 241 261 241 226 228 271 261 249 260 243 259 259 237 257 260 240 240 221 242 266 280 246 239 235 273 268 264 226 227 245 263 256 276 255 236 259 243 241 216 230 234 216 256 239 257 263 208 275 258 257 230 231 272 234 248 224 265 240 284 244 276 260 260 270 218 268 278 280 245 230 277 255 267 243 228 263 239 269 248 265 243 242 274 257 224 232 247 271 274 244 227 274 257 246 229 256 281 240 232 235 247 231 239 281 240 246 277 238 230 275 234 247 255 245 244 227 230 242 221 261 244 268 276 265 245 247 267 232 230 228 231 221 243 239 249 245 236 268 225 234 239 245 206 241 264 248 241 271 234 245 225 236 281 255 257 222 217 277 240 239 242 213 260 261 244 273 249 248 227 245 232 262 268 243 255 239 257 213 244 259 244 260 266 244 287 244 240 236 260 255 228 269 255 241 256 259 258 257 236 243 280 220 212 212 246 245 226 260 243 261 288 245 234 240 259 250 228 283 259 264 229 258 260 259 260 235 278 246 268 230 272 246 223 269 262 229 258 278 242 275 275 249 258 228 269 256 242 235 237 239 236 240 248 273 240 249 224 225 248 244 243 266 228 228 241 249 228 248 229 236 241 255 235 239 207 218 247 255 260 199 243 250 271 248 235 240 260 246 269 228 241 223 258 244 258 265 237 230 232 246 258 244 247 258 244 219 247 244 243 217 239 233 248 213 229 258 237 240 275 229 248 236 247 241 247 250 247 261 244 258 263 209 204 224 224 246 235 205 218 204 232 221 258 219 228 240 232 234 229 267 241 261 232 231 239 233 237 229 238 225 242 236 212 227 214 255 248 234 235 215 226 255 235 209 238 230 266 212 239 246 231 258 228 247 225 243 239 259 229 236 235 222 209 247 220 204 244 230 223 226 230 220 237 267 239 226 246 244 256 237 218 214 230 209 283 223 232 214 244 238 238 208 234 243 266 224 204 228 219 235 204 262 236 238 261 183 241 235 220 229 206 267 232 243 272 234 231 213 250 221 220 226 247 228 229 245 245 206 218 239 274 249 256 203 238 241 264 248 234 248 249 209 218 234 245 236 230 228 223 225 238 233 237 221 229 230 240 226 235 262 206 222 220 187 210 234 225 231 222 247 229 222 225 234 238 218 222 236 259 224 233 224 234 220 209 205 218 230 233 242 205 239 271 248 236 242 232 242 210 217 225 217 214 206 270 225 201 195 230 265 222 213 220 242 233 235 238 237 220 231 208 212 241 230 222 221 243 235 203 200 207 203 233 228 211 231 224 226 240 245 231 187 209 208 215 205 227 231 191 222 211 229 230 265 236 207 197 208 215 215 224 225 224 207 229 237 200 238 207 226 229 205 221 208 225 217 237 193 235 224 225 224 235 199 236 207 237 234 227 214 220 238 211 189 224 220 199 248 202 228 269 214 238 226 216 207 231 203 259 248 187 211 219 239 227 214 210 207 213 239 229 243 234 236 229 214 206 194 231 222 201 220 199 233 230 216 195 199 227 198 226 215 230 213 230 193 169 196 211 242 218 222 209 201 220 221 196 205 225 204 218 211 221 239 216 184 225 200 207 203 209 202 214 241 231 222 216 235 222 225 184 216 229 235 199 187 239 215 226 209 210 201 210 211 218 208 229 211 207 198 206 223 220 212 219 197 190 183 205 203 205 197 220 221 211 210 200 193 237 194 194 220 208 232 200 207 208 241 196 206 222 215 216 194 225 211 225 212 255 234 190 186 192 212 212 215 202 196 190 194 193 208 185 194 199 210 189 239 186 209 209 199 224 220 200 206 229 194 256 189 187 223 219 216 210 194 214 207 189 180 189 187 224 192 192 203 219 206 191 193 182 203 199 211 223 217 239 219 204 225 202 209 206 189 217 206 219 208 187 204 193 208 208 211 207 168 217 203 175 198 224 221 219 198 203 190 196 199 187 188 214 197 227 200 208 198 195 199 208 205 203 188 195 201 216 188 204 192 188 174 183 183 194 206 208 217 172 209 212 218 204 173 219 187 213 214 206 181 201 212 207 186 176 193 214 240 217 209 178 200 188 198 176 202 189 178 201 192 207 191 199 191 187 173 205 171 182 205 202 202 193 202 202 185 195 231 196 198 197 185 186 179 193 190 200 208 189 190 202 176 194 198 198 202 185 186 190 183 193 185 193 223 191 192 188 187 214 201 183 195 212 192 196 180 192 212 213 195 175 184 197 206 208 197 205 200 172 197 179 186 178 184 178 222 215 194 213 199 191 188 180 202 203 200 185 218 200 209 203 203 205 182 192 206 200 201 201 178 208 183 195 197 204 187 197 192 209 204 196 205 196 189 214 212 207 194 199 195 200 184 190 178 177 199 186 189 195 175 182 203 185 188 187 190 192 204 195 195 173 208 192 201 231 157 181 203 220 191 201 181 218 187 180 200 211 214 200 196 178 180 192 170 148 177 195 196 195 177 195 186 191 203 194 192 185 195 198 183 198 204 161 196 185 159 202 190 193 183 209 168 176 194 198 168 220 207 173 178 197 190 185 188 181 185 170 186 199 183 181 193 192 183 179 199 191 207 174 161 173 192 198 179 176 151 189 199 177 186 193 185 220 204 180 186 193 174 182 206 174 182 187 196 193 177 194 196 169 166 186 199 166 196 197 192 167 172 174 174 184 197 192 194 182 186 180 186 156 160 156 181 175 196 159 177 199 190 185 184 179 192 200 177 187 181 180 163 177 196 171 180 183 177 172 192 165 168 191 187 186 205 163 181 187 180 173 176 156 198 210 166 166 195 183 193 164 177 195 173 168 172 161 197 210 176 177 181 163 189 181 180 165 182 200 168 143 184 182 174 178 169 212 156 173 177 180 183 180 184 161 157 185 175 149 176 167 182 168 176 186 185 163 184 189 166 156 155 189 132 185 175 200 164 187 168 173 177 150 179 163 178 180 153 196 181 169 176 173 172 194 176 154 153 192 153 166 169 175 172 171 199 141 174 147 187 151 159 162 189 166 170 180 167 182 187 151 186 194 167 151 186 178 167 173 187 149 161 180 166 183 166 173 186 176 175 161 146 176 185 171 156 187 191 181 141 182 170 177 177 214 159 177 155 183 164 143 166 140 190 173 171 172 158 180 160 146 169 156 172 183 159 170 166 183 172 180 166 169 166 156 186 170 184 159 169 186 171 185 148 162 194 152 173 159 164 184 174 164 172 201 164 176 160 154 179 148 162 174 143 166 154 173 148 159 158 178 169 178 155 185 148 168 168 181 148 188 174 158 157 144 164 177 176 180 147 169 151 183 151 154 147 152 164 165 171 147 170 164 172 157 165 157 165 154 179 187 138 151 171 152 168 165 166 162 154 167 167 158 174 119 165 175 155 157 158 152 163 147 169 156 185 159 165 185 177 150 150 171 151 162 168 166 184 177 146 153 162 163 167 155 154 156 165 156 141 167 152 147 159 175 146 168 160 156 158 135 148 178 153 154 147 166 171 160 189 167 130 162 145 187 164 158 147 150 155 154 165 172 152 176 162 174 140 187 193 160 171 152 166 156 146 130 142 161 167 160 158 117 167 159 165 133 138 163 170 156 149 151 158 159 160 165 170 146 162 162 170 166 140 147 152 152 157 140 177 173 149 164 158 159 168 137 177 121 172 129 144 157 154 158 139 162 171 126 173 164 158 168 155 180 184 178 143 174 132 173 153 139 159 176 179 162 168 173 162 164 167 171 173 161 153 162 154 166 182 159 169 163 157 174 178 153 169 165 173 179 172 179 188 203 185 177 208 214 174 213 198 186 209 215 208 208 235 239 220 244 247 235 207 264 269 274 243 263 266 282 295 301 285 289 278 291 311 292 277 314 335 295 359 364 338 323 327 327 342 336 321 325 323 343 346 331 308 337 284 344 324 314 303 320 291 324 311 340 318 305 280 228 262 279 263 247 278 243 233 260 247 236 200 221 247 199 229 248 195 194 212 183 167 183 208 181 153 173 179 157 182 172 166 172 173 176 162 170 166 157 162 162 141 145 167 160 138 139 181 149 155 157 157 136 142 152 154 145 168 136 148 143 141 147 146 155 155 151 141 139 139 144 146 139 135 122 145 130 153 149 131 128 129 139 136 136 140 168 142 127 135 140 138 148 138 123 110 125 136 146 142 138 109 144 134 130 152 124 139 150 133 133 137 133 148 150 135 131 135 127 129 120 133 113 116 141 115 148 129 130 126 150 117 136 122 130 125 145 140 148 129 133 121 120 143 118 132 132 120 146 120 146 115 123 127 141 124 154 138 125 130 130 122 122 118 118 131 130 146 139 122 151 120 107 137 121 110 128 117 139 138 130 127 138 126 121 122 111 116 132 142 144 118 114 120 140 124 118 132 142 128 122 120 124 118 133 133 125 125 127 113 125 146 141 119 122 111 134 155 108 132 107 139 125 136 137 135 109 130 128 144 128 124 131 125 119 139 126 123 118 124 129 126 114 122 138 120 132 148 105 141 108 130 109 137 128 130 116 109 121 132 138 121 115 138 113 110 118 114 113 118 135 121 108 105 122 132 113 143 119 125 122 133 108 128 118 136 119 114 115 107 117 146 99 129 123 125 120 137 125 123 122 132 134 116 126 107 123 112 129 107 95 126 110 100 134 130 105 122 125 125 124 107 101 110 125 105 142 104 128 111 120 108 120 132 128 136 130 113 145 134 121 142 121 130 110 109 109 133 119 125 115 125 102 118 118 128 117 135 103 139 104 128 117 108 118 110 129 112 96 114 116 123 107 108 111 104 119 101 111 110 110 108 133 109 106 98 104 114 114 123 124 124 122 114 114 101 105 113 129 124 119 125 110 127 120 107 107 115 113 110 97 103 133 106 101 108 109 106 130 139 128 122 108 98 108 111 113 110 119 130 106 122 122 102 116 107 121 96 112 101 110 128 144 131 112 130 129 108 95 120 117 100 130 89 116 98 116 115 114 112 102 102 112 110 117 112 129 98 129 112 103 119 112 87 119 120 90 124 103 116 113 129 118 117 115 121 111 104 103 115 124 95 117 107 119 125 120 111 118 103 124 108 113 104 130 113 130 98 115 119 110 101 113 103 90 100 138 105 120 105 108 113 108 116 124 110 89 127 129 106 111 127 102 96 101 121 119 107 107 101 128 98 124 98 106 105 104 117 126 110 115 122 120 107 133 91 113 88 96 91 113 109 106 87 107 105 117 99 99 113 113 93 101 101 110 122 104 118 104 129 98 124 107 119 127 117 103 99 102 104 115 95 114 117 116 101 97 119 114 99 109 106 119 89 130 111 123 101 104 111 101 118 102 109 100 109 95 99 104 102 96 105 113 98 105 111 99 119 105 130 103 113 93 94 103 87 117 103 123 115 108 89 104 98 111 111 119 102 129 108 92 108 115 114 100 100 110 105 129 101 97 79 86 123 92 99 105 111 89 111 108 105 105 104 86 102 100 130 127 79 96 94 102 96 105 113 101 114 82 120 86 109 105 121 91 97 91 87 108 100 104 106 100 99 94 111 106 94 112 103 102 100 99 93 110 92 104 101 89 113 94 99 105 108 123 88 101 113 96 114 111 104 104 101 105 92 117 105 100 90 106 103 105 90 92 103 105 99 110 94 109 101 102 91 91 102 93 99 94 103 97 91 79 87 85 106 97 101 109 95 97 105 99 121 81 105 105 95 94 93 116 100 88 96 100 77 102 94 103 86 86 97 101 102 99 76 74 101 97 102 95 104 103 89 102 85 92 96 80 94 108 80 109 88 96 105 90 101 92 102 83 101 82 95 98 98 100 98 104 102 79 90 97 95 88 90 113 86 90 76 97 101 94 112 107 100 94 96 112 88 111 107 104 114 79 106 97 116 91 101 92 85 120 87 107 97 89 88 88 122 87 100 95 99 110 94 102 103 98 89 81 100 105 99 97 95 87 90 76 95 75 79 86 89 85 97 90 92 94 98 98 93 86 102 96 86 93 87 91 86 81 93 96 86 101 82 107 93 93 85 108 94 95 97 87 93 91 102 85 101 79 81 79 101 95 92 96 100 84 80 111 108 108 98 88 71 90 88 105 99 112 89 72 81 89 80 96 89 99 87 101 94 92 82 84 90 80 92 92 86 80 111 93 89 99 99 79 90 102 86 105 79 83 82 99 93 78 94 79 85 88 94 86 89 93 91 99 85 90 110 93 94 80 77 88 79 98 88 91 94 90 75 104 86 96 86 92 88 99 86 86 84 84 81 85 75 86 84 87 86 81 88 74 112 85 92 95 83 91 93 97 89 97 76 125 80 90 88 87 88 70 64 77 107 72 86 101 77 98 84 75 79 83 90 85 82 81 85 86 90 78 90 64 89 88 93 93 89 88 68 88 75 73 70 74 88 75 93 88 97 88 90 78 76 81 101 95 95 76 78 83 95 72 86 88 105 85 83 78 86 76 90 83 86 89 86 63 90 95 94 85 73 71 60 90 87 90 68 100 84 95 100 91 85 82 72 99 91 87 62 77 93 73 83 90 86 79 88 81 88 89 92 79 68 78 70 74 89 83 89 90 90 80 87 75 96 77 83 93 96 89 70 94 71 67 81 73 71 89 84 76 85 68 81 89 74 94 88 74 89 76 71 79 83 77 98 55 73 82 91 76 78 66 82 76 66 79 91 71 80 75 74 90 89 78 83 80 98 78 100 82 73 82 75 78 82 83 88 75 77 87 70 79 81 81 90 62 71 79 79 75 69 76 89 83 75 86 64 82 76 84 69 87 75 63 78 67 73 86 88 80 79 75 78 85 83 78 83 75 81 84 69 73 72 76 72 80 73 75 63 71 75 86 66 81 80 81 79 62 74 71 76 82 80 71 62 72 79 82 77 78 68 100 71 89 80 91 73 73 67 74 80 72 79 74 78 80 70 79 77 73 79 76 80 80 62 75 80 71 78 89 78 78 75 74 78 90 78 87 79 64 75 88 91 69 73 84 77 73 85 75 59 73 78 70 62 73 85 82 69 74 73 58 71 66 74 75 68 76 74 78 57 71 71 64 65 86 59 78 72 82 63 81 81 68 85 61 87 54 81 74 70 62 65 64 84 79 75 63 65 74 67 66 74 70 63 83 67 62 73 85 64 72 84 81 74 91 63 77 68 77 78 76 77 90 69 73 57 60 59 71 76 77 74 67 66 86 78 89 69 61 74 77 65 84 68 63 73 86 77 71 75 64 68 66 70 58 67 66 72 78 64 76 79 76 77 69 74 78 74 77 60 66 61 69 69 64 73 73 74 72 71 81 76 66 65 62 56 68 68 67 66 63 66 73 69 63 69 59 66 67 67 72 59 70 75 66 85 75 74 69 61 79 63 67 74 60 72 68 71 71 75 69 61 76 74 71 68 78 66 53 63 73 71 67 53 67 77 58 76 63 54 60 75 72 54 70 82 63 48 73 61 59 69 75 58 75 83 64 59 50 54 63 72 65 62 66 65 61 61 72 74 61 73 73 52 56 63 69 60 75 63 64 62 72 78 54 63 63 66 64 76 62 62 64 54 56 63 70 75 57 58 68 63 55 59 75 82 66 77 51 59 59 79 53 74 71 54 72 73 79 61 57 59 61 73 80 59 66 64 55 60 58 62 49 57 56 62 48 67 63 57 60 62 74 50 58 72 79 67 69 71 66 56 67 51 65 56 77 61 68 67 60 77 52 70 62 49 67 61 66 69 54 84 67 53 61 57 73 56 59 52 74 71 50 62 61 87 61 54 64 60 59 56 63 54 63 51 56 40 72 72 67 68 51 59 74 52 72 53 66 63 61 61 61 58 64 51 71 71 63 64 71 50 47 60 59 74 59 76 61 55 63 70 70 62 59 53 66 67 58 60 60 44 64 62 66 50 64 69 60 49 68 52 70 64 59 69 58 60 59 59 68 59 89 58 55 56 57 54 73 71 55 64 52 63 64 48 64 73 52 71 61 57 54 57 77 60 59 68 53 47 67 67 45 57 62 67 63 56 66 46 50 45 64 58 57 52 73 56 54 52 64 50 60 59 61 69 56 61 62 55 72 52 58 73 45 67 61 57 68 53 67 51 65 54 59 56 71 65 79 56 46 64 52 46 63 44 55 52 57 63 52 67 56 61 56 47 56 57 56 57 74 50 61 58 66 49 58 55 60 67 65 74 59 58 70 54 43 68 53 60 50 59 50 47 65 66 56 71 65 51 74 56 48 49 70 74 55 65 46 65 71 56 64 69 54 57 77 59 46 62 61 56 55 49 74 68 72 65 62 73 63 61 58 65 58 62 63 60 60 62 58 67 59 66 82 66 63 59 70 67 62 80 53 61 52 60 49 58 56 61 59 80 57 70 71 72 63 54 60 54 49 66 69 55 70 63 59 65 52 63 63 73 53 52 50 57 60 57 61 50 55 55 65 66 60 53 66 53 50 62 58 66 56 54 49 62 59 60 59 72 58 51 54 66 55 51 59 52 49 51 41 46 61 70 62 67 41 55 59 60 52 51 51 48 41 59 59 64 67 69 45 57 51 49 45 50 58 51 69 55 66 55 53 71 46 50 48 54 56 42 57 40 64 48 58 46 68 51 40 45 45 54 53 55 62 65 51 61 45 41 47 53 45 48 45 53 45 38 43 50 55 47 65 51 55 44 44 53 59 42 56 41 39 62 43 55 45 38 42 55 59 36 48 54 55 43 59 56 50 53 47 45 48 57 33 57 55 50 47 44 49 61 59 49 61 55 47 47 39 51 38 51 53 53 42 30 46 53 56 47 53 53 41 54 59 46 52 64 43 50 39 37 47 48 62 63 43 58 44 48 50 39 45 40 48 39 45 42 37 46 56 50 44 41 55 50 45 43 53 60 39 52 47 41 50 42 49 36 48 49 30 50 43 44 41 39 45 37 51 56 58 43 50 58 38 63 47 52 47 39 39 28 44 41 57 40 39 50 49 38 44 48 45 36 53 48 39 41 39 46 44 51 50 57 42 33 46 47 40 41 40 43 40 55 59 45 48 39 43 40 39 50 45 53 47 49 49 50 48 48 59 52 45 43 49 45 46 44 41 38 51 38 44 49 43 43 50 41 53 41 55 38 44 49 49 51 46 56 41 62 33 49 48 47 44 45 48 56 51 44 47 33 52 41 50 41 54 51 42 38 41 41 53 30 47 42 63 47 43 37 44 42 33 46 45 35 42 49 49 61 44 46 43 42 41 44 38 40 52 36 38 58 41 37 47 43 45 37 39 43 37 33 55 45 37 38 42 37 40 57 32 54 50 40 50 31 32 46 51 35 38 34 38 35 37 37 53 38 54 41 40 41 41 38 32 38 45 44 42 44 38 37 33 42 54 44 27 36 46 34 42 52 40 45 41 41 45 44 43 40 37 38 53 32 34 40 43 37 37 40 42 31 31 35 42 40 36 35 38 37 34 47 36 51 44 46 63 36 40 39 35 37 55 43 34 41 36 48 53 37 26 34 35 37 40 47 52 44 36 40 39 35 42 44 45 51 40 38 34 45 45 36 62 53 56 39 40 46 38 41 36 49 44 39 43 47 46 46 30 34 35 43 34 43 39 42 27 32 33 47 50 39 44 38 35 33 41 39 34 37 26 41 37 43 43 44 33 42 41 44 30 30 31 45 45 27 41 44 40 33 41 30 34 40 44 35 35 39 39 40 38 20 32 46 37 41 35 35 23 45 39 34 31 29 34 41 46 43 27 40 34 32 41 36 35 32 38 42 28 36 36 26 39 47 36 39 34 34 33 41 46 37 29 23 43 39 37 31 46 32 42 31 41 26 53 43 33 38 31 31 50 18 48 36 40 38 30 37 26 40 36 40 27 40 38 30 39 36 43 34 44 51 30 37 38 37 39 32 34 37 25 36 43 35 46 36 31 33 32 52 46 45 36 31 32 33 39 40 44 36 37 47 30 27 36 43 41 31 40 35 33 39 38 30 40 30 36 49 36 40 37 37 36 32 31 44 35 29 42 34 32 37 35 34 43 36 32 36 36 41 34 39 34 37 28 37 36 39 29 36 34 42 36 43 34 38 33 35 28 45 26 32 33 39 36 31 42 39 29 37 33 39 40 39 40 25 38 36 36 33 30 39 31 43 45 49 32 33 24 34 28 32 37 28 24 41 24 34 41 40 31 37 35 42 32 42 38 28 36 24 23 34 38 36 37 36 42 33 30 38 39 29 34 32 35 28 38 40 39 28 37 27 37 28 23 32 36 32 39 22 32 40 32 35 31 26 32 38 42 31 34 39 33 36 37 38 32 27 44 33 35 26 52 38 25 32 37 37 33 37 35 33 39 32 27 39 38 43 43 47 35 25 31 31 31 45 33 32 27 35 35 31 35 22 34 28 42 37 28 34 36 33 29 36 31 26 29 40 33 28 28 20 25 33 26 39 31 34 30 33 22 31 40 31 28 27 32 36 38 45 31 24 33 30 33 29 35 28 28 30 25 27 30 32 41 20 25 35 38 38 35 33 32 28 33 24 33 31 34 43 32 29 26 20 33 39 32 22 20 27 30 36 29 28 34 25 26 29 31 33 31 36 33 27 27 38 21 24 37 36 26 22 29 34 32 30 30 34 30 36 30 29 37 36 31 30 32 40 27 29 35 33 40 26 27 22 27 29 31 37 21 24 34 37 38 39 33 24 33 36 35 38 27 38 45 31 32 40 40 29 24 21 28 26 22 32 46 31 28 34 30 33 27 26 34 17 32 34 23 32 23 29 31 21 28 28 28 27 29 32 32 35 26 25 30 36 31 29 30 34 24 31 26 35 29 29 28 21 35 36 31 33 44 26 27 33 35 37 24 24 16 30 26 23 26 31 33 37 31 26 22 22 34 27 18 25 22 28 24 26 32 24 42 33 22 23 23 36 25 24 20 24 32 26 31 23 25 28 38 27 31 30 28 38 33 25 28 26 29 29 30 23 27 31 28 23 27 25 26 30 27 27 32 24 17 26 19 19 34 21 26 27 32 26 27 27 22 25 25 30 39 29 39 28 30 34 20 27 26 29 22 25 32 35 25 36 30 27 28 28 18 29 26 18 35 26 25 29 28 23 38 34 21 21 19 31 24 31 29 26 33 29 28 26 24 28 25 44 37 23 25 30 22 26 14 22 33 24 14 24 15 25 33 29 23 32 30 33 33 38 27 22 21 20 25 22 25 21 22 31 25 32 16 28 21 30 30 28 22 30 31 32 28 33 27 42 31 26 25 23 26 25 32 26 28 21 26 27 30 24 24 31 28 24 28 31 32 21 27 20 24 35 28 25 29 26 26 14 34 28 33 25 39 20 26 27 33 22 32 27 28 30 23 23 32 21 31 22 32 39 25 23 24 37 23 29 40 34 24 21 20 26 27 27 25 29 28 27 27 25 30 26 22 23 25 32 22 30 28 24 29 32 23 32 27 14 25 29 28 26 25 27 34 29 25 25 25 27 28 31 21 31 26 31 32 29 19 32 30 25 32 16 26 27 14 36 27 24 25 24 24 20 30 23 23 24 32 30 20 20 32 27 21 31 18 26 33 24 28 20 27 26 29 24 20 26 25 25 24 29 28 21 31 22 27 36 27 33 16 24 34 25 23 18 29 20 28 31 22 26 23 35 26 21 25 25 26 23 31 21 19 20 22 14 30 23 21 31 32 22 34 21 24 23 31 28 18 17 33 27 24 24 32 20 21 31 20 30 29 25 29 27 29 31 29 22 23 17 29 30 23 21 22 23 29 17 31 39 27 27 23 23 18 20 24 30 18 20 24 14 17 21 23 23 29 23 37 20 18 24 33 29 23 13 26 27 26 25 37 39 26 25 19 26 31 24 23 24 17 19 15 19 33 37 16 24 26 28 23 22 26 28 23 19 30 22 19 30 29 21 19 23 20 25 23 30 18 23 24 21 22 27 24 20 20 25 34 21 23 33 24 30 31 22 22 27 20 22 24 24 27 24 18 22 22 27 20 23 24 36 24 12 30 28 22 16 28 29 23 25 22 30 23 26 23 18 32 16 30 16 28 32 17 21 21 33 19 19 20 20 23 23 30 24 19 29 17 20 15 36 14 27 21 22 28 26 21 22 26 30 31 25 28 28 25 28 28 21 22 20 19 14 17 20 26 28 28 24 24 25 23 30 24 23 31 27 18 21 25 26 30 20 30 28 21 28 31 28 31 30 26 25 23 27 26 34 21 29 28 19 25 26 34 31 22 21 20 27 37 33 38 25 27 21 25 25 24 23 36 33 17 26 24 30 34 23 24 32 25 40 27 29 25 32 24 24 23 27 28 21 25 27 20 25 26 25 32 33 28 32 33 33 36 21 29 24 26 32 30 30 31 28 22 28 31 40 22 23 31 26 32 28 29 33 19 35 26 33 23 22 25 34 21 28 38 26 24 27 22 33 28 27 30 22 24 28 21 22 31 30 25 17 18 25 26 28 19 37 28 23 26 26 24 25 29 28 22 19 26 24 22 30 25 27 28 19 27 23 25 29 28 25 19 23 22 27 25 25 14 19 28 23 19 21 16 32 29 26 29 21 23 30 26 19 26 19 25 19 28 25 24 22 23 26 29 22 27 17 27 25 23 27 22 17 20 23 20 22 19 24 20 20 24 30 25 29 24 24 25 21 15 28 19 18 24 16 23 17 23 22 21 27 17 24 23 23 23 20</counts>
			</dataPoints>
		</scan>
	</xrdMeasurement>
</xrdMeasurements>