File: data/XRD/GIXRD/W6821-1D.xrdml
<xrdMeasurements xmlns="http://www.xrdml.com/XRDMeasurement/2.1" xmlns:xsi="http://www.w3.org/2001/XMLSchema-instance" xsi:schemaLocation="http://www.xrdml.com/XRDMeasurement/2.1 http://www.xrdml.com/XRDMeasurement/2.1/XRDMeasurement.xsd" status="Completed">
	<comment>
		<entry>Configuration=Factory configuration, Owner=User-1, Creation date=7/8/2013 4:01:53 PM</entry>
		<entry>Goniometer=PW3050/65 (Theta/2Theta); Minimum step size 2Theta:0.0001; Minimum step size Omega:0.0001</entry>
		<entry>Sample stage=MRD Cradle; Minimum step size Phi:0.01; Minimum step size Chi:0.01; Minimum step size X:0.01; Minimum step size Y:0.01; Minimum step size Z:0.001</entry>
		<entry>Diffractometer system=XPERT-PRO</entry>
		<entry>Measurement program=C:\PANalytical\Data Collector\Programs\SimonL\GIXRD_om_fest-2deg_2theta-10deg-80deg_40s.xrdmp, Identifier={5D08F084-E282-4D09-BA8B-67D165D754DE}</entry>
		<entry>Batch program=C:\PANalytical\Data Collector\Programs\SimonL\batch7x_2thom_10-130°_z9.1_x0,10,20,30_y10,20,30_57min.xrdmp, Identifier={E4DA177A-5C7A-4C52-834B-D6C6EE2424A1}</entry>
	</comment>
	<sample type="To be analyzed">
		<id></id>
		<name></name>
		<preparedBy></preparedBy>
	</sample>
	<xrdMeasurement measurementType="Scan" status="Completed" sampleMode="Reflection">
		<comment>
			<entry>PHD Lower Level = 4.83 (keV), PHD Upper Level = 11.27 (keV)</entry>
		</comment>
		<usedWavelength intended="K-Alpha 1">
			<kAlpha1 unit="Angstrom">1.5405980</kAlpha1>
			<kAlpha2 unit="Angstrom">1.5444260</kAlpha2>
			<kBeta unit="Angstrom">1.3922500</kBeta>
			<ratioKAlpha2KAlpha1>0.5000</ratioKAlpha2KAlpha1>
		</usedWavelength>
		<incidentBeamPath>
			<radius unit="mm">320.00</radius>
			<xRayTube id="1010048" name="Empyrean Cu LFF HR (9430 033 7310x) DK442154">
				<tension unit="kV">40.0</tension>
				<current unit="mA">40.0</current>
				<anodeMaterial>Cu</anodeMaterial>
				<focus type="Line">
					<length unit="mm">12.0</length>
					<width unit="mm">0.4</width>
					<takeOffAngle unit="deg">4.2</takeOffAngle>
				</focus>
			</xRayTube>
			<xRayMirror id="27010001" name="Inc. Beam Cu W/Si (parabolic MRD)" hybrid="false">
				<crystal type="Graded" shape="Parabolic">W/Si</crystal>
				<acceptanceAngle unit="deg">0.800</acceptanceAngle>
				<length unit="mm">60.0</length>
			</xRayMirror>
			<sollerSlit id="21010002" name="Soller slits 0.04 rad.">
				<opening unit="rad">0.0400</opening>
			</sollerSlit>
			<mask id="22030008" name="Fixed mask 4 mm">
				<distanceToSample unit="mm">220.00</distanceToSample>
				<width unit="mm">4.00</width>
			</mask>
			<divergenceSlit id="22010007" name="Fixed slit 1/8°" xsi:type="fixedDivergenceSlitType">
				<distanceToSample unit="mm">220.00</distanceToSample>
				<height unit="mm">0.19</height>
			</divergenceSlit>
		</incidentBeamPath>
		<diffractedBeamPath>
			<radius unit="mm">320.00</radius>
			<sollerSlit id="21010002" name="Soller slits 0.04 rad.">
				<opening unit="rad">0.0400</opening>
			</sollerSlit>
			<receivingSlit id="22010001" name="Fixed slit 4°">
				<height unit="mm">5.88</height>
			</receivingSlit>
			<detector id="7010017" name="PIXcel3D 1x1 detector" xsi:type="areaDetectorType">
				<phd unit="%">
					<lowerLevel>30.0</lowerLevel>
					<upperLevel>70.0</upperLevel>
				</phd>
				<mode>Scanning</mode>
				<activeChannelsEquatorial>255</activeChannelsEquatorial>
				<activeChannelsAxial>255</activeChannelsAxial>
				<pitchEquatorial unit="mm">0.05500</pitchEquatorial>
				<pitchAxial unit="mm">0.05500</pitchAxial>
				<readOutPeriod unit="seconds">0.155</readOutPeriod>
			</detector>
		</diffractedBeamPath>
		<scan appendNumber="0" mode="Continuous" scanAxis="2Theta" status="Completed">
			<header>
				<startTimeStamp>2024-11-01T19:33:34+01:00</startTimeStamp>
				<endTimeStamp>2024-11-01T20:11:43+01:00</endTimeStamp>
				<author>
					<name>PRO-MRD</name>
				</author>
				<source>
					<applicationSoftware version="6.1b">Data Collector</applicationSoftware>
					<instrumentControlSoftware version="7.0E 20130304">XPERT-PRO</instrumentControlSoftware>
					<instrumentID>0000000011142674</instrumentID>
				</source>
			</header>
			<dataPoints>
				<positions axis="2Theta" unit="deg">
					<startPosition>10.00246193</startPosition>
					<endPosition>79.99507515</endPosition>
				</positions>
				<positions axis="Omega" unit="deg">
					<commonPosition>2.0000</commonPosition>
				</positions>
				<positions axis="Phi" unit="deg">
					<commonPosition>0.00</commonPosition>
				</positions>
				<positions axis="Chi" unit="deg">
					<commonPosition>0.00</commonPosition>
				</positions>
				<positions axis="X" unit="mm">
					<commonPosition>10.00</commonPosition>
				</positions>
				<positions axis="Y" unit="mm">
					<commonPosition>0.00</commonPosition>
				</positions>
				<positions axis="Z" unit="mm">
					<commonPosition>9.100</commonPosition>
				</positions>
				<commonCountingTime unit="seconds">37.995</commonCountingTime>
				<counts 599 565 587 578 591 535 599 596 607 591 545 536 543 612 564 544 573 556 585 554 544 585 530 525 504 559 549 553 551 568 512 584 562 517 518 530 566 550 527 559 597 597 570 547 565 556 549 552 562 562 501 512 589 562 538 582 559 555 549 506 571 544 568 535 566 534 561 580 556 531 572 578 557 584 558 541 564 534 534 526 545 562 593 566 522 557 582 589 520 550 559 572 548 534 570 545 563 552 575 596 527 542 575 524 580 542 545 505 551 564 545 555 520 545 535 594 577 533 520 544 551 540 555 552 547 572 527 535 536 504 556 564 575 549 567 576 572 556 543 575 558 554 564 577 513 554 561 580 558 547 549 553 537 483 581 518 517 604 555 555 538 573 529 537 560 526 554 535 545 562 562 529 585 511 538 516 506 558 537 525 581 570 561 535 542 534 543 524 583 495 560 515 550 520 587 544 549 563 560 521 560 555 569 545 546 540 549 560 536 546 581 573 540 557 557 520 562 510 548 546 525 550 587 563 559 594 558 521 533 527 555 539 530 580 522 523 496 533 553 557 520 564 556 543 544 555 575 526 538 521 523 543 569 558 572 541 576 542 550 577 544 571 528 540 565 522 550 562 567 522 538 525 544 556 539 533 575 527 587 566 536 536 555 592 580 544 561 547 542 538 534 536 541 520 524 599 586 580 510 573 575 528 516 555 536 514 566 508 588 602 508 543 530 508 581 515 494 550 586 518 567 502 518 550 529 498 551 565 583 524 527 538 562 520 562 559 538 542 538 526 571 591 542 508 569 549 510 538 571 583 556 542 583 541 565 539 523 513 539 540 544 573 575 558 553 551 482 548 555 562 496 528 533 559 536 536 530 541 604 525 564 549 557 513 540 509 559 573 577 541 507 550 541 550 529 535 543 513 568 520 555 528 565 577 526 534 568 506 515 563 553 530 555 546 544 536 554 529 518 594 543 571 570 530 583 558 522 544 576 591 545 540 548 528 568 572 520 536 528 536 580 590 549 551 543 573 571 590 545 547 580 556 544 578 529 536 526 555 564 497 552 550 531 514 539 555 538 577 490 577 568 533 561 566 584 571 558 532 572 540 511 563 541 602 538 551 569 564 499 564 536 582 562 601 545 540 604 586 559 519 615 576 553 533 552 557 549 541 565 553 544 503 530 571 535 546 544 552 547 551 522 587 532 553 532 527 567 553 533 525 561 578 574 548 608 526 574 528 554 565 540 536 593 571 521 537 567 535 527 494 535 502 520 528 564 539 552 560 548 549 550 544 567 556 552 563 580 577 533 512 547 552 534 503 543 524 553 516 560 557 583 552 587 562 548 537 577 572 575 521 575 552 549 575 602 529 542 551 582 565 591 489 551 509 524 582 604 544 588 545 556 556 560 525 616 525 540 620 575 546 585 600 540 587 562 562 544 580 574 528 541 619 598 553 537 540 546 531 561 561 553 555 571 527 592 588 537 540 533 576 547 614 558 597 566 597 556 564 577 509 506 551 572 581 552 554 582 543 555 559 553 548 531 555 530 571 559 556 597 516 570 606 516 544 560 538 593 546 609 535 557 582 549 555 570 602 566 547 557 538 587 534 560 599 527 578 553 639 534 552 560 548 532 567 560 583 534 534 541 606 555 574 578 558 529 597 573 572 610 559 562 573 565 600 551 560 584 550 565 567 527 581 539 582 584 539 485 588 550 550 574 560 534 565 527 569 538 558 578 544 582 548 558 548 591 583 577 608 545 512 572 599 566 546 516 520 549 570 536 577 562 602 547 523 507 530 562 557 569 502 535 565 611 533 553 550 525 600 529 575 557 556 549 530 608 563 538 533 560 578 569 547 554 573 538 558 537 565 576 572 565 528 528 526 528 542 552 580 526 506 582 555 496 511 561 540 526 518 582 565 553 572 530 559 549 597 502 566 514 539 531 565 576 564 529 551 543 558 524 516 509 504 581 536 548 549 566 569 561 543 563 511 496 531 543 565 566 511 518 536 541 527 515 527 540 525 548 523 566 544 544 538 548 554 528 546 566 524 553 521 576 553 552 553 507 573 547 527 503 483 517 572 587 540 529 545 539 500 545 544 519 545 563 543 538 568 522 575 555 571 547 517 538 536 507 553 553 560 534 524 529 530 542 548 543 523 497 540 544 525 541 541 533 558 568 523 555 521 529 523 551 538 516 527 528 515 518 504 515 511 540 510 518 551 520 522 541 508 539 517 550 498 523 537 567 551 539 512 526 518 522 507 556 535 524 474 519 537 569 541 506 528 545 520 505 516 523 496 536 500 535 537 508 540 501 514 536 532 506 486 552 504 534 555 526 496 530 534 497 519 518 578 539 471 518 512 528 486 508 563 525 544 538 514 534 490 518 548 532 509 497 504 557 522 477 512 505 493 522 520 546 514 532 500 451 481 496 518 500 509 537 489 516 508 503 500 510 530 524 518 518 511 554 562 525 528 547 523 515 555 519 522 510 511 527 502 519 501 539 476 522 511 525 551 518 510 480 558 496 542 495 543 507 492 499 521 511 508 509 524 505 527 554 555 499 508 520 516 493 534 504 524 512 506 520 507 511 513 475 477 543 515 515 525 525 503 467 518 520 507 522 493 496 497 529 494 530 520 503 497 498 452 532 519 521 461 538 520 534 536 484 477 528 486 505 480 485 536 471 528 507 486 507 557 506 474 501 525 487 497 497 517 505 453 488 544 515 549 514 497 483 493 528 490 491 514 471 523 502 507 464 527 499 502 479 443 450 482 490 504 467 480 513 532 454 507 511 557 509 481 490 494 488 486 495 527 517 482 523 496 433 478 513 497 469 470 505 464 510 479 513 502 523 479 508 485 491 466 489 500 513 535 486 483 493 478 485 473 528 491 469 474 485 498 494 420 492 499 473 472 467 467 488 449 469 484 504 498 484 501 456 464 460 511 475 520 469 513 509 505 464 490 471 515 453 504 510 498 496 496 430 468 485 511 496 493 530 455 465 476 457 470 495 510 529 473 497 505 556 494 491 519 473 461 515 486 443 489 485 438 498 483 451 537 500 501 467 506 478 488 514 467 498 471 479 492 467 477 499 470 507 490 441 485 500 475 469 453 486 520 480 494 460 483 475 483 467 493 484 442 467 492 482 441 500 485 501 517 467 512 444 496 522 466 484 486 510 474 466 465 520 505 443 496 536 465 458 471 482 516 484 480 487 472 477 447 498 488 467 461 455 487 495 469 486 441 462 478 481 454 464 491 482 471 449 448 444 483 494 471 460 473 480 471 480 486 429 496 469 489 473 459 454 478 474 459 468 493 509 496 492 451 481 502 444 459 475 413 464 497 487 502 498 486 454 481 457 458 461 469 440 494 477 436 486 426 485 473 515 468 502 497 422 472 472 470 463 509 460 496 459 491 483 466 449 440 464 487 431 471 497 457 415 467 478 461 493 454 471 463 446 485 457 476 448 463 440 466 503 477 478 445 502 447 457 497 452 424 438 474 444 448 444 452 451 436 440 494 485 445 445 446 428 472 476 413 445 453 461 474 477 459 456 460 438 466 475 431 483 412 444 478 452 402 458 455 439 435 441 435 463 448 443 471 458 458 484 449 473 519 497 424 438 464 444 452 442 418 437 455 435 472 436 443 478 449 442 453 456 453 440 456 478 433 429 472 458 444 441 428 450 462 448 452 457 424 442 434 443 435 443 436 449 467 418 431 424 431 453 455 461 470 414 442 463 470 434 425 414 444 436 448 428 464 484 458 437 455 445 440 431 433 424 452 446 439 447 422 470 410 438 418 448 421 462 440 455 432 448 392 426 442 438 463 422 420 450 444 453 444 432 456 449 452 454 433 435 426 453 401 468 463 384 440 434 420 413 442 402 418 430 399 429 423 425 429 415 447 381 437 416 408 426 434 456 449 459 431 414 450 395 443 410 418 460 432 438 446 419 400 405 447 446 431 432 454 451 439 446 414 436 425 379 439 396 414 416 450 420 457 412 460 453 432 392 429 401 417 463 423 441 391 408 440 425 417 411 418 423 393 421 409 449 413 450 400 401 439 414 412 436 421 380 431 441 425 420 392 426 377 438 410 417 421 400 405 445 388 361 398 427 371 415 435 397 395 414 418 427 372 407 399 398 410 408 417 408 402 402 407 422 388 427 399 433 399 408 416 386 402 379 409 433 389 422 396 425 444 382 405 403 429 394 414 445 411 440 404 436 399 423 443 424 396 385 404 377 444 439 427 418 401 388 407 368 403 436 414 433 429 425 393 412 432 396 438 438 405 395 372 413 403 416 384 409 401 379 405 394 389 414 413 397 394 431 413 388 432 417 381 388 427 423 379 397 400 410 372 370 364 385 403 408 403 369 360 410 395 426 359 383 399 373 385 414 409 424 395 431 403 374 393 410 390 367 394 398 389 402 384 375 374 391 345 377 419 421 392 379 395 403 407 361 401 384 398 388 393 409 409 394 407 376 385 359 401 371 343 395 410 385 383 381 408 373 366 398 364 378 386 374 425 369 369 360 391 393 362 398 373 370 383 350 358 401 374 351 402 402 366 409 393 392 384 399 390 366 399 390 346 411 413 379 390 380 388 391 385 385 355 399 394 390 394 361 350 412 385 417 375 383 372 415 390 357 385 368 397 387 383 386 355 386 358 413 382 358 385 378 395 356 384 399 370 399 366 366 390 342 382 392 357 369 348 367 396 397 403 405 366 404 408 361 375 379 402 366 357 370 381 394 373 373 381 348 375 385 374 343 382 387 385 389 362 374 390 398 354 356 378 375 362 367 373 373 377 372 372 369 371 376 362 406 390 397 352 378 385 360 379 412 397 401 386 396 360 385 389 379 335 364 372 383 429 422 360 355 371 350 422 361 394 383 406 375 350 377 382 369 404 397 387 349 378 365 363 373 386 384 416 354 374 415 342 378 386 387 355 374 320 373 333 384 383 365 361 359 322 370 355 382 405 355 378 373 317 330 381 371 344 389 393 386 406 370 385 348 375 391 373 381 356 392 334 374 321 344 352 364 359 357 368 348 358 376 332 362 379 333 358 346 352 360 338 360 352 354 353 348 359 333 380 354 366 365 376 332 338 343 340 345 349 382 311 367 326 373 377 378 341 317 344 352 345 361 350 349 332 336 344 337 335 329 374 328 361 371 361 348 348 341 332 343 314 347 351 335 369 333 374 344 356 368 367 346 360 366 348 369 361 346 336 326 358 346 366 356 366 350 350 319 363 358 317 355 375 330 327 344 328 349 379 346 379 363 352 314 376 386 373 359 324 363 344 352 376 338 327 341 374 347 319 340 328 343 308 359 362 300 358 342 355 330 355 356 344 340 353 337 344 351 375 344 336 348 317 360 377 342 361 354 333 328 348 351 346 352 346 339 314 337 344 343 314 362 322 335 312 345 307 340 337 317 329 326 328 336 346 334 343 361 337 330 334 342 348 327 324 324 290 338 331 332 328 353 336 360 317 351 344 341 357 342 329 335 339 350 342 328 328 334 324 371 324 368 308 313 324 337 326 325 357 352 312 344 324 368 368 342 350 349 327 329 270 352 311 316 318 301 345 330 344 331 345 306 316 355 343 310 336 342 333 329 341 362 337 350 319 279 334 327 316 348 323 343 319 327 313 337 289 347 322 332 335 315 318 327 345 343 350 288 327 336 342 359 314 303 281 330 342 332 321 325 321 334 323 329 318 336 337 326 330 319 333 332 354 299 326 315 328 329 317 339 322 312 283 296 313 323 310 305 341 320 340 313 331 308 347 325 340 346 348 330 325 328 293 322 307 318 317 336 313 284 311 294 348 326 317 312 337 314 338 349 332 309 328 327 312 307 306 338 344 352 358 332 311 323 316 358 323 345 304 286 303 286 329 318 308 327 319 317 308 332 330 296 324 331 310 300 297 330 296 326 334 323 340 315 302 291 300 350 309 302 298 303 308 327 325 322 295 306 348 292 348 322 303 321 306 264 290 335 336 349 335 308 308 295 298 307 284 293 309 320 324 290 313 317 297 293 300 297 293 298 310 298 290 312 310 270 293 311 336 310 333 333 326 295 314 349 332 305 329 319 310 322 324 286 331 347 322 309 326 308 332 326 318 293 300 304 318 318 316 316 304 331 307 353 331 326 339 329 329 366 318 307 304 329 315 342 319 300 345 335 316 347 352 339 328 309 328 325 298 308 314 285 334 310 311 322 327 326 328 324 272 333 332 337 323 304 289 335 320 317 293 332 304 353 326 298 293 295 289 302 306 325 304 287 324 309 333 309 287 300 276 324 299 332 294 292 297 309 309 317 301 294 267 298 297 302 286 274 282 248 306 276 299 285 282 290 292 299 299 301 326 276 294 280 305 286 295 279 295 319 299 311 291 292 268 315 313 271 304 319 285 247 287 274 315 279 288 256 277 301 268 292 290 288 281 307 303 272 276 281 300 269 301 290 267 289 272 268 296 302 268 324 295 267 294 315 258 295 268 284 259 272 291 285 256 309 276 294 270 313 291 271 308 307 283 285 298 298 306 316 312 288 312 271 293 296 276 262 301 281 322 286 286 318 277 294 305 325 304 282 295 272 297 288 290 277 267 280 280 258 302 293 312 238 282 291 262 283 268 297 271 265 267 286 242 313 280 262 285 292 256 272 301 311 262 295 285 288 260 283 283 271 272 288 281 307 243 281 264 255 304 259 305 312 282 264 286 278 270 262 288 280 279 279 267 272 275 308 295 280 278 274 280 289 299 291 302 293 287 268 275 268 262 281 245 278 266 288 257 285 304 275 318 247 261 278 264 307 278 248 287 272 256 278 298 238 269 243 287 267 249 272 243 280 270 267 274 294 270 292 278 258 276 237 262 266 276 270 270 270 285 264 263 284 272 270 249 280 239 266 256 274 276 311 272 260 265 267 261 281 281 284 280 288 284 265 261 271 259 266 226 266 242 282 268 270 264 288 273 276 297 268 292 245 275 261 283 262 274 246 270 260 292 293 255 280 294 258 257 279 264 282 271 259 263 278 292 269 300 291 288 290 266 276 259 268 289 283 245 283 285 272 294 232 301 298 293 256 296 282 258 268 291 308 296 275 281 286 276 286 293 299 277 247 271 266 268 285 290 269 281 301 293 320 307 314 257 304 304 297 290 324 325 319 288 335 320 316 313 332 311 335 324 319 332 355 305 358 307 346 294 329 340 340 333 336 339 312 344 342 372 332 331 361 374 361 374 341 346 390 368 338 390 353 399 409 336 386 336 369 369 359 398 388 377 321 325 385 358 389 381 332 351 396 336 368 404 348 379 369 362 394 397 354 402 352 334 369 403 394 375 377 366 349 367 371 389 352 345 380 321 310 379 361 382 330 383 356 364 367 364 368 353 340 342 349 338 346 333 356 323 310 315 299 339 323 327 327 328 305 306 307 308 306 336 295 299 301 281 334 306 293 272 245 303 295 295 317 297 262 295 271 283 258 261 276 272 265 262 281 282 225 246 277 266 271 267 271 270 246 270 268 246 236 239 227 243 266 248 289 269 236 255 265 270 270 267 268 256 267 261 289 269 260 243 269 284 256 260 266 273 265 291 245 256 296 272 281 278 268 261 263 247 267 259 258 221 261 300 247 268 243 262 261 270 272 246 269 259 243 285 278 262 277 236 248 264 264 285 255 258 244 262 243 247 268 233 262 257 231 232 249 278 265 259 260 268 231 227 233 256 249 219 248 242 248 250 224 239 235 246 213 241 235 227 242 239 240 245 219 216 222 230 216 258 209 272 250 212 226 223 229 211 257 243 221 232 220 234 218 234 209 228 225 241 235 224 219 255 235 266 243 232 237 270 229 222 238 224 227 223 218 198 212 229 210 233 231 226 221 216 229 244 238 226 239 209 229 212 216 222 229 233 228 223 236 221 214 210 226 199 223 242 224 227 226 224 223 209 222 227 225 217 233 266 225 228 209 245 212 211 236 232 236 212 222 243 209 243 217 196 208 204 241 222 193 238 214 222 235 217 248 201 230 223 227 236 229 229 204 202 222 209 219 208 215 213 231 236 222 211 212 207 223 236 205 205 208 210 201 196 211 221 243 204 186 221 205 201 202 195 216 248 257 234 229 215 202 187 213 225 197 218 198 224 205 230 210 215 212 197 217 205 222 212 205 219 183 220 221 201 217 214 228 209 214 191 215 219 208 214 238 218 208 196 204 197 207 213 216 224 230 216 240 211 202 204 203 223 225 203 191 195 191 225 238 219 188 206 210 223 202 201 203 199 211 192 186 176 205 200 200 209 219 214 178 238 215 219 189 204 210 192 201 187 204 222 221 212 230 199 203 203 181 186 193 212 203 198 183 207 207 190 219 189 221 178 209 175 212 243 209 198 189 222 177 219 219 205 219 200 210 214 207 208 209 207 204 223 215 219 198 191 204 168 209 204 202 183 196 193 199 181 227 208 201 205 230 181 228 206 216 194 192 216 192 204 168 196 188 173 211 215 177 190 192 202 181 186 195 186 215 187 215 175 196 185 198 194 195 196 187 183 227 183 186 224 210 210 210 193 171 191 197 200 188 194 186 206 188 206 216 192 185 200 202 189 203 197 189 219 202 203 197 170 192 182 175 222 180 208 208 189 204 213 187 165 203 213 201 179 204 177 184 179 190 186 179 193 183 196 206 192 203 200 200 202 185 204 191 201 211 198 176 191 191 188 182 169 184 156 187 182 172 184 184 189 200 173 209 178 172 198 177 184 193 179 184 190 185 185 211 185 191 191 153 199 192 176 187 199 203 188 190 172 201 187 187 195 180 181 169 182 183 172 195 186 192 194 186 217 197 194 181 177 186 189 186 174 190 183 207 179 182 195 174 185 176 211 183 176 179 205 184 205 170 215 182 181 191 177 185 205 201 203 196 209 165 194 167 167 172 165 180 182 184 178 187 188 181 166 188 197 194 161 199 191 196 174 183 205 178 200 193 153 185 188 189 165 179 181 186 172 179 194 197 162 175 187 185 158 206 175 177 181 176 203 198 200 188 171 165 193 165 181 159 186 197 145 182 170 193 162 182 178 184 187 173 164 168 146 186 174 159 189 178 197 193 188 179 192 180 163 174 197 166 190 174 193 185 177 175 192 186 190 155 175 184 191 170 178 159 179 155 173 190 186 178 186 172 161 177 184 176 221 188 183 174 182 178 169 161 158 177 184 181 206 186 184 186 167 153 208 172 176 178 169 200 168 179 186 167 143 165 189 160 178 163 181 171 171 169 180 187 179 168 181 189 164 182 180 167 145 195 183 182 170 174 175 190 176 178 185 180 165 147 161 199 177 179 177 154 154 169 181 151 178 180 166 187 176 160 172 166 160 167 156 157 169 179 163 182 180 180 161 156 175 172 185 159 158 170 153 172 164 184 201 136 168 201 164 151 147 172 160 166 165 176 145 158 188 161 160 149 157 179 166 176 171 173 145 171 185 186 173 178 147 179 164 163 172 173 166 176 155 179 184 166 168 175 167 138 157 160 160 160 137 166 165 190 188 159 170 190 149 147 165 178 165 167 165 164 161 173 175 173 140 167 159 163 174 158 188 174 200 148 204 168 167 154 157 157 164 162 164 173 149 165 152 161 168 172 141 170 167 183 140 162 156 173 184 154 169 187 157 163 174 182 165 185 151 160 182 151 161 172 158 147 192 169 158 155 169 163 178 140 161 173 135 174 179 181 166 176 164 159 168 147 159 147 173 154 179 160 151 174 164 174 145 181 148 149 155 157 163 180 164 162 165 177 164 162 153 151 139 164 155 176 180 166 173 161 162 169 153 153 149 170 189 157 172 151 156 172 173 162 157 161 154 143 153 153 161 163 172 157 156 174 130 144 151 163 163 166 157 149 159 160 162 171 151 153 171 150 173 173 169 145 137 143 162 163 148 153 176 189 156 177 142 149 159 176 165 167 170 147 155 191 156 161 152 164 163 148 150 165 164 158 150 161 164 151 176 148 168 156 151 140 154 173 138 173 160 160 153 146 154 182 156 145 146 147 166 142 138 132 153 161 150 152 157 138 140 154 152 155 160 153 144 168 150 134 168 156 180 142 161 143 151 136 152 154 141 158 172 154 157 161 159 173 166 189 164 150 147 138 149 158 150 152 170 153 151 156 154 154 148 167 157 178 151 147 169 149 151 149 131 155 152 146 151 182 151 167 153 153 160 126 133 152 154 162 127 168 161 161 184 143 137 149 137 129 160 151 123 160 155 145 149 139 168 142 157 154 121 156 147 140 134 148 152 146 145 154 134 147 175 135 157 155 139 181 164 137 151 139 129 143 150 144 150 166 154 158 140 144 186 144 159 141 171 156 158 145 149 145 152 147 167 145 158 155 132 149 153 146 177 147 197 136 159 146 148 158 150 140 151 160 142 160 141 151 142 147 172 151 158 146 159 173 128 131 138 177 143 152 132 157 164 155 140 144 139 172 156 130 159 144 132 161 168 135 168 150 146 152 140 137 137 165 144 149 182 132 144 152 144 158 140 139 167 153 148 162 140 141 146 159 178 146 153 155 144 125 150 129 167 147 139 151 148 156 148 131 164 178 163 149 151 140 153 128 138 154 162 137 155 140 128 140 145 145 142 148 144 155 148 164 141 139 156 141 126 159 140 160 129 140 136 136 131 125 135 136 141 154 141 153 155 134 136 141 157 157 140 148 128 155 142 135 153 131 141 104 136 152 136 161 142 148 126 136 132 142 137 143 130 161 158 154 152 138 156 117 144 137 168 149 142 160 133 142 121 145 118 136 155 128 140 139 147 130 126 132 154 140 153 146 116 143 140 148 134 142 132 156 137 143 159 157 141 141 148 147 134 160 159 143 142 136 132 146 129 117 127 115 145 135 122 138 150 150 142 149 127 152 123 124 176 154 145 152 124 140 142 162 127 129 126 138 148 149 137 157 159 145 143 138 123 144 122 125 150 141 139 138 129 139 144 116 139 134 157 127 120 131 127 124 132 138 127 133 143 132 134 135 138 126 144 145 119 122 120 119 145 146 125 131 125 129 119 141 142 144 117 123 138 133 134 130 128 120 124 113 133 126 127 132 146 143 147 143 148 143 141 138 147 121 151 150 120 126 133 132 120 134 137 153 144 123 136 144 137 154 138 141 132 123 147 142 129 136 139 112 146 131 136 127 137 158 158 131 123 124 144 110 151 154 123 136 131 140 132 138 138 138 118 124 126 110 136 127 110 116 123 119 142 129 118 134 111 124 150 125 138 150 111 139 144 135 145 118 149 139 133 154 148 139 140 150 140 127 149 171 128 150 141 134 123 137 143 147 134 131 115 154 151 104 143 140 139 148 136 137 128 146 143 131 145 135 125 119 130 138 140 151 143 148 147 123 125 133 140 153 128 136 130 128 131 156 130 124 157 137 134 128 129 122 132 134 134 158 133 145 144 147 113 143 159 144 137 144 154 116 103 149 135 130 147 129 125 123 137 107 143 138 103 113 147 122 131 128 139 134 114 129 147 110 114 117 140 122 134 128 132 134 134 139 120 141 143 134 124 127 152 116 120 138 126 129 134 137 113 120 101 119 118 135 128 131 125 129 107 111 114 108 148 141 133 145 141 118 126 129 123 132 133 126 114 121 135 129 124 119 116 132 138 132 116 127 129 123 130 138 134 147 154 122 127 122 139 119 146 144 120 123 117 119 123 126 110 105 121 115 124 147 129 114 142 137 142 117 116 144 141 130 144 134 131 126 146 140 152 134 116 131 160 128 116 138 146 137 139 128 126 142 122 130 136 126 136 117 131 141 128 124 129 121 142 114 150 134 129 127 123 126 128 116 130 132 159 123 121 118 125 122 115 124 127 119 119 139 124 145 110 137 125 120 142 125 128 124 113 99 136 122 111 120 129 138 122 126 109 134 158 142 134 121 118 117 125 115 127 121 122 120 126 133 116 144 119 106 112 108 112 111 116 107 124 105 101 148 114 121 141 127 111 100 120 137 125 118 125 122 114 111 122 128 134 125 119 130 127 134 116 127 135 128 145 119 104 108 129 125 139 125 106 135 136 134 121 126 122 133 136 117 134 135 118 109 123 98 131 124 116 118 119 115 132 125 120 128 106 123 129 132 108 119 131 139 136 123 123 136 123 135 130 129 130 126 116 142 124 127 126 112 114 118 107 130 119 137 121 123 138 115 121 128 115 111 121 114 123 121 142 142 135 143 126 117 106 143 114 110 127 121 124 132 126 116 118 117 119 118 126 114 117 118 116 132 127 119 112 101 120 118 112 124 123 130 124 115 111 107 139 113 99 110 124 136 111 127 119 131 113 108 118 130 125 88 122 125 115 83 110 109 118 120 117 109 116 123 113 130 97 123 117 113 118 107 110 100 112 101 109 116 124 118 133 115 133 137 119 112 122 118 126 111 130 111 119 108 110 132 108 113 124 107 136 98 117 122 107 126 102 97 107 125 120 115 108 101 97 122 123 111 126 117 118 124 104 103 107 112 109 117 104 107 116 113 106 116 125 130 123 116 95 116 114 125 98 101 111 109 129 86 121 118 110 101 111 110 122 106 103 116 101 106 95 117 101 123 104 114 106 121 116 113 110 134 109 119 104 127 127 102 115 111 111 135 111 111 104 136 142 119 100 135 112 118 124 107 138 128 158 124 123 151 122 118 121 123 140 114 132 143 127 115 111 146 149 120 141 131 129 134 124 119 130 119 119 101 115 110 115 120 114 118 106 105 106 128 132 127 96 114 106 118 128 114 114 109 127 110 122 128 103 128 108 108 111 124 116 129 112 105 92 111 119 116 118 128 111 144 99 94 129 124 99 113 102 112 131 107 117 103 106 115 95 111 122 117 112 111 98 112 111 100 113 111 123 104 98 134 115 121 98 116 115 99 101 100 104 103 96 102 117 96 103 114 93 97 109 116 104 128 101 101 115 123 114 95 79 101 130 96 107 120 103 89 123 95 105 115 109 121 91 120 108 111 106 106 118 132 125 95 112 110 117 105 121 106 103 120 111 101 118 108 101 111 124 98 106 100 102 110 101 103 100 102 82 111 122 119 131 100 106 106 103 113 121 100 122 119 98 107 117 100 106 82 101 106 94 104 117 101 113 104 106 93 104 95 102 106 113 87 119 97 110 97 88 103 86 112 100 106 107 131 114 96 108 98 92 114 95 95 117 107 109 108 105 112 116 88 120 104 118 113 111 88 117 112 90 118 101 110 104 107 99 99 109 99 107 116 101 101 94 106 104 100 104 119 95 105 92 116 108 102 102 106 119 88 99 102 97 117 102 112 101 102 93 95 112 97 97 121 102 111 104 117 106 102 101 97 97 92 105 105 92 95 118 121 85 113 107 102 111 91 99 101 105 96 118 111 90 108 116 126 106 115 118 103 109 91 115 112 119 112 89 99 99 93 97 94 94 121 105 83 115 102 125 89 100 116 96 104 105 93 102 115 88 108 89 87 99 95 99 104 115 99 96 127 95 94 106 108 106 89 121 104 94 84 108 100 125 111 89 103 127 105 97 90 103 105 102 104 99 103 107 101 110 102 91 98 84 94 98 97 116 100 101 90 95 113 122 95 114 110 81 93 117 110 105 92 89 111 98 108 96 92 109 89 107 90 91 104 108 118 93 88 115 96 95 104 114 100 100 113 107 123 106 109 82 96 103 98 92 135 108 109 86 110 104 99 85 95 94 114 111 103 90 103 105 93 97 97 117 106 110 113 97 97 100 106 109 92 104 103 89 115 82 108 113 83 98 95 84 92 86 102 93 119 95 117 98 94 115 85 111 101 90 96 95 91 109 100 114 100 96 105 95 93 110 112 127 92 87 107 98 94 104 85 95 88 122 109 105 106 109 92 102 105 103 71 97 90 87 99 101 102 113 110 105 105 110 98 92 98 98 91 95 97 100 104 104 99 112 102 91 74 91 104 118 105 95 101 109 101 99 95 87 94 96 100 102 94 108 95 106 110 88 105 82 96 89 97 89 111 95 104 97 85 92 93 89 111 105 81 92 108 92 82 102 102 89 102 85 104 102 89 91 100 103 108 92 103 107 87 111 85 95 105 92 86 77 105 116 100 93 103 97 86 85 96 109 92 93 102 107 85 102 96 97 101 108 115 87 84 105 99 81 101 95 102 90 83 92 105 84 95 82 98 91 86 102 100 98 83 92 92 93 107 98 105 87 85 124 99 119 91 90 99 95 102 114 105 93 83 102 106 94 88 80 98 89 91 95 99 79 87 115 86 99 94 105 97 89 96 97 105 77 100 89 101 106 104 124 91 99 102 98 92 83 101 93 93 85 94 104 73 107 114 88 90 91 88 104 88 89 100 94 107 95 73 105 90 100 101 83 87 86 92 115 105 102 102 106 78 88 110 105 88 100 109 103 73 89 107 106 99 80 92 103 93 92 95 112 101 103 92 101 103 106 98 83 95 94 89 97 102 116 87 94 97 89 121 80 92 109 98 97 92 93 97 99 90 83 100 110 99 93 81 102 85 77 104 90 108 91 111 89 87 102 99 93 98 86 93 95 111 94 100 95 101 81 102 90 90 101 88 104 89 81 91 105 95 98 102 96 98 84 102 92 94 93 102 89 107 101 93 90 92 78 101 82 96 90 104 114 91 97 109 81 84 102 79 90 80 87 102 103 96 89 108 80 77 91 92 93 88 88 91 86 81 98 84 90 76 89 87 98 100 86 106 103 85 89 116 97 94 87 100 86 97 79 102 105 97 98 110 100 94 117 100 112 102 93 86 87 78 90 107 93 104 98 75 100 85 74 100 84 99 82 103 90 101 97 108 85 84 99 104 120 85 113 106 81 84 94 84 100 103 75 112 99 94 75 92 84 90 95 84 90 76 92 96 85 92 109 79 97 89 85 85 114 93 95 92 101 94 92 104 64 83 88 89 104 76 84 86 80 101 79 86 79 81 94 82 87 95 111 97 93 88 105 105 94 81 96 85 100 82 94 87 74 117 84 81 98 110 95 85 93 91 88 76 95 86 90 72 78 99 114 93 88 92 93 94 88 81 88 83 85 92 78 82 88 83 89 76 95 91 99 80 70 81 82 100 83 79 86 100 83 83 110 81 93 73 85 81 86 93 78 92 99 91 74 87 74 80 97 92 97 76 93 90 84 96 74 88 91 78 109 93 83 77 80 74 84 92 93 74 87 79 79 96 98 83 86 82 89 81 87 66 102 98 91 94 100 72 81 92 96 83 97 100 91 86 75 90 101 71 86 96 77 85 82 103 70 95 82 77 89 87 97 94 92 69 74 77 93 102 102 63 89 80 109 89 90 80 90 76 87 105 99 71 105 104 90 96 96 86 90 82 84 88 86 85 81 88 112 81 98 76 101 82 94 86 88 74 87 83 111 90 85 85 105 96 88 79 80 101 79 87 101 83 76 88 78 77 96 72 80 74 99 91 112 86 112 96 80 93 103 90 99 80 99 110 89 95 95 81 91 86 106 96 92 94 98 75 91 102 96 78 82 90 98 92 79 89 76 81 85 88 112 107 82 116 90 87 102 102 93 87 105 89 97 88 118 91 93 89 100 93 79 91 109 94 90 109 83 89 98 83 81 90 81 92 66 76 90 85 84 84 95 78 84 105 79 94 84 95 88 76 101 93 71 102 82 89 89 81 82 99 94 88 92 95 106 88 91 104 83 96 89 85 85 92 72 105 96 83 102 106 85 98 91 97 111 103 90 86 83 99 95 81 113 82 85 102 95 86 86 99 90 101 90 88 87 92 82 103 102 84 85 70 86 84 80 81 90 100 97 85 110 92 83 80 99 91 91 107 99 83 103 97 81 86 87 119 94 102 92 100 98 80 91 95 87 117 94 90 100 87 102 72 106 75 110 90 87 102 94 92 101 97 89 101 86 87 75 119 113 92 88 88 95 89 94 81 84 78 104 80 92 74 92 106 92 74 74 68 99 93 94 79 85 80 82 99 89 89 101 81 95 90 97 99 86 79 86 96 81 85 72 80 79 92 85 83 77 96 89 94 87 95 82 82 80 89 83 82 98 97 95 83 99 87 82 90 88 81 93 90 84 86 81 92 71 82 91 76 93 70 86</counts>
			</dataPoints>
		</scan>
	</xrdMeasurement>
</xrdMeasurements>