File: data/XRD/GIXRD/W6822-1D.xrdml
<xrdMeasurements xmlns="http://www.xrdml.com/XRDMeasurement/2.1" xmlns:xsi="http://www.w3.org/2001/XMLSchema-instance" xsi:schemaLocation="http://www.xrdml.com/XRDMeasurement/2.1 http://www.xrdml.com/XRDMeasurement/2.1/XRDMeasurement.xsd" status="Completed">
	<comment>
		<entry>Configuration=Factory configuration, Owner=User-1, Creation date=7/8/2013 4:01:53 PM</entry>
		<entry>Goniometer=PW3050/65 (Theta/2Theta); Minimum step size 2Theta:0.0001; Minimum step size Omega:0.0001</entry>
		<entry>Sample stage=MRD Cradle; Minimum step size Phi:0.01; Minimum step size Chi:0.01; Minimum step size X:0.01; Minimum step size Y:0.01; Minimum step size Z:0.001</entry>
		<entry>Diffractometer system=XPERT-PRO</entry>
		<entry>Measurement program=C:\PANalytical\Data Collector\Programs\SimonL\GIXRD_om_fest-2deg_2theta-10deg-80deg_40s.xrdmp, Identifier={5D08F084-E282-4D09-BA8B-67D165D754DE}</entry>
		<entry>Batch program=C:\PANalytical\Data Collector\Programs\SimonL\batch7x_2thom_10-130°_z9.1_x0,10,20,30_y10,20,30_57min.xrdmp, Identifier={E4DA177A-5C7A-4C52-834B-D6C6EE2424A1}</entry>
	</comment>
	<sample type="To be analyzed">
		<id></id>
		<name></name>
		<preparedBy></preparedBy>
	</sample>
	<xrdMeasurement measurementType="Scan" status="Completed" sampleMode="Reflection">
		<comment>
			<entry>PHD Lower Level = 4.83 (keV), PHD Upper Level = 11.27 (keV)</entry>
		</comment>
		<usedWavelength intended="K-Alpha 1">
			<kAlpha1 unit="Angstrom">1.5405980</kAlpha1>
			<kAlpha2 unit="Angstrom">1.5444260</kAlpha2>
			<kBeta unit="Angstrom">1.3922500</kBeta>
			<ratioKAlpha2KAlpha1>0.5000</ratioKAlpha2KAlpha1>
		</usedWavelength>
		<incidentBeamPath>
			<radius unit="mm">320.00</radius>
			<xRayTube id="1010048" name="Empyrean Cu LFF HR (9430 033 7310x) DK442154">
				<tension unit="kV">40.0</tension>
				<current unit="mA">40.0</current>
				<anodeMaterial>Cu</anodeMaterial>
				<focus type="Line">
					<length unit="mm">12.0</length>
					<width unit="mm">0.4</width>
					<takeOffAngle unit="deg">4.2</takeOffAngle>
				</focus>
			</xRayTube>
			<xRayMirror id="27010001" name="Inc. Beam Cu W/Si (parabolic MRD)" hybrid="false">
				<crystal type="Graded" shape="Parabolic">W/Si</crystal>
				<acceptanceAngle unit="deg">0.800</acceptanceAngle>
				<length unit="mm">60.0</length>
			</xRayMirror>
			<sollerSlit id="21010002" name="Soller slits 0.04 rad.">
				<opening unit="rad">0.0400</opening>
			</sollerSlit>
			<mask id="22030008" name="Fixed mask 4 mm">
				<distanceToSample unit="mm">220.00</distanceToSample>
				<width unit="mm">4.00</width>
			</mask>
			<divergenceSlit id="22010007" name="Fixed slit 1/8°" xsi:type="fixedDivergenceSlitType">
				<distanceToSample unit="mm">220.00</distanceToSample>
				<height unit="mm">0.19</height>
			</divergenceSlit>
		</incidentBeamPath>
		<diffractedBeamPath>
			<radius unit="mm">320.00</radius>
			<sollerSlit id="21010002" name="Soller slits 0.04 rad.">
				<opening unit="rad">0.0400</opening>
			</sollerSlit>
			<receivingSlit id="22010001" name="Fixed slit 4°">
				<height unit="mm">5.88</height>
			</receivingSlit>
			<detector id="7010017" name="PIXcel3D 1x1 detector" xsi:type="areaDetectorType">
				<phd unit="%">
					<lowerLevel>30.0</lowerLevel>
					<upperLevel>70.0</upperLevel>
				</phd>
				<mode>Scanning</mode>
				<activeChannelsEquatorial>255</activeChannelsEquatorial>
				<activeChannelsAxial>255</activeChannelsAxial>
				<pitchEquatorial unit="mm">0.05500</pitchEquatorial>
				<pitchAxial unit="mm">0.05500</pitchAxial>
				<readOutPeriod unit="seconds">0.155</readOutPeriod>
			</detector>
		</diffractedBeamPath>
		<scan appendNumber="0" mode="Continuous" scanAxis="2Theta" status="Completed">
			<header>
				<startTimeStamp>2024-11-01T20:12:09+01:00</startTimeStamp>
				<endTimeStamp>2024-11-01T20:50:18+01:00</endTimeStamp>
				<author>
					<name>PRO-MRD</name>
				</author>
				<source>
					<applicationSoftware version="6.1b">Data Collector</applicationSoftware>
					<instrumentControlSoftware version="7.0E 20130304">XPERT-PRO</instrumentControlSoftware>
					<instrumentID>0000000011142674</instrumentID>
				</source>
			</header>
			<dataPoints>
				<positions axis="2Theta" unit="deg">
					<startPosition>10.00246193</startPosition>
					<endPosition>79.99507515</endPosition>
				</positions>
				<positions axis="Omega" unit="deg">
					<commonPosition>2.0000</commonPosition>
				</positions>
				<positions axis="Phi" unit="deg">
					<commonPosition>0.00</commonPosition>
				</positions>
				<positions axis="Chi" unit="deg">
					<commonPosition>0.00</commonPosition>
				</positions>
				<positions axis="X" unit="mm">
					<commonPosition>20.00</commonPosition>
				</positions>
				<positions axis="Y" unit="mm">
					<commonPosition>0.00</commonPosition>
				</positions>
				<positions axis="Z" unit="mm">
					<commonPosition>9.100</commonPosition>
				</positions>
				<commonCountingTime unit="seconds">37.995</commonCountingTime>
				<counts 524 527 501 483 528 522 539 534 555 548 533 511 532 534 496 530 564 551 534 528 530 539 528 544 540 525 508 572 581 521 526 495 554 547 551 553 531 544 533 512 522 563 550 526 525 516 529 553 545 483 561 556 526 535 550 519 540 543 534 520 554 516 563 511 524 527 478 544 558 570 487 512 517 558 521 537 565 523 545 544 531 534 554 549 544 507 523 525 520 525 540 579 506 518 530 578 496 535 540 542 526 549 523 532 543 546 542 497 515 549 575 555 547 497 533 573 536 532 521 576 525 505 539 524 486 554 515 522 505 530 515 513 538 481 502 532 532 522 503 537 563 556 588 514 515 526 520 529 515 535 536 524 538 512 516 505 484 523 555 486 549 498 550 498 529 510 539 534 517 507 547 483 532 522 480 516 538 515 533 562 559 516 531 524 510 508 513 508 579 567 552 537 519 572 500 529 513 518 499 499 499 534 555 547 554 561 533 521 536 472 512 494 525 571 550 499 517 489 519 521 502 526 525 519 534 543 559 509 514 513 482 563 535 536 512 526 542 547 512 525 483 540 520 543 468 541 505 514 520 564 512 516 527 511 523 544 535 542 527 517 535 492 504 516 528 550 477 508 542 551 540 520 497 490 504 507 561 542 502 501 527 503 510 540 535 538 545 558 536 497 558 492 518 498 521 495 516 495 506 520 537 493 556 539 504 524 500 538 518 520 530 494 565 513 525 552 527 483 509 484 499 510 459 489 516 520 526 561 497 539 537 510 509 547 510 525 521 514 537 546 499 501 553 498 547 526 533 527 527 498 545 516 544 500 546 498 494 594 507 487 484 475 534 502 501 504 502 488 551 532 498 527 527 487 515 539 521 531 519 539 504 518 514 477 505 544 547 488 533 550 518 531 497 528 514 507 482 521 526 515 517 526 517 509 551 519 539 569 499 533 528 509 537 483 513 526 493 484 506 514 498 521 490 506 521 515 529 502 535 527 504 504 492 532 523 471 506 510 555 530 513 512 509 545 519 517 496 512 477 517 514 548 508 536 538 510 505 491 525 510 498 502 495 520 500 528 530 533 546 516 519 517 492 525 480 510 503 531 509 537 551 531 499 496 482 480 503 482 541 539 512 534 571 530 505 538 508 531 540 531 508 512 503 483 512 495 571 557 529 501 506 478 510 538 511 487 543 550 499 503 507 512 492 506 464 526 536 464 507 522 509 529 491 514 512 499 541 538 531 532 480 517 487 524 548 518 490 525 479 500 532 538 494 510 508 516 555 470 554 508 503 517 513 525 523 521 493 509 556 513 510 512 479 528 530 506 529 509 509 507 530 502 495 518 549 545 498 508 516 490 507 534 532 522 553 495 517 522 554 515 504 500 515 538 506 542 510 471 467 542 542 487 489 566 529 509 512 562 515 514 493 535 508 540 481 462 529 576 521 490 545 520 544 578 506 586 487 524 512 528 541 510 535 511 482 519 466 516 535 533 565 483 539 515 496 542 502 531 556 496 538 539 525 567 495 485 522 539 543 546 547 481 516 556 551 515 497 496 529 524 546 511 546 545 529 545 546 558 516 533 541 527 548 493 434 541 517 525 489 510 497 524 529 541 514 523 509 496 522 518 543 525 495 546 499 543 549 535 571 513 541 543 484 535 551 521 512 512 551 490 524 512 541 532 523 490 526 512 534 552 504 547 543 553 543 492 562 533 504 518 539 563 502 545 506 505 567 528 493 500 495 559 520 523 526 581 518 527 507 499 523 570 527 543 460 521 482 480 552 517 501 533 535 523 546 534 506 535 529 501 521 516 494 525 545 491 497 519 528 558 525 503 518 518 519 526 505 525 583 541 530 554 514 536 544 535 584 533 494 568 560 544 505 526 571 512 562 545 545 522 532 527 542 515 486 520 541 546 530 515 538 521 540 543 471 542 529 498 553 514 498 549 552 525 525 501 531 532 565 535 521 472 564 528 514 507 535 499 533 580 540 514 562 494 561 525 536 502 495 526 530 513 546 478 521 556 523 542 530 561 459 554 514 526 519 519 497 510 516 509 535 514 527 466 480 524 500 541 526 544 491 513 512 526 547 548 530 540 512 534 512 524 513 542 517 533 528 509 498 512 516 526 554 519 510 539 514 511 501 527 493 524 526 498 516 525 532 560 520 550 530 518 538 525 543 504 554 523 499 551 539 495 513 514 543 493 572 542 487 493 544 506 529 504 536 519 536 481 521 499 472 509 511 565 496 502 515 488 535 509 549 538 516 529 490 510 506 561 478 509 542 530 522 537 491 573 491 542 500 503 561 493 497 522 559 490 522 508 541 536 535 471 533 486 486 509 514 538 468 473 536 555 518 510 515 530 550 533 467 498 502 514 512 501 552 535 509 522 496 519 532 498 532 526 516 544 561 558 561 515 534 481 542 542 531 509 491 553 537 531 509 519 528 529 527 564 556 453 502 558 514 494 502 516 508 540 517 490 522 536 542 504 512 485 529 526 503 493 528 524 516 536 519 548 514 515 536 477 535 502 505 518 543 515 533 501 568 522 478 511 537 537 515 520 526 497 524 525 517 526 514 497 524 494 531 548 555 497 497 552 530 474 521 507 477 517 503 544 544 534 528 514 518 530 535 524 537 504 519 519 528 509 526 514 527 564 511 513 505 510 556 526 488 447 515 492 523 549 532 491 519 505 533 519 520 546 541 509 534 514 539 486 510 532 516 520 529 546 545 517 520 493 519 534 539 510 507 514 501 532 523 548 511 532 464 537 509 502 527 485 483 511 509 484 494 542 531 523 532 544 509 505 529 531 470 491 487 515 547 508 563 511 525 502 518 492 524 519 485 526 478 513 514 520 525 493 550 526 528 482 536 476 511 523 520 481 485 503 512 544 530 541 499 523 554 531 508 496 517 477 533 487 517 522 557 529 507 508 512 524 489 545 485 479 510 472 505 495 523 487 533 526 498 523 510 498 523 541 482 520 519 516 503 499 486 519 503 455 530 530 501 502 542 461 561 546 533 535 545 509 522 505 519 521 560 504 478 553 514 513 506 518 535 557 483 468 511 476 491 554 505 519 493 486 464 547 499 463 545 508 505 505 515 507 508 505 508 479 544 516 484 516 481 500 506 499 518 482 476 509 516 480 530 496 536 489 518 510 508 473 485 476 529 473 509 483 483 480 491 467 522 502 527 467 487 537 503 520 483 502 539 454 480 488 519 512 476 491 491 481 494 484 480 474 537 482 523 501 501 460 492 514 508 502 488 502 507 498 473 530 493 494 510 509 498 494 462 529 499 510 517 467 499 490 501 478 522 520 508 487 472 497 471 476 505 505 494 490 499 509 472 487 460 489 536 496 498 514 483 515 495 463 496 507 496 489 499 437 517 489 499 467 471 478 498 498 475 472 510 465 496 506 526 486 479 468 437 484 493 475 483 503 460 531 494 484 527 484 462 481 533 517 486 485 469 457 484 451 506 471 497 473 493 497 467 486 532 483 525 476 467 453 492 447 459 524 483 485 438 496 504 483 500 504 493 457 471 491 441 477 480 445 496 475 502 510 507 457 499 512 496 484 471 478 480 443 492 471 514 512 507 508 466 475 443 489 453 471 492 446 418 456 500 455 501 469 507 450 486 436 492 453 471 413 451 469 517 469 441 491 465 476 570 474 485 478 509 493 486 478 508 505 444 465 457 430 477 467 456 468 502 484 488 447 472 501 455 476 474 459 485 474 517 471 452 473 500 498 468 456 484 484 479 429 424 458 445 475 482 486 428 430 454 469 475 466 453 463 467 456 448 424 490 442 440 485 459 458 461 464 437 443 451 440 434 429 387 433 447 438 435 469 459 442 456 482 433 479 417 414 453 428 463 466 466 442 440 425 488 509 440 461 445 454 413 481 432 488 452 435 457 474 481 475 415 456 456 470 447 460 466 442 455 448 427 459 486 459 461 431 444 421 443 436 425 457 430 461 470 459 448 456 478 434 417 446 443 431 445 416 419 446 446 454 432 459 434 491 458 446 437 465 413 416 428 428 419 487 456 456 434 420 491 416 429 455 463 447 447 398 409 445 468 445 425 424 437 435 442 443 454 452 438 441 452 446 442 460 431 431 436 443 469 415 475 454 385 455 464 456 430 401 435 424 426 411 442 432 462 461 438 417 472 472 399 431 421 458 416 407 447 396 430 443 397 454 429 398 443 438 407 434 381 390 442 420 474 391 427 436 415 451 394 412 404 411 426 408 430 417 427 394 443 440 446 404 407 433 435 464 467 428 388 466 433 432 436 401 415 431 404 431 444 439 426 404 419 434 423 367 416 404 429 416 409 407 394 424 422 410 387 394 405 414 430 434 440 431 446 432 407 429 396 365 415 391 421 449 415 398 404 407 434 407 437 426 408 401 432 382 410 380 399 424 397 406 443 414 383 412 428 414 415 423 383 428 424 377 375 431 451 400 414 402 383 422 405 438 383 395 423 406 397 409 407 413 403 381 379 375 401 415 400 395 433 390 350 397 404 403 425 406 390 411 369 413 384 391 362 379 415 386 362 418 384 404 409 391 383 363 412 420 434 399 386 396 380 433 401 355 405 387 396 387 411 407 420 396 394 394 389 365 412 389 372 392 402 408 393 383 398 373 412 409 350 432 415 422 382 422 374 360 384 392 402 405 401 379 362 394 390 433 403 373 396 392 397 415 388 404 391 384 379 418 407 375 373 381 392 368 383 396 414 414 389 406 373 408 386 385 411 387 372 376 384 372 343 434 380 368 364 401 370 356 372 364 372 404 407 388 397 384 398 364 354 420 385 388 384 403 353 397 371 389 367 363 405 365 389 374 393 359 372 351 376 389 364 413 386 388 373 395 403 414 389 361 331 369 343 376 379 383 353 380 408 399 404 348 327 379 368 395 364 375 376 373 383 390 373 389 395 399 418 354 372 392 391 361 343 345 392 375 375 359 365 387 386 399 363 361 368 404 379 388 347 376 406 387 416 383 364 385 354 332 392 368 431 369 375 353 378 385 377 354 360 395 368 375 374 398 362 362 344 391 422 347 386 375 378 378 390 373 375 363 384 381 349 350 376 377 394 371 386 361 367 378 394 381 382 359 360 384 347 368 373 376 392 385 381 377 388 380 385 343 363 361 355 388 399 384 389 397 339 386 373 410 371 357 361 363 381 372 363 361 329 387 367 370 368 398 357 382 376 368 382 371 349 351 363 385 349 371 375 365 363 357 349 351 368 355 384 376 391 333 330 353 373 378 383 377 379 351 378 397 400 358 381 362 342 350 359 385 347 356 362 360 336 383 354 352 355 387 370 369 392 353 363 380 382 376 338 328 358 353 355 362 343 361 378 340 348 385 355 375 372 321 335 345 350 370 372 358 373 342 381 345 364 348 356 350 379 365 332 367 334 366 341 356 331 364 356 369 382 375 358 379 358 356 353 342 360 320 353 384 338 344 334 333 355 362 348 336 363 350 368 346 355 341 370 374 353 353 345 344 357 349 320 354 345 353 342 362 350 341 388 340 369 385 378 362 357 321 345 341 362 353 360 360 337 330 322 342 348 337 341 365 353 326 352 383 335 351 338 345 333 354 341 361 341 362 340 347 326 337 350 362 379 380 338 316 352 348 391 353 346 356 370 352 390 369 371 384 357 356 326 355 382 349 360 354 378 352 357 367 341 392 337 362 327 334 333 331 341 318 346 376 361 347 352 327 366 354 349 344 368 384 366 352 363 333 357 373 352 341 318 327 371 336 301 385 377 328 327 338 343 379 348 338 330 367 313 331 347 359 345 331 312 307 350 372 327 355 326 309 340 325 346 340 332 354 339 348 308 352 326 323 323 343 337 328 336 386 319 344 324 367 346 349 338 342 346 348 349 331 297 330 324 328 327 348 352 333 317 335 356 319 342 352 338 342 330 314 322 337 333 345 305 353 327 329 350 332 293 323 334 308 333 299 338 358 335 300 342 324 322 320 333 343 309 372 346 342 332 327 352 313 383 336 323 324 323 344 333 347 345 346 297 349 367 331 281 302 341 306 337 321 322 330 321 344 318 343 324 326 325 336 331 314 325 323 325 303 348 304 356 306 345 320 300 319 288 325 322 334 329 374 277 320 355 307 309 338 330 307 318 366 318 318 341 315 306 341 321 309 305 323 343 324 336 303 338 306 318 322 328 308 286 323 309 289 349 331 340 299 303 304 293 344 358 330 341 296 316 303 314 344 347 321 337 321 309 330 354 333 292 304 289 329 311 315 296 319 310 327 337 324 328 326 304 333 334 351 344 310 337 317 320 326 324 294 347 309 358 309 315 311 314 332 347 316 340 302 321 291 303 329 334 324 306 311 337 316 324 302 306 332 289 328 289 315 319 330 342 336 311 333 324 307 320 318 282 311 321 343 281 318 280 330 284 336 301 307 307 317 332 298 281 328 301 293 306 270 280 313 343 306 325 280 321 283 283 289 307 306 290 305 343 292 312 320 292 326 283 290 307 297 313 329 316 314 320 319 319 306 338 320 326 311 309 292 352 323 326 277 319 288 294 353 316 316 303 287 286 283 304 296 303 284 315 300 278 306 297 305 319 325 278 297 289 298 294 309 288 296 364 324 302 303 297 263 300 322 292 311 291 290 284 303 302 288 310 298 311 304 302 315 308 336 319 324 280 291 308 298 315 327 282 312 317 304 313 284 291 319 302 308 289 303 331 285 289 280 286 323 314 270 302 299 282 335 301 287 267 286 316 305 291 270 336 336 307 295 277 301 310 303 270 275 291 285 287 319 305 309 291 321 311 293 313 309 342 287 291 272 292 300 301 289 286 294 262 308 302 261 273 265 306 276 300 281 291 307 308 311 311 296 287 302 307 278 303 296 244 313 283 282 300 283 283 283 306 277 326 279 301 266 265 335 312 243 316 305 316 285 326 285 299 277 292 265 313 290 295 293 273 257 302 282 317 306 305 289 264 277 303 277 286 268 303 276 280 313 292 241 293 300 304 296 314 292 304 309 287 266 283 306 291 308 303 308 307 282 288 335 292 299 265 269 319 294 285 289 293 291 268 311 299 283 298 340 313 321 310 288 304 287 315 305 322 294 313 308 310 321 309 314 317 302 294 280 365 298 320 318 320 327 325 344 345 327 329 327 311 354 364 324 380 339 340 322 349 334 375 340 365 378 349 355 390 378 391 389 402 400 416 408 356 429 410 386 408 397 438 384 398 470 406 394 405 398 443 442 440 437 381 443 429 424 469 445 427 412 426 435 394 437 449 458 445 438 450 460 443 465 444 449 466 423 479 440 460 433 478 462 454 473 436 426 440 435 441 461 415 432 430 463 438 451 408 430 452 437 430 453 443 443 480 428 429 421 423 396 435 395 429 420 399 392 396 406 431 388 426 393 412 406 378 424 426 358 384 381 400 387 397 378 370 361 378 357 353 344 387 334 352 337 352 346 331 335 355 340 340 340 361 325 321 363 330 330 300 334 342 306 333 334 280 266 313 306 305 295 315 298 296 306 280 291 312 312 299 285 274 304 241 239 278 270 288 261 256 280 299 283 280 284 257 264 292 256 258 260 282 268 263 283 293 283 267 271 260 265 257 245 277 272 268 264 249 273 281 276 244 265 278 277 222 260 265 282 266 247 241 233 267 301 259 222 273 247 280 261 246 243 289 227 260 231 284 260 263 266 260 268 272 276 267 225 221 236 273 250 246 225 270 268 204 285 265 244 243 224 280 220 293 234 265 269 244 243 281 267 233 238 270 284 255 227 309 280 232 259 249 241 240 272 224 256 245 274 262 239 222 236 233 234 242 273 274 280 239 272 229 248 235 236 246 240 262 258 262 264 257 243 234 264 245 235 241 235 231 222 265 262 280 237 214 234 266 274 232 256 238 215 244 257 242 245 293 247 221 223 276 255 245 258 226 262 260 233 240 239 257 225 261 261 245 232 262 236 244 230 228 264 219 279 214 244 233 230 224 283 226 229 255 232 268 246 224 259 211 250 277 226 235 264 247 235 256 237 280 244 246 233 248 211 256 232 223 222 265 209 257 247 211 255 210 220 221 219 229 228 242 262 225 238 204 236 219 248 231 255 227 217 223 248 228 234 246 208 256 288 239 234 220 222 214 236 262 229 261 239 231 244 209 221 240 232 222 221 236 228 229 244 239 206 236 213 245 229 235 241 225 221 219 240 223 265 263 237 259 227 232 231 249 205 259 211 248 256 259 212 200 232 200 229 229 208 210 230 213 212 208 236 207 239 212 221 228 228 231 225 209 209 217 249 221 203 232 209 214 229 229 236 230 226 204 235 235 197 208 239 220 215 212 223 212 205 202 217 224 205 227 233 224 218 232 217 202 209 215 226 229 232 209 209 218 233 199 201 224 204 209 231 214 219 230 216 230 234 202 212 204 213 204 210 228 217 237 244 237 202 227 237 213 219 210 243 216 208 234 211 211 221 219 220 244 226 233 228 256 218 211 219 227 226 214 225 227 220 212 222 229 241 223 256 211 230 187 200 238 247 232 229 211 225 202 221 212 228 218 216 229 205 201 208 217 244 226 212 225 203 227 194 196 222 212 262 221 209 228 205 197 215 220 221 222 237 223 218 220 197 198 228 197 219 269 186 225 201 201 191 199 204 220 222 218 219 216 210 233 190 185 210 192 220 219 205 220 202 210 231 200 206 221 222 223 207 200 222 232 219 208 209 197 226 255 204 199 226 204 216 256 189 231 194 203 210 219 212 198 204 216 204 209 204 201 196 200 198 175 214 218 191 219 231 216 203 200 215 229 186 212 233 237 224 223 209 197 193 184 239 238 190 209 195 224 232 210 215 230 221 208 207 203 213 214 206 234 188 212 205 226 218 212 219 180 205 200 195 215 257 176 207 194 220 229 205 196 220 192 171 194 196 191 213 198 209 181 208 238 174 190 210 194 197 200 227 189 199 224 202 244 198 209 190 176 204 216 212 170 198 201 177 175 192 202 184 172 197 225 210 176 209 188 203 201 188 195 210 199 206 211 213 165 215 200 206 194 222 222 211 208 185 204 204 190 202 186 192 188 196 192 193 204 194 188 192 198 222 176 209 207 182 222 193 197 183 186 186 181 211 195 202 183 192 199 180 183 186 178 200 215 189 163 170 210 193 178 197 192 187 195 201 207 189 196 198 198 194 206 213 167 188 180 185 187 198 195 186 176 184 191 199 197 203 178 181 186 169 189 212 189 208 174 194 221 192 183 190 194 181 177 176 215 190 198 190 196 199 188 160 189 196 208 200 195 188 189 213 180 185 175 208 178 178 191 147 185 175 199 202 186 180 217 165 188 210 216 190 195 204 180 191 189 182 159 179 174 192 182 190 208 157 177 177 204 190 193 186 163 205 192 188 198 194 177 177 181 198 192 202 171 190 171 172 167 176 172 176 191 182 183 170 176 194 191 155 162 176 186 161 166 162 161 165 190 192 201 170 179 189 170 160 183 184 178 150 176 165 192 196 186 181 161 195 182 174 179 180 176 152 187 181 163 190 175 181 171 190 179 188 184 191 177 187 162 205 177 164 173 204 163 176 170 214 183 201 198 184 163 190 161 181 180 176 185 176 157 194 187 177 175 179 181 189 162 154 170 180 168 171 172 157 180 178 177 169 192 174 193 162 165 199 175 206 191 164 172 188 163 166 199 170 189 175 161 188 165 183 171 186 185 177 161 169 167 163 154 184 166 199 174 174 176 164 168 177 175 183 157 163 168 178 163 151 167 182 180 175 162 162 160 171 176 158 184 182 192 187 168 181 174 164 167 159 164 172 165 195 170 177 170 173 168 164 176 156 182 168 187 182 171 178 172 185 157 168 184 159 140 169 182 195 178 168 181 167 162 166 168 187 171 182 170 172 171 185 167 164 183 165 166 186 165 194 144 196 168 180 166 196 185 151 188 159 147 182 144 168 168 180 175 162 174 182 153 178 176 178 166 188 156 196 163 144 194 176 169 173 166 169 185 182 156 197 181 187 146 157 162 185 159 167 145 180 151 164 153 154 181 187 156 165 195 182 158 165 179 178 158 166 169 179 157 170 176 159 152 141 162 173 192 161 165 157 176 146 178 163 153 152 148 170 170 157 172 142 167 171 162 165 161 156 174 150 178 165 162 154 170 158 183 160 167 169 163 179 170 187 161 175 159 174 155 156 149 188 176 145 159 166 212 162 168 174 172 178 189 154 139 151 189 142 158 152 145 177 174 168 155 153 173 158 159 179 140 178 159 171 168 150 182 169 167 133 173 151 160 162 179 164 171 164 152 161 155 171 164 177 188 166 147 153 190 167 172 181 150 161 155 166 149 167 152 176 162 155 161 176 151 138 165 159 174 161 145 161 162 144 146 151 168 167 176 148 141 150 158 176 168 170 155 139 176 167 162 155 161 151 158 154 151 164 163 152 164 144 157 186 172 172 169 173 159 159 158 173 154 144 155 161 152 147 161 175 155 165 146 151 151 163 148 137 140 153 143 152 154 155 176 145 162 141 164 152 178 146 147 171 167 168 136 170 149 173 158 165 166 162 147 170 159 146 165 151 164 158 136 147 154 145 174 152 124 167 133 147 184 164 152 152 159 160 145 142 156 176 165 128 146 171 153 163 152 144 149 142 152 164 153 161 163 137 158 151 137 161 149 148 141 149 159 155 142 154 143 140 134 163 147 132 131 143 155 155 145 145 155 144 140 162 160 121 138 136 162 159 152 144 176 143 146 147 156 134 149 135 139 149 176 143 183 143 151 157 145 148 163 182 154 148 162 146 159 152 146 148 162 126 132 124 140 155 124 150 161 140 151 155 151 138 168 150 145 138 143 125 138 153 153 164 140 142 136 154 139 123 166 145 146 156 136 154 134 135 145 157 157 132 162 132 128 143 134 154 138 154 150 122 157 155 156 137 158 145 139 139 151 138 133 132 154 144 142 164 137 133 156 175 157 143 130 171 152 139 145 143 142 143 136 141 165 149 166 125 151 157 117 130 153 141 133 160 124 142 142 136 130 161 141 134 130 140 141 140 158 130 126 158 138 155 151 128 130 145 145 143 152 138 150 142 163 147 125 116 151 130 157 139 169 143 110 139 115 130 143 146 128 141 146 138 131 138 167 122 155 155 126 124 167 139 113 139 123 129 135 148 150 136 151 115 117 145 164 128 141 130 133 116 141 140 130 138 137 143 129 131 127 133 150 126 138 135 110 150 131 132 130 140 141 126 149 131 149 137 154 155 144 137 144 146 143 133 144 144 141 134 116 156 148 146 135 138 126 152 142 148 127 138 134 156 130 141 142 152 135 124 133 145 129 118 132 162 121 129 139 125 113 159 148 137 135 145 119 151 119 145 124 151 145 130 119 128 150 142 148 133 147 131 143 140 151 151 127 122 136 148 166 139 138 115 140 134 160 132 120 133 150 143 164 123 139 124 134 144 107 116 166 123 127 135 154 133 138 117 131 122 139 146 123 121 148 123 152 142 129 130 126 128 125 126 127 124 114 147 146 143 132 131 132 148 136 112 159 129 138 141 138 121 111 132 104 131 128 140 140 133 123 144 116 123 134 140 135 143 116 113 120 129 141 147 134 133 128 136 130 146 144 136 131 140 128 114 139 135 142 138 123 129 142 137 121 127 124 149 130 123 134 128 141 132 118 131 132 118 116 137 141 139 134 141 150 139 132 153 137 135 109 129 139 138 121 164 118 136 141 125 141 131 116 137 128 125 118 140 149 132 129 140 134 156 124 159 107 145 159 138 152 136 125 144 132 139 149 152 148 141 133 133 138 139 145 144 122 108 126 142 149 128 142 127 133 161 136 151 135 127 114 132 152 138 121 141 139 129 135 140 121 127 128 134 127 118 125 132 139 133 124 141 138 140 133 146 134 128 136 124 122 136 122 115 139 147 133 144 152 135 123 124 132 139 131 132 132 143 156 116 119 140 144 130 141 132 132 136 122 118 130 133 125 107 118 128 141 127 134 128 107 125 130 135 144 115 133 135 120 134 128 136 105 125 115 136 144 122 116 133 120 122 122 131 131 114 107 110 113 118 133 152 120 118 136 120 141 135 103 121 116 139 135 119 118 125 117 116 139 116 118 116 126 126 147 145 151 148 122 135 148 130 111 123 115 127 117 125 88 119 108 114 109 133 118 146 132 126 124 126 119 127 137 129 130 122 117 129 121 152 128 132 127 139 133 116 113 121 99 107 133 156 127 121 131 139 124 108 112 120 112 120 114 131 106 121 124 126 120 114 127 120 141 111 123 110 123 131 119 115 138 133 110 122 104 108 124 102 135 106 130 121 120 115 115 108 140 111 105 114 139 117 105 116 101 138 103 107 119 123 104 130 131 124 129 110 114 128 125 102 145 126 121 110 133 140 126 129 120 93 131 128 128 138 158 140 140 115 122 127 131 112 115 115 102 101 134 121 113 124 129 115 110 118 132 115 131 110 98 114 103 130 123 143 107 107 128 108 130 129 112 125 120 109 122 125 111 112 114 126 122 114 123 121 107 115 114 105 113 111 119 129 116 131 141 127 120 122 110 110 105 109 113 124 104 116 105 120 116 117 106 118 98 108 115 102 111 117 114 123 106 110 111 124 139 106 116 104 108 99 126 112 98 125 133 122 111 118 107 121 114 127 107 121 119 119 127 131 97 89 106 94 121 107 104 113 106 106 120 110 133 116 111 114 109 124 123 130 117 118 105 112 107 124 130 119 107 97 113 116 114 115 130 114 117 127 118 125 118 106 124 133 106 117 107 114 114 103 105 115 121 109 98 120 99 113 125 112 104 111 112 125 112 103 103 114 111 124 129 129 120 108 138 98 104 128 108 122 130 114 105 124 113 118 113 98 115 104 111 96 130 125 98 117 103 117 105 104 118 117 120 104 110 131 105 101 112 106 124 92 100 122 118 96 118 111 110 108 123 107 113 117 106 115 125 117 120 109 94 126 105 129 109 99 120 121 100 110 100 97 90 124 102 90 129 104 102 133 122 110 116 105 117 121 120 113 128 85 131 99 110 120 96 108 122 111 137 106 108 126 102 107 116 95 102 112 106 109 107 111 106 102 114 103 121 98 93 120 116 122 105 116 117 112 114 108 112 99 112 116 124 103 95 102 115 96 110 92 111 83 105 114 112 105 103 104 107 112 103 103 112 108 102 107 103 101 101 99 121 96 122 114 108 99 101 120 96 108 109 97 104 104 115 101 104 122 110 114 93 114 121 115 96 112 103 110 107 90 107 97 106 128 97 121 112 92 90 91 98 105 110 97 117 102 98 99 109 101 101 101 92 106 95 86 98 117 105 99 114 112 99 89 102 108 130 108 99 96 96 110 104 101 104 107 109 105 101 106 96 109 89 104 103 105 109 75 101 90 110 115 90 112 97 90 103 102 108 111 92 92 100 90 121 108 121 115 82 123 86 91 109 117 99 100 119 100 97 97 99 113 103 111 85 96 108 97 106 99 87 91 96 86 100 95 100 103 101 118 91 105 122 113 86 99 88 92 90 97 108 104 94 107 101 98 92 94 85 107 102 125 75 103 97 107 100 118 98 82 95 110 104 98 114 90 92 110 94 93 124 111 93 110 88 115 93 100 100 108 88 99 96 90 90 94 77 106 104 106 110 108 119 115 119 97 97 101 100 117 113 104 91 111 112 102 93 115 104 99 94 82 105 90 115 94 118 99 87 98 105 100 96 91 97 78 90 102 101 99 105 110 93 110 117 103 91 92 101 99 95 86 103 104 109 100 98 101 87 115 107 95 102 96 93 92 96 94 95 89 103 87 103 111 101 99 95 91 83 106 117 112 96 88 85 98 103 101 90 92 77 87 88 82 98 96 96 92 100 103 88 93 104 116 102 102 88 75 110 110 98 95 101 95 90 98 89 98 100 98 109 98 82 107 95 88 113 88 85 97 81 112 117 76 92 80 100 92 97 92 85 80 96 109 99 113 80 87 93 90 94 107 84 98 101 92 119 98 107 100 101 95 106 75 79 90 111 85 103 100 86 85 96 103 85 79 105 87 101 88 102 103 99 81 105 98 102 102 108 105 104 87 103 96 88 96 103 110 91 95 103 97 108 97 105 105 91 84 92 94 90 93 105 96 103 106 97 107 108 104 95 102 113 121 80 95 76 88 110 94 91 100 71 84 85 94 76 95 92 105 127 95 109 83 101 96 73 84 101 91 99 95 105 87 94 107 97 101 88 98 91 90 101 102 94 84 79 88 102 81 100 100 92 93 89 118 90 90 94 103 91 91 90 107 81 103 93 96 97 97 95 86 92 91 101 85 114 98 85 96 122 91 85 95 77 85 93 112 80 100 95 99 97 108 109 91 91 102 85 94 78 87 101 100 96 94 100 89 111 104 99 89 107 95 66 84 107 107 104 92 89 97 101 83 83 106 96 96 92 80 86 88 79 88 86 103 99 87 84 94 103 90 87 91 67 90 93 99 92 79 99 90 81 91 115 92 97 107 111 91 99 100 79 98 83 85 99 99 99 87 91 85 95 90 95 94 87 122 100 77 83 92 113 78 99 88 84 98 88 104 87 90 99 96 104 79 96 86 94 98 91 80 84 105 90 90 95 108 87 104 95 112 79 73 94 83 90 83 83 99 92 95 84 93 85 90 98 97 79 78 102 79 87 80 87 86 78 85 76 105 95 81 97 102 96 77 102 86 98 83 85 97 97 91 98 81 99 80 93 89 96 91 94 104 92 97 100 92 105 95 103 98 98 93 99 85 103 67 92 91 88 93 90 95 100 101 84 81 87 88 93 95 96 92 83 89 94 98 108 96 97 98 98 109 95 99 93 83 100 83 80 87 102 106 89 89 76 101 97 91 85 83 96 108 79 83 103 90 91 95 91 86 68 89 93 85 99 89 93 82 74 101 86 98 77 84 99 81 86 80 91 93 96 85 99 88 94 78 90 94 82 82 71 88 119 90 96 90 98 99 100 86 86 95 95 85 73 92 106 80 92 102 96 96 86 95 99 80 90 74 85 101 87 95 83 89 88 68 97 83 105 88 114 81 73 95 99 82 71 88 93 80 84 81 103 86 69 106 85 92 83 88 77 86 80 88 96 91 88 76 75 85 101 88 106 93 85 101 94 102 90 94 92 85 99 84 84 94 84 83 89 84 92 94 78 89 92 70 87 94 92 71 86 85 85 78 84 92 105 83 103 69 75 86 93 74 92 95 93 91 90 98 89 84 92 100 100 72 76 82 91 98 76 93 89 77 99 87 99 96 102 94 86 91 81 96 94 81 101 88 93 78 90 96 84 108 64 69 85 85 97 103 89 92 73 93 96 69 91 92 79 98 91 79 87 89 74 84 92 110 87 83 92 79 87 91 97 106 94 92 75 88 88 82 96 68 93 86 91 116 78 87 85 84 90 96 101 94 103 85 83 97 89 93 81 77 93 100 69 87 74 99 80 100 70 76 71 100 80 80 97 81 76 75 96 97 85 82 88 105 85 77 61 71 85 84 78 73 78 98 93 88 99 91 68 81 89 81 79 96 83 93 71 87 68 95 79 86 90 75 83 83 89 82 74 91 85 73 84 86 84 73 90 74 80 79 80 88 85 74 90 94 83 98 86 69 92 85 93 86 85 104 67 88 83 84 93 91 90 90 83 83 79 91 95 108 92 89 79 93 95 111 97 86 89 90 92 81 67 92 97 90 73 86 103 90 69 74 86 92 79 104 86 93 95 86 86 95 79 92 95 81 92 97 81 80 92 92 94 82 100 113 106 79 87 95 85 82 97 85 89 89 90 94 96 85 92 93 89 86 98 99 98 83 90 75 80 89 106 81 78 82 88 90 88 91 91 98 84 90 94 94 97 85 92 81 94 108 91 78 70 82 84 91 81 79 87 68 78 93 97 84 95 92 96 89 100 95 88 86 73 85 71 81 67 82 97 80 84 86 85 83 91 96 86 94 80 75 61 73 80 72 83 84 77 69 91 77 76 84 98 88 95 79 78 74 87 82 98 84 82 76 88 90 84 93 89 86 82 85 71 92 72 73 81 82 76 83 91 74 82 68 65 74 79 74 69 73 76 87 74 87</counts>
			</dataPoints>
		</scan>
	</xrdMeasurement>
</xrdMeasurements>