File: data/XRD/GIXRD/W6823-1D.xrdml
<xrdMeasurements xmlns="http://www.xrdml.com/XRDMeasurement/2.1" xmlns:xsi="http://www.w3.org/2001/XMLSchema-instance" xsi:schemaLocation="http://www.xrdml.com/XRDMeasurement/2.1 http://www.xrdml.com/XRDMeasurement/2.1/XRDMeasurement.xsd" status="Completed">
	<comment>
		<entry>Configuration=Factory configuration, Owner=User-1, Creation date=7/8/2013 4:01:53 PM</entry>
		<entry>Goniometer=PW3050/65 (Theta/2Theta); Minimum step size 2Theta:0.0001; Minimum step size Omega:0.0001</entry>
		<entry>Sample stage=MRD Cradle; Minimum step size Phi:0.01; Minimum step size Chi:0.01; Minimum step size X:0.01; Minimum step size Y:0.01; Minimum step size Z:0.001</entry>
		<entry>Diffractometer system=XPERT-PRO</entry>
		<entry>Measurement program=C:\PANalytical\Data Collector\Programs\SimonL\GIXRD_om_fest-2deg_2theta-10deg-80deg_40s.xrdmp, Identifier={5D08F084-E282-4D09-BA8B-67D165D754DE}</entry>
		<entry>Batch program=C:\PANalytical\Data Collector\Programs\SimonL\batch7x_2thom_10-130°_z9.1_x0,10,20,30_y10,20,30_57min.xrdmp, Identifier={E4DA177A-5C7A-4C52-834B-D6C6EE2424A1}</entry>
	</comment>
	<sample type="To be analyzed">
		<id></id>
		<name></name>
		<preparedBy></preparedBy>
	</sample>
	<xrdMeasurement measurementType="Scan" status="Completed" sampleMode="Reflection">
		<comment>
			<entry>PHD Lower Level = 4.83 (keV), PHD Upper Level = 11.27 (keV)</entry>
		</comment>
		<usedWavelength intended="K-Alpha 1">
			<kAlpha1 unit="Angstrom">1.5405980</kAlpha1>
			<kAlpha2 unit="Angstrom">1.5444260</kAlpha2>
			<kBeta unit="Angstrom">1.3922500</kBeta>
			<ratioKAlpha2KAlpha1>0.5000</ratioKAlpha2KAlpha1>
		</usedWavelength>
		<incidentBeamPath>
			<radius unit="mm">320.00</radius>
			<xRayTube id="1010048" name="Empyrean Cu LFF HR (9430 033 7310x) DK442154">
				<tension unit="kV">40.0</tension>
				<current unit="mA">40.0</current>
				<anodeMaterial>Cu</anodeMaterial>
				<focus type="Line">
					<length unit="mm">12.0</length>
					<width unit="mm">0.4</width>
					<takeOffAngle unit="deg">4.2</takeOffAngle>
				</focus>
			</xRayTube>
			<xRayMirror id="27010001" name="Inc. Beam Cu W/Si (parabolic MRD)" hybrid="false">
				<crystal type="Graded" shape="Parabolic">W/Si</crystal>
				<acceptanceAngle unit="deg">0.800</acceptanceAngle>
				<length unit="mm">60.0</length>
			</xRayMirror>
			<sollerSlit id="21010002" name="Soller slits 0.04 rad.">
				<opening unit="rad">0.0400</opening>
			</sollerSlit>
			<mask id="22030008" name="Fixed mask 4 mm">
				<distanceToSample unit="mm">220.00</distanceToSample>
				<width unit="mm">4.00</width>
			</mask>
			<divergenceSlit id="22010007" name="Fixed slit 1/8°" xsi:type="fixedDivergenceSlitType">
				<distanceToSample unit="mm">220.00</distanceToSample>
				<height unit="mm">0.19</height>
			</divergenceSlit>
		</incidentBeamPath>
		<diffractedBeamPath>
			<radius unit="mm">320.00</radius>
			<sollerSlit id="21010002" name="Soller slits 0.04 rad.">
				<opening unit="rad">0.0400</opening>
			</sollerSlit>
			<receivingSlit id="22010001" name="Fixed slit 4°">
				<height unit="mm">5.88</height>
			</receivingSlit>
			<detector id="7010017" name="PIXcel3D 1x1 detector" xsi:type="areaDetectorType">
				<phd unit="%">
					<lowerLevel>30.0</lowerLevel>
					<upperLevel>70.0</upperLevel>
				</phd>
				<mode>Scanning</mode>
				<activeChannelsEquatorial>255</activeChannelsEquatorial>
				<activeChannelsAxial>255</activeChannelsAxial>
				<pitchEquatorial unit="mm">0.05500</pitchEquatorial>
				<pitchAxial unit="mm">0.05500</pitchAxial>
				<readOutPeriod unit="seconds">0.155</readOutPeriod>
			</detector>
		</diffractedBeamPath>
		<scan appendNumber="0" mode="Continuous" scanAxis="2Theta" status="Completed">
			<header>
				<startTimeStamp>2024-11-01T20:50:44+01:00</startTimeStamp>
				<endTimeStamp>2024-11-01T21:28:53+01:00</endTimeStamp>
				<author>
					<name>PRO-MRD</name>
				</author>
				<source>
					<applicationSoftware version="6.1b">Data Collector</applicationSoftware>
					<instrumentControlSoftware version="7.0E 20130304">XPERT-PRO</instrumentControlSoftware>
					<instrumentID>0000000011142674</instrumentID>
				</source>
			</header>
			<dataPoints>
				<positions axis="2Theta" unit="deg">
					<startPosition>10.00246193</startPosition>
					<endPosition>79.99507515</endPosition>
				</positions>
				<positions axis="Omega" unit="deg">
					<commonPosition>2.0000</commonPosition>
				</positions>
				<positions axis="Phi" unit="deg">
					<commonPosition>0.00</commonPosition>
				</positions>
				<positions axis="Chi" unit="deg">
					<commonPosition>0.00</commonPosition>
				</positions>
				<positions axis="X" unit="mm">
					<commonPosition>30.00</commonPosition>
				</positions>
				<positions axis="Y" unit="mm">
					<commonPosition>0.00</commonPosition>
				</positions>
				<positions axis="Z" unit="mm">
					<commonPosition>9.100</commonPosition>
				</positions>
				<commonCountingTime unit="seconds">37.995</commonCountingTime>
				<counts 568 560 558 567 561 557 553 578 583 561 568 561 539 542 522 598 568 521 570 536 553 536 573 603 550 550 585 543 583 529 574 544 568 558 582 535 580 563 556 525 585 508 518 529 576 568 531 552 547 543 576 523 573 561 515 528 549 485 537 542 578 543 518 583 543 568 560 554 576 563 569 515 556 545 580 579 537 488 567 516 580 562 576 564 506 548 563 588 523 554 535 544 533 537 585 540 553 531 570 544 553 555 543 536 582 533 561 533 552 569 572 534 552 539 557 564 555 579 513 556 539 541 561 554 540 543 530 567 576 554 547 556 548 533 555 549 604 532 589 554 520 544 509 561 541 541 541 552 571 581 547 536 519 528 538 564 594 516 544 545 564 533 540 561 544 563 596 523 512 548 581 544 554 521 556 552 520 565 597 525 545 528 548 553 553 540 583 492 506 520 486 571 560 556 590 561 524 523 553 520 559 554 529 514 542 548 521 547 581 550 569 556 561 491 556 581 549 556 510 551 551 586 529 537 553 529 514 589 522 550 544 566 521 518 542 564 547 547 576 540 527 522 535 512 549 544 543 555 532 524 562 558 570 553 538 559 551 525 537 527 552 581 565 537 551 571 544 582 562 567 523 571 586 516 582 568 516 547 555 581 525 549 530 569 506 530 530 526 558 504 520 546 563 550 561 532 532 539 532 537 562 508 564 570 552 521 568 551 554 541 537 569 530 564 552 523 555 578 528 494 520 546 587 576 601 536 550 555 547 553 579 536 522 575 564 567 572 533 542 519 524 504 517 580 574 550 532 548 579 566 572 569 553 537 605 515 536 557 548 540 571 557 556 529 582 555 529 565 561 522 567 541 607 558 535 519 535 578 548 582 534 556 536 541 550 582 547 549 582 560 507 485 553 545 570 489 538 576 514 510 548 542 597 561 534 550 553 556 588 592 531 580 608 534 567 532 569 553 562 548 580 556 581 558 554 547 555 549 580 562 556 601 544 492 533 562 575 564 562 599 566 546 513 580 546 557 601 575 594 504 511 573 570 555 528 544 539 549 547 571 585 523 521 515 552 551 568 546 547 545 547 542 543 529 568 555 516 551 557 560 557 528 545 544 523 581 550 537 556 534 600 541 562 551 518 557 594 541 568 521 554 550 500 544 552 544 584 570 567 568 547 563 543 531 559 563 568 572 603 532 549 557 516 500 534 543 598 563 572 567 548 557 539 594 552 550 574 573 555 590 531 557 549 487 560 563 557 549 582 557 581 582 539 535 586 570 585 565 580 589 566 551 585 570 537 510 537 540 563 597 554 590 556 582 568 568 530 565 508 534 528 569 551 550 595 543 544 535 561 544 570 573 561 576 526 545 560 597 567 561 554 583 566 528 528 564 550 558 583 561 565 571 591 559 596 556 607 576 590 538 605 659 560 546 592 546 599 569 553 580 559 582 572 577 561 546 550 550 562 603 558 507 593 615 579 602 564 587 560 611 592 569 586 575 594 567 570 557 565 560 596 584 596 536 606 553 561 612 548 568 546 572 608 579 549 549 530 590 557 562 580 569 633 591 593 586 565 583 583 577 600 577 574 588 593 587 581 593 588 554 556 567 555 623 538 596 589 573 578 617 575 581 591 596 519 570 564 573 639 575 588 617 582 610 567 553 562 536 608 572 598 576 532 563 614 586 583 575 527 640 606 595 549 578 576 576 598 587 589 552 533 601 618 581 557 583 567 646 552 588 562 567 571 593 569 590 589 589 557 553 609 560 581 619 580 587 562 598 604 601 583 602 613 582 614 598 581 538 658 538 605 595 557 569 637 606 548 578 622 533 549 596 636 624 589 589 605 593 643 594 594 582 552 570 613 589 567 596 568 604 566 624 587 602 565 576 581 583 574 608 574 594 605 602 618 546 589 577 548 551 615 642 616 561 583 608 603 570 595 591 609 605 572 542 577 548 583 550 596 613 606 581 589 615 542 609 588 568 564 586 581 599 540 610 522 602 628 637 602 595 596 559 632 583 571 558 575 611 580 569 571 579 573 592 552 637 568 552 587 633 592 585 619 610 608 591 576 602 588 579 603 644 598 545 582 598 610 564 569 605 583 623 592 559 615 582 579 559 567 622 586 564 539 594 583 604 611 589 557 595 558 551 622 601 585 603 522 584 623 587 584 623 593 568 621 581 587 552 586 609 558 605 561 589 579 579 551 553 624 577 570 607 630 580 568 615 618 632 623 593 553 555 580 594 576 576 587 584 557 615 577 620 585 594 582 568 611 578 597 583 554 553 567 603 608 574 620 553 587 603 639 562 570 552 618 547 611 604 610 564 542 539 565 561 584 543 549 589 601 570 620 600 606 577 630 583 606 590 566 620 572 569 584 577 585 605 614 584 616 543 540 558 577 584 579 549 601 616 563 598 575 630 579 590 555 588 624 577 603 550 580 565 546 581 600 583 565 610 590 620 575 613 514 571 592 571 578 530 608 594 568 553 552 585 555 572 592 569 555 552 564 559 599 525 566 604 545 618 580 571 596 577 567 565 564 533 597 565 633 587 552 571 554 571 588 586 553 604 544 566 554 575 551 607 557 567 572 613 553 586 579 627 591 618 590 583 570 549 569 575 568 586 607 575 585 560 566 587 577 553 529 535 554 603 595 548 592 607 522 563 569 586 558 581 590 586 566 539 579 576 562 604 596 534 571 563 578 608 567 609 534 529 580 548 563 569 652 560 597 563 566 586 597 603 585 596 584 588 561 589 575 538 611 554 554 564 561 614 555 611 536 559 581 567 628 571 558 569 614 613 553 562 544 580 576 575 569 524 590 560 582 541 539 560 570 584 545 585 600 548 607 566 578 615 638 581 585 593 566 592 557 585 571 602 556 587 519 598 513 553 598 527 541 524 601 550 568 547 570 577 572 560 546 618 543 560 543 615 594 564 587 623 598 559 546 546 555 519 582 554 587 562 569 548 546 558 568 596 567 582 532 545 532 540 537 569 534 578 581 582 541 572 562 558 549 565 571 586 542 573 582 561 545 559 525 545 507 551 497 558 520 532 540 560 534 576 593 558 549 547 506 524 527 572 546 544 546 525 558 553 526 517 541 552 547 572 544 573 589 578 555 560 561 503 581 571 548 559 585 539 553 526 571 560 544 547 557 595 530 605 558 534 592 549 546 522 546 535 546 547 559 551 556 522 523 563 524 521 574 553 570 581 563 567 525 572 530 574 546 544 561 564 522 500 536 574 569 585 549 543 546 573 508 495 551 562 535 548 511 564 564 577 569 522 559 513 508 558 531 537 551 544 576 556 554 573 561 559 535 519 553 523 534 521 539 542 537 514 500 521 520 530 525 510 567 535 540 527 538 513 524 525 508 544 536 545 560 576 543 489 551 493 540 529 487 561 498 542 518 543 531 517 500 542 536 522 546 491 539 511 499 537 512 533 520 523 529 499 543 519 509 503 529 504 562 512 524 538 502 546 541 531 521 553 538 517 538 526 517 512 550 487 533 531 511 492 536 499 549 520 534 559 507 541 484 486 506 522 546 515 479 489 520 512 524 491 543 558 493 491 541 507 526 543 525 555 528 472 510 524 550 523 489 562 513 514 540 484 473 549 489 498 516 492 507 550 491 516 514 523 502 502 502 528 466 500 465 524 476 514 529 521 534 536 573 509 543 485 517 508 455 487 505 498 492 498 520 486 489 505 508 523 500 523 515 550 549 549 558 499 546 484 500 483 542 507 509 453 481 535 513 515 497 493 508 521 499 495 446 496 542 491 508 494 489 517 523 507 527 470 485 506 483 471 462 487 508 529 499 493 511 523 509 491 500 507 484 458 506 505 442 545 491 538 536 515 489 508 436 477 500 509 456 476 508 518 503 488 509 522 471 466 477 516 496 461 425 520 534 461 497 462 521 471 505 510 507 505 515 472 466 476 486 493 526 459 452 515 483 476 461 465 513 488 521 470 523 503 488 501 488 480 469 479 505 434 509 456 429 470 486 476 466 454 463 504 463 494 472 465 461 417 485 443 495 502 408 456 448 468 449 478 446 447 468 474 489 437 470 429 472 466 435 486 482 503 483 481 476 454 438 449 471 458 467 467 438 482 483 477 448 439 467 448 431 499 453 442 475 441 428 464 430 438 418 454 446 440 491 453 471 428 467 514 449 426 459 445 476 435 460 440 443 453 461 478 464 434 463 451 458 472 485 495 452 462 473 459 453 472 433 440 444 428 473 443 495 455 452 448 432 417 456 468 471 428 465 440 446 442 463 442 409 493 416 423 440 452 462 460 455 434 407 457 482 418 432 434 467 418 463 468 449 422 432 422 454 461 449 477 410 420 435 391 456 432 408 449 450 444 444 425 444 425 419 441 431 457 437 416 469 457 480 428 463 432 436 421 407 432 440 404 452 456 435 421 454 449 474 437 468 413 450 443 436 430 455 431 408 418 426 424 454 413 432 459 431 435 483 428 448 442 443 415 441 437 433 441 450 448 439 416 418 422 460 449 432 428 474 423 392 441 429 467 434 429 400 444 445 449 470 379 437 453 425 377 437 416 416 478 412 437 438 417 436 396 415 434 439 439 443 434 421 378 447 436 388 419 428 407 428 434 384 438 439 379 423 418 453 460 399 431 368 423 441 409 399 404 400 410 417 424 377 428 425 418 398 446 461 420 415 378 387 422 430 409 403 426 417 424 404 392 397 443 416 417 413 440 426 410 396 434 426 427 424 421 429 387 424 433 410 457 417 409 403 417 425 380 401 390 391 384 412 424 395 428 425 359 425 402 402 440 393 378 409 401 407 407 395 413 434 421 415 430 419 395 405 412 434 392 409 418 411 362 383 399 388 390 395 408 416 391 392 483 425 420 388 409 387 347 425 404 415 434 425 429 412 387 368 386 377 385 403 428 386 450 397 416 381 393 412 411 371 416 392 414 429 428 373 404 377 370 394 391 403 384 395 369 393 395 375 392 385 400 408 373 402 417 395 373 371 367 409 421 381 367 373 370 398 376 363 392 396 389 385 382 432 390 419 409 393 402 363 362 368 359 356 404 368 379 344 367 379 375 387 401 402 397 359 395 374 400 370 425 388 418 373 388 413 397 380 368 377 355 379 370 363 402 386 339 394 400 398 367 398 365 400 428 344 383 392 353 424 376 363 378 348 344 374 362 363 366 374 387 388 367 368 402 359 384 373 382 390 406 368 372 388 408 406 378 368 377 377 392 364 374 346 375 392 388 374 400 377 376 358 355 343 367 387 371 381 339 398 369 338 358 400 390 375 393 363 354 370 345 411 375 354 361 383 376 349 352 353 394 352 361 407 361 385 318 372 378 389 353 361 376 358 354 379 354 377 373 343 352 372 349 389 330 340 390 391 340 362 352 358 370 387 379 352 357 336 367 380 371 375 325 337 396 399 391 345 357 373 353 377 328 347 349 373 363 357 327 357 358 392 365 345 382 398 354 359 348 366 361 352 392 361 345 356 384 425 378 373 341 360 370 350 357 343 327 355 380 375 376 376 358 368 362 373 327 346 329 347 356 317 354 388 371 351 346 336 339 345 362 355 404 317 348 378 349 356 345 326 380 377 366 332 345 315 353 357 349 366 362 364 336 324 365 356 373 358 372 359 320 339 330 360 349 330 344 374 370 334 359 346 365 342 308 372 328 353 359 354 326 341 346 389 339 346 352 326 334 366 358 353 331 360 347 358 348 342 395 353 358 319 333 338 318 334 358 343 355 337 343 332 361 351 335 365 347 332 338 345 312 331 359 360 337 364 318 370 337 316 346 324 317 346 317 334 332 376 339 370 332 324 326 320 326 318 336 368 346 313 350 353 344 322 362 313 344 338 367 359 337 315 390 328 356 349 317 327 352 333 347 352 282 357 354 338 342 317 337 331 312 336 325 366 356 328 322 325 354 309 334 347 319 335 326 350 342 344 344 364 364 338 318 327 320 345 330 358 327 322 340 343 338 342 324 317 345 295 331 367 357 339 307 336 346 326 321 332 343 346 341 337 342 338 344 326 317 324 361 325 336 341 360 342 362 338 324 339 330 327 320 317 359 363 340 332 337 350 313 352 332 336 372 340 309 345 363 314 339 309 380 330 309 352 356 348 336 344 332 339 366 354 337 390 328 377 372 326 347 358 331 329 313 342 359 371 357 314 336 341 363 351 339 319 332 328 344 325 363 345 342 345 370 337 335 341 333 319 320 341 300 370 314 328 311 305 330 337 337 340 341 288 334 327 331 322 352 339 320 342 319 338 311 312 352 290 353 333 315 322 325 331 278 329 336 333 321 361 314 339 317 271 307 340 366 296 308 315 318 312 327 279 324 326 313 317 339 324 275 305 312 299 294 304 353 314 300 334 277 311 347 318 337 294 317 293 318 328 298 295 315 296 320 341 319 306 306 273 324 335 311 331 309 292 303 337 287 300 285 290 324 321 320 333 299 308 300 348 298 288 304 322 300 350 327 304 314 307 289 301 309 285 317 291 316 295 311 315 304 289 302 304 321 300 313 336 316 283 257 319 263 309 312 306 321 299 303 274 302 302 322 304 296 306 325 309 324 303 315 312 302 323 306 311 312 288 319 277 303 296 325 305 329 300 307 301 309 274 311 294 292 311 280 327 299 301 310 299 294 330 279 297 306 292 305 344 313 284 313 286 271 309 298 296 297 258 295 307 281 313 283 325 308 310 307 294 293 320 318 287 298 269 278 305 277 274 309 293 316 291 299 329 304 312 292 289 298 328 273 297 274 332 294 325 292 298 310 306 274 308 315 308 337 296 318 325 314 314 302 284 303 293 272 311 302 269 290 271 288 273 277 275 305 274 278 300 275 283 305 317 287 307 278 295 300 303 290 303 295 278 288 320 273 305 278 313 335 312 319 298 281 280 288 307 311 300 298 303 312 281 321 318 266 276 330 288 267 307 290 295 286 302 277 322 298 302 304 287 296 292 306 282 290 290 304 295 342 290 290 301 316 299 308 335 322 327 309 303 312 296 329 326 306 312 331 286 324 302 294 303 298 309 305 276 290 303 339 321 283 341 304 306 326 304 346 299 316 301 322 329 343 323 334 326 294 315 342 298 346 360 303 313 367 354 298 319 312 327 362 333 359 349 339 352 344 330 342 353 359 346 331 348 316 367 380 336 376 355 377 439 374 414 370 402 396 379 426 397 390 398 398 403 421 434 442 417 406 409 423 415 439 432 438 427 428 453 424 493 462 454 432 471 468 469 471 413 450 452 489 468 466 483 431 473 425 474 441 467 471 449 455 410 443 459 472 472 411 436 432 446 487 453 455 436 427 443 417 419 446 447 440 442 435 436 429 430 431 416 410 392 374 400 393 398 406 389 424 407 402 408 378 410 404 423 374 360 394 424 377 369 371 371 360 384 420 353 333 340 372 345 306 368 344 363 324 403 365 319 335 339 347 360 353 312 340 293 336 306 298 322 302 313 275 318 292 297 296 287 309 332 315 304 276 325 319 287 311 302 302 266 291 301 286 286 292 308 295 294 293 290 286 330 292 283 301 289 300 267 259 291 309 321 262 279 276 290 279 272 292 325 311 257 279 306 288 274 292 264 256 311 300 308 288 263 276 291 306 282 307 311 281 291 274 274 307 281 284 264 265 283 288 268 276 280 287 238 289 285 274 277 268 281 284 272 247 260 292 293 267 294 263 279 259 274 257 243 258 230 282 233 273 283 240 274 280 300 286 261 232 263 264 273 275 256 243 261 272 246 275 270 225 230 260 225 271 265 227 279 255 237 259 232 248 282 274 293 235 255 244 236 273 249 249 260 272 234 243 231 222 265 256 257 228 274 246 273 291 258 255 276 288 220 256 242 243 242 231 276 264 265 243 239 262 267 261 248 229 237 264 268 272 255 295 212 236 257 223 246 249 221 270 250 256 267 261 244 231 272 263 237 238 269 295 237 262 235 255 277 220 263 245 245 276 259 260 277 249 242 262 270 271 239 262 270 226 229 256 227 268 230 258 237 208 248 271 244 237 260 274 235 231 235 228 258 237 234 214 218 256 249 230 257 271 226 294 248 213 241 215 258 260 231 279 228 230 263 226 245 248 246 224 263 229 238 229 258 224 218 243 255 263 213 274 255 261 244 246 246 232 230 258 269 240 233 240 247 241 244 257 260 210 233 236 240 236 236 225 258 220 222 199 244 262 216 232 220 227 222 222 213 264 256 229 241 234 215 225 220 237 241 238 248 234 264 244 256 229 267 235 245 240 232 229 234 227 229 256 270 218 226 226 239 245 228 249 245 234 241 244 214 244 265 241 235 262 249 237 255 243 235 230 225 223 208 270 208 196 206 228 205 210 258 248 199 255 214 216 212 229 223 230 232 208 227 211 226 216 230 244 205 213 222 240 244 212 228 224 243 195 246 237 235 228 238 235 212 233 225 244 247 223 207 226 227 211 198 228 240 210 211 243 212 216 213 235 220 244 226 233 234 207 230 232 212 212 242 232 187 224 216 192 219 212 214 234 246 211 225 225 225 218 229 226 231 221 191 236 242 188 223 225 238 205 228 234 220 228 205 217 236 223 213 213 240 215 237 237 202 232 210 211 208 212 230 221 222 207 225 225 239 231 212 216 224 207 198 234 231 200 238 212 217 228 221 220 193 231 218 213 210 219 219 217 230 202 204 187 200 219 206 213 220 211 216 242 224 222 197 228 196 214 245 213 214 216 218 224 213 218 196 230 232 239 216 233 207 213 206 196 178 224 210 229 218 230 223 209 200 198 222 212 191 242 199 205 245 198 203 209 230 201 242 198 236 224 229 219 216 202 221 187 218 194 205 224 211 221 217 204 190 210 236 219 219 208 222 243 227 213 210 209 213 228 210 228 214 245 219 222 233 236 206 227 229 182 213 211 206 211 207 229 220 234 207 198 220 232 206 193 244 222 207 257 222 192 194 191 229 196 223 216 214 223 222 178 242 203 219 218 218 204 216 223 221 210 218 196 221 196 216 204 185 235 217 190 207 185 213 217 234 207 198 223 201 212 204 193 216 225 198 226 216 200 223 184 189 224 220 218 183 225 186 210 238 205 201 229 224 183 183 230 211 225 231 166 207 194 208 177 201 186 208 188 212 216 227 231 198 205 201 188 187 203 203 196 211 155 203 191 204 206 209 204 180 205 206 201 222 219 212 210 212 198 203 191 176 186 194 207 203 231 190 201 174 200 199 225 211 201 223 190 200 200 193 165 207 181 200 213 227 172 193 193 181 191 230 204 179 190 177 243 187 221 171 221 206 200 207 214 191 189 198 186 198 217 184 197 198 203 190 204 202 216 196 164 209 183 188 226 177 208 223 212 203 201 198 205 219 223 211 203 225 211 205 203 204 199 198 200 192 216 205 185 196 184 205 180 187 183 205 184 189 188 188 190 193 184 217 188 195 210 192 192 174 186 184 190 206 191 193 172 202 205 185 200 173 193 196 164 166 200 217 183 190 220 165 186 199 158 189 197 191 189 183 175 176 172 197 172 168 190 184 207 221 199 194 188 178 189 178 209 202 182 190 207 166 213 195 189 189 183 181 192 184 181 204 189 215 193 176 188 176 142 202 180 204 189 181 212 182 192 209 189 167 170 181 169 181 172 216 186 204 195 183 163 198 176 181 186 192 166 222 181 182 179 170 195 188 164 205 185 179 179 192 167 182 186 187 190 176 207 207 203 169 179 199 180 180 165 166 202 155 190 179 188 195 171 163 166 172 181 194 184 171 172 189 184 176 201 174 177 185 182 186 186 160 160 172 161 179 175 185 163 163 196 175 176 167 167 161 169 179 159 195 163 193 195 190 191 162 158 165 161 173 181 170 180 165 165 147 176 197 176 154 179 182 186 165 185 171 185 173 185 185 161 156 170 195 183 174 164 178 163 172 153 165 175 190 181 168 158 177 186 177 173 196 172 194 171 170 177 183 156 185 188 150 172 170 176 188 184 161 173 147 158 158 167 172 194 166 159 130 169 163 169 194 149 171 164 182 181 184 179 191 171 172 181 180 174 179 153 181 172 185 187 178 176 175 166 170 179 179 156 186 148 194 182 165 150 192 178 183 177 157 163 167 178 169 173 153 173 167 155 164 165 191 184 187 189 194 196 192 172 176 170 203 159 182 180 183 158 175 169 158 158 170 151 173 175 160 166 175 172 155 151 170 137 172 172 210 161 166 164 182 157 153 188 174 168 166 167 180 158 161 172 152 177 169 178 191 145 188 154 174 154 177 146 180 192 157 160 188 172 189 159 147 170 169 169 170 180 158 174 158 158 167 156 168 205 153 162 167 177 158 173 138 162 152 158 166 166 176 153 162 169 173 156 174 183 169 154 173 191 190 171 169 161 153 169 183 175 150 175 184 165 177 174 161 161 150 170 155 176 182 178 125 160 168 161 167 150 150 167 142 181 161 179 166 158 158 174 160 154 172 163 153 177 166 147 181 151 182 171 198 154 160 179 147 155 147 148 144 162 152 168 170 166 163 179 184 166 183 153 172 199 164 145 162 152 180 164 155 163 157 148 176 184 156 154 151 173 193 122 170 166 153 176 156 152 166 175 152 158 136 151 166 151 155 164 133 152 144 114 170 151 178 151 150 172 184 154 142 209 161 162 164 131 178 158 149 163 161 159 167 145 152 167 151 161 174 153 164 177 152 158 150 147 167 172 159 140 158 173 163 142 161 162 166 164 163 153 145 148 140 149 165 155 192 157 179 150 150 137 172 165 156 159 175 153 150 160 145 175 141 157 175 165 150 181 162 143 161 150 166 141 165 172 163 149 168 180 155 151 161 139 168 162 166 140 146 186 166 156 133 132 139 157 152 197 164 141 124 159 143 159 172 175 161 155 156 152 146 149 154 136 178 152 154 159 150 143 159 151 135 203 151 160 148 161 149 151 157 189 180 151 162 167 161 163 181 156 170 121 145 132 175 170 175 162 148 155 138 171 172 167 148 160 183 156 158 179 139 157 145 169 162 145 155 153 140 153 167 112 143 163 167 170 139 151 162 146 156 141 138 141 159 175 165 141 155 156 155 155 147 133 156 131 157 137 152 153 154 154 166 153 173 155 158 140 151 165 148 150 180 160 157 146 142 161 130 163 146 157 167 159 143 144 142 140 153 178 159 170 162 159 160 159 132 130 140 151 139 138 163 127 167 148 136 159 141 145 166 145 147 165 180 150 181 149 126 161 163 155 149 145 148 137 138 150 139 160 158 155 158 159 166 139 125 173 144 149 146 137 166 154 166 191 138 149 144 122 147 150 166 148 148 130 146 133 166 152 151 164 144 147 178 150 160 166 166 148 146 152 159 170 164 154 150 150 132 158 141 139 163 158 173 134 170 139 162 149 125 143 148 149 147 163 147 152 155 143 152 163 139 136 150 148 165 148 119 162 147 154 128 162 151 149 147 144 160 182 155 160 178 155 144 149 145 154 133 140 150 126 165 142 152 160 140 140 137 154 135 122 131 146 154 146 150 154 150 166 127 165 134 144 124 157 154 166 160 165 150 137 145 147 144 148 135 147 157 122 148 144 135 128 134 167 158 156 148 148 168 135 157 155 168 150 138 144 138 144 155 144 135 128 147 171 169 138 129 161 138 141 134 144 157 137 153 142 143 152 162 138 162 120 156 153 147 145 141 145 153 133 141 128 139 156 138 141 147 135 127 142 141 152 168 166 140 163 158 134 142 152 125 147 142 144 149 138 135 155 149 155 165 129 122 158 131 163 163 173 135 145 169 137 167 112 137 143 167 152 146 134 182 166 155 151 145 139 146 154 143 138 166 116 133 139 118 164 151 149 143 150 152 133 152 149 119 152 137 167 139 163 133 143 123 144 137 143 137 153 137 157 137 159 129 139 155 153 150 144 144 122 147 144 127 136 161 136 114 124 142 142 135 136 155 152 150 130 154 126 140 140 159 141 150 136 129 133 145 151 131 155 140 154 134 130 122 147 141 141 117 163 123 153 113 127 140 140 142 112 155 140 147 132 148 123 142 151 130 132 130 131 139 142 128 142 126 131 139 146 152 123 123 145 144 145 127 135 131 152 144 121 131 128 148 132 139 133 125 132 155 152 151 149 138 133 126 148 127 137 161 124 130 133 115 135 135 142 141 135 137 137 141 161 142 133 133 117 148 123 143 137 128 143 122 131 160 125 136 145 149 142 122 143 122 124 133 128 145 127 128 146 149 130 126 122 141 131 116 156 126 134 135 131 137 117 121 137 121 146 133 138 145 125 118 117 129 142 144 139 151 124 128 148 117 144 125 136 137 111 112 130 123 127 103 135 116 124 151 139 146 124 120 149 153 138 125 153 133 146 125 127 146 131 134 128 126 148 132 139 159 122 136 135 115 126 121 122 154 133 133 141 136 128 120 140 138 132 105 133 124 118 132 131 137 127 115 133 132 143 120 139 123 122 136 128 126 127 126 151 142 121 125 136 155 120 148 134 145 134 114 141 135 126 143 132 135 131 133 135 118 128 123 121 141 138 117 145 139 136 132 121 147 108 129 131 137 135 142 139 144 138 122 144 130 147 131 123 139 124 146 130 139 143 153 152 112 131 141 130 134 132 140 141 140 138 142 143 147 139 110 139 122 115 131 152 119 124 113 127 136 124 143 141 136 161 146 127 111 131 129 148 107 116 124 138 153 135 129 157 121 124 135 131 137 135 132 144 137 130 147 130 140 118 126 119 122 158 131 153 130 149 138 125 117 155 114 136 117 130 133 110 119 113 135 135 146 136 127 153 137 123 131 144 143 111 128 125 140 135 128 134 144 132 111 142 136 134 126 152 132 128 116 122 118 135 136 129 129 119 137 139 127 138 126 119 125 132 107 120 109 121 133 129 133 122 136 116 135 116 129 123 109 132 130 115 121 147 140 136 118 133 134 131 135 136 128 114 122 113 133 127 128 118 115 141 122 130 125 119 104 111 107 133 113 144 130 120 113 129 112 117 145 113 110 109 124 129 128 129 127 124 139 140 121 129 116 141 111 125 122 122 123 124 134 136 146 133 148 145 122 112 109 123 104 134 122 124 108 114 129 128 133 113 133 126 120 113 121 119 119 144 135 152 110 123 122 108 120 116 121 135 117 126 123 126 121 125 115 137 117 114 125 152 141 129 131 133 134 128 122 138 124 116 109 106 117 126 120 132 123 121 117 105 113 136 118 124 117 129 122 133 126 112 128 128 128 112 113 124 143 121 135 96 125 119 117 137 107 123 128 113 128 123 141 121 118 130 114 119 109 131 128 118 125 132 107 124 124 130 115 103 117 122 143 110 112 136 116 118 131 112 123 120 120 119 112 117 119 130 127 132 120 122 104 108 98 144 114 98 111 151 105 122 115 100 115 117 112 113 105 101 115 108 127 108 104 128 125 115 125 111 123 130 149 122 123 122 135 121 109 106 141 121 116 103 119 131 115 119 131 118 132 104 113 113 102 110 110 126 98 115 129 104 145 110 109 112 129 125 116 112 102 129 144 106 107 128 137 117 111 130 111 131 128 129 124 113 102 121 122 107 120 101 112 131 119 98 99 117 130 110 118 124 119 119 123 117 105 117 129 122 117 117 118 99 106 127 118 112 113 114 134 116 116 85 110 119 129 118 122 113 112 125 118 119 103 115 119 113 103 123 118 85 101 118 127 104 116 123 116 127 110 121 105 114 104 118 107 117 99 118 103 118 128 118 92 107 119 109 109 112 115 127 124 117 111 90 127 99 110 103 101 117 112 114 126 125 102 120 120 121 109 111 105 111 99 112 126 125 103 121 121 113 105 98 104 123 105 113 118 125 117 126 101 121 108 92 120 111 111 136 114 115 107 104 134 108 111 108 102 127 116 91 101 99 131 102 119 125 95 97 129 116 103 89 112 97 119 103 86 118 100 109 134 125 115 108 104 133 107 109 123 102 103 121 114 112 121 110 83 104 101 117 110 108 101 116 117 127 111 117 117 109 104 83 113 100 110 107 111 92 108 118 92 115 123 112 117 105 115 112 121 108 107 114 94 134 121 106 101 119 116 101 108 117 101 111 122 95 120 103 123 108 95 106 125 107 104 110 110 120 87 97 109 109 109 121 111 103 106 99 115 108 114 111 105 114 123 105 104 119 102 115 104 103 96 111 95 103 90 94 115 104 117 115 123 120 99 103 107 82 96 97 110 121 100 97 119 85 114 125 116 124 118 113 130 100 113 129 100 108 103 109 81 105 110 97 110 121 101 138 106 114 107 102 126 116 109 127 120 127 108 100 111 101 111 95 105 115 100 128 102 100 106 105 107 118 105 117 92 108 112 93 115 98 118 104 93 109 109 109 96 115 129 116 96 118 140 103 124 95 119 96 108 128 112 101 124 99 107 106 92 137 110 104 111 106 117 110 105 117 116 124 103 83 121 130 114 91 121 110 108 94 106 108 108 112 102 118 109 102 109 119 134 111 110 128 117 107 92 107 112 102 112 96 110 98 121 106 114 90 108 120 112 108 99 114 126 107 99 119 102 98 119 102 107 98 95 101 105 104 103 119 107 115 117 99 119 109 114 107 101 102 92 94 88 97 114 106 98 114 115 116 104 118 120 109 107 113 91 116 130 109 100 113 120 87 118 123 121 92 96 109 99 109 122 121 86 96 124 127 100 105 102 105 137 108 105 110 114 107 119 97 119 116 108 115 118 98 115 113 117 96 94 115 92 123 111 108 103 110 117 104 100 93 107 124 95 105 88 106 97 114 109 111 93 100 120 108 92 111 100 91 101 109 108 117 99 112 113 115 95 102 85 122 91 111 104 96 117 106 109 100 101 129 88 111 111 98 109 103 103 99 113 76 99 101 100 86 97 97 130 113 88 91 103 100 110 109 126 88 106 111 92 101 99 114 101 109 100 97 101 122 116 91 109 111 95 110 111 112 92 102 112 108 102 97 115 95 123 102 111 109 102 103 113 109 76 102 107 106 98 103 88 96 107 96 122 117 109 98 97 111 111 110 99 97 118 97 109 120 124 118 101 93 116 101 113 100 101 98 113 104 86 106 128 88 100 101 110 101 121 107 110 96 99 114 105 101 83 91 100 100 122 92 81 104 87 110 108 106 104 103 84 106 90 116 95 103 102 105 88 105 99 81 87 95 114 123 77 92 95 110 86 99 99 93 111 104 86 107 116 109 99 101 115 105 114 109 106 83 95 96 112 101 102 94 103 95 100 87 93 107 93 91 112 97 98 116 108 105 104 97 116 119 93 109 104 105 105 122 86 110 97 100 110 91 111 111 108 90 92 88 94 103 100 101 108 113 114 107 115 113 91 101 102 104 94 113 103 97 102 94 91 108 103 94 97 102 93 105 117 113 123 87 104 100 109 83 108 101 115 96 96 103 113 105 114 96 124 93 108 105 106 88 91 101 125 115 108 102 92 90 91 96 101 97 99 99 95 108 101 108 107 113 91 105 105 100 86 100 83 99 79 97 103 95 91 97 101 84 105 103 97 95 89 100 97 100 93 95 95 92 104 88 110 109 105 97 93 124 85 84 118 101 112 114 101 107 96 114 111 102 76 101 102 109 110 113 117 108 99 116 85 106 85 100 94 104 116 85 101 101 123 89 112 110 91 105 101 106 106 115 106 115 106 84 102 107 86 111 98 107 116 115 92 77 106 111 117 102 88 109 100 102 119 117 105 98 92 104 103 96 95 87 99 100 98 93 108 114 99 105 110 95 99 115 125 93 93 102 93 109 95 83 104 99 100 100 91 113 103 92 94 104 106 101 97 89 80 99 104 88 103 104 103 99 105 106 96 107 110 98 122 91 100 90 108 98 110 103 103 96 88 112 101 113 97 113 109 122 105 120 90 93 110 83 112 112 114 107 77 80 123 99 80 96 98 95 100 112 104 102 95 97 115 112 86 95 113 87 100 98 106 99 73 115 107 104 84 105 101 101 90 96 107 94 92 100 105 87 107 97 105 106 98 104 116 96 81 97 111 93 98 105 103 111 77 86 113 110 93 79 104 89 87 101 104 87 87 95 80 104 100 96 97 103 84 107 100 85 86 86 99 98 94 91 90 107 88 96 123 104</counts>
			</dataPoints>
		</scan>
	</xrdMeasurement>
</xrdMeasurements>