File: data/XRD/GIXRD/W6824-1D.xrdml
<xrdMeasurements xmlns="http://www.xrdml.com/XRDMeasurement/2.1" xmlns:xsi="http://www.w3.org/2001/XMLSchema-instance" xsi:schemaLocation="http://www.xrdml.com/XRDMeasurement/2.1 http://www.xrdml.com/XRDMeasurement/2.1/XRDMeasurement.xsd" status="Completed">
	<comment>
		<entry>Configuration=Factory configuration, Owner=User-1, Creation date=7/8/2013 4:01:53 PM</entry>
		<entry>Goniometer=PW3050/65 (Theta/2Theta); Minimum step size 2Theta:0.0001; Minimum step size Omega:0.0001</entry>
		<entry>Sample stage=MRD Cradle; Minimum step size Phi:0.01; Minimum step size Chi:0.01; Minimum step size X:0.01; Minimum step size Y:0.01; Minimum step size Z:0.001</entry>
		<entry>Diffractometer system=XPERT-PRO</entry>
		<entry>Measurement program=C:\PANalytical\Data Collector\Programs\SimonL\GIXRD_om_fest-2deg_2theta-10deg-80deg_40s.xrdmp, Identifier={5D08F084-E282-4D09-BA8B-67D165D754DE}</entry>
		<entry>Batch program=C:\PANalytical\Data Collector\Programs\SimonL\batch7x_2thom_10-130°_z9.1_x0,10,20,30_y10,20,30_57min.xrdmp, Identifier={E4DA177A-5C7A-4C52-834B-D6C6EE2424A1}</entry>
	</comment>
	<sample type="To be analyzed">
		<id></id>
		<name></name>
		<preparedBy></preparedBy>
	</sample>
	<xrdMeasurement measurementType="Scan" status="Completed" sampleMode="Reflection">
		<comment>
			<entry>PHD Lower Level = 4.83 (keV), PHD Upper Level = 11.27 (keV)</entry>
		</comment>
		<usedWavelength intended="K-Alpha 1">
			<kAlpha1 unit="Angstrom">1.5405980</kAlpha1>
			<kAlpha2 unit="Angstrom">1.5444260</kAlpha2>
			<kBeta unit="Angstrom">1.3922500</kBeta>
			<ratioKAlpha2KAlpha1>0.5000</ratioKAlpha2KAlpha1>
		</usedWavelength>
		<incidentBeamPath>
			<radius unit="mm">320.00</radius>
			<xRayTube id="1010048" name="Empyrean Cu LFF HR (9430 033 7310x) DK442154">
				<tension unit="kV">40.0</tension>
				<current unit="mA">40.0</current>
				<anodeMaterial>Cu</anodeMaterial>
				<focus type="Line">
					<length unit="mm">12.0</length>
					<width unit="mm">0.4</width>
					<takeOffAngle unit="deg">4.2</takeOffAngle>
				</focus>
			</xRayTube>
			<xRayMirror id="27010001" name="Inc. Beam Cu W/Si (parabolic MRD)" hybrid="false">
				<crystal type="Graded" shape="Parabolic">W/Si</crystal>
				<acceptanceAngle unit="deg">0.800</acceptanceAngle>
				<length unit="mm">60.0</length>
			</xRayMirror>
			<sollerSlit id="21010002" name="Soller slits 0.04 rad.">
				<opening unit="rad">0.0400</opening>
			</sollerSlit>
			<mask id="22030008" name="Fixed mask 4 mm">
				<distanceToSample unit="mm">220.00</distanceToSample>
				<width unit="mm">4.00</width>
			</mask>
			<divergenceSlit id="22010007" name="Fixed slit 1/8°" xsi:type="fixedDivergenceSlitType">
				<distanceToSample unit="mm">220.00</distanceToSample>
				<height unit="mm">0.19</height>
			</divergenceSlit>
		</incidentBeamPath>
		<diffractedBeamPath>
			<radius unit="mm">320.00</radius>
			<sollerSlit id="21010002" name="Soller slits 0.04 rad.">
				<opening unit="rad">0.0400</opening>
			</sollerSlit>
			<receivingSlit id="22010001" name="Fixed slit 4°">
				<height unit="mm">5.88</height>
			</receivingSlit>
			<detector id="7010017" name="PIXcel3D 1x1 detector" xsi:type="areaDetectorType">
				<phd unit="%">
					<lowerLevel>30.0</lowerLevel>
					<upperLevel>70.0</upperLevel>
				</phd>
				<mode>Scanning</mode>
				<activeChannelsEquatorial>255</activeChannelsEquatorial>
				<activeChannelsAxial>255</activeChannelsAxial>
				<pitchEquatorial unit="mm">0.05500</pitchEquatorial>
				<pitchAxial unit="mm">0.05500</pitchAxial>
				<readOutPeriod unit="seconds">0.155</readOutPeriod>
			</detector>
		</diffractedBeamPath>
		<scan appendNumber="0" mode="Continuous" scanAxis="2Theta" status="Completed">
			<header>
				<startTimeStamp>2024-11-01T21:29:19+01:00</startTimeStamp>
				<endTimeStamp>2024-11-01T22:07:27+01:00</endTimeStamp>
				<author>
					<name>PRO-MRD</name>
				</author>
				<source>
					<applicationSoftware version="6.1b">Data Collector</applicationSoftware>
					<instrumentControlSoftware version="7.0E 20130304">XPERT-PRO</instrumentControlSoftware>
					<instrumentID>0000000011142674</instrumentID>
				</source>
			</header>
			<dataPoints>
				<positions axis="2Theta" unit="deg">
					<startPosition>10.00246193</startPosition>
					<endPosition>79.99507515</endPosition>
				</positions>
				<positions axis="Omega" unit="deg">
					<commonPosition>2.0000</commonPosition>
				</positions>
				<positions axis="Phi" unit="deg">
					<commonPosition>0.00</commonPosition>
				</positions>
				<positions axis="Chi" unit="deg">
					<commonPosition>0.00</commonPosition>
				</positions>
				<positions axis="X" unit="mm">
					<commonPosition>40.00</commonPosition>
				</positions>
				<positions axis="Y" unit="mm">
					<commonPosition>0.00</commonPosition>
				</positions>
				<positions axis="Z" unit="mm">
					<commonPosition>9.100</commonPosition>
				</positions>
				<commonCountingTime unit="seconds">37.995</commonCountingTime>
				<counts 550 524 533 536 482 569 515 523 502 506 536 526 487 509 527 526 508 533 517 546 528 495 541 521 497 524 525 523 537 503 503 496 511 484 486 492 487 493 514 506 501 511 536 497 512 521 528 519 513 527 489 530 515 536 532 497 486 531 493 531 498 513 488 521 524 487 540 518 506 547 508 496 507 485 467 533 516 472 523 572 518 538 529 545 545 479 498 547 532 527 515 470 534 502 519 523 534 525 497 516 521 536 471 522 525 570 515 521 474 478 475 491 507 513 525 494 525 513 516 496 519 515 512 497 492 550 508 477 491 494 525 491 501 486 504 530 539 527 491 538 519 517 500 504 486 503 486 519 533 525 563 539 522 519 519 517 504 535 547 505 532 498 507 490 474 493 475 490 530 480 520 488 498 466 519 503 524 526 535 497 475 521 472 508 520 529 525 527 546 553 472 496 479 522 508 488 490 511 488 513 499 510 480 512 506 500 530 554 479 501 539 514 514 500 503 483 519 509 490 459 499 514 500 539 518 515 551 464 471 523 498 516 522 500 550 486 540 508 523 517 527 517 481 541 495 512 479 526 496 539 495 505 521 510 494 506 491 539 513 519 493 471 519 516 454 506 489 483 527 507 510 494 484 473 504 498 506 503 526 476 468 505 507 507 516 481 508 500 539 504 516 508 486 481 483 540 522 475 494 497 477 536 509 467 529 525 517 490 508 484 478 512 531 528 492 506 482 521 538 533 520 493 482 499 502 496 502 490 518 475 501 518 493 469 510 508 496 535 480 497 485 557 513 560 535 490 514 488 483 481 504 477 468 464 490 483 472 492 494 515 446 497 499 469 505 548 459 494 519 508 480 489 468 463 534 508 512 474 473 470 549 527 490 495 527 532 497 496 497 482 514 513 509 499 481 537 474 462 532 533 483 467 522 489 484 507 500 551 540 496 510 492 494 466 503 483 535 516 518 495 497 538 481 459 486 476 512 505 536 574 541 518 493 473 508 491 500 484 525 526 513 513 527 489 481 523 554 486 497 499 477 519 500 458 535 473 526 514 501 491 484 486 507 434 477 492 489 507 480 461 511 501 530 452 508 501 491 514 499 484 517 468 501 486 459 470 504 488 497 510 501 499 524 512 486 518 497 481 517 510 483 478 500 487 504 499 484 469 489 483 506 490 517 506 477 464 503 498 473 520 523 530 484 497 486 520 526 484 464 532 466 503 499 491 482 481 516 512 518 499 462 532 472 484 523 485 497 501 510 500 453 480 491 522 475 476 515 511 513 469 467 484 514 480 480 490 508 521 524 514 510 490 529 484 483 460 508 507 506 468 512 531 504 501 526 479 542 499 467 504 468 522 438 514 515 495 547 510 461 483 501 484 486 461 503 528 530 529 513 515 465 511 495 473 486 525 498 529 491 490 549 506 512 529 517 525 497 521 479 481 521 499 500 501 543 511 507 501 461 519 493 503 496 521 543 499 473 499 519 560 501 488 485 520 507 504 486 482 560 501 493 491 540 521 487 543 502 507 515 559 543 450 492 513 487 511 534 527 506 499 501 485 513 538 533 501 504 504 527 492 501 475 489 511 496 510 507 503 459 505 472 535 499 525 495 512 498 463 539 545 533 541 496 534 468 444 513 513 494 469 487 508 503 510 474 522 515 509 498 517 493 500 538 483 538 501 515 493 489 541 533 486 506 483 521 499 509 537 461 560 509 516 513 497 503 513 504 504 534 503 482 508 527 559 554 519 542 495 532 485 492 489 484 506 473 514 527 522 514 497 542 517 495 479 534 506 487 514 495 484 513 539 543 544 491 485 542 520 518 465 492 474 507 503 519 470 504 500 475 518 472 507 507 536 495 515 524 497 507 509 460 485 547 512 510 498 509 537 542 517 544 501 501 491 511 529 502 506 536 526 523 452 527 524 501 516 541 525 549 473 500 514 525 503 518 455 578 493 539 500 534 525 485 540 528 560 469 484 515 500 490 483 551 500 523 546 518 531 472 540 498 496 472 504 526 482 531 539 475 497 497 530 495 503 508 524 516 514 497 529 505 536 550 545 506 498 532 530 476 485 514 499 516 515 533 524 531 535 485 520 508 521 537 512 472 486 548 530 483 497 541 555 494 460 523 512 542 522 516 511 497 505 529 491 537 472 513 524 501 506 504 511 524 525 497 508 515 504 502 479 454 494 518 486 508 491 492 518 505 492 456 518 507 464 528 492 511 533 522 508 529 554 516 508 495 542 491 481 507 525 555 492 518 490 546 506 541 518 491 471 480 497 495 474 491 527 491 512 466 464 516 481 448 508 542 529 562 455 482 527 509 457 492 525 492 512 517 514 516 506 500 480 485 484 506 525 518 527 506 520 489 509 486 510 500 472 488 509 490 497 465 506 474 545 513 495 495 483 485 505 491 481 506 509 525 486 485 460 497 515 527 499 495 493 515 498 539 474 489 512 513 529 485 474 474 499 496 496 514 505 492 506 485 551 491 471 505 461 501 480 490 552 479 512 525 536 469 488 476 501 439 467 527 509 463 497 485 510 515 502 478 520 509 509 522 523 493 509 482 493 507 537 513 493 500 495 494 512 531 475 453 526 531 522 536 485 494 478 469 474 494 530 474 509 484 475 498 496 497 501 509 478 476 472 477 517 512 497 464 465 546 510 498 491 528 533 506 470 491 510 466 512 501 449 502 460 530 485 484 483 496 464 480 488 500 471 489 482 497 497 490 505 505 528 517 511 493 513 493 520 515 521 502 473 504 460 516 472 508 459 491 515 526 529 449 495 507 512 462 472 475 488 479 460 477 505 498 482 514 479 529 502 447 493 486 499 508 492 474 506 496 532 482 516 482 496 498 498 456 475 504 486 499 463 489 523 465 461 491 508 499 487 497 497 492 497 493 453 448 491 486 472 509 508 507 460 496 474 461 491 485 508 493 470 476 493 460 452 508 470 489 465 483 474 493 479 519 497 491 496 462 470 481 494 497 504 489 431 441 534 522 496 467 472 501 509 473 465 458 458 460 451 481 487 450 497 486 479 441 487 514 484 455 466 461 515 463 482 475 436 477 473 465 451 455 502 500 512 487 489 483 495 481 493 486 454 473 487 495 458 445 463 458 440 477 470 480 488 481 480 495 480 508 481 470 455 501 454 465 454 461 459 449 457 464 475 471 460 439 484 476 428 456 456 473 479 507 443 448 468 497 452 452 458 454 439 476 463 432 483 467 434 475 465 485 458 504 430 485 472 429 439 465 454 466 468 469 466 487 466 478 471 443 450 447 489 415 484 431 484 445 457 415 414 450 466 478 448 469 471 447 460 463 492 439 457 444 450 482 442 422 448 502 445 462 441 442 451 478 457 493 461 463 443 396 466 454 442 481 432 481 433 452 429 447 412 480 413 428 469 458 441 472 459 461 446 445 437 477 458 473 437 450 470 431 445 452 466 440 469 443 462 443 410 439 477 497 442 415 453 410 426 460 427 433 441 424 427 450 425 423 428 437 427 490 502 465 476 416 440 418 400 466 482 434 424 458 457 441 442 427 468 454 452 460 451 452 452 451 458 441 448 447 455 403 403 398 430 455 464 423 432 415 428 421 452 430 445 431 443 424 474 450 448 489 490 432 433 425 431 432 409 445 405 397 453 434 419 420 417 422 382 437 442 400 432 466 425 473 427 438 422 472 432 482 414 433 437 433 431 420 422 462 439 403 457 430 465 429 449 452 457 406 378 410 413 398 471 441 417 461 409 440 462 432 404 395 404 464 447 395 452 422 446 391 449 415 464 448 433 437 403 424 411 384 457 424 413 419 441 427 427 444 429 401 434 432 410 432 469 445 422 365 427 416 393 390 368 416 390 442 408 396 463 400 419 435 391 424 386 436 440 375 459 421 401 393 391 445 410 378 416 396 448 406 389 406 428 395 417 406 427 406 399 455 387 398 380 418 406 381 405 403 409 447 413 386 424 455 431 398 430 419 430 384 439 449 403 402 455 410 409 426 390 419 404 378 429 399 428 403 392 434 419 432 443 401 413 417 392 411 387 374 434 372 415 413 386 353 434 437 391 393 422 430 403 382 428 395 405 421 414 400 405 379 386 391 376 377 430 371 353 389 416 410 439 389 388 378 385 425 398 429 397 379 397 392 368 370 382 394 415 425 365 414 413 416 400 371 393 375 397 395 405 389 411 361 376 412 428 365 410 382 414 412 393 410 420 416 409 450 383 371 370 379 378 394 402 397 418 382 365 424 403 436 376 445 408 414 383 363 373 388 390 386 377 388 382 366 398 404 371 387 414 397 399 383 397 382 383 389 381 400 397 401 381 422 423 362 410 401 382 395 339 370 420 381 368 365 349 417 370 374 386 426 376 362 423 387 361 352 376 371 367 376 409 401 383 360 364 379 404 380 398 377 401 395 378 379 420 378 375 364 386 424 364 363 397 355 391 427 407 403 366 377 376 377 400 377 375 369 368 376 398 363 394 349 403 351 391 357 385 408 386 376 386 365 402 395 370 390 346 396 386 385 395 374 398 382 364 387 371 368 379 403 368 437 385 401 365 393 378 350 389 389 376 384 373 355 369 340 375 361 351 390 393 388 393 362 392 427 365 385 393 354 385 397 392 381 337 346 334 380 382 407 373 385 347 359 362 370 339 360 353 364 358 400 361 361 401 374 360 366 348 374 374 383 331 366 370 343 364 380 379 328 397 372 406 383 345 359 335 356 342 378 361 363 391 382 353 353 363 339 352 377 356 381 382 391 355 347 361 388 351 369 365 414 351 341 374 360 349 354 397 349 359 357 371 351 340 376 356 395 355 387 358 366 348 396 349 366 380 390 393 405 389 408 379 396 398 393 368 394 383 391 361 388 380 358 381 395 342 365 385 379 376 377 343 369 376 395 355 396 398 364 387 373 391 398 371 349 360 361 384 384 388 368 353 372 375 349 378 338 350 373 379 360 354 371 374 352 343 360 357 368 358 319 341 343 391 344 343 357 344 363 333 343 349 351 345 355 339 332 347 323 386 343 317 350 320 340 343 343 322 328 342 352 369 339 339 374 363 359 345 334 347 377 342 338 316 346 357 327 323 343 354 329 337 355 348 312 363 329 371 346 293 318 345 322 325 348 358 336 327 362 372 322 354 337 335 360 330 350 340 333 324 378 338 342 353 315 328 338 371 305 348 388 299 311 339 350 348 324 343 331 337 363 344 371 354 312 379 339 361 289 362 304 318 345 352 322 351 341 338 356 376 359 322 323 303 333 363 315 367 347 354 350 330 325 342 325 321 333 317 328 350 335 324 329 325 352 339 333 330 337 319 312 348 313 326 322 327 317 319 305 348 344 317 335 311 314 322 302 329 355 338 339 329 319 354 325 333 325 311 333 309 371 302 312 307 323 342 351 321 327 313 313 318 360 320 328 324 323 338 302 308 306 318 339 316 328 298 276 328 311 347 320 297 302 338 299 352 305 338 340 311 319 322 352 304 329 322 318 308 311 356 324 307 335 333 359 323 343 332 321 289 317 333 314 299 316 331 317 338 330 324 298 306 315 269 330 339 348 315 323 328 316 317 316 339 351 348 316 316 327 330 289 285 313 315 314 353 306 307 323 327 361 335 319 338 315 323 307 339 324 315 364 324 302 318 343 324 287 298 266 305 282 285 301 301 314 297 321 283 288 303 298 293 348 311 303 339 324 286 320 297 347 290 331 345 319 345 299 301 326 306 326 310 328 285 340 347 284 290 315 299 339 317 300 305 308 304 290 306 292 324 319 326 264 292 311 310 279 314 307 301 299 280 324 299 320 336 315 324 299 287 320 297 304 327 293 313 326 321 313 321 325 346 292 306 292 308 299 309 323 342 326 300 297 290 317 297 311 308 314 319 304 300 321 324 352 310 264 306 313 327 320 290 295 289 318 307 300 296 319 332 284 301 301 327 318 269 310 299 300 303 293 305 267 307 323 306 280 286 313 296 291 312 288 292 283 290 309 311 301 302 275 293 290 283 328 354 259 301 300 280 299 323 302 302 291 320 288 299 285 281 304 296 286 306 275 320 302 301 335 311 298 297 294 303 324 301 288 321 294 348 316 312 303 341 332 323 286 320 308 300 297 294 316 327 308 298 286 301 280 333 316 317 276 351 339 313 351 333 352 318 322 360 325 360 330 340 344 339 343 351 318 317 311 306 342 323 306 320 334 308 339 317 329 319 344 326 305 316 302 268 332 350 303 317 280 277 297 297 297 287 284 316 310 258 277 309 296 297 332 295 299 305 308 275 264 307 284 307 293 281 301 277 257 303 270 319 279 274 299 316 288 241 313 300 288 248 301 298 265 266 304 312 324 272 290 281 285 261 298 269 308 249 292 265 294 299 288 267 280 283 277 283 301 296 305 281 311 248 291 263 255 277 246 269 299 290 293 269 273 245 256 258 287 269 275 300 297 279 312 295 247 263 285 298 246 291 289 264 272 274 274 299 283 272 273 290 278 274 291 299 272 299 234 276 260 305 281 270 290 277 295 290 296 301 294 288 286 276 311 294 286 280 286 258 265 290 256 260 262 271 264 243 278 271 268 266 244 274 274 270 246 274 258 274 245 302 296 288 255 286 301 266 279 249 301 261 278 295 263 269 246 269 264 242 263 255 287 289 282 288 277 256 284 242 281 266 277 274 283 306 270 294 284 301 230 239 281 282 270 257 276 263 266 258 265 263 282 261 282 276 257 240 272 279 250 249 270 263 271 272 275 276 287 275 260 276 261 275 290 273 269 294 280 282 241 280 241 236 268 244 274 285 260 246 282 281 300 279 268 284 240 244 283 256 279 247 279 285 281 256 277 269 270 264 277 273 263 285 267 261 278 284 291 277 249 280 236 281 260 292 286 291 272 275 302 262 262 276 242 281 265 259 243 281 263 276 277 309 274 261 291 264 306 263 269 269 298 266 275 241 264 276 269 279 249 279 263 272 267 240 258 261 279 297 267 264 281 244 263 271 292 281 296 283 270 300 283 267 269 293 277 243 255 271 276 276 275 279 295 300 278 260 281 280 273 268 272 269 265 279 293 297 301 284 287 282 286 300 268 280 285 262 300 302 312 275 301 305 282 265 313 280 285 279 285 316 313 288 308 309 297 314 326 311 275 318 269 322 313 331 319 319 299 312 322 308 339 322 338 336 327 320 364 333 351 332 371 334 370 351 356 344 339 385 338 370 367 372 352 337 387 363 359 353 356 370 380 408 365 363 377 365 397 376 412 374 376 358 363 391 389 370 414 351 397 412 384 386 384 362 373 340 408 400 373 395 389 394 396 378 381 374 397 376 340 394 418 353 388 359 383 361 374 363 379 347 362 338 341 374 378 365 391 361 376 390 332 359 339 330 358 368 370 359 344 331 336 332 328 319 363 346 353 337 331 312 306 306 356 292 331 310 315 290 312 290 301 316 341 311 287 288 299 279 294 288 283 272 265 273 276 272 301 275 258 301 294 273 242 276 270 278 280 318 224 268 239 278 243 267 247 270 246 256 243 256 248 274 273 244 292 247 273 272 258 247 242 278 246 260 288 281 245 259 232 236 263 277 244 270 255 283 290 272 287 271 313 286 271 288 272 291 281 279 264 275 259 268 308 270 277 242 287 236 278 240 283 245 274 241 278 246 256 269 274 263 248 268 237 266 265 265 260 261 269 248 273 245 280 231 246 262 265 243 242 258 239 215 226 242 290 227 229 263 234 239 260 268 226 256 223 239 240 210 262 224 242 272 275 234 226 211 243 247 278 213 234 240 256 213 215 236 238 244 261 242 237 232 240 224 229 229 242 221 263 230 221 228 241 222 205 230 215 240 216 225 225 200 226 261 265 217 242 240 216 247 220 236 209 240 229 218 228 236 261 219 220 209 240 234 229 246 239 204 217 223 207 219 219 223 227 238 217 213 239 205 226 214 221 243 257 214 230 244 230 234 226 205 237 219 241 215 243 221 201 220 211 221 240 239 218 229 225 235 229 240 214 237 219 220 246 212 219 249 221 221 216 208 246 230 228 217 223 227 223 226 215 204 234 258 244 230 229 226 222 208 207 228 255 225 221 241 238 227 239 223 209 209 224 204 201 232 222 236 217 202 231 241 212 220 237 217 236 212 190 243 237 230 209 214 192 237 229 234 219 211 224 214 222 227 210 224 222 203 212 212 200 219 219 247 218 221 231 201 255 197 211 226 203 212 223 207 212 223 239 209 211 229 210 241 223 197 215 231 241 200 235 222 231 210 203 219 223 186 215 213 236 228 226 212 197 240 209 228 227 210 223 247 206 219 203 245 244 190 237 192 232 205 182 235 210 241 236 219 233 210 236 243 201 203 194 227 238 206 215 218 211 217 200 205 228 227 224 216 216 226 220 214 220 214 232 205 236 205 175 207 200 217 229 223 201 214 220 235 211 228 202 217 213 199 208 220 228 203 198 223 214 218 214 212 218 194 221 218 188 202 217 202 185 208 190 200 222 219 211 201 189 205 208 198 195 212 201 187 196 220 222 205 230 210 206 183 200 222 206 210 240 199 195 227 199 212 176 192 202 212 194 174 202 229 208 180 219 213 220 201 209 203 197 200 205 206 204 205 238 175 213 213 231 218 212 212 192 191 212 228 181 218 218 216 221 189 210 220 217 226 204 215 183 233 204 217 206 204 208 220 232 185 204 181 208 210 225 192 183 212 195 206 217 208 194 203 211 224 200 210 196 198 192 203 196 229 229 202 201 175 197 196 216 205 221 217 188 196 176 208 223 216 204 191 192 172 201 202 208 193 198 196 199 194 186 224 203 207 201 191 195 216 229 186 204 189 210 201 191 207 177 220 200 200 194 190 207 220 194 203 200 214 216 192 193 187 204 215 199 222 198 218 201 209 196 194 171 182 217 213 211 205 191 220 188 196 198 202 211 209 199 202 171 214 191 202 178 219 204 189 199 206 219 207 197 192 202 187 218 175 195 206 218 190 194 202 198 195 192 196 184 194 161 207 194 200 220 207 186 196 181 196 195 202 172 215 185 169 174 214 200 170 184 211 194 180 165 176 212 232 196 197 196 169 176 186 197 187 187 193 183 177 218 201 194 185 176 189 193 190 193 179 170 169 189 188 178 195 197 177 196 193 190 190 172 181 167 173 198 169 208 192 176 204 182 200 185 203 159 184 201 169 198 210 189 193 177 181 192 194 192 205 196 186 199 185 184 190 195 182 202 195 171 166 213 172 200 195 209 195 177 177 180 177 186 171 184 197 172 194 165 174 187 189 185 182 190 196 182 190 200 168 188 176 201 184 174 157 169 192 205 198 192 183 183 191 204 189 199 207 202 208 182 206 190 196 172 179 202 206 181 186 178 164 183 175 185 173 193 183 189 205 187 190 174 186 184 192 182 193 192 184 169 197 178 175 193 164 175 170 172 176 186 204 180 176 188 198 179 176 195 169 175 207 161 196 179 173 181 170 175 180 165 173 159 184 163 166 171 170 183 180 174 162 164 175 203 182 189 174 178 207 175 173 179 171 179 172 187 167 193 159 159 190 211 218 171 172 185 202 189 155 184 168 179 174 190 170 177 187 190 166 165 197 185 173 175 180 172 184 188 173 178 192 173 169 159 183 183 157 169 155 195 186 180 171 166 169 163 205 168 161 143 179 166 160 172 176 168 177 192 187 139 184 195 158 177 166 183 183 180 184 196 156 172 183 162 166 177 165 196 181 198 186 192 162 170 166 169 186 183 151 159 176 165 155 166 161 140 170 182 165 165 179 177 161 172 149 167 181 180 169 154 167 168 175 166 186 162 183 166 153 184 171 177 154 190 178 178 170 157 187 182 175 161 195 182 194 165 145 161 170 138 141 210 167 191 169 169 139 175 173 182 184 152 184 180 160 147 168 177 168 176 149 172 165 183 151 174 186 144 181 175 170 176 168 183 183 151 175 194 210 181 171 154 175 158 137 179 173 171 160 157 154 152 174 167 176 165 159 158 173 169 147 161 146 183 172 161 164 173 174 148 170 159 169 192 144 187 174 150 183 149 178 149 183 193 169 155 153 163 172 150 179 173 187 157 172 195 151 160 169 151 167 177 168 150 165 159 167 174 175 161 167 179 158 171 165 175 169 142 160 208 168 163 157 143 157 161 194 153 155 162 165 158 153 182 155 176 170 153 173 165 138 161 198 158 170 163 141 158 164 177 159 162 180 170 174 179 170 184 165 148 153 181 161 144 149 186 153 172 151 144 167 152 158 138 146 149 155 168 161 161 141 177 162 144 186 160 158 132 179 172 185 144 158 157 176 155 149 141 154 160 154 156 162 167 167 154 148 173 177 158 165 171 158 156 175 174 141 147 146 154 147 145 150 145 153 149 151 183 174 165 169 144 152 121 153 162 160 164 156 154 172 152 176 164 154 154 161 151 147 155 149 168 183 150 138 167 143 176 156 171 150 152 163 150 178 168 143 147 163 154 130 137 164 150 181 162 145 160 156 149 143 151 137 158 170 161 171 146 142 134 142 165 166 156 147 149 154 162 142 161 134 166 150 160 154 162 153 162 156 140 136 139 160 139 167 148 129 140 148 157 142 156 141 157 143 163 156 153 156 150 154 162 144 136 137 143 145 147 166 143 133 155 158 157 127 152 142 150 126 155 152 167 136 169 151 173 148 145 137 169 142 163 135 164 151 150 160 156 144 155 162 169 126 138 152 150 142 141 152 174 147 132 138 140 143 143 165 143 123 147 138 174 142 146 159 158 110 153 151 150 153 129 141 160 156 136 159 161 145 151 134 158 138 145 161 159 138 142 149 169 167 144 156 167 133 118 138 166 142 146 141 153 137 122 154 135 159 167 160 141 129 133 142 150 145 135 169 154 144 163 151 156 136 152 158 162 159 127 148 120 150 144 135 144 138 152 153 159 133 129 143 160 137 165 152 124 142 132 153 159 147 143 137 146 146 158 144 151 128 132 151 143 143 126 107 126 159 145 137 159 150 144 162 170 130 141 120 158 132 152 138 131 136 140 141 158 158 152 176 150 131 133 150 142 162 149 148 122 146 139 141 142 147 133 155 126 133 117 140 154 165 132 135 164 142 170 132 141 138 150 144 136 165 137 148 118 126 146 147 120 152 131 171 156 136 161 146 144 129 132 153 145 150 159 137 158 144 152 139 149 151 158 121 172 154 136 153 136 159 145 150 146 137 141 168 129 152 171 139 142 150 133 153 174 144 137 152 141 145 155 146 148 150 160 150 144 147 143 132 124 170 143 143 134 143 159 148 139 155 148 143 128 150 143 141 160 170 160 150 175 135 135 137 153 133 149 163 176 154 159 160 148 150 139 165 156 164 145 134 141 134 158 157 150 152 168 147 137 149 127 149 148 131 160 142 166 145 160 141 146 157 147 163 167 150 148 146 149 154 142 144 143 131 132 156 152 144 150 172 162 179 153 131 146 147 170 142 143 134 144 127 128 136 138 147 159 149 125 122 155 142 172 160 136 132 165 136 163 165 118 132 132 134 145 142 128 138 126 166 139 133 153 146 130 133 154 133 137 128 129 134 161 108 138 154 146 130 144 152 135 151 152 131 149 127 139 133 151 168 157 148 145 136 143 139 147 131 139 134 145 139 142 144 143 145 145 143 134 142 155 127 153 129 137 140 148 135 154 147 132 144 140 149 151 161 134 127 165 142 144 145 137 128 167 128 130 140 158 145 159 165 167 155 148 147 121 134 143 136 135 156 139 163 139 141 153 141 151 139 147 141 149 122 138 150 148 152 122 125 163 131 115 141 143 144 147 162 152 146 129 157 126 149 149 166 153 137 148 150 121 147 136 146 133 161 151 161 112 136 139 150 150 145 142 135 147 153 138 130 134 149 159 140 138 132 141 143 127 138 147 138 143 142 141 121 137 134 157 148 125 149 142 133 149 138 135 164 129 165 130 139 150 152 148 130 121 126 111 138 141 123 139 139 126 140 163 137 120 123 130 132 148 140 103 142 138 132 146 145 155 144 141 137 123 136 166 139 122 156 159 114 143 149 161 163 153 157 146 128 146 130 123 126 131 133 132 147 128 137 149 151 152 146 147 139 138 138 143 156 151 137 157 126 125 137 173 144 141 138 128 137 140 135 122 154 162 141 173 156 142 151 139 142 129 115 153 153 136 134 118 128 132 134 147 135 151 156 146 155 162 127 129 142 134 141 155 129 132 137 121 135 147 148 128 115 148 119 123 143 133 165 119 149 129 139 144 131 156 128 143 151 124 121 141 125 139 117 121 136 135 126 166 128 131 130 149 118 130 128 151 140 128 106 111 142 120 133 130 139 132 121 132 118 146 161 128 127 131 136 142 104 123 137 137 120 146 125 115 142 126 134 121 135 136 141 154 151 119 142 138 125 131 150 121 124 141 145 138 134 150 136 121 113 131 159 127 139 126 119 129 137 118 105 136 134 153 126 129 127 129 119 134 138 146 118 131 116 138 114 112 144 142 141 133 146 129 128 134 119 152 125 133 148 133 132 149 141 115 131 126 144 125 136 118 125 128 110 123 130 137 117 122 120 128 127 147 136 114 136 123 128 122 122 109 124 136 153 153 125 122 119 153 120 135 137 122 145 155 124 137 135 138 143 138 150 137 137 143 125 145 153 131 127 140 142 132 141 163 136 148 157 154 126 153 149 142 159 151 152 167 154 135 122 144 145 132 141 133 105 140 135 150 136 127 154 137 123 131 138 134 124 134 107 120 126 144 138 135 130 128 124 140 119 138 144 119 127 140 131 134 134 127 111 141 141 135 132 112 119 125 116 131 129 125 123 141 152 133 126 117 111 89 124 137 138 111 116 143 124 143 138 120 118 98 129 140 117 124 129 120 121 128 109 127 114 140 108 126 135 117 125 116 114 120 118 118 123 133 121 118 118 111 117 140 108 132 119 109 125 111 134 124 119 98 138 113 121 116 130 150 142 113 124 111 110 125 104 118 138 112 130 145 135 120 104 160 117 121 107 99 140 135 120 111 130 137 131 137 100 118 119 116 123 119 116 108 117 118 107 129 120 127 108 114 119 140 100 114 121 150 136 128 148 133 121 120 123 110 141 127 113 132 128 128 126 100 135 131 129 123 114 137 120 123 137 123 120 130 138 127 112 116 128 107 126 126 115 134 127 128 121 106 137 145 115 114 124 129 126 126 112 122 97 117 120 125 133 102 110 127 97 126 122 130 125 142 143 136 107 125 142 117 116 120 122 108 126 108 124 119 118 121 122 125 108 106 133 121 119 109 127 109 99 95 116 107 98 115 128 107 137 132 102 118 136 151 121 117 149 114 103 103 115 100 134 114 127 124 123 126 121 112 133 114 118 132 125 121 132 122 123 132 126 132 120 110 97 122 110 117 132 117 113 120 132 113 134 125 122 123 124 102 116 132 118 107 131 113 138 112 109 116 117 118 112 120 128 138 88 125 118 121 129 109 110 135 112 144 147 125 140 125 118 112 91 121 125 120 128 117 131 130 113 120 118 122 108 112 110 122 147 126 123 99 135 138 111 103 91 118 131 135 135 143 108 116 132 104 132 115 111 120 117 136 115 107 105 145 98 128 118 109 111 116 128 113 103 123 124 99 126 107 132 101 131 107 95 113 113 129 129 118 117 98 110 114 115 116 116 116 122 114 133 116 122 113 112 112 123 110 125 113 102 111 131 141 111 131 141 136 115 120 113 116 109 126 132 119 118 121 116 129 114 112 120 115 120 124 129 133 114 107 103 106 131 115 112 107 127 110 115 122 129 105 95 106 114 102 113 109 109 118 128 102 111 113 120 124 121 112 103 106 111 121 124 143 115 115 112 119 115 138 125 122 115 118 120 111 114 110 95 115 120 106 126 107 111 102 122 115 127 111 122 108 116 125 127 108 124 106 95 109 124 108 112 123 93 124 123 132 134 130 107 110 127 125 112 134 129 112 125 108 108 111 104 127 99 105 108 98 135 102 111 112 107 120 108 103 103 123 104 101 117 115 99 112 110 114 117 127 112 114 116 114 124 95 124 106 124 117 114 110 106 112 121 115 95 133 103 102 119 110 113 100 99 94 112 102 111 100 109 114 137 114 105 129 94 96 133 104 122 103 119 131 107 106 124 106 123 102 113 132 115 108 109 130 108 92 111 128 101 115 103 124 111 96 110 109 114 98 114 100 124 123 113 120 105 114 119 118 106 145 100 106 117 123 127 104 99 107 100 121 100 93 108 108 85 112 119 112 101 124 119 105 99 121 102 93 118 97 105 114 108 102 129 110 112 125 91 103 101 87 95 111 103 94 98 111 104 100 99 105 118 110 101 122 112 114 121 111 99 109 104 106 118 114 115 105 112 122 115 118 115 117 105 100 109 85 116 111 113 110 100 111 108 105 117 104 114 119 118 97 113 119 103 123 100 107 124 105 107 122 83 105 110 105 122 97 105 130 101 114 103 127 114 110 100 128 115 125 112 107 115 105 104 110 101 103 89 113 96 126 101 123 115 108 130 93 93 118 105 114 108 121 111 108 126 129 108 116 110 111 97 109 109 120 100 107 101 100 132 104 106 126 97 98 111 108 106 102 111 116 109 110 99 94 98 114 115 117 102 98 99 113 109 109 118 122 108 130 113 99 109 96 110 122 109 105 98 108 102 107 99 110 117 117 108 115 110 118 128 112 106 111 115 116 114 107 99 100 103 111 111 120 92 112 111 103 105 104 102 107 100 123 103 107 96 107 118 107 125 117 112 110 122 99 121 113 121 103 104 114 112 115 108 101 108 108 107 110 105 89 110 111 107 100 109 95 106 105 114 121 103 125 97 114 102 121 109 126 130 105 111 114 109 104 101 89 110 108 122 112 108 106 96 107 103 104 126 111 126 116 100 100 95 99 100 120 116 104 112 118 128 112 103 121 116 108 114 121 107 93 97 106 112 116 106 94 130 105 106 95 100 95 106 124 115 102 116 126 114 130 109 107 105 102 103 99 103 124 111 102 112 102 87 119 99 88 101 112 107 118 113 128 98 114 116 113 120 118 98 107 113 118 127 93 113 94 114 99 101 120 118 105 106 107 116 99 99 115 121 98 101 99 119 93 105 106 115 111 90 115 132 98 121 87 111 115 108 109 124 94 103 122 110 125 105 118 123 113 99 94 108 118 109 102 113 103 110 87 105 92 115 97 113 124 116 102 99 99 100 103 112 96 91 107 101 111 99 102 107 120 106 105 97 95 121 95 104 101 103 92 105 131 118 110 89 109 98 111 120 101 121 104 95 103 112 101 111 95 125 113 83 85 110 87 97 102 124 93 99 113 99 102 128 88 101 96 115 117 97 123 95 94 117 87 91 120 129 101 100 106 109 128 114 111 113 104 115 96 118 103 112 102 112 112 101 113 120 101 114 125 103 110 86 102 109 96 110 109 104 123 117 99 103 107 106 106 109 107 95 121 99 118 112 96 105 107 115 114 103 113 115 100 90 100 120 129 128 94 104 99 109 114 88 115 101 95 105 102 114 130 113 105 100 103 117 101 94 97 98 125 104 116 96 111 116 98 109 103 112 112 109 127 118 117 114 107 111 129 107 118 100 104 116 111 121 110 96 113 96 126 101 113 103 94 122 113 117 100 105 101 112 107 99 95 103 110 105 96 91 107 107 96 112 110 99 121 114 85 113 87 103 113 104 113 108 96 117 105 113 112 103 109 90 106 102 96 121 110 109 100 108 119 120 117 111 119 113 107 125 97 113 121 103 104 99 125 134 101 123 100 114 105 132 97 101 113 119 119 96 109 119 109 105 108 110 101 118 112 94 109 90 108 103 107 133 90 112 90 115 119 106 103 106 117 122 109 100 113 110 120 103 126 106 129 125 114 105 121 115 110 122 119 92 98 101 113 97 101 84 107 98 119 92 114 109 126 97 119 98 101 115 107 108 112 97 111 108 100 90 107 103 86 94 121 102 104 113 113 108 112 108 101 115 108 100 112 112 94 99 132 93 88 120 104 98 115 87 105 108 117 106 96 110 111 99 118 95 90 88 109 97 106 105 108 113 97 88 93 96 110 78 105 100 110 86 96 119 124 124 103 111</counts>
			</dataPoints>
		</scan>
	</xrdMeasurement>
</xrdMeasurements>