File: data/XRD/_misc/old/XG-700C/_absolute_2th-om_10-130deg_PIXscan_56min_4.xrdml
<xrdMeasurements xmlns="http://www.xrdml.com/XRDMeasurement/2.1" xmlns:xsi="http://www.w3.org/2001/XMLSchema-instance" xsi:schemaLocation="http://www.xrdml.com/XRDMeasurement/2.1 http://www.xrdml.com/XRDMeasurement/2.1/XRDMeasurement.xsd" status="Completed">
	<comment>
		<entry>Configuration=Factory configuration, Owner=User-1, Creation date=7/8/2013 4:01:53 PM</entry>
		<entry>Goniometer=PW3050/65 (Theta/2Theta); Minimum step size 2Theta:0.0001; Minimum step size Omega:0.0001</entry>
		<entry>Sample stage=MRD Cradle; Minimum step size Phi:0.01; Minimum step size Chi:0.01; Minimum step size X:0.01; Minimum step size Y:0.01; Minimum step size Z:0.001</entry>
		<entry>Diffractometer system=XPERT-PRO</entry>
		<entry>Measurement program=C:\PANalytical\Data Collector\Programs\Jorrit\2thom\_absolute_2th-om_10-130deg_PIXscan_56min.xrdmp, Identifier={15BCCF57-2807-42BD-B5B9-ECC0B3DC9284}</entry>
		<entry>Batch program=C:\PANalytical\Data Collector\Programs\SimonL\batch4x_2thom_10-130°_z9.1_x0,10,20,30_y0_57min.xrdmp, Identifier={EED9823A-2BEB-424C-9252-345C4EF2834A}</entry>
	</comment>
	<sample type="To be analyzed">
		<id></id>
		<name></name>
		<preparedBy></preparedBy>
	</sample>
	<xrdMeasurement measurementType="Scan" status="Completed" sampleMode="Reflection">
		<comment>
			<entry>_absolute_2th-om_10-130deg_PIXscan_56min</entry>
			<entry>PHD Lower Level = 4.83 (keV), PHD Upper Level = 11.27 (keV)</entry>
		</comment>
		<usedWavelength intended="K-Alpha 1">
			<kAlpha1 unit="Angstrom">1.5405980</kAlpha1>
			<kAlpha2 unit="Angstrom">1.5444260</kAlpha2>
			<kBeta unit="Angstrom">1.3922500</kBeta>
			<ratioKAlpha2KAlpha1>0.5000</ratioKAlpha2KAlpha1>
		</usedWavelength>
		<incidentBeamPath>
			<radius unit="mm">320.00</radius>
			<xRayTube id="1010048" name="Empyrean Cu LFF HR (9430 033 7310x) DK442154">
				<tension unit="kV">40.0</tension>
				<current unit="mA">40.0</current>
				<anodeMaterial>Cu</anodeMaterial>
				<focus type="Line">
					<length unit="mm">12.0</length>
					<width unit="mm">0.4</width>
					<takeOffAngle unit="deg">4.2</takeOffAngle>
				</focus>
			</xRayTube>
			<xRayMirror id="27010001" name="Inc. Beam Cu W/Si (parabolic MRD)" hybrid="false">
				<crystal type="Graded" shape="Parabolic">W/Si</crystal>
				<acceptanceAngle unit="deg">0.800</acceptanceAngle>
				<length unit="mm">60.0</length>
			</xRayMirror>
			<sollerSlit id="21010002" name="Soller slits 0.04 rad.">
				<opening unit="rad">0.0400</opening>
			</sollerSlit>
			<mask id="22030007" name="Fixed mask 2 mm">
				<distanceToSample unit="mm">220.00</distanceToSample>
				<width unit="mm">2.00</width>
			</mask>
			<divergenceSlit id="22010007" name="Fixed slit 1/8°" xsi:type="fixedDivergenceSlitType">
				<distanceToSample unit="mm">220.00</distanceToSample>
				<height unit="mm">0.19</height>
			</divergenceSlit>
		</incidentBeamPath>
		<diffractedBeamPath>
			<radius unit="mm">320.00</radius>
			<sollerSlit id="21010002" name="Soller slits 0.04 rad.">
				<opening unit="rad">0.0400</opening>
			</sollerSlit>
			<receivingSlit id="22010001" name="Fixed slit 4°">
				<height unit="mm">5.88</height>
			</receivingSlit>
			<detector id="7010017" name="PIXcel3D 1x1 detector" xsi:type="areaDetectorType">
				<phd unit="%">
					<lowerLevel>30.0</lowerLevel>
					<upperLevel>70.0</upperLevel>
				</phd>
				<mode>Scanning</mode>
				<activeChannelsEquatorial>255</activeChannelsEquatorial>
				<activeChannelsAxial>255</activeChannelsAxial>
				<pitchEquatorial unit="mm">0.05500</pitchEquatorial>
				<pitchAxial unit="mm">0.05500</pitchAxial>
				<readOutPeriod unit="seconds">0.135</readOutPeriod>
			</detector>
		</diffractedBeamPath>
		<scan appendNumber="0" mode="Continuous" scanAxis="2Theta-Omega" status="Completed">
			<header>
				<startTimeStamp>2024-09-03T21:02:16+02:00</startTimeStamp>
				<endTimeStamp>2024-09-03T21:58:22+02:00</endTimeStamp>
				<author>
					<name>PRO-MRD</name>
				</author>
				<source>
					<applicationSoftware version="6.1b">Data Collector</applicationSoftware>
					<instrumentControlSoftware version="7.0E 20130304">XPERT-PRO</instrumentControlSoftware>
					<instrumentID>0000000011142674</instrumentID>
				</source>
			</header>
			<dataPoints>
				<positions axis="2Theta" unit="deg">
					<startPosition>9.99826193</startPosition>
					<endPosition>129.99755682</endPosition>
				</positions>
				<positions axis="Omega" unit="deg">
					<startPosition>4.99913096</startPosition>
					<endPosition>64.99877841</endPosition>
				</positions>
				<positions axis="Phi" unit="deg">
					<commonPosition>0.00</commonPosition>
				</positions>
				<positions axis="Chi" unit="deg">
					<commonPosition>0.00</commonPosition>
				</positions>
				<positions axis="X" unit="mm">
					<commonPosition>30.00</commonPosition>
				</positions>
				<positions axis="Y" unit="mm">
					<commonPosition>0.00</commonPosition>
				</positions>
				<positions axis="Z" unit="mm">
					<commonPosition>9.100</commonPosition>
				</positions>
				<commonCountingTime unit="seconds">32.895</commonCountingTime>
				<counts 231 242 224 225 203 228 188 184 209 208 236 223 208 215 214 204 218 215 191 199 200 203 214 214 234 220 220 203 175 194 218 223 197 221 234 237 212 232 213 200 196 233 203 193 198 213 236 214 239 205 213 205 220 227 216 203 228 210 213 197 187 213 210 212 212 241 203 204 223 224 219 214 190 224 212 222 214 210 221 225 217 249 214 225 195 201 183 204 204 198 235 219 216 225 219 213 203 222 199 246 198 215 206 204 196 215 223 193 200 181 216 209 215 185 217 220 203 203 231 218 175 211 210 207 210 191 192 186 182 201 201 213 198 215 222 204 199 207 207 196 197 192 195 199 221 208 198 179 203 191 192 187 204 199 177 211 191 198 205 185 209 189 193 179 185 201 187 200 206 196 205 213 213 233 221 212 215 182 199 189 224 202 199 192 208 205 199 167 214 201 192 214 204 194 202 201 195 193 184 201 200 219 178 214 203 195 198 199 188 204 198 226 187 191 203 195 182 180 211 190 202 207 195 202 180 186 197 182 194 185 196 175 182 215 179 180 222 191 196 166 209 191 196 217 183 193 193 226 209 201 208 213 171 194 186 190 193 209 203 175 171 186 208 180 184 198 192 184 170 159 211 200 183 196 203 200 212 188 211 198 191 171 176 171 176 157 182 180 167 162 186 169 150 195 179 180 204 178 184 176 187 197 180 166 186 187 211 203 177 184 180 186 201 200 178 181 189 177 173 189 183 169 215 192 188 193 194 171 180 182 173 206 199 206 187 188 184 199 194 188 191 187 214 187 182 154 201 205 183 185 197 167 196 184 218 169 187 178 209 168 192 183 157 196 191 180 188 163 205 182 184 165 177 199 198 194 190 175 175 178 160 187 183 176 195 191 160 171 174 169 174 176 154 202 173 176 176 179 190 187 218 179 185 185 184 167 188 182 182 165 182 168 159 190 163 182 173 199 192 176 169 190 191 204 189 182 153 182 181 182 182 174 197 161 169 178 181 177 171 171 174 177 181 159 182 177 190 181 173 180 153 172 189 185 182 186 201 190 187 172 180 183 168 164 216 195 171 163 174 165 155 177 186 163 184 206 162 167 178 159 171 182 152 170 162 164 169 183 168 164 179 180 196 165 171 186 182 164 182 177 167 168 183 160 178 146 175 188 166 160 204 182 168 173 152 167 174 165 180 161 167 168 140 161 160 173 168 142 179 162 186 162 132 159 166 173 172 190 177 183 168 157 177 169 186 187 163 173 179 162 163 143 138 150 167 173 175 171 151 156 182 158 168 139 144 155 169 147 174 200 183 165 180 171 161 167 172 137 161 159 169 158 159 166 152 168 135 154 180 169 177 166 174 163 169 149 155 169 210 169 146 154 187 160 152 158 164 160 164 171 163 147 139 160 133 176 166 165 162 157 164 168 146 180 162 143 164 168 183 128 163 141 183 146 188 164 165 137 159 176 132 183 141 151 154 164 156 147 147 147 178 159 176 171 166 167 167 172 159 149 180 157 166 169 175 159 143 167 180 155 135 168 184 171 156 163 163 148 146 174 155 165 194 171 178 159 150 147 168 150 154 143 147 151 161 148 147 160 178 160 147 136 147 164 147 168 133 153 156 180 144 162 170 164 143 159 156 189 148 161 174 146 154 145 143 163 171 176 159 172 171 155 141 173 164 128 183 169 162 164 169 148 178 177 164 167 163 155 149 153 153 160 167 167 150 165 151 177 146 163 146 137 167 175 164 156 166 184 160 137 152 145 149 161 150 173 138 152 166 168 169 162 156 165 150 164 155 155 149 144 150 148 161 141 162 143 155 161 153 174 150 132 159 146 177 160 158 169 164 147 166 174 159 162 153 158 132 142 160 159 146 157 153 172 166 194 188 146 163 163 138 150 137 170 165 141 187 162 155 163 166 157 164 165 134 178 150 155 169 179 135 148 142 149 180 146 153 178 144 159 155 136 169 180 153 154 165 149 147 173 168 141 146 148 151 157 146 147 148 165 158 152 142 138 155 153 177 152 171 153 188 153 172 184 172 147 152 161 168 165 161 145 156 166 146 171 162 129 156 171 160 161 152 166 147 139 162 135 147 157 157 168 153 160 171 168 172 139 132 150 153 155 174 144 172 166 159 153 175 159 166 145 177 154 185 179 163 169 153 157 151 143 145 151 178 184 162 183 168 160 172 184 153 145 174 173 153 174 142 158 171 176 167 153 171 154 161 164 176 149 164 149 174 186 169 167 147 156 152 166 164 169 171 142 166 154 171 161 180 191 163 163 158 187 145 155 162 146 178 164 174 160 153 176 177 159 145 168 175 155 164 161 196 156 147 160 169 162 157 158 163 170 172 146 165 159 159 160 173 138 184 173 168 138 143 158 158 145 169 191 170 147 153 169 158 174 154 174 163 152 173 169 175 166 176 167 153 159 157 189 154 151 186 187 173 153 178 165 160 157 185 154 168 163 147 188 175 189 161 146 168 173 150 165 171 149 175 166 151 171 150 174 164 145 156 161 140 157 147 157 188 150 178 178 185 174 184 162 181 178 170 159 144 160 156 172 155 171 153 154 174 147 144 164 159 185 155 180 167 150 158 178 178 177 193 176 168 139 174 193 153 188 174 169 158 171 190 177 159 173 168 178 150 159 182 176 153 169 157 178 169 181 146 174 164 165 165 188 159 183 177 162 152 161 178 190 169 161 201 161 135 181 156 183 178 158 173 190 170 168 168 156 187 175 158 178 172 177 148 184 192 153 152 158 170 155 169 153 179 152 168 188 168 161 159 162 152 172 163 157 176 191 152 178 164 158 163 177 182 161 177 160 161 148 170 169 160 188 165 166 190 174 161 149 165 182 151 161 156 181 167 171 172 169 137 172 169 176 154 150 178 152 142 170 173 178 164 171 170 175 167 183 154 168 167 175 180 160 157 167 172 189 152 154 165 162 140 177 145 161 177 176 176 147 186 156 169 169 150 161 166 163 152 169 151 169 158 181 152 161 165 175 163 165 182 161 137 159 148 151 186 178 162 161 188 153 151 149 175 169 178 165 186 155 183 167 161 153 154 171 161 166 189 158 169 164 160 144 175 161 159 185 163 163 149 177 178 184 177 162 179 156 160 164 186 160 141 173 162 180 143 155 182 159 162 172 152 162 156 156 161 165 149 181 133 171 158 167 158 139 146 178 145 165 156 174 141 166 181 140 158 184 147 170 173 184 174 135 155 150 144 159 146 171 187 172 166 170 163 171 199 167 150 163 157 138 169 166 157 172 157 170 157 193 160 157 162 153 179 167 140 163 155 136 160 157 160 162 153 145 150 159 161 158 183 185 171 142 166 167 136 173 174 180 185 141 157 171 170 160 150 158 172 141 164 164 155 139 173 163 168 140 161 159 141 156 163 169 153 151 143 170 169 159 178 169 158 174 151 167 174 150 148 170 149 163 152 146 163 142 149 153 169 154 165 149 147 137 157 163 144 176 134 163 151 135 150 140 164 156 167 152 155 132 155 150 144 161 153 152 162 151 140 161 144 175 163 131 146 154 150 166 119 172 174 157 159 150 153 137 143 178 166 161 149 140 129 150 141 138 153 126 166 166 170 152 165 141 148 162 172 141 136 144 146 161 136 174 155 166 146 147 135 154 170 149 150 124 155 146 150 144 164 144 145 139 153 140 155 148 153 137 112 136 147 152 158 164 172 135 137 171 168 141 143 155 132 153 159 148 154 145 162 143 156 149 153 134 152 154 149 163 168 131 165 140 158 135 145 151 153 136 143 188 129 159 134 171 138 150 134 162 112 149 160 154 158 132 152 159 140 135 135 139 145 141 147 146 153 148 142 156 134 143 144 154 149 147 133 160 135 135 150 153 143 144 138 150 131 174 131 120 141 152 141 159 157 146 149 127 160 142 150 136 124 129 154 130 125 142 144 115 165 155 138 151 128 159 140 116 152 140 137 150 146 131 150 144 135 138 142 146 144 154 141 141 139 144 139 135 141 133 139 118 119 149 139 136 132 141 138 127 147 125 137 137 134 142 127 140 135 129 139 122 134 142 136 119 141 160 147 129 124 152 159 136 146 138 135 126 143 118 156 144 131 127 124 148 135 149 139 133 142 128 126 136 123 141 130 132 135 147 128 157 127 123 150 119 122 127 124 138 167 125 143 120 128 130 125 140 144 130 126 146 143 144 130 121 136 136 119 123 139 131 137 140 141 146 159 158 134 142 130 144 138 132 132 136 129 138 129 133 154 132 112 130 128 131 138 132 111 128 120 136 131 137 150 123 134 118 149 141 140 121 119 126 142 141 129 144 130 133 134 121 117 153 129 132 147 140 132 151 111 132 116 130 131 127 140 141 142 141 145 131 142 125 146 154 128 111 150 131 111 143 145 124 125 139 116 139 118 138 155 126 133 115 126 138 154 133 151 117 117 124 118 110 119 145 129 128 115 111 145 140 131 121 134 129 139 164 123 123 134 122 127 124 120 94 135 116 159 139 145 127 131 117 127 110 118 132 128 131 117 139 129 115 127 122 118 116 144 130 130 140 127 135 113 135 127 109 112 114 119 114 122 126 129 134 150 137 146 136 111 120 145 115 125 116 114 134 112 114 138 125 126 132 132 130 146 112 121 99 125 142 131 107 117 129 127 135 138 141 127 139 139 125 139 130 121 125 108 126 121 126 122 116 112 125 109 107 125 119 128 129 122 137 125 115 142 124 133 108 115 126 150 108 141 115 132 136 124 126 115 128 104 113 108 111 128 120 117 115 120 127 125 136 115 128 121 89 111 132 107 126 133 129 127 134 129 117 117 112 99 125 138 111 114 133 111 114 120 99 120 111 125 127 136 110 137 139 131 118 111 147 122 123 112 131 131 116 124 141 132 146 114 108 120 104 121 118 126 107 115 132 131 117 139 114 96 129 121 126 137 145 123 122 107 126 115 130 118 122 115 144 135 107 126 112 137 119 121 115 125 119 127 105 124 131 129 102 128 112 117 115 118 105 123 120 120 115 108 112 125 125 120 124 107 105 123 122 114 108 131 133 130 129 95 117 114 144 109 113 129 125 111 114 106 116 108 124 141 117 144 115 124 125 119 125 117 112 125 140 114 118 116 127 106 136 103 115 127 109 134 130 121 110 105 124 111 128 117 124 125 123 122 120 97 99 127 125 127 99 100 105 107 123 121 121 141 126 121 125 110 120 117 122 129 97 110 117 124 121 116 110 98 140 109 120 138 115 120 111 113 113 123 100 111 107 90 125 110 126 127 112 133 121 132 102 119 113 100 136 139 110 114 119 119 114 105 124 128 106 120 110 108 118 106 133 103 106 115 126 118 93 111 109 118 84 120 134 119 100 112 124 115 115 111 105 104 120 107 104 121 91 125 109 127 133 134 125 104 120 113 127 143 127 117 93 93 115 107 131 133 131 102 102 132 95 119 113 111 120 119 112 127 121 132 112 103 102 123 129 115 136 123 117 118 120 115 136 115 121 99 110 118 94 123 117 122 113 124 139 113 110 109 109 121 118 97 107 108 114 122 118 114 106 126 101 114 119 96 110 120 131 113 108 118 118 111 120 106 122 123 128 112 107 127 100 94 102 107 112 106 141 128 118 121 94 113 118 113 147 105 119 113 113 97 97 97 100 119 122 125 100 117 123 108 105 104 101 99 126 106 113 111 124 109 95 109 110 113 94 118 114 117 115 119 132 98 103 111 112 111 109 108 117 123 128 103 109 110 114 119 115 126 117 120 134 105 110 100 109 131 109 107 114 117 109 110 124 130 87 102 105 121 117 95 117 112 112 114 132 113 95 115 110 99 115 111 102 129 114 124 131 123 114 105 119 110 105 121 114 122 126 134 109 135 109 93 135 102 95 98 120 109 123 94 121 109 105 115 103 113 114 118 96 136 124 123 113 104 119 110 100 108 105 121 119 126 108 101 90 126 114 117 97 103 119 122 112 112 99 120 119 109 108 122 112 108 124 99 122 129 95 109 130 119 122 110 118 114 106 101 104 114 115 112 106 111 121 118 125 137 122 98 126 138 103 111 114 119 116 123 97 109 111 127 111 114 125 115 110 116 109 116 112 112 118 118 126 138 118 107 92 116 126 111 104 103 109 109 106 120 109 101 125 103 98 128 118 128 95 112 114 99 105 123 122 116 117 115 111 110 108 110 110 118 126 125 136 119 111 125 112 142 101 117 126 99 124 123 96 132 110 114 126 109 108 106 117 113 107 112 120 103 94 110 127 95 118 125 117 106 104 113 108 118 119 120 111 119 104 97 126 122 109 114 112 108 120 124 117 122 111 116 112 121 116 105 97 101 111 127 105 103 118 88 117 102 107 125 88 131 118 107 123 99 123 118 99 121 107 102 130 121 118 109 110 114 114 123 101 105 92 120 101 114 108 115 107 132 88 89 113 114 111 104 118 112 109 95 100 134 138 115 132 108 95 98 98 120 119 118 123 118 108 113 103 95 123 129 116 109 106 110 107 125 120 112 103 111 122 108 116 99 116 94 125 112 98 103 103 101 124 105 86 115 111 140 108 102 114 122 114 108 116 101 88 96 113 101 125 115 129 114 114 115 105 131 125 113 103 88 119 117 114 91 118 122 106 117 122 113 113 111 122 124 121 119 120 114 107 96 116 115 116 113 105 117 121 111 111 124 118 104 121 123 110 83 113 132 113 113 137 130 126 118 105 119 98 123 109 110 111 123 93 112 101 115 123 122 92 115 112 128 114 110 101 113 131 112 114 112 121 119 128 97 120 118 105 115 113 112 107 110 97 95 130 110 133 98 119 103 119 124 136 111 130 95 120 104 123 126 96 109 106 97 100 107 106 113 124 118 126 119 104 124 125 129 104 99 125 120 100 124 110 118 97 125 113 114 100 112 107 104 126 115 107 119 89 109 132 110 100 113 113 123 132 109 119 110 113 119 114 113 114 102 108 112 137 117 116 97 118 129 132 118 109 104 98 126 109 104 106 116 111 105 97 127 135 110 120 125 98 117 100 106 126 106 116 96 115 99 102 103 116 103 115 123 111 110 92 112 107 110 114 90 114 119 101 101 106 126 95 106 91 102 122 118 120 98 128 113 126 120 116 100 109 118 92 109 105 103 98 109 104 109 106 113 96 122 127 123 84 126 96 107 93 114 100 120 104 122 98 101 103 99 140 105 114 108 109 130 110 125 131 99 117 121 109 97 101 126 135 122 143 122 102 117 96 110 91 126 101 123 112 112 117 142 112 102 123 113 116 118 124 113 115 104 109 112 107 117 119 89 123 125 110 105 118 111 107 112 91 126 100 111 106 121 111 119 116 111 97 118 105 112 100 127 108 112 124 153 100 114 140 114 113 108 112 130 111 133 115 118 111 90 122 102 108 110 122 120 101 105 116 112 99 136 110 125 110 110 108 110 103 129 117 119 119 102 107 112 100 123 118 130 114 121 112 103 123 122 124 110 129 118 123 126 116 129 103 128 103 120 111 90 99 118 128 101 110 107 122 128 108 133 118 112 104 107 140 130 116 94 116 125 125 111 109 118 107 129 120 112 114 116 127 116 110 108 114 112 134 123 108 118 115 113 119 124 104 147 104 124 115 126 115 99 95 130 126 119 128 117 132 125 113 101 128 84 114 122 126 118 114 132 110 104 112 120 131 121 139 142 109 127 126 129 109 115 134 91 130 122 124 114 111 119 116 126 137 115 112 117 151 117 136 121 115 116 97 95 134 132 112 121 137 128 112 123 133 125 130 123 136 142 123 110 119 138 142 133 108 135 126 143 137 129 125 118 123 128 111 143 130 132 144 120 125 129 127 142 139 133 133 131 144 126 128 145 157 143 136 144 145 166 154 154 154 167 204 168 167 202 197 192 186 175 177 207 164 198 184 191 186 185 216 187 195 224 180 204 192 198 168 191 184 169 175 192 174 188 157 158 148 164 152 160 146 154 175 131 168 133 123 152 136 137 123 137 122 119 135 145 115 131 127 139 130 141 124 114 98 110 132 125 130 113 134 124 128 117 121 129 129 118 120 116 141 138 110 125 137 129 129 108 105 115 115 124 131 119 105 111 117 111 109 111 107 116 115 109 120 127 135 111 106 112 107 121 124 116 126 106 99 116 116 118 121 122 96 117 122 106 129 107 113 130 107 126 111 125 104 111 120 114 131 114 125 90 119 110 119 93 109 113 91 132 107 132 128 118 126 116 106 124 103 100 126 104 111 129 120 124 111 101 108 115 119 111 105 101 125 124 107 132 122 108 124 115 118 107 126 125 116 118 131 144 105 120 115 117 105 125 124 124 100 87 108 140 100 90 97 123 118 127 124 130 133 118 125 120 119 114 129 102 127 82 127 114 108 124 119 103 116 117 100 108 123 115 108 113 122 116 118 104 114 102 125 119 97 103 118 124 106 109 114 117 113 116 97 124 114 130 109 124 129 114 111 128 116 102 129 122 113 110 113 112 121 93 99 108 116 121 130 119 127 117 118 124 115 101 99 91 118 119 104 117 107 113 120 120 100 103 115 121 111 130 127 112 117 115 127 121 122 118 102 129 103 117 124 111 107 117 125 112 131 118 100 130 110 124 105 142 110 104 112 112 108 122 123 126 136 116 110 100 108 120 107 111 138 113 122 113 102 108 126 127 124 113 116 122 127 107 97 124 113 112 130 108 125 134 115 125 112 118 123 127 108 122 103 105 128 118 105 116 130 137 107 116 134 98 101 105 125 133 118 126 128 127 123 119 119 124 110 108 105 108 111 95 106 131 116 120 137 113 133 122 107 125 112 106 103 125 109 94 126 104 122 125 109 126 117 113 103 127 110 128 97 126 112 111 118 109 113 101 129 123 129 107 104 129 119 131 122 124 128 97 122 121 111 113 127 123 104 123 110 104 119 111 108 109 112 116 133 126 119 119 113 120 122 111 135 108 114 97 110 123 103 119 107 122 121 131 118 100 119 117 111 100 124 124 107 117 116 109 118 103 133 144 130 133 120 130 114 101 144 134 127 96 103 116 126 113 117 125 108 119 113 129 114 112 120 136 104 118 128 120 113 113 108 108 112 122 129 106 111 126 130 141 141 94 126 102 114 129 120 112 106 105 121 105 116 116 106 122 130 113 111 93 107 116 106 127 124 113 126 115 110 108 134 119 117 121 117 104 105 107 109 110 123 121 101 129 130 110 108 106 101 112 105 112 109 122 129 128 106 108 105 122 122 123 109 116 104 121 123 130 109 109 113 105 111 106 112 123 136 114 115 105 113 151 105 140 121 114 114 110 118 134 110 111 111 103 110 132 131 121 105 125 123 124 120 119 115 136 120 114 110 140 117 109 110 113 113 117 109 100 135 106 98 110 122 118 111 108 136 118 115 123 124 116 113 121 131 118 115 106 120 132 110 126 126 125 100 115 104 112 138 101 119 106 117 117 109 124 101 119 116 129 122 107 118 98 135 140 101 128 143 87 122 124 116 125 120 127 125 128 126 114 110 98 134 94 109 118 115 124 114 105 120 106 120 100 130 134 125 137 123 120 114 112 121 135 125 111 123 116 122 122 108 121 120 124 131 130 122 110 117 127 102 121 122 116 93 118 107 132 134 109 120 107 132 101 133 114 113 112 119 104 123 118 113 127 110 128 126 112 94 143 113 96 115 118 124 119 115 114 129 121 147 139 131 100 119 128 102 123 125 109 89 115 128 122 112 145 127 105 113 108 141 121 114 144 100 131 120 118 106 142 120 117 125 105 115 103 107 115 113 135 121 107 115 134 102 106 105 130 119 133 134 116 92 142 104 123 114 119 112 107 124 124 127 115 134 121 124 100 124 133 121 122 127 104 117 128 110 129 119 129 115 123 119 129 121 121 131 115 103 119 107 123 103 123 125 123 125 141 119 149 112 101 113 129 121 108 137 135 118 125 98 132 100 118 136 119 109 107 111 128 132 119 119 114 118 108 121 102 121 147 123 113 136 130 121 127 128 111 107 91 111 120 112 120 117 117 111 135 122 106 112 133 126 110 136 118 119 123 135 106 101 115 122 127 130 128 138 112 114 100 135 129 91 113 121 114 130 126 107 101 125 114 114 118 110 115 119 101 137 131 109 111 100 117 115 103 133 127 121 130 115 135 138 123 121 119 125 134 122 124 119 120 131 122 117 119 103 117 112 111 113 116 104 120 113 121 109 118 119 138 113 119 119 124 108 92 97 126 130 113 132 117 112 99 117 121 121 119 112 123 111 92 103 105 112 120 126 108 143 126 138 113 104 98 132 128 131 109 124 105 117 126 109 109 115 123 113 136 133 135 108 118 130 127 101 99 116 128 110 114 123 121 133 122 117 120 116 111 100 155 126 110 103 117 99 104 144 115 121 118 133 119 118 96 119 106 138 113 119 97 121 114 119 134 115 104 122 128 120 120 109 124 113 125 131 108 115 122 128 120 99 100 106 125 110 121 116 117 105 125 103 112 122 111 117 102 132 122 126 136 108 117 124 107 117 106 126 124 131 113 117 139 112 118 124 112 115 123 128 114 121 116 120 103 120 109 110 113 119 123 126 123 90 103 121 116 107 141 111 104 113 136 117 119 127 121 115 121 119 99 120 111 136 109 115 130 119 116 119 113 114 114 120 122 105 110 116 122 114 122 113 117 131 128 131 144 145 134 111 127 111 111 105 101 125 111 112 108 117 107 119 118 124 129 125 102 127 127 125 115 123 96 124 109 138 123 137 119 107 110 132 136 109 114 139 124 110 127 108 122 111 126 128 137 114 124 103 104 142 151 119 129 118 141 125 124 134 136 125 122 133 118 119 111 117 124 125 120 126 117 120 116 123 118 120 106 111 123 122 109 112 110 128 129 121 136 138 123 111 119 118 117 128 112 103 115 114 118 119 100 129 104 125 113 120 103 126 133 124 131 118 126 119 99 115 131 134 107 120 128 101 117 109 113 138 123 126 137 126 114 121 104 125 129 125 129 116 110 133 114 114 108 126 117 122 118 142 126 109 98 121 124 135 131 102 133 118 125 116 120 128 121 116 110 120 115 115 109 126 141 101 112 133 139 125 98 115 109 114 114 118 123 106 101 118 130 128 131 126 123 116 99 119 114 101 130 129 107 131 110 113 126 115 120 129 112 146 129 114 102 131 112 128 137 104 103 123 110 110 122 104 125 106 140 126 106 125 117 106 121 112 119 107 110 108 129 125 139 104 125 129 138 120 136 105 131 108 119 110 133 121 132 122 132 126 115 137 101 135 125 127 112 126 127 122 99 110 120 131 113 110 138 133 136 107 127 130 109 118 114 111 124 100 109 101 127 128 137 116 112 120 113 125 145 115 115 131 102 135 131 114 124 114 127 119 123 121 121 144 136 117 110 113 121 115 140 114 116 130 130 134 122 108 108 128 110 136 103 110 134 121 143 141 117 113 121 133 119 116 133 112 119 136 119 123 139 122 133 135 104 118 118 105 133 131 126 144 115 122 130 126 107 140 124 108 136 134 128 127 125 119 109 136 124 117 125 117 136 131 134 128 134 115 112 126 119 126 107 119 124 107 132 106 120 118 140 125 113 137 112 120 124 115 112 115 140 133 116 123 139 122 131 134 131 118 121 105 138 144 149 104 109 130 130 111 127 114 117 137 114 93 129 111 127 111 127 127 122 117 146 111 138 120 138 114 126 146 129 112 153 111 137 140 129 135 133 135 129 125 137 122 117 131 115 129 121 118 135 123 133 130 116 130 125 133 141 137 110 128 127 141 121 117 133 122 123 133 124 134 124 104 116 110 118 134 127 123 115 116 127 123 126 134 142 132 130 135 114 113 132 120 113 135 138 112 113 149 128 131 114 121 133 111 101 134 132 126 108 134 124 130 121 137 93 125 119 117 118 116 113 128 129 133 125 135 135 136 108 129 125 123 100 137 119 118 123 116 135 150 111 117 135 140 118 132 115 150 119 117 125 159 129 166 129 154 148 122 118 127 134 128 127 132 138 121 127 122 98 124 115 118 128 134 120 134 124 132 130 116 117 131 125 130 128 130 140 143 124 139 115 130 127 119 145 127 130 126 131 122 147 123 119 141 116 138 131 141 123 120 137 116 131 130 146 119 113 128 116 130 105 104 121 125 126 123 128 118 134 118 143 125 123 135 126 116 145 123 116 130 135 123 115 123 127 140 117 125 123 124 127 135 117 119 109 105 133 127 120 130 130 127 107 134 139 113 101 129 128 134 119 129 123 104 132 118 105 123 107 117 146 126 124 110 133 116 137 128 113 101 131 114 132 125 152 132 126 135 120 117 132 111 131 128 145 100 130 114 148 118 139 125 113 125 121 120 139 143 116 122 129 112 115 120 128 131 144 132 129 131 133 123 121 118 117 108 115 131 122 133 140 139 119 111 139 132 124 148 133 130 116 122 119 126 134 125 155 123 142 114 114 135 129 136 128 126 121 135 153 127 133 127 128 129 127 147 119 127 112 123 98 148 132 118 126 121 133 127 138 126 120 134 128 129 139 127 123 131 139 107 131 118 136 137 125 116 120 117 138 127 129 145 138 133 135 137 129 131 135 128 122 143 136 141 126 129 128 145 133 129 135 140 112 129 142 118 124 143 136 122 156 117 133 132 145 137 112 110 112 126 151 138 101 135 128 119 142 133 125 128 159 135 116 124 138 130 136 125 102 101 147 133 127 123 133 126 129 139 141 124 119 127 123 126 147 157 126 125 120 133 128 130 121 122 116 119 147 123 131 130 138 132 129 136 139 132 113 147 123 140 129 125 131 126 133 133 127 126 153 129 126 101 122 151 121 131 120 118 118 115 117 137 134 123 123 131 118 126 139 143 154 122 126 102 130 133 135 103 123 143 132 139 141 126 157 154 108 107 124 115 136 119 134 119 121 138 117 110 115 120 117 118 127 137 131 120 142 125 120 125 137 137 131 127 117 129 124 115 114 129 122 112 123 119 125 134 137 123 111 118 112 116 120 140 114 128 119 143 134 123 117 125 136 119 125 135 143 121 126 120 120 120 121 123 143 103 143 122 108 140 120 123 127 124 124 113 123 107 124 121 122 117 136 126 135 121 133 102 124 120 121 138 123 143 124 117 130 116 139 128 124 109 110 119 112 125 130 125 110 116 125 134 120 122 138 121 135 108 129 123 135 108 126 102 139 112 125 120 155 124 133 127 134 112 125 124 151 124 125 127 146 129 124 129 125 118 107 131 117 135 126 141 138 146 134 128 103 92 132 121 118 140 117 121 140 142 119 110 130 135 145 121 122 114 125 133 119 142 131 128 133 116 136 110 118 124 127 138 141 133 142 122 125 142 117 126 128 123 130 133 113 135 120 102 114 135 127 127 118 145 123 127 107 126 140 128 126 153 153 117 107 110 125 130 140 124 111 116 132 143 137 118 131 139 130 120 127 136 129 129 137 126 120 128 124 125 132 137 123 109 132 137 129 126 129 131 119 142 133 115 135 138 127 130 122 130 147 152 138 124 138 121 133 128 121 128 137 143 117 127 136 119 107 115 127 119 103 127 117 139 132 125 140 113 143 119 138 122 145 117 154 115 128 136 104 110 110 114 114 141 125 115 143 115 139 135 130 122 121 134 117 118 129 139 113 113 131 139 126 124 115 126 138 124 121 132 134 132 140 132 146 126 153 128 155 132 134 103 149 133 136 129 115 133 128 115 132 116 122 133 140 137 122 125 141 150 120 123 154 130 142 123 116 144 131 122 108 151 132 135 143 142 127 141 129 142 152 126 113 119 141 135 133 126 139 122 135 130 121 133 128 131 139 144 141 115 121 145 130 111 112 147 105 120 118 122 143 143 117 129 144 123 139 120 128 138 147 108 139 128 127 151 134 117 157 125 127 154 143 139 138 134 120 126 119 140 134 141 163 142 120 123 105 116 118 122 102 109 122 119 132 118 125 114 125 137 135 128 122 116 121 144 130 115 121 118 120 123 107 105 149 138 106 126 135 121 141 136 121 142 118 120 133 124 106 138 128 128 125 118 121 121 131 125 134 139 122 150 130 127 148 126 136 139 128 145 116 141 127 112 144 131 142 106 132 124 130 120 128 129 120 125 131 139 133 126 108 141 135 124 125 130 140 132 122 120 127 133 123 136 146 131 136 143 122 112 129 128 110 145 122 128 137 135 119 122 145 117 122 130 131 127 118 134 113 115 117 146 158 132 120 109 137 121 122 123 139 136 133 108 120 114 123 135 140 112 139 138 131 122 123 130 130 125 135 128 139 121 132 133 114 118 119 123 131 135 121 130 126 140 121 133 143 139 130 117 139 129 148 135 140 137 124 127 123 139 110 135 121 123 123 121 111 130 124 117 124 136 122 127 139 129 123 125 112 107 125 127 124 120 114 126 119 140 135 111 127 121 121 112 142 116 124 123 122 131 109 125 135 117 135 122 124 133 121 105 113 137 106 124 140 132 145 130 124 137 129 120 122 140 144 126 115 151 130 104 120 127 115 134 124 120 150 116 142 124 136 144 132 133 132 126 113 126 141 129 128 129 128 118 129 129 109 138 120 132 133 109 136 132 107 143 126 122 136 124 124 132 136 130 122 133 119 128 104 135 132 121 135 108 130 142 130 116 132 120 120 125 123 123 118 128 142 115 134 112 118 132 121 154 120 141 139 144 132 106 123 128 126 123 135 139 107 129 121 114 123 128 118 141 128 112 121 123 139 131 130 123 125 119 152 118 145 125 136 112 125 121 127 156 114 130 136 122 124 119 120 128 148 130 126 114 141 122 130 130 117 143 136 125 111 141 133 148 122 120 112 126 112 116 145 123 105 136 116 131 135 136 130 134 114 138 117 118 146 125 140 117 116 112 128 136 148 127 117 133 135 129 137 117 120 132 121 136 120 136 148 141 138 150 132 110 125 132 128 133 123 118 122 132 128 112 91 111 128 123 128 153 108 146 126 133 130 115 101 116 112 132 132 127 123 122 126 106 128 127 117 128 156 138 128 123 127 119 119 134 134 139 143 124 136 156 128 126 136 105 125 119 158 109 130 128 112 130 128 122 133 131 139 133 127 118 134 122 126 102 119 124 123 118 113 122 127 122 117 132 125 136 130 133 139 113 111 109 97 101 125 131 124 130 106 113 120 115 131 128 126 122 130 117 121 139 134 135 102 118 106 107 127 137 100 131 145 130 129 134 134 116 125 125 134 122 145 111 142 103 144 122 119 115 143 144 130 111 109 130 121 108 137 150 136 123 107 122 123 135 139 112 127 124 114 130 132 129 119 110 124 147 116 101 131 128 126 138 117 116 123 121 125 122 118 125 119 121 114 138 105 132 125 118 124 130 117 136 119 123 120 136 121 137 136 129 147 158 102 118 144 99 110 123 137 119 115 116 127 120 128 138 127 120 129 142 127 121 125 107 127 134 118 125 115 118 113 113 125 109 126 108 124 115 128 107 120 132 136 120 139 137 126 122 143 129 149 121 119 133 119 134 143 123 146 136 130 118 119 126 134 141 126 129 133 133 124 116 104 126 113 126 147 131 125 139 113 156 132 118 132 117 107 134 127 145 106 126 124 125 139 124 113 111 122 113 121 129 124 110 108 106 96 112 133 117 141 134 125 98 123 123 147 120 139 128 116 126 99 125 134 133 131 110 107 135 133 137 132 126 129 114 131 115 135 122 115 125 99 131 123 131 131 126 116 119 125 108 117 130 139 127 115 125 137 120 113 111 124 123 132 121 115 116 124 137 117 131 142 129 133 132 145 105 102 108 128 112 139 135 149 156 124 122 135 120 125 126 109 116 113 137 122 125 119 107 122 116 135 113 130 113 106 147 129 102 126 127 102 134 128 125 128 137 139 119 139 136 115 109 115 108 122 141 130 121 111 147 115 114 116 105 121 104 136 117 132 129 129 130 132 119 116 114 134 128 110 121 135 130 117 128 117 133 152 97 153 112 125 128 125 130 124 114 136 125 126 115 137 146 120 137 125 97 124 129 137 120 122 127 134 119 120 134 113 116 143 125 99 116 147 157 127 113 108 120 112 141 150 136 112 123 129 131 116 105 120 137 113 135 120 120 143 128 120 120 126 124 142 116 114 118 137 130 121 133 122 118 111 139 132 151 111 119 117 112 126 118 122 111 124 120 114 123 126 113 109 127 130 140 104 115 126 128 120 97 135 126 117 128 118 126 127 119 124 125 132 116 111 137 123 129 125 148 124 126 123 130 128 127 113 123 108 119 122 116 139 124 139 130 120 135 130 144 133 130 121 112 137 117 149 115 106 129 130 143 142 125 132 136 136 141 117 125 126 119 121 102 118 126 129 116 116 130 126 114 124 119 118 115 119 123 127 112 116 134 140 148 119 133 124 142 114 121 130 127 138 135 127 120 130 139 120 128 124 138 157 138 126 121 136 99 136 123 138 104 141 110 118 108 125 117 143 126 131 115 163 123 129 113 119 126 129 126 137 143 130 126 150 118 121 126 118 124 112 125 106 138 133 145 155 131 149 135 145 145 146 146 130 136 128 128 133 138 139 125 151 121 146 159 144 142 153 158 135 129 144 161 113 119 149 132 137 139 147 165 114 133 140 146 149 133 148 157 139 146 147 137 143 135 132 133 149 129 132 135 150 126 128 131 128 132 120 137 133 128 147 144 128 149 142 131 126 125 120 138 122 143 126 140 130 122 126 115 153 136 128 131 133 134 139 120 116 115 120 124 109 136 119 121 137 136 112 127 128 115 124 117 119 137 121 113 134 112 129 134 139 126 133 158 127 131 117 96 129 151 114 132 123 146 123 132 125 126 123 116 151 128 123 138 140 124 123 117 125 119 123 115 116 128 121 122 127 132 109 135 126 124 125 139 136 126 100 115 124 125 121 138 119 131 137 122 129 142 124 124 125 119 120 127 154 119 136 143 125 104 122 115 132 115 122 114 102 141 121 89 110 124 101 114 133 114 114 128 138 120 133 112 151 131 121 138 117 139 139 126 144 136 129 138 130 114 116 140 131 125 128 124 114 129 114 135 131 116 113 123 103 123 117 110 132 136 125 123 120 127 136 116 136 118 143 130 114 128 125 137 131 109 138 106 121 115 120 111 136 125 132 129 112 132 117 133 118 132 121 128 116 147 123 115 130 105 114 124 137 119 103 121 106 117 123 118 120 120 118 121 125 143 126 156 106 120 121 110 140 116 127 127 139 129 143 156 158 112 126 137 130 131 136 128 137 135 152 131 141 129 132 157 100 122 135 112 137 137 125 135 128 148 119 127 143 135 130 135 135 125 119 135 110 126 124 132 120 121 140 131 122 127 127 117 124 132 130 138 133 132 139 125 121 133 128 123 140 135 126 123 117 122 133 114 135 111 110 139 149 119 128 140 126 125 128 115 140 142 122 131 120 135 119 128 119 124 153 119 110 120 150 129 100 116 122 134 109 124 148 113 113 129 114 116 121 131 133 131 121 127 139 114 128 111 130 149 145 132 120 126 133 136 127 139 126 95 126 143 147 116 136 123 118 123 130 119 115 100 117 114 123 136 133 108 117 125 110 116 126 130 140 98 121 131 115 115 122 115 112 133 145 134 126 128 123 109 134 132 110 133 123 135 110 130 120 114 115 139 139 133 124 124 109 135 127 138 121 121 109 116 124 126 134 121 121 137 118 133 99 134 122 131 136 127 101 126 138 132 133 136 143 107 116 118 122 107 132 105 127 141 125 114 137 117 128 125 125 99 131 125 135 145 127 122 134 106 128 126 133 119 142 122 133 150 137 133 142 112 126 117 138 118 142 129 128 141 140 126 108 115 118 135 142 129 116 130 118 139 118 130 138 122 136 144 139 130 127 119 121 146 127 113 152 123 131 149 127 130 135 128 124 137 120 140 125 108 123 127 115 101 115 113 123 133 130 126 126 104 123 125 112 134 126 123 116 142 147 136 145 124 121 111 139 131 143 136 134 124 136 135 110 111 117 127 140 139 139 125 120 120 133 130 118 134 122 123 126 119 138 127 129 130 115 147 119 115 128 135 137 146 159 158 137 110 105 124 121 109 136 136 139 127 133 147 133 142 111 138 99 125 126 111 151 120 136 111 139 137 105 122 149 106 146 133 139 130 133 118 123 115 119 131 152 117 135 128 125 112 120 135 127 141 150 116 143 145 113 111 101 115 104 111 150 131 134 122 135 129 114 106 149 139 119 144 123 156 128 143 120 135 149 141 136 129 124 116 117 154 122 123 132 132 134 133 135 138 136 128 130 118 136 140 132 137 107 115 139 142 113 123 130 136 124 152 129 130 123 127 114 136 129 128 124 118 109 154 143 130 140 134 110 129 128 121 126 101 128 119 145 130 140 107 132 130 133 129 145 117 120 152 120 123 142 124 113 142 141 118 119 127 100 122 124 126 105 121 128 126 124 142 118 142 114 153 132 112 112 122 132 114 115 122 129 132 105 114 140 130 137 129 145 116 151 122 126 121 134 112 149 159 102 130 153 126 108 140 122 109 115 108 120 139 129 106 130 126 119 121 129 142 113 111 124 103 116 104 106 100 106 113 124 118 120 119 134 127 118 121 139 146 124 112 119 135 135 129 124 120 105 106 143 129 142 118 136 138 118 119 136 132 129 119 130 116 113 130 134 130 123 157 123 121 138 127 138 133 149 135 131 109 122 138 135 131 120 122 99 129 117 123 119 106 130 132 129 149 142 113 133 119 125 110 136 132 116 129 141 118 124 134 125 125 132 122 137 145 112 135 138 117 137 150 132 101 113 97 126 130 118 116 122 111 139 140 128 113 138 139 132 135 133 118 115 132 140 112 92 125 133 133 137 122 114 122 123 137 116 124 110 134 137 125 126 119 127 136 143 112 117 115 130 135 123 125 127 129 132 149 133 134 126 134 137 120 132 121 124 134 121 119 126 110 129 118 133 135 155 144 107 122 124 136 125 119 122 122 138 113 113 129 134 129 123 118 155 126 138 146 146 122 121 110 115 135 141 133 127 108 118 101 114 127 124 148 103 127 133 123 137 119 116 122 139 117 132 111 126 131 135 130 153 121 133 134 116 117 127 142 143 127 107 137 136 140 150 140 113 148 126 153 120 130 122 124 110 123 129 134 122 118 132 120 120 115 122 132 131 117 124 120 124 144 134 124 135 102 124 114 122 127 118 95 121 123 120 130 121 122 155 135 109 113 125 130 108 126 132 116 134 125 108 138 144 125 107 140 115 121 130 129 115 122 123 127 169 124 111 128 115 132 135 102 163 115 131 150 129 118 131 111 137 117 131 133 136 126 121 125 123 138 122 142 135 141 120 128 113 123 131 100 144 143 132 116 127 143 130 123 114 121 133 128 122 140 118 126 121 133 133 112 121 134 150 140 134 151 122 117 121 127 138 139 140 122 136 120 109 117 105 131 121 103 121 120 130 112 109 123 136 155 137 108 123 127 156 135 109 134 121 115 114 123 117 120 118 122 137 122 122 126 133 130 114 120 135 132 105 107 132 139 143 116 150 138 124 110 115 136 132 131 138 124 122 122 144 115 127 114 139 119 133 124 123 125 128 129 111 111 127 123 128 139 137 143 142 121 134 129 123 106 130 121 131 133 122 143 120 111 134 101 132 125 121 122 134 122 119 122 95 128 124 130 138 126 124 122 132 119 130 105 115 126 127 118 119 126 123 120 131 115 122 121 120 127 138 144 137 119 127 129 92 100 125 131 145 129 112 150 123 145 146 121 117 108 139 115 113 143 149 132 122 133 132 124 137 116 113 124 128 120 111 117 144 133 125 124 137 134 140 127 109 117 134 115 119 131 135 120 120 130 136 166 109 127 128 140 126 129 131 137 112 127 130 134 129 124 110 125 136 141 123 146 121 117 139 130 125 154 125 132 115 117 127 122 111 123 136 125 123 101 129 116 119 130 122 136 109 118 123 132 128 127 142 140 117 120 121 105 114 128 136 132 133 118 137 140 154 113 144 104 137 121 142 123 107 137 132 127 120 132 138 142 137 130 153 121 136 141 111 120 122 129 124 146 129 117 135 116 132 147 135 132 134 129 151 136 127 126 118 112 120 113 127 139 113 125 142 125 133 125 121 142 154 129 133 148 158 123 146 125 108 115 134 116 124 117 112 113 118 133 110 134 135 122 127 113 122 123 142 143 134 126 139 144 129 150 119 149 126 143 144 141 123 131 141 125 127 128 138 132 117 134 135 135 139 123 114 136 126 118 142 143 118 120 136 115 126 148 134 131 119 131 150 104 135 139 145 132 130 125 134 125 130 130 133 133 119 122 128 130 121 117 125 131 124 131 144 134 126 146 140 128 135 133 121 141 134 124 125 144 131 143 138 145 139 118 111 148 148 120 140 139 110 136 124 144 137 126 118 151 130 129 137 133 139 116 133 126 147 147 131 124 128 140 137 136 138 130 157 139 109 132 140 120 130 136 136 130 136 134 114 104 137 137 136 129 136 151 132 148 109 120 115 147 132 112 136 125 147 148 136 129 129 151 139 125 146 123 122 114 119 120 135 110 133 132 110 144 140 134 131 139 124 118 134 123 144 123 130 115 135 128 132 151 128 111 120 150 145 105 131 120 120 135 124 117 119 146 143 120 130 141 121 138 125 133 114 131 142 118 128 137 135 126 155 116 136 117 137 144 124 133 135 119 145 122 123 132 110 142 129 129 131 139 120 132 150 133 107 119 119 136 116 123 132 125 136 130 123 140 126 140 120 137 123 130 136 141 118 129 122 123 121 137 123 122 135 113 116 113 111 130 117 111 126 130 115 138 137 110 135 164 124 119 109 146 118 112 117 124 110 100 132 114 140 150 141 113 118 137 135 143 145 111 124 132 137 124 143 115 134 149 132 130 108 142 130 119 118 157 139 126 130 129 137 122 152 130 142 125 160 112 127 144 141 115 119 126 139 110 120 124 137 131 121 126 115 126 125 101 109 111 122 134 137 140 129 111 131 122 120 127 120 125 130 130 123 135 128 121 112 134 123 122 114 118 152 133 126 131 113 133 129 113 139 118 145 145 131 131 129 131 136 126 139 120 122 114 127 125 126 142 127 130 148 121 134 134 130 136 137 124 132 130 135 128 114 122 140 136 136 109 126 146 140 138 130 142 139 155 113 117 128 123 126 113 135 123 116 122 137 129 117 141 130 121 141 115 138 129 142 140 133 129 133 122 120 119 110 130 113 133 130 144 139 107 114 118 137 134 138 116 119 130 123 118 123 126 139 130 110 114 113 125 125 124 133 132 127 134 126 147 120 120 121 128 139 119 146 104 150 141 135 117 125 117 130 132 115 146 122 129 113 133 130 111 130 121 121 129 124 130 125 129 111 113 136 133 120 127 131 130 109 140 121 119 125 115 135 108 127 125 129 132 131 135 134 134 115 135 119 113 116 139 111 132 132 121 115 124 127 120 139 121 121 109 115 131 129 139 125 120 141 145 142 134 145 139 113 125 118 122 140 147 120 132 124 116 134 137 115 132 130 140 128 104 130 129 124 104 131 121 116 128 122 132 126 117 129 137 131 126 137 135 124 119 123 127 124 131 135 147 126 120 124 125 120 122 126 131 135 124 126 113 142 127 117 111 125 121 124 143 134 131 114 125 132 141 128 109 120 123 130 102 131 134 120 124 123 133 149 129 119 135 116 125 137 118 122 143 101 127 111 140 124 115 147 120 119 124 147 154 129 124 137 123 122 133 123 141 116 129 108 137 111 130 127 139 116 139 111 127 123 119 136 145 120 130 114 137 116 131 133 134 124 112 131 149 131 126 111 141 129 132 112 145 137 136 123 136 130 110 112 139 136 127 127 126 135 138 133 116 127 114 123 114 124 125 141 135 124 134 117 133 127 124 137 163 137 122 138 134 121 122 144 153 136 148 134 149 120 127 154 136 139 136 144 108 134 144 141 136 108 152 126 137 154 118 117 134 136 132 139 130 113 128 120 144 128 132 115 120 128 133 129 146 130 132 127 129 132 137 115 126 113 130 120 135 156 138 136 128 106 141 130 126 128 128 135 125 138 124 118 139 122 123 116 113 142 135 136 118 122 146 123 126 139 123 139 120 138 130 127 142 132 144 123 140 126 125 110 120 119 112 137 135 143 127 125 145 131 96 119 125 118 116 141 109 144 123 141 131 157 132 144 137 126 128 141 116 134 135 142 124 113 127 136 134 124 136 110 105 128 122 125 136 124 160 121 118 147 113 122 149 122 120 131 129 130 135 113 109 169 132 137 141 137 115 115 144 141 102 117 135 123 124 145 122 129 125 115 120 119 125 137 123 145 118 116 125 127 146 124 155 122 115 131 119 152 121 134 115 128 117 148 146 130 118 120 141 117 126 121 145 129 140 127 141 136 142 115 137 128 114 131 111 133 120 115 141 124 124 131 118 148 128 111 148 136 130 124 135 132 144 127 120 134 117 149 121 107 161 139 118 139 122 118 113 129 131 134 122 168 134 114 127 129 123 140 123 121 131 119 124 124 118 117 115 125 129 120 119 149 133 124 130 122 130 117 129 130 135 130 133 148 129 125 117 130 119 143 137 130 126 140 146 138 119 126 139 104 114 125 118 123 141 123 137 134 132 124 130 136 137 124 121 136 117 112 117 131 119 114 136 134 116 123 135 125 116 134 134 139 126 129 131 115 123 119 124 131 132 140 140 114 123 124 119 106 122 118 130 139 119 145 136 132 111 135 103 116 128 139 136 125 111 142 148 101 122 128 127 137 116 139 125 128 128 131 139 126 123 120 112 146 121 120 136 134 131 130 122 127 122 121 119 117 131 122 149 144 129 126 119 143 131 132 119 139 119 131 125 112 146 116 137 124 132 123 117 113 123 122 116 122 114 117 118 130 131 125 135 119 126 132 156 127 123 163 135 124 122 129 122 140 134 142 128 121 118 128 143 114 142 108 141 125 129 113 124 138 135 116 126 107 124 144 130 138 127 144 139 144 159 136 161 109 123 131 91 139 119 138 104 115 126 119 130 145 118 120 113 137 114 119 120 115 133 136 124 119 132 119 125 139 126 122 131 112 140 146 131 125 130 118 139 120 119 154 117 116 130 130 122 135 135 106 115 119 130 130 139 121 119 101 108 119 136 128 127 121 134 127 141 113 135 123 139 140 117 132 130 114 143 117 130 144 143 133 115 142 128 132 132 119 125 127 126 140 145 130 124 131 114 125 129 137 141 114 154 138 128 120 137 134 110 117 105 122 135 118 118 135 141 105 127 131 136 121 117 126 137 131 129 144 144 117 122 137 99 112 139 107 138 129 140 127 117 136 129 123 123 127 127 137 145 121 118 129 120 130 108 125 122 107 155 103 99 119 130 135 137 116 110 138 129 131 144 115 119 122 130 124 130 126 135 131 118 138 137 125 118 115 109 127 121 141 118 123 124 114 125 140 120 128 117 129 131 126 143 110 122 127 127 120 121 122 118 124 128 117 131 107 122 129 138 134 116 115 134 124 131 133 139 114 129 111 150 119 142 134 129 132 119 121 133 120 132 134 133 132 139 124 127 131 121 139 127 144 127 149 158 109 137 121 130 114 140 130 146 147 119 138 114 127 154 124 119 121 123 118 108 126 124 111 129 99 123 119 121 134 127 132 144 133 136 140 126 138 120 117 144 140 139 129 112 123 127 118 128 115 158 125 140 113 130 134 121 141 140 180 117 129 131 119 125 141 132 164 115 130 141 144 113 126 116 116 137 103 125 127 139 110 126 116 117 149 126 127 99 132 120 115 142 116 154 123 124 133 125 120 137 121 127 136 121 138 121 134 112 102 129 112 129 129 109 134 137 134 126 136 122 112 119 120 116 112 136 135 121 128 119 120 127 118 123 123 142 127 112 120 131 123 111 112 112 144 130 141 124 126 134 99 112 123 124 111 131 132 138 113 130 146 111 124 111 134 153 117 116 116 126 134 103 113 144 119 122 129 133 133 146 136 142 120 106 118 133 120 119 141 135 129 142 107 114 124 107 110 107 131 126 133 117 134 117 114 121 133 99 126 123 109 129 116 94 128 122 114 114 130 145 115 100 149 130 147 127 122 122 138 126 112 134 128 123 105 113 135 118 129 134 110 125 128 116 123 154 141 128 139 142 144 137 129 130 123 134 119 135 113 107 119 139 114 114 140 137 139 125 103 129 130 123 119 114 117 128 120 108 124 143 116 135 132 119 117 131 129 145 129 126 127 122 133 122 126 121 114 130 125 132 124 122 122 114 130 152 149 143 124 112 122 146 139 135 131 120 114 134 122 141 124 119 132 101 140 122 153 125 136 120 124 142 123 133 121 137 137 124 152 120 117 126 125 139 139 151 134 133 125 119 142 136 123 126 144 131 122 148 139 132 135 131 131 137 146 142 132 147 126 135 111 161 144 114 128 170 119 137 128 120 145 110 136 138 134 140 122 129 136 124 125 135 149 112 131 129 117 120 115 138 130 131 153 103 138 125 125 160 134 159 131 147 144 136 138 132 117 127 142 143 122 120 123 125 122 142 136 133 124 133 105 139 129 126 126 147 143 127 117 121 110 123 132 140 129 128 100 119 121 126 138 142 154 140 144 123 128 126 130 118 124 122 146 130 128 125 126 134 112 144 131 150 145 134 127 147 115 128 116 119 110 135 132 112 126 133 125 119 128 107 134 131 133 127 134 121 132 130 110 146 111 110 122 130 98 125 134 117 118 144 145 120 135 134 151 118 128 118 128 117 140 122 118 140 120 125 107 127 148 148 113 140 129 133 118 112 125 120 140 131 137 136 139 135 117 120 123 133 119 141 147 139 126 121 142 129 148 116 143 135 120 120 141 138 108 130 118 121 122 134 124 136 124 131 123 160 116 139 137 136 126 135 120 124 139 120 129 129 120 136 159 113 144 103 138 102 114 137 124 134 107 146 117 125 123 138 113 124 125 133 116 121 121 142 115 144 117 121 126 121 142 125 142 138 128 134 142 133 151 121 128 133 118 130 149 105 138 151 144 120 136 127 143 140 125 138 122 137 137 127 138 133 152 144 114 148 134 140 132 130 132 113 130 130 122 108 125 133 136 115 151 123 135 131 106 114 124 138 113 135 143 139 128 130 146 113 150 127 133 133 110 133 144 142 124 120 121 151 116 124 134 121 138 135 126 137 118 130 137 128 131 132 143 143 123 124 144 119 127 131 116 114 129 123 145 135 134 132 131 124 144 134 141 142 135 140 118 123 129 128 132 142 131 137 128 140 148 126 143 117 156 117 128 110 115 113 129 123 120 111 133 128 138 150 128 126 139 125 147 114 114 120 110 148 131 132 130 133 134 124 123 127 127 118 138 138 124 104 142 144 133 142 120 135 124 114 124 122 126 139 118 120 125 137 133 147 121 122 113 111 115 143 110 126 126 140 132 130 118 112 118 122 108 107 133 111 109 127 115 112 113 135 117 121 116 127 121 133 124 113 118 136 118 126 122 131 144 123 127 141 120 125 125 139 130 143 112 132 121 133 126 132 119 113 138 137 129 141 118 117 111 126 128 122 108 122 118 116 133 120 150 111 130 140 138 141 124 120 131 127 125 147 127 137 117 125 101 117 109 125 109 128 121 114 130 122 133 130 119 104 129 127 118 134 120 109 136 128 122 127 121 115 135 128 134 104 121 141 130 131 101 135 126 115 114 132 116 116 129 140 125 118 143 123 125 127 107 132 109 123 140 150 135 121 108 117 138 115 128 121 125 116 128 122 121 116 133 126 103 149 119 121 135 112 120 138 125 134 142 107 141 122 132 145 123 127 121 138 129 132 123 144 126 108 130 125 108 136 121 111 152 114 138 123 130 126 109 142 132 139 123 139 138 120 140 148 115 129 120 126 142 129 128 140 115 135 123 127 117 130 140 127 120 127 133 132 128 132 132 108 135 126 120 126 137 113 135 115 130 133 110 123 120 131 123 106 120 118 128 103 127 125 131 117 114 123 145 119 102 118 119 128 129 140 136 125 125 125 141 154 129 124 119 146 140 128 136 129 117 131 128 121 120 112 134 122 115 124 122 120 141 131 125 113 113 128 132 126 128 124 121 129 107 134 126 114 141 134 155 116 145 126 126 120 141 139 112 138 126 115 129 134 124 122 137 145 111 122 129 136 122 128 130 116 144 147 112 107 117 133 128 117 132 128 120 115 138 119 142 121 136 134 115 132 127 121 139 107 144 126 136 131 105 130 121 136 129 115 132 114 130 137 133 125 124 129 127 131 131 108 134 105 126 101 141 129 125 122 142 104 128 108 108 144 137 113 115 136 130 127 134 136 139 122 126 119 101 156 120 115 119 116 136 121 117 121 129 128 131 127 118 133 107 133 122 133 131 120 141 122 131 112 121 114 126 124 151 124 129 141 135 132 120 140 130 136 121 105 122 108 127 127 110 149 113 144 111 127 123 120 116 122 130 117 125 144 132 109 138 132 109 132 130 122 141 131 113 138 118 128 125 123 132 118 123 124 136 150 123 136 121 155 122 131 132 110 128 118 131 130 116 129 147 107 137 140 113 141 103 128 142 111 117 101 138 117 131 138 116 107 161 124 134 121 132 129 123 141 130 117 144 123 106 135 116 123 102 128 141 130 135 118 120 128 141 136 140 129 148 124 123 109 130 150 142 122 116 130 140 135 118 134 103 124 133 123 123 125 127 129 136 130 124 116 126 107 138 137 144 139 113 116 126 136 130 122 139 134 138 122 119 144 131 130 125 142 114 150 131 128 133 133 131 125 128 118 144 107 118 128 127 120 126 102 91 123 145 134 127 134 130 112 132 132 118 126 127 108 157 123 130 123 113 129 117 129 134 136 123 128 141 116 130 121 129 124 117 111 109 124 122 135 141 146 142 128 132 122 126 150 124 130 143 122 140 144 127 121 115 137 131 125 148 139 137 141 120 143 124 97 120 114 126 119 123 118 124 120 129 125 139 110 131 137 132 132 125 113 116 119 115 129 143 122 122 136 113 128 134 136 106 135 129 135 143 142 137 127 137 110 100 125 141 120 116 141 115 133 119 130 134 127 120 147 125 126 122 128 134 144 114 136 123 148 122 128 135 116 111 116 158 117 132 135 125 137 117 120 139 107 130 158 112 110 129 131 117 117 107 130 127 156 120 135 142 147 146 124 112 130 132 127 151 128 142 128 116 117 115 115 141 121 134 117 142 127 122 125 119 141 116 131 128 149 135 130 116 153 151 126 146 117 127 123 132 120 133 132 131 130 140 138 123 127 116 118 109 132 147 109 128 133 124 94 133 143 121 127 124 127 113 121 134 90 126 104 138 146 116 116 93 148 133 124 117 134 119 112 132 130 101 128 138 109 130 129 142 123 134 128 126 149 128 116 125 130 111 118 125 119 129 145 123 115 123 115 137 143 129 118 149 129 122 115 131 141 124 122 131 121 126 125 128 142 137 137 131 128 95 106 141 110 144 135 128 114 142 137 109 123 133 121 119 116 121 121 137 124 124 134 127 120 136 124 127 113 124 137 127 120 145 127 115 122 99 115 105 136 125 117 131 120 131 130 139 130 138 116 130 119 140 138 122 138 129 136 114 132 109 123 122 127</counts>
			</dataPoints>
		</scan>
	</xrdMeasurement>
</xrdMeasurements>