File: data/XRD/_misc/old/XG-700C/_absolute_2th-om_10-130deg_PIXscan_56min_3.xrdml
<xrdMeasurements xmlns="http://www.xrdml.com/XRDMeasurement/2.1" xmlns:xsi="http://www.w3.org/2001/XMLSchema-instance" xsi:schemaLocation="http://www.xrdml.com/XRDMeasurement/2.1 http://www.xrdml.com/XRDMeasurement/2.1/XRDMeasurement.xsd" status="Completed">
	<comment>
		<entry>Configuration=Factory configuration, Owner=User-1, Creation date=7/8/2013 4:01:53 PM</entry>
		<entry>Goniometer=PW3050/65 (Theta/2Theta); Minimum step size 2Theta:0.0001; Minimum step size Omega:0.0001</entry>
		<entry>Sample stage=MRD Cradle; Minimum step size Phi:0.01; Minimum step size Chi:0.01; Minimum step size X:0.01; Minimum step size Y:0.01; Minimum step size Z:0.001</entry>
		<entry>Diffractometer system=XPERT-PRO</entry>
		<entry>Measurement program=C:\PANalytical\Data Collector\Programs\Jorrit\2thom\_absolute_2th-om_10-130deg_PIXscan_56min.xrdmp, Identifier={15BCCF57-2807-42BD-B5B9-ECC0B3DC9284}</entry>
		<entry>Batch program=C:\PANalytical\Data Collector\Programs\SimonL\batch4x_2thom_10-130°_z9.1_x0,10,20,30_y0_57min.xrdmp, Identifier={EED9823A-2BEB-424C-9252-345C4EF2834A}</entry>
	</comment>
	<sample type="To be analyzed">
		<id></id>
		<name></name>
		<preparedBy></preparedBy>
	</sample>
	<xrdMeasurement measurementType="Scan" status="Completed" sampleMode="Reflection">
		<comment>
			<entry>_absolute_2th-om_10-130deg_PIXscan_56min</entry>
			<entry>PHD Lower Level = 4.83 (keV), PHD Upper Level = 11.27 (keV)</entry>
		</comment>
		<usedWavelength intended="K-Alpha 1">
			<kAlpha1 unit="Angstrom">1.5405980</kAlpha1>
			<kAlpha2 unit="Angstrom">1.5444260</kAlpha2>
			<kBeta unit="Angstrom">1.3922500</kBeta>
			<ratioKAlpha2KAlpha1>0.5000</ratioKAlpha2KAlpha1>
		</usedWavelength>
		<incidentBeamPath>
			<radius unit="mm">320.00</radius>
			<xRayTube id="1010048" name="Empyrean Cu LFF HR (9430 033 7310x) DK442154">
				<tension unit="kV">40.0</tension>
				<current unit="mA">40.0</current>
				<anodeMaterial>Cu</anodeMaterial>
				<focus type="Line">
					<length unit="mm">12.0</length>
					<width unit="mm">0.4</width>
					<takeOffAngle unit="deg">4.2</takeOffAngle>
				</focus>
			</xRayTube>
			<xRayMirror id="27010001" name="Inc. Beam Cu W/Si (parabolic MRD)" hybrid="false">
				<crystal type="Graded" shape="Parabolic">W/Si</crystal>
				<acceptanceAngle unit="deg">0.800</acceptanceAngle>
				<length unit="mm">60.0</length>
			</xRayMirror>
			<sollerSlit id="21010002" name="Soller slits 0.04 rad.">
				<opening unit="rad">0.0400</opening>
			</sollerSlit>
			<mask id="22030007" name="Fixed mask 2 mm">
				<distanceToSample unit="mm">220.00</distanceToSample>
				<width unit="mm">2.00</width>
			</mask>
			<divergenceSlit id="22010007" name="Fixed slit 1/8°" xsi:type="fixedDivergenceSlitType">
				<distanceToSample unit="mm">220.00</distanceToSample>
				<height unit="mm">0.19</height>
			</divergenceSlit>
		</incidentBeamPath>
		<diffractedBeamPath>
			<radius unit="mm">320.00</radius>
			<sollerSlit id="21010002" name="Soller slits 0.04 rad.">
				<opening unit="rad">0.0400</opening>
			</sollerSlit>
			<receivingSlit id="22010001" name="Fixed slit 4°">
				<height unit="mm">5.88</height>
			</receivingSlit>
			<detector id="7010017" name="PIXcel3D 1x1 detector" xsi:type="areaDetectorType">
				<phd unit="%">
					<lowerLevel>30.0</lowerLevel>
					<upperLevel>70.0</upperLevel>
				</phd>
				<mode>Scanning</mode>
				<activeChannelsEquatorial>255</activeChannelsEquatorial>
				<activeChannelsAxial>255</activeChannelsAxial>
				<pitchEquatorial unit="mm">0.05500</pitchEquatorial>
				<pitchAxial unit="mm">0.05500</pitchAxial>
				<readOutPeriod unit="seconds">0.135</readOutPeriod>
			</detector>
		</diffractedBeamPath>
		<scan appendNumber="0" mode="Continuous" scanAxis="2Theta-Omega" status="Completed">
			<header>
				<startTimeStamp>2024-09-03T20:05:39+02:00</startTimeStamp>
				<endTimeStamp>2024-09-03T21:01:45+02:00</endTimeStamp>
				<author>
					<name>PRO-MRD</name>
				</author>
				<source>
					<applicationSoftware version="6.1b">Data Collector</applicationSoftware>
					<instrumentControlSoftware version="7.0E 20130304">XPERT-PRO</instrumentControlSoftware>
					<instrumentID>0000000011142674</instrumentID>
				</source>
			</header>
			<dataPoints>
				<positions axis="2Theta" unit="deg">
					<startPosition>9.99826193</startPosition>
					<endPosition>129.99755682</endPosition>
				</positions>
				<positions axis="Omega" unit="deg">
					<startPosition>4.99913096</startPosition>
					<endPosition>64.99877841</endPosition>
				</positions>
				<positions axis="Phi" unit="deg">
					<commonPosition>0.00</commonPosition>
				</positions>
				<positions axis="Chi" unit="deg">
					<commonPosition>0.00</commonPosition>
				</positions>
				<positions axis="X" unit="mm">
					<commonPosition>20.00</commonPosition>
				</positions>
				<positions axis="Y" unit="mm">
					<commonPosition>0.00</commonPosition>
				</positions>
				<positions axis="Z" unit="mm">
					<commonPosition>9.100</commonPosition>
				</positions>
				<commonCountingTime unit="seconds">32.895</commonCountingTime>
				<counts 200 190 237 205 194 224 193 210 188 221 214 222 192 218 207 201 218 216 202 204 204 216 199 194 209 204 218 209 219 212 239 208 221 204 201 222 189 191 201 206 236 199 228 235 210 201 207 242 210 224 205 216 190 188 220 186 211 228 195 228 219 203 193 195 223 195 205 219 196 225 198 190 201 221 214 212 218 198 195 203 180 208 200 191 186 220 217 192 181 192 214 212 203 218 211 189 196 201 202 195 194 184 193 207 182 194 180 187 191 190 204 201 194 197 179 211 210 182 223 191 194 206 183 199 193 201 201 209 200 184 208 196 216 179 214 179 195 191 210 205 190 190 195 174 202 168 199 199 194 192 200 172 179 186 190 202 183 159 185 201 200 187 182 202 191 184 199 196 179 188 169 191 201 192 183 213 201 206 209 190 184 224 192 198 166 195 186 170 191 208 170 178 168 195 181 184 193 202 200 210 178 200 145 201 205 178 189 188 191 185 201 194 203 210 190 193 168 184 188 175 174 191 172 172 181 181 175 185 200 186 182 170 178 179 197 176 180 182 200 186 187 174 193 183 169 173 197 191 197 208 217 184 193 186 170 189 191 181 184 176 180 191 183 174 193 178 207 170 173 151 164 191 197 155 177 168 182 162 166 184 192 170 192 172 220 187 167 189 200 176 162 196 178 205 182 168 196 182 188 168 200 195 161 183 197 184 180 173 193 208 178 188 154 176 179 191 174 189 187 171 189 162 162 182 159 163 173 165 176 171 173 160 177 157 186 188 174 213 159 170 163 182 189 156 166 199 172 169 163 172 191 165 201 186 175 177 190 174 162 167 164 173 178 193 158 172 186 205 170 175 181 149 178 168 196 170 165 176 161 176 171 166 178 167 174 173 148 169 162 186 178 150 160 206 181 168 166 169 176 158 178 171 166 183 168 154 150 175 196 160 160 190 198 168 142 165 169 185 158 166 180 188 172 168 167 176 168 182 153 198 155 165 171 171 174 152 178 161 163 173 168 136 160 171 181 159 178 165 155 169 161 161 160 185 195 169 162 168 165 154 176 174 159 156 186 148 154 164 172 174 163 149 132 163 182 167 155 152 170 155 154 164 167 140 193 177 152 172 179 175 156 186 169 171 153 162 190 166 187 188 182 160 157 160 163 165 155 164 139 173 167 152 177 160 158 158 185 177 137 149 165 147 167 150 167 150 180 164 152 145 150 154 142 174 155 158 172 169 157 163 166 179 167 145 168 171 155 150 178 125 157 143 149 161 167 134 171 158 131 163 182 155 168 140 161 172 161 161 169 175 138 159 156 156 125 159 164 150 146 152 191 163 157 146 146 149 163 190 152 157 153 157 159 156 165 137 163 179 160 185 192 186 144 151 185 159 156 185 162 154 178 157 171 157 124 154 166 118 170 167 151 158 149 148 150 162 138 145 161 164 147 155 142 169 182 180 161 160 165 151 158 129 149 169 160 146 138 141 140 174 164 145 167 132 168 184 150 157 162 134 169 173 156 145 161 153 156 165 180 151 152 166 120 149 155 158 163 173 159 156 139 176 163 168 171 157 157 159 148 174 161 150 151 150 141 156 149 144 141 159 155 147 128 159 153 151 153 167 135 159 169 159 161 172 178 128 163 163 145 141 149 142 142 161 169 160 143 141 150 142 141 147 142 145 135 153 137 156 156 172 148 160 161 161 162 137 155 164 152 162 142 159 156 148 159 151 156 141 152 157 138 140 161 172 164 124 166 160 173 164 152 144 148 162 129 152 149 149 142 143 158 178 138 161 154 138 147 132 151 118 179 172 157 146 132 156 168 157 183 162 151 178 166 146 152 171 150 154 153 151 142 143 141 167 141 131 135 150 142 162 137 146 157 156 143 141 153 158 154 158 133 158 146 144 144 166 123 135 161 149 138 149 149 155 157 145 136 138 149 176 166 151 158 156 143 154 142 171 168 148 155 160 156 147 164 144 163 167 145 181 168 164 162 153 154 137 160 141 142 170 188 179 163 181 146 155 166 115 142 157 135 147 160 145 159 167 161 135 161 152 156 136 158 148 152 152 175 165 163 163 148 146 159 153 152 153 147 146 138 162 159 146 148 154 132 175 156 152 166 155 141 188 161 156 158 169 150 160 168 148 177 140 146 166 163 168 173 169 161 141 171 190 154 155 138 162 165 178 131 155 149 153 149 140 146 168 149 151 146 158 150 156 165 160 172 153 171 155 154 168 156 143 139 148 141 177 174 154 191 174 135 174 136 148 167 181 165 169 139 169 153 169 144 178 165 164 161 156 149 150 143 153 160 160 143 172 136 164 183 165 143 159 145 158 176 156 180 157 154 152 173 154 170 158 151 185 157 172 162 174 185 179 168 165 159 166 176 183 146 175 155 149 157 156 171 160 171 161 166 181 151 158 152 154 182 182 142 136 161 154 185 184 159 158 152 151 196 138 163 159 183 163 167 166 143 151 157 163 144 154 148 168 155 163 169 166 189 152 153 158 169 135 182 155 162 159 184 168 151 143 163 145 166 190 188 177 155 172 166 166 157 148 157 160 164 153 151 163 169 147 176 168 153 172 191 162 151 157 148 159 165 150 158 146 185 201 171 177 152 168 174 151 178 172 149 165 175 160 148 162 177 181 152 151 171 185 153 175 162 143 153 180 168 166 157 166 175 128 169 156 140 156 171 182 139 169 166 173 169 162 155 160 144 162 175 157 161 179 164 173 172 149 162 154 155 166 145 182 170 174 156 160 177 186 169 144 131 196 192 144 167 138 173 159 170 168 190 173 142 154 137 186 158 140 202 157 185 174 180 150 166 196 177 151 168 159 156 177 168 144 156 147 157 157 173 147 162 154 201 151 161 178 200 154 159 146 158 170 158 167 174 142 150 167 164 168 168 162 176 154 159 189 148 162 152 153 161 143 171 153 172 147 159 159 153 174 147 176 157 158 158 153 152 162 155 132 169 160 151 161 160 150 188 192 156 161 176 166 168 151 156 151 134 151 155 161 179 134 169 159 195 176 165 152 162 156 147 160 162 146 152 168 177 184 154 174 148 164 154 159 163 168 177 167 163 150 160 169 162 155 181 152 174 182 148 164 141 158 164 179 137 167 137 173 178 151 160 163 178 174 165 161 149 145 143 162 133 181 165 183 158 155 173 182 163 172 147 172 164 167 152 157 158 137 162 167 145 137 139 165 166 164 168 150 158 171 156 163 157 134 148 148 160 144 158 155 181 159 159 150 153 187 121 139 151 170 148 183 168 146 150 136 154 135 127 156 143 149 167 147 185 149 176 153 119 120 131 169 143 156 142 171 155 158 143 165 155 166 173 126 154 153 156 146 167 149 162 135 167 160 146 156 134 181 140 166 162 142 164 163 139 130 154 156 137 164 138 137 140 161 148 172 178 170 150 147 150 157 155 143 159 153 154 143 196 126 165 131 189 143 144 147 134 163 136 157 141 139 152 140 177 155 166 158 140 136 131 164 162 153 153 146 139 138 123 130 135 169 146 125 144 124 144 132 162 152 175 154 177 151 127 172 161 125 154 164 153 144 149 132 138 129 152 152 136 144 139 128 135 144 165 156 153 148 153 135 161 155 149 132 154 136 131 146 154 130 142 149 120 133 158 136 160 149 139 153 135 145 134 129 145 132 147 137 133 143 136 155 132 153 147 153 138 136 124 133 135 127 143 148 159 128 160 146 144 123 151 142 134 126 162 151 148 145 141 157 138 137 123 130 164 128 122 125 155 128 150 148 155 126 143 136 136 151 146 144 137 124 146 156 145 133 148 157 134 144 145 149 141 165 135 139 152 152 138 157 142 141 135 131 142 163 141 134 141 147 107 130 145 141 152 149 156 155 132 131 131 149 135 140 160 160 151 142 127 133 147 120 141 148 155 149 136 128 145 151 145 126 145 150 124 161 123 154 122 135 115 151 125 154 134 154 153 118 158 145 103 138 128 134 127 135 122 136 142 138 141 139 125 146 141 157 137 135 141 142 132 137 144 138 138 122 126 135 129 121 123 137 133 147 134 127 115 155 128 147 132 122 154 126 121 149 134 146 116 125 147 148 119 141 133 161 134 158 131 133 103 145 132 135 137 128 141 143 135 123 128 128 126 112 130 146 134 136 136 127 139 141 114 133 140 129 120 126 124 150 131 111 121 122 123 130 135 125 137 137 122 117 128 122 143 133 141 143 132 121 130 130 109 119 141 125 130 131 139 138 123 113 107 128 119 124 127 116 106 131 144 119 138 133 125 117 123 118 120 121 123 119 133 123 122 123 126 128 125 128 129 125 140 131 124 130 134 136 140 122 129 125 135 121 142 122 117 133 119 120 119 124 122 121 115 121 113 150 136 157 130 97 114 136 125 145 123 124 116 105 119 106 123 129 118 125 117 106 121 143 144 126 116 129 119 115 127 126 105 121 118 128 131 100 123 120 118 130 130 117 118 127 113 121 106 126 130 126 126 116 144 124 119 119 147 101 135 138 125 99 118 130 108 138 130 122 119 123 132 131 120 122 111 134 109 111 117 117 116 107 98 133 123 120 110 122 118 114 144 121 110 132 116 116 113 130 125 133 131 116 122 138 125 128 148 102 122 122 104 124 113 139 104 103 123 117 103 116 121 106 120 127 121 113 120 121 111 124 110 115 122 121 119 110 122 115 109 117 111 116 126 101 100 129 114 121 125 106 124 117 116 119 127 132 128 108 105 123 125 135 102 125 122 121 113 113 100 121 126 118 112 112 120 122 112 123 129 118 110 132 122 117 112 136 96 122 100 114 115 120 110 106 112 124 132 128 119 123 125 110 128 107 104 101 123 118 128 107 123 120 132 126 130 116 97 119 113 128 102 104 116 133 109 95 118 108 112 107 119 114 112 120 110 115 112 97 136 117 119 96 100 124 104 110 111 142 116 117 117 113 114 133 108 98 119 110 93 121 119 130 101 129 104 107 93 115 134 114 132 118 107 126 99 107 127 111 124 105 99 109 118 123 117 117 110 120 100 124 104 107 108 130 125 112 105 99 98 104 102 107 104 123 107 123 113 106 126 123 115 107 114 110 109 113 107 126 115 128 118 129 96 117 111 132 111 90 100 122 105 110 98 132 117 111 98 112 112 112 117 112 104 113 105 110 114 119 110 123 134 121 112 112 103 117 104 108 105 119 103 124 118 116 132 111 119 118 139 129 112 103 118 134 119 99 126 132 114 96 119 118 112 126 107 111 109 118 116 112 89 112 112 109 107 109 114 131 113 137 112 121 115 103 120 108 100 98 101 141 119 109 111 119 107 117 107 131 96 114 116 107 109 88 126 96 102 103 107 95 112 115 128 111 106 99 121 101 108 108 140 107 98 119 102 89 137 111 102 103 128 117 127 103 134 113 133 119 138 105 115 119 111 94 120 97 116 110 110 115 96 116 102 104 99 129 120 123 116 118 121 116 120 108 108 108 116 100 123 98 108 118 106 114 87 103 137 100 100 116 133 93 108 129 129 119 106 112 95 123 104 109 144 110 98 107 106 111 116 105 121 123 97 106 116 117 135 110 112 120 127 102 111 93 104 127 100 102 104 114 110 115 108 93 97 125 117 102 125 111 117 111 113 115 105 106 147 119 105 106 111 117 122 112 106 114 115 130 121 109 121 95 108 101 121 108 124 91 118 102 105 122 104 113 104 97 105 116 94 126 110 109 98 108 107 113 116 111 100 113 104 106 113 104 104 106 119 105 114 122 98 123 106 111 124 111 112 115 109 100 110 107 104 115 79 107 96 113 116 111 113 111 111 109 111 104 113 111 110 112 101 86 114 110 109 105 106 108 134 112 108 117 114 104 101 100 99 128 109 87 98 103 109 118 105 124 116 109 92 98 110 107 114 111 104 113 107 88 112 104 102 97 104 131 125 89 109 119 107 118 136 126 115 106 105 105 101 97 99 109 114 114 108 105 121 119 95 114 104 114 107 110 91 93 112 108 111 107 85 111 98 122 121 114 109 93 105 99 118 73 112 118 96 102 113 96 108 126 104 108 114 110 113 106 115 114 93 92 126 115 96 113 106 95 113 106 97 98 115 123 109 113 92 117 90 118 109 116 96 112 128 95 104 116 107 88 122 103 128 124 90 123 121 106 117 101 104 112 96 99 117 114 96 108 96 135 136 103 110 104 92 102 110 123 98 107 102 97 106 107 103 124 108 97 106 111 94 104 117 113 110 88 106 118 126 121 95 115 110 111 114 122 100 107 121 99 116 103 107 101 124 109 101 98 89 106 84 136 114 97 106 85 97 99 101 109 108 106 108 108 101 86 113 112 127 84 118 100 101 99 97 110 105 97 92 115 119 110 103 112 92 116 109 95 102 95 117 126 107 108 94 98 87 114 122 104 99 111 105 105 116 103 127 102 120 108 98 107 103 110 123 89 99 111 107 99 107 95 108 105 137 108 105 118 81 103 116 98 118 118 98 100 101 113 85 98 101 112 117 99 112 117 94 111 95 106 102 104 90 100 108 99 109 118 104 103 107 102 99 112 98 105 113 100 113 107 104 103 105 104 97 83 105 108 99 91 106 102 105 106 107 98 124 111 103 101 93 109 98 113 112 104 110 91 98 105 92 124 103 109 120 95 88 104 93 111 109 126 104 105 120 100 103 93 111 98 122 93 107 96 98 104 121 94 98 111 103 119 89 99 115 121 102 102 104 99 101 90 109 114 101 82 101 101 106 112 114 101 116 103 101 109 103 94 91 119 111 102 113 97 86 116 86 115 108 86 112 120 97 91 91 96 104 91 88 109 104 84 114 116 93 105 93 104 115 113 108 111 116 111 113 122 92 103 127 118 118 96 104 122 124 116 100 112 114 127 113 89 90 121 95 103 115 98 106 96 116 98 94 115 130 95 114 115 112 110 107 112 120 86 92 117 114 117 97 95 101 103 103 92 90 111 106 82 102 106 115 106 106 107 86 107 89 140 120 112 101 98 108 116 97 101 102 118 103 93 114 104 105 101 94 117 104 112 108 106 104 115 97 110 114 109 119 103 108 111 92 96 111 100 122 103 112 115 116 94 95 134 108 114 121 83 112 94 118 107 104 108 123 81 104 112 89 106 109 113 133 94 128 127 114 91 92 102 104 103 100 107 116 105 86 102 106 100 88 100 113 96 118 116 119 108 114 111 107 114 101 118 107 107 123 103 100 105 104 119 112 120 110 108 118 118 96 98 99 132 116 109 130 111 117 95 102 99 131 129 88 128 101 104 111 121 96 105 112 98 110 115 108 105 107 111 97 118 101 112 105 113 120 112 114 99 88 116 103 83 114 91 123 115 92 99 119 108 123 107 107 105 94 97 105 118 109 110 96 111 110 95 109 115 81 104 102 107 114 119 128 122 96 122 110 134 103 105 116 113 111 122 115 121 116 108 107 104 103 110 95 101 97 114 118 109 94 113 135 123 99 132 104 115 112 114 115 99 106 109 109 130 120 103 121 130 108 120 127 116 111 104 101 114 126 112 109 110 113 132 120 139 98 92 114 105 123 117 117 120 118 119 113 131 96 116 112 134 99 115 114 107 115 127 133 112 103 101 121 135 119 109 135 119 99 116 116 117 117 110 111 105 101 127 106 122 110 130 125 128 117 123 136 126 121 120 133 107 136 116 129 113 105 113 124 117 144 130 112 139 113 120 113 91 124 115 126 120 100 141 120 115 104 122 107 136 118 119 146 138 110 123 119 120 119 120 112 138 111 104 108 119 123 131 109 131 132 126 116 121 124 124 147 140 128 113 113 133 127 115 127 126 132 134 120 132 138 133 134 156 142 109 138 139 140 117 129 157 155 128 129 146 128 166 157 145 138 138 150 146 177 160 175 180 159 135 178 198 205 197 198 182 202 180 191 188 202 209 194 202 216 203 171 197 166 184 182 178 165 174 157 165 161 161 168 150 151 156 154 151 140 154 137 157 132 175 144 138 127 131 141 142 140 126 141 125 129 135 125 119 120 125 107 125 108 136 114 124 130 125 99 115 117 128 129 118 114 134 99 123 101 127 112 97 101 114 110 116 110 118 114 109 103 137 119 120 146 95 125 117 115 127 106 123 126 106 121 99 99 110 103 120 118 92 121 108 94 91 110 108 106 115 110 121 113 109 106 136 107 123 116 107 111 105 101 98 113 104 100 116 122 111 112 116 103 115 98 125 131 82 111 126 110 106 108 106 130 111 103 122 121 97 90 98 106 114 112 116 115 119 107 109 114 115 115 116 104 110 122 113 103 91 101 136 115 107 103 135 114 115 118 112 105 82 109 124 98 91 121 99 113 99 105 112 127 106 104 109 132 108 113 108 106 104 107 125 95 112 110 116 118 103 113 107 108 122 100 111 101 112 102 108 117 103 118 111 113 91 118 109 119 105 90 130 117 98 105 115 96 102 117 119 132 117 125 133 121 98 109 110 103 113 115 99 124 100 106 100 96 107 120 124 114 101 119 96 119 120 130 116 96 116 103 126 105 99 110 141 109 118 109 123 108 122 109 113 96 111 102 105 111 89 97 115 109 99 113 124 127 112 112 121 119 106 115 105 102 102 121 100 105 125 96 96 109 117 112 102 104 98 98 96 88 127 124 109 108 100 109 108 105 109 107 122 103 117 112 124 103 96 134 110 111 96 118 118 107 102 105 130 100 133 103 109 126 109 121 114 95 109 111 91 110 111 112 120 118 112 114 109 130 109 105 116 108 116 96 124 111 88 120 119 109 101 128 110 94 119 135 104 124 121 103 122 133 115 117 123 107 108 101 113 111 99 125 113 117 83 115 110 103 107 119 120 112 119 123 111 116 113 101 126 110 116 99 96 117 120 98 115 109 120 103 126 106 107 114 114 99 101 97 112 117 97 115 118 100 91 116 108 99 92 102 99 120 127 109 123 106 109 108 101 123 116 105 106 120 106 104 117 123 118 118 137 115 123 106 111 107 99 103 117 91 122 105 95 114 108 108 118 88 113 92 112 118 104 141 122 105 129 112 116 99 119 116 125 113 100 111 88 104 114 103 118 103 102 127 105 103 121 112 121 111 119 111 121 108 100 109 130 119 113 107 101 96 98 111 106 120 122 104 97 120 106 127 128 117 107 120 129 115 99 120 100 118 113 111 95 112 125 106 116 117 102 108 102 108 120 92 103 119 115 110 122 115 111 95 107 121 124 116 118 130 113 110 127 109 97 107 107 109 107 109 113 111 104 109 117 108 98 113 87 115 105 127 105 109 114 109 117 111 113 89 108 109 114 115 117 113 116 103 99 118 101 114 96 97 100 88 118 115 110 113 124 122 111 114 113 103 110 110 100 114 108 121 112 112 124 103 108 105 120 122 107 100 108 122 107 122 109 104 111 113 119 112 102 129 108 93 92 99 127 103 114 108 103 120 119 95 136 99 129 96 103 129 90 103 122 108 105 109 102 109 100 114 106 110 108 103 96 92 108 103 112 105 112 106 110 117 99 102 105 101 115 118 114 108 102 98 110 109 110 138 118 93 108 101 126 99 117 115 85 108 111 123 120 107 130 89 124 108 117 116 117 114 105 109 120 102 114 108 113 104 110 97 120 104 118 117 104 115 105 111 98 118 108 117 121 117 118 127 131 107 126 116 133 100 114 111 111 116 107 118 116 94 113 119 140 108 102 118 120 115 129 118 96 105 119 124 107 114 102 95 102 116 115 108 111 113 116 115 105 125 96 108 121 125 109 128 127 103 101 105 114 105 110 118 110 108 118 118 116 106 118 107 129 112 107 124 115 120 120 125 99 133 114 95 122 115 125 115 108 117 115 122 131 117 120 112 108 114 114 102 85 107 86 102 108 122 122 112 128 99 124 132 112 98 119 125 110 128 121 114 94 135 125 140 109 121 115 104 121 121 137 128 116 99 141 93 112 108 105 113 105 109 112 97 113 112 114 117 125 109 108 134 126 116 119 111 122 121 101 120 125 117 106 136 121 94 124 110 113 92 118 96 132 109 134 109 105 112 123 108 90 103 116 121 94 112 115 114 126 127 101 104 107 113 105 122 112 108 110 107 120 108 115 99 106 133 124 118 135 125 116 118 114 105 118 119 114 112 114 115 133 108 97 103 131 111 113 113 125 106 121 109 116 121 124 142 102 123 109 121 105 131 110 102 126 122 128 109 125 110 115 128 128 119 114 117 122 124 128 102 105 125 114 110 107 116 127 137 119 113 132 112 109 110 131 133 114 115 105 123 109 128 126 109 132 117 103 106 115 136 114 130 94 95 120 117 124 114 112 98 122 119 146 131 113 119 118 127 113 108 110 123 121 100 124 108 107 120 131 122 114 114 129 113 118 140 106 116 111 124 122 120 104 108 98 121 106 109 109 96 97 114 114 132 130 113 116 127 135 129 109 112 124 108 130 124 116 127 106 120 103 96 121 118 120 124 89 121 114 114 103 121 134 116 116 116 102 135 126 104 90 119 130 108 129 121 102 109 126 142 115 109 122 97 81 100 102 111 110 95 129 124 108 144 95 116 126 117 135 106 114 122 117 108 145 124 112 123 102 120 104 130 102 93 117 130 108 112 120 104 122 106 109 117 108 117 115 120 118 109 115 114 128 115 110 119 141 118 118 113 133 116 121 145 122 115 107 113 123 114 127 104 113 131 118 131 109 137 100 126 121 145 113 138 120 112 101 111 121 112 139 113 110 111 126 92 117 130 113 102 136 109 116 96 117 103 122 123 118 111 121 120 107 127 97 117 104 110 126 123 118 124 109 108 110 106 110 128 113 130 128 121 125 109 117 112 117 115 128 128 124 117 123 123 114 134 125 106 106 120 131 111 161 128 100 118 114 120 109 130 121 109 125 119 138 132 122 133 121 116 120 123 122 138 143 116 115 100 122 112 112 123 138 106 101 132 116 117 131 110 120 95 115 121 115 129 106 107 121 111 127 112 126 138 92 95 120 123 119 110 126 130 100 146 119 133 117 117 118 106 109 125 115 99 91 110 138 112 128 120 118 122 100 119 131 108 108 105 119 110 109 93 112 115 127 122 123 122 138 117 127 139 134 117 111 119 125 121 131 118 117 131 118 111 119 108 109 115 116 107 102 113 105 113 136 118 125 109 125 119 111 122 120 119 112 112 129 106 115 137 124 122 93 123 115 123 117 128 133 116 131 117 118 118 128 111 124 107 120 121 119 122 120 127 128 114 122 129 103 118 117 122 121 112 109 128 123 122 105 122 109 102 118 136 109 105 100 125 126 132 140 126 114 109 115 117 98 110 127 119 98 134 103 113 108 133 126 115 118 129 127 154 121 130 124 134 124 116 130 136 118 111 114 109 119 131 135 112 109 103 110 131 126 133 138 98 119 132 127 116 116 128 102 146 95 125 117 122 128 127 123 122 113 133 109 136 108 107 120 135 101 118 111 134 116 133 146 110 97 129 108 112 127 114 117 130 121 119 125 112 139 118 118 138 133 112 111 106 125 126 146 122 139 110 141 120 122 142 142 126 124 127 127 111 113 125 141 121 120 132 121 117 111 117 122 97 106 116 113 122 107 105 140 129 131 127 104 121 104 127 134 137 150 135 129 112 127 112 143 120 117 123 137 144 125 128 120 126 117 135 122 124 120 129 109 111 128 114 128 108 118 110 133 107 112 109 122 138 111 120 135 138 117 114 115 147 119 111 125 121 128 113 119 112 113 126 118 134 125 117 128 133 128 132 113 123 117 100 140 114 127 114 102 95 109 132 129 135 126 138 125 124 125 113 134 113 129 132 110 118 94 107 128 136 106 121 133 131 151 134 124 122 113 116 131 133 131 107 120 116 122 121 112 114 147 118 114 122 108 102 114 132 118 127 121 110 125 113 123 111 127 138 117 121 131 116 130 134 111 119 117 135 124 113 125 115 130 112 135 129 125 139 113 130 125 125 134 133 125 112 122 122 146 135 130 127 131 117 125 115 145 118 127 122 124 132 121 114 137 113 135 122 120 122 138 123 108 153 146 126 117 120 116 111 120 108 120 121 106 116 119 99 126 127 119 132 136 110 127 111 128 113 114 116 127 120 134 112 110 120 118 136 105 127 137 117 130 123 128 116 128 129 110 112 111 130 134 116 120 111 128 140 114 111 152 136 135 119 139 103 112 108 123 129 128 113 125 104 130 123 120 111 117 130 105 109 125 124 98 116 129 106 141 124 127 125 136 127 118 106 121 138 134 144 116 127 120 116 111 115 126 138 121 119 126 139 127 129 148 121 116 126 135 116 108 133 120 135 149 115 108 124 113 143 109 109 115 130 139 126 131 145 109 127 123 144 128 130 101 111 122 132 139 150 112 138 111 121 124 125 134 133 111 132 130 125 140 129 108 109 133 122 105 124 148 135 106 150 142 133 119 121 138 130 133 134 134 130 120 140 128 127 129 123 125 131 129 112 135 139 112 119 138 127 134 124 140 140 149 131 127 131 136 133 128 125 136 137 116 113 125 129 118 100 135 119 113 117 136 128 140 141 125 131 115 101 112 139 150 133 136 138 119 144 133 119 129 129 118 114 152 143 135 127 134 128 136 137 144 132 121 115 120 118 147 121 129 120 150 128 154 147 138 134 139 125 143 128 127 121 129 122 121 111 126 136 119 104 124 118 119 120 131 116 120 138 133 126 128 98 153 109 122 123 156 130 138 133 119 107 147 147 129 127 141 117 136 137 131 129 119 120 136 137 123 116 130 124 132 125 120 168 126 126 113 133 133 149 129 130 136 123 120 149 136 118 119 142 122 116 137 111 111 129 147 131 136 117 120 113 117 132 116 125 134 140 114 127 130 148 128 123 127 126 132 132 120 125 116 120 116 141 134 147 120 112 129 113 133 109 128 129 138 139 127 109 126 115 118 123 130 131 115 103 119 125 105 100 118 108 120 127 121 127 136 134 122 117 120 125 130 130 133 119 130 125 125 124 149 140 116 116 140 118 122 112 124 123 136 128 124 119 125 113 119 127 136 148 134 151 127 121 108 138 135 131 133 132 125 139 130 112 123 112 125 126 120 123 117 109 137 133 131 120 134 122 124 126 117 138 140 125 128 144 143 118 145 125 122 107 144 122 109 124 133 110 124 121 119 129 117 151 114 150 104 124 162 161 133 128 119 116 122 123 90 109 158 123 134 146 119 130 123 129 108 120 123 120 121 114 119 125 109 132 112 131 125 111 127 109 134 138 127 127 131 130 109 122 126 115 117 120 132 133 130 112 139 124 143 125 134 119 113 136 132 128 141 127 124 118 119 119 133 135 137 128 115 153 118 126 112 143 136 109 117 133 138 131 138 137 155 124 123 135 115 125 121 125 132 133 126 120 130 127 126 118 114 128 132 134 116 127 128 97 132 134 141 149 147 124 134 123 129 111 120 124 137 130 121 121 136 120 118 126 139 117 137 128 110 124 125 110 105 124 132 131 134 122 122 127 114 126 122 127 134 135 124 124 117 134 124 134 129 111 121 127 150 120 119 127 135 113 126 120 141 120 117 153 135 139 123 107 109 134 120 116 136 127 140 132 127 122 124 137 138 127 124 110 120 125 134 129 144 129 133 124 128 126 135 125 148 117 111 115 116 116 138 119 142 101 126 116 135 145 121 149 136 104 134 113 130 124 147 122 123 138 113 126 114 128 121 111 143 127 136 126 135 119 121 112 116 127 156 116 130 131 125 121 127 125 125 143 120 124 130 132 136 116 129 108 141 114 115 123 129 114 91 128 138 86 132 130 127 134 119 110 118 133 124 161 130 139 128 113 127 123 111 104 108 146 133 113 125 118 123 116 121 117 123 128 148 135 128 122 125 123 137 129 110 129 128 143 123 118 118 126 132 113 134 107 130 122 110 147 110 127 127 110 128 127 132 141 144 129 130 121 150 113 121 133 124 130 106 114 114 124 120 126 127 114 129 128 115 120 113 129 123 129 125 108 113 130 124 111 126 126 129 101 122 114 134 128 114 122 126 126 129 110 113 139 132 114 125 127 138 114 127 116 109 131 136 117 124 133 123 127 127 140 140 107 136 138 136 120 118 124 126 144 138 125 149 123 127 115 137 126 108 120 148 111 119 117 134 131 135 127 119 156 138 141 118 114 130 123 122 141 117 123 123 118 97 116 119 124 115 136 108 127 117 115 135 105 135 118 126 133 114 125 135 119 131 129 126 118 131 148 126 125 135 144 126 125 116 134 120 136 133 106 131 121 123 117 121 138 128 135 135 126 119 146 145 125 156 111 118 132 114 129 129 124 113 132 112 99 125 116 125 112 129 107 138 114 138 108 128 131 134 133 114 118 124 133 112 137 131 122 138 121 129 112 129 103 130 150 112 123 109 122 135 144 116 108 143 114 137 115 151 117 120 129 113 110 128 121 118 144 113 130 123 121 104 107 131 128 131 167 123 107 118 102 129 140 122 127 125 129 132 103 133 104 117 108 118 115 127 122 114 158 140 104 117 123 122 147 130 117 119 131 138 126 113 131 136 118 131 109 123 122 123 146 122 131 111 133 112 105 112 126 98 140 151 118 127 124 140 123 113 89 142 110 130 114 117 119 134 120 126 133 126 130 110 117 129 116 142 128 120 126 137 123 132 136 131 116 117 117 122 120 127 134 112 111 113 161 148 125 124 136 134 125 130 135 122 127 129 133 147 119 117 123 127 111 109 141 108 117 110 129 104 114 125 129 140 126 132 113 124 128 140 140 128 112 109 135 144 110 127 149 119 123 120 123 110 137 116 119 135 137 126 140 105 132 131 122 101 112 117 120 128 121 119 107 134 123 111 140 132 116 120 118 131 127 132 113 131 131 120 111 128 132 118 117 148 128 145 136 121 123 115 109 125 127 136 122 132 128 119 147 123 113 118 138 131 131 127 124 124 137 107 122 125 120 121 145 120 116 141 141 114 127 136 120 124 119 118 136 130 135 141 123 132 133 108 132 122 116 124 120 116 110 118 111 112 135 120 112 111 128 127 108 132 112 120 123 130 123 132 116 127 127 128 127 124 126 120 121 127 128 112 122 139 124 138 124 115 163 118 123 131 111 138 115 110 122 128 115 128 102 120 123 138 108 120 110 127 115 125 103 102 139 122 119 130 129 121 141 117 118 115 140 111 128 140 132 131 123 122 134 118 131 150 149 117 131 125 124 120 132 123 122 116 106 111 112 121 128 114 136 122 119 130 112 119 129 101 122 124 125 139 110 112 129 126 109 112 120 121 112 112 123 132 124 134 114 119 134 114 120 137 143 132 126 115 132 119 107 125 131 133 107 117 115 134 124 138 117 127 110 125 111 125 114 128 107 132 140 119 101 134 130 136 125 127 113 124 121 142 123 119 129 138 118 130 127 129 121 129 112 134 123 131 123 114 144 127 118 127 139 123 122 123 131 118 109 108 113 111 137 107 113 107 106 121 118 99 109 112 103 122 135 120 102 146 124 128 111 124 129 151 146 101 133 122 111 128 121 133 114 103 126 120 123 125 119 121 148 119 133 102 115 113 123 128 115 117 120 132 101 122 130 109 107 127 136 119 129 153 126 121 163 136 130 111 129 116 123 126 132 118 112 118 112 114 111 122 120 127 130 127 128 126 120 122 120 116 140 106 111 114 125 126 121 117 123 121 112 128 114 133 119 134 132 131 140 106 141 142 112 118 116 124 103 99 120 130 108 117 141 128 117 113 133 118 105 134 119 132 117 126 117 126 124 127 135 132 129 131 143 125 110 132 132 122 138 128 136 130 143 140 119 118 118 123 135 122 114 129 122 121 136 121 117 133 124 131 104 116 106 138 118 134 138 110 149 96 124 129 126 123 124 118 121 127 102 107 116 123 118 140 115 123 136 125 129 127 130 122 120 118 115 110 126 119 132 112 120 135 130 145 122 140 111 127 125 126 137 140 129 124 145 125 148 118 132 116 137 115 136 135 116 121 122 139 134 124 136 148 139 125 120 116 150 118 103 110 126 112 140 112 124 126 133 130 132 110 116 149 124 113 112 136 117 121 114 116 115 119 128 112 124 111 137 129 116 141 117 89 127 123 108 146 122 124 134 114 117 119 147 136 105 131 131 121 124 107 122 112 118 100 119 117 128 115 136 136 131 126 130 122 109 130 122 132 138 127 128 132 121 125 134 124 136 117 132 114 114 132 118 129 131 121 129 119 124 103 108 142 122 117 142 149 119 138 130 130 124 132 116 115 121 151 131 119 131 145 124 142 143 120 116 117 116 117 136 105 131 125 139 123 133 116 132 142 130 112 154 136 155 112 114 114 139 119 120 141 136 119 112 115 135 126 130 136 101 115 102 108 139 132 112 142 127 116 126 114 136 110 115 140 138 124 136 124 139 106 140 128 129 127 113 119 122 132 148 116 128 143 139 107 108 120 134 149 104 121 116 119 119 142 135 143 141 130 115 135 119 144 130 133 138 114 128 129 122 124 126 141 129 119 133 133 125 138 167 131 117 125 138 132 114 137 144 124 152 131 152 116 138 141 154 127 121 128 142 158 132 159 142 159 152 152 149 139 125 134 112 141 160 156 123 126 151 138 142 134 138 141 137 123 137 151 132 165 149 123 141 155 140 126 146 116 147 144 132 138 127 145 144 138 134 137 119 148 152 108 140 136 144 131 140 148 135 142 121 144 137 140 149 110 126 128 116 135 106 135 134 111 134 128 123 129 138 136 117 133 148 120 137 132 126 139 118 123 106 109 138 126 130 116 123 148 106 144 124 113 115 108 134 141 121 148 122 127 126 126 116 124 121 124 123 109 118 111 127 110 131 118 119 100 128 116 132 107 120 104 135 132 129 121 111 138 125 124 117 110 132 130 110 122 109 118 131 123 113 124 117 118 121 121 108 130 127 119 116 136 122 131 118 120 119 136 123 137 120 123 117 112 118 147 131 125 137 111 130 112 126 110 131 124 95 115 102 117 131 119 123 127 115 122 146 102 127 127 109 131 127 117 118 125 145 111 115 114 131 113 106 125 142 139 133 120 107 114 113 115 111 120 116 137 132 127 123 140 122 125 121 142 118 118 106 137 114 105 114 113 116 129 134 131 118 108 114 134 133 117 119 108 133 120 128 127 150 128 107 124 123 117 131 103 127 127 121 118 120 114 130 116 113 142 104 139 112 124 145 125 127 128 112 134 129 151 120 132 115 136 146 120 129 127 116 128 117 126 107 134 138 115 120 126 113 115 112 127 118 139 115 139 130 143 109 118 114 131 109 134 130 124 117 148 111 125 105 129 136 130 127 134 146 142 114 126 124 128 139 128 124 125 117 121 127 124 106 123 139 115 106 117 108 116 127 126 137 101 133 132 126 108 127 129 112 113 129 125 136 106 115 136 122 131 122 107 120 143 104 134 125 128 123 106 123 120 121 102 128 123 106 111 110 140 123 129 145 103 114 132 137 121 125 116 115 123 130 133 152 124 126 120 129 114 109 118 133 120 125 129 116 123 117 112 122 129 126 129 130 112 128 109 121 113 111 138 134 91 114 128 119 124 136 107 118 134 117 101 125 131 109 117 130 117 110 122 112 141 126 122 121 113 120 118 113 125 127 119 104 127 125 116 104 114 105 123 109 147 105 126 129 122 109 102 107 128 127 112 117 110 129 120 109 117 130 108 135 126 118 143 143 115 125 117 124 121 121 133 124 112 104 130 113 135 123 121 111 104 112 105 137 122 132 119 140 128 123 114 122 108 115 130 116 123 124 121 127 125 125 112 134 111 112 88 112 131 124 118 103 141 113 108 123 124 137 127 132 118 111 125 106 134 143 114 117 132 121 110 118 108 135 112 112 116 117 125 140 125 118 124 114 115 118 124 120 120 121 110 128 106 133 114 131 120 113 122 132 112 107 147 121 135 127 101 128 106 142 125 111 129 112 147 125 119 130 122 126 118 118 124 124 133 110 128 116 114 127 127 117 110 134 106 131 128 108 114 119 121 143 121 137 142 128 115 109 108 113 113 135 109 136 119 122 131 104 118 101 119 110 112 126 131 104 112 117 116 113 127 109 106 119 97 117 101 137 119 130 113 120 142 109 121 112 122 129 113 119 103 127 117 120 133 118 131 115 97 124 112 122 129 117 125 105 117 132 111 128 129 130 133 126 128 124 138 130 123 118 141 151 115 137 137 126 118 115 132 120 112 117 121 121 109 129 127 113 108 128 118 136 132 120 113 122 133 130 116 136 116 137 109 139 119 124 141 132 101 133 126 130 104 113 105 125 102 125 110 119 136 150 135 133 123 131 101 120 127 109 118 113 147 143 139 108 125 129 124 136 104 114 124 119 98 126 104 124 105 110 108 115 129 133 120 109 127 128 135 138 134 125 122 123 142 137 129 137 138 113 118 141 139 102 111 108 121 111 139 128 113 106 142 121 119 118 127 121 139 124 126 129 111 115 108 113 118 153 129 115 117 96 109 143 132 143 140 112 119 108 113 104 130 117 131 107 120 125 117 125 109 109 123 118 133 100 131 132 135 112 122 139 118 108 128 112 124 125 128 117 124 125 129 120 134 136 111 118 120 132 130 149 131 120 115 102 119 133 139 121 118 129 118 118 122 145 141 106 100 113 132 105 124 113 135 119 116 122 100 127 144 119 121 113 96 120 111 109 123 105 117 117 141 134 127 123 105 122 126 121 108 120 116 109 134 120 109 119 142 140 112 108 131 126 121 112 125 115 125 125 122 121 133 131 114 130 127 117 112 118 131 104 113 120 138 115 142 128 140 121 128 128 124 123 110 142 108 141 114 112 118 128 126 130 123 114 136 110 108 107 135 109 113 119 124 133 148 118 133 133 97 121 113 123 118 137 111 141 114 118 131 137 111 122 131 122 112 103 127 132 134 143 115 115 115 135 109 144 107 104 113 113 121 120 111 113 122 116 129 122 119 111 124 129 128 121 101 101 134 125 120 131 124 111 123 132 114 118 135 98 117 97 115 131 119 148 116 108 115 114 136 127 128 105 121 114 119 128 106 98 133 124 117 120 129 109 139 133 133 134 107 136 135 127 111 141 142 100 142 117 129 114 116 128 130 119 117 96 117 137 111 147 123 117 119 110 131 132 139 130 125 108 103 112 116 116 101 134 119 111 118 127 131 129 117 109 105 130 126 109 155 132 126 111 112 137 121 123 147 125 126 108 143 103 130 132 122 138 129 123 106 119 107 123 138 124 119 141 135 119 119 110 123 121 120 133 129 124 123 122 109 125 119 116 110 117 123 137 104 141 126 115 106 142 109 118 123 111 127 120 106 123 117 130 116 139 146 132 118 130 114 121 126 136 130 139 128 153 103 120 115 124 132 126 114 124 124 134 138 132 128 142 122 130 114 130 134 105 102 112 144 123 122 95 124 141 124 124 130 131 134 105 115 118 128 135 99 131 123 127 140 130 126 131 112 124 131 142 118 128 134 122 103 118 117 100 118 142 122 116 122 130 107 119 120 128 157 109 102 133 117 101 133 115 126 114 126 101 130 135 126 132 121 137 128 124 114 142 110 115 135 136 129 138 123 113 123 123 128 130 127 112 121 132 116 124 103 117 138 114 113 127 144 119 127 121 133 120 132 114 121 149 113 125 125 142 137 127 124 123 127 132 117 126 136 119 130 116 133 143 117 116 124 110 116 127 129 139 111 130 120 119 98 131 126 123 117 122 125 113 131 111 124 126 126 111 136 142 137 106 113 112 114 108 126 118 123 113 133 117 139 112 102 112 116 128 123 130 117 105 125 128 120 111 128 144 106 123 145 120 110 119 109 118 138 134 94 125 128 135 144 137 120 104 117 118 107 117 136 129 113 128 138 127 124 119 133 134 135 123 133 127 123 130 108 116 113 117 104 116 131 107 103 130 146 99 119 126 121 150 122 97 134 112 131 122 112 112 108 104 127 117 127 136 96 109 121 132 118 136 100 123 124 118 125 137 125 135 126 115 123 140 124 122 127 134 131 128 131 142 117 129 126 141 123 127 147 141 140 129 119 121 112 111 104 145 115 131 129 118 133 130 121 104 115 109 114 117 104 106 123 126 127 142 122 127 130 112 122 129 136 147 106 116 115 118 125 117 110 137 105 134 115 127 129 129 104 103 109 113 122 115 117 129 142 106 97 124 121 127 114 134 105 133 121 132 125 103 113 121 116 122 129 122 128 135 121 118 133 118 102 114 137 138 95 115 127 134 117 151 122 132 111 127 120 116 107 127 121 118 115 137 142 106 125 124 138 119 127 123 141 112 115 126 128 104 119 129 120 116 134 114 128 127 131 127 137 126 116 127 131 146 129 141 113 130 130 131 124 136 123 138 128 131 115 129 117 110 127 127 108 118 114 87 127 135 117 117 127 120 117 149 116 125 125 121 124 138 138 145 149 124 115 142 124 141 135 131 126 115 128 128 123 117 141 121 107 129 134 137 117 119 125 108 115 141 115 116 101 130 124 115 133 105 126 115 123 123 126 109 136 113 130 120 113 107 129 127 118 137 119 130 124 122 126 118 135 101 111 117 112 121 121 114 107 121 131 138 118 115 110 116 117 126 110 109 139 121 113 120 128 112 141 118 112 108 139 117 122 107 124 129 126 112 128 109 115 115 114 119 112 134 114 147 128 126 125 133 122 123 122 126 108 111 109 119 133 110 114 101 110 109 128 143 134 129 103 109 118 118 113 114 125 118 106 109 108 97 128 108 121 110 122 115 123 108 111 130 123 124 113 120 120 109 109 115 126 120 121 121 125 126 113 117 100 114 124 119 123 106 143 128 132 119 126 129 119 125 112 113 98 125 125 119 117 98 154 111 97 137 119 119 118 118 124 113 110 117 120 107 101 110 125 129 142 126 125 102 143 128 110 103 139 124 142 123 121 114 121 119 118 123 96 120 129 123 130 130 124 120 121 109 98 145 113 130 123 116 121 127 124 140 121 108 127 128 116 124 125 125 129 102 129 114 126 137 126 128 110 134 121 136 122 108 126 129 132 124 119 143 118 117 103 124 115 130 124 111 126 129 128 135 126 124 126 116 126 108 129 114 118 112 125 129 113 103 111 108 128 105 113 127 106 137 126 132 137 132 116 126 116 136 124 100 111 109 129 131 120 109 153 110 109 104 137 130 121 115 113 127 109 113 127 120 132 109 123 110 131 134 108 106 116 127 123 119 128 123 122 115 132 109 114 96 113 134 125 116 120 131 141 109 111 120 118 127 123 109 115 113 114 116 122 142 133 127 127 121 120 125 118 116 143 112 104 117 112 110 124 133 131 118 132 112 139 108 111 134 127 108 91 123 100 104 127 127 106 90 133 116 127 136 99 122 115 119 120 118 111 131 122 113 123 121 118 130 124 117 113 115 131 125 122 114 125 133 119 125 120 118 125 136 113 126 122 117 135 106 117 119 111 121 131 107 121 137 124 102 135 124 109 107 118 125 111 141 140 132 115 117 141 136 115 138 115 122 116 120 126 138 120 129 119 128 113 115 117 127 147 132 118 121 110 128 119 130 98 129 112 130 131 116 125 114 124 102 120 115 114 102 136 106 113 141 131 130 115 104 115 116 114 100 124 113 114 111 131 110 114 115 137 105 124 114 118 131 123 127 108 113 114 116 130 128 114 109 133 103 107 122 130 137 146 120 105 113 113 100 111 116 139 140 124 132 133 122 119 121 104 132 122 115 123 111 111 130 122 140 97 112 113 125 114 118 108 126 112 114 109 105 137 91 127 137 113 115 116 111 123 106 107 128 127 126 102 117 102 105 117 106 127 130 114 136 121 128 124 107 120 98 114 119 127 118 120 129 132 127 122 108 120 140 116 127 124 139 125 127 141 120 146 143 136 125 131 120 133 108 118 129 122 112 108 130 131 119 121 135 135 130 146 113 119 113 138 108 101 130 129 114 145 105 113 115 127 135 118 128 106 141 109 118 124 125 122 128 119 137 100 121 116 117 124 117 115 124 127 131 129 118 122 124 114 133 138 130 115 118 125 119 122 129 149 123 104 111 115 131 123 119 126 128 140 132 129 138 122 128 119 126 118 123 120 121 118 120 119 120 100 123 121 132 121 125 133 139 119 125 114 119 142 140 114 103 114 118 136 132 130 144 110 124 115 124 109 120 107 127 128 119 115 123 122 117 132 102 128 130 119 134 124 132 129 126 141 117 119 140 124 106 139 131 133 120 140 101 128 140 105 115 116 115 133 133 141 109 121 104 110 126 121 129 112 94 141 131 126 132 121 123 141 142 108 106 140 120 128 112 125 130 106 116 131 120 143 140 128 102 127 124 115 114 123 132 132 113 131 127 113 101 128 111 101 126 122 115 128 122 133 121 104 137 122 107 129 117 109 101 115 136 136 105 142 117 122 126 99 104 117 122 111 116 118 140 107 133 121 138 119 126 117 115 119 120 123 113 133 122 135 138 127 121 118 135 133 113 125 112 100 122 138 109 121 145 126 131 96 126 123 111 126 122 116 117 123 128 131 111 123 117 117 123 130 127 127 128 125 143 113 123 116 117 130 128 103 122 106 103 100 135 129 116 134 121 100 137 121 135 121 139 128 102 112 106 124 109 115 119 120 132 108 119 108 152 128 129 131 133 127 106 133 158 96 117 126 112 119 118 122 118 125 112 138 135 130 133 121 113 123 130 134 115 142 119 115 123 136 119 107 124 116 128 140 139 109 126 144 137 123 134 109 113 112 113 125 137 126 125 121 121 118 123 134 136 117 118 123 130 117 120 107 147 118 120 115 103 104 135 105 118 122 120 124 137 119 110 143 113 135 97 116 116 143 103 118 124 113 108 116 117 114 119 116 98 103 102 129 140 120 135 126 119 119 130 119 131 129 109 117 107 116 113 120 120 120 124 116 120 137 128 143 118 119 127 106 122 123 124 115 107 104 124 127 118 121 119 123 126 118 117 123 112 102 124 116 138 122 119 116 129 145 112 119 115 122 118 130 124 132 110 139 110 123 105 126 110 115 111 125 121 116 116 129 108 95 130 127 107 135 119 117 134 123 140 144 121 126 117 114 116 127 118 133 131 131 128 113 135 131 118 133 136 121 132 117 143 117 138 115 112 117 126 121 123 96 131 113 111 108 115 141 114 119 124 110 122 117 112 120 118 118 117 104 128 116 129 103 110 107 126 135 109 115 135 121 106 133 125 115 105 114 122 123 138 100 123 121 117 114 119 121 135 97 118 119 134 122 128 123 132 110 116 122 138 116 115 120 95 122 115 107 124 127 124 112 117 128 103 119 136 135 115 119 123 112 130 119 132 134 103 121 110 132 131 132 139 131 119 126 129 113 125 126 121 139 127 127 118 126 125 140 122 149 120 135 117 127 108 114 141 133 113 114 128 123 109 134 119 131 110 109 128 124 113 146 118 122 127 127 110 120 107 122 105 129 109 127 128 111 126 102 126 136 117 132 105 110 124 125 135 129 110 144 133 123 111 133 120 129 124 112 129 121 112 117 139 125 108 126 126 119 133 121 100 135 110 107 110 109 114 133 120 120 126 129 125 130 140 106 132 134 136 99 134 103 119 139 128 107 111 151 98 128 133 136 118 139 109 113 123 113 126 138 133 142 129 147 132 126 126 127 120 115 112 102 130 116 120 133 132 112 107 114 104 118 102 120 113 133 128 104 118 120 130 129 123 112 128 127 125 121 105 131 127 141 119 120 112 109 115 94 107 121 115 108 125 129 129 108 109 126 113 130 123 102 119 120 119 113 124 110 123 114 109 133 127 125 131 122 127 124 128 129 136 129 115 125 115 109 127 143 106 131 110 132 116 119 129 111 113 120 116 103 123 139 128 123 111 131 130 128 151 114 123 127 153 127 136 128 135 95 121 116 104 117 125 135 99 132 116 134 142 121 124 127 135 126 136 120 137 142 108 122 131 126 113 125 122 128 109 100 120 117 126 119 100 134 119 112 117 109 119 124 123 137 125 112 127 118 122 105 108 106 129 105 121 122 115 111 132 120 133 126 130 120 116 127 120 117 128 112 102 139 112 126 133 115 89 97 107 130 130 118 96 120 98 120 109 132 122 130 112 133 136 110 135 135 119 111 126 108 121 124 134 110 125 120 110 103 121 122 116 118 115 128 105 113 112 124 128 82 115 102 137 116 126 116 122 130 127 112 128 105 103 121 151 114 125 119 118 114 131 114 132 122 96 105 143 122 112 123 126 117 115 142 136 153 121 108 126 113 116 127 99 130 124 106 132 138 122 108 137 131 111 135 140 125 113 123 128 108 134 115 128 129 140 135 124 137 131 143 125 128 122 131 134 109 140 113 122 145 149 117 150 147 114 132 111 147 132 117 114 135 125 114 124 123 96 131 132 116 125 136 118 116 141 131 119 114 128 127 116 132 139 125 106 138 140 135 133 117 120 124 126 140 130 131 144 151 137 135 109 137 111 143 132 130 127 124 129 106 128 133 133 122 139 122 118 121 129 124 126 117 123 134 135 112 131 107 127 117 133 125 129 152 121 131 121 122 142 134 142 134 108 127 114 129 125 125 119 123 125 122 143 116 146 128 112 124 126 124 108 113 94 122 149 116 110 104 106 127 122 150 124 113 122 125 101 128 113 114 117 125 125 125 126 105 122 133 141 119 145 129 138 127 129 135 133 124 117 125 107 123 110 107 132 114 134 148 144 114 124 145 136 143 118 106 142 136 142 132 127 121 163 133 126 115 131 119 110 114 128 102 128 126 127 118 131 120 112 105 125 122 145 122 125 113 121 116 109 119 100 112 114 127 122 120 121 112 120 147 117 132 100 109 126 117 127 105 136 124 109 126 130 124 125 122 106 115 111 125 120 128 109 124 133 124 124 121 130 125 118 123 127 112 129 105 109 125 126 120 143 114 118 122 102 117 127 116 118 142 119 112 136 140 127 139 114 115 115 114 115 102 110 125 130 110 124 128 118 107 96 141 96 101 126 110 132 127 121 115 117 124 117 114 106 126 129 108 127 129 116 114 112 124 139 142 112 109 120 121 115 110 126 110 114 143 134 122 121 138 111 124 120 112 134 123 119 132 110 139 127 111 98 102 129 123 124 107 114 129 128 114 138 126 121 131 117 89 115 118 110 112 117 120 122 111 105 133 117 114 134 124 115 118 105 124 134 130 120 129 123 103 138 125 101 124 99 118 122 109 129 121 128 123 101 100 105 125 132 103 126 121 99 153 114 112 119 102 109 133 120 93 106 104 129 128 124 130 118 130 118 119 96 127 106 125 111 128 140 97 121 122 130 116 111 113 102 109 137 131 106 119 127 129 111 126 105 130 114 146 133 121 131 120 122 116 130 120 111 104 119 127 120 114 128 139 116 136 119 117 103 112 135 106 115 122 117 125 121 95 108 127 112 123 143 107 112 115 113 121 118 127 130 143 117 105 137 114 119 117 116 117 110 125 104 117 128 109 120 105 125 115 102 120 136 116 117 103 137 112 124 113 117 118 101 119 122 114 118 127 113 128 112 122 109 116 125 126 124 138 120 114 105 108 99 93 113 126 120 121 102 129 139 113 133 118 117 117 124 114 117 140 129 123 131 135 145 119 115 130 118 136 114 146 119 107 103 92 117 125 116 122 96 114 117 133 122 131 121 124 136 111 130 108 124 139 129 95 136 132 122 128 110 131 153 112 149 134 115 149 100 120 123 111 100 141 134 128 113 123 137 127 112 136 127 125 114 125 116 129 123 113 130 133 105 113 128 131 145 127 131 110 122 130 115 110 130 117 108 120 123 104 121 109 134 121 118 107 116 130 136 147 145 130 133 115 144 124 118 113 134 114 117 118 126 133 131 132 101 120 113 97 135 114 106 129 124 104 116 117 133 108 120 127 112 109 112 129 134 115 125 141 130 107 122 106 112 130 118 116 118 103 106 130 123 115 132 146 125 124 94 108 129 152 121 126 135 112 120 126 116 113 114 122 115 127 147 127 125 122 93 113 123 119 131 115 117 142 127 129 119 118 125 111 125 128 96 138 150 131 119 132 122 111 132 129 137 139 120 107 134 102 120 127 145 117 131 106 119 114 117 146 134 138 135 139 138 123 125 143 126 145 108 110 118 119 118 123 126 135 124 125 149 129 123 153 119 142 124 118 115 144 114 112 123 119 127 124 112 126 146 156 140 130 119 127 130 96 101 125 109 116 126 133 138 121 124 107 124 123 115 121 116 117 115 112 134 129 135 123 127 115 117 125 134 131 122 137 130 143 146 138 132 110 120 124 135 121 128 127 113 118 108 148 152 120 121 133 109 129 129 123 142 119 116 113 138 136 116 125 134 128 123 106 129 130 109 126 139 121 133 121 139 119 125 140 111 134 132 115 138 125 121 103 105 135 106 126 127 120 118 114 121 140 109 129 117 113 128 137 106 147 123 118 129 135 112 114 133 122 125 115 108 125 119 105 124 133 123 129 125 131 141 117 119 111 118 112 127 119 119 115 116 115 121 114 114 124 136 131 116 111 110 107 114 122 116 118 106 110 127 128 111 119 98 111 119 140 117 100 118 118 138 107 122 134 137 121 118 139 132 119 117 119 120 111 114 125 96 119 117 116 130 117 121 123 105 126 125 126 139 136 123 136 124 97 134 111 116 96 119 128 127 118 133 125 122 134 118 117 126 121 106 123 154 130 124 151 128 114 117 121 129 114 107 132 117 122 129 119 112 117 116 123 117 119 132 118 117 121 130 111 104 121 124 130 114 116 116 102 139 114 126 118 123 105 116 122 114 121 109 116 99 110 137 114 125 116 133 107 140 112 121 116 127 136 126 128 151 131 115 114 115 129 104 107 117 121 119 128 114 112 119 114 140 131 105 95 114 116 108 123 123 107 103 122 98 126 120 131 111 113 113 114 112 112 122 125 112 104 118 124 136 129 126 136 116 123 137 112 123 118 103 129 131 125 103 133 127 127 122 117 115 115 107 127 103 120 123 132 144 119 123 123 119 123 131 141 118 120 120 126 119 126 127 109 113 121 112 115 107 126 126 131 120 128 111 114 116 120 120 116 113 131 130 123 127 123 114 121 120 122 121 144 117 125 115 91 124 124 102 105 120 109 110 130 106 114 133 128 101 116 130 92 138 128 111 117 102 130 123 116 111 107 137 98 116 120 115 109 119 102 133 110 121 131 152 121 109 127 118 118 116 115 113 114 130 130 127 119 132 131 119 124 101 119 102 111 117 123 124 111 124 97 118 112 107 120 131 109 136 126 126 120 120 117 112 138 124 123 96 131 130 117 115 131 139 126 131 129 121 119 129 115 115 124 120 134 117 143 130 108 145 134 114 131 126 105 113 136 145 119 126 145 112 126 99 104 123 121 116 105 117 119 120 109 117 114 112 136 111 137 115 122 126 131 117 120 126 102 107 144 136 124 124 113 112 125 137 132 112 114 114 121 122 124 130 113 121 121 104 115 117 131 102 102 107 116 131 137 128 104 115 106 128 111 109 135 110 117 118 122 124 115 116 134 114 111 132 108 116 114 136 134 128 132 112 118 111 122 121 119 142 124 118 115 119 110 112 117 116 117 115 107 99 120 135 129 118 109 117 125 110 95 117 123 122 108 140 136</counts>
			</dataPoints>
		</scan>
	</xrdMeasurement>
</xrdMeasurements>