File: data/XRD/_misc/old/XG-700C/_absolute_2th-om_10-130deg_PIXscan_56min_2.xrdml
<xrdMeasurements xmlns="http://www.xrdml.com/XRDMeasurement/2.1" xmlns:xsi="http://www.w3.org/2001/XMLSchema-instance" xsi:schemaLocation="http://www.xrdml.com/XRDMeasurement/2.1 http://www.xrdml.com/XRDMeasurement/2.1/XRDMeasurement.xsd" status="Completed">
	<comment>
		<entry>Configuration=Factory configuration, Owner=User-1, Creation date=7/8/2013 4:01:53 PM</entry>
		<entry>Goniometer=PW3050/65 (Theta/2Theta); Minimum step size 2Theta:0.0001; Minimum step size Omega:0.0001</entry>
		<entry>Sample stage=MRD Cradle; Minimum step size Phi:0.01; Minimum step size Chi:0.01; Minimum step size X:0.01; Minimum step size Y:0.01; Minimum step size Z:0.001</entry>
		<entry>Diffractometer system=XPERT-PRO</entry>
		<entry>Measurement program=C:\PANalytical\Data Collector\Programs\Jorrit\2thom\_absolute_2th-om_10-130deg_PIXscan_56min.xrdmp, Identifier={15BCCF57-2807-42BD-B5B9-ECC0B3DC9284}</entry>
		<entry>Batch program=C:\PANalytical\Data Collector\Programs\SimonL\batch4x_2thom_10-130°_z9.1_x0,10,20,30_y0_57min.xrdmp, Identifier={EED9823A-2BEB-424C-9252-345C4EF2834A}</entry>
	</comment>
	<sample type="To be analyzed">
		<id></id>
		<name></name>
		<preparedBy></preparedBy>
	</sample>
	<xrdMeasurement measurementType="Scan" status="Completed" sampleMode="Reflection">
		<comment>
			<entry>_absolute_2th-om_10-130deg_PIXscan_56min</entry>
			<entry>PHD Lower Level = 4.83 (keV), PHD Upper Level = 11.27 (keV)</entry>
		</comment>
		<usedWavelength intended="K-Alpha 1">
			<kAlpha1 unit="Angstrom">1.5405980</kAlpha1>
			<kAlpha2 unit="Angstrom">1.5444260</kAlpha2>
			<kBeta unit="Angstrom">1.3922500</kBeta>
			<ratioKAlpha2KAlpha1>0.5000</ratioKAlpha2KAlpha1>
		</usedWavelength>
		<incidentBeamPath>
			<radius unit="mm">320.00</radius>
			<xRayTube id="1010048" name="Empyrean Cu LFF HR (9430 033 7310x) DK442154">
				<tension unit="kV">40.0</tension>
				<current unit="mA">40.0</current>
				<anodeMaterial>Cu</anodeMaterial>
				<focus type="Line">
					<length unit="mm">12.0</length>
					<width unit="mm">0.4</width>
					<takeOffAngle unit="deg">4.2</takeOffAngle>
				</focus>
			</xRayTube>
			<xRayMirror id="27010001" name="Inc. Beam Cu W/Si (parabolic MRD)" hybrid="false">
				<crystal type="Graded" shape="Parabolic">W/Si</crystal>
				<acceptanceAngle unit="deg">0.800</acceptanceAngle>
				<length unit="mm">60.0</length>
			</xRayMirror>
			<sollerSlit id="21010002" name="Soller slits 0.04 rad.">
				<opening unit="rad">0.0400</opening>
			</sollerSlit>
			<mask id="22030007" name="Fixed mask 2 mm">
				<distanceToSample unit="mm">220.00</distanceToSample>
				<width unit="mm">2.00</width>
			</mask>
			<divergenceSlit id="22010007" name="Fixed slit 1/8°" xsi:type="fixedDivergenceSlitType">
				<distanceToSample unit="mm">220.00</distanceToSample>
				<height unit="mm">0.19</height>
			</divergenceSlit>
		</incidentBeamPath>
		<diffractedBeamPath>
			<radius unit="mm">320.00</radius>
			<sollerSlit id="21010002" name="Soller slits 0.04 rad.">
				<opening unit="rad">0.0400</opening>
			</sollerSlit>
			<receivingSlit id="22010001" name="Fixed slit 4°">
				<height unit="mm">5.88</height>
			</receivingSlit>
			<detector id="7010017" name="PIXcel3D 1x1 detector" xsi:type="areaDetectorType">
				<phd unit="%">
					<lowerLevel>30.0</lowerLevel>
					<upperLevel>70.0</upperLevel>
				</phd>
				<mode>Scanning</mode>
				<activeChannelsEquatorial>255</activeChannelsEquatorial>
				<activeChannelsAxial>255</activeChannelsAxial>
				<pitchEquatorial unit="mm">0.05500</pitchEquatorial>
				<pitchAxial unit="mm">0.05500</pitchAxial>
				<readOutPeriod unit="seconds">0.135</readOutPeriod>
			</detector>
		</diffractedBeamPath>
		<scan appendNumber="0" mode="Continuous" scanAxis="2Theta-Omega" status="Completed">
			<header>
				<startTimeStamp>2024-09-03T19:09:02+02:00</startTimeStamp>
				<endTimeStamp>2024-09-03T20:05:08+02:00</endTimeStamp>
				<author>
					<name>PRO-MRD</name>
				</author>
				<source>
					<applicationSoftware version="6.1b">Data Collector</applicationSoftware>
					<instrumentControlSoftware version="7.0E 20130304">XPERT-PRO</instrumentControlSoftware>
					<instrumentID>0000000011142674</instrumentID>
				</source>
			</header>
			<dataPoints>
				<positions axis="2Theta" unit="deg">
					<startPosition>9.99826193</startPosition>
					<endPosition>129.99755682</endPosition>
				</positions>
				<positions axis="Omega" unit="deg">
					<startPosition>4.99913096</startPosition>
					<endPosition>64.99877841</endPosition>
				</positions>
				<positions axis="Phi" unit="deg">
					<commonPosition>0.00</commonPosition>
				</positions>
				<positions axis="Chi" unit="deg">
					<commonPosition>0.00</commonPosition>
				</positions>
				<positions axis="X" unit="mm">
					<commonPosition>10.00</commonPosition>
				</positions>
				<positions axis="Y" unit="mm">
					<commonPosition>0.00</commonPosition>
				</positions>
				<positions axis="Z" unit="mm">
					<commonPosition>9.100</commonPosition>
				</positions>
				<commonCountingTime unit="seconds">32.895</commonCountingTime>
				<counts 211 224 221 219 227 244 235 206 232 221 206 209 224 218 220 232 224 223 182 223 198 230 205 225 234 225 184 231 214 263 200 205 208 223 213 208 196 226 187 239 262 226 256 235 216 201 219 228 225 221 224 203 227 209 229 246 198 215 202 219 217 223 245 227 212 225 231 212 219 224 213 227 214 197 198 219 202 204 220 214 205 207 244 196 203 210 214 184 204 213 217 230 219 199 197 225 188 221 207 222 207 184 210 227 208 200 208 215 202 197 192 175 210 213 203 217 214 197 200 227 214 213 200 213 186 212 205 208 188 214 223 221 196 202 236 193 226 204 185 198 201 208 217 216 202 193 203 193 203 196 236 205 173 202 193 189 224 197 204 191 206 208 206 200 187 194 223 192 214 196 205 209 184 197 204 228 200 206 201 185 207 206 200 186 223 192 221 216 210 189 199 197 183 184 230 194 194 206 185 193 188 209 211 187 182 235 204 205 185 222 184 209 221 191 194 180 204 192 201 209 197 166 171 213 193 198 193 199 187 195 179 194 201 181 182 223 177 176 205 184 183 201 202 184 202 203 202 208 175 179 185 180 191 204 207 194 190 182 205 199 203 174 184 195 185 203 196 207 197 224 204 199 200 167 177 178 199 190 213 193 173 175 180 188 173 159 181 170 174 197 192 188 175 206 197 177 191 168 189 177 176 165 189 194 192 190 198 192 179 192 197 194 180 185 179 160 172 166 208 188 180 168 209 185 174 152 169 178 193 188 183 190 174 191 177 181 209 188 185 210 162 176 188 201 167 165 180 186 178 178 191 179 213 157 186 202 171 187 166 195 158 169 155 178 164 184 206 172 180 167 170 172 176 172 193 179 185 175 157 211 179 171 173 176 172 184 177 190 183 165 184 151 153 164 191 148 163 171 165 179 176 191 180 159 171 170 184 159 182 166 189 171 171 178 169 166 210 180 182 170 173 180 173 180 178 184 153 189 163 173 195 197 180 188 141 188 155 190 177 186 183 195 162 181 180 166 181 164 169 176 186 187 171 198 152 174 149 170 175 154 166 159 177 185 193 179 162 179 167 168 170 182 176 158 163 179 176 162 165 171 177 161 180 173 152 178 172 202 162 135 176 181 157 167 171 153 164 160 177 173 188 180 165 171 173 153 175 169 149 161 166 140 167 183 182 161 142 170 186 175 162 169 157 168 154 189 151 142 165 169 151 173 183 165 136 176 156 164 165 169 146 171 153 171 146 180 154 125 169 143 152 152 168 161 169 170 156 177 174 164 160 149 151 150 143 156 156 167 162 166 150 155 136 166 157 180 181 178 175 161 130 156 151 144 178 159 150 162 190 163 155 171 166 164 154 169 185 186 169 153 161 176 162 141 168 152 127 144 151 164 165 163 149 151 168 169 167 170 165 168 161 152 179 196 162 151 150 152 189 156 167 160 154 156 166 172 160 146 186 154 164 164 170 159 179 166 181 167 162 162 169 177 156 167 156 152 175 137 161 153 168 182 172 181 136 161 136 157 161 159 136 170 190 159 172 159 175 162 171 166 133 149 162 156 159 158 159 167 182 151 155 156 148 172 140 166 177 165 152 171 170 182 149 142 155 155 188 161 183 161 153 146 149 147 154 163 171 154 147 155 159 166 159 178 146 154 138 145 152 152 146 175 152 140 158 159 135 177 162 149 160 150 167 141 164 179 171 133 136 160 129 143 161 161 167 159 150 156 167 157 145 159 153 165 133 140 168 170 165 142 166 158 157 149 168 155 162 158 143 168 154 149 157 156 164 149 173 148 150 146 168 152 150 163 164 155 167 179 152 179 145 142 151 148 167 152 158 140 171 135 138 169 188 180 156 180 152 156 164 157 163 153 150 154 168 176 153 171 159 152 178 192 163 145 146 158 167 136 163 166 162 167 152 162 150 173 171 172 172 158 173 157 154 152 175 138 171 159 145 148 163 153 148 165 142 163 141 166 172 146 163 184 161 154 173 138 162 125 174 141 164 158 181 164 189 143 154 180 151 144 141 153 163 151 158 146 180 166 175 159 153 168 146 156 174 162 153 160 173 151 159 152 169 159 175 158 150 158 142 151 163 158 152 166 175 150 171 160 160 147 175 163 161 183 195 177 138 150 166 173 151 158 159 158 177 163 163 140 166 163 171 169 158 171 167 166 183 163 178 173 176 162 160 154 143 169 184 156 153 147 163 162 158 191 152 167 165 173 152 178 187 165 159 156 139 167 192 161 180 180 153 154 169 136 157 176 159 159 165 164 168 161 180 159 162 170 156 151 151 135 153 177 178 152 146 155 152 191 183 136 146 166 170 179 164 163 164 185 158 157 140 175 167 199 184 170 169 164 145 173 174 174 154 161 165 160 164 172 177 145 139 157 171 164 164 160 186 168 157 159 156 184 193 187 171 170 145 150 178 166 166 160 176 174 178 182 175 175 183 155 162 169 162 178 182 179 188 159 147 185 161 192 181 171 143 177 161 167 142 156 167 185 190 174 181 149 182 174 190 160 156 162 165 173 170 176 156 155 176 173 167 177 174 157 168 151 156 177 165 184 165 150 142 170 166 170 168 171 156 176 183 152 165 178 168 182 143 183 157 169 144 152 160 157 175 172 165 179 188 184 181 177 172 158 166 171 168 153 160 151 180 152 148 167 167 157 161 170 154 169 168 162 177 163 153 148 124 183 174 204 185 166 151 184 170 178 178 147 158 166 183 168 170 161 166 160 190 173 145 147 177 163 187 159 177 149 170 174 166 182 169 152 169 163 174 176 152 182 156 152 175 153 149 173 180 188 174 172 164 162 150 161 162 166 171 189 169 149 153 169 207 157 180 164 162 147 168 145 160 165 145 188 176 174 185 160 164 186 157 202 189 180 168 167 173 154 153 162 173 188 168 186 184 169 163 172 166 178 173 146 175 181 181 175 175 159 164 186 161 169 174 166 145 181 146 151 194 207 164 154 157 181 181 164 164 158 167 161 163 159 170 176 165 172 161 157 175 152 187 180 150 159 165 174 177 192 160 159 162 164 175 189 176 168 148 149 137 162 173 147 165 152 149 172 170 168 147 172 144 189 150 151 169 157 173 162 166 160 169 156 168 146 175 163 179 157 174 157 187 157 185 160 155 161 143 145 159 154 181 169 163 180 176 171 166 170 152 151 160 182 157 158 170 151 153 171 176 180 156 169 156 162 199 173 169 161 190 159 171 161 153 181 169 160 151 167 159 137 156 140 148 153 137 170 172 194 156 153 142 138 145 154 152 146 174 157 171 165 167 168 166 147 160 161 149 164 165 167 140 152 153 156 166 161 166 149 144 153 170 164 143 166 174 150 157 183 165 179 163 169 150 170 135 160 162 182 176 161 170 151 158 159 174 165 156 168 161 150 187 153 152 157 147 189 164 166 155 159 145 138 167 170 166 157 155 190 163 142 175 174 157 147 176 182 156 156 147 158 153 156 148 150 166 149 138 163 159 132 141 169 157 187 167 130 145 138 158 155 153 154 164 171 161 165 159 142 151 151 152 162 157 151 140 161 153 150 152 164 134 163 156 170 123 147 149 159 139 138 137 147 140 151 148 150 170 130 151 150 149 147 130 156 153 125 152 164 159 158 150 146 139 168 161 161 153 158 134 143 146 150 149 156 138 161 159 155 150 153 152 138 145 162 151 158 127 163 134 132 144 161 154 158 181 156 144 158 142 141 157 140 148 128 155 123 136 151 146 166 140 139 138 145 157 134 144 141 159 157 147 148 150 140 136 133 156 152 124 149 134 153 155 132 157 138 139 162 159 136 122 153 147 138 145 130 147 140 137 150 137 134 158 152 147 147 123 152 130 137 143 148 158 170 153 125 126 145 157 121 146 136 146 142 143 147 142 116 133 145 131 130 144 137 153 138 144 146 161 140 141 154 126 147 128 127 136 151 139 163 134 156 131 123 154 137 169 145 131 132 135 150 147 154 121 143 127 154 142 144 130 126 140 127 148 144 144 153 132 144 132 128 122 138 137 136 112 150 144 151 133 135 135 135 160 152 117 139 146 133 131 125 157 129 132 128 148 138 127 127 135 125 147 130 126 129 143 135 125 134 147 129 134 148 145 153 148 122 128 138 145 126 130 125 135 151 142 134 151 138 141 158 140 129 121 114 142 133 131 132 148 150 139 125 143 128 142 141 151 136 130 103 136 125 139 121 129 152 124 137 142 131 129 135 141 145 138 143 117 140 130 137 142 142 128 115 127 157 148 130 146 148 124 140 129 145 138 126 153 140 110 135 135 115 134 126 144 126 119 150 135 133 141 145 135 126 153 115 148 130 117 150 133 125 162 131 150 148 139 134 134 128 124 129 139 130 137 122 114 161 143 137 135 125 131 136 115 139 131 133 139 124 135 118 138 155 143 141 119 128 144 112 123 146 124 152 143 127 124 135 149 132 116 128 131 112 123 120 142 148 152 138 131 131 114 139 140 131 132 130 126 114 118 120 132 128 137 120 96 139 107 145 126 123 124 127 126 140 127 118 124 136 141 126 133 129 117 121 139 132 144 134 124 121 113 118 136 144 136 126 135 117 118 133 123 134 128 120 147 139 126 114 126 115 112 136 128 126 136 144 136 140 130 122 138 125 156 127 117 145 133 127 117 126 131 125 138 129 123 138 128 123 127 144 112 116 125 138 117 128 116 99 95 102 120 108 133 112 124 122 126 128 103 120 135 133 136 98 140 144 127 149 127 140 105 118 124 117 123 123 127 112 138 127 121 112 128 115 120 115 123 127 127 119 133 121 129 119 133 121 111 117 138 143 126 131 103 116 135 144 124 130 142 112 121 110 131 128 120 108 121 123 128 117 108 116 126 107 137 121 120 126 133 125 129 118 120 128 123 130 127 101 121 113 112 104 140 112 124 125 132 120 128 151 138 106 105 124 127 112 118 110 118 106 147 115 122 106 129 141 115 127 119 112 111 138 97 146 129 116 125 122 113 103 119 129 136 121 115 139 110 106 129 136 118 134 118 128 115 121 130 108 125 117 123 104 126 140 126 131 134 107 126 136 132 129 111 118 126 149 120 120 123 116 112 132 122 121 117 120 113 123 119 127 115 124 129 116 119 126 148 141 124 138 130 116 122 121 117 125 124 117 114 109 135 124 115 106 109 122 131 104 129 126 118 136 152 128 147 127 132 105 130 106 119 154 100 121 135 113 116 120 116 111 129 117 117 111 106 102 131 127 160 114 128 126 98 128 113 109 106 129 111 138 108 98 124 104 139 105 119 117 125 111 117 109 116 120 123 130 126 111 124 123 137 122 121 109 112 105 106 118 116 113 117 124 130 109 127 124 133 99 121 102 122 111 114 131 131 120 112 133 125 128 123 123 128 103 129 108 104 108 115 127 113 136 121 110 128 119 121 120 127 133 115 122 133 115 130 122 109 115 148 128 111 130 116 132 114 102 120 115 107 103 112 133 123 145 100 107 111 112 119 95 117 128 101 123 111 123 100 99 109 122 109 119 123 119 149 111 100 106 135 114 138 119 114 115 128 116 122 121 111 117 107 97 118 99 131 112 109 111 126 116 124 114 97 121 122 103 107 123 131 92 126 99 113 112 116 98 115 124 116 133 132 115 120 124 129 120 111 94 128 128 102 116 100 118 114 112 100 119 106 132 128 118 137 125 122 123 109 130 108 106 101 117 122 102 114 120 122 119 126 109 119 130 115 84 104 109 125 111 120 122 105 112 132 106 120 116 101 113 127 122 102 113 133 119 135 122 117 105 112 89 125 104 102 121 127 104 119 119 125 113 100 117 122 102 124 110 99 127 117 121 118 123 109 113 101 108 102 130 127 111 126 114 114 122 128 118 119 102 113 125 121 109 111 121 110 96 116 123 99 111 130 116 129 117 106 122 122 120 127 109 109 118 109 105 117 139 114 116 118 118 117 103 106 108 109 107 99 121 131 115 126 112 124 103 103 109 122 129 109 98 121 124 101 120 124 107 100 116 114 122 93 107 113 109 115 111 109 105 134 107 114 126 96 118 110 114 97 123 107 115 116 111 103 102 104 106 116 105 125 101 127 126 148 107 111 120 125 140 117 128 134 124 104 98 116 103 100 108 123 133 116 111 113 116 117 119 106 108 119 124 140 132 115 133 121 148 94 96 129 111 94 122 110 112 97 89 110 103 107 109 121 142 111 113 97 104 102 135 120 128 104 116 101 109 102 110 141 108 110 110 101 126 108 101 115 114 120 95 127 121 107 106 91 96 133 109 104 104 130 102 112 114 116 109 90 121 110 113 118 103 120 118 88 108 110 112 122 113 106 107 113 120 110 116 113 111 118 104 110 120 116 104 95 118 106 121 111 112 109 111 95 110 113 91 105 97 120 116 115 116 92 103 109 124 103 119 136 105 109 108 105 118 118 138 108 109 97 110 126 123 103 93 109 121 120 98 113 123 128 115 120 105 114 107 107 116 116 120 107 111 113 111 118 111 123 121 129 121 101 118 127 118 126 108 98 134 125 133 104 115 117 109 120 112 91 100 95 146 92 123 115 100 116 123 125 103 90 115 107 86 121 121 122 110 101 107 127 109 110 97 118 130 111 123 91 114 122 133 103 119 94 94 109 121 107 123 116 97 120 115 113 97 137 108 103 86 122 106 108 118 121 128 119 109 80 123 118 110 107 101 105 104 105 83 115 86 116 123 95 120 99 114 125 118 112 108 98 93 126 93 99 103 120 112 123 99 104 119 114 127 93 106 129 114 122 114 105 112 111 115 98 102 106 114 113 116 95 114 127 119 107 106 117 120 129 119 118 107 101 107 106 130 115 118 112 100 99 109 115 120 130 107 127 108 126 111 119 134 118 109 103 122 137 99 134 137 114 129 100 99 100 115 113 104 130 115 108 96 109 116 103 110 121 110 116 109 97 109 110 102 115 113 125 119 113 108 117 113 130 108 113 123 120 111 96 114 123 109 112 133 104 107 107 116 128 106 114 113 110 124 110 124 118 111 114 103 113 106 115 114 118 108 114 112 107 122 105 123 105 125 118 104 140 121 129 107 111 113 132 133 106 121 100 112 136 124 114 108 120 124 117 126 140 137 114 107 109 111 119 116 124 125 98 115 100 117 117 117 114 103 111 100 112 130 101 112 108 107 101 114 111 100 124 109 120 105 104 124 108 99 99 104 106 104 119 123 127 103 112 122 108 113 107 127 105 114 105 120 130 120 130 109 121 114 119 109 102 120 89 102 119 133 107 130 125 135 113 137 121 116 113 133 115 102 106 123 121 149 117 137 113 105 111 121 124 123 114 113 118 111 105 87 127 110 123 121 119 117 133 113 101 122 100 106 121 110 126 106 115 125 125 101 97 92 115 104 121 132 122 121 139 105 120 133 103 104 97 104 133 118 128 95 117 111 136 114 124 116 105 118 102 131 116 124 127 99 122 132 108 136 100 114 117 113 124 121 114 119 117 113 120 127 103 122 93 113 113 100 123 143 112 115 127 124 93 97 132 94 107 108 107 87 102 102 103 122 133 113 124 129 102 101 122 106 117 130 123 111 121 123 126 110 104 115 129 109 110 117 113 130 116 116 120 104 125 122 117 134 127 108 112 105 111 111 121 122 118 105 129 132 113 118 131 112 128 116 101 111 132 119 119 121 129 117 104 136 135 119 132 122 114 124 113 122 111 114 125 122 124 111 112 114 108 123 151 124 108 124 126 118 143 125 135 136 134 135 101 113 140 140 115 133 134 122 130 122 128 132 147 119 131 131 152 120 127 114 123 134 129 135 138 139 128 127 130 136 140 142 125 147 162 143 142 110 132 133 137 166 150 166 155 144 166 170 180 151 196 143 167 190 179 169 161 163 179 201 206 218 181 203 187 200 214 184 204 207 198 234 195 199 206 224 202 175 173 179 182 166 187 183 167 172 183 146 158 146 161 154 146 146 145 126 146 139 124 126 139 128 138 120 139 121 119 122 105 125 120 121 135 109 98 146 127 122 117 120 111 113 128 141 116 137 136 116 131 132 125 120 114 106 128 119 130 123 113 119 108 91 97 121 95 137 128 116 113 133 125 119 116 117 116 125 133 138 117 108 120 115 123 126 134 106 108 116 132 120 107 108 136 114 103 126 135 119 125 112 114 120 123 127 99 118 128 111 120 122 111 110 138 118 108 123 146 115 120 130 125 133 102 109 118 131 113 91 123 125 113 113 124 110 115 120 118 114 133 123 124 139 131 117 96 105 118 104 97 118 117 121 109 121 134 118 122 112 106 108 119 119 108 116 130 140 117 117 115 134 108 115 113 112 118 123 106 120 117 125 112 120 115 108 130 106 124 120 115 129 114 131 126 107 113 113 107 130 134 124 142 124 120 97 129 118 127 132 130 113 101 110 126 107 118 102 133 110 114 120 126 116 115 111 104 107 133 113 115 106 133 128 126 106 136 131 110 116 131 111 127 116 101 114 112 110 136 121 125 132 115 129 128 113 121 126 113 118 111 107 111 126 137 126 115 119 107 114 125 107 139 114 113 125 123 130 96 100 113 136 97 106 109 104 89 117 111 102 121 112 118 94 114 116 116 125 117 103 108 105 120 112 107 122 101 97 120 127 106 119 125 145 125 132 127 107 126 111 129 119 98 135 108 119 108 113 123 98 120 123 119 120 123 124 125 110 148 133 125 118 113 135 118 99 115 117 125 128 120 112 126 106 131 114 107 111 118 93 110 107 107 91 102 136 105 126 98 124 114 117 120 118 108 138 127 112 132 112 113 109 125 104 117 134 113 120 120 120 122 121 134 101 109 119 114 113 123 121 122 113 124 117 103 108 121 89 135 112 127 134 120 120 136 111 143 125 132 115 107 117 127 107 135 111 127 126 110 117 128 111 115 109 110 126 121 106 117 124 132 119 114 105 94 111 130 111 105 103 125 115 113 105 116 122 117 113 107 119 127 111 124 117 136 128 119 103 124 104 123 132 109 116 99 116 120 112 111 123 109 120 118 132 135 129 131 120 98 110 131 124 103 102 118 128 117 141 128 126 112 127 119 124 128 121 131 116 114 124 126 126 95 110 122 111 122 118 119 108 104 120 119 106 136 105 130 101 119 96 120 125 120 105 110 126 120 110 106 113 103 130 102 139 130 118 131 106 116 104 127 120 132 133 123 113 117 112 115 86 124 99 141 112 117 106 107 107 110 121 122 100 105 97 119 136 109 109 143 109 109 132 102 130 141 119 119 122 121 117 130 94 106 105 122 115 95 115 132 118 112 129 110 127 117 104 116 131 114 112 117 115 116 99 113 97 112 111 124 110 122 116 111 129 111 106 122 130 95 104 133 119 126 120 130 129 96 97 140 83 94 115 103 106 119 111 123 106 121 135 101 124 133 96 105 107 117 113 125 112 110 107 104 131 105 117 121 111 129 99 108 104 123 111 115 109 120 123 119 106 119 121 102 130 116 118 101 106 117 123 112 109 100 103 124 124 118 124 116 104 106 131 110 120 128 108 103 130 114 127 119 119 118 114 117 122 118 128 126 124 120 111 91 105 131 119 125 118 112 105 122 124 132 124 113 119 114 105 114 123 130 106 121 106 138 122 110 111 133 116 123 120 111 117 124 120 138 121 132 132 125 114 119 120 112 132 134 119 121 129 98 120 103 92 111 120 116 123 122 121 117 103 123 118 125 126 145 113 117 138 136 127 121 106 108 114 130 122 114 130 125 114 127 134 108 125 120 114 114 124 120 126 133 135 105 108 123 105 130 127 132 105 111 111 124 133 120 110 131 121 121 124 113 129 123 114 123 143 115 120 125 131 126 112 135 113 111 105 113 117 115 119 129 111 105 115 100 125 121 116 124 106 131 124 105 120 102 130 114 125 104 104 127 124 102 125 111 114 110 111 107 126 117 104 118 101 134 113 110 122 109 116 127 118 111 136 113 125 127 145 92 88 126 120 120 121 137 117 113 112 126 110 105 127 131 118 124 108 151 137 107 108 126 123 142 118 123 129 112 130 119 105 138 104 106 117 131 115 124 108 97 109 117 100 106 130 123 126 128 95 139 109 123 97 134 114 142 122 127 128 108 113 112 128 116 129 124 115 110 121 121 111 116 106 129 121 119 108 112 114 102 106 112 104 96 115 116 121 121 105 124 128 96 119 115 118 130 115 106 139 129 117 117 132 115 129 112 124 131 116 130 124 126 111 99 98 137 108 122 120 126 131 127 115 117 129 104 95 124 120 106 104 143 112 127 96 109 112 127 119 100 111 127 125 92 100 93 116 131 115 129 120 143 128 122 114 129 119 105 112 115 134 105 114 135 109 112 123 121 125 116 125 113 131 127 115 111 113 106 110 126 125 104 133 124 118 116 122 111 128 106 110 122 105 118 120 119 111 115 108 125 126 110 109 112 103 118 97 131 105 137 99 128 123 110 128 127 134 127 112 100 125 117 104 122 114 98 100 105 106 125 108 114 130 106 112 132 110 101 103 104 123 119 104 120 117 110 120 120 107 105 119 108 132 123 111 116 103 113 103 124 111 106 130 117 130 107 130 116 121 98 126 128 138 121 117 100 124 133 109 107 122 104 130 92 125 121 121 113 124 142 106 123 110 115 114 98 123 109 121 125 98 117 114 119 95 138 131 112 118 132 112 114 108 114 111 106 122 132 115 106 128 115 128 112 126 119 132 120 104 124 120 128 136 118 112 105 114 120 117 113 120 135 131 138 111 117 127 105 106 102 107 108 121 106 107 119 120 110 118 110 95 112 128 124 113 130 101 115 112 112 121 129 122 133 116 118 114 130 122 115 116 100 135 102 93 125 118 126 113 106 123 118 111 112 126 133 112 128 125 102 105 122 116 118 111 110 132 107 113 110 94 122 99 135 120 119 115 108 113 111 118 118 113 115 97 126 114 115 121 115 140 140 116 109 104 106 119 128 139 125 104 125 124 117 124 124 131 109 133 128 116 119 105 116 121 107 87 111 126 108 94 122 129 102 120 130 113 109 112 113 123 136 139 101 129 111 138 132 120 121 116 94 141 115 123 99 126 127 123 112 116 137 106 121 95 120 116 119 118 126 120 121 122 108 125 118 118 124 106 115 126 138 127 138 121 89 118 120 129 128 111 111 124 135 124 121 115 131 113 93 116 116 104 119 112 130 117 120 125 116 106 126 130 128 101 122 119 121 105 116 128 113 127 128 119 111 126 116 134 116 100 134 113 121 115 112 119 121 113 115 107 99 119 143 128 146 128 119 110 126 107 119 107 124 132 135 110 121 113 122 105 128 125 132 119 133 117 123 126 109 117 126 138 125 113 126 147 111 132 109 111 108 121 105 116 125 113 125 112 123 120 109 113 126 131 128 134 118 130 128 94 124 117 114 141 123 117 132 113 96 99 112 121 128 118 122 121 119 115 124 136 123 103 127 101 120 91 126 125 101 128 130 116 127 112 117 114 126 117 123 105 104 136 136 126 128 148 139 129 143 120 141 108 120 128 125 102 108 124 125 125 115 129 128 106 118 135 121 104 120 141 118 124 118 140 118 122 122 124 114 120 129 110 132 106 131 114 129 118 117 112 127 113 119 137 136 133 118 138 108 117 137 95 124 119 123 135 145 126 125 128 106 115 125 127 123 113 125 130 118 102 123 122 112 116 134 116 141 130 112 136 125 131 97 110 114 122 134 120 121 106 123 106 107 134 104 136 109 133 105 129 113 139 114 125 127 131 110 114 127 136 123 120 122 133 99 125 125 115 124 107 124 118 135 126 104 125 117 130 131 132 139 108 116 106 113 132 119 124 141 138 97 110 131 121 111 130 117 114 153 134 102 109 126 129 98 125 125 108 113 125 126 117 111 128 129 132 122 103 115 120 121 149 121 117 123 122 131 123 111 117 134 113 115 122 132 133 103 127 126 123 113 116 132 107 110 131 112 101 117 116 118 134 112 141 122 96 132 119 127 109 123 116 115 124 116 100 107 122 140 114 136 101 122 108 128 129 119 114 143 129 114 112 116 111 112 117 97 126 113 149 132 134 123 109 115 114 126 142 112 105 114 129 123 99 126 144 111 124 114 106 104 120 114 118 121 116 110 133 144 133 129 126 139 136 121 145 119 131 113 120 117 128 110 115 135 115 118 123 118 102 124 114 122 121 131 129 142 122 136 117 114 135 130 106 114 136 97 125 119 114 105 147 119 130 109 130 138 126 104 134 110 113 113 120 109 118 111 136 130 122 128 127 118 110 126 108 134 134 111 135 115 117 131 110 120 131 118 118 123 119 97 132 142 129 109 120 125 104 141 126 128 107 124 108 117 125 133 116 113 134 131 111 108 129 118 131 122 117 124 124 133 112 114 116 121 137 125 122 106 115 122 120 114 124 115 119 109 98 110 129 126 120 119 126 115 119 112 103 112 110 129 138 123 136 135 136 139 121 118 104 130 120 124 122 130 143 146 117 106 136 120 137 121 139 137 121 139 115 118 126 117 127 112 125 115 147 146 120 107 124 121 118 124 131 117 120 150 130 147 123 130 121 121 112 131 153 135 144 114 141 118 124 114 119 139 143 135 145 128 120 143 119 115 132 133 110 152 130 117 127 137 117 132 122 124 137 125 124 133 130 137 131 126 128 139 148 131 124 112 117 110 133 127 125 130 133 139 129 125 146 129 117 119 122 122 131 125 100 119 136 128 112 150 128 129 110 136 139 125 126 118 140 117 111 122 129 128 132 131 143 143 118 125 110 130 136 132 120 122 136 135 121 129 109 108 103 111 133 110 130 124 113 131 99 131 124 128 116 118 122 130 113 138 127 114 117 134 102 156 113 126 115 117 127 106 122 127 122 119 123 123 117 136 138 138 119 119 122 132 116 122 123 111 116 134 111 130 126 115 132 121 115 117 114 132 122 137 137 134 123 119 156 126 138 107 134 150 113 107 127 119 131 130 113 136 109 124 120 116 104 107 127 117 119 123 134 124 134 121 130 108 109 102 115 115 141 116 139 108 121 136 106 141 109 141 106 114 115 124 114 115 116 140 140 125 120 109 128 124 127 89 118 162 125 122 124 115 117 115 126 110 119 121 131 120 120 126 123 116 145 133 122 129 121 115 119 117 136 117 126 122 130 128 126 111 123 121 115 106 136 133 124 109 123 109 116 111 115 124 119 115 114 115 115 137 105 135 128 117 112 121 108 149 118 104 104 140 129 127 123 125 111 130 136 120 110 111 108 117 117 99 110 129 129 117 121 107 128 113 110 104 131 119 119 117 115 136 141 108 132 121 117 126 127 128 111 108 103 119 133 130 119 108 130 114 126 126 122 134 120 137 103 143 119 116 121 109 121 101 133 117 130 132 119 133 118 122 137 123 109 121 132 111 121 124 131 136 136 137 110 119 145 136 113 116 105 133 124 121 125 132 144 117 113 111 95 125 128 124 114 124 126 102 98 128 121 118 114 118 129 122 119 117 133 102 101 129 118 117 126 116 122 111 125 126 111 146 107 123 110 129 123 116 121 122 120 119 118 110 120 112 119 151 115 134 116 112 126 136 118 121 110 128 115 117 149 150 110 128 112 121 118 126 114 125 114 116 104 154 114 115 116 125 116 131 114 122 107 131 112 137 133 99 135 117 126 122 127 122 120 104 138 106 110 96 118 112 136 123 126 103 128 117 144 123 116 118 130 120 120 113 104 135 126 105 134 161 121 120 109 135 112 98 131 120 121 128 125 131 116 107 122 128 115 122 132 142 113 110 127 108 115 149 122 117 106 114 107 133 124 128 123 135 126 117 137 116 129 127 127 128 113 129 119 136 123 122 125 110 133 115 129 121 125 119 121 138 110 111 102 107 126 125 131 116 127 120 138 116 106 127 114 113 142 129 129 123 109 132 123 116 143 113 119 121 122 119 108 123 100 138 103 102 127 106 133 118 123 119 133 104 124 125 132 124 134 134 121 137 130 124 128 100 121 117 115 111 101 141 109 111 106 129 124 120 126 104 90 107 98 119 104 111 129 137 112 110 113 103 121 93 127 114 121 120 122 119 109 122 119 119 134 137 142 110 123 127 121 118 119 125 108 127 112 104 134 114 113 138 105 120 118 127 114 126 135 132 119 109 119 118 120 128 121 105 97 124 132 129 123 108 127 118 128 132 123 121 116 138 117 113 131 117 119 126 122 113 146 112 111 121 139 136 134 135 106 115 126 129 113 113 108 127 109 111 115 120 118 132 124 119 124 123 119 122 117 135 108 111 127 133 124 134 128 123 98 133 108 119 147 129 118 129 118 131 117 132 140 99 112 139 114 112 117 120 111 119 121 105 110 116 131 112 110 119 116 115 124 113 100 89 119 110 115 120 114 141 119 132 131 136 134 114 119 117 127 115 110 133 127 105 113 116 121 91 128 121 121 127 121 111 109 121 118 108 112 113 116 104 133 124 106 110 118 125 127 128 112 129 139 118 116 140 121 123 121 124 131 100 109 108 97 123 115 143 133 125 132 145 130 102 105 120 119 116 117 109 128 132 107 123 125 115 127 111 124 123 126 136 115 128 117 107 141 123 107 121 125 120 116 96 122 135 133 146 107 134 138 137 122 100 114 137 126 105 105 126 129 122 102 116 135 109 135 99 118 126 104 135 115 133 122 140 135 127 154 117 134 114 112 126 130 122 134 126 115 119 137 120 120 114 122 120 126 135 119 104 123 125 134 127 135 109 103 108 132 123 127 127 86 133 108 135 118 112 122 127 127 140 129 115 130 111 127 100 118 112 123 127 120 101 133 120 129 137 115 113 115 119 154 104 116 118 128 105 108 123 131 135 122 107 119 118 130 112 109 132 125 138 139 134 122 131 130 116 125 118 103 120 110 107 118 145 113 111 124 141 119 117 144 102 126 118 116 138 132 127 121 114 109 130 113 110 123 133 127 112 132 130 134 120 108 124 103 129 123 132 114 100 131 119 121 121 131 115 105 119 128 130 124 121 121 110 133 116 132 103 120 109 127 122 137 131 128 136 120 127 125 126 138 113 151 121 123 133 128 108 127 112 126 124 126 114 118 114 121 130 128 119 116 99 129 132 110 158 100 136 109 138 132 100 129 140 124 128 137 117 109 109 124 135 131 118 136 126 123 115 107 107 127 109 133 111 106 99 125 129 103 105 105 116 121 135 136 113 105 128 138 112 108 114 137 127 101 113 122 117 101 119 113 132 145 108 115 110 100 126 130 123 125 121 104 135 92 132 106 122 110 127 119 117 118 121 119 133 97 118 130 119 130 128 130 128 113 122 99 119 120 108 114 113 126 128 94 120 126 119 127 108 122 131 109 119 113 117 114 127 105 137 99 101 116 110 102 123 131 133 118 144 130 112 130 125 117 103 121 110 119 115 123 123 108 142 127 124 119 114 124 105 129 117 101 108 109 116 123 109 112 121 112 99 108 129 126 107 108 123 125 139 132 123 124 132 113 105 129 103 117 94 136 105 101 111 114 119 115 118 109 139 139 101 115 124 109 113 119 133 144 128 116 97 115 135 109 111 119 111 107 114 117 127 111 118 110 132 110 114 114 140 112 123 120 113 117 110 111 114 119 111 146 132 105 104 116 132 105 106 118 133 100 121 116 121 119 106 119 123 114 122 112 119 109 116 115 118 128 112 114 113 100 122 142 139 108 104 118 115 117 115 123 126 107 130 121 116 117 130 123 142 124 142 93 113 116 131 119 128 121 113 101 116 121 114 109 125 135 131 115 123 126 121 116 111 111 121 124 119 93 107 132 130 124 126 123 122 121 104 121 149 110 102 104 110 122 111 105 108 102 114 104 138 113 109 126 104 114 113 127 128 120 116 112 108 111 121 123 115 118 130 133 112 145 101 125 127 118 104 130 105 109 129 130 130 118 135 113 95 126 120 114 109 125 138 120 114 88 126 105 122 116 141 125 106 102 113 122 111 128 131 124 129 121 106 132 107 133 110 119 108 123 107 125 139 122 100 99 139 117 125 106 116 109 118 117 123 81 137 96 109 122 104 118 107 112 118 121 114 130 107 120 132 127 127 135 90 142 101 113 110 149 124 131 130 127 127 104 125 88 124 111 108 125 137 118 133 125 122 108 115 115 145 125 122 122 108 111 91 113 122 118 115 124 123 109 116 128 130 123 124 110 92 127 124 130 116 134 134 112 126 139 142 137 119 120 103 106 120 132 142 116 98 122 131 115 113 122 123 117 138 115 113 125 111 132 110 112 98 101 127 116 121 138 120 126 112 115 142 107 105 116 121 116 140 120 120 114 122 121 106 136 132 124 122 114 106 104 136 114 117 110 129 107 113 92 119 129 111 110 112 118 109 108 126 117 121 138 118 113 146 113 109 123 125 116 102 106 102 118 121 133 125 107 123 113 121 115 111 115 106 114 123 121 107 127 107 112 109 130 119 108 123 105 125 115 123 118 131 122 120 121 140 126 130 120 152 125 120 111 124 144 107 132 122 122 117 113 126 130 123 120 107 117 109 126 122 126 121 139 134 141 122 123 139 132 142 130 142 142 142 125 134 161 157 153 109 112 150 133 120 124 126 137 134 123 164 135 151 149 141 121 138 149 134 154 117 122 140 132 126 114 139 110 137 140 144 131 118 128 112 119 109 109 133 109 138 119 110 114 109 136 119 119 125 140 129 102 138 153 96 123 117 121 119 132 140 136 141 108 117 131 115 119 102 149 145 128 132 118 122 117 107 132 129 125 117 114 124 116 129 117 104 120 110 113 106 111 110 113 121 103 127 115 108 115 105 111 100 123 121 135 112 123 114 93 121 131 125 112 109 108 105 116 117 104 122 124 111 116 125 139 127 120 101 104 93 99 102 110 144 136 97 111 104 96 137 116 121 141 119 119 129 136 119 125 120 125 113 122 138 124 115 94 108 94 124 132 112 132 100 133 119 127 122 122 101 113 105 104 108 118 106 98 127 84 98 112 116 116 108 124 116 119 102 135 127 130 139 99 101 127 108 131 114 106 121 132 117 126 99 117 101 99 120 124 113 118 136 119 144 102 111 100 133 109 107 112 117 117 121 116 111 105 93 147 108 118 107 123 112 118 126 114 108 110 96 117 101 123 112 120 114 120 105 103 110 101 116 105 129 112 117 110 121 118 93 120 141 101 105 115 109 120 113 114 88 127 116 101 115 118 99 102 119 118 132 136 121 121 105 132 111 119 100 127 118 108 102 123 103 109 113 97 128 125 120 116 100 113 112 126 146 123 103 112 119 109 122 104 111 107 94 110 113 112 114 114 117 109 110 115 111 92 102 125 96 123 109 126 129 132 112 114 126 131 112 115 132 129 120 121 98 116 109 105 120 109 111 108 111 122 108 118 135 106 126 124 123 107 135 100 101 124 124 120 104 129 114 88 126 109 120 135 104 109 143 118 108 102 112 115 107 101 121 105 104 125 119 97 104 125 109 108 118 115 120 129 128 115 124 121 122 97 110 101 89 115 102 141 116 106 118 130 111 126 122 124 110 108 138 125 118 118 112 114 102 97 118 126 121 78 101 112 113 117 104 104 118 124 125 126 106 124 115 72 99 108 128 113 119 111 132 108 118 123 113 136 142 134 116 103 118 135 107 124 103 95 121 106 103 120 110 96 90 115 110 124 121 109 125 102 109 121 141 123 117 119 121 88 112 112 107 139 113 103 130 131 121 97 131 119 101 105 100 104 104 105 109 116 110 120 102 112 113 110 144 132 120 124 100 128 121 101 108 110 114 101 131 105 115 113 107 111 116 122 112 98 112 129 110 121 101 130 133 102 124 138 103 128 123 126 109 119 109 123 110 116 129 131 128 117 120 104 111 110 128 115 116 129 138 123 138 107 107 116 114 112 133 94 111 110 128 114 133 105 96 116 133 98 110 119 102 111 106 118 116 122 124 95 96 108 118 106 116 140 121 117 122 115 127 120 115 116 113 135 106 113 119 113 113 114 120 133 122 104 92 100 120 99 94 106 120 119 123 119 128 88 115 122 109 110 106 107 112 113 111 124 112 103 118 133 123 108 116 125 125 129 98 99 104 129 126 110 132 126 91 108 118 113 127 96 127 96 117 115 130 103 105 111 88 112 110 103 123 121 113 98 130 131 107 101 129 116 103 112 147 122 104 107 89 114 114 126 118 103 124 103 113 137 105 102 111 129 102 138 121 117 87 106 118 109 92 107 118 124 110 96 102 110 120 132 107 121 132 104 118 117 116 102 110 112 113 125 108 131 104 115 99 122 119 114 114 117 110 116 121 127 140 118 111 98 125 102 112 118 92 107 120 117 120 111 103 105 113 115 106 123 113 124 112 106 115 100 125 137 116 115 103 101 134 130 109 126 102 118 137 133 115 108 127 110 90 109 112 116 105 107 103 118 118 106 113 98 121 121 134 117 102 109 99 114 121 102 92 126 112 107 121 110 131 112 119 96 128 100 109 130 112 117 97 132 111 108 118 109 112 105 102 123 123 121 114 95 114 104 91 124 128 128 117 109 108 114 133 96 120 105 133 113 95 91 109 106 105 118 110 111 117 109 129 109 104 130 106 132 115 114 105 112 111 110 106 128 124 120 113 129 115 98 142 118 148 107 106 109 96 96 113 103 111 114 119 130 119 111 100 115 111 109 111 109 106 115 125 122 119 109 116 107 110 133 101 112 91 106 105 103 122 118 118 113 107 118 122 115 114 112 123 96 111 112 125 101 112 118 101 102 108 113 115 110 94 110 107 120 118 118 113 144 119 116 112 105 107 92 102 141 109 123 128 115 112 104 111 119 145 123 111 110 112 103 107 97 103 114 103 114 122 119 113 119 115 123 99 129 103 104 110 117 107 114 106 104 91 125 93 111 104 98 113 109 114 111 133 116 128 96 90 126 122 99 139 116 123 112 110 137 109 103 112 106 130 119 124 129 115 113 129 121 109 93 93 128 104 114 115 112 122 124 111 109 120 117 96 118 100 105 109 103 101 114 103 113 112 122 118 113 101 131 118 110 120 107 126 123 106 120 118 132 118 121 124 115 124 98 100 108 119 123 128 111 117 120 119 123 120 100 113 112 91 133 96 107 111 112 110 100 104 106 122 88 112 113 116 107 96 103 113 121 136 113 104 113 115 106 129 112 106 128 91 105 132 140 117 102 127 105 127 120 117 106 96 106 135 120 115 128 119 110 117 122 101 121 117 103 93 102 122 111 131 137 128 113 137 116 119 119 131 122 110 110 114 115 118 104 101 139 110 114 110 98 139 120 121 106 98 145 115 104 112 114 109 118 127 147 134 113 121 91 107 106 90 113 114 113 125 99 93 106 126 111 102 117 113 118 109 109 122 106 114 129 129 104 126 98 107 103 129 130 112 100 110 128 113 113 112 101 120 99 133 119 121 108 112 115 101 115 113 129 131 103 113 110 115 115 113 129 116 128 109 98 128 95 104 91 102 101 100 111 119 114 125 99 126 107 113 117 136 118 127 123 125 124 97 116 98 108 115 122 96 122 98 123 117 113 123 107 110 112 107 128 116 114 141 109 96 104 102 127 138 125 115 103 98 137 123 102 108 112 123 113 104 111 113 105 92 102 125 127 109 120 111 104 130 112 108 119 108 121 104 101 114 118 106 94 131 101 129 115 106 118 116 132 108 121 118 117 107 109 149 125 115 115 129 115 133 121 128 111 114 110 129 116 113 110 108 118 117 96 124 112 117 118 120 110 113 129 122 114 106 109 119 122 115 96 135 144 109 113 93 91 101 116 111 118 133 120 112 133 130 109 129 118 108 110 97 110 108 87 114 143 122 133 103 113 125 118 116 104 120 104 101 99 118 115 105 100 109 92 125 112 97 120 104 123 125 117 111 138 107 116 83 124 104 119 108 108 123 93 121 104 113 113 120 138 101 109 108 121 110 125 112 113 115 106 105 112 117 112 95 113 109 115 124 117 109 132 128 129 116 114 126 103 121 116 120 113 122 94 115 102 128 125 120 111 96 118 118 137 113 113 115 124 124 130 118 93 100 119 111 123 114 106 117 113 96 119 118 137 133 101 110 107 119 120 128 115 125 112 133 110 109 118 105 122 119 127 123 114 123 113 136 110 107 112 106 109 132 121 116 105 94 130 105 131 121 110 109 102 106 117 108 114 127 98 119 99 123 121 112 111 104 126 103 116 115 122 108 104 122 133 103 121 116 124 124 128 91 118 125 106 128 128 100 110 119 128 106 95 118 111 107 120 101 114 117 111 111 107 113 120 103 118 100 114 110 115 112 121 112 119 93 135 125 119 102 137 111 108 121 134 126 124 148 81 115 121 115 109 110 99 119 125 118 101 124 102 122 109 127 121 131 130 115 112 128 121 135 132 144 116 114 107 119 113 119 99 130 130 117 135 115 113 126 108 124 139 125 111 132 105 132 104 108 127 104 124 120 140 107 141 143 107 123 122 110 107 124 115 123 120 102 137 142 124 122 103 112 132 105 107 123 112 127 108 107 109 111 118 121 102 112 136 113 119 97 128 111 106 114 122 112 140 113 118 134 111 114 112 117 117 114 118 118 117 118 120 133 128 137 121 113 115 101 131 102 121 108 108 116 109 114 132 134 119 108 120 123 112 123 110 128 119 129 106 137 105 112 108 112 130 112 107 93 108 104 106 119 120 114 98 116 131 120 106 116 120 124 95 108 109 123 106 118 131 108 99 114 98 108 108 136 128 112 128 119 110 125 117 113 111 110 108 120 112 134 102 120 114 111 105 120 111 122 111 106 117 123 124 122 130 118 114 107 105 116 116 95 124 87 127 108 139 110 103 106 115 126 117 112 118 106 132 102 112 123 129 117 127 104 144 126 134 119 112 130 150 118 135 123 121 99 107 108 104 119 103 116 115 113 87 118 118 116 100 118 119 103 100 118 130 127 123 120 132 119 135 105 122 129 107 124 94 123 119 97 127 108 124 99 102 115 114 131 110 137 107 121 125 119 110 103 118 126 105 124 108 111 127 127 113 111 103 123 113 122 114 125 126 122 118 131 139 117 120 120 121 113 118 120 115 105 123 120 114 115 117 126 105 106 135 115 122 128 127 109 112 118 126 112 116 92 104 96 100 113 124 108 116 122 118 123 125 120 125 100 139 109 105 114 108 129 118 119 146 99 108 115 105 126 100 116 110 128 109 102 117 130 110 101 90 111 96 129 120 114 98 117 131 107 122 98 117 124 129 117 115 116 108 95 113 125 131 126 111 111 119 93 109 104 98 113 85 111 107 118 123 116 109 107 111 129 112 122 117 125 111 127 113 102 128 101 107 108 137 122 122 118 116 123 119 121 118 92 102 108 114 104 103 106 102 122 111 108 136 111 120 116 140 90 130 129 104 111 109 108 121 114 124 98 117 129 115 111 119 100 100 115 122 83 125 98 105 112 119 117 119 103 103 97 114 119 117 96 114 113 116 128 104 120 119 127 116 115 99 121 111 123 119 113 118 97 90 93 97 127 126 120 110 108 107 122 128 124 127 123 115 118 114 103 108 95 125 122 117 113 126 114 121 85 105 109 110 106 109 134 132 125 115 105 150 116 115 101 104 120 128 104 106 118 113 130 113 93 109 88 96 125 105 109 113 104 121 109 121 117 114 122 108 123 127 117 124 127 98 125 117 115 132 114 113 91 109 107 98 109 126 112 150 96 103 109 123 121 134 122 127 125 109 100 131 96 88 124 124 105 138 135 123 101 107 114 108 108 124 100 108 116 106 112 117 122 111 110 122 124 121 119 124 129 124 100 107 128 127 126 116 106 123 111 100 123 117 102 142 112 123 113 107 130 111 109 100 111 111 106 98 116 106 128 117 107 125 124 99 117 124 122 115 123 90 122 112 105 113 103 108 116 125 109 127 103 129 114 107 126 135 113 120 119 110 97 116 145 109 121 117 136 135 121 113 101 119 116 130 129 111 120 130 110 117 113 124 116 118 116 112 116 109 96 117 100 120 109 123 116 119 120 120 122 97 91 114 136 122 115 125 127 122 119 118 111 124 119 120 106 116 118 107 119 114 97 137 128 118 125 139 123 113 128 115 96 123 115 108 115 114 121 106 130 125 147 97 130 122 134 110 134 123 123 114 116 126 120 100 111 130 137 112 126 108 133 123 114 143 105 120 112 120 119 108 111 119 103 117 137 118 109 115 112 112 105 109 122 107 96 123 98 98 115 108 116 100 114 108 115 120 98 124 128 116 127 103 107 118 125 122 115 121 117 106 141 125 106 112 88 111 124 105 124 123 99 119 107 127 140 100 123 110 116 122 109 111 117 134 99 122 117 102 123 122 104 124 147 103 113 117 116 124 128 118 111 113 95 108 124 98 142 105 117 125 112 155 120 110 110 120 120 110 112 117 92 131 134 90 123 119 133 108 119 117 128 123 117 117 122 116 122 114 125 129 119 112 107 107 121 122 110 123 124 121 125 142 123 112 115 123 130 101 104 98 120 123 105 105 112 104 111 115 111 129 120 115 125 115 127 95 96 114 107 113 127 111 119 112 98 125 113 119 127 119 131 123 113 113 104 105 123 122 128 100 118 99 121 100 115 105 132 101 123 125 103 105 117 120 119 115 127 134 107 113 143 106 125 105 104 120 110 126 115 120 119 112 120 131 110 124 118 119 107 111 116 105 125 105 127 114 112 106 112 117 115 120 122 141 109 108 97 115 149 113 136 109 135 101 112 123 128 113 122 118 130 116 105 117 102 108 122 122 104 97 109 98 134 117 118 111 110 126 124 111 117 117 131 112 127 123 112 119 98 123 114 116 104 115 126 105 120 88 117 115 120 124 120 111 112 117 106 120 111 126 114 110 120 107 110 110 121 101 113 141 124 131 111 124 100 108 91 120 122 119 125 147 119 123 89 110 117 125 115 75 129 124 116 96 114 148 117 117 113 102 117 106 124 123 137 109 114 96 99 130 115 122 108 115 109 129 131 106 102 130 108 128 118 126 100 119 101 95 129 120 127 120 98 106 123 111 120 107 130 120 97 112 117 118 116 107 132 110 120 126 126 113 98 118 131 102 115 124 97 136 125 125 112 131 109 100 109 122 117 113 120 118 124 129 116 116 122 128 121 131 113 106 115 115 120 104 112 117 114 100 112 137 116 127 115 117 128 111 140 95 111 110 125 111 118 107 116 122 108 105 121 132 120 123 113 96 100 93 103 110 94 106 110 129 111 89 125 113 106 118 126 94 115 129 127 115 115 114 94 111 91 109 102 111 103 125 115 108 142 102 118 119 122 108 107 116 117 107 114 99 127 98 124 100 107 102 109 110 113 116 119 110 107 123 105 109 126 118 119 120 117 150 128 111 111 107 110 102 115 120 116 115 136 116 127 95 114 117 98 137 133 115 135 109 91 124 122 131 109 102 113 139 108 109 118 114 114 121 112 110 116 125 114 100 108 106 110 102 119 122 105 137 119 107 102 122 106 109 109 109 124 128 98 112 118 119 119 125 112 103 104 107 98 110 128 113 118 116 115 135 115 99 102 112 126 118 122 118 101 111 120 121 110 116 117 135 111 108 118 102 95 124 106 115 112 115 126 102 113 106 98 125 134 102 116 109 121 109 121 111 98 122 149 115 112 121 123 139 130 127 122 109 102 135 106 105 105 108 116 121 96 123 106 112 112 123 112 101 104 117 114 91 124 114 116 103 114 119 127 121 110 118 100 120 105 125 97 118 121 106 117 121 97 142 105 123 112 113 120 108 108 111 133 115 117 106 97 115 115 124 108 111 114 125 114 102 112 97 110 105 108 153 101 139 108 109 114 118 145 116 115 126 117 109 107 128 109 121 116 126 114 113 105 119 145 92 117 120 90 120 105 103 129 123 116 92 104 92 128 95 106 121 98 118 110 118 124 122 126 114 90 126 137 100 109 132 111 124 98 119 121 97 117 106 99 110 109 127 124 132 120 126 111 106 108 110 114 108 113 110 131 121 107 113 107 95 91 129 107 127 112 112 110 110 114 93 119 104 125 129 119 107 133 120 114 100 96 135 130 125 123 125 105 115 114 118 119 112 120 109 103 106 101 114 112 102 118 113 93 111 116 110 102 131 95 111 111 113 101 118 122 136 128 122 114 135 115 114 131 102 115 123 137 118 113 105 128 114 115 127 117 97 115 109 128 114 137 107 120 107 110 124 120 105 103 130 129 113 108 121 88 126 130 105 129 121 114 135 102 111 118 104 119 126 117 100 102 126 130 122 102 102 124 105 103 118 136 103 117 127 129 116 120 125 127 85 125 124 117 117 121 109 143 108 134 127 98 120 126 131 113 116 120 106 126 119 112 123 105 102 131 122 127 123 110 120 128 117 124 109 119 105 122 121 123 119 113 140 123 121 104 145 129 101 138 113 126 136 113 116 115 118 117 132 126 111 128 109 133 122 109 108 123 105 150 134 107 124 115 136 94 120 98 118 102 118 108 100 122 113 123 114 112 115 119 129 124 119 106 136 112 125 129 116 109 123 109 126 125 111 102 117 110 126 125 110 127 139 127 111 126 127 117 93 118 118 111 108 135 128 100 126 120 113 141 116 118 135 103 103 131 114 93 116 128 100 112 123 111 115 123 108 122 133 124 124 127 109 116 126 102 91 117 136 133 117 115 112 126 96 123 132 112 140 109 117 135 108 113 97 101 103 105 109 121 123 125 122 127 112 111 124 135 126 107 110 124 118 121 114 127 106 124 118 102 96 112 112 115 117 123 124 107 121 101 134 103 102 122 112 109 114 112 119 112 109 111 105 114 115 119 113 132 134 115 138 114 112 115 103 119 127 129 116 130 116 126 117 117 125 129 88 111 106 113 102 120 123 132 105 115 103 102 106 117 123 124 119 134 112 104 94 133 126 123 125 122 109 129 113 109 132 116 100 115 103 94 106 98 128 118 117 125 119 137 139 118 117 116 106 123 107 116 140 122 95 111 118 93 117 123 112 112 130 120 142 123 113 124 114 102 120 110 138 116 116 96 125 124 109 103 113 99 130 119 112 121 130 117 107 105 100 114 110 100 122 107 124 99 142 126 146 116 119 100 106 102 110 103 123 111 130 114 118 115 120 127 117 120 106 131 122 103 111 113 117 107 104 132 113 132 100 118 113 104 107 123 112 116 119 117 102 127 116 103 123 114 112 110 123 136 119 134 106 105 105 123 112 128 118 106 140 111 139 128 123 122 104 108 128 103 106 114 106 108 106 122 116 122 103 109 111 117 138 122 106 113 115 153 105 126 110 129 108 111 113 113 109 103 104 118 126 115 107 115 112 114 111 104 107 109 115 108 102 105 108 116 117 106 110 103 125 109 119 104 138 125 115 105 118 116 133 125 103 116 112 128 113 114 100 111 101 122 114 112 108 114 130 110 132 120 122 118 124 137 120 138 91 115 112 111 120 128 113 108 136 132 103 125 129 117 113 111 108 107 118 123 120 110 118 99 127 100 93 118 131 117 117 141 99 104 115 103 117 104 122 104 119 104 136 111 118 124 100 115 113 106 119 112 126 121 108 110 112 105 118 124 115 100 96 132 133 104 112 112 100 120 112 124 123 113 117 123 118 124 129 135 114 99 118 123 129 104 102 129 112 113 124 105 118 119 111 104 110 113 118 116 124 105 128 104 109 106 119 111 119 113 112 123 104 84 112 117 117 144 116 125 119 95 122 117 118 115 129 113 134 113 101 119 126 127 118 124 117 120 114 123 126 118 125 136 123 109 147 100 114 141 120 118 114 93 137 117 112 138 122 119 125 129 133 127 109 101 113 118 105 106 124 111 115 115 111 128 124 116 127 121 93 104 112 116 125 125 116 116 116 115 135 121 126 97 126 120 89 127 119 102 129 107 116 118 104 118 103 103 100 112 122 115 119 116 122 124 116 123 108 120 111 120 118 124 111 121 118 114 125 106 111 140 118 116 101 126 102 104 136 126 120 124 116 135 111 101 127 119 102 140 104 112 125 128 113 129 112 128 115 100 131 102 101 102 108 129 115 119 133 113 126 141 110 119 108 143 112 119 139 118 95 108 121 122 115 99 114 121 127 111 111 112 120 123 106 114 129 127 118 125 128 119 102 151 110 136 99 110 124 101 120 106 138 112 112 114 130 101 118 115 125 119 101 105 111 134 130 140 124 110 114 119 116 115 106 116 103 124 107 122 117 119 108 124 135 103 117 132 120 105 118 115 121 100 118 109 105 112 135 122 95 100 105 117 108 127 125 113 115 132 114 111 84 109 109 133 114 113 111 114 112 100 121 114 125 123 121 116 110 129 112 108 113 115 117 94 112 112 105 111 133 127 101 115 108 142 121 122 125 130 126 118 130 121 106 121 121 106 127 103 108 99 100 118 118 126 117 118 104 122 123 134 115 113 104 115 110 121 124 124 131 116 121 107 115 120 117 102 113 121 122 103 135 122 134 130 116 83 132 142 116 105 120 108 110 117 99 119 104 120 129 120 120 131 98 125 116 117 119 111 110 139 107 129 126 143 116 138 138 124 117 112 102 125 123 117 131 98 121 92 104 129 120 123 113 122 130 109 124 112 126 119 111 107 130 116 101 129 126 110 123 131 104 108 109 109 105 114 129 124 136 113 123 104 106 130 114 132 113 133 128 129 105 137 97 120 127 99 121 110 122 103 108 115 119 105 114 118 116 120 123 116 120 114 115 127 117 103 118 144 124 111 102 117 101 111 119 119 115 95 122 113 134 120 110 129 128 118 124 122 99 125 125 126 111 116 124 112 126 107 113 107 117 120 122 103 124 122 101 130 108 115 98 136 119 104 116 110 136 106 123 107 116 123 111 105 118 136 120 117 119 114 132 120 120 116 128 116 104 128 109 127 110 139 97 133 114 104 127 118 120 127 119 116 119 104 116 120 131 133 120 120 113 129 115 110 119 137 110 115 127 114 103 107 123 109 124 111 116 122 109 102 108 114 104 120 117 115 121 115 114 145 121 137 111 107 120 115 116 112 120 122 126 131 128 119 111 134 123 116 109 131 93 141 129 115 135 133 128 135 133 114 121 107 125 121 118 122 126 115 127 120 102 119 100 116 147 145 122 120 130 113 114 131 128 121 116 116 101 125 133 115 103 118 113 136 124 117 147 135 110 124 136 127 118 109 122 121 104 129 109 126 119 134 119 132 112 122 112 116 137 114 108 107 116 133 115 133 135 128 131 123 128 134 119 140 132 134 126 127 112 116 128 139 129 111 133 122 91 118 136 132 119 141 122 117 121 124 128 125 142 120 127 127 114 122 107 132 124 110 93 151 118 111 133 112 125 131 125 145 137 116 110 122 142 101 122 117 146 142 145 125 127 143 113 125 116 121 118 134 132 134 91 128 125 120 109 118 123 148 116 118 117 127 114 131 112 136 118 111 127 124 136 139 133 116 133 137 113 134 122 132 133 122 127 125 138 110 127 121 121 141 122 124 105 121 128 129 121 131 120 114 128 117 137 127 116 129 119 112 131 133 99 124 111 136 129 120 146 122 114 118 104 129 110 120 124 131 129 129 140 128 108 126 124 123 115 134 131 117 116 116 108 121 107 132 127 131 123 109 122</counts>
			</dataPoints>
		</scan>
	</xrdMeasurement>
</xrdMeasurements>