File: data/XRD/_misc/old/XG-700C/_absolute_2th-om_10-130deg_PIXscan_56min_1.xrdml
<xrdMeasurements xmlns="http://www.xrdml.com/XRDMeasurement/2.1" xmlns:xsi="http://www.w3.org/2001/XMLSchema-instance" xsi:schemaLocation="http://www.xrdml.com/XRDMeasurement/2.1 http://www.xrdml.com/XRDMeasurement/2.1/XRDMeasurement.xsd" status="Completed">
	<comment>
		<entry>Configuration=Factory configuration, Owner=User-1, Creation date=7/8/2013 4:01:53 PM</entry>
		<entry>Goniometer=PW3050/65 (Theta/2Theta); Minimum step size 2Theta:0.0001; Minimum step size Omega:0.0001</entry>
		<entry>Sample stage=MRD Cradle; Minimum step size Phi:0.01; Minimum step size Chi:0.01; Minimum step size X:0.01; Minimum step size Y:0.01; Minimum step size Z:0.001</entry>
		<entry>Diffractometer system=XPERT-PRO</entry>
		<entry>Measurement program=C:\PANalytical\Data Collector\Programs\Jorrit\2thom\_absolute_2th-om_10-130deg_PIXscan_56min.xrdmp, Identifier={15BCCF57-2807-42BD-B5B9-ECC0B3DC9284}</entry>
		<entry>Batch program=C:\PANalytical\Data Collector\Programs\SimonL\batch4x_2thom_10-130°_z9.1_x0,10,20,30_y0_57min.xrdmp, Identifier={EED9823A-2BEB-424C-9252-345C4EF2834A}</entry>
	</comment>
	<sample type="To be analyzed">
		<id></id>
		<name></name>
		<preparedBy></preparedBy>
	</sample>
	<xrdMeasurement measurementType="Scan" status="Completed" sampleMode="Reflection">
		<comment>
			<entry>_absolute_2th-om_10-130deg_PIXscan_56min</entry>
			<entry>PHD Lower Level = 4.83 (keV), PHD Upper Level = 11.27 (keV)</entry>
		</comment>
		<usedWavelength intended="K-Alpha 1">
			<kAlpha1 unit="Angstrom">1.5405980</kAlpha1>
			<kAlpha2 unit="Angstrom">1.5444260</kAlpha2>
			<kBeta unit="Angstrom">1.3922500</kBeta>
			<ratioKAlpha2KAlpha1>0.5000</ratioKAlpha2KAlpha1>
		</usedWavelength>
		<incidentBeamPath>
			<radius unit="mm">320.00</radius>
			<xRayTube id="1010048" name="Empyrean Cu LFF HR (9430 033 7310x) DK442154">
				<tension unit="kV">40.0</tension>
				<current unit="mA">40.0</current>
				<anodeMaterial>Cu</anodeMaterial>
				<focus type="Line">
					<length unit="mm">12.0</length>
					<width unit="mm">0.4</width>
					<takeOffAngle unit="deg">4.2</takeOffAngle>
				</focus>
			</xRayTube>
			<xRayMirror id="27010001" name="Inc. Beam Cu W/Si (parabolic MRD)" hybrid="false">
				<crystal type="Graded" shape="Parabolic">W/Si</crystal>
				<acceptanceAngle unit="deg">0.800</acceptanceAngle>
				<length unit="mm">60.0</length>
			</xRayMirror>
			<sollerSlit id="21010002" name="Soller slits 0.04 rad.">
				<opening unit="rad">0.0400</opening>
			</sollerSlit>
			<mask id="22030007" name="Fixed mask 2 mm">
				<distanceToSample unit="mm">220.00</distanceToSample>
				<width unit="mm">2.00</width>
			</mask>
			<divergenceSlit id="22010007" name="Fixed slit 1/8°" xsi:type="fixedDivergenceSlitType">
				<distanceToSample unit="mm">220.00</distanceToSample>
				<height unit="mm">0.19</height>
			</divergenceSlit>
		</incidentBeamPath>
		<diffractedBeamPath>
			<radius unit="mm">320.00</radius>
			<sollerSlit id="21010002" name="Soller slits 0.04 rad.">
				<opening unit="rad">0.0400</opening>
			</sollerSlit>
			<receivingSlit id="22010001" name="Fixed slit 4°">
				<height unit="mm">5.88</height>
			</receivingSlit>
			<detector id="7010017" name="PIXcel3D 1x1 detector" xsi:type="areaDetectorType">
				<phd unit="%">
					<lowerLevel>30.0</lowerLevel>
					<upperLevel>70.0</upperLevel>
				</phd>
				<mode>Scanning</mode>
				<activeChannelsEquatorial>255</activeChannelsEquatorial>
				<activeChannelsAxial>255</activeChannelsAxial>
				<pitchEquatorial unit="mm">0.05500</pitchEquatorial>
				<pitchAxial unit="mm">0.05500</pitchAxial>
				<readOutPeriod unit="seconds">0.135</readOutPeriod>
			</detector>
		</diffractedBeamPath>
		<scan appendNumber="0" mode="Continuous" scanAxis="2Theta-Omega" status="Completed">
			<header>
				<startTimeStamp>2024-09-03T18:12:27+02:00</startTimeStamp>
				<endTimeStamp>2024-09-03T19:08:31+02:00</endTimeStamp>
				<author>
					<name>PRO-MRD</name>
				</author>
				<source>
					<applicationSoftware version="6.1b">Data Collector</applicationSoftware>
					<instrumentControlSoftware version="7.0E 20130304">XPERT-PRO</instrumentControlSoftware>
					<instrumentID>0000000011142674</instrumentID>
				</source>
			</header>
			<dataPoints>
				<positions axis="2Theta" unit="deg">
					<startPosition>9.99826193</startPosition>
					<endPosition>129.99755682</endPosition>
				</positions>
				<positions axis="Omega" unit="deg">
					<startPosition>4.99913096</startPosition>
					<endPosition>64.99877841</endPosition>
				</positions>
				<positions axis="Phi" unit="deg">
					<commonPosition>0.00</commonPosition>
				</positions>
				<positions axis="Chi" unit="deg">
					<commonPosition>0.00</commonPosition>
				</positions>
				<positions axis="X" unit="mm">
					<commonPosition>0.00</commonPosition>
				</positions>
				<positions axis="Y" unit="mm">
					<commonPosition>0.00</commonPosition>
				</positions>
				<positions axis="Z" unit="mm">
					<commonPosition>9.100</commonPosition>
				</positions>
				<commonCountingTime unit="seconds">32.895</commonCountingTime>
				<counts 234 214 217 221 230 219 201 244 208 231 213 229 225 218 212 219 229 234 230 216 230 212 232 222 212 245 203 211 235 191 204 217 209 256 229 218 211 222 217 233 233 215 205 218 259 229 220 226 194 214 245 204 248 204 224 168 236 228 203 210 205 196 200 229 241 220 204 205 228 209 223 208 222 191 207 218 198 230 216 221 226 220 212 221 224 238 222 186 227 216 198 222 201 203 232 224 208 200 206 206 218 208 211 210 214 225 215 195 219 216 196 222 183 212 178 205 208 199 204 221 193 193 222 207 215 209 201 181 203 221 189 193 235 216 203 207 202 191 205 190 190 200 208 202 193 187 192 224 198 205 200 200 201 211 180 221 211 221 210 217 192 187 178 176 197 202 205 196 203 179 205 218 220 213 223 218 183 209 202 239 214 183 208 208 195 194 224 201 199 193 203 204 205 191 198 197 195 177 203 211 180 176 184 174 235 211 192 187 176 182 208 190 190 202 208 194 189 190 203 201 196 216 180 189 174 181 202 194 201 224 208 163 191 194 178 215 185 202 197 191 180 193 193 179 202 192 233 197 186 185 188 205 182 198 197 199 188 183 188 179 192 178 183 165 179 181 181 191 183 179 180 202 207 165 199 187 170 189 172 193 162 191 171 201 190 185 194 173 192 195 180 186 178 194 176 198 185 183 200 184 189 173 179 177 158 176 183 198 209 198 185 189 194 192 170 200 196 190 160 176 188 178 182 171 184 190 172 169 176 197 187 167 175 170 185 191 150 192 169 204 166 167 174 187 185 185 181 162 167 172 148 188 153 174 176 164 182 175 170 180 180 197 153 178 168 172 175 164 164 171 156 173 176 174 170 176 159 190 177 189 186 170 163 172 175 168 173 188 192 210 171 181 151 165 183 144 163 167 195 186 164 166 158 154 187 182 177 167 166 177 187 150 200 180 168 162 145 161 157 183 181 164 170 193 175 171 195 186 176 169 173 176 177 168 158 185 162 164 171 174 166 138 163 170 195 162 163 156 171 183 154 175 157 144 163 157 155 175 153 158 145 185 159 150 159 175 160 175 177 161 162 177 180 180 159 180 163 162 164 175 166 170 158 158 155 161 168 173 152 157 163 194 147 153 166 160 151 156 180 163 163 174 164 158 164 162 146 175 152 163 170 181 156 174 173 154 159 155 153 151 161 141 175 151 177 158 163 138 158 173 153 155 192 142 161 144 177 165 173 146 159 162 148 156 165 180 174 195 123 168 143 153 180 174 163 153 144 156 162 157 161 172 177 178 159 152 175 163 143 150 170 148 169 130 145 150 163 162 158 147 184 169 167 136 147 169 178 162 171 141 141 142 152 174 155 164 148 154 174 158 147 153 151 156 138 158 187 147 153 159 150 156 161 157 152 149 136 153 156 167 144 138 148 157 133 162 161 167 150 164 161 157 177 138 166 121 137 156 146 139 141 176 185 139 146 139 157 157 162 150 156 171 151 168 148 146 127 147 164 185 185 163 150 135 138 145 140 159 135 134 161 156 176 140 151 144 160 145 159 148 149 144 169 162 163 168 153 152 141 157 154 145 141 162 181 141 160 152 163 159 147 182 144 140 177 141 153 155 147 174 166 177 153 143 143 159 151 154 150 149 154 153 170 151 132 150 151 149 150 176 158 168 153 153 146 157 157 158 162 143 143 166 142 176 172 146 134 151 144 141 171 174 159 186 162 149 153 137 151 148 138 168 143 147 153 167 155 140 135 162 169 173 147 137 165 172 167 131 161 137 149 144 154 155 150 157 156 158 169 167 144 145 146 163 159 167 163 135 156 139 140 138 157 150 163 163 151 160 153 145 163 162 142 128 154 162 153 141 167 160 148 169 146 161 165 163 161 159 142 158 168 155 144 193 168 139 160 157 135 157 156 148 170 165 157 159 170 142 148 155 158 162 152 146 159 160 157 158 172 157 139 135 168 128 164 175 161 150 153 131 143 164 166 170 154 146 164 142 174 169 163 175 173 158 142 158 170 159 168 150 166 169 160 164 172 171 154 178 170 183 161 159 149 165 161 165 179 143 168 179 170 170 158 140 158 165 161 165 169 150 153 179 150 147 154 166 193 156 147 126 166 164 168 154 186 147 161 157 157 145 175 158 149 159 167 168 146 175 151 158 170 151 171 166 172 161 160 176 165 160 173 152 169 163 158 162 156 178 188 154 151 185 162 144 155 152 186 177 155 148 161 180 148 169 181 160 173 154 150 156 162 179 182 144 172 177 156 182 139 165 171 161 164 169 167 191 164 169 170 171 192 161 182 147 159 162 167 173 167 144 170 152 188 158 186 158 168 145 149 170 179 160 179 170 173 149 179 179 173 160 176 159 208 147 202 159 169 157 152 143 160 168 182 156 184 167 177 158 156 141 194 146 153 167 173 151 164 174 179 168 167 169 180 173 172 193 154 156 164 186 151 153 165 144 150 153 160 150 161 171 167 162 149 184 187 159 163 158 188 171 168 160 174 176 205 136 196 155 165 163 174 159 167 160 160 161 175 175 157 176 158 168 167 184 169 159 165 167 172 186 162 170 181 174 173 186 163 177 159 186 178 196 177 155 189 166 170 185 175 181 171 147 166 156 163 188 174 177 162 182 177 143 189 166 174 172 164 160 175 162 177 155 163 169 186 180 183 162 187 162 176 152 199 162 181 166 164 169 186 181 166 163 181 156 158 148 177 153 176 156 187 173 204 176 171 148 164 190 173 174 173 155 188 157 190 181 169 178 183 170 150 192 175 177 154 160 188 155 184 186 172 169 151 158 169 193 186 171 170 176 178 155 172 168 180 166 175 171 160 149 176 185 164 144 164 164 170 157 153 184 176 167 174 170 202 175 174 156 168 170 151 159 175 171 157 195 176 185 172 173 205 155 163 168 175 170 168 193 180 158 161 148 176 184 168 144 179 150 149 185 172 186 175 168 155 171 161 160 153 166 205 178 139 145 159 181 163 169 178 157 166 151 168 198 168 171 173 156 150 175 165 178 150 158 175 160 159 195 176 179 149 170 184 179 157 179 162 152 162 170 186 185 142 184 165 170 180 161 188 157 158 166 170 148 158 175 159 135 139 171 173 191 154 175 160 160 181 165 159 191 172 150 176 177 169 159 144 157 187 165 174 182 176 160 154 161 169 153 174 154 156 187 184 170 145 143 184 145 158 186 164 177 170 163 163 172 159 162 156 157 148 166 171 137 164 153 136 173 159 185 153 153 158 165 159 170 172 185 176 189 172 172 168 163 180 164 181 170 159 196 181 184 177 165 170 151 160 174 143 136 182 156 179 166 155 177 164 149 172 156 168 182 152 182 152 160 161 170 147 174 179 152 166 154 175 171 143 169 155 147 150 169 181 152 179 178 170 147 175 176 163 153 184 147 159 149 158 145 163 148 165 139 153 165 158 151 157 164 157 162 160 153 161 169 166 151 158 173 162 175 140 170 179 190 168 167 156 186 146 148 156 166 167 147 158 146 150 140 144 166 168 146 157 168 161 151 155 133 146 165 136 154 158 156 150 167 148 159 166 172 144 161 178 165 150 180 160 146 171 160 147 150 175 154 172 158 162 158 138 181 143 154 156 144 143 150 136 154 163 148 134 153 144 161 159 158 155 143 147 150 153 145 154 170 156 148 174 135 146 145 150 163 157 157 156 148 128 169 128 164 159 136 159 120 167 137 150 147 140 170 143 154 134 152 156 138 148 147 170 143 130 154 181 144 157 130 132 160 145 142 172 139 164 152 156 155 140 145 177 167 144 144 139 148 146 127 152 152 149 144 170 163 135 146 159 142 149 154 139 151 151 170 151 137 143 136 147 136 131 146 156 158 126 147 144 136 130 160 149 157 148 158 152 137 145 133 133 156 149 162 133 127 129 140 132 146 152 139 144 124 146 148 158 145 156 151 154 126 136 126 156 133 140 140 137 172 136 127 171 151 139 163 153 158 150 138 133 149 150 145 146 126 159 136 113 139 129 148 145 139 136 140 144 138 130 152 136 137 158 154 137 137 150 140 120 117 145 150 158 136 119 142 133 160 134 121 139 110 163 144 146 149 112 144 144 141 115 121 142 150 169 130 162 156 131 156 110 148 135 149 148 130 164 131 159 152 131 140 138 141 129 137 137 143 136 134 138 139 116 136 134 167 146 136 156 150 148 136 157 121 137 152 149 130 149 141 137 152 157 161 170 139 121 175 137 132 141 144 135 153 155 119 152 131 119 148 141 128 139 151 144 145 127 148 130 159 122 143 149 123 133 156 150 149 142 127 120 138 130 144 147 124 147 115 154 129 145 168 126 145 137 144 157 150 126 123 159 138 142 123 133 160 124 121 131 154 126 121 132 128 140 142 132 174 126 126 127 135 131 132 142 127 136 137 139 138 121 140 144 127 131 141 147 131 130 133 133 119 126 127 136 149 133 138 132 145 138 153 129 159 123 140 138 136 130 144 148 132 126 137 144 125 127 120 112 146 132 125 108 122 148 136 144 114 137 133 124 126 133 126 134 143 132 131 131 108 133 138 109 123 143 149 133 122 127 130 112 123 151 153 123 137 151 123 120 146 124 137 140 150 146 128 137 144 140 112 113 130 126 141 144 123 121 145 139 131 138 132 122 137 153 118 142 126 134 126 111 134 138 121 122 126 120 134 104 147 149 120 144 126 151 135 135 135 146 139 132 141 123 114 104 122 127 149 152 118 107 138 131 138 139 122 133 122 124 146 134 123 144 124 113 132 149 123 134 128 151 120 128 122 128 121 140 132 132 124 133 138 125 121 139 131 133 126 131 124 125 143 115 120 135 153 132 125 149 142 135 125 114 141 137 120 141 130 122 135 145 129 131 129 117 145 109 112 123 141 128 125 118 132 109 110 119 130 112 121 132 119 133 119 129 130 126 133 131 121 120 123 99 127 133 140 112 118 122 122 143 123 151 133 129 116 122 138 131 127 131 118 140 153 153 122 127 116 133 130 132 145 123 113 111 140 134 136 139 120 122 140 142 139 119 123 108 128 137 122 120 128 120 115 118 114 134 132 133 125 130 117 128 129 136 127 120 120 123 134 122 135 122 146 122 143 136 126 137 129 130 123 136 109 131 95 100 113 130 106 116 96 113 129 121 134 131 147 121 137 123 108 135 97 118 137 107 127 134 110 124 107 131 135 135 144 114 135 130 116 111 116 124 112 137 122 130 121 123 111 120 124 120 116 123 147 127 109 125 113 145 121 129 117 131 127 126 128 140 129 121 112 109 131 114 123 127 135 149 122 120 137 120 124 125 114 88 123 115 126 124 128 121 125 134 122 107 129 112 147 117 131 124 125 122 139 115 117 128 114 123 109 105 115 105 105 143 112 111 117 120 110 131 114 130 117 130 131 147 96 128 133 114 128 113 120 132 117 110 140 132 115 123 117 100 110 122 130 124 130 122 112 123 113 152 108 121 122 126 113 139 104 144 124 125 122 109 131 106 133 116 110 114 121 135 138 133 129 127 114 132 123 126 142 129 121 122 115 110 104 128 122 100 122 119 124 126 128 117 100 122 103 119 136 127 138 122 123 152 108 129 122 143 104 129 125 110 115 122 122 135 118 129 117 109 119 102 120 123 131 124 133 129 120 131 138 116 118 137 120 119 136 116 115 127 137 124 121 110 112 106 126 113 113 111 120 142 117 132 114 117 120 127 135 110 118 132 111 117 120 103 123 109 111 109 135 137 110 124 136 116 128 135 111 105 127 127 110 92 122 133 129 116 135 114 106 120 132 109 121 114 121 115 119 127 126 117 117 117 127 147 126 129 120 120 121 134 92 139 122 116 129 128 136 134 131 153 117 125 110 125 137 100 111 120 115 126 122 127 117 132 112 130 134 129 125 123 120 124 143 121 114 115 125 136 129 122 125 132 109 140 125 114 121 136 119 117 131 119 121 132 119 121 113 130 131 107 120 124 125 126 132 128 125 121 118 114 125 140 113 128 123 126 127 104 126 97 107 105 125 133 111 117 120 129 119 126 113 106 118 114 106 129 121 105 124 122 127 118 117 131 118 121 134 100 119 118 122 104 111 114 126 121 124 113 133 124 107 119 120 133 99 128 112 128 119 134 134 132 123 109 112 125 130 115 119 107 106 119 121 135 116 133 134 125 111 117 117 122 118 114 129 115 108 121 132 122 126 107 115 99 124 123 107 131 102 134 109 105 117 134 135 115 122 121 112 101 142 103 107 132 115 118 119 113 112 144 120 129 122 136 101 116 117 97 116 129 103 136 108 94 126 123 151 96 130 104 118 124 123 128 101 115 117 111 116 125 114 121 116 141 101 119 120 127 134 124 130 110 123 129 106 118 121 113 109 111 117 148 115 114 126 139 123 131 130 112 111 115 116 103 123 127 108 116 113 111 126 110 116 125 102 126 110 109 129 126 107 135 123 110 137 104 118 113 118 116 96 112 101 113 121 103 106 111 112 122 117 124 122 97 116 118 126 115 111 123 118 119 113 109 114 124 127 112 111 100 106 105 95 105 114 129 109 118 123 125 123 100 131 133 122 120 115 114 98 94 139 100 117 112 120 110 114 122 137 109 121 122 90 112 113 104 134 118 86 106 116 120 134 102 126 113 122 110 125 132 111 111 99 116 114 111 117 107 98 120 104 105 124 111 101 125 117 124 115 99 99 123 116 111 102 100 126 119 112 128 99 126 121 104 137 125 133 116 106 114 111 102 118 116 111 110 126 122 108 120 91 124 125 130 112 116 120 108 98 107 103 102 120 132 127 106 98 103 109 116 96 117 99 91 118 118 124 110 97 116 110 119 117 112 95 122 127 107 104 109 130 117 124 109 129 104 113 111 107 116 137 130 104 122 114 113 145 120 104 114 133 115 110 137 115 116 105 125 112 103 120 125 104 136 112 108 115 105 119 104 124 128 110 121 113 117 125 137 118 128 129 131 138 124 121 111 117 101 128 111 129 102 122 102 133 118 123 131 113 128 127 109 95 123 103 159 117 113 124 94 120 129 134 99 117 130 108 123 107 119 118 132 130 115 114 140 131 111 112 131 107 104 118 124 110 127 91 108 121 117 116 127 115 123 109 130 118 126 130 110 117 119 121 101 99 114 105 108 120 128 100 124 99 133 134 108 104 113 113 105 117 108 129 109 110 113 107 119 97 118 127 124 115 112 127 103 119 110 138 99 129 111 117 116 121 118 123 125 127 100 117 113 127 124 124 121 126 110 106 103 122 136 124 122 117 127 125 105 104 105 124 135 131 111 114 96 112 122 116 117 94 113 111 132 115 119 128 121 116 135 119 125 105 122 107 127 122 105 130 122 118 126 116 111 102 113 114 138 132 146 132 127 122 116 124 119 125 138 129 117 113 140 116 107 116 117 104 129 136 116 127 123 114 107 129 94 101 137 121 108 131 108 113 140 126 118 123 113 116 115 135 133 120 111 109 122 129 124 111 119 120 135 132 134 130 145 126 102 121 133 136 111 125 102 108 131 125 114 134 142 105 115 121 122 120 118 121 119 118 131 139 140 120 124 117 103 153 130 110 112 138 148 126 124 137 134 108 128 109 118 126 128 124 146 141 135 112 99 97 132 116 118 101 115 141 109 135 120 127 134 122 115 139 125 112 130 119 119 126 138 117 137 117 146 134 138 135 126 139 127 105 150 118 133 133 117 132 131 126 110 135 120 141 138 129 133 116 109 137 111 129 151 119 128 146 116 147 136 123 133 138 129 118 137 145 143 113 121 123 132 129 135 142 150 119 134 135 137 109 130 168 126 126 144 124 146 142 156 155 144 153 160 145 126 150 137 159 165 180 159 162 179 165 163 184 151 150 195 179 175 196 215 219 217 213 228 231 223 217 221 227 248 220 242 237 242 223 227 203 194 199 195 174 192 190 187 199 192 171 152 182 178 180 150 153 150 146 150 160 145 165 170 137 141 123 140 122 119 162 136 127 126 130 117 135 131 128 134 121 122 136 131 127 107 134 131 137 109 129 121 127 114 127 130 117 110 114 130 119 105 144 112 127 111 142 132 144 112 122 108 134 132 134 102 118 102 124 140 129 125 123 106 110 139 113 112 128 119 103 137 135 136 142 122 116 126 123 126 129 100 139 135 129 147 121 139 115 101 126 133 114 119 111 140 100 124 130 125 113 124 110 101 122 119 141 126 133 123 109 108 134 127 126 108 113 127 116 138 115 131 110 130 109 131 115 114 124 117 144 115 112 118 126 96 116 119 104 118 126 132 133 107 130 106 137 135 113 126 122 123 117 113 112 109 131 86 110 127 112 134 122 139 110 122 110 135 121 104 121 114 136 130 122 107 107 127 134 120 129 128 114 108 91 130 116 105 126 143 121 104 146 120 120 107 115 137 115 110 125 127 124 107 120 116 142 105 130 121 130 109 93 134 135 117 115 126 129 144 110 119 109 109 145 117 108 133 129 135 109 100 110 127 122 124 116 136 122 116 127 118 126 107 132 113 120 117 125 121 120 117 123 118 122 104 122 120 120 134 125 136 112 111 139 128 97 114 119 108 112 121 104 114 106 121 101 128 114 124 121 113 134 117 111 125 114 116 116 139 133 145 126 120 145 125 114 112 132 127 129 110 122 109 118 116 105 105 119 115 107 135 113 117 108 133 121 117 108 123 132 119 137 116 113 107 116 128 110 132 117 109 105 118 125 130 108 148 125 110 135 121 131 124 119 104 102 113 127 117 131 110 129 125 124 123 113 113 117 133 106 120 121 123 95 116 123 126 123 111 127 122 139 119 110 147 121 123 130 123 109 134 132 125 84 120 138 113 139 111 117 135 110 112 108 119 137 129 130 107 103 134 127 110 118 109 132 128 106 130 126 128 128 136 116 139 111 126 127 103 130 116 116 110 117 129 111 111 125 109 112 125 121 102 126 133 121 102 115 120 104 131 150 139 139 123 119 101 126 114 120 107 126 109 125 149 128 122 149 108 121 113 112 128 115 119 127 136 122 105 131 137 111 121 126 125 127 117 106 127 100 140 135 109 107 130 119 133 118 118 122 110 131 118 127 101 118 108 143 132 126 95 117 119 124 113 115 127 123 106 119 107 110 133 109 114 117 122 141 128 98 116 126 119 137 130 110 119 112 116 116 104 93 127 140 125 119 114 117 102 117 113 109 120 111 128 131 115 114 105 112 134 126 118 112 106 108 125 125 123 123 112 107 124 100 138 131 116 119 119 129 122 113 128 119 114 114 104 106 104 115 116 107 118 110 122 107 102 121 123 123 118 128 120 109 111 122 115 130 114 119 112 132 137 121 134 126 120 123 116 112 121 103 104 136 108 100 107 109 123 129 126 118 138 125 117 121 101 111 123 110 121 98 111 120 110 102 108 122 125 129 125 99 109 128 118 126 124 98 119 122 122 101 118 111 116 137 120 116 130 118 109 111 119 120 97 126 127 118 121 127 111 118 118 117 120 119 134 114 119 117 125 117 119 115 118 119 128 119 128 117 142 120 95 112 126 129 127 108 130 129 116 126 119 134 112 114 137 115 124 114 133 132 118 104 112 106 131 127 125 117 101 124 117 113 130 111 115 111 124 125 100 118 108 111 101 118 134 107 113 128 119 112 132 112 106 106 106 121 136 128 123 116 125 135 117 103 129 120 125 125 90 106 139 126 125 118 135 125 115 121 132 105 123 132 123 142 137 126 123 130 113 130 133 123 112 110 125 137 136 117 125 136 153 139 124 101 112 115 107 121 141 142 135 117 124 125 117 122 116 122 132 123 117 96 100 120 104 125 130 115 111 134 123 129 113 120 118 112 118 102 138 111 109 132 120 119 124 139 104 126 122 136 98 135 95 136 118 106 142 124 125 119 117 130 109 112 126 125 124 114 153 133 105 124 129 119 119 136 123 115 127 109 113 117 120 107 116 117 118 105 84 117 89 122 116 113 134 125 111 106 117 119 116 105 124 142 98 101 107 126 147 120 135 112 118 146 117 116 123 128 110 113 135 114 133 123 128 111 101 127 107 91 120 115 126 102 133 122 108 139 119 110 126 122 121 115 107 112 123 132 122 117 124 114 109 136 121 126 128 124 113 118 123 135 121 102 127 141 126 130 118 128 119 141 120 113 95 122 116 120 99 125 111 119 114 116 118 110 140 121 120 110 116 109 117 124 110 132 140 130 121 95 123 113 123 122 126 119 126 110 125 127 121 135 116 119 112 132 138 117 145 113 122 115 113 100 116 140 106 127 97 124 117 134 107 125 115 113 126 115 127 110 140 95 147 119 107 117 123 112 117 107 99 121 130 119 130 106 120 118 123 122 117 118 128 99 88 121 108 108 129 122 104 116 113 118 116 127 113 122 103 113 116 99 103 103 143 117 120 96 110 128 123 140 107 130 123 110 118 123 125 107 99 142 147 116 111 114 132 124 122 124 135 123 135 123 126 132 102 118 127 131 101 103 120 103 119 107 114 122 135 137 116 120 132 110 109 126 129 114 116 122 122 86 112 132 124 99 123 109 116 127 125 99 114 114 105 126 127 109 123 112 114 118 127 121 130 135 119 110 126 119 125 135 109 115 134 127 107 104 104 106 114 112 106 96 115 126 116 120 111 119 116 121 98 131 115 90 128 122 124 124 112 122 117 107 108 106 105 127 123 119 119 132 131 123 140 140 112 103 129 110 118 110 112 120 107 128 119 118 113 92 121 126 126 130 109 130 110 121 109 115 106 127 87 122 112 120 115 110 107 108 105 106 114 117 112 127 113 105 113 118 108 119 114 106 114 122 129 131 125 120 113 128 124 110 125 119 126 112 128 119 133 112 117 113 113 139 106 141 119 131 118 119 113 121 113 113 111 117 124 114 121 117 112 119 118 124 106 104 128 113 116 122 122 109 112 118 133 121 107 123 130 128 114 140 119 116 147 116 132 114 113 117 126 125 119 114 121 138 120 129 131 110 129 116 124 135 113 121 124 109 121 122 138 103 142 124 116 118 133 107 111 123 110 119 130 135 134 119 123 107 128 130 115 105 114 114 119 126 115 133 128 108 117 110 107 124 131 110 149 120 138 115 126 106 120 117 113 111 121 133 138 119 109 109 131 108 115 118 116 115 118 110 116 115 124 107 132 118 113 126 135 132 144 113 129 107 107 127 112 109 104 124 121 120 119 141 103 107 108 115 123 123 130 125 106 123 119 121 107 119 126 149 119 116 120 99 117 91 95 112 105 134 106 150 119 118 118 122 124 119 120 129 119 118 113 132 115 128 136 110 118 116 111 121 117 119 117 130 139 107 120 101 108 116 144 120 120 144 122 109 104 127 108 127 116 116 119 109 133 117 132 121 127 123 123 108 99 115 101 133 131 120 121 106 109 142 112 131 125 124 123 117 124 117 133 117 124 121 121 128 141 127 101 136 100 119 148 134 93 127 142 121 130 132 129 123 111 145 129 127 117 130 130 125 109 137 118 127 106 129 137 125 113 131 133 99 107 119 111 127 142 112 117 127 134 122 124 133 115 120 126 126 108 114 121 112 129 136 120 132 116 123 123 123 115 131 106 125 128 107 110 129 95 122 145 129 122 123 123 124 115 114 114 116 122 107 125 117 117 128 131 116 125 127 122 111 128 135 142 131 110 120 123 136 128 118 126 119 114 106 109 135 119 115 113 134 117 121 149 125 105 117 125 104 126 134 134 127 135 118 127 133 122 118 137 127 121 120 118 143 128 131 138 119 134 117 133 139 109 136 129 111 132 111 130 109 129 104 115 128 116 123 127 109 114 114 125 132 124 122 124 130 118 134 133 127 124 116 130 132 140 119 98 151 121 107 127 131 116 124 108 104 111 124 117 117 137 137 152 117 122 126 128 122 126 137 145 143 145 104 109 146 115 123 141 107 114 152 118 135 138 128 116 110 120 109 124 115 123 128 128 126 137 131 115 118 130 121 131 117 117 133 120 115 125 121 131 130 136 117 118 120 133 105 114 117 120 126 126 134 128 110 118 130 108 119 122 123 148 137 114 124 133 121 130 117 136 118 111 109 122 117 122 108 126 132 116 115 103 134 118 132 127 140 105 120 125 127 128 125 116 120 106 113 118 108 140 120 121 118 142 145 137 129 125 116 114 131 138 119 125 141 141 121 124 125 124 113 135 128 127 109 105 111 136 108 116 119 118 121 114 126 128 114 127 116 139 125 118 127 125 116 133 128 124 146 114 113 124 120 108 129 120 121 131 122 110 122 130 141 121 124 131 113 121 139 121 131 136 128 111 129 129 112 139 111 133 106 123 124 107 118 137 135 116 128 124 111 140 145 102 115 128 111 129 116 110 120 139 143 111 129 136 125 118 114 138 126 153 132 127 121 109 121 125 120 121 123 139 115 131 125 115 137 109 127 138 129 125 125 124 128 128 111 118 131 123 119 128 132 137 122 108 110 110 120 116 138 124 135 131 118 128 124 145 112 117 153 123 135 128 118 129 139 119 129 114 134 140 142 130 120 119 127 136 140 175 122 137 150 146 152 125 143 132 125 122 131 125 130 117 118 138 128 132 138 135 136 131 141 137 138 149 125 110 143 125 128 126 132 129 102 128 142 128 115 142 111 123 157 129 133 132 132 117 123 124 126 115 127 146 148 142 133 124 107 144 127 121 130 145 132 134 130 124 131 136 135 102 135 115 142 143 128 132 126 134 151 124 128 136 127 115 138 127 138 108 135 116 136 121 117 124 123 122 128 139 135 124 151 120 149 116 153 137 116 130 118 147 136 133 91 119 105 129 142 117 132 123 116 130 121 125 104 129 113 123 121 96 136 110 110 108 119 124 98 116 127 130 121 126 128 126 102 114 144 141 116 122 145 118 130 124 145 116 126 132 111 114 105 121 132 118 117 126 129 133 96 112 123 135 117 108 112 112 117 128 129 115 127 120 128 115 132 135 126 119 129 125 108 102 145 123 123 117 120 142 132 140 113 128 129 125 121 110 118 126 107 106 142 142 110 126 136 118 106 113 112 108 125 117 141 113 108 96 130 128 109 121 133 103 113 142 140 123 120 129 136 129 130 137 93 105 125 139 116 133 114 120 112 147 140 137 118 130 144 130 117 127 121 118 121 114 135 111 151 127 113 131 125 110 126 127 115 145 111 100 121 136 132 124 116 113 117 128 120 128 105 117 100 150 121 145 145 111 128 115 141 120 121 112 151 130 113 115 127 119 103 127 129 121 122 132 135 125 118 125 128 133 127 92 136 123 106 121 138 138 120 129 121 109 139 135 141 116 129 147 111 130 133 131 113 121 119 98 109 121 134 119 137 132 124 127 117 122 116 132 129 145 126 102 116 126 113 125 134 117 118 134 135 122 105 117 123 144 121 126 107 116 119 131 126 118 131 138 114 130 113 128 105 121 135 140 125 136 107 127 122 123 134 140 117 127 118 135 116 109 117 129 123 144 123 115 116 122 100 117 125 113 101 116 127 119 124 142 123 126 135 128 121 132 106 124 129 125 120 125 128 132 108 127 123 139 123 121 128 115 129 138 128 127 122 120 123 143 117 114 116 100 136 156 109 123 113 117 135 97 134 122 125 135 115 121 132 126 116 125 122 120 127 104 106 139 122 117 108 109 133 134 113 116 128 132 121 134 133 107 128 122 116 141 122 129 128 125 129 128 139 130 120 134 117 109 138 114 143 108 134 124 130 108 108 115 126 121 116 112 112 123 121 117 128 109 120 122 144 109 135 130 108 140 134 125 130 99 110 121 117 117 113 127 105 134 108 120 123 135 119 137 111 121 126 124 113 131 133 132 124 124 100 122 123 115 101 130 144 129 124 133 127 145 133 129 134 128 125 120 140 125 118 131 115 126 141 125 119 134 127 160 134 126 139 104 122 108 134 124 123 138 123 124 137 127 111 119 106 153 119 124 122 132 121 123 114 131 119 122 110 119 138 143 133 103 111 133 104 116 130 129 113 127 147 110 118 109 133 110 135 123 125 132 121 132 132 146 113 124 146 115 131 123 117 150 133 145 110 126 127 116 126 118 120 123 136 112 134 115 125 118 128 129 119 125 126 127 136 116 132 145 129 132 121 131 130 144 150 117 111 138 118 125 115 120 113 110 165 115 119 113 145 124 101 147 126 112 138 120 127 117 126 124 129 124 99 118 117 116 108 125 111 129 127 128 121 109 128 112 129 127 150 109 116 125 115 126 119 149 111 132 122 143 105 117 129 145 132 119 146 123 135 124 126 151 122 131 127 98 137 125 107 129 125 124 141 141 134 132 138 132 123 125 140 134 124 139 134 132 146 137 133 124 105 129 134 128 123 132 107 140 119 124 124 135 135 138 104 125 118 117 131 115 122 133 117 128 133 114 141 126 123 125 122 122 111 141 121 128 108 116 127 136 129 118 133 145 120 118 120 125 123 127 123 133 138 113 134 125 134 123 128 147 135 132 141 125 116 104 130 152 130 142 112 112 121 127 114 120 118 133 120 125 136 138 130 123 126 128 116 127 123 131 135 129 134 97 123 119 118 143 132 112 133 116 137 143 119 148 153 127 101 111 113 117 132 125 123 114 122 120 131 132 126 140 104 119 121 133 124 155 115 162 125 131 110 123 136 120 137 134 133 128 121 144 121 139 124 127 139 123 117 115 101 129 117 110 119 136 119 117 133 119 121 133 109 140 113 146 127 137 115 120 130 118 119 136 137 116 123 112 126 128 146 113 104 125 112 151 126 126 111 123 105 122 140 120 97 114 110 113 119 137 113 124 139 114 124 126 123 129 119 123 123 141 149 132 129 118 124 121 133 118 122 120 119 117 107 118 125 118 121 152 142 114 150 127 133 113 132 119 132 138 116 133 140 141 129 130 111 135 128 144 135 135 133 112 112 116 133 113 117 129 125 126 125 110 126 124 126 126 130 122 116 116 131 113 131 132 155 125 127 114 143 134 135 107 133 126 110 149 122 155 130 103 125 126 124 106 122 119 137 135 135 131 112 127 145 148 120 122 134 131 141 136 118 118 117 131 112 120 119 130 139 123 136 133 133 129 121 125 110 130 136 144 123 120 117 127 122 106 126 112 135 135 127 128 130 114 132 115 150 127 125 114 121 120 110 133 130 133 134 156 139 133 108 117 130 131 134 128 137 117 152 124 117 120 131 110 123 134 139 121 127 119 129 140 145 124 135 119 132 114 137 120 124 141 129 128 116 124 112 125 137 138 125 124 122 120 122 130 124 125 118 123 109 132 137 128 141 141 136 140 114 130 128 123 159 129 128 119 130 121 124 126 127 137 141 108 113 111 120 131 137 132 129 124 114 142 126 119 125 125 131 125 135 114 139 136 135 133 135 136 149 121 115 118 109 113 130 126 99 131 128 128 121 117 114 126 119 142 145 139 132 115 142 135 120 130 125 136 119 148 124 119 124 105 142 110 111 129 115 127 119 134 135 130 123 126 122 114 111 116 119 130 119 112 135 108 121 145 118 135 121 124 135 137 134 137 115 130 118 135 135 113 122 120 112 135 114 125 145 112 133 124 141 97 110 106 113 115 108 105 101 135 130 127 111 128 132 130 121 134 136 112 137 156 118 124 102 139 115 130 120 126 121 132 115 111 122 108 132 117 132 114 130 128 130 120 148 122 117 127 111 127 120 116 118 113 113 123 132 116 120 144 123 118 106 131 143 126 123 132 112 108 124 108 136 139 136 117 124 119 120 126 110 114 145 130 125 121 100 121 109 144 123 127 134 145 117 140 134 119 106 144 128 144 121 134 105 130 131 107 137 120 128 124 131 113 118 123 103 116 127 113 118 125 127 111 122 120 117 148 130 123 122 122 128 133 114 111 138 105 127 93 119 117 116 120 124 135 120 132 118 111 123 115 130 107 151 115 125 112 136 121 126 127 125 143 116 138 123 125 132 115 124 122 117 107 139 127 107 116 134 137 136 104 120 98 129 140 145 96 151 117 139 108 140 125 126 121 134 124 125 110 126 114 103 151 126 105 121 122 117 138 143 113 123 129 113 123 129 139 119 115 140 106 120 135 133 131 122 134 113 129 125 124 122 135 125 112 114 130 130 118 122 128 114 142 129 146 130 129 134 130 142 121 135 137 115 117 132 118 124 121 120 132 121 114 108 104 114 129 111 133 124 125 112 111 114 136 133 111 122 106 131 150 100 120 134 138 132 138 131 125 122 145 101 129 122 117 112 115 117 118 106 113 119 121 123 110 110 121 108 119 129 102 111 123 130 119 107 122 132 113 120 109 132 116 124 121 125 141 136 128 125 122 132 128 125 116 113 114 118 143 126 131 125 132 137 128 120 129 120 121 130 134 125 143 113 147 135 141 121 132 105 119 120 116 111 127 116 116 143 103 121 138 144 129 126 129 130 126 125 126 147 132 120 133 119 116 127 130 114 140 133 146 140 128 126 133 115 126 116 133 141 154 137 133 136 135 114 110 146 147 110 142 127 127 145 150 138 137 130 116 111 150 123 131 124 155 129 132 153 138 144 130 127 126 156 122 136 129 118 159 142 138 143 149 158 135 137 116 140 151 121 147 125 135 125 123 136 134 135 141 151 139 144 144 156 147 138 118 135 152 122 141 138 113 138 156 141 134 107 132 122 154 119 140 109 109 126 128 134 147 138 118 123 105 141 120 136 123 142 124 113 139 116 117 125 112 126 130 134 135 142 135 119 136 126 128 123 124 134 130 113 142 115 113 134 112 123 106 139 118 121 134 128 147 117 117 124 124 121 124 119 136 131 120 130 106 134 124 114 121 128 130 120 121 114 134 140 136 137 114 132 120 129 117 110 110 123 132 102 138 134 128 122 121 102 115 106 132 126 120 111 129 119 120 124 122 106 116 115 129 126 114 116 125 116 106 130 96 149 123 117 136 106 122 95 131 123 126 140 102 138 110 121 117 108 108 131 149 127 107 125 102 123 146 109 126 128 118 111 108 130 128 117 120 116 125 101 98 128 141 113 138 101 113 121 114 126 131 126 135 120 149 119 124 113 117 115 116 124 118 123 116 129 129 110 133 132 110 119 124 104 140 103 126 111 134 116 125 111 132 108 139 119 121 110 116 124 146 135 119 108 116 85 118 121 115 121 96 142 132 132 123 131 116 129 129 123 126 120 136 125 138 115 115 104 126 119 133 139 116 132 118 113 114 117 124 114 121 124 134 114 118 116 106 125 147 115 129 123 134 124 112 111 120 135 108 125 117 105 106 115 134 112 125 133 120 110 115 122 117 136 118 136 113 121 142 148 116 119 120 126 111 107 112 116 132 126 128 104 103 125 120 127 130 109 97 133 128 123 108 131 117 120 128 139 129 133 128 144 146 127 140 125 138 110 122 102 115 113 131 121 115 131 117 109 132 145 113 138 127 138 106 118 117 105 125 114 121 109 118 107 116 109 105 108 127 130 128 140 125 118 115 134 123 122 105 129 150 116 117 105 118 125 104 121 125 129 114 126 117 111 108 106 127 128 129 106 109 132 136 123 115 119 122 123 123 110 117 126 135 115 123 108 122 129 95 129 106 111 117 147 99 111 97 130 122 130 132 129 126 116 118 116 123 129 114 119 125 103 114 149 129 108 110 117 107 101 114 136 126 122 123 120 103 125 109 125 107 119 108 106 124 129 128 122 123 102 132 123 111 120 133 137 127 113 127 129 124 123 116 107 117 121 138 98 135 113 106 144 128 131 118 105 147 107 124 98 116 105 129 106 108 123 120 136 123 128 111 111 121 91 127 119 128 122 120 123 122 113 116 102 128 155 127 139 137 123 111 129 117 126 111 103 113 116 125 120 125 128 109 113 121 111 117 123 134 120 112 102 123 139 134 128 120 119 118 116 109 118 97 105 121 102 122 106 106 126 142 130 98 126 117 122 104 107 132 100 116 130 107 114 132 130 118 128 107 119 117 124 144 114 108 147 132 112 116 103 115 123 105 117 116 107 129 114 122 116 124 127 113 107 122 121 112 126 120 111 154 96 125 122 131 117 94 104 120 102 138 133 117 112 136 133 118 109 127 144 124 126 106 123 116 116 119 124 131 120 131 119 121 116 139 122 115 109 125 125 133 110 125 125 125 122 118 126 98 119 125 94 107 135 118 131 124 103 120 107 130 122 122 108 124 106 109 107 121 109 115 123 127 121 121 118 114 117 112 130 131 108 128 131 133 132 134 129 132 137 110 103 112 118 116 115 126 114 114 127 110 120 124 120 131 98 135 118 109 125 122 130 128 109 122 104 119 95 124 108 118 120 138 109 118 107 124 137 135 121 128 124 106 119 130 130 115 127 130 130 138 144 136 118 122 126 104 129 108 104 105 110 109 129 114 121 110 113 110 118 112 106 104 120 98 126 101 112 111 127 119 101 124 132 120 134 103 102 101 117 142 124 133 124 128 110 111 120 116 108 138 122 116 130 145 113 111 112 128 105 121 121 114 142 111 120 129 131 117 125 88 133 115 118 121 109 115 141 122 120 103 114 105 105 122 117 124 118 115 137 125 124 117 105 122 133 123 116 98 126 131 120 108 112 118 122 148 87 128 127 111 113 121 120 126 122 122 113 129 130 108 116 116 121 117 121 117 109 126 121 105 115 106 108 118 119 113 121 119 136 112 113 119 119 117 120 110 120 120 108 143 134 89 107 121 113 129 124 126 126 133 117 102 104 119 113 119 136 107 104 132 128 100 116 135 110 137 121 113 124 96 130 117 114 117 134 113 126 137 114 108 108 122 128 108 111 143 109 130 105 115 116 117 132 112 126 125 92 104 119 114 119 121 124 134 92 120 122 108 124 112 140 128 124 115 138 115 110 125 139 128 141 111 150 119 124 137 118 109 115 120 119 119 112 143 134 110 101 96 118 105 127 109 114 102 150 113 116 126 116 127 145 115 119 124 106 130 120 113 123 122 117 109 128 129 130 116 126 116 113 119 113 131 111 110 137 110 131 109 110 126 134 114 110 108 122 130 120 119 128 126 123 119 125 99 130 143 114 117 126 110 133 104 135 129 115 133 145 123 119 115 118 128 108 142 128 122 124 109 119 108 123 117 120 134 103 101 117 133 125 131 110 98 126 123 129 145 118 112 144 127 119 155 110 120 125 107 108 134 130 144 113 116 107 106 123 109 118 128 121 125 129 131 116 116 123 136 116 117 121 106 97 113 100 119 126 110 131 124 107 113 142 127 121 97 114 120 108 105 126 115 109 117 117 112 107 120 102 141 123 112 100 127 118 138 109 125 109 123 116 122 118 107 117 119 130 127 114 123 126 124 128 114 113 140 113 133 114 133 111 138 120 122 122 113 114 129 108 121 105 132 131 125 111 101 103 132 100 112 116 134 127 131 105 128 116 135 109 108 108 127 146 130 118 130 121 115 107 121 118 131 116 124 132 128 120 116 123 125 104 119 122 109 119 97 133 143 120 118 134 128 109 86 121 108 126 120 120 113 125 116 132 120 112 109 108 114 115 123 135 124 93 115 125 96 109 120 98 117 124 123 122 126 109 138 110 120 119 122 120 130 117 143 119 126 141 106 119 108 127 136 113 123 116 133 110 107 111 114 115 120 122 114 119 102 141 132 118 105 132 117 93 105 114 110 101 137 116 146 116 106 132 119 107 123 121 123 143 124 105 129 126 120 111 110 122 120 108 119 117 124 123 124 112 117 113 120 127 128 95 119 117 118 119 120 117 121 115 118 146 118 115 120 106 148 119 109 127 127 114 116 109 133 127 102 130 118 131 146 106 130 123 113 122 126 104 120 109 127 113 106 104 111 132 137 113 120 127 123 126 115 106 130 127 134 121 108 108 139 114 112 125 135 110 127 123 105 119 131 111 120 100 121 118 132 113 111 126 141 122 137 111 121 118 115 123 109 113 129 112 132 126 116 127 142 128 116 127 115 105 131 132 114 131 129 138 118 123 129 111 130 134 124 123 107 140 128 105 98 134 108 87 143 114 118 95 129 115 138 123 117 117 109 137 124 120 118 132 115 121 134 128 127 134 114 116 125 133 109 119 115 107 132 123 150 118 122 111 118 128 117 118 120 119 108 123 120 119 126 123 121 111 98 128 126 128 116 116 93 121 104 122 125 133 115 114 115 139 104 110 115 125 113 124 105 118 110 122 131 124 119 141 111 117 118 131 104 115 104 107 113 108 114 103 133 140 132 117 128 134 111 113 130 124 115 119 114 120 126 116 108 135 122 116 136 127 133 138 118 121 114 124 148 131 148 129 125 121 109 138 130 119 140 136 113 125 108 121 123 134 126 131 122 136 112 123 132 122 124 118 128 132 136 149 108 116 124 138 135 137 130 130 128 131 145 135 126 129 133 119 123 120 117 139 133 134 132 141 108 137 120 144 125 128 122 154 128 120 141 149 117 127 128 131 126 123 113 119 144 114 142 144 124 108 129 130 117 154 116 105 133 148 115 135 132 127 134 113 141 103 122 116 131 128 144 108 113 94 123 134 135 116 132 120 111 120 127 120 121 127 121 125 124 130 126 124 131 119 131 119 125 91 146 116 128 139 114 114 123 94 112 119 118 126 129 124 119 124 121 101 128 127 118 125 108 133 136 128 107 116 132 97 120 134 104 125 131 89 138 153 122 135 119 136 123 132 118 120 137 106 117 106 111 123 118 133 119 141 132 132 120 122 138 131 130 114 131 130 107 128 133 126 117 128 114 127 134 123 120 114 131 138 117 118 124 124 136 128 99 132 122 123 111 127 111 122 122 112 131 129 146 104 132 136 126 120 115 111 127 133 124 122 134 144 109 123 131 122 111 119 119 97 122 119 95 114 96 125 149 112 120 128 124 151 112 131 123 107 108 134 129 130 126 111 99 119 99 148 117 124 108 115 119 109 113 117 117 124 138 134 131 129 121 121 104 118 127 108 111 141 117 139 125 115 117 144 114 105 126 118 100 119 116 121 117 134 118 109 113 115 130 117 132 119 138 105 119 115 139 106 129 112 108 126 150 123 123 127 113 111 131 135 121 114 122 94 127 141 127 118 132 120 129 129 131 123 117 122 136 155 119 109 122 121 128 120 121 118 120 118 123 119 137 113 118 120 102 128 116 112 126 137 130 124 113 111 125 105 112 106 123 123 121 118 109 137 131 124 131 120 121 103 111 125 132 132 120 137 121 125 116 121 132 134 100 117 127 111 138 115 110 128 121 125 124 122 120 95 103 127 110 118 110 122 125 121 135 113 129 118 111 117 122 116 112 147 129 156 145 128 110 116 122 117 139 130 114 139 102 134 124 114 140 136 127 116 145 123 127 126 134 101 115 132 141 131 104 134 132 117 119 113 120 115 122 124 111 111 149 111 118 129 117 114 127 132 128 139 113 140 117 111 124 123 136 128 91 115 113 124 118 99 110 110 117 118 120 127 137 103 144 124 119 137 118 102 127 108 140 88 124 130 132 113 118 128 116 132 102 151 113 118 117 111 121 123 119 130 103 130 94 122 116 109 120 119 121 120 112 125 107 132 98 124 120 140 138 149 117 122 134 127 138 123 101 122 133 132 121 135 125 131 124 109 136 136 129 117 118 120 100 110 130 130 136 132 122 143 124 136 117 119 111 125 142 134 114 127 124 108 146 125 128 119 97 126 112 148 125 140 131 140 129 120 112 120 124 118 126 119 122 118 108 119 124 106 124 109 139 126 108 123 126 111 128 124 112 123 122 118 134 137 118 111 110 116 126 146 136 107 113 130 131 105 126 147 116 149 134 135 133 142 109 126 133 106 132 114 111 126 130 128 122 121 116 135 129 121 121 119 121 120 119 140 116 142 129 101 137 132 131 123 142 124 120 109 129 128 106 125 128 112 113 121 119 117 120 132 122 129 115 132 128 98 119 98 119 111 131 126 122 124 104 123 120 124 120 116 126 131 135 113 104 114 125 106 119 121 107 131 129 112 127 102 123 124 116 128 121 110 118 114 117 134 133 118 114 123 128 109 114 116 126 143 112 131 124 150 115 113 127 122 111 123 105 132 129 134 123 108 127 108 142 124 112 117 131 126 141 111 121 131 127 106 128 128 113 109 132 114 119 129 139 137 121 118 137 123 132 117 111 139 113 110 122 125 116 137 122 108 114 107 116 133 132 145 109 121 111 112 115 139 119 111 122 129 114 109 120 105 129 107 107 96 116 107 120 119 115 130 123 119 124 112 120 107 122 127 138 117 108 100 132 103 119 110 111 113 117 112 134 123 126 121 110 117 134 100 113 128 112 135 143 115 132 129 122 148 140 142 113 107 111 126 127 123 118 118 114 129 133 106 116 129 93 120 129 123 114 115 106 120 112 114 113 122 124 127 129 111 145 115 146 127 109 108 118 113 131 121 119 114 132 129 126 127 145 123 120 148 131 120 103 129 126 132 116 142 135 114 108 122 131 126 126 132 122 144 136 141 134 105 113 119 120 121 107 127 105 127 130 138 122 133 127 116 120 124 120 116 101 125 110 129 103 123 99 115 117 109 113 123 128 135 122 102 143 129 124 113 159 120 125 116 116 133 103 115 109 116 121 110 125 110 100 125 145 114 124 133 143 114 109 121 132 126 130 137 125 126 106 134 118 111 129 115 127 126 122 116 125 114 113 139 140 122 131 134 129 110 128 118 134 133 121 129 126 122 115 137 113 122 116 85 116 115 111 117 118 107 119 130 124 137 122 134 114 119 106 115 146 128 121 120 117 113 118 115 128 126 110 113 115 128 128 121 128 133 109 111 119 140 117 135 120 127 115 107 123 124 136 117 125 139 132 123 116 111 122 130 120 119 114 115 135 108 133 132 152 126 141 123 155 120 121 110 119 117 117 118 114 126 137 121 106 137 121 119 122 114 120 114 122 120 118 119 120 126 123 118 131 106 115 126 135 128 120 112 113 119 132 124 130 122 130 116 118 120 121 128 124 111 115 118 110 119 120 143 109 118 108 130 107 139 125 118 117 117 120 129 109 95 131 129 115 115 115 115 134 122 122 127 114 121 138 114 120 126 98 136 109 123 140 114 114 139 132 121 122 118 108 124 107 132 110 117 106 122 119 117 117 99 111 119 119 112 121 113 119 122 142 109 126 128 97 106 130 140 104 116 99 132 116 139 111 115 106 145 126 115 117 136 124 131 113 139 135 119 119 120 114 111 112 110 131 121 111 134 136 127 121 118 98 127 131 118 126 140 115 123 119 118 115 114 138 111 108 132 131 136 106 143 121 114 138 124 137 112 101 125 108 137 119 97 149 114 130 126 124 103 94 131 115 115 116 116 132 130 107 102 134 126 117 115 128 128 136 135 125 128 121 106 119 114 121 123 102 123 114 123 120 138 121 119 114 121 119 121 138 103 128 110 127 116 123 149 114 123 127 133 108 149 103 111 130 143 131 112 110 113 111 124 124 110 131 138 123 126 122 115 125 133 150 123 134 122 126 116 99 117 127 134 140 131 142 120 105 129 140 117 119 125 104 112 132 109 122 121 138 107 117 115 132 118 109 122 128 129 113 125 119 116 136 107 110 115 141 108 124 125 113 135 130 112 134 115 110 115 114 146 139 118 105 141 106 131 121 124 127 121 122 122 114 100 110 110 129 131 117 141 105 103 104 113 135 120 114 113 110 104 121 113 121 118 126 135 119 119 121 132 129 129 121 129 114 137 146 126 118 133 120 135 118 136 136 104 141 137 115 118 133 145 104 102 135 118 130 123 124 130 118 112 110 105 111 126 134 117 115 116 141 126 117 144 117 128 131 139 101 124 125 116 120 130 136 129 118 110 131 128 124 151 125 117 120 132 116 123 124 125 104 137 127 114 99 122 121 113 118 130 122 135 114 134 127 121 123 126 118 123 114 128 128 119 119 105 132 138 148 129 121 126 128 116 130 128 119 110 108 133 109 134 131 113 135 135 118 121 137 118 137 127 116 135 113 117 140 107 144 131 136 123 109 123 126 135 120 126 112 128 130 124 138 128 126 143 115 121 118 115 116 115 138 123 119 121 118 127 139 127 140 117 113 107 122 115 139 106 147 111 106 125 122 137 130 116 125 113 116 121 130 117 107 134 129 112 161 109 126 122 124 130 127 108 154 152 102 116 115 135 120 127 108 149 111 128 109 119 141 139 124 105 120 121 141 114 141 119 141 106 135 143 114 106 128 124 144 125 113 134 119 134 111 124 114 123 124 153 128 113 114 141 112 126 113 144 134 135 138 133 130 149 119 134 134 117 147 126 123 122 129 114 120 123 135 129 117 112 116 117 118 151 131 117 147 113 147 116 120 131 130 121 115 138 136 107 141 147 111 128 134 148 124 109 144 148 107 125 145 131 142 113 139 133 101 139 117 132 137 138 134 131 142 125 105 130 140 158 116 102 128 135 110 145 99 140 129 134 137 128 149 152 118 103 115 117 131 161 120 125 107 133 148 112 141 116 138 133 137 138 137 132 137 137 112 127 155 135 142 139 122 129 133 140 117 125 130 129 145 146 135 143 122 125 116 133 119 136 131 116 115 100 123 112 123 147 154 140 141 115 140 138 140 111 152 112 131 114 128 140 102 97 139 132 124 127 119 125 132 134 131 136 116 132 152 131 132 105 127 126 134 132 118 123 134 127 96 116 110 102 137 133 131 109 129 128 135 132 113 132 136 142 142 124 136 120 117 122 134 110 129 130 112 130 127 131 123 126 113 126 123 115 126 113 137 136 114 127 136 122 112 106 106 101 131 118 99 123 121 113 120 111 141 144 122 127 133 122 127 126 147 126 126 140 125 132 110 116 123 140 125 126 128 126 141 129 127 134 129 130 126 124 116 133 117 122 120 131 124 126 121 122 123 101 128 118 135 132 118 114 117 100 142 121 120 122 119 121 129 114 113 123 131 113 125 116 139 111 123 133 123 119 126 125 109 120 142 144 113 120 130 119 122 126 126 111 115 130 120 107 133 136 127 110 102 123 119 118 94 115 116 131 111 118 122 135 116 118 98 130 122 116 103 119 126 126 103 147 131 116 137 128 110 133 106 128 137 116 119 139 123 125 103 114 131 100 116 140 116 123 121 109 102 128 90 124 121 114 110 126 119 97 107 129 111 121 119 131 144 131 141 114 124 140 128 124 136 120 132 119 130 112 122 134 125 110 134 124 138 91 126 113 116 112 131 126 149 132 143 118 115 124 141 117 125 113 138 130 102 134 127 102 137 116 117 138 128 122 132 112 137 130 119 126 120 111 135 145 124 119 121 142 135 127 138 120 103 134 136 110 111 108 124 121 118 113 100 119 140 124 121 131 139 106 121 110 134 97 134 136 135 108 136 130 119 123 123 118 123 110 111 132 117 131 131 113 137 130 116 125 128 106 114 118 132 113 119 127 112 107 118 100 131 117 123 132 122 128 116 113 139 122 104 114 115 129 114 121 127 140 116 114 107 118 115 125 113 111 131 148 112 104 128 126 108 128 138 134 121 113 109 131 129 128 137 126 143 130 115 119 125 135 116 115 119 104 125 121 113 111 138 114 114 117 108 139 112 108 125 114 143 125 125 115 126 121 121 121 124 117 105 120 133 131 141 107 131 120 122 129 120 138 130 132 124 109 111 121 133 124 122 113 140 135 116 118 141 126 124 118 109 111 119 117 126 123 114 129 144 119 136 125 124 137 108 133 140 128 136 139 109 108 112 124 122 107 124 127 126 133 116 122 142 129 107 134 124 131 121 130 109 133 111 131 111 120 120 123 112 137 138 120 122 137 138 155 138 109 117 137 115 120 111 128 134 117 112 137 142 111 145 117 104 110 117 155 124 123 123 128 121 136 116 112 125 115 116 114 123 134 146 122 136 118 109 126 115 125 144 126 138 131 128 123 142 131 124 132 108 124 123 120 117 116 109 137 127 130 137 123 131 120 126 116 111 138 123 126 133 124 121 146 120 108 142 128 106 114 136 108 136 101 114 121 139 141 130 135 125 123 123 121 98 119 122 130 116 131 131 124 125 126 127 141 112 108 105 116 129 134 111 131 124 123 142 136 123 114 136 103 114 119 123 135 107 105 112 147 88 135 117 131 130 139 129 133 137 124 142 130 122 135 122 134 114 144 116 123 128 125 124 152 171 125 129 131 117 124 116 136 131 119 125 122 104 121 120 125 128 145 136 131 131 129 139 115 121 128 105 139 129 130 119 110 132 114 121 150 110 123 139 121 160 116 131 115 117 128 121 134 125 135 127 120 102 133 117 120 131 133 116 129 125 126 126 130 130 148 129 130 128 107 123 122 125 130 115 112 123 128 106 111 133 123 126 151 115 110 123 140 128 141 126 120 119 123 106 145 115 105 123 139 126 106 143 126 128 137 122 127 136 112 105 115 146 129 129 129 107 125 128 122 128 104 131 125 137 126 115 128 112 146 118 132 116 118 117 125 130 127 129 149 115 134 130 107 126 118 100 105 127 103 134 120 136 132 130 160 123 120 123 135 139 127 117 123 117 105 130 142 143 130 123 123 124 119 136 146 108 143 106 137 114 149 127 120 127 136 134 111 132 104 124 128 131 132 141 112 139 129 130 109 128 116 120 122 116 135 113 137 131 129 116 115 129 134 113 129 129 125 117 111 124 143 129 131 143 124 132 154 116 126 110 118 120 120 117 107 142 129 111 104 136 114 141 139 130 133 122 125 126 148 114 124 128 124 128 128 121 145 113 148 105 112 121 134 123 126 111 119 132 122 129 122 122 133 135 106 128 135 127 131 152 118 123 126 121 121 112 118 157 129 142 143 123 111 143 127 123 140 135 123 106 122 126 113 134 130 129 121 123 116 124 112 112 127 110 124 123 94 124 130 120 122 109 125 138 142 120 118 121 124 108 120 135 122 134 127 127 136 146 150 145 121 114 126 127 122 128 133 117 125 144 129 133 134 103 128 140 111 124 123 145 137 142 114 129 146 120 110 129 112 132 120 118 130 127 131 123 130 106 128 120 119 97 128 121 115 123 144 114 107 133 138 142 122 125 154 130 125 125 126 117 113 119 114 148 130 117 120 126 142 122 119 137 119 141 104 103 113 122 146 122 115 118 125 142 113 117 114 115 117 141 113 143 127 122 120 104 119 159 131 138 122 112 113 138 119 129 115 110 123 130 114 121 143 118 119 121 114 120 126 118 119 113 116 127 102 138 148 117 114 120 116 122 111 105 109 117 118 140 122 124 117 115 128 134 119 124 137 130 124 131 119 119 138 123 112 132 133 124 113 133 132 118 134 116 130 120 117 147 128 136 116 106 122 119 109 134 125 128 133 142 117 111 118 137 131 125 138 131 120 115 123 132 131 115 123 118 124 104 129 132 126 144 121 122 119 131 116 104 124 120 123 146 120 132 143 158 133 126 126 131 130 129 127 130 140 124 128 128 110 123 118 124 126 102 155 116 144 143 136 136 150 121 160 126 108 106 132 132 130 137 129 135 118 140 126 112 135 123 141 142 128 121 140 129 140 125 119 129 130 117 143 130 107 125 128 130 132 106 149 127 115 155 109 133 106 105 126 136 109 132 120 130 127 108 123 110 131 130 126 118 121 124 130 102 124 126 114 135 116</counts>
			</dataPoints>
		</scan>
	</xrdMeasurement>
</xrdMeasurements>