File: data/XRD/XG-Sauerstoff/XG-800/W6824-1B_XG_Sauerstoff_800.xrdml
<xrdMeasurements xmlns="http://www.xrdml.com/XRDMeasurement/2.1" xmlns:xsi="http://www.w3.org/2001/XMLSchema-instance" xsi:schemaLocation="http://www.xrdml.com/XRDMeasurement/2.1 http://www.xrdml.com/XRDMeasurement/2.1/XRDMeasurement.xsd" status="Completed">
	<comment>
		<entry>Configuration=Factory configuration, Owner=User-1, Creation date=7/8/2013 4:01:53 PM</entry>
		<entry>Goniometer=PW3050/65 (Theta/2Theta); Minimum step size 2Theta:0.0001; Minimum step size Omega:0.0001</entry>
		<entry>Sample stage=MRD Cradle; Minimum step size Phi:0.01; Minimum step size Chi:0.01; Minimum step size X:0.01; Minimum step size Y:0.01; Minimum step size Z:0.001</entry>
		<entry>Diffractometer system=XPERT-PRO</entry>
		<entry>Measurement program=C:\PANalytical\Data Collector\Programs\Jorrit\2thom\_absolute_2th-om_10-130deg_PIXscan_56min.xrdmp, Identifier={15BCCF57-2807-42BD-B5B9-ECC0B3DC9284}</entry>
		<entry>Batch program=C:\PANalytical\Data Collector\Programs\SimonL\batch4x_2thom_10-130°_z9.1_x0,10,20,30_y0_57min.xrdmp, Identifier={EED9823A-2BEB-424C-9252-345C4EF2834A}</entry>
	</comment>
	<sample type="To be analyzed">
		<id></id>
		<name></name>
		<preparedBy></preparedBy>
	</sample>
	<xrdMeasurement measurementType="Scan" status="Completed" sampleMode="Reflection">
		<comment>
			<entry>_absolute_2th-om_10-130deg_PIXscan_56min</entry>
			<entry>PHD Lower Level = 4.83 (keV), PHD Upper Level = 11.27 (keV)</entry>
		</comment>
		<usedWavelength intended="K-Alpha 1">
			<kAlpha1 unit="Angstrom">1.5405980</kAlpha1>
			<kAlpha2 unit="Angstrom">1.5444260</kAlpha2>
			<kBeta unit="Angstrom">1.3922500</kBeta>
			<ratioKAlpha2KAlpha1>0.5000</ratioKAlpha2KAlpha1>
		</usedWavelength>
		<incidentBeamPath>
			<radius unit="mm">320.00</radius>
			<xRayTube id="1010048" name="Empyrean Cu LFF HR (9430 033 7310x) DK442154">
				<tension unit="kV">40.0</tension>
				<current unit="mA">40.0</current>
				<anodeMaterial>Cu</anodeMaterial>
				<focus type="Line">
					<length unit="mm">12.0</length>
					<width unit="mm">0.4</width>
					<takeOffAngle unit="deg">4.2</takeOffAngle>
				</focus>
			</xRayTube>
			<xRayMirror id="27010001" name="Inc. Beam Cu W/Si (parabolic MRD)" hybrid="false">
				<crystal type="Graded" shape="Parabolic">W/Si</crystal>
				<acceptanceAngle unit="deg">0.800</acceptanceAngle>
				<length unit="mm">60.0</length>
			</xRayMirror>
			<sollerSlit id="21010002" name="Soller slits 0.04 rad.">
				<opening unit="rad">0.0400</opening>
			</sollerSlit>
			<mask id="22030007" name="Fixed mask 2 mm">
				<distanceToSample unit="mm">220.00</distanceToSample>
				<width unit="mm">2.00</width>
			</mask>
			<divergenceSlit id="22010007" name="Fixed slit 1/8°" xsi:type="fixedDivergenceSlitType">
				<distanceToSample unit="mm">220.00</distanceToSample>
				<height unit="mm">0.19</height>
			</divergenceSlit>
		</incidentBeamPath>
		<diffractedBeamPath>
			<radius unit="mm">320.00</radius>
			<sollerSlit id="21010002" name="Soller slits 0.04 rad.">
				<opening unit="rad">0.0400</opening>
			</sollerSlit>
			<receivingSlit id="22010001" name="Fixed slit 4°">
				<height unit="mm">5.88</height>
			</receivingSlit>
			<detector id="7010017" name="PIXcel3D 1x1 detector" xsi:type="areaDetectorType">
				<phd unit="%">
					<lowerLevel>30.0</lowerLevel>
					<upperLevel>70.0</upperLevel>
				</phd>
				<mode>Scanning</mode>
				<activeChannelsEquatorial>255</activeChannelsEquatorial>
				<activeChannelsAxial>255</activeChannelsAxial>
				<pitchEquatorial unit="mm">0.05500</pitchEquatorial>
				<pitchAxial unit="mm">0.05500</pitchAxial>
				<readOutPeriod unit="seconds">0.135</readOutPeriod>
			</detector>
		</diffractedBeamPath>
		<scan appendNumber="0" mode="Continuous" scanAxis="2Theta-Omega" status="Completed">
			<header>
				<startTimeStamp>2024-09-30T15:01:26+02:00</startTimeStamp>
				<endTimeStamp>2024-09-30T15:57:31+02:00</endTimeStamp>
				<author>
					<name>PRO-MRD</name>
				</author>
				<source>
					<applicationSoftware version="6.1b">Data Collector</applicationSoftware>
					<instrumentControlSoftware version="7.0E 20130304">XPERT-PRO</instrumentControlSoftware>
					<instrumentID>0000000011142674</instrumentID>
				</source>
			</header>
			<dataPoints>
				<positions axis="2Theta" unit="deg">
					<startPosition>9.99826193</startPosition>
					<endPosition>129.99755682</endPosition>
				</positions>
				<positions axis="Omega" unit="deg">
					<startPosition>4.99913096</startPosition>
					<endPosition>64.99877841</endPosition>
				</positions>
				<positions axis="Phi" unit="deg">
					<commonPosition>0.00</commonPosition>
				</positions>
				<positions axis="Chi" unit="deg">
					<commonPosition>0.00</commonPosition>
				</positions>
				<positions axis="X" unit="mm">
					<commonPosition>30.00</commonPosition>
				</positions>
				<positions axis="Y" unit="mm">
					<commonPosition>0.00</commonPosition>
				</positions>
				<positions axis="Z" unit="mm">
					<commonPosition>9.100</commonPosition>
				</positions>
				<commonCountingTime unit="seconds">32.895</commonCountingTime>
				<counts 216 213 206 227 221 210 194 216 233 216 242 200 237 259 213 220 198 215 203 208 234 217 228 179 221 212 214 235 222 238 209 204 244 249 221 225 218 205 238 230 229 229 243 213 256 225 232 213 246 225 234 239 245 207 240 219 234 217 227 204 226 214 209 227 204 220 221 209 212 187 205 207 181 201 195 195 208 211 227 198 219 211 197 201 204 257 209 232 223 208 196 192 213 207 198 188 216 208 210 198 232 204 188 186 224 181 213 213 198 186 207 208 184 195 208 208 198 199 196 216 173 191 182 193 186 205 203 210 207 192 164 205 210 209 210 219 184 204 195 195 204 230 181 190 212 197 172 184 200 191 195 195 229 209 219 217 189 223 207 217 191 206 210 223 217 194 190 182 210 191 197 191 226 186 193 169 197 191 205 202 215 191 205 196 198 183 197 209 189 200 181 175 181 201 193 200 184 175 201 201 182 185 190 185 187 178 197 205 182 192 172 227 205 189 192 203 171 199 175 222 213 203 205 185 192 178 206 181 194 180 189 189 182 189 230 167 186 197 200 191 190 190 179 164 192 198 199 177 178 182 206 186 188 223 192 161 184 180 157 184 193 159 197 209 184 214 175 194 194 216 210 174 216 199 198 211 182 203 176 188 178 192 191 181 195 204 210 186 193 189 177 189 189 208 177 202 176 199 211 209 167 156 190 207 174 191 187 198 164 179 184 181 180 188 175 190 167 191 178 151 159 177 196 188 188 199 163 183 168 160 196 185 201 187 171 164 146 191 179 184 209 191 179 170 166 207 156 183 183 189 167 194 193 173 188 184 159 168 176 201 164 196 184 178 199 195 191 166 166 160 187 174 186 185 178 188 180 178 186 195 175 194 200 162 199 172 190 185 179 178 196 185 166 167 168 186 204 157 175 161 165 191 181 195 177 193 173 177 173 163 195 170 153 168 174 180 182 192 175 190 167 154 178 165 161 196 177 167 169 169 166 173 171 171 194 191 190 153 193 175 172 164 193 153 152 157 150 179 161 196 189 162 174 172 176 170 186 156 162 163 167 166 170 176 170 162 178 179 173 164 169 175 175 173 174 169 168 151 161 155 158 164 192 190 174 161 189 181 174 192 187 159 140 164 188 178 180 168 185 151 167 164 156 173 148 170 174 172 150 162 130 176 165 161 170 196 164 168 166 156 158 168 167 185 181 190 166 166 169 189 160 171 161 161 154 173 175 156 159 169 162 163 174 145 161 152 166 142 173 171 166 168 155 155 183 168 159 156 176 179 146 147 168 171 133 137 163 187 171 177 156 177 169 179 156 149 170 183 152 167 151 136 169 159 173 151 175 157 156 159 145 173 173 168 144 152 155 169 165 142 171 165 160 174 160 166 120 141 160 170 175 152 152 171 159 157 165 158 165 165 179 151 132 178 166 150 162 156 175 146 175 162 144 170 153 161 165 143 156 159 179 155 187 155 153 150 167 165 158 152 137 171 136 147 140 155 150 153 161 173 158 148 152 159 143 166 176 155 151 143 177 161 143 193 136 159 173 173 143 159 177 151 169 173 138 158 158 162 160 140 165 149 153 158 143 140 153 145 171 147 165 173 164 160 170 172 152 166 154 150 172 167 157 145 153 147 152 154 180 159 152 142 155 143 165 158 143 147 163 173 157 152 178 181 143 148 142 145 159 150 148 135 166 155 148 148 150 160 147 157 157 145 163 166 158 143 155 139 166 152 150 152 176 159 157 141 156 165 182 142 166 149 147 163 170 153 153 151 144 167 156 141 177 152 148 146 143 159 142 157 163 153 167 171 164 135 146 164 156 152 172 154 169 140 150 157 152 137 146 143 168 157 145 156 170 119 175 146 135 150 144 166 141 173 154 147 171 154 164 162 146 151 150 161 153 147 184 178 129 156 146 150 154 158 151 156 157 152 145 154 154 178 151 151 139 147 158 156 137 152 144 128 166 154 134 150 152 146 151 142 137 147 166 151 177 139 164 165 135 155 160 169 161 158 146 149 153 159 156 144 163 170 171 156 163 147 143 165 152 167 138 161 127 159 161 161 165 138 147 170 150 146 177 147 162 145 168 137 169 175 167 161 171 165 145 171 164 150 146 130 168 174 160 160 139 136 164 149 171 160 165 153 152 162 167 146 149 144 139 151 148 143 150 162 161 150 137 175 140 166 163 161 163 140 153 175 166 142 151 189 154 175 135 155 142 176 159 166 181 173 150 145 172 177 160 158 154 160 146 164 184 160 190 173 148 157 175 164 160 165 152 172 145 172 182 153 141 139 149 163 189 170 176 147 162 179 180 148 178 181 177 168 155 176 166 174 171 153 160 157 148 175 181 160 150 158 164 156 170 169 172 169 148 156 141 139 183 165 173 150 180 159 168 166 169 158 164 184 148 176 180 161 172 162 177 168 149 164 162 183 170 183 161 158 163 156 154 152 186 155 167 161 159 184 144 156 176 184 164 177 147 146 173 179 176 178 160 184 160 164 171 171 154 166 156 174 195 167 157 167 149 173 179 153 184 157 156 162 184 159 166 154 152 173 161 180 185 169 181 146 146 155 150 152 145 182 172 163 163 169 149 160 157 192 172 157 164 133 150 162 177 171 147 157 151 176 169 161 150 168 174 173 156 179 163 161 175 171 173 161 160 160 160 151 150 178 151 174 151 142 163 169 178 157 175 163 139 166 186 161 154 168 187 166 161 187 169 169 169 168 175 155 177 175 171 141 155 154 169 167 162 165 159 154 148 178 162 180 162 173 165 177 190 165 174 170 181 173 142 179 176 177 150 172 175 184 172 143 174 174 167 145 175 156 166 163 146 169 167 161 162 157 174 167 186 167 168 178 153 175 165 164 174 166 148 183 154 168 169 142 189 164 166 174 148 159 157 174 165 148 167 158 175 172 161 138 176 169 149 171 191 157 150 160 167 176 162 172 169 166 168 163 166 154 178 162 177 171 156 156 167 165 183 164 171 169 164 160 155 169 171 188 150 182 183 135 187 176 137 146 166 155 162 182 160 165 166 160 176 173 180 131 149 160 174 145 168 167 193 175 139 169 161 164 158 160 131 146 169 158 156 143 164 169 168 172 169 145 167 157 160 155 164 134 180 169 169 180 169 166 181 147 165 153 163 166 177 171 169 169 156 173 160 139 161 168 159 178 165 156 172 158 177 180 158 158 156 167 164 137 170 163 148 172 189 159 169 167 157 180 150 169 158 181 182 141 176 147 156 141 172 185 174 159 161 175 129 144 141 144 166 156 168 153 164 151 160 163 184 176 139 141 175 148 155 144 157 141 162 143 149 152 156 138 134 154 156 171 177 173 168 169 178 169 152 188 132 140 150 172 160 166 161 165 148 143 159 153 145 177 166 161 166 155 129 175 165 168 160 175 179 142 136 184 172 157 166 156 162 170 187 135 168 138 149 161 140 153 163 161 156 156 172 157 165 165 164 161 158 170 146 169 165 130 166 174 143 177 148 143 138 185 157 148 153 155 149 153 160 169 147 168 149 155 155 152 143 151 143 159 156 177 136 160 163 151 137 144 141 143 156 158 164 131 161 133 158 146 144 146 153 160 155 137 141 154 151 124 141 154 174 169 159 165 161 150 165 148 154 141 129 169 177 150 182 142 144 137 149 144 147 165 161 147 152 134 139 167 174 165 158 133 152 115 131 150 140 160 160 139 153 149 174 160 155 152 136 144 146 143 134 148 157 142 155 148 150 159 152 145 165 149 160 122 138 165 137 157 145 157 150 157 163 129 126 162 158 136 178 151 149 142 149 135 157 128 165 147 158 156 155 129 151 136 156 152 146 131 152 144 128 154 163 161 149 148 153 142 140 138 138 146 161 148 166 153 140 146 150 133 134 142 142 140 152 155 137 148 136 170 149 158 141 157 138 176 117 133 149 127 118 147 131 156 144 120 146 136 152 145 136 142 147 150 145 144 161 122 173 152 128 156 152 117 138 134 153 144 143 154 151 180 148 132 124 151 142 134 123 141 143 149 128 138 141 117 148 170 125 148 126 130 128 141 149 147 127 156 167 122 116 169 140 147 137 143 142 160 125 144 143 115 153 127 138 130 136 163 125 131 148 133 133 132 148 155 149 136 144 154 142 133 137 139 144 159 123 119 152 133 134 133 136 135 132 144 124 148 140 141 141 144 123 156 149 133 133 142 153 133 149 132 143 148 148 146 140 131 129 151 140 149 128 145 122 133 140 146 122 124 165 139 147 131 147 140 123 166 118 170 130 163 140 158 141 132 145 124 112 122 155 143 121 146 124 142 132 146 143 158 142 139 130 134 130 121 131 121 138 123 122 148 134 139 147 147 132 141 131 147 130 120 113 118 143 136 151 127 122 124 137 124 115 128 125 138 128 134 133 131 147 133 146 128 137 137 135 154 136 114 142 144 132 132 135 138 141 149 152 143 140 136 146 131 142 129 137 126 139 106 136 142 127 142 122 135 126 129 129 139 127 138 146 135 137 139 135 140 131 119 119 135 135 123 119 134 130 154 136 142 133 134 123 146 131 139 127 132 140 157 124 136 129 122 139 154 144 139 154 129 151 122 122 131 120 159 151 133 142 135 140 134 127 148 119 139 125 140 127 118 119 110 115 123 126 139 127 128 120 122 125 143 142 107 141 148 131 120 154 151 153 128 119 136 137 132 142 149 140 142 132 114 122 132 113 110 124 125 145 118 131 128 117 108 125 126 124 107 144 116 121 131 128 142 123 140 111 138 119 123 109 137 118 124 132 143 160 141 126 124 127 132 123 144 134 106 121 106 125 140 108 116 147 122 131 104 118 141 132 123 135 135 146 125 144 124 129 145 131 128 125 112 140 121 127 124 130 122 114 125 130 123 126 131 138 125 122 122 131 120 122 129 129 158 140 127 124 125 136 131 133 135 116 136 117 123 122 127 119 105 138 121 96 115 134 118 106 123 119 142 147 143 135 113 115 142 133 133 117 146 131 121 122 107 137 126 116 123 146 121 123 121 140 131 128 123 121 128 136 134 146 135 133 122 128 133 131 107 126 136 126 145 141 134 119 124 109 115 110 124 122 112 136 129 133 141 132 162 133 141 118 132 118 138 127 114 122 121 135 135 120 140 127 125 129 127 106 129 135 125 117 118 127 118 108 125 134 138 115 121 127 118 120 112 134 135 124 116 138 145 123 131 132 137 124 109 129 115 114 107 120 121 122 123 125 116 128 125 119 123 128 108 123 124 119 130 121 130 126 112 136 132 122 102 119 128 132 129 119 130 123 117 115 148 132 125 140 124 140 93 142 114 137 131 112 121 111 115 110 114 135 122 123 117 127 128 110 110 147 113 117 125 102 103 124 112 116 119 115 103 112 118 125 118 125 115 137 106 133 120 129 101 116 118 105 134 115 120 124 125 107 132 135 108 105 111 108 121 117 119 137 109 137 118 93 113 139 150 130 133 122 134 130 118 119 111 107 135 119 112 113 145 117 125 104 134 107 143 111 134 115 127 117 113 119 122 115 143 107 124 131 103 120 104 120 126 131 126 123 129 114 130 113 123 101 101 124 136 138 121 136 135 100 136 124 105 101 109 115 129 133 141 128 118 118 123 135 114 146 136 108 142 129 135 134 125 115 119 115 123 116 119 143 108 137 126 110 128 132 107 121 121 104 123 123 118 93 130 116 122 103 126 111 110 104 115 125 101 123 128 110 136 117 113 127 127 130 125 126 117 120 112 117 113 121 123 115 116 110 114 125 122 104 140 117 125 122 123 133 131 131 137 112 130 119 124 125 126 120 118 124 135 104 116 126 117 121 120 137 122 110 117 111 106 129 128 117 128 116 110 118 118 119 104 121 106 114 121 115 110 104 125 116 131 113 107 119 125 121 109 133 127 135 96 126 117 113 108 117 114 121 114 119 128 131 102 123 121 121 141 134 116 109 126 118 92 116 114 123 122 124 121 134 139 125 114 132 155 133 126 114 124 120 113 140 122 134 132 114 124 118 138 137 120 131 110 114 120 130 104 110 117 121 123 126 116 116 121 114 130 135 103 119 115 137 111 111 115 116 106 131 133 126 129 118 120 110 121 127 122 107 131 148 121 111 114 113 135 110 130 126 134 113 113 100 115 122 149 108 127 123 119 98 134 126 118 112 120 127 135 103 119 136 126 122 140 117 114 151 116 139 119 121 137 121 107 135 122 128 112 110 120 127 130 114 127 125 132 116 127 118 127 101 108 106 132 133 126 145 114 139 133 132 128 133 102 134 110 97 125 115 105 108 118 126 112 113 137 115 97 101 108 120 121 115 121 116 113 98 109 111 116 126 99 127 142 135 106 122 127 116 116 113 114 96 130 117 88 120 114 102 115 119 124 123 112 104 128 103 134 112 107 99 88 100 95 128 117 130 102 111 106 108 114 120 129 115 121 97 116 107 105 115 105 130 114 110 102 120 94 123 104 118 125 119 125 141 114 105 104 117 117 105 120 113 112 107 123 122 127 119 115 115 117 116 129 114 96 118 128 111 131 88 141 118 120 94 146 115 107 117 114 123 121 114 113 134 87 126 117 125 135 116 103 106 96 109 110 125 105 123 116 110 124 123 122 119 105 130 119 130 120 122 119 117 114 120 114 116 133 129 112 104 112 120 116 114 126 109 117 115 117 144 137 114 120 115 115 106 120 93 124 91 122 103 102 113 114 102 101 102 97 109 122 116 102 124 110 106 122 123 108 110 112 118 108 116 97 101 125 115 123 132 126 108 122 115 101 99 105 128 127 125 132 108 109 113 125 104 97 113 126 103 120 101 102 121 110 100 135 137 98 108 119 108 110 137 115 115 101 107 120 98 121 117 123 124 117 113 113 98 138 119 118 114 134 108 117 109 115 103 120 112 136 117 99 125 116 103 131 83 101 101 141 119 93 123 99 121 129 130 116 129 120 106 103 108 107 104 120 111 127 116 112 99 115 114 129 122 120 124 106 111 118 113 116 115 120 129 107 122 119 102 124 117 124 113 99 129 116 120 111 101 131 117 110 117 114 124 125 105 91 104 113 120 115 125 114 116 144 128 102 108 111 125 104 96 118 111 116 99 122 116 126 126 119 116 135 105 119 127 116 113 98 115 125 125 116 114 127 129 110 123 101 118 130 129 126 95 130 130 125 113 118 101 125 117 117 114 139 125 112 121 113 139 135 109 125 112 114 128 120 98 128 104 116 119 116 91 126 132 104 101 104 112 121 131 91 120 123 137 130 142 124 119 128 114 117 119 123 120 96 126 104 124 95 111 109 108 114 120 107 137 121 122 139 115 103 129 107 119 118 138 113 115 120 139 90 135 112 128 116 108 122 141 120 104 120 126 108 122 111 107 121 122 131 110 120 122 131 112 130 123 111 117 113 128 115 120 125 105 118 130 113 103 127 125 110 107 124 110 99 104 127 105 122 131 118 129 94 105 116 122 126 114 128 102 117 128 114 118 115 112 120 118 135 126 134 116 113 128 103 110 129 103 109 113 111 130 112 115 129 120 123 118 118 123 116 107 97 121 133 109 113 122 127 111 114 112 127 128 109 119 131 132 104 129 155 118 135 87 116 111 120 103 113 109 134 116 126 139 136 126 103 119 133 118 120 110 118 112 122 113 96 118 128 106 124 125 135 114 99 114 120 135 120 118 132 132 135 138 116 117 126 146 113 137 148 106 123 111 127 121 134 127 127 131 135 117 120 125 123 134 114 109 144 112 120 140 129 127 104 134 155 130 122 116 142 146 127 130 128 127 152 115 135 134 121 133 125 138 129 134 148 139 126 159 139 120 161 139 149 153 157 153 150 134 151 165 154 144 142 164 176 129 174 175 170 189 156 151 184 183 190 198 198 205 184 197 204 237 219 226 207 221 227 194 204 180 196 216 217 197 170 190 199 194 191 179 209 159 174 180 146 164 152 142 150 166 162 137 163 163 140 171 143 145 145 154 132 128 126 114 133 147 126 142 111 130 121 118 132 143 140 102 130 128 127 127 124 116 115 117 122 144 120 121 132 141 121 127 133 128 108 103 122 132 103 139 119 125 133 121 115 148 121 131 140 111 144 117 131 132 127 132 132 99 138 131 134 128 134 137 107 116 124 123 118 115 112 124 105 133 126 127 116 115 124 115 106 127 134 125 119 118 121 123 119 113 118 120 129 136 131 124 130 120 116 113 125 120 135 120 131 125 110 113 139 118 133 145 117 113 141 124 129 124 119 116 116 121 102 120 134 113 128 104 135 105 121 140 114 111 126 109 104 134 118 131 109 126 114 95 135 115 134 123 143 142 119 126 103 112 116 101 129 119 119 122 136 122 135 146 132 117 126 116 105 116 125 142 123 121 109 132 127 121 142 121 111 120 130 111 105 113 116 121 119 112 123 136 130 131 107 130 128 117 105 108 123 130 126 109 117 147 115 107 134 107 111 135 120 113 149 121 119 113 115 122 120 126 120 121 123 135 144 118 110 124 118 127 104 110 121 127 114 137 124 122 131 116 105 117 126 123 115 120 112 103 135 130 126 129 126 121 110 135 131 135 108 129 134 127 142 137 135 130 125 130 121 147 135 121 116 113 113 147 131 114 123 101 123 127 97 115 137 117 122 133 124 123 129 127 123 123 134 132 105 135 118 114 132 93 121 116 127 134 102 103 129 135 113 109 131 121 121 116 103 121 126 126 135 115 108 124 125 113 109 114 110 126 122 116 133 106 109 119 127 131 129 104 114 127 136 120 109 128 105 119 118 126 118 108 125 112 136 105 130 118 101 120 122 107 129 122 119 111 96 129 107 119 117 125 117 106 127 105 121 136 124 114 120 105 116 123 125 118 127 125 108 118 118 117 122 103 129 110 114 100 123 121 148 131 147 104 111 122 116 128 116 120 122 127 107 118 104 102 116 125 110 117 125 101 132 132 119 126 93 119 113 122 122 131 121 132 130 122 131 109 106 119 103 100 120 103 108 144 128 98 111 109 119 110 122 122 134 133 121 117 126 117 124 114 107 138 115 136 115 109 110 120 129 130 111 119 124 116 113 128 131 126 118 129 120 122 130 131 119 120 122 140 114 124 123 125 105 122 113 126 111 143 124 104 109 139 139 130 106 137 120 121 125 121 127 139 112 127 118 106 117 130 106 128 126 148 121 126 130 112 129 107 118 118 134 135 114 132 111 114 107 112 112 115 103 123 128 134 108 118 122 131 130 100 118 110 122 142 132 132 112 131 138 114 135 123 118 110 107 125 127 138 116 89 97 98 117 105 127 105 113 109 132 120 125 124 117 125 114 107 111 116 125 110 115 125 110 108 113 143 112 126 143 112 123 113 140 121 127 107 118 110 114 110 139 122 137 125 133 106 129 125 121 141 130 130 127 130 127 143 106 102 123 98 119 123 134 136 118 115 110 125 113 107 127 109 117 131 113 120 136 118 119 113 112 117 131 123 137 136 117 128 141 139 121 116 129 117 116 140 126 122 152 126 118 115 107 132 125 127 134 128 131 104 126 120 116 122 131 125 120 123 107 150 113 111 125 111 130 142 115 120 98 120 114 129 123 125 118 115 88 120 125 134 125 129 113 115 114 122 112 148 127 103 108 138 127 131 100 112 102 125 127 112 120 133 127 101 121 103 116 134 118 113 109 121 115 109 123 113 133 116 136 118 134 111 116 132 104 104 126 125 120 110 130 129 114 116 99 124 127 131 120 95 136 109 106 127 112 126 137 123 112 124 117 116 127 123 113 136 116 125 102 143 134 121 107 118 123 127 106 108 128 134 104 139 144 130 124 123 120 113 124 114 124 129 106 132 112 118 121 123 104 118 139 115 129 108 138 119 122 138 120 123 120 121 112 118 131 126 101 129 117 125 119 111 128 127 125 119 117 113 128 128 131 132 128 103 130 127 132 111 121 108 105 123 136 112 110 137 102 124 122 103 139 112 114 142 121 121 143 116 125 112 113 98 123 114 112 113 129 117 122 126 122 131 129 133 111 102 125 125 128 126 124 113 137 131 106 125 125 130 109 131 122 121 142 112 104 123 119 137 145 134 128 110 121 125 121 127 139 126 118 134 133 118 129 111 140 121 118 136 111 122 111 124 118 120 125 117 111 115 123 110 117 136 100 106 130 107 117 129 128 122 105 107 126 117 124 109 118 114 125 125 143 115 125 123 122 117 121 133 103 116 121 129 118 112 151 114 129 125 119 125 104 120 138 115 130 123 139 130 134 119 109 116 119 124 133 107 134 122 138 108 108 118 113 127 95 110 118 131 115 124 108 123 128 126 115 132 112 118 113 135 135 128 133 134 133 109 123 104 108 130 121 121 128 116 113 129 135 137 117 125 124 114 116 113 119 118 128 101 135 128 113 97 122 120 121 117 138 117 131 121 97 138 104 135 120 112 128 138 144 143 112 127 97 119 130 106 123 104 132 112 138 100 132 120 133 153 125 125 120 116 113 118 125 119 117 146 144 119 118 107 113 112 121 141 117 123 130 124 104 135 108 115 107 144 135 113 120 136 131 138 106 111 141 119 119 127 109 137 124 129 134 128 127 134 128 108 134 135 117 112 129 116 127 136 107 128 125 129 117 129 107 117 133 116 113 132 116 131 128 112 126 116 142 119 109 135 120 114 124 98 119 137 117 122 139 117 120 111 134 110 118 126 108 123 138 117 116 118 116 113 151 125 127 142 144 125 142 117 124 132 128 144 121 147 106 126 121 120 120 130 109 114 133 113 128 141 107 118 130 108 111 111 105 117 128 121 119 126 127 134 121 134 129 118 156 92 107 117 136 134 142 123 121 138 153 134 139 107 119 125 113 111 125 119 127 109 135 148 130 119 116 132 132 111 129 111 124 142 129 109 117 99 128 128 120 122 113 115 126 111 128 134 141 126 124 119 131 138 124 132 108 120 119 125 133 99 126 84 129 120 125 127 112 132 107 143 132 116 132 111 131 120 137 131 118 117 120 137 109 125 124 121 104 121 112 124 114 102 113 120 119 141 140 128 117 103 142 131 118 110 135 132 94 132 131 132 132 140 152 118 108 133 130 132 140 133 121 104 124 124 115 134 130 144 96 128 126 105 132 131 116 125 129 109 122 116 119 123 123 117 134 111 110 119 129 103 115 123 122 105 141 108 128 129 134 122 105 118 121 143 117 125 125 147 136 131 134 132 127 104 138 111 124 126 119 127 121 126 101 125 134 142 140 129 121 126 122 127 131 110 137 128 114 133 108 113 119 128 126 122 107 102 130 143 117 125 145 107 133 120 106 144 113 129 121 117 126 114 124 150 134 109 118 117 123 140 128 110 129 131 104 145 140 137 109 132 123 136 132 122 132 163 140 147 127 130 143 133 135 124 133 112 127 126 105 145 121 121 118 129 122 141 109 125 117 112 128 135 131 113 133 123 116 116 118 142 115 119 120 145 130 117 116 112 122 126 126 128 127 135 122 113 112 126 124 117 117 111 131 134 114 138 114 128 128 124 122 109 125 116 109 111 118 127 131 135 120 113 129 135 130 126 116 121 145 145 116 137 121 127 120 125 119 101 124 131 121 103 135 121 132 124 125 125 118 131 110 134 126 108 90 134 110 111 116 138 118 142 135 124 128 120 129 116 133 123 143 110 116 133 120 140 148 122 130 124 125 136 117 132 104 119 124 125 128 128 129 150 124 138 134 132 123 134 119 145 119 130 123 160 133 130 138 145 106 124 136 139 138 122 116 130 119 136 110 118 122 130 139 118 115 121 122 114 117 126 129 116 124 116 118 135 94 110 141 117 148 115 115 131 138 130 109 128 114 141 128 129 136 111 124 128 132 125 118 109 120 125 121 129 129 137 121 117 115 124 128 119 115 132 132 119 118 126 122 127 132 101 114 120 118 116 131 129 117 113 134 122 136 120 115 127 112 110 120 126 121 116 107 125 116 112 116 115 145 124 120 116 129 124 119 116 135 128 136 118 136 132 127 141 121 132 135 105 129 132 113 121 135 116 140 118 115 112 122 121 126 111 125 130 104 146 127 126 127 144 132 133 126 109 126 119 134 127 137 144 129 108 129 129 132 129 140 144 132 135 146 132 125 138 134 151 142 128 128 134 112 130 145 120 120 141 115 114 139 124 128 117 129 138 143 132 132 127 126 121 140 99 105 138 137 128 121 124 129 115 141 141 124 122 116 129 151 119 137 129 131 115 130 125 130 118 134 131 129 114 116 121 120 119 143 138 108 137 125 115 123 105 118 126 136 143 119 109 101 128 133 114 123 138 116 125 125 134 141 125 118 119 109 110 141 136 117 125 136 145 117 120 125 158 130 128 136 120 136 127 117 148 97 132 129 130 115 123 145 105 126 130 117 125 122 148 136 136 134 137 129 139 127 131 143 137 141 138 121 118 136 130 118 116 111 117 134 115 152 136 133 112 133 132 123 120 127 112 129 120 129 127 144 139 139 137 137 121 121 126 138 121 135 137 134 136 145 122 126 130 144 136 118 135 124 137 138 138 135 126 141 135 146 136 121 124 131 134 124 138 134 143 132 103 130 138 149 141 132 137 131 107 130 144 144 126 143 132 133 162 125 123 130 137 121 139 125 141 131 144 127 134 110 134 149 131 118 129 125 122 112 148 143 138 128 116 140 144 142 131 135 140 123 142 145 115 123 119 115 140 140 140 117 134 126 144 127 119 147 126 134 117 117 139 136 140 123 136 138 121 138 147 136 122 125 137 129 128 121 119 119 118 148 124 116 139 130 110 124 111 124 123 128 151 133 130 127 127 129 111 131 120 144 128 120 126 131 142 137 122 130 137 132 120 113 132 122 126 121 135 110 132 138 130 132 115 126 142 114 129 124 129 123 152 137 120 124 127 133 135 122 126 123 96 127 147 129 130 130 134 118 138 123 140 107 111 121 128 113 146 128 132 130 130 115 133 105 122 118 114 141 124 122 113 138 127 141 128 127 150 140 116 150 132 142 131 129 117 134 123 118 121 125 109 121 152 131 127 153 138 131 120 136 127 134 123 120 132 138 136 117 155 118 124 132 118 127 112 108 118 166 131 125 125 133 125 152 126 130 131 133 131 146 123 127 112 132 118 129 126 149 116 146 133 111 130 133 121 133 121 127 149 138 124 141 115 133 125 132 120 133 119 139 113 135 108 130 121 124 122 113 121 115 114 139 101 147 144 129 121 133 127 126 120 122 143 131 131 120 108 136 127 128 114 140 122 141 134 109 136 111 130 120 126 107 128 99 121 124 134 137 132 121 125 139 121 105 136 143 97 157 134 142 133 116 144 131 150 123 133 153 141 114 151 120 142 122 133 148 145 144 127 127 154 122 117 138 116 133 129 131 140 138 134 134 131 139 143 136 120 125 140 148 122 133 144 109 140 121 131 114 129 117 139 147 132 123 124 134 132 159 122 139 114 121 141 129 126 118 149 153 124 133 125 123 134 126 137 136 125 144 118 124 130 143 134 116 131 128 147 120 121 109 125 121 135 147 135 126 126 133 125 117 127 117 138 110 131 126 128 158 149 136 121 111 117 138 127 127 110 114 125 159 119 129 133 140 160 121 112 135 126 118 127 116 139 138 127 128 129 128 121 128 127 125 141 124 105 146 137 135 129 138 119 113 118 139 132 134 118 126 123 146 139 131 144 119 145 124 131 139 139 122 123 139 114 111 122 135 137 133 122 123 108 120 128 120 98 135 131 130 139 142 115 127 131 120 129 103 104 122 127 119 118 125 143 132 117 143 133 129 131 115 124 119 124 139 125 101 132 139 132 131 127 126 150 113 142 122 129 138 116 100 128 125 154 122 125 132 127 141 129 112 104 127 113 150 130 125 102 131 130 137 115 136 123 134 123 130 135 135 121 129 108 119 110 125 149 106 124 117 115 123 123 132 142 132 132 101 139 144 140 117 135 120 134 119 137 133 140 129 124 123 120 116 132 141 114 140 111 132 114 131 125 113 121 123 111 112 135 136 125 121 120 132 125 134 118 141 132 125 123 125 128 132 146 142 134 118 114 153 123 137 130 130 116 122 139 123 119 117 114 121 132 143 125 144 140 127 116 133 99 110 134 113 105 130 124 130 151 122 121 127 124 144 145 142 141 159 121 125 129 145 141 126 170 134 127 105 128 135 131 146 169 124 122 127 149 155 132 150 134 124 121 134 122 157 133 131 134 132 133 121 124 140 152 133 124 145 108 115 130 102 129 126 121 137 122 108 100 147 155 127 151 143 114 124 144 117 118 138 120 114 139 128 114 129 137 128 124 124 149 134 130 134 135 132 138 113 123 118 142 131 128 127 146 108 111 136 138 126 127 152 130 118 103 124 154 147 131 130 134 136 133 144 153 128 128 124 134 129 129 137 122 137 114 126 122 130 146 111 115 122 106 144 130 119 128 136 129 128 98 161 123 122 115 143 133 117 115 132 139 140 115 133 143 139 128 120 135 128 142 124 135 129 116 102 129 121 129 125 132 115 129 128 116 151 161 142 130 136 122 114 118 130 135 111 122 139 139 153 141 125 148 141 124 120 138 140 142 137 127 116 133 141 139 126 141 134 126 109 144 145 142 127 113 142 120 128 133 139 148 139 134 127 127 131 142 124 118 128 146 108 128 133 133 131 123 125 110 132 125 127 120 108 142 118 132 116 129 145 122 132 138 136 116 133 136 117 130 130 134 140 137 127 114 148 135 124 144 138 129 132 142 120 123 145 128 135 135 142 124 137 112 113 124 121 151 114 121 127 150 138 144 117 148 136 112 129 147 140 124 153 136 118 125 114 139 125 135 140 130 122 131 124 139 140 124 135 135 114 124 118 131 137 100 129 138 146 132 133 118 129 126 134 123 150 122 131 129 122 141 134 110 126 120 134 141 123 113 144 131 129 131 136 124 142 150 133 146 115 147 132 137 134 139 131 137 154 149 143 135 129 140 136 130 128 119 119 144 136 138 114 111 125 123 116 151 122 108 115 117 132 129 137 121 144 102 102 132 136 122 119 135 142 132 127 138 137 121 144 126 134 147 144 119 123 162 161 106 128 124 140 143 115 137 138 129 135 141 107 125 144 128 130 117 127 139 109 132 129 118 137 125 125 129 139 131 135 109 136 126 149 140 131 106 140 120 112 131 150 141 165 138 138 124 140 125 131 117 131 138 118 139 113 136 120 123 145 122 118 124 118 125 109 125 134 129 133 126 136 142 132 134 120 130 142 118 110 132 134 115 110 112 115 146 133 125 109 131 135 134 142 112 114 113 105 128 116 116 136 137 141 118 131 127 122 129 141 120 132 124 141 130 141 147 131 139 133 109 130 141 124 151 120 125 129 142 118 127 142 142 120 135 140 125 100 122 147 109 128 138 130 120 143 122 115 131 127 143 163 137 143 117 141 117 140 112 114 126 123 123 112 134 146 146 116 135 121 113 118 146 145 141 144 118 129 134 123 114 125 132 129 155 135 127 121 111 154 123 129 118 136 139 127 124 139 144 146 131 118 144 145 152 109 150 119 112 121 130 147 146 132 106 116 140 136 109 130 123 143 145 131 146 140 118 122 117 148 127 130 133 131 131 116 147 133 106 113 140 126 149 130 133 136 150 142 132 118 138 136 148 128 135 121 132 135 150 144 120 150 156 147 101 123 130 127 133 123 138 124 121 136 139 137 123 115 134 136 119 137 108 135 134 138 109 122 131 130 137 146 117 132 111 122 133 135 124 144 110 119 123 124 119 146 131 138 147 113 130 121 111 115 139 131 116 140 129 127 115 116 128 119 106 135 127 135 134 136 119 110 127 114 135 151 134 125 127 119 121 152 136 131 149 131 128 136 124 123 145 121 157 122 132 138 115 119 111 124 138 146 145 144 108 144 144 130 119 131 124 133 120 113 121 112 131 143 131 125 113 147 116 125 128 117 142 129 122 114 142 138 113 137 133 104 129 125 158 131 110 127 115 124 131 121 131 103 124 146 135 145 140 102 110 121 100 129 128 129 131 121 126 128 135 124 130 140 125 126 120 132 142 117 109 147 117 126 159 118 149 137 147 138 145 105 140 122 114 147 132 145 132 129 130 127 144 137 139 126 121 122 121 136 121 144 125 125 141 117 121 132 149 136 124 119 128 126 147 139 118 115 127 116 123 137 120 128 116 143 123 126 125 126 124 146 121 127 129 141 127 136 118 132 118 125 143 127 111 123 111 149 118 151 133 122 113 139 133 130 136 120 128 125 138 139 149 121 153 128 132 125 127 133 119 157 144 141 144 140 123 137 124 126 125 112 138 123 126 152 156 137 117 117 141 129 129 134 133 119 121 140 127 117 118 119 131 128 117 120 125 111 129 114 128 150 149 125 128 127 143 131 115 135 123 136 134 119 139 130 119 131 131 152 125 154 123 135 126 134 140 114 107 129 122 127 142 147 152 127 146 132 129 146 123 154 150 139 150 138 155 125 134 157 136 136 128 152 152 117 114 143 131 137 134 132 156 136 130 157 141 144 155 125 153 123 126 147 178 138 153 130 127 179 127 164 130 116 156 138 142 136 132 146 134 151 154 146 154 137 141 150 135 159 122 146 150 152 145 156 156 125 120 149 138 134 137 136 130 156 126 156 145 147 157 152 156 132 145 134 147 129 139 116 130 115 155 132 137 146 123 143 135 142 134 142 128 127 118 140 132 130 133 119 133 123 133 129 137 127 148 131 134 128 130 128 141 150 151 153 142 125 138 150 121 140 139 125 137 113 112 144 138 140 132 110 128 131 146 105 139 130 128 122 154 129 118 139 116 143 160 119 137 115 98 126 126 142 132 138 132 116 119 120 131 112 139 125 128 149 133 129 108 126 128 135 142 148 115 121 141 133 130 112 110 121 124 127 138 132 130 126 119 125 148 145 130 145 111 122 139 124 136 145 145 141 125 128 138 126 115 116 106 130 131 131 135 126 124 126 125 122 137 135 127 134 132 125 133 137 121 136 137 119 132 113 130 140 118 126 135 135 111 128 131 157 142 130 105 127 126 141 136 110 125 147 125 127 119 129 130 148 139 123 114 118 148 122 128 132 138 123 125 134 124 112 122 159 107 136 115 113 138 132 121 123 140 144 137 137 132 114 128 160 141 119 138 134 135 120 132 125 122 128 123 109 124 120 130 151 116 142 138 126 133 133 99 118 141 128 140 158 150 130 136 131 125 131 100 136 112 90 123 121 143 125 137 125 131 153 116 117 151 100 135 99 111 131 137 121 140 130 134 119 141 129 116 138 133 125 143 117 134 112 145 107 122 127 141 114 121 126 118 130 127 124 114 134 132 131 142 133 120 154 128 111 122 151 120 118 122 118 122 126 125 131 135 128 128 123 108 122 136 121 136 131 106 143 142 133 123 146 144 142 108 113 111 128 104 100 118 143 137 143 115 134 135 122 115 126 137 121 129 113 124 108 139 143 122 126 113 101 119 129 137 126 129 135 122 93 108 118 115 122 125 141 108 146 106 137 111 122 112 123 136 116 144 119 122 139 121 116 147 141 137 135 126 126 131 113 110 127 110 119 126 126 147 124 121 135 144 133 127 146 125 113 133 149 141 136 150 132 137 112 110 131 144 122 128 125 125 133 133 133 152 142 138 164 124 134 132 126 142 139 137 133 137 122 137 125 109 131 114 151 118 123 134 136 130 123 138 140 131 115 154 125 153 130 132 111 124 115 114 113 140 140 105 135 126 137 126 131 138 140 137 137 124 127 116 137 145 117 113 120 120 111 127 130 115 127 130 138 119 137 140 115 126 131 115 123 127 126 143 137 168 127 123 124 129 145 133 125 119 143 134 125 149 119 142 138 126 118 143 138 115 120 100 138 128 149 128 131 134 130 117 120 122 122 149 130 124 128 124 114 129 146 118 148 123 134 117 139 120 136 148 123 136 106 131 152 116 113 117 129 117 120 124 145 148 130 121 138 151 128 137 123 108 96 122 120 127 124 120 135 118 135 119 119 117 115 119 117 116 126 116 140 141 121 125 127 118 116 135 117 122 142 133 121 126 141 137 142 108 128 126 120 149 136 159 140 124 146 124 139 133 120 120 134 127 144 140 142 132 128 128 115 131 144 133 117 115 124 123 144 122 101 132 115 140 126 132 119 153 124 125 122 126 134 133 137 136 132 131 148 119 129 111 150 123 123 130 124 117 131 144 140 114 111 134 138 141 123 134 122 116 126 138 122 139 157 144 123 135 111 112 132 126 107 111 135 134 135 143 124 144 113 124 136 151 105 131 119 133 113 118 146 109 135 123 155 139 122 128 140 130 109 113 133 124 149 128 122 115 142 151 113 131 138 116 121 130 148 130 123 121 117 143 141 120 138 119 105 125 138 141 123 134 120 118 106 134 126 111 121 151 131 141 122 143 127 137 148 116 138 117 118 130 145 119 142 125 125 133 140 125 122 132 147 130 134 131 121 138 118 128 105 119 126 129 130 137 131 142 108 141 137 129 123 125 112 118 126 127 116 139 130 132 146 138 112 124 132 117 146 135 143 159 123 115 116 124 135 129 137 149 142 115 96 126 126 125 111 129 122 106 132 127 128 131 150 138 135 128 146 138 125 140 129 118 132 114 145 113 127 125 140 140 137 113 147 139 126 119 123 121 111 140 151 119 131 122 125 123 135 127 110 139 134 120 134 125 131 134 137 114 124 122 120 124 127 121 128 137 120 135 137 127 120 118 141 156 138 142 132 120 132 126 149 125 137 131 129 132 133 152 135 127 131 127 135 117 147 141 137 110 138 121 150 124 163 131 139 115 124 135 133 135 107 143 110 135 125 126 129 132 110 127 114 116 136 136 129 132 114 130 120 119 138 133 156 153 145 139 138 137 138 129 157 152 143 106 121 107 138 142 124 124 136 112 119 142 118 122 131 123 153 123 130 123 120 104 140 144 148 121 142 118 156 134 102 123 127 119 129 129 143 139 131 138 125 112 131 124 146 131 138 138 156 119 122 139 132 120 108 112 136 134 112 139 120 124 139 132 135 124 119 135 123 118 116 137 142 122 152 131 135 142 123 112 138 160 129 144 142 122 132 100 137 122 132 155 139 116 144 109 110 133 125 151 108 132 131 121 135 124 141 140 130 125 123 128 124 136 143 157 115 114 128 144 142 123 150 144 119 139 128 142 115 131 140 136 147 162 139 138 126 122 129 117 137 140 120 140 133 150 114 116 111 118 129 134 127 113 120 131 117 107 138 126 133 122 136 138 130 126 130 145 139 122 136 129 126 111 136 137 127 137 125 161 132 140 113 152 130 125 129 105 123 137 142 150 125 132 146 136 138 140 128 127 133 129 135 133 134 135 125 151 107 140 131 131 141 157 105 127 137 147 144 132 143 126 155 145 123 121 129 131 134 119 118 151 119 109 140 132 115 138 119 119 131 141 143 142 125 108 125 150 128 138 123 139 123 118 148 136 133 128 129 153 115 135 142 149 138 141 136 126 113 146 133 131 130 128 118 112 109 123 134 135 126 143 128 135 123 116 125 143 140 130 132 108 122 116 109 135 130 134 133 135 135 122 142 124 126 126 156 123 132 118 136 131 143 145 122 120 139 118 129 143 140 111 125 131 128 131 134 127 132 132 131 117 127 125 102 118 125 124 123 139 119 153 144 110 137 146 136 145 133 126 122 128 119 117 127 148 122 112 132 136 122 137 136 139 130 134 137 138 142 139 118 136 113 121 139 136 128 136 135 123 158 145 123 139 138 128 127 112 115 133 129 155 133 119 145 134 117 142 150 119 133 129 136 133 147 132 115 129 124 141 144 120 151 125 122 133 138 111 120 130 127 139 122 111 125 131 132 121 141 109 126 124 116 131 120 145 132 106 138 149 132 134 121 116 115 122 118 149 131 138 124 132 131 129 125 118 117 114 105 131 127 118 145 139 125 136 103 123 134 121 133 137 124 121 133 144 133 107 120 119 134 146 122 128 112 128 128 130 129 126 110 119 133 123 136 146 144 145 130 145 135 125 140 142 117 122 141 130 141 131 110 137 116 134 166 139 130 108 144 136 141 117 128 112 125 104 135 118 136 135 127 124 132 123 146 139 141 150 134 136 126 131 148 140 151 134 126 147 126 128 139 146 128 121 130 136 123 118 130 121 134 123 131 130 131 154 149 142 140 129 120 123 134 134 104 110 140 118 117 127 127 140 130 123 134 134 126 145 138 139 144 144 114 128 146 138 134 137 162 117 105 136 121 135 136 120 119 131 137 107 107 114 118 135 123 151 149 115 119 142 143 136 138 143 132 134 142 144 145 130 154 130 131 147 153 139 117 140 125 148 133 121 130 119 136 149 127 121 138 135 150 135 135 157 137 140 134 138 135 133 144 154 142 122 121 107 121 125 125 137 126 129 149 141 140 144 154 151 118 147 141 135 129 158 135 137 137 124 153 119 143 141 121 144 137 149 125 144 142 131 127 155 127 138 123 133 158 136 119 145 117 142 140 144 143 132 110 136 140 129 124 134 135 119 117 111 120 122 120 122 113 124 138 116 122 142 123 155 136 149 130 103 131 136 142 104 125 134 109 146 131 124 124 128 136 119 134 128 139 146 133 129 129 122 121 141 137 120 145 127 104 120 106 114 109 120 108 116 127 146 107 140 131 120 113 139 121 148 137 128 113 112 120 112 140 149 129 122 145 106 119 111 120 118 129 112 119 119 117 129 125 133 129 125 131 125 131 156 128 129 118 122 136 143 120 135 128 141 132 120 134 111 135 94 130 151 116 119 148 140 145 150 117 136 132 148 117 114 119 136 144 115 129 130 125 131 113 125 132 124 138 126 130 126 140 146 129 123 140 120 139 141 100 117 124 139 123 132 118 150 122 115 138 121 125 123 124 124 126 115 141 110 133 148 123 154 127 131 129 122 118 116 122 108 124 145 134 125 119 154 132 115 131 113 147 141 118 141 109 137 128 129 156 130 123 125 135 136 150 120 130 139 130 126 134 128 133 146 132 129 123 115 139 143 130 112 130 131 107 114 145 101 147 146 123 138 123 143 124 116 125 138 125 130 100 136 135 124 137 124 133 129 111 151 133 101 120 136 123 162 117 138 116 134 105 117 130 123 123 114 102 133 135 131 117 112 128 142 123 123 124 137 132 122 117 138 154 132 131 144 139 134 135 144 159 132 141 135 118 124 137 140 138 135 120 141 135 132 142 105 120 120 129 131 130 133 119 137 116 133 134 126 144 131 105 118 124 138 125 114 124 108 131 111 127 136 113 113 143 110 120 106 122 126 144 124 134 112 115 119 111 126 125 146 128 119 117 126 137 147 131 135 115 117 124 122 137 125 133 134 136 124 122 109 136 120 135 148 110 124 143 125 102 135 123 135 127 127 120 113 108 133 143 133 128 135 144 155 116 123 137 123 133 126 143 120 119 110 131 128 138 114 123 118 146 137 141 136 114 134 111 129 131 139 133 117 138 126 101 129 128 146 119 129 132 130 133 132 116 139 141 142 144 124 138 130 144 138 150 136 136 126 131 131 133 143 132 142 130 123 145 127 131 132 133 120 129 142 110 129 136 131 130 151 129 129 132 121 128 139 113 129 106 146 137 131 126 126 116 135 149 132 140 102 121 153 150 123 124 137 133 149 121 136 122 130 133 149 137 130 124 124 114 133 143 126 116 131 123 115 151 147 142 112 115 147 118 128 133 130 136 134 144 133 149 129 126 144 130 141 143 144 128 127 123 141 131 141 117 136 126 155 122 145 131 130 143 118 135 131 138 136 129 132 131 143 128 134 126 118 102 127 132 130 125 144 135 135 122 139 131 134 132 152 126 145 128 133 138 101 104 131 123 110 156 123 124 126 129 113 129 119 122 146 125 129 121 132 137 120 129 119 144 130 131 134 128 135 170 141 132 153 143 135 132 123 116 120 106 123 123 140 150 138 141 126 130 154 109 104 134 137 115 136 125 135 120 135 137 148 122 116 125 133 124 126 128 122 138 147 140 141 131 144 118 131 136 140 128 153 146 109 135 117 135 123 125 120 119 131 126 136 123 118 147 143 142 131 156 116 146 138 131 144 149 134 123 110 138 107 128 145 141 125 132 131 133 123 152 131 125 130 133 125 142 132 139 151 131 136 130 134 137 133 107 138 151 137 125 144 127 147 149 120 114 135 120 124 130 114 134 131 144 127 123 125 141 133 134 133 148 156 124 121 135 102 132 135 135 130 119 139 134 126 119 130 117 129 144 130 144 120 123 137 120 129 138 136 118 119 163 129 148 117 133 130 129 131 119 132 126 136 129 136 127 117 143 124 133 156 139 123 115 126 129 117 116 122 124 144 130 150 130 119 121 121 133 136 135 148 144 135 132 148 120 139 163 146 125 140 126 112 134 131 138 130 129 141 124 150 139 124 144 124 149 129 130 144 125 130 131 126 132 123 136 128 115 136 132 133 123 142 140 142 136 112 128 121 140 130 143 127 133 127 115 122 128 148 108 124 133 134 143 112 138 115 133 115 126 153 134 143 150 128 141 148 145 138 133 158 115 122 149 152 132 136 138 126 122 131 118 132 126 125 141 148 139 133 137 159 124 137 137 129 139 137 129 131 148 147 124 119 135 149 126 115 152 136 135 132 119 149 150 134 124 146 123 141 131 119 107 113 148 126 122 128 130 138 122 133 154 150 131 124 148 133 127 135 132 134 145 148 131 136 121 153 124 123 113 109 136 138 138 134 157 119 149 132 139 116 103 155 143 134 144 121 131 131 117 107 130 136 138 138 145 129 137 125 133 127 133 119 124 126 123 129 146 123 119 134 131 116 127 146 128 132 125 115 118 135 144 118 139 126 128 128 110 119 125 105 113 151 147 110 144 114 126 119 125 117 151 138 157 126 130 123 137 106 131 130 126 140 140 128 139 143 126 124 130 130 135 141 130 114 129 121 143 135 136 130 133 140 140 126 127 131 133 137 115 139 126 127 147 116 132 154 127 141 137 133 132 124 125 110 149 136 106 139 126 134 118 142 143 137 138 162 138 128 115 122 143 139 131 142 149 128 128 123 146 154 138 133 124 135 117 120 132 132 151 135 126 148 138 137 106 122 139 134 127 136 156 136 142 108 131 143 125 119 144 137 127 138 110 121 122 124 130 137 137 148 134 142 116 126 143 119 132 141 130 126 133 139 130 146 130 136 126 115 131 119 136 126 128 132 149 158 134 143 132 123 143 142 133 125 111 130 134 141 128 124 138 131 139 143 133 116 135 157 140 131 119 133 137 144 143 130 130 137 148 124 103 138 123 134 130 150 129 142 134 148 128 130 128 121 131 138 106 134 139 120 140 119 137 132 131 137 146 136 134 125 126 130 112 159 132 132 144 133 143 131 139 118 117 131 109 134 119 126 131 136 133 149 130 128 121 117 150 135 137 145 149 144 147 129 144 122 135 135 113 156 144 152 137 120 120 126 140 133 154 113 129 125 158 126 128 144 133 138 127 123 131 121 128 126 125 139 155 118 144 143 109 128 143 138 129 113 128 120 118 111 129 124 123 135 132 117 133 136 157 124 133 121 140 133 142 138 125 127 130 124 127 131 141 136 144 138 121 107 118 126 131 139 89 147 133 126 135 127 142 137 148 136 126 122 144 119 134 159 132 119 132 121 129 142 141 137 129 130 140 132 129 150 131 135 121 121 122 139 148 134 116 129 139 127 128 132 149 119 132 144 118 149 144 112 140 128 112 129 142 133 139 137 121 148 141 155 138 128 126 142 123 136 137 137 133 140 134 134 136 146 140 140 114 130 123 124 112 113 139 130 158 157 124 148 122 140 126 134 121 130 132 131 130 136 141 144 111 140 127 136 126 119 133 138 132 151 131 143 131 157 123 133 146 129 133 132 122 127 120 120 125 141 145 130 135 131 130 142 122 142 123 138 122 142 117 133 123 128 121 141 135 139 160 121 135 140 146 127 150 117 137 125 122 151 112 154 140 120 141 139 139 125 157 134 136 126 141 125 136 117 146 114 130 112 113 133 147 131 126 122 135 111 126 140 148 137 127 135 121 113 133 133 113 134 159 140 126 132 119 132 125 115 137 122 131 150 118 145 128 123 135 138 126 121 138 120 128 118 146 134 145 149 137 139 126 128 118 148 146 137 128 133 123 132 126 134 138 139 118 137 125 142 135 117 124 127 142 118 145 119 131 123 123 135 134 112 157 122 138 115 125 141 116 105 138 143 146 121 135 103 146 119 146 131 127 140 144 129 138 153 141 130 119 135 145 129 126 135 146 159 134 135 131 163 112 146 147 164 130 113 110 157 146 133 141 148 137 130 128 137 128 143 130 126 142 134 135 129 123 123 136 141 142 148 125 147 156 154 147 157 146 126 131 135 142 143 119 163 138 129 143 117 143 157 146 129 125 134 148 123 134 123 144 141 129 145 158 118 124 114 129 127 144 151 135 140 146 129 137 133 142 142 136 142 153 130 135 123 126 129 139 149 117 130 131 143 132 141 149 125 143 154 144 129 127 124 123 123 151 126 157 134 137 136 128 125 143 125 117 129 135 140 127 132 153 142 149 132 136 137 123 149 108 134 128 141 117 140 118 144 124 137 125 151 112 124 138 129 129 139 139 141 124 144 128 133 124 130 128 136 160 159 140 131 119 152 133 139 133 129 143 132 136 139 137 132 158 150 136 135 120 131 129 110 122 130 140 129 126 150 124 120 134 129 116 126 152 135 140 153 136 136 157 123 113 133 117 143 147 136 132 123 116 147 152 127 161 141 137 134 119 129 122 131 125 142 126 125 134 152 136 118 138 122 126 115 130 135 136 137 129 125 131 130 110 128 130 125 122 136 147 133 129 131 125 130 148 121 126 130 126 114 128 142 141 132 115 139 105 127 154 153 140 139 123 138 150 129 129 131 145 121 115 139 130 104 134 142 124 139 134 125 127 137 145 131 137 131 136 132 131 120 116 134 112 120 132 138 121 140 126 117 154 147 135 123 129 146 120 141 128 130 128 130 131 118 133 137 142 133 138 123 121 125 146 132 131 127 124 133 140 126 163 138 117 117 135 118 140 132 122 128 122 126 125 112 143 135 126 132 105 131 132 119 119 126 144 110 123 119 122 131 133 138 123 142 149 131 141 145 129 121 131 121 143 138 138 126 148 130 119 133 107 130 135 113 157 119 117 130 121 115 145 117 116 138 142 130 127 107 140 124 117 136 137 118 124 125 119 122 136 122 120 121 107 133 118 129 120 132 130 112 125 129 136 131 138 143 108 110 122 141 120 138 138 130 136 132 148 139 137 120 137 125 139 126 127 117 120 135 129 135 128 124 119 129 117 150 138 127 122 113 131 120 123 128 127 126 148 129 134 126 130 149 133 135 102 143 124 135 133 127 112 131 133 148 132 103 128 119 123 130 144 129 125 126 130 122 144 138 137 133 116 117 133 120 113 121 140 129 149 139 128 120 152 128 121 117 116 139 130 128 103 120 121 134 140 137 108 114 126 132 152 121 136 104 127 111 104 125 128 149 132 144 132 125 117 116 124 121 148 148 143 112 141 133 129 122 110 124 136 125 134 129 129 125 146 125 128 148 140 149 130 118 113 131 124 130 134 120 153 129 124 119 127 117 132 128 144 129 125 153 122 130 127 113 133 131 124 123 132 130 131 131 136 128 129 127 142 132 144 140 118 131 130 132 121 136 144 143 127 134 122 129 124 132 129 124 111 146 139 120 136 131 136 131 121 109 142 144 141 110 125 115 154 137 139 138 120 119 120 118 112 151 132 132 129 129 128 110 108 153 121 125 134 130 119 123 137 115 126 139 117 139 140 109 138 121 144 129 116 126 127 128 128 123 128 140 121 126 133 139 110 133 112 120 112 124 139 134 151 113 105 131 121 101 135 121 120 124 125 131 129 124 142 135 133 118 131 107 151 134 107 118 112 129 140 124 129 135 134 127 121 124 120 129 128 118 119 116 139 129 132 105 118 129 122 152 131 135 124 114 108 126 141 150 126 128 125 141 115 132 141 143 127 126 128 128 112 131 119 119 102 131 126 118 128 116 137 129 106 115 136 114 135 112 117 132 133 135 141 155 131 134 122 126 139 114 141 127 135 135 122 123 130 137 129 134 109 133 132 135 120 142 124 105 146 126 122 136 122 133 147 140 116 117 134 128 125 129 116 108 104 106 112 113 114 146 146 139 123 121 122 117 111 131 122 144 139 127 135 116 125 141 137 130 120 123 132 134 112 117 120 144 124 140 133 112 126 144 112 125 122 139 119 112 118 129 118 150 118 131 136 125 125 119 134 132 128 127 122 151 135 115 126 141 154 132 141 133 126 141 126 129 130 121 130 142 130 123 116 113 114 145 127 104 133 125 129 105 130 128 141 117 129 123 127 114 127 133 119 119 125 119 121 125 114 122 136 133 118 136 143 125 136 126 129 139 131 111 135 132 140 134 117 128 129 138 128 146 128 123 143 133 124 164 148 120 132 128 119 142 138 138 120 122 145 143 142 136 144 124 121 133 139 134 113 123 130 111 113 126 136 129 127 124 142 142 121 134 108 135 121 139 132 131 126 125 125 135 112 129 141 142 123 145 126 118 120 131 134 114 157 117 130 148 127 131 121 125 112 140 141 126 138 119 122 142 135 123 125 123 118 123 126 131 101 136 127 110 117 133 134 128 150 134 125 131 141 131 128 139 129 113 124 111 124 123 127 123 117 128 125 140 123 131 139 118 138 121 150 135 134 121 126 101 128 130 126 131 117 136 136 161 128 113 129 121 130 120 130 132 137 146 119 135 125 133 137 159 122 142 156 124 121 116 129 125 131 121 128 137 128 139 113 138 137 119 117 116 142 141 141 119 105 132 130 111 135 145 129 125 114 126 121 111 127 140 126 134 108 157 150 125 145 151 123 123 133 113 127 125 135 130 137 125 126 111 131 123 129 137 134 121 113 142 148 113 121 128 131 123 140 119 129 124 111 133 126 114 117 121 133 135 119 129 131 142 138 124 133 157 130 120 102 118 141 120 151 132 121 128 113 125 142 117 142 135 111 128 124 132 120 137 122 133 101 136 128 117 106 118 134 117 130 130 125 139 119 125 113 123 129 123 130 124 129 139 114 109 135 125 124 122 106 147 125 139 121 100 135 111 122 112 123 131 120 132 142 139 126 120 132 115 133 116 119 141 101 133 113 117 125 113 120 126 101 127 139 112 123 129 118 142 118 117 123 140 146 132 115 115 139 108 110 150 135 127 141 122 111 128 114 108 127 121 124 115 139 131 124 133 124 108 112 122 122 123 124 113 137 116 127 124 109 124 134 138 108 145 131 136 135 119 114 148 138 108 126 121 112 109 125 116 127 103 121 136 125 94 141 132 120 119 104 121 122 112 120 126 120 125 132 138 127 126 137 104 116 156 149 117 141 112 128 125 133 116 133 109 114 127 114 116 116 129 141 112 137 120 112 123 148 117 118 129 129 138 114 128 131 143 118 136 141 131 135 129 123 119 114 131 130 133 151 111 124 152 138 117 111 115 119 120 134 133 133 138 111 126 124 119 126 149 132 133 125 131 146</counts>
			</dataPoints>
		</scan>
	</xrdMeasurement>
</xrdMeasurements>