File: data/XRD/XG-Sauerstoff/XG-800/W6823-1B_XG_Sauerstoff_800.xrdml
<xrdMeasurements xmlns="http://www.xrdml.com/XRDMeasurement/2.1" xmlns:xsi="http://www.w3.org/2001/XMLSchema-instance" xsi:schemaLocation="http://www.xrdml.com/XRDMeasurement/2.1 http://www.xrdml.com/XRDMeasurement/2.1/XRDMeasurement.xsd" status="Completed">
	<comment>
		<entry>Configuration=Factory configuration, Owner=User-1, Creation date=7/8/2013 4:01:53 PM</entry>
		<entry>Goniometer=PW3050/65 (Theta/2Theta); Minimum step size 2Theta:0.0001; Minimum step size Omega:0.0001</entry>
		<entry>Sample stage=MRD Cradle; Minimum step size Phi:0.01; Minimum step size Chi:0.01; Minimum step size X:0.01; Minimum step size Y:0.01; Minimum step size Z:0.001</entry>
		<entry>Diffractometer system=XPERT-PRO</entry>
		<entry>Measurement program=C:\PANalytical\Data Collector\Programs\Jorrit\2thom\_absolute_2th-om_10-130deg_PIXscan_56min.xrdmp, Identifier={15BCCF57-2807-42BD-B5B9-ECC0B3DC9284}</entry>
		<entry>Batch program=C:\PANalytical\Data Collector\Programs\SimonL\batch4x_2thom_10-130°_z9.1_x0,10,20,30_y0_57min.xrdmp, Identifier={EED9823A-2BEB-424C-9252-345C4EF2834A}</entry>
	</comment>
	<sample type="To be analyzed">
		<id></id>
		<name></name>
		<preparedBy></preparedBy>
	</sample>
	<xrdMeasurement measurementType="Scan" status="Completed" sampleMode="Reflection">
		<comment>
			<entry>_absolute_2th-om_10-130deg_PIXscan_56min</entry>
			<entry>PHD Lower Level = 4.83 (keV), PHD Upper Level = 11.27 (keV)</entry>
		</comment>
		<usedWavelength intended="K-Alpha 1">
			<kAlpha1 unit="Angstrom">1.5405980</kAlpha1>
			<kAlpha2 unit="Angstrom">1.5444260</kAlpha2>
			<kBeta unit="Angstrom">1.3922500</kBeta>
			<ratioKAlpha2KAlpha1>0.5000</ratioKAlpha2KAlpha1>
		</usedWavelength>
		<incidentBeamPath>
			<radius unit="mm">320.00</radius>
			<xRayTube id="1010048" name="Empyrean Cu LFF HR (9430 033 7310x) DK442154">
				<tension unit="kV">40.0</tension>
				<current unit="mA">40.0</current>
				<anodeMaterial>Cu</anodeMaterial>
				<focus type="Line">
					<length unit="mm">12.0</length>
					<width unit="mm">0.4</width>
					<takeOffAngle unit="deg">4.2</takeOffAngle>
				</focus>
			</xRayTube>
			<xRayMirror id="27010001" name="Inc. Beam Cu W/Si (parabolic MRD)" hybrid="false">
				<crystal type="Graded" shape="Parabolic">W/Si</crystal>
				<acceptanceAngle unit="deg">0.800</acceptanceAngle>
				<length unit="mm">60.0</length>
			</xRayMirror>
			<sollerSlit id="21010002" name="Soller slits 0.04 rad.">
				<opening unit="rad">0.0400</opening>
			</sollerSlit>
			<mask id="22030007" name="Fixed mask 2 mm">
				<distanceToSample unit="mm">220.00</distanceToSample>
				<width unit="mm">2.00</width>
			</mask>
			<divergenceSlit id="22010007" name="Fixed slit 1/8°" xsi:type="fixedDivergenceSlitType">
				<distanceToSample unit="mm">220.00</distanceToSample>
				<height unit="mm">0.19</height>
			</divergenceSlit>
		</incidentBeamPath>
		<diffractedBeamPath>
			<radius unit="mm">320.00</radius>
			<sollerSlit id="21010002" name="Soller slits 0.04 rad.">
				<opening unit="rad">0.0400</opening>
			</sollerSlit>
			<receivingSlit id="22010001" name="Fixed slit 4°">
				<height unit="mm">5.88</height>
			</receivingSlit>
			<detector id="7010017" name="PIXcel3D 1x1 detector" xsi:type="areaDetectorType">
				<phd unit="%">
					<lowerLevel>30.0</lowerLevel>
					<upperLevel>70.0</upperLevel>
				</phd>
				<mode>Scanning</mode>
				<activeChannelsEquatorial>255</activeChannelsEquatorial>
				<activeChannelsAxial>255</activeChannelsAxial>
				<pitchEquatorial unit="mm">0.05500</pitchEquatorial>
				<pitchAxial unit="mm">0.05500</pitchAxial>
				<readOutPeriod unit="seconds">0.135</readOutPeriod>
			</detector>
		</diffractedBeamPath>
		<scan appendNumber="0" mode="Continuous" scanAxis="2Theta-Omega" status="Completed">
			<header>
				<startTimeStamp>2024-09-30T14:04:49+02:00</startTimeStamp>
				<endTimeStamp>2024-09-30T15:00:55+02:00</endTimeStamp>
				<author>
					<name>PRO-MRD</name>
				</author>
				<source>
					<applicationSoftware version="6.1b">Data Collector</applicationSoftware>
					<instrumentControlSoftware version="7.0E 20130304">XPERT-PRO</instrumentControlSoftware>
					<instrumentID>0000000011142674</instrumentID>
				</source>
			</header>
			<dataPoints>
				<positions axis="2Theta" unit="deg">
					<startPosition>9.99826193</startPosition>
					<endPosition>129.99755682</endPosition>
				</positions>
				<positions axis="Omega" unit="deg">
					<startPosition>4.99913096</startPosition>
					<endPosition>64.99877841</endPosition>
				</positions>
				<positions axis="Phi" unit="deg">
					<commonPosition>0.00</commonPosition>
				</positions>
				<positions axis="Chi" unit="deg">
					<commonPosition>0.00</commonPosition>
				</positions>
				<positions axis="X" unit="mm">
					<commonPosition>20.00</commonPosition>
				</positions>
				<positions axis="Y" unit="mm">
					<commonPosition>0.00</commonPosition>
				</positions>
				<positions axis="Z" unit="mm">
					<commonPosition>9.100</commonPosition>
				</positions>
				<commonCountingTime unit="seconds">32.895</commonCountingTime>
				<counts 181 194 182 205 179 199 192 162 206 203 188 204 216 212 191 188 209 193 185 182 195 205 204 195 208 204 193 196 202 182 193 190 182 174 199 198 166 191 195 201 213 185 196 201 213 202 207 193 220 194 167 206 204 193 203 190 207 209 201 220 193 209 211 228 196 203 201 193 206 199 177 178 205 201 205 184 189 203 194 200 176 184 214 191 212 189 207 186 199 214 188 189 199 194 191 184 223 193 202 146 185 179 209 210 197 181 193 186 171 188 192 198 194 201 175 158 173 200 198 221 194 190 187 205 196 197 186 191 187 173 188 196 185 208 191 196 178 217 200 176 215 170 164 173 184 178 214 191 198 190 202 177 177 183 188 152 187 203 202 200 193 200 189 174 189 205 200 179 211 179 199 205 202 185 179 166 170 186 203 183 173 188 156 220 207 193 187 154 198 177 198 182 192 194 187 171 185 202 188 201 191 193 200 172 186 183 182 162 163 183 169 188 226 186 187 206 178 166 194 186 197 214 186 218 192 195 207 171 191 179 190 174 190 179 159 165 169 177 195 186 188 166 185 172 188 196 194 183 190 187 187 184 169 179 160 188 178 167 192 163 187 193 197 198 183 167 191 158 183 159 188 171 175 144 182 184 168 172 159 151 188 180 202 168 156 180 175 173 190 197 169 189 169 168 170 154 166 182 167 173 161 171 162 161 204 163 165 178 182 164 170 179 174 153 177 203 156 168 181 177 168 174 184 176 192 179 160 170 167 175 178 156 167 190 213 189 200 165 205 174 186 185 181 153 153 145 167 152 176 160 161 193 189 175 168 172 180 165 161 157 159 153 173 175 196 187 158 164 191 191 190 153 155 165 159 164 168 172 179 166 203 188 174 163 172 172 166 160 182 179 176 153 185 162 186 166 136 156 164 160 184 179 167 158 167 148 167 170 149 169 164 173 151 147 176 192 175 172 176 175 154 151 156 148 174 182 172 151 158 159 171 157 192 167 157 150 166 170 171 148 158 157 162 174 181 161 177 160 166 162 187 136 159 191 130 146 148 185 185 160 177 195 150 161 158 163 160 182 172 167 173 155 145 137 163 165 181 163 164 149 151 147 164 175 153 150 159 142 153 159 149 148 164 168 159 172 156 172 160 151 163 176 168 181 178 153 160 147 145 152 155 156 158 170 133 164 159 163 195 160 163 172 169 170 185 164 160 149 137 147 150 173 168 176 163 177 174 166 149 156 138 158 166 171 179 156 147 161 164 127 153 186 178 173 151 141 131 176 153 153 158 156 158 158 172 153 163 166 164 156 165 150 159 140 143 156 178 166 160 173 149 171 162 138 152 164 168 181 177 155 179 169 149 160 156 155 151 162 160 155 163 168 166 127 145 162 140 141 167 146 172 169 153 146 168 181 168 163 154 166 142 172 143 155 140 142 146 150 151 142 168 152 144 158 146 149 154 166 142 163 159 141 164 143 150 148 151 165 159 153 142 147 144 164 175 139 154 123 154 147 151 161 175 139 158 130 177 157 133 143 135 153 142 140 152 152 139 145 146 154 165 158 128 158 151 159 141 155 157 130 146 160 132 138 140 153 146 163 143 148 146 125 155 148 158 150 145 148 148 159 168 165 165 153 160 157 136 159 179 129 153 152 168 161 138 127 151 164 129 161 170 150 143 176 155 148 163 149 139 150 132 148 136 163 147 148 162 135 148 147 136 144 138 172 146 130 168 156 152 142 172 157 145 146 150 165 157 190 142 136 133 151 150 157 159 141 151 136 149 149 140 144 143 160 142 143 157 165 169 157 168 157 166 139 127 165 172 158 172 132 116 149 127 148 150 146 148 153 146 160 160 126 138 159 133 146 135 145 156 165 160 149 162 163 150 151 141 146 154 140 127 161 153 142 153 154 156 179 156 150 152 139 144 159 169 150 149 164 158 135 147 154 137 144 128 154 175 139 147 153 157 140 149 152 140 147 158 157 155 135 149 158 145 154 171 143 138 153 156 155 140 171 139 159 141 156 155 134 186 147 150 146 152 143 153 141 177 177 199 138 161 146 146 164 153 140 156 155 168 163 156 150 169 138 171 162 132 156 169 127 154 156 144 157 145 152 179 167 151 173 154 171 167 159 145 149 183 155 165 145 155 158 151 157 144 148 146 171 155 134 167 178 176 134 163 165 179 161 146 160 150 137 144 143 164 152 147 178 169 164 195 153 144 141 146 149 162 139 146 157 155 163 136 154 160 163 174 150 146 151 173 128 152 151 174 145 167 141 161 157 166 157 161 169 161 166 143 140 165 147 171 149 147 138 164 142 152 156 148 154 151 155 187 159 153 164 145 169 140 133 147 147 170 145 178 165 146 168 158 162 161 168 131 153 162 153 139 128 144 154 162 157 160 145 145 143 154 142 148 145 152 179 152 148 164 154 166 149 153 150 155 149 172 184 135 165 142 176 152 159 154 136 174 140 161 157 162 155 162 163 140 181 171 146 155 143 157 161 181 171 162 164 157 169 151 171 135 165 161 158 157 153 173 154 144 153 166 149 154 173 175 171 155 149 155 141 167 168 147 143 149 156 159 144 151 150 179 169 149 151 161 144 152 163 165 167 147 157 152 152 186 168 164 176 142 167 162 155 169 144 164 166 159 153 128 162 169 159 153 149 157 172 166 157 169 162 168 171 182 154 180 149 157 154 160 157 149 179 165 166 166 188 181 165 157 157 183 155 160 179 151 163 172 138 177 153 146 153 163 175 168 158 175 144 147 158 162 162 144 165 149 165 151 156 171 153 139 167 142 173 161 145 160 182 160 163 148 150 158 162 143 178 141 160 174 167 157 166 143 212 146 182 165 178 178 164 176 154 185 153 168 154 174 174 187 169 202 164 172 175 149 161 178 181 186 144 152 159 163 158 176 178 165 167 171 189 143 159 172 148 159 145 142 178 151 162 153 170 169 183 168 171 164 161 144 145 140 167 184 172 173 187 171 148 140 174 147 160 146 168 186 139 175 177 159 164 143 155 159 132 160 139 140 182 172 165 153 167 177 158 159 179 172 194 190 168 155 154 164 156 166 163 182 147 176 157 146 163 153 169 151 144 159 152 172 163 160 139 164 177 158 172 156 148 170 140 158 160 153 156 159 169 188 174 171 165 181 179 179 185 161 142 164 183 164 126 149 160 132 131 154 171 171 152 159 155 153 158 159 173 148 158 143 153 159 158 149 160 154 153 173 164 158 158 161 165 161 169 163 159 157 156 145 165 168 135 173 152 172 157 195 166 162 162 168 145 156 125 158 160 173 150 169 147 168 159 158 154 169 162 164 161 166 133 151 151 161 165 161 160 161 155 152 156 153 155 165 165 155 170 149 161 151 149 152 144 164 164 179 162 147 149 168 153 176 154 170 180 151 168 168 149 169 167 150 143 178 171 176 158 156 134 146 175 143 147 146 149 159 164 148 160 160 164 155 156 149 141 159 150 160 144 157 155 127 153 153 163 150 174 173 135 148 141 170 135 169 172 138 153 147 150 156 141 144 170 139 153 165 151 151 145 149 129 162 168 139 169 159 163 169 155 143 159 152 139 153 149 154 154 137 145 154 142 154 154 164 149 151 166 158 151 152 138 150 152 150 152 112 149 159 179 151 156 143 158 164 157 158 151 152 147 145 165 169 158 148 154 143 150 159 141 144 163 160 156 149 171 185 145 137 158 144 138 158 164 130 157 152 144 125 129 133 154 147 134 154 142 145 155 162 148 150 157 144 144 136 146 164 153 123 133 161 156 151 145 130 155 153 153 144 138 150 148 150 143 140 160 150 163 135 139 153 137 144 152 144 148 138 158 148 145 138 133 155 153 153 156 166 119 132 142 142 161 141 146 155 139 143 139 141 141 146 148 159 143 151 155 161 142 137 151 152 155 146 151 138 108 147 134 148 149 135 141 140 147 132 133 141 113 131 148 156 154 156 153 141 139 149 150 141 160 136 140 127 126 149 134 118 134 141 155 127 168 164 144 141 131 155 152 137 155 136 126 125 127 144 146 139 127 141 162 140 124 141 133 138 139 151 144 119 131 147 145 173 137 135 128 141 149 132 118 138 140 134 134 131 135 140 145 129 133 138 123 133 127 140 141 135 137 138 135 156 128 152 122 127 165 144 130 120 134 134 160 142 123 108 125 132 126 147 142 129 128 135 138 138 136 141 136 119 158 133 150 134 133 125 125 137 135 143 139 124 155 137 138 157 125 133 128 135 141 142 134 124 117 132 124 145 124 130 121 119 127 137 132 127 143 130 147 140 131 145 139 125 132 128 139 120 102 142 133 137 129 115 139 125 139 139 152 139 115 142 125 109 115 143 140 131 148 131 125 145 121 124 138 125 113 138 148 110 122 131 130 112 143 149 117 138 124 152 137 119 139 123 143 117 122 137 111 126 142 142 129 134 122 144 108 125 132 129 141 135 120 120 142 150 125 126 130 108 111 138 115 111 115 126 129 121 145 109 138 126 129 140 120 122 132 125 126 163 128 127 137 115 130 127 120 121 132 116 116 134 132 113 123 128 138 91 108 136 111 106 126 116 118 132 129 129 134 138 129 122 126 103 129 127 121 115 129 130 102 136 131 135 136 123 115 121 119 124 125 115 118 126 113 139 112 132 139 145 116 116 120 116 109 128 124 137 134 132 131 109 127 112 115 127 130 127 139 116 115 112 140 127 119 113 124 133 116 118 135 125 134 117 115 129 120 128 129 110 106 129 130 121 132 124 113 141 131 132 112 124 128 128 118 125 133 117 125 151 122 122 111 105 117 113 126 118 122 138 123 106 124 124 121 117 138 121 120 136 124 139 124 113 146 94 114 137 123 119 133 135 127 124 111 121 126 116 130 127 117 116 119 116 144 120 125 124 135 117 116 79 108 138 148 109 116 138 109 102 123 130 119 113 110 114 144 119 119 117 113 105 116 119 130 140 128 124 137 121 128 132 121 110 130 121 115 113 118 128 109 112 135 114 98 117 102 104 129 140 134 135 124 113 127 127 122 123 116 107 123 109 119 103 120 108 98 114 134 124 120 145 107 126 141 109 124 120 101 118 137 138 106 144 114 113 127 113 115 125 128 113 150 113 112 107 110 118 119 113 130 109 141 126 121 100 107 87 116 120 133 100 120 141 104 109 110 121 120 113 105 128 117 116 120 130 122 111 114 116 132 122 112 124 123 136 134 113 111 120 132 126 118 130 119 106 102 125 121 106 119 121 100 111 125 107 114 130 121 117 146 118 120 113 120 138 116 126 109 109 125 105 132 112 120 117 127 122 113 123 111 96 96 116 116 107 121 110 128 114 108 116 131 113 110 106 114 101 123 113 124 130 118 109 113 129 124 114 141 139 113 103 132 117 105 123 121 121 114 115 120 122 111 116 129 114 128 120 124 111 128 117 103 96 120 109 126 107 109 127 93 103 109 114 119 110 101 115 113 128 122 125 103 106 119 119 118 109 107 114 125 127 123 107 109 110 107 110 121 102 110 130 108 114 114 134 135 112 113 120 111 104 114 109 124 119 123 119 125 110 116 116 121 115 114 111 116 120 133 131 106 131 129 120 108 118 136 122 100 123 119 110 110 131 133 111 114 106 120 115 103 123 128 126 96 112 109 110 105 108 138 120 114 127 100 138 112 105 130 125 119 149 129 131 97 112 114 116 104 96 106 113 107 112 106 105 114 133 135 108 133 103 121 117 110 122 118 123 101 110 115 122 114 116 123 118 128 127 102 115 105 111 129 125 99 114 120 114 125 113 108 111 114 116 108 99 105 119 87 120 137 126 118 128 113 128 118 128 107 94 111 120 121 108 123 113 118 124 115 111 119 112 125 124 109 108 131 121 107 115 125 112 125 112 106 129 104 120 102 107 134 121 139 125 113 129 122 115 113 121 114 116 122 122 117 113 101 107 94 135 113 129 107 113 98 114 127 114 108 120 127 115 119 123 100 114 121 115 132 99 111 129 126 135 115 115 138 135 117 101 117 118 125 107 106 128 137 106 124 102 116 115 102 119 101 113 121 124 123 122 114 102 133 116 107 105 116 107 101 87 100 124 125 126 111 87 135 116 109 123 122 125 104 105 108 109 115 120 92 112 119 120 106 111 109 122 92 118 142 128 123 112 118 117 103 129 109 115 111 118 117 134 131 93 118 107 125 128 117 130 107 125 128 118 113 126 115 119 114 121 107 107 119 100 128 115 119 117 122 101 133 118 108 128 129 117 105 117 97 116 126 118 126 120 106 108 124 98 118 112 108 96 129 126 120 112 124 103 115 118 120 121 95 94 115 115 127 111 107 116 116 120 106 93 124 102 133 118 108 108 119 106 121 103 114 90 121 138 122 112 113 109 98 107 119 115 110 115 107 108 104 118 122 110 100 123 120 120 109 96 120 121 116 128 114 124 127 112 117 102 97 127 117 118 111 104 117 105 109 94 120 117 120 120 103 123 90 119 144 100 103 127 127 88 107 120 108 114 92 139 114 109 123 104 121 132 108 130 117 109 123 107 128 99 113 115 116 115 121 124 107 107 143 96 140 114 107 135 121 121 110 119 140 97 107 108 127 122 136 116 106 107 135 117 96 115 95 128 114 126 103 116 116 97 97 116 124 122 133 108 97 116 113 106 111 112 118 103 96 131 121 114 135 93 111 130 105 94 119 106 122 92 106 119 117 106 109 117 105 121 114 121 116 117 121 104 124 111 99 106 101 123 122 158 115 106 123 125 125 110 118 108 118 103 121 135 107 123 110 104 124 126 107 124 114 110 129 116 110 100 107 110 107 100 103 113 116 134 107 126 114 110 110 125 131 122 112 108 105 134 96 136 108 112 133 103 132 105 129 115 134 113 121 117 122 135 114 120 111 116 117 133 109 102 118 110 103 110 116 110 103 118 102 119 116 112 117 127 116 120 116 108 122 114 115 107 123 105 116 97 139 109 122 126 129 119 105 109 110 137 110 131 116 122 126 115 114 128 112 122 122 122 102 114 122 103 114 124 116 112 120 118 104 119 119 116 124 144 117 96 112 123 131 130 107 120 118 118 83 112 128 107 112 134 114 114 108 115 130 126 118 117 108 127 113 121 111 116 121 115 105 110 116 104 129 107 109 110 119 109 115 104 111 121 103 105 137 110 127 129 122 116 123 125 113 111 125 112 120 90 109 124 124 129 136 124 131 123 119 127 117 118 133 100 101 107 119 145 102 129 99 117 116 135 119 115 136 122 112 118 119 117 130 125 142 124 119 125 136 120 124 113 125 121 115 122 129 111 126 119 123 100 124 117 113 117 124 110 113 145 123 118 112 129 118 116 127 120 113 115 95 116 119 132 99 123 124 95 130 119 117 129 134 105 123 125 139 119 131 115 143 113 141 113 136 114 118 117 133 112 123 112 114 112 101 113 112 121 116 132 126 119 122 117 111 135 123 111 111 117 124 94 115 114 136 121 134 123 133 136 123 130 120 127 129 122 109 118 110 105 135 114 136 130 93 119 110 108 115 115 121 114 139 109 111 129 119 140 115 121 126 125 118 128 112 125 120 121 124 123 133 115 114 116 111 102 115 133 128 121 102 142 147 128 129 118 132 141 134 142 148 132 135 129 135 123 130 117 107 120 142 121 141 134 123 129 131 126 119 129 132 129 130 118 131 125 132 115 140 131 129 141 120 117 125 125 126 120 140 134 130 108 132 107 108 121 143 116 124 119 131 109 128 128 120 135 113 115 145 124 131 117 118 134 120 128 145 127 123 132 142 124 121 130 135 131 117 145 140 126 110 152 137 137 143 140 127 156 150 129 137 121 136 155 123 179 156 156 157 173 125 143 153 138 183 176 160 170 183 187 188 175 202 185 211 192 175 184 214 215 197 211 197 194 181 215 215 201 207 210 210 215 173 198 208 183 197 167 187 156 155 159 207 183 177 164 160 144 138 153 154 145 156 132 150 138 137 138 137 134 146 134 118 111 147 145 130 144 120 144 124 135 126 110 118 129 136 144 117 123 140 126 130 149 111 139 156 113 119 118 132 113 154 142 135 118 126 122 114 135 121 129 123 137 118 116 118 121 109 114 130 116 119 117 112 108 130 128 101 113 131 116 122 139 141 130 109 126 132 123 123 137 116 109 131 130 129 106 118 114 110 100 134 127 100 125 134 135 116 127 118 134 102 115 116 135 124 144 125 107 127 101 123 130 123 139 113 119 126 130 104 143 134 135 111 115 90 127 129 119 105 126 125 127 103 129 121 124 131 128 103 139 134 115 108 109 100 105 115 132 118 116 119 115 147 107 132 123 119 123 113 111 128 112 126 129 100 111 121 99 114 124 136 147 126 105 109 119 135 131 122 127 129 114 119 124 126 117 120 122 130 113 123 109 112 134 119 114 117 111 141 120 112 138 113 113 110 121 108 119 123 107 134 130 125 131 125 121 123 121 131 123 129 104 125 135 144 111 113 126 126 127 126 122 127 108 121 95 128 114 129 109 113 123 109 147 93 122 128 123 111 138 119 136 143 134 120 105 124 118 123 114 104 125 122 115 122 111 115 132 110 97 117 122 117 140 101 119 129 130 122 107 134 113 98 142 107 139 117 134 134 119 139 128 105 114 128 126 99 118 127 107 127 123 137 133 106 106 120 109 122 108 110 119 103 124 120 129 116 104 135 141 110 112 138 113 134 129 119 125 103 117 119 113 124 116 123 126 135 129 115 107 122 107 112 113 126 126 114 121 124 122 114 127 128 107 125 144 133 111 127 108 131 125 123 135 143 124 115 98 111 122 104 127 117 107 132 119 118 139 122 100 127 142 130 139 121 126 135 106 111 125 113 123 112 124 119 134 117 129 133 119 130 127 121 109 109 129 109 120 121 128 134 115 131 131 103 129 122 117 130 105 105 137 123 110 116 117 123 110 116 117 123 107 120 131 132 120 131 116 110 123 149 110 110 127 109 122 120 143 126 123 124 128 128 111 114 116 132 101 119 114 126 125 116 116 118 123 108 135 102 121 127 135 132 131 125 121 113 124 108 108 130 118 130 106 110 113 129 129 145 121 111 116 144 98 136 126 108 115 134 133 126 126 137 95 115 134 96 114 142 113 119 126 111 132 107 117 116 117 123 110 121 132 128 127 138 138 125 127 117 129 117 120 121 133 116 131 106 115 141 129 124 127 128 127 110 121 128 143 121 102 133 119 125 106 103 117 126 128 137 114 135 125 114 124 116 151 125 133 129 132 137 124 132 111 102 122 124 119 118 103 113 105 126 111 109 126 126 132 123 124 117 126 108 120 108 118 125 136 136 127 136 149 134 112 127 121 126 119 131 117 128 105 128 134 137 124 125 125 138 130 110 133 115 104 128 133 144 125 121 119 150 119 120 128 141 122 136 102 125 119 123 117 131 127 117 119 154 111 117 127 145 146 144 121 123 128 119 120 134 119 135 112 124 145 115 112 121 123 120 111 120 114 137 125 130 131 106 147 134 133 123 128 142 108 131 114 105 108 130 101 139 119 109 133 148 123 123 121 113 143 130 114 111 137 119 138 125 137 108 111 137 101 122 110 125 127 130 119 107 121 136 136 122 127 122 138 119 126 117 105 112 128 114 134 105 126 128 122 103 119 128 108 113 127 115 128 133 119 110 131 124 123 126 141 101 125 110 113 141 123 123 123 123 116 133 101 123 115 129 128 111 122 122 129 117 135 122 114 120 111 131 120 112 115 125 134 117 117 109 116 114 110 99 122 116 132 116 119 131 126 119 114 118 135 113 119 111 121 144 124 114 119 97 122 128 121 131 115 113 125 114 113 140 129 139 127 134 141 126 111 129 120 109 122 109 121 116 122 112 120 132 123 117 118 131 126 98 124 124 140 143 121 135 112 129 110 108 117 142 121 109 127 125 115 117 117 119 120 124 113 134 111 126 124 117 122 121 139 123 127 120 100 126 120 120 124 124 106 121 112 123 112 113 121 124 114 126 133 113 126 120 129 122 109 125 138 112 142 124 132 120 105 137 131 130 131 129 127 147 137 119 124 121 114 115 115 120 117 119 129 114 127 117 102 146 119 100 120 121 119 127 113 124 124 102 120 131 123 111 106 125 118 111 139 112 128 132 131 114 134 123 123 91 121 108 126 102 127 100 135 130 115 128 119 128 128 121 139 127 125 153 127 112 120 141 133 105 131 128 119 115 124 128 123 119 129 121 127 129 112 135 131 112 117 135 121 125 108 134 112 112 108 119 114 124 113 125 114 121 136 106 119 122 106 120 129 123 124 110 136 122 128 117 125 138 118 126 120 120 121 127 134 130 127 131 100 120 135 123 120 131 119 104 118 137 120 120 125 110 123 131 130 112 103 125 141 121 115 114 108 121 136 113 135 113 123 117 118 106 131 111 115 127 131 120 111 127 115 101 119 114 108 107 138 112 139 121 116 120 113 143 111 113 131 109 135 125 121 112 132 123 128 117 91 112 124 128 134 133 118 137 93 125 137 120 121 125 104 126 115 109 139 106 101 107 108 132 116 102 141 104 128 123 144 122 114 123 119 119 117 119 110 111 133 124 111 120 110 129 111 120 115 113 142 115 124 128 122 119 130 126 117 133 112 112 109 120 121 121 128 127 112 103 151 115 111 115 126 119 119 132 119 118 127 121 121 105 155 112 107 118 109 95 112 132 116 105 117 113 124 136 121 99 132 118 124 115 118 121 117 111 126 119 118 126 136 116 133 114 117 99 123 106 132 110 116 123 132 126 103 135 123 129 128 134 136 123 116 127 120 127 111 120 117 122 103 118 111 108 116 114 130 120 95 108 116 121 118 127 128 118 119 117 115 116 126 132 125 126 119 121 121 119 134 129 94 125 129 124 125 112 138 124 140 116 130 130 133 139 104 120 125 101 117 112 135 123 137 117 133 107 132 124 114 124 128 100 136 109 143 140 124 116 109 119 128 136 115 112 117 109 123 138 124 124 119 101 116 103 103 119 120 124 120 110 99 128 114 136 149 127 123 121 138 126 121 117 122 121 124 124 129 126 109 119 130 124 112 132 116 113 123 114 99 143 128 135 123 123 133 119 133 126 118 122 124 136 143 110 114 125 109 122 100 130 133 136 120 107 123 112 132 129 109 114 119 129 126 110 138 140 137 153 115 112 113 117 121 133 128 124 115 111 133 131 121 121 122 115 134 139 123 121 127 126 126 122 120 120 136 104 118 142 137 111 148 134 139 122 130 118 120 103 126 113 118 123 104 125 118 121 119 118 112 125 138 131 106 124 134 131 131 118 126 114 114 125 135 108 108 102 137 144 132 128 120 117 126 123 134 124 128 130 129 108 123 111 112 108 95 120 124 148 114 134 129 147 135 118 125 142 139 118 143 109 132 121 138 133 115 130 127 135 126 130 122 129 130 109 143 123 122 121 138 136 132 125 131 129 143 121 130 131 123 140 128 106 129 127 135 121 131 105 126 129 148 109 144 126 117 114 128 106 101 123 116 117 162 132 146 130 118 123 123 129 119 142 126 129 134 132 105 118 106 128 117 139 137 126 131 126 117 130 132 132 140 117 117 123 131 127 139 123 120 131 128 134 128 161 96 122 121 113 136 117 112 103 108 110 102 124 118 136 141 119 134 142 135 113 123 149 129 117 133 124 114 109 139 149 136 128 114 123 142 93 125 126 153 122 126 117 135 127 149 105 148 124 126 122 135 127 138 130 120 138 131 121 144 120 136 124 144 141 122 128 135 117 124 108 134 129 128 146 133 115 121 135 126 127 125 154 152 129 118 120 124 137 108 119 128 123 117 115 128 131 138 122 141 135 129 124 118 137 108 130 138 117 129 122 116 133 131 137 131 135 133 123 116 125 131 152 122 124 134 116 117 111 130 146 143 121 105 124 123 132 150 111 118 140 111 123 120 114 124 145 139 120 155 140 129 164 129 131 153 113 133 132 127 125 135 124 123 130 130 128 115 111 119 131 129 133 116 154 104 143 145 123 127 109 138 128 113 147 125 123 120 132 123 137 120 123 116 125 132 133 125 127 137 121 113 126 109 138 140 120 125 117 118 128 124 107 138 144 123 143 133 114 125 129 140 126 129 142 123 126 137 126 132 126 128 125 128 134 120 114 120 119 130 129 114 146 126 133 135 124 127 120 126 122 126 119 141 120 133 122 122 126 129 100 119 119 130 155 141 118 127 127 133 131 134 137 154 130 96 116 135 132 140 142 132 126 138 125 138 122 117 157 122 122 132 129 128 134 138 137 125 143 110 119 141 119 118 144 122 138 137 119 123 151 127 122 113 131 153 123 128 110 137 121 129 128 128 115 119 132 156 133 146 133 122 121 140 112 126 153 120 134 135 149 137 134 160 148 141 131 132 135 128 118 127 131 143 137 122 117 143 124 121 112 144 120 115 152 128 133 131 133 144 126 140 128 141 140 130 132 136 115 132 157 129 132 148 114 119 142 113 123 139 151 156 145 128 119 141 137 117 126 118 128 141 123 120 139 158 136 139 115 144 147 135 143 134 130 156 119 145 142 142 146 149 140 128 152 137 127 123 141 135 128 127 124 157 149 117 133 128 140 130 126 159 123 144 143 147 132 120 151 134 128 126 149 138 146 154 134 145 118 134 137 154 116 133 149 137 143 140 127 135 132 127 153 131 133 131 145 133 103 124 146 138 125 137 143 151 114 143 120 141 122 136 120 134 138 135 143 137 136 121 144 127 117 130 136 122 124 137 146 140 137 141 143 125 156 112 120 128 134 136 117 136 124 138 157 143 115 117 132 143 127 131 131 141 170 141 109 127 146 129 129 139 131 121 112 123 128 133 116 127 136 144 131 125 124 135 139 116 117 134 129 139 137 120 157 127 119 127 141 123 125 124 112 118 119 131 128 130 132 130 137 121 129 120 147 119 119 180 137 127 120 145 133 120 115 119 133 108 139 132 127 111 145 146 134 113 142 124 131 121 140 130 124 124 151 149 126 133 112 147 128 129 107 131 123 128 134 107 132 133 148 122 121 146 138 126 129 152 126 120 147 117 147 139 125 136 136 145 130 139 123 115 155 123 112 143 119 132 140 125 116 121 124 115 136 132 123 149 139 109 114 141 142 162 129 117 136 126 131 117 132 130 137 121 136 130 131 126 141 123 151 138 144 123 119 159 122 134 145 149 114 131 134 130 137 143 114 135 141 125 134 147 120 155 131 114 127 115 128 128 125 130 139 126 142 132 118 111 107 126 117 137 150 125 119 148 130 155 126 136 145 134 148 118 137 135 127 126 127 120 139 127 132 146 111 129 135 146 118 125 124 127 145 117 134 138 126 140 138 128 129 133 127 131 124 127 114 128 134 157 119 131 143 133 146 129 124 136 126 157 138 133 137 130 134 121 110 141 119 125 153 135 148 129 138 130 140 117 145 121 123 125 113 136 130 130 125 120 116 136 116 140 145 136 128 130 128 138 132 138 117 102 148 142 128 146 117 151 151 145 127 111 149 129 126 147 129 124 144 112 130 120 107 131 142 117 124 125 120 134 123 124 148 149 111 135 156 125 142 121 128 139 127 120 127 120 127 133 137 124 124 112 128 133 129 125 131 120 113 132 146 126 120 119 153 163 123 132 118 140 130 142 139 132 154 133 145 134 128 145 110 131 104 132 158 151 117 111 120 129 147 133 136 116 134 128 116 133 145 139 125 110 135 144 132 138 139 127 129 119 142 126 143 141 136 123 133 118 118 125 146 120 142 132 145 134 137 124 151 139 141 133 161 118 123 114 122 121 133 120 127 118 136 131 145 126 145 142 136 135 130 114 118 144 118 139 128 144 127 131 130 124 137 129 126 112 131 119 121 122 138 131 159 121 152 139 124 127 119 141 151 123 122 146 151 129 139 113 133 130 129 118 124 123 123 132 131 111 125 121 137 118 132 136 126 114 145 158 141 130 142 133 128 112 128 138 124 127 144 117 144 123 131 109 126 142 117 144 131 135 120 135 136 121 137 121 123 127 130 130 144 140 152 136 154 150 118 139 138 155 145 118 108 134 123 113 143 123 140 137 115 127 136 142 113 141 144 114 137 148 135 145 139 126 141 120 130 148 132 127 150 142 140 128 133 128 120 118 137 142 150 136 121 125 128 141 132 154 120 144 112 159 118 122 127 137 137 128 128 151 123 143 138 131 136 120 121 152 109 148 120 136 137 142 118 134 119 120 132 128 142 131 122 133 128 153 108 126 129 160 115 127 140 143 145 140 132 133 112 140 130 117 122 115 132 141 132 121 136 116 133 138 152 138 136 125 129 111 131 129 129 109 135 147 120 128 144 122 125 95 143 149 146 149 119 122 118 144 125 126 143 151 144 132 135 136 124 143 105 126 148 134 140 129 130 125 133 121 125 136 144 152 138 146 128 133 128 123 140 122 140 164 138 116 127 121 144 119 123 125 115 123 132 134 150 134 133 116 130 127 130 108 128 117 128 136 138 126 129 122 134 139 128 147 126 132 152 139 140 110 137 127 120 128 139 120 113 136 120 104 153 120 139 130 133 149 136 105 124 136 146 137 142 127 112 125 121 143 134 134 129 139 115 149 128 140 126 125 138 142 140 153 131 132 152 150 134 140 129 127 139 116 127 131 135 136 127 154 146 136 141 138 133 128 139 137 133 136 147 130 134 159 136 140 149 131 131 122 108 152 142 167 128 130 125 146 149 141 140 144 127 125 140 140 137 118 136 145 137 126 134 145 136 153 138 113 125 111 115 122 128 149 148 145 120 153 136 128 143 124 136 108 128 123 134 112 149 169 136 135 136 151 141 132 121 119 143 131 125 138 130 134 143 119 153 123 148 133 120 131 135 131 129 132 143 130 121 138 128 144 128 141 128 131 142 122 152 139 122 151 119 125 120 134 144 123 132 135 127 135 138 126 125 142 132 146 163 132 129 140 142 117 146 116 140 131 159 125 130 116 125 131 150 142 149 130 134 132 128 146 149 113 157 109 127 158 132 149 137 138 145 127 126 137 111 134 133 137 135 121 144 137 112 136 134 143 118 128 147 118 136 135 130 133 137 130 132 129 154 128 137 133 126 119 120 142 134 164 119 109 129 147 120 113 123 128 129 137 138 151 129 128 154 146 124 136 135 124 134 144 143 140 127 119 134 138 129 170 116 136 117 145 109 130 135 136 136 120 122 133 132 114 130 133 147 141 133 137 156 133 116 131 124 115 121 135 130 123 123 134 154 130 120 120 144 129 138 126 138 152 134 129 145 123 139 133 142 142 132 121 131 137 122 125 117 126 152 112 143 145 153 146 144 125 132 154 120 133 151 142 126 127 146 144 122 158 118 116 126 149 138 136 140 120 138 162 125 115 140 149 122 130 121 147 120 146 120 130 153 134 160 138 137 146 121 124 108 121 160 141 138 125 138 141 124 123 139 117 126 138 137 149 136 143 123 126 139 144 133 120 116 140 127 124 128 137 154 146 132 114 110 137 146 122 122 118 130 137 137 137 109 139 131 125 145 118 124 121 139 119 133 140 154 129 133 152 127 145 131 145 148 145 146 131 134 135 146 141 119 123 133 145 144 134 132 132 122 117 136 143 136 139 147 121 129 126 120 140 144 138 124 116 149 145 135 128 143 128 123 155 143 124 144 115 130 135 148 120 131 134 148 113 148 134 153 141 145 137 132 139 123 152 120 137 108 151 136 130 142 139 135 124 132 131 116 114 149 117 124 128 121 144 148 138 134 139 134 148 144 135 130 150 116 129 146 126 120 130 131 109 131 139 121 123 140 124 129 119 143 132 127 139 156 134 126 139 118 121 134 143 129 132 144 133 140 145 133 128 164 102 124 141 123 155 142 133 135 143 131 150 134 131 154 142 143 145 140 146 120 118 124 154 142 141 123 135 120 138 153 146 132 120 130 123 139 115 131 119 125 151 122 141 132 131 134 145 136 136 130 141 151 112 148 133 117 125 149 124 121 140 150 154 136 133 138 140 141 125 132 127 148 135 133 139 130 132 130 123 146 139 138 133 135 120 140 124 124 126 125 127 107 110 130 167 126 144 135 144 125 139 143 117 146 134 151 141 121 156 109 126 138 117 126 134 143 168 133 141 138 116 125 139 138 154 123 139 142 140 133 121 135 157 119 141 151 120 123 126 136 130 131 137 104 124 125 151 141 100 137 138 134 117 126 138 132 137 137 108 150 139 138 140 141 145 114 144 140 115 140 141 119 114 130 163 150 144 120 143 139 132 106 116 149 136 137 139 133 143 147 145 129 137 145 147 142 126 131 126 124 144 133 139 124 129 156 151 144 140 131 149 140 148 149 132 136 143 111 141 150 127 134 144 142 120 129 141 140 129 149 143 130 132 155 153 126 139 119 109 143 136 123 117 151 171 117 134 155 133 158 165 135 135 137 130 148 129 135 135 141 124 144 134 136 140 154 156 135 138 133 117 126 118 151 133 117 153 152 153 164 141 156 128 145 135 145 156 128 136 138 148 133 123 144 158 147 168 131 131 163 154 159 140 137 170 135 152 143 159 153 152 126 156 147 158 134 149 128 144 155 144 145 134 156 167 140 144 156 125 163 148 153 137 142 155 145 157 154 138 135 148 143 160 143 158 137 145 147 117 144 141 165 144 134 170 128 137 128 149 141 160 144 152 143 138 139 145 134 138 133 159 129 125 135 147 120 133 138 159 143 152 155 149 140 135 147 134 148 130 155 137 155 145 139 124 139 128 137 157 111 137 147 134 140 143 111 126 145 149 160 128 133 135 120 138 159 146 129 127 140 127 153 142 136 122 118 147 131 140 127 124 121 131 139 117 123 108 113 131 143 131 130 135 132 123 145 136 169 152 128 136 158 149 148 163 145 122 134 127 129 121 137 133 132 124 113 137 140 153 134 132 132 145 129 149 138 141 116 122 135 120 128 124 117 151 146 135 121 140 138 129 115 127 127 135 135 121 126 122 136 140 152 151 128 122 125 123 123 124 133 144 136 120 126 156 125 154 123 131 136 147 136 118 132 134 120 131 132 130 156 138 130 133 143 142 139 128 131 137 130 120 150 124 115 115 110 140 115 128 139 125 125 123 138 128 148 131 126 119 153 117 140 130 133 117 151 155 142 142 122 146 127 139 166 125 126 111 140 147 110 139 118 122 139 119 126 145 129 108 120 152 127 118 129 128 120 139 111 144 116 123 122 170 115 133 125 143 138 122 139 121 155 116 140 138 141 153 141 132 120 133 136 156 161 137 128 143 141 126 134 131 148 144 139 119 117 129 128 134 116 139 142 133 134 130 112 141 129 133 150 118 127 139 150 148 127 137 132 138 142 141 128 111 129 129 116 137 151 130 140 143 127 112 128 120 137 132 145 157 135 138 131 135 129 133 126 115 130 129 113 127 146 168 139 138 130 128 139 137 142 125 132 142 115 114 119 116 138 170 158 132 158 130 147 142 137 133 110 127 161 119 156 143 125 122 136 141 139 114 124 133 112 142 123 126 121 126 125 138 137 132 138 127 145 126 121 122 138 146 127 143 126 137 130 135 127 148 116 132 128 126 120 137 109 131 123 132 144 134 134 140 142 133 136 156 135 121 152 137 120 121 146 132 140 137 137 124 142 136 147 134 125 126 142 117 124 104 130 126 148 135 127 132 114 139 106 140 151 153 147 162 138 125 139 109 148 134 172 134 141 125 122 143 146 130 143 133 111 136 129 163 132 137 131 130 132 118 130 121 127 119 136 111 129 157 123 96 143 146 137 142 152 119 151 139 137 126 134 142 134 125 139 140 136 140 122 135 141 131 121 123 137 139 137 150 121 138 102 135 140 148 125 143 131 142 147 135 128 135 116 121 124 153 125 122 134 139 119 131 123 138 118 138 119 127 115 131 144 131 131 117 151 137 119 134 138 154 127 143 137 141 116 116 113 132 137 137 158 142 128 154 123 126 135 137 124 136 126 144 133 135 136 162 139 141 111 134 139 149 132 137 138 151 130 151 141 125 131 162 142 129 125 148 129 130 132 155 135 130 125 145 126 123 125 144 127 139 125 131 135 122 133 147 131 152 117 142 137 133 121 145 132 140 122 143 142 156 157 146 123 132 139 124 136 133 147 151 136 130 120 130 124 121 127 122 111 123 160 131 143 136 97 139 138 127 152 133 115 146 148 121 132 141 144 152 141 126 128 128 135 129 135 135 141 143 134 138 115 131 128 147 121 142 133 139 124 145 145 142 104 137 131 149 140 111 161 125 134 135 126 134 141 140 139 135 132 139 124 131 124 103 138 155 137 127 123 125 135 133 127 130 119 129 128 121 137 132 149 133 129 146 122 152 144 117 134 151 132 130 155 136 120 110 142 150 122 145 140 151 120 147 144 152 140 121 148 132 133 129 123 135 136 119 119 137 129 128 129 136 129 139 119 123 138 130 152 152 140 115 126 132 143 137 119 124 144 131 136 137 136 140 125 123 155 131 113 137 141 143 141 143 126 144 130 149 142 136 153 134 129 147 144 110 132 128 127 139 134 127 127 126 125 149 133 117 140 121 138 145 130 127 144 130 128 146 124 148 136 148 128 138 123 132 133 121 122 140 139 138 114 148 139 142 141 129 154 119 135 139 143 146 135 115 139 129 159 123 121 112 146 134 136 137 135 139 111 129 128 129 150 148 136 165 141 162 116 134 154 114 141 143 124 131 164 132 145 112 138 124 117 129 116 141 121 129 131 112 135 122 133 133 134 130 133 131 139 134 133 132 136 133 135 145 131 135 139 141 124 146 130 137 133 132 137 127 126 128 119 138 125 134 131 122 142 128 118 125 139 130 120 132 136 110 134 133 129 142 139 132 144 121 146 130 136 140 136 132 147 132 118 129 131 128 130 132 147 129 130 122 147 123 141 131 135 127 140 152 142 158 135 129 153 133 131 127 125 146 142 131 133 128 154 127 109 121 147 135 142 120 149 129 135 128 140 145 140 127 136 125 141 156 128 133 122 133 137 152 110 150 131 121 124 140 114 112 112 118 137 129 130 121 136 135 148 126 115 135 120 136 132 144 122 143 148 134 140 128 115 143 137 143 141 114 123 126 133 147 126 122 139 146 134 146 132 131 138 114 135 150 130 157 145 112 133 133 139 136 134 129 122 135 125 153 134 136 138 135 138 134 131 138 132 132 138 124 138 135 141 125 136 143 127 130 138 137 128 135 123 113 118 130 153 139 132 120 127 134 145 116 135 136 126 109 142 126 129 135 136 156 135 137 130 128 155 133 136 132 155 129 128 128 138 133 137 137 137 130 126 131 155 151 119 145 133 133 134 134 154 109 116 133 145 138 136 123 120 120 127 128 133 113 128 129 149 131 144 138 136 137 173 165 142 121 107 145 159 132 141 150 118 122 132 122 123 114 128 155 127 138 121 117 161 155 135 146 119 125 121 144 133 104 114 126 150 125 137 125 147 146 118 139 134 138 141 147 131 126 116 148 132 136 128 153 137 150 138 131 122 125 115 123 135 137 134 134 138 144 147 156 117 132 117 139 132 137 120 135 153 140 137 141 126 125 133 148 131 146 125 137 124 127 148 138 111 140 125 130 132 112 123 132 129 140 137 123 122 136 121 132 144 143 123 150 131 145 143 126 148 121 127 134 121 126 140 124 132 129 141 136 121 144 122 124 120 147 142 136 136 142 124 117 132 143 141 134 136 124 127 142 148 135 161 135 142 137 130 136 136 135 122 144 116 120 134 127 141 145 115 148 130 118 128 125 128 135 132 130 137 131 144 131 143 135 120 129 125 131 151 134 129 100 137 133 137 140 133 136 148 121 134 97 142 146 130 154 119 136 137 133 136 119 128 124 156 125 128 144 146 140 117 152 139 127 137 150 151 151 133 137 134 123 126 145 117 144 122 131 158 129 156 129 132 116 113 126 138 143 133 125 138 130 134 128 140 145 123 116 129 153 136 127 112 152 141 126 146 129 133 147 133 150 142 127 130 147 138 123 148 140 148 131 125 149 125 154 126 141 126 127 130 127 123 138 131 146 132 127 119 144 120 135 132 114 127 133 147 126 146 123 135 126 131 145 145 138 125 165 134 143 135 135 133 127 125 145 128 133 130 116 162 138 130 138 142 126 126 121 158 141 150 120 127 142 133 149 132 125 133 126 120 140 150 143 131 131 153 138 135 137 119 124 128 134 124 135 130 117 148 118 131 137 146 127 161 125 138 130 133 158 119 128 146 139 140 143 125 144 127 134 137 132 139 163 128 127 138 130 127 125 145 137 140 151 140 131 133 130 149 141 136 137 147 146 128 136 159 144 143 106 123 147 142 131 150 124 142 139 134 141 136 141 114 122 168 133 157 152 147 139 153 164 141 140 120 138 140 130 135 145 145 154 128 131 131 138 151 119 141 139 140 137 137 143 132 146 153 150 136 131 127 125 160 163 147 161 142 133 127 143 137 120 136 152 132 141 128 142 130 133 127 133 153 136 136 140 122 156 127 147 123 136 125 134 154 126 142 136 143 140 124 145 109 134 136 131 148 112 128 125 130 128 155 134 137 123 138 146 125 127 138 125 119 120 149 130 136 147 129 132 129 133 134 152 145 134 127 119 143 127 142 130 124 119 145 145 124 140 140 123 128 129 125 144 124 127 131 119 124 131 133 147 123 151 125 136 137 128 132 123 128 105 115 149 130 166 137 132 131 139 125 126 138 159 142 127 125 124 150 113 154 122 123 148 136 128 136 134 121 120 131 153 127 124 125 128 142 134 153 142 120 141 120 144 128 134 148 141 120 142 130 142 137 127 132 110 121 113 119 122 136 139 130 144 126 143 131 119 145 134 123 134 131 137 123 120 122 146 137 128 131 137 150 131 147 121 137 135 138 135 142 135 133 138 146 118 138 119 122 131 135 111 137 131 116 142 125 135 119 148 146 132 118 118 129 111 136 136 134 127 127 149 126 138 135 127 139 113 131 119 122 151 135 129 137 137 125 136 151 132 118 138 143 130 142 147 117 117 146 139 140 134 125 134 125 114 130 147 126 139 142 133 140 137 121 147 122 142 129 152 133 128 154 139 132 140 144 127 139 133 122 131 125 149 122 129 138 147 132 117 144 139 160 128 138 122 143 153 137 122 121 124 148 115 133 128 141 121 115 123 126 135 108 149 143 139 122 121 142 134 145 136 127 128 134 133 125 121 137 126 142 125 113 150 121 123 145 137 149 145 134 137 143 149 133 150 126 131 130 146 136 125 132 130 138 113 142 145 144 150 156 120 121 147 119 133 143 126 120 113 143 145 144 139 127 131 143 119 134 120 132 146 129 141 118 116 144 121 141 115 140 134 129 134 137 138 142 130 135 138 131 118 133 129 110 127 128 125 126 159 143 142 142 116 144 114 130 126 130 127 136 114 145 141 124 119 131 127 120 128 133 110 139 149 142 125 140 128 115 133 141 134 118 161 135 142 122 137 136 127 122 125 150 142 132 153 142 117 119 133 111 137 145 133 147 159 125 121 132 120 139 149 139 135 151 128 140 119 123 148 118 136 126 128 124 131 120 122 128 137 108 147 141 112 142 128 124 138 130 141 146 118 158 127 135 132 158 110 145 123 137 114 116 132 147 130 140 141 152 115 128 157 137 135 128 144 125 143 143 114 160 119 142 132 127 118 137 144 101 128 138 152 137 122 144 131 129 127 107 136 127 143 110 142 150 128 154 127 136 150 112 122 151 140 135 147 126 130 138 148 141 121 125 126 134 127 152 122 138 135 125 126 132 124 139 128 131 141 123 140 108 153 139 141 162 137 143 144 114 139 131 134 124 123 125 127 131 134 127 135 134 138 139 137 134 134 138 149 133 129 170 120 135 139 136 140 137 143 129 151 132 137 143 128 125 135 142 120 128 147 156 130 139 137 131 141 133 137 127 122 125 136 115 119 135 146 155 156 141 128 133 142 151 129 126 139 138 136 133 126 140 114 113 126 116 120 124 118 120 116 132 141 131 137 122 144 118 129 125 119 113 126 134 131 130 139 128 141 135 153 136 132 162 136 111 127 134 135 150 149 128 145 128 130 147 131 138 137 120 117 116 136 134 139 122 131 153 131 132 122 117 121 116 131 124 127 145 143 135 151 126 136 136 129 135 126 140 139 128 122 132 137 148 133 136 155 129 119 144 128 149 131 123 132 126 129 121 141 138 143 121 141 145 126 145 133 149 140 128 143 128 117 148 133 153 137 133 146 120 140 111 111 147 150 136 138 128 120 142 120 135 119 127 123 113 151 135 132 138 144 131 121 129 130 135 145 124 125 140 139 121 143 126 127 145 138 130 113 131 135 133 115 136 124 142 141 129 145 120 121 140 120 146 149 130 128 128 143 137 138 114 146 140 142 114 122 139 142 134 137 135 143 152 134 111 142 143 140 151 131 151 116 135 134 149 127 132 132 125 138 127 138 128 143 126 124 122 140 130 132 122 137 131 127 109 137 127 147 141 134 136 112 121 117 123 128 119 142 137 131 126 127 130 107 128 138 115 152 129 129 114 136 140 125 143 147 146 144 153 132 132 134 124 147 144 117 128 146 139 147 134 129 140 150 120 147 128 117 118 124 128 137 146 130 141 142 139 155 130 131 135 139 139 116 129 141 152 141 134 120 136 122 138 139 141 135 138 128 131 123 127 138 138 128 125 140 137 139 113 153 143 122 129 116 169 134 129 121 127 142 125 139 135 134 121 124 142 137 145 125 133 137 160 129 127 150 140 105 139 142 143 139 114 138 127 133 117 121 145 143 151 145 142 127 136 137 126 117 124 118 128 134 142 125 129 122 121 155 158 124 134 149 124 122 131 150 135 133 141 134 145 138 138 138 142 117 134 136 145 139 118 125 124 151 136 142 128 122 133 122 156 130 124 137 128 135 132 127 141 126 133 136 152 114 132 125 132 139 142 115 138 140 106 141 155 108 147 141 146 134 124 129 124 130 156 124 149 170 126 146 127 141 125 122 133 113 134 148 152 144 122 121 125 132 122 120 124 137 123 142 135 131 129 139 114 136 127 118 115 156 124 136 140 116 131 122 138 105 133 130 132 132 151 143 148 119 126 118 136 115 140 130 148 125 127 161 145 151 129 118 143 116 144 132 149 114 137 149 148 129 126 115 115 132 134 147 125 124 114 147 139 126 122 131 142 136 128 147 130 129 146 130 141 127 124 134 144 122 135 112 162 134 128 134 138 134 112 144 142 149 149 129 130 146 129 128 144 147 124 122 126 143 106 131 123 116 132 136 130 146 124 150 102 140 134 145 139 152 140 138 137 142 140 127 121 133 124 136 130 117 133 134 126 126 146 124 127 153 116 147 117 145 132 156 125 150 112 143 121 158 139 163 131 125 119 114 123 127 136 128 141 136 124 145 131 135 147 132 128 128 139 127 130 132 131 166 124 127 113 129 134 148 118 137 135 141 142 140 134 131 130 117 135 115 131 142 125 119 122 135 151 141 118 130 138 113 124 125 105 129 137 128 134 134 118 126 140 145 141 139 135 119 138 140 121 121 138 127 120 128 120 125 133 128 118 132 126 144 134 124 115 111 122 152 144 147 124 135 142 123 139 105 130 130 136 143 130 138 134 151 126 129 142 127 123 130 128 138 118 168 121 136 130 130 141 150 132 145 144 141 136 111 138 132 143 138 126 124 144 123 121 142 141 133 130 129 133 110 135 139 128 141 133 130 148 126 148 131 147 120 143 128 121 132 139 148 150 129 139 155 127 145 131 113 127 114 154 133 144 134 141 132 148 139 149 123 140 125 122 141 120 148 150 135 114 156 135 142 124 139 140 126 138 137 142 141 134 146 144 136 135 138 141 125 146 147 129 139 141 150 126 134 129 127 136 139 118 127 124 118 130 140 125 132 141 138 123 162 133 145 143 152 116 147 141 111 126 112 120 143 134 156 114 143 137 129 130 132 129 136 111 124 137 130 124 151 156 135 136 139 141 121 135 143 139 131 143 132 126 148 144 111 129 125 122 132 129 129 138 157 140 134 138 131 140 123 127 138 132 135 125 146 148 125 130 126 139 129 143 142 149 113 155 132 118 126 115 136 121 135 124 132 160 156 126 140 129 135 134 134 139 127 155 144 124 143 134 136 129 138 139 140 142 155 121 156 128 146 146 120 150 114 147 149 147 134 139 142 134 143 135 146 146 150 124 134 153 160 139 128 136 162 137 120 131 134 130 134 101 149 127 121 163 120 138 122 156 143 140 132 137 140 164 110 137 125 140 136 143 138 131 119 129 137 144 124 125 157 146 122 135 140 120 117 141 154 159 146 134 129 164 134 154 133 131 149 133 137 115 119 127 125 151 129 161 121 161 160 144 130 140 143 140 149 143 152 141 153 129 154 129 144 138 142 149 146 135 140 157 143 158 145 118 150 152 151 145 142 126 137 147 139 153 157 125 150 129 149 135 124 148 155 142 133 136 142 148 136 127 146 143 134 138 156 138 144 126 160 144 117 120 138 138 154 135 142 130 137 142 139 150 160 127 157 142 134 146 118 129 145 142 127 133 144 124 127 145 157 142 130 134 135 151 121 156 136 141 130 120 155 158 130 121 126 110 120 141 120 121 157 128 141 151 119 151 150 131 123 126 151 144 139 146 130 137 135 144 129 147 130 126 147 152 147 132 130 140 141 158 147 126 121 144 136 125 123 126 128 130 135 121 126 154 142 168 155 138 135 133 130 128 132 137 148 145 131 137 129 150 140 144 130 141 135 116 152 155 133 137 148 142 156 143 150 136 129 130 137 122 127 139 121 134 134 141 160 112 123 129 121 143 148 135 151 140 141 141 108 147 156 131 134 145 149 121 154 121 141 134 143 143 140 142 146 147 141 146 132 125 146 129 135 123 124 157 127 115 157 137 141 140 119 129 136 121 154 153 128 130 128 133 139 162 141 135 145 143 141 129 147 126 149 138 129 111 157 134 114 150 149 150 129 143 131 139 157 127 132 117 163 136 117 145 114 133 148 154 140 145 124 144 122 152 139 127 141 144 124 123 148 128 143 142 104 137 134 135 123 120 138 146 138 126 130 176 143 150 156 151 117 122 136 124 131 123 131 122 142 118 140 131 153 132 130 147 135 153 124 141 135 132 144 139 138 136 127 137 141 125 135 124 146 132 153 158 142 139 123 121 134 151 149 135 111 134 132 140 126 139 142 126 136 125 159 119 138 143 122 142 121 151 140 131 141 118 135 132 128 143 144 132 155 132 119 129 136 147 120 136 144 119 159 128 120 107 132 134 130 127 140 122 150 129 145 128 136 130 131 122 113 121 132 126 137 132 133 146 136 113 133 119 143 137 153 136 120 125 104 133 131 156 142 140 133 123 133 122 135 152 131 127 130 113 142 136 122 133 133 133 146 125 133 128 137 118 129 144 149 146 152 154 128 144 112 127 133 130 142 115 110 144 120 131 138 145 122 128 132 137 156 149 110 114 150 117 124 126 126 134 154 148 152 148 138 125 136 134 122 112 110 123 152 115 151 146 132 150 112 144 136 116 135 148 152 138 105 111 130 122 155 141 151 157 159 143 126 149 127 134 151 136 120 117 126 145 135 143 137 150 129 146 136 136 116 129 130 117 129 139 136 131 162 154 135 118 136 133 124 123 118 142 136 137 122 120 134 150 118 128 133 132 127 136 137 126 150 128 132 109 127 127 137 134 137 130 129 157 122 129 126 139 142 135 148 152 126 120 119 136 151 126 119 138 146 130 122 140 135 131 139 152 126 159 137 130 141 129 124 137 143 140 132 134 129 121 135 135 122 144 128 137 144 129 146 109 132 155 118 143 125 125 151 132 128 130 120 137 122 118 151 136 145 146 114 140 124 157 139 121 136 127 129 140 113 124 116 152 119 132 151 138 143 136 129 144 130 108 115 146 126 109 130 134 139 171 154 152 123 136 121 117 130 120 133 124 122 139 154 116 129 142 119 141 133 163 116 124 130 125 135 134 130 134 128 155 157 130 131 139 127 118 137 146 129 120 128 136 126 126 148 133 124 134 126 128 151 138 128 144 114 157 149 125 116 124 144 116 140 124 138 154 96 115 139 144 130 114 110 137 119 148 153 129 145 149 144 145 137 143 127 134 146 119 112 135 133 129 124 128 144 157 123 120 133 133 151 141 136 116 137 123 141 143 141 146 120 129 112 132 112 142 137 166 138 131 131 122 124 135 149 133 130 134 139 114 132 116 154 139 141 155 125 147 137 124 150 131 135 144 138 139 112 149 118 116 127 134 131 126 135 166 126 132 135 168 137 143 144 141 131 117 134 117 134 137 135 135 157 122 124 145 154 141 139 143 149 129 133 126 117 134 129 143 141 134 115 132 132 145 132 138 149 153 155 146 110 138 152 116 134 129 160 122 138 140 147 142 150 127 133 132 120 121 140 143 126 125 113 120 145 121 131 128 144 127 130 119 145 133 163 133 125 138 126 122 131 125 135 132 133 124 146 126 134 137 138 144 123 132 141 135 141 139 150 151 141 139 139 124 128 125 143 130 125 116 130 139 130 135 128 142 141 129 142 127 127 126 129 120 127 144 122 114 120 143 130 149 141 142 120 119 141 119 126 140 139 148 117 121 106 170 123 148 140 149 133 156 101 138 119 122 147 138 141 137 147 142 124 129 128 150 102 141 131 137 143 118 160 128 128 137 120 126 112 147 139 133 129 128 123 120 124 143 127 128 161 144 168 142 127 130 128 126 137 151 146 165 126 133 145 131 148 126 159 135 117 135 137 122 123 138 125 123 146 118 111 147 123 134 133 143 125 137 159 132 128 142 135 147 137 132 132 152 151 145 127 120 137 135 134 144 129 141 128 142 122 119 120 127 117 128 130 128 121 128 137 115 137 137 141 124 136 134 141 124 120 101 138 132 140 157 147 120 136 132 145 132 127 148 144 133 137 129 133 146 146 146 148 124 126 122 146 126 139 129 140 140 112 147 130 164 134 146 152 153 130 135 142 147 153 112 132 130 154 136 150 133 105 129 115 152 133 136 137 133 151 137 134 139 144 127 132 126 148 152 135 126 148 131 137 142 141 132 120 146 150 127 119 152 144 117 140 152 142 112 153 125 134 136 146 141 159 129 130 136 153 128 129 149 129 143 150 127 138 114 111 119 132 127 151 136 133 143 151 128 130 131 124 128 137 149 158 117 133 141 119 125 146 161 158 129 142 141 131 132 148 115 143 133 127 129 153 145 141 140 161 139 128 122 126 128 127 144 140 147 150 125 126 137 134 147 133 124 111 156 143 135 129 124 135 131 136 121 134 129 126 145 141 124 127 140 146 132 146 130 109 149 139 133 136 116 135 150 135 135 151 142 128 140 145 125 132 140 146 134 135 149 151 138 148 145 134 126 151 136 119 149 132 131 153 131 155 133 137 136 125 143 112 145 128 138 125 121 119 122 128 159 114 150 139 123 129 126 115 133 110 134 137 126 141 136 141 140 137 131 134 151 148 147 125 132 143 160 146 157 139 125 111 131 143 140 126 160 136 127 133 135 129 130 145 120 147 146 120 111 141 122</counts>
			</dataPoints>
		</scan>
	</xrdMeasurement>
</xrdMeasurements>