File: data/XRD/XG-Sauerstoff/XG-800/W6821-1B_XG_Sauerstoff_800.xrdml
<xrdMeasurements xmlns="http://www.xrdml.com/XRDMeasurement/2.1" xmlns:xsi="http://www.w3.org/2001/XMLSchema-instance" xsi:schemaLocation="http://www.xrdml.com/XRDMeasurement/2.1 http://www.xrdml.com/XRDMeasurement/2.1/XRDMeasurement.xsd" status="Completed">
	<comment>
		<entry>Configuration=Factory configuration, Owner=User-1, Creation date=7/8/2013 4:01:53 PM</entry>
		<entry>Goniometer=PW3050/65 (Theta/2Theta); Minimum step size 2Theta:0.0001; Minimum step size Omega:0.0001</entry>
		<entry>Sample stage=MRD Cradle; Minimum step size Phi:0.01; Minimum step size Chi:0.01; Minimum step size X:0.01; Minimum step size Y:0.01; Minimum step size Z:0.001</entry>
		<entry>Diffractometer system=XPERT-PRO</entry>
		<entry>Measurement program=C:\PANalytical\Data Collector\Programs\Jorrit\2thom\_absolute_2th-om_10-130deg_PIXscan_56min.xrdmp, Identifier={15BCCF57-2807-42BD-B5B9-ECC0B3DC9284}</entry>
		<entry>Batch program=C:\PANalytical\Data Collector\Programs\SimonL\batch4x_2thom_10-130°_z9.1_x0,10,20,30_y0_57min.xrdmp, Identifier={EED9823A-2BEB-424C-9252-345C4EF2834A}</entry>
	</comment>
	<sample type="To be analyzed">
		<id></id>
		<name></name>
		<preparedBy></preparedBy>
	</sample>
	<xrdMeasurement measurementType="Scan" status="Completed" sampleMode="Reflection">
		<comment>
			<entry>_absolute_2th-om_10-130deg_PIXscan_56min</entry>
			<entry>PHD Lower Level = 4.83 (keV), PHD Upper Level = 11.27 (keV)</entry>
		</comment>
		<usedWavelength intended="K-Alpha 1">
			<kAlpha1 unit="Angstrom">1.5405980</kAlpha1>
			<kAlpha2 unit="Angstrom">1.5444260</kAlpha2>
			<kBeta unit="Angstrom">1.3922500</kBeta>
			<ratioKAlpha2KAlpha1>0.5000</ratioKAlpha2KAlpha1>
		</usedWavelength>
		<incidentBeamPath>
			<radius unit="mm">320.00</radius>
			<xRayTube id="1010048" name="Empyrean Cu LFF HR (9430 033 7310x) DK442154">
				<tension unit="kV">40.0</tension>
				<current unit="mA">40.0</current>
				<anodeMaterial>Cu</anodeMaterial>
				<focus type="Line">
					<length unit="mm">12.0</length>
					<width unit="mm">0.4</width>
					<takeOffAngle unit="deg">4.2</takeOffAngle>
				</focus>
			</xRayTube>
			<xRayMirror id="27010001" name="Inc. Beam Cu W/Si (parabolic MRD)" hybrid="false">
				<crystal type="Graded" shape="Parabolic">W/Si</crystal>
				<acceptanceAngle unit="deg">0.800</acceptanceAngle>
				<length unit="mm">60.0</length>
			</xRayMirror>
			<sollerSlit id="21010002" name="Soller slits 0.04 rad.">
				<opening unit="rad">0.0400</opening>
			</sollerSlit>
			<mask id="22030007" name="Fixed mask 2 mm">
				<distanceToSample unit="mm">220.00</distanceToSample>
				<width unit="mm">2.00</width>
			</mask>
			<divergenceSlit id="22010007" name="Fixed slit 1/8°" xsi:type="fixedDivergenceSlitType">
				<distanceToSample unit="mm">220.00</distanceToSample>
				<height unit="mm">0.19</height>
			</divergenceSlit>
		</incidentBeamPath>
		<diffractedBeamPath>
			<radius unit="mm">320.00</radius>
			<sollerSlit id="21010002" name="Soller slits 0.04 rad.">
				<opening unit="rad">0.0400</opening>
			</sollerSlit>
			<receivingSlit id="22010001" name="Fixed slit 4°">
				<height unit="mm">5.88</height>
			</receivingSlit>
			<detector id="7010017" name="PIXcel3D 1x1 detector" xsi:type="areaDetectorType">
				<phd unit="%">
					<lowerLevel>30.0</lowerLevel>
					<upperLevel>70.0</upperLevel>
				</phd>
				<mode>Scanning</mode>
				<activeChannelsEquatorial>255</activeChannelsEquatorial>
				<activeChannelsAxial>255</activeChannelsAxial>
				<pitchEquatorial unit="mm">0.05500</pitchEquatorial>
				<pitchAxial unit="mm">0.05500</pitchAxial>
				<readOutPeriod unit="seconds">0.135</readOutPeriod>
			</detector>
		</diffractedBeamPath>
		<scan appendNumber="0" mode="Continuous" scanAxis="2Theta-Omega" status="Completed">
			<header>
				<startTimeStamp>2024-09-30T12:11:37+02:00</startTimeStamp>
				<endTimeStamp>2024-09-30T13:07:41+02:00</endTimeStamp>
				<author>
					<name>PRO-MRD</name>
				</author>
				<source>
					<applicationSoftware version="6.1b">Data Collector</applicationSoftware>
					<instrumentControlSoftware version="7.0E 20130304">XPERT-PRO</instrumentControlSoftware>
					<instrumentID>0000000011142674</instrumentID>
				</source>
			</header>
			<dataPoints>
				<positions axis="2Theta" unit="deg">
					<startPosition>9.99826193</startPosition>
					<endPosition>129.99755682</endPosition>
				</positions>
				<positions axis="Omega" unit="deg">
					<startPosition>4.99913096</startPosition>
					<endPosition>64.99877841</endPosition>
				</positions>
				<positions axis="Phi" unit="deg">
					<commonPosition>0.00</commonPosition>
				</positions>
				<positions axis="Chi" unit="deg">
					<commonPosition>0.00</commonPosition>
				</positions>
				<positions axis="X" unit="mm">
					<commonPosition>0.00</commonPosition>
				</positions>
				<positions axis="Y" unit="mm">
					<commonPosition>0.00</commonPosition>
				</positions>
				<positions axis="Z" unit="mm">
					<commonPosition>9.100</commonPosition>
				</positions>
				<commonCountingTime unit="seconds">32.895</commonCountingTime>
				<counts 229 227 225 209 200 222 226 216 231 193 208 185 194 226 173 204 218 204 240 210 217 180 192 215 212 213 211 204 214 208 201 222 189 206 170 185 208 192 200 185 204 186 211 191 198 231 197 199 188 190 202 206 210 183 204 222 186 218 203 225 198 196 199 222 205 186 197 183 200 210 206 192 197 187 199 204 219 192 212 172 215 197 168 184 210 195 176 213 175 207 191 184 199 200 191 216 187 213 198 212 193 211 187 176 221 193 193 188 182 201 205 189 187 186 191 197 200 157 196 188 215 204 186 174 177 187 186 181 184 179 191 184 193 177 156 199 169 180 189 178 185 199 184 160 187 166 182 189 174 175 169 186 193 169 191 184 196 176 175 194 189 196 204 189 154 176 171 186 202 180 170 185 185 174 183 176 173 185 173 192 191 189 212 171 174 178 173 176 174 174 171 169 199 175 181 169 159 159 177 169 170 188 182 172 176 201 164 183 187 185 180 185 178 163 174 191 181 193 168 202 195 173 181 208 166 169 179 166 181 161 191 185 176 190 183 173 173 177 158 166 163 178 187 164 189 178 190 183 168 153 170 188 186 179 192 175 165 153 165 176 162 164 171 159 162 187 137 176 178 156 184 163 175 180 166 160 151 180 175 183 185 178 166 169 168 148 169 145 168 179 161 162 178 188 150 167 146 184 168 159 158 161 172 158 167 175 163 170 150 159 164 157 182 156 170 165 160 159 148 178 158 157 146 159 141 179 161 157 135 195 181 176 169 147 171 170 164 175 136 158 140 158 164 144 151 159 156 171 165 138 153 150 171 157 173 158 160 165 153 156 162 180 159 145 149 157 171 162 146 154 173 156 142 157 144 159 170 163 165 162 171 156 172 167 151 155 170 163 163 166 147 157 139 153 177 154 162 166 168 171 143 144 152 139 142 146 163 139 179 139 153 179 145 153 141 139 151 147 167 152 166 152 157 148 165 174 146 158 167 173 151 134 165 155 153 182 156 146 165 147 155 148 149 153 157 157 168 138 155 151 166 144 140 152 154 142 144 131 139 150 166 155 150 164 155 145 148 148 150 137 145 139 138 149 140 148 128 145 147 163 159 137 157 133 148 135 155 141 150 131 149 133 146 141 140 143 143 143 135 147 149 150 145 142 149 122 140 159 122 131 152 165 128 126 156 162 121 137 164 142 149 148 157 126 154 157 142 151 138 116 152 156 157 130 149 166 138 132 145 146 128 139 160 127 143 160 143 149 151 153 149 127 133 142 155 157 169 148 131 136 148 131 146 167 163 140 157 141 137 152 145 126 152 134 153 134 133 130 126 150 127 136 137 145 138 156 162 132 140 131 137 136 154 156 151 133 119 151 147 117 148 128 137 143 118 154 120 166 142 126 144 155 154 134 149 123 145 143 155 153 150 134 131 156 138 141 147 151 135 141 140 142 153 142 167 134 162 128 151 153 150 126 153 142 148 132 142 144 143 117 138 145 141 137 150 144 149 139 121 150 142 122 145 135 150 133 153 151 129 142 137 145 146 125 132 144 134 123 141 149 160 126 146 147 155 133 134 150 143 141 137 132 159 104 128 126 136 156 152 129 154 130 142 137 156 141 149 145 148 142 132 140 146 142 140 146 124 135 143 132 133 155 140 151 152 132 141 145 136 137 133 124 146 158 155 157 144 138 141 167 124 164 140 138 143 140 141 136 143 149 128 142 133 125 140 158 147 146 139 135 151 154 143 126 128 146 142 151 149 145 139 152 140 142 165 140 123 151 146 147 146 159 116 132 146 168 162 162 144 137 126 156 135 163 158 141 143 137 146 165 140 152 162 130 148 150 147 147 144 131 132 137 145 150 149 130 146 160 123 138 155 156 144 132 142 130 141 149 151 160 144 136 163 142 149 151 160 134 142 130 133 154 148 132 138 154 168 140 134 132 148 149 152 126 144 166 134 141 142 152 134 141 173 126 168 137 139 138 140 135 143 133 154 156 150 154 135 146 152 141 154 119 151 149 158 170 147 151 127 156 175 138 143 133 153 150 166 151 136 142 140 160 142 155 149 130 153 142 147 143 157 165 165 151 155 160 120 150 150 152 134 152 151 153 135 158 135 164 146 142 133 143 157 140 139 150 169 145 162 150 163 136 143 163 145 153 134 170 154 140 166 144 147 149 161 122 156 157 147 134 157 155 176 137 136 147 167 145 136 139 136 142 153 144 154 157 131 115 153 169 176 170 152 161 137 121 139 152 157 141 143 155 141 168 138 142 146 168 131 159 135 141 159 137 139 146 184 153 171 146 137 156 157 168 163 151 154 140 175 162 159 170 129 142 136 152 172 148 154 153 152 128 150 162 156 144 163 155 157 160 161 156 138 153 145 127 182 161 167 155 154 178 156 149 148 175 143 164 149 145 175 155 157 158 141 171 173 162 153 142 170 142 155 132 147 151 140 168 153 149 152 143 141 164 152 153 166 157 160 152 154 166 157 147 160 157 154 140 146 160 134 150 160 164 139 156 153 147 158 169 161 156 154 145 151 161 179 143 148 144 154 161 156 156 146 155 142 150 134 143 138 153 145 152 162 159 145 154 174 136 171 150 154 163 171 156 163 149 122 155 144 138 150 143 154 172 128 149 137 134 172 153 143 140 165 188 153 165 182 140 162 162 182 168 165 155 161 142 155 148 165 140 165 145 170 151 152 128 148 149 161 146 142 146 150 162 167 155 148 165 146 154 165 146 165 177 155 156 135 154 157 150 185 171 139 154 195 151 176 166 154 154 154 147 154 144 153 166 160 146 139 175 153 174 164 153 156 161 157 160 137 142 185 165 149 182 146 169 168 162 150 178 166 148 153 159 172 173 156 161 177 162 151 143 144 160 166 141 136 150 174 142 143 152 154 160 172 151 167 172 133 165 142 164 139 154 167 173 169 151 149 171 177 162 153 175 179 173 150 150 176 146 141 160 150 171 144 155 163 149 154 169 169 170 169 150 158 145 150 148 159 144 174 132 164 167 162 175 163 143 139 187 172 150 176 168 136 129 157 151 167 141 147 142 160 155 157 135 169 146 142 162 155 159 178 147 143 160 168 138 134 144 159 134 171 166 122 161 132 162 156 150 153 176 158 156 147 170 135 159 156 158 171 151 146 161 158 186 124 161 157 138 164 150 160 142 143 186 154 143 159 159 124 130 136 161 151 152 156 146 152 157 155 161 167 172 158 162 142 154 154 143 149 136 132 161 143 146 146 169 163 174 159 170 168 144 161 180 153 142 124 156 170 159 154 119 137 162 161 157 145 158 167 153 153 163 140 158 153 159 154 153 146 157 108 163 148 150 163 145 165 162 139 165 172 151 169 141 126 129 156 150 156 165 130 151 149 147 173 151 162 143 157 129 157 165 126 135 141 143 139 155 145 154 155 168 177 129 169 143 123 148 132 141 152 131 147 159 126 126 134 144 158 146 144 133 140 168 153 128 137 147 109 132 137 145 144 143 164 136 127 131 153 135 139 164 151 138 127 146 176 155 145 151 144 148 146 154 136 150 143 172 135 135 147 121 158 118 155 146 170 156 145 159 128 134 164 139 143 157 121 140 139 145 134 125 162 141 145 151 153 137 133 152 168 153 135 152 141 130 125 143 143 148 147 131 169 138 151 155 153 122 152 113 141 146 152 126 129 139 129 150 132 130 127 161 178 139 153 150 150 145 141 152 136 137 126 144 139 131 134 142 132 153 138 136 147 135 139 117 132 153 143 148 152 129 148 144 166 141 119 131 149 130 139 155 122 140 137 115 157 146 140 130 144 132 132 131 165 133 150 134 139 169 133 140 125 136 168 124 157 142 153 139 153 139 129 147 144 128 126 130 136 130 140 147 145 135 154 120 134 142 129 146 128 125 135 160 140 126 129 157 159 130 144 119 147 150 141 139 138 165 131 138 127 149 126 140 146 138 146 113 136 150 144 141 144 143 127 170 156 143 156 126 118 149 138 128 121 142 129 144 125 138 125 128 107 136 121 135 130 120 130 139 155 131 154 119 135 130 117 141 126 125 128 146 134 142 143 113 135 149 152 127 122 122 147 132 141 149 133 140 134 138 124 107 134 121 133 138 128 145 137 134 107 133 135 111 143 137 125 142 121 108 123 116 143 141 120 134 147 132 121 151 139 138 132 124 133 146 128 129 130 125 126 132 132 147 145 134 117 141 113 130 126 141 115 128 146 115 149 108 130 106 135 119 113 143 129 127 135 134 112 161 128 121 121 109 140 150 134 131 133 124 129 134 118 113 135 140 131 113 142 139 144 128 126 134 132 116 110 137 101 101 129 130 111 116 151 121 142 131 117 129 114 112 115 132 149 127 129 131 132 125 146 116 126 122 147 114 125 125 129 123 142 140 134 139 114 137 155 118 126 113 119 110 136 129 114 141 112 138 134 117 113 127 107 134 131 126 126 123 146 134 147 119 121 113 131 121 119 111 128 137 110 130 136 115 115 120 124 125 115 121 136 140 124 139 125 127 143 137 125 122 132 130 125 108 131 142 117 108 129 134 122 128 141 124 132 124 125 139 129 151 109 118 107 127 123 117 129 118 120 105 122 128 119 121 111 135 117 122 129 132 128 108 109 149 133 122 141 133 133 143 126 131 142 127 126 117 112 120 139 110 151 127 127 115 140 125 119 107 130 127 134 122 122 126 118 100 136 114 137 111 124 118 118 123 140 124 146 117 126 114 107 117 113 108 117 129 140 121 107 114 128 128 103 126 123 137 126 119 125 142 136 118 120 129 103 117 121 147 123 116 126 128 120 114 119 134 120 114 99 109 138 115 127 120 113 134 146 148 102 120 101 126 117 107 133 125 120 104 113 117 144 120 127 122 131 128 104 114 137 138 125 119 138 136 128 123 126 115 122 100 121 132 122 126 145 105 111 131 117 126 108 121 123 127 103 115 146 112 134 133 114 117 139 128 106 119 111 119 100 133 134 127 127 141 118 108 112 107 102 126 109 106 125 115 130 118 113 132 115 106 116 118 130 120 133 139 116 122 120 109 136 104 116 110 119 125 129 116 115 126 109 135 121 121 108 102 111 111 130 113 133 126 119 130 120 134 127 117 113 126 134 107 119 135 108 113 123 103 96 120 123 113 122 116 111 134 108 110 113 129 130 113 111 128 132 130 104 114 111 119 120 132 111 109 119 133 118 117 114 121 107 94 118 121 126 120 131 109 110 117 133 132 120 122 107 119 115 128 112 98 98 119 113 98 119 130 113 106 104 113 99 140 108 120 127 113 122 126 110 117 107 110 121 112 120 115 117 107 124 102 101 128 101 126 120 134 125 116 120 121 121 122 128 101 128 125 113 114 124 113 100 111 116 119 102 118 110 130 107 127 126 115 127 116 138 95 94 112 121 98 122 119 109 133 92 107 104 132 124 125 109 131 129 108 114 109 123 125 115 107 122 114 117 118 129 128 120 122 109 107 109 103 130 124 119 114 117 111 130 115 121 117 123 123 127 114 120 124 99 118 125 129 107 108 112 115 101 108 98 121 109 126 117 99 128 116 96 99 108 115 117 110 128 107 125 107 114 113 108 114 118 129 114 117 110 119 129 109 133 113 135 121 109 115 116 107 122 116 110 102 116 100 121 109 142 99 113 126 116 116 101 132 137 123 106 117 126 109 109 101 127 115 110 131 116 135 115 112 114 112 134 107 104 122 119 145 137 105 101 129 121 134 122 126 135 115 105 112 125 115 107 108 119 102 118 121 108 93 111 118 96 100 115 123 103 123 112 105 125 111 132 118 105 105 118 117 98 115 113 113 113 116 112 110 123 121 121 108 111 129 113 118 114 122 109 109 105 114 97 102 112 92 111 128 100 103 117 102 113 121 115 110 125 99 128 124 111 111 117 124 123 114 120 107 103 121 122 115 107 117 144 107 126 115 101 110 105 119 109 112 105 126 125 119 124 115 110 113 112 107 111 131 98 118 108 110 104 111 93 81 120 122 138 111 107 99 113 98 105 110 121 120 126 99 109 126 119 97 110 102 79 113 115 140 97 106 98 105 117 102 89 130 116 115 116 109 109 124 98 101 127 116 105 93 118 101 104 119 130 122 122 125 113 115 112 132 107 120 123 136 93 114 109 105 121 111 121 125 129 94 90 114 116 117 99 124 119 130 101 123 102 131 132 115 112 127 119 108 120 124 120 115 124 122 121 127 103 129 119 111 137 121 123 107 133 132 109 90 111 121 132 130 99 107 119 107 113 123 119 116 111 110 120 103 122 97 127 102 105 123 102 99 103 130 105 92 86 120 111 109 96 107 101 100 101 111 107 85 96 116 113 110 108 127 104 103 94 113 124 120 101 85 119 108 112 114 122 87 104 93 107 99 121 107 116 102 127 113 102 116 101 110 108 99 116 110 85 118 114 107 109 114 89 115 99 103 114 91 132 111 113 123 116 109 115 106 96 136 115 130 104 106 122 105 120 94 106 115 113 98 108 106 102 95 89 120 113 95 117 101 104 101 113 98 93 97 98 108 95 109 118 88 105 125 107 111 103 121 112 119 96 106 108 122 106 111 118 108 133 111 113 110 99 102 103 93 95 110 109 113 121 102 91 119 107 106 106 115 107 117 122 115 125 101 97 106 103 119 116 109 105 111 91 98 115 117 133 115 133 106 98 103 109 118 105 116 115 99 107 101 110 110 98 113 109 105 112 112 106 93 118 118 105 100 128 106 120 89 121 96 101 104 98 100 108 106 97 112 104 97 95 110 102 105 95 120 118 101 119 102 95 115 128 114 106 116 98 101 127 120 95 117 107 111 116 112 94 119 104 104 126 99 101 96 114 99 112 109 108 111 101 102 110 110 107 125 95 93 104 124 116 98 100 104 88 76 105 108 114 98 123 110 114 112 117 109 111 128 96 107 115 117 117 95 107 113 95 97 118 117 111 107 102 93 140 114 127 99 110 111 116 95 106 96 103 99 98 112 121 115 101 121 104 110 116 116 115 126 108 111 120 110 101 125 107 125 129 122 110 127 110 89 109 82 98 120 111 134 88 98 94 103 96 119 98 101 110 103 116 104 112 105 103 96 100 121 109 114 104 113 118 104 123 105 104 123 110 119 104 107 91 93 116 120 106 101 125 112 112 102 108 103 114 105 99 107 107 109 108 105 108 107 121 114 105 93 111 108 122 86 102 113 111 100 118 113 103 112 119 117 116 90 100 120 114 106 101 114 103 85 106 106 124 114 106 110 108 101 114 121 103 120 116 85 109 127 110 111 114 92 105 116 95 121 115 105 112 107 116 105 114 117 128 118 108 112 119 106 97 96 116 120 108 132 94 112 106 138 109 101 116 121 94 103 100 122 121 98 102 89 114 105 118 97 88 109 102 112 104 112 128 119 97 110 97 104 112 98 98 116 104 113 109 90 86 111 140 113 108 112 97 107 100 99 115 112 112 106 108 97 109 105 114 104 112 98 106 121 115 107 103 118 111 113 112 104 110 117 114 102 112 120 117 98 102 105 107 112 103 104 115 119 114 111 98 122 111 132 122 113 125 111 107 97 105 113 127 95 118 117 95 121 122 105 111 108 109 109 100 116 105 96 114 105 104 126 137 85 112 133 111 115 127 111 122 101 113 100 118 118 104 120 102 107 110 130 124 108 138 110 93 127 112 153 120 133 130 123 131 134 111 119 115 109 121 115 133 117 112 121 109 121 98 125 116 112 109 134 116 131 126 108 119 130 125 127 134 121 110 131 121 86 114 120 139 133 119 136 128 128 109 127 129 122 128 145 119 105 116 126 108 121 136 149 142 147 147 145 131 141 162 138 146 135 151 158 161 140 154 144 181 172 160 151 172 168 190 184 187 172 189 175 188 190 197 215 193 213 204 191 209 203 208 197 187 209 186 198 182 162 183 173 190 189 177 151 178 168 200 159 147 149 128 152 160 137 128 154 136 148 130 132 123 135 123 105 127 121 123 113 121 131 134 111 108 125 132 133 118 105 109 132 142 112 123 133 123 108 105 114 117 116 144 120 114 137 127 121 114 112 104 111 109 146 105 120 127 95 120 128 106 96 109 134 113 136 111 114 103 114 104 115 98 99 118 110 128 114 121 115 125 108 127 119 140 101 121 96 101 118 103 110 115 121 114 116 96 110 112 104 123 117 110 121 112 106 128 123 110 106 112 121 127 112 97 119 112 119 126 121 126 124 113 146 100 118 116 115 105 91 118 130 109 113 112 106 108 128 126 86 113 120 109 110 116 112 92 109 127 121 106 119 102 125 109 107 93 118 100 108 96 116 126 118 122 103 129 119 124 119 121 125 100 111 101 113 90 112 112 92 103 115 114 125 117 123 111 106 101 129 113 111 98 103 115 106 104 92 92 109 106 126 92 101 99 113 116 105 111 113 138 112 116 119 111 97 119 112 108 101 118 118 100 107 102 102 134 110 121 135 114 125 127 97 131 110 117 124 126 119 110 108 111 120 135 123 118 109 120 111 114 118 111 102 104 116 108 108 108 115 114 88 119 102 135 101 121 104 81 108 126 116 124 133 121 90 121 124 111 104 114 110 126 114 109 126 119 116 105 131 93 110 101 125 117 118 119 121 109 125 107 112 111 102 101 138 120 98 107 110 95 108 125 115 99 102 120 110 91 119 127 114 100 97 106 99 97 106 99 123 112 117 114 119 110 93 100 115 93 115 128 99 101 107 106 104 111 111 124 126 112 116 115 108 117 108 87 108 123 97 129 115 114 106 112 92 106 114 84 118 113 112 115 120 108 112 118 129 102 106 106 112 117 99 114 122 119 131 131 99 105 115 136 122 105 105 115 136 106 110 96 110 113 99 114 126 124 102 92 107 105 105 106 109 130 113 113 116 119 114 105 114 136 107 112 132 114 118 91 103 108 110 106 102 110 113 111 117 110 116 102 114 91 119 111 106 101 95 124 117 120 100 132 120 121 94 99 113 116 127 97 104 112 130 117 122 120 123 128 119 126 115 116 101 110 130 131 103 113 102 119 124 104 95 122 146 101 128 118 110 95 113 113 115 121 106 122 125 112 98 114 89 105 122 139 108 95 114 126 123 121 113 102 137 98 116 106 119 113 96 108 107 99 113 113 98 109 106 109 112 115 105 108 98 121 113 107 132 116 117 111 113 104 120 114 94 103 113 109 119 121 137 124 116 118 107 108 120 116 112 157 101 114 104 125 129 111 109 122 118 103 114 107 122 111 124 104 104 116 98 116 134 115 123 113 106 117 103 104 114 130 112 102 104 99 85 122 111 131 121 96 120 104 111 95 101 126 117 103 119 124 97 110 127 117 136 121 134 99 107 115 124 116 125 110 124 119 110 100 120 95 102 126 108 101 105 109 113 131 124 112 105 112 119 115 120 111 105 112 106 130 98 109 123 120 109 118 95 128 93 103 115 117 113 115 117 114 129 106 107 119 98 104 117 129 130 119 103 110 128 116 110 134 104 111 123 108 105 96 123 139 119 112 121 148 115 90 132 123 114 115 104 100 111 105 110 109 128 89 105 114 110 127 118 111 102 121 115 129 121 117 119 94 103 116 110 106 123 125 110 111 125 124 114 101 121 122 132 136 123 95 118 137 97 119 116 124 110 110 139 126 120 109 105 107 118 124 114 97 125 130 109 133 109 108 107 115 109 109 115 119 127 122 120 120 105 116 102 108 116 120 113 121 106 110 102 112 110 111 92 103 109 105 107 132 115 100 107 120 107 104 116 96 106 111 117 115 115 108 120 144 119 127 109 113 112 105 107 127 115 106 115 117 125 116 115 122 115 128 121 119 119 106 111 96 127 106 126 123 104 129 121 109 105 118 111 105 121 125 115 120 113 113 115 117 106 106 93 120 124 112 97 111 111 109 126 129 116 124 101 123 110 92 119 107 130 132 111 131 113 110 103 110 115 106 120 98 118 124 100 93 108 125 121 97 105 114 118 130 116 121 102 99 104 123 99 121 116 108 115 119 116 103 118 106 113 130 110 116 118 129 106 125 104 136 137 122 124 100 114 104 111 115 101 106 107 137 109 122 113 122 100 123 98 115 111 131 127 105 105 100 115 121 121 119 97 108 120 97 94 130 107 110 122 106 123 102 109 137 118 121 106 103 102 111 116 124 111 109 104 96 102 109 119 117 113 110 120 110 97 115 115 107 115 105 109 109 103 108 115 118 111 97 121 114 104 112 115 124 104 102 111 112 122 99 96 88 119 131 108 106 120 114 105 106 111 114 101 105 132 118 105 93 110 131 110 123 107 114 131 135 107 119 104 125 114 111 114 107 128 116 97 103 113 95 99 115 100 106 126 106 125 113 110 98 102 88 100 124 103 103 106 141 132 113 120 117 111 125 115 108 112 99 115 116 114 124 112 104 96 114 108 115 113 121 119 102 95 105 135 119 110 119 130 118 109 119 97 97 113 130 109 110 114 136 115 114 113 104 131 105 130 121 116 130 129 119 128 98 122 117 151 101 119 108 112 134 105 115 99 127 109 123 134 114 109 119 127 140 119 119 125 114 106 110 99 139 116 157 115 132 117 109 127 142 120 115 120 102 117 106 121 116 112 122 115 105 128 129 110 100 125 127 95 140 116 127 118 126 111 115 122 129 122 118 115 125 135 102 112 105 122 119 98 95 104 102 106 99 106 109 108 116 114 115 117 125 119 117 104 104 125 94 117 129 115 103 123 102 118 110 95 119 119 86 131 108 102 103 127 124 123 103 101 113 113 128 115 127 114 115 111 113 113 108 112 114 106 103 109 115 92 125 105 111 111 99 134 94 117 129 106 112 110 125 114 105 115 120 104 115 104 140 122 114 125 126 106 106 107 98 118 112 124 99 108 134 107 119 120 122 112 101 99 137 118 127 105 123 108 120 104 112 136 97 109 105 122 125 108 117 124 121 106 130 96 101 120 107 111 102 108 114 110 107 103 114 113 93 113 119 95 113 105 131 115 118 134 105 113 109 107 115 119 100 122 130 134 106 108 133 121 120 122 127 103 103 102 104 107 107 108 120 111 120 105 121 122 100 132 129 97 119 103 106 137 109 110 127 122 98 109 112 110 110 109 105 121 116 120 102 110 116 117 141 150 130 109 141 104 119 108 118 108 122 111 116 109 91 124 98 105 118 132 108 112 109 125 100 104 126 113 103 105 111 110 120 121 130 139 129 128 141 122 89 107 146 110 121 105 101 121 103 115 110 106 111 122 119 101 110 119 103 123 124 107 112 101 123 121 101 111 132 126 120 113 130 111 124 116 104 95 117 100 109 95 111 115 109 106 145 116 120 112 116 109 124 108 119 110 124 101 136 121 110 113 122 103 120 110 98 103 121 105 124 118 118 101 116 111 118 124 128 115 108 118 105 154 114 129 115 102 118 126 119 118 105 110 129 105 128 133 102 109 101 101 111 112 100 120 97 123 118 107 116 110 94 90 103 127 109 137 98 98 119 106 113 107 109 109 117 114 108 134 96 107 120 88 113 98 101 109 93 109 118 124 107 108 100 110 122 124 127 124 110 113 116 126 113 103 116 115 115 137 93 127 124 109 121 134 110 132 118 119 110 104 104 116 109 103 122 107 119 125 98 113 113 116 132 115 125 110 115 120 101 122 107 121 98 100 125 128 92 117 117 115 122 123 123 113 119 103 102 111 113 114 123 109 97 127 114 98 110 104 108 132 106 131 115 120 116 132 118 126 128 141 110 124 135 114 101 87 121 115 116 120 104 106 117 112 105 118 110 103 131 128 114 104 111 99 104 128 117 110 127 121 109 126 128 109 107 120 118 97 118 102 120 122 117 120 129 110 115 106 115 123 104 117 101 127 113 114 104 129 109 113 118 113 128 111 113 116 109 107 115 131 133 105 129 135 133 118 118 135 107 116 117 99 103 119 111 115 112 105 106 118 120 101 140 103 101 127 117 120 128 114 114 102 120 112 140 97 116 119 125 109 101 117 131 122 116 127 98 110 117 114 122 119 105 98 127 124 125 121 118 103 114 124 124 132 111 117 117 126 111 112 127 110 106 122 128 133 116 115 101 121 126 121 120 109 138 101 114 117 103 101 110 121 143 122 100 96 107 109 116 126 120 103 103 119 121 110 125 125 129 106 127 107 143 109 113 117 108 126 113 117 128 116 99 121 105 106 99 129 115 113 115 119 107 116 129 127 131 108 138 117 116 111 97 117 118 103 109 114 141 109 104 112 115 124 133 122 131 116 112 122 106 100 115 109 108 106 106 124 97 124 102 109 107 114 102 105 106 92 104 108 122 122 102 125 108 116 101 133 115 122 106 131 122 101 133 139 126 111 132 114 112 92 95 127 96 123 112 116 126 125 140 124 115 129 105 117 111 117 123 100 114 102 114 130 123 108 109 123 122 125 139 117 97 103 103 125 129 140 143 121 107 113 113 96 100 127 117 109 119 124 146 115 131 123 115 123 132 127 132 125 125 114 125 115 85 127 101 99 123 119 113 124 109 122 120 108 129 137 129 127 103 116 117 117 151 129 129 115 133 130 120 143 105 126 104 113 129 130 103 121 96 143 130 109 132 125 120 132 114 89 112 102 117 127 135 112 122 103 100 123 110 110 120 118 117 95 106 130 104 110 111 115 105 121 109 116 133 120 114 103 110 111 107 121 117 138 118 126 129 108 125 103 111 110 102 127 109 124 120 125 109 125 99 111 102 111 125 105 119 111 109 134 123 116 106 115 122 121 113 115 100 103 108 111 106 123 117 121 113 98 115 110 120 117 100 123 113 117 109 119 130 131 96 122 107 100 112 122 112 125 91 118 124 119 104 135 108 101 126 112 122 114 117 101 100 108 111 103 102 109 129 97 121 97 109 98 100 127 123 110 98 113 126 117 110 107 127 105 122 119 93 111 109 110 114 115 101 131 98 98 111 90 134 113 122 114 98 125 134 104 101 100 125 115 105 102 122 104 127 101 120 110 113 122 112 123 105 107 128 115 122 119 127 100 119 95 95 111 96 104 119 106 111 116 117 103 121 136 98 107 110 116 95 92 123 118 118 85 111 130 116 93 123 99 114 127 110 104 100 98 109 117 124 127 114 122 98 112 92 110 112 113 125 119 101 113 109 112 114 100 109 118 113 117 126 109 111 98 111 124 112 128 113 118 119 101 134 98 101 111 123 103 114 113 114 112 101 121 99 102 147 123 121 117 126 118 105 120 112 102 117 112 106 124 120 116 122 111 99 109 136 105 117 106 99 110 103 125 113 115 125 95 118 126 100 116 127 111 113 117 123 106 116 103 116 116 117 121 121 122 107 96 119 107 119 127 144 94 138 115 110 108 121 113 128 110 113 109 126 101 117 111 116 97 97 131 116 143 123 132 98 110 108 120 108 115 122 114 117 96 116 118 111 101 107 110 109 115 107 106 116 89 106 126 113 129 97 121 104 108 116 119 93 106 119 135 133 110 82 116 109 125 108 93 117 120 125 127 112 129 116 122 109 92 103 109 126 124 112 133 93 96 114 102 118 101 114 125 107 115 119 102 114 113 124 106 115 101 91 111 119 109 105 101 101 116 123 119 103 118 87 113 115 112 115 116 132 104 112 108 105 110 103 126 106 133 110 122 111 107 123 113 107 106 119 99 123 104 102 114 100 136 112 115 110 105 98 103 112 121 116 116 107 111 99 128 98 109 115 114 114 113 101 122 107 117 115 116 123 125 107 112 124 121 103 125 113 123 108 93 97 119 108 118 102 120 125 121 111 106 108 121 97 107 117 114 109 96 132 113 135 126 112 117 95 122 105 107 125 98 128 109 101 106 108 121 122 113 113 114 111 122 130 108 122 127 128 101 123 111 126 104 109 124 110 118 117 115 123 107 103 107 101 116 121 112 102 121 78 105 102 107 119 120 101 107 115 112 92 102 101 109 107 96 112 131 110 112 107 94 125 119 119 124 119 111 128 99 98 137 103 115 105 121 116 103 126 105 123 126 98 94 114 126 110 125 96 99 107 111 125 97 90 130 104 116 106 102 108 119 128 106 120 108 109 118 119 108 110 118 101 97 144 115 105 125 127 117 111 102 108 136 104 97 115 105 134 116 109 114 118 99 108 91 89 122 106 104 125 115 120 100 101 121 97 113 120 104 103 111 120 106 121 105 118 113 121 135 109 108 114 107 98 121 106 113 111 111 94 116 97 115 93 120 123 106 108 92 120 91 101 109 107 134 117 109 113 99 116 101 104 105 111 127 101 124 103 114 87 135 121 106 106 125 99 84 98 109 91 116 106 99 123 105 99 120 98 127 135 95 111 115 125 125 141 117 111 124 111 118 107 113 105 101 108 120 99 109 123 100 112 111 105 115 113 113 99 93 98 109 104 98 116 122 112 117 102 99 113 115 122 109 105 114 123 127 114 123 103 109 101 129 119 113 115 129 122 106 112 108 108 111 98 112 107 117 121 96 120 112 107 124 98 105 121 107 106 105 108 105 113 114 122 112 119 122 110 93 97 109 122 121 118 108 106 104 107 124 120 105 111 94 109 107 139 108 117 98 104 106 111 95 113 111 116 107 109 117 106 117 133 123 121 123 103 103 107 97 110 100 141 133 111 121 120 106 107 124 112 121 115 112 101 115 93 95 93 99 106 123 123 94 114 102 110 115 122 105 121 110 103 116 115 109 125 120 119 112 112 103 111 122 111 120 125 101 89 113 104 119 107 131 116 100 114 115 124 122 104 118 96 118 105 122 125 115 121 112 110 103 109 111 100 119 113 102 121 118 108 118 99 117 120 114 125 98 89 105 113 118 125 98 121 103 99 118 116 92 111 106 124 99 109 105 107 115 116 116 107 119 98 124 105 106 109 103 122 103 111 118 109 127 117 108 131 121 121 127 110 118 117 131 134 111 98 127 127 128 108 124 84 107 99 121 102 119 113 113 116 119 125 134 97 105 111 120 114 118 102 122 104 99 122 121 106 105 103 98 106 107 105 105 113 115 109 92 129 114 131 106 120 135 118 113 95 110 104 124 128 106 117 96 119 127 102 129 99 119 129 112 112 101 97 116 117 114 119 107 91 112 121 117 116 101 103 103 126 132 94 111 123 114 98 109 122 106 92 95 115 106 113 121 102 88 110 98 105 118 109 114 106 124 110 119 120 97 124 115 102 126 108 120 100 117 90 100 119 107 108 117 129 100 120 112 109 100 114 109 117 101 107 96 116 125 115 120 115 123 108 109 114 115 122 122 101 95 105 120 100 125 114 123 131 118 105 132 99 94 117 110 85 108 127 103 107 112 113 107 107 103 112 119 126 89 118 107 113 110 94 115 105 108 107 105 137 113 118 110 97 113 113 110 82 104 113 106 103 112 115 96 111 97 104 126 122 130 99 118 98 114 105 123 98 129 110 92 99 118 117 108 131 99 119 97 125 112 105 125 110 117 111 112 113 138 117 112 116 107 125 104 119 100 99 138 109 111 122 131 100 110 114 117 94 121 121 116 115 108 106 116 116 116 112 112 108 107 111 91 107 112 119 138 130 122 134 109 106 125 126 113 111 103 120 104 133 104 114 108 118 124 96 98 118 121 99 119 111 91 113 105 128 92 123 99 126 119 109 91 114 117 107 127 107 107 104 119 119 123 123 123 122 87 109 110 111 105 116 96 118 116 111 104 95 107 124 122 125 110 108 117 109 101 110 119 102 102 112 114 109 118 114 107 99 114 119 99 118 103 131 122 105 116 118 127 113 119 119 132 104 110 93 120 102 110 114 87 127 123 119 113 136 99 129 116 116 119 116 128 129 114 125 105 125 112 114 135 115 114 120 135 114 113 123 113 104 100 114 119 96 124 129 112 113 96 100 141 132 113 112 117 106 122 113 117 126 107 115 109 124 112 116 118 106 108 109 95 109 102 105 121 100 103 108 127 124 117 122 129 110 115 111 106 105 118 125 123 109 114 110 106 111 124 92 100 107 110 102 109 121 114 118 114 126 115 99 106 87 128 101 111 121 131 125 101 105 139 121 125 112 119 136 104 109 100 94 109 111 115 123 120 120 114 100 112 109 138 129 111 131 121 131 113 106 121 124 114 102 111 123 107 90 94 114 119 106 94 123 139 108 148 96 103 111 100 103 126 101 105 116 113 116 117 108 114 125 111 111 103 128 110 123 109 101 126 106 120 117 115 110 128 89 122 111 112 115 109 129 126 110 119 99 131 111 96 108 106 106 111 112 99 122 118 120 102 112 113 98 104 100 110 106 110 134 101 104 117 121 117 106 111 101 116 94 107 115 106 134 107 115 118 125 112 101 128 108 107 122 120 95 123 115 121 123 99 102 124 106 106 129 101 108 105 109 108 120 137 112 120 95 113 121 100 105 110 111 127 119 126 112 123 115 112 107 100 102 125 126 115 111 107 127 108 115 100 119 115 113 110 115 117 115 122 105 99 125 121 120 113 113 137 104 127 130 120 133 129 141 125 112 139 120 112 135 122 124 127 124 127 123 125 111 129 121 119 123 145 130 139 115 113 101 130 133 143 123 132 104 134 125 129 135 121 126 119 132 140 123 131 128 130 133 131 126 127 112 143 114 123 119 128 128 138 127 134 121 119 107 127 144 119 129 121 129 122 127 139 116 117 99 145 103 112 101 119 136 108 116 127 119 121 129 109 118 123 104 122 127 89 110 111 105 125 131 102 105 119 107 117 110 135 109 104 115 131 119 104 119 109 118 112 110 120 108 110 115 118 115 109 100 123 105 137 118 109 126 113 106 99 107 109 115 128 109 125 133 109 104 120 113 116 104 116 127 125 112 115 114 104 111 128 102 108 100 105 111 81 135 112 103 113 103 123 116 112 96 123 110 97 123 114 118 101 102 91 125 104 110 111 129 111 108 114 98 103 108 119 132 126 101 121 128 116 109 100 132 100 98 119 107 128 113 113 111 111 132 117 105 109 122 114 110 117 129 110 89 111 133 100 100 89 113 105 99 91 122 97 95 130 99 109 116 104 111 125 103 101 108 133 111 106 112 99 103 115 113 101 99 92 113 109 111 116 122 111 117 111 97 116 111 101 119 112 128 106 110 107 93 112 105 123 116 102 104 120 115 113 96 107 108 94 101 116 112 110 119 122 116 119 114 123 128 96 111 102 103 131 106 106 102 90 116 120 133 107 106 121 99 120 105 110 115 110 102 120 114 98 107 116 126 109 117 136 126 95 104 116 104 103 135 82 123 102 122 123 112 126 114 119 103 110 101 112 125 103 95 113 105 94 116 117 113 115 102 106 103 106 131 108 119 111 108 105 114 111 114 92 100 113 129 130 123 105 121 114 115 107 114 116 109 105 107 115 107 105 113 109 116 97 115 123 122 111 120 111 119 116 113 113 91 101 120 100 101 110 109 107 120 111 99 119 116 101 110 105 121 110 107 113 118 128 108 104 118 103 127 112 91 108 118 106 107 123 91 114 116 105 134 116 117 128 105 102 102 103 125 121 97 114 102 113 104 137 114 98 123 128 125 119 102 108 92 109 97 113 104 113 123 118 101 116 104 124 117 136 126 95 107 106 122 116 124 80 106 84 114 112 105 104 133 113 134 125 94 110 130 105 96 115 121 119 117 102 125 111 106 111 119 116 113 129 118 107 96 116 116 110 119 124 136 117 108 128 116 110 103 108 119 122 110 121 115 133 102 93 114 123 107 128 90 124 110 111 117 106 125 116 129 106 110 127 103 110 102 114 117 102 115 114 121 118 126 115 101 105 104 116 123 116 118 108 113 105 118 101 121 116 90 111 124 118 117 102 106 104 113 116 124 111 122 106 100 100 90 118 104 118 107 127 119 115 123 108 125 105 100 118 111 119 89 98 132 129 119 105 103 111 137 109 104 96 112 102 108 101 103 125 96 119 109 124 102 124 119 101 125 99 119 112 107 123 104 93 104 111 122 105 107 119 135 116 106 118 120 101 105 111 127 121 101 112 114 102 96 129 96 117 126 110 101 101 130 115 94 103 106 117 108 112 107 113 104 109 117 110 104 114 110 108 126 91 87 108 82 108 86 109 117 106 113 121 107 117 111 119 95 110 111 111 112 131 112 99 108 112 112 106 113 102 97 109 111 113 122 124 116 111 116 109 89 113 88 99 104 111 84 112 115 104 110 87 117 105 94 110 117 96 90 103 123 118 108 114 105 106 116 101 88 114 101 96 104 98 108 113 104 110 108 89 94 116 122 103 119 92 135 110 110 129 100 110 105 125 104 123 124 92 116 101 109 111 98 99 118 114 113 115 105 100 124 96 94 100 98 84 94 124 95 92 102 103 121 117 102 115 120 113 109 99 103 113 121 96 110 107 119 106 98 91 111 93 95 112 114 113 108 119 119 119 112 112 110 103 91 97 109 103 113 89 95 98 98 107 96 98 108 125 114 102 111 105 110 121 115 92 125 111 95 113 126 125 103 107 99 115 110 102 112 126 103 104 96 108 109 113 130 96 115 114 97 99 95 98 127 106 94 116 115 106 113 106 120 134 117 90 120 116 89 112 91 104 95 99 102 114 118 97 98 75 98 100 92 118 101 109 103 112 101 126 115 96 125 115 87 101 119 100 124 111 106 124 97 140 117 108 95 115 93 95 123 130 97 105 109 114 101 95 120 121 107 103 100 104 113 97 108 98 125 101 111 107 98 106 117 123 107 103 123 95 123 93 118 117 103 108 107 115 108 91 112 114 113 107 115 80 115 94 124 92 123 97 99 109 106 117 103 114 100 111 106 114 98 109 107 109 121 104 107 94 120 126 103 106 103 109 107 112 115 99 109 97 104 112 93 116 117 104 112 122 110 108 101 117 120 98 99 102 116 121 116 98 117 96 106 123 104 104 105 126 84 113 92 110 120 97 93 108 104 113 100 100 87 142 103 111 98 105 107 100 114 88 116 127 106 114 99 102 121 99 106 111 100 120 110 110 114 104 104 121 105 112 105 98 104 115 89 113 124 99 87 114 127 114 112 111 104 105 112 112 103 104 100 113 121 92 103 93 95 89 109 104 107 111 107 89 101 112 115 107 94 115 108 99 112 122 107 88 108 105 106 125 96 118 103 100 115 87 99 125 121 91 112 120 98 113 124 108 119 102 114 100 112 119 104 101 94 99 108 130 118 92 119 112 110 99 115 96 104 84 113 104 112 117 106 96 99 103 105 105 92 119 99 92 104 108 90 102 108 124 112 118 94 113 106 99 106 98 86 97 94 113 95 99 107 115 104 115 117 106 105 117 107 92 87 99 119 114 110 97 100 108 114 114 128 100 106 113 99 105 99 111 110 104 107 102 108 105 104 107 107 95 117 115 101 100 86 121 94 110 111 114 119 106 114 122 108 97 108 101 110 100 119 89 129 103 111 99 102 117 111 117 114 100 116 99 110 111 115 109 92 109 116 104 93 99 112 109 132 110 102 86 109 115 84 100 116 98 118 111 93 107 106 109 120 116 114 95 107 86 107 90 104 111 107 96 93 100 101 133 95 108 109 124 115 110 106 118 117 106 109 114 108 109 107 118 110 104 118 119 102 95 91 119 113 93 94 99 104 113 116 109 120 111 106 122 111 115 112 109 104 121 117 94 98 104 117 106 108 92 126 109 116 125 118 106 108 111 96 94 102 109 107 95 117 108 113 119 118 127 105 108 132 86 100 105 112 119 109 118 110 115 125 122 113 106 99 97 88 103 107 120 94 88 113 112 115 135 107 104 114 111 109 111 106 114 98 96 95 123 107 120 97 97 108 120 127 120 124 112 103 115 100 108 112 108 118 106 114 95 103 97 118 100 116 133 114 102 107 90 106 112 113 110 109 106 113 114 107 109 115 110 97 103 125 118 93 119 121 117 113 102 100 115 99 105 93 109 110 93 91 118 119 111 92 117 121 135 135 100 110 108 101 122 97 100 104 122 101 92 113 127 104 121 103 122 87 115 105 106 109 131 121 112 109 144 110 124 123 115 114 108 110 107 111 104 124 93 125 110 100 128 102 124 133 104 88 112 126 113 95 114 106 102 118 90 112 114 108 115 118 102 106 109 103 96 100 111 114 123 99 107 93 115 116 113 123 104 134 105 111 130 125 112 113 93 94 100 121 101 125 109 127 102 98 101 93 102 120 114 120 106 117 119 119 103 113 89 109 96 106 104 102 99 112 112 117 120 126 122 120 113 110 97 125 118 118 124 138 114 112 126 119 115 113 130 115 108 130 101 120 107 117 108 117 110 115 108 111 127 99 104 105 130 92 91 120 112 105 117 120 110 115 111 103 115 130 105 105 116 98 110 124 131 110 105 99 121 105 99 124 134 116 135 100 117 130 107 104 95 112 111 114 117 108 125 102 130 103 134 125 112 121 142 112 118 123 111 102 96 121 112 111 110 115 124 134 117 117 133 93 120 107 124 120 125 115 110 127 124 119 121 113 100 101 106 111 128 116 122 112 104 115 100 111 87 114 120 124 107 111 106 116 122 118 92 116 121 100 118 115 102 111 110 105 100 107 117 122 114 103 107 97 108 113 116 96 94 105 120 108 114 103 113 113 97 124 102 98 124 115 128 132 128 116 105 105 100 102 102 120 109 110 135 104 99 100 102 130 117 93 103 90 130 105 110 105 111 134 105 101 115 137 120 105 106 117 117 111 126 108 98 112 108 110 118 112 123 114 118 115 114 111 119 114 135 126 116 114 128 117 107 97 112 109 111 101 111 131 116 111 109 113 117 119 114 115 119 98 113 110 116 86 114 114 102 123 110 110 102 107 115 113 110 103 102 104 100 106 114 107 114 127 121 103 110 127 137 96 104 99 125 103 100 105 98 105 107 127 101 137 113 112 100 118 116 113 129 108 101 133 107 123 128 99 99 106 99 107 123 126 87 114 109 123 125 109 115 103 95 106 120 117 117 125 101 122 121 111 126 99 100 99 114 127 112 103 120 116 113 117 112 123 102 107 94 96 117 123 103 111 117 98 107 106 93 119 99 94 98 115 115 109 124 100 86 111 102 116 106 132 95 95 98 92 110 117 124 99 95 109 100 92 124 110 103 106 102 128 123 121 97 116 101 121 94 115 109 82 106 91 119 106 122 101 118 106 121 96 95 96 129 117 109 105 104 107 114 112 99 93 132 109 109 82 102 109 102 110 114 116 117 111 119 113 97 116 112 126 104 114 131 138 117 115 99 92 105 89 101 110 99 126 100 99 111 103 113 107 112 99 112 103 105 108 99 99 112 97 95 98 112 118 109 124 95 96 110 105 137 103 110 116 109 105 110 122 109 122 93 118 116 110 96 108 105 112 99 116 107 103 95 98 106 99 119 113 109 107 106 102 105 108 133 100 105 107 117 115 104 101 115 109 88 106 107 107 115 86 101 98 120 109 112 118 114 114 110 107 113 107 110 118 97 120 94 111 119 120 108 119 111 130 97 105 105 93 121 114 102 131 107 91 106 112 127 112 119 99 101 102 114 112 112 141 104 111 112 101 114 122 103 108 120 96 105 121 106 123 100 119 108 88 104 93 101 113 95 106 99 88 106 102 108 130 111 104 113 120 126 116 103 104 122 115 106 109 113 117 97 111 127 117 106 118 121 127 104 133 116 119 104 103 106 93 109 106 99 114 99 109 106 114 106 108 103 107 101 110 115 115 100 115 115 103 105 106 115 102 104 129 124 121 100 94 105 106 106 123 121 114 115 98 110 118 130 119 106 98 116 111 107 125 104 89 89 100 115 114 102 110 129 113 100 103 116 115 115 118 114 102 114 109 90 123 96 127 125 104 109 115 110 101 116 109 107 108 112 118 93 98 117 118 115 112 108 92 116 100 81 123 100 113 111 109 86 125 110 110 118 97 111 108 133 102 115 116 131 119 94 123 121 94 101 115 117 107 120 108 112 124 112 112 108 102 114 114 92 119 117 85 123 110 125 119 121 121 127 113 95 109 84 125 120 125 112 99 101 105 121 118 115 99 121 121 110 116 114 106 117 105 108 121 96 117 118 113 123 114 95 106 118 110 107 110 103 118 109 121 116 100 98 117 120 131 108 123 110 107 119 116 123 95 117 123 101 95 110 88 100 112 101 98 100 121 99 109 122 108 105 106 99 115 113 96 87 120 116 91 120 117 102 100 90 109 128 120 126 108 106 86 107 104 99 124 107 113 116 124 113 129 105 106 100 99 103 109 112 104 105 102 122 116 115 115 109 107 113 103 111 108 113 92 101 117 110 110 109 112 104 113 110 120 97 111 116 102 119 111 106 116 127 113 103 106 114 114 103 125 122 134 111 132 95 107 114 118 98 117 131 101 115 101 89 115 116 111 128 110 105 102 118 108 122 100 106 116 107 100 98 113 101 105 117 104 88 104 106 105 101 113 119 107 112 114 121 120 115 124 105 113 114 107 112 103 111 124 103 91 92 120 111 128 111 116 110 115 119 116 105 119 105 112 114 123 91 87 114 120 115 120 109 93 111 102 98 111 103 99 113 126 123 120 89 106 102 117 100 115 108 117 114 112 112 114 132 125 114 110 99 99 103 113 112 91 106 118 118 100 129 104 104 109 116 105 92 125 97 119 94 104 121 111 104 116 130 127 123 128 123 99 113 113 86 125 105 131 117 135 104 126 106 120 100 100 110 105 118 94 131 113 114 103 116 99 108 101 110 114 109 88 110 126 105 126 118 111 109 108 95 103 102 120 127 124 119 119 107 118 113 98 115 120 136 104 109 111 113 127 120 133 119 108 120 115 124 112 97 101 104 111 114 92 96 107 103 107 114 108 117 115 114 105 108 109 109 113 102 101 100 110 120 123 104 117 98 109 116 98 120 118 118 102 121 104 106 118 100 118 110 101 113 120 111 119 115 130 99 125 121 123 92 131 124 116 105 109 97 113 115 109 122 108 110 110 108 127 114 107 115 108 100 115 93 111 123 105 98 111 117 99 103 109 116 101 94 105 101 118 113 104 134 106 115 109 111 115 108 122 112 122 119 99 114 104 96 116 115 99 111 111 102 107 113 121 117 122 124 118 112 108 117 102 130 107 97 134 109 127 115 108 112 117 110 123 98 101 134 119 103 95 113 112 112 128 105 129 99 103 100 124 97 114 110 109 120 117 131 105 114 122 108 107 121 123 137 131 109 133 112 89 122 103 101 110 121 96 98 116 107 137 105 124 107 122 111 120 116 116 108 118 117 120 123 125 109 107 122 122 92 99 116 100 111 125 123 117 100 104 130 122 103 116 117 122 107 103 110 105 123 119 119 98 143 114 108 125 143 136 101 119 107 125 97 117 106 104 116 90 119 121 123 113 130 102 111 94 121 123 115 110 108 103 125 124 109 112 113 107 126 106 100 112 124 130 110 103 104 108 103 122 126 119 101 112 90 114 114 122 113 105 111 114 107 115 101 121 111 116 109 129 109 113 124 103 121 103 99 111 135 121 115 98 97 102 127 115 116 122 111 96 112 126 115 96 120 118 92 98 102 122 93 103 105 109 118 132 118 107 99 125 110 105 127 117 109 115 109 118 105 118 131 96 96 150 97 118 111 101 136 134 119 120 106 127 110 96 113 118 92 108 107 127 106 99 114 100 129 108 115 118 117 91 111 97 108 121 111 117 104 114 116 123 89 124 102 116 113 114 119 131 115 117 102 126 124 125 116 109 108 111 100 112 120 121 112 112 124 91 109 111 100 111 105 113 118 112 134 117 125 121 128 134 120 105 110 115 117 105 115 94 124 114 110 110 105 109 109 119 106 114 105 125 118 105 133 105 101 113 127 98 127 117 116 86 125 113 102 118 114 140 112 114 101 111 104 117 118 117 101 109 136 117 128 132 99 116 112 127 108 121 110 97 99 127 108 105 101 107 114 103 122 99 120 110 130 105 121 103 111 111 117 114 110 111 99 107 113 91 99 113 111 109 106 127 104 113 111 119 106 114 110 122 95 137 117 128 95 117 120 119 116 110 120 113 106 126 126 129 115 112 105 110 116 114 110 114 97 119 120 116 130 107 111 109 107 113 122 109 107 86 108 112 99 102 103 139 125 117 108 120 129 115 115 114 119 125 110 101 120 135 118 110 120 96 125 119 117 120 123 115 100 112 106 126 113 114 114 114 111 130 122 114 127 123 131 126 103 110 138 117 115 119 114 128 108 120 115 127 123 124 111 115 119 119 114 116 113 119 103 119 109 119 115 132 115 108 104 116 119 115 115 122 117 112 93 143 98 106 104 115 115 125 115 123 127 122 100 120 128 104 115 124 115 138 98 119 120 122 113 112 111 131 118 114 117 139 136 120 126 142 137 120 117 117 125 108 117 149 130 121 106 125 106 129 110 121 125 130 119 125 118 122 128 96 123 125 121 115 129 116 115 113 141 137 132 126 135 124 110 113 111 138 127 132 128 126 123 105 115 115 125 126 99 120 129 114 136 125 119 116 120 127 132 119 114 124 122 117 123 98 113 102 111 139 111 117 118 104 106 119 142 118 115 105 123 109 108 103 138 110 115 120 107 134 102 110 109 127 123 109 110 105 111 137 98 118 113 109 136 118 120 111 128 124 110 142 113 107 117 116 112 128 101 109 129 112 115 100 129 93 116 136 115 97 126 116 112 102 100 130 119 113 109 104 114 116 103 129 112 130 107 103 123 134 106 126 110 120 108 133 120 103 126 109 119 101 123 90 126 111 123 109 109 101 122 132 123 117 102 115 123 102 119 105 102 118 122 129 108 111 116 113 124 119 128 106 127 119 116 113 114 124 105 120 102 107 116 122 118 117 116 114 107 123 125 97 95 112 108 112 135 118 107 94 111 104 132 127 109 117 111 91 109 123 102 122 111 114 113 116 119 105 122 105 130 124 122 127 104 109 128 114 114 123 125 111 113 106 125 115 130 109 129 106 116 118 115 109 119 108 120 109 106 99 127 135 118 87 127 104 127 102 98 119 100 122 106 99 118 101 108 99 124 115 121 113 118 120 101 108 117 116 131 114 117 118 115 89 129 119 126 125 129 92 101 110 98 108 106 96 135 115 120 124 118 99 125 119 106 123 111 107 114 119 112 110 103 111 96 93 107 102 129 125 99 113 120 119 107 103 119 119 107 119 104 108 103 131 121 103 108 114 104 101 124 106 137 102 114 107 115 100 129 110 105 117 112 116 116 101 127 115 114 124 126 119 94 116 96 119 106 122 121 112 110 120 111 136 133 118 132 110 132 103 107 115 101 120 112 145 96 104 118 103 113 111 115 100 110 99 127 116 112 125 110 119 116 98 125 106 125 119 116 112 118 100 114 123 117 98 120 114 110 113 104 115 103 96 107 119 109 118 111 94 102 114 116 109 110 116 123 96 108 108 97 110 136 117 123 122 113 114 116 134 115 94 106 105 99 123 121 124 112 103 133 121 120 123 112 96 118 106 105 111 129 122 128 116 123 136 110 91 101 111 115 110 93 104 113 129 119 116 96 107 109 105 101 104 108 115 124 97 136 117 104 104 96 101 117 112 134 124 125 110 103 132 118 108 115 130 113 102 119 127 110 105 111 116 118 101 98 133 131 114 115 96 117 113 113 108 88 109 117 110 119 106 127 144 114 118 109 125 108 97 121 118 98 108 118 115 101 117 104 100 123 108 118 125 121 114 109 113 111 103 109 110 106 104 100 114 110 129 110 121 99 98 119 122 116 107 118 130 105 111 117 96 120 119 102 96 127 107 129 127 109 105 108 120 118 105 115 128 100 112 111 106 101 115 122 117 105 99 104 101 107 97 116 115 129 102 129 116 119 107 106 115 114 99 110 118 117 112 126 124 119 94 99 126 130 120 108 119 113 138 105 108 107 130 106 109 128 116 118 103 96 130 122 118 117 87 120 127 97 120 100 103 115 111 97 105 100 135 115 124 100 110 121 117 97 119 118 113 123 93 109 119 100 115 111 122 119 106 112 93 111 111 109 120 106 134 117 106 113 111 104 95 102 106 99 105 119 107 97 108 120 98 100 115 94 129 120 116 120 87 116 110 109 110 111 120 91 101 104 110 101 118 96 95 82 117 99 113 132 86 114 91 122 116 117 114 104 119 120 117 110 123 92 140 116 124 115 100 115 124 112 103 101 109 127 110 115 85 107 112 100 106 112 111 108 111 109 113 131 126 119 126 112 107 116 124 104 103 111 119 113 91 108 118 108 109 127 99 133 102 109 122 135 91 120 105 121 94 110 108 118 123 109 116 122 105 120 111 112 112 115 93 126 128 108 119 114 124 120 125 99 117 130 130 109 116 101 97 120 117 109 100 98 120 115 122 110 119 112 121 126 108 105 127 108 100 139 109 121 113 93 121 128 117 110 106 103 103 108 119 117 104 111 123 120 102 97 110 115 120 100 112 114 103 109 119 111 125 118 129 93 105 108 101 116 106 93 100 121 122 105 116 115 106 96 129 121 119 128 100 123 109 125 98 120 110 123 104 107 127 128 122 110 106 133 107 101 127 125 120 116 115 97 110 108 86 144 93 94 114 112 94 119 118 120 114 113 126 113 123 102 96 116 118 103 113 120 113 136 86 119 122 124 113 112 120 114 105 104 105 121 116 130 103 118 87 121 133 124 124 107 112 102 120 110 103 101 108 122 110 109 113 117 117 106 108 102 90 101 98 105 98 110 113 127 102 112 113 102 106 107 127 112 120 106 112 115 102 124 102 120 111 129 105 109 126 119 125 117 114 131 118 100 119 110 134 126 112 95 121 100 98 102 97 98 107 105 122 107 102 96 124 109 115 115 104 109 116 111 122 116 131 111 132 115 116 114 106 114 118 92 96 116 117 94 115 108 121 111 120 103 100 119 120 97 107 113 111 127 113 115 122 131 99 115 98 111 96 120 99 112 133 114 127 86 123 117 118 94 108 108 100 122 111 109 123 116 112 111 97 98 100 111 122 117 102 120 108 109 107 102 129 130 125 106 100 104 109 114 92 106 115 122 104 98 104 114 104 107 108 107 146 103 103 123 103 104 109 122 101 102 93 109 117 108 108 118 108 107 114 104 93 104 106 115 91 113 110 107 105 110 112 112 101 134 122 114 116 110 114 122 106 106 117 118 125 112 115 90 103 96 119 122 107 98 130 128 109 99 112 95 113 118 107 97 94 115 93 99 100 121 113 84 121 126 124 88 108 111 123 120 114 101 102 111 109 118 117 97 102 111 128 125 112 120 94 106 137 113 110 107 117 130 109 117 112 112 98 119 99 104 123 108 131 125 106 102 128 115 118 92 98 105 110 110 95 111 126 108 99 106 113 123 101 95 114 105 106 124 119 106 121 111 120 98 127 100 101 113 122 101 115 98 104 114 120 106 115 131 110 114 103 114 111 119 117 108 126 106 98 110 107 117 111 106 111 117 111 113 117 102 117 110 105 104 122 129 109 98 113 121 94 105 120 109 107 100 121 91 121 111 102 108 119 92 99 112 106 115 111 126 91 100 117 114 130 104 103 100 97 105 106 109 123 111 101 103 100 97 112 95 111 110 103 97 122 115 121 112 117 114 108 105 109 114 118 130 109 104 119 108 118 105 113 115 104 103 115 122 102 123 123 112</counts>
			</dataPoints>
		</scan>
	</xrdMeasurement>
</xrdMeasurements>