File: data/XRD/XG-Sauerstoff/XG-800/W6822-1B_XG_Sauerstoff_800.xrdml
<xrdMeasurements xmlns="http://www.xrdml.com/XRDMeasurement/2.1" xmlns:xsi="http://www.w3.org/2001/XMLSchema-instance" xsi:schemaLocation="http://www.xrdml.com/XRDMeasurement/2.1 http://www.xrdml.com/XRDMeasurement/2.1/XRDMeasurement.xsd" status="Completed">
	<comment>
		<entry>Configuration=Factory configuration, Owner=User-1, Creation date=7/8/2013 4:01:53 PM</entry>
		<entry>Goniometer=PW3050/65 (Theta/2Theta); Minimum step size 2Theta:0.0001; Minimum step size Omega:0.0001</entry>
		<entry>Sample stage=MRD Cradle; Minimum step size Phi:0.01; Minimum step size Chi:0.01; Minimum step size X:0.01; Minimum step size Y:0.01; Minimum step size Z:0.001</entry>
		<entry>Diffractometer system=XPERT-PRO</entry>
		<entry>Measurement program=C:\PANalytical\Data Collector\Programs\Jorrit\2thom\_absolute_2th-om_10-130deg_PIXscan_56min.xrdmp, Identifier={15BCCF57-2807-42BD-B5B9-ECC0B3DC9284}</entry>
		<entry>Batch program=C:\PANalytical\Data Collector\Programs\SimonL\batch4x_2thom_10-130°_z9.1_x0,10,20,30_y0_57min.xrdmp, Identifier={EED9823A-2BEB-424C-9252-345C4EF2834A}</entry>
	</comment>
	<sample type="To be analyzed">
		<id></id>
		<name></name>
		<preparedBy></preparedBy>
	</sample>
	<xrdMeasurement measurementType="Scan" status="Completed" sampleMode="Reflection">
		<comment>
			<entry>_absolute_2th-om_10-130deg_PIXscan_56min</entry>
			<entry>PHD Lower Level = 4.83 (keV), PHD Upper Level = 11.27 (keV)</entry>
		</comment>
		<usedWavelength intended="K-Alpha 1">
			<kAlpha1 unit="Angstrom">1.5405980</kAlpha1>
			<kAlpha2 unit="Angstrom">1.5444260</kAlpha2>
			<kBeta unit="Angstrom">1.3922500</kBeta>
			<ratioKAlpha2KAlpha1>0.5000</ratioKAlpha2KAlpha1>
		</usedWavelength>
		<incidentBeamPath>
			<radius unit="mm">320.00</radius>
			<xRayTube id="1010048" name="Empyrean Cu LFF HR (9430 033 7310x) DK442154">
				<tension unit="kV">40.0</tension>
				<current unit="mA">40.0</current>
				<anodeMaterial>Cu</anodeMaterial>
				<focus type="Line">
					<length unit="mm">12.0</length>
					<width unit="mm">0.4</width>
					<takeOffAngle unit="deg">4.2</takeOffAngle>
				</focus>
			</xRayTube>
			<xRayMirror id="27010001" name="Inc. Beam Cu W/Si (parabolic MRD)" hybrid="false">
				<crystal type="Graded" shape="Parabolic">W/Si</crystal>
				<acceptanceAngle unit="deg">0.800</acceptanceAngle>
				<length unit="mm">60.0</length>
			</xRayMirror>
			<sollerSlit id="21010002" name="Soller slits 0.04 rad.">
				<opening unit="rad">0.0400</opening>
			</sollerSlit>
			<mask id="22030007" name="Fixed mask 2 mm">
				<distanceToSample unit="mm">220.00</distanceToSample>
				<width unit="mm">2.00</width>
			</mask>
			<divergenceSlit id="22010007" name="Fixed slit 1/8°" xsi:type="fixedDivergenceSlitType">
				<distanceToSample unit="mm">220.00</distanceToSample>
				<height unit="mm">0.19</height>
			</divergenceSlit>
		</incidentBeamPath>
		<diffractedBeamPath>
			<radius unit="mm">320.00</radius>
			<sollerSlit id="21010002" name="Soller slits 0.04 rad.">
				<opening unit="rad">0.0400</opening>
			</sollerSlit>
			<receivingSlit id="22010001" name="Fixed slit 4°">
				<height unit="mm">5.88</height>
			</receivingSlit>
			<detector id="7010017" name="PIXcel3D 1x1 detector" xsi:type="areaDetectorType">
				<phd unit="%">
					<lowerLevel>30.0</lowerLevel>
					<upperLevel>70.0</upperLevel>
				</phd>
				<mode>Scanning</mode>
				<activeChannelsEquatorial>255</activeChannelsEquatorial>
				<activeChannelsAxial>255</activeChannelsAxial>
				<pitchEquatorial unit="mm">0.05500</pitchEquatorial>
				<pitchAxial unit="mm">0.05500</pitchAxial>
				<readOutPeriod unit="seconds">0.135</readOutPeriod>
			</detector>
		</diffractedBeamPath>
		<scan appendNumber="0" mode="Continuous" scanAxis="2Theta-Omega" status="Completed">
			<header>
				<startTimeStamp>2024-09-30T13:08:12+02:00</startTimeStamp>
				<endTimeStamp>2024-09-30T14:04:18+02:00</endTimeStamp>
				<author>
					<name>PRO-MRD</name>
				</author>
				<source>
					<applicationSoftware version="6.1b">Data Collector</applicationSoftware>
					<instrumentControlSoftware version="7.0E 20130304">XPERT-PRO</instrumentControlSoftware>
					<instrumentID>0000000011142674</instrumentID>
				</source>
			</header>
			<dataPoints>
				<positions axis="2Theta" unit="deg">
					<startPosition>9.99826193</startPosition>
					<endPosition>129.99755682</endPosition>
				</positions>
				<positions axis="Omega" unit="deg">
					<startPosition>4.99913096</startPosition>
					<endPosition>64.99877841</endPosition>
				</positions>
				<positions axis="Phi" unit="deg">
					<commonPosition>0.00</commonPosition>
				</positions>
				<positions axis="Chi" unit="deg">
					<commonPosition>0.00</commonPosition>
				</positions>
				<positions axis="X" unit="mm">
					<commonPosition>10.00</commonPosition>
				</positions>
				<positions axis="Y" unit="mm">
					<commonPosition>0.00</commonPosition>
				</positions>
				<positions axis="Z" unit="mm">
					<commonPosition>9.100</commonPosition>
				</positions>
				<commonCountingTime unit="seconds">32.895</commonCountingTime>
				<counts 222 203 214 210 222 224 211 261 235 227 219 209 197 233 226 198 248 211 216 188 217 205 232 208 218 211 218 205 214 198 217 216 261 214 233 196 223 203 218 214 202 228 207 228 181 234 208 224 212 193 202 198 186 195 233 214 209 179 212 212 209 211 222 182 197 219 212 206 216 199 210 226 199 192 192 240 181 216 186 191 200 196 215 187 217 201 203 178 191 190 206 196 213 203 207 203 197 212 189 177 208 205 200 184 191 218 230 207 208 188 196 224 200 210 177 195 225 204 221 195 203 200 222 183 177 204 188 188 185 201 186 195 165 189 203 182 200 185 186 211 206 174 184 201 192 195 217 210 206 196 169 196 222 203 204 186 194 182 203 190 179 214 182 215 203 193 214 180 179 221 184 192 216 210 195 213 227 209 166 184 200 196 170 171 190 173 212 169 188 189 208 178 182 198 211 178 169 200 204 206 183 212 197 200 182 182 186 200 153 184 188 181 188 169 186 191 198 186 189 174 192 186 190 172 209 203 166 196 191 182 183 197 205 177 167 196 194 190 188 197 181 169 174 194 177 169 196 189 198 179 188 185 184 199 185 201 195 181 170 198 171 182 199 185 194 179 174 175 184 221 211 168 162 195 163 191 173 209 176 194 189 166 181 156 166 201 193 168 185 166 176 171 192 171 184 181 191 164 166 174 172 162 171 157 189 176 183 171 207 155 171 159 176 179 190 178 170 180 153 184 147 200 163 158 181 138 161 170 174 169 174 176 165 189 166 193 186 184 198 172 177 190 168 169 175 167 175 154 177 170 182 176 176 196 177 159 154 142 174 172 185 173 167 162 167 175 166 161 171 164 166 175 133 170 188 154 164 183 174 177 153 181 150 171 153 180 167 171 157 160 182 170 162 156 162 169 162 173 178 167 156 188 145 179 158 172 155 163 164 191 170 151 160 167 170 150 179 153 165 190 164 153 164 167 159 162 149 153 157 172 162 165 160 163 176 164 171 167 140 142 160 170 154 167 142 148 177 153 157 144 167 163 152 174 181 149 173 153 148 155 169 163 160 190 157 157 192 146 153 172 171 146 174 160 152 160 156 180 133 144 143 177 155 169 157 167 146 158 146 178 163 159 167 144 191 154 170 167 157 149 145 188 168 181 125 153 158 163 128 138 160 179 164 164 176 167 147 153 155 153 145 169 173 155 158 147 135 154 156 160 152 158 159 163 145 156 149 136 135 154 179 138 133 141 148 150 162 139 133 179 141 159 125 164 150 162 157 137 146 158 182 163 134 160 143 162 153 150 172 140 136 154 140 159 157 160 157 159 122 135 165 146 133 149 156 143 153 151 143 143 167 123 169 163 139 150 148 144 157 161 138 141 145 147 163 155 155 150 149 131 150 138 152 164 160 157 144 165 160 142 145 135 142 165 164 147 140 141 149 148 173 150 145 169 167 156 150 151 128 146 156 146 154 162 145 148 147 164 157 141 139 155 147 155 151 166 144 138 160 143 167 137 163 146 163 156 137 144 162 119 130 144 141 142 170 154 148 119 155 134 168 156 135 148 139 177 139 170 151 170 146 155 144 154 118 147 159 142 134 145 128 143 158 152 163 149 166 149 144 163 134 141 148 153 154 143 159 134 158 156 146 136 154 151 133 155 147 144 153 144 130 145 156 147 159 133 138 143 160 153 130 149 165 141 129 164 130 163 146 150 154 168 125 141 138 143 129 162 125 151 147 138 144 146 150 146 160 157 130 157 143 149 161 143 151 135 160 150 170 145 149 168 146 148 152 140 130 167 154 154 152 145 127 131 130 154 161 151 159 157 148 138 143 151 153 147 151 142 158 143 146 168 157 121 142 156 157 150 165 163 138 136 161 142 158 149 130 139 138 139 132 156 149 155 161 145 140 145 144 146 159 138 155 156 152 137 158 164 160 135 138 121 139 150 130 156 147 137 147 141 146 157 156 142 157 150 135 144 155 144 157 128 140 152 144 138 154 152 139 149 146 146 142 129 145 146 158 137 152 126 132 134 149 151 147 133 136 148 138 140 164 144 125 165 148 155 164 158 134 151 162 148 139 152 143 145 153 156 131 148 149 148 182 154 149 148 181 151 133 138 156 146 140 143 142 150 163 140 140 146 136 140 156 130 149 165 146 168 156 155 142 155 158 152 132 155 146 165 138 155 142 138 148 151 167 162 131 123 162 153 147 150 133 140 158 139 118 144 141 114 131 150 162 165 129 144 144 138 153 164 132 145 163 146 158 147 132 140 167 165 165 134 141 155 134 132 151 139 190 170 129 160 123 162 127 171 162 153 151 147 148 130 186 138 159 165 160 146 141 136 136 149 146 123 146 147 146 173 158 130 166 161 133 138 148 157 141 158 141 130 154 149 140 147 140 164 155 159 139 153 155 145 150 155 160 146 116 143 150 137 128 140 174 128 153 142 147 143 137 152 154 148 155 174 131 166 154 165 154 144 158 148 156 151 154 162 156 164 128 126 140 135 139 147 178 147 156 156 153 149 149 158 166 140 139 162 126 158 144 137 145 140 157 140 144 151 162 145 150 149 145 135 165 160 130 148 157 133 141 133 162 159 144 147 142 134 143 145 131 147 153 160 150 145 155 141 170 149 137 148 145 160 169 146 140 162 173 163 171 134 124 162 152 160 139 150 151 170 158 147 149 147 143 166 135 144 152 143 135 145 132 152 151 153 141 164 138 146 150 157 141 143 120 142 152 145 125 147 147 137 146 158 152 143 142 140 142 137 167 159 124 153 147 132 161 152 154 147 142 175 129 123 145 130 138 168 154 149 150 124 155 146 144 167 149 172 124 156 161 163 145 152 173 141 147 141 162 162 159 157 118 135 148 133 144 166 163 145 152 138 152 151 149 152 162 132 132 143 152 140 160 132 141 154 126 159 153 131 147 140 143 154 143 156 129 143 156 143 153 146 161 158 161 143 161 172 138 126 160 144 138 143 148 158 147 149 146 149 146 133 157 159 142 157 154 146 146 134 143 138 142 164 144 152 151 138 145 143 159 164 154 139 151 159 157 141 145 146 163 151 168 144 151 134 143 164 151 126 155 128 162 161 160 137 154 150 149 166 145 152 154 147 154 176 138 143 138 165 173 157 144 154 137 154 142 159 168 148 159 116 160 141 148 157 145 168 158 142 155 149 148 144 157 141 151 164 158 164 162 161 148 158 136 169 143 153 163 162 168 171 140 147 157 175 157 135 158 146 160 153 150 133 156 165 152 164 172 160 159 134 150 155 165 117 141 158 152 143 159 142 156 134 149 162 172 168 133 144 123 139 159 133 151 142 157 144 161 145 156 143 145 157 134 150 163 145 157 152 137 164 148 122 144 162 141 142 152 123 144 151 158 131 158 154 169 161 146 126 160 155 131 164 180 159 163 151 157 171 135 141 142 142 148 159 165 154 146 155 161 162 153 157 152 149 138 142 158 155 145 161 152 136 165 145 136 161 131 142 161 187 156 180 155 143 158 143 148 137 161 148 132 132 162 145 130 149 138 152 157 142 158 154 151 154 148 156 140 155 160 161 146 148 164 158 142 166 132 158 159 141 148 143 130 148 147 161 166 163 164 150 139 148 165 162 137 139 128 146 136 134 153 140 144 150 161 144 162 143 137 159 132 149 160 161 148 169 159 142 144 135 164 147 142 173 161 156 145 151 143 159 151 149 169 144 151 152 139 167 154 156 149 160 132 154 148 152 162 155 143 136 141 145 150 163 128 166 146 150 170 138 165 156 119 155 147 147 158 156 146 137 127 152 162 150 185 144 142 149 155 161 139 144 149 145 151 165 145 155 141 160 148 139 161 133 133 136 156 137 168 163 157 134 144 135 160 134 140 141 137 141 150 149 156 137 145 155 147 129 155 143 147 151 138 159 130 150 144 165 176 130 155 136 147 156 135 128 145 141 148 149 129 142 145 152 148 153 128 146 134 146 148 166 137 152 157 131 164 146 135 141 139 144 119 166 145 138 148 157 152 145 145 130 153 152 158 148 135 159 147 144 130 143 124 163 163 118 121 145 132 144 136 163 166 126 155 128 147 147 150 150 145 138 140 139 147 123 136 152 176 157 139 149 141 143 138 159 124 130 149 132 130 143 127 134 134 136 134 153 146 136 139 123 138 126 141 157 128 141 145 131 156 131 136 134 157 135 145 146 157 174 156 116 142 141 123 116 165 138 112 155 140 144 183 127 140 131 163 156 133 148 133 133 120 124 151 160 150 147 152 134 151 152 133 142 158 140 135 131 143 131 138 148 126 143 122 129 127 119 147 133 123 135 124 124 136 129 137 136 135 141 119 152 163 123 160 130 122 138 141 140 153 122 147 148 130 121 139 145 145 145 141 129 126 119 139 146 155 155 145 146 137 127 129 126 154 143 144 140 120 125 118 129 110 152 140 130 135 128 130 144 140 134 129 131 132 136 151 132 149 134 140 126 155 159 116 144 128 134 121 127 129 141 133 138 140 148 136 136 122 126 152 120 138 136 141 144 134 140 129 135 134 154 122 137 124 146 129 120 120 147 134 137 135 141 142 131 149 135 134 137 128 153 140 145 136 120 121 128 120 138 134 127 120 132 134 141 135 123 131 144 133 147 145 135 152 121 127 128 126 125 142 116 140 125 131 131 150 131 139 136 128 132 137 129 151 139 167 154 127 128 149 127 129 128 126 140 135 136 120 133 122 139 138 120 144 125 147 131 130 149 120 129 158 132 124 141 158 155 134 141 146 126 131 136 135 139 136 133 132 127 130 122 131 149 143 132 154 129 138 139 140 156 131 127 154 151 143 134 127 127 145 142 130 127 118 136 138 130 150 124 126 146 149 154 136 122 133 126 129 157 137 124 130 125 133 127 131 144 111 117 140 138 139 151 117 126 137 128 138 147 126 155 121 123 131 139 129 115 127 126 121 133 129 122 130 124 138 145 126 143 125 120 122 157 106 138 125 108 131 138 135 119 128 124 116 122 118 136 128 127 136 141 126 128 113 119 130 123 109 136 135 140 115 132 114 134 134 110 132 130 126 141 138 142 141 139 149 133 127 149 127 119 124 137 116 115 122 141 117 130 130 135 116 115 136 128 113 132 130 124 115 116 129 115 142 103 120 118 112 115 151 112 126 122 125 127 130 125 142 126 124 108 119 134 127 151 148 122 123 131 140 112 122 117 126 114 146 121 129 125 121 125 126 125 124 139 135 137 141 133 141 137 135 134 135 117 137 109 125 151 124 134 114 142 136 124 120 133 113 119 122 135 117 128 136 111 121 116 136 106 129 156 134 107 120 141 118 146 122 122 120 126 131 139 140 128 146 135 153 116 130 135 142 129 134 137 128 127 127 121 126 143 115 143 140 115 140 133 132 126 126 134 117 131 122 135 133 127 130 138 114 120 117 130 120 129 112 94 115 109 141 137 113 120 114 125 106 102 141 126 135 96 116 125 134 109 106 127 142 129 128 114 102 126 126 121 108 116 127 120 131 141 135 149 123 142 103 110 139 125 141 130 110 136 123 140 137 121 137 138 121 123 123 133 118 97 119 127 119 127 119 142 119 109 122 135 123 131 118 121 124 115 131 121 113 109 124 121 130 128 136 127 125 124 119 120 125 125 123 121 112 122 116 151 112 89 128 115 120 125 134 130 132 131 116 121 125 143 145 118 125 122 139 109 127 130 108 126 123 101 122 135 103 120 123 127 118 120 140 132 130 125 148 130 101 129 122 101 132 127 120 113 115 133 128 115 128 130 138 131 134 103 114 130 122 134 122 129 142 101 141 133 128 125 133 114 134 125 122 131 133 145 133 132 129 136 121 120 117 119 121 124 134 111 109 122 110 112 125 124 105 125 110 111 129 133 94 113 129 116 129 124 134 124 135 114 131 128 107 122 111 125 109 109 118 141 100 95 119 118 140 110 98 112 131 136 112 113 149 134 110 106 125 115 110 110 156 124 113 117 116 132 110 129 106 104 118 114 118 97 126 106 135 107 120 130 124 152 122 124 132 124 108 116 127 115 111 126 160 129 126 115 124 114 127 113 123 125 112 127 124 136 129 115 116 158 116 131 149 137 111 112 116 124 120 119 118 131 130 107 124 122 121 136 116 131 125 105 105 129 122 140 96 121 145 126 136 130 124 130 107 150 122 138 123 123 126 126 128 151 129 131 135 104 108 134 117 139 127 147 113 128 151 117 135 115 139 131 141 132 114 111 98 130 136 155 123 113 117 128 114 127 121 141 108 130 132 122 118 121 128 145 110 120 119 145 109 134 123 122 98 118 138 139 129 109 127 107 147 131 104 128 125 120 137 108 132 123 109 112 121 132 118 127 123 130 101 114 132 120 109 118 121 107 136 118 135 153 123 116 115 100 126 109 143 121 112 119 121 108 128 119 125 115 98 127 126 140 114 122 131 108 119 132 112 115 147 107 108 119 122 122 110 109 133 136 123 109 112 107 145 116 100 135 131 136 122 139 149 149 110 115 140 124 118 136 135 105 122 133 119 108 130 130 130 117 139 111 129 117 128 108 130 113 126 114 130 146 114 116 128 115 109 98 117 87 125 114 114 111 147 125 110 105 122 127 130 111 116 112 117 117 137 111 114 120 142 139 120 109 120 131 120 120 112 130 103 129 109 116 109 117 141 104 109 97 141 107 126 122 134 134 110 121 128 133 124 119 129 104 134 127 116 100 121 101 119 117 101 108 119 119 116 115 112 127 109 130 141 119 126 135 143 115 126 114 127 123 106 94 133 112 108 115 108 126 118 140 121 113 120 127 110 142 102 129 126 106 117 121 114 120 136 123 127 122 121 118 124 144 140 125 141 127 116 112 123 123 137 121 133 102 144 127 116 137 99 132 134 118 122 119 145 124 93 103 117 130 108 119 122 103 114 112 109 111 141 104 124 124 113 112 124 109 130 124 117 135 113 131 131 129 121 132 117 135 116 120 126 125 145 136 124 114 127 131 118 134 116 120 134 129 137 136 141 106 124 119 121 127 111 159 124 123 121 110 116 104 99 117 118 139 127 125 117 127 114 111 118 145 128 103 111 128 118 133 125 112 116 118 120 106 143 122 110 115 117 122 111 138 115 118 116 122 113 122 118 110 115 110 125 129 153 124 114 125 117 122 116 133 125 109 128 129 109 116 119 116 146 101 112 124 106 145 119 106 126 139 132 124 132 146 129 122 101 128 126 119 126 118 120 114 118 122 126 109 112 117 121 109 116 120 146 125 112 133 130 98 139 122 114 116 135 116 119 118 116 114 133 122 140 126 132 114 137 120 129 108 114 115 119 124 124 127 132 137 116 139 123 119 133 132 147 136 116 133 119 103 122 133 113 106 125 123 111 126 113 129 152 127 122 119 123 117 114 129 108 112 106 114 107 107 124 137 112 116 120 129 125 117 132 137 126 136 118 147 115 127 138 95 120 140 132 98 145 127 124 134 120 116 133 102 128 132 140 143 119 126 149 118 126 136 112 121 123 131 105 129 128 132 104 121 122 136 119 134 124 124 131 132 114 130 115 141 126 138 110 114 137 127 129 127 144 117 147 120 122 106 113 116 125 143 140 138 120 131 135 119 129 138 127 128 135 127 122 119 121 152 155 133 138 139 125 123 124 132 139 122 134 135 145 133 143 119 130 114 124 131 123 110 132 135 132 131 144 131 157 140 146 110 129 115 143 133 140 127 140 129 129 121 143 136 129 133 145 125 143 135 144 129 123 134 146 133 138 144 142 130 135 146 128 132 165 127 127 130 151 108 138 161 120 145 138 141 139 152 148 138 173 143 169 143 146 152 137 142 131 136 155 154 175 179 168 184 166 179 160 180 176 182 181 153 163 175 191 201 213 207 198 214 227 211 203 205 221 219 200 210 227 215 198 195 213 207 200 192 205 168 213 163 176 164 184 171 151 146 162 153 175 155 164 140 165 149 156 149 140 140 144 154 129 137 184 145 147 130 152 140 137 147 134 128 153 133 145 148 129 138 117 117 139 146 134 127 124 133 143 110 125 122 129 131 140 134 112 154 117 162 139 134 118 125 133 131 129 140 128 137 127 118 128 135 144 117 123 135 125 128 115 139 137 128 137 146 121 125 141 159 121 128 120 121 137 106 148 121 128 149 111 135 142 118 143 128 119 113 135 113 134 134 133 120 130 130 130 132 137 136 119 135 109 140 130 113 129 124 127 119 113 117 128 126 137 140 123 121 139 138 114 124 141 108 130 120 123 137 116 133 133 94 113 122 134 111 137 124 118 136 119 127 108 122 110 120 150 110 113 132 120 133 139 103 127 105 143 116 136 127 133 127 124 130 122 128 119 129 137 146 143 129 124 120 118 130 127 128 133 145 141 128 108 149 131 131 133 125 108 125 136 142 129 119 105 112 126 121 120 121 131 133 131 138 107 136 133 109 130 134 120 111 123 149 118 125 133 124 114 111 103 114 131 137 108 142 119 129 126 137 131 119 130 122 119 131 139 136 128 114 115 136 121 122 135 123 122 124 127 131 127 122 141 138 139 133 123 133 117 123 116 129 150 135 132 131 125 138 125 132 135 123 131 141 129 124 133 113 129 129 125 116 117 133 129 137 124 116 140 125 146 104 137 120 124 117 126 127 131 128 119 137 104 112 129 128 129 119 134 127 123 120 120 135 134 119 123 144 119 118 104 127 112 130 120 123 121 117 129 104 122 119 127 118 125 134 125 120 129 117 112 139 126 156 124 123 119 149 127 128 135 122 129 116 127 112 146 117 147 107 128 128 126 130 148 126 134 137 121 106 125 128 116 113 146 125 153 136 121 117 124 131 132 130 101 129 122 139 118 114 125 120 136 127 120 120 118 138 121 130 122 116 124 125 130 141 127 108 130 118 120 122 124 118 117 121 121 138 118 117 129 122 126 124 123 140 132 116 110 129 109 135 129 146 138 112 149 114 128 140 145 109 116 121 116 141 135 119 106 117 137 143 115 108 152 140 128 144 137 120 113 121 117 122 115 135 127 139 112 134 117 128 132 124 129 116 116 123 131 121 120 127 148 152 111 107 131 149 122 127 127 105 151 130 136 114 124 131 127 114 131 108 118 130 115 125 126 118 143 118 130 135 133 127 121 132 127 137 129 118 130 114 123 134 122 127 114 117 138 112 125 109 129 147 138 128 126 129 118 134 131 142 123 138 123 133 140 144 128 117 131 117 101 140 144 121 111 118 143 133 141 119 117 132 143 134 131 145 127 113 124 125 109 136 121 142 105 120 106 123 130 124 120 125 120 109 117 120 121 133 123 117 152 135 128 125 124 129 109 113 135 119 141 108 127 119 128 121 120 125 119 116 127 141 112 136 127 133 117 136 129 138 130 145 136 151 141 135 135 112 127 129 133 118 127 111 133 130 118 106 119 118 135 99 154 140 122 139 111 106 117 131 126 138 125 123 121 127 121 122 135 115 129 124 111 132 140 142 113 124 129 140 116 139 123 135 130 148 125 122 132 133 129 118 132 127 135 128 137 132 119 123 132 143 153 129 115 127 122 135 148 155 134 132 140 129 137 137 124 135 122 136 141 121 126 134 128 144 126 120 123 127 127 126 155 115 147 145 126 122 144 117 113 129 133 119 137 138 123 128 137 139 134 141 130 143 137 107 136 134 119 126 124 111 125 134 131 155 135 138 135 125 134 121 139 121 131 126 157 135 116 151 145 147 136 143 126 143 133 144 106 145 129 129 120 123 120 147 133 129 128 133 131 129 130 141 133 111 124 121 117 128 126 133 135 144 131 129 124 146 131 137 143 113 132 103 120 125 135 151 137 128 133 145 122 130 132 136 116 126 119 121 128 130 132 119 149 143 146 120 127 135 114 109 121 134 108 134 118 116 136 126 125 112 133 120 127 125 134 141 114 129 124 120 125 123 140 116 141 128 139 122 126 153 129 137 116 116 150 142 126 132 121 126 143 146 125 135 122 98 111 116 161 122 125 124 134 123 105 109 125 142 141 124 152 145 146 117 114 129 126 121 111 115 119 129 138 125 125 134 135 110 142 128 135 131 128 118 134 140 121 136 137 129 114 117 112 123 114 139 130 138 103 128 123 117 113 123 125 122 123 128 120 138 137 128 113 124 141 122 107 138 119 137 122 132 119 109 124 129 148 112 135 130 134 140 143 120 133 113 136 117 132 126 102 135 148 116 115 115 133 130 151 135 128 130 117 120 117 134 134 123 142 122 150 136 127 132 135 142 133 133 113 137 135 131 121 128 115 138 134 137 144 115 131 110 126 128 119 126 130 134 139 114 122 112 136 128 164 119 135 136 116 124 143 131 137 143 134 143 118 127 114 151 131 133 117 127 107 117 129 106 132 138 118 125 131 121 130 141 129 113 143 119 109 139 119 127 110 127 106 142 130 127 145 127 119 146 132 145 142 120 117 147 132 133 109 118 129 137 126 133 89 151 136 116 136 120 133 121 118 136 134 125 134 116 117 129 131 130 122 137 128 138 131 133 127 117 125 139 116 117 134 129 134 117 142 113 140 143 137 128 134 137 124 121 143 121 119 154 128 117 107 144 128 139 129 128 138 130 131 119 110 139 125 124 119 135 118 132 141 118 134 127 119 137 132 141 144 130 127 112 127 92 135 133 131 125 148 127 127 118 124 124 121 130 134 138 122 151 117 120 125 130 132 131 134 136 126 120 129 111 111 104 124 120 112 128 113 117 141 111 131 127 138 129 155 129 134 130 127 112 113 130 139 111 130 113 133 131 111 101 124 121 110 120 119 134 139 113 126 131 123 126 112 121 123 145 132 107 141 132 119 128 149 115 121 136 154 122 118 141 132 114 137 116 128 124 141 126 137 116 118 144 132 106 135 145 118 141 121 124 96 124 132 121 145 136 119 131 117 122 150 115 121 131 156 128 135 114 121 137 137 154 138 108 130 127 131 127 128 123 129 142 134 117 124 146 136 108 124 131 130 118 128 162 135 141 120 135 131 156 108 160 129 141 138 115 129 129 143 136 131 151 129 127 122 116 118 124 129 103 125 134 130 145 146 129 114 134 152 98 137 129 143 144 115 147 131 122 128 121 127 122 124 148 138 135 112 104 107 106 123 150 112 110 141 131 129 137 106 130 132 122 107 127 131 122 136 136 119 117 125 149 132 129 136 135 125 134 144 127 135 135 126 119 123 109 117 134 128 156 127 128 135 110 134 119 122 125 119 131 128 129 123 145 132 123 130 134 122 133 119 131 117 115 128 123 132 123 127 137 124 137 127 126 149 131 112 118 118 143 119 116 123 130 129 136 139 128 104 114 130 123 133 128 139 121 124 136 122 121 129 139 120 112 142 125 104 129 121 142 135 112 112 127 128 139 126 119 134 120 139 127 128 106 128 131 135 138 133 138 140 135 118 107 143 137 113 164 132 129 108 119 140 144 132 129 118 137 108 119 145 125 104 133 141 119 111 123 133 137 121 124 139 132 121 119 115 127 136 120 117 126 113 138 152 114 126 142 124 116 138 134 132 125 110 132 117 154 125 131 137 138 123 121 137 149 112 141 144 119 117 118 129 138 134 127 127 133 118 120 128 130 142 123 117 120 130 131 135 133 128 140 135 122 121 150 130 129 133 129 131 131 109 134 109 130 143 103 142 130 124 133 136 124 113 131 127 132 138 127 123 139 140 143 150 134 118 143 138 136 126 121 130 145 112 135 122 148 141 121 140 124 119 154 119 131 135 135 134 137 124 125 133 123 119 127 114 117 135 128 132 122 143 136 119 127 123 132 129 135 135 139 112 135 115 120 127 143 116 129 104 147 125 153 133 125 131 132 140 119 124 112 133 150 129 129 153 142 128 126 158 134 147 143 153 128 120 122 118 120 132 120 140 143 143 123 116 125 124 125 126 122 123 129 126 137 132 135 141 144 137 108 138 107 148 129 132 115 136 125 130 110 112 141 127 117 123 132 136 134 117 127 129 125 139 139 143 133 103 138 120 99 125 128 141 115 112 125 124 126 133 141 152 128 108 141 157 124 117 151 140 119 128 139 142 117 119 129 117 128 142 146 134 134 114 123 118 121 126 130 151 126 135 126 131 130 132 134 124 107 123 123 135 131 118 135 122 151 138 107 138 133 158 144 116 142 151 134 112 137 120 117 142 130 147 145 139 123 118 121 126 132 144 142 120 128 152 144 126 148 139 125 142 114 145 129 117 119 122 130 137 121 121 113 120 116 135 120 104 126 131 134 153 149 128 125 147 113 126 127 123 124 128 129 143 141 127 134 126 124 119 138 129 134 125 135 145 121 136 145 133 148 113 121 141 122 131 137 134 130 160 131 134 124 126 149 138 137 129 121 126 128 138 124 107 143 98 125 108 144 129 132 141 132 131 131 132 135 161 136 132 125 116 133 115 148 131 148 134 136 124 120 127 134 124 142 145 128 134 125 140 129 145 135 105 153 140 137 152 129 139 148 134 116 141 121 137 121 118 131 124 128 125 140 136 135 118 140 124 125 148 136 141 117 120 140 159 130 139 143 131 122 130 153 143 146 129 136 112 143 138 118 139 160 145 137 143 139 129 138 147 129 152 134 125 124 152 144 120 144 137 158 138 138 137 141 136 145 140 121 142 142 135 114 136 165 155 141 135 136 132 123 130 142 152 140 149 136 135 134 128 140 149 110 122 137 144 118 129 114 139 130 139 136 125 107 132 146 137 150 155 136 114 116 128 129 152 138 143 135 143 117 136 126 118 109 131 136 134 134 125 135 147 120 148 154 114 126 125 129 132 120 161 144 144 129 142 132 134 123 135 152 118 142 139 128 139 150 118 122 154 152 126 120 147 117 149 137 120 142 132 133 119 128 110 138 124 157 145 125 131 115 161 130 146 126 133 122 140 118 119 143 130 124 137 135 147 96 135 119 140 128 125 117 114 147 129 132 134 138 121 129 126 146 138 137 137 128 143 136 106 140 134 137 124 116 143 136 128 151 138 145 131 123 140 146 153 119 113 119 117 133 141 140 127 136 136 131 127 122 126 146 125 166 120 124 107 120 138 143 110 136 103 108 128 145 158 128 136 116 129 139 143 136 120 130 139 134 118 150 128 124 131 127 128 134 122 137 117 123 131 124 127 133 123 119 129 128 138 114 135 132 144 130 142 125 128 130 127 91 136 125 146 142 121 130 122 137 123 140 112 106 102 114 119 130 126 132 154 125 119 158 120 118 136 131 135 135 106 140 119 118 120 125 128 157 111 131 150 140 113 135 127 138 138 113 119 122 151 149 134 144 124 125 117 126 133 131 142 157 122 137 137 106 121 127 116 108 104 134 157 132 124 120 153 130 126 130 135 131 131 147 115 120 137 140 140 129 125 116 127 128 133 124 124 132 135 115 144 132 141 122 120 138 134 133 126 142 108 129 136 134 149 132 134 120 123 132 127 144 144 135 126 135 128 121 119 132 137 122 131 123 121 126 120 124 144 129 106 133 114 130 124 142 147 135 111 130 151 146 121 137 127 134 127 130 136 147 111 152 127 147 123 116 146 142 138 123 119 128 127 127 121 128 120 138 120 119 132 116 149 142 148 124 124 139 131 132 102 126 111 136 146 136 126 136 136 134 140 129 138 121 125 99 132 137 137 124 113 124 132 138 121 153 127 108 129 151 136 116 128 142 141 139 119 140 112 146 114 124 125 148 134 111 147 157 118 106 115 116 143 129 115 137 147 159 143 119 114 101 151 149 144 144 138 152 135 121 149 117 109 118 138 117 125 143 134 124 145 136 128 125 133 128 132 113 134 131 147 125 123 121 131 139 146 138 143 138 129 133 110 132 150 122 133 135 139 136 109 122 160 132 131 144 144 141 122 126 116 128 110 129 147 129 132 126 149 119 124 142 126 126 126 128 143 137 124 140 145 126 130 128 146 128 112 132 120 122 125 125 140 132 114 128 120 140 139 133 128 131 139 124 147 122 156 126 127 132 122 131 142 113 148 133 150 163 138 135 132 124 140 143 125 133 139 116 137 153 144 137 125 136 121 136 130 140 117 123 148 120 151 127 127 118 133 139 128 116 137 120 128 150 110 126 141 116 140 136 124 144 156 121 132 124 143 109 116 144 131 123 149 135 122 138 161 128 137 155 113 129 123 116 133 134 105 131 127 116 135 143 122 135 134 127 156 140 121 120 127 112 106 121 123 129 131 152 131 129 130 130 145 131 126 129 148 111 131 133 117 120 111 121 133 114 136 122 124 127 126 110 131 128 124 120 130 122 131 115 126 131 118 137 121 123 116 124 161 118 142 146 130 139 131 118 132 122 127 142 131 129 145 140 139 140 109 132 118 108 148 130 113 128 148 128 111 141 98 139 137 139 157 140 133 127 117 125 149 134 126 135 135 145 133 159 141 128 113 107 116 140 120 119 144 135 159 121 129 149 145 120 152 140 135 124 135 141 147 123 140 134 119 159 133 124 122 146 123 138 138 116 120 132 156 131 118 115 120 123 147 133 130 134 154 115 118 124 125 148 140 143 132 137 159 131 132 121 125 140 132 144 146 121 135 138 139 137 135 123 133 117 136 133 112 120 144 133 119 138 132 128 117 131 122 125 137 135 133 130 131 105 150 128 136 138 151 137 139 125 139 132 125 119 145 140 134 127 124 131 121 159 152 136 127 138 150 133 131 127 107 139 123 137 132 125 119 104 115 140 125 114 148 123 123 125 125 124 142 135 139 125 147 141 125 109 117 137 128 134 129 131 104 116 136 140 129 141 135 136 118 135 130 129 123 135 140 146 143 113 134 129 159 139 133 129 133 150 138 127 149 123 121 129 154 136 125 148 134 113 147 133 137 122 126 126 109 133 122 134 139 121 121 124 114 127 122 131 153 144 127 115 133 125 121 142 148 114 150 135 141 130 136 126 132 128 137 115 148 125 113 128 132 145 126 129 128 129 125 132 127 130 155 151 130 127 124 144 140 128 134 126 130 115 107 122 127 129 126 140 131 118 139 143 123 114 123 128 112 130 138 141 125 118 116 126 137 139 118 120 135 121 135 129 118 132 134 134 106 129 121 125 130 124 130 145 126 133 132 134 139 155 136 123 124 151 144 126 117 137 144 135 112 136 131 126 125 133 124 127 141 118 132 143 108 113 165 141 120 116 114 133 124 132 111 136 123 131 150 124 132 146 151 121 139 129 145 126 123 114 104 122 117 131 131 128 132 129 143 117 130 153 149 139 138 117 126 120 137 150 127 132 136 140 133 131 102 146 131 126 118 113 113 125 134 121 124 125 142 141 117 140 124 127 111 147 128 145 137 141 139 133 128 118 129 122 141 135 129 124 114 133 135 122 122 129 118 113 119 120 139 126 132 142 112 126 133 134 117 119 131 127 127 132 116 115 138 125 139 121 150 136 121 132 127 111 140 120 140 130 142 130 145 129 109 123 146 151 141 134 113 144 144 132 139 141 135 128 159 142 123 126 132 142 143 119 130 136 115 134 156 114 117 127 117 128 125 136 140 140 122 111 138 134 144 142 133 137 121 123 103 137 143 139 118 130 129 123 144 141 122 144 123 142 139 128 122 125 131 132 146 126 134 140 128 139 137 121 123 104 138 130 128 123 133 115 129 134 116 129 137 130 125 135 137 136 132 121 137 128 130 139 124 147 124 132 152 130 148 124 132 119 139 129 144 142 144 130 118 125 130 140 140 140 139 135 134 133 142 137 118 139 121 142 113 135 144 124 143 107 111 143 141 126 152 144 143 141 158 131 127 135 127 128 143 137 149 121 150 139 139 137 124 122 143 125 114 126 138 138 145 120 151 140 130 145 125 110 159 146 119 110 127 114 160 158 132 142 147 139 126 144 123 141 147 148 133 129 151 139 126 120 137 137 149 132 142 141 124 131 127 135 126 150 134 129 140 146 137 137 135 142 110 141 137 132 137 151 154 120 125 129 116 111 128 148 127 142 126 121 132 114 139 145 108 114 142 140 162 133 112 122 129 103 120 108 135 128 135 140 108 156 125 121 153 143 141 127 141 131 136 163 141 121 138 129 127 132 121 121 139 123 146 137 140 122 112 135 127 136 112 141 150 130 148 143 126 127 132 123 151 129 131 125 147 135 139 133 133 118 145 140 138 142 137 131 119 146 124 139 136 151 154 134 125 141 125 144 126 123 145 136 145 112 143 131 138 155 112 154 122 125 139 129 141 113 130 129 122 126 131 131 119 140 157 140 155 121 129 137 125 150 131 142 120 128 121 119 133 119 123 146 147 153 134 130 140 123 173 137 132 142 128 117 127 141 146 128 129 137 144 126 152 149 125 124 129 122 143 133 127 146 138 124 144 133 134 154 138 131 135 133 128 129 156 128 123 127 137 127 134 149 130 140 130 124 123 123 134 125 144 155 128 131 112 154 146 145 125 153 157 128 145 134 135 165 129 162 125 146 151 139 143 145 140 140 128 128 159 143 140 130 126 122 144 133 130 150 163 143 151 146 150 122 145 142 138 123 154 156 136 151 117 150 131 135 170 144 147 156 155 143 163 164 180 149 158 150 164 140 153 172 157 147 153 148 155 162 143 130 168 130 178 133 141 167 140 153 150 127 147 151 158 135 127 138 150 152 148 124 124 150 146 143 127 135 148 131 147 140 130 155 152 135 114 124 149 139 138 140 144 134 131 128 112 141 133 140 126 149 141 139 127 150 117 135 138 123 125 151 112 154 129 145 126 141 151 124 136 138 136 131 140 123 139 140 139 109 116 125 131 143 122 127 137 129 113 132 122 139 135 134 124 125 138 131 120 146 130 136 143 127 126 123 131 133 137 143 117 114 122 114 132 115 134 118 117 127 127 147 144 135 119 130 123 121 141 122 120 138 132 132 137 135 123 120 122 126 144 128 105 128 142 138 136 127 109 125 155 134 143 136 132 128 119 122 136 137 124 145 116 129 138 129 147 124 124 138 109 120 148 147 134 130 143 123 140 121 112 117 129 118 138 131 145 126 150 127 129 120 129 125 137 153 121 141 119 141 130 143 126 150 104 130 118 128 132 129 113 134 119 130 123 127 133 131 137 146 125 121 133 119 119 113 132 109 127 135 102 127 128 146 131 129 99 123 127 145 135 138 152 128 121 122 122 133 126 118 128 154 147 134 130 115 118 138 108 131 138 118 129 127 130 142 147 104 133 139 111 147 139 136 123 141 122 123 127 129 142 126 141 118 130 130 141 137 148 117 113 132 124 120 159 139 122 152 139 128 114 132 137 117 129 116 149 122 110 127 119 133 139 127 127 115 115 130 125 132 118 131 126 114 136 112 129 143 134 146 120 140 135 111 129 111 151 151 125 119 102 110 102 132 113 142 129 142 108 128 113 121 124 130 111 141 117 137 137 150 119 127 145 135 136 148 122 113 132 127 137 141 126 132 121 143 131 119 139 131 123 117 135 112 110 144 148 127 126 125 127 102 127 118 110 123 107 144 114 135 109 124 125 96 155 130 121 136 126 147 132 124 127 140 131 116 116 135 145 118 119 125 125 134 112 104 132 123 120 166 140 121 124 103 125 129 134 124 117 141 127 110 124 155 142 114 127 125 142 134 125 112 128 118 135 109 118 103 127 129 134 125 118 125 141 144 115 137 120 151 115 122 130 120 109 107 128 134 127 130 121 145 121 112 132 131 128 115 121 140 133 149 121 131 124 104 155 142 122 137 125 132 120 134 127 129 134 123 108 147 114 122 134 134 121 138 120 137 130 146 136 118 128 126 130 122 130 126 131 123 132 128 120 133 138 123 108 145 122 126 139 125 131 124 119 137 145 155 121 131 128 131 138 146 119 145 133 117 135 126 141 142 124 137 144 125 129 145 114 120 120 120 130 111 123 117 124 125 140 125 132 135 119 137 122 132 126 118 124 125 124 122 137 125 124 133 118 120 128 143 128 106 113 114 125 130 115 136 135 122 112 133 121 130 120 124 119 129 121 114 113 119 135 129 126 124 131 128 117 123 122 130 137 130 124 133 118 121 135 140 142 128 118 113 134 130 132 114 123 136 136 130 119 141 137 128 124 131 107 140 143 128 109 132 125 102 132 139 130 114 137 126 133 110 130 110 125 107 112 125 135 127 124 134 121 132 121 112 120 131 134 121 147 124 141 113 126 120 137 115 128 136 88 134 148 109 113 109 128 113 128 134 120 128 106 142 130 116 124 135 161 117 144 101 121 115 124 143 130 129 131 112 130 147 127 105 127 120 117 121 117 120 106 129 136 123 119 127 124 128 125 120 129 124 120 141 124 136 145 114 138 123 120 127 123 118 119 114 133 122 136 111 124 148 137 127 120 125 127 125 116 117 152 124 135 138 112 96 125 138 145 140 123 121 104 141 120 125 114 133 131 158 144 120 122 136 130 117 142 136 114 124 110 121 105 110 139 112 132 116 127 143 127 134 139 134 143 127 127 129 130 131 120 130 135 120 127 123 144 134 109 135 113 106 124 115 125 130 131 134 154 131 127 152 120 106 122 133 117 134 119 110 131 121 121 126 130 130 139 113 107 112 145 142 108 120 134 140 117 139 135 135 123 128 137 121 133 138 135 116 115 146 144 126 124 143 114 134 134 125 131 124 125 129 136 134 125 124 111 125 126 129 122 121 117 126 121 122 115 131 133 122 125 121 135 149 136 132 139 121 133 105 129 119 129 117 137 141 121 119 106 142 125 113 138 134 144 124 121 144 124 139 127 123 134 117 127 124 135 116 129 131 124 139 136 124 128 128 126 138 122 114 144 129 110 128 139 117 125 144 135 111 139 128 156 119 124 135 126 127 129 131 144 116 132 122 113 114 136 122 141 149 124 143 129 142 141 136 120 133 129 113 135 130 126 128 136 124 127 134 131 138 144 134 124 141 116 140 119 120 117 135 125 113 132 128 128 126 138 129 130 135 102 123 110 131 125 138 139 115 108 106 120 124 131 139 111 124 128 149 126 122 107 122 130 130 137 131 126 140 124 115 141 132 130 119 130 110 127 120 106 146 125 113 126 145 129 145 145 133 114 119 155 103 136 120 129 125 140 122 116 118 130 118 115 145 150 120 118 131 126 109 115 129 122 114 125 131 131 138 115 117 121 126 145 136 129 117 114 142 124 149 130 140 123 132 143 130 123 129 133 103 114 132 120 133 149 127 118 142 119 139 139 131 111 144 132 130 136 122 123 122 127 130 130 124 116 121 126 114 132 141 115 129 139 117 159 137 146 129 139 117 126 137 130 120 130 123 129 121 122 142 105 123 120 120 132 128 108 127 123 135 126 131 110 97 139 135 116 115 120 128 125 130 115 114 131 127 125 127 107 117 111 128 119 125 118 146 135 116 111 126 133 119 124 125 128 149 141 134 131 128 130 119 132 103 125 116 117 106 131 136 118 122 130 135 125 124 145 125 147 136 119 133 137 147 114 108 144 132 120 106 122 138 124 117 144 132 127 140 118 114 146 132 134 127 120 145 121 139 142 155 156 120 114 118 127 114 136 126 116 120 116 120 125 127 119 138 127 141 121 140 131 137 114 147 133 124 126 119 136 120 145 132 129 112 127 134 126 129 124 123 107 124 129 128 112 132 138 117 124 123 116 108 136 122 122 127 129 111 119 117 110 118 122 128 142 126 103 123 127 129 128 139 110 117 114 102 132 124 129 139 130 120 125 113 119 124 116 144 117 117 130 122 131 113 124 157 125 124 111 113 131 128 127 124 118 124 115 135 143 120 125 122 132 105 127 129 116 126 137 124 124 122 157 109 127 121 125 113 128 130 136 108 137 111 153 138 109 122 119 128 134 115 123 117 105 105 130 126 132 121 137 122 120 132 121 104 141 128 128 119 118 156 104 146 124 129 109 108 129 132 121 120 129 134 126 127 115 129 121 100 127 140 105 120 111 124 124 132 117 126 133 137 129 109 131 127 119 132 103 105 127 119 129 116 113 141 127 116 115 121 126 120 103 137 120 144 133 148 128 115 131 137 132 120 104 126 106 132 132 119 113 127 133 114 127 121 125 133 126 131 130 131 128 122 122 121 129 126 139 119 108 113 116 150 110 133 116 141 140 125 140 118 104 129 120 124 135 108 130 135 121 153 140 140 112 135 133 136 127 115 123 127 127 126 127 123 132 124 134 140 121 121 121 124 131 135 112 148 119 131 145 130 124 115 133 149 124 119 126 113 138 100 116 136 113 115 116 141 98 136 113 134 124 124 118 129 113 124 134 127 125 120 129 133 144 114 133 114 122 132 127 131 96 112 123 142 122 139 133 157 112 141 122 143 134 117 123 124 130 132 135 141 125 132 126 124 131 112 130 120 129 127 138 113 124 124 149 134 122 130 129 129 136 114 144 137 129 120 112 121 131 122 121 144 130 141 136 142 139 109 131 147 113 138 123 114 142 127 120 152 142 122 154 139 130 126 124 117 142 135 133 130 132 152 133 128 120 127 122 149 134 126 123 125 136 120 104 134 133 132 151 130 135 125 146 117 114 129 116 135 138 141 130 123 115 112 138 118 141 131 117 132 132 117 125 118 118 132 118 155 120 109 129 132 110 126 133 129 106 127 123 101 125 135 125 109 126 128 104 125 125 114 120 119 122 128 130 128 128 125 129 116 137 144 123 121 122 122 131 121 124 121 124 118 139 126 115 121 137 138 125 140 137 125 119 124 134 135 136 148 141 135 133 142 118 147 122 118 126 104 129 129 162 113 113 112 118 161 102 122 117 104 106 138 141 112 115 121 124 138 106 108 125 135 125 126 124 138 146 140 126 131 126 127 130 129 140 138 150 145 134 130 131 101 127 108 128 140 129 117 113 114 137 142 133 117 127 116 129 142 124 124 117 132 113 132 116 131 136 125 119 146 121 119 127 121 119 135 128 118 113 135 115 124 110 126 104 120 119 140 132 126 126 121 117 130 137 130 117 133 134 102 109 108 100 131 121 143 125 119 111 152 138 127 117 118 124 112 117 120 128 125 128 120 133 126 120 144 125 131 134 122 121 130 115 127 111 136 118 115 147 129 133 139 118 140 128 140 125 133 134 122 116 135 111 107 121 127 120 135 123 133 135 145 118 128 110 103 126 113 128 140 136 138 135 114 118 145 131 144 114 133 125 133 114 118 124 126 128 120 103 135 131 135 117 116 110 149 115 133 112 118 136 131 132 133 131 134 126 114 116 129 118 128 96 119 123 147 136 115 144 144 116 139 146 127 123 109 138 121 122 120 124 138 123 121 112 133 130 134 131 136 122 121 112 117 128 147 110 129 122 136 121 151 124 126 130 146 124 115 105 123 140 131 127 138 141 133 115 129 135 112 124 134 131 122 128 123 113 137 135 136 125 124 124 142 119 152 128 120 128 123 136 135 141 153 114 115 132 139 144 124 134 122 118 121 150 109 127 115 130 134 120 119 136 131 138 131 136 124 124 131 133 118 122 120 138 107 108 139 124 125 132 118 149 144 104 147 127 117 136 124 123 112 132 123 141 114 141 146 118 133 143 127 135 134 120 131 143 128 110 133 119 119 131 131 110 141 130 128 125 106 148 151 133 128 151 145 129 137 115 129 137 113 148 124 125 136 119 116 131 126 140 120 134 131 121 126 135 108 113 123 128 124 124 100 131 132 145 128 129 115 109 130 120 139 132 116 142 134 129 117 106 124 116 119 113 127 155 123 124 131 125 140 127 131 145 146 119 118 116 128 107 123 139 146 122 127 134 135 135 121 126 141 123 137 119 129 119 131 125 110 138 130 136 138 135 121 122 136 137 113 128 124 127 127 132 132 126 130 130 141 118 120 141 134 118 115 126 130 168 137 137 126 144 123 126 146 120 114 117 127 110 120 160 123 131 134 129 116 136 144 136 138 118 127 135 120 131 99 137 140 147 116 134 119 143 126 125 142 112 141 148 159 125 119 136 134 126 135 139 148 129 126 139 152 132 124 148 139 132 130 129 130 124 135 131 136 141 114 109 108 139 114 139 140 115 147 134 130 128 138 126 123 132 118 149 134 123 143 129 153 109 135 135 123 132 122 135 132 131 120 126 134 118 125 136 125 120 132 142 135 142 120 151 152 127 116 121 145 107 119 133 146 128 131 115 146 132 116 129 128 128 133 150 121 145 134 102 120 138 128 124 133 120 114 127 140 135 134 108 136 120 120 144 120 139 151 142 127 120 131 141 130 129 109 125 146 135 136 140 122 122 129 119 136 138 137 125 121 124 123 119 134 147 113 123 119 138 110 128 135 130 134 143 110 132 117 125 117 141 141 144 137 145 125 130 132 143 129 124 112 116 134 140 120 123 92 116 131 130 140 143 160 113 132 129 135 132 131 131 137 127 123 120 127 137 145 134 123 134 120 117 141 137 121 137 123 133 127 137 145 146 131 136 133 129 130 113 114 140 118 122 129 131 147 134 131 135 136 129 141 126 163 141 130 128 130 137 143 128 120 140 129 130 113 123 139 124 131 126 150 140 117 107 120 124 137 121 131 116 114 140 123 136 142 163 127 134 131 124 131 135 132 152 115 139 130 116 138 122 137 125 121 122 133 138 119 130 135 123 117 128 140 112 124 139 118 146 107 127 139 150 123 144 130 136 129 138 144 134 131 129 133 137 131 108 123 154 154 141 119 120 121 133 146 119 124 119 149 144 155 130 115 141 127 113 135 145 123 152 126 125 116 139 128 128 120 149 125 126 124 124 144 130 143 118 129 142 126 119 120 148 136 142 134 121 129 138 120 132 154 121 136 132 131 127 122 136 128 130 119 113 133 134 146 137 133 130 130 133 117 134 131 133 134 131 121 126 132 127 115 127 118 123 140 122 126 146 113 136 120 139 136 148 130 125 135 128 131 150 127 120 126 115 128 109 137 136 136 120 127 135 120 148 126 141 144 142 143 119 156 136 127 141 126 130 139 129 162 140 105 130 120 133 131 143 141 132 141 129 118 121 118 115 138 116 144 136 137 145 115 105 147 148 142 151 130 113 134 133 136 125 120 110 139 129 139 145 150 140 137 127 126 127 142 154 126 106 159 125 137 122 139 133 132 142 109 117 125 124 145 134 148 143 119 124 111 132 121 125 125 135 131 137 124 153 138 146 141 133 130 126 139 146 109 123 145 147 113 131 142 125 136 122 117 143 152 122 141 127 129 114 158 126 149 147 139 123 143 116 133 134 145 112 134 142 127 134 131 141 132 138 128 125 116 129 115 138 127 136 137 114 114 118 140 150 127 133 117 109 154 141 120 138 119 119 106 137 129 141 138 121 135 139 123 104 121 131 143 126 119 127 150 131 141 141 113 131 133 136 124 120 121 137 114 140 129 131 125 139 136 142 136 127 143 142 108 116 121 152 129 155 132 121 118 142 133 125 149 130 125 130 146 123 145 142 140 121 118 135 140 145 132 121 124 120 136 130 131 127 118 149 125 139 120 147 131 116 131 113 120 142 116 152 119 169 120 120 121 135 118 141 130 139 112 139 112 134 126 128 139 133 131 147 142 140 118 129 129 128 118 146 128 116 150 144 111 149 122 119 133 141 126 141 132 137 131 134 138 125 145 154 132 133 128 143 142 137 135 118 128 128 143 126 135 124 120 134 151 131 159 123 129 129 125 150 136 136 126 136 127 131 125 125 107 131 142 119 125 134 140 130 146 144 121 130 138 106 136 133 146 121 122 124 104 111 141 123 138 130 121 110 141 136 123 132 151 136 143 121 143 114 138 125 122 121 166 124 118 141 136 136 132 148 116 130 128 149 142 104 138 119 156 127 129 130 127 126 127 117 158 110 140 124 122 136 113 137 124 138 134 121 118 133 109 125 127 131 158 134 150 136 123 115 132 123 120 143 119 128 153 135 123 143 121 132 134 137 129 111 117 134 132 133 139 120 99 127 137 141 141 142 158 122 126 148 140 146 130 141 119 133 120 125 119 128 125 144 126 164 114 125 136 133 129 152 137 124 127 136 128 139 125 104 146 134 145 149 136 126 127 154 131 133 141 127 129 134 152 139 129 102 149 132 140 106 127 152 155 143 128 117 124 151 122 118 126 142 119 145 119 131 95 121 133 144 143 135 158 138 134 144 143 107 131 153 142 134 132 155 122 116 134 125 143 133 111 141 125 141 143 139 121 125 138 139 144 124 127 140 118 132 113 136 144 144 142 109 140 112 131 143 138 149 154 146 129 148 124 126 146 117 132 128 138 132 142 132 121 142 139 138 117 132 136 152 159 134 141 118 162 143 128 131 150 138 136 161 142 127 128 135 146 150 142 114 133 132 123 128 135 127 150 131 150 132 155 139 150 133 116 150 146 125 125 131 135 146 113 140 135 137 137 123 133 142 143 139 144 135 168 130 146 121 136 135 155 141 142 146 121 124 140 147 122 143 152 146 135 161 122 136 138 129 137 122 128 134 149 129 137 145 139 145 127 151 120 130 141 120 108 131 135 118 147 141 131 136 142 128 125 113 133 156 128 150 119 136 142 139 137 133 136 124 125 126 143 126 123 135 155 154 131 143 146 122 124 126 130 127 138 128 144 147 132 127 140 136 127 153 139 137 137 121 144 146 125 151 135 145 146 134 143 135 113 127 132 157 126 115 116 148 138 108 141 120 157 126 135 157 134 129 128 122 138 139 123 132 113 130 130 137 112 125 110 126 129 122 133 130 130 129 129 144 111 116 147 132 142 136 120 123 146 136 140 125 135 127 122 129 136 147 110 125 125 142 120 128 124 144 137 145 133 128 141 143 133 120 133 133 128 135 140 132 133 150 126 139 112 132 117 129 136 137 133 111 145 147 136 148 136 112 120 141 127 133 135 133 135 139 121 133 106 129 146 120 116 117 107 119 129 127 147 121 142 121 128 145 156 127 159 132 138 137 126 149 132 116 151 119 141 116 137 130 146 128 131 139 135 124 134 117 146 139 143 131 116 134 140 143 134 138 124 115 124 112 135 130 128 120 144 116 128 130 107 138 129 123 139 138 131 116 135 135 133 125 135 138 138 117 125 128 120 165 127 118 149 137 126 161 136 130 129 141 116 143 147 145 140 140 140 125 127 135 129 126 123 118 105 140 102 130 124 109 141 122 136 139 132 140 119 136 113 121 127 120 120 126 128 112 129 106 147 140 118 125 115 129 132 121 140 131 138 132 118 117 127 126 122 134 142 135 152 144 119 128 120 133 131 126 135 125 118 127 126 151 124 134 128 141 124 133 143 120 126 122 119 110 139 112 129 136 136 128 120 138 111 150 131 130 122 115 132 141 131 112 139 142 157 126 134 130 136 123 118 151 132 118 133 138 124 123 129 137 119 119 134 149 123 115 128 155 129 134 132 142 128 129 111 124 115 159 124 136 119 134 140 134 140 135 127 144 134 140 124 124 103 144 104 150 114 128 143 135 128 114 117 127 125 132 130 121 135 121 133 115 145 141 122 124 120 156 119 127 124 131 121 128 113 135 135 120 114 149 126 125 136 148 144 127 120 131 113 129 135 142 129 119 115 146 136 160 141 124 122 139 118 107 122 133 118 113 109 132 139 115 142 92 140 142 130 120 139 105 123 115 122 127 135 120 135 135 135 148 138 121 123 117 128 102 122 114 136 139 112 140 120 109 130 116 124 141 131 143 121 120 133 152 135 101 151 129 143 116 126 119 117 98 123 134 122 140 138 108 133 133 126 121 130 114 122 141 150 140 128 139 138 126 138 136 123 156 136 144 117 111 144 134 128 117 140 123 149 141 114 159 124 120 110 129 130 152 113 127 148 124 121 113 125 126 139 120 127 142 152 135 123 127 147 129 138 128 111 146 111 140 128 118 143 123 129 122 117 120 150 131 142 112 157 126 146 157 126 144 134 140 144 134 127 142 138 121 133 122 134 129 105 116 131 113 120 125 140 133 129 142 106 140 129 143 147 123 128 133 110 165 128 136 140 120 145 122 131 125 104 119 126 125 137 142 121 140 155 144 156 133 121 118 126 127 138 135 121 114 152 144 123 155 142 133 137 134 128 137 111 129 132 142 150 146 142 144 146 137 120 118 130 136 134 121 125 131 123 143 110 137 141 152 149 140 148 156 134 135 121 124 138 125 129 129 127 146 133 115 130 141 144 124 125 119 123 148 136 129 146 142 133 141 148 159 120 116 140 102 127 122 121 126 157 131 155 122 124 131 133 106 135 116 142 147 124 137 116 154 147 122 119 134 152 135 138 124 121 132 123 126 129 123 124 123 120 122 122 139 131 133 116 148 137 136 149 131 143 126 144 130 134 132 126 110 138 110 121 153 152 133 146 117 136 134 141 125 162 124 119 140 158 122 109 130 141 133 139 144 124 125 139 125 119 127 142 133 130 139 147 153 148 152 128 126 134 143 118 127 156 134 152 104 145 121 129 120 129 130 136 140 125 125 119 144 133 110 136 143 128 147 131 126 141 110 136 123 130 131 141 134 151 131 127 121 130 122 116 137 127 138 165 136 149 118 122 125 116 136 130 135 142 137 143 144 137 135 136 134 123 110 122 142 115 125 144 122 115 153 134 147 104 139 122 127 131 111 139 140 132 149 130 129 131 126 122 133 158 148 137 110 152 134 135 136 148 152 140 137 160 159 143 117 139 121 134 141 111 138 132 123 140 135 134 143 135 113 146 102 157 116 141 140 131 125 122 121 147 120 119 148 130 156 126 128 119 145 122 128 132 144 131 127 139 135 144 120 142 143 143 138 159 143 136 123 143 138 111 117 143 126 159 148 141 123 144 144 117 115 140 138 154 133 154 113 109 148 144 138 118 137 171 109 122 128 142 135 136 145 150 139 108 130 126 147 140 134 129 131 122 122 134 143 137 149 127 137 144 150 133 148 160 146 139 114 164 157 144 143 132 161 138 142 139 133 126 132 143 126 157 128 148 117 168 145 136 117 130 133 120 128 137 145 139 138 125 118 139 148 140 134 117 136 137 161 162 128 133 116 126 140 138 109 148 130 130 157 139 121 146 152 125 118 144 129 110 113 132 144 130 141 145 143 136 134 144 126 124 136 123 123 112 136 136 112 146 120 116 131 129 140 130 129 171 116 129 116 145 113 118 118 134 142 131 142 129 136 129 145 156 124 136 123 132 129 126 133 131 116 138 130 122 129 123 127 138 151 135 128 128 132 120 118 135 134 128 146 138 129 123 129 127 150 139 134 131 133 106 141 127 139 139 151 117 108 117 137 141 147 152 152 140 131 147 130 132 122 126 147 130 155 127 134 136 148 139 129 121 135 121 128 126 142 131 122 141 144 115 126 123 149 145 122 132 130 126 123 120 128 137 149 140 122 136 126 151 136 129 119 120 134 139 137 143 139 111 105 132 137 137 145 123 143 120 145 130 142 125 135 129 142 139 130 141 127 123 116 126 140 155 151 138 135 135 161 118 134 124 131 136 141 150 141 129 139 136 144 139 135 130 134 132 127 130 147 150 122 151 139 128 128 147 142 125 151 123 130 137 143 116 142 126 132 121 128 133 142 137 123 135 124 126 141 132 136 118 141 131 141 131 145 127 146 117 133 123 147 136 131 124 143 126</counts>
			</dataPoints>
		</scan>
	</xrdMeasurement>
</xrdMeasurements>