File: data/XRD/XG-Luft/XG-700/W6824-1D_XG_Luft_700.xrdml
<xrdMeasurements xmlns="http://www.xrdml.com/XRDMeasurement/2.1" xmlns:xsi="http://www.w3.org/2001/XMLSchema-instance" xsi:schemaLocation="http://www.xrdml.com/XRDMeasurement/2.1 http://www.xrdml.com/XRDMeasurement/2.1/XRDMeasurement.xsd" status="Completed">
	<comment>
		<entry>Configuration=Factory configuration, Owner=User-1, Creation date=7/8/2013 4:01:53 PM</entry>
		<entry>Goniometer=PW3050/65 (Theta/2Theta); Minimum step size 2Theta:0.0001; Minimum step size Omega:0.0001</entry>
		<entry>Sample stage=MRD Cradle; Minimum step size Phi:0.01; Minimum step size Chi:0.01; Minimum step size X:0.01; Minimum step size Y:0.01; Minimum step size Z:0.001</entry>
		<entry>Diffractometer system=XPERT-PRO</entry>
		<entry>Measurement program=C:\PANalytical\Data Collector\Programs\Jorrit\2thom\_absolute_2th-om_10-130deg_PIXscan_56min.xrdmp, Identifier={15BCCF57-2807-42BD-B5B9-ECC0B3DC9284}</entry>
		<entry>Batch program=C:\PANalytical\Data Collector\Programs\SimonL\batch4x_2thom_10-130°_z9.1_x0,10,20,30_y0_57min.xrdmp, Identifier={EED9823A-2BEB-424C-9252-345C4EF2834A}</entry>
	</comment>
	<sample type="To be analyzed">
		<id></id>
		<name></name>
		<preparedBy></preparedBy>
	</sample>
	<xrdMeasurement measurementType="Scan" status="Completed" sampleMode="Reflection">
		<comment>
			<entry>_absolute_2th-om_10-130deg_PIXscan_56min</entry>
			<entry>PHD Lower Level = 4.83 (keV), PHD Upper Level = 11.27 (keV)</entry>
		</comment>
		<usedWavelength intended="K-Alpha 1">
			<kAlpha1 unit="Angstrom">1.5405980</kAlpha1>
			<kAlpha2 unit="Angstrom">1.5444260</kAlpha2>
			<kBeta unit="Angstrom">1.3922500</kBeta>
			<ratioKAlpha2KAlpha1>0.5000</ratioKAlpha2KAlpha1>
		</usedWavelength>
		<incidentBeamPath>
			<radius unit="mm">320.00</radius>
			<xRayTube id="1010048" name="Empyrean Cu LFF HR (9430 033 7310x) DK442154">
				<tension unit="kV">40.0</tension>
				<current unit="mA">40.0</current>
				<anodeMaterial>Cu</anodeMaterial>
				<focus type="Line">
					<length unit="mm">12.0</length>
					<width unit="mm">0.4</width>
					<takeOffAngle unit="deg">4.2</takeOffAngle>
				</focus>
			</xRayTube>
			<xRayMirror id="27010001" name="Inc. Beam Cu W/Si (parabolic MRD)" hybrid="false">
				<crystal type="Graded" shape="Parabolic">W/Si</crystal>
				<acceptanceAngle unit="deg">0.800</acceptanceAngle>
				<length unit="mm">60.0</length>
			</xRayMirror>
			<sollerSlit id="21010002" name="Soller slits 0.04 rad.">
				<opening unit="rad">0.0400</opening>
			</sollerSlit>
			<mask id="22030007" name="Fixed mask 2 mm">
				<distanceToSample unit="mm">220.00</distanceToSample>
				<width unit="mm">2.00</width>
			</mask>
			<divergenceSlit id="22010007" name="Fixed slit 1/8°" xsi:type="fixedDivergenceSlitType">
				<distanceToSample unit="mm">220.00</distanceToSample>
				<height unit="mm">0.19</height>
			</divergenceSlit>
		</incidentBeamPath>
		<diffractedBeamPath>
			<radius unit="mm">320.00</radius>
			<sollerSlit id="21010002" name="Soller slits 0.04 rad.">
				<opening unit="rad">0.0400</opening>
			</sollerSlit>
			<receivingSlit id="22010001" name="Fixed slit 4°">
				<height unit="mm">5.88</height>
			</receivingSlit>
			<detector id="7010017" name="PIXcel3D 1x1 detector" xsi:type="areaDetectorType">
				<phd unit="%">
					<lowerLevel>30.0</lowerLevel>
					<upperLevel>70.0</upperLevel>
				</phd>
				<mode>Scanning</mode>
				<activeChannelsEquatorial>255</activeChannelsEquatorial>
				<activeChannelsAxial>255</activeChannelsAxial>
				<pitchEquatorial unit="mm">0.05500</pitchEquatorial>
				<pitchAxial unit="mm">0.05500</pitchAxial>
				<readOutPeriod unit="seconds">0.135</readOutPeriod>
			</detector>
		</diffractedBeamPath>
		<scan appendNumber="0" mode="Continuous" scanAxis="2Theta-Omega" status="Completed">
			<header>
				<startTimeStamp>2024-10-25T12:54:24+02:00</startTimeStamp>
				<endTimeStamp>2024-10-25T13:50:30+02:00</endTimeStamp>
				<author>
					<name>PRO-MRD</name>
				</author>
				<source>
					<applicationSoftware version="6.1b">Data Collector</applicationSoftware>
					<instrumentControlSoftware version="7.0E 20130304">XPERT-PRO</instrumentControlSoftware>
					<instrumentID>0000000011142674</instrumentID>
				</source>
			</header>
			<dataPoints>
				<positions axis="2Theta" unit="deg">
					<startPosition>9.99826193</startPosition>
					<endPosition>129.99755682</endPosition>
				</positions>
				<positions axis="Omega" unit="deg">
					<startPosition>4.99913096</startPosition>
					<endPosition>64.99877841</endPosition>
				</positions>
				<positions axis="Phi" unit="deg">
					<commonPosition>0.00</commonPosition>
				</positions>
				<positions axis="Chi" unit="deg">
					<commonPosition>0.00</commonPosition>
				</positions>
				<positions axis="X" unit="mm">
					<commonPosition>30.00</commonPosition>
				</positions>
				<positions axis="Y" unit="mm">
					<commonPosition>0.00</commonPosition>
				</positions>
				<positions axis="Z" unit="mm">
					<commonPosition>9.100</commonPosition>
				</positions>
				<commonCountingTime unit="seconds">32.895</commonCountingTime>
				<counts 344 367 351 398 370 390 364 371 426 345 381 366 369 386 376 362 371 357 398 420 370 367 380 366 342 359 355 359 388 379 363 317 415 364 381 362 395 382 375 366 372 372 357 388 353 396 379 380 398 369 359 360 387 390 374 388 377 363 347 405 355 364 400 390 346 382 382 391 403 334 353 363 347 367 359 367 370 353 345 366 375 352 373 355 356 328 351 370 341 357 356 374 361 340 334 352 311 321 386 366 379 366 381 348 382 359 381 354 356 339 339 364 362 320 370 374 364 332 375 343 368 334 357 379 339 345 326 356 364 320 343 344 357 329 337 344 373 341 371 347 354 365 349 351 361 353 357 337 364 350 321 306 341 333 335 343 357 355 367 348 334 329 361 336 375 355 342 364 333 327 395 366 325 347 356 343 357 362 308 361 335 333 319 351 359 327 353 348 342 358 332 347 373 331 314 358 357 364 336 375 311 357 326 339 350 365 344 356 321 368 337 338 333 340 333 343 335 354 363 343 360 344 339 386 329 317 332 336 328 338 312 358 360 336 347 313 346 302 295 319 347 362 359 357 318 360 317 307 302 331 320 323 329 328 328 340 310 329 332 332 330 304 341 332 350 345 286 324 320 326 319 342 339 351 320 315 317 317 326 324 316 325 325 342 326 342 355 343 336 324 329 315 343 352 284 315 315 342 316 316 319 334 331 307 330 337 310 323 319 313 303 336 298 307 344 329 323 345 327 319 314 328 301 309 331 328 326 328 335 322 326 337 316 321 303 286 304 300 366 302 321 308 309 309 258 296 310 290 318 307 313 305 362 318 326 297 294 285 316 326 337 328 322 331 294 301 314 318 297 329 305 332 318 313 300 347 321 293 319 343 279 309 291 289 320 298 322 311 284 290 281 321 346 291 290 296 284 328 302 304 311 299 304 322 287 304 294 267 306 286 312 294 302 286 335 289 296 291 288 294 324 289 308 323 281 315 338 289 312 288 279 309 280 345 294 334 324 331 322 324 305 312 301 293 283 289 302 303 298 306 316 287 294 304 311 320 301 304 307 317 316 314 285 314 289 299 293 295 290 288 295 281 285 285 294 302 310 311 281 244 275 297 281 278 278 294 249 306 315 288 296 316 270 280 312 274 283 313 307 282 276 318 297 285 268 294 288 314 275 280 295 278 291 286 289 289 294 293 299 317 292 315 322 312 271 276 291 291 259 282 296 290 286 271 304 274 284 267 293 259 291 323 293 298 277 296 280 313 266 285 283 279 266 319 274 284 272 237 265 279 297 262 293 292 281 295 297 298 320 282 281 278 295 294 305 308 303 272 336 256 261 283 276 289 279 269 304 298 302 258 269 281 297 294 275 269 266 291 288 298 303 308 299 279 294 310 262 297 295 273 239 298 268 266 262 297 269 265 304 282 306 286 279 255 300 302 288 295 279 270 275 302 298 295 283 280 261 259 290 289 268 302 288 292 290 317 290 240 284 268 256 293 285 284 300 287 277 265 280 314 255 287 294 292 263 303 261 288 291 264 263 307 259 291 299 283 276 261 269 278 265 289 285 280 247 276 278 269 291 260 280 248 273 277 262 247 285 273 271 260 281 267 286 289 245 276 290 269 276 289 263 276 291 281 281 273 291 288 263 281 260 276 273 279 267 267 275 275 263 270 302 262 258 292 283 270 287 275 289 269 289 250 283 276 281 307 264 284 246 268 277 295 300 304 286 276 290 258 268 278 259 276 273 290 285 304 269 296 303 279 279 295 263 272 279 265 265 240 255 276 265 266 239 294 294 283 287 245 290 249 266 268 269 268 280 262 299 271 307 280 265 264 272 264 265 271 257 284 268 274 263 298 287 278 263 301 273 277 267 310 290 240 291 281 291 258 271 303 288 274 303 270 282 274 285 262 248 258 273 267 296 277 277 279 292 283 279 264 269 245 229 279 293 266 293 306 269 291 266 289 263 281 291 281 273 245 268 287 267 246 302 271 305 283 287 293 240 282 272 290 292 271 262 311 272 267 307 256 258 282 246 270 293 278 256 266 282 275 248 310 272 246 279 261 284 288 288 257 266 283 298 267 283 278 295 301 290 280 270 262 278 280 273 269 243 285 315 276 281 282 231 265 233 290 262 278 269 286 293 273 287 277 290 287 257 291 279 291 280 281 262 279 277 284 312 284 279 280 283 243 300 272 305 279 282 263 263 302 290 258 266 284 276 295 293 281 295 250 289 301 272 289 271 289 284 268 286 300 264 283 299 277 298 259 257 278 303 278 282 292 246 295 299 267 242 292 293 283 275 279 280 280 258 276 273 279 284 278 269 291 318 272 310 306 286 288 298 260 270 285 297 285 288 276 313 283 281 293 279 247 292 289 297 305 280 290 284 296 263 309 267 300 289 266 280 300 300 269 286 286 290 289 275 303 294 296 302 296 283 284 270 305 267 297 291 315 286 298 265 293 276 257 282 285 293 278 267 286 282 307 282 293 274 278 278 305 304 297 275 293 310 314 247 305 282 317 282 311 307 289 291 284 279 268 294 305 304 295 293 290 273 279 271 291 288 278 281 266 291 307 298 285 300 293 291 302 301 290 288 328 283 312 300 269 301 300 308 295 292 274 283 310 302 265 277 287 260 286 302 278 311 291 315 314 283 303 316 299 273 297 271 307 293 286 304 313 279 302 354 304 307 288 325 285 293 305 345 308 296 274 320 303 263 291 299 303 291 323 286 321 305 276 272 322 296 348 293 313 296 305 303 275 313 290 316 282 291 287 290 270 286 334 295 291 330 255 311 303 323 297 316 310 281 292 301 307 295 265 320 293 317 266 267 308 298 279 300 281 299 265 298 299 291 313 290 287 285 299 310 332 282 284 290 296 283 321 248 291 310 287 300 307 275 289 287 301 278 316 321 327 320 304 297 294 305 289 330 281 289 318 307 302 292 343 277 326 287 294 299 285 329 289 311 306 339 337 297 298 305 288 303 306 299 272 271 293 316 298 308 297 302 298 299 297 316 281 297 311 312 348 300 315 272 289 288 303 299 264 286 302 301 259 279 287 297 275 341 285 343 313 294 293 267 277 263 302 305 289 271 327 313 283 300 304 294 266 298 281 313 289 320 299 301 274 268 263 284 317 302 305 300 293 265 299 293 291 290 303 286 288 268 287 323 328 284 280 282 295 289 271 263 267 279 269 306 295 294 311 281 298 292 305 287 286 295 312 314 315 325 266 270 266 285 309 293 308 301 300 268 284 277 277 287 313 293 290 288 271 280 309 313 287 283 306 303 276 314 321 270 280 269 322 288 269 309 287 271 275 288 281 288 312 293 268 290 282 319 269 276 285 283 266 281 312 304 298 322 289 307 294 306 326 315 291 285 287 266 290 282 283 276 249 283 259 257 283 281 288 282 285 270 266 301 309 319 295 308 304 288 277 279 292 278 275 300 274 275 275 299 315 291 270 263 282 307 266 283 281 308 264 299 293 270 283 259 272 271 275 285 276 290 296 271 308 290 302 266 287 300 283 286 301 263 246 273 267 285 307 264 287 275 284 284 269 294 293 272 261 249 278 282 284 264 280 272 272 294 259 279 282 293 278 284 257 303 256 264 293 308 279 255 259 284 287 287 286 299 259 287 247 268 276 260 245 241 292 291 280 294 278 288 273 247 296 264 271 262 299 273 262 266 255 258 261 257 299 258 256 285 256 279 245 289 296 280 285 270 279 255 272 269 259 286 283 249 263 248 271 290 299 266 244 279 250 268 225 245 260 247 280 272 287 296 260 246 267 274 274 257 290 282 291 282 266 260 283 267 281 290 293 247 269 246 260 239 261 258 275 282 278 274 256 294 227 262 229 269 264 276 277 279 222 264 266 256 266 258 276 260 239 262 240 246 234 260 245 242 248 271 264 268 295 267 238 281 275 272 268 275 255 240 246 266 269 239 249 247 279 284 233 280 249 280 256 239 239 241 247 268 264 270 245 262 267 255 263 246 273 212 270 233 265 243 271 263 261 248 237 265 267 236 272 221 248 280 203 278 260 256 238 281 237 262 266 259 226 250 271 262 240 243 291 246 224 256 235 260 213 273 235 216 257 246 236 307 284 265 290 241 266 238 216 255 231 227 280 301 259 225 278 257 273 240 237 242 238 260 218 260 268 229 233 243 220 235 263 232 244 239 248 228 238 257 276 230 257 230 225 246 229 258 265 236 277 259 261 239 273 272 258 260 237 238 246 258 223 242 237 237 245 272 212 246 264 240 242 244 229 232 255 269 256 289 242 267 246 260 257 232 216 223 256 244 269 238 239 241 240 257 226 225 248 221 234 235 259 220 242 223 237 257 266 227 238 238 234 233 220 221 277 228 227 275 229 235 258 239 203 260 255 265 248 260 242 218 227 248 233 216 243 234 225 221 249 263 261 260 239 212 216 225 216 243 227 225 229 249 257 236 267 270 240 238 257 229 267 230 238 215 236 263 216 227 235 263 243 255 227 277 233 237 215 276 215 243 255 221 247 263 225 228 240 237 230 257 214 233 225 230 260 256 256 239 228 217 249 227 217 227 231 244 232 239 242 215 242 236 246 239 237 234 236 232 227 236 223 255 231 272 240 232 236 236 225 272 261 226 209 262 223 227 242 209 216 227 241 249 244 234 267 234 238 234 203 231 222 224 222 239 214 219 258 216 202 257 229 245 236 236 233 246 222 242 239 230 203 224 199 266 211 225 221 212 216 231 204 227 259 206 262 240 230 210 242 266 269 221 265 233 239 240 232 270 255 218 228 235 247 229 226 236 212 225 222 238 232 228 246 240 231 233 214 219 255 241 225 233 237 231 258 242 216 235 223 248 262 244 219 244 262 229 225 259 199 228 226 233 224 204 240 205 231 241 211 239 265 242 248 217 248 231 239 229 224 222 228 230 219 215 205 270 281 232 228 227 267 225 244 240 214 221 240 220 226 228 213 265 216 235 236 247 248 229 257 231 248 207 210 242 230 214 219 209 224 207 212 236 231 218 222 202 217 224 229 211 221 220 279 217 225 244 217 207 246 256 242 234 215 203 219 241 228 214 222 221 230 217 229 204 224 236 220 208 206 231 194 210 233 238 249 216 209 235 219 230 229 225 219 237 193 212 214 239 229 246 218 218 224 243 206 234 219 224 258 226 217 216 213 240 221 231 233 197 234 278 227 256 207 191 201 220 217 219 227 225 238 244 255 230 243 221 256 232 226 236 211 220 201 204 214 245 219 237 203 228 220 237 201 246 231 228 230 227 240 205 228 227 204 226 228 237 245 240 203 211 208 246 239 227 223 222 224 213 222 226 242 228 230 237 228 238 220 212 212 241 198 220 231 189 221 243 233 243 234 218 248 218 239 235 212 220 223 234 212 220 216 217 215 207 217 204 225 206 216 223 250 201 227 243 257 227 214 237 227 211 236 230 229 214 208 258 224 222 212 248 235 231 231 207 217 219 212 242 257 240 213 232 181 199 226 216 211 207 222 244 213 238 224 226 217 216 213 237 204 221 236 223 240 210 209 221 223 205 215 231 214 259 255 222 216 192 220 226 192 221 218 255 244 234 193 203 231 245 218 215 215 230 231 218 222 238 237 263 199 224 244 246 222 225 198 217 213 208 208 212 222 218 225 222 231 221 221 217 204 234 212 227 237 225 215 184 218 232 203 224 223 226 226 233 235 216 219 229 202 217 216 209 203 237 185 211 229 202 238 212 240 228 218 226 196 227 216 216 239 222 237 233 224 234 238 201 211 214 204 256 240 211 230 212 211 235 220 213 213 215 213 214 229 217 234 228 236 197 220 206 235 197 226 227 204 236 221 219 221 234 206 256 191 263 237 227 200 216 240 220 222 237 210 242 228 209 197 209 258 223 228 246 200 202 201 196 226 240 238 226 242 223 227 216 232 215 211 213 212 236 230 203 233 208 189 255 222 219 209 209 219 210 217 210 202 230 247 188 223 203 214 196 232 206 230 185 206 229 217 211 222 219 226 219 248 241 227 188 202 206 199 206 243 240 212 233 216 217 218 220 220 236 233 234 227 257 195 242 224 227 217 213 214 224 192 213 258 215 230 238 209 197 244 206 232 216 181 211 209 216 219 272 212 213 230 212 217 216 221 222 226 224 223 255 209 219 220 217 223 232 227 211 209 191 223 225 239 206 255 229 228 220 216 258 247 234 235 230 230 241 219 227 231 244 212 229 225 224 236 228 222 229 207 243 244 236 221 220 217 225 212 227 212 247 201 232 225 198 225 227 259 232 220 228 229 226 230 214 268 228 242 191 214 178 258 219 222 202 196 195 213 214 233 220 216 227 232 216 187 213 228 226 207 204 224 256 204 198 239 234 213 178 238 213 210 203 236 211 205 217 213 217 228 221 229 196 197 200 231 234 211 204 190 226 195 181 213 220 217 209 193 208 231 231 201 215 232 214 205 220 209 218 212 208 230 201 223 217 217 210 220 220 235 202 223 218 205 216 222 220 213 197 200 218 198 216 214 209 213 206 200 218 190 216 224 197 206 220 205 212 202 213 181 237 209 197 224 226 211 225 238 215 215 227 202 191 220 216 214 200 233 214 197 198 212 219 230 193 209 212 232 215 221 214 202 206 203 227 205 200 203 244 229 193 184 211 202 207 229 191 199 204 224 206 190 248 219 230 219 216 234 234 219 220 207 219 216 211 191 213 220 204 216 197 217 213 184 202 241 248 228 195 223 207 211 191 230 210 226 193 208 215 262 212 215 216 204 230 195 207 221 216 210 231 200 209 221 222 215 210 215 221 215 222 219 207 239 195 212 231 230 231 231 202 226 205 211 199 219 202 236 215 226 241 205 227 178 218 203 204 197 239 194 234 214 223 221 207 214 200 227 226 216 225 242 229 217 242 205 183 210 208 209 199 190 243 198 208 215 214 202 238 237 220 178 216 221 180 195 219 242 239 224 218 224 220 225 218 212 240 214 217 205 205 239 221 229 237 199 211 222 213 199 221 206 190 198 227 230 213 227 205 202 245 219 217 219 210 206 224 211 249 212 240 206 214 215 190 219 233 200 202 210 218 218 215 208 214 227 216 214 207 218 224 220 220 239 226 208 230 240 219 204 192 227 203 205 207 228 227 216 215 217 235 232 221 204 213 201 185 213 204 231 204 228 200 219 210 191 199 214 205 212 218 209 225 213 209 214 201 259 200 211 227 221 227 218 204 198 215 225 222 223 210 223 201 246 200 223 235 219 224 243 226 222 223 228 239 229 215 216 199 220 222 217 211 216 242 255 190 225 225 194 209 228 219 191 222 211 230 205 207 202 235 209 219 213 222 192 230 225 243 221 190 214 219 234 189 259 234 210 234 209 242 205 210 201 224 224 189 218 216 216 207 205 221 241 213 230 205 219 194 214 229 221 261 236 222 198 241 216 216 225 205 237 244 208 241 236 230 236 181 219 214 195 215 211 223 209 213 230 240 216 215 217 244 202 235 226 236 188 235 204 238 228 231 240 221 227 231 210 206 215 235 212 202 210 236 202 219 242 224 230 225 231 241 228 210 237 221 233 221 222 222 213 226 220 236 219 223 216 209 255 255 235 217 231 197 206 218 191 240 220 220 223 235 268 224 233 223 237 243 219 197 225 209 219 211 206 203 218 205 227 208 233 213 204 218 244 240 230 230 212 236 236 227 223 223 211 215 227 212 208 227 208 243 271 232 239 227 243 207 224 219 227 232 246 238 195 220 232 213 229 221 245 225 247 259 245 255 249 264 208 259 249 236 234 233 259 250 236 186 287 262 273 215 275 260 245 228 245 240 262 283 246 274 265 260 244 267 255 261 284 281 274 265 285 292 324 267 296 293 311 316 298 372 318 341 340 339 368 379 381 402 361 407 389 383 394 384 380 380 410 396 387 411 428 385 364 367 386 335 339 352 355 339 347 310 324 320 326 332 298 315 276 321 310 259 278 281 287 289 293 259 247 246 237 221 276 234 220 243 242 242 212 256 260 235 250 277 225 218 214 247 245 236 256 259 223 240 244 227 246 233 232 221 210 247 218 223 245 230 234 218 240 228 267 232 200 217 224 220 208 210 233 213 232 247 213 210 230 244 238 191 262 186 219 243 239 224 244 234 208 211 206 238 203 245 230 230 217 194 215 219 213 237 237 203 215 221 221 210 237 221 232 197 202 228 207 234 220 211 197 243 229 235 228 215 199 219 239 225 235 216 222 228 200 209 193 241 207 223 233 236 233 211 224 233 225 202 201 231 249 209 230 216 183 257 207 215 203 221 235 245 180 228 197 203 216 239 226 220 195 231 211 242 219 222 222 221 212 213 203 202 255 237 227 190 216 221 185 220 211 206 214 233 206 216 201 235 213 237 223 183 225 200 256 233 236 226 228 236 221 231 228 230 211 233 232 194 240 220 222 217 196 214 224 247 265 221 225 209 217 212 223 244 218 219 209 206 227 230 195 210 239 231 209 201 236 200 231 217 255 207 225 226 211 213 209 264 213 205 212 212 236 190 199 245 200 193 216 192 223 212 201 213 216 200 216 183 201 218 248 214 203 210 221 195 214 235 223 236 197 230 206 235 219 196 233 229 221 225 223 234 233 231 227 212 235 203 219 210 211 225 225 219 224 258 232 242 197 191 221 239 227 201 201 250 246 237 200 242 208 229 242 244 230 224 215 218 210 225 202 223 239 215 236 228 233 232 236 213 205 234 221 207 233 200 228 216 212 219 223 210 223 243 216 249 215 222 213 223 240 234 227 214 225 208 198 213 211 210 237 215 207 240 191 242 235 239 236 185 217 215 208 228 227 240 201 211 227 248 219 212 214 201 215 194 247 203 204 225 225 222 238 208 200 218 207 219 233 220 243 230 196 242 204 216 226 211 213 217 214 214 211 220 220 209 218 206 204 203 210 208 199 227 220 230 221 230 241 235 225 201 205 231 208 201 193 214 240 218 228 231 219 225 223 234 207 234 220 221 221 189 219 212 220 236 209 204 213 211 209 202 220 229 208 230 249 227 209 207 247 212 245 210 200 207 185 209 186 242 211 228 234 209 214 241 226 198 232 186 222 225 220 228 234 234 201 227 225 228 205 232 210 229 218 220 210 205 228 207 221 221 228 244 235 215 265 225 206 232 210 217 214 222 233 203 212 229 195 217 221 218 231 234 197 236 226 204 228 225 206 208 196 220 228 240 204 240 214 228 225 240 209 231 214 175 215 218 247 213 216 222 234 208 207 239 216 208 202 204 220 215 208 226 239 221 210 226 203 233 222 216 227 236 232 200 236 269 224 231 229 192 227 199 199 234 222 216 185 224 220 230 238 200 243 221 234 207 235 238 216 211 250 220 235 224 226 208 214 232 212 241 229 229 204 219 236 236 231 211 217 236 233 213 205 220 198 211 206 244 233 201 216 248 238 204 219 211 233 227 217 210 221 214 193 225 242 223 216 227 230 210 225 215 225 207 239 218 235 231 223 237 228 228 232 219 238 225 186 224 260 224 232 185 204 235 226 235 205 222 208 207 223 213 218 206 225 228 202 212 224 244 225 218 196 229 207 235 231 212 230 231 232 237 220 220 232 231 236 227 221 238 216 202 225 217 235 221 229 223 217 212 237 255 217 240 202 231 228 232 241 216 217 232 249 218 208 221 207 228 237 194 239 218 208 226 220 213 259 235 207 206 202 203 218 199 199 220 207 212 182 232 247 195 200 218 220 195 263 217 230 220 243 233 188 221 255 241 207 214 240 240 208 207 224 220 216 215 222 259 224 206 206 217 208 219 219 198 226 203 200 259 206 220 210 204 212 217 211 229 222 213 237 239 212 212 227 238 221 203 222 193 214 224 240 226 217 239 233 222 243 213 207 236 216 225 231 233 225 225 224 209 232 229 227 222 209 182 241 225 240 210 220 236 237 246 217 224 234 209 225 223 245 235 220 222 202 235 226 230 200 222 241 212 232 209 217 229 229 230 217 221 248 238 231 239 230 212 217 232 237 191 219 237 249 207 212 222 192 235 224 248 216 226 236 205 198 232 257 235 249 220 234 223 224 209 212 209 209 263 240 249 204 224 215 220 235 224 232 205 211 229 245 225 231 222 205 213 199 226 225 249 205 237 215 214 208 209 189 201 228 225 249 233 230 216 214 230 217 194 215 244 223 239 240 199 227 242 238 237 234 219 224 235 238 213 198 212 221 261 215 270 228 207 247 207 255 221 232 228 234 259 226 256 218 212 222 219 229 243 226 213 230 221 214 210 231 201 201 237 230 232 220 220 226 225 231 250 229 228 246 213 233 232 222 213 230 206 176 189 243 220 223 223 247 219 262 198 213 204 192 201 207 229 218 222 246 229 214 258 219 224 241 217 219 225 204 231 218 238 222 196 211 215 222 203 220 228 223 211 234 260 217 232 248 210 226 221 188 214 213 205 205 225 247 257 209 211 224 228 227 225 234 262 216 224 234 195 214 227 206 216 236 238 207 258 211 220 223 200 220 201 235 207 248 229 236 247 224 238 237 259 217 232 240 233 235 286 230 219 231 206 206 241 207 232 231 256 211 198 240 230 218 221 202 246 258 238 262 232 249 227 211 209 229 245 223 246 218 238 226 233 227 233 227 236 226 240 221 220 245 205 241 237 245 203 227 219 197 235 218 228 238 226 223 249 242 228 237 223 237 262 237 226 220 208 246 205 212 241 242 262 207 231 265 255 217 221 225 240 245 237 196 203 246 233 215 278 224 259 243 208 218 223 225 223 225 231 209 223 213 211 236 232 196 232 227 233 208 204 242 236 229 237 249 212 225 226 221 232 228 213 260 255 236 232 234 242 238 195 214 220 215 239 209 204 235 215 227 258 205 223 281 246 220 211 215 213 238 237 232 210 234 237 229 247 222 259 229 223 243 201 232 263 233 239 229 209 219 228 220 220 223 232 217 224 212 260 225 216 209 211 231 236 218 230 211 221 221 222 204 209 249 249 238 226 231 215 259 220 232 192 255 216 227 221 232 231 222 237 219 206 229 244 224 247 224 224 218 200 222 200 248 200 237 206 215 263 200 222 225 257 211 248 240 213 232 211 223 236 241 261 235 242 234 260 245 257 244 222 247 239 199 257 211 205 235 217 242 275 235 224 208 241 224 232 231 196 215 263 241 222 233 274 231 245 266 188 199 210 223 238 233 259 215 202 226 227 218 229 225 242 236 237 229 223 227 229 199 200 224 232 215 234 227 228 219 244 181 221 208 211 235 214 224 217 224 212 214 233 250 225 216 224 213 242 205 217 205 220 249 238 215 230 219 212 228 240 207 209 224 236 220 202 219 212 227 223 214 232 241 234 229 226 219 230 215 226 266 184 218 230 232 227 223 221 222 224 220 239 238 256 227 235 223 228 261 236 240 232 228 228 233 247 258 246 235 217 224 227 266 211 225 243 237 235 247 206 244 210 212 220 219 226 209 236 221 247 227 236 234 212 240 217 214 218 213 210 210 222 226 216 224 230 244 215 229 222 236 238 226 239 235 233 226 228 239 221 284 241 223 225 220 232 267 234 235 227 213 216 235 226 236 234 229 222 217 223 266 236 225 200 244 238 240 212 216 225 244 234 230 214 229 263 245 258 223 232 220 214 230 212 232 246 222 236 246 228 250 205 264 228 230 227 240 220 256 211 273 208 232 229 201 242 217 222 231 220 232 232 231 256 242 229 249 272 227 227 255 240 256 226 215 224 235 216 226 243 268 229 225 218 255 225 235 203 216 278 218 233 243 234 229 226 238 243 247 227 230 222 245 241 246 223 234 207 215 227 214 218 234 221 219 267 221 230 227 248 219 241 243 211 221 244 232 224 219 272 229 249 231 267 214 218 232 241 226 262 226 220 234 220 257 241 234 237 207 217 246 227 213 233 227 246 214 238 215 228 239 214 218 247 224 239 215 237 230 230 226 258 249 237 244 222 256 262 228 224 245 246 236 219 204 211 219 244 248 227 216 236 232 225 218 247 228 235 240 224 229 233 235 219 233 260 210 214 236 236 219 213 228 236 257 214 242 262 237 237 229 248 261 237 249 244 259 235 239 233 276 256 237 233 231 247 222 231 257 227 222 242 232 234 246 242 259 249 240 239 232 219 237 266 259 217 232 241 246 210 218 263 208 224 217 216 241 232 220 232 214 240 246 221 239 215 233 235 233 229 225 215 256 241 233 242 247 231 239 231 219 233 256 246 260 244 202 255 247 233 242 236 240 229 244 229 237 239 246 228 223 238 224 222 250 234 240 236 229 245 268 241 241 242 248 221 227 246 242 233 241 220 284 233 212 231 246 223 238 218 268 240 208 265 269 237 226 227 230 258 241 185 218 226 243 219 239 244 234 226 258 256 221 273 267 220 259 258 259 228 256 249 232 243 212 221 229 255 219 245 270 234 235 227 237 263 267 228 222 244 233 249 255 230 229 265 261 259 242 221 256 218 261 260 213 219 244 240 249 258 263 259 256 228 265 204 265 263 257 274 220 248 225 230 256 242 242 241 242 262 213 266 269 261 258 259 258 268 231 205 255 240 243 258 240 257 269 245 259 222 277 224 233 256 214 233 257 267 275 273 261 234 270 199 240 236 273 245 242 258 261 246 241 227 257 244 224 237 250 247 223 261 223 241 261 220 240 264 227 229 286 213 215 259 242 238 235 243 241 232 238 300 243 219 244 216 238 274 200 267 233 236 222 244 228 234 217 278 250 250 259 231 248 270 229 244 230 228 257 240 267 265 191 241 220 234 287 216 263 221 218 268 211 232 239 232 233 245 256 244 228 220 263 237 234 230 231 231 237 238 226 259 260 245 245 242 235 213 267 233 271 244 223 235 233 237 229 277 263 248 260 244 231 232 225 217 228 233 261 216 230 247 211 237 256 229 229 233 246 222 231 250 237 228 236 224 220 259 271 300 220 259 229 229 229 212 217 206 224 237 257 240 237 218 233 249 270 237 249 255 267 269 230 258 230 247 241 216 207 247 245 260 247 219 240 226 224 256 239 240 257 241 218 260 219 232 229 278 235 225 213 259 261 228 243 230 245 240 293 248 267 260 236 208 245 246 231 260 247 225 220 234 270 238 231 210 243 238 244 273 274 264 234 233 248 262 228 243 242 249 234 273 247 257 225 209 219 229 232 228 240 233 240 257 231 241 236 227 214 225 248 248 238 237 232 255 238 236 242 211 238 248 221 236 262 212 241 261 231 226 271 224 250 235 217 264 228 237 214 228 213 227 232 214 283 211 213 249 233 242 245 215 265 256 246 239 234 243 245 250 232 244 228 248 233 256 244 207 245 248 288 217 259 227 255 235 227 237 235 243 234 248 243 238 266 240 259 277 226 249 271 245 235 233 262 242 198 256 236 242 245 244 249 242 244 240 270 214 246 239 234 259 242 236 232 229 268 224 226 232 247 282 230 247 244 231 215 234 269 259 230 243 224 233 228 226 265 237 222 246 240 240 249 216 214 235 249 246 229 255 258 267 221 223 209 256 231 244 217 220 201 238 235 217 232 245 236 242 243 240 274 233 236 257 237 257 257 227 264 235 240 269 232 223 234 219 243 274 234 218 256 248 238 232 222 236 240 245 213 247 247 230 222 227 237 234 224 222 244 243 238 223 231 280 236 225 215 243 229 207 243 275 293 221 262 255 221 241 235 250 239 230 234 203 233 235 213 258 258 256 238 261 231 213 239 230 194 231 244 264 261 257 243 249 248 227 207 234 260 230 245 247 272 225 264 265 229 246 236 266 249 239 294 224 245 227 246 259 269 242 229 264 239 226 241 244 235 248 217 249 260 261 237 246 255 219 230 244 231 229 279 261 280 239 244 266 282 229 227 241 255 244 247 248 237 262 269 229 257 233 247 245 247 258 240 216 235 238 239 260 221 241 249 245 262 227 232 246 268 249 245 223 226 262 244 232 217 226 249 243 258 245 256 226 220 233 234 240 227 231 221 239 225 243 229 240 235 242 259 203 256 235 239 230 266 256 234 239 261 223 233 273 258 275 231 221 223 270 261 241 237 242 232 258 255 210 267 247 239 245 232 261 230 234 244 257 244 240 250 236 265 226 233 225 247 262 243 258 250 233 236 214 236 244 249 268 279 228 237 255 234 242 237 207 237 256 249 239 241 244 231 241 262 246 202 208 229 259 246 234 239 224 236 240 256 230 220 259 250 259 249 257 241 242 240 232 247 262 243 223 259 267 271 246 217 212 246 234 229 235 244 223 245 213 259 235 256 265 243 235 225 267 219 237 214 230 226 219 208 246 293 258 240 247 233 227 237 256 244 240 270 231 238 259 235 234 247 210 241 239 245 209 244 234 226 256 268 246 277 228 240 230 234 261 244 282 260 226 256 281 262 229 268 248 269 271 244 242 229 241 258 232 246 229 222 228 264 247 243 271 268 264 228 247 250 261 229 219 245 231 226 245 233 247 232 269 285 225 223 242 255 227 263 260 217 231 258 232 260 262 239 214 266 265 225 232 214 238 248 267 217 264 259 211 245 224 264 234 231 217 212 248 247 262 269 226 214 229 277 224 255 244 221 237 245 221 259 205 225 242 249 260 244 241 249 256 230 214 271 245 241 223 242 240 262 249 258 271 270 216 269 224 264 228 234 219 228 274 284 206 242 248 232 216 268 245 248 240 227 246 245 238 223 260 239 215 259 228 229 221 218 219 238 232 224 256 228 258 264 237 242 236 233 243 257 217 233 246 228 233 240 278 241 246 233 239 221 233 237 257 222 227 238 238 239 244 205 266 268 257 218 247 271 227 213 290 270 230 271 231 233 262 249 243 225 235 217 233 218 224 243 223 233 233 233 255 202 240 236 264 228 242 257 245 242 224 247 221 255 275 230 204 230 263 236 268 203 272 225 242 227 225 259 224 258 234 228 246 249 248 244 249 265 250 227 245 249 236 245 249 234 246 245 302 233 261 258 241 280 266 245 219 311 273 220 256 260 232 207 231 240 216 278 278 230 248 223 240 248 264 221 206 263 241 243 232 257 241 229 233 263 248 233 223 236 234 237 260 239 231 230 249 264 220 282 256 230 245 236 223 236 228 234 258 263 249 243 212 233 232 224 237 220 241 223 274 274 259 236 241 283 269 247 249 260 243 236 223 237 267 270 239 244 243 236 215 246 243 239 219 214 294 230 261 269 233 260 230 268 229 223 235 259 224 229 249 238 243 230 235 243 243 235 235 239 213 265 261 243 223 235 247 270 239 225 240 269 258 257 235 257 240 236 232 249 248 262 245 228 263 283 244 220 260 268 246 241 226 258 236 270 237 225 236 234 269 219 278 221 229 233 233 264 229 226 235 264 235 234 242 235 239 249 238 228 237 270 273 213 244 255 222 243 238 239 239 240 229 226 236 240 263 261 228 241 218 242 246 216 225 257 217 241 227 266 220 214 257 255 238 241 242 240 219 258 224 229 260 247 239 233 214 241 237 237 223 268 240 229 240 227 234 220 218 235 249 204 226 236 263 245 222 229 223 239 244 242 246 244 244 229 271 247 236 243 250 276 220 244 260 226 230 257 235 234 264 230 242 221 247 236 222 224 230 248 245 249 229 246 227 271 245 258 224 221 225 263 264 210 243 247 239 260 218 239 264 219 228 258 234 229 239 240 244 229 223 236 267 235 201 227 195 304 238 257 220 227 242 238 244 218 249 243 214 282 230 220 238 237 245 272 269 220 258 210 241 214 269 261 214 224 217 244 257 281 236 241 223 257 212 229 242 238 230 246 269 228 256 224 241 238 244 220 244 232 225 213 218 261 249 240 242 231 220 235 283 228 220 235 226 266 240 241 248 227 231 218 222 228 264 231 232 249 222 223 219 229 236 236 230 255 239 241 240 263 236 230 234 240 226 236 247 257 258 235 226 263 234 222 215 203 221 239 270 255 226 236 219 224 247 245 212 225 221 257 209 224 220 213 243 232 256 238 200 243 245 230 238 234 235 236 249 225 235 257 231 222 262 228 234 236 256 260 219 227 229 246 225 239 221 219 260 229 238 226 246 234 225 222 246 249 257 225 212 238 238 213 229 283 243 257 230 222 235 257 209 230 226 242 234 237 255 215 259 228 218 214 230 266 215 243 223 230 246 257 264 236 228 243 217 228 232 210 222 247 222 228 240 242 221 238 248 226 260 234 240 264 255 264 240 201 212 204 237 233 233 231 229 239 246 242 260 220 229 237 232 243 275 243 231 230 249 206 228 256 208 241 242 201 212 291 228 237 240 240 267 263 214 271 262 249 226 236 248 238 216 224 282 210 233 248 227 237 239 271 226 229 263 233 222 229 217 246 220 199 240 235 233 214 270 212 228 239 240 230 246 257 237 225 240 224 243 243 234 259 217 233 257 255 221 232 243 231 286 259 277 235 270 246 246 258 265 235 259 229 239 236 233 234 237 227 203 236 243 274 257 247 256 249 230 212 242 270 266 231 243 232 239 255 263 281 228 267 279 243 278 275 268 269 243 265 295 276 265 222 281 236 304 281 274 268 270 307 246 232 297 266 299 248 271 285 316 273 292 292 261 267 255 245 294 267 248 247 279 244 262 290 261 269 238 248 279 229 272 255 274 263 267 287 223 268 295 278 248 275 284 244 229 255 294 263 284 247 243 244 244 247 241 243 238 277 255 255 216 262 238 247 240 211 246 241 238 237 263 214 246 241 258 273 223 239 236 219 249 276 249 228 264 242 227 249 256 210 247 247 240 242 233 230 220 268 244 224 233 230 223 260 250 238 224 249 240 224 249 227 223 230 221 261 261 237 262 285 276 245 261 261 223 242 210 228 237 234 259 212 232 248 242 199 246 225 230 215 245 239 237 228 270 203 218 218 236 246 249 264 220 211 264 269 214 258 227 233 239 248 234 257 233 206 258 228 211 239 232 222 266 209 239 242 215 269 234 219 212 214 234 210 257 238 227 243 227 245 232 219 234 219 190 230 224 216 227 245 264 200 220 227 240 259 225 219 214 248 260 214 256 230 245 240 231 230 209 233 222 207 208 220 249 209 238 221 236 231 221 256 219 234 226 236 218 227 243 226 270 234 236 234 237 255 217 227 259 203 241 220 245 220 277 245 228 227 234 229 244 222 218 242 225 237 234 233 201 231 245 222 216 215 256 243 219 241 217 268 217 218 204 246 226 266 226 272 238 214 230 204 207 236 238 229 204 221 237 264 280 207 240 257 216 229 236 215 214 215 215 225 257 246 216 231 220 227 186 258 227 248 213 236 210 250 208 232 226 228 216 234 242 230 216 229 239 240 263 273 219 235 245 227 247 248 234 235 231 222 219 255 229 238 207 212 222 229 247 239 218 215 228 222 232 232 240 206 224 217 220 211 207 218 223 220 224 230 280 243 198 217 237 209 218 267 257 211 236 238 232 220 218 196 214 226 209 258 245 273 227 231 268 212 269 228 227 239 235 220 232 227 215 260 226 219 222 223 267 213 221 208 227 266 239 223 228 223 226 229 226 222 231 260 217 249 233 244 232 232 237 225 236 230 224 245 247 236 200 218 272 232 237 243 234 220 210 240 233 247 233 214 259 247 220 262 240 244 244 243 222 229 214 231 220 258 239 240 208 227 233 226 241 224 256 220 225 244 237 244 248 238 236 225 235 246 261 239 211 235 212 256 237 235 234 233 246 220 205 241 217 242 235 256 231 216 238 262 234 243 226 226 247 233 222 243 228 223 232 210 231 255 237 207 238 239 248 216 230 230 261 237 222 215 260 233 232 231 235 229 219 214 256 239 217 257 198 247 262 215 260 232 250 231 232 225 236 201 220 226 221 268 233 228 217 245 236 229 210 234 231 228 239 247 243 269 232 238 236 261 225 234 214 257 236 235 265 213 242 235 246 223 257 243 226 226 235 256 229 264 199 216 232 220 218 230 209 234 200 233 241 218 221 217 239 271 242 260 236 224 258 211 220 210 220 219 235 231 222 212 263 237 212 188 241 233 232 235 220 209 244 221 233 240 218 234 248 218 224 237 212 245 258 227 230 226 206 223 238 206 210 235 230 208 236 246 217 225 233 223 264 227 238 246 266 225 226 245 232 263 240 239 285 207 212 234 211 226 242 223 239 223 229 235 255 192 237 234 212 240 222 256 235 198 221 250 228 200 232 239 232 242 244 209 234 207 210 217 258 222 230 238 209 229 249 276 218 218 236 202 213 221 243 230 241 229 225 237 227 211 220 232 231 235 230 232 219 214 227 241 213 256 229 236 231 262 230 243 238 242 245 244 223 249 222 236 223 241 234 231 263 234 220 198 233 231 233 202 262 239 208 229 215 237 247 208 229 220 227 226 222 222 218 249 232 239 210 241 245 248 226 261 212 233 222 219 228 236 231 217 192 244 242 217 211 250 228 222 232 227 219 214 222 207 231 221 247 241 218 202 260 233 237 244 229 235 236 217 244 233 219 236 244 212 226 224 222 207 227 226 223 237 235 209 261 265 200 230 238 222 261 229 213 243 233 210 233 242 258 223 212 241 220 216 224 202 215 211 234 245 245 213 234 226 259 234 214 224 206 239 228 228 246 229 223 240 220 246 235 233 256 217 245 196 259 223 223 225 226 237 216 232 269 231 259 236 238 226 215 238 216 227 229 245 220 233 208 227 210 232 213 223 229 260 228 245 240 212 243 245 244 248 231 226 222 247 229 234 258 241 267 257 222 241 261 242 240 257 267 221 242 236 246 217 267 243 222 249 245 250 223 194 216 248 242 213 217 211 220 221 257 226 239 247 238 238 198 217 229 237 257 239 266 250 212 215 232 245 256 221 228 236 223 230 235 235 230 223 198 241 220 240 234 229 221 237 233 214 231 205 211 211 236 240 242 260 246 236 215 238 246 238 248 229 241 259 219 256 233 232 236 233 250 220 246 236 239 210 231 249 277 214 231 271 238 241 231 233 279 239 225 247 222 236 240 242 217 247 228 229 261 243 258 247 257 214 222 244 215 240 220 269 231 269 240 230 220 213 231 217 213 245 219 185 250 256 214 243 210 233 245 230 199 242 231 208 234 271 266 225 278 218 246 228 278 213 234 224 216 238 246 219 232 245 230 231 235 238 219 221 243 225 256 216 258 264 260 244 249 255 243 232 248 231 221 249 241 231 225 257 267 257 237 223 241 216 228 225 230 209 234 241 225 221 218 214 236 241 218 223 238 239 275 234 233 222 221 201 229 236 217 225 250 237 220 224 228 232 241 229 246 212 249 229 227 259 234 215 220 223 220 248 238 228 255 234 206 247 256 243 209 227 240 280 239 223 233 224 230 233 223 231 263 223 248 237 222 226 262 222 240 208 240 267 229 216 231 238 224 220 240 230 232 230 248 227 233 256 218 234 221 200 227 235 258 204 229 238 231 220 231 226 230 237 242 222 236 221 208 248 234 218 220 224 275 224 241 259 200 213 231 224 222 218 237 218 215 225 246 240 223 216 220 235 229 230 260 224 233 224 213 218 263 243 210 237 222 212 214 229 233 214 229 258 256 244 232 214 247 227 227 249 226 228 223 197 209 282 245 240 239 249 230 230 274 232 244 228 243 243 236 210 238 238 227 243 204 236 220 267 229 244 235 216 231 231 244 233 238 211 234 229 231 243 215 228 235 226 238 219 239 211 235 247 235 228 235 264 206 219 236 255 240 230 239 224 193 237 247 258 226 265 220 258 236 216 227 249 224 236 217 244 214 238 242 212 231 236 260 225 227 208 210 227 231 277 257 233 226 230 208 219 228 229 221 236 214 228 212 242 247 209 232 243 243 246 228 215 245 256 274 261 257 224 226 199 216 233 236 255 237 209 231 229 256 242 213 218 233 239 255 245 249 238 266 242 240 206 256 223 239 242 220 218 225 221 258 238 224 226 193 243 206 216 221 215 277 209 217 225 217 224 234 220 218 207 231 230 219 240 261 227 256 213 233 230 212 215 257 222 215 233 237 231 223 232 241 238 242 227 229 208 218 250 226 197 240 243 262 229 243 236 232 218 223 225 245 221 223 220 246 232 216 237 212 226 199 237 264 232 224 217 226 258 247 234 223 236 230 224 222 208 234 223 226 244 257 227 237 230 247 225 261 238 225 233 225 232 226 230 230 238 234 229 245 237 209 241 225 234 228 248 227 215 258 228 245 195 226 212 250 234 245 217 228 231 210 248 239 248 245 211 229 235 235 212 235 255 258 242 256 271 243 228 263 220 200 240 244 223 269 226 241 232 236 239 248 230 208 268 232 225 257 249 265 217 277 232 265 244 234 228 261 236 246 246 219 248 209 221 242 246 256 258 250 248 277 223 264 256 230 262 230 223 239 225 233 244 245 256 214 258 267 204 235 231 257 220 224 243 250 277 227 243 232 245 245 243 240 295 245 226 231 225 255 229 218 226 246 266 229 267 241 231 228 258 233 239 232 237 228 231 255 237 230 243 241 221 280 232 241 225 235 237 244 243 234 227 269 237 212 220 245 245 246 257 233 263 247 228 229 231 233 220 242 245 247 235 227 232 226 258 215 235 226 231 249 225 237 207 223 235 211 257 260 250 269 230 226 214 261 247 215 240 237 245 217 238 229 274 215 229 255 225 243 240 241 241 238 227 205 234 230 227 236 225 210 234 232 244 215 250 232 276 200 204 264 224 259 219 218 218 206 228 238 246 245 266 224 263 224 222 241 231 224 216 247 229 231 231 257 224 204 257 220 269 231 250 240 226 243 229 229 247 233 216 255 211 256 217 233 209 234 248 229 222 220 258 213 263 223 239 247 236 221 226 279 205 233 220 233 234 226 224 222 223 234 262 242 215 221 262 220 241 218 233 234 230 237 266 206 224 231 255 240 223 239 243 226 263 226 243 201 225 217 217 223 226 238 248 235 212 216 217 228 227 243 262 224 220 256 223 230 231 247 260 216 205 247 235 272 248 195 199 245 223 244 237 247 215 233 243 225 222 216 248 208 234 238 256 259 258 209 262 246 240 235 255 227 260 224 218 234 219 229 238 248 217 249 265 217 225 243 237 197 259 230 241 221 241 239 211 235 205 233 246 217 257 238 242 243 259 210 230 227 257 226 235 226 236 246 221 214 247 208 232 240 256 228 241 229 206 235 244 225 211 241 237 227 225 207 205 249 244 249 222 234 249 231 246 237 246 211 236 217 244 262 220 255 225 219 227 202 226 240 248 223 244 243 274 232 233 259 236 211 259 237 247 245 217 220 223 248 218 221 193 228 219 223 226 221 234 234 221 230 224 246 235 266 231 236 242 226 219 230 235 229 243 222 258 258 226 221 238 226 224 211 208 230 223 243 232 237 232 228 259 186 234 227 260 257 248 233 221 219 224 222 217 225 228 247 235 247 231 233 238 261 225 208 270 247 200 214 234 217 245 213 229 261 267 238 233 234 224 234 256 235 223 263 234 220 255 265 223 269 246 265 215 219 225 246 228 239 244 208 231 225 224 242 204 244 244 228 234 246 220 233 285 199 237 246 226 203 221 272 219 229 249 246 263 231 222 269 220 229 257 283 238 239 221 234 248 227 243 241 216 233 256 222 210 228 268 226 255 237 258 230 267 215 211 240 257 240 221 225 220 227 234 240 234 213 189 231 226 242 255 229 233 228 242 240 239 230 249 249 225 233 225 255 217 226 208 211 244 230 240 235 226 220 268 224 267 248 238 229 225 262 235 210 239 227 227 229 237 249 218 231 224 273 236 276 208 215 285 260 240 208 230 216 236 222 234 219 211 222 230 257 218 261 243 241 228 256 220 269 223 260 229 240 236 219 255 221 244 213 219 207 224 271 233 246 233 223 226 240 240 234 227 230 246 231 226 223 234 214 232 264 243 239 221 235 258 248 246 204 246 266 241 239 219 256 229 262 206 247 245 229 261 242 230 206 219 256 225 261 240 262 245 239 228 243 237 245 215 236 263 219 217 229 218 238 247 241 236 256 230 230 225 216 236 205 227 266 246 247 246 249 211 230 222 237 218 244 202 203 214 248 258 255 220 221 219 228 255 231 270 260 240 233 214 237 233 210 239 221 248 229 277 238 241 218 256 255 261 247 245 233 248 224 238 238 245 234 237 249 238 223 235 248 229 228 239 230 222 228 233 247 231 244 238 236 246 230 255 244 232 210 286 235 255 225 212 255 233 255 232 222 206 205 239 230 279 236 244 225 238 223 240 237 236 244 270 210 229 264 266 223 227 238 225 269 230 226 229 233 216 227 239 237 205 246 225 245 224 256 198 231 239 222 201 230 241 244 237 273 228 230 223 191 223 215 256 230 224 284 244 263 260 210 221 239 257 256 234 246 218 262 242 247 212 248 259 215 262 255 269 231 236 255 245 239 240 260 243 197 219 222 229 228 213 217 209 233 244 211 245 234 233 238 243 230 247 237 241 245 240 222 204 237 222 235 244 229 246 247 206 239 240 227 248 208 231 189 243 243 213 225 237 246 242 214 258 210 223 244 241 236 234 268 226 227 223 270 209 218 238 224 238 249 266 214 219 228 238 217 226 208 233 216 262 215 218 248 260 231 239 237 247 246 212 209 233 260 238 216 257 278 228 268 232 238 232 242 232 232 225 237 250 230 247 223 238 246 199 234 241 200 242 206 220 240 242 228 240 229 220 246 257 242 208 229 255 240 196 220 231 224 276 248 236 245 237 213 268 230 215 235 213 269 213 244 237 236 243 223 242 245 222 216 267 219 217 257 227 234 217 259 245 229 230 220 264 229 216 236 257 228 200 228 238 201 223 231 235 226 230 226 273 264 216 219 213 238 234 213 255 256 227 256 231 245 235 259 225 256 248 227 209 219 211 234 243 258 228 232 256 231 238 232 245 260 267 265 226 237 222 237 231 244 255 246 233 231 227 232 229 237 232 223 236 213 232 217 267 245 215 242 230 235 250 234 234 227 206 244 229 225 260 239 212 239 244 210 246 260 206 244 223 229 223 204 245 221 228 278 221 210 249 210 232 228 229 224 238 229 260 247 221 255 222 204 235 220 245 263 239 229 237 230 245 215 239 242 227 235 257 248 231 235 218 238 243 245 236 225 214 203 222 240 227 258 227 257 228 241 208 244 227 238 255 231 212 222 234 233 243 260 242 211 238 258 228 249 242 205 230 237 224 220 258 230 206 267 237 213 206 260 201 255 242 219 225 222 224 259 214 233 247 228 212 241 257 234 232 259 228 223 264 234 207 194 221 235 230 231 244 211 216 208 227 219 246 239 232 211 229 239 219 231 222 246 237 240 242 240 267 236 216 221 225 243 256 265 243 223 235 241 240 210 242 241 239 220 222 260 215 243 209 237 240 233 229 230 246 229 247 224 271 227 246 215 217 224 228 217 243 269 257 211 212 266 260 255 209 228 215 217 247 226 211 230 236 223 232 247 257 245 219 223 215 218 233 242 223 227 267 238 258 236 256 214 220 241 259 238 231 225 229 202 226 239 258 273 199 237 222 233 234 225 222 220 233 196 205 216 202 232 247 209 236 210 255 236 218 246 225 224 258 210 201 235 222 237 258 232 255 242 261 211 232 225 243 203 207 261 222 230 233 223 211 236 230 215 223 246 208 247 223 221 256 239 240 241 240 216 242 262 220 223 221 223 240 220 243 243 225 236 235 231 246 222 246 226 215 249 217 219 193 212 208 238 224 241 246 204 207 235 260 218 235 225 235 258 242 245 228 214 255 227 219 227 224 234 240 237 209 228 222 230 245 247 264 229 241 230 263 213 248 265 248 220 217 236 227 225 228 228 207 231 257 244 197 228 214 264 248 233 257 213 185 225 239 213 233 241 233 265 228 241 228 233 227 228 238 227 214 219 239 218 239 223 265 245 230 257 259 235 234 221 247 234 226 239 241 267 246 221 206 217 222 225 223 211 212 232 218 245 224 233 257 212 237 220 220 215 250 225 222 264 218 231 226 216 213 241 218 225 235 201 213 245 224 225 218 217 202 221 231 235 233 225 234 212 231 229 230 240 272 246 231 230 263 238 226 226 257 234 230 256 238 224 209 222 218 226 230 222 240 201 237 211 220 224 230 244 255 241 232 255 220 268 240 233 224 227 233 223 234 233 220 218 242 200 234 228 226 263 238 237 238 235 238 222 198 274 238 213 232 246 215 218 232 243 240 215 213 244 206 216 263 221 230 223 234 242 228 250 218 215 274 257 229 238 237 238 227 259 227 234 200 211 231 247 229 255 228 249 223 225 267 228 244 236 259 222 228 257 258 246 236 231 240 240 219 255 234 234 218 237 248 245 225 215 227 229 213 240 249 245 238 250 237 271 229 247 237 218 231 234 238 255 242 273 233 239 244 239 250 229 238 228 249 241 238 239 231 248 247 248 231 220 263 271 278 246 220 232 259 244 220 243 261 258 225 270 235 240 238 258 258 260 248 209 236 215 272 237 259 229 274 238 270 227 248 212 269 210 247 229 228 243 231 221 215 265 222 235 258 211 231 236 261 235 262 237 267 235 213 235 240 247 235 231 234 229 232 209 240 221 239 260 261 206 256 243 236 206 205 229 224 230 260 244 274 241 270 234 229 235 215 225 260 226 245 238 234 229 233 223 257 219 231 231 243 235 239 227 271 233 216 226 237 234 235 261 211 249 246 217 245 238 234 201 246 206 227 256 227 227 217 258 224 238 231 218 227 226 227 215 240 237 233 231 282 217 240 240 209 241 228 220 238 261 233 236 212 245 231 216 205 228 245 232 234 220 255 239 217 226 212 241 201 205 249 229 230 233 236 235 211 274 225 222 201 234 234 229 231 203 238 219 244 244 220 245 231 209 212 232 230 228 262 240 259 225 222 236 227 227 232 262 243 268 227 240 229 232 216 243 228 223 233 202 229 205 246 239 229 237 240 257 214 236 280 236 245 222 226 224 237 231 221 232 228 245 210 216 229 228 217 239 233 228 224 234 224 231 232 234 231 238 236 233 208 242 239 201 244 258 221 228 213 225 207 211 227 199 235 249 218 246 261 255 214 225 228 224 239 235 226 236 232 278 245 240 245 232 221 233 211 238 256 260 240 223 265 246 245 227 215 226 249 236 266 198 260 238 194 231 222 225 205 230 258 235 206 243 240 211 236 209 228 243 199 199 210 250 225 218 216 247 237 228 209 211 209 242 229 209 231 260 225 245 240 230 202 239 230 224 228 234 189 196 233 228 218 182 199 219 266 246 218 237 242 257 256 265 258 275 208 241 256 203 232 239 238 246 216 265 223 229 228 260 224 237 245 220 233 233 212 243 227 239 247 213 223 216 222 243 220 240 218 220 230 218 211 245 239 249 206 247 214 217 227 239 224 247 232 214 217 247 225 213 245 240 234 236 260 209 237 220 256 246 229 222 244 238 240 241 242 234 235 214 255 223 201 213 228 234 219 231 223 247 228 214 240 230 258 239 217 240 213 214 246 260 228 222 236 230 222 248 209 216 269 226 222 210 221 243 265 236 218 243 243 224 259 242 245 219 244 215 236 219 217 244 217 220 234 225 222 231 244 210 249 244 237 210 240 243 260 233 223 206 238 249 219 262 234 255 236 217 206 231 237 233 231 231 216 209 236 267 241 276 225 230 229 238 223 255 265 255 220 243 244 241 240 222 225 210 273 244 218 218 238 222 231 237 218 210 242 261 232 218 220 231 234 234 227 217 230 228 239 212 247 235 242 258 231 243 232 214 237 232 225 232 230 236 244 263 196 236 232 235 230 223 231 223 240 274 237 218 233 240 236 243 219 215 229 255 234 232 224 247 232 232 212 221 246 213 244 264 233 215 237 231 235 234 226 223 222 241 228 192 218 223 212 221 236 261 228 230 255 220 233 268 215 209 208 242 240 220 247 239 214 211 246 228 238 228 240 239 244 229 232 216 249 219 250 248 230 222 223 265 217 216 207 228 216 244 211 209 229 276 213 225 212 240 208 223 213 231 237 210 213 196 239 209 237 229 235 256 211 281 240 235 226 197 249 240 233 249 220 257 222 211 224 246 233 220 238 258 236 234 247 229 231 247 218 237 222 214 259 231 232 244 247 216 203 225 236 214 229 216 229 246 227 214 187 231 213 247 239 240 209 242 237 233 235 239 216 246 234 232 225 244 241 242 229 230 244 211 246 206 225 222 243 224 218 220 213 229 232 246 195 235 240 239 231 229 219 239 240 247 242 217 234 209 202 233 215 234 241 235 262 228 232 230 224 249 232 241 238 261 232 228 240 233 228 242 206 234 257 227 263 225 273 213 215 211 225 228 229 236 247 242 234 229 200 231 233 286 228 211 223 236 221 239 262 239 245 218 225 218 235 218 231 220 240 256 255 206 248 234 233 201 217 223 203 227 227 227 221 231 228 221 249 236 204 209 223 247 222 257 234 235 216 200 244 268 213 210 233 269 223 219 242 222 235 215 224 214 272 246 237 238 256 239 257 273 239 206 226 229 228 236 261 238 213 187 220 228 238 234 236 228 226 221 238 241 235 239 224 263 227 210 255 235 214 234 227 227 247 246 245 256 238 235 217 228 231 199 226 211 232 224 240 212 219 233 271 248 242 214 218 238 243 255 236 258 242 224 226 240 216 226 256 196 228 236 232 267 199 245 218 218 229 265 248 237 241 230 231 223 243 214 241 255 249 235 219 241 217 243 219 236 235 239 231 229 235 224 221 240 230 222 225 229 239 216 221 237 245 258 269 250 205 234 256 231 214 208 232 221 225 224 234 231 230 200 228 238 225 240 219 269 265 231 236 226 217 213 223 246 243 231 261 214 222 233 237 257 226 245 241 226 259 237 244 280 256 274 241 227 244 227 240 238 239 268 258 272 237 239 235 213 218 239 239 224 233 223 239 260 267 222 229 228 258 226 204 262 228 220 241 245 235 248 237 250 232 223 222 230 218 235 240 238 227 238 247 220 225 225 234 219 234 240 246 236 246 228 230 249 199 247 237 228 225 258 281 240 238 232 233 228 219 234 247 222 204 249 233 235 232 226 280 206 222 206 219 240 237 210 226 229 235 228 258 214 221 236 230 231 258 214 245 221 215 242 259 237 259 208 224 230 225 219 221 205 248 229 227 235 247 257 244 213 225 226 266 246 240 261 219 223 231 248 219 256 242 211 239 235 218 235 210 204 226 215 255 235 237 238 257 234 224 215 257 240 241 218 238 227 227 233 268 213 229 229 259 215 232 236 260 224 198 227 249 262 237 223 246 240 237 248 225 242 214 240 240 270 239 224 227 231 217 248 223 223 234 231 215 236 234 275 221 230 218 229 256 245 249 255 243 244 244 218 265 227 240 256 255 235 213 240 224 236 230 210 239 192 236 227 255 232 224 245 218 269 204 217 236 245 247 217 240 219 224 230 220 220 289 222 241 223 239 248 248 238 194 218 239 228 262 264 210 246 234 243 221 217 223 219 214 223 255 233 226 245 230 221 256 255 243 258 255 244 221 213 239 189 225 225 262 263 237 228 221 229 262 246 214 221 264 228 261 227 236 255 219 211 229 260 237 234 233 234 224 238 234 223 216 221 222 229 241 226 232</counts>
			</dataPoints>
		</scan>
	</xrdMeasurement>
</xrdMeasurements>