File: data/XRD/XG-Luft/XG-700/W6823-1D_XG_Luft_700.xrdml
<xrdMeasurements xmlns="http://www.xrdml.com/XRDMeasurement/2.1" xmlns:xsi="http://www.w3.org/2001/XMLSchema-instance" xsi:schemaLocation="http://www.xrdml.com/XRDMeasurement/2.1 http://www.xrdml.com/XRDMeasurement/2.1/XRDMeasurement.xsd" status="Completed">
	<comment>
		<entry>Configuration=Factory configuration, Owner=User-1, Creation date=7/8/2013 4:01:53 PM</entry>
		<entry>Goniometer=PW3050/65 (Theta/2Theta); Minimum step size 2Theta:0.0001; Minimum step size Omega:0.0001</entry>
		<entry>Sample stage=MRD Cradle; Minimum step size Phi:0.01; Minimum step size Chi:0.01; Minimum step size X:0.01; Minimum step size Y:0.01; Minimum step size Z:0.001</entry>
		<entry>Diffractometer system=XPERT-PRO</entry>
		<entry>Measurement program=C:\PANalytical\Data Collector\Programs\Jorrit\2thom\_absolute_2th-om_10-130deg_PIXscan_56min.xrdmp, Identifier={15BCCF57-2807-42BD-B5B9-ECC0B3DC9284}</entry>
		<entry>Batch program=C:\PANalytical\Data Collector\Programs\SimonL\batch4x_2thom_10-130°_z9.1_x0,10,20,30_y0_57min.xrdmp, Identifier={EED9823A-2BEB-424C-9252-345C4EF2834A}</entry>
	</comment>
	<sample type="To be analyzed">
		<id></id>
		<name></name>
		<preparedBy></preparedBy>
	</sample>
	<xrdMeasurement measurementType="Scan" status="Completed" sampleMode="Reflection">
		<comment>
			<entry>_absolute_2th-om_10-130deg_PIXscan_56min</entry>
			<entry>PHD Lower Level = 4.83 (keV), PHD Upper Level = 11.27 (keV)</entry>
		</comment>
		<usedWavelength intended="K-Alpha 1">
			<kAlpha1 unit="Angstrom">1.5405980</kAlpha1>
			<kAlpha2 unit="Angstrom">1.5444260</kAlpha2>
			<kBeta unit="Angstrom">1.3922500</kBeta>
			<ratioKAlpha2KAlpha1>0.5000</ratioKAlpha2KAlpha1>
		</usedWavelength>
		<incidentBeamPath>
			<radius unit="mm">320.00</radius>
			<xRayTube id="1010048" name="Empyrean Cu LFF HR (9430 033 7310x) DK442154">
				<tension unit="kV">40.0</tension>
				<current unit="mA">40.0</current>
				<anodeMaterial>Cu</anodeMaterial>
				<focus type="Line">
					<length unit="mm">12.0</length>
					<width unit="mm">0.4</width>
					<takeOffAngle unit="deg">4.2</takeOffAngle>
				</focus>
			</xRayTube>
			<xRayMirror id="27010001" name="Inc. Beam Cu W/Si (parabolic MRD)" hybrid="false">
				<crystal type="Graded" shape="Parabolic">W/Si</crystal>
				<acceptanceAngle unit="deg">0.800</acceptanceAngle>
				<length unit="mm">60.0</length>
			</xRayMirror>
			<sollerSlit id="21010002" name="Soller slits 0.04 rad.">
				<opening unit="rad">0.0400</opening>
			</sollerSlit>
			<mask id="22030007" name="Fixed mask 2 mm">
				<distanceToSample unit="mm">220.00</distanceToSample>
				<width unit="mm">2.00</width>
			</mask>
			<divergenceSlit id="22010007" name="Fixed slit 1/8°" xsi:type="fixedDivergenceSlitType">
				<distanceToSample unit="mm">220.00</distanceToSample>
				<height unit="mm">0.19</height>
			</divergenceSlit>
		</incidentBeamPath>
		<diffractedBeamPath>
			<radius unit="mm">320.00</radius>
			<sollerSlit id="21010002" name="Soller slits 0.04 rad.">
				<opening unit="rad">0.0400</opening>
			</sollerSlit>
			<receivingSlit id="22010001" name="Fixed slit 4°">
				<height unit="mm">5.88</height>
			</receivingSlit>
			<detector id="7010017" name="PIXcel3D 1x1 detector" xsi:type="areaDetectorType">
				<phd unit="%">
					<lowerLevel>30.0</lowerLevel>
					<upperLevel>70.0</upperLevel>
				</phd>
				<mode>Scanning</mode>
				<activeChannelsEquatorial>255</activeChannelsEquatorial>
				<activeChannelsAxial>255</activeChannelsAxial>
				<pitchEquatorial unit="mm">0.05500</pitchEquatorial>
				<pitchAxial unit="mm">0.05500</pitchAxial>
				<readOutPeriod unit="seconds">0.135</readOutPeriod>
			</detector>
		</diffractedBeamPath>
		<scan appendNumber="0" mode="Continuous" scanAxis="2Theta-Omega" status="Completed">
			<header>
				<startTimeStamp>2024-10-25T11:57:47+02:00</startTimeStamp>
				<endTimeStamp>2024-10-25T12:53:53+02:00</endTimeStamp>
				<author>
					<name>PRO-MRD</name>
				</author>
				<source>
					<applicationSoftware version="6.1b">Data Collector</applicationSoftware>
					<instrumentControlSoftware version="7.0E 20130304">XPERT-PRO</instrumentControlSoftware>
					<instrumentID>0000000011142674</instrumentID>
				</source>
			</header>
			<dataPoints>
				<positions axis="2Theta" unit="deg">
					<startPosition>9.99826193</startPosition>
					<endPosition>129.99755682</endPosition>
				</positions>
				<positions axis="Omega" unit="deg">
					<startPosition>4.99913096</startPosition>
					<endPosition>64.99877841</endPosition>
				</positions>
				<positions axis="Phi" unit="deg">
					<commonPosition>0.00</commonPosition>
				</positions>
				<positions axis="Chi" unit="deg">
					<commonPosition>0.00</commonPosition>
				</positions>
				<positions axis="X" unit="mm">
					<commonPosition>20.00</commonPosition>
				</positions>
				<positions axis="Y" unit="mm">
					<commonPosition>0.00</commonPosition>
				</positions>
				<positions axis="Z" unit="mm">
					<commonPosition>9.100</commonPosition>
				</positions>
				<commonCountingTime unit="seconds">32.895</commonCountingTime>
				<counts 372 359 385 355 356 352 357 403 370 372 355 337 346 343 411 370 361 387 335 374 362 372 377 396 356 365 381 359 380 375 406 342 366 344 392 381 392 355 366 373 366 349 378 380 338 339 358 397 390 353 392 392 409 385 384 390 355 388 332 375 358 375 358 346 380 355 387 394 367 380 369 351 355 378 381 372 400 368 404 354 388 362 392 346 355 369 361 359 400 393 355 364 388 334 347 379 351 386 365 340 353 373 396 370 348 357 360 365 314 349 325 362 355 334 352 351 373 366 354 387 326 362 373 336 366 363 365 388 344 332 388 372 361 357 343 347 357 370 370 389 363 334 324 343 338 343 322 358 337 335 349 357 357 358 372 374 360 341 356 378 343 389 359 361 364 307 356 341 328 365 343 371 346 347 370 360 381 369 325 342 358 350 372 350 373 339 337 322 354 346 315 363 357 309 354 312 310 335 355 353 333 350 358 338 330 317 334 314 335 297 347 307 321 335 343 323 332 347 311 313 343 334 336 306 295 347 325 336 336 352 348 341 368 334 334 323 335 306 352 331 346 320 323 333 344 312 359 350 336 334 337 318 327 349 350 320 300 324 357 315 337 344 320 326 363 303 354 309 333 328 334 326 307 308 316 305 284 298 328 337 342 298 314 351 324 350 298 328 320 325 291 323 326 319 322 299 350 315 319 319 300 315 305 318 361 324 327 343 300 329 342 297 335 343 305 302 325 317 319 301 313 319 318 301 322 294 327 306 307 298 291 300 291 298 317 320 316 340 346 289 311 298 324 320 354 306 337 319 295 324 306 332 302 310 333 314 318 303 306 305 297 301 270 329 293 350 323 323 324 284 331 312 318 305 302 278 275 325 298 311 310 299 295 307 288 310 308 300 297 295 286 295 314 312 306 299 315 311 287 309 276 309 287 291 309 291 319 316 305 303 271 293 289 312 321 316 322 290 326 296 294 309 309 279 292 268 304 262 273 283 296 313 328 311 290 287 316 249 318 313 304 303 269 291 287 266 286 297 326 290 312 325 284 277 310 300 272 300 275 262 269 296 295 278 319 294 308 272 287 297 264 311 309 300 286 281 279 326 281 320 299 312 274 306 271 292 292 305 310 292 308 302 265 269 302 244 279 285 296 270 278 291 303 275 296 295 281 292 281 282 289 313 295 272 286 293 315 318 289 282 286 276 291 287 317 280 276 293 259 276 308 296 306 297 286 274 299 313 287 277 303 280 311 265 316 290 283 246 304 290 273 304 294 298 310 249 303 289 286 263 257 281 274 301 273 289 293 242 291 317 264 279 243 247 296 279 275 269 305 280 265 256 300 295 277 261 296 270 284 294 282 285 282 288 270 264 294 282 274 302 283 273 291 284 257 265 279 259 271 288 290 242 305 269 275 284 280 246 247 264 284 297 237 270 296 285 261 275 293 288 287 269 300 248 269 268 262 261 270 286 293 303 286 279 245 282 264 260 249 302 259 287 285 306 259 262 271 265 293 286 293 269 275 295 277 291 317 274 279 295 289 277 289 282 256 261 295 271 288 271 321 296 270 245 305 270 289 288 255 261 264 300 246 292 269 260 271 270 243 303 280 284 260 264 286 260 276 259 248 262 294 291 265 239 281 265 288 256 260 290 258 269 244 270 274 271 266 266 274 243 266 277 275 275 268 255 318 246 247 274 279 261 276 269 222 263 244 279 259 279 278 277 275 295 292 297 241 268 293 275 262 239 245 294 265 272 266 265 259 273 292 265 278 272 290 244 309 256 283 263 262 240 282 238 284 248 274 255 248 263 287 301 255 283 294 256 265 284 286 284 289 234 285 258 273 271 272 280 292 269 280 237 282 288 271 258 267 248 241 292 279 289 284 305 259 283 281 282 272 271 272 262 288 262 237 279 265 271 285 282 245 278 275 273 262 286 284 247 281 289 296 302 282 292 299 277 256 276 286 236 261 295 268 275 249 271 263 266 268 249 266 230 258 248 242 261 274 293 262 273 246 269 276 304 277 240 266 273 275 286 276 317 278 257 284 295 269 244 280 261 274 280 291 261 215 272 235 273 248 257 273 277 268 268 294 266 287 281 264 258 279 291 268 279 268 283 292 260 283 268 271 245 292 260 292 246 300 250 280 261 293 277 268 283 306 278 258 301 303 258 270 277 241 293 309 280 293 282 278 265 266 257 266 268 283 278 264 275 298 266 264 268 278 269 300 272 287 285 284 308 279 283 263 289 320 291 230 267 248 270 278 274 292 256 261 242 277 255 284 284 262 290 287 242 320 270 289 271 266 285 262 267 243 284 283 325 295 233 246 268 303 290 271 265 279 257 289 233 271 280 305 310 314 282 255 271 281 270 283 270 239 259 277 315 260 291 286 280 281 288 291 240 277 273 269 305 293 269 283 263 268 304 293 303 268 298 278 325 284 267 244 275 286 301 262 290 249 266 280 288 275 307 279 263 292 276 268 299 281 273 317 309 296 272 273 309 274 277 281 292 275 261 277 295 315 287 286 307 268 289 278 306 286 289 265 278 281 243 270 275 269 242 270 298 264 279 295 274 280 317 245 273 274 271 317 276 278 262 318 260 279 280 295 290 283 242 278 281 282 279 318 308 278 292 290 298 273 298 292 301 295 260 257 289 282 290 244 284 279 272 261 284 264 310 300 299 274 300 271 296 279 294 282 248 294 276 307 320 311 300 285 249 299 246 322 286 321 294 291 299 276 299 285 273 282 279 290 297 289 272 287 301 294 310 282 267 288 292 278 290 275 310 256 288 281 301 312 271 298 271 280 292 286 275 322 309 274 288 276 275 288 261 289 301 304 280 299 284 310 288 310 289 318 306 285 264 256 282 272 300 306 279 260 316 303 286 284 291 289 338 292 260 321 290 296 319 268 321 318 274 292 262 289 331 290 282 314 258 271 271 327 276 287 302 276 309 265 292 300 304 258 320 296 287 300 293 269 267 281 306 307 310 316 306 263 294 284 317 293 289 266 275 299 322 272 329 241 304 302 286 295 272 299 281 258 290 271 280 309 308 293 247 279 288 268 301 286 291 322 302 271 300 289 277 280 280 301 280 286 311 259 243 279 293 274 276 313 287 283 294 258 262 300 258 291 301 291 301 282 262 270 260 282 290 265 281 304 272 271 281 286 306 302 304 270 266 270 297 283 293 281 276 241 261 291 261 297 306 284 303 271 291 246 279 259 292 280 298 277 302 288 264 277 270 289 277 238 303 278 262 304 298 285 286 269 301 285 229 275 272 314 291 248 278 271 283 280 266 272 291 265 277 257 278 300 239 284 270 269 282 276 270 259 300 268 272 274 286 280 290 257 258 250 286 262 280 271 294 292 269 274 262 286 291 272 256 261 276 268 237 281 283 293 235 279 278 277 256 282 250 257 233 226 257 285 283 309 265 269 275 297 269 263 269 263 257 276 224 249 238 239 290 218 282 272 257 278 245 261 220 263 271 243 288 273 287 235 276 289 269 257 226 239 266 259 272 276 277 257 274 275 263 266 248 249 266 260 276 265 273 275 265 262 262 235 263 274 248 237 281 247 273 260 275 227 244 244 276 240 239 263 266 264 236 276 237 262 269 229 263 222 217 257 278 247 234 292 259 239 272 268 238 260 242 304 237 211 264 233 256 266 264 215 255 230 230 211 239 250 223 237 244 218 243 234 243 248 250 278 270 249 250 264 249 247 235 238 245 243 302 226 256 238 246 243 239 244 255 267 257 260 193 247 237 233 265 226 230 267 271 263 270 241 240 240 264 245 238 242 258 218 217 241 221 236 232 237 225 229 231 255 267 234 243 243 258 274 242 239 248 249 220 273 249 227 224 223 259 218 218 238 217 241 241 243 217 239 217 237 236 221 242 236 256 247 247 222 221 242 240 207 243 222 246 249 227 207 233 245 278 241 273 239 203 232 250 227 235 231 208 219 241 234 241 217 222 206 259 238 233 243 219 223 198 209 284 212 224 227 234 231 223 229 240 244 218 191 235 208 223 207 230 250 223 206 239 243 229 228 213 231 215 227 256 235 220 259 218 207 227 236 241 214 213 211 216 223 246 218 228 229 230 198 228 196 229 233 242 241 240 233 221 237 232 212 223 224 218 217 237 210 238 243 235 245 224 188 230 238 237 231 221 233 255 213 219 236 220 230 221 246 223 232 226 240 248 236 216 227 209 227 213 245 192 234 226 221 220 228 212 243 190 207 193 193 256 205 230 231 248 235 215 235 202 214 207 223 226 218 224 222 209 226 223 211 236 221 208 216 194 215 260 204 228 242 209 219 211 212 230 203 206 201 189 211 193 197 206 224 205 228 216 208 212 209 216 222 224 211 209 213 229 221 211 224 209 223 202 208 216 224 206 229 227 185 206 214 209 193 224 228 213 203 210 199 224 190 219 208 212 207 227 190 211 214 223 230 226 233 216 207 203 223 230 207 215 206 206 193 202 195 182 206 179 216 226 212 227 222 196 175 193 208 243 227 212 220 223 211 196 212 219 194 207 216 219 211 202 226 208 201 185 237 230 194 215 198 205 207 209 179 190 236 196 214 212 209 215 188 207 218 209 205 195 184 209 192 189 196 201 211 202 200 198 212 226 210 207 202 196 186 216 214 216 206 209 225 187 202 183 203 214 207 196 199 211 202 210 191 187 204 201 185 215 212 205 199 205 210 205 210 191 192 222 216 206 222 197 212 199 195 195 206 212 200 203 187 181 209 190 207 191 194 184 200 225 181 179 214 211 223 214 219 211 193 203 210 170 198 186 215 210 178 212 219 190 220 204 176 200 191 183 192 189 188 195 229 220 169 177 206 185 186 201 204 183 198 220 207 206 228 198 222 182 199 191 196 213 168 195 184 187 206 204 207 188 207 208 213 213 216 193 184 192 221 207 206 207 198 173 176 198 206 198 202 212 201 210 170 196 201 207 185 204 205 203 189 201 198 197 179 211 194 192 208 186 218 180 208 165 159 206 193 175 177 199 182 182 178 200 202 175 195 234 194 184 194 190 146 219 217 182 209 161 191 199 196 193 182 183 196 187 179 202 202 184 188 198 197 175 187 202 207 212 207 201 212 187 214 206 203 198 178 185 198 212 194 193 168 186 208 193 201 176 168 204 204 169 203 211 188 174 188 191 177 184 187 195 178 193 204 193 195 198 189 162 176 188 162 183 192 199 202 198 190 184 191 191 188 184 183 177 199 179 204 189 175 190 189 202 177 189 186 181 222 186 196 208 179 184 169 174 167 203 185 194 185 186 190 168 191 180 179 182 180 198 180 154 191 165 177 187 172 198 185 184 158 185 204 187 164 187 170 187 188 183 165 208 207 185 179 198 190 194 193 207 162 195 190 169 194 192 188 170 193 176 191 193 189 193 206 165 174 201 180 192 189 180 180 190 183 194 194 203 179 186 170 179 183 197 179 176 175 181 177 176 184 200 167 163 200 175 186 194 197 189 176 195 181 194 180 164 151 187 162 199 164 181 146 190 186 186 176 194 185 202 202 195 196 185 185 233 189 199 189 164 198 186 173 183 171 224 179 178 204 183 203 208 185 174 184 174 174 186 172 180 192 195 157 193 155 184 177 192 186 182 176 165 190 171 204 185 172 196 176 191 202 198 186 192 186 196 175 189 161 199 194 185 179 193 170 175 186 166 182 203 182 173 186 159 179 174 196 192 181 183 166 203 193 192 173 172 182 202 210 167 179 183 191 177 166 158 167 180 204 184 172 173 177 163 187 193 196 220 169 180 165 174 200 199 175 168 179 181 219 180 197 212 179 179 201 198 190 197 187 192 184 193 194 196 152 175 197 176 174 171 169 197 168 194 175 168 173 154 157 189 174 180 165 207 187 175 187 199 169 191 160 183 179 197 179 175 190 171 210 164 216 188 177 183 171 163 161 192 190 174 201 199 177 179 200 165 168 197 191 163 182 177 185 162 192 163 164 165 192 194 168 182 187 178 155 185 166 189 174 174 171 186 159 175 178 186 168 165 157 171 168 176 186 179 171 194 170 185 209 199 191 204 196 183 181 168 179 182 188 194 159 199 180 144 173 182 176 187 157 176 180 162 201 190 172 200 161 174 163 172 171 178 177 184 188 184 175 198 186 177 144 175 157 189 179 175 161 183 186 187 207 203 196 165 161 189 183 178 202 191 164 180 165 192 174 200 189 174 170 170 179 205 179 175 199 173 169 182 193 171 158 172 182 196 175 157 173 219 162 171 191 164 194 163 182 173 165 178 194 155 193 192 182 201 174 182 199 195 191 187 190 183 171 199 161 163 186 177 192 185 167 176 194 191 194 170 173 180 199 181 167 170 179 169 170 168 171 178 180 196 192 183 211 158 186 183 183 166 159 177 174 147 168 186 172 183 186 156 164 178 177 167 166 176 166 157 179 185 189 182 187 199 164 167 193 183 171 175 163 166 205 178 162 179 177 190 186 182 177 176 186 180 170 169 172 179 153 195 159 173 185 176 187 187 190 175 174 184 174 187 173 186 193 174 199 168 164 172 193 185 193 167 197 194 159 184 170 183 190 179 163 209 177 172 153 179 182 204 149 196 151 154 170 175 170 179 185 177 154 187 171 168 187 132 170 186 176 190 174 148 185 173 180 173 171 187 166 174 170 178 192 168 167 175 203 178 190 188 192 179 172 167 163 176 189 168 173 169 179 192 188 169 189 189 167 182 172 172 180 177 186 164 175 185 180 185 173 155 176 194 214 162 176 168 182 165 179 165 189 172 184 189 200 172 180 190 208 186 175 188 187 170 186 187 182 185 182 170 174 176 153 182 201 188 176 180 161 173 164 181 172 183 157 181 192 178 199 180 142 198 154 163 160 185 163 154 161 182 165 159 175 166 175 187 165 185 197 197 186 221 180 169 198 169 170 171 184 178 171 181 185 196 185 182 161 161 177 178 169 178 197 187 191 144 190 175 190 169 157 185 166 176 170 181 178 170 190 173 172 166 181 187 192 172 203 171 180 196 170 172 187 155 181 197 180 173 186 165 175 167 204 192 193 160 181 192 178 173 194 170 181 188 183 181 157 168 186 167 175 188 164 165 168 173 185 187 161 160 159 175 170 184 180 162 171 184 187 162 171 176 187 160 178 162 166 186 170 180 167 173 173 178 169 186 174 166 180 178 185 171 153 183 183 191 165 182 156 197 181 210 164 174 181 200 190 167 196 171 173 200 173 174 149 179 178 169 231 192 181 196 197 157 180 182 176 198 193 199 166 187 207 169 168 180 193 190 183 171 175 172 171 182 173 162 178 178 189 197 179 188 169 183 170 188 168 199 162 159 181 187 185 178 145 170 179 173 190 185 202 199 179 192 179 185 176 171 177 172 177 169 202 158 186 174 191 177 211 189 150 177 171 192 174 161 166 182 197 193 207 186 186 187 191 169 192 166 217 186 179 189 191 171 174 180 195 172 186 191 178 165 183 179 182 179 182 183 178 187 205 178 190 173 209 191 185 217 175 186 198 166 200 193 193 204 196 193 195 179 206 181 193 221 202 198 179 217 202 190 189 207 242 185 232 210 215 195 201 225 186 213 185 193 192 200 233 203 212 213 187 220 224 216 205 175 204 201 176 204 207 202 198 173 210 204 174 204 194 207 173 187 208 183 188 188 197 207 186 173 207 188 205 216 186 185 210 204 216 194 190 197 170 186 203 179 217 182 170 189 198 205 199 201 191 198 197 220 196 214 198 192 209 207 195 194 227 235 227 224 191 196 193 220 211 216 184 181 212 206 188 186 212 219 230 222 183 213 226 226 220 169 210 206 235 208 213 200 224 225 268 228 231 241 246 230 228 207 217 272 271 237 221 238 265 266 260 272 300 267 294 287 298 302 295 335 321 323 315 325 313 321 325 346 284 326 294 322 281 289 337 305 306 303 295 265 261 275 225 249 250 269 262 245 228 263 282 216 213 224 217 219 272 205 208 207 232 230 224 223 208 211 195 204 218 217 164 197 186 208 207 198 179 205 182 197 212 194 184 205 202 176 202 172 183 181 206 184 196 194 192 187 195 201 210 177 166 186 204 184 200 195 205 211 177 185 183 184 184 194 203 176 194 213 198 175 171 178 191 168 189 181 180 206 191 194 208 156 214 193 178 200 190 197 202 185 203 187 192 173 200 198 215 205 210 168 185 208 177 190 192 201 184 182 181 184 193 189 180 173 189 189 180 184 187 213 195 184 191 211 187 191 175 182 183 215 192 191 197 203 188 177 197 186 191 161 208 213 185 175 214 164 180 214 185 205 186 206 189 179 192 199 205 197 192 197 204 172 177 190 175 192 193 178 193 174 177 224 168 199 168 190 185 182 175 194 171 190 188 200 191 179 182 178 194 222 192 166 192 199 206 198 174 181 195 196 195 192 190 201 190 178 174 197 165 181 194 197 205 187 193 198 191 184 202 178 197 199 193 188 208 176 179 191 181 184 197 196 182 171 176 193 184 188 195 188 182 192 169 155 198 190 188 178 174 175 183 198 187 207 175 192 195 171 186 163 183 175 183 207 178 199 202 177 175 176 177 181 191 181 176 205 191 174 206 196 167 173 184 192 182 188 203 156 164 182 176 197 184 178 191 201 208 178 183 213 210 168 197 206 181 170 202 198 174 194 205 193 195 198 167 186 194 189 218 201 190 197 186 163 172 188 190 205 178 175 160 205 192 165 193 184 193 187 166 166 183 176 191 190 178 177 190 212 175 205 171 154 179 157 182 169 203 209 179 184 174 182 190 181 164 168 199 186 174 201 186 196 197 186 191 189 182 164 206 183 203 188 184 186 175 171 175 199 203 195 185 198 192 189 170 192 189 212 186 197 178 198 188 187 211 171 199 207 182 178 196 177 202 178 169 171 171 207 170 180 176 180 190 177 181 173 172 184 195 191 194 223 222 209 191 183 174 180 170 185 194 181 196 188 230 218 182 190 186 205 188 163 182 184 189 199 188 204 186 203 192 173 189 160 205 208 200 163 176 178 203 204 190 172 173 183 188 173 182 174 181 196 159 195 179 186 166 182 198 197 180 182 184 190 216 187 205 200 183 178 198 200 190 199 174 203 174 193 180 187 165 181 170 181 169 194 191 185 176 195 176 173 188 186 187 222 173 191 167 192 185 222 169 193 170 172 198 175 187 175 173 197 167 200 182 186 201 204 171 217 185 157 194 173 171 189 196 167 181 182 159 176 187 183 201 198 195 179 178 179 204 190 164 182 187 193 168 187 195 192 184 176 202 169 179 180 199 197 209 185 206 199 178 173 189 174 190 193 222 193 192 185 184 185 186 192 178 194 194 174 181 208 181 164 193 179 167 190 192 197 166 180 172 185 180 185 204 211 184 188 205 179 156 181 180 212 177 176 199 174 193 179 174 160 175 164 213 173 182 206 183 183 209 174 191 192 174 186 202 183 170 194 171 156 175 189 187 188 179 189 178 184 189 192 159 218 192 179 178 187 170 185 162 182 180 192 192 204 181 199 183 187 187 179 205 177 176 181 170 161 171 188 194 176 177 204 182 181 195 204 194 211 199 197 181 199 179 169 179 191 195 175 152 176 184 184 190 206 188 210 195 189 196 184 193 195 181 192 178 181 164 183 176 184 187 181 201 185 196 182 195 164 183 176 184 176 197 178 180 182 172 210 202 166 195 183 162 174 164 174 170 190 173 186 195 187 184 162 164 199 177 191 189 189 169 178 189 166 202 189 170 186 183 174 212 197 203 172 214 196 205 185 194 185 180 190 183 167 215 182 174 181 181 191 171 177 178 174 177 163 201 192 177 167 181 165 200 178 177 201 206 174 168 208 165 198 193 176 200 173 196 178 194 178 156 188 174 166 183 191 199 194 174 148 207 183 173 195 190 166 168 199 180 191 183 184 171 183 181 160 188 184 179 196 179 190 186 192 162 190 203 188 182 183 211 194 205 187 186 186 176 192 178 201 172 187 153 181 166 165 189 209 185 179 182 187 203 207 206 222 188 184 186 200 182 180 182 151 164 197 192 186 179 185 162 209 164 213 195 189 196 172 178 170 144 192 188 198 167 181 192 177 194 201 204 157 173 186 178 176 187 178 188 176 176 180 181 195 182 184 188 188 183 195 175 189 211 186 186 175 189 192 206 181 166 188 189 189 182 180 178 198 176 171 178 195 175 205 185 182 179 172 180 200 185 182 157 199 168 185 182 160 214 148 174 182 148 178 176 166 179 203 190 212 179 209 168 167 184 194 204 193 179 186 183 190 168 177 172 186 217 164 203 173 194 173 169 208 195 177 211 161 170 194 186 170 175 194 211 174 190 173 150 193 172 177 178 202 201 184 188 204 175 172 166 190 166 159 199 186 175 202 198 210 192 189 192 216 189 193 173 162 207 212 182 176 179 174 176 169 154 184 207 192 178 189 189 180 164 182 161 185 170 181 174 182 160 200 189 162 169 154 190 183 174 196 170 184 195 175 172 210 185 179 198 193 210 196 182 179 186 187 201 182 176 220 181 187 194 188 211 195 211 173 171 167 202 177 189 178 176 176 209 174 201 181 165 218 162 197 186 183 194 186 184 208 190 181 192 188 194 163 177 181 176 196 170 197 176 168 146 201 195 201 192 150 190 148 193 189 184 201 197 189 216 164 170 185 180 184 181 187 199 187 185 164 198 176 172 180 192 204 197 211 187 181 190 188 169 192 177 211 149 164 175 208 183 177 208 205 168 188 185 175 190 160 200 203 207 178 188 194 188 179 195 173 200 177 185 191 175 164 200 222 216 175 178 194 200 177 181 204 205 188 202 180 189 168 182 182 185 192 181 207 181 200 159 195 178 181 169 195 215 187 177 196 177 191 197 174 177 205 193 179 184 165 175 210 180 189 161 189 203 177 183 195 169 173 186 184 188 190 188 204 178 188 213 207 188 202 183 200 198 169 195 167 205 183 180 209 183 189 182 196 179 195 175 176 197 205 173 197 191 197 205 184 190 186 183 187 186 188 164 196 201 178 196 189 192 176 195 216 207 175 177 179 173 182 172 168 182 188 194 192 172 162 174 185 200 185 180 174 191 180 199 195 192 183 190 198 172 193 194 206 184 177 174 200 209 198 190 182 178 179 180 195 215 201 178 176 181 215 179 187 180 218 172 180 200 190 192 183 197 202 184 163 199 201 203 203 183 189 172 182 206 181 237 199 200 185 178 179 196 188 202 190 167 211 180 198 186 178 179 179 194 182 215 181 188 195 202 195 194 179 184 196 180 198 178 171 197 201 182 210 167 184 194 200 200 189 198 179 181 198 177 183 185 177 191 196 186 174 206 180 182 181 158 182 182 207 197 196 197 191 215 190 188 212 178 197 204 158 208 199 183 193 200 176 209 204 176 200 181 201 196 204 189 195 173 196 179 194 165 186 177 185 208 165 183 181 178 164 192 199 181 172 199 183 190 189 174 181 170 189 186 193 188 202 209 172 190 177 173 181 193 196 210 193 161 187 194 193 173 234 194 202 180 177 175 188 191 207 189 186 189 186 183 194 194 220 175 215 186 200 205 202 211 210 190 187 172 194 185 187 183 201 191 188 188 176 171 174 192 209 190 179 185 197 182 201 208 206 195 182 220 212 166 187 193 197 178 190 188 202 212 198 197 175 193 181 211 210 228 180 210 170 209 198 171 174 195 177 181 183 187 204 196 190 196 207 189 180 214 183 184 178 185 170 195 211 189 189 179 218 202 200 210 206 214 194 190 184 212 173 212 194 193 183 188 210 187 197 215 184 165 235 176 201 183 227 178 210 201 215 151 186 212 178 218 199 191 182 190 212 188 200 194 181 190 205 194 172 211 198 189 202 193 188 177 195 208 201 209 200 197 173 192 206 203 203 172 193 176 192 178 187 183 204 214 199 179 188 218 211 191 203 180 181 183 175 206 207 192 195 196 184 201 189 165 175 173 200 190 206 201 164 182 209 216 207 184 195 158 198 203 199 200 181 192 193 198 202 187 203 189 199 174 185 178 160 159 194 197 217 221 154 201 187 209 204 181 165 199 187 206 203 166 199 181 190 204 167 210 174 170 200 188 233 190 197 203 186 208 183 189 192 178 186 201 209 193 200 192 224 209 179 192 188 203 199 217 210 198 193 197 208 176 191 180 182 207 203 204 179 197 212 221 193 162 191 188 177 164 184 191 172 195 179 194 186 167 197 217 189 215 191 190 205 214 186 191 200 176 175 201 192 188 188 192 192 207 178 176 193 188 203 180 198 195 204 190 189 196 216 177 178 210 180 170 180 190 194 200 208 191 199 183 177 211 203 198 193 179 214 204 189 188 200 188 171 173 184 194 182 198 209 182 185 182 188 160 192 190 187 215 201 171 180 175 190 185 170 184 191 220 200 205 190 191 181 184 192 168 206 188 173 220 178 183 200 200 186 214 195 204 194 163 197 216 191 211 185 187 190 189 184 199 174 190 192 196 207 202 180 185 199 208 191 216 177 199 227 182 207 218 174 207 174 215 208 176 209 196 191 219 175 172 207 182 212 194 172 217 206 193 228 192 204 223 190 211 198 203 185 179 199 217 188 183 186 197 225 195 228 215 196 201 188 232 192 180 194 185 189 196 200 207 211 213 191 216 218 211 201 187 185 209 185 213 197 193 184 183 182 186 172 207 204 184 172 202 200 225 212 203 224 194 205 198 242 215 186 183 199 183 192 166 198 210 230 198 196 192 174 182 198 192 188 192 179 174 184 225 162 175 204 199 211 182 211 192 198 203 204 181 204 182 217 191 202 194 185 206 197 188 199 211 186 220 200 209 209 199 214 186 202 193 206 209 220 192 219 199 182 201 178 175 197 221 197 175 204 203 184 176 201 198 200 182 186 210 216 209 205 192 193 185 177 195 175 198 166 209 193 204 207 159 211 197 199 186 187 193 178 193 184 196 169 165 193 192 198 191 203 184 206 191 194 188 165 218 205 196 197 195 204 155 198 197 191 196 204 176 179 214 208 220 181 221 210 209 197 197 178 187 204 182 174 185 187 220 199 195 200 190 214 215 177 193 181 198 182 172 195 196 183 181 202 192 197 188 215 178 197 169 185 201 196 195 198 210 211 190 194 182 195 188 173 184 183 189 204 193 179 205 181 209 176 182 201 207 174 203 188 195 201 178 198 152 182 175 202 216 203 202 208 198 182 207 207 200 215 197 190 185 199 196 180 173 195 204 190 198 222 218 175 192 216 187 193 206 191 209 205 197 196 185 190 181 170 190 187 185 204 184 202 209 197 197 200 175 218 215 214 187 199 169 191 182 212 188 189 204 208 184 197 191 204 205 202 190 190 185 175 187 183 205 192 195 211 176 197 196 183 193 209 200 175 178 206 187 194 213 215 209 195 208 185 163 199 187 207 206 197 192 176 177 187 197 198 207 211 203 171 213 184 175 175 189 179 211 201 201 184 193 197 192 176 194 192 168 179 223 197 205 192 213 185 203 207 195 201 197 189 173 183 203 225 185 165 166 197 188 207 195 206 200 211 195 183 186 183 184 216 189 218 211 170 220 208 198 185 187 194 177 186 187 184 186 218 194 189 183 178 200 171 189 177 184 215 197 164 192 224 179 184 197 193 225 172 182 187 200 196 194 191 197 185 195 186 187 197 204 164 192 192 165 180 212 217 171 206 213 174 182 192 197 206 192 176 220 206 195 189 212 197 204 182 187 182 179 191 202 195 183 169 188 193 192 202 196 201 196 217 179 185 199 187 200 180 193 186 189 198 205 212 202 205 214 204 183 186 201 173 198 168 225 215 219 235 167 214 196 197 192 200 193 191 193 195 191 180 207 196 193 200 191 191 212 198 146 194 173 195 187 189 184 159 185 201 194 216 196 190 178 179 193 208 211 214 200 208 194 202 206 202 196 220 201 178 224 214 183 192 201 177 208 175 190 198 196 181 170 209 190 197 200 177 179 203 194 217 180 199 198 201 218 192 190 190 201 200 187 189 204 219 208 176 205 203 235 168 205 187 207 197 174 202 200 184 188 214 202 195 180 166 178 200 205 180 186 176 221 187 200 209 205 190 180 207 195 196 193 205 194 203 198 206 175 193 172 205 191 203 185 181 179 173 181 180 186 209 195 202 174 190 172 193 169 203 203 227 199 206 181 205 209 176 197 228 198 219 213 173 165 171 188 195 178 185 190 199 210 174 208 212 202 185 189 198 194 184 180 192 207 204 210 194 182 186 185 181 202 199 176 201 194 184 205 187 182 206 195 192 215 181 192 175 197 193 191 199 210 201 178 207 186 170 180 188 202 179 152 191 191 194 215 186 208 183 202 214 192 187 213 183 208 177 179 207 189 192 201 190 189 196 190 200 196 183 170 191 190 203 167 203 201 197 202 196 183 174 189 203 175 178 198 206 219 183 214 195 191 194 172 202 185 176 207 185 187 190 178 197 183 202 202 205 185 200 207 202 204 189 209 190 197 186 174 212 200 181 203 160 206 192 177 178 200 195 182 183 195 201 215 194 192 180 176 182 188 194 190 189 182 184 201 185 204 200 189 214 190 197 205 217 191 171 185 173 193 182 218 179 192 164 214 202 178 211 198 211 188 177 185 200 176 240 203 197 196 187 184 194 192 193 180 185 181 194 205 171 204 181 182 185 185 180 194 195 185 180 225 188 209 185 205 177 191 202 210 192 212 189 204 215 209 172 210 208 179 201 185 193 164 181 203 189 206 177 201 208 165 185 204 190 190 237 219 193 185 183 180 179 197 218 178 191 207 196 196 195 187 198 196 161 182 217 205 200 177 197 175 197 186 185 191 197 184 191 202 185 183 182 203 173 182 172 176 197 197 200 210 191 201 183 191 186 201 215 197 193 180 206 208 219 174 181 193 207 201 176 199 174 202 206 172 186 213 197 211 180 211 197 211 190 191 186 206 195 198 167 202 216 216 174 186 187 198 207 209 176 192 189 194 186 202 202 213 186 185 190 214 199 186 196 198 186 182 199 193 201 203 195 177 202 203 192 207 191 223 180 181 193 154 188 171 192 203 198 190 166 204 184 179 193 175 197 205 193 188 176 188 184 201 205 177 195 207 226 188 168 196 190 191 203 159 197 195 190 195 203 206 179 209 185 212 180 185 179 205 201 181 181 186 194 208 203 196 175 186 189 196 197 207 188 200 209 191 204 197 170 195 200 193 192 205 178 173 198 194 185 195 205 182 206 209 182 210 188 181 214 203 213 198 183 198 172 183 178 159 193 204 172 207 200 180 190 192 182 189 198 166 184 177 183 212 188 195 173 174 168 178 202 188 215 192 206 193 210 204 202 187 192 202 215 195 225 209 216 208 210 206 191 213 193 194 208 206 199 191 207 203 198 178 194 209 176 202 195 212 193 193 204 190 173 201 191 193 202 189 224 187 207 161 196 188 190 186 210 165 197 194 174 178 175 193 203 210 192 169 223 192 171 191 190 217 210 219 197 186 199 184 173 197 198 217 178 205 195 170 182 215 175 175 199 191 200 223 187 212 166 200 216 198 198 205 203 190 200 179 197 209 181 202 157 211 173 186 204 179 183 167 198 207 179 193 195 198 181 176 187 214 185 166 186 169 183 206 190 187 191 200 223 213 193 193 188 199 169 198 207 170 204 194 204 184 198 212 211 232 212 183 155 187 192 214 199 217 180 178 205 186 214 197 184 192 181 179 189 189 211 181 205 181 208 204 196 193 193 190 190 194 197 202 192 206 196 179 202 205 187 198 221 192 192 194 175 174 201 171 186 174 175 179 205 189 204 196 197 165 193 191 177 196 205 200 195 199 193 161 221 184 189 205 185 186 199 171 188 160 194 171 164 188 173 170 179 185 188 206 182 178 185 211 176 190 193 181 204 173 197 210 218 191 165 199 205 212 207 166 227 195 176 218 169 167 206 219 194 190 199 190 199 186 210 200 207 185 199 189 196 183 189 191 194 197 204 172 208 177 200 182 215 190 205 189 198 216 191 170 187 195 188 202 176 197 188 189 170 210 200 182 196 195 187 198 190 190 201 199 204 212 193 159 186 183 179 177 180 178 199 185 200 184 204 170 198 196 198 203 182 233 188 183 168 207 200 217 177 193 182 198 175 199 177 198 193 168 201 187 179 197 188 178 185 197 200 193 197 197 190 206 217 189 163 180 188 196 195 196 187 197 210 193 200 197 183 213 187 186 202 184 195 177 208 204 197 204 187 220 222 193 183 178 201 197 196 162 215 187 190 182 190 175 185 196 190 192 179 213 193 192 199 198 214 203 205 239 187 177 170 191 177 197 198 196 199 173 204 193 173 200 188 193 170 212 179 197 167 177 203 205 192 201 191 204 181 195 196 183 182 222 199 177 187 193 197 192 169 200 198 191 220 172 197 200 209 176 187 205 192 200 200 189 211 200 214 201 206 193 226 236 195 189 225 209 191 210 191 198 207 205 194 210 208 209 198 210 213 221 209 194 217 208 224 202 205 192 196 193 183 212 229 247 219 240 209 222 248 214 187 225 214 186 208 175 220 228 210 213 225 201 214 217 217 224 233 206 211 214 218 225 230 216 234 218 206 194 237 231 217 226 221 220 217 214 237 211 220 185 212 190 193 208 216 216 202 196 194 204 209 211 205 206 214 211 211 213 203 190 191 188 198 191 194 189 198 204 202 190 207 220 189 198 190 196 195 165 210 203 201 224 204 196 194 193 191 181 179 202 178 184 199 186 176 192 181 174 191 190 188 190 197 198 206 159 204 212 202 189 189 205 178 195 177 213 193 210 165 172 199 177 187 206 194 192 181 208 186 204 192 184 194 191 202 214 210 172 202 176 186 192 203 191 198 198 175 196 181 186 200 159 213 201 172 164 185 165 180 168 199 191 198 193 178 178 184 190 194 216 184 199 199 184 204 204 187 210 190 192 205 176 181 175 182 192 191 190 178 185 188 197 169 197 178 181 186 193 186 191 209 212 213 176 184 180 174 187 194 190 185 148 174 194 181 181 192 164 179 194 178 203 175 219 174 181 183 173 202 180 188 181 179 206 191 208 167 183 184 190 203 187 188 185 202 187 188 207 188 179 193 170 180 170 205 209 186 203 197 199 192 169 192 185 188 237 170 188 201 195 199 201 198 184 211 185 201 194 210 218 184 191 194 189 196 177 160 197 180 166 160 203 187 200 194 163 204 202 185 196 182 207 173 200 180 177 217 184 184 179 179 198 190 200 202 187 189 190 166 158 188 189 159 196 200 187 181 179 210 190 196 220 192 179 193 217 216 206 199 178 177 213 185 190 188 190 198 200 178 187 196 185 219 195 164 203 208 180 177 217 218 166 183 184 206 166 189 176 190 170 191 189 183 208 188 201 201 216 208 205 201 175 188 194 188 196 178 189 194 176 185 193 178 176 196 198 188 184 180 191 208 198 173 162 182 178 176 193 158 190 189 183 200 190 161 198 175 182 185 178 187 203 177 194 174 176 188 174 191 177 183 222 202 192 169 163 195 176 178 191 195 180 179 196 160 180 173 180 202 175 189 186 182 186 166 169 209 183 196 165 174 195 178 173 195 195 203 195 187 177 185 187 172 167 209 184 161 218 186 204 198 186 183 194 183 215 160 180 181 175 178 165 192 188 203 187 169 192 168 190 210 190 173 186 194 202 192 164 173 169 189 198 201 181 205 197 184 190 206 181 174 201 148 194 166 190 186 193 176 181 190 196 196 179 161 194 160 171 185 179 198 196 204 201 198 189 178 192 173 191 194 159 199 194 190 183 206 193 168 193 173 182 183 198 170 200 216 174 184 200 195 185 194 179 182 191 194 183 155 194 186 194 190 178 191 190 177 175 170 187 200 192 174 181 165 197 219 184 212 200 182 183 185 200 205 203 196 195 189 183 201 190 194 208 200 168 203 184 201 201 184 219 203 174 205 198 177 192 207 179 186 194 202 170 201 189 183 190 195 217 171 176 201 210 157 179 182 204 193 198 200 202 179 206 184 175 197 176 203 179 195 190 177 165 205 175 206 197 203 191 219 173 222 164 177 199 184 182 187 178 196 180 167 194 205 186 181 153 193 187 189 199 185 192 171 179 170 176 203 179 197 188 173 174 184 195 178 184 188 191 188 181 156 180 176 204 169 177 170 153 172 173 190 199 180 191 186 201 166 184 181 191 185 205 207 193 195 187 206 176 177 199 175 191 166 193 191 192 196 206 192 207 188 198 174 146 180 203 173 192 179 181 174 193 223 188 201 193 204 174 199 202 194 192 200 188 201 193 191 183 204 187 184 181 196 182 189 169 237 179 201 199 169 200 175 178 193 178 193 189 177 190 176 199 183 198 159 171 206 222 189 191 193 205 201 170 175 173 173 190 181 190 177 195 195 182 188 209 173 183 167 176 215 169 167 198 184 199 212 182 177 184 203 182 177 169 183 180 206 184 193 191 191 182 188 185 187 181 172 179 196 190 187 220 186 183 200 178 166 187 168 172 192 193 189 205 201 194 182 152 176 193 185 190 174 187 187 180 188 181 192 194 163 193 187 197 190 183 183 205 184 176 179 185 210 225 197 184 174 174 177 167 193 188 178 190 186 192 201 196 179 188 207 215 158 181 161 200 214 163 201 180 206 165 174 184 183 199 181 186 190 194 187 190 183 203 170 189 172 184 173 191 182 177 187 179 188 178 171 148 185 190 214 173 202 208 208 193 182 196 160 171 191 205 177 189 197 194 189 180 185 180 158 207 180 203 168 181 201 170 191 180 191 197 212 210 179 195 198 188 165 196 172 162 175 175 174 158 202 190 165 165 182 199 196 185 165 170 182 183 215 170 168 190 163 188 203 176 187 195 189 189 196 194 207 164 172 163 201 194 211 177 184 176 186 187 199 177 181 171 182 191 181 167 192 203 163 186 205 179 171 191 166 187 156 188 182 169 166 192 209 164 186 153 207 197 178 206 178 182 210 196 190 186 209 179 199 178 179 152 202 181 199 198 185 187 205 152 177 181 186 190 210 176 185 159 209 184 204 201 195 198 214 176 178 180 179 165 199 207 218 214 176 198 181 191 189 174 205 195 177 199 182 207 181 181 205 185 199 194 170 165 201 181 196 184 197 170 190 164 170 188 182 190 198 173 175 169 211 204 173 177 176 194 202 211 196 172 179 181 193 189 196 162 154 157 161 190 196 226 160 168 200 196 170 186 185 200 187 190 165 197 197 184 192 169 167 165 199 185 213 167 168 192 187 191 187 169 174 185 178 172 215 185 197 216 205 189 199 154 198 189 178 196 201 179 200 164 183 211 169 179 190 189 188 187 164 179 177 188 178 179 197 178 194 179 195 185 197 177 180 186 193 182 221 199 210 176 198 201 199 182 188 171 189 190 206 194 154 176 201 176 165 214 180 185 189 178 207 197 186 182 195 184 193 174 183 177 194 176 193 179 202 178 171 204 174 186 195 163 187 184 207 189 192 199 182 175 202 176 199 182 200 196 173 195 178 176 170 193 176 170 211 177 175 191 182 186 200 184 175 190 174 179 172 200 195 211 179 171 204 192 181 179 190 180 182 185 193 170 182 200 190 191 175 184 207 184 185 210 171 203 200 171 206 174 187 184 185 175 189 193 190 172 210 191 159 176 175 184 178 156 205 179 171 186 178 191 207 179 213 197 188 192 178 180 172 194 157 193 188 205 180 180 198 189 190 180 196 189 197 198 173 179 208 205 199 182 184 184 179 173 176 186 196 198 194 198 178 193 195 204 221 211 189 197 155 217 191 190 198 186 184 190 185 187 170 172 187 171 204 186 163 213 201 209 175 189 184 184 187 179 191 167 184 171 189 207 189 182 174 198 197 174 166 193 176 184 182 184 198 191 189 170 169 184 203 220 190 198 185 177 203 175 188 191 175 201 173 193 173 199 198 181 176 197 187 175 193 207 191 190 193 193 201 199 225 186 217 196 197 193 183 187 200 191 165 186 188 181 191 151 186 167 193 201 179 220 186 179 194 183 173 195 196 206 181 154 159 165 175 163 191 188 191 186 167 191 212 168 184 205 182 184 187 188 191 172 185 180 179 199 201 182 192 221 190 179 161 172 178 187 191 216 207 194 190 182 177 193 182 212 167 169 155 170 184 174 173 198 182 194 199 190 192 192 186 164 193 192 184 197 185 181 170 173 177 187 180 186 185 193 201 203 193 206 194 202 207 189 184 203 186 175 186 206 200 165 175 187 184 185 208 186 216 184 194 176 199 177 219 184 184 162 191 181 176 192 203 206 188 199 183 208 187 180 207 200 177 167 218 181 210 189 167 213 178 204 201 174 177 204 181 175 219 201 170 211 190 183 190 190 163 201 176 177 172 187 189 195 193 200 158 193 187 213 175 159 222 205 184 214 178 193 206 194 193 189 195 185 204 194 199 196 181 206 180 183 186 190 219 214 192 188 187 175 203 190 202 180 207 196 170 206 179 190 168 198 177 205 177 175 201 214 209 227 192 196 163 202 195 207 179 183 201 199 178 172 193 191 191 192 192 168 184 181 193 157 190 181 213 198 179 189 178 196 190 186 195 167 184 190 199 183 191 191 154 203 198 198 190 208 186 194 182 179 160 198 173 180 202 184 206 184 173 183 197 175 181 166 186 188 182 204 196 193 180 184 191 198 190 180 183 205 206 201 186 197 194 192 189 213 185 195 167 180 189 182 180 214 199 183 191 191 189 181 194 175 199 174 205 182 176 162 212 217 189 175 193 187 198 174 187 198 213 226 186 230 190 189 162 181 178 184 192 223 214 172 208 197 196 176 182 183 181 184 212 181 184 195 200 187 183 196 197 177 185 216 173 199 174 178 197 189 198 210 190 199 185 205 204 152 199 218 176 194 190 171 173 180 215 190 201 179 200 195 188 194 174 189 174 184 173 179 189 168 197 166 184 191 162 201 189 180 184 188 173 196 208 174 198 203 192 185 194 194 214 198 172 185 180 191 186 195 202 195 205 188 176 200 178 169 197 188 171 200 181 176 190 212 164 181 187 161 187 185 177 189 193 188 194 195 184 185 204 204 214 228 204 180 174 205 196 183 190 207 188 213 178 189 179 199 185 200 180 212 198 183 206 174 187 151 187 189 188 207 217 204 180 173 173 185 205 198 187 191 177 194 199 161 199 177 203 201 217 179 185 199 171 198 207 184 200 176 194 182 197 181 192 187 190 185 161 188 188 184 150 204 184 210 232 170 188 182 178 202 161 183 191 178 221 161 165 185 180 183 192 193 178 190 200 224 165 176 189 213 189 194 192 198 184 174 179 198 178 175 184 166 201 194 175 185 184 184 199 202 180 200 197 210 195 161 174 206 189 178 194 180 182 193 171 197 185 195 186 190 163 211 192 203 176 195 155 151 191 169 181 183 187 187 165 192 186 171 177 177 173 194 188 187 167 178 182 188 187 179 190 183 183 177 184 197 201 197 206 154 161 159 182 208 198 205 201 182 209 189 170 182 184 201 199 206 192 201 186 190 185 179 180 192 183 207 190 193 204 196 182 218 181 181 189 173 198 198 179 201 154 186 166 188 187 201 183 198 179 172 194 184 166 179 200 199 187 181 190 172 171 206 160 194 191 172 193 196 218 185 191 201 186 184 176 198 162 179 169 184 187 182 182 204 198 173 183 167 195 185 172 194 192 192 191 183 190 203 194 176 182 178 220 153 201 197 195 179 176 195 187 202 168 189 181 180 178 165 203 202 204 209 198 186 189 206 189 192 190 180 166 190 189 184 181 181 190 194 187 194 192 189 191 200 203 199 197 187 195 199 177 198 161 177 185 188 174 196 187 184 185 215 156 175 208 165 190 191 206 173 187 186 192 194 185 197 223 202 190 191 208 189 196 205 187 214 169 174 197 216 170 163 176 169 204 167 210 201 199 180 176 174 190 175 177 187 176 173 160 203 191 192 178 183 176 189 214 162 198 189 195 171 188 173 204 173 204 191 179 190 179 182 162 209 202 182 218 177 193 193 190 179 191 182 182 173 178 212 193 183 194 157 173 191 169 173 159 200 181 181 181 175 197 176 179 171 210 197 173 173 204 189 183 202 181 165 192 193 203 191 203 187 185 174 195 189 183 171 172 195 170 156 194 190 187 190 180 186 178 185 171 187 200 196 185 188 194 176 168 172 188 192 172 203 181 187 189 179 188 180 170 220 180 201 183 200 175 186 178 182 200 186 167 200 209 195 171 236 189 184 210 194 165 184 175 181 183 179 195 213 199 168 214 198 187 181 205 200 183 180 165 199 210 176 141 181 184 191 187 171 187 192 197 213 201 199 208 183 175 205 195 165 189 197 198 207 187 156 182 184 183 201 191 191 185 187 171 193 170 200 155 180 179 196 189 160 165 155 199 186 147 172 168 190 168 197 187 158 206 179 192 198 187 193 185 200 201 182 161 175 185 162 169 187 172 164 171 181 182 194 194 192 174 194 198 181 179 182 195 184 198 198 194 173 204 164 166 176 200 188 189 205 206 181 197 216 178 173 162 182 207 160 174 175 189 178 201 208 225 196 177 182 206 169 216 184 187 197 216 177 172 193 205 181 170 196 163 191 200 184 168 187 187 172 187 181 180 188 171 183 189 180 213 174 191 194 174 174 181 181 186 167 178 188 171 191 185 182 182 209 184 187 207 196 168 199 178 200 207 192 181 223 164 187 198 194 182 197 171 167 178 188 195 197 190 190 183 184 180 179 177 204 170 174 191 178 166 186 176 168 191 186 190 168 183 199 172 189 183 207 182 179 221 190 154 193 179 172 204 204 152 223 165 183 171 155 181 205 169 183 188 164 161 185 176 180 186 170 182 188 183 184 178 159 200 201 184 208 175 190 155 180 180 183 204 199 183 175 173 224 166 191 178 177 172 207 177 188 196 196 181 203 158 153 173 181 181 205 173 197 181 175 187 178 156 204 198 191 160 198 189 181 175 172 182 182 199 176 189 176 203 172 206 223 203 195 220 185 186 205 203 192 196 177 187 204 174 198 158 182 163 194 178 206 209 185 176 189 158 170 210 174 205 192 179 163 184 174 197 177 190 164 202 195 179 189 179 198 169 201 186 205 192 201 181 205 175 182 196 173 163 170 175 183 187 170 207 172 196 189 158 182 178 177 190 197 204 185 167 190 182 208 204 169 201 199 208 181 186 176 191 174 176 184 192 179 181 180 182 199 175 178 190 183 184 182 169 151 203 173 194 172 191 189 192 177 186 211 207 182 185 183 199 200 180 188 208 151 207 175 185 183 179 166 183 193 227 179 167 196 168 192 197 181 191 212 225 186 172 193 187 181 189 183 201 189 191 193 179 180 193 181 167 188 188 185 184 202 189 178 194 176 172 197 194 177 167 153 160 182 180 177 183 189 182 186 174 183 205 184 200 185 197 181 196 195 178 178 193 176 182 186 207 194 189 169 187 171 197 165 168 208 160 197 186 194 166 194 179 194 178 198 199 178 202 170 165 192 188 180 185 163 193 160 174 183 187 186 193 154 181 213 186 173 189 190 195 199 177 185 200 190 188 164 213 189 154 178 170 189 165 178 182 197 200 197 185 176 169 164 190 204 193 178 198 178 192 202 194 203 180 200 190 210 171 185 196 177 192 174 192 180 186 197 172 164 188 190 165 183 184 187 182 177 188 193 202 183 177 173 181 198 166 166 177 191 175 162 190 226 166 203 170 194 197 176 197 219 181 195 201 215 198 167 185 186 187 188 200 199 201 170 200 187 187 184 190 178 191 180 169 199 214 180 190 180 180 171 181 209 190 185 158 170 190 180 192 200 161 186 192 214 164 162 185 206 191 165 216 186 162 170 193 176 189 192 195 170 211 187 202 190 167 176 199 165 176 198 196 179 169 206 197 193 191 155 167 198 177 164 200 194 189 189 207 183 186 184 165 205 197 175 207 174 192 183 202 169 201 193 185 162 205 191 195 179 180 187 197 182 168 206 178 207 197 164 200 198 189 169 199 174 194 188 191 201 201 192 200 191 193 196 212 196 188 187 205 196 189 157 187 173 165 194 186 173 190 190 211 195 184 179 197 170 179 171 187 181 180 192 195 188 198 212 173 186 197 210 202 190 183 179 200 190 192 196 201 198 201 152 196 171 179 209 200 158 204 194 174 173 196 184 187 190 182 180 196 174 175 186 195 205 200 193 171 191 182 195 215 209 204 199 201 181 177 177 198 189 196 198 196 197 189 204 196 221 209 162 198 188 190 189 191 201 189 201 187 198 197 213 201 192 205 197 198 207 174 186 212 214 178 173 182 213 220 196 215 184 189 202 187 204 187 192 211 211 212 210 200 191 191 182 195 192 216 207 169 175 207 212 198 196 178 173 191 225 204 204 190 186 193 189 191 203 184 203 192 200 200 195 202 198 199 184 196 217 158 221 204 181 195 205 191 166 199 201 201 215 219 196 185 196 199 197 177 165 196 186 213 205 208 218 165 196 195 178 164 178 184 187 224 187 187 182 164 205 199 203 205 172 205 199 189 200 202 205 210 206 174 187 193 195 176 223 194 194 190 219 195 186 200 218 203 181 185 202 201 209 185 171 168 196 180 165 204 198 192 189 204 177 190 184 193 210 193 180 200 190 191 212 164 194 187 176 190 186 173 192 198 188 185 188 208 167 209 206 198 206 176 200 171 192 180 174 172 199 192 173 203 202 162 192 190 185 167 196 178 174 206 189 184 181 152 172 182 182 215 184 200 214 187 198 197 166 165 188 221 190 195 179 189 189 180 218 176 208 159 178 207 195 185 194 182 186 188 182 195 189 197 191 206 190 188 168 180 196 192 162 182 173 193 173 192 167 185 204 194 181 153 170 179 184 167 185 221 199 216 176 176 187 189 165 198 180 184 185 181 174 180 188 240 187 193 185 180 180 187 185 184 198 178 185 207 173 199 172 196 185 214 197 169 226 199 169 173 196 188 192 195 196 172 190 204 167 166 193 192 207 196 208 192 218 190 200 186 181 187 195 188 211 195 188 179 199 174 177 200 169 175 179 186 187 182 189 189 187 176 212 207 189 192 196 190 201 187 169 202 168 217 202 175 185 189 181 168 177 207 203 179 191 189 195 198 190 192 203 183 190 200 183 176 182 191 192 174 198 170 195 174 199 170 211 206 193 159 179 201 170 186 196 192 204 189 172 188 193 163 209 183 200 192 180 160 197 165 186 186 190 171 181 204 199 177 199 187 174 201 193 182 210 200 200 178 178 185 196 185 198 201 203 174 169 203 189 213 199 204 203 185 176 201 163 195 214 168 164 189 195 194 172 189 179 204 180 183 189 193 192 173 190 181 203 184 174 172 197 208 173 178 205 179 189 206 187 174 201 217 194 190 192 174 192 196 198 207 183 189 147 203 191 157 200 233 212 182 186 201 164 212 188 174 181 202 193 172 186 163 195 174 204 192 187 195 174 171 159 194 170 210 201 172 196 185 193 209 161 176 195 187 211 171 180 204 175 223 197 201 193 185 185 171 166 185 174 167 200 200 197 168 196 158 202 200 205 182 168 183 171 191 190 192 178 211 169 179 219 178 213 184 190 184 205 186 199 189 204 174 187 191 197 207 188 190 207 197 202 200 187 154 192 184 183 173 182 146 190 198 182 186 195 185 207 188 186 200 184 190 190 183 186 198 185 206 177 178 181 226 179 203 168 179 197 172 189 198 156 208 177 183 189 175 192 211 184 194 198 193 176 183 193 198 190 189 201 203 184 197 185 211 203 178 206 201 174 201 192 162 164 193 170 192 181 196 189 194 184 187 184 195 185 220 182 192 186 202 189 184 188 184 183 193 166 185 188 183 194 182 195 200 180 215 175 182 171 182 213 219 171 195 177 187 183 171 169 175 175 188 193 163 193 182 198 193 207 191 177 162 194 177 183 199 173 169 194 175 196 194 174 177 179 224 203 183 204 199 188 178 196 203 212 202 209 196 212 192 174 159 195 194 182 185 191 203 186 181 177 175 182 179 190 205 190 202 186 187 178 191 183 199 193 180 194 194 183 205 185 186 193 199 198 184 202 182 189 180 191 176 212 214 191 193 196 212 183 185 179 191 174 200 188 206 211 198 199 182 186 189 183 211 179 188 169 193 203 185 208 183 194 189 181 196 192 185 195 186 187 169 180 209 190 198 184 180 208 177 195 194 182 170 181 192 201 208 191 181 180 180 208 174 191 159 186 185 192 169 216 184 169 193 176 185 184 178 202 201 172 179 192 209 193 171 186 188 196 191 176 179 181 203 200 194 181 146 196 184 196 173 193 203 203 205 188 195 169 191 179 185 195 207 199 208 172 194 197 197 167 183 182 190 160 177 192 190 171 193 167 167 185 186 200 186 181 176 170 170 180 188 186 187 180 188 186 185 186 209 199 208 176 154 202 181 176 170 205 209 189 191 205 183 186 181 169 188 201 171 193 187 197 194 185 181 164 185 180 198 194 187 186 186 191 185 163 175 207 188 205 174 193 196 202 199 190 204 198 174 170 225 201 189 184 195 178 209 188 194 189 160 190 199 175 215 181 191 187 151 196 199 171 189 189 198 182 183 162 213 198 201 210 186 189 185 188 211 190 167 218 184 190 186 192 189 171 177 169 184 197 187 165 193 196 171 197 196 193 173 208 206 207 199 194 207 178 209 190 186 184 180 198 158 224 201 180 185 167 178 185 187 194 214 184 189 181 206 206 189 191 200 193 193 179 152 183 176 200 206 168 196 194 202 190 199 176 179 190 194 192 202 166 180 193 180 199 190 207 164 194 180 181 186 196 169 199 186 176 205 182 168 181 195 197 187 191 181 185 207 192 195 200 186 190 188 195 193 177 228 181 191 168 184 191 188 201 191 196 226 186 187 184 206 202 211 225 205 177 160 171 204 188 202 180 209 183 175 208 200 195 170 184 196 186 169 171 221 208 197 176 190 184 189 179 204 205 183 165 188 197 197 165 205 185 184 192 194 171 187 187 164 210 190 184 182 204 197 201 205 203 200 206 169 192 191 172 176 172 197 176 184 182 186 187 197 193 179 198 157 212 202 191 187 178 186 195 191 213 192 193 185 169 193 195 207 176 195 204 186 191 193 191 196 183 197 200 171 198 182 212 195 176 177 186 205 162 186 196 176 206 189 180 162 192 219 190 197 176 163 191 203 197 177 170 171 179 175 173 202 190 202 165 186 165 204 186 197 181 196 200 200 186 191 176 181 182 193 217 204 178 201 177 180 176 182 178 213 201 208 201 217 194 188 217 197 211 174 174 178 161 173 179 191 186 188 192 205 182 188 181 201 194 211 196 189 180 187 206 190 200 172 193 161 195 182 194 185 190 188 201 185 174 189 196 199 213 194 196 197 199 184 207 203 187 214 197 187 172 203 186 194 170 192 166 199 171 180 208 186 180 213 209 217 184 198 215 201 195 186 196 200 182 191 200 198 187 188 184 180 205 180 193 205 202 175 182 212 181 174 168 201 178 216 177 191 179 182 175 198 188 164 199 182 159 200 178 207 195 182 180 184 198 178 183 179 206 192 212 187 197 198 192 209</counts>
			</dataPoints>
		</scan>
	</xrdMeasurement>
</xrdMeasurements>