File: data/XRD/XG-Luft/XG-700/W6822-1D_XG_Luft_700.xrdml
<xrdMeasurements xmlns="http://www.xrdml.com/XRDMeasurement/2.1" xmlns:xsi="http://www.w3.org/2001/XMLSchema-instance" xsi:schemaLocation="http://www.xrdml.com/XRDMeasurement/2.1 http://www.xrdml.com/XRDMeasurement/2.1/XRDMeasurement.xsd" status="Completed">
	<comment>
		<entry>Configuration=Factory configuration, Owner=User-1, Creation date=7/8/2013 4:01:53 PM</entry>
		<entry>Goniometer=PW3050/65 (Theta/2Theta); Minimum step size 2Theta:0.0001; Minimum step size Omega:0.0001</entry>
		<entry>Sample stage=MRD Cradle; Minimum step size Phi:0.01; Minimum step size Chi:0.01; Minimum step size X:0.01; Minimum step size Y:0.01; Minimum step size Z:0.001</entry>
		<entry>Diffractometer system=XPERT-PRO</entry>
		<entry>Measurement program=C:\PANalytical\Data Collector\Programs\Jorrit\2thom\_absolute_2th-om_10-130deg_PIXscan_56min.xrdmp, Identifier={15BCCF57-2807-42BD-B5B9-ECC0B3DC9284}</entry>
		<entry>Batch program=C:\PANalytical\Data Collector\Programs\SimonL\batch4x_2thom_10-130°_z9.1_x0,10,20,30_y0_57min.xrdmp, Identifier={EED9823A-2BEB-424C-9252-345C4EF2834A}</entry>
	</comment>
	<sample type="To be analyzed">
		<id></id>
		<name></name>
		<preparedBy></preparedBy>
	</sample>
	<xrdMeasurement measurementType="Scan" status="Completed" sampleMode="Reflection">
		<comment>
			<entry>_absolute_2th-om_10-130deg_PIXscan_56min</entry>
			<entry>PHD Lower Level = 4.83 (keV), PHD Upper Level = 11.27 (keV)</entry>
		</comment>
		<usedWavelength intended="K-Alpha 1">
			<kAlpha1 unit="Angstrom">1.5405980</kAlpha1>
			<kAlpha2 unit="Angstrom">1.5444260</kAlpha2>
			<kBeta unit="Angstrom">1.3922500</kBeta>
			<ratioKAlpha2KAlpha1>0.5000</ratioKAlpha2KAlpha1>
		</usedWavelength>
		<incidentBeamPath>
			<radius unit="mm">320.00</radius>
			<xRayTube id="1010048" name="Empyrean Cu LFF HR (9430 033 7310x) DK442154">
				<tension unit="kV">40.0</tension>
				<current unit="mA">40.0</current>
				<anodeMaterial>Cu</anodeMaterial>
				<focus type="Line">
					<length unit="mm">12.0</length>
					<width unit="mm">0.4</width>
					<takeOffAngle unit="deg">4.2</takeOffAngle>
				</focus>
			</xRayTube>
			<xRayMirror id="27010001" name="Inc. Beam Cu W/Si (parabolic MRD)" hybrid="false">
				<crystal type="Graded" shape="Parabolic">W/Si</crystal>
				<acceptanceAngle unit="deg">0.800</acceptanceAngle>
				<length unit="mm">60.0</length>
			</xRayMirror>
			<sollerSlit id="21010002" name="Soller slits 0.04 rad.">
				<opening unit="rad">0.0400</opening>
			</sollerSlit>
			<mask id="22030007" name="Fixed mask 2 mm">
				<distanceToSample unit="mm">220.00</distanceToSample>
				<width unit="mm">2.00</width>
			</mask>
			<divergenceSlit id="22010007" name="Fixed slit 1/8°" xsi:type="fixedDivergenceSlitType">
				<distanceToSample unit="mm">220.00</distanceToSample>
				<height unit="mm">0.19</height>
			</divergenceSlit>
		</incidentBeamPath>
		<diffractedBeamPath>
			<radius unit="mm">320.00</radius>
			<sollerSlit id="21010002" name="Soller slits 0.04 rad.">
				<opening unit="rad">0.0400</opening>
			</sollerSlit>
			<receivingSlit id="22010001" name="Fixed slit 4°">
				<height unit="mm">5.88</height>
			</receivingSlit>
			<detector id="7010017" name="PIXcel3D 1x1 detector" xsi:type="areaDetectorType">
				<phd unit="%">
					<lowerLevel>30.0</lowerLevel>
					<upperLevel>70.0</upperLevel>
				</phd>
				<mode>Scanning</mode>
				<activeChannelsEquatorial>255</activeChannelsEquatorial>
				<activeChannelsAxial>255</activeChannelsAxial>
				<pitchEquatorial unit="mm">0.05500</pitchEquatorial>
				<pitchAxial unit="mm">0.05500</pitchAxial>
				<readOutPeriod unit="seconds">0.135</readOutPeriod>
			</detector>
		</diffractedBeamPath>
		<scan appendNumber="0" mode="Continuous" scanAxis="2Theta-Omega" status="Completed">
			<header>
				<startTimeStamp>2024-10-25T11:01:11+02:00</startTimeStamp>
				<endTimeStamp>2024-10-25T11:57:17+02:00</endTimeStamp>
				<author>
					<name>PRO-MRD</name>
				</author>
				<source>
					<applicationSoftware version="6.1b">Data Collector</applicationSoftware>
					<instrumentControlSoftware version="7.0E 20130304">XPERT-PRO</instrumentControlSoftware>
					<instrumentID>0000000011142674</instrumentID>
				</source>
			</header>
			<dataPoints>
				<positions axis="2Theta" unit="deg">
					<startPosition>9.99826193</startPosition>
					<endPosition>129.99755682</endPosition>
				</positions>
				<positions axis="Omega" unit="deg">
					<startPosition>4.99913096</startPosition>
					<endPosition>64.99877841</endPosition>
				</positions>
				<positions axis="Phi" unit="deg">
					<commonPosition>0.00</commonPosition>
				</positions>
				<positions axis="Chi" unit="deg">
					<commonPosition>0.00</commonPosition>
				</positions>
				<positions axis="X" unit="mm">
					<commonPosition>10.00</commonPosition>
				</positions>
				<positions axis="Y" unit="mm">
					<commonPosition>0.00</commonPosition>
				</positions>
				<positions axis="Z" unit="mm">
					<commonPosition>9.100</commonPosition>
				</positions>
				<commonCountingTime unit="seconds">32.895</commonCountingTime>
				<counts 414 398 439 413 425 395 408 437 436 459 402 433 393 448 400 426 464 457 405 395 440 387 409 425 405 428 432 446 454 420 427 401 432 420 431 387 450 441 421 438 402 442 404 423 424 425 463 445 437 403 409 427 457 414 435 418 478 434 449 404 438 476 411 394 414 400 459 410 426 419 416 395 393 402 440 398 397 426 460 416 397 398 421 406 422 431 390 408 424 403 435 402 373 388 425 390 437 401 418 419 381 415 404 406 433 390 402 386 409 421 414 418 429 392 422 411 407 432 401 392 433 383 359 376 394 410 407 381 372 401 364 380 391 400 386 379 410 412 416 386 399 417 377 399 398 383 397 400 424 437 425 438 401 386 403 375 353 403 394 397 408 373 383 393 376 379 353 390 401 371 404 363 389 371 383 382 401 399 404 371 397 382 385 382 407 360 397 377 350 354 363 394 399 370 367 409 390 395 357 387 401 377 376 363 344 387 399 367 328 359 347 378 379 363 382 386 366 368 374 373 405 373 366 371 359 351 392 402 358 370 400 379 341 352 379 363 394 364 386 362 371 367 356 429 400 378 367 382 362 384 397 374 356 369 318 368 369 366 367 324 366 338 349 359 350 346 382 390 339 386 390 352 376 343 371 383 354 374 326 384 351 359 344 366 323 340 338 363 361 331 377 325 318 358 380 375 395 365 332 331 341 341 355 357 380 338 354 357 377 359 356 335 359 366 356 333 359 321 299 329 352 336 364 324 362 344 317 359 365 370 348 342 358 381 327 342 352 367 354 337 388 343 378 368 353 363 337 329 343 347 364 347 310 337 331 342 316 337 346 342 323 341 328 329 338 378 313 349 332 365 339 364 343 332 310 335 380 346 349 326 318 300 319 310 365 376 323 310 320 316 319 352 323 334 322 337 333 307 342 329 335 340 337 315 299 324 324 329 311 334 323 342 320 350 329 311 339 336 321 364 317 316 342 345 324 311 323 304 342 305 339 330 318 345 343 328 311 309 312 328 332 296 294 324 334 302 291 316 327 296 343 317 347 294 333 332 323 302 342 293 319 321 297 309 330 354 337 311 324 337 331 321 345 300 293 315 293 328 309 298 310 336 321 323 298 297 344 342 314 307 342 313 310 327 316 307 305 325 332 313 290 303 340 287 300 297 312 302 315 299 348 323 318 296 307 301 309 313 310 316 289 292 313 302 310 329 293 356 297 309 316 312 305 302 314 273 279 304 288 316 288 309 292 329 340 315 283 288 341 306 341 314 291 312 318 314 280 340 350 368 298 296 305 332 298 325 312 310 323 314 331 300 309 312 300 316 294 278 301 296 280 301 299 310 292 299 323 277 303 314 328 305 316 276 288 290 302 272 315 324 333 319 283 283 291 308 301 317 283 281 302 299 313 297 310 292 279 286 320 273 290 316 288 288 273 260 308 306 324 265 272 302 312 281 272 274 302 302 318 279 257 288 327 299 321 284 272 301 301 281 292 281 337 285 289 296 310 331 296 309 283 322 291 311 292 283 307 290 318 303 299 331 314 325 313 303 279 285 270 270 286 280 317 276 316 265 280 332 286 298 267 316 276 281 311 278 276 291 286 287 303 288 321 287 283 294 294 280 296 282 286 296 336 300 274 292 295 303 265 297 271 292 277 288 285 313 301 278 275 297 309 311 317 293 290 295 324 266 286 305 276 299 265 305 304 296 301 293 280 306 310 262 296 268 323 276 317 308 275 315 296 277 305 303 330 273 280 312 309 315 293 303 276 301 313 288 293 288 317 293 295 297 280 287 308 307 289 329 272 282 311 296 244 292 267 248 309 294 309 303 293 277 280 313 288 286 308 300 302 274 300 289 315 295 290 284 300 278 300 323 292 328 279 275 308 311 273 312 299 272 270 261 301 281 280 320 313 299 245 303 298 327 328 283 274 277 303 278 275 276 316 320 319 285 304 294 317 310 303 330 284 274 248 297 327 267 313 274 300 301 284 293 268 296 264 282 288 301 308 311 275 249 303 301 245 312 260 269 315 286 312 300 310 331 280 283 300 323 257 304 290 306 287 258 309 287 311 258 298 308 290 315 309 303 284 303 289 289 320 306 286 275 288 301 290 320 325 320 305 302 327 303 296 288 333 309 285 287 322 283 301 306 315 316 339 314 292 273 281 322 307 275 290 305 304 310 333 301 332 305 295 312 295 278 278 329 282 287 323 342 301 295 275 319 309 260 291 322 302 245 282 296 337 284 302 281 336 292 287 338 298 286 326 284 327 303 295 311 304 292 306 291 298 327 281 283 326 313 277 299 293 311 310 289 314 301 302 329 299 310 284 303 280 285 284 289 283 294 313 307 297 290 299 292 293 298 304 281 277 323 310 318 325 293 312 271 319 308 308 242 315 323 303 302 273 285 291 286 316 287 292 295 301 285 293 323 299 323 303 283 289 321 291 302 291 299 310 299 351 304 319 320 298 316 315 294 299 293 311 282 328 291 315 298 275 294 311 296 314 260 275 300 321 299 302 312 295 309 319 344 321 258 286 278 285 295 317 281 272 267 308 314 325 334 306 273 284 315 299 304 306 284 275 303 325 300 296 294 304 324 310 300 326 324 317 317 302 336 318 301 275 295 291 288 298 293 290 301 304 306 311 299 300 315 312 298 310 306 294 319 307 313 280 322 320 322 304 318 279 295 276 304 304 298 299 292 289 318 306 325 289 316 298 314 314 307 295 294 299 293 323 324 311 309 331 321 307 284 288 300 322 298 294 310 305 288 300 300 265 305 322 329 284 289 283 270 317 310 278 324 361 347 316 323 289 309 289 334 299 297 284 302 322 319 335 290 306 300 330 335 344 309 301 283 300 283 319 300 306 305 294 305 343 304 348 293 304 321 299 304 300 324 346 300 330 302 289 289 338 314 309 301 260 313 283 324 334 296 311 304 341 280 298 295 336 322 317 312 338 299 318 332 325 334 322 339 314 309 330 319 310 326 323 319 298 328 336 337 313 325 313 312 289 331 307 327 284 306 307 304 343 324 309 317 276 307 295 345 343 268 298 301 307 307 341 325 321 326 325 313 300 330 324 290 304 290 316 285 293 328 322 288 295 308 293 331 296 332 305 305 353 335 287 331 317 283 332 296 325 306 313 311 301 354 324 297 285 334 288 315 303 280 293 306 298 305 335 299 316 294 283 329 304 306 282 288 309 300 274 284 299 303 307 325 296 297 311 346 287 326 309 299 303 350 317 284 312 291 335 305 307 298 333 295 283 314 334 290 302 296 306 300 303 300 333 290 302 293 287 271 307 298 319 267 287 290 310 303 291 309 306 290 302 304 329 310 322 328 282 300 294 290 328 310 304 322 299 304 333 304 280 313 307 292 316 322 291 311 303 273 285 316 296 282 281 257 308 291 295 265 318 298 300 315 318 299 286 263 308 284 288 294 274 305 281 303 295 285 291 296 280 279 311 292 284 285 332 277 320 296 308 321 295 317 292 297 297 331 277 302 298 260 307 275 265 301 292 306 275 311 311 272 306 279 320 302 291 291 300 288 271 261 276 291 303 324 289 312 301 303 308 284 305 300 286 312 306 287 308 300 290 320 299 314 330 286 288 292 305 308 287 271 288 272 290 296 303 288 294 285 296 298 307 302 267 302 275 298 278 280 321 291 272 309 248 303 282 264 314 293 248 325 262 291 328 259 276 268 289 281 275 255 291 314 281 271 295 296 259 288 228 236 262 278 263 237 262 274 295 287 266 297 285 271 297 261 262 274 316 283 287 262 287 287 278 286 280 277 270 274 276 277 285 310 286 301 290 279 292 259 273 256 285 263 265 295 284 278 278 268 268 273 294 289 259 272 267 260 249 291 285 259 273 247 261 268 292 271 285 278 258 262 279 264 298 305 275 269 307 235 279 283 288 309 273 300 262 246 259 298 261 263 280 281 261 286 278 276 281 255 277 261 266 282 264 272 286 302 266 273 278 267 267 271 277 255 283 268 315 288 287 295 276 271 296 278 289 283 290 256 261 284 264 278 241 305 259 275 266 262 274 296 262 258 235 264 249 290 229 261 261 260 237 282 257 284 294 269 281 294 273 263 283 260 293 276 273 290 273 280 281 271 271 297 248 260 305 239 265 276 263 255 305 274 250 300 273 284 270 268 268 276 262 255 282 245 278 279 288 282 238 266 270 260 241 294 250 271 245 292 246 246 264 275 273 268 242 266 262 247 283 266 270 228 273 276 256 230 245 291 289 292 249 285 279 217 249 248 311 235 262 215 266 259 249 255 281 244 266 277 271 224 239 257 233 226 278 249 245 264 269 244 269 257 241 243 248 296 248 270 234 238 296 272 265 256 255 239 265 225 234 227 277 235 258 244 245 266 244 244 269 256 258 255 274 221 259 268 260 231 285 247 278 263 247 257 279 235 241 284 271 269 270 266 272 243 272 279 269 247 261 265 263 245 248 225 237 268 287 300 220 259 261 290 269 244 255 261 230 243 273 274 267 236 237 248 238 274 269 255 267 257 229 242 248 262 224 240 260 240 266 235 216 287 305 258 263 256 228 269 238 231 275 267 261 260 243 272 268 276 261 273 268 246 283 224 282 239 225 245 278 263 257 269 249 231 273 247 235 260 262 215 240 275 239 263 266 248 260 226 247 271 265 237 291 284 266 275 232 231 255 258 283 276 236 266 243 258 242 257 259 234 237 245 277 234 281 260 223 230 227 286 218 273 229 296 229 266 235 238 255 235 264 263 247 256 238 260 243 230 243 265 256 243 258 257 227 246 250 235 231 218 257 237 257 286 243 257 258 258 223 265 276 281 236 267 212 237 242 234 250 231 240 280 243 232 283 239 280 267 244 255 233 273 260 239 217 265 241 257 257 256 235 281 284 232 222 280 257 265 281 303 306 276 240 223 248 238 272 276 273 230 274 238 263 267 247 248 239 248 284 247 274 224 237 237 231 248 266 238 264 269 228 248 208 248 245 248 282 263 221 281 255 273 228 276 238 236 279 244 243 232 224 206 241 239 273 247 267 256 228 257 233 222 258 239 231 255 248 241 232 239 241 242 224 257 267 262 235 238 242 262 281 248 270 212 266 241 214 245 255 250 274 248 265 248 275 264 244 270 276 229 227 239 244 263 262 269 247 239 258 266 270 284 232 269 263 234 265 223 232 264 258 247 257 276 245 274 273 271 241 233 236 247 257 239 235 213 276 267 226 233 242 256 248 218 276 233 245 208 255 236 231 244 262 250 232 236 269 228 236 243 256 274 256 258 229 277 239 247 242 220 246 222 279 246 235 261 229 234 225 281 245 230 258 260 255 247 284 222 229 255 246 247 267 268 238 211 245 231 244 257 261 260 265 255 283 243 248 267 245 264 236 256 267 244 259 235 236 220 235 227 247 228 212 225 240 236 215 258 255 237 276 256 231 232 261 231 261 225 237 240 240 236 222 237 237 266 231 257 245 237 248 249 212 215 229 234 244 232 259 267 230 247 236 205 238 238 229 241 245 259 248 248 228 248 224 222 215 221 262 292 243 211 242 244 236 221 259 248 268 264 241 255 266 250 231 264 246 248 223 228 260 197 272 241 235 240 231 255 247 242 264 262 224 248 236 270 238 265 262 269 205 259 232 255 244 266 262 246 243 232 256 246 280 260 250 236 226 215 262 221 269 248 255 257 275 225 266 238 230 210 247 227 220 263 216 255 246 240 259 237 226 270 228 257 266 240 236 262 242 241 249 264 227 230 248 264 235 241 236 255 230 246 239 237 229 280 237 210 233 247 247 244 269 238 268 228 218 266 247 255 229 235 245 242 242 225 268 230 242 217 289 248 249 248 245 262 241 226 222 255 256 273 248 241 248 271 226 260 255 273 224 236 256 239 271 229 206 274 242 219 231 230 236 241 217 216 268 257 243 256 217 255 247 233 248 222 226 245 255 228 239 260 233 272 250 237 247 241 257 217 225 255 262 247 201 246 226 234 229 246 234 258 231 265 218 246 233 257 231 246 220 224 240 266 257 236 228 216 272 232 246 224 267 225 256 263 246 240 257 225 255 241 248 268 225 243 231 228 220 240 272 243 203 234 256 215 240 234 243 242 230 246 228 236 246 244 215 258 214 225 262 249 271 242 248 234 235 229 236 231 245 266 239 216 246 242 245 267 219 224 243 244 227 246 256 268 246 237 250 248 225 220 244 236 243 232 248 242 267 234 244 261 240 241 260 249 236 263 240 271 236 246 247 235 239 266 231 247 261 205 217 232 241 258 266 227 263 258 248 214 225 237 230 242 244 229 263 217 235 242 256 243 269 216 220 273 203 242 261 234 243 242 216 241 224 240 230 247 227 245 224 237 219 212 255 236 227 229 240 267 257 236 257 245 225 210 246 256 227 241 261 260 258 214 209 246 273 256 239 232 228 209 223 243 231 247 222 259 233 219 262 246 237 258 231 201 230 231 260 244 244 234 238 237 279 230 240 219 234 231 222 248 209 226 241 236 217 265 227 236 219 241 221 213 243 213 256 217 223 239 235 234 241 258 249 259 247 227 260 227 258 239 234 247 215 274 259 223 229 227 236 231 256 233 245 229 280 220 242 231 245 260 234 236 264 245 261 229 224 232 222 202 206 226 231 224 234 236 261 257 245 233 219 265 245 239 239 234 232 263 230 246 226 233 242 224 236 258 273 220 231 228 238 246 219 238 223 239 233 221 269 219 239 236 249 226 228 256 240 261 240 236 226 230 231 225 243 228 240 226 184 213 248 220 232 247 238 220 231 220 204 210 276 231 270 263 216 238 212 239 231 248 209 245 245 234 231 234 260 224 268 242 228 278 228 231 208 221 215 248 200 240 257 213 271 262 240 239 280 257 255 265 239 257 213 242 239 242 223 295 246 193 220 218 216 240 239 258 237 260 242 228 227 236 209 248 248 257 222 256 265 248 245 234 262 222 211 273 210 237 248 258 225 233 239 268 245 236 227 234 224 208 247 225 226 232 221 226 234 199 264 261 264 232 222 245 238 218 248 236 242 247 243 227 230 249 256 231 247 220 237 239 225 222 225 213 229 242 249 262 234 240 243 246 276 239 232 228 257 269 232 233 246 258 249 238 229 216 241 271 262 256 236 240 241 243 279 230 255 235 283 219 247 195 238 248 258 234 233 259 233 243 260 218 264 244 237 234 222 222 220 238 224 277 238 239 263 248 262 214 223 268 240 242 230 227 219 238 239 239 220 239 277 256 281 224 199 283 263 258 248 258 270 227 248 264 256 292 260 213 237 225 229 247 218 241 223 263 271 229 244 236 216 247 243 234 267 205 262 258 256 238 227 225 213 231 228 209 243 241 226 276 230 240 256 269 268 247 241 236 237 225 227 237 234 230 233 230 236 239 232 276 262 262 257 249 195 237 243 233 268 235 236 250 240 271 241 235 236 229 267 266 257 240 233 225 246 248 256 263 206 242 272 228 242 235 246 231 270 255 240 261 256 259 209 263 249 232 245 244 260 247 260 238 266 258 261 275 232 275 228 219 264 214 243 223 238 259 238 245 258 229 278 266 274 248 236 233 299 243 235 243 216 243 246 265 238 271 259 238 262 244 265 245 268 231 232 294 250 250 265 245 274 238 264 249 242 243 272 282 234 247 261 279 264 274 269 244 273 277 240 259 268 278 237 255 236 257 262 262 278 243 264 284 245 283 270 282 281 249 255 272 246 270 280 275 273 240 249 260 240 280 282 270 263 247 263 265 266 244 282 289 268 239 299 268 262 278 246 279 312 295 302 273 255 262 283 293 270 287 259 300 304 260 313 281 286 307 303 313 324 271 317 323 305 305 288 340 394 328 364 328 334 297 335 338 376 372 375 363 386 395 378 384 395 436 382 423 421 423 408 417 458 473 433 431 425 439 429 415 438 407 389 442 414 428 396 371 337 353 400 383 353 318 348 329 346 311 335 309 327 330 285 271 318 315 283 296 249 309 265 285 311 305 256 265 277 283 248 267 246 272 213 311 269 277 258 275 267 270 247 248 239 291 242 322 312 268 260 245 260 247 263 262 259 249 267 241 261 273 273 238 239 246 243 273 260 244 259 238 231 242 262 245 255 230 248 235 246 258 246 277 244 266 264 225 247 249 275 261 258 298 231 263 270 274 244 272 259 233 281 237 255 250 267 231 211 244 308 258 234 224 264 266 292 248 216 233 268 243 247 272 241 244 247 227 249 239 248 277 259 238 239 248 261 264 222 236 271 263 262 267 195 256 261 245 263 233 242 256 239 266 228 215 260 255 241 215 233 262 272 233 262 247 242 240 266 224 245 255 267 247 229 232 233 270 274 247 249 271 234 222 263 265 270 242 243 257 242 257 242 244 237 246 245 215 248 260 231 218 267 212 239 229 285 255 235 235 289 269 229 266 267 245 246 239 262 242 241 206 239 218 222 219 248 231 242 221 239 256 230 229 266 236 255 274 249 232 235 270 240 260 257 240 238 288 249 245 256 255 255 241 229 249 260 230 249 230 261 243 234 238 274 262 266 271 237 244 244 195 240 250 246 231 262 228 261 259 233 240 271 256 223 249 263 219 268 243 272 237 256 260 267 268 256 262 261 231 237 273 216 250 232 219 236 266 258 270 232 239 226 259 261 245 243 236 231 256 228 234 273 264 216 260 258 249 249 239 236 247 248 233 265 241 238 270 216 244 281 225 239 270 271 268 248 274 234 256 228 265 263 259 258 237 270 217 274 273 257 210 257 262 221 230 228 246 258 240 259 263 237 246 232 267 231 249 244 222 236 224 285 211 248 255 256 248 235 224 231 277 246 220 229 215 230 223 238 284 243 223 230 272 269 238 270 260 223 259 236 238 239 246 233 220 247 247 223 242 222 262 257 265 238 230 245 229 245 233 247 232 239 287 261 262 231 223 241 243 271 239 244 228 269 244 248 256 232 241 235 256 243 220 260 235 217 242 247 285 278 278 225 248 250 230 240 221 257 234 244 285 247 236 248 221 240 276 237 223 261 234 255 244 236 257 271 247 264 256 240 244 247 213 263 225 216 232 244 269 248 257 246 230 237 239 229 260 232 227 249 240 263 247 262 249 283 199 256 233 227 274 237 273 242 255 223 234 270 255 267 258 244 267 275 243 243 221 218 267 223 230 265 244 230 232 255 232 261 233 249 235 256 234 236 243 255 260 244 267 283 233 266 237 241 266 244 220 238 257 238 219 231 204 203 238 231 240 263 276 204 231 229 256 258 246 265 218 272 228 260 236 277 230 279 258 274 226 299 232 283 238 302 231 246 243 235 261 257 229 266 256 239 242 239 242 217 249 232 241 247 243 242 249 249 261 240 258 203 257 257 243 225 244 265 225 215 247 246 246 232 244 237 262 256 230 238 256 223 235 258 295 227 225 238 265 243 226 244 258 264 275 247 245 235 255 240 222 228 255 257 266 227 240 249 231 218 269 256 268 243 263 256 259 257 243 282 257 216 244 260 255 209 244 225 234 238 230 247 247 257 230 256 270 270 243 239 242 255 273 281 236 243 281 261 260 233 247 268 268 209 260 243 236 245 271 271 270 256 234 243 221 234 284 256 240 227 245 238 267 237 272 235 256 262 255 244 229 283 227 280 224 260 246 277 258 269 213 271 238 269 236 264 249 273 279 248 259 263 262 275 238 249 237 264 267 237 255 232 283 240 231 268 265 262 261 284 266 233 211 221 238 280 224 271 235 210 233 232 256 260 217 261 239 266 223 235 207 233 220 266 278 271 248 218 262 255 259 229 289 268 289 240 265 247 247 244 261 209 214 259 257 231 268 224 234 279 234 228 226 245 244 256 247 266 240 259 228 235 282 227 255 262 267 225 241 267 279 235 271 278 265 261 276 270 224 261 249 233 227 265 228 270 271 283 223 229 249 249 247 257 259 266 243 239 265 244 270 243 243 246 246 285 258 280 249 234 242 278 270 261 244 261 262 241 257 261 286 264 257 232 291 206 230 229 243 259 236 272 267 265 245 265 234 243 225 271 259 236 227 281 233 250 223 259 228 217 243 268 238 266 227 262 264 245 268 264 281 240 232 272 243 258 222 238 240 246 245 228 246 241 266 268 257 240 245 264 264 267 258 237 244 245 231 238 250 229 242 242 295 236 248 272 260 257 250 272 275 261 257 247 274 262 293 264 259 256 242 257 232 250 255 255 230 268 270 259 260 278 234 258 207 227 269 248 256 268 236 242 283 232 295 234 224 245 217 240 261 231 260 233 250 228 267 241 247 265 244 236 264 228 262 270 267 258 232 297 225 271 269 223 256 267 255 236 255 219 222 256 256 238 231 267 257 236 240 259 261 260 237 264 256 256 255 274 219 233 240 258 235 255 263 221 232 228 277 266 273 257 238 266 258 261 221 256 263 264 276 256 240 263 276 231 274 249 292 248 235 266 245 272 234 259 270 275 227 261 259 243 250 255 257 247 280 279 260 246 244 264 234 230 262 262 261 224 241 278 257 260 242 241 264 230 260 278 229 242 240 271 295 294 221 224 257 239 237 244 243 235 277 275 262 270 249 269 241 262 261 268 255 269 265 262 232 248 279 249 259 283 248 262 265 241 231 279 256 288 241 255 221 268 246 247 245 241 269 269 234 209 242 258 267 242 232 263 266 238 219 261 235 238 277 278 266 233 249 276 265 258 290 237 260 241 227 240 259 249 262 255 232 265 212 241 224 259 230 273 280 262 281 241 260 270 255 247 249 266 256 232 242 229 280 217 244 221 236 241 228 237 237 248 274 239 259 243 245 262 232 268 255 237 248 275 228 274 239 248 235 243 264 261 229 260 270 248 259 259 215 264 243 255 243 243 265 267 272 272 243 255 265 296 224 283 241 222 263 239 259 242 248 241 267 256 275 266 229 239 270 286 249 241 264 242 243 246 233 261 233 261 282 238 262 259 277 249 267 259 283 241 247 256 259 235 260 291 255 245 277 260 237 268 263 258 226 236 276 239 255 248 265 235 256 272 267 248 243 235 238 240 289 227 242 245 271 264 236 271 275 258 246 227 257 241 243 261 259 262 246 248 228 266 240 255 258 257 242 249 233 240 272 238 270 213 269 260 222 278 255 291 241 262 259 261 236 271 272 265 277 231 237 234 264 246 260 260 289 243 234 226 255 238 292 244 296 230 241 255 248 235 256 266 247 277 261 236 275 227 224 293 240 239 229 276 246 222 249 248 260 244 242 246 225 273 283 244 257 236 272 241 266 235 246 244 292 231 266 265 241 300 224 237 230 241 239 314 262 263 233 268 263 233 274 266 290 245 287 238 243 245 246 235 220 295 267 240 238 239 283 203 244 282 232 200 256 218 275 241 255 256 247 269 265 246 212 240 232 248 272 223 240 258 273 263 235 266 240 230 282 238 249 248 269 244 240 294 268 256 268 227 227 255 269 262 272 298 231 236 272 270 274 250 262 213 270 222 271 290 225 232 267 232 258 219 246 231 289 258 237 237 259 234 267 271 282 270 286 282 237 273 274 225 247 255 266 270 263 258 279 264 245 297 228 248 261 280 285 265 275 273 269 272 260 256 284 238 235 240 255 236 236 243 275 249 276 259 267 263 269 234 249 236 262 267 268 235 249 239 221 240 226 274 242 244 262 255 256 244 261 217 207 288 240 264 307 293 239 257 248 224 240 261 257 244 264 267 281 291 269 265 246 256 234 239 242 263 250 258 256 237 241 249 246 272 236 259 286 250 277 284 236 272 263 238 273 244 283 256 240 264 262 242 256 286 275 260 255 271 249 296 264 272 277 243 237 261 263 226 266 270 247 225 291 246 274 230 264 273 238 269 267 268 310 217 234 275 260 271 283 266 241 256 262 263 266 241 241 235 264 224 261 243 265 255 257 255 266 258 263 279 278 268 272 279 261 268 234 240 246 266 273 278 249 273 233 239 239 270 269 243 243 265 249 266 246 283 269 242 273 263 248 271 268 234 283 268 263 227 280 312 285 257 268 271 250 259 261 278 266 232 280 263 229 244 258 266 283 263 244 262 249 269 290 248 269 260 230 248 221 213 256 268 236 278 255 255 277 256 239 273 269 273 238 239 241 256 271 261 259 266 247 306 242 249 272 246 237 269 275 266 278 270 265 270 262 241 247 260 286 280 273 294 227 230 257 262 218 269 212 237 227 277 298 283 273 259 239 276 257 274 238 236 266 246 219 236 248 284 268 245 242 247 247 208 257 263 282 257 229 264 273 269 246 258 224 276 259 287 270 236 231 279 237 288 242 231 272 265 249 238 247 263 292 255 234 262 237 260 271 237 242 268 257 257 275 271 238 246 260 277 244 242 245 262 260 285 306 249 246 263 230 246 263 245 249 275 272 241 291 261 264 247 234 273 259 264 274 257 269 237 268 217 256 235 273 270 255 270 258 249 263 249 240 242 260 260 273 237 288 245 277 261 267 272 268 288 284 258 256 276 263 243 276 283 269 236 277 236 263 247 269 256 224 268 257 272 291 257 280 277 280 272 232 275 259 303 227 269 297 290 276 310 273 261 276 241 268 286 267 260 275 241 248 279 273 263 260 276 288 284 283 270 302 266 257 261 257 284 262 267 294 282 277 240 287 256 289 264 262 271 234 280 232 249 225 256 258 312 237 230 270 239 247 255 246 248 278 262 271 264 271 281 267 268 271 280 256 279 297 282 275 296 274 298 280 255 276 272 239 282 242 258 266 266 239 259 261 277 277 276 275 275 250 289 263 283 269 231 278 270 242 255 264 226 269 259 241 288 255 257 270 269 299 262 261 264 269 262 264 224 289 265 268 261 268 269 245 255 233 247 244 264 247 257 269 267 261 238 250 219 265 231 285 284 241 267 235 302 273 226 242 264 284 297 280 247 274 263 222 230 266 285 247 270 260 234 249 278 273 272 246 266 261 249 277 224 279 269 240 261 246 262 277 263 272 241 260 287 235 249 280 230 250 248 294 256 248 255 255 260 248 245 242 259 234 247 240 248 255 242 289 291 264 220 231 293 239 233 243 279 283 247 237 261 239 265 270 281 258 289 238 264 255 245 255 259 256 282 245 228 238 271 261 258 248 276 235 231 265 280 225 276 284 259 243 255 243 290 261 228 242 267 264 224 241 242 261 230 258 259 232 238 255 264 238 270 239 289 274 272 255 261 267 286 266 245 297 247 256 249 246 274 262 236 277 260 239 297 266 261 230 246 233 271 247 247 260 271 242 269 244 279 237 227 246 264 249 267 259 260 266 276 261 284 245 258 257 232 274 279 291 244 233 236 227 259 235 241 238 262 229 263 249 238 242 264 267 248 263 259 232 263 237 239 264 262 272 274 274 271 273 260 281 294 262 275 249 287 275 223 297 244 270 243 264 261 270 278 290 233 278 272 257 246 241 258 277 231 272 268 249 266 272 256 278 266 229 236 242 289 259 246 226 248 243 257 234 272 222 230 289 221 259 232 230 263 264 239 245 236 260 261 240 276 264 255 239 229 275 246 244 270 258 258 241 242 235 244 281 290 261 272 280 248 245 265 223 260 276 237 272 230 236 240 278 256 247 267 276 288 237 292 244 260 247 259 262 273 248 234 262 267 274 256 274 238 226 294 273 307 266 225 274 271 262 230 263 232 255 264 266 229 246 269 276 270 261 271 231 238 256 287 229 269 238 271 235 274 274 227 259 265 262 249 241 261 294 239 273 225 260 272 235 244 281 260 268 245 209 237 281 267 268 276 258 242 265 237 273 259 235 236 241 249 237 233 282 260 269 234 276 248 259 235 260 261 209 231 258 278 260 280 221 245 261 234 284 268 278 246 259 258 235 235 264 237 238 247 284 262 255 277 272 256 276 237 255 238 262 234 244 212 236 273 242 267 259 241 208 270 269 230 274 266 238 233 258 244 266 260 264 268 241 263 260 255 244 241 240 269 233 257 242 264 220 263 282 229 272 247 262 255 228 247 246 260 216 290 267 268 233 242 274 257 281 260 259 233 259 224 227 223 250 257 231 240 230 262 243 266 267 267 265 270 249 272 281 228 243 220 262 243 278 265 282 247 299 246 236 259 269 272 266 269 259 277 246 275 256 272 244 233 246 242 246 248 240 245 245 272 290 280 260 248 243 248 258 285 223 226 228 258 241 264 270 262 278 222 258 279 241 274 274 275 236 270 278 270 248 243 258 288 272 231 259 236 249 264 276 267 265 273 257 255 239 258 246 271 229 238 292 233 246 263 256 277 268 241 257 258 256 244 269 270 246 279 245 255 264 239 235 237 234 256 257 260 248 261 228 261 240 262 242 220 258 238 242 249 259 257 266 270 273 255 276 245 293 259 266 280 263 278 260 269 231 258 257 244 228 241 241 265 245 262 259 263 211 256 230 236 273 260 247 240 276 244 262 270 244 262 250 270 255 262 278 267 228 259 264 227 228 273 262 244 289 220 242 279 259 244 246 243 245 211 267 276 280 290 263 258 225 250 242 287 264 239 218 272 265 246 259 270 260 284 249 258 261 265 218 242 270 257 242 260 279 284 221 262 272 246 249 245 280 270 243 249 238 247 261 211 248 273 262 219 256 281 261 260 266 245 249 271 256 268 276 233 250 243 276 263 298 257 295 260 258 220 266 278 258 240 258 242 291 257 272 245 230 247 247 233 240 243 281 228 266 246 237 228 260 265 255 228 256 276 260 247 257 228 256 240 257 250 226 258 294 265 271 244 240 270 266 270 230 258 276 258 250 259 281 272 262 234 242 245 242 282 229 229 247 262 259 289 277 241 243 267 275 267 273 243 237 278 240 270 263 235 277 273 267 247 284 262 246 276 277 238 232 235 268 236 259 278 249 260 291 244 268 247 231 263 265 273 232 244 236 286 265 261 247 262 262 258 233 268 294 266 281 296 244 270 266 264 265 263 279 267 272 259 230 264 247 250 238 262 247 284 258 240 239 270 262 246 283 275 268 228 296 262 270 243 285 276 256 233 249 276 256 272 294 257 248 288 267 276 264 264 272 267 288 245 238 247 259 277 267 239 258 258 255 235 242 294 276 260 278 257 243 231 256 259 226 293 284 235 262 235 267 264 233 241 260 228 229 275 261 244 233 255 289 270 260 297 271 237 229 269 255 280 266 274 266 269 287 260 265 249 231 259 268 279 271 230 255 272 256 275 258 257 239 270 250 257 257 285 262 241 278 249 240 269 241 248 256 279 280 243 255 235 267 266 245 249 290 245 276 280 233 228 261 280 286 267 242 244 241 312 267 264 264 248 245 262 293 292 248 264 243 228 231 245 234 275 250 277 240 280 262 269 243 263 267 246 280 246 263 248 230 241 274 276 231 245 282 266 237 269 291 231 301 267 272 277 282 239 258 278 265 275 302 240 244 281 268 267 267 297 259 245 259 272 279 274 244 273 282 278 242 261 284 249 278 239 249 277 239 288 231 258 281 241 274 249 261 244 263 292 255 275 232 262 255 277 285 249 224 231 264 240 265 268 267 267 259 265 270 255 260 255 246 286 281 233 275 241 246 270 261 243 272 265 287 290 316 277 278 247 218 213 268 273 235 261 259 272 271 268 258 240 248 240 261 270 243 258 269 256 245 276 284 248 269 279 229 273 303 246 257 239 257 266 266 265 241 276 259 268 230 243 287 263 232 273 290 256 271 236 230 258 242 264 269 248 265 292 247 244 264 262 278 228 247 248 261 241 259 274 257 256 249 273 286 249 272 264 249 246 255 218 270 231 257 248 259 247 279 260 263 268 259 239 255 273 259 249 255 274 278 275 261 264 246 239 275 258 259 271 299 259 257 245 261 238 268 287 243 263 233 234 282 290 267 282 269 263 290 277 273 273 282 274 230 277 266 255 265 233 262 243 274 281 284 246 255 280 255 266 288 230 270 282 255 278 258 265 259 243 272 287 273 227 279 269 282 270 257 235 242 290 262 249 269 277 263 232 234 281 309 247 277 259 278 248 250 266 258 245 237 286 275 267 268 263 243 256 232 243 263 284 236 231 256 213 226 247 283 268 260 234 263 264 268 283 247 286 247 272 288 264 278 277 256 247 216 229 272 277 262 249 267 290 240 261 224 239 285 240 271 266 281 268 306 270 240 228 261 261 255 272 287 269 310 221 260 266 239 265 257 274 230 245 237 287 261 240 261 289 273 281 243 264 241 274 237 272 256 245 259 270 245 255 263 237 292 269 231 273 241 269 258 241 276 242 246 289 267 267 278 273 263 282 309 288 286 260 272 264 271 270 286 264 262 264 258 268 281 273 244 281 233 269 241 289 269 266 236 289 286 256 239 244 245 284 266 267 257 284 256 281 227 269 266 284 295 282 225 283 273 257 286 269 255 265 286 276 271 265 285 263 277 260 274 273 263 308 269 259 268 258 249 261 282 260 260 246 288 246 276 276 270 262 274 277 274 274 283 293 278 288 255 289 278 257 235 286 266 271 302 286 264 284 262 304 310 310 308 261 256 283 284 293 267 275 292 307 244 307 310 289 293 285 287 300 300 316 272 306 300 280 324 314 315 318 296 281 300 308 305 282 308 304 308 319 291 293 295 326 300 302 322 293 319 288 294 268 294 278 280 288 313 288 277 299 291 304 243 264 281 307 268 292 297 295 331 289 268 256 266 281 285 263 295 301 262 283 291 282 261 258 279 255 282 269 278 266 278 278 247 239 293 262 283 267 233 249 271 266 249 280 278 242 284 240 240 304 277 255 250 246 282 267 225 258 237 276 293 258 270 234 262 266 277 275 286 234 263 278 261 269 280 231 267 239 231 298 259 275 272 238 260 238 246 282 265 242 243 275 286 244 260 237 229 260 269 267 232 276 264 261 249 283 263 249 283 261 260 269 269 238 280 262 274 276 225 248 284 262 240 263 261 267 245 273 244 256 285 267 266 248 262 266 229 256 287 275 292 279 267 237 243 267 261 299 277 249 248 247 248 234 266 266 280 273 247 278 239 248 246 244 259 264 246 247 277 272 286 264 276 258 260 246 250 287 279 277 264 247 241 282 238 274 264 268 247 272 237 287 234 239 265 248 274 259 248 237 257 271 268 259 267 244 268 239 299 270 260 277 287 244 264 232 281 293 268 234 241 268 267 280 291 241 227 284 269 260 229 249 306 265 288 264 273 229 260 236 259 267 244 268 260 267 236 259 278 273 249 248 246 231 259 296 249 244 257 233 269 266 219 257 261 235 249 244 270 266 273 260 280 274 237 247 270 262 258 269 272 236 276 281 238 284 246 279 257 236 288 266 232 244 256 272 228 241 265 281 244 265 282 287 291 242 241 248 239 263 217 248 244 259 269 286 268 256 241 246 239 233 245 222 291 246 241 273 258 267 263 258 236 278 259 267 256 265 256 262 281 263 248 262 255 266 240 306 221 261 272 226 229 249 269 260 255 227 264 225 292 243 219 261 238 223 250 236 247 256 284 274 244 242 238 264 248 234 257 261 260 279 250 248 236 282 255 250 261 257 257 294 263 239 226 238 262 226 235 264 250 234 220 262 263 258 243 259 235 267 257 268 240 287 267 258 276 273 265 214 237 265 268 236 278 222 295 277 265 226 256 261 259 239 248 263 247 267 280 249 235 248 256 244 212 220 294 245 259 271 258 215 248 277 265 262 241 256 265 257 238 255 245 231 257 246 247 279 232 259 276 284 236 263 277 282 246 269 221 280 245 240 217 249 199 279 240 260 250 250 261 242 284 246 247 275 258 258 269 230 248 263 262 258 238 264 256 247 266 271 227 249 278 236 270 234 229 242 268 245 242 266 236 231 217 233 241 238 274 261 222 285 240 242 263 272 240 271 247 230 273 244 240 264 276 259 258 248 244 255 259 259 274 240 216 281 238 231 278 296 219 273 256 241 241 246 270 235 226 266 267 262 265 228 244 267 286 283 279 232 257 244 261 241 241 241 239 272 270 232 229 263 273 232 276 268 238 286 299 277 256 241 244 239 306 262 273 240 228 240 262 248 278 262 249 255 242 264 245 241 234 261 275 263 282 242 265 244 267 232 269 240 234 260 264 238 248 233 267 264 247 257 274 236 267 291 240 255 245 266 275 233 262 258 229 229 255 263 263 267 267 235 233 258 220 257 290 246 282 233 263 304 263 256 221 303 241 261 244 260 259 258 264 261 268 255 263 240 255 249 260 257 239 243 237 277 271 273 257 280 282 235 265 279 257 274 256 263 248 269 268 267 248 238 231 235 273 261 259 237 235 287 250 225 265 238 216 248 246 233 238 230 260 267 230 246 264 301 278 267 263 286 248 223 262 230 240 246 279 250 287 285 255 256 242 229 276 243 282 231 207 272 263 266 269 261 231 250 272 243 263 246 236 218 230 258 246 244 256 248 262 264 240 287 263 263 259 266 262 259 284 250 299 267 236 249 257 274 260 249 284 238 259 239 267 262 278 241 245 221 238 233 246 282 264 281 244 273 241 265 231 298 267 240 249 256 237 259 259 249 260 282 224 228 247 245 230 269 268 277 240 236 268 282 255 265 234 279 243 269 227 256 236 245 258 244 239 265 289 306 259 263 274 250 258 230 255 284 279 238 256 233 260 259 238 285 245 268 282 277 218 249 265 231 257 243 268 283 229 298 228 241 261 287 226 243 275 278 265 243 227 239 224 249 232 246 259 265 223 248 265 211 224 241 285 241 246 238 258 245 256 280 241 265 241 278 211 227 266 242 235 263 239 278 257 255 281 286 267 247 265 241 226 230 276 240 280 274 261 244 284 217 272 270 264 261 268 261 233 259 246 239 277 247 233 247 232 276 218 255 236 266 268 234 274 264 272 229 238 258 243 259 265 241 281 233 242 245 263 277 255 243 248 258 223 259 268 259 234 277 257 247 271 246 237 225 247 243 256 261 257 234 218 264 249 244 229 264 246 263 227 271 245 232 261 235 273 273 270 218 260 278 244 255 282 246 255 255 233 233 261 265 260 238 246 234 255 223 237 268 269 265 263 259 262 256 259 234 229 258 264 224 279 241 260 241 238 218 265 215 261 257 234 282 262 248 257 238 263 263 222 244 240 235 268 240 241 258 257 269 244 276 282 287 260 243 243 250 242 240 258 256 249 243 275 258 257 243 233 216 228 280 247 262 264 274 246 256 227 269 256 229 271 273 248 237 288 232 256 273 265 244 224 247 262 261 260 265 261 227 272 260 243 266 269 277 216 263 239 264 275 266 246 240 276 240 264 228 266 244 267 208 263 258 259 266 255 258 256 224 242 279 225 262 271 257 237 234 264 282 272 247 247 240 258 287 267 243 221 289 218 256 295 241 273 241 245 265 236 256 261 241 240 257 256 246 260 275 221 265 301 270 259 280 280 276 268 235 262 231 287 256 259 260 228 255 269 269 285 247 256 233 225 255 249 263 244 246 265 257 263 257 256 236 238 256 235 239 250 270 255 261 246 242 223 268 249 239 228 266 246 281 246 264 250 261 267 261 228 241 226 255 248 286 242 269 250 279 244 277 280 240 282 257 233 284 247 266 249 266 273 257 242 299 256 276 272 240 276 245 278 278 269 245 269 258 260 288 249 235 268 265 274 224 230 276 274 262 262 248 261 260 256 244 280 285 219 243 247 258 266 267 241 269 288 270 269 265 237 245 242 244 260 235 259 240 259 240 271 244 219 261 270 231 271 262 242 244 244 261 276 261 263 256 237 289 281 261 241 263 246 234 229 233 298 245 259 245 255 270 249 241 214 290 263 293 287 247 274 247 243 245 282 235 245 235 270 262 266 285 236 287 259 290 238 240 261 286 257 236 269 279 246 249 245 265 240 278 271 261 270 270 243 233 279 246 275 270 283 256 239 271 243 245 282 237 259 246 248 256 262 258 276 271 259 266 259 229 258 240 281 284 239 257 240 242 291 255 274 229 260 274 261 281 268 282 249 268 262 257 270 238 258 234 264 257 238 227 245 237 249 235 284 264 256 275 274 264 240 260 241 270 267 229 256 263 262 229 249 263 257 226 267 260 295 241 261 231 226 257 280 250 264 266 275 275 261 266 238 270 294 256 241 236 268 287 271 300 270 271 265 234 264 264 256 244 246 226 263 244 261 242 244 287 264 266 288 249 257 235 268 268 267 274 298 288 256 274 247 268 270 230 274 255 255 241 225 278 256 264 282 259 266 281 237 275 263 277 277 267 220 235 241 268 259 226 236 268 229 248 265 272 246 271 277 266 268 281 269 278 272 248 281 275 273 260 264 243 268 277 242 243 244 288 249 257 234 248 269 264 263 242 259 257 305 247 302 228 259 271 236 259 245 269 248 247 261 293 269 271 283 255 274 257 256 260 264 279 277 282 261 290 294 247 235 258 279 260 269 226 276 264 298 257 272 260 288 236 290 284 274 273 268 271 261 272 279 275 291 243 258 265 248 244 284 300 260 271 268 257 246 267 265 265 260 244 261 285 229 277 304 228 266 279 280 288 281 258 291 233 244 257 233 283 247 284 244 236 314 267 265 303 297 269 298 273 249 242 255 275 277 288 265 244 245 263 270 280 268 246 232 290 230 242 268 260 272 239 284 220 255 241 270 273 269 262 257 260 271 255 234 265 263 282 246 242 259 266 283 248 273 238 259 257 263 268 270 266 245 236 249 247 267 278 263 247 260 249 259 258 296 210 232 238 269 247 283 265 268 213 265 232 242 240 244 262 223 223 241 249 234 299 260 241 273 256 264 259 257 261 266 278 257 277 242 235 246 285 285 286 263 282 274 241 277 286 271 280 231 225 272 284 281 248 264 300 238 289 260 237 284 236 228 248 274 288 293 247 260 264 281 237 270 276 287 248 250 276 267 263 247 238 264 279 281 286 263 257 277 286 269 284 270 286 273 268 288 242 280 231 257 260 249 260 234 274 270 266 255 262 227 268 260 255 221 273 229 238 282 265 256 277 266 263 267 272 221 287 276 230 270 265 259 255 277 293 282 239 283 292 269 273 242 238 270 278 274 288 274 262 272 238 275 259 278 268 229 236 246 261 267 266 276 267 278 266 269 237 245 256 267 259 268 255 237 290 239 270 266 265 244 248 259 261 279 271 277 274 266 265 279 250 272 292 245 273 263 255 267 263 225 279 281 279 273 278 261 264 264 260 271 246 268 272 247 265 258 264 288 236 282 267 266 282 265 281 273 262 279 257 239 244 273 258 276 271 258 248 233 255 294 258 272 266 245 279 269 268 257 281 227 292 273 277 234 259 261 263 276 256 243 277 248 270 255 263 275 265 284 243 245 289 250 221 232 242 282 279 287 235 222 262 287 260 227 274 266 242 240 262 278 248 266 273 256 259 270 272 307 275 274 269 267 271 268 259 246 270 286 267 258 286 269 275 284 276 270 275 302 235 282 247 238 241 238 225 245 270 268 259 244 234 258 275 290 259 299 259 226 272 269 278 245 242 240 244 268 258 271 219 239 255 267 295 267 214 231 289 291 285 261 278 283 264 263 255 272 255 230 266 274 237 285 285 260 242 242 220 284 262 221 240 275 269 259 246 264 266 275 232 286 261 264 271 257 266 246 265 271 264 259 266 263 244 257 264 266 265 263 281 268 270 258 278 240 264 280 258 290 248 255 255 280 246 265 279 247 262 282 281 248 240 244 266 272 277 257 263 231 247 243 241 260 276 269 272 297 235 279 272 247 304 271 261 245 261 274 285 244 239 270 282 293 277 244 255 221 296 275 225 277 241 241 266 282 235 281 260 245 235 248 266 256 236 249 269 272 260 250 279 261 264 231 248 257 287 262 289 271 248 262 261 240 271 240 275 272 245 256 260 292 227 285 264 266 258 255 276 242 266 230 267 229 243 272 300 265 239 247 270 234 272 247 267 237 249 262 282 259 262 256 246 257 262 263 269 233 281 271 267 256 279 266 257 263 281 275 241 261 291 273 230 250 258 278 242 269 241 231 266 273 272 286 233 240 241 235 265 266 239 261 291 262 270 242 274 284 258 246 231 238 250 246 238 285 294 258 256 273 247 278 241 246 260 269 274 258 266 247 268 282 276 261 218 256 278 258 274 243 291 274 244 259 260 237 271 286 243 242 277 232 271 269 277 301 267 258 236 259 230 242 286 243 229 238 234 240 247 261 275 244 281 272 277 244 260 297 265 264 244 257 269 234 289 235 225 250 274 247 272 222 245 259 240 249 275 280 257 272 259 263 266 266 271 240 237 277 264 223 248 224 222 233 296 273 243 263 255 276 255 271 266 246 261 236 248 280 269 260 238 230 245 269 277 241 278 284 243 233 272 224 265 265 275 235 250 291 270 281 246 258 261 278 248 266 248 277 263 263 280 262 264 236 249 280 284 277 274 264 272 266 250 245 250 223 266 296 262 264 261 243 264 250 241 257 245 240 262 255 259 278 248 275 237 271 278 296 280 268 244 221 256 271 297 242 268 269 260 242 268 240 262 259 288 278 250 286 247 280 269 245 264 247 231 270 240 290 279 249 273 275 271 267 255 297 285 286 258 228 282 279 244 267 280 263 289 272 266 220 234 247 259 271 245 245 267 231 280 281 250 266 262 283 241 259 256 301 241 272 282 245 244 264 244 258 280 234 273 259 285 256 268 273 287 242 235 283 309 277 290 308 272 243 273 246 263 262 222 247 259 273 245 244 239 278 248 276 271 229 259 276 276 234 260 262 240 243 272 292 269 263 257 287 286 262 235 262 294 265 259 257 262 268 258 226 245 294 263 264 264 301 276 272 270 258 288 282 245 262 295 246 237 236 237 272 271 281 260 233 292 273 269 275 267 255 273 258 265 232 263 280 261 260 221 259 258 281 240 268 269 292 255 297 263 302 264 276 258 279 269 266 272 282 298 255 242 294 260 246 241 276 278 238 273 281 258 267 260 289 298 276 255 299 255 238 286 274 272 292 244 235 285 257 233 266 235 282 269 256 270 264 269 297 257 263 276 248 275 256 225 261 248 266 276 244 296 275 288 247 264 243 261 257 245 272 288 262 261 275 296 264 281 256 263 285 280 276 295 269 256 258 246 260 245 284 288 259 279 286 230 269 247 257 283 264 270 262 246 293 258 294 240 242 242 274 259 231 270 267 278 280 255 273 263 262 277 271 294 268 225 258 266 267 282 271 273 299 274 269 241 259 248 257 271 289 256 259 262 256 264 247 271 266 241 258 280 257 285 255 270 238 255 265 246 241 245 242 262 258 262 270 246 281 260 211 300 287 245 237 291 263 248 281 292 266 276 241 230 258 266 257 271 293 275 238 298 265 232 296 303 261 260 229 274 227 280 277 269 264 268 234 294 242 278 270 270 261 295 285 262 264 243 265 242 259 241 233 268 268 298 279 260 271 258 265 266 258 286 232 258 266 250 257 292 256 261 242 279 230 282 269 261 249 273 262 224 260 262 289 257 242 268 255 240 242 295 239 260 244 235 295 295 260 282 263 298 272 257 262 290 290 260 248 243 267 280 275 280 266 258 240 263 265 275 229 272 303 273 286 272 256 233 265 287 268 275 258 236 258 262 272 243 265 278 273 274 258 277 285 276 245 265 260 269 231 269 278 263 248 267 286 271 286 303 286 269 264 238 293 244 257 279 262 294 269 242 256 265 276 284 277 249 240 280 300 274 279 264 265 277 266 231 277 282 266 259 273 276 242 228 256 271 282 237 277 271 243 265 256 237 256 236 267 271 304 261 248 274 258 288 218 276 238 296 272 235 263 280 272 275 267 221 255 282 262 255 279 296 269 249 270 272 249 258 267 279 265 247 299 267 263 249 245 289 241 242 273 268 245 239 281 265 243 271 231 238 280 282 246 264 271 271 255 249 265 263 280 235 243 245 239 267 267 284 285 296 231 230 287 258 273 263 261 259 263 245 216 274 250 250 235 240 241 258 236 244 241 245 267 249 246 244 286 269 241 249 262 279 264 249 238 274 279 256 241 259 300 250 268 260 259 242 286 230 255 268 261 298 271 235 263 287 279 249 231 258 229 285 281 270 232 260 283 259 223 264 281 239 244 234 270 279 268 242 280 257 282 260 287 268 259 246 270 302 277 231 261 275 277 274 242 266 291 233 314 295 278 272 248 273 238 248 245 268 276 260 267 285 255 237 281 273 257 304 249 243 267 269 269 245 287 259 283 256 257 241 286 261 241 235 283 279 270 248 274 235 256 261 220 297 304 275 242 302 279 287 260 295 299 247 258 275 267 298 291 256 266 271 270 286 280 247 262 292 278 278 248 273 264 259 270 285 243 267 290 263 279 281 290 245 281 246 284 290 262 263 277 269 271 303 262 285 265 296 297 276 270 286 303 285 278 297 270 292 276 278 293 308 270 271 284 295 315 263 263 279 281 283 286 255 296 231 285 282 299 275 283 270 316 273 304 271 265 283 297 275 303 262 295 286 285 274 300 242 262 279 298 285 268 315 285 250 299 284 268 284 286 284 268 257 272 300 284 291 232 269 268 294 245 258 257 269 275 283 279 269 248 258 285 247 293 268 267 281 286 316 247 271 220 261 259 292 265 256 306 265 285 267 263 246 283 245 266 293 265 283 282 265 301 257 255 266 305 278 269 307 271 267 241 277 243 274 255 276 297 265 287 272 271 297 265 264 269 288 257 275 264 294 277 281 271 264 284 244 285 284 283 265 261 286 261 270 274 281 279 262 287 273 241 238 277 282 260 225 270 239 247 288 275 270 272 255 270 237 276 282 257 245 301 279 242 272 262 303 236 236 283 277 247 256 287 275 266 272 230 260 288 261 263 266 274 248 259 270 267 278 282 270 265 257 284 246 290 265 223 262 268 281 294 274 281 279 266 271 228 273 268 242 278 258 265 259 269 277 274 270 259 280 258 284 282 265 272 243 259 259 270 258 248 288 283 255 261 257 273 288 260 228 228 271 283 265 263 259 285 238 291 282 269 279 255 283 276 277 279 264 262 278 294 281 283 256 241 257 274 268 260 240 256 277 288 273 281 240 274 265 275 269 247 239 249 259 294 282 264 223 245 282 276 243 283 262 276 248 292 232 274 299 260 266 279 264 274 293 263 261 262 238 308 238 278 215 282 277 267 241 230 283 263 245 264 299 280 269 295 313 272 244 287 273 289 267 283 282 269 261 276 259 279 286 258 291 267 277 266 262 248 279 250 248 256 250 246 274 235 249 283 269 227 266 245 264 257 249 272 277 265 248 287 242 267 258 260 261 244 268 265 242 286 274 286 274 275 259 302 245 247 243 274 237 257 277 278 275 256 248 245 257 258 262 244 269 275 266 247 258 265 247 260 276 287 283 249 226 256 269 269 285 280 261 269 269 258 275 270 249 266 279 271 271 259 234 259 255 276 244 283 240 268 241 243 257 226 269 290 268 258 259 275 241 241 256 263 267 271 267 271 250 244 250 263 245 256 263 259 287 271 233 283 267 265 259 267 258 231 258 275 276 259 257 282 241 287 278 251 261 277 275 278 249 262 275 244 274 255 271 277 259 275 272 248 241 265 276 234 246 238 227 270 258 289 262 257 238 280 259 239 246 244 249 265 279 271 249 238 280 263 261 236 273 270 276 277 242 268 234 255 257 265 291 258 244 268 285 274 259 265 276 263 247 262 258 242 242 299 268 271 263 261 237 283 283 272 237 249 270 269 271 277 305 262 230 292 285 287 289 258 265 245 267 291 268 273 274 282 261 241 271 241 267 291 247 244 278 278 291 274 273 256 249 275 241 245 285 275 259 224 263 290 232 261 246 271 289 290 273 265 276 239 238 263 238 260 277 268 284 257 288 268 280 239 275 250 278 243 260 270 241 241 272 274 289 266 270 262 256 296 264 262 270 297 296 269 275 271 277 272 280 247 284 300 246 232 221 285 268 270 271 290 301 233 304 255 285 238 276 269 292 265 230 291 280 274 218 269 279 259 225 255 225 268 304 270 246 260 238 265 274 287 276 248 295 257 297 288 257 249 262 265 258 299 288 235 280 229 276 246 281 291 261 243 239 257 239 291 257 291 263 277 278 257 259 244 283 244 285 276 270 277 275 264 260 249 298 274 231 299 267 267 262 272 284 244 271 269 281 268 280 275 241 276 234 259 275 249 294 257 278 275 248 286 272 268 286 288 283 226 249 244 275 267 287 266 231 285 282 280 280 275 269 319 267 281 294 239 255 249 247 241 258 265 237 297 228 271 259 276 246 291 274 266 287 243 264 269 234 283 276 243 273 262 257 256 250 262 265 278 249 259 255 299 246 241 268 245 272 225 292 272 238 282 281 269 287 257 244 271 227 238 236 263 276 264 247 237 248 276 283 249 230 265 286 268 258 275 298 284 281 249 221 276 263 258 262 269 265 237 293 285 275 261 256 256 246 262 242 272 247 289 239 246 280 273 257 268 269 284 278 234 268 242 286 260 246 283 246 289 242 260 231 261 248 275 273 268 290 273 284 279 243 247 241 274 271 281 248 262 233 274 241 241 246 257 273 315 308 280 294 217 278 266 283 266 266 225 249 268 257 265 288 278 273 249 242 248 265 297 268 262 268 274 282 267 263 268 286 281 269 262 269 212 240 267 260 276 263 284 287 224 262 272 305 268 236 274 271 272 273 258 264 226 243 267 255 270 286 296 259 259 264 245 288 266 268 239 267 265 232 242 237 276 248 230 280 248 259 279 237 257 235 244 248 261 270 292 287 280 270 257 247 247 306 240 246 277 249 298 245 237 263 265 246 228 268 268 240 278 263 280 271 257 285 273 268 247 268 264 280 258 257 261 275 272 259 265 269 265 239 275 285 247 275 268 279 272 249 256 266 276 263 259 249 278 264 249 227 274 309 291 233 264 282 257 238 269 243 277 293 276 263 257 257 259 272 287 280 265 289 291 243 261 262 282 269 243 271 299 291 261 280 260 278 260 278 303 294 256 255 232 257 280 280 271 265 288 279 283 283 291 256 266 256 242 243 273 285 285 261 245 267 268 266 259 266 247 263 281 263 280 258 269 273 277 266 265 274 272 268 255 285 284 293 264 263 318 263 269 294 244 259 255 273 262 272 260 283 293 262 286 242 273 275 260 263 267 272 248 274 264 299 264 266 246 275 272 247 276 257 271 284 290 268 256 249 309 270 267 273 269 255 277 274 250 303 283 275 279 256 290 246 280 222 310 240 311 288 264 265 296 279 243 281 288 274 263 276 277 262 283 245 265 272 290 250 298 274 267 249 272 291 248 264 261 260 278 277 273 262 282 277 274 287 273 260 286 266 269 266 283 279 240 265 276 292 268 260 279 268 274 296 260 299 234 280 296 288 238 314 259 262 283 261 266 302 256 282 234 286 286 266 266 267 246 258 279 280 261 302 270 287 258 259 264 261 289 265 282 270 246 259 266 282 280 260 270 281 246 306 260 297 279 284 276 256 276 277 260 272 257 269 279 263 270 248 288 281 300 288 317 299 268 282 259 263 255 235 294 267 248 272 299 264 295 282 292 283 248 296 287 266 271 299 266 249 273 265 246 287 244 238 258 280 259 267 271 279 255 295 281 240 286 277 265 289 286 240 267 276 259 271 273 273 250</counts>
			</dataPoints>
		</scan>
	</xrdMeasurement>
</xrdMeasurements>