File: data/XRD/XG-Luft/XG-700/W6821-1D_XG_Luft_700.xrdml
<xrdMeasurements xmlns="http://www.xrdml.com/XRDMeasurement/2.1" xmlns:xsi="http://www.w3.org/2001/XMLSchema-instance" xsi:schemaLocation="http://www.xrdml.com/XRDMeasurement/2.1 http://www.xrdml.com/XRDMeasurement/2.1/XRDMeasurement.xsd" status="Completed">
	<comment>
		<entry>Configuration=Factory configuration, Owner=User-1, Creation date=7/8/2013 4:01:53 PM</entry>
		<entry>Goniometer=PW3050/65 (Theta/2Theta); Minimum step size 2Theta:0.0001; Minimum step size Omega:0.0001</entry>
		<entry>Sample stage=MRD Cradle; Minimum step size Phi:0.01; Minimum step size Chi:0.01; Minimum step size X:0.01; Minimum step size Y:0.01; Minimum step size Z:0.001</entry>
		<entry>Diffractometer system=XPERT-PRO</entry>
		<entry>Measurement program=C:\PANalytical\Data Collector\Programs\Jorrit\2thom\_absolute_2th-om_10-130deg_PIXscan_56min.xrdmp, Identifier={15BCCF57-2807-42BD-B5B9-ECC0B3DC9284}</entry>
		<entry>Batch program=C:\PANalytical\Data Collector\Programs\SimonL\batch4x_2thom_10-130°_z9.1_x0,10,20,30_y0_57min.xrdmp, Identifier={EED9823A-2BEB-424C-9252-345C4EF2834A}</entry>
	</comment>
	<sample type="To be analyzed">
		<id></id>
		<name></name>
		<preparedBy></preparedBy>
	</sample>
	<xrdMeasurement measurementType="Scan" status="Completed" sampleMode="Reflection">
		<comment>
			<entry>_absolute_2th-om_10-130deg_PIXscan_56min</entry>
			<entry>PHD Lower Level = 4.83 (keV), PHD Upper Level = 11.27 (keV)</entry>
		</comment>
		<usedWavelength intended="K-Alpha 1">
			<kAlpha1 unit="Angstrom">1.5405980</kAlpha1>
			<kAlpha2 unit="Angstrom">1.5444260</kAlpha2>
			<kBeta unit="Angstrom">1.3922500</kBeta>
			<ratioKAlpha2KAlpha1>0.5000</ratioKAlpha2KAlpha1>
		</usedWavelength>
		<incidentBeamPath>
			<radius unit="mm">320.00</radius>
			<xRayTube id="1010048" name="Empyrean Cu LFF HR (9430 033 7310x) DK442154">
				<tension unit="kV">40.0</tension>
				<current unit="mA">40.0</current>
				<anodeMaterial>Cu</anodeMaterial>
				<focus type="Line">
					<length unit="mm">12.0</length>
					<width unit="mm">0.4</width>
					<takeOffAngle unit="deg">4.2</takeOffAngle>
				</focus>
			</xRayTube>
			<xRayMirror id="27010001" name="Inc. Beam Cu W/Si (parabolic MRD)" hybrid="false">
				<crystal type="Graded" shape="Parabolic">W/Si</crystal>
				<acceptanceAngle unit="deg">0.800</acceptanceAngle>
				<length unit="mm">60.0</length>
			</xRayMirror>
			<sollerSlit id="21010002" name="Soller slits 0.04 rad.">
				<opening unit="rad">0.0400</opening>
			</sollerSlit>
			<mask id="22030007" name="Fixed mask 2 mm">
				<distanceToSample unit="mm">220.00</distanceToSample>
				<width unit="mm">2.00</width>
			</mask>
			<divergenceSlit id="22010007" name="Fixed slit 1/8°" xsi:type="fixedDivergenceSlitType">
				<distanceToSample unit="mm">220.00</distanceToSample>
				<height unit="mm">0.19</height>
			</divergenceSlit>
		</incidentBeamPath>
		<diffractedBeamPath>
			<radius unit="mm">320.00</radius>
			<sollerSlit id="21010002" name="Soller slits 0.04 rad.">
				<opening unit="rad">0.0400</opening>
			</sollerSlit>
			<receivingSlit id="22010001" name="Fixed slit 4°">
				<height unit="mm">5.88</height>
			</receivingSlit>
			<detector id="7010017" name="PIXcel3D 1x1 detector" xsi:type="areaDetectorType">
				<phd unit="%">
					<lowerLevel>30.0</lowerLevel>
					<upperLevel>70.0</upperLevel>
				</phd>
				<mode>Scanning</mode>
				<activeChannelsEquatorial>255</activeChannelsEquatorial>
				<activeChannelsAxial>255</activeChannelsAxial>
				<pitchEquatorial unit="mm">0.05500</pitchEquatorial>
				<pitchAxial unit="mm">0.05500</pitchAxial>
				<readOutPeriod unit="seconds">0.135</readOutPeriod>
			</detector>
		</diffractedBeamPath>
		<scan appendNumber="0" mode="Continuous" scanAxis="2Theta-Omega" status="Completed">
			<header>
				<startTimeStamp>2024-10-25T10:04:34+02:00</startTimeStamp>
				<endTimeStamp>2024-10-25T11:00:40+02:00</endTimeStamp>
				<author>
					<name>PRO-MRD</name>
				</author>
				<source>
					<applicationSoftware version="6.1b">Data Collector</applicationSoftware>
					<instrumentControlSoftware version="7.0E 20130304">XPERT-PRO</instrumentControlSoftware>
					<instrumentID>0000000011142674</instrumentID>
				</source>
			</header>
			<dataPoints>
				<positions axis="2Theta" unit="deg">
					<startPosition>9.99826193</startPosition>
					<endPosition>129.99755682</endPosition>
				</positions>
				<positions axis="Omega" unit="deg">
					<startPosition>4.99913096</startPosition>
					<endPosition>64.99877841</endPosition>
				</positions>
				<positions axis="Phi" unit="deg">
					<commonPosition>0.00</commonPosition>
				</positions>
				<positions axis="Chi" unit="deg">
					<commonPosition>0.00</commonPosition>
				</positions>
				<positions axis="X" unit="mm">
					<commonPosition>0.00</commonPosition>
				</positions>
				<positions axis="Y" unit="mm">
					<commonPosition>0.00</commonPosition>
				</positions>
				<positions axis="Z" unit="mm">
					<commonPosition>9.100</commonPosition>
				</positions>
				<commonCountingTime unit="seconds">32.895</commonCountingTime>
				<counts 420 422 435 406 453 417 416 414 439 442 428 418 447 417 370 454 432 444 395 425 437 391 424 403 444 408 398 425 420 420 369 409 387 419 435 412 490 447 411 428 440 410 427 401 407 399 438 400 382 394 426 426 383 394 384 389 376 419 413 388 400 394 403 392 418 399 411 421 389 407 419 382 385 392 403 392 356 425 426 412 368 406 396 420 401 424 420 442 388 393 396 411 409 402 393 374 439 403 433 412 352 350 392 397 398 397 404 384 408 389 401 393 423 389 362 375 400 352 360 352 379 388 386 383 403 378 373 369 386 388 386 367 384 410 393 374 370 368 394 369 380 371 373 385 408 368 373 400 369 368 360 394 381 360 361 379 384 356 403 347 390 389 338 386 371 395 357 366 360 374 350 354 386 361 349 348 375 360 348 381 361 385 382 390 345 361 371 377 369 360 341 359 396 357 369 357 355 368 377 371 389 384 358 368 346 384 381 385 360 344 365 369 390 350 378 370 360 360 360 335 387 350 366 375 370 389 353 395 352 329 337 375 382 349 370 324 330 345 361 357 314 337 327 341 354 369 334 381 345 351 338 334 361 341 342 353 383 357 382 344 339 332 356 408 342 357 349 317 383 350 350 358 333 344 382 327 341 354 339 341 348 340 353 363 366 366 336 346 356 366 348 321 379 313 345 324 350 361 318 345 328 320 352 352 348 337 335 326 327 353 321 338 329 341 330 339 325 335 332 322 312 326 342 322 299 307 315 334 341 324 343 341 367 336 318 320 310 317 330 325 311 353 360 340 360 321 335 303 343 323 317 333 338 350 348 302 338 318 304 318 290 353 343 327 309 341 312 323 346 318 334 308 346 322 308 324 360 322 304 344 329 355 331 336 348 332 357 305 334 312 346 299 282 331 319 334 322 313 316 323 336 290 292 326 328 321 326 286 303 324 318 300 313 331 330 336 317 312 312 309 335 307 299 342 365 294 332 330 319 320 290 337 311 328 330 331 312 310 311 327 313 291 301 306 291 299 285 309 332 313 296 327 287 296 336 300 293 327 272 321 328 309 293 332 312 349 314 281 307 290 283 315 292 304 338 309 322 311 325 310 284 317 327 338 307 317 289 285 285 286 288 275 308 325 308 286 295 308 300 302 311 285 268 306 292 280 297 306 281 271 328 309 276 275 307 289 302 267 298 295 314 271 277 308 306 270 287 324 336 286 297 260 290 257 305 304 288 340 278 281 307 299 293 330 303 301 267 288 336 314 308 294 310 294 299 289 289 313 272 269 278 306 269 292 282 304 294 274 302 294 285 290 286 340 301 309 306 310 308 270 303 322 276 290 283 246 319 255 303 289 330 307 339 294 324 316 316 302 294 286 284 285 282 289 312 270 279 278 319 284 286 299 323 303 295 286 318 322 322 309 277 316 297 290 265 288 297 296 295 281 287 282 282 278 302 298 279 287 331 325 285 300 286 284 296 310 272 266 301 291 277 297 268 299 290 286 266 275 325 284 290 323 304 290 277 289 288 305 275 278 307 294 318 245 309 278 307 289 256 299 300 323 297 300 288 296 291 296 308 282 306 285 289 303 276 304 307 298 294 271 282 305 271 259 255 278 295 285 295 244 296 294 317 296 307 319 307 302 304 247 274 283 306 286 294 287 307 309 295 271 333 287 303 307 300 261 270 282 273 272 269 272 287 281 314 319 294 319 288 284 303 297 341 272 302 301 277 293 289 296 291 292 311 326 297 300 276 300 269 285 299 299 301 326 280 319 313 281 275 299 278 298 297 311 283 289 282 272 298 315 312 272 268 328 275 259 270 270 307 301 322 282 285 270 289 318 327 289 273 278 309 309 305 326 299 288 274 308 284 301 311 318 301 283 291 298 248 267 297 328 296 350 277 300 280 291 318 316 293 297 285 303 316 303 313 318 304 278 301 327 305 303 305 308 277 316 286 300 280 282 273 290 282 312 282 273 307 291 302 293 299 289 304 321 307 278 289 296 301 292 287 285 289 311 281 293 274 308 280 312 329 295 284 272 297 288 304 313 314 270 300 308 293 319 273 314 283 302 282 314 287 295 292 318 329 306 300 288 319 282 291 300 326 287 336 310 265 295 285 322 298 319 336 294 341 273 311 311 311 321 295 293 292 330 316 293 336 330 301 310 303 271 310 299 307 290 289 284 277 282 291 291 292 297 278 278 297 315 295 261 287 285 275 303 294 293 301 315 292 313 299 303 300 277 307 320 288 320 302 296 311 282 327 295 334 316 312 287 306 306 314 327 298 299 334 301 312 300 312 316 290 315 289 288 288 314 322 293 300 278 292 326 320 326 321 351 324 313 308 316 332 295 305 301 303 324 329 320 290 327 313 331 298 278 295 306 310 316 329 308 307 321 305 282 345 312 293 335 300 325 331 331 313 327 328 305 291 312 305 314 309 344 316 326 300 311 313 297 333 321 290 289 337 313 316 310 306 322 311 325 309 334 321 314 321 330 324 329 332 307 301 310 307 301 320 331 336 333 299 328 325 287 326 268 305 372 273 297 306 321 310 286 286 310 306 295 333 283 308 345 317 314 354 329 326 314 310 342 273 315 295 316 304 298 342 323 323 359 307 301 316 321 319 300 321 347 324 283 310 311 302 300 307 333 310 328 330 304 341 266 329 346 320 326 288 302 312 292 301 309 351 324 314 318 296 303 294 330 288 311 348 308 283 310 313 315 335 312 283 301 306 315 345 342 323 321 331 309 281 302 320 341 330 324 325 278 332 338 328 326 326 336 337 314 326 361 303 332 328 304 290 304 313 305 345 331 310 279 314 323 310 301 300 298 318 273 340 308 339 299 339 321 336 321 303 353 286 334 317 280 334 356 339 312 302 305 335 291 331 325 302 322 310 327 316 338 354 345 312 302 290 300 292 335 310 316 300 312 318 296 359 354 332 318 304 298 283 287 322 310 316 332 320 296 323 299 300 328 310 302 313 313 322 313 277 302 314 311 316 341 369 329 314 336 328 350 283 359 291 333 327 347 299 338 323 317 334 351 287 298 318 321 321 331 308 314 291 332 318 322 315 359 299 311 334 306 312 332 334 300 321 314 294 324 281 311 354 347 332 324 302 323 308 301 301 299 295 290 306 309 313 334 303 320 296 309 312 320 326 323 325 310 311 294 328 329 315 289 301 289 311 335 358 311 314 335 320 330 298 302 310 286 356 318 309 339 317 316 308 285 317 328 299 317 317 299 285 319 331 318 332 262 346 332 338 306 343 292 297 280 321 290 306 310 304 291 299 315 315 320 274 299 345 290 324 290 322 320 332 313 288 317 319 291 272 316 327 348 319 312 303 300 333 328 309 309 315 314 317 327 319 291 324 293 301 290 280 333 287 309 257 313 360 302 259 295 296 257 284 298 305 313 279 296 302 306 302 307 302 317 296 336 297 323 328 328 319 324 301 301 317 294 277 299 288 328 287 313 294 316 329 319 306 277 290 345 281 295 303 305 309 320 316 303 324 324 286 276 319 303 293 322 295 311 308 331 313 277 302 291 288 298 291 325 305 326 296 312 283 315 300 294 273 279 314 294 308 318 283 317 308 312 279 303 308 289 307 245 280 304 287 309 293 284 290 314 285 269 321 303 286 303 287 324 292 312 321 315 306 268 309 261 304 316 279 303 293 316 311 300 301 272 294 318 301 279 285 277 310 319 268 302 316 302 264 312 272 319 304 294 276 278 319 287 294 301 327 287 294 298 301 275 280 291 264 298 294 265 258 290 302 288 284 315 282 305 307 296 273 284 297 293 269 301 273 303 287 303 307 293 270 309 305 296 285 276 285 298 305 292 269 307 289 282 282 274 290 283 263 331 301 307 271 277 278 313 304 336 299 288 268 275 303 272 299 284 309 285 292 278 255 280 303 273 297 292 278 284 280 294 259 288 296 315 281 289 288 271 293 290 290 262 274 294 292 266 279 278 297 263 303 277 258 290 274 298 299 324 290 287 300 284 273 307 289 264 291 327 288 284 301 282 306 271 286 294 269 298 268 277 265 276 281 285 290 280 291 274 293 264 275 273 288 286 285 273 276 302 311 281 274 297 267 279 273 276 272 297 251 300 276 293 264 301 266 283 282 265 281 319 267 286 284 269 286 290 294 312 302 314 297 290 284 279 303 299 295 294 292 279 282 292 293 283 299 280 248 235 257 308 288 300 301 286 289 284 298 287 266 277 289 280 299 303 304 305 294 293 278 270 293 284 274 318 264 276 306 297 269 280 298 243 321 294 268 279 283 287 310 290 276 263 268 266 271 276 272 275 285 308 274 267 294 281 255 275 257 277 291 275 263 282 289 280 289 269 239 267 267 284 291 269 277 281 300 268 301 282 270 267 294 334 272 289 285 281 276 274 304 276 280 262 314 284 301 290 262 239 311 238 266 275 290 275 292 280 297 242 296 265 270 284 249 292 272 272 244 278 269 255 268 281 269 287 296 266 295 282 283 297 285 284 274 292 245 286 271 267 294 267 308 291 298 263 270 282 282 280 256 283 282 303 277 268 267 255 278 285 264 269 269 277 248 272 273 270 278 272 284 263 275 275 267 262 280 287 259 276 244 265 259 283 289 280 282 261 270 284 267 256 261 231 269 280 273 271 269 277 247 272 269 244 271 279 262 277 284 276 293 295 244 278 290 287 296 263 288 296 262 258 283 242 260 302 288 276 280 271 273 270 274 264 270 257 246 219 247 292 312 266 240 289 278 266 239 259 261 279 279 296 268 241 270 249 271 272 266 258 285 285 277 283 281 271 267 244 290 277 264 262 233 246 267 260 313 268 284 259 297 262 266 292 286 262 296 245 261 271 228 257 264 271 288 231 267 259 299 266 244 286 286 272 271 266 273 265 292 248 255 243 267 285 271 260 274 302 257 271 263 238 258 271 245 290 264 301 300 288 263 267 281 245 248 278 276 293 247 286 304 229 263 256 287 294 271 263 283 287 249 261 265 289 256 267 245 268 269 274 273 271 289 264 263 237 266 267 257 274 265 279 260 240 256 274 277 273 299 292 272 245 262 246 271 256 263 244 299 275 286 290 241 282 249 281 269 249 270 283 232 290 275 249 248 262 240 255 288 270 269 236 229 263 244 244 239 267 256 267 275 270 247 271 268 274 279 276 249 258 279 237 249 246 230 266 234 276 241 267 257 221 279 274 246 248 263 248 276 284 269 271 258 264 240 272 260 266 247 237 246 269 229 273 259 266 297 288 290 225 273 267 264 266 282 261 258 298 255 248 236 239 242 247 270 246 270 237 264 275 261 245 298 262 297 267 259 263 259 287 292 271 277 248 261 255 264 296 263 277 284 243 269 299 255 238 236 260 268 256 279 266 288 272 266 257 260 246 280 263 257 269 256 268 291 270 264 256 244 256 271 272 291 258 266 249 245 264 262 296 267 265 223 257 231 258 256 285 286 228 270 276 259 248 273 270 265 261 258 227 249 294 263 249 258 226 256 246 265 248 271 284 255 284 287 228 271 280 264 258 244 260 290 275 239 257 242 265 255 237 275 266 255 267 281 270 274 243 271 236 244 240 245 256 266 279 244 289 270 238 227 267 274 227 290 257 270 237 276 278 245 262 242 289 270 274 241 245 258 262 258 272 248 241 261 248 284 236 243 276 260 232 283 243 232 258 244 267 257 247 277 248 274 240 257 239 268 245 268 240 238 260 264 263 272 278 248 250 273 267 272 272 242 287 255 262 267 276 288 219 283 291 296 263 278 256 260 260 272 281 247 268 265 258 246 271 282 232 289 257 265 245 215 283 245 276 275 264 291 259 270 244 272 281 272 246 282 255 261 268 279 272 248 276 255 255 246 294 277 255 263 256 266 257 245 248 271 276 260 265 238 277 231 276 268 256 238 249 242 287 276 241 230 246 294 231 262 247 246 261 284 266 262 273 286 278 277 280 266 237 245 248 261 280 261 273 246 237 256 269 275 263 233 283 285 278 248 271 276 238 269 265 269 245 250 270 244 266 259 283 248 245 264 264 259 280 264 266 273 281 209 244 268 292 240 263 255 292 246 242 232 258 289 240 266 263 286 263 264 258 271 257 263 273 248 245 249 259 263 223 264 259 228 264 275 246 243 278 269 244 234 292 260 274 260 271 285 277 276 221 271 256 288 259 264 262 255 268 256 260 260 243 236 267 285 263 277 278 287 266 250 235 257 274 243 267 295 248 261 239 273 263 272 248 263 288 261 285 232 257 218 241 228 234 257 267 214 225 233 271 240 282 269 269 276 230 302 305 281 278 265 304 263 230 279 289 290 260 256 258 242 239 309 238 244 244 259 268 256 244 265 246 266 241 277 216 261 276 263 266 291 262 239 236 258 256 261 255 281 276 248 277 287 228 277 211 266 272 256 255 256 255 237 261 259 271 270 274 239 273 273 238 257 288 240 261 287 247 255 248 269 249 268 255 264 265 255 280 269 225 259 265 247 239 264 258 275 256 263 249 265 233 262 268 290 248 244 291 297 244 228 282 280 264 265 232 247 272 229 263 255 243 268 259 221 268 247 270 285 275 273 301 270 271 248 278 270 257 268 260 236 243 258 243 258 277 278 277 270 262 247 228 275 249 259 303 272 270 246 235 256 272 280 264 282 261 281 232 266 258 257 248 247 266 280 246 244 241 224 247 287 248 268 261 226 234 264 265 270 260 261 261 273 303 282 226 266 260 282 310 264 265 295 287 271 241 237 247 261 249 278 268 272 237 255 241 282 231 284 263 263 240 238 266 265 273 288 289 241 286 220 258 258 257 283 232 243 256 268 261 257 269 276 283 292 282 242 261 246 248 276 280 266 290 255 261 280 260 249 255 270 230 276 316 258 257 285 277 273 277 231 275 229 275 271 269 270 265 259 264 265 287 235 282 259 275 271 262 244 262 264 276 276 270 261 256 257 281 248 246 285 233 246 299 249 271 278 288 305 282 221 220 273 275 285 309 238 268 269 264 268 296 237 267 292 234 256 282 270 290 244 280 297 287 304 249 285 256 243 230 266 277 275 272 263 282 273 262 272 283 246 302 266 243 276 258 269 269 245 271 279 279 235 288 257 268 270 260 267 277 278 264 240 241 280 265 273 290 279 243 244 244 260 298 278 243 284 269 271 269 257 282 280 280 283 263 273 289 274 261 279 229 282 263 269 263 269 262 256 279 259 288 257 266 274 298 259 234 245 297 256 299 301 260 250 273 286 249 262 242 277 258 257 244 240 302 278 257 287 276 280 257 267 287 234 262 267 264 233 269 232 277 278 301 284 270 247 290 224 287 241 266 290 262 266 267 261 272 268 265 236 271 289 242 316 288 273 266 291 278 289 267 236 245 279 258 240 276 288 256 274 264 292 270 277 269 247 284 272 272 270 234 282 287 278 261 267 288 264 288 280 271 306 278 242 282 272 277 268 309 258 250 232 274 277 267 284 311 266 286 249 271 290 319 268 276 273 294 290 269 268 274 268 287 274 292 289 260 258 275 284 288 241 282 279 309 244 276 292 287 272 268 286 301 265 278 277 280 313 283 277 273 285 304 247 274 304 301 262 261 280 264 294 280 291 281 309 263 250 275 270 259 246 275 278 285 293 299 287 291 287 266 270 292 283 300 292 261 287 256 234 272 277 288 277 286 305 288 277 275 320 244 274 277 297 307 287 277 303 305 281 280 277 298 267 273 275 310 304 263 293 291 284 311 307 291 324 291 280 301 321 295 308 297 301 294 313 289 294 295 311 292 323 300 291 302 304 294 300 312 325 326 324 313 317 330 348 333 326 285 324 312 315 362 376 308 313 362 350 364 376 369 397 351 367 401 362 411 404 421 423 460 421 427 422 444 458 488 478 511 507 507 507 521 544 547 517 524 531 548 524 541 529 552 522 491 528 494 450 452 463 459 415 402 393 404 435 396 380 390 392 382 385 376 370 366 347 339 340 322 318 324 309 332 287 307 336 335 329 291 297 337 300 328 305 303 275 295 295 280 289 319 296 284 288 270 307 294 314 291 315 292 304 271 284 296 290 292 279 324 281 320 285 268 292 261 298 290 293 278 263 288 305 288 288 304 298 275 303 269 276 294 259 266 263 268 295 279 270 243 208 309 274 294 278 284 294 274 325 280 274 263 314 286 291 246 263 275 306 269 280 288 305 284 276 261 279 333 299 263 261 304 265 306 278 268 271 273 269 295 275 286 290 284 266 278 273 267 248 264 271 290 292 300 276 281 268 280 301 290 283 277 272 288 297 281 263 272 258 259 315 288 274 273 296 270 272 273 248 270 290 244 288 301 280 236 283 284 278 269 326 295 299 301 287 289 292 292 286 256 255 247 312 261 278 306 267 318 278 263 243 290 285 276 250 302 291 229 246 261 280 274 320 278 264 259 287 275 272 292 291 283 276 282 256 244 287 308 255 273 276 269 278 268 276 235 269 239 289 284 292 258 287 274 284 278 262 258 273 283 297 281 307 281 296 275 290 307 290 261 274 255 279 321 272 280 269 245 259 271 259 272 312 299 266 277 280 266 256 284 275 280 265 246 269 281 248 278 283 321 273 281 282 261 269 276 280 301 274 278 294 264 283 277 271 299 233 294 272 297 264 273 274 291 264 260 278 285 262 269 279 272 299 259 277 260 298 269 277 292 303 265 283 299 285 319 274 290 258 240 263 299 248 266 260 264 270 247 300 288 231 270 278 306 235 283 274 303 297 277 288 268 266 262 287 262 257 265 263 285 268 271 270 295 270 275 293 273 269 304 277 284 325 244 286 281 256 258 289 272 263 290 259 297 244 294 267 299 272 255 261 263 293 279 259 280 277 297 299 264 280 271 270 255 304 268 261 298 279 249 258 281 263 279 301 292 297 257 294 292 303 225 294 291 275 280 301 277 266 297 273 290 250 301 281 274 271 298 291 316 278 261 273 283 288 285 248 272 259 311 267 293 268 270 329 273 295 284 299 288 256 303 293 295 246 280 256 291 317 278 271 291 287 256 256 266 282 278 259 310 271 267 287 298 297 300 244 284 270 278 286 294 298 287 285 289 275 278 315 284 268 261 286 247 273 267 280 259 296 306 246 273 286 296 260 273 286 280 261 290 284 260 284 282 268 282 257 286 273 275 288 288 274 312 285 273 284 272 294 280 276 283 255 262 291 256 295 258 264 296 280 288 266 308 268 310 277 284 296 283 274 307 313 237 239 257 268 306 266 303 273 284 287 292 273 256 278 274 226 288 285 272 271 280 260 276 260 246 257 266 275 260 276 288 281 278 281 288 273 267 284 325 291 269 289 286 244 294 280 277 302 261 292 235 283 229 280 292 255 262 296 307 272 277 267 277 237 235 280 295 299 279 256 274 273 308 290 345 280 316 258 263 280 241 310 262 280 275 291 264 286 283 277 281 270 314 285 282 287 277 275 283 294 280 307 285 309 271 259 296 297 296 282 261 282 281 267 267 288 246 279 297 246 296 304 285 289 295 291 269 240 303 276 270 256 257 259 281 275 267 259 281 282 269 272 264 299 301 303 291 279 247 294 266 298 304 273 261 290 257 281 292 285 282 288 282 277 266 257 244 239 287 270 301 266 260 276 266 277 289 284 330 282 280 281 290 289 247 245 244 284 278 283 264 264 281 263 258 283 292 299 271 299 272 258 286 279 309 288 286 285 268 287 241 264 321 270 241 305 279 267 287 322 296 275 288 274 258 299 247 260 262 278 275 277 281 286 291 288 267 295 247 302 262 281 248 281 278 273 273 240 287 304 287 274 294 248 262 262 280 291 298 268 274 282 284 296 292 309 248 248 297 263 283 276 278 264 275 272 246 273 291 295 235 297 257 276 282 296 291 275 272 295 286 281 295 281 295 276 271 224 312 295 262 271 279 242 285 304 281 326 278 263 267 285 270 278 234 268 264 301 280 276 265 241 271 291 290 287 269 314 287 282 259 262 273 290 267 275 290 287 291 288 273 266 261 255 261 290 262 277 282 285 237 303 275 265 276 272 273 292 264 268 307 304 263 278 282 289 276 294 291 243 247 248 281 265 282 278 262 242 272 263 283 281 293 259 264 279 283 294 272 293 258 267 261 288 272 260 320 261 269 277 299 266 281 314 275 275 285 274 250 262 290 275 269 274 270 277 283 226 264 275 260 301 286 291 276 288 277 272 247 309 294 308 233 285 257 287 272 281 266 277 274 264 231 293 306 273 273 276 264 269 260 285 257 292 258 290 312 289 295 284 278 285 279 284 287 261 269 280 266 281 271 255 290 257 282 298 264 272 272 278 268 259 249 295 277 270 246 299 281 268 258 260 300 276 278 284 255 294 301 262 279 263 267 299 267 276 262 283 267 256 270 258 306 261 261 280 271 275 284 267 280 308 272 269 258 260 294 298 288 266 279 248 291 281 271 265 267 314 258 268 281 301 257 293 269 248 280 283 267 280 294 317 272 293 258 268 296 279 247 283 274 284 273 303 276 279 305 299 336 298 274 283 281 262 277 244 283 262 259 250 263 271 287 246 277 246 283 295 266 256 262 278 255 274 273 274 291 294 272 282 305 270 286 293 299 255 296 258 292 263 260 273 325 279 284 282 274 281 265 268 277 290 287 281 276 258 298 283 280 270 294 260 292 268 277 272 269 277 279 306 267 261 255 296 267 287 275 249 270 260 259 250 266 297 301 288 299 295 270 260 274 290 282 266 306 264 298 286 274 309 266 275 307 245 277 271 250 321 295 283 289 279 259 289 309 268 314 271 269 275 234 255 243 295 283 260 290 295 293 282 309 277 288 272 276 291 291 264 256 274 280 274 287 290 273 285 301 260 283 273 295 295 273 282 277 282 260 308 259 261 279 271 244 291 260 266 282 293 283 267 280 266 262 281 304 275 275 294 267 257 288 324 296 249 235 281 259 246 285 279 293 259 246 272 282 277 281 264 270 284 298 292 269 257 294 249 303 279 261 270 298 276 288 287 279 294 266 275 284 264 298 273 270 274 276 261 292 300 257 284 267 268 282 279 286 294 276 281 245 264 298 276 284 288 308 268 261 275 268 296 296 270 274 282 269 263 285 281 239 240 271 273 277 261 280 300 283 255 269 265 269 272 280 267 307 273 276 278 283 274 267 267 260 279 271 304 286 296 291 266 265 263 270 268 282 273 282 301 294 273 277 273 273 290 271 265 271 271 295 298 292 276 304 294 303 280 265 278 273 288 290 262 298 290 287 257 273 277 249 299 260 258 248 285 259 261 298 240 277 288 286 291 261 291 277 274 288 301 257 295 262 265 269 303 288 270 287 262 238 273 262 273 306 283 289 301 235 240 313 306 283 280 273 265 248 291 307 276 266 261 277 290 256 282 259 279 309 300 271 326 243 276 290 265 280 275 286 267 267 282 301 261 307 280 227 267 263 288 281 300 307 273 323 269 266 288 290 281 271 262 275 258 296 266 279 287 293 285 283 298 298 239 261 278 250 272 272 261 292 268 285 305 276 296 292 279 276 271 282 280 268 288 247 289 273 259 292 285 278 273 272 261 289 274 287 236 287 296 274 274 280 293 284 277 302 278 268 307 310 266 244 266 275 280 257 285 281 277 272 268 272 279 246 246 279 289 260 269 290 290 315 236 288 258 278 274 270 298 247 282 281 295 242 250 294 272 270 304 275 279 286 263 268 275 256 284 298 309 274 291 310 307 329 283 280 288 285 279 286 260 238 304 273 277 280 264 266 260 273 282 321 297 339 258 313 277 277 287 290 268 296 286 282 296 261 280 284 311 301 292 291 289 272 278 264 261 278 320 324 288 260 277 314 289 272 279 280 271 265 310 305 278 268 300 269 261 282 301 281 231 284 275 305 274 298 259 281 291 255 246 270 271 273 267 250 268 274 283 270 278 294 297 296 277 266 271 259 292 283 288 295 292 287 270 303 291 278 275 274 278 296 284 284 311 281 277 270 279 271 262 292 282 277 276 300 279 280 303 289 325 287 295 271 272 274 270 289 289 311 276 293 268 300 268 300 300 264 239 295 315 304 264 311 294 287 284 267 293 284 267 265 249 286 274 277 289 276 271 308 311 273 307 294 285 297 267 320 263 298 272 290 271 248 290 275 282 292 287 288 298 270 289 274 268 275 272 295 274 278 283 283 272 272 298 277 296 271 274 268 259 242 306 292 265 269 271 283 262 312 268 293 309 304 294 307 284 291 279 298 286 278 308 262 287 302 269 282 288 308 277 301 285 265 268 296 297 281 286 274 315 278 264 284 278 255 255 295 298 273 282 246 275 296 280 284 278 290 293 246 272 249 303 275 281 296 287 313 286 292 273 261 333 274 294 282 289 329 271 278 277 293 265 266 275 269 259 299 283 302 275 256 307 308 291 315 302 279 270 298 289 301 244 272 270 261 300 273 286 300 278 321 307 273 275 285 306 272 275 267 274 281 265 303 300 265 278 313 279 291 293 291 273 297 298 286 284 307 279 290 269 302 282 332 298 264 304 285 320 317 306 295 297 313 299 321 301 306 273 290 327 319 290 305 300 297 322 328 286 277 288 293 327 308 298 295 303 300 303 278 344 306 294 326 306 319 292 314 303 280 256 289 303 301 308 265 309 296 286 326 311 263 276 286 300 269 295 313 289 305 300 289 321 286 317 284 284 291 276 279 313 284 271 287 328 268 322 305 316 288 275 300 279 279 287 286 288 246 297 271 276 302 263 288 287 270 248 262 277 274 291 306 256 296 283 283 294 281 289 295 299 291 256 286 287 284 294 299 269 288 298 259 273 329 263 272 309 275 280 304 286 283 225 281 249 289 280 273 279 267 308 297 259 298 257 290 278 283 270 263 290 268 313 284 289 290 281 278 279 301 290 304 292 295 248 298 291 285 286 286 281 292 275 281 280 295 280 268 272 317 274 267 291 265 283 265 306 281 264 286 299 281 255 301 293 246 259 280 260 316 265 292 267 282 258 291 285 264 314 277 290 262 299 286 292 281 289 299 255 263 304 288 304 283 314 257 297 291 263 274 278 290 250 293 264 294 322 309 267 275 298 280 280 296 310 279 283 274 278 297 284 297 293 299 243 297 313 302 263 292 274 274 290 288 242 279 294 289 305 270 250 290 245 283 291 283 264 284 278 267 263 284 286 302 269 298 309 256 269 279 271 271 280 307 294 259 268 294 271 279 271 307 297 268 303 279 257 242 280 235 237 270 275 245 273 332 242 307 287 232 316 295 272 277 296 283 263 282 291 291 285 287 293 282 311 283 280 262 293 276 277 292 294 292 274 267 275 301 293 294 268 272 289 249 265 304 287 290 263 286 283 302 296 302 290 289 259 288 302 299 280 290 327 289 292 286 265 271 262 264 285 286 274 277 287 266 246 277 274 275 288 308 240 260 272 279 289 298 305 264 266 277 310 292 289 285 257 261 279 288 269 302 274 288 278 258 289 309 244 262 279 288 281 255 295 286 257 262 288 261 270 288 285 265 294 284 263 300 293 261 295 311 279 274 294 291 281 257 275 271 279 288 244 273 261 255 271 270 264 297 278 300 285 273 289 297 334 292 278 257 299 308 325 274 271 268 282 286 285 285 283 284 292 266 271 271 280 299 313 286 268 261 267 286 313 267 282 281 275 274 263 310 280 281 278 332 297 262 248 267 307 288 300 237 279 311 298 282 289 282 284 286 290 279 283 291 304 290 283 286 249 275 284 275 261 298 283 315 269 264 295 274 287 264 287 269 290 305 286 274 301 276 300 275 284 285 281 316 308 287 244 324 285 276 303 299 282 323 275 274 288 299 298 293 292 278 247 277 308 265 245 259 249 300 286 276 281 304 299 263 269 268 269 269 315 290 306 276 270 281 286 276 265 291 287 290 294 269 264 235 288 300 284 286 292 284 269 284 288 264 294 323 288 286 286 298 304 288 322 285 247 276 261 316 288 277 264 285 289 291 293 270 311 291 270 294 303 310 290 276 307 269 306 271 263 284 279 320 267 296 287 281 260 278 289 295 293 278 271 282 303 282 245 277 284 311 270 299 280 293 285 275 279 268 291 296 257 298 309 294 276 261 247 288 294 281 280 308 280 291 274 301 271 296 263 287 310 281 276 314 293 248 281 296 279 311 284 271 281 283 298 268 292 286 240 299 242 280 294 269 294 287 263 281 279 262 286 312 284 281 258 285 261 320 293 294 261 278 266 289 303 281 294 287 304 267 333 302 274 259 267 277 306 288 262 301 289 285 283 288 269 296 261 266 299 274 300 303 295 300 313 277 282 290 301 304 300 273 262 244 287 240 289 243 307 290 316 309 293 291 280 272 293 308 312 287 304 285 274 262 277 272 311 306 282 256 295 260 308 266 310 282 295 308 305 259 250 279 318 264 247 285 310 285 300 271 277 283 317 328 261 301 299 283 247 272 270 280 259 279 280 283 291 289 279 299 274 280 285 288 306 274 247 299 249 279 287 296 270 295 304 306 298 235 296 295 291 280 296 275 321 264 287 262 296 267 277 266 290 284 290 271 260 291 276 282 306 270 278 289 304 285 244 248 293 297 268 262 280 274 297 268 316 279 297 284 292 261 299 263 277 275 295 275 294 266 296 274 294 269 276 285 266 277 270 277 284 298 292 274 270 292 286 304 307 266 287 336 268 303 305 303 273 265 296 267 265 277 276 301 291 288 326 285 304 288 300 285 276 268 274 299 308 279 298 295 294 288 271 312 293 281 279 303 267 278 260 312 271 301 289 277 310 308 319 263 274 265 306 287 288 312 298 272 275 289 305 311 318 307 294 295 281 276 301 259 311 266 305 278 305 278 284 275 312 309 300 281 247 266 299 255 261 264 294 286 309 280 301 312 314 302 288 298 301 312 339 306 297 281 262 306 284 282 284 304 289 300 282 269 319 261 304 277 281 264 284 276 272 276 284 312 266 271 281 274 271 302 278 295 272 308 295 300 334 279 294 272 295 304 290 298 298 307 290 267 299 299 281 273 295 273 315 279 250 283 257 290 281 283 271 279 292 288 283 296 272 293 294 275 313 273 301 287 281 310 273 321 277 245 299 297 311 286 278 313 271 295 282 276 310 304 276 318 274 285 271 323 326 315 317 309 305 279 309 336 291 282 285 313 276 293 311 274 288 270 274 295 308 274 280 324 268 277 293 282 299 301 281 299 314 318 314 284 326 287 296 295 312 288 293 287 320 304 322 287 283 288 268 316 271 264 305 306 298 298 287 297 291 280 268 284 293 296 311 285 311 295 259 304 271 285 301 285 275 276 295 274 295 271 283 275 325 279 275 292 290 309 296 285 268 303 308 274 309 284 308 328 278 267 289 279 287 294 295 311 291 276 290 258 311 311 307 328 306 273 279 285 286 290 284 275 311 273 273 296 302 284 285 244 319 295 295 291 280 259 280 270 321 318 265 290 312 306 300 294 274 278 305 288 297 247 289 278 315 283 284 292 288 293 274 281 293 273 267 274 315 248 279 283 291 256 294 270 279 293 278 274 287 274 275 267 274 265 274 287 284 300 294 258 289 271 311 298 301 273 288 283 296 285 315 273 277 273 281 282 296 283 282 284 298 281 269 267 303 280 269 315 289 314 271 291 325 321 274 294 276 279 290 292 319 279 300 238 318 283 275 290 303 262 287 284 287 267 286 303 289 303 298 274 277 282 249 289 250 326 283 284 304 312 274 264 270 295 281 277 293 303 284 279 278 295 276 291 306 272 282 318 299 270 276 317 290 282 294 304 272 291 299 310 279 310 283 294 298 307 291 279 288 302 298 290 270 289 300 319 279 227 294 300 293 268 302 250 294 301 297 277 279 267 324 276 273 283 293 285 288 317 296 311 282 263 282 281 276 266 278 293 293 268 272 315 315 284 278 301 293 271 312 310 296 299 293 287 288 304 299 286 283 289 279 288 314 290 245 295 307 265 275 313 297 270 287 319 302 277 260 299 279 284 287 291 305 276 322 283 289 236 303 298 274 322 276 286 249 269 326 279 294 306 281 291 272 296 285 302 311 262 280 281 298 282 282 298 288 272 315 271 283 280 287 289 293 275 246 269 283 267 271 290 309 272 306 283 268 293 279 277 246 300 278 288 263 277 271 262 300 267 301 276 301 303 297 292 298 284 300 290 262 312 302 286 274 244 292 307 288 316 301 274 295 295 287 285 269 256 264 280 299 311 273 288 312 280 296 292 291 274 276 314 299 271 282 279 289 312 320 286 265 286 304 298 282 270 292 277 281 289 312 267 267 292 280 322 255 288 303 280 276 264 285 284 298 275 303 297 285 277 300 308 299 282 312 308 281 302 264 286 293 274 282 288 263 290 286 309 297 288 299 269 305 317 298 291 312 292 324 270 292 295 306 295 306 269 297 311 336 283 276 327 290 306 299 277 283 317 284 316 319 301 258 334 359 291 303 337 310 317 319 292 319 318 326 299 280 327 309 309 295 286 301 296 298 315 339 326 332 309 323 313 278 351 329 329 318 293 346 330 339 331 336 307 348 314 347 323 359 339 323 328 359 358 307 325 327 317 330 339 355 335 337 366 343 312 310 309 337 336 336 359 339 336 350 314 333 341 297 333 295 331 318 323 308 313 318 330 304 321 317 307 309 318 307 302 306 315 308 314 312 276 305 284 323 288 296 259 283 320 304 310 297 290 291 288 317 304 293 288 297 291 298 305 268 279 324 317 283 291 299 326 280 277 274 281 305 303 313 275 324 289 303 292 259 274 269 277 300 276 308 293 263 242 286 305 302 273 303 281 296 277 305 274 267 305 272 272 305 299 280 309 317 283 281 288 318 272 307 282 318 270 300 297 278 318 286 303 255 302 300 295 275 279 277 283 291 311 279 261 290 298 300 279 275 298 291 284 270 303 300 292 278 296 297 288 291 292 316 291 321 262 302 286 310 317 276 281 323 277 236 277 294 293 325 305 278 294 288 280 275 296 308 281 264 291 307 288 280 292 266 246 285 287 292 284 295 282 286 295 305 282 276 269 303 273 297 305 290 297 265 270 265 301 286 307 272 281 290 272 264 268 283 295 288 257 292 284 249 269 299 267 256 332 298 273 290 281 307 270 289 292 276 296 290 309 293 273 270 297 301 262 277 295 302 300 296 282 286 278 292 316 268 280 270 318 248 288 291 299 293 280 301 278 278 289 283 294 294 307 283 279 283 291 280 274 287 256 284 272 288 287 273 274 296 297 304 284 289 282 284 293 270 273 302 300 296 278 283 302 298 279 297 308 269 295 288 284 262 290 279 272 267 290 269 282 275 300 304 299 279 267 271 298 289 282 295 291 271 300 274 308 288 282 262 290 284 311 305 293 304 285 283 271 318 243 278 301 295 285 293 284 257 274 296 298 276 265 287 313 293 297 270 237 295 301 283 279 294 247 272 279 267 296 309 279 285 288 270 272 286 280 284 275 297 256 272 286 278 296 292 270 272 294 286 285 277 306 283 292 287 270 259 273 290 270 289 259 281 294 273 270 302 290 313 269 277 274 290 281 272 284 270 276 282 274 285 301 316 287 285 298 309 309 289 275 313 304 276 299 266 267 275 324 278 243 301 286 263 285 301 265 285 293 271 285 255 295 285 309 271 284 288 307 306 283 305 283 248 288 284 285 287 288 293 282 259 295 277 294 279 274 287 297 284 285 300 297 308 271 289 278 278 271 273 292 304 292 271 273 257 292 295 322 269 272 290 273 293 272 307 283 276 278 340 261 274 259 317 287 288 292 271 257 243 267 243 265 279 298 293 282 299 258 286 264 271 278 267 304 274 300 288 294 272 289 291 309 300 275 279 287 271 299 288 275 260 270 265 282 279 299 273 307 286 283 256 299 283 241 281 288 278 301 286 283 313 263 299 271 274 255 277 266 280 287 285 296 269 304 268 293 297 272 286 284 287 262 285 269 310 278 295 241 285 268 291 262 318 294 283 268 274 306 280 263 293 295 249 296 278 297 272 291 257 269 287 284 259 287 266 279 271 301 258 296 291 255 281 301 277 297 296 278 286 287 291 295 301 270 299 267 286 273 279 282 249 294 277 257 310 256 302 233 271 273 293 278 294 265 277 290 275 263 268 292 263 267 265 242 287 272 291 302 238 250 298 249 250 281 283 271 272 304 294 269 281 273 276 275 297 269 291 275 263 302 304 299 270 259 234 266 280 273 278 256 247 279 249 268 290 285 280 276 276 285 274 292 295 258 308 270 261 262 290 261 274 291 273 295 293 268 259 308 292 255 259 292 271 286 293 291 306 294 267 256 277 291 288 294 274 243 283 279 306 246 282 299 269 285 302 298 288 279 299 296 284 280 300 277 292 283 318 275 273 282 281 272 283 267 244 315 290 279 295 297 267 295 311 269 265 276 275 288 249 281 284 287 277 247 288 302 271 270 280 242 272 257 283 286 248 271 300 276 289 301 298 278 255 285 273 277 273 273 266 283 301 260 240 281 296 285 274 228 270 281 274 274 288 291 300 286 303 282 258 273 296 312 288 279 288 284 292 289 283 264 277 271 292 288 276 309 300 267 272 259 294 313 278 280 282 290 309 270 259 245 256 272 301 269 272 292 271 297 290 288 278 269 295 269 300 322 300 291 266 288 280 260 281 301 290 266 284 283 278 273 270 334 296 282 264 232 266 286 285 294 258 267 298 286 259 269 282 292 270 287 275 257 249 311 298 303 278 248 273 289 278 306 280 281 297 271 269 283 288 283 299 302 260 247 282 249 272 277 292 291 262 267 281 279 327 289 301 278 271 280 263 283 288 272 306 293 292 286 280 268 261 267 246 271 261 294 259 276 308 270 263 260 261 270 277 298 299 265 284 319 307 259 274 289 285 295 269 285 265 305 283 274 305 263 278 269 296 272 269 259 283 270 256 257 260 320 291 270 266 290 287 282 268 284 272 278 272 278 266 279 287 272 277 262 281 282 272 279 242 279 274 249 271 269 292 267 273 283 267 261 275 275 273 292 289 312 272 287 303 263 278 301 290 236 288 278 274 297 273 300 268 284 268 280 259 286 288 266 278 288 292 271 297 294 298 270 273 271 236 282 301 261 289 271 280 272 271 255 231 291 265 262 279 293 298 264 286 262 262 290 270 294 249 262 279 269 265 308 262 298 283 269 289 275 247 271 284 277 285 263 308 243 261 313 285 295 281 268 306 273 256 274 275 267 246 277 275 300 238 287 263 295 287 271 287 272 273 271 244 259 288 273 295 234 255 262 259 259 296 296 262 288 278 268 282 270 283 283 300 292 284 270 286 275 285 287 292 273 256 245 256 290 244 284 259 265 288 274 287 305 267 299 286 259 282 275 291 245 282 287 275 262 279 244 257 316 278 294 275 282 290 264 270 247 273 260 277 299 269 295 278 272 276 267 245 288 221 263 244 276 273 247 260 279 246 316 303 277 286 272 282 284 294 287 258 281 319 259 324 266 270 309 231 319 296 233 293 288 286 282 266 305 273 278 280 284 312 277 260 280 302 265 267 266 278 309 248 267 284 284 298 300 284 255 281 279 285 267 298 292 275 274 307 247 290 271 291 273 293 263 275 268 284 273 275 265 275 271 264 283 290 303 287 257 303 278 267 284 271 306 276 266 294 269 268 262 299 309 289 304 282 258 271 269 272 279 290 274 290 265 282 289 280 297 283 302 280 280 266 275 278 264 256 300 282 265 260 286 281 233 272 291 312 299 272 288 259 282 277 282 300 298 272 240 270 269 293 283 313 297 294 256 233 265 272 280 306 282 258 295 264 304 312 268 295 278 249 305 288 270 303 305 302 283 275 291 320 284 269 278 283 287 287 271 271 277 256 265 278 281 273 256 279 328 281 280 270 311 283 265 302 295 262 260 275 302 275 298 283 245 295 271 290 260 282 266 276 283 292 265 299 260 292 269 295 299 249 293 247 268 296 246 294 289 295 283 281 280 310 266 282 293 293 293 286 273 272 291 246 264 273 279 275 279 281 301 263 302 249 275 260 285 266 342 268 238 285 285 291 291 265 315 277 314 284 290 307 258 293 267 318 263 287 279 276 271 288 289 310 305 287 276 277 247 278 278 292 272 307 293 303 288 270 273 276 247 279 281 292 279 320 270 262 277 301 297 268 273 275 295 286 278 301 270 269 293 298 280 291 264 275 277 242 271 315 272 258 302 278 286 259 296 298 284 293 282 285 288 285 249 294 272 284 297 293 266 301 303 279 275 255 259 282 268 286 299 287 307 261 304 307 245 303 296 300 269 288 276 299 267 279 282 279 276 288 292 288 285 294 287 306 319 296 286 302 288 285 290 289 293 289 283 284 287 274 314 305 291 294 304 302 309 328 298 324 309 281 287 320 314 261 303 298 303 300 311 293 281 298 305 331 291 291 315 308 285 269 312 283 306 296 289 246 307 306 260 285 279 274 307 286 309 270 285 303 309 313 276 282 285 277 287 301 287 280 288 310 297 296 297 292 246 283 260 289 280 270 241 258 283 317 279 270 317 296 284 263 288 300 241 279 268 303 301 296 295 280 274 289 290 295 282 292 276 272 292 294 294 276 261 286 282 284 292 279 270 283 280 288 259 286 291 280 278 299 282 317 282 294 286 293 261 258 307 272 323 281 274 283 297 272 275 259 256 285 266 310 295 278 242 302 277 290 278 280 275 299 286 284 294 275 304 281 278 275 265 299 264 307 285 275 298 265 276 260 278 281 302 267 295 297 270 299 270 307 289 306 283 267 238 286 280 285 244 284 273 307 280 310 291 284 291 286 277 309 286 299 274 294 261 276 271 282 264 274 282 302 295 282 304 268 276 315 263 291 284 258 265 261 283 265 280 264 306 263 256 257 249 285 271 305 293 274 262 270 286 321 276 238 312 285 294 260 260 265 257 268 297 264 285 293 283 295 288 297 301 271 250 290 284 287 278 300 286 267 289 280 256 274 270 283 290 287 294 271 291 281 284 282 283 273 276 280 282 275 277 274 264 255 315 276 274 258 256 291 259 280 293 280 285 277 317 270 284 279 298 276 264 298 280 296 258 266 284 265 266 263 272 297 280 302 271 270 270 307 328 314 288 290 288 277 256 287 270 293 290 273 285 283 283 278 276 297 264 287 289 294 278 292 280 275 293 294 267 285 273 276 294 284 286 304 258 290 282 285 289 286 316 242 283 305 313 293 258 297 270 281 303 261 280 290 283 305 276 272 305 290 292 310 292 292 263 272 291 277 295 281 284 312 279 291 274 284 273 291 265 290 283 305 271 246 289 296 275 295 267 309 246 272 286 285 298 271 293 274 270 262 280 274 271 242 280 308 269 261 281 314 270 285 275 257 278 271 295 332 318 294 280 285 241 264 273 291 327 279 264 288 318 279 248 299 258 268 291 300 237 296 309 269 266 289 264 295 293 263 278 279 284 266 295 283 266 287 298 268 270 309 243 291 312 262 287 241 274 325 261 277 279 279 279 307 281 259 295 264 267 258 285 249 299 295 265 287 279 304 276 287 275 283 270 303 282 290 266 274 265 285 279 249 282 267 264 294 288 277 268 268 273 279 268 268 284 302 266 313 301 300 272 299 309 297 302 271 291 262 269 305 271 283 266 275 298 305 283 272 280 275 258 272 281 285 265 278 279 281 275 296 271 282 276 264 285 282 280 280 287 266 281 293 268 268 298 270 297 283 257 271 270 282 298 279 270 278 277 277 290 283 295 294 277 283 313 299 291 239 318 285 265 260 278 273 294 290 304 260 275 294 255 275 267 289 259 302 301 301 263 286 292 304 270 288 263 304 259 299 239 277 282 258 265 281 296 328 279 292 268 276 284 284 290 270 297 293 258 288 273 270 275 262 282 306 305 289 281 282 279 291 257 276 296 322 283 300 294 275 258 278 285 288 290 239 280 303 303 281 285 283 302 296 271 294 274 305 286 275 270 269 281 265 310 308 286 312 249 249 269 301 290 301 259 245 285 291 265 257 248 310 289 276 279 287 256 292 285 279 310 281 287 270 287 261 280 285 293 288 319 277 275 323 286 248 255 261 290 278 295 280 297 277 244 281 305 266 259 279 266 319 262 272 244 261 290 298 296 274 278 301 272 284 299 297 271 268 332 257 286 283 280 292 292 264 302 299 270 281 280 265 285 284 256 268 277 268 300 310 293 265 275 291 258 284 293 292 294 300 274 313 272 276 292 264 296 283 301 302 265 262 274 268 247 275 296 266 300 305 276 244 256 294 247 288 287 269 292 278 278 338 267 290 282 264 244 304 264 300 285 277 281 276 271 283 297 270 300 293 295 294 249 278 277 271 310 282 257 296 301 291 303 255 291 281 294 299 279 278 275 317 279 291 304 269 300 272 286 269 243 282 289 296 292 296 308 246 326 290 308 311 260 284 305 316 304 298 306 284 296 274 294 286 266 297 258 292 272 267 280 275 303 297 307 276 288 312 295 285 294 255 313 272 275 299 311 261 319 295 306 289 259 265 271 290 284 299 289 288 272 275 297 261 299 273 295 277 275 270 280 268 283 291 305 267 320 270 285 272 292 273 265 295 286 257 297 306 270 267 294 278 276 291 302 301 261 273 269 280 286 302 288 295 276 263 282 305 310 310 325 288 287 265 275 280 260 278 242 278 271 283 269 314 299 273 279 284 271 299 279 287 269 272 249 285 298 327 255 284 271 289 256 282 292 286 281 334 293 259 285 284 281 277 313 299 275 275 305 275 270 313 272 280 246 290 290 263 287 323 299 308 311 300 291 275 277 272 274 277 302 302 301 315 281 268 273 276 285 301 288 307 284 283 318 291 298 284 265 285 282 305 293 256 278 294 284 260 308 298 288 316 291 273 287 280 302 281 279 286 276 271 259 291 309 303 281 280 314 280 275 302 296 303 299 286 288 295 296 276 284 270 284 260 290 288 286 284 287 302 255 291 294 280 301 299 298 275 291 300 278 246 241 287 270 288 290 297 295 310 313 275 276 277 265 271 284 296 281 295 290 298 282 239 270 282 277 284 263 281 302 299 272 281 313 291 290 283 289 265 306 273 299 281 299 299 304 311 288 304 278 282 269 275 293 257 308 290 267 280 288 281 293 304 306 241 287 258 257 279 285 307 285 310 284 291 298 285 296 276 290 308 283 305 320 270 278 283 318 287 286 286 273 339 287 289 285 268 299 303 298 265 286 316 272 307 294 285 240 318 287 319 300 283 296 291 302 301 273 278 283 291 281 311 292 272 310 296 310 243 286 311 290 321 291 287 306 299 288 293 310 314 280 280 282 281 299 289 268 289 294 271 281 260 293 289 275 301 284 266 282 283 293 270 295 257 270 282 274 303 276 284 258 268 274 298 318 260 240 258 284 277 281 283 269 277 320 280 321 280 304 267 285 315 286 295 304 275 271 310 293 313 275 285 250 271 266 268 281 264 241 262 288 303 292 248 294 325 285 300 318 271 276 283 277 300 285 291 271 269 266 293 237 303 290 248 308 289 303 294 301 273 291 271 309 303 299 296 287 266 284 295 288 285 306 282 320 303 268 298 262 282 302 273 308 264 288 272 309 287 274 282 287 270 294 310 276 284 303 268 293 270 307 284 283 268 305 256 280 288 295 295 266 306 294 271 245 305 283 266 274 282 298 303 292 287 269 290 289 297 298 273 293 300 285 313 285 275 306 293 287 291 294 288 311 264 292 285 299 266 316 282 288 283 273 289 269 304 285 321 304 280 268 296 303 244 258 289 279 269 278 311 293 287 265 276 259 270 271 315 312 262 307 279 290 296 292 316 281 281 332 300 269 296 332 271 291 272 307 268 259 281 285 273 271 277 248 286 285 277 326 280 287 300 294 298 272 291 271 294 272 279 285 303 277 261 304 307 293 283 314 290 283 274 297 271 280 278 292 292 283 278 280 288 286 280 285 319 308 303 285 294 282 338 281 288 298 294 285 272 314 282 312 306 283 287 266 317 322 299 295 289 280 313 295 309 270 279 306 277 271 284 269 278 280 304 299 295 303 300 292 282 291 305 293 283 310 277 288 334 267 316 302 271 314 273 292 266 303 301 312 287 278 299 297 278 297 298 282 312 302 296 312 298 297 328 308 283 330 261 274 324 288 320 311 284 248 287 294 268 295 318 305 245 297 300 274 294 306 312 286 286 290 297 294 311 288 284 303 292 274 284 305 281 301 287 290 287 305 302 289 304 312 321 269 302 305 260 279 292 276 319 266 288 309 268 290 286 302 286 318 316 315 263 263 302 292 270 300 303 263 298 272 276 321 306 304 336 300 303 343 285 312 286 305 295 279 305 319 299 280 309 300 299 291 328 311 296 305 310 292 339 291 300 314 276 317 304 316 295 291 317 335 319 324 296 291 303 323 281 288 295 320 310 288 307 311 267 306 316 282 297 300 277 305 300 293 318 283 293 276 338 315 300 266 309 290 297 310 332 305 306 302 275 338 305 302 290 285 344 349 311 302 325 314 270 324 307 310 329 285 335 271 299 309 274 297 299 294 245 334 321 314 292 289 283 280 294 285 332 323 306 293 286 318 272 312 298 299 282 313 278 317 300 272 292 291 284 290 287 308 274 280 340 268 311 295 290 267 308 283 300 277 287 297 266 311 290 241 287 311 277 289 301 305 268 269 293 296 300 312 265 324 296 295 265 314 325 323 291 271 288 292 275 294 294 309 310 303 301 291 282 274 249 289 298 302 291 313 296 284 324 273 317 314 295 269 275 242 293 300 275 301 308 310 316 271 269 305 278 314 308 281 291 274 283 290 292 260 297 256 299 258 290 294 267 272 300 300 303 276 270 295 307 247 293 290 305 285 276 277 286 287 312 264 297 264 233 284 284 282 300 284 274 274 280 310 309 286 273 296 271 311 304 268 310 268 261 271 302 277 276 297 285 288 316 302 274 257 293 296 303 294 296 309 285 282 288 282 285 282 290 310 286 308 292 297 282 321 285 305 297 271 294 283 290 297 282 297 304 287 299 278 310 306 275 291 296 283 291 289 286 287 299 287 274 287 289 260 293 293 310 314 317 275 295 299 325 273 291 312 288 272 246 307 310 300 302 296 293 278 282 295 270 293 310 284 294 268 260 274 305 285 284 301 270 276 309 295 279 287 324 244 311 263 285 312 302 307 312 260 279 245 300 289 269 284 271 302 299 291 264 290 280 276 285 318 280 285 317 272 315 283 266 297 285 284 289 281 269 280 277 297 284 299 301 308 301 284 304 263 294 308 285 312 300 266 279 284 289 318 301 317 298 291 271 298 259 314 305 306 273 304 277 288 281 281 307 309 301 316 293 300 317 289 284 323 267 295 285 287 296 301 304 298 309 309 294 314 295 289 294 269 293 326 295 278 278 272 308 301 303 301 301 301 281 296 321 278 286 283 293 288 299 277 308 261 276 313 298 316 286 299 318 305 294 281 301 291 321 288 296 299 280 313 291 286 306 286 317 280 303 289 294 272 287 287 291 294 287 270 270 313 295 287 307 318 295 321 286 278 299 288 297 286 264 283 299 336 260 316 338 290 273 325 297 290 318 277 318 268 287 300 301 323 298 311 289 306 307 291 282 277 291 318 297 308 305 291 304 268 267 287 294 289 249 289 286 291 312 285 271 272 279 289 275 292 332 307 299 273 295 348 298 316 291 326 284 297 281 279 267 308 295 279 292 300 276 292 247 279 287 277 303 288 296 289 272 281 301 238 272 288 278 290 330 303 293 292 261 319 268 302 287 311 298 285 262 317 304 307 309 259 294 291 296 323 302 286 304 273 281 316 312 285 271 279 283 299 260 287 323 275 296 284 287 290 272 306 272 282 285 295 310 292 280 268 314 267 287 306 308 277 286 285 282 312 272 297 303 287 289 298 309 272 263 246 287 282 281 286 285 288 300 335 302 308 269 317 310 278 281 292 316 298 293 300 291 309 318 331 266 269 296 293 282 313 294 267 304 312 270 289 301 293 325 292 291 289 300 292 299 304 288 274 313 295 285 297 292 276 312 308 294 278 281 286 280 314 312 314 317 263 291 279 280 301 268 277 311 290 290 311 314 247 282 310 302 298 308 314 272 297 261 282 312 282 285 306 311 279 279 310 280 283 297 305 288 292 256 293 321 311 276 282 294 296 318 267 279 299 265 283 285 285 287 282 311 287 285 294 306 301 303 298 275 307 305 312 290 292 304 289 295 278 292 281 265 311 267 273 257 306 285 284 295 259 257 282 289 284 281 322 261 299 270 313 294 302 298 304 326 296 289 284 298 294 316 298 296 298 308 287 280 285 290 274 283 283 280 313 265 299 299 313 318 313 268 281 281 233 276 297 312 313 322 273 293 292 291 287 319 293 301 289 295 306 274 294 304 302 269 273 301 290 300 311 292 292 303 329 313 289 278 267 306 310 289 273 290 293 312 286 281 276 302 292 270 272 261 280 318 309 298 296 299 305 282 281 294 325 315 281 291 311 275 280 281 277 269 275 282 295 285 298 290 313 291 290 308 279 303 307 318 259 233 315 281 288 300 315 288 310 311 269 308 313 310 339 272 316 291 309 307 287 315 317 274 271 311 293 323 302 296 295 280 281 273 275 289 295 293 272 310 282 308 323 289 297 321 311 331 326 293 259 299 323 313 291 288 286 291 282 283 269 303 247 293 305 276 290 311 301 257 310 293 295 288 282 293 319 294 317 280 293 315 283 293 282 312 296 321 285 281 309 290 277 303 293 279 311 292 307 292 318 289 287 282 283 294 291 289 268 313 295 292 320 268 329 322 269 297 302 262 316 289 316 308 282 312 280 280 293 301 275 264 297 263 308 268 274 319 279 312 294 297 317 310 295 304 292 302 309 288 279 319 285 298 273 287 290 307 305 300 333 295 307 298 309 287 281 318 293 284 322 317 302 279 306 319 302 311 301 312 281 278 292 305 308 288 265 291 255 301 311 273 282 307 313 303 314 279 277 297 312 300 332 317 289 314 322 276 310 292 273 287 281 299 268 286 280 321 283 275 302 309 274 311 294 286 276 289 287 311 298 290 326 325 310 308 265 296 301 295 322 298 315 286 275 293 294 293 310 296 325 294 296 309 293 304 280 304 320 291 261 300 298 332 273 300 281 298 312 294 295 289 294 291 286 286 292 283 346 283 288 340 295 293 286 299 290 290 309 309 285 317 286 268 294 303 338 279 296 286 290 294 338 307 250 338 277 315 289 284 297 272 261 286 309 300 293 272 310 287 299 311 312 314 310 294 275 311 260 300 299 278 275 332 282 260 328 300 289 285 287 273 306 293 281 283 298 288 289 270 299 271 281 290 296 306 264 293 294 282 281 285 299 296 303 317 312 298 312 293 271 293 277 280 311 281 320 305 307 280 291 315 296 298 286 312 259 319 307 317 293 269 294 286 305 289 283 280 294 316 283 300 304 278 296 293 288 281 313 269 290 304 296 304 290 239 332 288 278 296 308 321 248 280 312 300 295 280 301 285 287 290 272 266 295 297 303 289 287 318 305 289 324 303 284 300 297 288 300 284 274 308 311 317 273 353 307 269 268 313 289 319 329</counts>
			</dataPoints>
		</scan>
	</xrdMeasurement>
</xrdMeasurements>