File: data/XRD/XG-Sauerstoff/XG-700/W6823-1B_XG_Sauerstoff_700.xrdml
<xrdMeasurements xmlns="http://www.xrdml.com/XRDMeasurement/2.1" xmlns:xsi="http://www.w3.org/2001/XMLSchema-instance" xsi:schemaLocation="http://www.xrdml.com/XRDMeasurement/2.1 http://www.xrdml.com/XRDMeasurement/2.1/XRDMeasurement.xsd" status="Completed">
	<comment>
		<entry>Configuration=Factory configuration, Owner=User-1, Creation date=7/8/2013 4:01:53 PM</entry>
		<entry>Goniometer=PW3050/65 (Theta/2Theta); Minimum step size 2Theta:0.0001; Minimum step size Omega:0.0001</entry>
		<entry>Sample stage=MRD Cradle; Minimum step size Phi:0.01; Minimum step size Chi:0.01; Minimum step size X:0.01; Minimum step size Y:0.01; Minimum step size Z:0.001</entry>
		<entry>Diffractometer system=XPERT-PRO</entry>
		<entry>Measurement program=C:\PANalytical\Data Collector\Programs\Jorrit\2thom\_absolute_2th-om_10-130deg_PIXscan_56min.xrdmp, Identifier={15BCCF57-2807-42BD-B5B9-ECC0B3DC9284}</entry>
		<entry>Batch program=C:\PANalytical\Data Collector\Programs\SimonL\batch4x_2thom_10-130°_z9.1_x0,10,20,30_y0_57min.xrdmp, Identifier={EED9823A-2BEB-424C-9252-345C4EF2834A}</entry>
	</comment>
	<sample type="To be analyzed">
		<id></id>
		<name></name>
		<preparedBy></preparedBy>
	</sample>
	<xrdMeasurement measurementType="Scan" status="Completed" sampleMode="Reflection">
		<comment>
			<entry>_absolute_2th-om_10-130deg_PIXscan_56min</entry>
			<entry>PHD Lower Level = 4.83 (keV), PHD Upper Level = 11.27 (keV)</entry>
		</comment>
		<usedWavelength intended="K-Alpha 1">
			<kAlpha1 unit="Angstrom">1.5405980</kAlpha1>
			<kAlpha2 unit="Angstrom">1.5444260</kAlpha2>
			<kBeta unit="Angstrom">1.3922500</kBeta>
			<ratioKAlpha2KAlpha1>0.5000</ratioKAlpha2KAlpha1>
		</usedWavelength>
		<incidentBeamPath>
			<radius unit="mm">320.00</radius>
			<xRayTube id="1010048" name="Empyrean Cu LFF HR (9430 033 7310x) DK442154">
				<tension unit="kV">40.0</tension>
				<current unit="mA">40.0</current>
				<anodeMaterial>Cu</anodeMaterial>
				<focus type="Line">
					<length unit="mm">12.0</length>
					<width unit="mm">0.4</width>
					<takeOffAngle unit="deg">4.2</takeOffAngle>
				</focus>
			</xRayTube>
			<xRayMirror id="27010001" name="Inc. Beam Cu W/Si (parabolic MRD)" hybrid="false">
				<crystal type="Graded" shape="Parabolic">W/Si</crystal>
				<acceptanceAngle unit="deg">0.800</acceptanceAngle>
				<length unit="mm">60.0</length>
			</xRayMirror>
			<sollerSlit id="21010002" name="Soller slits 0.04 rad.">
				<opening unit="rad">0.0400</opening>
			</sollerSlit>
			<mask id="22030007" name="Fixed mask 2 mm">
				<distanceToSample unit="mm">220.00</distanceToSample>
				<width unit="mm">2.00</width>
			</mask>
			<divergenceSlit id="22010007" name="Fixed slit 1/8°" xsi:type="fixedDivergenceSlitType">
				<distanceToSample unit="mm">220.00</distanceToSample>
				<height unit="mm">0.19</height>
			</divergenceSlit>
		</incidentBeamPath>
		<diffractedBeamPath>
			<radius unit="mm">320.00</radius>
			<sollerSlit id="21010002" name="Soller slits 0.04 rad.">
				<opening unit="rad">0.0400</opening>
			</sollerSlit>
			<receivingSlit id="22010001" name="Fixed slit 4°">
				<height unit="mm">5.88</height>
			</receivingSlit>
			<detector id="7010017" name="PIXcel3D 1x1 detector" xsi:type="areaDetectorType">
				<phd unit="%">
					<lowerLevel>30.0</lowerLevel>
					<upperLevel>70.0</upperLevel>
				</phd>
				<mode>Scanning</mode>
				<activeChannelsEquatorial>255</activeChannelsEquatorial>
				<activeChannelsAxial>255</activeChannelsAxial>
				<pitchEquatorial unit="mm">0.05500</pitchEquatorial>
				<pitchAxial unit="mm">0.05500</pitchAxial>
				<readOutPeriod unit="seconds">0.135</readOutPeriod>
			</detector>
		</diffractedBeamPath>
		<scan appendNumber="0" mode="Continuous" scanAxis="2Theta-Omega" status="Completed">
			<header>
				<startTimeStamp>2024-09-12T17:00:59+02:00</startTimeStamp>
				<endTimeStamp>2024-09-12T17:57:05+02:00</endTimeStamp>
				<author>
					<name>PRO-MRD</name>
				</author>
				<source>
					<applicationSoftware version="6.1b">Data Collector</applicationSoftware>
					<instrumentControlSoftware version="7.0E 20130304">XPERT-PRO</instrumentControlSoftware>
					<instrumentID>0000000011142674</instrumentID>
				</source>
			</header>
			<dataPoints>
				<positions axis="2Theta" unit="deg">
					<startPosition>9.99826193</startPosition>
					<endPosition>129.99755682</endPosition>
				</positions>
				<positions axis="Omega" unit="deg">
					<startPosition>4.99913096</startPosition>
					<endPosition>64.99877841</endPosition>
				</positions>
				<positions axis="Phi" unit="deg">
					<commonPosition>0.00</commonPosition>
				</positions>
				<positions axis="Chi" unit="deg">
					<commonPosition>0.00</commonPosition>
				</positions>
				<positions axis="X" unit="mm">
					<commonPosition>20.00</commonPosition>
				</positions>
				<positions axis="Y" unit="mm">
					<commonPosition>0.00</commonPosition>
				</positions>
				<positions axis="Z" unit="mm">
					<commonPosition>9.100</commonPosition>
				</positions>
				<commonCountingTime unit="seconds">32.895</commonCountingTime>
				<counts 221 214 211 210 209 231 216 226 194 206 210 233 205 169 231 202 196 206 232 202 170 214 209 223 209 200 229 201 213 208 204 196 216 186 208 204 193 194 205 201 191 215 220 201 225 216 212 220 199 259 208 202 213 215 212 190 191 200 209 200 200 207 176 237 218 199 233 205 213 226 236 237 203 198 231 202 210 206 197 170 216 222 197 193 189 200 187 195 194 192 204 208 177 200 220 206 199 186 188 208 184 195 203 238 210 186 175 198 221 184 163 170 196 203 174 217 197 179 238 209 210 188 208 185 201 199 219 209 201 216 190 187 196 226 212 213 195 196 189 185 178 171 177 215 202 199 197 210 193 181 195 177 199 183 213 186 202 189 220 218 181 198 201 212 201 206 196 202 183 181 182 220 185 209 207 217 216 178 198 186 191 176 176 221 188 184 210 183 189 206 160 181 206 212 165 192 193 187 195 176 210 214 199 180 205 183 192 181 164 217 156 197 193 173 166 217 197 203 169 209 192 198 187 181 203 207 205 190 169 179 167 203 170 209 188 187 171 175 195 182 196 178 174 192 164 181 188 213 191 183 187 173 209 184 173 206 180 206 162 163 184 197 181 174 189 181 191 235 187 207 179 171 174 166 187 192 182 166 165 187 168 200 176 187 170 188 165 167 153 183 176 177 188 188 146 186 175 177 182 175 180 192 162 169 220 185 183 199 181 172 178 180 173 176 193 209 163 169 181 159 178 197 171 188 168 163 177 191 181 191 177 186 176 172 166 175 196 163 200 173 192 155 190 158 172 174 166 185 176 207 169 209 162 193 184 162 188 180 181 176 182 165 178 179 184 160 194 175 192 181 171 140 197 181 154 182 179 175 157 196 156 202 179 159 163 147 165 181 181 183 195 161 169 204 170 164 188 155 157 160 164 187 171 201 156 179 166 201 172 150 173 169 151 175 184 182 177 166 149 181 166 191 175 155 160 173 176 169 177 176 181 144 179 168 185 174 173 149 198 153 178 167 170 162 182 177 163 170 174 168 173 159 155 138 160 174 179 169 164 174 180 168 176 189 167 152 189 165 156 181 179 179 159 166 189 158 183 150 166 146 152 161 173 145 182 152 173 168 171 177 166 148 168 171 158 161 168 163 181 158 177 179 172 162 167 168 166 171 172 183 165 181 156 195 150 152 171 142 157 168 168 151 154 173 177 165 156 172 159 148 163 172 171 169 170 165 157 144 183 169 144 183 167 142 172 155 166 150 164 167 163 141 161 151 140 162 168 172 166 186 175 179 164 174 173 138 157 196 154 163 155 145 176 151 166 165 168 170 158 171 159 160 173 148 152 165 141 144 167 149 158 165 186 150 151 173 186 165 121 165 179 170 160 162 164 157 142 150 161 168 162 158 147 157 167 157 160 140 168 166 189 149 156 146 156 155 185 149 154 145 169 145 161 143 152 169 144 158 144 159 146 173 165 155 157 153 151 137 151 160 172 144 167 153 156 142 145 151 141 145 159 160 164 154 167 139 145 155 160 160 173 157 176 145 169 167 127 151 158 142 132 147 160 163 167 163 157 173 174 162 157 166 158 173 164 159 165 138 167 165 151 158 163 140 161 142 159 171 145 179 164 151 172 171 144 129 165 162 163 158 162 162 156 175 156 149 166 162 146 148 154 166 148 146 169 142 171 170 158 168 163 134 160 157 189 157 153 150 154 161 175 165 171 148 176 156 152 155 145 170 154 163 163 181 153 154 168 159 156 157 164 157 150 159 156 185 141 152 148 151 166 157 144 135 163 139 180 168 167 143 183 159 153 154 158 142 159 164 149 171 157 150 162 154 143 159 154 175 168 162 164 153 161 153 151 173 153 178 174 151 136 181 154 150 178 146 177 156 161 165 167 149 160 144 165 164 159 157 163 153 136 155 156 145 179 141 152 152 168 169 163 171 149 150 142 169 168 167 153 164 153 160 172 185 173 191 149 154 155 181 139 163 149 152 168 156 179 159 160 174 159 151 163 162 158 160 179 162 153 179 179 156 157 163 165 193 162 155 165 150 183 161 172 180 156 151 163 174 164 170 156 155 160 174 160 195 149 147 174 169 184 163 156 172 148 154 165 157 178 151 149 155 153 192 159 171 191 170 179 186 168 175 154 161 160 162 151 156 159 159 175 156 164 151 167 154 141 148 165 161 149 167 188 169 162 158 172 172 160 171 174 168 161 179 187 144 151 168 157 171 174 156 146 155 145 167 175 172 171 156 177 175 161 169 174 174 178 165 175 183 170 175 142 169 162 154 174 175 160 173 173 157 157 182 165 163 174 162 156 160 175 180 201 169 163 167 176 157 165 135 162 174 142 159 175 164 192 178 169 157 163 179 182 169 155 173 173 168 161 154 166 162 162 158 153 164 183 161 197 164 184 170 176 167 151 153 168 160 147 157 163 180 169 175 175 159 159 160 173 174 158 152 164 176 173 171 183 176 147 159 166 174 159 143 181 178 157 153 180 169 146 177 161 189 153 176 163 164 155 142 169 185 174 159 143 156 168 189 191 154 155 177 168 168 158 202 177 172 135 179 158 191 176 174 174 173 174 155 205 179 149 156 181 159 181 178 163 169 176 156 164 160 177 169 147 164 163 179 168 175 171 169 203 169 169 172 175 162 160 154 161 184 177 172 129 183 167 179 154 144 164 156 163 167 208 157 177 152 184 164 156 176 198 168 179 174 151 173 173 138 189 173 168 167 170 171 163 156 171 181 165 166 154 159 179 193 155 159 162 174 157 166 167 169 160 195 157 172 157 148 172 190 186 163 167 163 181 175 157 183 181 175 152 173 170 160 175 177 187 155 175 188 176 186 156 173 164 170 183 151 166 176 169 158 170 175 173 168 190 140 166 200 175 167 168 150 185 195 158 170 177 180 159 170 171 179 166 146 169 162 174 177 175 164 158 170 156 147 170 190 140 163 186 173 173 171 196 172 161 165 169 168 161 152 162 164 171 154 173 168 170 177 158 197 154 170 181 173 170 147 179 185 166 179 157 162 184 182 177 168 169 164 174 166 126 166 178 173 163 166 187 167 150 167 157 169 155 155 168 157 188 160 187 157 161 142 176 161 163 164 159 197 164 148 161 169 143 148 149 157 155 153 168 182 192 175 158 162 176 172 144 166 182 173 177 171 158 182 165 158 163 176 143 155 176 160 146 156 152 179 147 147 159 177 165 157 167 164 190 157 164 150 149 169 178 192 141 164 157 161 156 169 170 181 192 150 180 165 170 159 162 150 148 161 175 137 148 150 163 171 171 173 151 151 163 181 151 165 149 149 154 155 160 176 187 159 175 171 161 193 174 149 173 150 157 154 169 157 147 150 141 157 156 184 182 150 164 170 132 166 148 168 163 162 147 176 164 159 119 183 150 163 174 147 157 150 163 161 158 172 151 174 149 168 164 166 165 177 168 161 163 150 158 146 135 167 153 158 150 180 159 137 149 150 137 157 162 164 151 158 150 143 157 155 140 157 159 141 155 160 179 145 151 135 169 141 158 161 178 147 166 164 158 137 151 142 152 152 167 141 160 130 154 153 140 161 158 137 151 136 158 153 159 144 144 171 145 148 146 137 145 143 148 180 135 157 140 146 128 152 148 148 145 130 152 152 134 144 175 145 153 113 140 143 151 150 141 135 148 151 147 138 157 151 132 144 141 130 154 153 137 146 134 147 155 145 149 148 130 127 126 150 154 152 124 130 141 145 139 127 134 162 160 143 137 142 171 161 143 156 128 148 148 137 160 150 133 158 154 133 146 122 162 159 168 124 169 153 128 137 149 142 134 160 144 140 124 126 148 152 142 143 137 146 176 161 129 129 150 134 141 174 134 133 144 125 120 154 147 138 121 111 148 160 130 139 161 134 130 131 146 129 125 139 126 144 143 144 145 138 127 124 112 141 124 141 135 131 148 127 138 145 141 131 132 137 143 150 135 148 136 119 127 160 138 161 153 151 132 124 140 154 143 128 128 158 130 129 142 118 124 130 134 133 150 122 147 139 155 132 141 132 130 142 138 140 142 130 128 138 144 135 113 143 134 129 129 150 117 144 125 149 143 131 152 138 134 130 136 131 115 134 141 152 128 134 126 127 141 131 134 138 121 132 108 124 141 138 123 120 135 130 128 115 118 118 140 131 113 145 125 143 137 141 136 139 118 108 151 140 128 138 131 153 122 128 132 135 125 129 133 118 112 128 142 120 146 132 124 136 132 133 118 104 144 120 132 132 129 134 108 122 120 130 129 122 137 125 134 147 153 114 106 122 124 142 124 127 133 137 129 154 120 127 126 139 112 138 119 140 125 124 108 116 125 122 116 106 122 123 122 124 118 126 139 144 116 130 123 106 114 131 140 130 114 124 131 115 94 122 124 120 141 127 139 112 145 120 126 122 126 127 131 116 110 122 116 121 133 125 116 115 105 126 128 114 121 117 144 115 129 117 111 124 124 113 126 119 138 117 111 119 134 125 132 120 107 114 145 112 99 115 141 123 118 141 111 119 126 100 131 137 114 134 143 116 113 133 118 132 135 131 130 111 143 140 129 133 128 106 129 107 138 116 107 122 120 134 125 104 143 142 114 101 121 106 114 126 112 119 127 120 138 113 124 135 137 107 115 116 118 108 98 136 105 121 125 140 129 125 123 124 117 116 116 112 121 114 104 120 118 126 103 121 114 121 138 137 107 144 118 93 117 114 122 124 126 114 124 125 109 123 126 125 111 107 114 115 110 126 109 113 121 112 108 126 100 101 114 128 142 118 89 146 132 115 117 122 106 120 105 119 107 117 129 125 105 117 143 129 101 113 125 106 114 110 131 134 94 121 123 109 116 134 98 112 124 148 115 117 100 141 112 106 124 109 119 125 129 129 135 113 115 136 126 119 134 114 114 118 114 103 122 109 118 112 93 113 117 112 110 121 115 121 109 89 106 135 108 90 112 104 127 119 120 115 127 119 103 113 110 114 127 125 126 104 97 119 111 111 111 111 100 114 109 121 110 107 128 134 120 124 113 119 127 128 121 113 105 101 111 139 116 121 129 112 104 103 113 121 121 126 121 97 118 99 121 113 120 95 98 109 125 118 119 116 127 124 133 122 117 121 136 110 108 109 117 112 100 122 102 105 109 101 145 110 129 106 99 115 92 99 106 95 112 94 109 123 117 119 109 123 105 112 107 116 111 128 102 116 106 97 95 118 114 113 114 94 123 112 112 116 105 93 107 108 108 126 114 112 103 107 123 119 103 126 125 107 121 126 108 100 118 102 95 102 98 107 104 117 102 98 109 129 108 103 103 105 103 97 107 116 112 111 114 127 117 111 110 103 117 110 111 108 143 110 102 113 111 97 117 115 112 100 109 113 120 122 84 106 107 98 90 111 107 113 123 98 109 108 101 147 83 94 114 116 121 117 111 111 126 103 103 117 121 109 99 113 122 113 107 99 104 114 116 103 132 85 113 112 106 117 125 111 93 99 100 102 108 96 99 115 121 108 117 105 98 97 107 93 100 101 96 107 112 113 103 89 111 106 107 112 111 103 95 104 110 89 117 96 111 87 103 101 106 91 123 103 105 91 97 102 98 112 115 123 105 112 108 108 83 96 103 106 115 115 114 93 95 94 98 105 86 99 107 116 124 104 126 110 126 86 118 105 110 107 102 97 108 116 106 112 86 116 109 94 113 117 107 107 133 84 111 102 106 101 105 115 122 91 104 109 84 102 95 105 76 111 93 132 116 121 113 117 103 89 101 88 102 119 104 102 101 117 98 127 93 93 90 113 104 94 97 94 116 94 81 99 113 87 119 119 106 110 88 98 108 100 106 126 113 110 110 130 107 121 100 98 127 97 106 109 115 109 116 112 107 88 95 108 97 100 118 95 105 97 117 113 102 108 111 114 115 107 119 97 98 108 84 113 106 101 103 120 99 105 96 109 114 93 119 111 114 101 102 100 122 97 100 104 95 99 96 117 100 115 95 103 107 108 119 113 117 80 100 123 107 105 115 103 98 103 139 90 118 110 131 110 103 117 109 124 110 96 90 107 115 109 127 112 129 118 108 114 94 114 118 111 98 105 106 103 105 103 113 106 108 107 97 90 101 99 117 108 105 129 104 115 114 110 111 118 107 115 96 133 120 120 97 115 122 103 101 90 99 101 120 102 108 131 107 136 105 95 121 116 108 114 94 92 109 102 87 87 118 96 94 85 106 110 95 103 106 125 112 122 94 96 107 123 115 132 95 95 104 120 103 113 109 104 109 105 106 104 110 113 115 100 92 97 116 118 95 85 102 103 101 115 112 100 100 129 101 94 113 93 113 99 125 122 102 101 113 86 105 129 108 106 107 103 101 95 87 99 119 96 85 126 105 119 119 109 89 104 111 126 93 97 116 103 105 120 113 100 127 116 119 95 126 108 128 111 111 102 105 112 106 114 98 102 110 88 113 104 104 109 101 120 96 117 117 91 113 104 109 90 108 99 107 113 109 84 112 124 113 100 92 105 114 111 105 103 98 105 101 92 107 114 108 87 100 124 111 127 91 129 119 97 95 99 111 103 103 88 99 120 104 100 98 110 111 113 95 102 97 116 97 99 112 109 100 100 103 111 131 108 98 123 127 96 114 102 113 118 108 104 116 99 112 87 92 87 117 100 95 104 105 102 104 104 82 97 103 95 92 95 101 108 109 96 101 109 109 118 104 119 93 106 105 90 116 106 98 101 92 122 103 97 107 104 92 101 100 103 115 92 109 110 116 114 108 91 102 104 100 102 102 95 95 98 104 93 97 112 112 100 111 100 89 112 103 109 92 88 117 92 87 109 97 93 87 103 114 112 106 101 102 96 109 120 87 92 109 102 125 96 113 105 114 114 98 112 99 98 102 124 106 101 95 100 102 118 99 120 106 107 115 101 94 109 90 104 123 92 103 121 113 104 88 103 144 97 102 121 94 113 99 90 92 97 90 100 97 99 126 97 108 96 99 96 99 120 89 105 113 122 105 97 115 94 90 91 107 112 99 116 127 102 90 95 112 108 84 120 121 96 135 94 108 99 85 101 115 99 118 104 101 86 95 107 116 95 103 98 95 101 112 109 91 105 101 102 107 95 98 106 109 105 92 106 104 102 101 100 95 101 99 99 108 100 114 100 113 112 84 109 102 102 115 106 107 94 117 122 86 100 114 116 89 111 93 114 103 101 121 106 96 98 105 103 114 94 101 117 103 108 102 98 103 106 106 110 103 93 96 98 88 102 105 90 100 102 133 98 89 90 106 93 107 104 95 123 92 105 101 106 117 115 93 116 94 114 103 110 123 99 117 95 97 85 98 89 124 121 112 88 109 95 81 96 118 104 119 99 121 102 102 112 122 125 106 100 93 105 110 117 108 101 95 117 110 99 90 106 100 107 111 110 100 117 99 121 126 109 109 95 108 97 84 124 135 112 107 110 132 118 124 103 102 107 102 120 108 113 115 130 105 125 101 98 116 114 129 101 129 103 97 102 114 107 116 98 114 104 117 138 119 118 123 133 122 116 112 131 108 111 120 109 124 129 112 109 124 120 134 125 132 131 118 110 138 141 106 114 130 106 133 123 115 114 105 92 111 125 121 117 118 121 98 110 109 132 99 98 85 110 126 128 123 119 107 126 112 100 112 117 113 117 105 108 111 129 92 121 112 120 106 115 91 114 98 116 104 130 112 112 123 128 116 130 120 98 122 102 108 128 104 121 126 122 128 113 88 117 120 111 93 142 108 132 114 125 137 130 111 106 107 125 100 141 122 102 113 121 130 125 119 125 107 134 136 134 151 119 112 115 107 132 151 127 157 146 123 137 153 147 165 150 147 150 151 136 161 170 168 183 186 175 151 170 181 204 166 207 165 203 185 194 178 177 171 170 167 190 158 176 173 167 170 156 141 155 153 151 150 146 132 147 133 164 126 144 133 128 141 128 137 136 134 119 124 137 121 122 132 122 105 107 127 117 134 123 115 120 117 132 138 112 110 122 122 108 116 99 121 116 106 129 114 120 114 142 118 117 111 110 91 106 103 126 114 104 141 114 128 106 111 99 108 128 96 107 83 100 106 115 105 95 108 120 90 114 118 125 107 115 129 96 100 114 127 106 100 123 106 112 112 111 90 108 106 88 119 112 105 97 106 102 93 114 103 113 111 123 98 102 103 108 108 105 107 116 106 106 106 97 105 95 106 92 90 106 96 96 110 93 113 102 106 113 102 87 102 110 114 110 100 109 100 87 105 119 103 116 108 97 100 125 101 107 91 107 100 109 109 100 110 108 104 109 115 110 100 94 95 115 86 101 105 106 134 115 113 116 101 105 99 106 98 114 114 94 115 113 131 102 100 103 128 128 107 94 94 122 127 99 119 118 104 123 114 102 114 93 93 115 110 107 116 113 90 95 111 117 100 110 105 85 108 111 111 97 93 119 121 108 123 100 116 101 121 116 87 122 106 122 116 106 102 112 105 111 100 104 105 104 102 107 133 123 135 103 107 113 100 116 97 95 97 99 111 106 112 114 104 119 90 94 111 119 103 103 113 116 95 92 138 100 125 107 111 104 102 104 103 111 116 96 118 121 120 95 104 100 112 96 118 107 104 96 104 128 106 106 113 107 103 118 92 129 103 110 117 101 117 115 112 118 116 106 104 116 91 113 94 114 100 110 88 123 110 109 114 107 100 109 128 93 89 104 89 130 92 120 100 101 112 107 93 102 129 88 102 102 104 107 114 99 107 127 116 111 111 104 105 113 105 110 87 111 100 96 113 102 108 109 93 104 102 123 111 97 118 96 101 104 116 105 121 89 107 109 107 105 107 108 105 116 116 117 121 102 119 101 106 93 98 97 108 123 115 116 114 101 103 93 112 97 86 113 115 109 109 94 112 83 100 123 89 97 109 119 104 119 102 112 104 94 112 103 82 128 88 119 123 104 97 108 113 92 91 114 116 105 107 104 110 106 97 106 109 111 99 107 115 94 91 98 112 110 104 122 118 107 110 127 123 93 108 104 104 108 128 120 105 113 98 101 108 99 97 99 89 104 104 116 98 84 123 94 117 106 84 109 95 103 113 118 115 106 95 114 108 99 114 117 115 102 110 131 118 107 97 106 104 101 115 115 100 116 120 93 129 108 129 86 97 125 97 119 111 101 113 92 102 108 96 101 99 102 112 115 111 127 105 92 112 99 101 114 92 122 105 105 120 134 122 121 106 110 89 94 88 95 108 113 105 104 94 125 113 96 129 101 111 97 96 119 104 93 90 86 128 107 100 105 93 111 108 103 121 109 97 120 122 110 110 120 117 112 105 100 82 88 118 104 97 95 102 106 98 103 109 96 107 112 100 112 90 108 98 103 112 102 113 106 109 108 110 95 108 110 108 114 101 108 103 110 135 99 114 93 110 97 110 124 106 95 103 95 121 116 116 94 103 106 103 106 92 95 108 110 116 121 118 133 136 109 101 96 108 105 97 113 129 105 106 103 114 98 106 85 98 111 108 112 121 113 88 91 110 120 117 114 128 97 91 106 109 115 107 104 104 103 110 105 96 99 121 107 107 103 130 108 122 115 110 106 102 101 108 114 120 118 96 128 92 121 103 92 125 95 100 99 107 117 123 108 87 117 122 112 103 107 108 103 115 113 97 101 111 95 116 91 96 112 125 115 105 113 82 105 126 99 117 111 126 118 118 106 118 105 105 109 139 124 118 106 116 110 98 110 99 120 111 111 98 105 120 114 109 122 115 99 109 104 100 124 103 83 98 106 111 107 88 115 103 106 120 110 111 116 125 118 100 113 101 94 119 91 117 102 108 104 115 118 113 133 117 109 116 124 97 104 95 115 118 110 105 105 106 98 109 100 112 111 106 112 111 108 122 121 103 128 127 114 102 105 116 112 102 102 127 108 104 86 122 115 115 102 117 99 76 107 116 98 96 103 133 110 106 102 109 124 123 96 101 101 114 112 108 103 116 102 115 123 114 126 115 118 103 91 104 113 98 114 108 109 114 111 94 101 103 99 113 122 101 106 128 126 93 118 105 126 120 121 115 113 106 111 117 116 104 97 114 121 91 125 101 99 101 132 106 103 117 107 98 114 109 108 114 103 104 108 114 126 115 107 109 115 111 111 101 113 106 97 93 124 116 109 102 122 115 105 103 106 112 139 97 109 102 111 114 99 106 116 100 93 99 124 113 116 116 105 109 105 115 107 128 115 127 110 100 122 113 111 125 104 120 108 99 116 131 129 96 103 111 113 125 98 110 115 102 123 98 99 124 108 116 104 105 127 99 123 106 107 111 99 84 106 110 106 120 93 127 112 112 143 92 122 96 104 105 98 109 110 104 114 119 124 107 124 111 112 104 121 100 121 128 116 124 117 115 97 106 98 96 128 121 124 105 121 94 98 98 119 113 123 101 126 112 97 123 113 111 115 103 92 138 109 129 111 118 83 126 108 120 105 129 116 93 104 108 119 98 111 106 103 112 103 119 139 127 102 102 99 114 101 113 116 99 106 116 109 116 110 126 109 90 96 109 116 95 105 94 106 104 121 116 86 92 108 97 103 113 117 111 101 119 103 110 111 107 120 84 114 107 126 136 91 123 90 104 123 100 149 102 115 118 102 127 118 104 105 97 116 102 117 116 99 113 134 103 106 116 121 119 105 118 109 104 110 106 99 97 142 121 99 102 123 106 111 123 105 99 112 123 106 102 109 97 97 114 105 126 106 107 124 99 101 112 93 103 113 106 121 112 118 86 123 103 99 106 96 123 114 124 111 115 99 122 116 102 108 104 118 124 120 128 123 115 103 93 102 110 106 112 100 112 116 100 89 99 92 116 113 112 116 119 115 111 101 116 104 121 115 112 110 108 108 94 112 113 132 82 113 103 94 110 101 113 95 91 107 110 122 117 107 107 132 102 73 111 95 95 110 137 96 130 106 107 111 119 117 113 104 103 108 105 125 115 107 95 99 116 113 109 103 112 119 101 120 102 107 109 130 99 111 104 137 114 110 114 116 123 127 111 123 101 132 113 121 95 102 99 110 123 117 109 107 90 130 110 100 127 102 118 112 86 125 112 117 120 101 123 120 105 110 134 99 120 105 97 123 95 99 107 112 91 107 98 107 117 91 105 113 120 116 112 113 122 110 125 114 124 109 106 111 129 109 102 106 112 128 132 122 127 115 86 108 97 115 118 117 96 105 117 99 117 107 119 97 120 93 125 112 116 115 110 119 108 111 118 101 117 124 121 132 112 97 114 105 104 110 115 99 109 101 109 89 109 103 103 105 118 101 106 130 100 93 100 118 106 119 107 88 109 110 96 121 91 111 97 127 111 108 118 123 131 103 100 121 109 105 111 112 116 131 112 109 132 121 117 132 100 100 107 110 127 109 87 108 118 121 106 130 118 116 107 119 116 103 100 119 133 100 106 115 132 130 102 119 115 130 107 108 103 91 111 115 122 102 120 121 113 110 110 129 122 119 101 120 120 133 108 99 110 114 108 126 124 112 112 123 131 136 119 110 124 105 119 123 104 129 96 123 99 112 104 105 104 120 127 111 119 108 103 110 98 105 110 118 109 109 100 123 123 117 103 117 114 125 128 114 112 128 104 109 107 93 105 114 128 92 122 122 113 105 112 110 128 124 139 109 119 117 107 112 134 114 139 111 100 100 110 158 93 92 124 118 115 135 100 129 117 109 117 125 114 132 126 112 117 125 122 107 105 131 118 101 151 131 117 110 105 115 116 122 120 108 98 112 95 129 109 121 98 104 99 104 109 122 124 124 123 91 124 102 129 103 121 114 92 126 108 122 106 103 100 115 94 122 96 116 110 123 123 113 116 118 99 106 96 117 116 134 109 116 110 133 108 123 101 120 129 114 129 101 112 111 102 111 117 128 95 101 116 126 122 89 103 117 122 115 120 107 110 102 103 107 108 111 126 99 111 116 117 130 115 124 98 104 128 109 130 99 119 94 118 86 103 119 128 106 94 123 99 98 116 104 108 133 119 108 114 108 112 121 104 95 100 110 123 117 120 125 115 108 105 134 110 105 106 116 127 116 123 105 126 105 120 110 97 107 101 118 109 115 128 110 121 99 104 124 128 130 130 113 107 131 116 123 107 113 105 103 110 126 97 111 97 114 123 105 107 102 97 114 105 126 107 111 101 95 114 127 108 98 111 108 117 112 120 108 115 119 117 107 116 118 99 100 120 118 103 113 111 93 112 101 120 114 114 107 101 105 122 120 139 101 108 114 115 129 116 99 102 115 107 100 122 124 112 101 104 102 115 97 111 114 105 128 117 111 145 116 108 118 110 117 114 106 107 112 111 98 107 121 116 105 122 124 114 120 124 124 112 107 109 117 108 116 106 118 96 110 111 119 106 102 111 107 124 103 128 101 113 102 127 112 109 116 99 117 103 139 107 110 114 111 96 102 98 111 102 121 140 114 79 122 122 101 110 113 115 117 110 92 114 116 127 99 98 121 121 118 76 126 102 126 131 113 122 119 119 128 114 115 126 121 126 123 102 98 145 109 122 115 106 117 119 123 122 114 99 100 136 119 125 90 104 130 101 106 122 106 128 106 122 105 125 101 109 107 114 131 101 116 102 128 150 115 109 120 135 113 96 129 116 114 111 107 102 111 122 92 113 111 115 111 122 104 109 124 130 119 101 116 112 99 107 123 112 116 114 130 121 115 135 114 97 112 112 113 106 107 120 97 116 134 122 120 118 105 99 129 116 122 120 112 103 107 129 123 100 113 126 123 124 113 105 136 117 108 109 127 112 104 118 100 116 121 113 119 129 106 87 116 107 102 108 108 119 105 105 127 115 92 101 107 107 103 115 108 110 99 99 113 96 131 120 114 125 110 110 105 115 108 103 125 102 95 105 101 115 107 112 127 108 117 129 131 118 91 110 99 122 123 111 120 103 113 112 120 109 101 131 106 114 117 118 113 92 106 106 137 100 126 118 120 106 117 112 120 105 103 111 134 112 109 118 135 132 107 117 118 109 107 129 108 88 114 127 110 114 118 101 115 108 122 113 105 103 123 116 127 145 108 108 100 109 115 110 115 130 114 100 122 138 109 120 109 110 111 118 132 107 115 110 111 109 112 120 103 113 90 117 117 130 106 104 115 120 110 118 118 119 123 113 105 102 98 121 97 125 95 123 112 109 110 139 119 107 114 120 115 111 107 108 109 101 123 107 118 94 120 120 129 122 119 123 126 111 90 94 118 131 112 116 110 103 105 108 110 125 114 90 119 131 127 96 134 94 105 109 102 107 90 111 122 104 109 118 105 105 106 114 116 107 106 116 105 112 98 123 110 134 132 119 137 126 127 112 119 109 105 120 112 133 124 126 113 108 126 124 108 97 111 105 107 101 109 119 110 115 120 113 106 108 118 126 129 124 112 106 140 100 112 117 122 104 122 106 125 94 112 96 129 103 118 112 115 112 124 116 109 122 110 111 120 117 110 117 102 123 120 98 137 114 119 116 106 123 129 96 123 118 109 118 116 129 115 102 112 101 115 93 107 114 104 115 102 128 105 110 109 105 106 132 118 102 124 109 127 119 116 107 119 123 95 122 108 136 99 110 111 87 109 112 91 129 99 101 106 107 106 97 105 114 120 119 106 110 112 120 133 119 132 140 101 143 128 109 121 133 103 105 108 106 105 121 126 109 127 121 118 95 120 101 108 110 114 92 114 116 110 100 115 115 110 109 123 102 123 113 113 110 102 113 129 103 119 113 119 123 108 105 104 87 101 106 106 112 132 107 101 103 104 106 113 127 115 109 116 140 106 113 120 120 101 101 124 102 85 119 97 112 120 115 110 119 113 119 135 133 92 99 126 94 125 122 117 118 104 103 102 101 107 114 123 118 146 113 120 124 108 102 112 139 117 102 103 101 119 105 105 121 114 111 123 101 124 97 102 125 105 119 109 95 116 112 100 119 110 94 101 107 131 117 100 121 109 114 128 109 97 109 115 106 109 100 121 116 118 109 101 104 95 135 110 138 98 103 105 116 116 111 104 122 117 112 125 122 111 121 113 130 118 120 105 120 99 98 123 128 110 106 121 124 115 108 95 109 87 122 103 120 108 96 115 113 108 128 120 109 124 107 137 96 106 104 106 122 114 132 101 114 119 111 103 117 121 95 115 104 112 116 109 123 117 117 112 130 111 104 107 100 122 105 107 103 94 112 99 100 129 114 115 121 117 117 117 99 115 93 139 115 106 116 121 120 106 120 118 94 120 109 137 117 125 134 118 112 112 115 132 116 114 109 115 115 114 125 122 127 119 110 108 95 115 105 126 105 119 106 110 114 117 119 105 107 122 119 109 111 122 110 99 121 130 128 115 142 127 114 123 124 114 128 117 118 106 115 104 129 137 123 111 112 126 104 105 120 121 118 113 119 122 116 122 109 97 106 127 105 110 107 126 112 114 124 118 106 116 108 121 113 113 121 117 110 98 137 116 94 115 105 112 109 103 99 129 105 128 117 115 124 108 105 129 121 141 113 102 117 129 107 118 110 128 118 123 121 121 123 140 112 117 112 112 95 126 98 141 122 94 89 111 98 115 114 134 116 110 119 123 134 131 116 128 128 116 108 113 118 98 134 111 108 129 139 114 123 114 106 132 90 108 131 104 122 114 123 110 88 100 128 114 110 111 107 94 107 125 101 126 97 104 124 104 98 121 130 126 116 106 141 111 112 113 100 108 110 115 140 110 121 113 122 121 121 115 100 105 129 109 120 125 126 118 106 115 106 119 121 114 124 127 101 110 105 120 117 102 109 147 97 99 130 119 117 96 110 119 97 115 108 110 127 95 137 99 122 124 86 129 96 118 134 131 123 114 121 106 95 109 112 122 107 146 112 126 111 105 100 131 115 116 114 90 119 132 114 122 113 104 100 133 114 144 112 106 111 105 93 105 100 108 110 103 103 107 113 129 99 123 113 125 118 104 87 96 107 100 105 111 125 120 106 118 121 109 121 120 122 112 118 124 101 112 102 134 117 121 114 103 114 127 122 104 100 120 112 108 101 101 111 105 95 118 99 119 104 110 112 100 108 112 113 120 120 121 128 117 113 121 107 119 105 124 116 116 129 109 105 117 117 106 120 105 101 113 124 128 118 107 136 121 104 114 113 129 134 120 99 140 119 112 114 109 106 114 94 124 107 111 122 102 130 100 120 116 102 113 123 105 135 128 109 87 99 154 108 132 118 120 109 101 87 117 105 110 113 111 120 114 124 118 100 124 130 118 135 125 124 123 119 123 129 124 127 108 104 127 129 98 103 127 107 101 106 109 94 109 96 113 113 113 114 109 108 118 116 125 128 117 110 107 113 93 116 113 106 120 110 125 115 99 106 121 99 111 113 124 112 105 110 103 111 123 116 102 117 111 96 95 126 105 139 112 126 109 113 112 88 99 107 121 113 114 116 118 119 120 131 86 119 127 126 101 115 108 97 139 114 119 105 113 136 121 133 113 103 104 137 114 101 122 109 110 130 117 112 110 95 124 105 96 108 111 121 130 140 113 123 122 101 98 115 122 116 112 113 100 102 121 104 122 118 116 112 107 109 131 121 106 116 82 107 101 107 109 106 124 126 119 95 96 126 118 103 128 104 105 128 132 112 107 96 99 103 125 109 114 127 116 102 126 108 112 102 115 116 114 116 143 103 109 100 97 124 110 102 121 111 111 118 138 110 111 127 123 128 111 137 104 115 111 102 96 128 130 128 110 110 119 138 121 126 119 111 114 116 108 121 133 104 112 115 119 130 110 93 128 111 110 118 117 121 112 127 124 112 126 117 110 106 97 121 99 102 120 122 113 97 114 118 113 125 106 99 111 113 103 112 113 129 114 114 105 134 112 108 121 122 125 110 112 106 118 126 117 97 128 99 126 133 114 113 105 117 123 115 130 113 134 93 100 121 106 134 100 123 111 118 103 104 120 125 104 137 135 117 101 124 115 133 120 125 105 130 98 122 127 105 128 104 108 124 100 114 131 105 128 114 100 131 104 109 111 127 119 117 112 126 95 104 135 105 104 124 123 116 120 120 106 94 116 127 119 115 102 126 112 100 114 103 116 137 105 126 90 107 119 119 130 110 110 116 120 100 108 125 113 115 115 122 120 109 124 117 105 110 119 131 102 128 130 121 99 120 115 117 103 124 130 112 123 108 112 133 124 135 132 125 124 115 115 123 116 127 143 116 127 113 121 99 128 116 113 126 99 93 130 106 106 128 113 130 120 113 125 136 123 112 122 120 136 93 107 117 102 116 96 101 109 131 126 110 120 96 104 124 111 120 130 125 99 108 138 132 109 99 124 109 133 116 109 118 118 127 119 102 118 91 100 127 106 112 115 134 116 115 116 126 138 127 118 100 116 124 109 133 117 122 95 107 119 137 113 125 113 142 107 113 114 128 127 120 125 135 114 117 118 139 148 110 112 113 122 113 105 127 129 122 128 124 112 111 115 125 129 113 136 121 134 129 146 144 131 129 117 119 121 116 140 138 129 133 134 124 122 128 143 125 132 120 126 126 135 146 125 133 121 136 125 136 122 129 122 136 115 111 107 118 138 124 145 121 119 114 104 140 146 133 128 117 114 115 114 120 145 136 113 96 120 112 111 124 139 126 122 139 134 110 111 111 119 131 107 102 122 125 131 122 108 148 109 89 110 136 97 111 118 120 131 99 117 109 125 118 119 101 127 100 110 105 131 104 98 117 119 108 115 107 122 112 107 122 90 115 120 110 118 127 105 107 102 118 130 124 138 123 134 108 117 129 114 118 107 109 113 95 122 129 111 119 110 96 99 120 106 100 136 113 107 138 118 133 126 107 91 124 106 133 124 124 117 109 112 131 117 128 109 124 102 109 118 113 110 126 133 122 103 120 125 120 117 120 113 128 119 92 120 102 109 79 111 111 121 98 94 96 107 111 114 113 121 127 105 117 95 108 122 116 112 129 116 112 93 103 113 104 139 123 111 115 121 96 103 109 111 99 111 112 112 118 123 120 111 108 102 115 108 115 107 123 116 101 115 110 111 110 115 121 103 104 102 121 114 122 110 122 110 116 109 105 110 110 134 106 99 121 118 112 114 103 101 105 117 124 121 114 108 104 114 126 113 124 117 120 94 117 110 137 107 111 94 117 111 100 105 106 110 111 114 111 107 117 104 108 125 96 104 109 101 126 118 117 103 106 114 105 103 123 97 97 122 115 107 119 118 118 104 101 106 98 100 116 113 118 112 126 103 117 115 114 125 103 133 103 97 110 117 90 111 101 105 128 116 108 113 108 117 114 129 90 113 112 118 101 121 113 109 103 107 116 139 112 109 124 103 128 110 125 113 111 99 122 105 99 103 106 110 106 119 111 110 112 108 107 101 92 100 121 118 133 102 100 117 114 102 107 109 104 101 115 121 111 108 103 122 114 113 96 124 108 106 126 111 116 102 123 102 107 105 118 92 97 109 114 121 107 103 104 105 111 107 117 111 100 117 102 124 120 119 119 115 117 118 113 103 106 94 103 110 113 109 110 110 112 107 120 113 118 105 116 99 96 106 108 117 104 120 103 100 108 132 113 111 112 99 114 119 95 110 105 121 109 102 111 112 115 97 112 118 113 115 123 93 112 117 139 114 111 125 106 80 114 132 118 105 103 102 99 116 103 115 121 84 103 103 103 106 117 116 115 115 123 138 102 114 102 121 101 112 125 131 123 115 106 122 102 96 121 108 151 99 110 106 123 131 94 123 112 108 127 111 113 109 111 98 100 98 103 100 116 80 106 100 121 96 129 111 107 119 119 92 104 100 116 121 124 100 104 91 99 108 123 111 101 115 103 113 122 97 97 116 115 103 115 113 98 128 129 102 106 110 130 95 103 100 97 106 111 105 117 104 115 110 110 120 107 118 125 119 97 94 98 87 125 114 103 98 110 112 104 101 94 111 128 115 116 125 106 107 97 104 101 96 101 98 96 100 95 122 103 103 108 112 117 125 107 95 124 99 114 113 107 101 130 114 116 105 117 102 111 117 103 103 109 117 115 112 110 103 107 110 99 99 117 92 102 98 125 129 119 119 109 98 110 122 125 102 104 102 106 112 105 112 107 102 98 98 106 107 94 119 116 114 108 131 120 119 98 111 98 99 105 118 97 102 119 111 116 96 110 121 109 108 111 99 100 102 111 91 102 97 131 106 115 120 99 123 116 101 82 97 98 108 114 110 125 108 108 105 122 122 103 119 101 119 97 121 108 111 125 110 104 109 105 103 117 111 93 102 110 92 105 115 88 112 114 103 115 120 122 114 108 114 113 87 111 107 122 117 109 109 114 99 111 89 118 108 123 108 88 117 94 123 100 105 99 97 121 109 103 100 115 132 122 115 112 82 117 102 99 122 124 117 130 105 98 124 112 114 95 101 107 116 107 104 102 107 110 114 131 97 106 125 118 129 100 100 101 110 101 121 124 116 100 123 92 113 107 99 104 91 105 97 135 108 126 101 124 124 106 106 106 96 110 129 106 103 108 121 103 98 128 117 117 115 129 127 99 110 116 98 125 126 104 105 107 122 107 129 105 131 106 113 119 128 106 118 128 105 103 132 108 103 131 104 101 119 116 110 112 111 112 117 91 98 120 111 97 108 112 97 111 105 138 75 112 106 107 130 114 119 130 97 108 115 91 93 120 116 119 127 113 114 95 123 101 91 130 117 108 93 108 121 101 113 101 111 120 106 132 115 130 111 99 110 117 113 134 110 107 87 126 116 117 99 100 102 98 109 125 116 100 115 108 106 119 115 100 103 112 112 116 98 118 128 96 95 88 107 99 108 85 100 107 105 122 118 111 108 101 124 122 103 109 107 111 117 116 111 106 103 114 102 105 106 100 126 108 112 96 114 89 113 95 99 127 84 114 111 108 111 101 122 97 110 102 108 98 84 124 102 103 106 110 122 111 108 105 104 98 114 121 114 108 115 99 113 112 118 114 105 122 102 103 139 106 110 99 94 96 113 101 104 125 108 98 107 109 103 105 108 101 121 86 116 113 119 112 111 106 102 113 109 121 110 104 102 104 120 105 107 104 102 99 96 115 87 112 111 130 118 118 115 110 104 99 114 113 102 125 101 93 110 115 124 103 92 123 86 112 92 91 101 114 101 101 90 102 114 109 91 120 110 129 106 111 97 110 93 113 98 97 108 100 118 119 118 115 112 122 105 100 106 103 115 93 128 103 102 120 102 96 104 102 118 117 102 101 101 119 99 113 112 115 113 97 114 113 111 114 96 110 128 112 107 104 108 97 107 121 98 101 118 92 119 105 125 116 101 121 101 113 117 118 104 101 102 117 112 100 97 109 119 119 115 124 119 115 116 122 117 98 84 106 108 112 110 100 125 95 109 118 114 130 77 105 102 131 117 95 98 117 114 91 114 109 94 115 95 111 97 122 90 125 102 97 100 89 115 104 105 109 101 133 116 110 100 105 110 115 112 106 105 112 115 100 111 103 106 129 111 108 120 102 115 121 111 105 124 125 116 102 120 109 117 112 97 100 110 115 109 126 89 112 135 109 122 95 90 104 110 114 113 113 115 108 109 107 93 104 103 117 99 118 102 121 90 124 120 89 111 118 101 124 118 99 84 116 116 114 93 102 98 110 118 113 108 119 89 119 114 101 101 111 111 100 105 111 104 104 118 106 100 105 102 103 122 95 98 121 106 100 132 114 97 104 121 96 114 118 104 128 104 116 103 113 89 111 122 121 106 109 93 97 115 103 117 117 107 109 98 102 119 92 106 117 88 103 109 115 108 124 104 86 111 98 94 120 98 102 116 110 111 94 75 124 105 96 104 101 119 86 93 112 118 122 101 117 104 98 96 124 113 110 121 107 117 116 97 100 114 104 114 117 117 117 103 92 100 116 118 105 104 92 120 123 92 95 115 114 105 114 87 92 115 112 111 101 107 90 101 85 95 105 114 112 96 107 102 111 111 95 110 123 115 117 99 114 122 113 108 105 103 135 81 111 121 129 109 120 115 118 127 106 119 143 111 107 106 111 117 132 112 114 97 127 91 102 97 109 112 90 121 110 106 120 104 117 117 121 110 107 103 119 123 107 111 110 117 126 104 111 89 120 112 120 117 112 107 106 124 132 105 112 99 98 105 111 105 115 113 96 111 94 127 112 108 94 116 98 113 100 118 125 101 114 117 118 104 101 116 126 120 112 103 94 96 112 123 84 107 114 102 123 117 122 107 117 113 108 119 118 115 106 101 116 118 118 100 116 121 117 114 119 107 116 126 116 99 113 125 92 110 107 101 95 106 111 114 104 121 105 116 116 120 122 103 139 112 99 130 136 115 113 129 118 105 99 139 102 122 129 108 138 120 121 94 110 107 113 123 93 122 102 120 109 139 102 103 91 119 127 103 126 110 113 119 109 112 110 118 119 111 131 112 110 99 121 113 118 108 103 98 110 99 105 106 125 121 120 128 94 121 121 99 109 102 119 111 119 107 127 121 121 104 107 102 116 117 139 99 94 113 117 117 119 118 115 109 111 89 120 95 102 124 90 100 98 102 114 104 109 109 117 119 120 112 128 122 101 96 118 105 105 119 93 104 99 117 120 106 108 99 96 82 121 120 115 94 96 93 112 109 102 118 108 128 100 111 99 104 118 112 118 105 124 90 119 104 107 94 104 118 101 137 106 93 118 106 104 120 116 98 112 91 119 103 102 116 84 115 97 103 97 129 110 118 121 112 124 90 122 111 112 106 88 99 126 106 111 137 116 115 118 108 97 95 103 131 118 111 95 98 119 106 127 116 99 112 82 107 126 114 119 106 97 113 115 98 96 103 109 96 109 99 101 117 111 98 106 136 95 103 133 123 126 117 108 117 99 127 106 106 99 105 112 101 98 94 126 117 88 111 120 118 115 128 104 108 110 108 117 108 110 99 111 121 114 118 118 117 115 94 95 100 113 113 99 124 110 112 101 98 106 105 88 118 100 106 120 125 100 79 88 114 103 110 110 110 118 96 103 101 104 101 112 111 106 124 97 107 98 133 107 113 106 99 106 115 93 106 116 108 105 103 104 101 96 100 101 88 99 125 122 95 116 110 100 115 109 121 104 106 120 108 106 106 136 98 93 105 105 108 114 113 112 108 110 100 101 130 123 115 113 113 106 109 102 99 123 89 106 119 118 111 107 114 127 108 110 83 100 121 123 112 114 121 108 124 117 107 101 91 109 119 94 112 126 98 108 116 112 99 110 119 104 127 123 115 118 116 90 118 122 91 92 88 115 111 83 104 108 102 97 93 115 108 98 102 117 129 126 115 109 98 102 93 102 102 105 91 115 129 118 102 112 96 99 120 136 106 95 102 113 111 105 114 106 91 114 96 103 117 113 118 123 106 99 112 110 113 108 117 101 102 107 105 102 109 102 110 109 102 107 95 109 111 93 100 118 117 97 109 106 114 111 109 98 108 113 98 114 98 104 110 103 127 116 104 112 120 106 114 107 106 109 117 102 118 110 109 114 108 116 98 102 100 101 101 103 110 104 91 110 117 123 106 118 114 88 111 115 110 87 110 96 124 115 119 103 119 101 127 121 107 113 102 109 97 126 111 120 130 91 118 101 103 95 116 108 124 107 111 104 106 104 97 110 113 116 122 110 103 111 101 105 101 101 118 105 113 122 108 106 102 97 98 100 112 100 117 121 100 104 100 118 101 99 116 127 102 108 117 115 135 102 103 90 109 104 103 111 92 106 107 122 112 107 92 99 83 109 115 110 117 101 123 115 116 116 106 118 115 113 106 113 119 105 128 121 127 126 113 93 115 103 116 119 107 99 117 117 105 104 116 113 107 122 121 111 88 98 116 112 98 102 104 120 123 132 108 98 111 112 132 110 118 88 112 116 124 105 112 102 100 103 105 110 97 127 137 107 96 102 121 117 97 133 107 127 107 95 117 100 112 105 103 113 111 111 110 95 124 90 110 117 112 111 132 103 124 119 100 100 118 94 112 112 120 104 120 87 108 109 109 106 94 115 128 127 95 100 110 110 129 125 89 121 114 107 120 101 111 97 107 108 106 95 125 122 125 111 114 126 87 108 111 110 128 120 126 107 105 105 113 118 111 103 112 132 123 107 103 127 91 118 96 127 105 102 94 117 112 116 113 100 119 120 113 126 118 112 93 107 97 115 106 106 115 106 108 108 95 104 109 111 93 114 95 120 91 106 111 103 121 112 85 117 98 109 99 110 107 115 109 101 92 105 126 87 107 105 99 114 115 102 103 104 119 95 102 119 96 92 90 115 116 87 114 114 103 110 95 115 101 73 116 109 106 109 103 125 119 110 114 115 83 107 110 105 114 101 101 118 96 121 119 105 113 111 110 98 109 106 92 114 121 112 107 112 92 112 106 115 118 117 95 112 106 108 92 103 115 119 89 115 109 116 107 95 110 127 123 93 115 100 105 125 117 111 92 102 97 104 110 97 119 95 100 141 109 96 95 105 127 114 112 107 108 118 115 112 120 110 120 105 112 109 132 103 109 116 106 115 122 108 107 100 116 99 107 90 108 98 99 119 116 107 118 120 114 125 106 119 99 91 111 124 106 97 105 106 108 119 116 103 118 101 96 99 128 111 120 99 102 105 101 125 122 121 107 105 97 120 104 109 123 94 127 110 113 108 119 115 117 111 104 109 92 114 105 116 86 126 110 115 112 102 116 109 118 113 124 114 107 105 99 99 115 110 125 115 98 92 119 101 112 107 122 111 97 115 119 103 108 109 107 106 119 100 106 113 111 107 117 119 95 121 109 103 113 99 117 120 93 107 113 125 113 106 109 101 118 130 113 99 112 109 89 115 107 114 115 98 109 110 97 112 125 122 109 114 118 117 99 112 116 90 118 96 111 118 109 98 87 112 104 118 116 88 113 123 100 120 115 109 112 107 106 119 117 103 109 106 103 110 93 120 96 112 105 126 113 124 97 109 124 98 107 116 91 133 109 108 118 94 115 114 144 96 105 102 110 116 106 93 108 110 97 114 123 102 113 103 117 103 124 106 103 103 114 121 114 116 109 120 105 85 114 113 115 117 96 95 109 113 95 118 97 120 110 105 88 107 115 120 115 102 120 114 114 111 128 115 115 109 88 113 117 121 114 92 89 103 93 107 103 114 98 112 107 105 124 117 114 103 124 112 109 104 92 120 114 108 102 110 119 101 96 89 94 107 103 110 118 113 110 120 115 104 110 116 115 108 115 108 109 118 104 87 108 119 110 103 120 121 120 99 121 102 117 104 79 94 109 107 120 103 112 106 106 111 110 104 95 122 119 112 117 108 128 107 122 98 110 125 104 129 112 117 127 99 114 125 113 118 109 124 99 102 97 109 117 104 112 98 123 133 97 122 95 104 125 89 104 109 97 116 100 103 109 97 97 110 108 99 106 104 130 135 97 118 104 109 115 108 96 100 132 107 103 120 83 104 109 101 93 136 110 118 105 115 102 106 123 122 109 103 104 95 130 126 104 85 90 134 101 108 114 110 106 89 104 116 111 113 105 107 113 101 98 124 114 122 105 111 108 93 115 104 112 115 112 109 105 89 112 126 112 101 102 124 110 122 91 128 118 111 105 102 107 101 107 109 100 106 111 105 100 109 119 102 107 102 109 107 108 125 110 104 119 97 115 120 103 110 105 96 114 103 93 93 116 122 95 104 108 110 110 96 116 96 109 91 90 96 101 106 109 108 107 117 116 107 98 93 96 91 123 106 117 126 119 105 129 90 89 111 106 119 112 111 85 128 108 86 99 102 86 105 104 88 109 103 105 112 115 106 112 135 102 106 104 119 118 81 116 99 110 118 84 103 100 91 107 112 109 104 125 115 108 127 111 95 112 108 106 115 111 99 110 96 97 132 93 107 113 104 122 107 98 116 99 114 115 113 112 117 115 118 116 126 115 119 110 112 98 88 100 98 110 119 136 123 101 126 94 116 124 95 101 114 111 127 124 105 114 110 96 117 87 100 110 103 102 122 127 97 99 86 122 108 94 106 107 97 118 114 107 121 106 107 113 99 117 96 112 104 110 119 116 99 112 103 105 106 110 103 109 118 118 113 90 92 99 118 103 113 104 93 112 119 101 118 113 99 101 96 108 114 109 117 112 100 124 108 109 114 104 110 110 108 97 122 86 106 115 122 115 125 97 111 105 123 101 102 109 92 118 107 106 113 109 116 108 108 123 110 101 121 101 114 120 108 133 121 94 125 111 110 108 113 129 105 122 127 92 138 104 94 123 122 93 120 111 117 110 123 130 106 112 102 107 123 101 128 120 126 113 108 102 110 107 110 102 109 123 123 114 117 104 118 133 100 111 136 115 101 115 106 118 109 138 118 119 103 123 110 116 125 104 98 109 124 136 108 107 96 115 109 119 113 99 104 107 114 100 109 88 126 114 104 101 123 119 119 102 105 99 102 135 107 106 91 106 115 110 91 102 80 114 99 98 99 136 103 99 98 114 103 103 107 96 126 99 107 113 121 131 104 95 126 106 104 101 113 93 109 111 117 101 102 100 117 111 113 115 117 111 147 103 102 126 104 88 102 139 97 109 126 122 102 90 97 101 114 98 110 125 108 142 113 102 91 117 101 108 113 109 90 92 118 127 103 102 104 113 102 118 116 119 124 125 109 106 119 99 101 99 108 121 113 110 100 99 104 92 112 107 93 105 120 114 85 111 119 107 107 95 117 98 109 101 99 103 103 108 105 99 89 100 109 106 91 112 119 92 118 95 86 121 105 138 115 106 95 123 120 98 98 80 124 94 103 109 96 100 105 116 103 103 107 111 107 107 109 103 124 105 127 91 109 111 113 112 114 115 94 105 102 125 98 108 101 110 110 109 110 125 109 113 106 99 111 84 114 117 98 112 117 112 92 135 111 106 119 122 122 81 94 112 109 100 124 113 97 105 100 94 110 101 109 114 100 117 104 103 109 97 130 103 96 108 114 110 113 124 104 102 104 105 99 90 102 107 105 105 104 103 117 113 110 107 111 125 108 103 95 106 109 122 122 100 110 109 112 86 106 98 122 99 98 115 108 96 113 125 115 110 111 105 104 104 92 112 93 101 97 126 111 113 122 116 103 110 103 80 107 107 104 127 97 105 119 100 123 105 115 101 129 97 94 123 120 115 124 94 100 102 96 112 90 95 114 93 94 93 105 100 111 104 127 118 105 134 103 108 101 97 113 120 111 108 93 121 100 123 124 97 110 93 100 104 102 86 107 123 108 96 117 106 110 89 110 127 112 114 102 115 115 126 90 100 113 95 119 106 101 116 96 114 108 100 119 96 126 104 103 114 110 112 104 90 93 133 96 115 101 101 99 90 104 108 129 101 100 101 107 106 99 86 95 96 125 104 111 94 103 125 103 90 108 112 104 105 99 106 92 109 97 102 117 109 95 120 98 102 85 114 125 107 95 107 92 113 117 99 115 114 103 111 111 116 101 100 128 103 117 104 106 117 106 99 112 119 103 113 110 104 114 102 104 100 107 111 95 101 111 100 110 104 104 106 100 101 102 98 97 120 112 110 99 115 101 104 98 101 98 87 103 103 107 98 95 96 92 103 88 99 105 101 125 101 113 108 101 108 97 112 101 113 116 102 109 119 100 128 130 106 102 91 103 97 90 106 126 96 97 113 102 104 90 119 105 99 105 126 92 118 104 103 114 114 104 109 112 95 99 113 77 100 102 95 99 96 97 119 93 127 112 103 77 88 115 101 107 96 102 101 104 124 99 90 95 101 108 103 93 101 100 115 93 119 113 98 111 104 107 112 118 109 97 114 113 109 104 100 118 114 91 114 107 106 98 95 112 108 106 121 113 111 108 85 105 110 97 94 108 103 91 93 100 127 94 114 98 114 104 101 113 89 96 109 124 92 123 110 101 122 117 125 102 108 101 97 94 100 87 115 100 110 122 117 91 105 95 102 119 124 97 104 91 95 100 102 98 123 96 96 85 101 89 113 115 93 105 109 112 100 112 90 98 100 99 103 124 94 127 109 109 126 97 112 101 110 97 98 97 119 99 102 88 97 78 97 94 103 105 99 90 118 122 110 126 104 108 95 102 99 108 123 107 106 109 112 120 114 118 117 115 94 109 88 99 111 120 94 103 101 109 114 93 96 115 100 99 91 108 114 102 121 103 116 114 103 118 109 99 100 88 92 121 101 127 100 106 102 101 114 105 106 106 117 112 104 88 117 105 93 115 124 101 119 115 120 125 104 95 108 93 101 104 105 112 110 83 103 98 99 96 108 104 112 113 105 108 99 110 127 95 107 100 112 96 95 106 111 99 118 117 97 116 115 120 117 101 101 100 101 109 106 98 104 109 108 103 109 109 99 101 106 96 94 108 113 98 103 106 108 92 96 117 119 113 111 106 103 102 116 113 112 111 128 115 112 117 113 94 117 117 102 94 103 110 115 116 103 86 105 112 105 125 128 105 92 97 113 108 97 98 115 107 93 89 114 94 114 124 115 107 96 122 111 116 104 84 114 115 110 98 113 101 120 90 113 102 112 124 118 116 111 127 113 97 107 95 117 121 84 102 132 97 99 97 92 102 108 116 110 96 104 114 107 105 88 110 108 94 132 88 103 126 113 106 121 103 102 113 116 101 104 109 113 112 89 114 98 100 87 93 97 91 101 117 107 122 104 110 100 100 112 107 108 107 120 113 146 120 85 131 112 102 98 103 102 112 107 102 118 97 132 116 103 102 104 114 108 98 100 106 110 123 106 129 116 119 124 89 92 91 100 103 100 104 102 110 113 101 109 102 126 123 108 92 112 108 100 107 96 90 107 112 96 104 111 110 96 109 108 118 114 97 107 108 99 104 95 104 124 111 74 97 106 115 106 105 110 116 101 91 99 105 111 108 109 111 106 103 108 111 103 103 119 113 116 124 113 114 105 107 97 97 117 113 117 104 100 122 89 97 119 98 102 101 111 102 98 110 86 107 88 96 106 103 95 106 124 87 106 100 112 104 97 112 89 97 111 111 87 108 108 122 107 98 106 87 91 105 102 110 97 109 103 103 85 108 98 104 91 114 101 93 122 100 99 119 89 111 115 102 100 112 115 115 104 116 99 103 109 112 89 101 97 98 100 90 101 124 111 111 82 112 107 110 103 101 126 97 121 107 92 106 112 89 101 103 114 94 105 113 109 102 107 90 85 102 95 101 91 109 112 101 104 127 93 106 105 94 103 109 98 104 117 115 106 121 104 102 122 101 104 117 109 95 112 111 103 106 96 115 108 108 102 105 106 107 104 102 86 114 122 107 112 117 92 97 112 105 118 110 111 104 110 141 120 106 102 108 123 99 100 96 94 107 103 111 105 116 106 95 112 109 110 110 115 115 87 116 111 115 124 109 115 102 107 107 122 136 80 86 109 112 96 110 101 103 102 105 93 104 89 131 98 101 120 102 96 124 109 102 104 100 113 104 118 113 90 119 101 101 105 108 97 106 116 96 101 93 107 102 85 90 114 100 101 129 103 104 114 100 100 123 109 112 116 110 110 112 113</counts>
			</dataPoints>
		</scan>
	</xrdMeasurement>
</xrdMeasurements>