File: data/XRD/XG-Sauerstoff/XG-700/W6822-1B_XG_Sauerstoff_700.xrdml
<xrdMeasurements xmlns="http://www.xrdml.com/XRDMeasurement/2.1" xmlns:xsi="http://www.w3.org/2001/XMLSchema-instance" xsi:schemaLocation="http://www.xrdml.com/XRDMeasurement/2.1 http://www.xrdml.com/XRDMeasurement/2.1/XRDMeasurement.xsd" status="Completed">
	<comment>
		<entry>Configuration=Factory configuration, Owner=User-1, Creation date=7/8/2013 4:01:53 PM</entry>
		<entry>Goniometer=PW3050/65 (Theta/2Theta); Minimum step size 2Theta:0.0001; Minimum step size Omega:0.0001</entry>
		<entry>Sample stage=MRD Cradle; Minimum step size Phi:0.01; Minimum step size Chi:0.01; Minimum step size X:0.01; Minimum step size Y:0.01; Minimum step size Z:0.001</entry>
		<entry>Diffractometer system=XPERT-PRO</entry>
		<entry>Measurement program=C:\PANalytical\Data Collector\Programs\Jorrit\2thom\_absolute_2th-om_10-130deg_PIXscan_56min.xrdmp, Identifier={15BCCF57-2807-42BD-B5B9-ECC0B3DC9284}</entry>
		<entry>Batch program=C:\PANalytical\Data Collector\Programs\SimonL\batch4x_2thom_10-130°_z9.1_x0,10,20,30_y0_57min.xrdmp, Identifier={EED9823A-2BEB-424C-9252-345C4EF2834A}</entry>
	</comment>
	<sample type="To be analyzed">
		<id></id>
		<name></name>
		<preparedBy></preparedBy>
	</sample>
	<xrdMeasurement measurementType="Scan" status="Completed" sampleMode="Reflection">
		<comment>
			<entry>_absolute_2th-om_10-130deg_PIXscan_56min</entry>
			<entry>PHD Lower Level = 4.83 (keV), PHD Upper Level = 11.27 (keV)</entry>
		</comment>
		<usedWavelength intended="K-Alpha 1">
			<kAlpha1 unit="Angstrom">1.5405980</kAlpha1>
			<kAlpha2 unit="Angstrom">1.5444260</kAlpha2>
			<kBeta unit="Angstrom">1.3922500</kBeta>
			<ratioKAlpha2KAlpha1>0.5000</ratioKAlpha2KAlpha1>
		</usedWavelength>
		<incidentBeamPath>
			<radius unit="mm">320.00</radius>
			<xRayTube id="1010048" name="Empyrean Cu LFF HR (9430 033 7310x) DK442154">
				<tension unit="kV">40.0</tension>
				<current unit="mA">40.0</current>
				<anodeMaterial>Cu</anodeMaterial>
				<focus type="Line">
					<length unit="mm">12.0</length>
					<width unit="mm">0.4</width>
					<takeOffAngle unit="deg">4.2</takeOffAngle>
				</focus>
			</xRayTube>
			<xRayMirror id="27010001" name="Inc. Beam Cu W/Si (parabolic MRD)" hybrid="false">
				<crystal type="Graded" shape="Parabolic">W/Si</crystal>
				<acceptanceAngle unit="deg">0.800</acceptanceAngle>
				<length unit="mm">60.0</length>
			</xRayMirror>
			<sollerSlit id="21010002" name="Soller slits 0.04 rad.">
				<opening unit="rad">0.0400</opening>
			</sollerSlit>
			<mask id="22030007" name="Fixed mask 2 mm">
				<distanceToSample unit="mm">220.00</distanceToSample>
				<width unit="mm">2.00</width>
			</mask>
			<divergenceSlit id="22010007" name="Fixed slit 1/8°" xsi:type="fixedDivergenceSlitType">
				<distanceToSample unit="mm">220.00</distanceToSample>
				<height unit="mm">0.19</height>
			</divergenceSlit>
		</incidentBeamPath>
		<diffractedBeamPath>
			<radius unit="mm">320.00</radius>
			<sollerSlit id="21010002" name="Soller slits 0.04 rad.">
				<opening unit="rad">0.0400</opening>
			</sollerSlit>
			<receivingSlit id="22010001" name="Fixed slit 4°">
				<height unit="mm">5.88</height>
			</receivingSlit>
			<detector id="7010017" name="PIXcel3D 1x1 detector" xsi:type="areaDetectorType">
				<phd unit="%">
					<lowerLevel>30.0</lowerLevel>
					<upperLevel>70.0</upperLevel>
				</phd>
				<mode>Scanning</mode>
				<activeChannelsEquatorial>255</activeChannelsEquatorial>
				<activeChannelsAxial>255</activeChannelsAxial>
				<pitchEquatorial unit="mm">0.05500</pitchEquatorial>
				<pitchAxial unit="mm">0.05500</pitchAxial>
				<readOutPeriod unit="seconds">0.135</readOutPeriod>
			</detector>
		</diffractedBeamPath>
		<scan appendNumber="0" mode="Continuous" scanAxis="2Theta-Omega" status="Completed">
			<header>
				<startTimeStamp>2024-09-12T16:04:22+02:00</startTimeStamp>
				<endTimeStamp>2024-09-12T17:00:28+02:00</endTimeStamp>
				<author>
					<name>PRO-MRD</name>
				</author>
				<source>
					<applicationSoftware version="6.1b">Data Collector</applicationSoftware>
					<instrumentControlSoftware version="7.0E 20130304">XPERT-PRO</instrumentControlSoftware>
					<instrumentID>0000000011142674</instrumentID>
				</source>
			</header>
			<dataPoints>
				<positions axis="2Theta" unit="deg">
					<startPosition>9.99826193</startPosition>
					<endPosition>129.99755682</endPosition>
				</positions>
				<positions axis="Omega" unit="deg">
					<startPosition>4.99913096</startPosition>
					<endPosition>64.99877841</endPosition>
				</positions>
				<positions axis="Phi" unit="deg">
					<commonPosition>0.00</commonPosition>
				</positions>
				<positions axis="Chi" unit="deg">
					<commonPosition>0.00</commonPosition>
				</positions>
				<positions axis="X" unit="mm">
					<commonPosition>10.00</commonPosition>
				</positions>
				<positions axis="Y" unit="mm">
					<commonPosition>0.00</commonPosition>
				</positions>
				<positions axis="Z" unit="mm">
					<commonPosition>9.100</commonPosition>
				</positions>
				<commonCountingTime unit="seconds">32.895</commonCountingTime>
				<counts 233 231 210 224 213 229 298 241 249 204 215 233 216 213 242 248 233 224 220 249 249 262 261 223 248 220 220 275 239 245 244 256 258 242 242 228 256 247 236 246 248 238 260 277 265 245 231 239 221 224 274 236 207 225 230 241 248 226 225 275 221 261 227 230 240 262 242 216 227 238 218 222 235 239 242 264 225 202 237 211 235 228 214 226 201 216 227 237 227 249 249 229 243 215 234 226 216 229 221 203 233 223 180 210 242 246 215 245 220 230 195 220 249 245 224 249 218 208 216 228 238 228 231 226 211 182 239 234 233 217 213 218 197 245 234 214 204 242 213 184 225 219 221 224 269 204 224 215 218 218 211 238 200 195 203 245 194 229 216 238 231 212 225 234 227 216 233 224 213 173 225 220 194 190 255 206 233 195 228 237 220 204 229 233 227 209 187 241 227 209 234 209 197 201 179 223 213 205 226 236 199 221 193 205 189 236 224 218 214 219 199 182 225 216 208 234 209 212 224 212 206 222 208 196 218 206 215 215 201 224 193 192 217 208 205 228 211 204 211 206 209 190 233 191 216 224 229 215 211 211 205 201 201 221 201 221 185 195 202 229 216 223 212 179 200 190 219 209 215 238 205 192 222 179 204 191 228 207 205 203 221 217 218 212 193 203 213 190 190 206 186 188 200 192 208 203 218 218 217 211 200 212 214 208 228 202 205 205 187 205 193 170 214 189 197 225 181 215 189 193 204 173 219 221 184 184 193 201 197 206 234 176 213 197 197 193 188 203 177 201 207 199 176 199 195 210 185 220 191 233 210 206 195 211 208 186 207 196 196 187 213 185 225 165 166 210 207 177 206 199 204 205 212 177 223 169 179 207 190 202 199 200 217 195 214 192 183 216 200 201 192 212 187 190 190 192 174 186 206 186 195 181 218 180 184 182 207 166 192 178 196 215 204 208 188 191 175 208 189 205 185 199 188 164 208 195 191 194 205 200 215 218 176 173 192 197 193 202 195 177 199 180 189 168 176 196 168 182 202 218 184 189 177 191 190 177 208 204 204 200 191 195 192 204 188 200 195 165 198 192 174 159 174 196 209 173 201 184 192 189 194 176 178 193 189 188 203 187 193 186 201 172 187 171 176 184 174 208 189 203 180 194 193 192 194 185 172 180 164 190 192 181 174 167 184 174 194 209 189 222 190 179 185 196 193 184 201 172 187 194 178 209 189 178 193 185 169 198 170 180 190 170 195 202 180 179 197 189 187 185 169 217 191 170 193 174 182 192 165 197 187 180 189 211 169 210 175 172 191 189 178 214 184 208 205 188 177 199 178 189 172 187 191 170 172 194 164 201 180 167 197 182 181 177 178 203 197 166 217 210 192 191 191 191 208 175 205 191 177 193 182 183 199 169 193 193 165 176 198 190 193 182 163 187 185 171 168 180 181 184 182 186 178 169 178 183 193 164 176 188 193 169 202 175 171 172 191 180 177 175 188 185 175 179 173 186 208 160 183 209 173 210 164 190 195 183 195 209 187 201 185 164 184 185 176 204 175 189 175 186 182 208 154 186 178 184 189 222 196 178 186 221 160 183 166 180 194 178 181 207 194 158 189 186 179 187 198 187 177 222 169 191 181 182 197 173 199 177 197 218 172 191 190 178 165 194 186 195 186 195 195 188 189 192 183 166 196 187 186 178 191 165 174 183 195 209 202 185 179 198 184 181 183 184 184 204 184 200 204 210 174 200 187 169 170 173 170 191 192 180 164 197 169 193 195 194 187 182 193 185 187 174 191 176 167 167 192 162 192 208 165 186 199 164 202 181 201 196 196 180 178 166 198 197 190 182 202 185 196 180 178 189 191 182 161 191 181 180 194 175 190 173 197 186 198 179 191 176 194 203 206 174 191 187 161 180 193 191 179 193 171 210 176 184 182 195 175 185 190 204 195 167 168 182 171 181 203 174 173 179 170 176 163 169 214 196 205 193 191 168 185 168 205 178 190 199 178 181 193 175 187 180 174 195 167 192 192 201 168 173 197 190 168 169 194 189 174 198 196 184 206 210 207 210 197 197 167 153 184 208 202 171 190 186 197 181 205 182 175 182 203 197 176 194 196 173 174 200 218 198 185 193 212 174 189 189 194 163 177 167 176 171 159 202 193 181 200 174 183 189 181 208 197 172 185 198 185 193 187 192 196 216 192 190 192 156 174 193 202 186 189 198 172 190 210 172 184 186 176 174 179 182 185 184 186 221 189 186 195 211 167 170 172 190 200 180 187 195 199 178 185 191 170 193 183 170 176 182 190 174 207 178 184 160 190 173 180 186 184 198 173 170 189 192 187 181 186 179 208 187 198 189 187 191 179 190 170 202 206 161 190 183 171 204 203 181 195 192 188 181 199 179 169 172 201 193 155 207 175 208 189 203 191 166 189 193 186 212 183 162 195 184 166 181 208 192 190 189 198 159 174 180 197 192 192 177 180 204 183 203 189 183 186 209 186 193 188 197 199 206 188 201 186 224 197 195 220 191 212 185 177 170 178 150 185 202 191 188 211 178 207 197 197 187 191 201 188 214 183 196 203 213 189 182 194 188 167 196 182 217 207 193 238 185 179 189 173 186 200 185 189 192 185 202 176 173 208 202 181 178 185 198 181 175 189 195 217 207 191 186 180 160 196 203 184 184 192 187 204 202 167 192 179 191 189 178 181 185 180 201 184 189 195 207 218 185 193 193 174 212 184 197 178 163 204 210 203 172 198 182 163 209 177 183 183 189 182 200 179 214 188 181 199 179 193 181 186 202 191 194 197 202 165 165 161 169 186 177 219 166 189 204 168 200 168 192 187 173 181 195 197 200 210 180 173 191 182 176 186 188 183 192 171 208 179 182 187 172 165 170 176 202 183 179 189 200 174 193 168 184 167 184 185 208 193 177 195 186 183 196 183 194 216 168 177 175 190 176 177 178 213 175 180 195 172 198 197 195 214 181 169 169 167 170 183 180 200 180 197 155 193 189 192 179 180 182 197 167 184 188 179 189 203 188 174 196 194 158 172 183 174 192 163 170 173 182 205 197 180 174 194 179 184 162 197 175 195 179 174 173 177 193 162 198 187 193 174 195 154 188 161 180 188 176 170 175 188 192 178 179 189 178 178 213 173 174 171 171 189 182 184 180 178 173 197 186 179 160 177 189 207 168 175 165 170 164 185 146 152 167 182 172 178 173 185 175 171 177 176 176 181 170 170 162 201 149 188 162 165 190 160 183 166 191 171 160 159 180 162 196 161 172 185 164 171 173 196 159 155 178 161 164 155 158 140 197 169 141 192 140 167 190 169 163 187 177 175 184 186 179 157 162 164 177 171 198 171 147 159 186 181 161 181 163 167 170 180 167 171 171 177 190 164 135 169 157 188 153 174 189 164 158 145 160 153 161 167 167 167 138 167 185 137 160 153 155 174 188 164 157 171 159 144 181 153 162 157 160 150 170 182 157 188 200 179 162 174 168 170 156 179 173 149 161 175 179 167 173 173 179 157 175 174 158 162 161 157 163 144 149 180 172 164 148 163 163 145 165 176 138 176 176 158 172 157 173 165 168 154 161 171 190 142 160 175 150 176 152 168 173 166 148 147 167 161 148 161 169 166 148 149 171 155 163 149 155 159 189 154 164 137 142 159 172 164 138 165 169 163 150 159 164 160 153 168 174 161 152 165 141 167 166 183 151 136 147 167 175 169 134 163 142 157 150 175 155 138 149 165 171 167 133 161 161 188 170 167 173 150 151 148 173 169 141 145 160 149 161 149 153 169 155 155 151 156 160 160 156 157 155 172 155 163 162 167 182 170 140 148 145 186 152 163 170 185 162 146 151 138 159 146 147 134 157 169 163 134 128 153 171 135 146 169 159 145 138 132 161 130 135 141 145 141 169 143 140 146 141 165 148 160 125 145 137 144 152 146 137 139 152 144 152 162 149 152 142 137 138 153 153 159 149 146 153 154 147 148 175 151 127 162 141 142 153 156 130 149 143 127 144 156 130 139 127 152 133 147 125 145 141 152 146 129 132 147 128 131 155 135 130 136 132 133 132 134 151 143 144 146 140 132 157 149 129 152 150 134 156 149 139 145 157 148 142 121 145 133 121 139 134 147 127 157 129 147 126 160 147 161 142 146 155 144 129 137 172 145 134 146 144 128 164 150 146 149 140 126 158 166 132 139 133 124 141 118 144 134 171 151 160 155 128 126 126 132 150 133 134 140 134 149 147 145 136 143 143 119 131 140 139 144 153 140 110 140 144 129 124 145 125 146 139 143 130 126 117 128 134 124 142 128 140 128 129 137 123 123 148 127 127 125 128 128 118 145 122 137 122 137 126 125 141 135 135 159 136 120 126 126 145 128 137 122 141 118 129 137 149 141 123 131 119 132 127 149 139 124 121 127 118 128 127 119 131 144 142 128 134 134 143 146 119 132 141 137 143 127 123 129 143 142 126 130 139 147 122 121 138 143 143 125 147 122 119 142 136 147 149 142 129 118 124 140 104 124 138 140 127 141 124 141 134 151 110 156 120 133 151 127 117 135 131 156 117 122 112 147 121 113 132 134 136 130 136 140 129 127 135 128 134 129 134 111 133 146 126 124 118 125 143 129 137 128 130 120 121 121 120 128 138 138 131 129 145 149 129 128 135 119 122 126 125 146 130 134 132 127 123 126 120 124 134 141 107 119 121 142 127 132 133 125 117 126 121 132 119 119 132 140 107 140 111 136 132 123 123 138 146 116 138 117 142 125 126 106 124 117 127 112 117 129 135 119 122 128 109 119 123 101 129 120 134 117 152 113 140 111 133 120 128 135 127 129 111 140 128 139 127 139 134 117 143 156 111 115 108 119 104 133 134 132 136 133 134 124 130 136 129 132 133 116 118 114 134 101 118 115 150 116 149 128 127 156 124 156 118 146 119 110 126 116 124 124 126 124 106 123 128 120 102 130 122 111 111 149 124 132 124 117 119 135 135 116 113 121 128 117 141 123 137 116 121 145 120 114 105 122 110 112 134 122 119 139 124 117 133 148 110 122 122 139 111 115 130 147 129 138 112 137 110 138 118 130 130 113 142 136 118 115 105 119 99 112 115 140 118 140 137 126 133 119 105 140 118 132 114 103 114 92 132 139 146 125 126 130 122 147 136 114 134 134 130 122 123 129 121 113 117 109 128 109 112 147 124 121 109 111 103 116 115 118 122 119 124 118 142 115 117 111 111 103 118 108 117 104 121 115 135 122 122 125 145 120 128 114 125 124 111 103 139 112 113 121 121 123 124 125 116 136 135 113 115 97 139 123 106 128 118 122 110 116 125 129 118 109 138 120 109 107 134 135 119 127 99 116 147 123 136 130 145 114 133 118 122 133 123 113 118 123 130 109 136 114 126 135 138 132 123 132 116 114 125 128 104 114 121 117 108 113 116 107 97 140 119 115 111 117 113 102 90 118 120 101 113 136 112 114 105 98 116 111 108 118 113 127 131 119 135 108 130 130 123 114 111 124 105 121 140 117 113 123 109 112 113 98 115 125 132 94 118 122 122 132 116 126 107 116 134 123 138 126 127 124 112 118 130 109 116 124 101 125 126 103 129 119 116 118 109 127 102 116 121 112 107 122 120 114 128 128 110 114 125 114 127 111 128 113 111 114 112 126 112 123 127 147 119 120 113 130 120 105 108 101 120 122 116 111 116 121 145 103 101 116 109 140 121 137 119 115 112 100 114 133 99 116 126 103 113 111 113 111 109 100 129 93 125 116 116 141 120 103 113 98 130 119 124 110 120 109 107 112 133 129 127 122 111 96 103 120 129 117 107 110 126 111 122 95 101 112 112 102 110 121 116 126 122 103 120 111 105 108 128 126 117 118 118 111 117 111 105 123 101 123 113 97 109 131 129 132 125 112 124 124 108 108 125 106 113 119 108 113 95 105 124 114 100 123 110 105 117 98 116 103 87 128 117 135 131 100 105 119 105 122 115 113 120 129 106 124 125 103 104 103 105 119 125 112 94 107 94 111 119 109 124 108 129 126 92 112 127 124 116 98 126 102 132 132 111 107 110 140 99 114 109 114 109 110 110 116 124 121 119 124 106 120 128 125 127 125 112 123 134 104 114 107 121 117 107 118 106 111 100 115 120 114 114 97 119 108 129 104 123 131 124 121 126 111 115 124 129 108 140 144 150 110 133 129 138 130 140 149 120 119 118 132 115 142 130 135 132 136 124 115 116 126 143 107 136 121 139 111 120 102 112 124 114 126 101 121 113 119 108 118 104 108 97 110 110 98 118 122 121 104 108 98 113 105 130 111 120 113 131 115 129 110 107 103 116 117 132 146 111 120 122 102 103 120 115 135 101 114 120 92 104 93 108 96 97 103 108 139 117 101 102 102 114 94 108 97 112 118 96 114 106 119 95 106 116 99 110 114 116 105 125 98 125 110 108 115 119 101 116 102 98 93 100 94 118 100 121 113 104 104 112 124 104 109 110 100 111 116 100 117 117 97 106 116 114 116 122 104 109 90 115 119 107 112 122 133 129 114 110 113 110 103 94 103 111 109 104 104 127 103 120 116 116 107 111 95 126 113 120 109 121 115 100 122 104 97 123 112 104 104 107 114 111 124 97 108 96 126 108 106 111 100 115 123 108 103 114 101 107 126 82 120 127 112 118 109 124 123 118 120 111 106 99 91 139 112 110 109 115 114 110 107 118 103 120 129 117 97 101 110 99 118 97 94 105 132 103 108 110 110 115 104 106 110 110 117 118 117 119 118 101 109 117 106 118 90 101 113 102 107 114 125 118 116 114 114 117 125 88 125 125 110 114 108 113 103 121 119 113 100 127 111 97 118 103 124 106 94 103 102 125 116 99 99 108 107 99 119 120 105 105 100 100 112 115 98 100 110 108 116 105 102 99 114 98 95 86 107 119 116 105 119 94 134 116 108 122 119 106 110 105 129 108 123 113 88 99 110 100 130 119 127 121 108 106 117 99 112 110 98 136 112 93 97 93 116 114 101 109 104 103 129 129 99 126 127 86 105 101 111 109 109 122 110 100 94 111 116 102 90 112 85 107 103 116 106 122 117 103 135 119 113 95 115 102 97 109 99 98 128 104 101 118 111 112 105 103 110 97 107 136 106 113 110 121 102 113 118 107 108 98 107 105 120 113 113 112 117 111 120 98 102 87 102 111 109 109 97 98 109 111 109 105 125 116 117 108 127 103 123 106 104 121 106 108 99 126 124 103 107 112 96 119 117 89 116 115 119 114 117 104 109 100 113 113 129 134 107 106 114 109 92 102 100 109 108 120 98 106 106 125 93 112 121 116 119 105 112 113 113 117 101 106 154 116 118 121 109 111 105 85 102 101 101 113 103 110 110 123 111 116 98 118 117 110 101 95 120 108 128 102 94 109 116 121 117 103 105 135 105 87 110 109 115 96 118 106 111 120 107 107 139 118 109 108 104 135 111 113 116 124 118 102 145 98 119 119 102 106 120 108 111 123 101 124 115 103 126 104 109 99 100 111 110 118 93 108 103 106 119 108 111 115 133 101 93 103 135 118 117 100 115 119 119 127 122 133 117 125 117 102 109 103 105 121 111 135 129 116 109 124 132 111 132 127 113 140 118 118 105 99 131 113 124 108 110 106 122 115 114 103 105 96 116 114 115 127 117 100 104 135 106 130 126 127 128 103 132 134 102 111 103 124 120 115 123 104 112 112 112 108 142 141 116 124 125 127 113 118 130 113 135 120 112 123 126 126 135 123 131 127 142 134 128 118 142 112 120 133 125 109 110 137 142 135 126 124 138 134 150 109 143 126 135 122 136 137 169 150 169 148 150 150 145 147 146 153 152 187 178 164 179 180 171 171 159 189 173 176 197 207 188 193 192 199 192 201 180 187 179 194 171 182 194 182 177 171 155 155 132 145 167 149 124 151 130 140 150 146 135 131 155 135 137 166 119 120 125 144 116 132 110 122 127 118 125 122 117 114 129 116 130 119 126 113 123 139 131 111 98 120 122 138 115 113 109 130 96 133 109 123 120 104 115 117 102 138 114 100 128 113 109 98 105 109 124 119 110 112 98 112 97 112 122 110 104 112 138 122 105 129 110 130 114 119 118 116 105 114 141 119 101 115 115 108 131 119 106 120 119 117 109 113 111 105 134 129 118 105 85 104 92 116 126 112 125 111 101 118 121 98 107 119 118 106 113 115 109 129 92 108 101 118 108 91 125 123 115 103 115 112 105 116 97 108 105 109 112 108 117 107 99 84 101 134 91 108 112 111 104 99 109 122 101 111 118 102 93 104 112 114 107 102 108 100 115 107 95 118 114 107 107 115 119 117 102 114 111 114 104 115 110 114 115 112 110 104 127 121 103 120 128 103 102 127 107 126 122 102 99 117 116 112 111 115 121 111 113 101 105 94 123 107 133 100 99 130 105 100 118 114 110 126 121 127 112 95 123 109 126 112 119 105 104 113 113 125 119 98 103 97 105 87 130 126 113 115 109 111 120 105 97 86 110 95 110 119 89 127 105 106 108 98 127 114 108 102 127 114 112 110 103 117 113 111 97 91 98 118 127 118 127 124 121 115 110 114 102 110 114 107 131 101 107 102 111 127 104 91 105 110 106 111 117 136 102 99 113 103 113 93 103 111 112 115 91 108 119 127 121 107 102 107 118 114 133 114 101 128 121 119 113 103 109 120 116 114 110 113 110 105 118 125 121 102 102 107 88 99 112 127 111 104 107 114 103 122 139 106 108 108 107 113 129 109 99 111 110 121 102 108 116 95 123 106 126 86 108 103 111 88 117 138 117 105 120 101 112 102 105 112 95 120 94 109 132 106 116 118 111 106 117 119 114 108 109 112 89 117 110 107 116 125 114 107 112 94 123 120 102 103 108 89 105 123 108 136 126 111 113 129 111 112 94 131 117 112 104 110 119 108 108 124 90 107 105 118 98 124 116 111 111 122 131 119 109 115 107 93 115 111 115 105 106 109 101 134 129 90 129 92 90 126 110 103 114 105 95 120 127 101 105 115 100 95 106 86 97 110 105 104 116 102 91 87 128 101 104 83 132 106 114 82 123 112 109 98 112 105 92 124 102 115 118 105 118 111 113 104 102 104 116 132 115 95 122 118 105 119 106 119 126 95 104 106 101 95 104 108 115 101 122 121 97 96 91 128 111 118 108 127 112 92 106 126 102 118 110 92 113 104 114 111 104 115 103 98 104 96 90 112 110 132 115 96 116 122 96 95 104 118 101 112 107 116 112 96 92 113 102 121 109 111 114 105 107 106 107 104 105 104 111 98 107 96 99 96 108 131 106 86 101 112 117 127 108 118 103 114 119 117 100 121 111 114 113 100 102 124 120 100 116 124 142 96 86 122 120 106 101 100 104 109 117 113 108 100 108 106 118 103 117 106 115 122 97 109 102 109 130 123 108 100 107 118 108 104 120 113 105 97 127 99 125 115 106 106 113 130 114 127 120 116 109 107 102 96 117 108 113 104 121 111 122 126 118 101 101 105 121 102 117 119 115 125 115 85 119 110 116 117 97 105 113 108 139 107 119 109 98 121 100 114 106 106 122 115 105 110 123 95 79 99 120 123 110 114 114 115 112 105 116 108 94 86 108 100 111 110 114 106 107 110 114 138 113 125 97 100 96 106 104 105 113 113 98 109 77 116 97 103 113 124 137 119 134 103 125 95 108 115 103 112 131 125 118 81 103 107 107 99 122 103 103 94 110 103 105 105 89 116 100 117 102 118 109 118 110 110 99 113 118 101 113 110 88 98 133 99 91 98 99 106 95 109 98 129 109 111 119 85 102 106 106 109 115 108 88 106 128 127 112 112 119 132 114 103 117 92 121 127 127 105 122 108 123 119 106 98 109 111 111 131 104 130 95 113 112 110 116 116 125 111 105 126 90 97 93 123 113 118 112 117 105 114 113 90 122 125 98 97 112 99 96 96 108 120 102 91 115 117 137 98 115 104 111 97 109 100 103 91 92 109 102 114 119 94 103 93 92 126 82 111 104 102 107 118 93 115 110 105 109 110 96 103 108 91 103 107 118 126 110 104 113 93 101 124 104 110 98 114 115 109 106 109 100 108 121 103 108 113 104 132 125 102 95 106 98 114 110 104 105 106 115 124 96 98 124 98 104 117 114 104 110 131 116 103 134 102 108 110 106 100 104 118 104 113 108 104 95 86 108 89 110 128 116 143 120 96 104 117 99 113 122 114 103 104 100 148 124 110 110 115 120 105 97 111 97 113 123 110 106 114 83 111 107 101 103 113 89 146 96 106 132 99 122 94 100 126 103 100 117 116 105 113 121 112 113 112 116 120 127 115 107 105 89 89 125 104 114 109 112 103 112 112 147 104 111 120 118 107 131 120 120 110 110 114 110 133 100 118 98 119 102 110 92 103 107 109 98 112 118 99 114 117 111 111 121 84 106 98 106 105 101 87 122 104 97 122 124 114 104 115 133 110 114 134 124 95 113 113 94 98 92 129 128 135 112 115 106 101 118 102 123 106 99 107 114 113 112 110 116 128 119 119 113 108 116 139 98 123 121 115 100 116 118 98 119 99 98 113 107 102 91 98 90 116 99 93 103 107 101 90 99 120 110 99 100 96 123 107 100 110 110 106 110 112 115 110 121 103 110 94 124 106 126 114 109 117 98 113 115 108 105 112 104 98 119 107 110 103 93 110 98 115 114 96 117 105 120 113 92 101 103 105 116 111 140 115 105 94 115 102 106 90 106 122 133 103 100 111 117 101 96 117 77 127 106 107 109 91 97 116 116 105 108 110 128 112 95 83 101 98 122 118 103 106 82 117 104 93 102 116 118 118 126 131 110 130 132 119 95 113 118 102 115 112 113 102 120 109 112 119 114 108 105 127 124 104 125 115 96 110 103 122 91 100 100 116 111 114 96 108 114 118 94 117 114 101 107 110 109 111 107 111 106 117 116 98 110 104 95 97 122 108 98 109 116 106 84 114 98 119 106 92 122 114 127 97 93 130 125 123 114 118 105 111 120 112 77 101 93 105 103 106 106 117 103 91 102 108 115 132 108 120 105 111 103 94 85 119 102 130 104 108 111 107 98 116 103 103 106 115 109 123 98 108 123 106 109 123 107 117 113 113 133 128 125 121 108 101 122 102 110 97 118 104 131 106 125 105 94 108 112 103 116 94 104 122 112 115 99 91 127 94 114 114 102 101 112 101 143 106 110 123 111 101 119 117 119 111 100 111 118 109 105 109 115 108 107 109 97 110 107 119 124 105 108 106 100 118 106 92 99 112 105 108 97 123 101 116 117 111 116 103 103 107 120 111 115 107 102 119 115 112 107 124 112 102 105 104 108 106 103 86 94 113 115 91 114 108 132 95 119 103 102 112 103 107 117 110 108 113 107 111 108 99 109 88 111 106 103 107 114 123 95 102 109 115 108 111 111 102 131 116 105 96 96 112 100 116 122 119 106 110 125 112 102 124 134 124 119 107 109 112 96 100 114 107 97 106 117 111 124 108 124 116 131 84 98 118 114 117 99 108 117 107 90 117 108 119 123 102 98 97 109 106 102 130 118 90 109 106 100 113 115 111 94 126 93 110 109 119 112 97 109 121 105 103 111 108 101 100 117 120 128 113 130 97 123 122 106 117 124 126 123 120 106 126 100 101 138 107 120 131 115 101 114 117 95 115 99 116 121 117 101 125 108 113 107 113 120 112 101 98 114 123 123 113 101 77 119 106 110 136 118 102 127 108 97 117 96 116 122 115 120 112 97 90 117 112 122 105 96 91 95 119 120 108 122 107 120 96 98 114 82 96 94 144 115 108 103 110 114 90 109 128 122 93 116 108 84 116 114 109 106 111 95 95 117 114 119 113 116 112 111 128 110 109 120 103 106 98 116 126 102 121 120 98 107 134 106 97 108 96 113 117 113 97 117 126 118 93 119 113 101 110 99 102 123 105 130 107 106 124 115 102 122 123 111 97 131 96 99 105 94 107 128 113 115 124 95 102 84 129 129 126 116 110 115 125 116 117 100 101 126 124 105 110 118 112 109 106 122 129 103 126 112 108 116 104 105 123 108 108 118 123 115 111 77 108 106 111 134 107 101 119 110 110 105 104 106 101 122 110 145 107 104 102 101 108 114 104 95 94 109 112 127 114 89 95 116 111 107 114 112 119 125 113 108 118 126 112 124 102 94 106 96 114 91 100 105 132 116 114 110 127 116 110 119 105 105 99 91 123 107 105 95 106 93 125 108 95 106 113 115 97 118 102 115 128 105 103 100 127 118 113 107 106 114 116 102 101 94 134 127 116 105 100 110 121 119 101 106 121 121 107 117 115 123 102 127 106 114 119 99 99 93 103 121 117 103 91 108 105 100 123 119 116 131 91 104 97 132 113 116 110 113 100 115 116 112 122 122 117 96 133 108 112 99 114 113 101 112 88 120 92 123 111 103 113 99 109 116 112 111 113 123 122 101 106 115 118 124 107 118 117 134 124 133 140 113 100 123 106 118 117 112 111 121 109 86 126 113 119 116 118 132 112 108 102 113 110 103 109 125 133 111 126 109 116 132 121 101 105 122 118 125 106 113 117 119 117 103 118 103 117 108 110 121 128 117 100 114 134 101 113 123 104 107 105 110 126 84 127 106 111 115 123 109 117 135 112 126 106 126 111 110 127 98 124 106 100 121 96 132 127 97 132 92 122 119 104 129 126 117 120 102 107 118 117 125 105 116 128 137 106 111 119 104 108 125 112 94 106 95 100 110 126 119 141 122 96 111 121 109 89 127 119 104 90 100 107 100 99 100 130 117 120 116 112 106 101 103 136 94 120 110 97 123 114 120 94 116 134 111 125 103 92 115 113 113 120 120 99 120 106 110 103 113 113 112 106 115 105 118 113 105 111 110 112 117 103 110 95 122 97 104 130 104 111 114 101 121 105 133 110 107 96 113 97 119 131 116 111 114 102 115 107 109 127 110 113 99 106 131 121 112 120 115 117 115 100 101 105 124 108 122 118 108 114 104 105 105 102 114 113 121 97 99 119 91 104 104 113 113 124 128 121 109 104 116 103 125 94 110 85 119 110 121 98 126 100 109 106 124 94 118 118 131 102 102 102 101 111 114 107 114 111 97 112 98 111 99 113 105 103 116 122 106 111 99 103 113 118 128 111 117 110 106 110 118 93 110 118 111 121 107 129 119 102 104 110 106 112 116 93 107 116 123 110 101 93 113 122 103 110 107 109 114 116 88 133 105 98 108 90 118 111 102 101 105 125 95 112 113 96 123 98 118 104 122 127 117 125 109 119 126 121 101 105 118 116 112 112 124 118 113 113 112 129 127 107 107 118 103 94 110 114 108 126 107 107 114 100 101 107 104 125 103 110 113 117 121 106 114 114 114 120 103 105 124 113 118 111 97 113 103 102 111 121 123 113 106 96 92 107 106 124 113 130 114 123 104 102 99 107 87 115 130 104 110 111 105 116 95 120 102 98 131 92 108 100 125 105 100 111 97 105 115 101 106 132 118 92 110 109 106 107 94 99 106 92 124 112 102 96 101 100 105 122 110 107 117 88 111 88 109 94 104 117 100 106 127 103 114 115 97 124 116 90 104 105 107 95 110 122 104 106 119 90 125 101 117 120 93 96 98 93 98 121 99 104 103 93 114 117 116 106 99 115 115 122 125 101 108 101 118 103 109 120 105 107 83 112 107 122 113 116 111 111 104 101 105 99 110 113 103 106 116 103 136 100 109 108 119 111 121 112 105 100 101 122 113 109 89 104 135 109 115 125 117 108 109 118 101 120 112 106 113 116 107 91 104 122 103 97 99 108 114 118 113 99 102 104 111 113 126 81 121 101 98 123 103 100 117 83 81 116 103 125 99 93 110 111 102 106 103 105 120 102 113 118 97 122 112 113 116 112 110 108 93 126 117 128 114 104 103 107 129 101 100 105 107 120 108 111 107 89 118 107 113 86 100 119 126 108 99 113 95 104 95 119 107 99 104 102 110 123 106 126 126 98 114 113 109 114 118 96 102 111 110 113 104 104 121 92 100 97 113 138 108 98 123 103 120 117 124 127 96 104 105 115 113 109 116 123 99 107 118 97 101 105 105 108 111 122 112 107 102 128 114 111 107 109 100 102 118 111 108 107 93 103 103 105 118 93 118 103 127 123 121 111 123 120 123 120 102 106 119 111 100 128 112 117 126 101 98 104 113 80 102 109 98 108 124 116 94 110 115 128 116 109 106 108 104 127 110 107 98 101 119 93 137 115 119 115 104 108 100 99 127 119 103 111 114 103 105 103 113 105 120 109 115 111 113 96 112 126 126 126 111 113 99 101 106 113 111 100 105 131 99 109 106 109 108 120 125 98 83 109 113 116 108 109 94 104 100 116 114 111 111 99 110 120 114 114 111 94 110 114 118 115 104 109 90 102 102 117 106 118 103 106 113 102 98 103 119 113 116 123 109 98 91 103 116 126 108 92 118 121 112 114 98 85 120 104 106 104 126 111 106 101 95 98 106 114 123 101 95 113 94 124 111 112 109 107 116 99 107 123 112 105 124 90 98 113 109 113 116 110 99 103 109 103 97 110 124 139 105 117 103 102 117 118 114 113 101 97 123 109 107 119 115 115 103 94 115 95 86 105 114 119 96 93 108 108 120 107 85 121 93 100 106 109 119 114 91 97 98 122 127 97 115 125 111 107 108 103 102 106 111 112 105 125 118 112 98 116 104 95 118 107 108 128 87 118 116 107 121 86 127 119 89 102 102 103 115 108 122 123 90 115 96 111 93 131 117 94 109 86 90 108 106 106 111 115 120 97 126 103 114 107 96 125 122 113 96 97 104 116 100 117 115 88 113 116 102 100 104 105 91 107 99 103 108 135 115 105 106 118 135 124 115 105 119 110 114 111 120 94 111 117 125 114 116 107 115 90 118 109 130 111 130 85 113 107 108 122 91 133 120 99 127 94 109 96 121 108 91 111 100 121 116 114 113 95 116 99 118 100 100 113 115 107 98 98 89 109 113 111 94 105 124 116 106 116 94 115 114 116 102 82 118 118 102 117 112 100 89 120 116 93 118 108 83 110 100 109 107 126 96 95 91 109 104 104 92 112 123 112 109 127 102 99 102 104 122 102 92 103 98 120 111 100 103 138 120 115 119 115 110 119 117 124 101 119 99 101 114 115 119 98 133 101 105 108 122 110 107 121 113 113 110 100 118 114 122 104 98 106 127 94 91 115 122 101 74 104 137 108 97 103 93 100 101 110 107 118 118 111 109 118 129 94 106 92 122 98 112 125 117 101 99 105 99 90 96 104 121 106 110 116 80 105 98 103 88 127 109 92 121 120 127 115 106 96 99 100 96 116 99 106 109 107 101 107 107 102 126 100 98 115 105 111 113 108 96 110 103 90 100 104 95 113 99 117 119 106 117 114 113 109 113 116 95 119 110 113 107 107 111 115 118 98 117 77 100 107 112 99 132 114 111 115 108 119 114 101 110 96 103 95 92 107 116 98 92 98 109 122 129 116 101 102 116 115 106 109 122 114 95 94 110 111 103 114 131 110 120 110 115 100 109 97 100 114 115 130 119 106 121 100 123 108 111 116 110 133 91 109 118 86 118 108 97 100 107 94 102 124 96 92 122 98 117 93 95 98 100 121 98 120 111 97 117 121 103 111 107 129 105 102 120 104 98 108 105 115 109 120 108 123 106 103 115 116 107 113 100 138 94 108 113 99 111 117 128 97 94 106 99 105 108 134 116 90 89 102 98 93 110 121 102 104 98 113 112 113 104 99 104 84 115 113 106 124 107 92 111 90 119 109 112 112 90 121 114 138 103 113 105 97 99 114 97 105 114 104 121 124 116 134 123 128 109 113 108 98 99 110 106 98 105 94 133 112 89 120 106 110 127 130 105 114 117 98 125 108 108 100 107 111 98 103 104 102 102 136 117 122 89 118 100 109 89 118 108 102 97 94 109 135 99 112 101 122 99 107 116 107 101 108 111 101 117 112 112 97 103 110 112 101 116 115 105 106 113 116 106 103 114 96 106 97 110 92 113 108 99 114 130 105 112 103 110 101 108 95 108 95 103 112 94 108 112 102 123 109 110 106 91 99 108 108 121 104 108 125 113 83 101 99 122 108 105 98 83 107 91 118 127 112 106 120 109 118 94 99 95 111 116 112 89 110 115 121 118 101 108 85 110 110 121 107 120 114 96 115 89 109 106 99 88 109 96 112 109 101 91 109 106 98 120 104 107 102 106 109 97 101 100 81 115 92 105 113 111 102 115 106 91 92 95 122 121 112 122 96 126 118 113 122 103 121 96 115 101 99 111 103 107 79 110 110 115 102 112 113 108 114 98 120 124 92 125 125 111 106 125 102 124 119 126 103 113 113 108 119 106 103 123 134 91 107 102 99 106 98 112 114 101 110 97 105 120 138 128 119 118 124 109 118 110 144 128 133 109 104 131 119 105 125 133 129 127 111 103 107 130 119 115 122 129 128 130 117 112 116 132 131 129 129 121 133 114 147 131 105 144 97 120 103 130 119 101 131 116 111 110 93 106 130 108 127 114 125 124 112 119 113 117 109 119 132 109 121 99 109 107 122 103 98 116 110 96 137 102 106 125 97 121 106 97 109 120 127 104 111 117 114 111 109 124 117 113 124 113 101 103 108 90 105 102 138 112 103 112 121 109 114 113 106 111 104 114 109 107 115 108 114 112 101 111 115 118 100 106 103 105 84 110 104 125 104 109 101 118 114 99 122 118 112 112 111 101 107 116 102 99 119 102 94 107 121 123 104 110 94 100 103 117 103 94 98 94 107 116 103 103 99 103 94 109 102 99 106 120 129 114 104 125 118 89 96 112 118 109 114 116 91 95 120 110 117 116 96 111 110 93 98 103 105 115 101 89 127 120 121 107 104 108 111 95 105 126 128 105 106 95 115 108 113 108 103 108 103 125 110 83 95 111 108 104 96 122 129 104 104 119 88 95 104 111 105 95 102 135 118 126 90 102 107 122 94 112 110 112 109 88 105 109 98 115 128 101 99 100 126 103 141 102 105 108 99 101 103 86 109 109 101 98 122 117 98 100 114 116 101 111 95 100 113 106 112 108 110 102 125 106 123 99 113 105 111 92 89 84 105 115 118 88 86 93 125 103 109 124 91 99 99 105 104 100 104 115 108 114 103 120 101 95 114 124 109 122 128 107 109 112 90 106 104 113 115 118 97 118 106 108 85 106 104 96 99 116 111 97 104 112 120 99 116 118 91 112 120 96 101 111 106 115 100 105 101 104 103 101 106 112 98 104 95 113 112 107 116 112 101 106 118 107 107 104 103 106 114 103 106 107 115 72 132 109 95 99 99 110 104 116 92 120 101 102 111 90 94 106 89 107 117 97 121 111 118 108 114 105 111 105 116 95 107 103 119 112 107 102 123 102 109 123 112 116 102 107 115 113 108 117 125 97 98 104 120 89 114 107 108 88 113 106 117 109 95 95 100 112 116 90 91 109 97 126 100 118 94 110 93 113 98 115 104 99 99 109 128 110 113 96 106 98 112 104 113 104 103 117 93 100 108 135 112 101 125 100 121 90 109 114 99 115 111 107 79 103 120 121 104 107 116 108 118 111 98 109 93 122 105 104 121 114 104 108 107 100 101 89 103 107 108 100 119 103 105 128 77 110 100 110 87 118 121 107 117 94 109 119 96 94 95 102 108 107 111 100 97 121 117 98 82 110 103 96 109 102 105 113 128 115 97 109 116 113 88 109 91 120 114 113 102 108 94 107 104 90 78 111 119 83 103 109 103 108 112 109 102 99 98 110 105 90 126 103 112 125 111 110 97 104 126 104 111 96 110 104 98 103 111 108 109 103 98 120 91 101 111 99 103 113 106 93 111 97 108 102 102 112 97 115 102 99 112 85 115 127 108 109 119 103 97 94 89 83 121 93 100 94 95 116 105 100 103 88 114 95 86 105 96 106 91 108 96 129 88 114 100 114 107 107 116 102 103 107 98 77 104 90 93 97 102 117 110 117 98 94 92 88 128 116 99 99 108 123 99 96 113 112 123 107 88 100 114 102 115 109 118 96 93 119 88 102 108 88 109 99 114 114 116 101 99 103 108 103 101 115 103 127 103 116 92 106 120 133 95 111 123 99 98 112 117 107 97 105 108 117 110 100 94 107 89 114 109 104 93 89 105 109 101 96 127 101 101 106 116 122 111 98 103 106 110 108 102 100 101 100 119 128 101 104 106 117 97 98 101 95 102 109 110 94 96 107 105 112 103 100 101 97 81 107 92 93 96 117 115 102 103 134 94 102 100 100 122 109 107 123 104 118 104 106 116 87 102 91 101 97 111 107 109 102 118 112 102 90 101 114 109 97 111 119 95 107 96 116 98 111 101 113 123 108 124 107 107 84 110 90 107 107 105 105 97 87 95 115 77 119 100 106 100 103 94 107 108 99 100 90 94 92 102 104 84 97 108 90 111 99 101 87 105 124 117 108 90 98 106 93 111 120 85 106 99 102 117 96 84 101 107 91 131 113 99 111 113 109 92 108 92 118 106 108 89 106 103 108 107 101 121 104 103 104 86 116 108 95 109 96 104 113 114 92 94 102 115 122 107 105 87 101 105 101 100 108 104 100 108 104 117 112 102 99 111 94 115 104 104 95 99 116 108 102 80 102 84 106 102 90 101 94 112 112 121 92 116 131 84 104 112 93 99 113 98 102 107 113 103 90 113 97 105 112 98 90 107 106 113 106 108 118 101 97 116 96 95 83 113 87 101 95 102 116 98 86 101 92 107 104 80 113 95 115 119 98 110 98 100 100 121 107 97 90 102 120 115 102 99 90 104 102 96 102 104 96 129 95 101 106 107 132 99 118 86 110 94 107 106 90 96 105 93 102 117 103 88 110 114 97 98 100 81 88 109 92 124 114 93 104 102 106 102 106 107 95 122 102 79 112 107 102 96 103 127 89 107 109 99 90 114 99 105 98 99 97 101 93 102 113 110 85 97 102 112 108 127 129 108 112 103 111 83 100 105 100 97 94 114 99 118 104 95 83 113 106 122 112 110 106 99 114 103 105 118 95 113 114 94 94 95 93 113 99 105 104 92 102 100 83 93 86 100 95 101 101 94 104 110 108 106 101 95 106 102 98 109 98 88 99 107 108 100 102 99 110 113 85 116 110 99 112 102 118 110 98 96 121 98 96 106 100 98 110 109 107 104 102 83 109 90 108 101 90 101 106 101 104 86 85 86 103 94 106 98 97 98 83 105 114 116 106 99 89 105 86 106 99 117 103 93 98 103 113 80 106 98 115 86 102 96 107 101 128 87 116 110 100 116 91 99 97 111 110 108 84 83 85 99 95 91 98 88 95 102 105 89 96 102 121 98 84 97 93 97 116 107 99 97 107 102 106 99 107 93 102 93 107 105 108 92 112 91 98 91 103 105 108 106 97 104 94 106 103 98 88 126 107 103 92 99 111 83 115 99 129 91 89 101 105 97 97 103 106 96 120 101 97 103 90 103 113 119 108 118 92 99 102 109 111 98 91 108 94 124 88 106 100 105 103 111 88 103 106 97 128 91 130 103 115 92 100 122 108 106 97 86 94 83 103 106 117 90 121 94 119 100 107 107 107 93 99 97 104 85 93 95 128 101 98 104 99 92 107 95 91 106 90 118 92 101 140 96 109 103 119 93 100 100 98 79 96 103 102 100 116 107 99 82 104 112 105 110 104 92 100 112 109 105 104 110 111 93 96 101 89 101 94 102 92 112 94 116 87 91 117 118 102 97 93 103 111 116 110 97 106 79 113 106 111 89 96 101 108 94 93 99 107 86 118 105 110 126 97 109 95 91 75 107 97 112 92 101 105 99 109 116 106 99 100 92 88 95 106 88 114 98 110 112 93 100 99 101 116 112 119 104 108 115 88 81 119 86 100 107 106 108 114 110 102 101 102 107 106 89 114 95 96 89 114 107 81 99 108 99 103 104 106 113 105 95 117 102 100 97 96 110 100 104 103 83 126 103 83 93 111 90 103 107 89 97 109 112 102 110 116 98 112 109 99 113 89 122 103 90 97 96 119 93 97 93 101 116 89 80 104 101 105 101 104 116 104 92 115 100 109 117 93 103 108 98 100 100 115 99 85 99 119 98 106 98 102 69 92 86 96 105 93 122 98 105 79 96 112 104 101 85 102 109 107 98 123 100 105 101 99 113 123 122 98 101 102 117 94 111 110 93 104 114 92 93 112 103 115 128 123 106 117 101 100 92 103 103 101 112 88 101 117 103 121 117 96 112 90 124 114 116 96 100 100 99 103 87 117 98 106 110 109 108 93 98 103 107 100 116 91 97 103 112 117 98 103 118 112 91 130 96 98 122 114 90 109 104 106 99 112 97 112 123 121 96 109 104 89 102 99 116 90 109 113 92 108 112 106 109 97 98 104 99 98 104 106 106 86 110 93 97 111 109 111 101 100 83 99 97 98 86 96 91 105 108 101 98 123 103 118 106 99 95 108 91 106 84 90 85 96 88 86 87 91 85 97 81 98 104 115 95 136 113 105 96 91 108 81 102 112 104 100 98 99 113 93 101 82 115 104 100 109 98 103 98 122 103 121 126 88 105 93 126 112 113 111 106 96 89 103 99 109 106 99 92 91 95 98 99 101 102 91 98 110 107 107 111 109 98 116 89 100 97 88 101 114 98 89 131 99 98 98 86 124 96 96 104 102 85 112 97 95 119 106 113 87 102 107 97 104 98 106 94 89 105 109 105 113 105 106 114 91 95 94 89 104 90 110 110 91 108 115 102 94 103 90 105 115 100 115 105 97 99 101 86 94 100 107 104 87 109 103 84 99 106 103 128 104 91 106 73 87 105 90 100 94 114 82 91 98 111 91 84 101 87 104 87 113 105 91 102 99 125 90 99 98 89 100 106 96 109 111 114 98 117 80 92 99 111 105 96 95 106 114 112 107 109 100 99 89 98 95 105 91 139 114 109 83 105 135 108 92 95 105 99 109 95 111 107 94 99 95 95 100 94 106 103 100 116 98 111 80 91 106 112 104 90 82 115 96 84 102 89 97 95 94 116 113 87 119 104 110 98 94 102 104 99 87 103 98 106 111 104 112 87 109 84 98 106 112 94 97 95 104 93 113 96 90 104 95 104 114 91 107 106 84 90 89 96 83 109 85 95 97 102 104 111 106 93 70 91 109 105 96 100 87 101 93 92 109 105 114 101 108 104 102 96 98 107 105 91 81 98 104 87 96 108 90 106 115 114 103 96 100 107 108 82 98 79 109 90 104 106 106 111 77 86 102 105 107 120 122 113 110 119 116 112 97 118 93 117 117 101 107 106 95 101 114 99 100 118 92 100 112 91 99 105 96 104 92 99 86 96 110 95 100 105 101 96 90 100 108 119 91 103 102 103 95 101 91 113 107 112 108 94 99 94 114 92 115 104 102 88 109 102 91 95 94 93 97 107 90 109 110 105 101 113 90 91 108 106 99 98 109 89 87 92 96 107 93 110 102 102 98 101 104 103 110 91 115 105 97 102 89 99 104 100 117 107 99 123 97 94 83 99 107 92 118 88 115 96 106 104 104 89 94 112 112 100 104 100 96 103 96 107 112 92 90 113 87 99 88 97 99 105 114 106 94 101 94 113 104 106 108 99 99 91 104 87 104 98 82 103 91 99 111 115 103 113 103 88 100 101 101 110 84 93 108 97 92 102 98 105 95 96 106 94 110 107 91 102 97 91 112 106 75 90 115 91 99 102 110 102 105 104 115 109 111 89 115 103 112 105 103 100 111 96 95 105 107 93 112 96 107 115 88 100 101 98 112 102 104 109 86 112 86 112 107 95 87 99 90 88 112 81 105 104 105 105 103 105 103 104 118 109 101 106 97 95 109 110 91 110 98 111 70 108 91 105 101 99 96 119 88 116 107 106 95 95 110 105 96 98 105 119 102 117 99 91 95 90 91 84 105 94 127 106 94 80 97 81 116 89 96 111 106 78 96 111 118 117 116 105 119 109 95 92 102 105 118 93 115 107 101 89 81 88 102 116 104 85 116 100 123 98 114 117 87 81 102 108 115 91 101 94 110 110 94 84 103 110 126 92 115 88 83 97 95 110 86 107 92 107 92 83 107 116 121 106 93 105 92 103 139 99 87 99 89 92 96 97 94 93 102 86 96 87 104 100 96 103 87 101 100 83 113 101 92 100 113 114 113 115 91 82 107 102 114 97 91 118 67 103 121 77 119 107 108 101 103 82 98 113 105 92 99 100 86 110 109 90 109 101 116 117 98 108 81 109 101 108 84 122 96 94 111 94 110 88 122 102 95 108 98 99 99 116 98 120 93 100 91 117 111 107 107 93 96 112 100 96 102 91 99 99 106 97 94 105 105 107 94 102 118 99 121 107 90 109 110 99 91 91 105 101 87 98 109 88 82 88 92 101 95 119 105 90 97 97 109 121 90 114 86 86 85 99 93 90 111 88 98 121 99 100 117 96 107 90 98 112 102 94 102 108 93 98 101 93 110 92 91 101 101 101 95 92 109 97 100 87 92 89 86 80 88 110 98 116 98 104 97 106 79 90 94 100 110 104 111 114 118 112 94 112 81 104 108 92 101 113 99 120 101 115 88 94 90 104 100 98 97 109 112 101 101 100 98 108 94 107 87 97 107 122 100 91 107 104 111 105 104 100 91 114 95 104 91 104 98 112 97 98 95 98 112 90 103 99 85 99 113 87 99 101 93 100 98 98 89 81 96 100 119 87 128 103 98 102 96 74 100 101 99 98 101 96 78 109 100 107 86 107 106 87 82 98 103 94 98 113 97 101 113 109 111 123 100 114 107 81 111 103 81 90 100 85 95 109 95 100 99 88 104 93 93 76 106 112 101 78 89 91 94 101 113 101 97 100 94 102 110 103 110 100 110 101 108 99 94 110 105 92 113 97 96 91 125 95 114 103 101 89 101 117 112 107 124 91 117 88 90 81 104 82 98 100 100 110 97 107 91 91 107 126 110 91 104 85 108 110 107 94 98 113 110 105 103 104 104 105 102 94 92 104 104 94 97 91 94 101 93 114 82 98 97 114 94 100 111 115 100 117 108 112 102 100 114 109 91 104 103 101 101 106 95 111 106 98 98 94 91 118 107 98 93 102 116 97 95 102 89 105 106 109 96 97 112 98 125 104 94 117 93 109 107 110 104 107 90 96 94 90 99 97 111 113 103 105 85 117 99 116 101 73 99 97 102 117 83 102 93 98 109 115 90 83 87 89 86 101 96 84 86 99 93 108 87 99 102 118 98 92 107 103 103 100 98 108 118 113 88 117 91 101 100 134 99 115 99 109 112 98 103 108 105 96 94 93 106 108 109 106 91 103 92 110 92 107 96 98 99 105 112 94 96 104 114 115 90 94 92 92 111 107 87 109 107 102 103 101 111 94 109 114 97 110 111 112 109 101 99 100 100 112 97 89 104 101 102 111 99 81 83 93 111 106 115 113 100 90 111 85 88 96 84 85 85 103 92 109 112 97 79 114 100 92 87 102 96 104 114 109 101 113 128 104 91 111 115 106 109 97 104 100 102 110 110 125 98 101 98 110 97 89 113 106 121 81 102 89 90 115 94 96 108 93 93 122 116 99 102 106 96 99 104 96 93 96 81 99 82 120 118 111 119 108 79 98 98 116 94 94 98 131 115 121 108 120 97 98 102 104 112 106 99 110 105 91 115 114 94 111 102 104 102 111 99 104 94 94 90 88 91 104 97 107 89 95 98 123 89 84 106 108 102 107 107 127 115 116 109 101 102 93 103 113 91 98 114 105 88 119 81 106 106 110 106 96 111 83 91 110 86 115 127 92 95 104 92 99 102 105 95 110 100 93 101 94 109 97 94 97 127 101 86 91 92 95 86 90 113 108 103 105 107 98 96 97 109 103 92 89 94 101 86 108 108 114 107 88 99 98 108 90 117 90 104 96 101 107 96 107 86 92 128 95 102 93 103 124 105 116 97 103 98 123 103 100 106 112 115 88 102 111 125 107 113 119 97 95 89 98 105 107 125 122 97 98 101 110 78 104 117 107 94 99 112 115 111 109 113 101 92 118 116 107 113 118 114 106 100 103 101 93 115 104 96 111 106 100 105 96 137 115 88 128 123 88 103 117 114 131 99 113 108 106 96 102 92 103 118 113 94 117 125 103 105 102 103 110 105 127 108 102 128 107 104 111 111 82 123 110 114 110 105 98 130 120 108 117 103 116 119 101 117 120 110 105 94 110 92 91 119 110 114 119 106 99 105 98 111 118 113 105 115 107 113 110 116 105 116 110 105 86 110 97 114 91 106 131 101 110 116 115 118 111 108 127 90 111 94 112 90 100 116 104 74 116 137 115 89 104 110 103 117 112 94 92 125 122 104 97 117 102 100 110 114 107 103 106 90 126 125 102 111 109 93 100 124 104 109 111 106 100 102 112 121 128 102 102 105 98 97 101 111 115 107 104 114 99 111 112 107 109 90 109 117 110 112 96 97 112 106 92 109 114 106 111 111 98 107 100 109 120 117 124 108 116 121 101 109 113 111 99 123 104 84 112 122 114 129 127 116 99 105 111 112 111 100 105 118 113 91 109 101 111 101 86 102 113 129 111 112 105 118 109 105 112 100 106 99 97 113 112 104 99 116 94 96 108 101 102 103 93 97 100 86 109 114 87 117 114 97 116 94 104 86 111 102 107 94 108 102 118 96 128 105 116 92 115 116 100 121 100 119 116 121 111 113 111 106 116 116 111 124 109 114 102 124 103 110 107 104 108 98 117 91 112 100 95 106 88 110 105 107 106 107 95 96 102 131 123 111 99 128 97 93 120 100 104 103 105 108 91 118 101 115 117 103 93 82 99 110 100 108 96 117 102 104 117 102 107 115 123 143 104 99 104 116 106 96 121 105 97 95 126 100 104 97 102 114 95 91 105 94 103 118 112 92 98 91 112 102 117 102 106 122 113 114 99 104 107 116 88 135 129 106 119 108 119 110 105 123 123 98 118 108 107 88 120 105 101 116 99 101 104 107 106 124 79 103 106 95 119 111 97 103 116 96 112 114 102 122 94 95 115 94 107 100 109 121 98 124 136 102 120 111 106 103 103 115 117 97 115 109 109 95 119 112 109 98 114 99 113 113 102 113 120 97 83 96 94 113 98 98 94 101 101 120 109 88 112 120 109 104 110 125 99 93 96 98 103 100 95 114 108 92 130 116 103 105 104 91 89 115 85 124 104 100 108 111 106 113 109 97 111 102 118 119 120 111 113 114 119 118 130 129 110 109 98 103 90 117 106 103 109 111 112 115 81 103 103 116 111 105 119 98 90 93 104 98 115 110 106 116 79 118 87 103 115 78 94 121 116 123 120 96 100 124 111 113 115 105 122 106 110 123 102 139 117 110 107 89 124 103 108 109 104 94 109 113 112 98 122 101 115 124 111 112 118 98 97 140 105 108 125 108 92 114 111 111 100 75 117 97 112 108 114 88 109 120 110 97 117 110 121 112 112 123 117 111 112 103 106 115 107 96 120 108 114 124 107 121 114 112 119 104 117 128 99 118 99 118 132 122 113 102 99 121 103 106 117 114 113 103 130 121 93 113 106 108 119 105 89 111 111 122 91 108 126 103 100 94 91 104 87 100 109 117 121 129 114 104 119 106 128 104 103 116 85 110 114 105 112 99 122 124 96 111 106 109 118 116 98 127 133 111 117 111 116 117 104 120 111 123 129 113 117 101 103 107 107 104 122 114 122 100 115 101 107 108 113 113 107 110 106 100 110 91 100 113 109 110 130 126 113 127 100 102 104 126 93 113 132 114 109 118 109 99 109 133 119 96 101 116 100 129 115 104 139 119 93 113 108 122 101 121 118 124 114 119 107 123 91 104 116 103 100 110 104 101 116 87 113 132 121 110 117 117 117 115 94 109 110 108 116 117 121 114 114 129 131 118 115 99 113 127 104 96 114 110 123 101 112 119 119 120 108 112 100 106 102 110 110 115 107 111 116 90 127 123 130 109 100 118 113 106 97 111 107 99 108 111 97 122 112 114 116 113 117 119 90 107 87 104 100 101 106 105 102 119 112 114 114 106 122 123 126 107 116 95 104 120 102 109 105 102 122 134 122 108 118 103 122 122 97 100 113 119 107 130 108 108 124 108 117 119 112 106 135 102 111 115 99 105 124 100 119 82 99 126 101 97 109 114 116 114 97 117 117 111 118 103 108 93 144 112 112 130 103 101 100 110 111 111 121 112 121 93 106 105 114 117 113 118 110 96 122 98 99 105 112 114 121 104 112 100 112 136 112 114 109 123 100 101 109 117 115 105 113 104 97 93 101 109 106 110 113 123 110 113 97 118 103 114 117 100 102 97 122 111 108 101 110 116 101 112 94 89 118 109 104 115 128 113 105 115 108 109 105 133 124 114 138 132 117 110 111 122 130 120 124 127 113 113 115 108 106 96 124 127 127 110 101 130 111 124 114 111 119 122 110 130 103 117 139 108 101 101 110 92 92 97 114 110 121 115 104 121 118 100 115 119 105 112 118 107 133 111 93 142 109 115 108 117 116 111 106 110 106 113 107 114 92 116 105 109 96 118 94 105 120 112 96 121 111 105 106 100 102 113 105 114 117 128 116 106 109 118 116 123 130 117 103 118 114 114 123 130 105 122 123 122 119 117 140 135 124 105 127 122 116 115 98 106 117 97 112 129 115 112 114 128 109 135 119 121 104 108 105 108 118 107 123 127 128 108 113 120 109 108 103 123 125 108 126 117 112 121 110 106 104 111 125 104 120 92 119 110 129 109 104 111 118 124 105 117 138 109 119 115 104 104 113 112 128 130 108 108 110 110 110 131 148 116 120 109 126 102 105 101 115 105 114 119 101 140 116 130 118 125 134 114 127 107 114 103 114 107 109 103 111 127 104 133 120 131 109 122 119 113 108 102 108 125 120 116 115 112 122 101 102 92 123 109 122 124 117 103 124 129 108 129 106 113 116 125 99 123 121 117 121 120 108 116 131 102 137 122 103 106 118 100 123 116 122 116 117 102 100 126 120 127 123 126 120 117 122 97 126 119 103 114 120 122 138 107 114 111 120 112 116 117 114 117 120 105 124 110 122 113 122 108 110 119 102 120 106 118 105 102 116 128 117 121 117 90 116 106 104 106 125 111 110 131 110 95 96 110 116 115 111 97 107 102 119 111 133 120 121 103 114 121 114 103 111 120 118 134 116 116 116 109 126 98 101 106 117 114 111 109 117 115 105 123 119 102 122 121 106 118 121 108 122 123 110 115 107 113 122 121 122 111 129 103 108 98 101 102 95 116 102 110 95 107 123 105 119 127 110 108 107 130 94 140 107 125 115 117 104 113 138 121 123 133 118 121 109 138 113 113 101 99 127 122 103 124 104 134 131 123 119 132 103 119 116 114 107 133 94 122 94 114 123 130 118 126 128 117 125 115 117 121 119 102 104 101 108 131 125</counts>
			</dataPoints>
		</scan>
	</xrdMeasurement>
</xrdMeasurements>