File: data/XRD/XG-Sauerstoff/XG-700/W6824-1B_XG_Sauerstoff_700.xrdml
<xrdMeasurements xmlns="http://www.xrdml.com/XRDMeasurement/2.1" xmlns:xsi="http://www.w3.org/2001/XMLSchema-instance" xsi:schemaLocation="http://www.xrdml.com/XRDMeasurement/2.1 http://www.xrdml.com/XRDMeasurement/2.1/XRDMeasurement.xsd" status="Completed">
	<comment>
		<entry>Configuration=Factory configuration, Owner=User-1, Creation date=7/8/2013 4:01:53 PM</entry>
		<entry>Goniometer=PW3050/65 (Theta/2Theta); Minimum step size 2Theta:0.0001; Minimum step size Omega:0.0001</entry>
		<entry>Sample stage=MRD Cradle; Minimum step size Phi:0.01; Minimum step size Chi:0.01; Minimum step size X:0.01; Minimum step size Y:0.01; Minimum step size Z:0.001</entry>
		<entry>Diffractometer system=XPERT-PRO</entry>
		<entry>Measurement program=C:\PANalytical\Data Collector\Programs\Jorrit\2thom\_absolute_2th-om_10-130deg_PIXscan_56min.xrdmp, Identifier={15BCCF57-2807-42BD-B5B9-ECC0B3DC9284}</entry>
		<entry>Batch program=C:\PANalytical\Data Collector\Programs\SimonL\batch4x_2thom_10-130°_z9.1_x0,10,20,30_y0_57min.xrdmp, Identifier={EED9823A-2BEB-424C-9252-345C4EF2834A}</entry>
	</comment>
	<sample type="To be analyzed">
		<id></id>
		<name></name>
		<preparedBy></preparedBy>
	</sample>
	<xrdMeasurement measurementType="Scan" status="Completed" sampleMode="Reflection">
		<comment>
			<entry>_absolute_2th-om_10-130deg_PIXscan_56min</entry>
			<entry>PHD Lower Level = 4.83 (keV), PHD Upper Level = 11.27 (keV)</entry>
		</comment>
		<usedWavelength intended="K-Alpha 1">
			<kAlpha1 unit="Angstrom">1.5405980</kAlpha1>
			<kAlpha2 unit="Angstrom">1.5444260</kAlpha2>
			<kBeta unit="Angstrom">1.3922500</kBeta>
			<ratioKAlpha2KAlpha1>0.5000</ratioKAlpha2KAlpha1>
		</usedWavelength>
		<incidentBeamPath>
			<radius unit="mm">320.00</radius>
			<xRayTube id="1010048" name="Empyrean Cu LFF HR (9430 033 7310x) DK442154">
				<tension unit="kV">40.0</tension>
				<current unit="mA">40.0</current>
				<anodeMaterial>Cu</anodeMaterial>
				<focus type="Line">
					<length unit="mm">12.0</length>
					<width unit="mm">0.4</width>
					<takeOffAngle unit="deg">4.2</takeOffAngle>
				</focus>
			</xRayTube>
			<xRayMirror id="27010001" name="Inc. Beam Cu W/Si (parabolic MRD)" hybrid="false">
				<crystal type="Graded" shape="Parabolic">W/Si</crystal>
				<acceptanceAngle unit="deg">0.800</acceptanceAngle>
				<length unit="mm">60.0</length>
			</xRayMirror>
			<sollerSlit id="21010002" name="Soller slits 0.04 rad.">
				<opening unit="rad">0.0400</opening>
			</sollerSlit>
			<mask id="22030007" name="Fixed mask 2 mm">
				<distanceToSample unit="mm">220.00</distanceToSample>
				<width unit="mm">2.00</width>
			</mask>
			<divergenceSlit id="22010007" name="Fixed slit 1/8°" xsi:type="fixedDivergenceSlitType">
				<distanceToSample unit="mm">220.00</distanceToSample>
				<height unit="mm">0.19</height>
			</divergenceSlit>
		</incidentBeamPath>
		<diffractedBeamPath>
			<radius unit="mm">320.00</radius>
			<sollerSlit id="21010002" name="Soller slits 0.04 rad.">
				<opening unit="rad">0.0400</opening>
			</sollerSlit>
			<receivingSlit id="22010001" name="Fixed slit 4°">
				<height unit="mm">5.88</height>
			</receivingSlit>
			<detector id="7010017" name="PIXcel3D 1x1 detector" xsi:type="areaDetectorType">
				<phd unit="%">
					<lowerLevel>30.0</lowerLevel>
					<upperLevel>70.0</upperLevel>
				</phd>
				<mode>Scanning</mode>
				<activeChannelsEquatorial>255</activeChannelsEquatorial>
				<activeChannelsAxial>255</activeChannelsAxial>
				<pitchEquatorial unit="mm">0.05500</pitchEquatorial>
				<pitchAxial unit="mm">0.05500</pitchAxial>
				<readOutPeriod unit="seconds">0.135</readOutPeriod>
			</detector>
		</diffractedBeamPath>
		<scan appendNumber="0" mode="Continuous" scanAxis="2Theta-Omega" status="Completed">
			<header>
				<startTimeStamp>2024-09-12T17:57:36+02:00</startTimeStamp>
				<endTimeStamp>2024-09-12T18:53:42+02:00</endTimeStamp>
				<author>
					<name>PRO-MRD</name>
				</author>
				<source>
					<applicationSoftware version="6.1b">Data Collector</applicationSoftware>
					<instrumentControlSoftware version="7.0E 20130304">XPERT-PRO</instrumentControlSoftware>
					<instrumentID>0000000011142674</instrumentID>
				</source>
			</header>
			<dataPoints>
				<positions axis="2Theta" unit="deg">
					<startPosition>9.99826193</startPosition>
					<endPosition>129.99755682</endPosition>
				</positions>
				<positions axis="Omega" unit="deg">
					<startPosition>4.99913096</startPosition>
					<endPosition>64.99877841</endPosition>
				</positions>
				<positions axis="Phi" unit="deg">
					<commonPosition>0.00</commonPosition>
				</positions>
				<positions axis="Chi" unit="deg">
					<commonPosition>0.00</commonPosition>
				</positions>
				<positions axis="X" unit="mm">
					<commonPosition>30.00</commonPosition>
				</positions>
				<positions axis="Y" unit="mm">
					<commonPosition>0.00</commonPosition>
				</positions>
				<positions axis="Z" unit="mm">
					<commonPosition>9.100</commonPosition>
				</positions>
				<commonCountingTime unit="seconds">32.895</commonCountingTime>
				<counts 228 226 247 237 238 200 215 208 221 215 235 237 238 210 230 236 225 249 212 226 227 210 210 240 214 213 242 212 228 236 232 225 224 212 231 217 243 210 231 219 198 224 247 239 216 235 207 269 227 258 244 229 213 211 243 233 237 223 240 214 205 223 259 241 236 260 263 258 231 220 221 241 216 235 243 234 231 215 230 245 221 227 208 187 220 222 215 201 218 231 233 225 229 212 212 216 225 228 202 233 229 217 236 190 213 216 223 241 199 239 247 187 181 192 213 188 217 229 219 221 235 242 226 205 209 233 207 219 210 211 232 229 213 209 230 235 217 235 208 221 232 209 212 237 216 225 194 197 194 188 218 212 227 229 225 207 216 216 213 232 223 244 201 228 211 219 220 212 197 206 201 209 244 211 234 228 213 210 195 221 212 206 200 204 196 215 214 212 178 226 229 214 212 226 211 200 221 239 214 213 190 210 215 199 194 221 211 231 229 207 220 203 207 199 218 200 173 202 212 202 197 195 195 233 213 181 213 191 199 194 204 186 186 209 195 216 229 204 213 222 213 213 222 174 206 212 213 200 191 227 199 200 189 219 186 201 208 205 173 187 202 205 222 198 219 198 214 191 210 221 183 195 206 204 203 210 185 223 214 193 206 200 217 193 206 169 202 213 187 198 166 200 192 214 199 196 212 188 191 208 198 194 205 191 175 200 195 170 181 195 210 184 194 201 206 171 189 177 184 192 212 167 206 204 198 208 187 187 207 199 179 197 190 200 194 214 191 176 202 177 189 190 194 192 190 171 185 191 182 197 196 179 171 199 176 211 187 187 191 189 180 202 217 183 195 217 176 168 210 196 181 187 155 188 180 184 172 165 224 181 179 200 213 166 156 193 204 181 182 179 192 172 195 182 171 207 183 183 201 186 189 156 183 182 211 179 195 212 180 157 189 188 157 175 191 158 196 189 175 190 175 173 178 182 187 185 177 193 199 182 192 181 160 175 191 171 194 197 191 185 183 184 225 175 195 202 190 163 170 152 205 176 188 169 183 183 173 164 184 172 162 177 164 187 180 184 155 180 174 182 177 166 165 183 182 162 179 171 198 177 199 187 175 180 169 170 175 172 175 190 170 152 173 184 175 180 184 199 184 195 180 166 160 183 187 198 185 207 185 180 188 193 192 187 177 189 174 178 167 152 186 152 180 183 186 155 187 183 172 167 180 171 161 183 169 172 162 173 176 163 178 171 172 202 173 188 185 176 154 167 167 164 179 169 184 176 168 174 174 187 186 157 161 171 176 182 164 197 167 172 175 176 181 154 153 182 171 165 196 169 186 177 158 170 181 165 176 172 199 180 155 165 159 158 129 150 167 164 161 181 177 178 180 168 170 163 161 174 170 173 161 166 182 180 159 184 184 173 180 133 153 183 150 176 171 190 176 160 171 183 166 187 166 176 148 140 134 185 161 164 169 160 176 167 187 166 160 187 183 170 152 201 164 179 183 162 183 177 201 172 165 152 175 182 149 198 181 170 175 153 163 196 159 136 186 167 169 166 161 151 187 180 148 161 158 147 163 156 175 158 162 175 193 173 173 188 186 167 150 175 180 162 154 169 175 153 168 154 168 206 154 176 146 190 172 177 184 172 160 177 165 192 188 152 166 162 180 179 149 183 148 165 175 155 155 184 185 164 179 166 182 153 177 175 181 184 149 181 175 166 153 183 164 192 160 158 161 149 146 199 195 170 164 173 161 146 165 169 144 165 161 188 188 174 168 165 158 164 175 193 170 133 163 162 148 169 136 185 151 150 163 149 164 184 187 180 165 177 181 160 164 150 176 152 184 163 139 171 159 174 163 160 175 176 192 194 172 165 172 153 180 193 165 163 166 166 152 173 167 182 180 167 159 209 153 180 191 163 138 161 187 178 167 150 192 155 136 189 187 143 159 170 189 162 181 168 164 155 139 163 167 169 160 156 174 169 181 178 179 172 167 170 160 158 155 154 159 163 175 132 175 155 175 172 189 160 173 185 161 169 194 175 164 157 186 182 167 173 174 173 197 182 182 169 174 180 198 165 191 209 162 158 193 186 180 165 171 166 164 190 162 168 160 180 154 152 159 168 158 170 165 169 173 173 153 176 181 184 174 181 159 176 154 166 161 194 158 177 163 155 146 174 177 175 162 149 171 187 171 153 185 176 172 186 189 169 147 180 186 165 167 189 163 158 166 161 179 169 150 171 173 173 164 149 182 174 166 180 161 181 156 164 172 164 179 172 182 166 172 152 153 145 186 202 175 182 174 154 151 180 170 169 164 190 186 161 149 155 176 165 169 159 157 170 192 152 167 172 170 188 163 163 190 162 182 185 174 154 193 171 173 170 181 177 158 168 155 183 180 183 180 168 199 193 181 185 156 168 158 164 171 184 153 187 167 176 171 170 172 191 174 177 174 185 168 195 177 172 174 161 173 198 171 176 160 176 175 173 152 167 203 157 174 191 199 169 155 138 163 167 182 179 200 170 185 177 176 197 190 181 182 165 160 192 168 178 171 176 187 159 183 191 172 180 171 165 172 157 166 186 185 175 181 180 176 191 176 191 185 161 180 192 167 173 182 161 193 176 183 151 201 180 171 167 192 180 175 169 167 169 192 174 190 176 170 198 178 177 177 199 170 157 186 165 189 187 187 169 185 163 178 158 170 189 182 170 144 189 166 190 195 160 163 173 164 199 197 167 204 177 188 170 186 178 152 174 189 194 157 165 174 158 171 164 169 160 195 172 164 174 175 182 162 182 169 162 174 169 173 163 186 188 165 166 175 187 166 160 167 194 180 185 179 181 185 174 151 170 165 176 188 191 186 162 198 173 168 170 174 184 184 210 178 159 169 178 176 177 176 192 194 168 193 179 167 187 173 187 167 176 173 183 176 177 182 199 170 175 190 167 190 187 171 158 186 179 194 173 190 165 166 215 168 187 195 164 168 147 193 200 199 177 167 171 206 156 179 204 167 173 176 170 174 153 168 165 169 180 174 179 176 151 193 197 190 167 145 185 169 170 151 167 180 177 161 151 177 191 172 176 205 162 167 159 184 156 148 173 161 149 148 175 161 167 175 182 173 151 167 165 174 155 156 154 162 189 155 192 180 188 174 167 175 175 163 174 162 162 196 159 182 158 164 155 169 184 173 167 176 157 170 180 187 165 157 180 175 181 161 149 156 168 162 177 171 148 170 180 188 147 189 162 166 180 208 161 145 184 180 172 191 190 177 165 178 176 150 170 178 181 184 173 179 160 181 172 177 162 167 158 166 168 173 161 171 179 163 164 177 179 167 147 186 174 165 162 152 159 178 193 164 179 161 156 190 165 167 160 169 178 165 185 167 170 169 169 159 171 176 166 188 172 172 167 172 183 200 174 163 160 187 177 184 181 149 169 177 168 197 156 157 165 159 155 169 141 176 147 160 160 178 142 153 163 150 156 156 153 158 152 169 176 175 163 162 175 175 162 148 175 177 186 170 179 160 168 168 158 177 152 164 165 179 148 159 174 159 153 181 168 160 161 164 160 149 172 137 171 152 164 126 173 193 177 166 149 173 177 181 181 141 168 145 175 153 184 163 150 170 157 146 162 164 147 142 193 154 156 159 144 139 151 170 150 154 142 155 150 165 158 161 173 157 151 165 171 159 196 154 148 157 145 136 135 150 154 164 148 154 144 150 142 177 165 173 142 156 157 159 151 170 167 180 163 160 172 163 173 133 151 163 166 139 163 163 149 150 165 164 157 166 171 160 179 153 175 167 165 150 165 156 151 155 163 153 153 140 138 156 157 144 157 143 169 182 153 148 145 167 157 172 160 136 171 143 129 153 168 148 161 165 167 162 141 125 160 159 165 155 139 140 146 155 148 153 164 167 163 156 161 148 157 143 155 170 168 161 134 145 164 138 152 168 183 144 164 137 157 150 154 148 135 155 152 146 140 166 163 171 155 166 156 128 142 157 162 149 153 158 128 172 169 141 148 168 154 155 145 154 141 138 154 147 138 138 154 135 135 147 165 141 153 156 168 148 156 153 116 145 183 120 136 141 153 145 144 136 146 122 151 152 140 154 153 165 144 158 135 135 154 162 143 167 152 154 135 152 162 148 137 139 162 178 162 159 128 103 106 132 160 153 151 149 151 130 150 138 122 135 142 147 154 149 149 151 142 144 133 128 131 149 138 137 132 152 170 131 141 146 149 124 159 130 146 164 149 150 156 147 142 138 148 177 149 143 140 144 134 150 160 144 142 134 144 158 162 149 139 141 125 151 126 133 168 144 152 145 144 159 136 159 143 127 130 156 132 136 165 157 129 152 143 131 145 135 148 126 147 140 145 159 146 132 132 163 143 143 141 140 155 160 140 138 139 128 145 141 126 149 160 147 137 144 137 124 125 159 170 137 134 140 128 137 145 144 122 150 126 153 116 131 151 125 145 119 129 132 139 117 133 129 143 139 150 135 143 165 138 123 147 136 146 125 127 116 122 131 130 128 128 132 113 119 144 143 139 147 145 157 136 103 132 134 125 140 145 146 142 140 149 140 127 143 139 146 134 123 141 147 151 134 143 156 158 158 131 130 143 146 129 140 130 144 130 132 136 132 133 133 155 125 145 143 145 131 146 154 133 132 145 110 130 149 122 135 144 150 125 117 116 120 105 133 131 127 124 146 143 138 152 120 141 144 127 130 156 121 121 135 145 132 144 142 129 140 136 135 142 139 132 128 116 157 123 119 128 130 134 148 162 132 132 127 143 148 148 168 155 125 131 126 147 137 127 137 143 121 142 154 143 128 137 151 122 123 142 125 128 129 129 165 115 121 140 136 134 134 134 140 136 126 146 147 123 130 132 142 130 129 147 122 141 136 115 129 123 133 132 123 122 138 137 113 134 146 122 145 120 127 137 146 135 134 130 127 118 148 144 137 129 142 145 137 132 129 138 124 141 117 124 117 117 146 103 151 145 140 140 127 132 137 142 158 130 131 140 138 121 123 112 134 91 129 122 122 148 126 120 134 126 129 127 140 129 133 127 124 137 121 121 133 126 105 156 124 108 117 140 119 121 136 132 151 131 144 117 142 142 123 141 126 145 130 126 141 108 133 111 120 125 106 126 139 128 140 137 122 130 126 122 112 104 127 134 107 121 138 133 135 126 114 127 120 109 121 125 113 127 122 142 100 136 135 122 134 135 131 140 125 131 131 135 139 134 123 134 140 122 121 133 129 124 130 122 111 132 111 147 118 136 137 123 103 128 124 118 108 114 121 123 127 136 141 120 108 134 116 137 112 116 125 114 129 136 108 117 120 111 133 119 142 157 121 120 131 156 118 135 132 150 114 132 113 129 124 138 121 131 123 119 153 116 135 114 142 112 125 136 101 132 120 119 123 121 118 125 89 119 125 109 145 141 131 137 150 132 136 146 125 117 113 145 126 127 147 129 117 127 136 122 125 136 118 130 107 102 121 133 120 117 139 99 125 106 126 106 90 136 112 122 135 111 120 127 113 127 137 105 137 116 109 139 121 135 112 140 107 125 122 120 120 126 105 135 121 118 129 123 107 131 121 137 105 128 133 131 138 140 140 129 133 143 99 110 114 129 143 116 107 92 102 125 99 120 111 127 155 112 131 130 118 137 123 140 124 139 110 130 107 113 118 130 126 115 139 127 130 117 126 124 129 127 144 131 106 105 120 128 127 120 125 122 128 137 135 125 127 106 116 142 141 116 121 111 98 141 111 116 153 135 122 103 116 142 116 117 102 130 127 129 132 120 116 100 134 99 130 137 120 95 127 136 121 131 126 138 119 116 136 127 121 138 123 126 135 122 138 137 109 127 127 104 126 118 124 124 136 132 122 107 134 112 122 125 128 112 136 138 138 116 130 115 130 123 123 129 118 116 130 118 121 121 137 119 130 127 105 133 113 126 128 129 115 121 132 111 134 123 141 113 125 119 112 141 107 122 154 108 119 122 113 129 138 150 142 137 141 120 131 120 127 141 133 136 133 120 105 139 135 115 130 127 113 117 127 111 118 117 127 126 123 125 124 130 122 135 118 114 128 115 108 109 119 122 113 129 116 130 120 115 118 139 124 120 121 121 102 109 92 136 84 129 127 119 107 128 125 143 127 107 112 100 120 133 141 131 137 147 125 130 145 131 144 139 152 124 128 142 131 133 144 153 126 147 144 134 134 164 155 136 155 146 151 146 132 144 149 117 133 137 127 126 126 121 146 110 140 125 138 127 128 127 130 124 137 122 136 103 113 124 114 120 122 134 135 123 122 103 124 135 113 118 123 101 120 138 129 126 135 121 122 132 125 102 124 129 131 148 153 138 132 132 122 119 116 132 118 115 130 113 115 110 135 122 135 116 124 115 142 125 128 107 111 102 125 107 111 134 130 123 133 104 115 126 127 117 108 128 126 138 117 132 142 129 127 141 122 126 104 125 129 130 126 119 119 121 131 129 116 146 129 126 107 118 117 129 115 139 119 122 119 125 91 108 106 123 117 126 129 108 131 116 125 132 133 110 132 122 127 111 119 130 118 133 120 122 131 118 129 118 120 125 106 114 128 125 121 119 126 134 124 128 113 138 143 109 117 125 112 92 123 126 129 123 114 119 131 116 114 107 116 126 114 120 138 100 130 122 119 116 117 119 139 127 116 123 120 124 119 121 121 111 137 133 113 133 121 103 118 106 112 120 122 101 119 127 125 103 130 133 121 117 117 135 121 108 129 126 116 112 136 115 112 115 133 128 122 119 120 124 122 120 116 114 132 137 114 130 117 118 130 121 122 127 105 122 136 116 132 123 119 123 112 121 120 126 97 126 124 116 130 116 111 140 124 112 124 111 122 108 141 110 122 123 128 101 118 129 124 116 125 135 131 144 129 118 129 138 126 115 121 139 120 133 121 122 122 131 114 117 126 141 122 133 135 106 138 132 119 120 110 119 113 120 114 128 139 118 112 114 133 120 104 111 142 111 113 100 123 112 124 122 118 112 106 114 130 121 120 103 114 130 113 120 110 150 103 112 122 105 138 129 105 130 119 122 117 134 106 132 120 153 129 105 128 136 122 110 124 128 144 140 134 111 119 143 138 121 119 125 117 153 116 129 118 129 115 132 125 107 114 130 140 112 127 126 108 115 135 120 106 110 116 118 142 127 128 100 125 119 145 142 142 124 122 116 122 106 130 96 136 134 141 131 119 119 127 121 136 118 134 125 111 121 122 133 132 127 126 114 101 126 120 97 123 128 125 106 95 123 124 124 121 119 136 124 126 135 116 139 118 123 143 134 119 115 123 119 127 124 116 127 144 102 144 120 129 125 128 120 123 144 123 125 106 122 122 133 133 133 141 145 135 123 139 128 105 145 116 124 122 112 112 122 129 142 139 121 118 125 126 116 126 116 140 119 126 117 111 119 131 125 114 125 107 111 105 117 116 131 142 120 131 136 120 124 115 126 127 108 135 108 129 117 114 106 150 130 135 122 146 120 124 152 129 120 133 162 116 98 109 128 121 116 125 131 130 144 125 139 121 133 132 120 120 129 128 130 96 147 116 114 125 136 141 129 140 135 155 124 109 123 129 127 124 115 107 136 143 133 116 126 130 116 133 135 124 141 123 125 132 130 125 142 147 127 113 127 148 126 128 127 128 131 139 131 134 150 117 134 139 120 155 132 151 106 124 144 127 134 123 110 141 131 119 143 157 112 145 133 127 111 137 108 137 124 154 146 138 139 132 144 144 148 132 150 135 149 134 128 150 141 137 157 120 142 129 154 161 134 162 139 158 139 137 143 121 131 127 131 124 154 148 137 151 144 151 147 180 154 153 184 150 148 172 172 174 184 200 169 181 180 190 210 184 197 207 220 200 221 197 220 231 218 243 242 228 229 262 208 247 221 229 200 224 198 187 197 177 193 188 194 198 174 197 187 175 159 173 151 156 156 172 147 175 147 159 156 168 144 148 135 163 131 148 155 134 158 139 139 164 144 140 149 124 126 134 125 146 124 130 111 139 131 144 132 115 127 124 152 128 132 133 127 137 142 125 114 135 142 135 135 124 102 125 139 122 135 139 126 129 112 143 145 149 156 141 120 125 123 103 109 124 139 129 129 108 140 142 133 137 119 146 131 141 113 139 133 89 120 142 131 127 163 156 123 118 146 136 144 125 134 125 128 130 113 118 124 132 117 133 117 122 136 110 119 124 105 128 141 126 130 122 128 124 114 140 120 122 114 134 115 127 128 132 119 128 127 125 121 144 121 121 134 120 120 116 121 136 99 139 127 147 128 123 113 125 127 125 120 127 132 130 129 113 119 111 121 121 121 119 108 151 103 135 115 116 126 147 110 124 118 120 128 132 138 121 137 143 127 123 127 117 111 118 107 133 135 105 117 121 108 118 117 118 120 120 118 119 154 127 122 141 128 119 142 117 134 119 123 115 124 131 115 120 137 102 119 128 117 118 128 126 128 128 144 141 132 131 137 121 125 122 127 139 130 120 130 150 124 135 148 158 123 129 110 151 118 134 120 127 140 142 121 132 128 125 124 119 125 114 128 104 132 121 121 118 120 118 139 129 122 121 119 118 143 117 124 124 118 117 104 130 123 118 118 135 137 132 155 127 128 110 138 136 104 117 102 120 130 123 142 133 115 124 117 120 129 117 116 119 125 115 129 128 103 112 136 120 109 132 119 139 132 128 127 121 142 123 111 148 110 145 136 136 119 119 135 136 114 109 139 121 115 97 115 157 118 125 142 124 121 133 129 140 114 110 121 141 125 123 124 105 125 110 142 126 106 132 136 112 117 131 114 121 135 118 128 113 118 108 122 124 124 121 113 134 138 114 129 155 132 146 138 135 134 129 157 127 125 117 119 144 127 109 114 126 142 130 123 116 124 122 130 135 134 137 136 129 123 133 140 127 126 119 118 140 126 111 117 115 121 138 126 133 149 134 113 140 119 131 111 110 121 113 135 126 129 109 118 106 133 136 138 135 136 125 133 128 119 129 127 119 135 127 122 135 118 116 141 129 103 121 131 126 122 139 136 129 135 133 123 133 123 137 152 133 141 132 125 122 133 119 129 123 123 122 135 114 122 140 118 123 135 146 135 119 140 118 115 128 138 120 148 134 132 117 122 129 146 136 123 123 121 116 113 139 125 134 122 122 111 119 108 102 133 145 126 128 132 120 134 127 115 133 116 142 131 114 131 123 146 141 125 121 131 105 157 136 141 132 140 125 125 121 142 120 107 136 129 124 117 121 115 114 125 119 136 131 132 116 108 122 116 125 127 121 122 126 140 107 127 131 108 133 144 148 115 147 138 133 126 119 126 128 123 120 115 107 143 129 106 141 118 110 137 121 135 124 141 129 114 119 130 135 131 124 117 139 134 130 154 136 108 123 136 118 127 147 132 129 126 131 123 145 122 149 115 134 112 129 122 124 129 135 129 125 122 136 139 118 130 138 134 134 103 151 116 118 123 137 94 132 148 119 118 112 122 136 119 134 127 118 126 129 134 118 96 117 138 106 121 125 129 124 132 142 122 123 122 137 120 108 106 147 102 126 128 118 132 120 115 139 131 127 123 130 132 136 144 124 128 120 154 125 120 120 121 118 143 125 125 125 142 130 126 139 128 130 123 142 133 122 114 128 131 133 131 120 128 132 141 116 105 108 125 119 119 136 126 131 119 120 120 129 137 130 129 116 118 126 125 129 113 120 127 131 139 105 127 129 131 113 137 124 123 139 133 125 109 137 133 129 123 123 132 106 126 136 117 113 145 134 139 133 124 108 140 122 128 143 118 114 111 135 101 119 129 126 126 124 141 151 103 135 144 134 115 122 113 114 124 123 139 131 153 123 128 127 120 146 127 106 110 120 143 130 111 128 115 145 109 121 134 129 140 116 121 128 114 121 143 127 127 128 118 126 119 138 118 130 141 131 138 133 131 128 137 112 147 133 129 115 124 123 119 140 141 136 155 136 117 124 132 135 138 123 116 140 133 115 146 129 118 119 122 123 109 128 124 139 118 115 122 126 123 119 116 161 128 129 111 124 134 135 134 123 121 124 119 149 138 122 127 143 137 143 138 131 130 115 124 144 128 104 131 126 132 125 121 127 140 138 115 130 127 123 131 133 144 131 111 114 137 131 123 121 139 134 135 127 127 111 121 123 116 131 124 125 135 146 128 119 120 124 133 121 119 135 119 127 113 130 119 133 111 148 127 120 111 127 124 119 123 125 130 121 117 119 121 132 138 123 139 115 127 127 126 119 126 124 125 131 122 129 108 147 131 114 123 138 128 130 136 110 111 139 133 98 115 127 123 129 130 128 141 128 142 143 132 132 156 131 123 137 116 137 146 120 124 106 139 137 131 125 113 131 143 126 123 144 118 152 128 144 118 130 137 119 130 128 124 114 126 137 130 123 116 104 116 116 109 120 117 121 147 132 130 142 138 125 111 122 108 135 126 112 122 127 152 113 124 122 123 118 132 129 137 125 130 141 144 122 136 119 111 144 138 136 126 118 139 125 123 129 109 131 127 123 120 127 135 119 137 127 140 111 150 137 111 124 121 121 124 127 140 133 132 110 131 128 149 115 129 120 146 122 126 112 116 122 124 118 139 127 133 120 121 134 133 122 124 127 130 138 142 116 141 129 135 122 130 121 136 133 129 103 109 105 131 122 131 124 114 131 137 150 123 111 146 114 128 146 124 126 133 127 126 109 126 123 118 115 128 112 126 128 123 110 134 139 126 139 117 143 140 142 113 133 142 146 101 121 137 145 137 120 114 113 134 116 122 120 137 135 128 139 154 136 138 128 155 119 116 135 124 111 127 123 137 122 120 133 123 123 120 113 147 123 109 116 125 129 138 116 130 119 127 153 113 140 129 125 129 129 123 132 117 108 151 123 139 127 121 130 137 146 153 113 143 130 130 111 123 131 116 126 117 131 118 118 128 98 132 129 146 135 121 144 133 124 120 128 121 113 121 139 107 132 127 123 124 149 127 144 123 110 129 115 139 129 108 151 119 112 114 131 122 142 134 135 139 107 138 136 140 129 118 144 125 122 109 141 129 139 115 117 158 136 150 148 136 134 121 124 124 124 137 132 119 147 126 113 124 124 112 129 113 126 111 126 130 130 119 113 124 103 118 117 137 132 108 122 139 146 144 125 129 116 122 111 115 134 126 111 123 128 114 117 126 119 118 127 133 135 137 123 128 122 124 105 132 120 126 138 119 137 112 140 117 134 118 127 154 133 126 129 139 144 121 112 131 131 127 158 119 130 121 102 120 123 130 129 123 133 123 121 129 116 140 122 117 117 132 142 133 137 139 135 128 143 154 126 128 137 142 145 116 128 129 111 129 122 127 145 134 133 108 130 124 124 126 139 130 144 138 131 124 120 118 126 131 139 142 127 124 124 146 129 111 127 134 137 146 141 163 119 144 143 125 135 103 129 143 115 111 118 112 122 123 145 132 118 141 131 124 143 139 140 149 128 142 126 136 104 136 146 120 139 141 145 138 134 131 136 134 111 128 126 135 121 145 119 138 117 136 136 128 135 127 154 128 135 119 135 126 134 156 126 125 129 140 126 123 141 145 119 126 125 140 140 119 152 127 137 118 127 121 153 117 147 129 158 132 128 124 102 120 130 134 131 134 117 129 122 113 128 119 118 126 126 105 123 119 132 142 151 147 124 145 126 141 145 141 125 138 127 125 133 131 122 125 142 150 131 147 132 137 138 134 138 142 140 141 130 113 116 139 129 151 121 147 128 133 138 143 136 136 136 132 123 137 127 126 114 131 150 151 150 138 135 125 117 132 124 130 127 129 125 140 115 124 128 122 126 126 128 158 118 117 128 119 131 129 117 132 135 122 137 137 144 117 135 128 135 132 131 135 133 135 119 119 140 144 123 141 127 138 136 147 128 140 112 128 108 131 146 152 127 106 140 127 139 111 148 130 121 155 107 140 117 124 118 140 138 144 145 163 138 136 140 144 123 133 125 128 127 144 144 132 137 117 122 124 122 117 128 119 144 130 141 129 115 123 137 153 131 128 149 133 136 131 116 136 121 131 135 131 132 149 125 142 134 138 152 136 134 120 137 141 147 134 120 121 130 131 122 128 115 125 115 138 128 122 135 138 120 121 116 129 148 126 143 117 123 146 146 169 140 114 144 136 141 150 128 117 113 121 127 146 134 106 136 148 137 136 142 138 120 117 127 133 130 149 150 140 141 126 161 146 152 146 116 138 129 118 132 125 119 134 135 137 151 131 119 132 127 128 125 143 120 127 136 125 143 121 136 138 117 129 139 132 117 131 125 156 134 120 144 122 130 126 141 151 131 128 132 108 158 146 120 134 138 129 133 131 156 133 133 114 152 144 129 146 137 131 127 157 124 135 134 134 146 129 131 155 123 134 140 133 146 138 157 142 150 134 116 172 162 121 154 127 137 124 116 134 131 130 165 149 156 134 140 150 147 143 147 148 146 153 163 123 149 134 118 125 117 156 119 144 153 131 120 139 142 150 129 148 156 143 138 131 132 144 139 144 132 132 143 129 154 153 134 121 140 135 159 123 136 129 139 134 142 139 138 146 146 129 151 130 122 119 140 143 133 134 139 138 149 141 130 158 143 137 128 157 148 126 138 126 125 125 134 145 154 127 121 137 141 129 138 131 146 150 143 121 138 114 139 135 140 137 149 132 126 167 145 113 145 128 123 145 150 132 139 154 155 138 120 146 137 153 135 143 140 142 139 132 146 122 154 145 134 149 137 139 113 122 134 152 129 114 150 156 136 133 135 143 128 123 140 145 126 122 132 142 131 129 148 145 145 134 136 144 124 151 112 121 139 142 124 129 135 143 122 135 156 141 123 133 158 130 122 126 140 125 134 131 136 122 141 145 131 135 145 137 127 133 127 160 131 130 137 126 132 129 138 149 143 134 146 130 148 131 126 139 125 136 138 138 144 124 130 137 141 147 155 133 140 134 119 142 131 132 142 145 122 131 132 113 157 126 146 133 131 125 126 148 144 107 133 127 135 140 151 131 138 134 139 132 152 146 136 131 132 137 126 134 129 117 143 137 147 153 135 153 124 119 124 149 113 135 120 126 126 157 131 118 127 124 114 139 138 125 125 134 132 116 139 136 140 137 135 133 129 140 140 124 136 149 150 156 134 140 118 151 136 120 136 132 152 128 146 146 127 120 136 137 154 133 121 127 131 160 127 141 118 132 140 146 155 138 124 137 140 148 132 152 134 128 127 154 117 129 138 143 141 138 146 144 132 127 151 101 118 132 136 126 123 131 129 113 119 121 141 132 146 119 131 147 152 127 144 121 133 145 136 151 130 127 125 126 138 146 133 136 140 121 139 142 159 148 147 122 111 148 143 122 137 123 149 134 132 134 137 149 134 139 146 131 133 154 140 128 143 138 138 146 129 153 128 143 154 131 125 137 131 143 121 131 128 133 133 132 118 134 143 124 138 158 124 137 133 140 150 119 137 151 140 141 133 167 141 146 156 147 146 129 140 129 141 126 148 136 126 130 116 128 141 108 112 139 146 139 122 151 145 145 108 126 139 140 143 133 140 142 140 144 156 148 118 135 128 116 144 119 111 162 137 119 132 131 124 138 137 155 138 123 137 147 156 126 149 144 146 119 135 129 118 143 135 122 125 137 110 160 134 145 118 137 149 133 157 139 132 117 156 139 129 130 128 130 146 120 144 133 132 138 139 137 138 116 131 156 148 150 147 144 108 128 148 133 156 155 117 139 143 133 117 138 148 127 122 142 133 131 117 128 147 119 137 138 127 152 134 126 140 134 140 130 128 143 133 139 149 125 120 129 124 143 129 138 140 138 121 142 139 133 136 133 131 114 143 118 143 137 121 130 117 154 118 125 112 134 137 147 150 143 146 137 114 151 127 134 138 132 118 136 128 138 143 157 134 148 136 136 128 131 122 135 149 119 133 131 127 106 126 137 147 119 153 116 141 142 139 157 134 120 161 122 134 148 136 131 121 142 134 114 135 137 139 133 124 147 138 132 123 143 116 129 139 143 141 128 149 143 125 128 126 128 116 124 146 162 137 150 101 142 151 135 124 136 109 157 145 151 150 124 131 152 127 133 153 136 116 142 143 135 143 133 154 165 140 136 116 117 138 118 147 136 140 151 131 145 147 125 130 125 116 134 140 163 139 128 135 134 129 133 147 146 133 132 124 143 129 140 149 143 116 140 123 146 130 149 140 117 143 163 158 165 127 136 130 124 141 137 141 138 135 138 130 118 136 148 131 150 154 145 152 133 147 127 133 153 120 96 134 116 140 128 143 150 129 129 130 147 135 137 127 132 135 146 144 127 129 140 152 148 135 137 138 143 150 133 137 162 139 121 143 135 137 156 156 134 140 165 136 113 148 132 126 121 118 139 131 124 132 125 143 134 144 126 135 139 138 127 125 123 141 143 122 142 144 138 117 147 137 147 130 155 136 134 128 130 132 128 135 117 137 136 128 146 126 136 162 141 123 126 128 133 127 128 133 141 154 147 115 161 153 137 145 138 138 156 146 137 141 170 115 126 133 142 159 143 123 135 128 146 150 133 121 134 152 139 131 145 166 150 141 159 137 115 128 140 143 138 132 122 138 140 150 134 155 121 128 130 146 137 113 162 129 135 135 117 153 145 133 138 147 136 147 144 157 142 133 143 150 148 129 132 154 134 115 140 117 142 123 138 163 122 130 129 147 136 146 137 148 142 137 144 162 147 161 153 142 148 131 121 133 143 154 137 129 153 137 141 111 132 131 135 136 98 139 165 154 128 123 117 117 161 144 136 139 162 130 119 137 127 121 123 149 128 139 159 156 146 139 149 149 123 140 132 157 120 138 134 136 134 134 135 130 145 143 132 128 128 163 136 151 138 151 145 105 128 167 129 139 161 149 145 137 150 133 143 113 143 141 147 149 147 146 139 138 155 142 114 124 141 119 123 147 123 135 140 151 133 156 129 135 138 132 150 134 140 114 137 130 137 150 107 156 141 133 156 164 138 143 149 121 141 144 122 165 141 119 135 145 118 132 134 124 128 138 123 129 134 129 156 158 148 158 124 166 150 115 134 133 132 140 140 139 142 155 129 136 142 150 135 153 143 135 142 147 123 143 142 131 147 145 144 158 138 137 136 124 159 140 134 144 132 130 139 150 132 126 153 139 105 119 138 135 123 149 127 145 156 136 136 157 136 130 131 122 136 145 143 145 120 132 124 139 151 126 144 125 139 138 147 129 128 140 118 118 127 145 137 136 145 135 157 142 125 140 131 135 137 142 149 136 142 122 138 111 141 116 126 137 152 138 133 139 149 144 119 126 125 149 147 139 143 143 155 117 131 148 138 156 118 142 151 138 138 118 122 127 150 134 114 107 147 140 133 137 132 150 144 133 144 128 148 139 121 129 155 156 130 133 131 159 149 124 160 117 140 124 128 144 139 147 147 161 141 143 127 115 152 138 139 137 142 136 138 135 137 113 145 135 132 134 122 142 119 149 143 131 133 144 129 139 129 152 120 132 141 130 134 136 147 112 132 159 136 120 134 129 146 131 145 127 131 146 131 141 141 142 141 145 127 148 138 145 131 129 117 129 159 124 125 148 152 136 134 148 143 137 138 122 118 148 152 135 128 120 145 132 142 129 95 103 138 162 126 147 125 125 120 139 139 129 152 136 134 137 136 131 136 112 152 133 121 167 140 140 125 149 135 127 134 129 164 125 145 164 133 128 138 141 148 131 137 143 149 124 122 151 152 127 135 130 154 130 119 151 127 154 155 131 154 139 119 160 139 113 156 132 152 146 159 125 124 143 119 142 137 137 141 137 136 147 144 146 145 127 140 110 137 147 156 143 135 157 137 151 134 133 136 121 149 141 153 138 138 130 139 155 129 129 119 130 149 158 147 136 130 146 144 149 146 139 142 124 124 147 151 122 157 139 163 135 146 131 144 124 149 149 142 131 145 148 135 139 133 139 121 131 136 116 125 137 168 132 170 153 137 134 158 128 140 133 148 134 153 136 131 142 163 115 150 121 128 137 139 134 139 137 133 125 144 126 119 163 124 126 153 140 126 123 149 155 120 128 114 132 141 122 142 143 126 129 154 134 148 150 124 125 137 121 136 143 137 137 133 133 141 129 153 138 127 125 142 150 126 140 142 152 146 140 136 129 143 130 144 149 143 120 149 142 130 145 128 130 131 132 142 128 136 130 131 137 137 151 142 141 143 144 125 111 147 132 121 126 120 126 112 152 123 133 141 136 129 122 139 129 143 144 137 130 140 144 140 128 133 142 150 148 163 137 142 128 140 152 158 137 120 136 134 155 165 150 147 147 121 177 150 132 131 152 133 134 146 107 147 132 154 149 144 134 152 135 140 157 128 128 162 118 119 117 144 149 143 145 147 121 146 157 138 144 138 146 154 121 125 127 126 149 169 154 146 124 148 158 173 160 157 142 150 134 141 160 150 164 124 165 140 154 149 167 141 135 144 149 148 139 139 162 165 162 167 153 131 157 165 157 130 150 148 147 171 159 161 148 163 136 175 137 155 160 160 133 177 145 114 164 137 168 141 174 143 166 167 160 163 183 144 144 150 154 170 122 175 171 139 149 162 166 148 132 145 144 149 161 133 144 129 127 147 148 144 137 151 147 147 128 149 147 163 147 135 156 147 143 127 155 157 154 147 127 137 130 155 135 146 134 124 140 147 121 140 141 129 132 144 149 118 135 138 151 133 122 125 126 113 141 143 141 136 138 128 130 136 132 154 133 134 133 152 137 142 139 139 140 148 151 138 140 146 130 148 127 118 132 132 136 134 136 136 139 134 143 154 134 120 134 139 146 139 156 169 160 134 138 154 129 124 122 161 123 139 139 139 125 143 125 126 130 155 138 151 143 133 164 147 141 120 127 129 132 164 134 147 115 125 134 152 123 125 137 154 132 128 149 154 146 146 137 150 149 136 137 150 131 139 141 156 133 136 111 125 157 150 137 147 141 133 137 132 141 137 146 132 134 124 155 127 130 117 128 123 124 135 124 141 147 125 127 140 132 143 128 132 135 147 141 144 116 129 139 138 144 130 145 135 157 148 125 159 138 134 152 142 160 121 140 165 140 146 146 132 130 128 145 121 149 124 153 151 127 125 131 136 129 140 138 137 148 146 140 135 145 148 131 117 132 139 149 124 153 143 133 141 127 148 126 147 139 118 131 138 141 136 143 142 126 149 133 131 133 150 133 144 131 140 130 140 119 142 124 142 149 130 147 135 141 136 107 116 130 139 122 133 116 130 118 127 147 129 128 139 148 145 128 137 126 139 141 137 138 142 131 141 119 148 114 156 138 124 126 136 136 135 147 135 136 114 134 114 145 131 167 139 147 134 129 121 157 138 132 149 131 151 127 150 125 119 125 142 132 134 116 143 124 155 153 115 141 141 135 134 132 126 142 124 123 135 125 138 116 148 136 140 132 134 144 129 144 135 143 108 122 135 115 157 151 150 135 140 146 139 153 148 131 150 138 161 150 132 147 162 135 132 135 132 136 156 153 148 137 159 119 148 146 135 137 156 146 124 146 141 130 134 136 146 147 148 136 148 138 127 145 141 115 132 149 138 143 134 174 146 153 128 127 142 128 141 138 127 152 124 153 130 136 129 128 138 126 156 121 137 122 133 126 133 122 135 150 136 139 154 145 138 158 129 160 152 137 129 132 111 149 139 126 137 157 135 130 135 147 134 137 153 145 112 127 151 143 136 146 149 143 133 152 128 137 140 125 141 139 132 126 156 133 130 139 144 137 122 148 126 136 131 127 150 144 148 164 121 139 135 120 125 144 149 120 126 144 133 157 135 129 136 123 153 126 124 142 141 143 153 142 135 134 147 140 124 128 144 134 135 151 130 140 142 155 129 135 138 140 134 144 142 142 131 117 138 117 141 135 144 140 127 152 148 128 120 131 124 143 115 133 128 139 145 127 138 139 113 152 143 132 165 121 130 154 148 156 163 134 157 155 136 127 131 127 120 144 123 138 138 148 144 150 155 138 125 120 134 137 153 136 126 138 107 142 127 152 115 128 133 141 170 131 154 139 132 143 145 132 145 144 139 124 145 121 158 111 139 128 135 144 129 135 136 134 135 125 146 148 128 131 139 114 142 141 152 129 134 140 118 130 142 140 152 144 139 127 125 143 135 124 126 132 136 120 140 134 135 130 145 151 132 118 141 134 130 124 122 136 151 121 137 139 127 122 135 154 125 131 139 127 130 147 143 126 133 128 135 147 130 149 163 134 160 168 150 136 135 138 141 123 122 124 123 130 151 125 172 127 140 127 145 132 139 127 139 140 156 118 122 123 117 159 121 140 123 128 138 113 152 134 125 153 133 137 131 149 109 132 135 116 148 138 129 145 131 141 142 133 153 124 141 132 122 136 129 119 139 161 152 134 151 150 148 143 142 126 126 120 120 140 126 146 142 141 138 125 146 117 110 154 161 135 123 131 129 157 118 130 139 103 135 131 144 114 116 147 134 127 135 152 137 145 131 120 135 144 135 110 128 114 145 142 119 151 148 132 145 146 135 120 138 152 127 132 149 137 126 134 135 116 129 123 149 131 124 120 149 117 128 156 145 129 132 151 138 133 128 127 136 139 120 154 137 136 137 141 130 143 163 142 124 123 129 119 112 140 124 135 141 138 117 137 117 136 135 142 152 126 137 152 125 120 133 135 125 134 139 126 137 138 145 139 136 154 116 125 108 158 136 135 119 142 124 117 149 128 147 123 137 125 121 136 139 117 143 139 118 119 135 155 133 150 126 134 135 138 141 118 115 124 131 129 149 143 157 144 137 115 126 161 133 165 112 161 153 147 140 115 125 129 123 135 126 143 126 107 111 138 130 137 141 139 131 128 147 121 140 115 118 126 111 134 118 138 132 121 127 133 136 134 140 136 144 122 102 117 121 142 154 130 138 125 110 157 136 137 142 121 131 142 117 138 122 126 146 136 137 116 118 139 123 136 145 139 142 137 178 123 166 120 124 148 144 139 147 109 138 159 134 133 112 152 146 132 127 133 123 136 134 131 165 131 113 144 133 132 147 132 135 132 126 137 122 144 137 110 122 130 137 152 149 139 116 138 137 125 141 135 120 123 133 132 134 130 139 134 152 153 137 138 131 142 127 142 126 132 131 142 143 144 123 140 140 138 135 146 126 127 152 125 135 141 149 135 119 128 131 142 157 148 145 129 136 129 158 125 156 129 120 159 147 138 122 133 137 132 147 154 131 140 105 137 139 114 136 161 123 112 140 122 142 120 138 167 139 151 164 147 147 122 126 147 127 133 121 151 125 134 143 132 142 155 137 130 128 148 147 134 152 147 132 130 131 160 132 138 123 124 143 120 139 138 126 153 129 150 145 147 131 129 121 128 136 132 132 115 147 141 119 135 125 136 135 150 130 126 140 116 154 139 123 117 129 154 144 141 113 151 145 130 133 139 147 125 119 159 139 136 140 145 148 146 144 147 171 145 122 154 124 146 144 142 139 129 153 129 130 150 141 124 126 134 159 141 130 123 121 159 148 134 124 138 119 123 122 142 154 131 129 139 142 117 125 146 142 141 151 144 121 143 120 136 128 119 127 117 127 152 123 132 148 141 105 137 146 138 129 146 136 124 141 126 153 127 163 130 142 129 133 142 115 138 143 137 126 131 128 127 151 135 134 101 162 124 122 134 127 118 143 150 131 135 116 139 142 135 136 103 144 149 128 134 136 140 140 153 143 141 145 159 141 142 147 153 179 146 139 118 142 153 152 119 130 132 144 138 141 144 126 138 128 114 161 143 134 136 134 150 124 149 134 136 133 133 137 151 133 124 168 147 148 116 136 120 149 138 120 131 133 152 123 141 146 138 135 134 135 151 127 139 118 141 141 116 155 128 155 136 159 121 141 137 120 130 136 131 132 141 140 134 128 122 108 140 146 142 149 132 147 124 159 152 134 130 129 127 138 143 119 141 139 126 135 130 146 144 140 162 135 130 141 120 137 154 153 126 154 142 131 151 137 148 142 134 135 118 135 123 134 135 130 144 128 137 103 138 141 154 143 126 161 148 163 129 127 159 141 143 151 128 143 129 156 129 152 147 137 145 124 157 129 146 156 164 126 129 103 147 112 140 130 154 151 133 131 142 124 127 131 149 146 128 153 141 150 133 131 141 135 132 133 142 136 134 133 158 176 153 119 133 116 147 131 152 116 137 124 168 152 151 142 144 143 142 132 135 156 125 153 139 128 116 135 139 140 137 133 126 120 117 140 135 140 165 143 129 136 144 148 142 128 139 142 170 141 141 140 143 156 133 142 152 145 160 147 145 144 154 152 129 137 122 137 139 144 160 151 136 132 125 150 148 139 154 155 178 138 141 159 131 121 145 136 140 153 139 152 153 145 147 148 165 134 166 128 131 130 148 158 153 137 148 116 126 131 146 133 137 158 122 134 159 128 132 147 136 151 148 150 142 143 143 129 137 135 132 135 138 133 154 141 153 147 130 138 145 136 141 142 150 149 142 130 127 141 112 133 142 133 120 142 160 138 142 148 114 134 137 140 136 144 128 118 122 146 142 142 136 119 136 148 165 125 132 136 144 155 142 134 116 141 131 146 119 152 126 132 142 123 118 130 136 138 164 138 135 136 137 130 145 119 154 152 131 129 113 131 137 123 136 150 136 125 132 136 134 133 143 131 143 123 136 113 148 131 126 146 135 137 133 155 118 161 148 141 144 136 144 157 137 126 133 139 126 138 137 123 134 128 118 119 148 97 139 144 115 164 135 152 123 148 137 132 133 147 140 159 126 159 150 128 135 130 135 122 155 127 150 130 132 118 117 142 145 123 118 141 139 129 145 140 137 137 143 122 143 128 132 138 143 138 138 137 123 118 156 117 131 144 141 136 138 145 138 136 133 132 145 125 128 142 138 143 140 130 139 158 120 141 136 133 153 148 131 152 137 123 140 121 118 136 142 127 135 141 129 145 143 141 141 135 140 139 112 137 132 144 140 138 135 140 129 128 136 118 129 119 132 116 128 131 130 120 128 134 136 146 121 123 123 130 135 136 172 133 147 123 146 142 135 126 122 129 114 138 131 119 140 153 133 135 128 160 136 153 145 118 156 123 134 112 140 148 128 151 150 147 144 134 136 142 134 121 151 125 131 140 123 157 134 134 147 114 126 153 140 155 132 142 118 130 131 161 131 147 127 144 146 142 135 145 116 148 137 142 140 135 125 126 119 132 134 122 151 127 144 134 132 142 129 137 157 125 144 151 139 121 118 151 127 135 135 126 128 132 150 142 130 117 150 137 142 111 150 161 138 132 149 145 147 130 130 134 125 144 151 138 140 132 136 130 151 153 138 140 146 132 136 156 137 117 138 100 146 135 116 137 132 145 146 129 137 138 107 149 137 127 125 126 130 135 148 155 140 119 127 139 129 122 126 139 144 143 150 135 136 131 138 132 117 156 147 133 134 146 139 117 149 130 154 138 150 136 138 153 144 136 151 147 143 142 118 125 130 134 139 119 131 126 127 149 126 136 132 126 132 130 139 156 128 147 146 136 135 121 133 137 124 130 125 149 123 130 129 126 138 121 119 131 120 146 138 141 148 139 150 136 136 123 136 143 146 133 140 107 128 135 137 142 149 142 147 125 137 136 125 122 145 156 136 113 152 134 131 158 111 132 116 130 151 107 135 137 137 145 130 103 135 125 124 162 123 129 130 120 141 131 135 128 127 122 132 139 130 115 152 136 167 151 135 135 144 132 140 116 117 139 127 132 138 156 130 136 153 144 157 169 128 139 161 115 140 119 124 142 135 120 132 129 125 129 139 147 115 137 135 135 126 132 127 138 129 134 131 119 137 111 124 161 131 130 121 150 140 135 124 133 114 123 138 157 119 116 139 136 134 128 142 141 101 131 139 119 156 122 159 141 148 146 133 126 154 142 157 136 154 133 145 142 144 118 121 162 151 129 138 135 139 143 123 143 154 123 122 137 119 141 149 149 119 129 151 146 118 117 132 136 124 124 138 130 146 150 116 137 127 134 143 125 132 124 147 140 149 138 133 153 154 141 113 130 147 120 145 119 137 145 152 147 133 134 137 140 150 133 128 120 130 142 139 140 154 143 149 120 147 151 131 132 133 152 111 144 131 140 155 113 142 149 131 140 135 127 128 157 132 126 102 141 133 143 128 130 151 139 153 153 134 153 129 139 133 133 144 134 135 133 135 120 135 156 144 161 125 141 133 143 125 117 132 124 135 125 129 126 156 148 147 135 124 135 136 143 130 128 139 124 132 130 141 138 148 142 149 139 118 144 142 114 142 149 127 133 141 124 148 141 144 140 142 125 136 142 141 134 156 140 133 138 121 145 140 149 129 131 139 157 127 138 150 129 131 124 149 109 140 134 139 128 144 155 161 131 130 120 130 146 136 124 152 106 112 136 136 141 144 149 142 133 120 142 150 152 119 141 151 144 155 140 140 122 132 119 154 137 134 153 125 130 124 130 134 154 140 118 126 121 130 117 141 137 132 140 133 107 144 125 152 154 127 131 151 134 135 123 106 133 128 121 139 150 137 149 148 133 131 127 147 161 136 140 111 120 132 137 134 143 134 144 153 153 133 124 108 128 145 133 125 139 138 135 125 141 144 168 151 138 121 129 136 121 130 157 134 145 129 136 103 160 132 129 123 137 144 115 139 115 137 135 132 139 114 145 140 134 136 113 140 111 144 139 113 130 137 122 136 157 153 136 145 123 136 155 146 133 139 141 120 130 146 151 140 137 132 173 108 138 127 140 126 140 136 138 132 139 140 137 139 147 135 132 121 148 137 117 148 141 123 147 149 156 134 149 123 140 121 138 126 154 110 126 129 141 134 134 143 119 136 112 147 146 116 139 152 138 156 129 129 142 123 132 127 144 133 126 147 140 122 134 140 144 131 131 142 120 107 141 134 148 128 126 133 133 139 121 125 134 127 127 150 135 129 139 128 148 139 154 128 138 121 159 154 143 153 117 130 134 138 132 143 136 124 140 113 134 128 129 114 147 120 134 144 126 154 136 129 131 132 148 146 138 104 116 129 144 132 119 150 147 129 145 127 131 126 157 127 137 117 126 132 133 145 146 139 129 143 143 123 135 133 136 141 134 132 139 128 155 154 144 135 126 132 143 140 136 132 146 138 149 124 134 167 127 136 132 139 135 147 116 130 127 144 115 137 142 109 138 147 114 114 141 127 138 141 120 131 148 136 147 133 139 131 160 153 145 138 137 126 156 128 128 151 143 147 117 135 155 124 146 130 123 135 122 159 129 129 105 130 138 150 148 134 152 146 122 138 120 120 146 123 129 134 132 125 118 140 129 137 124 131 156 143 132 142 138 115 150 127 127 140 119 137 112 143 135 118 130 151 123 122 128 123 116 128 131 130 146 133 118 145 130 142 140 136 130 133 145 109 126 140 160 153 110 129 133 127 153 121 123 133 143 129 141 152 137 144 135 154 144 137 115 138 140 121 134 138 147 131 154 128 131 141 130 132 154 158 135 142 129 152 127 115 130 140 120 121 130 164 135 156 128 130 141 141 122 127 122 118 130 121 117 138 149 146 126 147 113 146 138 121 136 156 149 114 138 121 142 149 114 134 147 120 125 125 137 129 127 130 126 151 144 139 133 131 117 157 136 148 157 153 140 128 126 138 131 140 146 158 159 135 130 136 156 138 146 136 126 127 130 142 119 152 114 131 127 135 156 135 136 152 144 147 153 164 151 172 125 112 131 134 133 108 121 140 137 124 131 121 135 120 138 148 137 133 124 147 148 147 119 128 138 141 134 130 140 142 135 130 124 137 143 132 107 144 154 114 136 148 146 131 118 146 147 127 138 110 130 120 151 105 141 110 137 137 139 131 111 131 128 141 118 137 139 138 142 138 132 149 118 128 123 138 141 156 139 127 127 120 154 143 147 126 150 141 132 134 127 119 111 154 145 144 153 145 137 125 135 118 117 139 116 135 127 117 123 125 138 143 127 112 126 121 147 119 144 150 118 119 123 145 127 120 157 134 129 133 157 124 139 121 132 157 147 120 142 138 132 133 116 134 128 134 128 138 138 148 130 121 134 143 140 146 149 151 155 131 153 139 119 133 156 148 134 123 129 160 137 146 139 133 133 138 140 143 125 150 144 139 122 152 144 148 143 124 169 134 164 165 140 126 135 140 151 149 121 151 135 131 148 138 151 152 128 142 132 152 146 161 155 169 155 154 127 122 137 148 135 154 132 150 149 129 134 130 142 130 175 168 143 150 145 127 150 127 142 138 156 143 135 137 151 155 140 140 148 152 127 142 159 141 135 153 140 160 148 141 164 158 131 163 142 142 130 143 152 144 132 144 146 122 120 118 148 141 132 153 146 154 129 154 133 144 132 140 142 131 136 141 131 130 138 174 117 142 135 148 131 137 130 117 129 128 154 130 144 154 122 121 145 135 135 150 132 132 139 143 152 154 130 152 144 171 142 136 145 132 158 148 139 119 140 141 143 131 142 122 120 130 136 140 139 143 152 143 167 147 152 124 143 134 119 111 139 152 139 140 153 138 144 170 144 125 128 145 129 115 120 152 158 135 134 139 130 135 137 158 152 113 127 129 129 146 141 141 149 141 143 115 138 148 130 122 149 122 123 136 139 141 138 138 144 148 153 135 131 128 132 125 142 127 157 136 134 145 134 134 144 134 115 135 167 141 156 128 140 135 136 134 124 122 132 138 125 146 132 137 162 144 126 137 152 135 137 152 144 130 143 133 134 162 135 142 137 157 126 116 117 121 136 153 141 152 138 141 151 133 146 131 135 132 123 131 133 152 125 156 156 144 122 148 145 140 157 114 134 138 126 126 105 129 145 137 124 120 134 152 139 130 123 126 161 144 126 146 131 120 122 110 134 129 133 134 131 126 151 145 147 152 141 147 129 140 151 144 136 143 133 159 141 134 136 138 131 132 107 139 139 147 121 122 138 139 159 147 144 126 156 122 148 153 155 117 132 130 148 138 137 137 140 130 141 154 140 131 138 130 133 134 136 124 117 128 132 113 137 118 116 143 131 155 137 129 129 119 125 108 150 144 141 127 148 145 135 118 154 137 151 140 133 149 135 139 149 141 146 125 146 135 123 153 131 148 125 131 156 137 154 144 120 129 123 111 108 133 156 151 133 139 135 124 127 135 152 129 130 137 131 123 116 149 148 111 140 136 142 132 142 129 137 136 148 137 124 140 121 112 115 118 139 112 155 120 117 137 123 154 138 128 129 150 128 141 142 144 132 113 127 127 118 144 146 134 134 139 140 131 150 136 135 135 152 110 149 154 118 127 163 121 144 150 129 140 134 134 143 137 130 137 131 137 132 136 143 121 138 142 121 110 132 115 111 140 132 130 156 109 151 123 130 157 145 153 146 133 134 125 113 132 117 126 136 142 130 129 120 137 162 142 125 130 139 138 122 151 128 121 131 127 144 138 146 140 121 141 125 126 139 132 119 136 127 140 133 127 119 143 139 139 137 134 144 129 126 117 148 137 129 121 153 109 114 136 129 136 129 151 142 122 127 140 132 141 141 144 126 144 142 124 127 130 129 125 129 141 158 136 141 144 129 133 137 120 142 144 129 133 112 131 120 153 143 125 138 129 149 129 126 139 140 155 152 118 142 151 137 131 152 144 143 140 120 124 120 132 140 129 125 129 125 125 143 143 129 117 129 154 135 122 137 158 129 136 138 126 163 120 157 157 143 152 134 126 138 147 128 121 117 132 135 118 132 128 138 137 124 106 136 127 158 129 148 138 117 133 146 126 119 118 120 145 144 151 137 143 123 135 114 132 138 135 132 136 151 157 157 139 149 138 141 147 125 145 148 133 109 135 141 128 127 122 152 121 134 127 131 158 153 143 146 144 140 120 127 135 132 134 128 130 123 128 137 138 133 129 136 130 123 112 144 132 141 137 139 131 117 120 156 158 149 135 142 128 156 124 121 113 125 134 160 127 140 145 150 134 132 157 144 127 131 121 156 136 149 150 135 143 121 143 132 142 145 148 124 118 145 126 128 135 130 134 148 126 132 141 117 130 141 152 127 126 129 139 146 143 141 110 132 123 133 143 134 149 139 115 146 137 113 135 139 123 140 125 141 116 117 117 116 132 126 148 125 137 140 135 148 127 126 137 134 150 119 144 138 137 118 152 124 132 134 148 127 122 128 128 134 121 134 143 158 130 119 128 127 127 137 121 126 132 125 132 125 112 147 138 164 129 122 156 120 134 132 132 138 122 143 149 145 128 137 125 115 122 124 138 140 130 98 122 117 126 120 130 139 125 135 124 140 134 146 134 132 114 122 129 131 110 135 122 123 132 119 141 132 171 140 149 121 132 132 128 127 133 149 149 143 135 152 128 110 136 140 131 129 110 150 107 122 138 136 123 165 136 148 132 126 125 136 147 133 113 147 128 141 141 132 124 129 145 129 119 132 127 136 145 143 117 126 127 119 134 123 138 129 133 140 129 140 118 120 126 112 142 137 136 138 124 106 140 142 147 131 114 137 99 133 133 139 131 129 123 146 145 133 133 126 128 123 127 137 145 130 132 163 132 147 142 149 128 138 137 117 126 125 153 141 142 133 131 141 140 130 126 131 125 131 115 136 131 121 135 131 132 135 127 130 131 119 151 126 105 140 148 112 118 155 121 129 123 122 140 110 128 138 119 141 113 137 138 118 125 128 125 120 106 147 134 132 117 141 108 145 137 141 136 136 125 120 138 132 130 153 135 155 124 152 119 153 152 142 130 144 113 139 139 115 124 124 129 127 135 142 121 123 124 110 123 118 131 133 126 141 132 124 126 120 123 128 117 160 126 137 126 139 127 143 142 150 127 113 149 137 125 130 143 145 138 137 117 123 134 138 141 127 123 129 141 129 138 123 147 129 131 139 127 105 121 141 143 131 115 128 116 145 133 137 128 146 126 131 137 116 124 150 123 149 141 145 116 128 139 123 134 125 143 120 146 132 119 125 124 123 113 158 123 126 136 115 134 128 113 134 133 117 128 137 99 151 132 134 124 126 115 145 117 120 132 141 127 149 131 133 145 129 128 137 132 121 141 140 138 119 112 124 109 142 118 123 129 137 109 135 123 140 134 131 142 139 120 120 134 135 128 128 143 115 126 127 110 97 132 130 116 129 124 137 132 150 142 123 147 129 117 136 115 124 153 136 124 136 124 140 118 137 138 133 134 135 127 116 125 140 136 158 130 130 148 129 134 140 118 123 125 117 127 128 123 125 136 136 117 141 131 127 145 120 130 132 123 135 134 120 131 132 127 125 125 125 120 111 143 122 137 137 130 121 127 121 117 118 130 124 153 137 122 134 139 119 131 117 120 125 149 129 124 131 144 140 135 134 157 142 136 138 138 135 130 115 148 159 129 124 152 132 129 120 131 143 122 142 133 134 139 126 132 129 127 105 123 137 147 121 117 141 134 140 123 116 123 134 122 138 140 121 125 113 138 123</counts>
			</dataPoints>
		</scan>
	</xrdMeasurement>
</xrdMeasurements>