File: data/XRD/XG-Sauerstoff/XG-700/W6821-1B_XG_Sauerstoff_700.xrdml
<xrdMeasurements xmlns="http://www.xrdml.com/XRDMeasurement/2.1" xmlns:xsi="http://www.w3.org/2001/XMLSchema-instance" xsi:schemaLocation="http://www.xrdml.com/XRDMeasurement/2.1 http://www.xrdml.com/XRDMeasurement/2.1/XRDMeasurement.xsd" status="Completed">
	<comment>
		<entry>Configuration=Factory configuration, Owner=User-1, Creation date=7/8/2013 4:01:53 PM</entry>
		<entry>Goniometer=PW3050/65 (Theta/2Theta); Minimum step size 2Theta:0.0001; Minimum step size Omega:0.0001</entry>
		<entry>Sample stage=MRD Cradle; Minimum step size Phi:0.01; Minimum step size Chi:0.01; Minimum step size X:0.01; Minimum step size Y:0.01; Minimum step size Z:0.001</entry>
		<entry>Diffractometer system=XPERT-PRO</entry>
		<entry>Measurement program=C:\PANalytical\Data Collector\Programs\Jorrit\2thom\_absolute_2th-om_10-130deg_PIXscan_56min.xrdmp, Identifier={15BCCF57-2807-42BD-B5B9-ECC0B3DC9284}</entry>
		<entry>Batch program=C:\PANalytical\Data Collector\Programs\SimonL\batch4x_2thom_10-130°_z9.1_x0,10,20,30_y0_57min.xrdmp, Identifier={EED9823A-2BEB-424C-9252-345C4EF2834A}</entry>
	</comment>
	<sample type="To be analyzed">
		<id></id>
		<name></name>
		<preparedBy></preparedBy>
	</sample>
	<xrdMeasurement measurementType="Scan" status="Completed" sampleMode="Reflection">
		<comment>
			<entry>_absolute_2th-om_10-130deg_PIXscan_56min</entry>
			<entry>PHD Lower Level = 4.83 (keV), PHD Upper Level = 11.27 (keV)</entry>
		</comment>
		<usedWavelength intended="K-Alpha 1">
			<kAlpha1 unit="Angstrom">1.5405980</kAlpha1>
			<kAlpha2 unit="Angstrom">1.5444260</kAlpha2>
			<kBeta unit="Angstrom">1.3922500</kBeta>
			<ratioKAlpha2KAlpha1>0.5000</ratioKAlpha2KAlpha1>
		</usedWavelength>
		<incidentBeamPath>
			<radius unit="mm">320.00</radius>
			<xRayTube id="1010048" name="Empyrean Cu LFF HR (9430 033 7310x) DK442154">
				<tension unit="kV">40.0</tension>
				<current unit="mA">40.0</current>
				<anodeMaterial>Cu</anodeMaterial>
				<focus type="Line">
					<length unit="mm">12.0</length>
					<width unit="mm">0.4</width>
					<takeOffAngle unit="deg">4.2</takeOffAngle>
				</focus>
			</xRayTube>
			<xRayMirror id="27010001" name="Inc. Beam Cu W/Si (parabolic MRD)" hybrid="false">
				<crystal type="Graded" shape="Parabolic">W/Si</crystal>
				<acceptanceAngle unit="deg">0.800</acceptanceAngle>
				<length unit="mm">60.0</length>
			</xRayMirror>
			<sollerSlit id="21010002" name="Soller slits 0.04 rad.">
				<opening unit="rad">0.0400</opening>
			</sollerSlit>
			<mask id="22030007" name="Fixed mask 2 mm">
				<distanceToSample unit="mm">220.00</distanceToSample>
				<width unit="mm">2.00</width>
			</mask>
			<divergenceSlit id="22010007" name="Fixed slit 1/8°" xsi:type="fixedDivergenceSlitType">
				<distanceToSample unit="mm">220.00</distanceToSample>
				<height unit="mm">0.19</height>
			</divergenceSlit>
		</incidentBeamPath>
		<diffractedBeamPath>
			<radius unit="mm">320.00</radius>
			<sollerSlit id="21010002" name="Soller slits 0.04 rad.">
				<opening unit="rad">0.0400</opening>
			</sollerSlit>
			<receivingSlit id="22010001" name="Fixed slit 4°">
				<height unit="mm">5.88</height>
			</receivingSlit>
			<detector id="7010017" name="PIXcel3D 1x1 detector" xsi:type="areaDetectorType">
				<phd unit="%">
					<lowerLevel>30.0</lowerLevel>
					<upperLevel>70.0</upperLevel>
				</phd>
				<mode>Scanning</mode>
				<activeChannelsEquatorial>255</activeChannelsEquatorial>
				<activeChannelsAxial>255</activeChannelsAxial>
				<pitchEquatorial unit="mm">0.05500</pitchEquatorial>
				<pitchAxial unit="mm">0.05500</pitchAxial>
				<readOutPeriod unit="seconds">0.135</readOutPeriod>
			</detector>
		</diffractedBeamPath>
		<scan appendNumber="0" mode="Continuous" scanAxis="2Theta-Omega" status="Completed">
			<header>
				<startTimeStamp>2024-09-12T15:07:49+02:00</startTimeStamp>
				<endTimeStamp>2024-09-12T16:03:51+02:00</endTimeStamp>
				<author>
					<name>PRO-MRD</name>
				</author>
				<source>
					<applicationSoftware version="6.1b">Data Collector</applicationSoftware>
					<instrumentControlSoftware version="7.0E 20130304">XPERT-PRO</instrumentControlSoftware>
					<instrumentID>0000000011142674</instrumentID>
				</source>
			</header>
			<dataPoints>
				<positions axis="2Theta" unit="deg">
					<startPosition>9.99826193</startPosition>
					<endPosition>129.99755682</endPosition>
				</positions>
				<positions axis="Omega" unit="deg">
					<startPosition>4.99913096</startPosition>
					<endPosition>64.99877841</endPosition>
				</positions>
				<positions axis="Phi" unit="deg">
					<commonPosition>0.00</commonPosition>
				</positions>
				<positions axis="Chi" unit="deg">
					<commonPosition>0.00</commonPosition>
				</positions>
				<positions axis="X" unit="mm">
					<commonPosition>0.00</commonPosition>
				</positions>
				<positions axis="Y" unit="mm">
					<commonPosition>0.00</commonPosition>
				</positions>
				<positions axis="Z" unit="mm">
					<commonPosition>9.100</commonPosition>
				</positions>
				<commonCountingTime unit="seconds">32.895</commonCountingTime>
				<counts 227 247 241 216 239 226 200 240 191 233 234 234 201 217 236 227 213 205 209 219 224 221 206 232 213 225 227 197 208 231 238 218 228 215 213 205 228 224 223 236 223 216 222 226 249 238 226 200 234 233 234 195 222 210 242 227 260 224 218 220 243 222 212 215 225 207 222 218 240 223 233 214 204 220 239 208 213 208 203 231 207 208 196 227 199 220 214 210 218 214 223 257 208 213 200 228 225 207 221 217 229 196 200 212 262 223 182 214 227 209 223 235 200 222 201 201 221 217 183 215 218 196 234 216 224 208 234 182 221 238 213 197 194 196 215 192 217 203 226 230 232 214 206 225 235 228 212 192 214 203 222 195 185 205 206 210 217 205 202 211 229 191 208 200 224 188 190 205 185 227 212 204 218 210 212 234 178 211 228 194 183 224 193 187 186 177 180 203 230 190 207 171 184 198 177 191 215 191 206 188 203 203 194 213 175 200 188 216 196 191 201 185 213 198 234 162 175 206 219 191 201 200 181 189 200 193 178 197 181 215 183 229 175 204 188 195 178 171 192 178 211 196 198 169 221 198 177 187 178 179 193 183 205 201 198 186 213 194 190 199 172 210 194 166 196 198 201 165 161 167 182 188 192 169 191 190 195 211 182 192 209 209 195 180 185 221 168 182 200 187 160 186 160 160 190 177 199 191 182 171 196 174 166 192 179 177 182 185 177 187 185 181 166 169 177 177 200 165 161 176 171 189 189 184 182 166 177 169 190 174 200 164 158 188 209 169 201 166 204 165 187 184 189 207 163 159 174 180 177 176 199 185 179 184 158 163 180 166 165 153 159 189 149 192 174 161 167 179 166 172 173 180 185 183 184 150 174 179 170 177 179 156 183 161 180 166 154 171 168 198 174 176 162 162 169 152 167 163 165 172 164 162 150 181 169 166 180 169 174 180 175 191 160 167 189 191 173 152 190 168 160 177 169 170 164 207 166 161 177 166 177 154 177 180 161 184 167 174 162 167 194 171 179 162 175 203 166 172 168 162 175 168 171 171 178 174 169 184 174 164 158 172 165 176 156 194 136 181 174 151 147 142 181 165 168 149 169 171 162 173 137 151 146 170 164 147 183 176 178 179 176 178 147 164 168 170 169 161 181 174 149 173 173 140 179 163 159 163 181 177 136 152 164 170 157 162 185 150 188 156 171 146 163 151 160 150 166 173 143 169 150 152 171 169 153 147 163 188 166 178 172 178 168 135 158 144 163 189 148 173 170 182 156 157 175 159 155 172 159 165 159 168 150 146 162 145 165 153 166 170 182 171 170 147 158 170 165 167 141 157 166 159 162 143 152 169 157 169 159 162 148 180 146 136 166 145 159 154 165 163 176 159 141 186 152 155 162 137 163 196 149 153 163 164 179 152 159 168 157 172 173 165 156 151 154 156 146 159 169 168 166 160 171 165 204 146 127 164 168 156 164 179 150 150 164 161 154 165 164 157 177 179 149 156 184 170 149 136 162 174 153 166 164 152 148 138 160 136 164 164 181 164 166 184 184 154 176 161 188 168 152 168 147 167 159 140 160 158 159 152 162 146 167 161 157 162 170 159 143 171 162 168 146 157 169 171 161 142 149 172 156 185 159 176 189 166 155 164 172 135 136 150 160 144 154 142 163 184 162 170 131 154 140 152 154 153 186 161 165 152 167 145 185 169 134 160 165 167 180 161 143 177 176 144 157 149 158 171 157 170 148 153 178 158 176 164 165 165 157 154 167 122 172 173 179 156 168 161 160 175 163 155 167 171 188 158 162 152 133 185 175 157 154 162 165 174 191 156 158 166 159 146 158 159 159 131 158 168 150 142 182 168 163 163 180 181 163 169 162 165 170 155 153 166 153 180 169 154 163 145 150 178 167 150 162 146 161 181 173 171 173 162 149 163 170 189 175 152 157 163 193 152 158 152 153 148 164 148 154 133 154 173 154 143 164 171 147 150 145 162 144 157 162 162 170 176 153 164 165 178 178 165 144 153 172 173 176 182 151 149 158 161 161 158 163 199 169 160 173 165 135 167 166 164 167 170 160 175 192 181 185 171 166 157 171 161 158 188 162 180 176 172 154 180 176 183 141 187 162 165 170 162 148 153 191 164 169 142 163 160 163 176 149 158 158 180 188 155 178 191 169 170 152 146 189 155 186 172 161 188 147 193 180 148 168 180 160 183 161 170 187 167 165 173 164 175 178 165 156 177 156 171 180 184 191 167 174 161 186 164 178 169 182 158 176 177 153 168 164 171 150 139 176 161 171 152 166 144 165 165 158 165 174 168 165 195 177 182 140 174 164 173 174 202 213 183 173 156 174 152 168 148 171 168 188 160 172 160 187 180 170 171 178 175 163 183 164 164 165 185 176 156 178 159 170 173 159 198 165 173 172 176 163 156 140 195 201 179 167 166 154 173 165 133 183 186 175 143 189 196 163 162 168 167 190 189 185 192 152 165 184 163 178 183 180 196 188 185 166 163 185 187 174 172 190 164 186 163 174 155 188 166 173 164 171 158 193 187 189 198 171 153 172 181 164 181 142 164 178 166 192 169 191 180 172 175 182 184 169 177 188 171 176 159 185 171 175 177 175 167 162 178 166 178 152 139 170 171 159 154 163 180 167 161 171 191 185 179 182 171 159 168 187 178 174 181 178 196 180 167 189 177 165 209 152 183 208 156 158 201 182 183 160 154 195 167 165 183 185 188 170 169 148 167 176 185 175 176 173 190 175 173 178 176 176 187 172 163 187 166 175 188 182 174 177 155 153 177 187 191 202 168 206 148 196 172 177 190 184 189 181 177 153 192 163 163 158 165 174 170 165 155 148 175 169 173 160 182 174 169 172 193 176 180 157 166 146 165 177 200 159 164 203 187 168 165 201 173 167 180 176 181 159 184 143 177 201 182 157 162 190 183 189 146 160 212 190 169 180 162 181 156 170 163 188 164 178 181 178 172 180 193 169 164 177 190 171 186 154 192 177 157 147 191 167 194 171 178 162 161 191 180 179 164 159 169 170 177 164 189 181 190 184 174 170 186 159 186 169 156 176 182 182 173 173 161 166 189 167 175 158 187 155 186 175 155 158 159 184 168 180 178 188 179 165 159 156 153 167 184 140 162 154 168 174 171 158 163 164 163 150 178 165 184 178 193 186 165 181 192 179 183 176 158 163 200 177 179 140 190 187 176 166 150 189 171 174 158 163 169 188 156 174 153 158 169 197 186 181 154 166 181 183 167 178 170 140 169 169 176 170 182 170 178 165 173 156 173 180 186 153 182 154 158 156 164 168 164 167 165 182 169 146 171 152 167 153 172 159 180 150 170 183 159 178 179 166 164 161 171 187 163 147 147 156 152 180 142 155 163 196 161 164 160 172 167 159 165 174 162 144 176 158 164 184 169 180 150 150 173 177 172 167 156 169 166 160 178 161 179 151 156 175 147 166 163 195 174 142 167 147 177 164 170 161 145 170 151 166 152 176 152 141 176 187 155 155 174 152 169 165 156 168 185 155 155 148 178 168 177 168 140 158 174 171 173 151 194 150 130 141 171 161 164 165 154 157 160 137 140 162 157 177 154 154 150 156 182 169 145 126 159 152 130 161 159 142 175 137 178 150 175 155 170 166 162 152 142 161 174 142 144 143 160 170 171 133 175 145 148 159 143 167 172 171 148 158 163 156 158 132 148 167 160 163 152 135 148 157 157 163 171 148 166 164 181 145 176 179 166 168 146 165 161 157 154 160 148 159 183 160 140 148 152 149 153 156 145 163 148 152 169 152 146 151 149 163 170 172 147 132 139 140 155 170 184 192 136 150 153 148 166 151 154 140 144 154 139 149 147 157 155 143 152 174 150 158 131 166 156 151 146 155 159 140 179 145 158 171 151 165 143 188 133 151 143 147 145 179 142 148 141 132 155 138 133 147 153 146 149 151 128 159 151 175 146 129 149 139 164 158 159 147 143 139 168 164 147 166 144 118 147 133 173 149 152 168 142 151 164 137 148 156 148 144 150 151 151 131 139 162 147 141 129 146 155 139 139 146 141 131 166 137 162 163 171 165 161 125 149 163 167 134 149 144 114 135 160 154 154 155 148 129 123 135 142 171 155 150 163 141 145 134 138 156 145 152 139 167 149 121 145 148 140 155 130 138 138 140 136 151 145 157 147 152 141 143 137 125 154 129 154 152 149 139 150 125 176 152 127 132 129 136 143 135 130 119 145 123 150 139 141 145 132 138 148 127 152 130 129 143 144 178 141 166 135 148 145 139 154 169 156 151 157 132 135 149 145 141 145 147 143 149 143 122 111 148 136 156 140 145 159 142 152 153 145 163 140 115 126 143 124 146 156 142 149 137 142 148 145 137 146 140 146 143 145 137 130 134 136 143 127 127 143 121 143 131 143 133 139 141 144 151 156 135 120 128 137 137 159 140 131 157 138 141 134 147 137 133 136 140 127 132 125 130 112 126 132 133 125 120 146 142 130 122 128 134 142 128 142 146 134 147 133 149 162 128 128 143 125 126 136 133 129 148 126 129 142 135 144 116 155 151 132 136 139 136 146 120 132 113 147 140 143 169 147 134 130 148 145 149 142 134 141 142 132 116 138 124 140 142 147 117 129 155 140 155 131 149 127 148 121 121 136 137 115 129 133 131 141 125 136 146 135 121 144 131 151 131 127 130 122 149 123 130 131 128 116 140 126 122 117 121 143 136 123 150 133 139 161 132 116 140 152 133 156 136 130 140 160 121 120 141 129 141 128 142 126 141 138 119 140 133 117 134 130 128 130 136 138 147 135 130 127 119 128 130 124 139 118 131 128 132 136 147 124 139 145 125 133 145 144 154 137 139 120 129 138 112 125 122 122 143 132 151 129 123 133 123 115 130 141 121 118 153 143 147 116 130 120 134 129 107 139 147 136 110 145 113 126 128 139 123 126 152 129 124 121 126 130 144 138 126 119 114 119 130 117 127 131 128 136 120 111 117 123 130 133 145 101 124 138 105 124 148 134 124 127 110 124 119 116 129 137 121 124 104 114 161 140 120 111 112 136 127 109 112 123 136 125 133 129 130 134 167 127 116 139 128 135 137 117 129 141 146 140 141 121 139 142 140 127 131 131 126 109 133 135 114 129 123 115 144 124 142 132 136 119 122 118 128 131 120 111 114 123 114 120 131 129 125 130 128 123 115 141 116 128 132 110 142 135 138 135 140 118 131 113 126 129 125 108 115 131 136 126 107 127 141 121 128 135 124 124 120 112 119 136 148 126 117 131 115 131 131 138 112 116 113 99 128 116 119 104 125 128 137 117 113 126 98 118 115 127 122 99 131 115 123 144 140 124 121 114 119 145 121 127 132 129 125 111 131 119 130 114 132 129 134 121 123 113 142 115 138 117 119 141 145 134 109 122 126 136 115 135 134 132 117 123 140 121 121 128 122 116 118 124 130 130 133 111 104 127 108 116 107 122 138 124 134 111 129 113 120 120 116 126 122 109 108 127 135 119 141 100 126 121 121 124 101 130 140 99 139 123 104 109 129 103 129 137 117 142 125 124 113 115 137 119 112 127 112 127 120 124 115 111 130 124 144 107 121 111 113 125 126 134 112 109 151 139 131 120 133 114 127 100 138 132 142 127 131 124 120 121 128 111 121 119 107 144 141 151 110 137 111 105 126 126 121 120 110 111 108 119 110 109 125 119 125 93 139 103 131 118 120 135 131 133 117 129 127 122 118 104 120 128 110 119 122 111 135 122 104 117 133 116 123 124 108 134 127 124 120 109 149 128 119 132 118 132 131 126 127 129 122 108 107 109 116 109 105 137 129 129 118 121 108 136 116 127 98 108 130 103 116 128 121 133 124 137 117 113 110 124 99 145 120 137 95 142 122 133 138 120 115 116 117 124 148 110 105 129 146 106 119 138 116 136 116 134 113 125 115 120 122 133 101 94 141 134 107 119 141 135 134 111 152 130 113 123 118 123 113 139 130 132 111 120 105 123 116 94 113 140 106 117 119 118 127 114 111 117 123 128 124 122 133 121 126 126 128 135 101 123 127 145 122 111 110 116 111 116 116 113 115 130 129 131 125 123 115 130 127 163 113 117 112 121 115 111 134 104 101 116 124 119 125 141 131 119 119 125 136 127 120 133 120 122 154 109 138 125 123 126 144 127 126 146 111 138 121 129 134 125 126 137 110 140 137 161 141 140 132 130 145 131 107 128 121 126 122 129 133 121 134 122 107 134 135 118 115 117 138 122 121 116 116 125 124 120 129 121 112 107 106 117 108 113 141 149 124 119 110 112 135 109 93 115 101 130 114 132 115 134 118 127 108 116 104 111 107 118 140 123 115 109 118 101 140 124 124 117 120 105 146 125 111 123 123 121 149 153 123 113 114 107 119 120 119 125 103 121 133 118 137 116 117 127 134 119 127 101 123 125 94 118 115 111 106 121 111 109 111 120 114 137 114 125 123 125 113 132 130 106 100 117 119 127 115 114 108 105 108 125 105 101 117 112 131 120 109 119 119 104 123 132 123 125 109 123 128 139 100 140 113 115 107 141 127 142 106 143 111 107 125 120 131 110 125 135 124 130 113 121 129 128 129 131 115 128 121 107 107 110 119 115 127 128 126 104 112 122 127 127 119 132 118 102 112 118 134 116 104 108 135 109 119 109 120 127 131 122 150 114 119 129 119 112 116 122 111 121 114 129 115 132 133 112 109 118 98 111 119 105 94 108 108 116 117 104 123 110 106 114 113 119 110 119 97 121 129 117 109 124 124 132 135 111 118 121 100 139 124 110 123 136 137 105 112 105 120 127 110 128 117 134 133 96 127 116 124 134 127 132 139 129 129 100 117 146 128 114 137 127 121 119 118 118 138 118 133 134 146 118 106 100 124 128 126 120 102 119 105 115 119 125 100 115 134 118 153 120 126 134 114 126 121 117 122 105 118 123 114 146 133 124 110 120 121 116 112 105 123 119 128 118 117 111 110 107 109 130 117 134 114 113 119 120 111 113 141 122 116 124 124 123 137 131 116 136 123 124 112 137 115 94 118 111 124 121 119 122 109 121 124 119 137 117 141 118 123 125 133 132 108 141 114 90 107 123 117 129 113 117 126 135 120 108 139 112 102 108 123 121 117 146 150 116 134 111 136 119 101 116 148 124 127 134 121 107 111 127 127 110 121 137 144 113 112 121 135 143 116 137 107 110 131 105 105 116 125 112 134 113 112 111 121 122 111 123 120 129 111 119 113 131 121 124 128 115 125 110 127 114 144 143 128 109 122 124 109 131 142 129 118 110 130 115 120 121 121 122 130 126 113 118 102 132 120 132 111 108 118 129 108 121 115 107 119 132 128 127 137 117 103 131 122 112 115 118 142 120 133 122 141 140 115 122 118 114 123 117 126 126 124 121 107 139 117 115 112 121 117 140 112 134 126 103 131 112 132 120 140 120 113 124 140 120 127 131 127 128 116 119 104 111 115 103 118 117 137 125 116 123 121 108 131 118 138 133 111 110 144 106 126 109 121 129 125 115 131 136 131 136 117 133 119 128 124 103 115 141 146 118 124 125 121 126 127 130 136 133 114 128 129 106 136 133 123 120 129 135 135 130 140 128 122 155 140 123 117 116 137 136 137 147 124 133 124 134 133 131 144 131 115 130 135 136 109 129 122 144 120 132 139 97 136 124 121 119 125 150 140 121 104 126 139 122 142 129 128 128 128 144 141 116 113 140 129 137 123 135 127 140 129 126 133 141 127 131 117 146 164 139 140 130 128 170 157 138 136 143 142 128 145 123 149 155 134 141 155 137 184 137 151 150 139 186 156 166 141 161 180 178 144 186 187 184 224 190 207 196 205 201 233 222 234 229 256 245 216 211 240 238 248 237 248 199 232 232 229 213 221 218 186 184 219 181 160 190 177 183 170 200 169 151 190 158 170 163 164 146 158 143 139 148 140 145 135 161 142 155 151 123 125 147 155 153 128 125 133 136 133 134 151 127 138 142 115 111 152 132 131 156 113 132 155 136 129 126 158 107 118 141 108 133 120 132 138 135 147 138 129 148 112 159 153 113 143 128 120 128 127 134 134 139 144 120 133 154 129 144 109 114 127 135 114 126 119 124 132 140 115 126 148 107 122 118 126 140 119 130 128 128 103 158 110 139 129 131 132 126 120 135 116 106 108 136 111 124 123 132 137 124 120 128 116 110 123 138 118 133 113 124 106 106 126 123 113 134 158 113 129 138 97 112 126 114 133 125 122 124 110 117 116 124 123 122 121 128 132 132 136 132 132 131 108 112 113 129 113 113 133 125 117 119 122 130 116 100 141 128 128 138 137 113 124 124 114 101 121 157 113 122 131 126 120 130 121 124 124 123 132 121 113 130 116 129 120 116 126 110 118 130 130 129 121 110 134 113 122 131 129 107 124 140 110 108 114 121 116 117 116 110 129 120 131 123 132 129 119 123 118 126 134 112 131 107 123 125 113 100 124 126 109 139 136 121 110 113 113 132 121 119 120 111 141 126 135 117 123 139 118 104 117 118 128 110 131 120 117 116 124 132 132 117 123 124 96 117 124 120 124 120 115 138 107 132 118 114 120 103 116 122 130 123 124 155 127 104 108 143 130 100 115 127 129 133 108 115 109 141 128 120 113 120 130 132 143 130 123 113 119 112 129 141 112 132 106 117 111 107 128 121 114 142 139 100 119 118 114 144 101 125 141 126 118 133 136 133 112 116 142 129 138 97 127 128 133 118 124 117 140 138 132 117 122 127 116 135 125 124 135 130 122 104 115 110 118 116 115 101 122 141 124 127 108 133 133 140 116 122 123 120 125 136 114 121 105 135 130 135 120 135 134 117 134 131 124 124 122 131 134 130 112 119 115 112 122 119 127 118 123 115 115 118 127 120 104 112 106 124 136 126 116 113 112 140 115 129 127 113 115 109 115 118 117 153 118 136 110 126 112 127 133 120 111 121 119 133 126 140 115 133 132 106 110 114 142 129 123 126 121 130 127 107 126 122 125 114 103 117 117 125 127 100 107 120 130 135 113 117 104 114 139 118 121 121 123 119 111 142 132 125 122 116 111 131 133 126 109 112 135 113 137 128 143 114 122 117 111 120 117 132 110 115 114 139 117 128 130 120 126 133 119 118 134 132 133 118 129 133 113 129 128 133 127 111 124 109 99 137 108 97 111 124 114 121 127 117 115 120 105 119 140 122 112 129 106 129 124 111 120 126 113 115 113 131 135 115 135 116 114 115 130 105 107 113 147 115 102 140 133 109 97 121 120 131 126 125 109 111 114 108 132 121 107 111 125 115 138 108 146 119 89 150 91 125 111 100 123 111 121 115 116 120 114 127 130 116 121 129 96 114 119 117 123 128 98 119 146 112 101 121 125 131 125 120 129 114 110 130 133 113 113 124 114 124 116 115 126 107 127 124 109 118 112 107 99 145 124 115 140 107 118 121 119 123 110 116 118 126 125 112 113 119 123 126 102 121 99 115 104 117 118 96 141 131 123 118 131 112 117 116 121 122 116 134 140 102 111 132 126 110 123 141 132 116 127 110 120 105 95 128 134 117 142 123 116 127 120 126 115 132 109 121 120 111 111 116 101 118 146 114 111 138 110 134 110 120 157 117 97 127 130 131 123 133 113 131 127 113 134 122 108 121 116 127 137 114 111 114 118 125 114 114 99 126 118 131 132 111 117 120 121 122 129 124 122 150 133 127 122 126 119 130 113 112 125 113 121 124 131 132 118 121 124 126 121 109 133 115 116 108 108 125 142 121 106 114 113 115 116 128 124 127 125 123 116 108 141 111 122 126 113 118 138 130 116 112 112 133 101 123 118 108 106 109 127 122 112 140 92 129 132 125 132 130 122 113 116 119 147 109 112 124 135 101 101 116 103 131 119 127 107 125 139 111 105 111 109 128 120 137 108 120 102 110 129 124 103 129 126 133 120 139 135 115 134 104 117 129 137 114 146 122 117 125 125 96 109 112 113 122 121 108 111 128 129 135 115 120 104 115 107 129 111 114 103 110 128 124 139 123 108 105 115 121 129 128 121 111 136 119 114 125 137 124 124 121 109 121 113 144 118 120 125 113 134 113 115 132 106 119 132 126 97 130 119 110 109 96 134 135 117 108 116 137 103 148 139 132 116 127 104 125 118 145 129 124 135 121 102 115 114 149 106 110 114 126 114 122 113 111 141 134 136 116 121 133 112 124 135 111 112 139 118 127 116 125 113 117 111 111 112 120 100 122 133 119 119 132 119 116 101 119 109 110 119 130 124 116 113 108 107 123 117 129 116 126 125 104 143 111 130 114 126 120 114 119 101 102 128 146 114 105 124 124 133 135 122 110 107 128 132 138 132 115 114 121 132 109 116 114 99 106 105 108 92 121 106 117 113 123 126 96 105 142 116 119 121 116 121 118 123 100 129 124 122 103 93 120 128 117 123 115 138 116 115 127 116 96 129 122 128 108 115 120 130 107 102 115 124 134 130 118 120 113 124 108 124 126 119 111 108 119 129 118 148 130 133 118 112 113 134 111 127 122 137 122 137 98 109 106 120 127 116 128 127 136 149 137 102 134 120 100 121 94 110 129 100 104 135 135 112 113 116 135 105 128 101 118 131 122 128 113 133 133 122 111 96 118 127 109 122 116 115 113 117 119 124 113 122 127 102 110 111 129 111 104 120 149 106 120 121 109 110 115 116 113 131 122 123 133 121 116 127 133 113 105 116 134 134 117 116 109 128 122 112 126 127 137 116 115 136 106 109 112 120 112 119 118 123 131 129 142 122 112 128 132 120 132 131 139 114 113 111 129 131 117 126 134 113 129 126 120 137 103 133 99 123 106 120 124 115 115 121 120 108 106 113 133 120 138 124 116 103 117 120 117 126 123 110 113 116 123 116 113 126 109 108 125 129 126 114 137 133 107 122 111 116 92 132 121 118 130 120 110 161 107 129 118 115 117 138 125 112 113 121 137 120 106 128 125 114 138 121 118 130 104 137 141 127 135 111 124 129 114 151 109 121 130 114 120 122 119 133 134 135 112 119 125 121 114 124 126 132 122 122 127 119 120 140 116 133 117 124 123 118 118 126 126 118 120 125 126 119 115 137 118 126 124 124 123 134 129 127 120 122 109 114 115 110 125 141 110 116 88 125 125 133 124 122 113 116 112 102 105 127 107 105 124 130 135 145 126 133 127 126 126 133 117 122 125 117 135 117 131 108 143 105 127 107 123 126 115 124 129 102 114 115 104 134 117 125 132 130 107 109 115 134 108 122 105 109 131 113 126 125 123 128 129 129 142 127 151 117 141 119 116 114 100 118 118 109 123 124 113 126 99 141 130 122 105 121 135 103 114 132 109 118 118 109 138 104 137 115 129 134 99 119 135 106 127 127 107 132 94 116 116 118 120 125 134 122 128 122 136 124 111 130 134 124 125 100 138 128 125 127 112 135 113 141 118 121 118 127 123 99 133 133 127 116 103 125 137 108 126 120 116 129 104 138 108 105 129 128 115 115 132 130 115 105 138 132 109 115 120 114 126 116 95 109 122 120 129 132 115 123 125 121 129 114 125 113 118 113 122 107 99 143 123 130 130 120 131 111 117 138 124 123 123 130 145 111 127 135 104 123 106 124 122 124 128 143 128 118 111 131 122 106 137 109 129 123 115 131 122 130 134 133 119 123 108 116 131 138 120 108 120 127 129 133 113 115 126 121 123 105 107 101 122 144 127 133 124 116 119 116 128 107 122 111 145 109 139 125 136 115 143 136 124 112 120 122 110 109 110 122 119 116 105 103 116 121 132 122 123 119 128 106 105 122 114 95 134 94 129 110 131 108 117 121 140 142 117 127 116 114 114 124 112 132 119 111 113 136 110 119 124 114 107 126 132 119 120 121 112 122 121 115 109 123 153 115 141 112 122 117 139 121 117 116 128 126 119 140 128 115 110 117 114 129 129 102 120 130 121 139 126 127 149 131 116 111 113 118 109 131 146 108 114 120 140 100 126 135 130 121 133 119 133 147 130 147 120 144 122 113 122 127 115 128 147 102 125 131 126 109 138 114 111 118 118 131 98 116 144 117 122 124 126 126 137 123 139 140 106 122 112 126 114 115 91 129 117 119 119 136 120 127 136 129 107 128 133 98 105 108 118 115 142 138 132 144 109 129 129 135 120 122 111 106 136 130 107 90 147 132 120 116 125 132 100 130 118 127 127 124 117 111 124 133 121 126 149 114 130 148 122 137 134 131 130 118 126 112 121 123 125 150 127 123 125 119 132 113 116 118 119 134 121 137 115 110 119 129 111 126 135 118 139 114 136 127 111 137 127 135 148 116 118 111 121 132 143 132 130 140 125 110 134 130 123 124 130 139 146 108 132 139 98 128 114 118 110 114 143 118 144 129 132 129 115 127 117 147 143 120 140 126 105 125 125 114 133 149 139 115 125 138 134 117 128 121 123 136 127 138 136 144 134 137 152 142 139 141 132 137 119 139 114 120 135 139 144 155 116 117 116 142 139 111 139 122 137 134 131 149 136 146 122 132 119 112 126 137 123 126 117 122 143 151 146 130 124 121 138 137 131 128 131 120 132 141 135 122 136 119 121 106 145 140 134 132 134 108 126 141 115 114 121 126 136 134 136 123 128 132 110 103 133 117 123 150 118 142 128 126 117 111 120 129 147 107 131 127 112 131 118 132 125 145 111 123 107 147 122 126 128 115 142 134 140 115 119 107 115 132 131 115 135 127 145 136 124 114 123 142 124 121 119 136 118 104 121 124 106 134 102 135 138 128 119 122 132 125 137 133 129 131 109 120 98 115 124 137 141 140 123 107 119 137 119 115 135 125 124 116 134 122 120 125 137 141 131 113 121 118 138 126 125 126 132 116 128 142 144 110 115 123 130 123 119 115 122 128 134 122 137 103 129 110 109 138 107 117 128 147 105 110 132 123 128 109 133 135 136 104 129 112 133 128 138 116 109 127 110 111 109 132 116 108 127 128 111 106 126 134 125 113 113 132 122 106 140 127 126 141 120 116 112 134 125 137 113 120 129 136 131 135 128 134 118 143 127 126 127 125 129 119 120 124 106 121 102 141 126 119 115 110 122 131 142 107 118 131 119 114 132 113 137 122 110 123 145 140 120 105 140 124 143 133 123 126 113 119 114 138 117 104 146 113 125 113 117 127 113 119 136 114 104 130 113 112 126 120 133 118 108 132 116 107 118 86 128 115 114 122 116 125 112 115 119 114 139 110 109 111 109 129 109 105 123 101 120 108 136 136 131 126 119 131 111 99 130 104 120 119 114 108 125 155 139 132 123 116 118 114 123 143 117 131 118 124 126 114 130 123 129 95 141 129 132 125 141 122 127 125 120 117 117 138 134 133 121 109 120 101 129 102 149 135 103 125 124 119 117 118 123 122 114 115 127 123 112 110 123 132 127 143 109 113 129 134 124 140 123 134 133 120 129 134 120 115 116 145 105 119 120 108 128 125 125 111 131 127 141 110 109 92 124 111 132 139 119 108 111 118 121 109 125 109 131 113 117 122 114 121 123 117 123 110 113 142 127 123 120 126 125 137 120 126 130 117 111 123 128 133 111 114 131 131 114 116 119 124 128 113 112 121 110 134 126 129 124 111 118 141 98 154 126 121 106 133 133 114 109 115 112 126 104 121 131 128 119 111 124 119 128 117 103 133 142 118 115 112 106 130 108 114 132 143 124 118 147 112 123 119 128 121 137 112 111 105 131 133 129 123 127 124 125 121 120 118 126 135 114 130 127 140 144 120 135 124 120 96 118 117 104 139 132 126 119 116 105 105 137 123 116 137 124 120 145 110 124 131 138 116 111 134 112 133 126 112 105 124 123 119 120 118 98 91 124 120 115 128 112 130 133 107 116 130 139 121 115 112 121 107 126 127 117 118 133 120 127 121 133 129 115 130 122 122 112 133 109 112 111 136 109 113 126 127 103 135 121 124 125 124 104 119 108 122 129 139 132 112 114 119 120 112 107 145 127 99 126 98 112 123 109 126 110 128 111 125 124 110 123 135 122 113 134 128 119 120 118 116 115 143 122 121 116 122 116 139 112 142 119 134 106 102 124 104 113 119 118 109 121 129 114 107 119 147 125 132 109 123 140 126 118 103 112 127 126 120 133 124 130 110 135 130 115 109 121 117 115 115 103 127 106 132 110 125 129 127 123 135 126 121 115 130 103 107 95 134 134 121 133 131 128 117 126 119 118 114 127 140 134 120 138 108 122 131 122 120 105 115 127 119 116 129 140 111 137 116 112 100 116 117 112 118 112 116 109 114 127 131 115 127 143 142 107 103 130 127 111 114 114 121 142 133 119 116 118 119 129 110 105 129 95 108 135 108 127 115 108 133 124 109 124 120 126 135 127 121 115 100 128 119 135 118 120 128 123 131 132 109 104 115 118 122 115 107 113 117 118 129 125 122 131 105 118 131 109 114 127 118 119 114 115 138 130 122 119 128 115 111 125 119 130 113 110 109 130 126 105 117 119 120 117 113 135 112 130 109 139 111 119 119 113 115 145 144 132 115 112 121 126 129 116 101 111 110 106 110 120 119 130 124 131 123 145 104 133 129 135 108 124 109 134 116 104 128 117 121 135 114 105 117 133 123 122 117 128 124 129 135 113 101 136 133 115 117 125 138 120 116 109 114 114 125 133 109 100 125 135 155 114 117 130 125 134 114 110 86 120 126 98 138 125 111 121 93 128 114 97 122 134 116 130 108 120 130 117 128 125 100 115 122 125 127 107 124 130 114 131 114 129 115 119 129 134 116 105 123 119 122 128 117 118 125 111 126 144 116 120 131 128 130 107 109 122 108 114 111 117 113 134 115 110 120 106 126 137 111 134 129 127 133 133 117 124 118 122 124 104 116 122 148 125 135 125 126 117 121 132 125 125 132 137 109 102 118 114 113 142 126 128 127 111 124 140 130 134 145 117 118 113 104 92 123 115 119 117 113 113 118 118 116 129 108 101 121 125 120 117 140 117 128 132 120 116 109 116 115 123 125 123 115 128 126 110 103 120 116 122 119 109 114 128 112 110 142 106 113 115 127 105 132 120 139 126 135 131 117 131 126 116 106 116 118 119 120 114 138 122 139 123 110 131 115 132 106 100 123 117 110 112 123 116 110 117 113 142 98 117 107 146 128 108 131 118 112 117 140 98 128 115 107 114 126 131 160 121 133 133 118 105 116 139 113 118 123 136 124 131 127 116 115 137 115 127 135 119 123 119 119 117 120 142 126 137 105 114 135 117 126 124 124 119 118 123 110 120 135 118 116 127 109 114 116 116 127 127 119 142 137 124 123 140 127 115 121 128 111 129 130 120 148 100 118 141 129 146 119 131 120 130 121 134 129 126 131 124 117 119 122 136 122 127 124 133 106 126 125 109 118 120 119 130 108 133 129 120 127 129 123 117 136 135 111 126 123 135 132 136 131 116 127 128 128 137 125 122 116 122 142 115 107 137 130 132 120 134 119 122 122 134 116 141 129 138 94 106 133 112 138 132 140 129 123 133 125 112 126 116 123 130 126 114 140 131 123 105 129 146 119 132 124 143 128 128 115 115 135 118 119 120 129 120 135 108 117 132 130 148 128 114 134 140 93 113 106 139 124 122 139 140 112 128 132 135 113 120 120 138 112 117 127 123 120 138 129 91 115 131 116 123 117 115 144 120 121 137 124 119 134 117 131 113 115 117 129 112 111 119 127 125 118 119 130 113 118 117 118 130 125 123 116 115 131 118 116 118 107 145 108 122 115 158 123 140 133 122 140 123 137 113 105 146 123 120 134 121 108 123 109 123 112 151 126 141 126 121 137 133 126 139 112 111 116 117 134 120 118 117 124 115 126 125 109 127 144 113 140 141 131 113 106 127 110 122 134 121 139 133 129 132 142 126 119 99 123 127 137 132 139 145 141 118 139 129 136 128 124 119 99 123 124 139 136 135 118 122 132 142 116 116 116 126 125 136 135 107 123 131 122 115 122 138 144 126 124 119 124 120 117 149 120 139 131 148 122 127 141 131 135 135 139 125 144 130 113 107 128 125 136 121 117 122 121 125 138 132 117 123 121 111 109 129 126 122 129 125 107 126 117 104 138 158 123 119 131 119 130 118 116 116 135 127 127 117 140 126 118 118 115 116 119 123 125 137 129 128 133 138 125 132 148 126 124 128 133 122 121 127 124 118 158 139 112 130 126 129 118 128 119 115 119 134 108 110 124 138 121 120 109 112 127 99 112 117 120 125 127 124 118 145 127 140 133 141 121 136 126 114 112 127 136 120 127 115 101 116 132 137 124 134 112 149 133 122 129 136 141 119 147 136 113 117 138 115 133 107 116 126 138 141 113 139 128 131 127 121 118 151 149 134 120 144 119 139 123 128 133 120 132 120 129 132 135 135 128 131 127 135 141 137 134 143 151 124 141 137 129 148 126 131 134 145 130 171 130 132 147 118 154 136 132 130 154 121 153 159 137 144 161 136 161 135 125 153 127 153 149 144 146 142 151 136 159 121 140 138 129 138 138 141 107 134 143 121 138 153 138 120 140 130 133 134 164 123 134 148 151 135 138 151 150 131 134 113 137 121 144 121 130 128 131 134 109 128 112 132 128 116 155 119 140 114 127 118 132 119 125 117 121 138 132 124 120 126 110 120 125 124 115 151 108 130 117 116 117 130 146 115 128 140 158 111 127 131 110 121 136 129 118 118 116 128 125 134 103 125 97 120 124 115 135 115 119 113 125 115 112 111 122 122 115 120 125 124 124 117 120 103 119 120 122 129 132 114 111 132 136 139 111 127 125 117 125 140 127 143 114 125 103 138 114 139 133 121 125 144 137 112 114 122 128 133 131 124 118 148 125 123 111 149 106 121 127 117 128 121 111 123 118 139 124 122 109 111 120 132 117 128 117 126 111 123 116 117 115 139 118 129 115 111 140 125 106 115 133 112 130 120 115 141 122 126 130 139 104 120 111 113 129 130 107 115 120 117 127 111 131 140 122 128 105 112 135 115 129 114 97 127 107 122 139 111 111 120 106 135 114 112 128 138 115 109 99 122 111 145 118 123 113 118 137 129 114 119 125 128 108 128 108 118 122 129 134 109 120 107 119 121 105 118 125 108 144 114 123 97 106 126 138 114 109 125 117 103 114 106 131 116 125 132 127 104 119 117 122 119 132 125 122 126 133 112 131 129 121 121 124 117 124 111 125 125 119 121 115 118 113 131 131 116 123 140 108 145 105 125 120 114 145 127 118 95 110 124 116 118 114 118 111 119 117 150 125 113 123 107 113 100 135 136 130 147 123 120 123 115 108 96 112 122 128 124 112 111 106 109 125 127 129 131 109 142 108 126 116 121 114 117 102 127 107 113 134 96 117 144 113 129 115 128 109 113 104 127 116 131 123 121 127 114 122 120 115 117 109 123 129 128 135 138 136 115 106 102 110 123 127 113 113 112 128 106 120 120 116 117 125 113 126 113 120 141 132 124 114 103 134 134 113 121 121 140 126 122 115 141 128 129 111 111 106 109 128 126 139 126 119 113 120 109 140 126 119 104 117 100 105 121 110 118 116 118 130 110 114 101 150 125 119 120 132 126 112 125 125 99 114 131 117 124 135 128 118 119 105 126 113 125 130 127 129 120 138 155 113 152 122 114 129 121 117 115 121 116 130 117 114 127 127 131 133 127 136 122 115 118 123 117 105 106 139 112 122 120 125 158 122 122 136 123 118 118 96 126 127 122 129 111 118 109 128 115 109 133 119 112 136 131 113 108 116 118 122 139 132 106 130 124 114 119 120 127 117 122 119 134 111 142 128 135 127 126 129 100 122 107 136 118 119 118 133 124 121 137 124 118 118 120 133 120 115 140 117 116 117 112 128 111 131 109 106 105 106 116 121 103 129 134 126 101 126 113 107 130 121 111 109 136 120 120 110 131 114 120 104 122 126 128 137 115 134 104 122 132 99 126 113 125 109 105 112 123 108 102 110 128 136 137 120 113 152 117 121 97 102 129 115 111 115 117 116 124 125 115 144 122 129 121 127 127 125 124 145 108 120 119 114 115 142 127 126 139 131 136 113 118 118 117 121 106 103 114 116 118 118 132 123 126 129 99 117 122 118 114 113 126 101 109 127 138 109 133 127 120 116 115 125 124 123 117 129 132 118 145 106 114 110 118 118 117 121 115 102 125 121 128 125 131 118 123 127 120 110 130 120 122 113 132 116 113 98 105 113 120 117 93 104 102 114 116 106 107 125 121 122 122 116 123 106 122 97 118 114 150 104 100 98 122 121 132 133 114 125 143 92 112 131 127 116 115 136 118 131 117 128 112 131 119 99 115 124 99 119 111 105 130 132 131 128 120 128 117 115 124 139 131 129 138 99 116 127 141 108 132 112 124 118 125 113 113 121 132 97 104 118 146 123 136 120 137 123 110 113 133 126 118 110 118 115 114 131 121 113 112 121 118 126 140 141 108 138 135 118 153 106 117 125 105 121 133 118 133 122 118 118 113 122 135 127 132 138 120 118 120 120 114 103 125 132 87 112 133 110 119 125 113 134 124 121 111 121 116 131 127 136 104 120 93 125 144 141 119 108 109 127 109 97 116 115 122 121 113 104 117 111 105 118 118 106 119 118 112 115 132 130 122 119 120 114 110 125 106 127 146 117 126 123 105 132 121 110 115 111 126 116 102 119 122 114 153 120 130 105 138 100 106 135 133 112 114 123 117 109 115 127 125 115 140 108 114 105 129 104 115 121 134 126 135 120 110 135 117 125 119 129 121 111 116 114 121 103 116 113 116 104 125 109 110 129 125 138 96 109 106 136 119 108 104 112 121 127 123 115 105 123 108 129 134 123 122 128 103 133 105 120 116 130 108 120 126 119 112 132 129 110 105 117 107 131 117 122 116 128 125 134 103 115 123 121 130 117 138 127 117 107 132 124 121 143 107 114 128 96 116 106 101 137 133 133 135 125 123 105 135 111 108 113 121 145 112 129 127 112 107 132 118 102 125 126 113 111 110 105 134 125 125 130 107 119 128 114 111 125 129 129 110 115 126 120 121 129 149 118 129 116 131 133 107 113 139 128 123 129 119 130 110 102 130 120 113 111 113 112 124 111 120 104 107 115 135 144 114 139 130 114 125 109 164 144 111 139 119 155 110 111 131 109 124 124 122 130 128 106 133 120 112 124 114 107 142 113 135 126 124 113 101 133 120 133 122 108 117 126 120 131 115 130 127 132 122 116 110 121 142 108 132 117 116 130 108 115 123 108 129 129 110 114 130 106 113 124 135 124 131 121 108 126 126 116 111 113 121 113 116 110 122 102 119 138 120 114 133 110 98 119 132 107 126 102 125 125 109 122 124 107 135 124 127 104 128 120 106 99 106 143 99 116 109 117 115 107 108 115 125 122 123 128 127 131 115 115 108 127 121 140 132 119 115 129 112 127 122 126 110 109 115 118 146 133 131 107 141 118 124 103 112 115 102 128 123 112 123 121 116 136 108 124 146 116 122 123 119 125 136 112 111 116 111 124 113 135 115 114 149 120 123 128 108 135 122 98 121 134 126 111 123 126 115 109 133 110 121 118 123 114 135 133 103 127 123 132 131 106 117 140 117 125 110 114 139 125 124 109 133 111 105 97 118 132 121 109 106 126 119 112 120 118 125 125 135 108 113 125 140 126 121 98 102 108 141 116 116 137 101 126 115 133 120 116 120 128 96 116 111 117 110 117 109 121 122 109 131 110 121 122 113 113 115 108 117 123 113 121 125 133 118 115 105 135 102 120 102 127 122 124 118 135 149 112 107 135 124 115 131 97 129 103 121 120 118 110 123 99 130 137 116 113 124 115 115 137 102 114 128 128 130 115 127 124 135 140 128 114 104 135 124 110 104 110 112 109 116 125 137 117 119 114 124 116 122 123 105 111 112 124 120 113 134 119 105 112 120 109 115 103 110 134 106 108 110 130 106 108 123 112 106 113 143 130 113 135 118 120 100 128 108 108 126 118 99 108 138 119 123 113 134 118 98 115 109 125 122 107 124 134 116 118 120 120 123 121 128 120 130 143 133 122 120 131 117 114 113 123 137 113 124 134 126 126 121 108 127 114 117 122 122 128 116 136 119 116 106 145 126 112 127 117 116 116 111 146 100 112 122 111 140 123 147 121 135 128 125 109 117 115 128 124 130 108 110 136 112 130 115 124 138 108 120 122 109 121 123 126 98 115 123 106 131 125 112 132 113 126 115 126 107 110 116 107 138 121 134 138 135 98 128 96 123 129 118 118 115 136 113 120 119 121 130 128 121 110 127 125 123 122 134 116 136 108 125 100 107 109 129 119 119 114 122 127 135 148 123 130 119 136 146 142 110 112 122 120 137 131 100 131 138 129 115 117 117 142 130 121 130 115 115 144 101 122 134 148 120 117 106 139 123 140 108 112 114 132 108 133 127 141 102 111 117 98 137 117 117 108 118 114 110 117 124 137 147 112 114 118 134 139 114 129 111 92 115 126 112 124 115 109 119 108 128 127 123 118 119 118 125 130 109 105 110 122 117 132 104 139 119 119 114 113 118 130 111 123 115 108 110 132 113 107 111 133 128 120 109 123 126 115 123 147 129 127 115 119 126 124 127 124 102 121 125 117 137 125 117 122 113 120 118 116 123 144 96 120 134 117 116 126 128 105 110 103 131 128 120 94 121 117 118 113 128 137 132 108 119 103 128 120 114 118 115 117 129 130 124 115 117 118 117 115 95 126 120 128 102 127 101 131 106 125 113 121 131 128 110 138 143 134 125 102 114 111 106 110 117 136 131 112 112 122 123 134 112 120 112 111 119 123 113 108 113 137 97 126 128 120 114 112 93 122 116 122 127 112 109 104 98 118 143 133 95 102 119 110 112 102 127 128 117 120 107 108 132 115 115 112 128 102 122 108 117 107 132 131 125 122 136 119 101 109 102 111 135 108 107 126 108 113 114 130 114 124 127 108 107 130 114 112 133 105 122 119 123 98 119 124 105 123 107 110 130 110 135 113 129 127 125 131 130 117 132 114 89 125 111 121 114 126 122 120 140 106 121 111 132 138 117 123 120 134 113 131 130 123 110 138 109 116 111 118 120 109 110 120 96 121 99 120 139 114 108 133 106 124 108 124 122 120 123 104 115 118 136 134 132 121 138 98 96 126 113 107 129 117 117 105 116 128 99 130 110 113 124 143 106 126 111 107 133 126 129 109 139 113 116 109 128 127 127 117 118 113 91 114 114 128 113 115 118 127 130 120 127 127 118 120 113 115 114 121 108 128 108 98 116 134 105 124 125 135 114 116 111 125 136 107 110 108 123 109 111 124 111 128 128 124 132 130 111 111 115 126 130 115 111 145 104 134 115 107 113 108 133 120 106 112 119 119 110 109 107 119 113 128 132 114 122 119 115 114 115 100 121 102 125 107 130 135 110 122 123 121 118 114 122 121 114 114 102 119 128 139 120 112 120 144 114 130 128 110 116 119 115 134 115 128 131 112 124 125 112 127 112 99 129 120 111 96 144 128 122 130 119 118 115 108 139 116 126 134 142 113 108 121 110 127 121 107 136 109 140 125 110 122 129 108 105 115 132 125 112 105 127 139 132 114 115 119 117 118 126 120 96 108 118 97 112 113 110 108 115 101 128 125 135 121 122 122 128 134 108 112 117 119 117 127 115 128 132 122 113 126 108 127 103 119 122 121 113 114 115 130 118 124 95 118 123 101 122 125 120 122 122 142 97 116 105 123 99 132 128 127 118 122 103 114 120 129 122 125 101 113 127 128 147 139 107 126 121 97 111 140 120 114 111 109 123 118 122 106 124 120 117 119 114 99 137 118 107 95 111 107 121 107 121 121 108 127 126 131 102 117 112 125 134 114 128 121 116 121 124 114 113 120 123 132 126 125 114 117 113 135 119 114 121 110 115 115 124 121 119 95 111 120 110 113 128 117 117 139 122 135 110 136 100 132 123 94 107 114 131 111 133 120 127 111 114 98 102 112 109 125 126 137 138 111 139 123 112 115 118 118 109 122 137 122 139 103 109 118 114 105 96 116 126 135 108 106 106 140 127 104 120 132 109 120 125 126 111 121 131 105 122 106 126 132 112 116 112 110 119 124 112 112 117 120 119 122 126 125 125 125 117 120 127 121 129 134 101 127 107 120 115 112 133 126 118 107 93 112 113 113 112 117 121 113 113 142 115 122 122 126 115 121 129 117 109 115 109 111 110 142 141 124 113 120 119 133 129 94 113 124 138 99 87 127 131 128 122 96 130 120 128 107 128 124 126 109 126 126 120 118 101 121 117 135 117 131 131 114 135 106 137 118 112 116 129 119 119 142 119 112 141 104 117 108 132 135 111 131 108 128 117 120 118 116 137 118 123 124 124 148 114 112 116 113 122 125 133 111 125 137 137 125 126 113 110 109 128 130 122 139 112 117 128 121 118 124 132 123 126 122 131 107 115 114 127 128 129 112 114 126 114 118 100 119 119 116 123 110 114 122 131 117 156 126 123 141 138 133 101 119 118 115 110 123 121 137 124 125 121 118 132 119 122 101 100 106 139 133 110 115 110 110 117 124 127 119 124 124 124 134 109 149 128 137 121 125 122 137 128 113 136 131 120 139 112 115 126 145 116 130 129 141 126 140 125 140 104 131 132 117 146 112 134 120 140 99 111 112 130 100 126 126 116 112 119 110 116 129 130 132 123 148 123 111 135 114 121 133 116 127 127 122 116 117 119 147 127 123 116 116 92 117 127 123 120 135 138 114 132 118 113 111 120 127 114 122 135 113 118 123 117 116 137 100 125 122 138 126 115 109 116 116 107 121 128 117 122 121 113 127 107 119 128 112 120 151 124 108 132 122 123 144 120 135 144 116 114 141 110 120 133 113 121 127 115 127 119 145 131 105 123 125 113 112 129 140 107 115 123 139 139 128 121 122 118 110 154 117 113 116 131 107 134 137 120 124 106 118 146 138 137 122 122 123 123 141 119 114 137 117 130 144 129 132 126 112 113 132 129 118 121 123 129 116 111 109 106 129 118 103 99 127 129 131 119 129 105 147 131 123 145 116 104 121 137 132 117 127 98 134 113 135 135 144 121 129 139 118 120 115 109 132 130 134 116 123 133 121 122 114 141 116 125 137 101 131 99 135 110 124 128 105 124 127 114 134 113 119 136 126 131 111 125 121 134 125 105 106 104 128 120 113 133 126 129 134 139 102 134 124 117 113 115 118 123 119 128 120 112 115 141 128 103 124 118 130 136 114 130 115 126 135 128 133 119 118 135 143 148 129 135 113 134 126 122 108 127 122 112 124 120 120 120 116 137 121 121 132 118 101 112 113 123 114 120 112 125 112 128 105 116 126 99 122 116 107 119 122 121 127 122 118 125 133 141 120 132 121 124 98 117 113 137 131 146 124 115 141 131 119 135 120 119 121 118 115 140 106 118 119 126 148 125 118 134 117 124 122 123 118 141 125 130 122 128 149 130 121 113 125 139 118 130 106 110 128 112 135 125 120 114 109 131 115 134 140 107 115 154 108 133 108 134 114 130 130 109 112 123 103 125 130 145 129 123 129 141 116 100 115 131 113 116 125 129 123 131 114 136 123 149 130 132 131 130 128 133 128 116 102 132 115 122 134 122 135 124 132 113 113 140 111 113 109 145 135 117 141 117 110 117 128 121 128 125 139 120 119 124 129 117 125 148 112 117 138 138 135 127 126 123 120 124 132 121 99 133 132 140 103 126 126 123 131 132 122 113 143 110 117 119 135 131 135 121 120 107 112 128 118 143 139 117 101 116 121 134 109 138 130 126 141 118 110 137 139 115 99 117 122 126 97 148 106 126 127 134 127 120 133 115 121 123 126 137 138 105 119 143 116 129 125 116 127 111 116 122 95 120 117 131 119 113 128 116 135 125 136 110 123 139 121 137 108 138 145 136 119 124 115 130 129 109 128 120 112 121 139 127 119 134 125 120 125 114 124 112 113 121 132 136 114 135 137 143 141 138 108 143 125 134 142 115 131 131 107 106 135 110 135 138 113 123 118 147 146 127 117 118 127 132 145 133 123 140 132 133 121 149 144 129 124 136 117 138 131 131 136 128 121 130 129 120 115 116 115 112 112 131 140 122 130 127 118 140 143 120 125 120 131 120 126 138 127 150 125 121 133 159 132 144 121 107 138 122 138 125 126 121 118 105 147 137 126 130 107 133 143 113 121 143 133 134 128 134 114 142 127 115 145 128 121 124 111 125 128 121 158 131 145 144 120 123 132 117 135 135 124 110 143 126 135 118 132 138 123 125 122 116 127 136 155 131 133 133 124 129 119 95 110 130 139 145 126 152 111 130 135 115 116 117 142 133 145 144 144 127 122 141 132 146 145 116 122 124 100 139 118 135 149 152 109 138 124 125 120 136 129 103 146 134 124 144 111 136 111 123 128 129 127 134 128 124 121 132 127 138 130 148 129 118 130 129 129 113 131 112 111 125 108 128 124 122 117 122 124 124 127 133 124 130 123 132 129 120 109 132 110 151 108 103 130 140 124 108 124 128 111 131 134 130 111 102 137 124 125 123 112 116 121 133 114 128 136 99 124 112 125 134 127 131 123 114 131 127 105 106 103 142 115 112 140 139 121 123 125 121 102 127 119 121 126 131 123 124 107 117 138 125 122 111 139 148 114 116 133 114 120 118 137 133 132 130 137 118 120 124 121 97 139 129 135 124 131 134 141 124 143 145 127 138 115 116 128 107 132 135 127 137 117 128 133 122 122 125 115 146 122 122 98 119 152 151 122 131 120 126 113 121 135 126 146 130 121 127 136 148 123 124 136 115 134 119 135 137 130 111 119 131 121 129 125 116 113 101 123 126 130 143 141 121 126 131 135 121 142 115 114 133 120 147 120 117 121 124 128 138 137 118 118 139 133 122 108 98 115 133 130 118 134 122 102 107 115 125 129 118 126 123 143 112 133 136 119 127 130 130 146 125 120 124 113 117 115 137 123 115 122 123 129 141 110 120 129 112 126 104 101 123 123 115 127 105 99 130 135 119 140 121 120 126 123 95 136 151 120 123 104 122 121 116 130 122 133 104 126 122 98 106 134 110 125 125 99 121 111 140 109 132 139 138 124 130 137 120 146 127 135 104 116 116 138 151 120 114 121 131 129 115 114 125 110 113 108 120 128 122 134 126 131 124 116 128 109 119 142 128 123 119 111 117 129 124 132 113 122 139 134 124 141 127 140 123 109 113 122 117 145 117 130 112 126 119 127 121 117 124 133 130 136 134 130 143 119 131 110 124 113 125 121 117 118 142 131 142 98 138 101 121 129 124 104 150 128 120 131 121 129 117 133 113 100 111 121 117 120 124 133 123 135 129 116 121 130 113 116 120 114 123 131 132 138 118 128 105 123 102 112 132 118 128 123 109 117 119 122 116 138 122 129 124 134 131 127 135 136 120 119 110 126 121 132 125 117 111 102 126 117 126 124 101 143 140 110 138 137 113 149 127 129 110 117 134 116 135 131 102 133 127 123 115 116 117 107 114 126 120 115 111 117 108 113 117 139 107 125 126 122 92 104 123 156 109 107 115 133 104 117 119 112 128 129 114 120 114 132 130 105 125 133 109 146 129 112 127 125 134 119 119 119 121 129 123 126 124 124 141 116 135 120 127 123 125 133 117 125 116 127 107 115 124 133 134 101 126 122 125 133 130 144 135 129 100 135 133 135 125 134 126 119 124 120 108 124 107 125 119 128 120 121 128 119 132 118 138 111 127 127 138 116 136 105 103 109 113 111 127 128 127 118 137 117 149 107 126 120 112 133 150 123 113 114 120 134 131 142 128 145 125 121 115 138 126 112 110 136 130 120 124 145 128 128 122 127 111 121 127 141 130 107 123 140 133 131 116 125 119 123 134 107 124 103 116 149 139 143 131 118 122 125 131 138 117 132 150 134 127 119 129 117 137 132 119 121 126 116 122 121 103 123 113 133 136 126 142 122 146 130 130 130 117 121 112 134 120 109 138 133 130 135 144 120 113 116 114 105 117 127 105 132 142 126 135 121 123 114 130 122 114 119 116 138 129 154 124 132 125 138 123 118 100 125 131 120 134 131 130 125 121 117 138 131 135 128 124 132 138 110 108 129 107 124 121 143 103 127 119 149 148 121 133 136 131 126 120 128 122 120 120 131 134 131 139 136 117 104 128 134 127 128 112 122 120 126 122 136 133 123 93 130 125 115 122 133 109 135 116 123 127 124 119 112 124 120 114 114 134 129 129 108 132 129 96 125 140 129 115 132 147 131 137 118 120 129 118 128 126 125 127 120 132 117 117 100 107 124 129 133 124 123 123 133 127 109 139 104 119 96 113 118 114 126 121 129 173 127 139 132 135 110 123 135 136 116 123 89 124 119 120 130 134 129 109 127 127 128 123 134 119 135 123 118 136 149 136 130 96 127 111 132 124 122 118 145 135 133 119 119 128 126 110 131 118 121 144 136 160 120 128 108 130 113 114 128 136 118 134 125 128 93 118 138 126 124 129 124 137 140 115 118 118 130 100 138 130 136 132 138 111 128 125 118 132 145 130 132 122 123 126 128 108 131 141 132 130 137 132 127 129 118 128 134 131 135 138 135 120 119 118 118 124 109 127 119 137 120 116 136 120 115 129 127 126 118 126 134 137 135 141 118 111 129 129 123 131 118 121 113 110 116 134 116 123 122 138 109 93 119 125 96 132 129 138 121 123 121 115 134 123 140 127 126 114 117 116 123 112 117 114 110 116 117 120 120 121 115 105 138 129 111 106 133 145 116 139 124 137 135 131 151 114 121 132 128 138 118 129 124 130 142 132 123 119 125 126 130 136 127 117 143 137 127 112 122 125 134 123 143 117 130 134 123 113 126 123 128 118 117 128 131 130 137 114 141 128 116 130 135 114 125 123 130 133 133 131 132 116 107 137 146 115 148 114 109 120 130 122 123 111 121 113 111 130 124 115 151 135 120 120 127 116 112 125 124 137 121 120 125 120 122 128 131 120 143 140 159 115 139 119 141 116 134 141 120 131 125 126 147 117 149 112 109 125 113 132 132 122 137 132 111 123 150 119 129 122 129 130 150 119 113 150 130 150 123 106 124 132 119 124 124 110 123 122 121 128 132 126 126 140 136 131 118 134 116 134 122 124 126 126 125 134 144 131 107 118 165 135 137 127 134 124 115 124 126 147 137 125 129 129 135 121 126 126 131 122 139 123 106 124 129 101 126 129 107 136 127 122 138 129 112 139 130 116 129 136 120 123 127 121 127 117 130 133 139 125 130 111 125 117 124 137 120 139 142 134 140 119 147 128 130 119 121 134 129 116 130 145 121 105 124 121 118 143 141 132 126 141 133 129 120 131 122 130 128 122 121 123 128 139 124 131 109 128 147 133 113 134 123 148 114 141 129 123 112 124 122 126 123 148 125 131 122 128 129 138 124 158 128 107 123 134 121 129 103 125 91 118</counts>
			</dataPoints>
		</scan>
	</xrdMeasurement>
</xrdMeasurements>