File: data/XRD/XG-Vakuum/XG-700/W6822-1C_XG_Vakuum_700.xrdml
<xrdMeasurements xmlns="http://www.xrdml.com/XRDMeasurement/2.1" xmlns:xsi="http://www.w3.org/2001/XMLSchema-instance" xsi:schemaLocation="http://www.xrdml.com/XRDMeasurement/2.1 http://www.xrdml.com/XRDMeasurement/2.1/XRDMeasurement.xsd" status="Completed">
	<comment>
		<entry>Configuration=Factory configuration, Owner=User-1, Creation date=7/8/2013 4:01:53 PM</entry>
		<entry>Goniometer=PW3050/65 (Theta/2Theta); Minimum step size 2Theta:0.0001; Minimum step size Omega:0.0001</entry>
		<entry>Sample stage=MRD Cradle; Minimum step size Phi:0.01; Minimum step size Chi:0.01; Minimum step size X:0.01; Minimum step size Y:0.01; Minimum step size Z:0.001</entry>
		<entry>Diffractometer system=XPERT-PRO</entry>
		<entry>Measurement program=C:\PANalytical\Data Collector\Programs\Jorrit\2thom\_absolute_2th-om_10-130deg_PIXscan_56min.xrdmp, Identifier={15BCCF57-2807-42BD-B5B9-ECC0B3DC9284}</entry>
		<entry>Batch program=C:\PANalytical\Data Collector\Programs\SimonL\batch4x_2thom_10-130°_z9.1_x0,10,20,30_y0_57min.xrdmp, Identifier={EED9823A-2BEB-424C-9252-345C4EF2834A}</entry>
	</comment>
	<sample type="To be analyzed">
		<id></id>
		<name></name>
		<preparedBy></preparedBy>
	</sample>
	<xrdMeasurement measurementType="Scan" status="Completed" sampleMode="Reflection">
		<comment>
			<entry>_absolute_2th-om_10-130deg_PIXscan_56min</entry>
			<entry>PHD Lower Level = 4.83 (keV), PHD Upper Level = 11.27 (keV)</entry>
		</comment>
		<usedWavelength intended="K-Alpha 1">
			<kAlpha1 unit="Angstrom">1.5405980</kAlpha1>
			<kAlpha2 unit="Angstrom">1.5444260</kAlpha2>
			<kBeta unit="Angstrom">1.3922500</kBeta>
			<ratioKAlpha2KAlpha1>0.5000</ratioKAlpha2KAlpha1>
		</usedWavelength>
		<incidentBeamPath>
			<radius unit="mm">320.00</radius>
			<xRayTube id="1010048" name="Empyrean Cu LFF HR (9430 033 7310x) DK442154">
				<tension unit="kV">40.0</tension>
				<current unit="mA">40.0</current>
				<anodeMaterial>Cu</anodeMaterial>
				<focus type="Line">
					<length unit="mm">12.0</length>
					<width unit="mm">0.4</width>
					<takeOffAngle unit="deg">4.2</takeOffAngle>
				</focus>
			</xRayTube>
			<xRayMirror id="27010001" name="Inc. Beam Cu W/Si (parabolic MRD)" hybrid="false">
				<crystal type="Graded" shape="Parabolic">W/Si</crystal>
				<acceptanceAngle unit="deg">0.800</acceptanceAngle>
				<length unit="mm">60.0</length>
			</xRayMirror>
			<sollerSlit id="21010002" name="Soller slits 0.04 rad.">
				<opening unit="rad">0.0400</opening>
			</sollerSlit>
			<mask id="22030008" name="Fixed mask 4 mm">
				<distanceToSample unit="mm">220.00</distanceToSample>
				<width unit="mm">4.00</width>
			</mask>
			<divergenceSlit id="22010007" name="Fixed slit 1/8°" xsi:type="fixedDivergenceSlitType">
				<distanceToSample unit="mm">220.00</distanceToSample>
				<height unit="mm">0.19</height>
			</divergenceSlit>
		</incidentBeamPath>
		<diffractedBeamPath>
			<radius unit="mm">320.00</radius>
			<sollerSlit id="21010002" name="Soller slits 0.04 rad.">
				<opening unit="rad">0.0400</opening>
			</sollerSlit>
			<receivingSlit id="22010001" name="Fixed slit 4°">
				<height unit="mm">5.88</height>
			</receivingSlit>
			<detector id="7010017" name="PIXcel3D 1x1 detector" xsi:type="areaDetectorType">
				<phd unit="%">
					<lowerLevel>30.0</lowerLevel>
					<upperLevel>70.0</upperLevel>
				</phd>
				<mode>Scanning</mode>
				<activeChannelsEquatorial>255</activeChannelsEquatorial>
				<activeChannelsAxial>255</activeChannelsAxial>
				<pitchEquatorial unit="mm">0.05500</pitchEquatorial>
				<pitchAxial unit="mm">0.05500</pitchAxial>
				<readOutPeriod unit="seconds">0.135</readOutPeriod>
			</detector>
		</diffractedBeamPath>
		<scan appendNumber="0" mode="Continuous" scanAxis="2Theta-Omega" status="Completed">
			<header>
				<startTimeStamp>2024-10-09T11:18:10+02:00</startTimeStamp>
				<endTimeStamp>2024-10-09T12:14:17+02:00</endTimeStamp>
				<author>
					<name>PRO-MRD</name>
				</author>
				<source>
					<applicationSoftware version="6.1b">Data Collector</applicationSoftware>
					<instrumentControlSoftware version="7.0E 20130304">XPERT-PRO</instrumentControlSoftware>
					<instrumentID>0000000011142674</instrumentID>
				</source>
			</header>
			<dataPoints>
				<positions axis="2Theta" unit="deg">
					<startPosition>9.99826193</startPosition>
					<endPosition>129.99755682</endPosition>
				</positions>
				<positions axis="Omega" unit="deg">
					<startPosition>4.99913096</startPosition>
					<endPosition>64.99877841</endPosition>
				</positions>
				<positions axis="Phi" unit="deg">
					<commonPosition>0.00</commonPosition>
				</positions>
				<positions axis="Chi" unit="deg">
					<commonPosition>0.00</commonPosition>
				</positions>
				<positions axis="X" unit="mm">
					<commonPosition>10.00</commonPosition>
				</positions>
				<positions axis="Y" unit="mm">
					<commonPosition>0.00</commonPosition>
				</positions>
				<positions axis="Z" unit="mm">
					<commonPosition>9.100</commonPosition>
				</positions>
				<commonCountingTime unit="seconds">32.895</commonCountingTime>
				<counts 420 417 415 414 412 449 431 456 455 441 452 396 460 417 430 397 401 431 434 433 416 429 431 435 460 432 421 411 436 414 427 442 410 459 434 463 413 456 474 404 466 433 429 446 437 459 456 465 423 430 407 429 461 441 436 481 449 404 442 423 435 411 398 424 391 390 443 427 425 426 454 419 430 423 404 426 409 436 405 442 405 383 420 416 402 411 422 408 405 420 429 415 412 454 395 394 446 428 429 384 419 414 373 380 401 416 413 411 444 413 396 398 398 428 434 383 420 366 395 401 469 422 398 434 421 411 404 419 389 405 382 372 440 422 396 434 400 422 453 419 406 366 410 404 383 404 393 374 395 381 387 361 431 405 390 392 375 405 390 390 404 391 396 401 403 388 401 404 415 374 403 391 360 393 389 405 412 413 378 437 376 405 405 380 390 375 433 371 381 386 411 385 368 407 367 378 388 388 411 393 378 399 380 355 367 387 400 364 395 360 413 372 389 341 355 383 407 376 365 364 348 362 367 382 359 384 374 382 401 388 365 375 383 361 386 427 374 410 366 352 343 383 385 357 345 391 383 391 434 369 379 384 376 384 401 378 399 384 390 393 383 339 343 372 372 353 408 337 395 403 348 319 359 350 374 364 394 374 385 365 352 363 382 359 376 338 331 363 373 373 366 354 337 386 344 374 361 371 331 329 355 342 358 360 313 366 372 349 365 344 355 367 345 358 354 405 369 321 357 354 348 328 367 381 386 364 349 357 357 353 364 335 350 361 331 316 316 367 370 340 338 383 346 354 319 357 320 356 339 333 322 349 321 345 347 336 358 324 363 371 338 366 343 354 377 334 356 312 322 340 333 350 324 339 342 316 341 312 352 349 345 322 358 304 331 369 347 329 336 322 347 289 333 327 328 325 352 335 360 378 344 313 326 325 341 374 334 346 345 335 320 328 321 346 354 341 313 306 353 322 316 297 331 344 345 343 327 329 355 346 310 323 322 302 332 331 339 318 328 342 333 339 342 324 335 314 296 326 345 304 314 322 317 318 317 323 318 328 313 333 329 345 343 326 299 330 328 300 304 328 308 318 318 331 310 340 333 296 317 293 299 337 320 321 310 332 332 354 296 328 312 300 317 352 335 333 293 328 310 332 348 333 316 328 301 297 300 319 317 336 311 326 301 353 304 312 334 306 336 336 327 313 349 350 302 316 312 316 303 306 297 279 347 324 305 321 282 314 304 274 277 344 269 343 303 357 300 282 301 296 283 280 308 330 317 329 306 325 307 319 284 326 314 365 315 315 303 321 294 313 315 325 316 304 299 295 304 321 354 297 297 266 305 264 297 311 283 315 325 304 318 320 318 338 305 329 284 309 302 293 311 347 303 280 308 327 263 289 307 303 313 344 315 295 313 270 301 309 297 311 320 313 323 292 291 294 308 316 344 306 283 310 315 307 324 331 313 291 310 301 312 310 302 293 314 297 288 334 310 299 290 291 310 344 298 295 290 307 308 307 313 321 290 296 276 311 349 309 313 306 305 314 332 296 337 313 293 321 326 312 310 306 307 328 309 301 297 286 318 316 292 285 330 339 307 277 296 276 313 299 297 279 312 293 298 306 287 295 309 319 322 299 294 275 288 308 314 316 271 269 311 324 301 330 292 285 338 290 319 284 318 279 308 293 323 328 323 325 284 282 324 298 297 298 291 303 306 334 269 304 294 288 277 304 291 298 328 313 290 262 317 309 300 287 286 308 307 341 329 275 326 286 284 300 284 312 289 300 297 263 293 291 309 327 282 298 325 304 305 305 327 300 296 317 291 283 277 339 324 314 319 315 298 303 300 327 307 322 313 294 301 299 322 325 349 320 315 290 334 286 301 300 310 333 318 300 308 311 301 344 349 297 325 288 280 302 283 321 310 311 263 298 293 309 292 315 302 289 323 339 318 311 309 300 312 300 304 293 302 314 311 317 324 310 303 283 321 325 304 303 311 321 288 305 321 317 294 289 311 321 286 322 299 345 335 308 288 304 294 303 316 318 313 332 329 286 331 311 299 307 305 303 303 326 324 314 343 300 320 283 303 306 258 287 285 300 319 326 300 343 327 317 304 315 293 302 286 331 315 300 298 290 336 296 328 335 325 306 323 305 309 279 321 296 289 318 311 322 299 317 333 301 320 308 300 301 294 319 290 298 319 317 304 321 312 315 295 322 310 314 335 347 312 319 280 309 301 288 312 323 282 313 277 311 327 339 328 312 341 324 330 313 303 325 290 311 322 351 315 315 339 349 331 313 323 328 316 314 258 305 317 312 321 320 297 332 320 313 295 296 330 309 305 315 321 287 312 303 355 335 302 295 307 326 337 332 357 336 331 294 316 337 351 338 315 336 320 329 322 306 339 342 331 345 311 315 327 345 321 304 297 332 325 304 320 320 331 329 304 314 318 331 332 325 356 345 292 299 308 330 301 319 309 305 326 361 313 344 339 294 309 281 323 316 360 296 324 341 338 307 341 311 330 306 330 339 329 326 324 320 315 300 297 326 307 338 353 295 306 345 338 349 333 320 327 341 307 327 316 340 320 336 334 306 314 333 302 318 303 297 310 354 319 319 355 311 319 323 313 313 330 300 366 319 311 341 298 301 313 303 325 319 307 351 307 315 334 340 360 341 313 315 319 331 342 337 363 323 335 317 341 307 337 322 355 324 334 322 300 322 322 302 323 348 314 296 329 324 312 342 302 313 370 343 329 313 326 333 341 318 310 307 357 317 358 304 352 324 325 315 340 315 314 343 326 318 325 300 295 347 344 329 323 298 335 322 329 348 314 308 320 351 332 306 332 310 304 363 345 308 312 314 358 338 333 319 305 332 324 363 323 296 319 326 326 339 279 319 310 358 322 333 315 335 335 332 338 311 345 322 335 331 314 327 346 329 334 352 325 292 290 310 351 311 318 324 334 326 372 330 357 333 377 342 322 339 327 327 309 289 309 295 319 327 286 352 354 334 313 329 306 339 308 331 295 339 301 318 343 341 314 333 374 305 328 303 318 317 334 314 343 322 322 299 320 347 290 299 325 319 318 329 305 286 320 322 327 314 299 314 318 316 343 326 293 312 313 327 289 304 353 328 319 283 354 327 335 346 341 317 321 337 360 347 348 321 337 287 342 338 292 322 325 345 326 327 329 308 331 334 319 329 297 330 313 349 334 304 300 327 326 317 301 350 350 322 293 335 353 338 305 358 322 318 324 323 314 304 309 311 344 307 343 302 308 341 339 305 260 320 291 344 282 320 321 342 280 320 308 339 322 316 282 317 319 270 315 318 317 299 301 279 290 324 350 290 331 320 309 299 341 300 292 344 330 300 292 357 321 293 362 305 335 321 289 285 276 288 302 326 308 308 309 319 296 324 322 297 284 322 297 312 319 332 297 338 307 308 334 294 279 358 324 286 308 309 301 307 309 298 310 315 292 261 279 296 324 304 325 294 290 300 306 299 290 294 291 325 319 300 297 294 292 298 319 307 302 314 286 307 281 261 305 312 298 307 315 297 321 313 323 284 309 303 316 274 325 321 275 322 297 331 289 342 264 283 297 295 293 302 298 294 307 288 281 335 321 305 308 279 280 320 299 296 307 291 283 296 321 302 293 293 310 304 295 277 292 337 301 290 327 281 294 266 313 286 297 308 310 316 313 263 290 316 308 271 288 316 275 299 305 307 305 275 280 294 287 294 265 270 305 283 274 296 292 292 306 300 305 289 283 301 292 296 302 289 281 279 301 278 278 295 307 304 274 266 299 274 258 265 325 271 294 301 305 295 291 284 331 291 287 282 283 282 313 296 291 297 301 307 281 255 312 269 319 267 299 276 299 272 324 325 319 282 281 312 267 281 305 276 288 311 281 278 281 275 304 303 285 292 278 265 279 300 271 296 300 273 290 300 242 288 274 280 271 274 300 294 282 265 265 257 269 319 287 284 313 280 295 279 287 287 273 280 296 292 303 281 283 277 273 268 282 272 266 276 324 278 290 271 284 294 249 309 260 272 293 274 305 284 317 278 264 293 247 303 278 244 294 268 329 277 287 259 293 271 276 272 235 275 288 271 277 295 243 279 278 283 278 262 277 274 267 260 295 259 277 279 277 260 277 241 274 288 257 268 289 301 281 258 289 264 286 256 256 265 243 280 266 301 276 285 278 286 282 249 310 273 265 279 272 291 272 270 273 266 273 271 215 270 276 264 241 274 284 294 242 290 278 269 282 268 298 264 243 279 289 275 286 280 264 285 265 285 274 240 279 295 264 237 277 274 283 249 264 279 258 288 263 264 249 268 288 258 271 256 248 263 282 246 266 255 224 268 268 260 266 278 245 258 271 270 237 291 266 294 273 265 275 295 291 281 264 270 273 260 259 261 259 288 282 271 287 294 237 248 260 263 262 263 260 278 273 214 249 281 270 257 215 276 298 257 244 270 244 238 236 242 277 241 243 275 262 259 258 263 248 245 277 270 239 286 242 243 273 233 264 228 286 230 228 248 255 267 241 233 266 259 264 256 242 247 237 242 255 255 257 259 262 284 258 287 267 284 233 244 278 244 272 246 262 236 257 293 255 250 240 240 267 240 261 255 256 286 262 248 212 269 218 272 235 233 244 234 269 226 247 261 233 262 264 261 229 268 242 258 241 238 257 256 244 258 264 237 299 249 276 267 236 258 247 213 268 247 247 245 239 277 248 218 236 249 262 255 225 228 261 225 262 259 239 264 269 261 230 243 221 232 237 246 233 272 239 223 230 281 233 235 234 201 256 239 246 250 245 218 255 249 245 256 211 256 260 249 239 243 234 238 247 263 288 242 240 242 236 257 248 247 257 222 257 271 268 228 238 255 256 236 257 244 228 245 245 228 266 232 277 258 220 248 238 224 249 222 222 256 262 232 259 262 262 240 250 219 247 270 245 240 257 224 244 231 205 240 230 216 265 246 237 224 239 237 230 224 220 247 262 248 223 219 223 257 226 235 225 230 239 262 243 227 242 230 227 246 245 242 234 234 236 260 242 230 264 244 246 242 222 249 238 243 272 242 248 261 218 231 216 230 221 230 225 225 219 231 234 229 232 234 269 237 256 239 237 205 225 244 237 227 268 237 233 234 207 219 247 273 217 247 274 206 235 219 230 218 209 236 227 247 258 231 227 221 237 239 250 247 247 230 218 226 255 204 263 218 235 240 218 223 271 206 238 232 203 255 188 266 225 249 234 261 227 212 242 249 215 223 224 261 224 225 234 235 230 243 233 235 226 223 211 226 237 230 216 222 256 203 201 236 275 241 200 218 220 237 224 249 250 237 255 249 238 238 242 200 230 230 235 240 206 220 198 225 228 233 223 225 256 245 194 212 215 221 215 200 233 199 204 231 208 236 208 210 235 262 240 208 238 243 208 233 239 194 240 234 224 234 213 208 224 247 230 226 244 225 237 225 214 204 223 206 237 237 226 264 262 206 246 217 262 230 211 248 233 226 227 258 238 229 236 221 216 228 236 224 241 229 250 199 179 234 199 222 230 218 219 211 256 232 230 207 217 212 222 235 200 227 227 214 274 220 235 235 217 226 227 221 247 219 227 217 230 219 224 232 223 212 204 216 235 212 216 227 224 210 232 241 233 247 208 201 237 226 243 203 202 237 235 239 210 218 233 244 243 236 232 203 242 240 214 263 258 231 255 227 236 217 212 227 263 229 234 220 256 241 247 208 220 230 222 233 230 220 222 231 231 227 204 231 226 210 224 215 240 227 228 236 208 225 229 231 245 204 246 217 218 218 218 214 230 213 223 223 260 229 281 216 231 222 242 242 247 224 227 225 226 220 231 218 217 265 229 204 218 230 218 232 223 231 268 236 225 237 205 203 246 209 235 216 222 209 216 237 223 221 237 219 212 205 222 208 230 210 232 209 209 221 229 236 231 213 230 213 210 206 202 239 206 221 258 240 262 236 220 247 228 211 224 230 214 209 226 210 217 228 228 219 250 212 229 232 199 208 267 231 223 227 208 235 229 207 224 229 231 262 228 230 231 241 244 234 237 205 232 245 238 219 231 199 258 231 214 217 212 243 221 261 232 225 283 225 219 232 232 228 230 224 229 243 229 235 242 220 225 233 230 285 263 227 243 257 209 229 236 209 236 213 221 199 267 270 228 236 213 239 236 208 223 208 214 214 219 230 203 226 235 191 218 223 243 224 208 236 199 205 217 235 234 220 225 223 240 213 218 210 236 209 235 215 244 208 208 233 219 206 245 199 217 211 228 228 202 207 210 223 211 221 214 242 212 228 198 197 213 219 238 211 235 221 210 261 230 217 220 228 193 226 230 207 256 204 220 235 210 235 220 227 224 226 219 234 221 214 218 211 245 229 218 223 240 255 211 224 236 269 216 209 227 223 203 216 208 226 257 217 238 220 208 257 222 231 202 229 227 208 241 212 218 215 225 214 237 223 215 207 212 239 228 210 197 227 230 231 219 227 220 233 215 214 218 247 197 239 216 232 220 227 213 202 214 235 227 213 221 204 238 228 223 245 219 236 225 241 218 202 210 229 240 220 200 226 210 210 223 222 208 221 206 224 235 239 220 205 226 228 210 203 211 217 218 214 228 216 272 229 208 262 242 203 231 204 202 220 223 238 230 219 217 223 228 215 227 229 216 241 232 218 210 231 214 199 218 243 220 249 213 189 229 226 227 259 221 201 225 216 241 212 225 208 223 207 232 232 211 238 231 216 215 242 225 206 242 226 247 212 218 242 216 213 230 217 220 203 235 221 209 212 237 215 258 204 223 214 242 214 240 226 226 198 211 204 195 264 213 210 202 241 222 237 225 199 211 234 228 221 215 221 221 208 210 220 225 225 219 234 208 236 231 212 224 242 199 262 231 215 217 180 235 205 235 203 232 216 216 234 248 194 244 220 211 227 236 237 240 222 207 227 227 210 244 205 216 230 202 226 187 238 192 219 238 215 241 223 212 235 217 203 243 219 207 211 247 245 229 210 211 206 246 218 215 207 220 258 217 230 233 197 226 220 235 234 230 249 221 203 187 218 203 228 221 234 238 211 194 241 216 222 234 216 232 229 247 222 263 223 235 219 228 204 216 219 238 208 236 214 220 210 231 206 236 228 237 237 204 212 216 231 242 215 210 195 242 218 234 222 235 237 238 255 227 214 226 224 239 220 231 233 257 209 261 216 231 215 205 219 232 229 239 204 213 220 209 207 236 214 222 232 235 212 208 213 215 211 213 216 230 218 222 243 212 210 227 214 206 202 225 214 231 216 206 221 222 225 240 207 200 240 216 243 197 206 235 216 206 233 211 239 229 227 219 228 222 203 212 235 262 212 215 213 210 218 230 238 213 196 221 223 216 224 201 221 208 223 223 205 229 222 202 248 238 216 224 236 220 235 214 239 225 232 234 232 236 211 244 218 210 226 247 219 221 222 215 247 205 220 207 230 256 223 226 207 242 245 240 217 199 263 223 219 204 235 246 234 235 218 242 233 223 211 255 204 261 226 244 238 232 235 239 221 207 218 221 247 216 236 214 191 235 216 248 224 263 270 231 246 231 263 258 259 260 215 224 248 231 245 237 265 241 257 224 232 259 255 225 226 236 219 225 206 195 243 244 231 220 231 210 207 242 210 234 201 228 249 231 219 226 229 209 214 211 213 229 242 227 224 197 237 242 263 233 218 200 216 256 222 244 223 214 241 236 232 249 233 236 247 272 245 214 235 230 232 223 229 250 247 240 224 228 233 242 264 241 256 264 244 263 244 245 235 248 287 264 261 268 257 244 233 238 262 267 293 270 292 250 269 282 285 280 272 262 308 287 289 304 313 295 323 298 316 306 342 317 295 365 336 374 379 389 377 375 376 401 387 369 385 402 407 406 376 403 401 354 372 367 355 362 357 332 335 343 350 314 306 313 289 312 326 303 292 274 287 273 281 246 261 280 250 234 243 209 277 228 243 267 227 243 239 240 268 236 240 267 224 223 232 233 243 236 232 216 228 246 241 230 220 233 212 233 240 207 240 225 248 243 257 242 213 222 221 227 223 250 213 214 212 255 239 226 206 213 222 213 230 223 226 219 210 229 225 231 228 218 226 208 221 234 202 218 228 195 211 208 228 233 209 208 247 240 226 223 223 227 226 234 201 259 228 211 226 245 220 222 229 225 225 237 229 235 207 219 200 221 223 221 220 227 266 213 211 205 234 219 212 228 256 227 209 233 206 238 245 212 216 235 187 236 222 239 213 239 257 221 242 207 225 202 234 205 213 205 215 216 230 220 215 197 229 227 215 215 223 219 218 227 208 211 232 224 206 211 222 221 212 223 230 210 199 192 215 211 197 225 257 222 195 205 226 206 221 198 220 216 228 209 213 260 205 292 227 195 216 207 255 198 195 188 224 189 219 206 221 215 216 227 193 220 208 235 225 189 205 208 235 196 221 227 223 201 208 226 215 225 237 232 222 226 228 196 217 222 221 261 225 221 237 220 250 227 208 232 229 230 225 236 206 209 227 228 212 215 221 222 221 200 212 220 211 237 239 218 216 212 225 233 244 203 228 217 241 248 223 211 232 215 236 241 207 206 205 220 235 231 216 232 222 224 213 200 204 208 242 225 214 205 213 219 240 244 204 212 226 212 237 231 205 208 222 236 232 185 202 225 227 202 208 222 213 213 215 200 211 211 192 200 192 227 216 208 204 227 222 217 217 223 227 217 218 250 240 218 241 220 222 228 206 249 224 214 214 211 222 223 235 283 236 228 221 218 213 226 224 249 241 244 214 229 216 230 231 230 221 184 204 217 233 201 231 272 202 216 223 189 209 222 230 267 217 267 227 226 241 201 226 222 236 185 238 214 217 216 210 193 225 238 200 243 220 229 192 237 237 199 230 208 223 222 232 212 238 232 235 188 217 204 232 228 242 221 190 247 210 220 195 219 203 201 229 210 214 255 225 212 232 238 198 221 224 199 219 232 226 239 206 208 223 246 225 215 209 238 221 202 225 205 237 241 209 230 224 209 219 202 237 182 228 209 218 196 218 216 239 205 218 205 201 220 207 196 222 236 198 212 202 227 222 246 205 195 223 219 237 224 222 212 235 214 231 224 199 200 179 263 219 193 211 226 219 208 221 224 213 210 222 207 203 186 220 222 230 234 216 201 214 223 210 225 206 246 234 207 196 237 206 219 218 219 226 238 205 227 226 193 209 231 214 238 213 202 229 233 213 197 207 218 209 210 227 221 208 227 214 204 215 225 212 229 236 212 227 227 216 209 223 236 246 221 228 209 196 196 231 213 201 214 216 230 227 184 203 215 227 221 215 198 220 212 223 214 186 208 219 214 213 222 208 211 232 201 245 224 210 212 241 186 223 226 244 229 199 221 224 202 225 210 231 232 233 205 209 250 230 186 234 200 238 257 234 232 214 240 219 217 202 198 213 190 227 205 218 213 219 224 234 237 190 219 243 236 216 201 204 198 224 211 189 242 233 195 205 230 263 218 189 200 224 225 216 203 183 221 200 194 238 220 195 235 249 245 189 202 206 225 250 228 202 207 211 221 238 222 204 219 226 245 213 199 244 202 223 249 242 207 201 225 224 237 211 242 175 216 206 204 192 177 208 210 234 169 188 241 206 237 217 217 163 220 214 239 191 232 223 233 216 191 222 223 214 189 212 222 222 216 231 188 213 214 194 190 223 187 187 223 231 195 240 212 196 223 194 217 219 225 237 220 209 222 198 214 215 199 214 214 223 217 231 219 202 197 202 226 202 198 198 202 197 210 240 194 184 223 200 210 206 206 219 225 204 214 204 224 203 234 216 236 205 208 206 210 194 231 212 243 228 201 208 215 202 223 231 189 224 224 197 211 207 221 236 211 183 214 205 262 201 206 238 184 212 223 202 232 234 224 233 202 245 214 222 218 240 225 193 210 173 207 226 223 205 208 224 238 240 211 219 207 225 215 225 189 206 168 242 235 225 223 195 198 202 247 209 205 216 223 227 222 212 204 233 198 205 231 225 210 200 216 220 182 222 244 194 191 231 210 203 192 205 219 220 220 210 242 202 189 207 208 186 218 218 199 221 210 210 212 189 216 193 207 216 213 222 230 201 224 203 216 188 204 229 208 235 231 242 216 207 193 224 235 201 219 218 229 213 207 225 195 186 217 207 203 222 236 222 230 243 262 199 218 215 218 190 223 215 197 214 196 191 197 206 221 239 194 221 200 224 231 191 208 202 235 223 227 224 209 207 209 221 223 222 209 206 226 191 216 223 200 216 237 216 235 198 229 178 228 208 201 183 211 226 196 206 204 200 208 207 223 210 211 203 205 194 212 205 225 213 206 193 228 210 184 231 208 228 217 216 209 205 238 221 208 221 217 237 184 215 221 216 228 240 204 210 213 214 211 233 230 197 190 195 202 238 217 189 202 211 190 223 212 220 210 234 179 216 255 229 245 241 231 200 203 216 197 191 225 227 216 209 226 255 225 241 222 222 187 238 231 209 209 204 209 198 234 230 194 194 212 215 229 227 218 240 208 219 207 228 225 215 219 204 210 210 213 207 197 224 208 204 199 227 231 224 230 208 213 196 221 231 222 215 198 224 199 230 207 205 188 212 227 196 205 218 209 225 214 208 204 222 242 219 213 206 231 232 214 207 211 213 221 203 220 229 215 232 232 210 215 232 219 194 194 229 213 227 249 220 227 199 219 198 195 216 217 216 218 221 215 225 232 210 190 232 201 216 240 229 210 235 213 194 208 225 220 215 201 220 210 229 217 243 212 235 210 205 211 203 192 210 221 213 221 243 230 195 231 214 240 256 207 220 214 234 225 217 242 202 201 211 230 214 249 238 219 220 228 189 218 213 222 211 208 221 235 200 227 237 233 225 188 228 210 233 228 225 216 215 220 241 236 211 236 256 214 225 237 242 205 208 216 217 238 240 227 236 206 205 207 207 214 223 203 231 201 210 204 218 233 210 233 225 222 212 209 208 194 210 222 236 234 241 183 244 217 223 225 219 250 223 224 210 240 215 228 215 200 210 207 208 221 205 250 219 209 235 207 232 205 224 200 210 190 211 220 221 239 234 221 226 234 226 194 208 225 219 231 197 208 206 222 213 205 224 218 238 202 196 249 221 192 194 210 208 184 239 240 193 236 204 212 240 207 223 232 224 220 227 255 205 200 218 214 211 210 202 224 235 244 205 217 214 220 238 234 242 219 196 205 224 212 222 215 205 208 206 213 209 224 230 206 230 196 236 225 223 211 222 213 200 210 217 201 205 203 223 217 238 217 212 191 217 224 206 216 206 258 218 208 211 228 218 210 215 231 215 213 221 227 215 222 224 218 224 197 223 189 219 238 232 233 207 214 217 205 216 240 228 255 229 181 215 224 206 216 220 225 221 248 191 201 212 219 226 197 212 200 205 186 240 222 203 184 208 229 200 217 195 259 195 200 196 208 202 199 232 217 212 208 232 227 227 214 227 210 214 216 201 187 240 210 220 216 219 200 226 208 198 202 243 216 215 231 215 204 206 214 207 214 218 216 206 240 174 212 238 206 220 229 209 235 219 264 221 193 212 226 205 217 227 211 201 208 230 232 205 245 229 216 209 215 226 246 204 202 219 248 195 212 228 220 223 210 218 217 207 209 228 244 206 218 212 211 206 212 224 228 188 220 228 206 198 221 213 231 219 241 220 219 225 228 228 207 210 227 201 221 215 218 191 224 199 229 219 211 211 223 233 236 235 227 192 226 221 240 194 200 187 220 225 219 210 202 218 215 217 212 209 244 245 206 214 193 218 206 204 228 209 208 199 196 219 180 218 197 198 217 197 245 236 218 213 239 257 203 221 201 192 191 210 208 227 207 227 205 218 219 215 193 213 195 215 230 190 205 222 229 217 203 219 210 236 212 244 241 236 244 230 237 217 230 226 227 216 174 207 230 216 236 214 234 212 221 228 223 234 224 201 212 225 229 206 220 199 217 244 229 214 214 211 222 217 200 225 218 243 243 222 217 220 223 211 238 218 235 216 245 210 205 201 275 241 211 196 216 225 193 234 225 220 214 208 205 235 229 211 240 232 237 194 217 213 231 235 211 212 230 233 231 175 227 213 210 235 213 229 200 237 193 202 202 212 216 200 238 223 198 215 193 238 225 205 201 218 208 214 188 216 218 194 216 242 212 219 218 231 200 248 225 202 241 203 211 210 211 205 217 259 211 216 217 207 213 198 203 209 209 215 206 211 219 211 208 216 227 233 208 199 217 233 222 228 202 239 190 238 210 226 223 198 215 222 236 230 207 231 193 212 216 203 247 194 235 231 201 220 210 207 249 211 209 212 220 224 194 198 198 199 231 225 279 214 226 242 220 214 244 222 206 257 225 224 219 214 225 206 224 235 230 210 194 230 215 228 210 208 222 238 204 193 222 221 194 227 231 217 197 211 216 228 219 217 235 193 211 223 215 226 208 201 230 218 233 223 227 227 227 224 237 224 233 237 196 255 209 240 218 210 213 228 230 212 212 217 250 231 228 209 222 233 218 225 234 241 246 219 229 214 256 220 243 229 235 236 240 223 219 226 194 209 195 245 237 219 233 224 224 225 220 225 214 202 233 222 228 245 256 228 218 208 231 243 217 234 233 218 199 223 228 236 226 212 207 243 219 210 191 231 230 226 222 217 256 212 223 207 217 204 229 196 236 229 231 205 220 207 215 218 227 218 220 225 228 204 214 219 220 228 238 225 175 227 222 226 219 208 244 213 204 218 209 221 230 194 230 209 223 202 223 208 246 203 191 238 241 206 225 222 230 195 214 214 207 205 220 220 217 241 203 226 213 221 220 202 222 199 221 228 244 229 219 193 233 235 222 232 244 225 201 220 185 233 214 235 226 204 209 223 247 211 247 213 229 232 211 244 209 189 206 229 218 223 214 213 213 225 219 213 214 212 185 201 218 223 213 197 239 231 213 220 211 256 198 217 225 226 237 224 216 221 212 239 246 197 224 237 223 230 235 215 242 220 228 224 221 242 211 213 206 195 209 209 201 229 201 221 218 228 266 238 206 206 201 220 205 230 213 215 228 217 231 221 229 230 222 213 220 211 213 192 238 200 234 237 228 221 210 231 230 215 211 232 211 228 203 213 225 216 201 221 212 186 203 227 183 231 216 236 222 233 212 218 225 216 217 220 236 200 216 215 220 226 219 220 212 223 206 201 206 237 208 217 203 227 192 230 232 238 235 206 199 227 220 233 211 201 221 221 229 216 219 239 204 216 206 195 195 218 225 220 216 225 238 232 224 217 204 214 182 209 213 232 229 256 221 236 210 209 211 234 225 201 220 205 195 190 228 226 235 214 226 213 216 210 224 258 228 237 234 227 237 238 237 199 240 214 228 217 228 194 201 226 215 212 185 236 246 237 227 206 225 208 209 207 193 229 216 249 229 213 189 204 210 203 230 188 214 218 224 231 201 282 202 226 257 207 245 213 218 236 206 221 200 228 228 190 218 198 190 216 218 232 208 235 199 242 233 209 187 232 257 206 216 229 216 212 230 227 213 210 216 226 221 210 207 202 203 217 233 203 220 198 205 211 256 213 221 205 222 203 207 227 203 232 206 222 207 206 220 197 204 238 229 212 204 220 219 236 203 204 205 231 218 244 205 225 217 227 219 192 201 240 208 210 189 213 229 239 213 222 203 182 214 218 228 214 222 183 209 223 214 195 261 227 221 205 212 250 224 243 208 207 234 247 244 208 186 213 190 243 226 211 194 220 223 225 211 207 207 210 233 244 201 219 236 203 221 219 228 229 229 224 203 182 222 199 236 233 216 227 208 206 210 207 217 203 224 202 217 209 227 225 213 223 192 219 198 223 212 219 217 219 246 201 256 178 219 207 204 210 197 221 232 215 209 223 189 241 233 211 217 222 206 232 203 197 200 219 200 209 225 232 198 215 213 235 213 213 208 207 223 210 194 212 200 213 181 227 205 208 226 232 232 224 219 223 208 226 190 212 218 249 231 210 195 226 200 218 255 216 216 210 218 229 214 224 211 194 207 217 204 231 209 208 204 225 204 208 207 223 215 208 207 214 225 226 211 208 208 228 217 225 215 212 217 219 197 190 214 218 202 219 207 235 244 220 225 204 200 234 238 224 214 232 213 232 204 215 214 230 194 203 242 209 264 221 217 191 206 207 207 227 216 240 225 257 194 224 263 236 238 191 232 216 215 175 230 235 217 228 232 207 230 216 208 192 213 214 223 216 228 218 225 206 201 221 200 216 234 188 202 214 230 202 256 204 217 201 197 188 236 212 217 221 215 219 229 205 218 211 232 208 216 180 215 215 239 212 214 201 227 196 211 213 238 199 199 192 199 213 217 226 219 215 225 214 231 230 211 208 198 225 199 214 216 215 219 216 236 211 199 220 211 255 215 206 218 210 210 240 231 205 248 197 203 215 235 236 213 189 226 209 207 204 237 226 186 217 213 210 204 209 227 222 263 205 221 220 221 202 212 216 191 243 221 205 215 225 217 223 207 221 207 237 234 214 226 207 213 230 212 190 206 204 208 210 196 240 203 244 205 224 222 223 211 215 213 208 223 219 234 240 205 211 221 231 212 231 213 213 211 229 227 202 218 211 225 204 217 231 204 238 220 217 215 202 192 210 203 221 205 225 216 196 212 223 196 218 228 225 175 212 206 214 220 218 207 206 212 204 231 215 199 223 238 203 236 200 216 232 262 190 212 227 222 223 198 220 176 222 219 212 196 220 207 236 211 200 228 236 240 217 222 206 233 197 229 236 242 239 230 232 211 236 218 230 231 207 222 196 204 233 215 242 226 237 213 229 233 224 206 195 212 214 241 225 236 224 213 229 230 220 200 214 235 219 237 213 222 216 204 240 211 199 224 223 221 242 228 255 260 215 219 211 202 227 206 212 243 222 240 226 239 227 197 218 211 203 200 267 209 229 221 225 216 184 250 201 210 200 189 225 203 189 213 236 233 201 210 234 219 197 200 237 225 197 216 213 201 206 233 215 214 226 202 206 208 201 197 189 191 196 209 221 240 202 241 216 205 211 214 238 199 226 225 218 246 194 223 204 204 208 230 215 220 232 213 210 231 223 203 194 205 212 236 182 209 209 221 207 235 235 211 219 219 217 190 193 202 235 214 195 211 189 209 193 222 221 186 204 225 221 205 218 235 224 193 210 226 223 220 216 240 203 202 207 189 187 216 204 216 215 241 234 217 168 216 210 224 188 215 201 182 219 227 240 202 199 219 236 184 193 227 227 209 215 230 212 207 239 203 215 204 220 207 225 207 213 229 230 219 198 209 218 217 202 227 234 228 207 220 207 205 209 196 225 221 209 191 189 239 217 209 211 212 192 207 216 203 219 199 205 209 239 218 212 234 186 205 206 218 173 218 212 221 187 232 220 185 215 240 226 202 193 208 195 210 192 238 216 215 223 205 203 213 231 231 202 203 202 200 214 235 196 201 215 209 210 216 216 212 220 217 232 212 213 210 206 228 212 221 208 217 224 216 191 189 205 197 218 215 216 177 226 214 185 199 207 227 203 218 239 190 224 200 193 220 231 209 204 211 210 205 220 184 219 195 202 188 225 191 211 206 213 192 210 212 216 201 219 220 230 209 211 198 198 183 194 202 228 239 234 183 228 239 214 228 185 224 221 202 235 216 199 235 212 182 207 194 217 209 229 203 203 216 199 231 210 199 172 182 224 196 207 235 215 227 218 207 210 235 218 216 195 204 197 207 190 185 235 202 232 215 195 213 219 226 211 194 213 217 211 210 211 224 215 216 199 227 200 209 209 211 226 193 202 186 217 219 213 210 203 239 214 224 221 214 196 232 209 210 188 199 221 203 187 236 210 206 215 207 209 236 215 209 197 200 206 211 229 191 185 220 218 211 208 218 203 198 213 206 217 216 208 217 188 213 203 206 218 219 189 225 217 187 193 233 196 196 209 209 212 218 205 224 214 237 200 219 225 191 223 218 186 178 218 196 209 199 192 198 225 201 245 217 220 245 191 222 215 214 210 216 223 213 226 221 184 197 197 226 208 192 244 238 226 230 208 205 205 193 219 222 225 216 223 228 178 215 219 211 212 199 224 204 220 199 210 241 214 205 224 209 191 216 204 219 212 226 235 209 209 202 182 226 208 204 199 205 206 210 261 214 231 221 205 221 211 209 197 188 201 188 220 226 210 205 215 203 207 216 236 208 225 223 200 197 217 207 221 229 227 205 238 200 213 216 213 193 225 217 215 227 227 227 222 233 215 208 217 201 203 199 230 187 214 256 207 230 235 204 235 209 204 185 213 206 200 184 208 239 215 196 192 201 195 229 205 228 237 209 233 214 240 207 240 227 198 211 222 264 238 217 218 229 203 211 204 241 215 236 223 224 221 195 217 219 208 208 205 193 191 228 215 230 236 236 217 233 207 224 235 224 266 242 214 233 231 271 205 223 237 211 218 232 229 213 237 240 235 259 238 225 250 237 224 230 220 222 229 236 283 264 213 230 259 225 212 236 246 262 205 257 274 231 267 231 263 234 273 261 235 241 235 206 243 231 247 248 236 230 226 230 256 241 260 268 261 220 220 200 212 220 224 227 238 211 197 231 208 243 224 197 228 187 261 232 226 230 220 202 206 237 237 218 220 225 247 225 234 206 204 209 244 227 225 213 197 217 234 234 208 242 197 218 219 210 232 217 218 214 229 206 235 184 216 206 213 213 202 186 210 198 194 204 220 231 214 220 216 221 218 198 204 206 192 232 201 218 236 205 205 230 232 203 196 211 205 199 213 217 207 204 216 227 201 206 196 209 196 223 246 226 197 235 230 185 190 197 203 238 234 201 220 200 227 212 236 194 190 185 192 225 213 221 194 221 211 204 218 204 211 211 220 208 229 220 216 224 221 228 230 213 213 236 188 199 219 207 212 182 203 180 193 212 191 186 176 215 203 173 200 212 187 215 220 221 196 224 206 210 215 218 227 181 224 185 209 192 179 189 200 198 207 217 196 187 199 200 187 237 226 212 189 215 193 204 204 188 214 210 187 228 206 221 214 227 205 241 203 209 207 194 209 192 200 200 200 216 207 207 215 200 196 189 228 208 194 202 230 210 222 185 203 207 183 214 188 210 201 218 223 220 196 180 181 186 197 215 208 219 176 230 211 215 216 200 207 211 195 214 219 187 234 209 225 192 203 199 205 234 207 213 199 205 186 221 223 207 198 201 208 223 218 226 206 188 192 196 206 205 210 217 209 185 197 200 211 207 221 228 193 213 208 186 206 204 204 228 207 193 211 223 186 201 196 225 200 198 214 196 214 201 217 196 185 223 244 196 201 203 211 192 185 222 207 221 200 183 198 225 212 214 204 208 184 197 201 202 200 194 199 227 201 238 190 193 241 228 201 209 207 212 212 216 197 230 226 216 185 225 181 218 225 217 206 207 204 211 218 214 193 204 220 199 221 209 243 204 217 218 192 189 206 178 189 183 216 201 193 195 203 214 184 197 204 214 210 213 192 215 220 210 209 182 218 202 229 188 207 197 204 221 194 206 206 197 198 223 203 211 191 217 225 206 189 193 215 204 221 195 201 236 207 179 188 206 195 224 190 194 210 234 242 200 204 201 212 203 226 198 239 216 230 225 189 203 173 196 209 198 186 191 198 210 209 188 232 221 217 192 200 216 173 216 202 184 182 209 203 205 183 220 201 187 196 187 223 214 211 197 206 182 210 230 222 191 211 189 207 199 229 207 191 201 195 222 210 205 203 219 199 187 201 200 183 215 192 222 193 186 216 189 210 206 192 213 228 201 224 200 197 222 203 222 204 206 213 204 202 225 215 227 209 199 192 202 201 201 219 189 225 194 217 222 191 247 183 189 178 221 198 240 198 221 209 200 205 204 229 189 178 202 222 176 199 213 202 192 193 214 222 182 230 211 204 214 195 218 202 201 187 204 231 187 198 196 209 188 194 220 207 177 185 213 207 225 190 210 196 194 212 223 198 182 218 184 192 221 195 179 213 190 217 208 223 203 167 188 198 205 210 214 184 190 189 226 197 209 219 197 191 200 235 218 191 215 199 209 200 190 187 217 196 236 181 229 218 214 195 214 186 203 192 188 218 212 212 195 202 187 197 208 210 201 205 168 191 217 181 218 213 181 167 209 207 190 212 204 194 214 219 207 213 194 198 218 202 202 178 199 216 205 199 210 201 185 220 220 210 186 202 204 181 200 170 213 170 202 184 207 200 209 209 212 191 208 202 195 186 200 183 203 210 205 196 208 206 222 218 212 207 207 179 200 199 220 205 216 210 179 174 198 207 213 202 236 204 188 193 197 188 185 204 191 185 173 211 226 222 197 187 199 187 171 203 216 213 202 202 194 186 186 179 217 214 199 198 216 230 179 193 185 179 196 215 207 213 185 209 206 194 192 206 194 204 220 190 183 216 176 191 172 212 218 208 205 190 204 233 207 204 206 193 195 205 191 195 194 205 205 187 183 189 182 196 201 207 214 184 171 208 218 200 231 203 208 195 202 199 190 196 240 196 200 200 203 186 202 193 210 211 212 220 191 234 212 227 194 223 194 190 189 218 182 188 179 198 211 203 224 193 192 226 201 178 194 185 184 205 202 185 220 210 184 176 196 230 221 197 196 220 208 200 188 214 207 194 204 196 204 196 170 186 205 182 186 200 204 203 207 192 204 197 186 181 206 212 208 193 192 180 228 214 209 192 196 191 213 213 180 194 188 198 212 213 202 222 195 208 196 211 220 179 210 207 217 187 209 207 223 217 177 232 187 188 217 205 206 194 218 200 179 205 193 247 204 185 199 215 198 183 208 208 209 187 190 199 191 190 211 206 219 200 173 195 203 211 208 199 190 192 208 208 205 199 212 198 195 189 202 203 189 204 192 195 227 192 193 243 226 217 196 224 204 221 213 192 191 231 180 235 204 233 198 207 208 192 206 204 216 221 209 191 219 191 224 222 195 192 211 212 211 221 208 191 200 193 257 208 201 177 224 218 189 184 204 197 185 206 235 206 189 197 206 215 201 192 191 186 212 196 216 208 216 207 193 196 185 202 226 185 201 197 208 213 191 173 193 194 206 211 213 208 211 218 191 198 211 198 219 168 207 198 211 224 226 221 205 230 213 189 212 222 204 200 218 188 217 200 184 201 201 207 211 201 188 220 223 204 205 203 195 206 199 209 192 220 196 226 215 190 231 198 184 198 199 211 192 205 211 197 189 196 178 210 185 191 205 192 217 190 183 177 211 228 202 206 206 214 207 201 214 208 212 230 191 211 192 157 212 194 204 198 209 203 223 188 200 244 218 209 169 200 188 202 201 185 195 181 213 186 194 195 219 225 200 236 209 198 182 224 204 195 208 213 189 163 207 183 219 194 220 220 213 170 221 213 187 211 201 165 221 199 179 233 193 207 189 205 165 207 192 189 194 198 184 225 196 196 183 190 195 228 188 208 187 178 210 219 200 224 210 189 224 187 205 219 226 185 169 227 197 241 207 227 194 194 195 205 201 182 184 215 238 215 228 205 195 184 206 198 212 198 197 202 204 225 214 171 203 213 219 195 206 186 222 185 216 207 213 181 214 213 217 199 229 187 189 217 199 207 219 214 205 190 212 199 201 175 189 183 187 218 208 246 206 200 200 218 196 201 198 197 188 184 197 167 219 204 232 216 190 206 213 216 184 189 214 203 205 217 190 212 196 201 200 190 224 187 197 193 217 194 199 182 156 212 204 213 192 186 190 197 201 216 203 205 195 229 227 212 207 210 189 215 189 202 200 196 217 198 180 196 199 207 184 222 207 205 224 203 187 201 185 204 212 198 215 183 207 174 209 206 180 194 203 204 219 208 217 188 200 203 220 223 210 190 192 215 195 224 195 201 190 235 200 211 178 247 199 219 182 174 177 197 207 225 186 233 226 215 184 198 226 202 200 227 212 202 208 187 212 214 204 210 216 192 209 213 203 199 191 200 213 194 219 199 198 206 222 194 213 213 221 189 223 196 197 222 204 214 187 188 240 198 223 204 216 196 186 214 224 209 212 206 213 196 221 215 203 196 188 219 211 194 207 233 212 188 191 207 206 203 198 205 231 207 208 205 194 236 222 200 209 203 188 195 231 191 210 217 214 205 223 207 196 192 200 216 221 214 204 218 214 221 207 206 205 210 205 213 188 229 213 180 199 197 183 198 200 224 207 194 222 235 216 206 197 200 211 215 206 200 192 229 185 209 227 223 200 223 215 205 221 189 218 219 202 242 202 218 196 204 241 215 232 210 217 202 181 192 206 229 227 217 205 226 204 232 222 207 241 205 223 218 235 229 205 228 215 200 203 223 202 206 216 192 219 245 208 211 240 202 213 200 216 195 187 212 216 184 216 204 209 210 196 221 189 238 219 206 214 221 209 204 218 188 200 220 204 203 200 192 229 215 225 214 188 208 230 186 190 219 199 226 195 179 224 183 184 213 196 219 182 204 201 213 198 196 206 231 225 217 188 222 195 216 204 211 237 214 216 208 199 212 216 202 231 195 198 217 210 204 203 190 225 199 226 189 200 201 202 189 199 225 207 210 240 213 197 192 211 185 178 197 185 236 227 216 177 209 208 211 244 196 182 205 214 225 226 197 210 222 205 202 205 210 220 259 201 177 187 219 257 212 188 249 177 210 215 204 206 234 215 189 211 198 184 187 216 206 217 229 206 176 207 217 221 193 204 183 205 235 237 208 191 199 198 223 194 213 204 211 211 200 188 218 217 217 228 212 223 192 224 201 200 181 209 215 177 196 196 198 219 203 218 229 211 200 204 186 208 202 209 210 193 221 215 204 192 225 187 215 217 206 193 212 197 212 202 195 200 211 217 215 196 197 211 229 197 190 210 208 195 198 207 200 229 172 199 191 202 203 192 185 207 231 182 211 169 230 201 182 191 205 191 205 200 195 222 221 207 205 215 202 203 202 193 193 206 187 241 211 200 205 221 185 197 195 204 193 215 221 214 213 214 210 209 216 229 200 192 212 210 201 193 185 200 202 215 190 187 198 207 207 211 202 192 201 206 215 164 191 188 201 218 222 197 175 218 194 211 205 190 197 218 204 230 180 199 243 217 195 200 222 206 169 202 196 230 213 220 206 225 191 182 208 229 192 202 207 213 194 224 224 207 174 220 224 202 205 198 216 230 198 195 222 192 201 195 198 205 222 235 210 216 223 202 210 212 192 203 242 197 192 214 227 199 208 212 219 214 191 207 203 189 188 207 219 210 201 211 216 199 196 240 205 206 187 218 193 211 191 234 211 186 235 225 218 200 212 182 222 199 231 219 193 210 201 233 211 215 209 192 213 204 215 209 199 203 202 226 231 225 205 231 187 184 189 221 209 181 213 190 216 224 205 211 200 206 222 214 206 191 207 231 197 219 205 222 197 216 190 203 198 186 230 207 221 218 195 217 237 196 220 216 193 221 195 200 209 193 196 228 182 237 220 202 203 202 211 221 219 242 206 192 199 208 206 211 204 204 205 202 225 224 182 208 211 185 199 194 209 195 189 211 198 196 203 203 215 193 203 187 181 220 190 202 212 218 212 231 179 225 200 189 234 227 196 209 197 215 195 209 207 225 204 200 209 243 223 193 222 237 179 208 225 199 210 200 198 191 212 206 231 201 214 194 206 203 210 208 209 193 221 213 194 223 171 212 228 208 205 214 224 194 209 202 221 200 217 214 182 213 208 220 197 194 214 202 188 226 209 193 231 205 207 222 225 197 187 219 213 210 219 186 208 198 192 216 204 206 201 178 214 213 208 202 219 206 203 209 200 211 213 213 195 216 189 199 181 202 193 206 206 231 206 209 197 209 206 213 194 188 187 183 208 197 226 210 227 197 212 219 194 214 200 193 206 221 213 190 226 215 189 204 214 203 193 208 204 205 157 215 188 215 210 217 202 212 207 215 202 201 199 192 188 192 210 210 208 204 224 181 198 211 219 196 214 198 226 204 214 200 204 210 222 201 194 189 201 213 185 208 218 196 194 212 204 194 196 192 204 204 217 194 212 217 197 202 194 212 194 189 197 198 196 210 246 191 261 219 215 170 203 162 204 201 211 201 198 189 193 238 193 208 188 199 218 207 203 208 202 184 197 221 201 195 200 203 180 220 211 200 197 214 187 195 177 171 194 201 232 216 172 179 209 206 223 217 204 188 203 201 185 192 223 203 194 212 244 198 193 194 221 191 203 211 196 181 208 183 201 194 216 199 221 224 209 211 205 220 217 186 194 196 211 204 194 234 202 186 182 201 192 214 208 207 221 192 193 233 193 220 204 209 190 185 173 200 197 223 201 205 188 201 188 204 214 202 198 191 217 206 218 200 222 193 187 194 204 192 213 204 212 204 205 211 204 220 195 216 204 217 202 229 212 223 215 213 206 211 227 178 191 189 217 205 215 218 223 192 194 216 199 200 205 184 165 210 235 193 197 198 196 214 188 204 212 213 195 205 193 209 192 192 191 202 170 169 191 208 194 218 182 177 210 196 195 187 206 195 203 209 198 209 207 193 183 189 202 206 218 204 191 204 216 189 219 196 189 209 202 212 203 225 190 190 180 204 192 196 213 184 222 192 203 195 216 212 186 222 177 190 183 198 221 193 181 183 177 186 228 198 190 192 239 212 208 211 213 207 211 197 217 185 219 226 193 205 205 221 220 209 206 190 227 209 190 210 186 207 201 190 207 198 197 200 200 197 226 178 193 202 218 221 184 217 207 216 202 214 231 207 188 183 235 215 221 237 206 210 187 226 218 191 196 212 185 210 163 190 228 229 205 211 185 180 211 233 247 210 186 209 214 192 201 193 183 201 220 212 199 228 193 198 206 202 224 191 206 214 210 215 228 207 212 208 210 207 229 211 209 222 206 221 235 215 198 215 185 220 207 209 200 195 225 206 199 170 194 193 216 211 196 195 207 189 221 238 202 195 207 218 232 225 221 196 214 229 195 188 206 193 197 198 197 191 229 206 238 196 214 207 228 205 206 208 192 187 225 162 224 191 218 221 201 206 194 203 191 200 202 214 199 192 192 223 192 225 219 222 198 219 217 208 212 215 218 195 224 186 205 181 189 201 198 238 193 185 203 203 207 220 193 188 208 203 214 215 190 231 213 206 200 218 235 237 205 207 244 207 223 162 207 184 206 196 181 209 224 199 205 245 197 210 226 199 187 209 186 214 201 199 183 216 202 231 222 214 193 201 194 205 232 209 203 202 209 189 180 204 213 208 201 173 207 207 205 233 218 182 207 202 225 214 189 220 209 171 212 190 210 213 204 207 193 209 225 207 195 183 169 213 214 207 184 212 212 192 223 204 212 194 202 215 173 210 217 224 226 198 200 206 196 194 225 195 223 195 211 209 218 220 213 178 232 237 210 212 227 233 201 180 222 204 205 208 171 194 199 204 200 210 217 207 224 234 203 214 197 201 225 221 195 190 185 189 212 203 217 202 207 218 199 211 221 207 201 220 203 207 195 204 240 219 191 212 192 224 184 208 222 224 220 205 207 202 203 230 207 195 210 192 204 217 230 192 194 198 190 211 223 207 223 220 210 189 211 229 204 206 213 218 220 227 202 213 204 198 185 218 225 220 191 192 206 216 184 224 211 237 204 223 216 226 192 189 226 211 201 235 190 195 198 217 200 220 215 221 223 176 208 198 221 219 216 194 203 235 218 225 212 195 213 200 207 193 195 201 231 201 184 190 235 191 227 207 240 187 209 185 206 223 192 167 225 244 211 249 222 197 204 224 226 212 221 220 207 204 195 228 218 194 200 229 200 197 202 191 233 238 202 226 209 219 200 194 228 185 222 214 218 223 231 212 223 218 242 205 215 226 211 190 180 218 210 216 196 196 203 173 210 210 212 232 219 200 232 212 187 222 190 201 208 214 209 203 209 212 221 185 220 214 203 235 199 209 211 192 228 202 204 211 225 222 229 211 207 203 206 215 195 227 186 198 242 209 219 186 240 218 231 218 213 219 216 205 216 217 227 233 187 186 230 238 224 210 211 192 214 200 229 233 196 225 224 224 221 210 201 214 196 221 215 219 191 204 206 223 227 214 236 209 191 222 230 209 260 200 198 224 222 219 224 219 216 203 226 230 227 227 208 242 211 216 224 222 222 224 237 208 199 249 217 224 224 214 201 201 255 205 221 205 241 213 186 208 220 228 237 217 204 223 209 218 216 215 233 201 223 233 213 222 216 189 234 210 229 233 227 204 218 232 256 245 219 225 222 207 232 263 257 212 248 223 217 221 234 256 226 209 212 201 241 235 201 276 222 219 222 219 220 213 231 257 200 231 239 231 213 235 208 218 213 208 211 230 224 215 228 197 224 210 221 233 241 237 234 215 222 202 248 217 214 216 227 242 231 236 223 231 237 223 230 217 218 236 208 214 235 238 234 212 213 210 233 189 206 224 225 175 197 227 245 210 196 234 220 226 223 221 226 262 208 258 195 241 216 203 223 189 224 214 232 195 200 231 208 210 209 226 201 247 245 214 201 221 219 206 231 185 227 198 220 194 202 222 228 226 193 190 213 223 196 216 239 255 221 216 229 211 221 207 225 209 216 222 245 212 229 246 220 222 207 216 205 237 215 219 213 203 214 202 235 201 204 203 194 217 230 219 211 221 215 234 211 187 206 210 235 249 216 211 212 204 208 189 216 202 230 190 223 199 216 220 230 197 220 202 215 233 199 241 210 201 224 215 201 231 214 213 235 239 226 241 217 229 230 226 217 201 226 199 236 209 231 221 221 227 225 228 221 210 213 187 200 216 237 231 198 214 209 212 230 242 217 226 199 216 201 226 176 213 212 216 236 228 201 201 223 231 217 229 199 231 239 218 233 218 231 209 205 196 219 240 219 223 210 212 196 216 206 216 232 230 209 205 238 204 199 231 212 185 233 220 202 199 224 218 220 203 200 210 204 215 231 195 215 212 224 214 216 199 209 201 210 210 207 225 225 233 218 206 206 206 243 225 220 198 211 247 226 234 192 221 209 213 194 207 222 219 201 227 230 210 206 213 231 220 232 207 201 209 236 205 222 193 230 207 238 215 203 203 221 175 219 200 237 219 209 235 235 201 186 219 201 246 214 208 241 208 218 217 202 220 204 209 215 219 242 204 213 216 213 225 223 222 219 218 228 213 222 215 204 241 231 188 231 223 261 224 235 208 210 211 217 207 234 225 227 228 210 204 211 209 206 198 213 210 206 241 206 193 226 238 219 186 219 217 203 238 234 232 210 198 186 205 230 225 219 240 209 205 250 218 207 220 246 217 226 215 206 218 249 211 215 211 236 199 209 204 227 231 202 208 213 232 241 200 217 215 222 224 210 222 216 204 228 186 218 205 233 227 226 227 225 217 214 198 189 214 246 226 225 225 221 231 226 223 216 195 233 200 222 206 212 229 214 182 241 250 208 217 221 182 219 225 205 226 232 219 230 216 212 203 222 244 215 227 255 240 227 210 225 227 216 215 220 221 228 224 220 205 222 202 222 222 243 258 211 248 189 231 228 218 223 222 227 196 219 236 210 227 225 207 218 198 225 226 222 207 209 230 241 241 204 194 225 221 211 243 221 194 208 219 249 210 243 229 242 230 206 224 225 213 220 227 260 219 179 192 232 225 213 210 231 220 194 224 219 227 211 241 207 231 203 231 211 219 211 223 219 232 234 206 230 230 214 211 215 215 240 224 236 233 214 242 239 202 227 226 236 226 208 225 204 196 201 237 221 215 229 215 215 219 216 248 213 233 224 227 231 239 202 204 205 214 223 181 215 230 230 225 236 235 233 200 212 217 204 219 209 197 218 242 205 234 213 215 220 227 223 219 236 246 244 225 220 269 244 224 228 195 239 220 209 227 239 216 256 240 232 216 223 209 234 211 210 211 198 211 243 199 236 233 222 256 223 216 221 230 231 192 203 243 230 223 208 210 213 217 209 218 240 236 233 238 212 236 240 225 213 233 225 211 236 240 193 212 226 213 234 203 210 206 221 255 228 220 233 199 212 233 226 181 207 244 245 232 194 206 221 224 197 214 214 210 227 216 242 240 240 219 232 213 230 209 204 195 244 216 221 213 232 230 215 246 215 230 230 226 236 236 198 216 187 215 237 235 264 201 213 213 231 229 213 250 218 224 231 219 215 259 234 203 235 232 232 242 210 243 243 232 215 229 237 207 228 246 230 209 207 221 197 200 234 237 225 212 233 220 194 217 237 238 231 248 229 242 229 215 216 267 223 220 207 212 217 191 210 235 230 209 226 216 213 214 257 230 229 183 209 245 260 234 222 228 236 200 245 239 230 237 215 235 193 230 206 232 209 220 220 236 247 244 257 213 209 217 244 211 200 237 211 217 211 226 209 264 232 232 227 234 230 232 201 246 245 262 222 241 220 232 228 214 242 237 233 233 241 210 237 233 228 209 241 247 210 229 219 226 238 196 221 220 206 211 201 211 239 232 216 224 206 224 244 228 235 214 229 206 233 224 217 246 223 211 212 212 199 210 222 234 243 236 238 216 240 243 241 227 219 210 232 227 233 255 246 232 224 233 209 234 216 236 209 231 236 232 228 197 248 250 237 229 231 200 216 192 224 219 216 263 236 182 192 239 221 210 236 235 215 217 245 213 235 238 211 239 209 246 214 208 257 242 189 244 224 214 246 226 246 198 235 206 201 217 207 206 212 217 207 209 225 217 190 201 233 230 220 222 238 224 238 221 230 232 245 221 241 213 234 207 214 226 222 260 234 241 220 229 234 228 227 243 220 237 216 220 227 235 214 240 216 224 204 238 246 249 224 211 238 221 225 203 222 226 236 210 261 232 229 215 233 249 237 224 235 240 190 240 205 211 227 217 222 227 221 237 236 218 205 209 242 211 248 213 238 229 228 228 232 222 218 220 239 223 230 216 202 232 228 223 241 240 232 234 238 226 236 219 264 249 221 225 248 221 225 228 218 225 240 230 210 234 195 204 228 226 226 226 210 205 205 224 224 189 203 219 213 245 226 220 211 205 226 239 217 233 200 241 220 227 216 218 232 223 221 225 207 218 234 231 233 218 225 217 219 223 222 225 224 229 257 257 228 236 239 209 228 239 217 213 223 223 203 232 224 217 233 228 224 208 237 234 205 233 224 193 220 237 249 211 233 214 232 221 207 239 197 190 219 216 227 229 220 201 207 227 201 222 224 223 244 215 238 216 233 211 211 237 220 236 205 227 231 228 230 222 219 221 223 273 212 204 258 202 236 225 224 261 235 220 243 228 257 200 247 218 204 203 224 199 229 218 247 210 238 213 239 203 213 216 228 221 207 221 217 225 231 226 210 221 246 225 196 238 213 244 230 213 221 226 190 221 198 240 212 248 235 204 200 240 221 213 230 215 221 242 225 220 213 232 239 206 218 262 191 212 218 234 237 239 232 231 216 264 218 225 243 241 230 237 215 232 234 228 247 214 189 268 236 240 214 224 202 243 235 235 230 206 221 193 231 215 236 225 208 274 224</counts>
			</dataPoints>
		</scan>
	</xrdMeasurement>
</xrdMeasurements>