File: data/XRD/XG-Vakuum/XG-700/W6821-1C_XG_Vakuum_700.xrdml
<xrdMeasurements xmlns="http://www.xrdml.com/XRDMeasurement/2.1" xmlns:xsi="http://www.w3.org/2001/XMLSchema-instance" xsi:schemaLocation="http://www.xrdml.com/XRDMeasurement/2.1 http://www.xrdml.com/XRDMeasurement/2.1/XRDMeasurement.xsd" status="Completed">
	<comment>
		<entry>Configuration=Factory configuration, Owner=User-1, Creation date=7/8/2013 4:01:53 PM</entry>
		<entry>Goniometer=PW3050/65 (Theta/2Theta); Minimum step size 2Theta:0.0001; Minimum step size Omega:0.0001</entry>
		<entry>Sample stage=MRD Cradle; Minimum step size Phi:0.01; Minimum step size Chi:0.01; Minimum step size X:0.01; Minimum step size Y:0.01; Minimum step size Z:0.001</entry>
		<entry>Diffractometer system=XPERT-PRO</entry>
		<entry>Measurement program=C:\PANalytical\Data Collector\Programs\Jorrit\2thom\_absolute_2th-om_10-130deg_PIXscan_56min.xrdmp, Identifier={15BCCF57-2807-42BD-B5B9-ECC0B3DC9284}</entry>
		<entry>Batch program=C:\PANalytical\Data Collector\Programs\SimonL\batch4x_2thom_10-130°_z9.1_x0,10,20,30_y0_57min.xrdmp, Identifier={EED9823A-2BEB-424C-9252-345C4EF2834A}</entry>
	</comment>
	<sample type="To be analyzed">
		<id></id>
		<name></name>
		<preparedBy></preparedBy>
	</sample>
	<xrdMeasurement measurementType="Scan" status="Completed" sampleMode="Reflection">
		<comment>
			<entry>_absolute_2th-om_10-130deg_PIXscan_56min</entry>
			<entry>PHD Lower Level = 4.83 (keV), PHD Upper Level = 11.27 (keV)</entry>
		</comment>
		<usedWavelength intended="K-Alpha 1">
			<kAlpha1 unit="Angstrom">1.5405980</kAlpha1>
			<kAlpha2 unit="Angstrom">1.5444260</kAlpha2>
			<kBeta unit="Angstrom">1.3922500</kBeta>
			<ratioKAlpha2KAlpha1>0.5000</ratioKAlpha2KAlpha1>
		</usedWavelength>
		<incidentBeamPath>
			<radius unit="mm">320.00</radius>
			<xRayTube id="1010048" name="Empyrean Cu LFF HR (9430 033 7310x) DK442154">
				<tension unit="kV">40.0</tension>
				<current unit="mA">40.0</current>
				<anodeMaterial>Cu</anodeMaterial>
				<focus type="Line">
					<length unit="mm">12.0</length>
					<width unit="mm">0.4</width>
					<takeOffAngle unit="deg">4.2</takeOffAngle>
				</focus>
			</xRayTube>
			<xRayMirror id="27010001" name="Inc. Beam Cu W/Si (parabolic MRD)" hybrid="false">
				<crystal type="Graded" shape="Parabolic">W/Si</crystal>
				<acceptanceAngle unit="deg">0.800</acceptanceAngle>
				<length unit="mm">60.0</length>
			</xRayMirror>
			<sollerSlit id="21010002" name="Soller slits 0.04 rad.">
				<opening unit="rad">0.0400</opening>
			</sollerSlit>
			<mask id="22030008" name="Fixed mask 4 mm">
				<distanceToSample unit="mm">220.00</distanceToSample>
				<width unit="mm">4.00</width>
			</mask>
			<divergenceSlit id="22010007" name="Fixed slit 1/8°" xsi:type="fixedDivergenceSlitType">
				<distanceToSample unit="mm">220.00</distanceToSample>
				<height unit="mm">0.19</height>
			</divergenceSlit>
		</incidentBeamPath>
		<diffractedBeamPath>
			<radius unit="mm">320.00</radius>
			<sollerSlit id="21010002" name="Soller slits 0.04 rad.">
				<opening unit="rad">0.0400</opening>
			</sollerSlit>
			<receivingSlit id="22010001" name="Fixed slit 4°">
				<height unit="mm">5.88</height>
			</receivingSlit>
			<detector id="7010017" name="PIXcel3D 1x1 detector" xsi:type="areaDetectorType">
				<phd unit="%">
					<lowerLevel>30.0</lowerLevel>
					<upperLevel>70.0</upperLevel>
				</phd>
				<mode>Scanning</mode>
				<activeChannelsEquatorial>255</activeChannelsEquatorial>
				<activeChannelsAxial>255</activeChannelsAxial>
				<pitchEquatorial unit="mm">0.05500</pitchEquatorial>
				<pitchAxial unit="mm">0.05500</pitchAxial>
				<readOutPeriod unit="seconds">0.135</readOutPeriod>
			</detector>
		</diffractedBeamPath>
		<scan appendNumber="0" mode="Continuous" scanAxis="2Theta-Omega" status="Completed">
			<header>
				<startTimeStamp>2024-10-09T10:21:33+02:00</startTimeStamp>
				<endTimeStamp>2024-10-09T11:17:40+02:00</endTimeStamp>
				<author>
					<name>PRO-MRD</name>
				</author>
				<source>
					<applicationSoftware version="6.1b">Data Collector</applicationSoftware>
					<instrumentControlSoftware version="7.0E 20130304">XPERT-PRO</instrumentControlSoftware>
					<instrumentID>0000000011142674</instrumentID>
				</source>
			</header>
			<dataPoints>
				<positions axis="2Theta" unit="deg">
					<startPosition>9.99826193</startPosition>
					<endPosition>129.99755682</endPosition>
				</positions>
				<positions axis="Omega" unit="deg">
					<startPosition>4.99913096</startPosition>
					<endPosition>64.99877841</endPosition>
				</positions>
				<positions axis="Phi" unit="deg">
					<commonPosition>0.00</commonPosition>
				</positions>
				<positions axis="Chi" unit="deg">
					<commonPosition>0.00</commonPosition>
				</positions>
				<positions axis="X" unit="mm">
					<commonPosition>0.00</commonPosition>
				</positions>
				<positions axis="Y" unit="mm">
					<commonPosition>0.00</commonPosition>
				</positions>
				<positions axis="Z" unit="mm">
					<commonPosition>9.100</commonPosition>
				</positions>
				<commonCountingTime unit="seconds">32.895</commonCountingTime>
				<counts 452 441 439 424 440 461 472 418 431 426 425 441 441 464 396 421 450 451 469 433 440 464 450 415 453 439 416 429 430 446 427 459 436 418 436 454 423 407 431 459 417 416 452 414 439 419 442 452 456 417 420 450 418 398 426 445 380 452 387 454 430 388 434 394 386 386 419 386 415 395 426 413 411 406 397 413 425 383 442 427 389 392 385 415 430 444 438 423 415 436 421 418 438 381 423 393 383 451 375 377 412 408 440 440 388 400 377 389 390 423 434 392 388 399 404 380 400 394 378 441 411 405 403 370 390 395 398 376 376 370 422 378 406 409 368 412 347 384 402 404 406 394 374 376 393 395 394 383 382 415 392 344 382 410 406 382 401 371 399 386 385 385 411 414 393 428 368 399 366 374 374 385 379 374 421 373 392 380 378 344 405 362 368 421 389 375 364 346 393 388 392 375 352 341 353 396 397 388 364 414 347 348 346 386 342 355 391 348 403 359 400 381 392 375 415 373 369 373 377 388 407 383 371 365 394 402 347 354 366 369 386 362 372 366 376 343 362 377 346 395 395 322 390 374 350 344 363 325 360 335 359 325 395 362 380 367 372 352 361 386 346 380 359 350 377 392 400 354 361 364 320 355 351 377 339 352 364 370 365 351 327 316 391 377 372 348 350 352 375 364 323 355 341 379 370 334 364 352 359 364 365 383 364 320 356 355 381 345 334 353 337 356 330 338 352 381 349 368 340 333 329 338 340 330 358 367 329 328 385 345 324 346 335 374 328 337 329 354 371 345 342 329 355 348 345 357 316 323 322 336 328 323 349 351 343 354 348 319 351 324 351 321 341 361 308 360 329 328 321 340 322 344 339 332 319 326 321 333 359 311 315 346 348 333 320 333 322 334 342 362 321 352 333 343 341 311 320 283 342 349 340 294 344 335 343 344 340 348 305 345 313 324 325 295 320 356 335 311 334 329 312 333 332 349 322 313 347 330 319 356 354 349 364 332 327 311 311 295 314 319 313 348 325 309 338 315 284 331 325 309 314 322 355 315 318 308 317 321 338 323 312 295 339 333 331 333 327 289 320 333 339 345 296 326 342 300 317 317 317 364 304 297 349 315 322 310 347 285 308 330 304 304 318 329 317 307 321 321 332 340 309 321 292 318 318 299 306 296 283 303 314 302 314 310 299 310 338 329 345 280 333 344 272 321 328 297 275 318 309 302 310 316 303 273 301 300 307 279 340 310 315 301 315 307 310 281 340 307 284 311 278 315 325 310 313 303 308 287 307 317 332 306 286 310 316 328 296 305 335 325 306 331 313 321 337 313 295 286 295 270 323 297 323 307 298 303 297 276 294 323 308 290 310 333 313 329 293 311 303 260 307 288 307 303 306 322 295 323 292 302 298 317 287 308 328 305 280 300 305 330 279 293 305 311 310 276 317 294 278 293 283 309 296 302 303 295 286 298 296 297 294 292 322 283 291 315 304 304 303 328 295 313 289 307 313 301 272 318 304 296 341 306 306 315 313 276 297 314 290 277 275 313 316 315 266 315 282 294 304 278 302 303 318 272 304 293 294 298 309 296 345 277 348 304 313 300 292 290 321 282 317 285 318 296 294 301 291 290 302 306 269 315 301 303 313 295 304 294 278 297 304 267 306 278 304 299 292 281 315 282 282 328 296 306 298 282 327 292 297 298 323 319 336 311 309 321 312 289 318 302 312 282 290 274 269 270 288 265 288 320 307 306 286 284 275 302 319 316 297 281 293 275 308 324 309 292 286 297 288 292 289 301 301 307 307 316 303 294 320 276 283 282 267 295 287 284 307 299 285 294 280 333 284 255 315 286 292 312 299 293 294 283 332 285 279 313 278 282 267 267 301 314 312 306 294 289 305 276 298 293 281 298 306 289 320 300 313 317 320 289 296 311 316 291 286 276 294 301 292 299 313 299 278 327 324 277 291 269 308 291 301 311 315 320 332 308 313 314 317 315 292 311 331 327 307 280 322 295 304 336 300 286 294 297 298 330 293 315 330 315 311 305 327 290 331 292 314 298 309 308 330 325 313 339 322 306 282 268 284 301 323 286 303 307 290 298 297 305 337 328 318 331 318 302 327 299 298 290 327 280 311 311 318 301 326 299 302 317 331 289 320 334 295 294 301 298 320 307 303 293 322 281 293 326 312 310 288 330 289 329 287 301 291 306 292 319 301 354 267 296 300 305 307 307 316 330 350 301 314 309 309 328 330 312 305 308 326 342 319 311 317 336 334 294 314 329 335 348 335 319 319 293 303 341 295 312 310 323 320 308 299 333 356 370 307 330 341 326 314 317 329 334 347 307 306 331 325 322 306 293 326 330 319 330 321 287 308 300 300 314 305 325 315 300 275 312 306 332 320 348 324 347 313 323 329 315 309 306 345 342 312 332 318 314 346 339 325 296 307 350 351 322 347 333 315 298 324 334 304 318 326 330 314 315 288 324 320 315 306 321 311 308 327 320 327 314 309 306 315 313 317 331 330 331 329 334 335 338 332 307 289 297 318 326 309 347 323 341 318 303 308 306 317 331 307 307 310 353 308 297 311 319 322 358 314 338 331 327 345 287 321 308 331 315 344 325 381 318 357 319 352 317 309 343 329 308 334 314 315 300 368 372 355 315 307 330 339 309 312 324 317 314 304 326 315 333 332 309 348 337 323 342 311 319 318 341 328 338 321 340 313 320 346 340 317 357 334 354 320 360 344 366 316 306 349 383 304 349 341 345 368 323 333 355 312 301 344 311 335 313 346 321 304 331 340 324 338 298 358 318 348 361 337 333 339 320 305 340 321 346 312 346 332 338 330 311 367 340 332 335 322 362 325 323 325 327 293 353 357 360 347 344 334 333 309 332 340 322 339 332 317 313 317 335 300 332 307 309 342 359 311 349 335 313 342 324 347 307 330 331 325 306 348 327 329 308 330 315 340 357 348 322 320 292 347 317 334 343 353 361 316 335 339 311 316 301 337 335 321 328 305 366 330 368 368 338 335 293 361 320 335 356 326 309 316 294 344 309 320 334 331 319 300 303 309 326 350 340 302 313 319 286 339 310 303 334 327 317 347 305 316 314 324 329 304 337 362 313 349 295 322 323 350 352 332 346 329 309 322 328 323 340 336 353 343 309 302 313 343 309 315 308 328 310 314 318 334 309 332 304 332 347 337 290 307 342 318 310 334 314 351 334 304 328 309 358 294 328 321 318 311 352 316 329 332 296 334 306 314 331 327 301 300 317 314 335 307 320 328 334 304 319 318 295 340 319 310 345 329 310 332 270 295 335 314 314 301 323 294 319 292 348 321 332 315 305 313 307 338 308 311 330 302 306 288 317 328 323 343 286 324 300 298 363 327 310 323 321 301 307 293 303 308 309 328 320 273 316 312 318 325 320 313 290 318 314 329 336 314 310 345 314 344 292 306 318 347 315 275 317 304 313 325 311 285 289 314 314 338 307 325 301 313 305 290 316 325 310 292 283 309 332 329 326 317 306 337 325 283 292 321 311 307 320 326 298 314 293 332 277 324 343 285 316 303 321 321 319 308 310 366 339 311 330 298 325 297 314 292 310 308 303 324 315 285 363 304 301 318 315 320 306 308 332 300 298 304 335 327 313 290 289 284 320 303 289 303 336 312 273 297 283 320 325 296 318 307 318 305 318 305 290 282 316 297 311 323 304 294 300 277 299 270 300 287 285 300 280 308 287 306 322 273 319 311 292 286 328 346 309 309 287 300 284 313 313 299 292 315 295 293 299 294 277 290 303 283 292 300 296 296 280 304 297 299 299 311 264 311 286 309 310 308 285 343 324 255 302 290 334 302 300 314 290 268 273 288 316 289 307 271 296 308 304 283 303 298 297 294 319 290 287 268 283 308 288 278 312 337 324 299 273 274 305 295 284 296 323 317 302 319 289 283 309 282 311 298 304 299 287 306 271 295 298 281 299 292 277 308 289 279 282 306 286 308 259 282 301 271 297 317 301 276 307 275 302 286 281 292 304 282 324 289 286 298 306 285 300 312 303 266 281 324 292 298 303 271 304 312 275 287 301 282 318 311 307 296 356 298 287 288 276 275 290 288 302 295 289 271 313 290 319 286 275 292 298 305 292 307 307 301 283 315 291 306 231 279 309 260 285 287 297 290 280 289 304 298 277 298 248 307 259 281 301 275 278 287 294 297 305 287 297 276 298 283 293 264 256 290 288 281 290 274 279 266 297 267 275 263 267 280 263 290 292 256 291 284 287 270 281 283 270 275 262 263 275 300 302 293 285 282 280 287 298 288 273 281 267 272 263 277 294 302 229 292 271 248 291 268 278 296 298 263 262 294 282 260 248 292 265 274 260 286 271 296 266 316 315 238 280 275 292 276 279 258 303 282 276 273 281 245 285 255 297 293 286 300 236 264 268 276 274 287 261 281 255 274 278 293 280 310 246 262 269 265 235 271 309 299 293 261 266 257 288 267 280 262 279 268 284 263 237 268 281 273 300 250 259 240 238 263 282 275 257 239 247 243 264 271 275 262 245 281 261 290 271 309 249 243 277 255 255 247 283 279 265 272 256 285 271 295 231 269 269 257 272 268 243 301 282 264 243 285 276 270 260 261 303 279 288 248 274 269 265 287 244 236 268 236 220 271 264 238 267 263 231 239 284 274 243 271 269 272 264 266 276 238 262 238 285 260 262 248 244 226 247 241 264 230 273 220 232 256 257 238 229 238 235 269 248 265 270 262 263 268 276 238 295 279 280 249 263 277 255 247 283 280 268 259 286 276 255 257 277 257 257 269 238 245 263 231 250 262 249 277 247 264 248 255 282 227 272 219 236 260 257 240 232 276 245 229 233 236 255 280 271 273 230 260 223 259 291 279 259 230 265 241 255 265 240 282 280 248 239 267 259 263 258 215 269 266 263 261 269 238 247 277 237 275 249 275 240 232 270 258 232 247 249 271 274 231 226 239 247 248 267 224 282 270 255 259 233 271 233 276 239 247 267 246 281 268 259 263 280 244 237 262 266 238 255 221 258 238 283 274 237 246 271 229 275 256 263 266 264 246 245 226 258 248 246 228 244 246 263 270 256 225 267 255 261 257 231 247 236 235 245 242 269 246 212 278 221 277 221 284 259 270 257 249 243 235 217 249 230 263 235 264 210 286 277 287 249 244 272 220 268 234 241 249 276 225 243 249 235 271 223 266 247 230 239 237 236 234 289 256 264 233 222 228 256 279 245 272 246 240 227 270 256 290 240 262 238 270 265 271 260 246 245 241 234 277 272 236 230 234 259 241 230 242 280 239 261 257 237 255 201 230 248 242 221 256 238 256 225 269 258 275 216 205 273 270 273 263 271 246 229 227 272 225 236 273 224 235 232 226 240 234 249 228 259 225 227 256 270 235 235 248 293 278 245 257 244 229 274 278 249 266 237 264 233 230 267 260 242 257 265 223 223 261 219 282 247 265 233 241 268 249 269 271 268 221 304 284 235 258 229 241 225 243 249 231 265 256 241 231 243 262 231 247 239 198 222 255 225 226 267 235 234 243 231 239 227 231 260 248 220 263 248 224 264 269 261 249 260 237 248 232 246 242 249 261 236 233 242 243 225 272 247 249 239 235 260 235 277 213 257 232 241 225 239 233 237 259 243 262 238 225 232 257 243 268 232 246 207 245 258 239 257 240 228 265 249 237 271 269 235 219 258 238 261 250 228 256 228 219 257 270 226 239 266 228 237 236 265 241 242 233 233 230 231 249 225 211 266 248 226 269 247 242 225 285 223 226 238 261 261 233 240 278 260 259 266 223 240 231 260 255 230 226 221 238 230 260 231 241 246 240 229 224 244 247 219 245 244 282 240 245 256 238 275 203 221 239 241 247 231 267 242 238 236 255 240 258 276 267 245 257 272 243 241 244 236 236 219 222 236 250 260 280 220 242 224 237 219 255 250 234 234 216 261 235 243 257 208 228 246 255 235 258 202 244 258 243 234 233 232 235 243 246 233 246 200 265 260 248 228 272 248 212 259 257 263 237 250 236 235 263 213 247 231 264 236 209 227 236 245 235 237 225 228 232 244 243 233 261 260 255 239 271 236 227 223 256 266 214 224 269 241 242 244 236 237 239 237 239 237 248 266 229 244 258 265 247 243 267 231 259 224 256 272 229 256 247 219 229 236 266 249 256 258 263 248 244 245 237 218 266 249 215 204 233 231 222 257 208 220 215 278 215 234 223 232 240 242 262 224 226 217 229 244 281 199 256 231 222 257 244 229 216 229 240 232 229 217 236 239 264 233 276 226 208 212 242 208 247 247 239 221 233 274 228 232 236 249 218 260 234 255 232 205 231 264 225 241 213 192 229 234 239 248 255 260 211 238 230 244 276 229 222 220 261 227 226 234 223 258 249 225 241 246 237 207 216 224 233 256 220 233 223 244 285 276 242 223 248 219 221 233 235 260 233 239 207 242 237 224 225 256 263 262 230 242 239 225 230 219 242 244 250 212 259 239 216 216 246 226 235 204 243 228 234 248 240 230 225 225 235 219 220 260 216 236 262 266 244 258 276 223 230 219 232 231 245 219 230 246 259 225 239 268 238 226 227 220 206 213 222 220 245 228 235 227 224 232 246 246 222 237 240 226 240 208 263 238 235 223 201 222 233 215 239 263 239 249 206 265 222 196 218 230 242 267 262 265 221 281 255 233 216 257 249 211 261 245 265 265 240 212 221 225 271 230 231 250 237 212 222 217 244 247 243 228 241 239 239 228 257 242 240 242 223 247 242 199 226 241 222 226 241 263 243 273 240 190 256 234 234 232 226 227 228 227 225 236 224 230 246 235 243 242 225 247 230 231 227 287 236 231 236 233 212 216 238 204 247 265 269 248 228 233 255 238 238 232 245 270 239 275 230 229 233 241 259 255 249 225 237 245 225 243 264 258 239 238 238 212 215 286 230 234 240 233 207 218 226 239 267 222 261 249 220 225 237 255 267 245 230 257 249 255 222 242 284 241 243 243 257 272 233 221 265 237 234 250 265 272 258 219 230 270 228 244 258 230 226 243 263 258 258 240 237 217 223 250 281 223 244 246 210 211 231 272 255 249 243 258 233 244 230 242 247 244 234 259 229 267 246 231 240 245 218 238 219 227 234 240 247 230 239 249 232 249 271 257 219 243 234 232 244 233 227 257 230 250 232 259 215 259 249 232 283 237 219 243 248 222 230 276 246 268 249 235 242 240 245 234 233 233 263 243 218 237 260 213 228 232 261 239 236 221 229 220 225 249 239 223 239 235 230 265 249 243 281 190 232 237 231 247 240 256 242 237 242 263 232 250 267 255 235 230 225 233 236 217 240 277 259 281 249 238 221 243 231 221 249 244 235 261 219 271 256 266 241 265 245 274 246 205 270 227 260 248 221 272 272 258 255 244 226 237 262 224 238 268 262 217 215 229 256 267 257 236 235 255 265 229 275 262 261 239 244 235 261 250 235 258 263 243 229 266 238 255 269 241 256 264 243 255 247 257 256 244 273 247 264 264 267 236 266 280 271 273 241 259 276 255 258 288 280 285 272 263 293 287 282 284 303 285 286 286 267 255 258 290 260 267 285 281 249 272 257 263 272 270 258 232 260 240 231 294 264 247 267 267 228 247 239 245 237 273 265 267 292 222 238 283 259 231 226 246 260 276 288 246 265 273 259 270 259 248 224 249 221 259 241 243 271 271 267 248 265 274 241 234 291 269 244 299 278 257 276 284 287 309 223 271 271 281 257 318 277 278 279 296 301 280 233 276 301 276 327 323 309 308 286 309 305 302 293 301 323 303 290 300 317 284 310 321 332 323 336 353 351 346 370 336 352 352 377 360 374 409 422 410 419 432 464 449 477 458 442 492 488 476 491 448 410 442 461 448 462 424 480 432 446 420 402 340 447 380 392 398 361 358 377 335 333 355 353 314 314 297 327 289 289 291 318 290 289 285 299 296 282 277 271 284 291 237 292 288 259 275 271 282 268 269 258 299 243 238 284 265 279 247 245 265 272 279 264 256 262 227 283 238 274 265 256 266 260 247 296 264 238 235 258 255 263 272 266 274 245 226 261 245 243 282 239 250 267 269 277 282 238 239 265 237 266 270 223 236 267 271 255 257 271 261 282 244 287 267 228 276 250 262 290 277 269 246 270 250 264 274 248 257 261 248 263 227 266 207 228 287 255 280 256 263 242 274 230 264 275 234 245 262 237 250 283 278 227 215 259 232 225 212 244 280 255 215 245 275 276 245 247 233 258 241 246 258 250 263 262 249 259 291 239 205 240 267 230 231 257 231 255 265 247 277 235 241 255 226 240 261 231 228 256 217 214 212 247 245 266 238 255 262 237 273 267 287 239 246 237 229 262 233 260 245 238 283 227 242 258 258 284 267 257 244 233 233 255 268 256 258 217 281 244 275 270 255 238 260 250 239 244 260 227 235 233 268 240 256 231 229 256 230 274 249 239 219 265 255 248 240 223 235 232 238 232 248 211 267 239 210 264 238 262 231 267 275 236 230 244 242 260 232 231 231 230 265 229 225 235 279 210 270 245 267 197 232 238 234 248 243 277 236 240 234 256 250 227 249 236 212 245 235 242 283 273 236 248 267 248 243 221 267 249 257 235 266 264 234 237 247 240 257 234 241 224 247 214 256 245 260 230 234 263 241 262 256 248 301 210 247 211 235 262 235 250 273 259 211 212 250 261 230 257 259 217 258 245 266 260 244 259 244 234 256 237 247 285 259 227 294 265 259 249 230 215 226 262 238 248 232 223 219 256 263 237 259 220 260 264 221 275 266 223 206 258 275 249 248 234 262 264 248 275 246 238 234 214 229 243 205 227 263 291 213 238 280 273 244 247 229 260 222 267 242 224 256 260 257 243 239 271 247 244 240 226 192 256 207 223 222 270 242 239 221 226 227 247 233 222 234 218 218 269 227 245 227 234 255 238 266 241 248 234 215 235 243 242 237 248 270 240 257 218 260 207 223 262 239 233 272 259 271 242 225 277 262 260 246 241 237 267 255 264 256 244 237 241 245 243 234 236 256 260 263 238 261 279 221 262 231 232 232 221 245 256 275 258 218 245 268 238 214 242 240 274 229 258 271 239 226 236 227 248 241 273 237 249 260 272 222 235 233 256 244 216 267 243 228 239 210 237 243 243 260 232 272 266 240 234 246 244 245 255 219 242 223 256 245 274 225 229 239 245 234 239 243 266 236 263 247 231 246 260 256 273 235 267 256 238 270 269 260 230 221 243 268 240 248 273 242 279 228 240 238 260 224 249 259 243 258 238 224 279 246 268 241 240 247 250 240 261 237 268 270 221 241 265 242 257 239 260 240 225 237 232 237 206 273 268 257 249 218 260 282 309 237 234 240 248 260 262 258 233 235 261 270 247 283 259 240 237 256 235 262 240 225 271 256 273 240 240 228 272 240 260 273 269 232 263 233 274 257 224 246 239 228 246 258 279 248 264 237 242 229 234 235 267 265 217 262 216 235 277 264 259 261 249 227 283 270 233 237 249 222 225 239 259 219 208 265 244 265 222 257 227 245 246 239 269 282 259 256 237 234 281 246 245 219 270 233 261 271 277 275 240 239 236 257 244 271 229 270 246 242 257 238 268 243 295 241 247 256 223 241 226 232 248 233 269 231 278 258 218 257 242 248 247 222 240 227 244 234 245 265 274 219 243 292 265 242 227 258 248 262 248 292 271 229 234 243 258 232 246 261 248 228 233 232 266 242 268 230 267 237 248 234 239 247 238 197 239 243 240 262 228 236 258 244 249 232 273 272 223 248 237 261 233 246 235 284 237 247 221 232 230 277 234 266 231 259 256 237 257 230 235 239 281 228 219 276 259 255 281 249 279 236 222 238 219 264 224 280 269 271 236 249 247 229 210 264 246 240 245 267 257 234 227 257 235 228 244 248 236 261 260 249 267 241 234 240 249 250 268 257 278 269 226 233 246 244 238 255 249 220 270 225 219 233 246 237 273 218 245 246 264 267 288 229 255 265 270 225 212 256 236 238 245 261 226 230 244 284 221 233 228 201 245 264 242 237 240 267 246 260 274 213 260 231 262 235 244 263 257 278 263 236 276 231 248 239 262 213 214 227 242 228 246 245 229 245 227 255 261 247 229 274 257 207 242 267 275 261 242 260 211 267 256 246 240 256 268 221 257 237 257 269 244 245 259 270 218 248 265 238 223 261 256 243 234 271 272 238 266 248 228 230 248 258 233 213 271 232 240 273 205 230 250 245 245 225 281 232 238 246 233 273 241 268 257 267 281 268 232 261 258 259 257 257 269 247 264 228 233 244 233 235 242 240 228 265 242 240 223 242 246 250 260 259 269 262 258 238 218 264 256 234 220 246 258 260 256 275 243 245 227 262 257 225 236 220 230 240 248 223 257 234 259 246 255 266 275 243 239 230 223 244 223 244 264 241 288 240 255 241 261 249 263 249 245 227 292 232 255 263 262 258 248 257 244 280 218 248 243 223 245 287 238 278 265 237 265 217 235 230 235 277 244 242 258 241 255 239 246 233 268 239 250 212 220 215 273 262 218 242 241 231 242 259 247 238 262 263 242 245 271 236 260 258 235 234 244 234 258 259 275 244 242 246 260 264 229 220 231 232 266 249 231 255 258 227 255 257 274 264 217 220 229 244 239 244 234 216 226 226 241 238 265 261 272 231 246 244 230 274 302 243 255 244 238 262 219 236 268 243 258 225 274 234 236 289 268 262 257 286 228 260 275 202 258 250 272 233 260 262 237 273 234 243 264 273 238 229 261 283 238 235 257 256 238 228 248 244 231 270 266 224 294 226 262 230 278 238 265 210 266 247 216 226 261 263 246 249 255 244 226 262 271 222 227 249 242 263 217 239 272 243 238 260 258 239 243 282 245 256 236 243 232 263 290 243 245 243 262 249 232 222 266 233 240 234 247 272 228 241 245 223 245 263 246 238 241 264 226 275 266 241 225 245 258 245 256 257 228 249 256 275 257 255 265 225 273 272 276 234 239 248 230 266 223 262 225 237 293 247 255 258 274 276 257 224 240 265 264 247 264 227 263 238 256 248 259 233 225 242 240 268 234 235 239 222 228 277 231 232 232 263 233 224 229 235 243 238 242 247 237 257 250 278 262 220 242 244 244 267 284 290 243 257 209 247 272 263 212 265 258 247 230 226 262 259 246 277 263 227 248 258 240 228 265 230 239 242 293 232 234 258 242 231 248 259 258 235 266 273 238 243 266 230 263 260 258 225 234 222 244 263 266 267 242 242 268 233 239 224 262 260 239 267 230 239 268 283 242 246 285 235 265 255 230 261 241 244 263 269 236 264 240 236 226 270 261 261 240 255 282 245 242 244 261 245 263 262 227 239 271 258 270 242 275 278 237 260 241 275 272 237 255 258 258 238 248 237 269 241 249 268 243 271 237 247 235 241 245 271 257 264 245 265 233 224 239 223 272 244 248 242 255 263 223 223 288 260 235 256 262 246 211 238 236 263 241 239 296 262 264 261 258 277 292 250 256 248 231 279 227 258 238 258 263 290 238 255 228 257 267 288 269 250 277 230 244 272 240 274 268 272 267 245 269 232 246 242 259 257 261 259 233 294 286 261 246 221 256 237 222 249 257 265 267 247 270 248 269 258 238 245 230 245 265 227 239 286 247 226 229 224 258 257 273 250 249 279 243 233 237 257 240 289 256 234 259 219 241 241 232 223 235 274 244 285 278 276 278 265 249 233 239 290 260 246 270 226 233 267 276 291 264 274 241 278 243 246 238 214 279 270 244 237 276 273 221 276 258 277 227 262 256 244 241 243 248 277 260 244 272 284 269 237 284 264 241 257 263 228 270 226 249 243 234 266 217 222 296 274 272 241 247 239 225 256 230 265 274 250 258 262 235 237 276 265 237 277 236 265 264 263 259 250 265 268 258 287 261 266 238 230 236 221 272 259 276 308 218 237 262 266 301 241 261 248 246 267 258 262 275 285 245 234 228 271 245 279 266 240 269 211 240 276 276 238 250 257 257 283 288 268 247 235 267 239 265 249 231 263 215 230 285 257 277 241 248 269 243 242 270 274 278 258 267 268 242 287 302 272 232 237 262 269 249 270 272 242 239 246 243 226 261 255 232 246 235 271 270 266 237 265 243 278 247 225 232 234 225 234 242 221 241 247 237 227 270 259 239 217 256 242 260 236 264 242 217 247 266 270 271 260 236 231 239 267 234 255 217 237 244 233 241 257 261 264 258 243 264 266 288 230 266 213 264 219 234 266 234 242 260 246 264 259 266 287 249 241 275 257 226 227 269 256 285 244 256 222 235 227 243 276 257 238 279 218 243 256 243 288 239 221 270 244 273 267 265 229 264 263 225 232 234 246 231 273 265 239 268 259 230 241 235 265 223 260 257 242 262 238 264 262 267 230 263 245 270 263 292 258 290 258 248 255 273 267 272 258 224 272 257 278 282 264 277 260 267 268 245 262 248 264 276 285 279 291 245 281 279 260 262 272 287 257 277 288 283 260 240 256 273 255 273 277 277 247 270 231 264 292 238 265 264 286 247 259 243 240 269 268 239 274 280 280 263 275 261 236 239 232 247 263 239 273 245 264 255 262 249 239 264 268 273 255 281 248 257 282 230 262 288 260 235 262 292 242 239 271 217 277 263 245 248 227 257 231 240 250 250 243 286 221 242 261 260 239 226 241 220 235 257 265 265 241 255 261 266 247 240 237 214 232 271 260 245 255 278 232 238 231 242 237 248 266 279 264 195 258 275 237 215 247 258 247 241 255 236 226 246 240 262 261 235 240 262 232 256 281 255 243 226 245 255 224 249 267 248 228 241 243 240 250 235 260 280 230 255 248 202 274 244 233 240 234 238 261 238 284 267 257 257 243 272 222 279 260 238 227 262 237 260 244 230 239 242 266 259 213 263 256 264 245 260 224 261 301 230 240 230 215 260 267 259 245 255 266 235 273 236 277 246 218 259 245 244 240 242 290 235 250 244 279 244 257 255 277 261 249 247 247 262 226 243 245 280 246 237 230 218 260 273 231 255 274 226 261 297 242 244 256 235 256 216 242 222 255 266 238 260 237 229 237 260 282 216 215 224 242 213 255 264 238 226 217 245 230 226 257 256 262 226 215 260 259 260 245 261 239 215 266 235 268 215 244 244 229 227 240 230 243 235 245 231 214 240 242 257 263 227 255 249 216 233 258 271 238 241 247 236 256 249 241 264 262 236 249 283 231 255 237 245 283 229 268 256 264 248 246 225 238 243 234 262 260 211 266 245 258 233 244 231 232 242 257 270 260 262 244 242 234 237 249 265 235 258 246 277 242 245 279 259 225 221 244 234 238 233 243 228 256 264 239 215 229 226 238 245 272 225 266 285 238 220 226 264 245 218 258 238 226 235 256 261 235 266 200 284 245 245 239 212 230 232 249 256 263 267 255 215 273 258 228 266 227 273 266 262 235 232 239 241 262 270 265 246 269 269 240 223 242 226 235 266 226 249 280 255 233 214 235 245 222 215 213 288 224 249 241 255 245 231 220 246 249 244 215 234 248 224 220 226 239 224 266 226 234 223 208 244 257 246 265 267 255 240 231 243 246 217 269 262 223 277 236 237 243 245 244 274 236 224 241 260 246 236 278 231 242 247 272 236 266 271 248 236 228 244 284 238 233 230 220 264 261 265 288 248 257 257 233 257 224 266 217 234 277 239 248 237 248 266 240 239 244 267 266 227 238 257 249 230 262 246 223 246 225 248 237 259 246 256 271 214 249 263 235 250 240 229 267 231 240 220 242 255 241 257 278 256 281 244 238 238 220 241 247 226 265 266 238 212 234 234 268 218 229 264 247 272 233 241 240 271 269 211 247 260 245 230 237 224 244 234 209 274 259 241 246 223 245 256 261 290 258 257 232 259 282 224 237 247 226 245 244 241 262 232 242 237 258 227 243 274 277 241 246 221 226 260 227 266 260 247 265 266 238 274 247 220 274 258 282 247 214 230 247 258 269 270 238 282 222 281 236 209 210 229 244 231 245 246 287 268 244 239 226 271 217 246 233 247 259 255 248 263 247 278 236 256 266 239 248 206 233 224 260 283 258 223 263 238 279 262 265 267 233 246 280 236 258 235 245 235 231 230 257 238 247 255 292 223 264 240 216 244 238 234 286 236 235 245 256 226 259 240 265 216 228 222 266 224 267 280 240 219 240 226 260 266 237 225 226 264 231 244 244 246 245 264 269 217 243 242 266 288 226 256 235 249 281 224 210 264 258 224 263 228 222 258 278 268 230 218 234 257 226 228 231 263 269 266 282 243 258 242 266 273 229 225 267 233 250 282 246 248 237 263 243 249 273 219 241 240 217 242 256 241 232 248 265 268 258 233 247 243 240 270 238 236 270 222 242 232 260 276 264 236 263 278 262 256 279 248 257 234 256 259 262 237 224 267 286 258 277 220 226 264 263 218 242 264 258 224 235 250 238 249 233 238 240 243 260 212 263 241 264 260 228 225 245 257 239 245 241 257 217 267 247 250 270 230 244 247 248 258 259 230 258 245 247 260 238 264 261 269 244 234 241 271 248 245 243 234 260 257 277 231 237 218 219 273 206 242 246 257 238 218 226 246 249 265 270 240 245 241 235 223 229 249 256 226 236 267 241 257 235 259 273 244 242 233 226 262 246 271 260 248 255 259 237 233 261 235 221 228 256 243 259 263 243 258 244 260 248 219 238 260 235 266 265 245 244 233 235 255 219 248 249 238 238 250 240 267 285 243 258 247 267 270 247 229 235 241 237 250 265 246 243 269 268 259 243 286 236 239 261 239 238 262 247 247 241 247 261 271 246 277 246 227 277 268 292 255 234 247 263 267 240 264 283 248 256 263 241 285 256 266 258 239 249 247 219 259 244 223 244 232 270 268 255 240 271 276 223 244 243 244 255 266 218 264 262 268 243 246 235 260 265 234 287 280 297 243 243 281 247 264 258 238 289 223 246 246 259 262 259 275 255 239 243 205 233 247 236 259 256 241 257 236 231 270 276 241 234 279 265 265 257 268 249 261 272 257 249 261 245 260 246 217 246 248 247 278 257 241 239 237 229 256 258 218 243 235 249 247 299 246 265 223 244 238 240 263 230 247 260 247 233 260 249 244 256 245 249 265 265 257 228 265 224 256 249 255 266 219 244 246 261 240 282 221 256 262 241 267 258 234 235 264 274 256 236 256 256 241 242 228 242 259 238 228 245 255 250 261 282 217 263 220 266 266 244 287 267 225 245 245 222 266 268 261 245 255 269 219 246 262 234 274 287 248 234 275 274 233 225 270 229 260 263 248 255 245 282 257 257 223 243 239 261 237 246 231 247 257 225 248 250 237 248 217 242 241 266 269 237 293 233 216 289 241 257 283 207 281 226 267 261 246 271 263 256 275 228 230 295 261 284 247 255 241 270 226 242 240 231 221 225 229 248 262 282 242 242 262 236 257 246 245 267 230 248 240 232 261 229 231 231 215 267 268 241 277 234 225 247 268 225 213 237 240 271 215 269 227 258 239 260 261 273 204 242 262 279 217 235 259 244 271 242 237 247 266 245 218 267 235 262 242 237 216 255 260 248 284 240 245 257 257 272 270 236 239 230 257 215 250 274 248 258 263 205 271 261 231 284 223 243 247 236 270 261 264 270 240 267 243 263 265 280 245 244 274 256 235 221 235 243 229 281 241 240 230 244 263 256 248 232 242 264 269 264 247 268 259 255 269 246 226 248 258 235 257 236 234 274 257 248 231 219 237 265 235 265 259 244 269 267 244 260 260 242 214 244 235 250 267 266 255 237 259 234 259 239 273 243 233 233 245 228 262 248 238 259 247 258 274 255 243 235 272 244 256 257 250 239 262 249 228 224 233 258 247 262 249 270 246 256 240 279 216 230 271 262 255 202 291 238 243 240 242 250 280 242 248 223 228 238 260 222 207 266 263 241 247 232 256 269 246 247 260 247 244 259 266 236 257 247 258 238 247 223 255 250 242 224 243 245 227 245 237 245 243 245 240 248 259 261 242 268 228 234 237 260 243 262 230 206 246 239 239 210 245 266 257 262 268 238 267 236 242 212 265 270 270 258 269 228 255 272 269 248 259 256 242 265 276 243 256 248 242 248 244 260 290 266 243 262 230 274 236 296 266 264 235 240 249 244 215 247 249 246 246 218 271 267 240 260 262 256 272 245 275 268 240 240 259 245 248 247 241 248 255 280 268 229 233 234 250 242 246 257 228 227 272 245 247 232 229 258 241 257 228 242 243 273 276 228 262 263 273 262 239 235 259 247 249 239 218 266 237 264 238 223 242 277 248 264 281 269 284 256 259 255 239 243 270 246 229 213 248 260 227 281 237 224 273 217 271 273 237 271 250 258 255 258 283 282 277 255 249 241 294 291 244 276 282 277 259 261 259 258 286 242 260 271 268 258 276 238 282 292 285 276 290 257 292 263 272 312 272 299 298 283 279 311 305 283 283 292 271 284 303 292 290 303 296 292 288 275 304 282 276 272 296 285 277 298 295 271 282 308 315 288 309 282 292 246 270 289 266 268 269 239 277 319 276 243 272 315 248 232 265 282 259 278 277 265 245 242 259 277 249 261 257 277 247 262 294 245 244 267 225 266 237 257 258 271 264 237 271 283 261 261 234 283 240 221 256 268 266 258 258 256 246 272 248 255 240 236 279 262 265 244 233 265 267 237 248 223 235 273 288 237 222 255 243 235 281 220 255 231 243 257 217 237 264 265 216 265 257 280 248 274 246 234 240 261 275 248 248 261 246 264 255 249 221 257 219 243 256 266 211 267 239 240 235 226 227 237 239 240 258 243 209 235 261 247 239 241 262 238 245 258 257 238 230 260 234 231 204 256 237 269 259 256 268 271 249 244 241 239 257 256 240 248 247 245 270 256 257 277 275 217 295 246 250 260 228 260 225 240 249 241 235 266 230 233 242 255 230 232 213 266 230 243 227 263 244 241 239 290 226 277 241 259 280 240 235 271 243 262 256 249 235 275 229 234 226 257 237 229 221 235 236 247 262 234 230 238 258 255 277 258 230 238 235 228 246 245 246 214 290 267 255 241 239 265 227 246 280 256 260 258 273 243 246 235 204 268 230 228 247 231 257 214 257 237 233 257 236 240 258 246 243 242 242 241 237 260 244 248 239 240 239 228 256 267 242 266 242 259 264 220 249 263 236 237 208 238 225 243 231 218 256 244 214 264 263 266 217 235 238 245 229 243 287 237 267 261 269 260 243 244 239 241 257 260 222 257 255 221 232 241 242 231 265 241 247 237 257 242 220 263 218 220 224 243 238 265 213 240 223 250 239 262 237 245 220 263 214 264 234 248 236 242 259 256 240 219 228 243 234 271 231 266 239 204 276 262 232 225 238 242 236 250 216 216 285 245 201 234 228 238 235 221 205 256 241 237 222 256 236 233 246 260 220 249 228 249 249 238 256 242 231 221 274 270 234 232 237 218 240 237 244 216 207 259 247 228 236 242 233 222 223 247 225 240 239 260 219 224 211 247 257 266 231 234 274 242 259 256 246 232 232 249 236 233 262 245 234 258 233 210 280 257 247 259 231 248 245 260 244 258 241 259 248 232 260 258 238 238 233 274 201 244 255 234 241 266 238 258 245 242 237 229 238 293 222 247 261 233 235 242 279 246 228 267 239 260 239 232 227 266 247 247 260 264 255 220 287 233 224 238 230 268 241 247 256 245 240 243 223 242 248 232 242 267 246 250 262 242 248 229 259 208 274 232 234 235 269 245 237 247 237 218 240 234 247 220 235 227 233 256 235 220 218 239 244 219 255 242 245 233 228 266 292 241 260 240 239 257 244 232 246 258 232 259 229 261 242 248 238 230 221 264 229 232 243 213 236 283 279 266 266 229 244 261 224 267 213 221 269 241 238 240 223 234 220 268 245 239 221 245 227 269 230 239 243 262 264 220 242 214 256 223 250 231 229 241 243 256 246 233 245 239 266 241 263 238 279 237 237 249 239 258 262 257 241 249 262 249 236 212 270 241 231 231 229 222 241 237 240 242 236 226 234 247 241 231 262 255 275 230 236 188 245 247 279 218 255 237 260 274 266 240 260 217 220 238 228 299 247 231 259 236 257 224 240 257 227 245 273 248 217 259 238 229 232 273 260 219 266 233 231 242 235 260 205 256 262 238 236 262 241 256 228 239 209 227 247 260 229 235 255 273 239 261 232 257 217 243 250 220 237 210 236 256 276 249 220 256 229 235 278 244 212 236 274 245 239 250 220 232 212 258 233 231 256 230 233 232 247 229 218 265 244 245 271 261 273 237 246 226 257 257 221 216 247 244 221 225 257 268 235 241 267 257 222 233 211 231 243 226 255 275 255 267 239 279 280 240 271 257 245 228 214 282 229 218 205 274 261 262 255 242 220 217 236 217 238 247 232 215 248 248 230 232 222 240 236 249 214 243 241 247 256 237 246 257 258 226 265 240 234 226 233 229 237 245 240 257 223 237 261 209 213 233 255 209 278 245 242 266 228 236 255 240 247 266 234 232 229 248 224 279 268 247 245 234 238 248 232 248 242 238 237 246 226 232 261 246 228 239 258 208 234 265 239 244 245 260 234 263 230 245 247 224 262 273 249 224 240 246 232 242 230 256 247 245 291 246 223 223 218 238 268 228 241 232 257 239 226 226 259 232 247 257 238 228 260 241 285 272 230 249 261 263 275 248 265 267 226 240 247 240 240 241 249 257 248 270 238 220 240 228 205 267 248 234 235 221 238 273 223 258 224 245 210 259 237 242 245 273 265 255 255 257 261 296 227 247 231 225 208 267 234 278 242 269 255 243 262 268 228 242 257 226 260 256 220 237 261 281 245 259 249 270 255 259 276 238 238 229 261 243 220 271 255 258 239 262 235 238 238 233 256 244 246 238 231 256 265 227 218 225 262 245 244 266 260 275 277 239 248 240 239 234 235 209 194 270 246 220 271 236 240 247 242 240 235 223 232 306 240 246 247 256 265 274 258 263 274 210 246 268 224 260 241 227 235 233 246 280 248 216 262 232 222 287 272 259 239 226 234 267 246 240 238 288 260 269 221 241 250 222 217 231 261 219 241 240 274 258 205 232 272 243 257 232 240 244 231 249 261 256 249 231 256 247 264 277 238 241 269 277 237 232 243 242 246 286 244 274 270 273 246 262 273 236 242 235 230 232 235 259 257 221 242 240 239 261 244 268 228 257 274 249 239 226 225 257 234 248 241 274 231 219 243 218 241 240 219 209 271 242 237 259 271 271 220 246 233 265 245 223 237 259 249 242 229 256 242 226 273 241 248 249 236 240 255 275 265 258 239 223 240 244 268 215 264 214 241 244 231 227 259 229 220 255 262 274 262 229 228 280 264 275 221 237 270 232 229 233 212 243 240 239 264 299 232 263 232 237 238 269 228 231 261 256 242 277 264 285 224 249 239 214 267 238 257 243 244 241 241 257 240 240 239 265 262 224 238 265 229 226 243 275 249 228 239 248 246 257 243 248 271 258 244 225 256 241 240 244 256 222 227 266 257 241 263 261 243 240 231 247 285 260 237 271 218 262 265 260 230 250 214 191 243 260 226 217 241 228 238 242 247 225 264 248 260 260 261 244 271 267 250 229 263 246 247 247 220 268 245 250 274 279 260 269 239 241 264 240 280 232 270 223 263 281 237 257 227 258 248 274 246 270 237 259 293 210 231 231 264 237 231 245 247 229 210 241 235 242 220 275 243 239 268 260 239 248 217 226 245 224 223 241 250 234 261 255 221 249 217 228 248 262 262 267 259 238 225 228 222 260 233 234 238 262 213 229 233 236 259 225 242 246 232 240 239 238 232 234 240 260 257 226 266 270 221 225 258 261 231 257 240 260 262 236 223 239 211 236 231 249 245 222 259 246 281 236 237 220 255 258 257 255 244 255 226 224 264 244 223 261 230 264 247 233 228 238 269 268 235 264 235 244 226 262 241 236 245 229 246 228 287 221 255 245 245 249 214 241 244 294 240 289 269 223 261 205 219 263 236 231 208 238 222 258 245 268 256 230 226 263 264 265 272 246 231 231 246 279 250 232 255 281 262 237 287 242 227 274 223 288 243 264 230 256 257 276 264 264 233 267 294 226 247 231 261 235 248 263 250 265 247 240 273 246 240 234 256 260 236 261 234 256 246 263 280 229 245 245 249 244 255 258 249 281 263 237 242 246 229 247 232 243 260 222 271 272 262 257 234 272 279 256 266 277 239 287 257 260 259 256 255 265 248 292 264 268 259 275 271 279 291 267 245 229 248 263 294 266 249 242 255 260 247 281 261 278 284 283 231 258 278 260 270 286 267 247 277 260 250 269 274 245 297 227 256 281 270 235 280 260 245 250 256 284 243 240 279 238 246 248 286 247 241 259 261 262 248 234 270 240 231 243 267 280 241 218 224 234 299 217 281 259 280 270 258 258 264 249 269 260 221 239 229 267 244 257 262 240 257 248 262 237 271 242 263 210 269 264 244 231 225 263 242 241 280 222 250 240 266 243 240 261 225 249 228 237 229 256 284 230 219 239 262 230 292 243 237 260 259 235 243 229 245 226 232 240 257 269 243 262 249 273 244 274 263 267 259 237 223 256 246 232 229 266 236 227 235 259 243 286 214 233 283 270 256 266 262 220 242 255 234 249 241 226 246 240 266 256 225 242 241 231 260 268 255 231 275 248 255 259 236 255 289 243 239 258 248 242 249 249 244 221 226 228 282 260 232 256 246 241 275 229 241 270 279 239 241 231 222 226 235 239 215 235 227 231 240 223 276 257 274 278 268 238 280 216 261 238 240 234 233 250 265 222 245 241 256 225 278 260 259 229 243 239 234 257 239 262 262 236 248 268 236 243 258 257 280 226 244 260 277 231 224 245 241 240 274 237 240 261 248 250 268 217 256 229 216 240 256 248 220 259 231 279 248 249 262 288 233 266 261 271 278 248 265 238 245 221 262 227 238 247 229 240 240 229 266 262 261 238 231 226 260 223 269 259 261 244 262 262 247 233 228 231 258 237 227 232 237 245 248 238 258 242 246 241 243 279 238 244 264 279 265 242 228 256 265 242 231 247 258 235 228 257 244 276 245 233 262 229 293 269 242 276 245 266 242 266 234 259 266 217 264 260 257 250 267 217 275 240 273 245 246 233 236 245 240 283 231 262 230 242 227 272 212 248 235 223 234 275 239 241 235 218 267 268 266 247 268 276 223 236 230 227 217 264 255 248 262 282 226 258 228 267 260 233 263 233 232 273 248 258 263 230 246 228 261 259 247 236 242 246 236 248 214 242 241 249 244 267 271 239 238 258 235 223 237 261 234 244 266 235 223 266 229 245 247 259 262 259 215 234 247 227 256 247 248 242 280 277 256 272 217 243 258 204 261 238 233 223 238 236 249 221 241 237 269 273 227 263 243 224 255 256 225 269 250 256 208 246 243 270 238 278 218 246 255 264 244 266 227 266 249 250 243 276 238 240 243 241 276 242 257 224 240 225 242 256 266 242 255 276 263 266 239 263 271 236 258 290 260 231 246 257 242 250 247 246 249 255 220 295 256 248 266 262 256 240 269 267 218 258 222 270 249 239 231 221 239 267 279 240 255 234 230 226 243 239 249 255 262 240 242 258 262 247 245 234 262 246 224 256 276 225 279 266 215 244 232 267 248 245 231 234 244 243 235 274 265 257 244 228 233 272 229 226 240 256 275 231 264 246 241 235 245 276 242 250 270 260 255 244 226 223 267 234 239 225 244 258 237 238 241 223 264 239 269 257 258 259 264 218 236 269 225 244 255 230 264 236 204 237 244 240 258 235 259 249 202 261 232 248 243 245 263 237 259 283 221 271 247 248 280 260 268 219 234 237 228 259 266 267 218 257 274 273 242 241 236 259 237 228 263 229 266 220 231 243 222 242 257 255 249 227 226 241 226 229 241 226 222 258 238 227 260 246 263 220 232 280 277 213 241 266 198 230 247 238 270 239 231 242 232 232 245 242 230 269 229 237 267 240 235 199 245 258 248 248 285 224 249 237 255 265 242 259 225 246 255 224 243 236 248 232 225 229 221 267 240 228 260 244 241 248 259 246 208 238 274 262 257 244 264 227 243 198 227 272 231 268 236 266 248 224 222 235 241 250 278 225 265 275 273 247 223 246 241 257 242 236 228 265 247 225 249 270 258 218 227 266 264 262 260 264 271 269 244 217 257 250 274 224 256 243 271 211 246 227 236 224 264 262 236 227 247 208 269 265 276 222 257 258 283 227 227 255 241 265 234 238 237 256 259 246 260 266 220 244 240 240 214 207 255 259 264 276 220 241 247 280 233 244 242 259 246 222 219 258 236 264 272 271 280 241 230 245 241 266 235 230 255 258 224 229 268 249 249 258 244 228 246 256 247 263 228 240 255 228 263 230 275 236 288 271 262 242 236 239 236 246 244 228 235 231 239 244 256 234 221 268 240 233 234 263 233 249 243 236 264 229 255 212 212 257 236 266 262 245 259 230 257 226 246 241 240 233 241 233 222 220 239 274 256 262 242 242 277 290 206 242 248 247 245 242 286 257 236 230 235 225 256 244 248 259 228 239 229 266 248 267 243 223 234 244 274 258 267 225 240 217 185 257 230 223 244 220 270 242 241 289 261 237 234 236 235 238 231 258 257 269 270 212 233 242 234 238 227 246 243 264 248 265 258 238 240 225 204 266 226 262 217 259 229 242 235 279 256 228 234 257 239 209 188 244 256 266 269 258 275 268 217 228 266 223 244 232 249 258 243 248 244 226 274 236 249 237 266 250 248 256 238 237 256 229 238 257 241 246 263 270 243 264 266 266 231 286 255 230 255 239 257 270 280 237 265 258 226 250 244 246 245 240 271 241 247 230 278 235 260 226 235 271 220 239 256 261 235 226 258 248 259 246 248 234 272 256 235 239 255 248 274 277 257 270 212 261 268 259 234 216 262 260 285 223 223 249 270 246 236 238 247 272 229 260 224 225 244 248 271 236 216 238 243 231 236 255 245 261 236 235 269 286 222 248 257 265 265 249 269 237 255 277 261 255 233 262 232 238 268 215 243 258 257 262 245 246 233 267 241 240 222 243 263 275 229 267 227 234 257 247 246 232 249 225 239 278 258 271 263 242 250 231 275 240 248 248 255 237 209 291 242 238 220 240 248 235 239 255 246 271 234 242 256 250 224 242 213 286 235 256 270 247 216 225 243 241 270 289 233 271 231 242 222 259 228 258 242 264 226 264 258 224 263 236 271 239 231 235 263 243 223 218 246 241 259 261 268 240 234 244 239 229 235 234 242 234 237 244 230 259 237 265 198 231 263 226 245 230 235 281 269 237 247 239 235 248 237 276 240 231 287 260 257 246 235 237 217 235 268 223 219 235 255 229 239 246 244 222 270 245 237 256 270 247 260 239 227 259 233 229 225 259 211 246 247 234 237 246 263 257 228 255 256 247 274 259 225 261 243 247 266 247 245 223 272 206 227 240 244 261 266 248 250 239 265 270 256 247 269 247 255 259 239 230 264 241 260 215 242 250 237 264 241 269 271 257 237 292 269 232 240 264 259 244 226 239 242 249 242 237 256 263 236 237 239 245 221 207 227 244 259 259 228 266 227 256 235 237 228 233 245 274 255 225 263 217 238 244 220 236 221 233 235 245 231 249 230 255 231 245 238 262 230 263 249 210 231 232 224 267 237 240 291 264 239 234 247 235 234 280 275 221 247 244 221 247 271 246 243 240 244 259 234 239 239 241 238 256 248 241 241 261 237 261 246 258 255 242 236 242 225 284 277 216 211 257 236 257 239 235 248 236 224 270 245 265 267 229 243 236 276 255 269 272 246 268 248 244 243 261 260 272 263 224 229 224 248 274 261 256 273 249 257 231 260 249 261 274 268 289 233 248 277 257 229 248 284 246 273 246 238 217 262 263 242 264 237 255 245 265 243 244 259 280 269 239 249 237 258 243 234 260 285 223 261 239 247 241 234 250 276 239 244 248 260 267 279 244 234 244 278 257 247 265 264 239 233 230 271 234 213 242 249 277 217 267 232 243 240 259 241 243 260 234 243 255 269 275 257 238 255 248 244 246 233 257 236 257 239 269 237 273 278 244 235 262 213 285 267 242 233 232 233 262 243 243 271 270 273 281 233 279 302 258 266 255 259 235 228 256 264 225 245 256 262 266 256 286 274 288 260 278 244 240 273 233 241 248 241 257 246 263 292 288 262 272 260 259 276 279 259 261 303 288 264 303 282 241 269 240 246 265 261 245 286 259 279 241 271 273 269 265 264 279 255 248 274 256 276 255 258 248 273 256 259 270 245 266 241 271 292 278 236 229 234 249 282 279 275 276 294 239 262 243 261 269 258 265 237 219 250 261 268 261 248 286 237 227 222 229 273 241 229 264 261 275 256 268 289 247 258 264 269 281 273 235 285 262 271 241 244 269 283 258 266 274 237 244 233 240 235 271 240 265 243 273 243 257 237 230 249 288 249 241 277 261 264 281 273 258 277 242 262 249 284 271 284 259 244 255 273 282 244 231 237 245 291 238 228 270 237 272 264 285 286 263 285 256 258 248 260 227 257 245 276 208 277 271 227 258 233 234 241 229 258 275 303 266 284 258 262 261 235 270 257 264 246 271 230 255 296 223 262 256 221 264 264 260 239 229 210 256 245 272 247 271 257 259 244 240 244 279 245 246 233 240 260 238 237 243 273 288 256 267 260 288 261 258 274 223 255 263 239 268 237 246 249 271 236 242 269 266 220 216 260 246 238 284 268 276 209 276 257 235 241 259 271 240 243 245 247 241 281 280 222 255 245 229 275 280 270 267 212 258 278 265 268 264 276 262 258 245 283 272 264 267 274 267 248 241 220 259 259 237 250 242 266 247 228 237 258 261 242 222 231 215 269 244 243 239 241 241 258 235 281 246 235 230 244 248 245 269 265 227 265 229 268 278 260 269 255 244 270 223 269 262 267 239 255 234 273 232 238 257 246 258 247 258 235 271 255 232 239 243 258 256 265 235 242 290 220 264 265 239 279 270 257 271 267 264 267 280 265 250 249 269 219 266 231 227 233 233 277 277 264 244 277 286 224 274 239 220 246 219 236 266 244 269 264 249 248 281 216 307 228 238 239 267 308 259 275 280 265 281 257 267 258 266 269 245 270 267 260 258 274 239 289 241 263 243 244 283 241 271 260 291 255 262 265 226 277 233 259 258 275 234 267 275 271 240 235 234 239 246 223 255 246 248 263 236 275 243 234 264 244 274 213 276 256 276 289 264 261 297 276 270 236 287 268 264 271 245 286 275 261 248 236 291 232 256 277 224 260 234 263 233 260 272 245 237 268 243 233 260 266 259 245 237 249 257 263 288 271 258 260 265 243 240 287 297 263 241 234 239 238 235 268 263 221 243 260 230 225 264 271 224 278 245 236 244 248 246 249 249 244 286 279 230 241 259 231 237 259 274 247 281 270 247 278 278 258 263 269 267 257 261 266 243 266 237 244 238 233 234 270 261 234 263 256 264 260 282 282 286 226 259 217 278 259 260 243 243 236 265 277 218 270 234 274 233 247 236 276 260 273 258 232 264 265 280 227 229 243 257 247 238 265 275 228 257 233 259 279 247 264 246 241 232 255 248 255 239 258 262 245 268 273 278 255 280 256 265 247 276 237 244 238 243 249 256 265 246 241 220 219 271 267 268 203 267 250 259 280 237 255 270 267 245 272 241 263 267 237 261 234 239 245 227 263 237 218 298 247 266 262 242 222 266 280 240 262 258 287 272 242 266 271 220 269 261 281 246 270 259 248 265 248 236 262 236 267 274 237 238 229 273 267 233 264 244 240 242 244 295 259 247 243 248 276 237 239 275 257 237 272 239 259 281 274 259 240 239 246 244 259 248 240 261 244 268 256 245 243 228 259 220 230 268 227 289 221 246 221 231 275 259 221 272 247 237 268 227 245 279 247 236 284 247 250 223 274 271 266 247 242 261 224 263 261 270 228 266 209 232 265 224 258 248 232 273 256 256 243 226 255 232 263 229 246 248 244 272 256 274 270 246 234 263 279 258 230 218 239 247 264 244 249 280 264 259 237 292 245 228 257 244 234 277 247 266 249 273 278 273 231 240 261 247 240 276 270 255 260 241 265 245 263 249 235 217 243 233 289 281 268 237 239 236 267 278 283 212 257 256 234 274 233 247 271 263 269 250 247 245 264 261 248 284 229 226 240 246 249 259 250 240 244 255 247 265 247 238 260 270 225 272 243 260 256 283 267 236 267 263 238 237 240 237 216 246 268 241 236 262 237 244 265 260 263 240 256 268 222 235 258 248 246 255 266 263 275 263 227 245 286 278 241 271 271 279 275 262 282 246 248 278 269 260 237 268 263 244 277 249 244 261 271 267 226 238 261 250 249 248 229 250 255 265 249 247 240 244 268 277 267 243 249 241 233 267 240 243 247 247 279 248 264 256 260 246 234 228 228 267 247 231 276 262 227 280 235 247 243 255 240 249 225 268 267 232 263 267 276 210 237 226 225 217 240 237 266 249 238 233 246 260 258 234 233 269 233 240 240 263 229 226 262 240 240 239 247 247 243 248 248 268 257 259 266 249 220 247 214 244 260 243 235 244 259 270 257 258 280 264 223 277 268 242 242 208 282 267 244 247 275 233 221 280 258 272 255 271 262 283 236 224 246 268 261 258 268 256 237 224 280 238 283 242 274 220 234 249 255 276 231 277 236 247 250 266 224 266 271 223 244 270 305 270 240 236 268 256 237 244 260 250 284 236 232 258 284 238 263 302 258 232 255 213 270 256 239 247 286 258 245 222 236 249 278 267 273 257 220 261 249 239 280 277 273 242 250 269 241 287 226 266 264 248 229 273 265 245 234 249 269 272 228 221 271 266 288 243 262 258 241 230 260 260 223 259 248 232 246 262 266 288 271 247 239 233 267 236 286 244 273 260 239 269 274 247 267 279 275 244 288 256 257 223 242 259 235 268 292 264 260 237 268 272 258 226 280 272 246 247 248 272 258 229 259 224 238 246 224 222 220 228 284 260 274 240 265 257 208 270 259 247 246 277 280 257 240 262 248 278 260 228 247 238 262 233 262 233 230 264 256 256 227 257 264 229 260 247 285 270 270 260 263 238 264 262 258 272 243 262 274 227 280 231 241 269 243 280 267 243 260 264 264 269 264 278 268 233 257 235 268 235 266 247 258 244 286 266 256 282 261 242 242 217 234 241 235 239 301 248 249 259 246 263 225 259 247 222 235 242 244 248 208 269 246 248 238 232 266 219 218 235 226 269 241 288 302 218 255 246 229 283 216 266 232 239 242 248 274 233 265 265 259 268 290 225 222 258 291 227 241 259 257 228 266 273 238 242 238 263 236 257 240 265 247 280 226 250 246 259 221 260 239 245 260 275 231 267 266 222 283 240 211 271 236 239 229 243 266 257 261 218 238 237 248 219 220 224 281 235</counts>
			</dataPoints>
		</scan>
	</xrdMeasurement>
</xrdMeasurements>