File: data/XRD/XG-Vakuum/XG-700/W6823-1C_XG_Vakuum_700.xrdml
<xrdMeasurements xmlns="http://www.xrdml.com/XRDMeasurement/2.1" xmlns:xsi="http://www.w3.org/2001/XMLSchema-instance" xsi:schemaLocation="http://www.xrdml.com/XRDMeasurement/2.1 http://www.xrdml.com/XRDMeasurement/2.1/XRDMeasurement.xsd" status="Completed">
	<comment>
		<entry>Configuration=Factory configuration, Owner=User-1, Creation date=7/8/2013 4:01:53 PM</entry>
		<entry>Goniometer=PW3050/65 (Theta/2Theta); Minimum step size 2Theta:0.0001; Minimum step size Omega:0.0001</entry>
		<entry>Sample stage=MRD Cradle; Minimum step size Phi:0.01; Minimum step size Chi:0.01; Minimum step size X:0.01; Minimum step size Y:0.01; Minimum step size Z:0.001</entry>
		<entry>Diffractometer system=XPERT-PRO</entry>
		<entry>Measurement program=C:\PANalytical\Data Collector\Programs\Jorrit\2thom\_absolute_2th-om_10-130deg_PIXscan_56min.xrdmp, Identifier={15BCCF57-2807-42BD-B5B9-ECC0B3DC9284}</entry>
		<entry>Batch program=C:\PANalytical\Data Collector\Programs\SimonL\batch4x_2thom_10-130°_z9.1_x0,10,20,30_y0_57min.xrdmp, Identifier={EED9823A-2BEB-424C-9252-345C4EF2834A}</entry>
	</comment>
	<sample type="To be analyzed">
		<id></id>
		<name></name>
		<preparedBy></preparedBy>
	</sample>
	<xrdMeasurement measurementType="Scan" status="Completed" sampleMode="Reflection">
		<comment>
			<entry>_absolute_2th-om_10-130deg_PIXscan_56min</entry>
			<entry>PHD Lower Level = 4.83 (keV), PHD Upper Level = 11.27 (keV)</entry>
		</comment>
		<usedWavelength intended="K-Alpha 1">
			<kAlpha1 unit="Angstrom">1.5405980</kAlpha1>
			<kAlpha2 unit="Angstrom">1.5444260</kAlpha2>
			<kBeta unit="Angstrom">1.3922500</kBeta>
			<ratioKAlpha2KAlpha1>0.5000</ratioKAlpha2KAlpha1>
		</usedWavelength>
		<incidentBeamPath>
			<radius unit="mm">320.00</radius>
			<xRayTube id="1010048" name="Empyrean Cu LFF HR (9430 033 7310x) DK442154">
				<tension unit="kV">40.0</tension>
				<current unit="mA">40.0</current>
				<anodeMaterial>Cu</anodeMaterial>
				<focus type="Line">
					<length unit="mm">12.0</length>
					<width unit="mm">0.4</width>
					<takeOffAngle unit="deg">4.2</takeOffAngle>
				</focus>
			</xRayTube>
			<xRayMirror id="27010001" name="Inc. Beam Cu W/Si (parabolic MRD)" hybrid="false">
				<crystal type="Graded" shape="Parabolic">W/Si</crystal>
				<acceptanceAngle unit="deg">0.800</acceptanceAngle>
				<length unit="mm">60.0</length>
			</xRayMirror>
			<sollerSlit id="21010002" name="Soller slits 0.04 rad.">
				<opening unit="rad">0.0400</opening>
			</sollerSlit>
			<mask id="22030008" name="Fixed mask 4 mm">
				<distanceToSample unit="mm">220.00</distanceToSample>
				<width unit="mm">4.00</width>
			</mask>
			<divergenceSlit id="22010007" name="Fixed slit 1/8°" xsi:type="fixedDivergenceSlitType">
				<distanceToSample unit="mm">220.00</distanceToSample>
				<height unit="mm">0.19</height>
			</divergenceSlit>
		</incidentBeamPath>
		<diffractedBeamPath>
			<radius unit="mm">320.00</radius>
			<sollerSlit id="21010002" name="Soller slits 0.04 rad.">
				<opening unit="rad">0.0400</opening>
			</sollerSlit>
			<receivingSlit id="22010001" name="Fixed slit 4°">
				<height unit="mm">5.88</height>
			</receivingSlit>
			<detector id="7010017" name="PIXcel3D 1x1 detector" xsi:type="areaDetectorType">
				<phd unit="%">
					<lowerLevel>30.0</lowerLevel>
					<upperLevel>70.0</upperLevel>
				</phd>
				<mode>Scanning</mode>
				<activeChannelsEquatorial>255</activeChannelsEquatorial>
				<activeChannelsAxial>255</activeChannelsAxial>
				<pitchEquatorial unit="mm">0.05500</pitchEquatorial>
				<pitchAxial unit="mm">0.05500</pitchAxial>
				<readOutPeriod unit="seconds">0.135</readOutPeriod>
			</detector>
		</diffractedBeamPath>
		<scan appendNumber="0" mode="Continuous" scanAxis="2Theta-Omega" status="Completed">
			<header>
				<startTimeStamp>2024-10-09T12:14:47+02:00</startTimeStamp>
				<endTimeStamp>2024-10-09T13:10:53+02:00</endTimeStamp>
				<author>
					<name>PRO-MRD</name>
				</author>
				<source>
					<applicationSoftware version="6.1b">Data Collector</applicationSoftware>
					<instrumentControlSoftware version="7.0E 20130304">XPERT-PRO</instrumentControlSoftware>
					<instrumentID>0000000011142674</instrumentID>
				</source>
			</header>
			<dataPoints>
				<positions axis="2Theta" unit="deg">
					<startPosition>9.99826193</startPosition>
					<endPosition>129.99755682</endPosition>
				</positions>
				<positions axis="Omega" unit="deg">
					<startPosition>4.99913096</startPosition>
					<endPosition>64.99877841</endPosition>
				</positions>
				<positions axis="Phi" unit="deg">
					<commonPosition>0.00</commonPosition>
				</positions>
				<positions axis="Chi" unit="deg">
					<commonPosition>0.00</commonPosition>
				</positions>
				<positions axis="X" unit="mm">
					<commonPosition>20.00</commonPosition>
				</positions>
				<positions axis="Y" unit="mm">
					<commonPosition>0.00</commonPosition>
				</positions>
				<positions axis="Z" unit="mm">
					<commonPosition>9.100</commonPosition>
				</positions>
				<commonCountingTime unit="seconds">32.895</commonCountingTime>
				<counts 371 362 341 381 376 363 364 408 367 360 398 407 352 373 372 354 375 372 375 382 387 375 358 397 380 365 357 372 383 387 375 364 361 371 390 336 349 359 344 352 375 372 367 361 400 392 348 416 376 347 379 382 382 372 369 365 369 372 379 376 379 360 346 358 377 339 374 345 333 336 348 363 357 354 416 410 330 365 342 367 332 346 379 378 366 363 357 361 375 317 350 381 342 368 360 357 383 367 352 347 336 379 368 345 375 338 350 341 366 345 353 326 367 374 330 381 355 350 345 328 343 351 339 337 364 357 374 340 374 368 338 361 370 348 352 344 314 345 359 310 330 386 354 321 347 354 349 336 337 345 295 315 355 350 336 330 326 351 351 316 329 304 352 341 323 346 301 303 390 338 304 316 328 327 360 298 313 305 366 339 400 330 326 351 301 324 356 339 298 326 333 304 338 361 340 323 320 329 316 322 363 343 346 360 345 345 322 316 310 330 353 320 358 343 332 324 341 331 371 325 333 341 347 307 316 337 352 361 323 313 332 323 346 340 345 333 303 318 362 324 334 307 354 331 337 362 358 323 334 353 346 362 357 319 332 332 301 313 345 353 344 310 321 302 323 320 316 326 318 347 311 313 342 342 331 340 308 295 315 326 309 321 313 356 323 332 345 342 354 311 297 299 345 341 324 319 353 304 311 299 346 334 325 330 318 277 327 285 322 329 307 305 330 320 323 295 320 351 313 314 299 332 318 341 302 287 376 298 371 330 309 326 296 320 310 317 324 322 332 360 306 289 335 332 315 314 350 305 306 289 279 293 309 335 307 305 286 311 327 295 324 320 311 339 331 310 299 337 310 340 302 317 332 302 315 366 318 302 346 323 293 315 308 299 314 317 332 317 286 293 336 302 308 301 297 303 289 321 336 322 313 304 296 332 318 305 298 315 301 351 306 271 312 305 303 305 300 304 312 314 335 324 290 293 304 324 318 295 283 317 325 311 328 318 283 292 291 287 332 312 312 300 323 301 285 314 279 357 293 330 292 304 296 298 305 305 294 304 289 282 305 326 287 305 297 324 330 289 281 297 257 320 293 285 303 307 281 307 306 337 290 318 274 298 276 305 288 298 300 315 303 299 260 262 284 295 276 292 297 297 293 283 307 285 311 304 279 281 303 284 335 308 275 299 261 283 289 284 305 303 293 278 287 277 279 273 305 270 296 290 276 267 314 286 283 290 291 301 271 285 297 261 276 261 342 278 257 289 298 264 275 292 283 283 293 305 270 313 278 276 297 285 272 293 325 296 292 311 276 269 270 284 306 281 296 298 298 282 267 290 316 286 260 302 292 262 264 257 273 290 303 279 286 280 274 283 279 256 262 286 269 279 277 287 287 291 265 300 297 262 328 290 270 306 275 277 288 278 271 281 302 264 295 286 262 293 289 292 290 245 270 271 308 280 271 267 281 291 292 297 272 247 297 300 295 273 282 289 273 271 284 298 272 262 315 277 282 292 298 303 283 282 293 281 255 320 300 277 317 302 250 292 255 277 287 272 278 308 269 290 261 280 276 258 276 282 297 278 282 259 281 271 290 267 273 283 285 265 277 280 304 304 283 298 266 285 280 261 274 293 272 268 302 267 271 291 283 263 276 292 237 279 279 275 266 296 260 281 268 258 270 310 266 302 284 296 291 275 279 299 255 287 277 271 283 299 261 315 286 284 275 277 297 294 227 263 264 308 302 285 286 262 275 269 273 270 311 284 320 289 304 274 246 245 229 303 272 281 259 268 264 302 244 286 297 258 274 302 255 271 284 301 283 239 286 313 259 268 288 271 320 288 258 301 270 291 282 273 302 257 300 297 294 275 294 249 273 323 279 276 270 288 306 266 271 267 288 284 258 295 295 303 284 298 262 268 284 310 293 290 276 257 293 283 276 293 291 267 259 278 271 298 246 242 282 258 277 268 285 287 302 294 281 289 275 286 283 294 263 281 272 286 280 269 298 306 268 301 271 270 308 294 282 279 272 298 272 298 283 277 281 261 274 283 290 282 315 279 291 288 268 310 285 284 291 258 244 294 295 289 283 299 264 280 288 294 275 272 288 285 277 292 298 269 305 294 310 297 298 289 285 288 310 284 284 291 301 245 298 305 294 293 323 317 289 322 245 292 301 237 260 283 319 291 294 284 301 294 312 312 277 299 283 295 303 259 288 272 306 284 293 302 272 321 300 296 290 321 289 299 300 298 305 300 296 246 286 258 307 287 286 285 270 270 302 301 278 314 284 290 307 296 318 322 288 308 307 271 287 317 317 310 294 311 304 293 277 297 275 307 312 281 287 312 289 312 312 306 298 312 315 313 298 306 282 288 309 312 295 275 284 298 275 282 314 274 283 276 302 289 278 334 308 315 294 328 301 295 293 285 300 332 278 308 300 323 301 324 302 282 303 296 257 325 326 318 328 314 295 285 281 334 258 311 318 311 285 306 310 299 295 302 320 297 291 278 302 318 306 273 291 315 322 308 293 325 286 327 287 328 296 312 281 287 260 317 307 324 304 306 346 299 317 302 323 280 317 329 297 307 283 315 316 289 303 320 322 303 313 301 279 308 308 293 300 311 331 323 305 328 314 279 313 299 327 308 310 317 331 268 304 321 317 333 291 317 313 294 292 307 293 286 314 311 302 294 332 331 309 317 290 318 308 301 323 324 349 291 304 320 299 305 309 295 314 325 319 314 302 300 316 313 298 306 306 328 315 330 299 300 317 333 326 332 303 341 306 325 280 273 348 339 285 319 336 296 315 309 308 312 309 322 328 313 302 313 291 316 311 308 315 318 333 299 332 289 326 325 299 282 288 292 298 341 324 325 300 323 286 341 295 336 317 329 302 311 317 324 295 297 308 292 311 305 322 320 317 308 308 320 305 301 295 312 333 339 316 298 303 330 321 300 308 308 288 314 311 324 292 302 355 330 301 346 328 308 309 323 305 294 329 328 313 298 306 302 334 343 320 316 354 357 303 308 308 291 325 335 316 323 325 303 312 321 297 281 327 331 305 315 314 321 313 306 281 323 303 347 287 297 284 329 278 299 302 333 318 323 293 265 290 310 292 285 303 326 324 319 307 312 289 341 324 330 291 303 321 325 299 309 292 305 279 296 329 304 323 329 286 299 306 328 313 333 302 304 316 306 317 299 289 305 322 310 306 313 314 303 297 330 311 302 325 316 297 308 333 312 330 299 308 316 304 301 348 301 342 313 340 297 301 270 288 290 304 295 305 290 334 312 279 292 329 339 282 302 324 308 304 307 295 311 330 284 291 320 294 286 322 274 298 307 297 278 291 286 290 337 330 290 273 263 290 286 266 297 296 300 282 297 326 308 308 308 317 295 302 329 303 307 303 307 296 272 315 305 281 302 306 308 307 346 289 297 309 301 302 304 295 307 292 295 291 315 287 284 310 308 286 274 284 312 329 300 312 266 330 320 277 278 318 269 312 277 286 317 264 315 285 302 325 319 286 294 286 337 281 308 288 290 282 327 324 279 303 311 290 300 265 296 297 292 286 302 281 288 308 301 274 305 307 320 287 308 282 294 280 286 283 303 300 298 301 281 301 283 318 295 263 286 285 286 314 244 291 293 290 283 279 276 269 306 317 284 266 278 306 294 303 285 301 295 283 285 303 278 292 295 288 294 288 296 281 274 298 299 293 296 293 293 301 264 319 286 300 302 281 296 299 288 313 288 319 270 276 282 294 293 287 288 307 280 263 298 287 277 273 316 268 300 320 303 292 286 266 274 272 291 276 275 299 272 293 292 271 280 285 273 292 267 281 297 274 260 287 307 262 285 279 301 244 262 326 288 271 267 280 279 283 306 301 257 289 275 280 276 306 224 295 280 299 287 295 281 302 277 276 300 277 266 302 273 264 270 241 259 289 265 295 247 255 279 255 264 293 266 282 247 306 276 260 283 297 270 294 264 287 245 274 265 237 285 259 245 267 233 273 282 296 267 289 245 288 303 260 295 247 295 264 270 297 246 269 240 278 268 262 257 260 271 229 277 278 263 262 277 242 264 273 294 245 245 286 242 272 264 247 268 247 280 273 273 275 243 273 273 298 289 274 286 261 235 231 292 272 266 242 280 236 286 279 286 271 249 270 263 266 233 299 285 265 287 257 260 298 224 271 272 244 271 280 277 242 277 262 271 269 246 257 272 268 247 261 238 258 288 256 268 261 225 237 278 271 270 267 245 271 237 227 247 214 261 307 281 293 293 257 290 249 278 249 260 298 266 247 266 246 249 281 260 263 264 244 240 244 262 281 271 277 239 219 289 234 233 287 242 249 265 232 241 245 235 232 242 266 264 230 259 259 267 265 246 258 266 239 258 242 247 238 241 237 270 235 201 247 257 249 257 236 247 243 249 237 237 236 256 229 261 245 227 268 229 241 229 248 284 278 241 223 244 276 255 223 255 258 260 269 287 243 240 291 249 270 220 240 258 234 225 238 235 236 256 259 228 250 258 258 230 244 250 230 245 215 242 246 249 243 246 244 237 268 267 234 262 269 237 239 237 217 273 215 217 262 220 260 250 249 257 229 229 272 229 244 230 219 264 229 245 240 243 244 227 256 237 271 244 263 244 239 265 222 229 257 221 248 218 261 257 244 228 236 248 250 248 228 269 245 223 262 238 242 220 237 243 240 255 219 223 271 273 262 279 232 237 271 266 234 248 238 231 229 231 231 243 241 219 225 239 260 267 241 212 231 268 224 222 276 232 242 233 237 226 210 248 247 233 235 241 242 238 245 232 236 227 223 243 248 246 245 241 233 256 242 220 235 221 277 275 235 206 235 248 243 221 214 207 223 239 209 216 206 233 233 241 237 211 240 232 236 225 231 237 236 231 232 207 204 212 261 237 237 229 218 248 241 212 262 245 224 234 225 233 247 237 256 257 242 226 233 279 231 227 217 241 264 233 236 206 227 250 233 239 238 226 227 213 233 215 262 225 241 220 264 249 217 240 246 240 260 228 237 237 221 236 257 220 241 246 230 220 212 229 229 264 265 224 228 260 231 216 227 229 247 238 237 210 223 245 245 231 209 232 214 246 244 230 196 237 288 225 234 270 222 233 238 229 260 241 218 231 222 226 240 247 244 214 238 231 245 242 234 233 213 233 263 222 209 232 214 225 218 203 240 224 243 256 220 223 247 233 202 221 260 246 213 213 231 230 261 258 234 257 248 222 209 191 235 227 243 232 239 225 236 235 266 194 225 212 248 241 229 263 256 244 231 226 219 217 226 229 215 226 232 222 236 218 224 221 219 228 244 266 271 224 250 248 243 243 229 196 220 226 238 221 199 220 221 228 247 235 217 246 261 212 236 228 203 197 237 242 210 232 220 227 203 221 234 226 223 244 215 256 245 211 208 258 242 244 213 239 240 235 214 258 221 272 247 248 235 211 235 210 232 215 215 238 216 218 243 234 263 224 213 231 217 208 238 232 214 247 219 223 230 205 229 219 218 215 219 197 225 231 232 234 265 217 243 220 267 229 218 223 217 212 221 233 224 221 222 239 220 245 243 237 237 199 200 236 224 231 231 214 223 229 213 259 207 228 220 229 261 243 206 188 211 218 207 210 204 194 220 226 217 240 263 230 237 213 259 216 211 247 204 218 207 220 221 248 234 227 230 219 215 227 236 224 233 239 203 209 230 215 258 239 216 236 226 206 210 237 208 224 245 245 190 233 221 218 218 227 217 212 212 222 209 227 257 236 236 237 222 214 241 225 220 222 210 225 236 230 226 194 219 226 234 223 240 238 213 247 257 215 220 207 208 212 208 234 220 212 243 224 219 220 240 221 244 258 177 207 210 198 208 242 208 208 225 215 202 222 215 243 242 231 256 178 249 207 221 212 212 229 244 199 221 203 229 229 256 255 209 213 234 225 224 226 201 235 220 199 237 192 246 225 238 212 229 229 211 240 221 200 224 215 217 223 210 203 206 235 212 205 221 224 220 224 226 205 212 212 215 221 225 221 243 211 230 241 227 236 237 222 204 210 225 214 224 221 218 218 209 229 213 249 216 216 238 224 248 204 227 224 222 257 223 205 219 220 239 243 224 240 214 240 225 230 220 214 202 244 237 215 238 207 229 213 220 221 203 200 217 235 214 215 239 229 209 226 193 217 221 221 197 180 234 237 240 199 212 222 231 218 209 203 226 198 210 219 223 239 218 239 194 239 205 239 268 232 219 216 216 218 222 263 213 235 230 237 230 207 225 230 236 217 230 234 227 215 210 223 240 238 201 230 233 230 219 226 225 224 211 229 222 227 237 207 229 225 189 237 212 218 207 231 206 219 216 227 216 217 228 205 244 217 211 239 198 217 224 212 215 243 223 197 227 220 228 219 212 212 228 186 258 247 199 201 237 232 224 208 229 248 232 205 200 232 198 189 219 221 194 227 211 211 206 230 206 224 214 205 198 231 223 202 198 221 227 237 197 209 221 222 225 237 241 264 230 201 212 214 231 219 203 216 227 198 258 225 181 221 216 223 257 255 238 237 235 230 209 227 250 229 210 212 227 242 211 224 211 211 233 197 234 210 223 206 198 230 211 206 211 238 227 231 233 207 218 248 233 217 212 239 220 213 221 230 218 210 235 229 229 232 208 232 201 239 225 222 206 238 233 216 220 234 211 196 227 210 209 210 247 229 223 239 206 228 230 233 214 232 227 233 213 222 200 209 235 205 223 240 204 225 219 195 248 211 199 223 247 199 220 205 214 235 242 242 212 203 224 216 230 235 210 210 235 235 268 238 249 237 225 229 224 237 242 219 237 213 211 203 222 198 229 210 226 230 217 233 234 225 222 242 261 237 247 212 229 203 226 237 224 244 214 211 238 229 229 257 218 220 194 215 216 238 212 229 217 240 247 246 218 247 223 258 215 232 242 244 239 220 233 239 236 206 213 210 220 209 232 232 222 201 238 208 227 232 245 236 243 211 228 217 231 230 223 235 260 214 250 238 227 266 259 239 221 181 243 256 234 205 216 215 243 222 230 234 231 224 224 228 246 248 238 235 237 202 228 221 240 233 214 231 220 248 258 220 219 248 226 218 220 208 216 224 239 258 243 242 240 264 237 217 229 235 244 228 261 193 228 224 219 228 247 201 216 210 223 222 259 237 216 197 197 255 245 221 217 216 227 221 260 239 232 238 207 247 239 241 206 225 225 226 236 259 214 212 227 258 225 198 218 244 223 207 231 222 231 212 234 202 236 216 208 245 205 239 217 214 219 212 214 264 217 264 264 227 255 239 239 232 234 236 256 269 242 215 236 233 260 266 263 237 258 236 233 263 241 230 256 240 238 240 223 227 236 223 242 234 239 227 226 238 238 225 225 255 221 211 221 245 207 257 224 212 244 244 223 237 234 229 236 219 222 217 225 211 210 229 237 214 239 236 207 234 177 245 219 232 220 229 217 238 232 214 223 219 221 230 225 222 218 222 255 232 235 250 227 226 271 212 243 246 241 207 231 210 255 224 217 241 271 233 258 238 227 216 228 248 235 245 215 242 230 236 222 237 230 219 261 231 244 268 244 226 227 218 234 222 248 213 248 246 266 230 245 230 248 235 244 259 235 232 239 245 229 270 216 235 249 213 235 260 231 214 236 260 247 231 237 283 231 240 238 225 239 224 243 229 246 215 232 256 265 246 245 226 257 266 258 265 257 303 259 267 245 264 259 263 265 242 244 242 230 237 233 243 263 270 246 234 214 215 230 268 274 248 248 297 281 263 258 264 259 264 239 228 258 297 246 282 243 257 244 282 264 263 271 278 276 271 284 273 286 305 272 323 289 271 305 291 332 303 305 318 339 306 339 346 367 355 332 415 369 379 365 358 385 392 403 399 413 382 433 425 418 427 384 371 431 405 444 418 428 410 400 391 399 363 408 363 356 350 345 385 330 343 335 304 321 317 299 301 307 272 297 279 271 296 261 265 263 275 262 258 255 306 243 290 258 255 285 241 242 278 260 243 274 275 260 272 240 236 246 238 262 241 241 236 243 244 214 243 236 260 224 284 267 247 239 278 248 249 228 242 230 223 255 234 239 231 270 240 275 249 248 246 211 223 234 262 230 222 241 234 241 250 267 239 244 241 233 263 241 248 226 266 245 225 255 255 238 220 258 248 222 255 235 256 234 237 246 225 237 258 233 228 257 244 233 262 261 238 232 245 232 236 230 226 226 243 261 227 243 194 241 231 236 256 247 264 236 233 239 256 242 263 220 267 248 206 246 243 239 243 228 255 229 238 268 224 235 257 258 248 208 259 237 250 257 216 234 220 274 222 210 250 248 217 225 227 212 256 261 272 240 228 230 243 249 240 245 283 223 205 244 249 241 230 260 227 271 248 236 222 244 231 236 204 223 263 263 248 220 229 243 249 224 219 283 239 222 255 248 240 240 230 216 200 244 220 235 263 245 238 236 220 218 222 274 242 232 235 241 242 233 232 228 241 222 244 222 278 238 275 248 243 241 241 221 244 244 271 257 238 262 247 243 223 250 273 230 241 217 228 234 221 248 207 242 230 233 244 245 240 258 238 263 240 258 231 249 233 226 246 228 235 265 282 218 241 220 236 243 242 230 255 241 235 247 256 262 236 242 236 213 234 231 221 268 239 264 273 256 234 232 209 242 258 232 236 240 232 245 223 265 215 230 262 257 226 230 234 265 271 244 229 244 244 230 268 230 273 255 259 235 247 238 225 231 224 226 241 216 207 233 224 236 230 241 248 237 247 248 255 242 255 241 218 205 247 235 235 256 220 248 227 244 262 222 244 246 242 268 227 241 273 238 246 249 216 240 237 225 238 226 233 272 240 242 237 234 214 207 239 221 228 239 235 220 248 256 261 235 209 232 232 234 225 225 238 243 232 236 248 226 221 241 276 242 243 230 208 227 248 217 221 224 272 268 234 237 242 211 258 235 219 238 259 255 237 239 225 244 232 226 238 236 222 232 240 228 269 261 226 237 232 256 268 250 228 234 245 238 256 208 248 238 227 220 227 222 225 259 213 222 230 222 224 255 244 231 225 244 248 211 243 259 240 240 246 260 212 234 233 245 249 217 229 228 217 229 260 230 236 211 227 269 231 219 268 248 262 220 247 237 255 264 241 226 222 257 227 241 212 259 260 239 208 209 239 258 244 258 250 258 219 249 230 235 269 219 237 230 243 243 242 242 228 227 245 235 285 241 268 242 224 269 231 214 257 243 236 222 229 206 264 257 212 240 265 235 243 256 217 220 232 223 222 227 235 265 228 248 265 216 240 250 240 240 234 249 261 228 247 238 241 245 233 242 225 230 243 241 239 225 213 239 263 258 225 233 238 207 194 240 221 235 227 250 220 239 241 230 226 222 232 211 245 264 243 255 214 258 222 235 241 248 285 223 275 250 247 256 212 255 250 203 220 261 248 261 238 243 235 227 241 265 257 239 229 269 231 234 219 250 243 262 235 248 241 245 275 262 234 213 221 228 240 258 212 236 239 244 249 269 233 223 259 248 274 245 264 268 243 229 239 230 245 241 230 245 219 231 240 260 257 246 247 245 259 224 260 237 237 273 244 248 217 240 236 238 239 250 223 222 235 264 227 249 228 232 208 266 228 262 231 264 224 236 246 261 224 274 225 226 221 238 238 264 229 212 240 242 247 259 236 258 232 235 263 256 245 238 272 272 218 261 263 274 223 244 230 249 248 257 235 232 236 222 243 248 276 222 257 244 246 207 197 249 244 246 283 205 243 206 243 239 245 255 269 214 258 234 268 234 231 230 234 246 231 272 205 228 246 225 268 248 239 217 240 260 262 243 267 243 279 223 224 239 249 246 241 266 262 245 265 245 265 270 256 258 243 239 297 265 219 245 268 222 291 239 247 270 257 238 258 248 274 223 257 275 218 256 256 238 271 230 219 233 233 249 217 246 235 266 232 257 220 248 261 236 262 276 255 221 260 237 248 260 235 267 245 237 214 265 237 233 269 262 243 259 236 225 236 282 258 212 269 235 256 249 231 244 247 234 256 240 242 231 210 259 232 260 272 265 267 272 246 247 246 258 256 245 227 255 245 241 222 236 264 261 257 233 263 226 222 277 284 258 234 236 235 241 259 236 270 256 230 256 258 232 249 243 220 240 229 262 231 241 219 243 232 266 243 240 264 268 235 241 241 216 267 260 223 237 264 229 256 225 241 241 237 258 242 238 225 224 240 240 235 263 245 261 240 239 219 271 273 242 261 236 247 236 264 246 234 278 262 232 225 221 233 258 247 262 243 244 264 246 281 240 273 239 263 261 232 245 258 248 258 260 224 217 230 256 193 250 261 236 244 227 262 238 232 239 255 255 217 244 225 258 264 278 263 263 279 257 242 233 238 265 217 238 245 229 244 280 230 250 267 255 227 255 240 290 259 267 256 237 234 248 264 257 224 247 232 217 244 270 274 236 240 267 213 257 250 218 261 257 235 246 249 246 244 242 262 260 236 262 249 270 249 266 256 240 245 247 206 231 233 239 239 234 216 255 214 276 238 258 229 264 239 272 281 283 269 278 276 245 257 258 258 259 218 276 232 228 239 262 258 243 238 259 250 259 261 246 217 250 262 268 235 259 227 229 290 222 232 249 243 209 237 241 244 256 222 241 229 232 226 244 235 259 256 233 249 235 260 242 250 259 236 241 246 272 257 266 226 226 233 216 259 256 225 234 257 257 259 247 223 226 227 234 250 241 265 241 218 239 220 236 263 246 241 227 232 292 241 220 244 245 257 241 221 257 222 229 263 245 247 233 232 256 276 290 231 271 257 243 241 238 243 275 284 217 223 261 220 235 257 270 258 239 216 274 276 226 248 257 244 270 238 209 265 257 232 223 246 261 236 272 224 234 260 214 278 259 281 243 231 260 256 258 247 231 267 249 261 233 247 237 236 223 228 211 237 216 207 266 227 240 238 260 256 269 269 229 232 242 248 267 250 231 278 245 206 233 265 248 224 256 227 204 247 222 203 229 230 249 256 255 223 249 236 260 237 237 225 264 220 222 239 258 245 257 195 236 229 248 228 259 278 239 226 234 234 261 241 290 255 237 219 242 242 269 242 220 237 262 261 246 229 281 271 226 245 240 272 264 248 232 258 232 269 260 233 244 257 234 260 234 227 243 235 249 256 229 243 244 235 255 262 237 281 259 241 237 270 281 221 256 244 266 232 260 245 225 222 207 250 257 247 244 240 234 263 246 238 279 263 227 266 258 245 219 244 228 235 223 241 245 232 256 256 242 260 226 226 255 220 221 234 243 228 226 234 224 239 273 261 256 242 227 267 248 235 282 270 233 231 226 235 256 236 224 232 239 243 243 257 266 243 235 244 219 223 230 269 248 228 264 272 239 240 264 232 241 259 274 277 225 237 284 266 232 234 269 211 238 248 234 214 240 231 230 237 277 261 261 271 198 249 234 277 247 242 242 243 234 231 230 257 265 222 276 279 242 266 276 238 255 273 237 230 213 236 274 267 233 272 243 229 230 230 245 261 229 273 238 293 238 239 257 220 259 226 229 265 260 241 262 257 268 245 243 257 248 277 276 218 236 260 248 257 235 240 245 265 266 271 239 218 248 260 246 255 265 245 255 230 222 230 259 213 266 245 238 258 235 274 242 226 260 234 220 243 258 277 223 256 259 257 266 241 236 266 275 222 222 240 248 255 237 249 255 255 260 259 236 272 270 266 231 236 232 266 265 258 279 265 248 224 240 258 239 268 282 249 257 228 233 255 198 230 242 268 258 259 247 248 255 241 255 234 262 271 235 242 244 248 236 225 224 260 225 269 247 256 243 246 271 249 245 264 255 244 244 260 272 260 239 241 258 247 224 267 223 241 274 238 291 268 259 242 238 262 247 276 268 230 249 274 294 226 257 257 243 248 223 231 247 235 243 236 238 234 230 222 245 246 222 236 260 236 264 237 248 245 228 259 242 266 246 246 239 248 238 244 227 278 240 247 227 243 229 283 246 239 219 274 246 243 244 233 257 282 245 283 240 246 248 259 249 265 269 269 243 220 249 260 245 236 232 266 255 241 211 241 246 260 291 228 237 272 233 256 240 244 262 233 258 234 224 264 230 244 249 230 260 225 247 241 261 232 225 224 245 236 235 287 268 257 260 256 245 234 258 240 232 235 233 239 249 241 233 235 238 241 246 240 223 226 236 219 239 232 244 256 263 243 233 256 263 255 281 245 218 241 256 234 285 235 265 241 244 234 264 215 238 244 244 257 218 245 257 276 241 259 247 256 239 267 260 278 236 241 234 274 241 266 255 218 243 246 225 245 267 245 225 231 210 288 247 259 236 268 238 228 241 232 276 238 228 258 240 282 246 242 240 244 285 235 270 241 241 240 268 241 277 257 231 242 262 262 250 239 274 264 220 267 240 240 229 228 248 239 249 259 262 227 278 248 258 260 282 242 267 265 264 234 223 267 231 255 209 274 262 238 281 259 234 247 235 298 238 277 262 258 278 259 230 255 238 271 275 244 300 246 235 259 264 270 237 243 286 250 273 262 246 273 220 233 286 273 289 284 262 255 245 281 267 249 236 278 248 264 239 283 235 277 277 257 262 262 213 244 280 266 266 292 282 269 238 273 249 244 270 275 265 248 271 261 249 236 263 279 265 275 276 245 246 304 240 223 266 274 232 255 264 288 261 259 266 236 243 261 232 249 259 245 238 257 245 277 268 232 245 206 256 262 271 250 231 256 225 258 229 279 231 227 263 235 232 289 237 243 230 227 255 247 271 267 246 269 266 279 287 258 230 282 244 261 258 261 200 236 266 249 268 235 249 277 257 237 274 249 236 261 258 249 278 272 227 244 249 246 259 247 245 260 292 262 276 263 275 271 282 231 290 255 223 274 239 276 261 234 262 250 234 219 241 263 247 249 271 235 222 244 287 240 228 265 241 267 274 262 263 244 245 281 231 270 298 235 256 247 224 223 271 266 268 274 231 288 265 226 232 261 240 261 275 236 234 259 250 262 247 249 244 272 286 256 233 274 250 232 264 293 294 230 244 244 238 269 261 229 237 272 287 268 256 247 261 229 240 246 255 266 269 245 229 256 238 262 256 232 216 262 256 232 258 228 242 232 275 270 259 237 259 235 279 248 267 261 257 244 269 284 268 257 248 262 249 272 245 249 263 261 257 262 259 291 255 255 248 277 261 223 261 221 265 280 246 256 239 239 265 257 238 281 243 263 264 289 271 230 235 273 231 271 255 232 268 299 255 264 265 239 279 268 248 245 233 247 257 262 240 240 244 262 270 278 267 274 259 247 287 280 276 244 267 232 237 255 274 279 236 243 237 264 244 272 288 269 299 230 264 277 260 259 294 248 227 260 255 298 267 257 246 277 222 232 244 255 288 230 239 270 263 267 266 261 272 250 257 271 247 237 232 289 250 249 275 287 266 243 260 227 241 245 241 223 304 236 241 277 247 273 219 238 246 218 258 278 259 232 270 236 246 232 245 239 262 229 273 283 237 258 258 271 269 265 259 243 230 224 256 278 288 279 245 259 259 240 271 255 267 275 273 280 274 260 269 261 259 282 247 246 265 255 258 293 266 273 262 248 278 264 227 248 280 276 274 213 277 257 232 255 246 272 265 258 248 230 259 219 249 281 249 258 275 273 258 244 257 258 250 293 228 223 260 265 244 237 243 244 226 231 234 266 244 240 277 260 260 276 235 257 245 261 275 258 221 261 248 247 238 238 250 263 249 268 270 255 214 240 236 281 249 238 271 255 244 237 266 266 267 286 272 241 265 273 264 226 244 223 229 276 257 226 232 267 239 261 279 247 244 220 225 244 261 267 258 265 256 249 267 263 277 240 274 237 269 234 250 230 267 225 271 232 285 262 266 279 275 242 257 261 232 230 256 283 262 244 278 256 228 259 259 247 248 242 236 224 238 248 266 267 242 231 258 291 262 292 234 250 238 272 246 271 273 291 262 266 273 257 274 264 259 257 259 266 245 245 240 275 248 267 237 230 263 276 234 290 243 222 270 244 257 231 263 276 259 222 255 210 249 262 228 262 249 223 275 273 280 285 266 255 266 249 266 239 271 231 275 270 255 220 266 264 225 256 238 278 301 270 276 257 265 261 283 281 247 230 262 257 265 259 256 248 247 268 234 244 235 267 278 246 278 259 241 283 263 243 248 286 262 235 237 258 218 233 265 278 273 256 274 255 224 256 265 256 289 283 295 256 271 263 244 242 267 255 260 236 247 283 284 237 229 255 263 246 261 244 259 256 247 270 234 292 227 243 226 280 259 262 258 236 255 257 265 240 270 256 239 255 285 240 266 273 265 307 261 259 225 268 260 228 249 263 265 276 241 261 233 263 244 261 233 259 257 263 230 266 259 274 204 247 233 270 279 226 238 276 275 283 267 258 242 256 260 279 292 246 284 241 260 236 255 256 257 270 286 268 260 270 240 233 231 278 247 228 265 244 243 278 248 247 239 256 265 256 242 255 262 222 260 272 274 213 247 226 233 260 232 248 280 234 288 266 258 243 269 262 263 286 245 219 232 229 238 249 269 249 242 236 259 240 262 238 221 284 268 260 276 291 249 241 215 255 262 239 216 236 262 270 243 264 278 268 256 289 301 244 259 283 248 280 266 285 262 247 276 238 249 270 262 236 243 233 275 260 272 246 289 228 232 278 245 241 264 280 283 241 234 260 264 260 244 246 267 271 260 237 292 242 266 258 223 247 239 271 286 275 287 273 239 274 240 288 268 245 255 264 257 246 258 238 304 277 264 243 228 276 247 304 285 239 283 235 246 266 234 232 274 237 263 266 255 261 255 224 250 242 257 258 239 227 244 265 261 245 286 259 267 229 275 280 233 260 257 275 270 277 270 238 243 271 261 243 298 221 249 246 269 243 259 233 262 260 234 265 263 281 265 258 263 234 259 268 233 257 234 276 256 266 275 238 266 284 242 270 276 277 235 243 260 262 268 257 245 215 271 257 263 267 246 250 262 255 241 255 267 295 244 257 255 241 274 259 239 264 275 258 257 243 259 242 272 255 257 245 265 273 273 264 255 236 285 284 257 241 272 277 246 258 260 246 238 240 247 293 283 255 227 272 268 249 257 221 278 264 224 245 233 240 278 270 240 283 264 240 261 280 270 223 275 235 244 249 287 279 236 257 270 239 266 245 261 238 269 247 266 231 245 220 269 277 267 256 238 263 211 257 267 265 279 270 282 240 241 248 229 260 272 269 277 237 267 256 272 230 257 276 281 245 261 242 242 281 233 255 242 258 237 266 265 248 260 247 264 273 249 245 232 277 264 235 237 242 277 266 294 242 243 240 270 257 258 255 249 243 249 280 246 286 265 262 225 232 248 257 248 239 243 234 259 250 234 275 240 235 235 272 256 276 246 238 238 241 265 263 259 230 247 243 236 238 259 271 285 286 242 286 238 266 262 238 270 235 256 222 258 249 238 247 223 258 249 270 246 256 290 265 261 248 258 259 269 258 279 273 265 249 226 276 274 249 217 267 231 268 260 287 269 237 244 247 257 262 260 242 236 288 266 282 273 260 235 263 276 255 237 224 292 264 236 262 273 238 258 274 273 268 240 280 272 265 247 247 237 246 248 287 270 219 255 245 270 269 218 261 258 229 236 248 248 242 272 297 276 249 272 218 259 236 201 257 263 273 284 265 261 283 240 232 262 259 263 255 263 244 243 266 248 238 243 242 230 237 274 238 261 246 261 274 239 227 242 272 236 232 255 268 271 248 259 228 245 241 222 259 271 273 259 244 219 278 278 240 246 231 226 222 243 237 237 291 255 244 259 237 248 228 280 228 238 245 239 283 275 267 289 240 230 232 279 264 273 262 264 283 279 235 274 274 255 276 297 278 245 269 237 221 261 269 259 283 267 247 240 246 247 245 267 234 267 273 226 257 245 272 236 256 246 239 249 231 232 236 260 242 259 232 229 262 257 244 249 238 278 243 276 235 272 246 245 237 244 273 281 266 267 211 290 289 267 243 232 270 246 267 233 273 211 238 270 263 242 272 242 265 261 239 233 276 267 235 247 246 240 233 228 233 261 282 262 280 274 240 255 258 266 245 255 236 247 241 236 263 237 260 256 246 267 233 237 236 270 240 232 275 258 259 265 236 263 266 268 258 281 238 243 257 275 263 280 229 258 257 270 244 262 241 218 231 249 265 266 265 263 208 274 269 265 242 255 236 255 266 234 257 243 231 262 289 265 227 259 228 299 261 233 248 231 262 240 290 258 245 318 265 266 235 273 270 242 218 223 272 267 249 268 261 261 266 259 234 272 242 260 248 257 237 241 277 250 234 269 242 257 270 272 243 271 277 267 243 219 260 242 279 221 244 273 249 264 260 259 242 240 238 287 286 271 229 262 232 268 267 271 277 249 271 281 267 263 275 265 270 302 248 257 271 259 279 241 257 238 243 250 291 264 269 290 278 291 286 267 292 290 245 281 259 263 264 280 262 316 297 276 280 270 264 290 280 315 270 327 303 282 288 294 308 280 270 303 304 300 289 272 313 302 270 276 275 300 304 313 327 267 279 262 273 303 262 268 308 289 286 274 283 295 285 282 288 324 299 294 294 293 280 262 280 294 241 259 263 244 297 281 231 241 264 242 263 304 257 282 249 247 242 247 261 263 265 245 273 262 277 243 264 255 266 237 274 269 278 259 256 224 235 271 231 286 247 285 272 262 271 247 271 255 265 259 267 255 221 236 240 249 268 280 248 224 258 237 258 235 259 260 228 236 284 232 258 257 248 259 261 261 233 248 226 232 255 240 236 257 306 270 229 263 265 246 249 260 297 227 244 243 235 229 246 259 264 248 244 247 249 227 231 249 262 272 217 262 267 243 234 277 247 266 218 220 238 255 231 231 257 241 258 250 240 244 234 258 278 278 247 265 249 232 250 258 219 267 272 245 255 239 221 250 248 249 250 236 233 255 241 249 260 281 261 268 261 243 246 242 245 242 262 249 239 242 220 231 256 268 237 258 247 264 231 237 237 234 231 229 267 246 256 258 261 258 228 222 262 277 233 272 246 236 270 260 232 269 259 225 225 223 223 224 239 239 250 264 222 217 263 268 229 245 269 288 237 244 227 236 224 265 265 232 237 280 241 261 240 261 264 240 237 236 270 262 270 240 218 229 237 228 242 245 259 224 240 267 242 225 215 236 235 234 245 248 240 224 231 230 241 267 210 246 248 235 258 271 233 236 228 234 232 245 264 248 246 236 240 250 236 225 262 228 256 263 261 264 233 262 240 223 249 240 236 269 232 263 238 237 246 237 239 267 230 236 246 248 245 227 269 234 216 236 226 237 280 222 244 243 256 225 239 255 238 244 241 218 236 257 228 259 224 243 230 225 232 259 241 237 267 269 266 230 256 247 264 249 255 261 260 260 247 257 273 266 258 241 259 217 257 247 215 225 244 231 243 263 214 221 282 217 257 247 203 220 261 245 260 244 242 286 274 261 226 265 241 265 256 226 236 246 237 267 269 240 227 243 245 241 257 207 245 237 237 232 243 218 248 249 230 224 241 256 214 264 261 230 262 245 260 271 222 243 249 233 235 227 223 269 297 281 206 229 244 241 212 275 239 255 228 270 271 233 240 221 264 241 248 302 242 245 261 232 236 271 259 264 223 229 223 241 230 234 224 228 236 232 225 266 230 213 228 246 243 240 234 263 216 269 220 207 235 230 231 232 248 249 248 255 220 221 238 222 258 236 260 219 246 220 241 222 228 203 234 228 255 236 261 233 247 228 229 256 255 243 268 206 266 248 247 228 262 262 238 236 249 231 257 258 235 239 237 208 245 238 248 249 244 239 232 248 257 240 248 274 233 233 265 232 223 257 222 228 226 228 265 285 226 238 226 227 226 235 219 202 259 234 228 225 267 228 270 220 259 234 261 255 237 237 235 237 236 275 237 240 244 231 221 264 257 274 238 248 233 242 200 243 243 234 238 245 255 247 263 222 244 241 239 268 233 224 264 236 233 249 248 199 240 243 246 243 233 267 274 233 248 264 232 233 225 227 243 260 240 258 236 224 248 256 225 270 260 231 242 256 271 249 242 249 213 247 218 227 262 241 229 199 235 250 246 232 243 245 263 236 241 240 243 238 231 221 274 220 215 224 226 231 236 221 247 262 247 271 237 244 244 237 224 255 261 229 234 245 236 228 255 232 235 243 233 244 263 237 236 248 262 215 221 259 244 257 249 275 263 268 261 296 233 219 233 238 269 258 241 234 209 246 267 235 242 261 268 258 276 242 235 230 233 263 255 239 275 248 225 273 235 243 206 241 237 247 266 257 240 257 265 260 255 215 240 236 225 271 228 261 268 255 246 259 241 218 250 240 233 244 238 268 211 214 225 230 258 228 240 264 233 238 281 218 259 232 238 221 262 286 265 273 236 244 213 240 248 243 257 233 226 219 218 240 275 231 259 234 240 250 268 258 236 247 274 238 264 245 227 234 257 234 225 244 262 261 244 228 264 230 238 213 242 228 249 245 226 278 255 244 237 227 209 264 235 273 264 267 223 231 230 224 224 260 267 277 258 271 241 249 265 236 206 231 226 239 261 220 231 262 275 258 221 237 243 268 228 246 258 246 225 261 226 231 259 246 237 221 241 239 237 269 269 207 247 227 249 226 240 242 222 250 224 248 244 241 216 234 235 243 246 203 255 244 223 219 249 234 236 239 221 257 234 223 234 259 233 229 243 262 256 265 234 216 231 269 240 242 226 256 237 257 244 223 228 239 231 241 267 286 240 261 260 231 274 229 232 243 236 241 265 267 243 237 237 233 248 212 238 266 286 245 247 210 225 192 237 237 263 271 240 249 246 201 255 230 258 231 246 237 228 226 282 264 234 227 258 228 243 259 226 262 217 230 237 217 227 231 268 225 245 243 266 226 243 257 244 245 239 235 256 271 266 220 218 236 250 230 239 203 264 229 230 233 248 258 196 213 219 230 224 230 227 217 232 274 239 233 232 244 227 250 208 259 262 241 275 242 243 262 300 261 259 236 233 217 246 248 207 232 206 218 225 244 209 247 222 256 203 240 261 239 266 241 261 249 242 232 229 223 238 223 241 210 257 206 216 227 240 244 274 240 227 258 231 228 236 248 232 236 246 241 241 223 237 233 226 274 264 234 224 214 283 242 236 238 233 225 246 236 236 207 248 227 248 245 243 243 255 241 225 216 239 294 233 259 255 266 272 233 263 248 231 266 241 264 245 219 226 235 234 261 239 217 242 235 246 237 230 271 267 225 214 245 245 242 228 232 257 238 229 234 242 225 245 245 279 227 256 258 272 247 223 238 246 231 216 224 236 238 246 212 249 249 260 240 258 267 218 272 216 241 255 266 246 217 229 240 227 257 237 231 206 239 221 228 242 255 205 275 275 235 259 249 215 281 198 224 246 263 256 260 219 221 249 217 217 220 208 235 225 250 241 234 215 231 247 222 223 270 240 258 263 215 248 241 218 218 255 227 233 211 240 232 225 230 224 238 242 221 232 224 267 225 235 227 211 239 239 257 238 249 236 259 228 269 234 247 259 241 256 294 255 246 206 207 242 215 226 234 277 232 208 232 213 224 229 259 241 227 249 204 258 241 242 240 240 229 239 231 210 276 232 241 243 225 246 261 248 248 259 257 237 237 222 220 256 235 264 233 237 224 237 224 280 271 219 223 237 213 242 219 233 262 267 237 240 249 233 259 239 212 221 242 246 228 212 285 221 238 259 233 223 247 241 246 244 260 239 245 263 256 224 234 235 223 235 261 261 241 219 249 219 224 274 223 224 240 237 235 238 257 221 230 228 216 240 263 241 226 242 272 249 242 230 248 224 236 255 223 226 246 255 259 238 232 258 229 222 225 248 235 237 246 261 245 230 231 255 228 259 259 237 265 262 255 240 259 219 238 235 260 242 272 246 226 257 239 227 268 258 245 239 265 244 243 239 224 264 227 244 248 219 235 243 228 247 244 210 258 236 239 247 236 239 259 241 224 257 266 246 230 212 236 235 278 229 266 238 237 224 257 249 218 229 259 218 256 238 231 278 258 271 230 203 234 248 266 238 234 257 246 242 224 231 209 267 263 266 242 230 228 247 219 233 216 213 240 245 229 214 226 199 232 235 246 244 248 258 241 262 261 256 248 273 256 231 258 239 235 268 248 261 237 266 242 227 237 225 220 198 256 268 235 273 265 224 237 230 264 230 232 215 263 262 241 222 230 244 256 244 245 238 229 241 271 241 246 231 260 270 258 263 249 228 245 230 256 242 247 269 258 273 235 264 285 240 257 234 231 234 250 265 243 248 238 248 236 274 236 258 267 245 229 261 236 257 234 261 241 255 279 229 268 234 247 234 247 272 214 259 235 223 233 236 261 235 217 257 264 227 256 235 230 237 274 275 219 243 264 261 272 241 242 259 246 222 284 242 263 220 231 213 241 238 277 233 225 237 240 215 258 197 243 241 258 265 266 244 257 259 249 248 223 238 256 257 221 234 243 214 239 229 236 228 223 235 243 232 255 229 232 266 226 219 218 246 225 240 242 243 260 219 257 271 234 238 270 266 249 246 241 248 235 242 195 247 249 262 218 239 265 242 232 245 219 249 227 248 216 272 263 219 258 274 247 260 225 256 224 223 234 232 255 233 220 241 241 264 255 241 279 208 235 237 244 234 235 259 238 226 238 286 259 234 282 260 218 226 255 227 237 215 239 261 232 214 228 260 223 224 256 241 257 255 232 236 232 217 266 208 231 255 240 266 267 216 255 220 234 237 266 224 221 238 226 243 248 221 239 263 256 262 240 233 239 234 246 223 242 245 222 226 246 234 229 231 241 248 216 261 231 257 231 205 231 243 237 241 237 247 243 192 244 237 235 239 244 224 204 260 270 234 260 240 258 227 227 234 221 241 267 222 224 234 212 217 218 242 277 256 272 239 249 231 255 221 255 233 242 256 260 238 222 236 246 215 218 267 233 239 267 237 269 240 218 240 236 220 220 263 210 211 246 237 224 223 255 226 227 232 259 217 218 221 277 258 232 218 258 243 239 264 261 210 246 237 205 239 239 242 227 259 282 226 239 262 269 261 227 228 234 221 226 233 259 272 244 275 237 233 248 223 217 214 230 225 237 220 264 273 236 216 255 215 222 225 243 236 224 236 263 239 255 245 225 240 229 257 218 236 214 213 247 222 217 226 239 259 225 228 228 217 257 244 209 266 222 236 218 234 232 234 226 245 242 224 225 228 246 236 238 233 235 235 235 243 218 202 264 263 207 258 258 243 268 257 245 248 244 243 207 224 226 266 221 220 288 225 223 244 245 236 227 261 240 242 211 212 202 227 246 227 239 265 242 272 214 232 242 234 247 250 239 234 229 227 239 222 260 232 245 264 239 237 240 247 230 258 247 242 214 276 211 217 263 237 260 234 260 234 239 224 263 243 261 257 267 257 263 229 240 229 255 248 221 220 262 231 207 240 220 240 228 218 221 231 262 237 238 248 242 190 248 243 229 243 231 230 262 241 242 239 232 265 244 232 236 230 244 228 232 263 256 230 228 235 295 233 235 249 271 229 228 226 244 261 218 228 246 265 241 260 210 244 238 230 255 220 241 259 246 247 260 240 240 242 224 234 225 266 235 229 228 266 228 240 241 240 257 212 224 209 210 240 258 262 221 235 244 217 237 219 249 234 260 221 225 236 228 275 255 255 241 243 234 214 233 205 258 269 238 235 245 243 224 224 244 234 231 242 232 232 240 232 236 212 262 241 236 240 237 231 231 259 238 242 264 216 249 239 231 225 267 238 216 222 237 257 239 227 256 228 271 235 216 228 228 214 237 227 248 241 260 231 260 218 247 244 235 238 223 237 243 239 249 220 233 256 224 259 219 244 236 255 234 231 215 241 248 228 219 230 236 259 258 240 187 242 268 276 239 247 235 234 262 228 235 247 207 297 256 265 211 238 229 205 241 267 224 249 246 238 210 234 240 209 260 246 265 244 237 226 241 277 229 234 219 231 248 221 225 245 215 268 242 230 214 211 214 236 233 260 256 264 220 248 244 278 237 220 212 265 214 255 245 249 247 256 240 217 225 208 235 245 237 261 256 248 234 247 242 221 249 237 234 238 245 239 249 229 234 262 234 231 221 272 229 234 239 237 234 237 225 234 231 248 232 244 272 243 246 226 255 255 246 232 249 247 230 232 229 235 265 221 247 267 246 202 257 262 262 232 237 249 230 230 222 247 240 226 240 243 241 261 240 268 213 270 256 234 260 255 233 232 223 240 266 246 248 203 255 207 231 244 263 258 214 231 267 245 234 236 226 241 257 222 223 264 235 234 210 239 214 230 283 258 239 239 260 237 241 258 262 242 262 231 246 240 244 232 239 232 210 245 231 232 229 249 235 227 256 237 228 259 239 218 235 263 240 210 232 237 255 223 258 236 246 228 246 239 262 258 242 249 249 247 286 240 249 250 257 223 278 255 256 240 231 248 277 262 240 224 231 249 216 243 245 264 241 259 273 221 255 233 248 244 228 243 264 217 250 277 256 217 225 218 235 243 228 234 238 256 215 217 247 261 229 236 231 257 212 216 239 257 224 240 258 239 211 260 241 257 248 213 221 228 245 238 217 221 261 256 255 227 227 250 240 256 236 230 238 234 267 238 239 248 250 213 242 247 230 231 231 234 255 226 233 242 248 244 237 243 237 241 257 223 246 229 227 238 215 261 232 244 219 258 219 256 236 223 233 229 261 218 241 228 229 263 261 241 241 259 272 233 226 248 230 247 238 237 238 220 248 222 264 226 229 238 209 247 273 256 225 218 237 224 214 202 230 231 220 225 268 213 246 238 243 264 215 230 257 220 269 227 267 250 220 228 215 235 247 218 213 222 259 281 244 276 277 230 220 249 226 240 235 229 234 233 239 244 200 247 206 227 268 255 234 264 243 262 242 208 223 228 269 237 241 243 235 262 283 258 240 228 245 243 220 236 241 224 223 223 226 238 270 218 239 232 221 272 235 274 229 240 203 221 232 272 246 229 236 207 243 247 233 236 258 224 223 211 258 217 247 224 242 242 222 230 224 221 231 236 215 257 230 245 237 235 235 208 223 239 256 225 268 238 268 213 256 261 255 246 226 264 270 220 248 261 231 241 246 244 259 229 268 264 260 221 239 256 218 229 238 240 237 240 218 273 248 240 235 229 231 235 257 258 260 237 263 243 246 266 222 229 235 259 236 232 246 202 246 232 234 241 214 241 206 228 237 234 234 223 210 233 226 241 217 221 241 227 269 241 247 242 234 214 241 246 233 268 255 232 230 249 237 248 236 233 226 258 224 244 205 249 227 234 249 222 260 244 238 231 235 244 222 210 235 220 226 247 230 260 226 201 248 233 263 217 263 231 244 217 223 268 198 248 240 228 227 232 244 240 224 259 228 223 217 240 272 233 258 216 230 242 257 260 248 225 260 264 256 234 248 242 242 240 258 237 222 242 225 234 230 249 270 225 265 230 265 263 227 245 235 240 244 236 240 231 224 234 270 229 272 248 231 234 245 247 232 238 234 220 286 241 217 225 246 229 262 258 236 231 226 257 230 235 238 246 247 266 228 217 236 204 218 224 233 245 237 242 255 242 237 234 224 245 283 259 229 241 237 260 235 247 233 216 230 238 230 256 236 260 241 223 246 237 255 262 268 227 237 211 233 250 210 233 257 217 230 263 256 238 239 243 266 206 246 232 270 219 259 255 229 237 242 260 266 216 263 226 266 235 238 229 260 244 235 255 292 212 231 232 232 263 244 240 230 238 231 241 266 243 256 219 229 226 221 266 243 238 261 240 218 274 267 245 224 224 208 241 268 273 221 245 221 242 236 225 239 280 234 273 233 235 207 246 222 236 244 234 246 249 267 244 258 260 223 225 268 241 220 249 256 242 236 246 274 232 224 237 240 269 239 237 236 256 222 234 234 238 238 267 218 244 282 240 257 247 228 222 259 219 276 244 225 223 256 230 269 246 243 245 229 238 243 234 239 255 247 243 246 227 245 269 214 223 263 240 264 238 239 221 232 257 259 260 227 217 257 243 264 249 215 236 237 266 249 228 238 266 269 230 243 273 247 225 207 232 228 265 243 258 268 230 235 245 242 221 231 245 246 243 219 255 231 268 235 247 231 244 246 276 226 228 258 256 245 229 243 280 264 232 244 241 248 246 283 246 236 246 241 234 245 236 277 280 247 233 241 275 229 232 243 231 233 274 255 275 233 260 236 234 243 237 247 257 269 240 246 236 274 266 280 246 246 241 259 263 284 225 250 260 243 270 237 250 230 284 261 255 266 255 261 232 299 237 223 262 256 242 249 246 230 259 290 240 264 269 232 248 270 268 249 240 264 288 273 222 231 276 236 238 256 234 239 275 271 260 244 242 256 241 239 231 236 236 250 242 237 235 234 235 288 261 243 240 243 234 274 248 255 216 235 287 260 259 230 219 259 248 246 229 217 226 216 239 270 236 234 223 232 228 226 210 238 227 238 238 257 236 216 293 228 276 223 240 263 249 260 234 234 242 239 241 230 221 228 279 243 243 232 221 233 247 265 236 235 268 236 236 255 245 225 232 226 239 280 224 224 219 270 209 244 241 214 223 222 232 230 264 247 232 232 243 208 218 260 216 218 224 223 247 240 227 259 226 245 226 249 258 232 260 238 243 225 228 227 224 242 224 230 210 257 263 241 223 224 250 250 223 249 232 264 237 224 242 226 246 219 236 247 233 245 229 211 224 226 243 266 235 255 228 234 220 232 226 261 259 261 238 222 248 241 228 212 226 257 265 226 204 245 217 236 215 243 240 265 227 258 231 238 235 231 237 231 229 262 196 228 266 201 209 270 240 270 250 256 234 233 244 258 249 247 225 232 225 227 240 230 238 258 237 260 236 228 257 220 236 237 263 237 258 223 215 225 243 219 249 203 218 230 240 229 264 214 232 230 270 248 225 222 225 248 235 235 235 227 215 243 233 235 217 238 247 243 231 250 220 242 257 231 248 229 244 229 238 244 233 234 210 202 249 240 238 225 227 227 263 213 227 236 224 213 207 211 242 228 228 223 194 248 261 225 250 225 225 256 215 231 264 229 242 236 248 198 222 218 197 235 238 237 234 224 243 222 240 215 236 217 243 222 231 230 269 246 242 236 226 233 255 212 229 244 230 236 226 220 215 248 241 216 267 238 247 233 200 273 228 242 233 249 226 224 224 239 233 245 230 204 219 246 200 247 231 231 262 238 240 235 235 230 234 203 262 218 240 203 238 215 245 221 249 277 240 247 231 249 214 236 228 227 236 229 225 258 244 226 241 259 224 248 232 267 227 239 241 222 228 262 258 234 229 246 234 234 216 241 232 244 234 222 298 237 208 224 263 238 223 227 243 223 256 272 220 245 241 196 240 243 216 269 237 245 244 234 261 219 249 238 211 250 225 260 249 244 225 259 232 225 238 255 242 236 241 222 230 245 227 226 230 228 249 243 222 237 209 231 224 228 275 240 229 242 243 228 236 280 249 224 219 277 240 276 216 232 215 234 265 246 206 243 232 247 203 219 223 223 239 233 213 217 249 267 230 249 239 224 206 235 243 236 267 246 225 260 243 225 243 228 223 194 236 247 239 232 238 246 268 213 220 215 237 266 218 241 237 244 227 239 209 229 229 224 231 241 211 228 241 241 217 207 238 243 217 224 239 231 220 228 270 226 256 243 276 219 228 212 238 236 256 248 262 233 209 241 229 238 221 214 232 233 270 224 248 276 212 236 249 241 256 242 247 239 229 260 264 242 236 234 225 220 234 231 223 264 246 220 236 225 232 249 240 224 226 238 260 247 245 269 234 222 246 225 225 232 238 263 267 244 228 226 246 258 232 247 237 213 220 256 212 237 234 218 248 263 209 233 242 233 246 234 219 226 240 240 261 217 223 214 212 233 232 233 222 205 260 258 184 283 224 223 225 226 248 220 209 233 208 226 246 205 221 235 219 257 240 224 225 228 256 234 236 240 241 239 234 222 236 224 217 233 232 247 234 236 233 226 231 246 241 228 263 272 260 268 201 212 231 226 259 231 234 244 237 263 244 264 248 214 208 224 244 248 258 210 225 232 243 227 216 230 249 240 244 238 240 210 245 213 234 242 202 231 212 229 245 219 231 222 267 237 247 275 222 231 218 244 248 248 241 233 247 227 267 224 226 230 229 245 218 292 239 249 250 216 248 247 219 242 256 222 268 224 260 239 244 242 222 248 234 239 227 244 220 240 195 208 260 257 236 246 263 235 217 222 238 283 259 257 236 218 228 241 236 225 239 243 225 244 229 212 241 217 237 240 256 267 223 245 237 218 246 271 243 230 231 226 234 227 231 264 238 243 202 241 223 247 243 243 269 233 225 248 259 237 219 249 236 266 265 239 258 262 238 243 249 234 216 228 246 235 242 259 265 240 242 237 221 262 201 244 233 239 228 224 257 257 239 239 255 234 228 221 223 269 242 260 230 245 225 234 218 242 249 259 233 265 227 223 261 223 233 267 241 262 208 222 241 216 265 242 241 229 262 223 270 230 267 213 247 242 218 280 247 234 263 262 256 247 240 262 235 245 261 232 229 268 229 261 249 257 219 228 249 198 231 236 236 256 222 239 216 243 256 244 269 248 219 206 211 225 212 234 242 247 258 247 233 274 222 224 285 245 250 246 228 243 255 236 261 234 221 212 235 243 237 239 243 239 255 275 258 284 229 230 242 232 262 244 234 239 224 258 246 259 241 247 269 223 235 245 232 240 239 230 257 227 225 256 243 233 232 213 209 223 237 246 268 241 267 245 268 233 266 255 241 232 222 274 292 214 265 236 239 241 238 258 239 215 244 241 222 268 226 261 225 257 204 242 216 219 232 249 227 235 227 227 214 235 242 228 241 247 263 243 257 245 233 208 258 223 221 257 209 221 277 257 234 236 232 239 257 262 255 246 248 241 247 259 269 259 214 266 280 280 247 242 239 227 229 236 226 227 243 268 240 192 259 214 263 250 197 221 261 258 269 246 272 209 246 260 244 227 262 246 227 232 233 236 262 220 261 235 258 258 239 246 242 211 230 273 213 218 269 226 236 226 216 248 272 230 289 268 223 247 248 229 238 245 239 237 232 255 249 240 230 237 234 260 246 235 276 239 244 238 242 237 259 263 255 266 266 216 237 257 256 271 239 230 263 242 247 245 246 260 255 271 233 239 226 248 259 210 217 293 255 220 232 221 265 237 269 232 235 264 222 240 239 237 285 248 220 239 277 270 233 228 241 241 271 244 261 211 213 261 241 222 261 233 216 230 259 223 240 243 260 235 237 245 209 234 230 240 226 276 221 249 231 244 230 263 260 246 255 240 231 238 245 269 232 259 257 248 223 221 230 245 243 239 240 248 213 264 234 223 259 219 238 246 287 201 232 246 244 210 260 247 233 239 235 260 259 255 255 263 246 234 266 232 257 239 240 227 234 245 233 217 237 268 233</counts>
			</dataPoints>
		</scan>
	</xrdMeasurement>
</xrdMeasurements>