File: data/XRD/XG-Vakuum/XG-700/W6824-1C_XG_Vakuum_700.xrdml
<xrdMeasurements xmlns="http://www.xrdml.com/XRDMeasurement/2.1" xmlns:xsi="http://www.w3.org/2001/XMLSchema-instance" xsi:schemaLocation="http://www.xrdml.com/XRDMeasurement/2.1 http://www.xrdml.com/XRDMeasurement/2.1/XRDMeasurement.xsd" status="Completed">
	<comment>
		<entry>Configuration=Factory configuration, Owner=User-1, Creation date=7/8/2013 4:01:53 PM</entry>
		<entry>Goniometer=PW3050/65 (Theta/2Theta); Minimum step size 2Theta:0.0001; Minimum step size Omega:0.0001</entry>
		<entry>Sample stage=MRD Cradle; Minimum step size Phi:0.01; Minimum step size Chi:0.01; Minimum step size X:0.01; Minimum step size Y:0.01; Minimum step size Z:0.001</entry>
		<entry>Diffractometer system=XPERT-PRO</entry>
		<entry>Measurement program=C:\PANalytical\Data Collector\Programs\Jorrit\2thom\_absolute_2th-om_10-130deg_PIXscan_56min.xrdmp, Identifier={15BCCF57-2807-42BD-B5B9-ECC0B3DC9284}</entry>
		<entry>Batch program=C:\PANalytical\Data Collector\Programs\SimonL\batch4x_2thom_10-130°_z9.1_x0,10,20,30_y0_57min.xrdmp, Identifier={EED9823A-2BEB-424C-9252-345C4EF2834A}</entry>
	</comment>
	<sample type="To be analyzed">
		<id></id>
		<name></name>
		<preparedBy></preparedBy>
	</sample>
	<xrdMeasurement measurementType="Scan" status="Completed" sampleMode="Reflection">
		<comment>
			<entry>_absolute_2th-om_10-130deg_PIXscan_56min</entry>
			<entry>PHD Lower Level = 4.83 (keV), PHD Upper Level = 11.27 (keV)</entry>
		</comment>
		<usedWavelength intended="K-Alpha 1">
			<kAlpha1 unit="Angstrom">1.5405980</kAlpha1>
			<kAlpha2 unit="Angstrom">1.5444260</kAlpha2>
			<kBeta unit="Angstrom">1.3922500</kBeta>
			<ratioKAlpha2KAlpha1>0.5000</ratioKAlpha2KAlpha1>
		</usedWavelength>
		<incidentBeamPath>
			<radius unit="mm">320.00</radius>
			<xRayTube id="1010048" name="Empyrean Cu LFF HR (9430 033 7310x) DK442154">
				<tension unit="kV">40.0</tension>
				<current unit="mA">40.0</current>
				<anodeMaterial>Cu</anodeMaterial>
				<focus type="Line">
					<length unit="mm">12.0</length>
					<width unit="mm">0.4</width>
					<takeOffAngle unit="deg">4.2</takeOffAngle>
				</focus>
			</xRayTube>
			<xRayMirror id="27010001" name="Inc. Beam Cu W/Si (parabolic MRD)" hybrid="false">
				<crystal type="Graded" shape="Parabolic">W/Si</crystal>
				<acceptanceAngle unit="deg">0.800</acceptanceAngle>
				<length unit="mm">60.0</length>
			</xRayMirror>
			<sollerSlit id="21010002" name="Soller slits 0.04 rad.">
				<opening unit="rad">0.0400</opening>
			</sollerSlit>
			<mask id="22030008" name="Fixed mask 4 mm">
				<distanceToSample unit="mm">220.00</distanceToSample>
				<width unit="mm">4.00</width>
			</mask>
			<divergenceSlit id="22010007" name="Fixed slit 1/8°" xsi:type="fixedDivergenceSlitType">
				<distanceToSample unit="mm">220.00</distanceToSample>
				<height unit="mm">0.19</height>
			</divergenceSlit>
		</incidentBeamPath>
		<diffractedBeamPath>
			<radius unit="mm">320.00</radius>
			<sollerSlit id="21010002" name="Soller slits 0.04 rad.">
				<opening unit="rad">0.0400</opening>
			</sollerSlit>
			<receivingSlit id="22010001" name="Fixed slit 4°">
				<height unit="mm">5.88</height>
			</receivingSlit>
			<detector id="7010017" name="PIXcel3D 1x1 detector" xsi:type="areaDetectorType">
				<phd unit="%">
					<lowerLevel>30.0</lowerLevel>
					<upperLevel>70.0</upperLevel>
				</phd>
				<mode>Scanning</mode>
				<activeChannelsEquatorial>255</activeChannelsEquatorial>
				<activeChannelsAxial>255</activeChannelsAxial>
				<pitchEquatorial unit="mm">0.05500</pitchEquatorial>
				<pitchAxial unit="mm">0.05500</pitchAxial>
				<readOutPeriod unit="seconds">0.135</readOutPeriod>
			</detector>
		</diffractedBeamPath>
		<scan appendNumber="0" mode="Continuous" scanAxis="2Theta-Omega" status="Completed">
			<header>
				<startTimeStamp>2024-10-09T13:11:24+02:00</startTimeStamp>
				<endTimeStamp>2024-10-09T14:07:30+02:00</endTimeStamp>
				<author>
					<name>PRO-MRD</name>
				</author>
				<source>
					<applicationSoftware version="6.1b">Data Collector</applicationSoftware>
					<instrumentControlSoftware version="7.0E 20130304">XPERT-PRO</instrumentControlSoftware>
					<instrumentID>0000000011142674</instrumentID>
				</source>
			</header>
			<dataPoints>
				<positions axis="2Theta" unit="deg">
					<startPosition>9.99826193</startPosition>
					<endPosition>129.99755682</endPosition>
				</positions>
				<positions axis="Omega" unit="deg">
					<startPosition>4.99913096</startPosition>
					<endPosition>64.99877841</endPosition>
				</positions>
				<positions axis="Phi" unit="deg">
					<commonPosition>0.00</commonPosition>
				</positions>
				<positions axis="Chi" unit="deg">
					<commonPosition>0.00</commonPosition>
				</positions>
				<positions axis="X" unit="mm">
					<commonPosition>30.00</commonPosition>
				</positions>
				<positions axis="Y" unit="mm">
					<commonPosition>0.00</commonPosition>
				</positions>
				<positions axis="Z" unit="mm">
					<commonPosition>9.100</commonPosition>
				</positions>
				<commonCountingTime unit="seconds">32.895</commonCountingTime>
				<counts 440 429 436 432 422 444 444 400 398 430 408 458 406 396 399 422 414 434 403 412 406 420 385 405 458 436 426 410 421 416 398 424 422 426 413 428 453 404 417 463 426 415 399 406 382 394 433 441 445 440 432 419 406 433 430 439 417 423 424 450 401 426 423 426 398 417 397 394 409 426 421 365 398 382 411 397 400 397 415 421 376 367 373 388 369 386 412 410 413 402 401 407 410 375 411 390 395 402 417 442 415 407 428 380 437 384 432 394 435 426 422 422 421 430 404 439 389 418 395 403 380 415 368 410 422 426 391 417 405 408 399 411 420 377 404 395 403 385 374 422 407 381 364 377 354 369 379 394 400 456 381 389 402 418 377 399 370 396 360 394 387 386 376 387 428 404 386 369 372 395 377 386 378 381 402 381 371 368 406 369 410 414 391 391 402 407 399 393 383 327 383 367 394 368 406 362 382 370 410 390 374 389 351 397 372 383 321 375 396 405 362 366 367 399 378 380 382 370 362 376 347 364 387 355 390 353 417 376 384 374 353 406 386 378 390 375 373 370 404 370 371 356 397 355 376 375 388 389 370 362 371 369 381 370 328 337 332 348 384 364 335 374 395 408 378 362 399 358 377 393 370 362 373 390 396 407 373 357 391 344 424 367 371 344 383 389 348 347 390 376 366 358 364 366 387 400 391 383 391 307 340 396 342 354 412 366 373 372 331 366 373 351 364 368 356 384 331 384 357 372 376 369 343 348 358 347 321 381 358 335 361 372 342 396 344 373 380 349 339 330 361 385 353 371 343 380 356 351 350 390 335 318 348 348 392 358 352 357 346 376 303 379 362 328 356 327 351 363 388 334 331 367 355 366 326 318 332 352 331 324 354 335 354 332 335 365 342 349 326 329 358 342 333 337 318 325 356 363 349 317 357 334 335 310 336 331 351 338 328 301 355 344 345 346 346 346 364 302 336 370 340 288 336 313 376 342 339 335 323 330 326 336 329 309 306 329 328 319 351 296 342 342 319 346 349 301 326 365 340 372 320 308 336 334 342 336 334 344 346 329 317 347 332 319 327 338 306 300 325 363 328 328 295 302 326 324 328 343 307 322 350 337 305 335 309 297 328 332 331 329 342 335 332 337 331 309 321 351 328 324 314 324 338 334 322 329 355 324 332 324 344 317 325 337 360 309 312 309 354 361 321 282 339 340 313 313 334 305 294 355 301 311 323 307 332 342 315 290 304 318 277 342 358 339 321 344 326 322 325 337 306 331 349 315 304 329 337 322 340 308 287 297 321 336 330 338 351 306 337 338 335 320 368 281 306 290 325 328 281 311 325 316 316 323 317 317 316 323 330 319 306 326 306 327 304 305 304 303 285 328 326 312 306 293 331 329 314 312 320 339 303 329 329 303 343 336 318 288 312 323 295 328 287 342 325 316 320 312 333 314 306 320 324 322 343 319 330 343 352 339 310 291 330 302 342 342 344 309 323 322 341 296 306 301 336 321 316 312 296 315 313 317 335 321 336 316 312 310 338 276 340 331 290 297 317 311 321 354 297 321 346 310 300 323 298 329 327 316 349 351 317 292 302 308 316 292 319 304 345 291 327 300 284 334 314 302 309 329 313 334 354 348 325 313 324 321 334 342 317 305 337 308 293 298 331 311 318 308 318 317 310 330 298 296 324 322 282 305 320 334 303 302 311 315 303 268 298 316 321 287 301 338 282 318 308 327 300 337 341 278 321 317 313 307 314 316 302 325 284 310 292 306 319 310 322 290 310 305 306 340 299 324 314 304 311 322 309 329 317 334 280 289 299 306 333 339 302 322 301 307 307 304 292 322 291 328 342 307 302 315 312 309 324 320 300 312 311 300 336 343 311 320 305 318 334 338 314 299 310 321 329 300 352 337 310 279 297 328 300 345 289 267 298 326 322 298 297 341 287 318 326 278 315 304 299 311 303 336 330 274 309 316 346 306 330 292 311 291 303 313 335 311 298 343 331 317 327 277 318 322 311 316 319 298 321 320 278 295 312 342 354 342 306 313 318 308 294 302 350 306 338 336 274 336 348 316 282 323 324 320 313 318 326 303 304 298 272 315 290 269 311 308 250 346 333 305 322 325 298 345 329 323 305 310 334 318 344 303 283 308 288 270 318 286 286 380 335 333 321 299 336 302 291 282 325 337 314 310 328 289 328 327 321 322 347 317 325 307 266 279 280 315 308 326 285 308 279 346 302 308 301 350 292 296 314 286 343 319 313 312 307 292 301 281 307 310 311 309 316 335 302 324 333 330 323 295 336 319 293 307 278 306 299 331 327 287 306 319 310 298 282 313 319 330 333 344 305 316 314 339 303 339 296 306 302 315 319 317 308 323 360 319 308 275 306 302 319 301 308 287 310 347 335 311 333 341 298 311 325 304 333 308 319 305 306 317 304 311 332 320 299 334 333 322 326 293 311 365 314 296 303 331 308 285 312 343 296 313 322 285 297 311 313 328 316 324 281 322 316 316 305 285 301 332 314 311 337 304 308 286 322 312 318 330 301 331 299 316 307 339 348 326 340 334 326 320 297 332 346 316 343 312 315 299 316 312 312 290 303 321 324 310 310 325 320 329 314 305 279 331 355 307 300 304 324 324 313 330 289 347 312 357 355 328 322 282 338 317 306 337 312 322 297 297 313 321 327 311 308 301 307 328 295 294 307 295 299 347 333 287 360 321 307 324 357 318 312 322 323 339 346 301 302 307 323 317 329 300 337 321 322 333 306 325 323 332 333 305 287 301 298 307 315 308 311 341 324 325 310 356 315 336 311 320 330 299 295 282 332 322 314 329 321 309 300 320 324 343 325 306 295 321 313 277 316 282 336 327 363 337 291 285 301 346 338 304 325 323 318 338 294 294 310 294 305 320 337 314 278 352 321 327 332 340 310 323 345 345 293 343 334 359 286 306 306 326 318 333 301 315 295 343 315 295 314 306 304 286 300 316 317 307 296 323 334 313 293 347 311 300 345 343 298 310 332 344 328 337 324 294 317 317 332 328 309 291 314 319 308 311 302 310 341 332 321 309 319 297 299 320 287 324 317 301 318 318 307 290 283 324 314 311 309 314 286 348 285 303 306 318 290 308 295 307 355 315 317 298 320 324 288 323 299 294 333 323 316 369 313 341 285 304 309 321 329 330 296 354 294 318 317 318 301 303 306 339 362 329 310 333 269 302 314 283 320 280 322 326 325 312 298 309 307 269 300 287 319 308 282 278 317 317 329 301 287 293 313 301 288 324 341 296 288 302 284 296 303 319 298 271 318 321 317 320 332 321 322 314 334 295 297 316 297 273 294 282 300 279 305 320 304 285 324 314 331 301 322 313 316 276 314 300 310 308 282 329 297 325 286 283 302 316 280 279 306 303 313 296 323 295 275 302 274 307 318 271 305 309 293 277 321 301 289 344 294 287 284 304 327 302 290 305 290 308 299 326 303 306 308 306 311 283 323 268 282 329 277 316 296 274 284 300 318 299 303 303 256 313 306 269 327 306 277 298 290 308 301 353 273 311 286 312 313 280 281 293 288 272 316 302 308 286 303 281 281 274 296 278 309 280 287 299 303 318 290 304 277 282 243 300 299 289 273 277 285 293 293 287 317 294 270 293 295 296 287 295 255 295 308 305 334 283 306 302 312 303 311 301 285 297 300 275 287 280 265 306 266 296 294 295 313 255 302 272 342 277 314 305 300 281 304 298 301 269 293 282 275 306 279 266 289 282 300 273 290 281 288 287 272 273 295 283 286 288 276 327 316 304 294 276 276 286 286 289 300 280 310 269 324 260 245 267 256 271 276 273 262 259 288 300 287 289 280 282 289 289 267 275 289 298 275 277 282 297 308 284 310 285 274 259 259 266 281 255 267 313 270 261 316 277 268 246 247 276 271 283 247 291 295 275 282 305 308 310 309 279 270 273 300 264 248 270 262 329 297 289 289 270 281 288 280 303 271 267 270 256 269 300 257 270 281 247 283 266 241 263 279 276 300 240 303 263 277 269 268 242 291 263 291 255 288 264 283 282 287 315 277 294 280 289 298 286 267 276 285 280 269 267 245 256 283 279 245 276 294 265 281 255 244 230 243 274 241 294 270 267 273 237 220 255 267 262 273 278 276 267 274 239 284 261 265 256 262 261 279 268 272 277 267 271 269 264 261 235 248 249 243 235 263 263 246 256 269 282 230 244 271 244 297 280 210 288 255 265 235 271 245 263 261 245 282 266 267 271 263 264 244 269 267 244 265 242 291 248 243 268 230 239 299 222 231 231 255 241 297 279 274 237 259 261 276 237 250 234 258 293 262 231 228 270 245 263 250 267 247 241 248 229 227 259 228 244 240 276 267 239 296 235 271 281 258 266 258 238 258 231 284 214 241 255 237 284 248 257 257 267 237 236 259 243 275 241 265 262 270 240 259 237 263 232 203 266 242 237 262 287 232 258 204 237 238 237 244 230 228 263 229 249 255 266 234 269 246 263 233 243 240 234 235 267 236 260 245 235 223 259 263 268 242 229 272 260 240 248 226 217 224 226 213 245 243 257 238 269 240 238 243 245 225 257 242 245 226 219 244 258 284 228 229 223 236 256 259 239 225 246 229 221 213 204 274 221 258 243 221 248 232 263 245 217 242 234 255 259 249 264 219 246 197 236 226 239 230 218 266 246 249 238 228 228 258 232 244 216 248 224 263 238 264 231 227 230 240 231 277 227 217 229 227 242 231 211 256 234 246 234 225 248 209 216 257 262 235 249 228 243 230 207 230 223 238 227 267 229 246 212 208 221 215 243 241 209 227 217 235 213 230 210 230 213 247 200 230 235 206 243 240 227 217 259 231 227 236 217 210 216 223 245 219 246 217 227 237 291 213 231 239 225 236 242 206 237 250 225 228 214 235 220 212 245 236 184 224 225 260 232 223 259 209 227 227 223 208 236 215 216 218 265 259 224 218 222 215 235 231 204 221 227 265 235 227 229 244 229 220 223 212 227 207 234 198 221 244 229 238 224 231 231 216 195 185 231 245 233 217 237 228 237 222 217 204 225 207 249 223 222 232 261 241 226 198 233 211 236 238 218 248 221 228 211 195 242 221 223 243 225 240 211 195 217 215 212 193 201 220 256 221 192 224 240 211 211 222 204 213 225 235 219 215 234 237 210 222 233 215 222 225 237 226 226 207 218 232 222 250 208 209 225 235 219 220 215 226 218 240 229 201 198 223 206 224 239 230 203 221 230 183 236 236 226 215 206 232 224 220 226 204 222 214 220 201 199 200 220 219 219 225 225 203 203 211 243 211 267 204 236 241 186 192 239 219 203 212 207 229 211 210 226 182 225 186 229 212 224 245 208 223 247 224 230 223 219 227 189 228 221 216 230 220 232 225 212 218 248 241 227 229 202 204 242 218 212 221 215 205 210 236 229 211 208 246 205 224 214 224 207 241 221 222 236 204 196 230 209 238 231 238 211 213 210 225 219 211 217 228 198 214 214 202 240 230 192 199 202 202 216 209 205 215 236 183 224 220 209 223 241 180 238 190 207 205 219 198 197 239 225 224 220 192 209 202 220 237 207 222 231 205 213 215 226 226 236 209 213 233 210 204 220 221 203 221 222 191 208 217 229 217 243 230 242 208 219 185 213 210 226 192 213 224 234 196 240 234 239 221 237 243 233 202 230 219 244 223 221 230 217 207 201 216 215 216 217 240 230 183 218 227 233 222 214 204 196 222 210 185 188 228 228 243 207 235 201 216 190 214 228 209 226 215 213 214 215 213 221 215 230 198 239 217 208 218 222 197 223 220 210 217 202 218 203 204 239 216 214 225 200 216 216 238 192 230 211 228 216 225 205 213 195 229 227 209 213 207 225 203 224 213 210 235 210 240 238 221 202 205 215 234 208 236 222 196 233 232 190 211 221 198 197 231 193 225 193 219 220 217 205 210 200 209 219 200 229 230 231 201 207 196 210 199 241 229 200 222 243 177 210 222 222 212 219 217 216 204 205 233 218 235 205 194 224 205 217 228 230 226 245 199 210 231 222 227 227 193 206 227 235 222 192 238 188 205 204 216 226 210 231 208 229 196 187 192 227 215 194 227 221 226 200 205 223 198 230 217 223 203 224 219 216 234 213 234 229 199 199 207 189 188 222 199 209 214 224 189 204 206 211 232 240 229 182 219 210 222 202 235 195 201 219 233 229 191 244 197 237 200 192 208 190 203 208 215 223 237 243 203 212 214 183 223 182 216 209 214 207 202 206 216 218 259 192 201 179 207 206 202 187 231 208 191 214 199 220 187 196 212 216 198 198 194 204 223 205 237 218 210 258 239 207 217 222 203 174 190 230 228 207 234 234 203 209 214 203 219 229 206 234 211 208 228 209 223 213 215 211 202 190 196 199 220 201 214 208 210 182 189 214 222 224 204 210 204 209 179 216 202 191 216 195 223 198 187 218 218 233 201 209 230 199 204 214 215 207 198 217 205 216 238 199 241 218 234 218 222 201 205 207 206 231 176 205 213 227 248 204 202 215 197 217 197 209 204 217 206 201 170 206 217 217 219 232 192 231 204 223 184 220 201 212 216 196 215 195 207 204 248 216 182 201 224 196 226 184 219 209 205 209 197 210 207 193 211 178 217 205 220 220 233 220 212 215 202 229 238 211 177 214 196 230 201 217 213 194 200 212 221 197 199 221 203 191 201 218 204 174 188 183 187 209 219 221 204 213 194 200 207 198 181 204 214 224 216 189 243 216 182 208 216 219 230 204 234 233 197 222 180 205 191 219 230 202 199 238 210 208 195 208 193 202 222 198 202 189 194 193 217 203 189 235 199 190 220 201 209 199 230 212 197 206 209 210 202 204 211 191 210 222 178 220 197 225 196 222 206 198 245 220 217 184 194 190 209 221 222 232 212 203 185 204 202 206 209 192 213 195 222 208 192 235 203 225 209 204 206 194 190 229 211 200 187 230 194 225 226 200 210 228 202 196 223 221 205 209 226 188 199 209 185 196 215 198 195 225 242 201 226 187 205 221 223 207 204 218 218 248 205 206 208 213 227 224 199 224 241 228 208 190 183 229 233 205 237 214 222 204 194 215 232 240 183 223 237 207 225 216 223 240 205 205 200 212 223 205 217 233 212 220 196 215 202 206 221 177 205 212 223 180 201 218 236 202 176 202 219 207 224 204 201 229 221 222 228 212 197 207 219 231 231 186 226 237 222 225 203 200 243 213 217 199 212 209 237 214 210 218 205 218 210 203 206 255 219 202 234 198 226 213 205 235 213 215 231 227 204 225 222 216 230 228 235 229 240 220 190 223 219 234 199 213 210 240 234 235 225 190 238 227 225 194 240 226 223 195 202 226 219 183 225 201 202 191 259 227 221 238 197 218 225 226 217 221 225 237 210 234 232 242 195 198 237 240 227 229 227 215 225 209 224 231 237 209 226 225 248 222 222 208 233 229 211 222 244 229 223 223 210 241 221 190 178 209 211 236 206 221 240 208 218 211 246 236 221 218 223 226 213 269 243 223 232 217 212 243 237 220 214 241 220 223 233 227 235 218 241 226 227 202 241 188 210 226 234 233 223 226 220 236 216 221 214 214 224 221 229 225 219 225 205 259 235 230 223 208 217 227 220 243 216 216 245 202 231 211 213 199 244 212 229 238 189 230 249 222 216 236 209 223 256 235 238 237 213 218 226 248 211 231 265 235 228 261 211 269 229 228 235 270 231 225 237 268 227 212 257 233 234 248 242 242 246 237 238 257 236 255 244 261 244 290 265 260 261 266 250 260 268 240 265 261 246 261 256 261 259 274 264 278 276 279 284 292 272 282 294 309 281 331 312 297 333 330 328 350 305 333 340 325 354 388 377 372 344 361 341 372 401 374 395 358 419 427 348 395 343 367 358 339 334 354 379 342 349 333 301 316 320 330 299 290 277 270 289 262 266 275 247 245 262 239 235 255 223 249 234 258 255 273 260 224 226 232 261 255 227 237 257 234 230 261 245 206 235 235 259 224 245 231 239 207 227 221 232 249 229 231 230 232 204 236 269 218 213 220 231 213 234 234 217 219 214 233 245 227 230 225 238 215 236 240 239 205 233 209 206 266 225 242 223 227 224 213 207 210 256 230 241 212 241 224 213 209 199 222 266 214 243 237 197 222 224 229 210 231 219 241 218 197 227 232 219 208 227 234 226 238 257 214 235 211 204 236 241 217 257 240 217 225 248 215 207 187 233 211 213 220 229 208 215 268 230 232 238 218 186 223 208 219 229 199 242 213 241 228 227 237 261 249 210 229 226 218 226 235 249 190 224 249 249 291 226 245 207 225 226 221 203 226 246 233 181 219 216 201 216 230 207 226 274 234 213 245 236 246 229 214 240 212 226 237 242 207 233 231 231 235 257 228 236 213 200 245 222 223 222 219 209 238 249 223 216 219 222 215 229 232 239 223 210 246 223 223 213 228 183 219 231 215 209 230 230 245 215 224 207 213 247 220 208 215 227 235 220 232 245 225 248 222 220 272 227 199 255 185 264 223 224 224 256 218 240 229 217 255 207 218 221 224 227 247 202 186 231 242 224 228 219 203 225 227 220 236 234 203 211 271 226 248 247 241 217 209 233 207 185 210 196 224 216 211 236 270 240 205 214 216 245 229 225 214 214 233 242 243 244 257 221 267 235 221 243 243 227 235 228 225 227 214 238 246 221 205 208 208 230 236 228 226 247 214 224 231 213 223 230 209 247 212 208 229 208 245 223 195 211 249 233 231 210 203 236 219 240 212 240 196 208 240 195 227 228 205 219 219 213 211 214 227 244 247 227 224 220 257 231 227 209 234 211 239 209 229 247 241 226 238 226 246 245 208 246 190 225 226 222 224 245 234 201 223 219 215 239 255 213 242 228 241 225 226 219 225 215 216 240 241 198 235 209 224 231 266 212 221 237 242 218 214 205 248 223 228 220 210 221 209 217 240 242 219 226 219 236 227 229 227 241 225 230 223 216 216 231 222 217 232 229 228 245 200 237 226 213 217 229 248 220 215 200 229 233 250 205 230 182 241 243 225 221 227 228 278 219 225 209 227 228 224 232 234 224 215 237 240 215 217 212 220 214 207 246 218 222 225 214 207 199 221 248 243 218 224 207 239 237 224 259 259 215 234 231 229 243 229 226 228 244 221 210 221 216 211 215 222 223 219 227 191 219 204 222 221 248 213 189 230 218 226 233 211 221 232 224 203 256 229 231 235 220 228 258 247 221 238 220 224 238 225 211 232 233 221 226 222 232 210 247 240 195 224 236 238 205 224 227 219 233 230 198 208 245 247 242 213 234 238 228 231 255 240 206 227 193 233 245 228 227 223 226 188 208 227 244 227 226 227 216 233 221 230 240 241 234 228 222 239 229 226 222 212 237 209 194 217 207 247 248 205 234 245 256 249 231 245 238 218 214 226 235 211 237 217 237 198 248 215 229 230 229 217 241 230 220 234 247 235 236 225 213 242 233 203 210 196 245 211 246 230 190 220 246 261 223 219 216 217 238 220 258 231 210 227 242 214 223 232 239 234 262 266 240 223 263 208 236 235 231 212 235 248 230 230 228 214 217 240 230 222 218 211 210 233 246 230 186 228 203 236 216 221 189 223 249 210 233 202 242 233 215 237 207 227 237 213 226 210 256 219 231 233 247 201 223 220 214 243 229 239 191 234 223 232 243 209 195 233 224 193 214 221 236 226 232 237 239 218 182 237 226 237 244 266 198 229 265 240 226 220 232 246 229 225 218 232 213 240 228 231 226 216 233 225 230 232 223 228 218 221 239 231 200 215 218 244 226 229 243 216 228 212 233 220 209 210 240 259 257 230 204 238 227 218 234 205 223 249 226 234 234 234 237 221 223 236 243 245 227 237 227 203 237 218 218 272 237 231 228 188 217 255 214 232 232 200 236 228 248 188 215 210 233 212 243 232 244 220 219 229 199 208 214 235 258 218 266 211 240 232 217 236 207 222 232 223 242 222 207 212 202 260 240 220 233 256 227 225 245 210 216 220 230 239 239 240 250 234 230 212 271 242 243 215 232 224 218 218 217 218 241 221 204 238 232 225 256 228 212 207 215 224 268 230 240 237 212 218 224 225 256 228 233 211 242 232 230 208 224 209 230 210 276 213 235 230 220 229 215 264 223 219 213 209 232 245 241 239 246 245 228 241 195 214 227 221 239 217 227 231 234 236 223 222 194 210 224 198 236 189 214 239 208 240 232 234 230 239 203 239 229 227 237 214 213 217 207 224 249 250 202 224 230 232 218 214 228 232 223 219 231 208 219 249 211 219 230 202 240 240 207 218 241 225 238 229 233 210 232 222 238 214 229 241 215 243 232 229 211 218 218 228 226 211 244 257 213 223 238 217 230 222 256 234 227 216 224 232 270 218 247 220 198 249 220 235 220 224 227 218 218 224 205 222 220 232 213 236 213 225 209 215 239 207 262 209 247 235 223 207 248 226 249 194 229 229 211 238 215 245 240 195 235 232 256 246 228 234 232 229 224 222 223 212 206 232 236 210 239 246 214 261 226 225 207 230 265 221 249 246 273 235 224 224 202 230 230 194 231 238 274 214 218 260 228 229 256 237 263 259 237 214 216 234 249 233 233 219 232 233 226 247 231 227 220 232 223 208 223 209 196 230 232 241 261 196 239 229 240 224 247 214 241 236 208 234 220 234 237 274 238 257 201 235 238 237 221 211 228 242 259 212 207 224 240 230 224 226 247 211 237 228 248 243 238 235 225 244 212 233 208 220 233 239 248 211 237 237 245 225 240 227 211 225 230 222 237 238 262 212 237 211 216 229 230 212 262 220 228 244 240 229 203 226 227 234 208 231 238 227 264 255 229 225 235 216 213 257 239 221 243 231 214 229 258 205 213 207 230 233 233 225 236 236 225 241 226 223 228 207 245 227 233 221 199 231 260 206 214 215 206 206 220 236 226 222 228 230 223 223 237 247 196 225 234 203 247 218 229 247 238 233 221 229 209 222 239 212 235 220 230 221 234 238 233 219 213 229 232 228 218 258 239 244 249 248 217 259 226 246 243 225 256 249 225 229 217 238 244 239 208 213 219 211 226 215 234 235 237 242 273 232 230 230 235 250 210 197 233 218 245 238 256 225 202 207 228 228 228 233 217 267 233 232 240 220 222 250 241 229 228 217 262 239 243 232 217 225 237 213 215 224 232 231 264 212 240 244 230 239 246 223 239 244 235 213 222 232 244 211 201 248 243 250 230 237 265 231 281 237 263 240 234 210 215 258 223 219 243 257 214 259 232 221 226 227 235 223 229 207 235 242 249 209 229 226 232 210 245 241 238 232 231 232 247 255 243 262 241 239 206 247 247 244 238 228 241 243 209 231 240 235 238 212 229 234 223 214 231 238 233 230 268 258 237 227 255 222 244 245 211 234 246 199 271 237 255 229 219 224 233 244 242 226 257 224 259 236 242 231 227 222 203 222 196 259 242 238 232 245 227 266 231 243 246 258 216 220 215 235 220 216 210 222 244 206 273 257 272 226 226 238 247 245 207 249 244 240 247 242 228 237 220 226 235 230 223 246 218 221 214 263 247 229 223 244 225 224 206 233 266 209 198 255 221 207 243 222 255 221 228 213 200 237 224 229 247 243 230 232 260 225 212 243 222 222 233 261 241 188 245 222 231 249 238 246 224 206 217 248 230 228 232 247 236 273 226 260 228 238 237 234 216 219 255 217 224 232 209 255 246 246 207 230 240 212 232 256 233 221 222 261 215 218 238 240 240 246 237 200 228 248 241 217 238 247 224 233 241 217 233 214 245 225 221 227 244 201 231 261 210 231 235 226 234 244 220 229 238 207 219 264 245 234 242 246 240 239 248 237 258 256 244 211 245 229 230 261 206 228 221 216 240 209 234 216 243 243 228 241 235 236 242 247 243 258 242 268 242 264 209 240 225 225 227 218 233 210 258 245 225 257 230 266 257 247 244 248 242 227 230 247 208 246 235 206 245 207 196 246 270 246 239 231 264 231 227 226 226 238 281 274 232 234 209 225 256 244 231 226 240 220 233 233 225 258 234 271 240 215 217 237 231 272 237 245 262 230 220 223 224 217 205 255 256 208 275 224 244 241 237 232 228 240 211 258 229 225 244 233 241 235 234 234 216 229 237 227 247 235 237 230 225 236 210 234 258 214 220 262 241 223 221 231 238 202 225 247 257 218 243 231 261 219 233 231 235 245 213 236 207 227 219 219 210 217 235 210 238 235 222 209 246 240 215 255 200 228 263 197 234 227 184 227 232 238 220 225 230 213 225 235 226 258 236 218 238 209 232 267 239 215 266 232 226 201 238 234 212 223 263 243 226 230 231 270 229 259 243 238 247 209 235 255 211 227 255 237 234 229 221 240 246 267 249 235 239 222 243 262 235 215 228 259 241 242 234 242 245 258 233 259 238 264 214 236 259 242 223 217 222 236 239 223 234 247 248 235 250 264 269 230 239 284 277 271 264 242 258 227 261 246 273 236 233 264 249 259 258 273 230 235 256 271 230 243 238 249 269 239 233 242 256 257 242 225 233 221 238 249 256 237 214 262 284 276 227 275 260 248 278 236 243 217 228 240 246 229 239 273 229 273 260 257 279 285 266 274 237 255 235 257 242 213 212 275 244 240 244 227 262 241 255 248 263 220 262 268 239 243 237 225 226 231 239 230 235 240 221 238 238 222 255 226 255 268 249 250 240 261 246 207 244 257 218 223 244 247 247 246 261 231 246 272 247 232 263 241 233 243 216 238 210 246 255 244 258 276 223 218 226 248 238 214 272 249 264 271 230 257 206 255 215 257 237 217 277 246 226 227 237 228 224 227 213 231 262 250 266 243 258 263 235 244 244 221 243 247 239 244 240 234 249 217 248 259 224 241 279 236 257 242 233 228 234 208 226 266 268 231 216 231 263 255 234 258 247 241 239 226 219 261 260 247 248 248 247 262 264 212 222 250 245 275 229 274 232 268 246 266 247 218 233 264 240 210 223 265 260 258 236 260 245 229 228 217 235 222 226 234 233 263 219 267 231 230 238 237 240 244 230 239 243 255 242 207 239 286 270 256 265 255 229 236 225 257 235 217 247 233 243 261 259 248 255 270 226 231 217 236 264 240 210 258 232 276 239 245 259 246 214 244 233 230 220 273 272 247 238 239 240 275 255 276 237 242 233 219 276 230 224 223 244 242 216 256 236 227 225 220 223 246 237 231 233 206 247 232 223 223 263 260 214 249 237 277 272 240 231 229 224 231 260 233 225 258 230 245 232 221 234 218 266 258 279 239 231 236 233 244 230 264 223 258 243 245 245 204 270 267 237 229 268 225 233 236 226 265 235 238 242 246 220 233 232 240 213 235 223 276 235 278 229 245 240 263 271 273 237 234 220 267 221 232 242 212 243 232 246 248 224 248 288 221 234 257 200 218 256 239 236 266 235 264 279 237 238 236 230 264 242 221 245 217 241 244 230 239 207 259 219 248 245 240 218 223 234 206 227 266 241 255 247 258 240 245 247 269 249 256 271 255 235 269 214 246 259 227 243 238 247 233 228 255 245 235 229 238 246 208 236 269 244 243 238 239 265 235 232 246 240 284 240 255 207 241 263 260 235 241 238 235 248 238 241 263 233 240 267 222 229 249 270 268 231 255 248 261 220 235 263 245 240 233 229 256 231 238 238 215 242 219 247 255 263 231 232 222 248 242 219 236 257 245 274 273 262 244 255 240 249 235 227 265 232 246 237 243 240 243 249 220 248 266 244 262 241 236 242 239 235 241 240 196 258 240 263 257 230 236 247 226 223 258 219 242 211 271 240 259 217 236 234 232 249 263 264 231 235 213 267 260 247 216 232 244 241 265 227 235 204 234 224 237 220 269 207 243 245 245 244 224 218 249 234 218 237 219 226 262 234 258 205 236 233 234 261 243 238 247 238 235 238 258 242 226 255 260 245 259 248 248 239 241 226 233 266 222 245 234 274 264 236 268 249 233 233 241 241 246 247 230 238 232 246 220 223 239 217 276 232 268 230 235 227 246 246 232 257 263 231 255 237 237 217 242 210 209 219 230 262 248 229 236 233 250 230 202 243 237 286 227 217 227 255 248 237 230 245 234 257 246 241 245 292 236 214 262 242 207 224 218 266 246 230 226 233 267 235 241 243 244 270 243 213 245 273 226 232 237 263 273 227 266 242 226 236 223 229 238 266 245 230 246 232 233 260 267 266 257 264 267 248 213 243 198 243 229 227 240 226 245 267 234 261 246 246 239 206 242 257 245 238 235 205 237 231 230 245 206 231 226 227 237 235 247 257 248 242 245 225 235 225 256 231 239 266 214 257 224 231 228 211 248 240 223 232 231 268 242 230 257 256 264 257 255 270 234 243 268 258 234 241 260 209 227 245 248 258 209 249 229 261 243 227 208 265 261 229 228 234 231 256 242 240 247 221 245 224 228 264 260 228 226 244 244 228 255 235 261 242 257 213 261 228 255 225 241 249 255 242 224 222 242 222 240 258 286 236 238 238 262 242 239 235 249 225 188 210 243 240 234 261 233 224 248 240 264 271 225 270 260 222 224 244 215 243 276 245 261 242 274 237 255 239 255 221 284 232 262 234 210 219 239 233 256 271 246 263 229 240 218 243 243 249 231 263 237 256 245 232 255 237 227 250 222 259 217 245 230 233 241 256 258 272 248 242 263 270 269 235 225 231 247 219 272 255 237 257 238 274 222 238 249 239 234 239 223 235 238 282 243 265 261 277 232 257 268 241 226 238 242 239 259 258 244 220 240 257 220 262 235 236 260 270 268 261 282 213 243 241 222 249 258 245 271 229 271 244 224 241 241 276 220 234 260 246 247 227 243 242 249 222 236 235 250 265 248 241 262 244 242 247 290 237 272 261 248 237 207 230 235 281 234 259 216 239 235 241 263 258 240 278 249 236 256 246 241 238 248 258 221 237 239 256 220 214 233 219 225 242 268 231 218 229 274 260 229 213 239 262 219 215 245 221 228 235 248 224 243 241 273 216 231 204 227 266 243 236 232 256 261 228 242 258 219 235 227 218 235 228 273 246 234 268 247 283 263 246 277 240 266 285 256 228 282 258 243 236 234 275 227 269 249 238 243 264 246 257 249 236 217 234 229 248 255 250 227 207 225 248 232 267 224 238 249 246 262 269 227 222 229 235 260 268 244 261 256 259 236 237 260 241 244 258 213 243 220 233 240 246 244 244 262 241 227 231 231 259 229 238 250 226 256 256 248 231 235 240 235 276 247 236 206 273 248 235 245 257 234 260 266 235 261 247 266 244 272 264 260 237 239 207 237 273 235 258 229 221 232 248 226 229 246 288 234 257 222 271 223 241 293 257 261 246 264 223 263 242 270 244 245 278 229 234 243 265 258 233 238 234 246 242 245 232 294 194 222 219 217 258 242 234 232 221 239 255 216 270 258 244 271 232 231 231 262 288 228 241 249 264 241 230 260 236 264 234 242 281 248 279 257 262 255 244 245 264 229 233 245 255 259 247 230 266 239 236 263 236 255 249 243 245 229 257 224 260 256 207 263 213 243 241 243 207 264 257 242 217 240 246 265 213 232 219 246 256 225 237 237 234 220 218 235 271 241 229 247 249 264 276 244 244 258 227 274 242 243 247 267 237 243 278 239 256 238 219 279 260 233 238 243 247 237 236 278 243 225 242 239 293 275 245 257 261 258 214 232 226 256 268 238 242 237 249 233 240 235 209 223 211 247 222 260 272 270 233 233 257 258 256 216 239 283 273 244 227 265 257 241 265 228 232 243 220 214 232 264 247 237 260 243 205 239 240 231 236 234 226 236 250 211 258 255 229 234 242 241 245 255 226 243 241 267 270 285 239 265 267 247 239 258 286 235 204 229 256 246 296 247 228 242 273 243 237 237 232 257 261 267 275 226 238 280 242 262 214 263 266 246 265 230 228 245 245 272 259 282 243 227 202 244 271 282 248 258 219 266 225 241 265 273 223 237 213 245 255 233 230 226 226 257 282 219 272 229 258 232 256 248 241 226 266 236 224 241 244 236 227 260 265 238 270 223 229 231 242 277 262 193 221 260 256 276 249 273 248 241 263 230 217 243 245 267 261 262 233 240 249 241 256 223 231 239 227 237 234 273 246 238 261 239 277 224 243 279 258 219 240 233 247 232 262 233 274 261 224 241 232 293 249 264 224 232 229 239 241 271 227 213 216 282 233 256 246 240 237 260 235 272 242 260 281 260 258 226 264 256 213 259 232 236 269 237 267 245 222 264 228 267 262 228 258 223 269 234 236 230 243 244 234 266 241 247 248 267 250 246 237 267 262 230 257 281 235 241 240 256 294 274 234 217 240 256 278 286 243 234 245 262 248 244 247 242 243 257 278 233 255 243 249 239 246 270 270 258 256 240 247 249 267 275 279 275 248 256 269 297 262 268 262 287 285 273 291 249 300 241 282 264 255 281 262 260 249 267 262 287 280 275 282 285 284 313 291 320 291 302 260 267 294 313 292 243 263 285 262 267 267 257 268 274 270 250 264 287 296 274 292 270 308 275 262 256 262 249 259 304 276 290 275 260 233 235 312 233 295 259 224 275 243 255 280 244 266 275 269 226 278 212 263 279 242 241 256 250 240 239 245 258 257 222 269 259 268 255 284 261 243 233 278 241 247 263 258 250 258 270 258 246 239 245 234 230 255 240 220 235 239 207 285 243 235 216 261 233 236 266 228 258 238 215 259 261 231 243 257 260 233 245 244 239 232 264 225 247 239 245 236 247 236 222 216 244 256 222 250 246 225 248 243 225 223 229 228 227 247 261 238 241 229 240 247 277 257 233 216 259 239 217 272 234 237 246 226 277 231 256 232 241 265 274 257 265 231 214 230 223 238 226 228 217 212 230 258 245 227 256 220 249 238 232 235 240 241 239 222 263 245 208 261 242 242 236 222 224 239 225 215 229 240 236 267 244 248 210 245 246 256 240 244 275 229 209 231 209 238 223 222 244 266 236 215 235 262 255 228 259 234 225 241 219 229 249 237 204 262 217 238 213 221 271 241 247 236 225 242 221 229 234 256 259 212 217 241 234 230 245 232 230 270 227 234 230 231 219 247 245 249 236 211 261 239 246 257 233 202 216 247 234 266 229 230 231 256 278 224 224 245 267 244 255 218 229 221 227 258 269 218 222 230 247 242 264 213 236 210 218 224 245 265 258 235 230 225 233 231 227 207 229 231 246 247 243 274 218 262 233 217 248 248 228 261 238 222 237 256 214 225 257 233 255 236 245 236 227 241 209 262 233 229 227 209 230 255 269 248 258 261 265 223 222 247 237 270 233 230 234 238 222 255 243 240 242 233 231 242 256 233 241 236 221 229 261 265 219 222 231 228 238 231 202 230 206 240 244 261 217 233 244 259 261 225 222 237 228 249 244 225 234 240 236 248 233 228 240 219 207 235 236 246 230 231 234 236 195 227 227 219 218 238 217 272 280 247 255 256 249 257 211 230 239 219 217 233 237 235 267 234 221 238 220 244 241 256 224 216 279 219 267 245 242 210 224 226 229 258 248 237 228 228 267 226 236 238 225 225 243 267 239 238 247 257 264 231 286 241 225 221 216 255 235 264 259 230 234 263 209 217 234 222 259 233 250 240 235 239 244 229 256 228 222 227 261 260 239 210 230 233 266 241 275 195 258 236 218 260 284 236 231 222 237 245 239 209 232 248 262 249 239 231 224 240 216 213 235 215 234 219 244 244 246 239 249 241 207 228 230 241 263 239 256 221 246 231 216 238 224 221 225 239 227 240 267 223 223 246 211 227 214 239 230 263 233 233 238 229 225 230 245 243 255 232 213 212 255 199 203 207 220 212 237 229 264 229 226 232 244 244 224 230 229 242 261 217 221 246 257 243 248 224 234 228 221 263 239 227 238 227 212 208 226 217 244 216 257 222 204 248 262 210 242 250 225 210 242 232 256 223 240 232 249 208 229 213 247 230 242 231 232 270 232 263 218 226 217 230 237 235 262 225 246 205 229 236 240 250 264 239 238 207 228 263 215 221 230 234 242 264 248 262 224 242 234 223 241 267 244 268 235 241 245 238 234 258 232 245 244 257 219 235 246 244 246 245 209 293 281 235 229 243 214 258 240 226 219 212 237 237 224 248 234 230 234 221 240 227 264 218 233 191 217 226 247 264 209 244 256 255 266 241 200 255 209 230 225 236 202 235 261 241 221 235 237 246 256 222 235 232 247 220 224 228 219 224 240 249 238 280 222 196 262 207 242 224 221 220 255 245 273 233 256 230 231 220 236 221 239 214 249 223 229 236 236 243 238 256 221 257 227 241 257 238 267 256 249 220 212 235 224 267 219 248 265 218 257 235 232 217 224 205 241 228 226 222 235 221 241 228 267 233 213 219 246 228 229 237 224 258 233 239 256 263 220 257 241 248 238 236 240 227 245 249 235 257 247 231 215 232 219 232 232 257 238 240 256 263 228 237 278 212 202 240 232 223 248 237 238 217 295 245 242 220 215 238 225 230 219 240 233 223 248 235 238 225 231 241 263 233 210 243 220 234 241 209 214 201 255 217 228 229 244 247 244 241 215 229 229 258 227 228 245 256 233 267 228 257 258 213 236 262 228 243 257 231 193 240 208 249 256 210 250 237 225 220 213 218 233 228 232 267 231 230 217 223 223 232 256 208 243 221 217 207 247 227 236 247 240 257 206 231 249 215 231 241 227 228 192 236 244 238 222 240 244 236 223 227 249 234 242 220 241 256 275 220 244 261 232 211 256 230 233 241 268 205 225 213 231 218 226 229 235 225 248 247 236 226 237 237 249 241 258 222 244 259 246 258 255 236 263 230 281 260 249 240 247 217 229 217 207 244 221 243 225 231 247 224 232 260 268 270 222 225 222 215 239 245 221 234 241 209 231 224 234 219 223 255 210 217 215 239 230 248 233 271 240 259 273 265 234 238 247 238 260 244 267 240 218 213 242 255 250 262 233 233 232 234 230 212 228 233 225 249 277 215 218 261 219 224 240 235 230 246 214 258 261 227 233 242 232 210 205 219 258 246 229 235 214 242 240 217 246 221 242 227 249 257 229 243 225 229 268 264 234 241 205 259 225 232 245 235 209 224 239 234 236 231 265 246 237 232 258 248 215 240 200 220 208 248 244 223 243 244 234 235 217 232 257 233 228 231 260 235 213 231 245 282 258 225 255 257 237 219 237 231 261 259 244 230 222 247 243 238 232 225 245 225 273 243 241 233 234 262 229 219 227 237 247 233 233 237 237 220 238 244 230 256 245 230 257 222 245 217 271 244 204 219 201 224 236 228 271 237 223 242 265 229 242 247 259 215 222 219 270 218 215 248 247 246 213 236 214 243 232 260 233 237 231 228 237 228 229 224 226 227 239 209 259 230 261 211 237 255 232 243 243 260 226 213 225 241 244 213 226 198 228 242 244 249 239 203 218 244 260 262 219 222 246 236 258 244 187 232 227 247 271 216 235 235 218 238 235 202 247 212 221 245 234 241 219 258 217 246 243 217 224 207 216 233 249 217 240 198 235 215 215 226 203 228 216 245 217 239 246 222 226 214 260 229 224 234 268 219 213 227 212 223 227 232 216 224 243 236 260 231 237 232 267 243 248 201 245 236 283 234 228 236 208 238 265 235 249 242 230 219 256 226 210 207 230 237 205 257 220 233 238 238 224 243 222 196 228 230 237 240 209 240 237 249 273 229 248 217 222 273 214 260 237 230 227 207 225 238 234 231 225 230 233 218 272 241 210 276 241 250 214 243 206 242 257 239 231 206 241 242 242 227 230 242 229 233 224 237 239 247 239 245 260 224 218 216 219 217 202 257 216 234 221 236 249 245 221 227 244 239 227 213 228 216 245 243 245 232 226 219 262 275 228 228 242 237 237 226 242 218 209 229 245 234 231 242 237 234 236 218 236 232 229 220 225 244 234 222 263 231 215 208 231 219 231 258 211 242 229 233 248 244 242 217 265 217 230 265 203 217 226 225 237 258 208 215 239 242 237 219 240 211 228 231 232 245 236 234 247 257 228 244 260 216 238 240 241 238 236 227 225 213 232 255 211 198 232 241 221 237 217 236 248 240 223 239 229 245 219 197 250 228 268 258 231 241 238 257 243 256 239 212 229 244 240 241 264 246 221 260 280 244 262 229 218 232 234 228 231 255 245 222 238 234 243 246 225 245 250 242 230 277 256 238 276 255 233 235 227 248 243 233 256 241 233 258 273 276 231 232 204 221 222 266 230 224 237 248 228 221 242 232 241 238 273 256 248 205 228 241 243 247 242 248 280 265 259 245 204 249 261 237 245 223 238 262 200 224 245 233 255 245 248 255 247 264 221 264 277 255 266 209 258 241 229 266 215 246 271 259 241 259 219 263 223 245 236 262 247 266 235 249 232 241 221 229 261 206 230 244 256 261 246 228 209 240 235 256 209 206 220 244 269 232 242 226 234 257 258 206 229 237 217 201 244 237 226 206 238 267 280 235 262 238 258 241 223 225 261 227 216 229 235 233 259 211 247 231 239 243 228 232 208 223 245 242 220 222 248 248 231 264 240 243 237 244 256 228 228 229 255 212 241 239 257 249 226 249 239 231 221 263 218 236 289 257 248 236 226 242 222 220 225 233 234 216 233 231 230 246 226 232 255 230 237 226 240 271 247 226 261 233 233 244 244 256 228 236 225 218 208 221 260 228 227 244 239 263 266 241 236 224 233 215 278 234 224 240 216 219 245 229 247 209 213 229 238 216 218 248 231 229 229 248 244 258 240 229 262 198 234 188 242 233 229 212 236 218 229 228 228 258 224 220 215 274 242 242 238 241 240 257 242 202 229 233 226 194 220 201 239 227 229 226 237 241 248 228 234 224 240 227 220 228 229 233 234 267 241 218 230 229 249 243 242 220 204 234 216 224 244 247 222 231 256 211 241 248 219 224 242 255 228 242 219 228 259 222 214 228 247 222 225 205 247 232 244 227 222 225 211 266 227 242 231 217 211 265 233 226 227 249 213 222 238 230 249 219 229 249 238 238 231 231 235 231 205 224 272 246 234 243 245 236 205 243 234 266 250 239 195 248 232 243 255 240 239 223 226 228 240 227 245 223 227 256 244 232 241 224 264 236 225 226 228 270 243 232 250 271 233 239 239 213 223 247 217 212 236 225 264 241 247 241 266 233 268 249 241 221 227 210 225 221 270 224 243 269 216 220 230 241 214 207 229 242 231 234 260 224 229 242 232 235 230 245 256 238 220 249 236 247 245 217 225 249 247 228 238 301 218 227 244 230 233 226 241 220 223 242 239 236 211 236 273 202 223 226 236 240 216 232 228 236 225 224 232 231 220 236 223 237 225 236 211 248 239 208 228 217 217 238 212 256 236 265 217 265 264 237 246 256 209 222 222 209 260 227 223 243 262 243 207 223 204 228 214 240 199 233 219 230 256 245 237 236 238 258 229 239 233 246 240 229 260 242 210 257 258 246 217 220 219 201 243 220 211 208 246 232 246 228 242 235 206 217 218 218 224 239 224 232 264 238 224 235 243 224 255 219 256 218 214 217 222 225 213 227 234 241 228 217 236 247 234 241 239 240 232 263 237 223 272 264 232 229 222 248 220 241 240 237 240 233 228 230 266 206 233 213 265 221 200 231 229 229 236 269 248 220 211 257 214 219 223 221 231 196 235 223 244 242 221 212 237 206 222 229 231 259 265 228 218 227 241 238 234 246 229 233 231 267 233 235 247 266 238 236 229 245 229 240 210 219 227 250 228 223 237 230 224 208 217 185 223 219 241 226 203 228 214 246 238 227 257 228 229 227 229 231 216 229 213 208 258 208 249 218 232 257 229 224 208 222 207 257 233 259 224 222 202 211 232 245 241 264 247 233 219 216 239 235 231 201 258 196 220 221 231 231 259 212 261 221 235 270 216 256 243 238 220 237 216 257 264 239 216 203 205 222 219 266 235 225 226 245 266 264 245 214 225 218 206 242 235 218 244 236 235 199 205 235 274 206 210 226 246 233 231 220 228 241 218 217 232 228 229 204 239 226 274 199 227 238 237 244 208 214 246 227 207 224 228 229 259 235 244 244 223 221 234 247 231 220 213 218 213 224 197 241 230 213 255 188 221 267 214 227 211 230 230 259 248 257 227 255 210 232 198 214 219 230 220 228 203 221 212 213 239 227 219 218 206 236 244 247 224 223 227 233 224 217 236 236 226 229 228 227 229 231 217 215 199 221 208 218 216 225 222 250 208 218 234 207 219 211 212 236 223 225 222 237 208 247 229 204 221 230 222 230 220 222 246 230 241 212 215 210 222 223 208 255 229 230 243 234 228 224 201 259 218 223 227 204 235 230 239 213 267 210 209 211 237 228 245 213 233 232 233 223 232 226 189 208 230 217 212 222 236 228 209 224 228 230 235 233 220 220 245 213 232 229 236 200 256 224 211 196 236 223 219 248 205 249 266 220 217 207 228 235 199 223 202 235 207 231 216 226 229 264 245 219 190 201 256 238 202 219 224 219 234 234 193 216 232 234 198 241 215 222 249 247 239 213 210 223 213 217 235 197 260 222 200 239 231 205 258 199 225 215 238 213 216 231 242 219 225 220 220 249 231 244 228 210 212 177 215 227 229 224 193 228 208 189 215 232 232 224 222 221 220 229 231 197 228 209 208 219 204 231 221 213 236 212 229 228 201 215 241 206 213 249 233 233 239 224 226 229 228 257 225 242 209 212 212 227 235 222 219 214 230 197 225 205 257 225 233 229 224 255 212 237 257 235 211 198 225 237 227 233 200 219 201 264 232 248 198 231 223 218 218 280 239 221 222 232 223 220 238 232 223 260 213 218 233 211 218 211 194 262 221 247 224 232 207 235 230 229 224 243 221 244 233 233 223 261 208 238 212 228 259 233 237 230 263 225 233 210 234 244 240 237 234 207 212 213 278 206 259 234 235 216 223 240 276 224 205 235 247 238 246 225 204 277 211 258 190 234 226 180 204 224 231 240 224 231 241 225 245 213 219 231 217 223 213 238 255 238 239 231 216 218 213 225 233 208 239 235 247 247 198 260 229 208 245 249 246 219 225 218 233 239 221 224 211 232 223 209 256 238 223 232 228 196 215 228 222 229 214 235 227 220 225 204 223 215 219 210 218 221 250 250 196 232 232 241 209 248 241 197 257 229 194 234 221 243 246 195 237 242 230 223 243 224 244 234 239 243 233 240 244 231 243 200 222 229 208 235 225 215 232 232 233 223 227 246 231 221 226 226 202 233 227 213 231 206 243 228 244 230 228 242 207 216 241 219 228 221 221 232 230 224 195 216 235 243 215 226 225 204 219 228 244 219 211 235 233 244 208 249 216 229 226 245 219 236 234 237 241 237 215 226 219 223 210 229 248 230 229 220 238 235 229 227 238 224 265 236 203 210 204 241 240 221 226 230 243 234 223 235 227 272 237 226 224 215 225 236 244 224 224 223 223 216 239 249 203 220 233 234 231 235 226 220 188 249 214 218 245 193 206 217 215 208 239 238 221 228 229 234 227 248 229 206 224 256 203 205 236 236 209 234 233 227 214 221 193 218 255 229 222 228 237 190 216 247 211 229 198 226 222 225 209 202 211 212 219 242 210 227 200 201 228 258 219 222 224 232 221 228 233 236 208 232 223 207 214 226 238 230 230 244 211 224 207 242 267 217 223 235 208 262 221 224 265 274 222 207 230 219 218 239 225 204 224 234 263 207 247 214 190 218 211 270 226 220 249 227 211 220 226 217 225 233 224 226 212 230 230 229 227 234 238 219 229 205 216 238 256 243 217 227 263 248 221 243 206 237 214 229 207 210 238 231 230 227 205 216 213 219 202 212 211 192 231 233 228 267 223 208 242 234 232 238 231 236 232 195 208 214 237 255 220 231 215 214 241 212 225 215 238 280 224 228 233 203 241 218 218 224 222 216 205 229 222 216 227 266 237 218 208 235 200 215 223 227 241 199 216 220 212 236 208 209 237 210 245 229 215 225 212 232 218 213 236 247 236 245 234 237 233 233 242 220 227 260 247 238 218 222 205 229 231 234 216 229 248 213 240 246 237 241 238 236 221 236 224 205 238 233 235 258 227 264 220 203 201 207 226 227 239 225 220 249 233 225 229 242 231 248 218 255 242 236 221 249 242 246 261 235 236 261 208 235 226 268 245 210 228 224 233 241 236 240 260 223 232 231 255 230 223 243 221 217 233 242 222 237 217 233 260 223 229 224 258 207 264 237 230 229 240 266 234 243 259 209 230 263 220 216 240 216 239 230 265 225 229 246 247 238 215 232 276 244 237 270 223 229 222 246 247 217 210 210 238 277 207 226 214 239 215 271 246 220 229 239 244 248 204 230 229 239 245 230 233 260 242 245 244 240 240 213 222 211 223 222 221 209 238 219 241 240 265 232 228 258 248 233 267 241 224 208 225 224 227 240 224 260 264 233 243 241 240 217 250 212 222 245 214 245 224 222 236 228 212 228 260 228 258 235 243 236 229 212 225 228 209 247 242 264 232 202 235 232 245 240 233 240 250 222 202 246 218 240 247 242 227 221 237 217 239 191 218 231 210 241 248 232 215 250 229 227 230 220 247 241 219 240 227 230 235 230 259 228 236 209 206 241 199 220 208 227 233 216 239 209 216 208 234 229 226 233 232 232 226 262 249 216 232 256 198 227 227 239 208 233 245 236 239 235 231 264 191 241 228 228 236 237 216 216 208 202 248 241 226 216 218 238 209 246 231 237 223 200 236 217 205 215 224 225 240 205 231 214 220 240 245 210 207 216 239 241 229 238 208 218 230 216 222 215 226 214 231 229 233 211 220 232 221 223 225 231 221 205 203 214 207 174 248 213 240 217 210 246 222 233 238 225 215 197 211 220 204 190 220 211 206 236 234 221 243 211 200 243 244 233 235 199 227 219 227 236 221 248 236 224 237 188 212 245 209 190 193 255 221 214 212 246 240 227 223 230 221 233 235 232 231 235 219 226 222 231 227 206 215 231 239 222 220 230 224 218 208 226 201 230 229 224 212 225 211 214 230 247 208 225 213 227 194 244 227 200 221 240 215 215 224 216 238 232 218 230 228 229 225 235 228 237 205 219 248 222 211 248 207 233 213 228 227 243 212 244 215 245 213 201 235 231 209 225 237 242 227 236 228 201 222 218 194 209 237 247 248 196 234 232 219 238 240 250 226 213 211 217 213 234 196 218 211 245 199 242 236 238 199 236 233 217 212 219 244 220 220 215 229 223 220 207 236 232 228 247 228 220 228 233 225 215 188 230 226 224 199 265 196 246 216 234 245 246 208 205 223 262 226 220 246 211 196 218 239 212 181 204 249 192 210 243 243 243 245 227 226 239 222 213 234 198 221 248 220 217 260 219 221 243 223 209 237 255 203 229 215 222 219 231 229 230 219 211 220 244 241 217 257 206 214 260 216 220 215 214 244 208 208 208 236 237 223 226 248 229 249 216 220 206 211 281 221 248 210 227 233 260 213 208 217 227 257 230 257 216 235 231 202 233 224 228 241 219 255 197 214 227 226 227 239 241 199 234 207 207 231 237 209 225 232 194 256 227 243 230 210 201 210 232 203 190 248 208 238 227 237 215 209 226 236 241 234 229 210 212 224 237 216 239 234 224 225 242 224 220 229 208 201 227 197 222 232 189 223 188 209 221 230 227 196 228 215 233 261 210 220 213 243 214 232 220 265 248 220 233 217 227 259 248 219 209 224 228 230 236 209 227 222 218 205 214 234 201 202 236 234 205 218 231 248 238 242 208 222 237 217 222 217 229 199 241 216 234 227 220 212 243 233 245 260 216 209 221 222 221 215 178 223 212 220 214 231 225 220 212 236 196 217 244 206 202 202 245 211 212 201 204 197 226 206 213 216 214 239 208 216 232 227 202 247 244 226 226 203 221 230 229 243 224 215 208 234 226 239 223 233 220 231 206 212 203 209 208 217 225 231 204 219 227 218 201 213 209 240 210 259 242 226 207 222 249 227 193 217 217 238 205 211 215 241 215 208 256 217 224 216 232 237 232 223 218 239 221 236 233 237 207 224 203 213 230 207 203 222 225 223 229 207 231 205 232 205 233 233 200 219 213 255 202 224 211 205 227 217 233 203 231 244 216 228 246 223 211 200 192 209 214 208 230 211 204 210 243 257 232 194 221 233 235 232 234 223 231 239 210 243 206 221 213 220 224 227 218 219 215 236 212 222 204 226 208 218 214 208 211 217 218 214 212 193 226 210 233 228 222 199 224 225 234 207 236 243 222 221 221 236 218 218 196 217 200 198 224 219 232 215 213 217 230 230 209 202 233 209 228 209 219 219 221 210 238 234 212 225 219 204 213 247 222 231 210 175 205 227 235 217 221 226 225 232 214 201 241 202 214 281 191 250 255 244 229 233 235 211 221 235 199 222 214 193 201 223 199 232 203 214 223 237 208 238 240 201 216 227 259 250 205 221 225 211 234 225 212 236 222 264 212 217 225 230 214 218 216 217 225 234 208 216 204 222 217 193 207 238 223 217 235 215 205 221 236 229 230 218 207 256 220 224 229 194 217 221 210 208 203 225 222 209 196 216 205 230 221 212 205 211 203 218 213 229 212 239 221 228 246 256 220 240 226 225 214 222 227 201 221 219 233 211 221 205 217 207 227 216 216 236 207 193 199 240 230 216 198 235 199 217 210 205 219 243 235 223 197 202 213 216 266 238 212 200 225 212 187 194 210 231 222 195 226 224 235 223 232 210 224 212 218 210 205 186 226 234 215 228 219 194 217 174 211 238 220 203 256 199 208 238 213 226 220 234 213 223 234 225 195 205 208 220 242 231 244 212 224 234 267 201 206 229 232 245 247 218 203 195 200 212 202 208 224 190 209 176 221 217 225 239 226 209 216 212 233 258 217 248 211 247 235 226 219 203 230 218 206 234 192 242 239 194 205 202 243 241 214 224 210 224 210 205 214 216 211 207 234 238 221 200 232 212 214 212 220 210 198 257 226 197 217 213 203 215 206 238 228 221 202 223 211 200 215 215 206 219 230 216 225 212 206 191 206 229 196 211 205 232 236 261 209 216 203 236 231 213 223 206 239 228 214 231 217 226 231 234 193 237 220 231 198 211 220 207 223 235 201 210 235 205 228 227 208 203 211 208 214 215 212 239 211 199 192 239 221 210 239 238 203 201 201 213 206 198 223 207 215 198 215 218 213 217 208 197 232 211 236 225 208 214 203 215 204 233 258 204 221 220 214 209 223 217 208 224 226 215 223 216 222 183 212 228 232 193 196 219 210 220 241 210 215 208 225 177 225 232 220 218 233 208 209 211 217 211 211 214 203 213 207 243 209 225 217 237 201 224 223 229 200 224 210 215 237 244 183 236 207 228 236 189 228 196 211 226 198 195 225 226 183 235 177 218 228 226 225 209 239 217 211 221 213 225 235 199 212 222 203 236 216 222 228 214</counts>
			</dataPoints>
		</scan>
	</xrdMeasurement>
</xrdMeasurements>