File: data/XRD/_misc/old/XG-750C/W6821-1A_absolute_2th-om_10-130deg_PIXscan_56min_1.xrdml
<xrdMeasurements xmlns="http://www.xrdml.com/XRDMeasurement/2.1" xmlns:xsi="http://www.w3.org/2001/XMLSchema-instance" xsi:schemaLocation="http://www.xrdml.com/XRDMeasurement/2.1 http://www.xrdml.com/XRDMeasurement/2.1/XRDMeasurement.xsd" status="Completed">
	<comment>
		<entry>Configuration=Factory configuration, Owner=User-1, Creation date=7/8/2013 4:01:53 PM</entry>
		<entry>Goniometer=PW3050/65 (Theta/2Theta); Minimum step size 2Theta:0.0001; Minimum step size Omega:0.0001</entry>
		<entry>Sample stage=MRD Cradle; Minimum step size Phi:0.01; Minimum step size Chi:0.01; Minimum step size X:0.01; Minimum step size Y:0.01; Minimum step size Z:0.001</entry>
		<entry>Diffractometer system=XPERT-PRO</entry>
		<entry>Measurement program=C:\PANalytical\Data Collector\Programs\Jorrit\2thom\_absolute_2th-om_10-130deg_PIXscan_56min.xrdmp, Identifier={15BCCF57-2807-42BD-B5B9-ECC0B3DC9284}</entry>
		<entry>Batch program=C:\PANalytical\Data Collector\Programs\SimonL\batch4x_2thom_10-130°_z9.1_x0,10,20,30_y0_57min.xrdmp, Identifier={EED9823A-2BEB-424C-9252-345C4EF2834A}</entry>
	</comment>
	<sample type="To be analyzed">
		<id></id>
		<name></name>
		<preparedBy></preparedBy>
	</sample>
	<xrdMeasurement measurementType="Scan" status="Completed" sampleMode="Reflection">
		<comment>
			<entry>_absolute_2th-om_10-130deg_PIXscan_56min</entry>
			<entry>PHD Lower Level = 4.83 (keV), PHD Upper Level = 11.27 (keV)</entry>
		</comment>
		<usedWavelength intended="K-Alpha 1">
			<kAlpha1 unit="Angstrom">1.5405980</kAlpha1>
			<kAlpha2 unit="Angstrom">1.5444260</kAlpha2>
			<kBeta unit="Angstrom">1.3922500</kBeta>
			<ratioKAlpha2KAlpha1>0.5000</ratioKAlpha2KAlpha1>
		</usedWavelength>
		<incidentBeamPath>
			<radius unit="mm">320.00</radius>
			<xRayTube id="1010048" name="Empyrean Cu LFF HR (9430 033 7310x) DK442154">
				<tension unit="kV">40.0</tension>
				<current unit="mA">40.0</current>
				<anodeMaterial>Cu</anodeMaterial>
				<focus type="Line">
					<length unit="mm">12.0</length>
					<width unit="mm">0.4</width>
					<takeOffAngle unit="deg">4.2</takeOffAngle>
				</focus>
			</xRayTube>
			<xRayMirror id="27010001" name="Inc. Beam Cu W/Si (parabolic MRD)" hybrid="false">
				<crystal type="Graded" shape="Parabolic">W/Si</crystal>
				<acceptanceAngle unit="deg">0.800</acceptanceAngle>
				<length unit="mm">60.0</length>
			</xRayMirror>
			<sollerSlit id="21010002" name="Soller slits 0.04 rad.">
				<opening unit="rad">0.0400</opening>
			</sollerSlit>
			<mask id="22030007" name="Fixed mask 2 mm">
				<distanceToSample unit="mm">220.00</distanceToSample>
				<width unit="mm">2.00</width>
			</mask>
			<divergenceSlit id="22010007" name="Fixed slit 1/8°" xsi:type="fixedDivergenceSlitType">
				<distanceToSample unit="mm">220.00</distanceToSample>
				<height unit="mm">0.19</height>
			</divergenceSlit>
		</incidentBeamPath>
		<diffractedBeamPath>
			<radius unit="mm">320.00</radius>
			<sollerSlit id="21010002" name="Soller slits 0.04 rad.">
				<opening unit="rad">0.0400</opening>
			</sollerSlit>
			<receivingSlit id="22010001" name="Fixed slit 4°">
				<height unit="mm">5.88</height>
			</receivingSlit>
			<detector id="7010017" name="PIXcel3D 1x1 detector" xsi:type="areaDetectorType">
				<phd unit="%">
					<lowerLevel>30.0</lowerLevel>
					<upperLevel>70.0</upperLevel>
				</phd>
				<mode>Scanning</mode>
				<activeChannelsEquatorial>255</activeChannelsEquatorial>
				<activeChannelsAxial>255</activeChannelsAxial>
				<pitchEquatorial unit="mm">0.05500</pitchEquatorial>
				<pitchAxial unit="mm">0.05500</pitchAxial>
				<readOutPeriod unit="seconds">0.135</readOutPeriod>
			</detector>
		</diffractedBeamPath>
		<scan appendNumber="0" mode="Continuous" scanAxis="2Theta-Omega" status="Completed">
			<header>
				<startTimeStamp>2024-09-04T10:32:22+02:00</startTimeStamp>
				<endTimeStamp>2024-09-04T11:28:28+02:00</endTimeStamp>
				<author>
					<name>PRO-MRD</name>
				</author>
				<source>
					<applicationSoftware version="6.1b">Data Collector</applicationSoftware>
					<instrumentControlSoftware version="7.0E 20130304">XPERT-PRO</instrumentControlSoftware>
					<instrumentID>0000000011142674</instrumentID>
				</source>
			</header>
			<dataPoints>
				<positions axis="2Theta" unit="deg">
					<startPosition>9.99826193</startPosition>
					<endPosition>129.99755682</endPosition>
				</positions>
				<positions axis="Omega" unit="deg">
					<startPosition>4.99913096</startPosition>
					<endPosition>64.99877841</endPosition>
				</positions>
				<positions axis="Phi" unit="deg">
					<commonPosition>0.00</commonPosition>
				</positions>
				<positions axis="Chi" unit="deg">
					<commonPosition>0.00</commonPosition>
				</positions>
				<positions axis="X" unit="mm">
					<commonPosition>0.00</commonPosition>
				</positions>
				<positions axis="Y" unit="mm">
					<commonPosition>0.00</commonPosition>
				</positions>
				<positions axis="Z" unit="mm">
					<commonPosition>9.100</commonPosition>
				</positions>
				<commonCountingTime unit="seconds">32.895</commonCountingTime>
				<counts 239 248 229 208 215 205 188 196 231 214 202 209 197 237 226 205 203 206 199 199 228 199 238 209 208 210 206 191 207 184 211 210 218 212 218 216 204 227 214 210 258 209 210 195 210 219 173 221 235 205 197 205 220 196 210 215 173 207 187 206 204 206 204 207 216 208 207 220 223 184 212 228 231 220 203 198 212 229 215 204 209 197 214 194 231 185 201 182 207 210 212 199 192 191 186 211 216 223 207 195 234 235 199 218 213 215 199 226 217 189 188 213 201 215 193 205 201 226 187 208 192 228 236 200 183 198 205 197 219 188 204 210 194 173 219 214 216 192 203 211 200 230 208 203 186 198 176 188 194 220 204 198 204 202 195 182 181 171 195 198 180 214 195 202 193 180 225 194 198 196 196 202 197 164 209 205 189 175 205 205 203 199 167 200 178 199 174 206 209 200 187 201 191 172 200 186 200 174 194 188 205 187 167 184 170 177 193 179 208 171 186 173 190 200 181 198 176 191 187 178 197 180 195 181 219 192 178 161 170 202 180 171 186 173 200 191 199 176 164 195 179 178 183 181 164 191 168 175 159 205 171 174 199 167 174 187 183 179 183 179 189 174 157 173 167 208 165 184 187 183 173 192 148 185 186 167 174 171 167 164 186 175 194 178 178 168 158 202 190 200 196 168 148 197 191 200 186 191 193 175 181 188 157 192 164 165 171 178 158 178 186 187 170 149 182 185 186 165 174 186 153 193 169 190 172 184 153 172 165 150 170 167 157 172 180 172 182 210 170 155 197 151 156 164 170 156 162 160 195 170 160 177 173 163 168 152 179 157 190 186 162 184 152 168 171 151 167 170 162 147 177 164 168 170 160 191 165 166 169 194 164 159 162 192 172 172 180 163 158 187 167 173 155 170 160 159 170 157 168 151 143 169 173 163 188 184 166 182 168 173 154 180 176 172 176 164 153 168 170 183 162 195 163 197 154 151 171 162 146 130 163 157 171 194 170 151 180 166 169 199 178 164 174 171 171 189 174 183 164 149 146 186 170 163 153 157 142 162 158 166 175 157 170 152 144 177 181 144 156 171 165 152 166 133 169 169 153 154 158 140 173 172 163 157 169 153 152 154 131 151 172 136 166 170 178 156 168 143 160 142 153 163 179 169 166 149 156 156 151 152 157 153 170 162 167 164 155 139 171 169 153 152 179 166 155 176 171 138 159 185 165 161 171 178 167 146 169 152 141 134 159 146 175 162 174 159 161 165 147 135 137 167 141 176 156 141 146 157 180 162 144 159 154 150 162 160 159 143 168 146 149 148 156 167 148 152 164 168 159 150 153 162 151 184 141 161 159 161 151 129 152 181 174 145 141 165 152 163 151 144 135 162 155 149 145 160 157 143 152 144 153 165 151 164 166 162 152 164 150 148 136 188 156 134 177 156 152 150 126 145 161 165 138 140 140 159 148 133 154 192 155 160 161 178 151 159 157 120 161 154 153 161 141 148 128 148 139 139 150 167 151 155 169 153 155 182 151 138 153 140 137 163 155 178 143 160 153 147 156 151 131 165 146 167 171 161 158 157 166 134 156 165 168 163 138 171 152 154 141 122 147 157 153 174 186 154 168 185 149 164 142 151 141 131 164 152 146 131 165 147 156 138 160 154 165 170 164 161 144 161 161 170 152 146 126 175 149 143 158 152 153 149 149 143 139 161 156 152 158 168 126 162 139 148 166 155 153 161 167 159 166 137 152 145 144 156 162 148 146 167 149 163 157 167 148 151 143 161 172 152 166 143 149 159 166 152 137 151 133 158 146 154 158 151 155 162 171 133 162 156 154 164 167 165 140 152 138 153 161 138 144 154 134 165 162 127 156 154 144 154 187 166 165 146 160 137 146 160 160 152 148 155 120 141 143 161 147 156 144 139 161 155 126 157 142 172 152 151 139 176 163 179 128 171 155 141 143 171 141 147 176 134 146 178 149 147 138 136 160 150 143 150 167 159 159 137 157 155 157 156 145 162 178 141 157 169 176 143 150 173 148 147 147 169 175 158 160 153 155 174 144 145 162 168 146 148 153 129 149 153 166 170 168 155 145 155 152 172 155 159 155 145 157 163 159 162 144 140 152 142 170 158 155 126 143 149 163 173 174 166 146 170 172 147 175 152 173 148 162 164 147 176 169 151 167 163 150 175 143 134 164 152 154 147 164 131 175 139 131 145 170 145 160 168 193 160 190 159 163 159 163 173 141 146 161 147 172 145 152 136 151 144 153 154 154 170 154 165 147 148 140 164 174 145 146 152 151 174 206 180 143 184 167 157 184 145 145 150 145 164 157 159 148 150 177 159 147 154 172 143 173 156 146 161 157 142 168 164 173 166 141 165 169 165 188 160 160 167 160 156 155 163 150 168 135 160 166 157 158 171 130 153 185 166 180 167 144 169 183 161 163 165 160 180 161 155 177 173 158 193 163 153 173 164 171 183 160 158 167 147 160 170 155 174 181 152 164 168 198 168 176 161 159 166 168 160 162 177 173 150 185 172 161 163 153 157 172 178 156 133 153 157 158 190 145 174 166 160 187 173 164 166 191 173 157 159 167 177 187 176 152 143 177 194 171 154 150 152 199 179 159 192 164 176 161 145 195 165 168 145 175 162 130 163 178 166 165 176 167 173 168 173 185 162 170 174 139 158 160 165 150 160 147 150 148 181 176 157 163 144 161 192 167 167 176 184 169 160 186 184 151 170 171 185 165 165 151 171 173 197 157 182 169 151 173 173 170 152 175 157 188 187 165 172 156 175 182 170 151 159 162 155 189 148 161 158 153 159 165 163 168 172 151 170 170 175 149 178 157 176 160 183 158 187 159 176 150 156 154 173 184 174 189 192 163 149 174 179 181 167 189 161 167 173 182 160 150 187 156 188 165 168 170 147 154 153 166 183 173 176 153 168 176 187 165 173 179 153 169 187 168 167 177 191 158 185 159 192 160 173 147 158 150 165 156 146 172 168 171 183 162 146 175 176 163 167 147 189 184 163 143 168 156 179 160 171 181 165 154 164 182 199 136 194 169 164 180 150 165 159 176 164 186 156 165 161 170 176 166 158 183 176 196 158 148 175 162 192 182 177 166 179 182 166 164 146 144 181 154 176 163 156 167 169 154 141 161 149 185 195 171 167 166 169 174 148 167 156 162 182 167 167 154 173 172 181 166 165 166 166 167 181 161 158 160 192 168 176 142 151 176 141 142 172 168 154 186 159 168 160 177 153 169 170 146 164 154 167 161 154 161 162 164 149 166 149 149 160 159 149 170 137 150 165 170 179 184 164 148 167 170 141 171 142 137 171 148 138 173 174 161 157 160 148 154 158 151 164 171 155 184 153 158 155 166 160 168 175 170 173 159 159 171 154 153 171 155 138 166 154 168 157 180 169 144 161 149 178 169 172 148 141 134 166 174 161 144 152 162 173 174 186 148 137 165 169 153 165 147 155 171 181 148 162 156 170 144 149 169 140 194 153 138 166 164 146 135 162 176 146 139 172 151 161 154 153 158 138 166 163 147 147 144 170 149 141 177 151 180 170 149 167 145 166 158 156 145 176 149 167 157 151 164 165 161 140 148 164 157 160 168 145 140 188 152 155 148 155 161 149 135 155 156 148 149 162 148 152 157 155 150 143 148 162 161 171 151 141 146 146 156 166 147 162 167 152 155 175 147 155 161 144 173 166 158 143 150 149 156 159 161 160 170 153 161 150 157 134 152 159 164 164 156 150 149 158 132 163 163 169 169 157 158 149 145 150 175 152 158 149 165 154 158 144 138 141 170 137 146 154 183 156 150 139 165 159 171 138 132 155 171 138 159 148 152 142 159 167 148 152 151 147 145 141 145 131 159 164 161 157 149 139 156 143 158 147 156 150 169 160 158 158 162 182 152 138 173 156 166 162 177 143 154 153 151 152 152 161 166 165 175 148 138 161 147 139 153 133 146 127 160 168 125 130 162 141 140 136 152 164 143 134 149 130 155 165 128 155 131 138 151 145 146 170 143 169 141 148 148 132 132 141 154 134 145 178 147 134 146 141 140 140 137 128 124 140 136 147 127 134 135 161 158 144 139 147 162 151 134 152 141 146 158 152 157 145 178 156 161 133 144 144 143 134 142 168 146 141 124 131 133 150 143 149 148 145 131 149 146 133 137 153 150 140 161 137 132 159 137 126 165 140 138 152 145 127 159 165 127 150 160 138 150 144 128 156 145 136 148 142 150 154 149 144 138 121 139 141 169 176 151 146 148 126 141 130 136 143 154 117 166 140 127 127 124 132 160 156 160 151 151 155 150 128 165 163 153 152 151 124 153 151 140 131 137 130 160 143 157 138 145 132 152 130 155 149 146 136 167 137 131 140 131 133 158 139 119 139 140 152 149 129 131 132 135 115 150 155 137 133 152 123 144 147 142 140 151 146 143 137 161 140 151 153 129 136 165 145 158 148 145 126 125 133 151 144 153 141 147 133 126 150 134 141 134 137 161 158 139 152 139 137 141 147 149 162 142 140 140 142 141 136 146 140 146 154 147 141 127 128 147 144 125 122 148 122 159 138 139 127 140 148 139 152 140 144 144 150 129 125 131 136 163 147 137 139 140 153 146 141 135 135 154 134 150 137 117 154 136 133 147 137 147 144 139 147 165 148 145 143 136 131 145 146 130 138 130 150 145 137 144 133 132 150 132 150 123 130 168 138 136 148 135 129 148 124 141 150 136 145 136 131 162 131 125 146 130 137 155 140 138 124 121 128 145 148 163 124 145 153 156 147 123 124 112 157 120 144 138 134 141 132 153 140 118 142 133 131 132 136 144 140 144 119 151 135 125 144 133 131 148 149 134 150 123 164 148 145 150 119 154 136 141 131 151 147 134 152 131 113 133 138 126 142 138 133 136 139 148 113 133 141 134 149 128 134 139 121 155 127 140 141 133 141 142 140 133 144 120 147 132 125 135 129 120 152 153 153 128 135 125 130 135 152 153 158 140 159 132 128 135 139 156 148 141 115 127 146 139 128 126 141 107 120 144 140 151 158 146 122 150 122 111 136 136 139 133 133 139 115 130 146 139 117 131 143 119 150 151 135 136 138 120 130 149 147 133 151 134 141 126 137 143 172 136 142 150 123 135 123 142 128 122 128 140 136 127 130 130 131 134 142 139 132 140 119 121 144 125 135 155 135 144 124 132 139 144 142 132 140 149 150 134 148 150 151 122 123 128 129 121 127 129 127 130 131 140 101 138 137 118 141 130 124 133 143 143 133 132 126 140 129 138 135 137 134 130 142 137 139 138 135 133 132 125 153 151 128 139 128 140 150 126 121 135 130 141 115 131 123 169 149 139 133 146 139 130 124 134 155 145 128 143 126 142 149 128 130 145 124 142 171 140 126 125 122 151 133 121 132 146 137 137 163 130 151 126 119 142 146 126 157 128 141 104 135 135 116 119 134 130 112 150 131 122 130 130 140 141 139 147 138 145 108 142 126 141 153 140 130 114 119 141 130 159 132 125 143 141 134 155 131 145 127 128 143 164 133 125 127 160 151 137 135 150 133 133 140 140 121 128 133 144 123 144 137 132 124 134 153 133 130 127 142 148 121 136 128 137 139 118 125 145 145 138 136 148 136 148 140 137 124 137 138 117 133 129 116 134 143 136 131 147 146 143 131 132 129 131 144 136 119 142 133 136 125 128 137 126 123 133 122 139 133 140 153 115 133 129 144 141 134 144 140 128 153 120 145 115 134 120 127 139 139 142 142 106 149 129 147 133 137 149 120 94 155 128 134 128 122 141 137 131 124 130 162 147 144 112 118 125 129 142 108 141 137 125 123 128 135 139 139 122 129 118 143 137 122 147 106 144 122 116 141 129 135 139 146 119 116 132 140 151 112 130 129 135 115 125 114 156 110 110 118 138 120 143 125 141 157 114 137 137 136 144 149 119 146 121 177 155 139 127 144 138 120 144 113 125 138 145 124 136 156 125 125 120 128 150 157 147 143 145 119 132 120 126 132 138 123 150 157 144 141 112 140 141 117 162 115 132 134 140 119 153 125 147 131 117 127 146 135 124 104 131 132 152 146 135 159 136 155 114 123 135 113 136 130 134 129 120 135 138 164 132 137 117 123 132 132 139 151 119 131 125 126 147 132 133 120 157 129 132 139 141 113 141 128 121 122 119 131 164 106 142 138 131 123 132 131 129 119 135 123 115 139 124 136 138 144 134 119 115 124 132 131 135 131 161 110 139 122 129 129 145 103 122 133 123 143 126 141 113 151 134 145 105 145 135 141 130 146 123 152 122 132 129 128 123 131 132 114 125 152 131 114 104 115 139 141 148 145 132 128 147 127 150 128 127 140 141 125 105 150 144 122 137 122 140 113 130 140 123 109 106 133 136 147 130 133 131 145 141 150 130 143 145 123 141 150 152 152 138 131 116 147 125 137 126 149 122 131 141 137 128 136 130 109 123 128 125 106 130 161 165 122 134 126 143 120 118 132 105 125 132 118 144 118 144 133 115 123 134 127 129 125 148 140 120 154 133 136 118 131 126 130 130 129 136 122 121 139 140 150 119 125 138 147 121 136 130 141 142 136 154 124 117 130 110 146 128 126 135 113 144 141 119 126 117 121 124 135 121 106 124 151 117 124 122 127 148 119 121 140 125 136 131 138 133 139 153 136 147 132 126 131 150 141 132 134 150 140 155 119 144 110 142 119 137 124 140 126 137 129 134 137 126 142 150 137 117 135 137 115 123 141 139 118 123 127 151 141 132 119 135 129 143 137 117 144 132 123 129 135 161 123 130 117 138 108 141 144 140 127 104 138 132 121 133 142 137 126 130 141 147 136 129 134 110 125 134 153 130 127 122 140 138 133 144 140 142 126 136 122 129 142 127 133 137 107 131 128 130 129 121 126 128 137 142 158 142 127 148 139 131 136 129 134 144 128 112 114 154 125 141 136 147 131 131 129 126 140 139 134 155 126 140 127 135 124 135 120 149 121 141 119 131 125 144 143 132 142 122 136 134 127 123 146 136 116 149 111 131 132 129 139 137 119 144 157 144 128 133 125 147 132 118 118 141 129 120 131 148 132 127 126 132 139 118 145 151 139 155 145 134 144 147 141 156 138 154 127 147 139 137 133 141 147 145 140 116 145 134 141 135 137 127 120 129 140 131 138 125 132 124 155 130 148 131 126 153 148 136 155 149 152 138 153 120 136 132 135 132 134 130 144 141 128 145 137 130 145 155 137 122 131 131 148 134 127 137 145 113 139 132 130 156 117 144 147 142 135 123 126 124 152 135 128 155 141 138 131 146 131 153 138 138 162 132 133 161 151 136 132 137 138 149 133 146 122 150 132 150 147 133 139 121 115 131 116 141 125 121 147 139 127 128 126 139 144 120 123 133 127 146 130 128 141 126 134 129 138 138 136 138 126 144 141 124 155 142 125 136 153 140 153 130 117 128 126 178 139 168 163 141 129 150 130 122 138 140 135 162 141 139 118 138 150 132 150 122 138 137 149 123 146 139 131 140 136 139 120 121 137 122 130 138 135 153 133 130 159 139 143 131 126 139 155 145 155 137 146 123 132 131 122 153 128 120 141 123 141 130 170 139 136 119 140 139 144 135 126 138 149 152 146 128 130 156 125 154 145 134 125 149 148 157 152 148 150 150 158 131 141 159 128 135 144 145 146 151 152 132 175 147 154 144 135 148 157 139 159 129 145 149 138 152 154 152 154 132 144 151 150 142 151 163 143 163 154 135 148 148 147 161 151 135 141 174 138 159 164 172 159 128 148 163 173 179 168 176 174 160 164 171 174 161 155 163 173 180 191 189 174 193 228 214 223 199 210 225 199 232 242 238 257 235 281 268 268 242 273 279 262 284 248 278 281 286 255 246 235 268 229 258 249 256 238 224 217 225 207 187 188 209 186 179 185 188 182 168 181 187 179 165 168 169 168 167 141 177 159 177 163 150 150 147 156 135 181 163 127 155 142 146 143 148 158 146 131 149 168 156 145 154 130 141 138 143 141 138 127 143 118 133 135 129 148 143 137 150 114 146 141 145 133 163 143 142 152 161 147 148 135 158 126 135 130 163 120 140 150 115 145 131 148 165 135 133 163 119 155 141 133 122 126 141 143 130 129 156 133 139 149 144 128 145 141 139 126 154 145 136 159 120 124 135 129 131 159 122 131 142 111 145 139 119 114 149 133 132 149 110 134 137 146 125 141 122 136 138 123 140 115 133 132 140 145 129 134 142 146 147 146 152 148 133 158 145 163 130 132 151 132 125 128 122 139 140 147 134 134 123 142 148 141 114 140 125 172 131 146 133 137 150 155 147 137 121 149 132 134 130 128 130 116 144 113 141 123 144 128 129 125 127 126 131 135 143 159 125 142 150 146 152 146 122 143 141 128 137 119 130 137 131 148 149 133 128 130 130 158 143 121 102 141 129 159 135 136 132 133 150 134 138 122 108 130 130 131 134 141 154 139 137 148 140 151 135 130 145 142 124 142 134 122 123 141 138 145 129 141 139 136 143 122 143 137 145 115 130 138 139 142 117 154 98 126 148 121 129 124 130 137 132 127 124 129 143 146 140 127 133 147 139 135 131 151 140 121 129 143 140 138 136 135 148 142 130 138 126 127 130 133 125 126 122 118 149 163 138 135 140 148 135 133 151 130 148 159 121 118 136 124 125 140 143 138 142 128 141 130 131 171 149 139 128 136 130 117 134 129 138 141 142 136 122 131 151 123 133 155 128 104 160 127 135 141 128 124 138 131 127 133 139 136 132 147 113 147 111 132 135 142 159 132 149 145 135 140 119 140 140 125 127 124 131 140 132 116 111 134 140 121 125 131 128 131 146 146 130 141 139 145 127 125 124 132 100 110 131 137 123 124 126 139 145 135 146 145 117 129 131 118 125 138 139 116 137 151 133 117 147 126 136 152 139 136 129 140 137 119 162 142 146 153 140 130 144 145 134 139 145 153 140 142 131 125 112 118 130 140 130 157 146 150 125 136 139 125 139 139 135 144 127 129 135 141 130 141 137 144 126 125 124 127 124 152 143 131 135 120 123 131 124 145 117 129 137 130 129 127 119 159 133 134 124 156 138 152 119 141 144 140 123 131 135 122 131 136 145 156 137 124 135 122 140 120 133 129 125 136 147 107 145 150 136 146 124 148 141 130 136 135 133 142 104 132 143 120 147 131 136 128 147 138 136 126 144 146 133 138 138 126 138 162 137 164 137 127 137 143 146 137 132 173 145 137 140 137 153 146 131 139 151 129 130 141 155 116 129 122 128 139 134 119 146 137 143 134 159 144 149 147 130 139 137 137 143 137 135 130 151 117 133 134 125 134 134 133 139 130 123 155 140 154 113 137 129 132 134 132 132 136 136 110 141 115 134 135 122 143 151 149 146 121 133 141 144 120 135 119 118 115 146 127 119 120 139 135 127 127 134 116 126 142 150 136 146 143 115 142 128 142 144 133 143 138 150 104 144 151 107 128 131 128 147 154 136 132 113 142 132 141 158 141 117 123 124 127 125 150 131 131 139 120 134 140 131 152 136 141 147 137 127 178 122 142 134 126 142 153 134 129 127 132 145 136 137 142 135 134 123 128 140 149 120 115 137 155 149 124 146 152 129 140 129 137 129 132 123 149 127 130 158 124 137 130 134 120 138 125 147 139 137 134 157 131 156 125 118 124 135 114 118 139 164 157 133 140 127 162 156 139 160 133 150 158 140 127 139 141 128 131 124 121 132 134 106 163 138 145 139 131 141 123 141 111 145 160 142 128 122 126 134 131 142 130 138 128 131 149 153 133 156 133 142 139 142 140 158 136 159 144 147 150 146 144 120 136 129 131 129 130 161 147 152 136 122 120 143 130 148 135 128 144 130 132 156 141 146 161 142 131 138 139 147 150 134 149 134 148 137 135 132 138 155 117 150 157 135 136 129 125 134 148 134 158 153 122 128 141 142 129 135 140 137 146 164 130 123 130 129 118 148 156 136 135 147 126 140 152 148 128 136 152 160 126 154 150 150 139 157 126 124 157 135 132 155 149 133 127 134 131 143 123 149 132 150 136 130 116 143 148 129 105 130 118 159 142 125 136 137 143 138 134 150 144 119 141 125 130 131 149 141 137 138 141 119 143 150 136 136 134 135 149 126 129 133 137 134 130 137 129 137 142 130 147 138 139 143 147 148 129 139 154 162 140 134 143 137 124 160 138 126 142 136 135 127 137 155 123 133 128 150 140 127 152 120 132 150 134 140 147 149 134 140 120 151 140 150 148 125 141 126 142 144 139 134 140 134 141 135 141 148 161 132 138 132 137 148 132 135 125 133 135 143 130 138 126 152 124 135 133 132 137 137 129 147 131 121 143 146 122 127 143 127 132 153 119 144 138 123 136 151 157 138 136 135 124 140 153 155 130 135 130 146 139 125 139 145 145 134 162 136 151 137 141 135 146 142 143 134 149 153 155 145 149 123 115 138 141 151 160 139 163 111 155 160 147 124 131 126 124 128 134 145 157 133 131 153 140 137 132 133 139 148 130 160 131 128 129 125 136 130 141 129 131 155 149 136 134 145 131 133 147 142 139 138 138 111 136 123 152 147 123 139 122 162 129 147 159 141 142 134 133 118 121 146 155 108 133 144 139 133 153 133 147 119 136 135 141 143 133 138 151 117 118 143 151 160 151 146 113 131 149 139 141 119 150 142 126 123 119 142 144 132 141 124 125 136 134 131 155 139 140 154 128 163 130 133 145 147 137 141 131 124 150 123 141 135 128 156 150 141 137 138 142 164 125 132 126 148 140 132 144 136 157 129 141 147 145 135 157 126 156 147 106 161 132 154 124 156 118 127 155 118 118 141 150 147 107 121 130 151 153 150 124 121 146 128 166 142 122 145 144 152 114 153 145 131 142 120 158 132 118 134 144 124 137 143 148 151 119 137 130 134 145 143 134 134 154 154 129 126 125 122 147 129 145 121 142 136 123 152 145 161 149 104 139 119 164 142 149 152 156 141 128 142 124 137 144 147 143 137 159 138 129 157 138 135 150 142 117 127 155 140 149 127 148 133 160 139 150 138 130 157 134 160 111 136 141 127 165 151 145 150 152 146 148 141 146 137 129 144 142 119 128 157 142 138 144 118 151 136 159 117 138 146 131 152 127 143 130 149 120 143 161 137 137 148 143 135 121 139 132 141 137 150 138 127 150 150 130 147 146 124 134 136 142 133 138 123 131 130 145 151 139 138 143 144 151 136 141 139 137 137 142 151 125 136 147 146 132 147 143 145 143 137 148 155 153 148 135 160 143 134 127 133 142 159 136 130 150 134 129 142 130 150 151 122 144 136 132 149 151 146 131 125 154 155 165 162 122 134 142 120 144 134 151 152 129 170 112 161 128 126 147 120 126 137 157 140 136 133 126 146 140 144 129 120 143 141 143 139 136 155 135 156 133 145 172 122 131 143 156 139 152 174 121 129 111 136 135 126 139 133 146 150 138 146 121 152 119 138 142 125 126 141 134 138 124 133 145 124 137 123 158 147 143 121 143 136 129 134 124 145 148 139 142 157 120 138 145 135 155 131 166 152 128 136 139 125 127 143 144 149 121 122 139 129 129 123 137 151 143 146 136 152 152 132 130 130 136 128 120 159 138 122 142 127 151 150 134 108 144 131 170 141 146 136 162 108 144 144 149 144 145 150 148 145 133 113 134 128 127 148 133 146 143 153 148 166 131 141 131 117 139 145 159 133 120 147 139 147 125 164 162 114 133 140 177 146 120 144 155 154 128 127 149 155 144 129 142 126 137 154 149 119 136 127 130 139 154 124 141 165 125 130 135 145 132 154 132 134 135 152 144 154 142 157 141 130 127 150 137 109 111 115 144 145 127 139 147 142 131 129 117 140 153 152 155 142 159 141 150 144 149 129 137 142 161 145 139 138 136 150 134 155 160 120 121 135 132 123 147 153 141 178 149 149 128 128 155 124 135 139 113 138 134 137 143 134 137 141 132 128 132 139 150 128 168 151 154 164 145 140 133 139 127 141 148 155 137 155 135 161 150 112 106 139 144 129 127 156 133 127 134 150 120 136 141 151 139 150 124 164 134 132 139 157 152 132 134 152 123 126 151 149 123 145 145 163 122 133 146 131 133 116 133 144 128 136 134 133 140 148 133 147 143 153 135 126 144 126 162 145 149 161 139 132 143 148 145 150 153 149 150 144 144 149 140 134 127 137 137 138 137 147 158 138 137 166 150 138 143 127 130 141 151 141 146 130 141 148 134 160 137 127 150 146 135 139 154 144 149 135 127 142 130 141 154 133 161 141 139 151 141 146 150 118 127 148 162 150 148 150 131 143 139 140 128 123 156 144 136 138 142 125 132 156 138 138 133 156 144 152 134 164 156 127 141 127 148 139 138 150 133 165 146 149 144 157 168 150 155 138 129 157 123 142 136 150 139 156 137 141 135 141 149 145 175 142 137 159 146 130 145 151 167 146 144 154 136 137 138 157 152 151 172 169 146 145 165 137 157 149 157 140 163 122 143 147 164 152 138 160 151 150 143 163 162 166 139 139 146 162 151 165 184 157 137 164 156 131 155 136 174 151 150 152 146 132 132 133 163 137 134 148 170 156 146 139 139 140 148 151 136 131 139 149 138 130 137 154 146 137 141 127 150 131 149 155 141 161 175 136 158 136 161 139 135 153 137 147 131 137 141 138 131 138 139 130 142 137 134 126 140 150 178 168 127 137 141 148 171 141 131 140 155 135 136 157 157 148 143 145 128 142 133 143 122 149 141 117 152 132 138 138 149 150 132 108 118 163 132 135 143 132 133 119 147 135 143 155 145 154 149 147 159 136 142 151 136 139 136 150 128 167 130 132 135 113 138 147 133 158 133 132 149 142 139 146 125 146 129 155 160 122 132 155 143 137 139 144 155 158 157 136 137 123 170 146 133 140 131 161 150 141 114 128 123 152 151 140 132 121 139 140 146 139 134 146 140 126 159 126 141 138 103 140 135 147 159 142 153 139 154 130 142 150 114 137 144 149 127 140 134 148 168 139 131 154 148 162 132 127 171 142 155 157 136 160 160 139 138 139 130 148 125 120 170 132 134 130 139 123 140 139 148 142 155 145 129 139 136 145 138 123 143 143 129 128 159 165 147 148 137 152 148 154 149 163 136 140 165 138 152 145 130 151 136 169 147 122 137 147 160 140 147 131 154 156 147 147 154 139 136 162 142 151 145 137 138 128 151 158 148 139 158 153 148 138 147 162 137 126 143 139 129 153 136 160 160 136 139 157 151 153 150 149 140 145 135 136 141 144 161 135 133 141 127 144 150 154 149 148 144 172 129 153 140 155 163 140 149 139 134 154 146 153 136 129 145 140 174 147 131 158 149 134 148 148 135 146 139 151 153 149 154 151 121 151 117 147 139 148 139 168 163 155 142 155 144 153 146 125 140 154 131 147 147 142 124 105 143 127 142 151 135 161 146 143 154 123 124 144 138 142 133 173 138 163 149 151 144 155 133 153 147 146 157 127 136 124 140 127 141 153 149 142 142 138 172 160 129 122 130 139 137 130 148 135 163 159 145 137 160 137 161 143 135 147 154 160 167 152 130 153 147 132 149 127 146 141 128 154 143 122 158 116 115 144 135 152 165 126 147 130 157 125 128 161 126 135 124 138 156 155 141 149 129 149 156 169 143 126 159 145 151 133 133 160 141 159 164 154 133 130 133 127 136 138 148 140 142 131 133 125 145 137 155 148 135 145 141 135 143 123 159 127 140 151 140 136 146 161 149 142 121 154 150 152 139 139 118 135 144 152 146 154 129 159 146 146 159 139 132 157 119 151 156 145 143 136 111 142 146 139 166 138 116 107 137 134 165 148 144 155 142 143 141 151 136 130 153 152 156 144 161 152 153 145 132 128 141 138 146 145 138 134 138 144 160 141 149 137 128 159 132 136 137 143 125 138 149 137 115 135 143 141 152 158 147 126 149 160 129 138 139 132 134 138 119 130 155 151 137 128 132 155 136 130 148 141 133 150 145 158 135 140 157 154 138 153 143 156 137 131 139 140 129 135 138 155 146 148 128 126 132 141 152 152 148 141 113 155 147 147 128 146 134 140 127 142 149 170 156 146 133 158 150 142 170 128 154 139 147 128 129 121 146 126 129 152 158 167 144 139 145 138 154 131 145 136 153 137 135 127 128 147 139 150 141 147 116 145 138 139 147 140 145 119 155 144 140 129 128 134 127 140 143 138 163 144 143 135 141 155 135 121 156 122 152 137 138 133 146 141 144 135 145 152 144 116 131 129 158 142 129 146 133 141 128 127 140 144 142 134 126 143 142 132 140 158 158 144 165 154 157 146 161 148 146 136 135 147 120 134 134 127 126 148 140 134 154 135 153 137 126 141 156 136 132 178 137 129 147 122 128 143 132 129 158 148 162 136 149 137 139 158 133 161 148 137 132 172 143 153 156 130 151 151 140 152 144 130 153 152 120 130 161 155 168 124 137 143 138 147 145 140 154 150 153 136 139 138 132 153 145 126 123 139 143 151 157 142 126 173 130 169 152 128 146 144 139 134 148 156 154 139 133 130 166 129 160 135 160 124 111 137 152 167 139 130 120 164 148 144 138 140 119 140 136 142 150 157 156 135 144 137 156 140 141 143 162 148 135 123 137 163 143 154 143 142 124 135 167 140 164 139 119 143 149 143 122 131 143 142 136 147 164 156 146 139 158 165 139 131 161 156 159 164 143 139 150 125 150 138 148 158 132 152 129 130 135 156 142 142 141 148 145 138 146 147 152 145 158 142 143 167 143 142 142 162 151 172 138 147 168 126 156 137 113 136 130 132 160 131 137 144 158 150 148 131 150 146 161 132 154 165 149 121 158 146 123 151 150 136 113 152 149 128 158 156 144 145 141 135 159 135 137 144 151 129 145 128 135 114 147 127 131 145 133 142 155 130 147 138 131 127 151 122 140 140 120 133 143 149 173 122 138 125 160 150 149 141 140 156 149 140 146 143 151 145 154 136 162 149 118 154 126 142 137 147 154 150 140 141 144 136 145 159 133 135 143 124 162 144 133 152 131 143 145 138 153 155 131 139 145 156 121 145 137 156 163 129 149 144 136 125 159 157 165 143 136 163 154 144 128 138 163 155 155 135 144 139 129 161 132 180 153 143 147 166 165 143 153 146 143 158 158 153 135 144 144 150 139 142 136 140 141 151 153 144 125 155 143 137 132 143 135 138 126 165 146 137 163 146 143 162 126 122 160 141 137 154 142 152 153 145 138 151 133 171 178 146 119 139 139 129 137 133 139 139 134 167 160 147 147 149 144 155 136 171 150 141 124 135 146 143 154 133 137 156 144 123 143 150 160 161 135 158 171 162 160 153 151 136 132 147 164 154 126 165 131 122 148 132 136 151 127 145 158 149 143 135 137 137 158 150 122 153 117 142 141 150 147 137 116 152 159 163 133 136 151 151 143 147 159 130 148 161 141 151 165 140 130 146 164 144 152 150 150 163 145 125 131 154 152 107 128 143 137 141 168 142 142 141 135 137 150 139 136 144 125 155 130 166 159 147 146 140 138 129 149 143 140 150 141 136 159 149 157 154 129 134 155 157 157 137 134 139 143 127 126 161 125 139 162 134 140 155 126 135 149 153 145 145 136 156 133 127 144 148 139 159 143 158 131 169 141 142 142 150 152 147 157 125 156 163 132 146 125 154 128 131 132 139 140 128 142 125 152 141 166 141 162 141 137 154 158 138 140 140 137 136 128 142 145 150 126 114 130 123 137 152 147 138 147 147 158 133 141 146 125 141 138 141 165 127 159 157 129 127 145 144 148 132 134 140 146 147 143 147 171 129 150 138 128 149 157 142 153 146 129 157 140 175 157 131 156 140 142 163 152 151 148 140 168 145 161 154 138 157 144 141 142 172 152 149 141 110 125 164 134 148 152 146 121 142 115 138 142 137 134 117 157 132 153 144 139 127 141 149 116 140 161 125 145 158 140 136 133 144 131 130 152 169 133 153 138 137 129 139 147 139 151 153 146 153 126 124 127 134 145 142 145 127 134 155 140 145 153 126 144 133 122 154 154 138 137 143 129 132 146 152 138 142 155 123 167 136 141 120 166 143 143 149 128 141 118 157 143 132 150 133 152 137 146 155 139 128 129 141 130 157 140 147 146 168 126 146 159 132 155 130 153 146 141 139 154 148 151 151 150 151 146 148 147 143 131 130 150 151 137 131 155 136 149 132 143 148 174 140 144 142 133 116 129 143 145 122 145 152 129 156 141 140 131 136 145 138 129 146 165 141 180 142 137 147 139 150 147 150 140 147 127 138 141 143 139 154 171 135 144 157 140 155 144 161 145 149 146 162 153 135 143 166 128 143 151 147 138 167 158 153 160 149 133 147 155 159 158 134 165 142 141 145 133 164 158 165 145 181 136 153 132 158 171 139 137 155 155 148 143 148 163 160 155 139 159 165 169 183 149 178 158 164 150 158 161 163 168 166 162 177 162 156 175 171 170 170 135 144 144 150 164 155 162 157 163 150 154 157 126 172 171 155 172 163 159 166 177 148 162 172 154 159 146 141 143 162 139 147 171 152 163 118 162 145 159 148 182 146 156 157 136 155 148 139 152 145 144 166 143 125 145 145 157 148 152 163 147 136 144 149 128 155 153 143 136 128 168 147 139 155 140 160 142 126 151 151 134 138 165 145 131 143 164 147 148 151 136 136 163 147 134 147 149 151 128 131 161 171 143 136 125 149 154 127 121 139 156 151 170 144 151 141 153 146 150 153 147 122 157 142 128 158 130 142 148 141 127 162 129 147 157 170 143 121 154 168 138 154 137 147 134 141 154 136 149 151 141 108 153 134 138 147 150 139 148 149 151 131 157 144 152 145 149 128 134 133 124 149 150 136 122 134 167 138 153 156 148 126 141 130 138 142 159 145 134 145 123 150 151 152 105 144 162 154 134 121 141 153 141 125 130 134 160 136 142 137 129 118 119 151 137 123 130 139 146 160 143 150 138 126 143 148 131 130 111 137 108 175 171 126 133 159 139 146 138 165 143 162 154 132 127 140 153 121 133 126 143 154 141 134 146 155 134 153 145 133 156 123 145 144 143 136 129 142 153 140 124 126 153 156 156 141 133 140 144 140 137 148 129 140 151 143 148 142 119 132 134 133 139 132 138 131 138 122 168 110 125 119 151 139 147 149 147 141 140 156 150 153 162 130 157 130 129 165 125 139 126 143 137 149 135 165 127 156 138 160 138 138 137 115 115 157 145 136 149 136 130 154 118 127 150 155 153 156 144 126 137 137 146 130 138 134 153 138 145 142 152 159 133 155 139 122 113 134 123 146 143 145 160 129 133 135 124 152 147 128 152 139 136 145 143 143 134 149 150 142 149 126 141 136 129 156 138 141 151 146 124 140 115 157 157 158 133 154 139 154 156 119 130 134 138 180 149 135 120 135 149 155 135 134 123 150 147 135 160 145 137 131 138 136 131 145 157 143 146 126 124 154 137 140 150 124 136 148 147 164 155 149 126 138 132 152 144 149 138 129 131 125 135 139 131 125 137 147 162 143 138 153 147 135 155 133 120 148 140 156 142 135 142 170 139 156 162 126 134 146 134 111 165 148 112 144 131 127 125 137 140 158 135 136 156 152 146 142 159 123 135 142 155 122 134 117 135 154 156 126 144 123 153 140 143 127 137 134 119 149 138 125 124 123 142 138 145 146 122 138 142 130 136 154 153 130 162 152 153 144 141 135 125 153 115 147 122 142 123 113 148 154 144 153 149 141 123 157 152 122 152 132 139 149 115 136 136 138 168 132 163 159 145 131 136 137 139 140 119 153 143 122 130 126 144 126 104 149 138 149 127 136 134 132 124 116 140 144 144 135 130 146 146 116 126 131 130 138 149 129 145 138 126 124 158 156 141 135 138 134 137 159 145 168 126 125 126 141 158 146 137 148 136 145 145 136 138 137 149 125 135 130 130 138 113 130 137 134 134 155 124 135 120 145 134 168 139 135 145 145 136 150 137 118 134 147 140 127 129 135 129 126 158 128 132 150 165 142 134 146 137 147 159 154 149 131 159 151 133 134 165 147 140 139 160 144 126 141 132 153 151 125 144 164 153 129 152 156 149 125 146 156 144 152 144 147 153 153 132 121 130 139 132 126 117 128 120 158 125 142 158 143 141 133 131 129 133 127 145 180 149 131 152 128 150 145 126 138 130 143 150 121 142 149 139 134 133 155 153 129 147 134 139 140 161 139 141 129 145 149 146 135 143 139 133 153 129 132 142 105 132 137 138 134 141 130 139 148 104 150 122 144 130 126 144 173 126 136 140 167 136 144 130 146 138 135 143 123 138 152 150 132 137 139 135 169 127 147 138 160 145 136 147 165 139 125 127 139 140 135 133 140 134 130 115 154 130 141 148 162 127 129 137 137 126 127 130 147 122 141 131 151 115 149 157 149 151 140 165 127 143 138 119 124 141 155 152 136 138 140 130 139 145 143 129 132 138 145 137 136 132 136 158 147 139 127 159 157 138 135 142 155 154 154 143 149 152 137 123 139 164 141 146 142 141 136 150 142 123 146 140 134 151 148 151 134 156 143 130 153 126 130 150 142 131 142 152 146 127 125 138 160 133 138 144 161 150 140 143 146 152 136 146 154 113 136 147 136 145 145 132 135 128 149 146 165 133 133 134 114 143 123 131 148 143 157 136 135 137 144 139 141 151 135 159 139 129 131 161 137 140 139 125 146 143 143 139 144 171 153 135 147 137 130 154 132 131 148 146 145 120 170 137 150 127 130 133 142 126 135 115 138 132 146 137 141 148 148 124 132 131 128 126 125 125 131 149 138 138 155 124 134 150 126 129 148 154 123 142 143 138 135 164 119 142 146 150 157 149 144 144 180 124 131 131 126 137 123 128 132 119 129 116 139 139 142 149 135 139 125 149 132 121 162 125 128 131 145 128 137 139 135 149 147 126 117 149 127 139 135 150 120 131 153 138 139 132 131 106 158 127 132 135 131 126 136 122 133 126 151 148 155 149 130 148 163 126 142 135 127 148 138 146 126 167 134 143 127 132 131 154 143 142 143 131 138 165 131 145 149 144 163 150 147 146 144 148 151 139 152 151 141 132 124 129 135 142 128 142 126 151 130 119 153 125 150 133 136 146 133 141 129 125 133 137 121 134 137 167 125 136 141 149 150 121 127 137 136 143 160 148 142 147 141 125 154 142 125 148 136 157 140 119 142 142 136 139 139 130 131 136 142 130 125 135 148 125 124 156 141 129 151 140 153 117 145 131 145 125 146 133 145 163 128 134 151 140 148 126 131 136 154 131 140 129 136 129 138 143 138 154 162 119 156 148 136 151 155 131 130 155 149 146 150 142 145 133 116 153 121 148 146 151 161 138 139 121 146 134 158 143 138 153 153 148 134 137 137 136 124 144 161 137 166 141 139 171 112 158 124 123 131 135 136 145 148 135 149 140 139 162 156 126 164 122 153 151 140 123 138 136 140 128 129 126 157 160 157 141 120 138 143 132 166 144 149 151 168 137 129 121 150 136 138 151 152 145 135 140 147 146 134 152 149 130 133 138 125 134 112 136 134 144 144 137 125 129 128 133 124 150 127 130 136 153 140 144 138 137 135 142 157 138 141 179 130 145 113 144 138 123 146 148 137 147 137 133 137 148 145 124 156 142 139 153 145 143 153 146 131 137 125 134 135 148 140 116 142 145 137 160 143 131 157 140 132 144 132 137 135 124 124 142 127 121 141 149 136 154 149 150 130 141 125 154 152 123 143 155 152 136 129 131 138 137 138 147 146 149 138 136 170 151 141 124 148 116 137 127 137 123 141 142 128 127 137 173 153 135 126 138 154 135 149 137 154 128 135 132 142 143 136 149 141 128 168 131 155 134 131 141 130 128 136 146 144 134 138 137 133 135 141 124 132 123 155 125 139 136 134 134 142 155 124 141 150 131 131 135 130 126 150 139 139 121 129 131 138 147 143 127 125 131 146 176 159 152 151 141 130 145 134 129 124 144 132 145 147 153 136 145 145 121 128 149 133 133 165 125 150 141 113 150 132 140 145 140 142 147 142 127 134 149 148 159 133 138 151 159 139 150 144 116 152 132 149 155 162 152 118 133 132 160 138 129 161 133 123 138 151 157 144 153 150 119 150 159 151 128 157 148 133 146 148 123 131 148 151 127 127 128 129 125 141 151 144 138 134 139 129 145 150 152 145 153 136 138 150 143 139 153 134 116 148 134 165 154 137 137 148 149 150 137 165 138 146 151 146 145 139 138 161 137 165 160 148 145 138 142 137 138 145 147 154 137 122 135 147 131 129 144 137 155 153 147 156 142 152 174 140 150 131 158 151 141 144 150 145 157 142 145 146 149 140 144 149 114 147 137 154 141 147 134 134 153 169 159 147 139 133 139 132 119 124 173 172 147 142 116 151 155 153 128 132 152 125 145 126 146 125 151 121 157 139 145 163 123 139 154 130 123 127 162 149 129 146 152 148 142 143 141 131 109 133 149 140 159 144 140 145 123 148 128 148 151 151 139 148 154 134 135 153 111 141 135 151 141 141 154 131 133 130 142 138 141 140 141 148 166 152 143 150 148 124 131 129 164 143 173 139 119 156 156 131 118 141 141 153 159 150 143 135 135 164 125 137 136 133 125 147 137 126 140 122 127 134 141 122 158 142 130 150 106 140 137 139 143 150 118 147 137 137 166 153 128 140 134 123 135 169 137 130 132 137 126 125 140 143 142 147 136 149 144 121 156 121 158 137 126 141 163 134 133 129 137 148 143 131 148 144 145 136 128 145 133 144 141 139 133 155 159 136 135 156 135 127 124 131 131 136 156 135 127 139 130 141 137 153 135 150 134 135 156 133 130 133 137 131 124 158 134 141 139 142 133 147 141 132 147 132 128 149 143 170 148 128 126 140 140 149 148 133 155 133 165 143 172 153 152 134 141 125 129 155 140 151 144 147 135 139 145 129 160 145 143 149 150 133 137 136 135 151 145 150 132 129 135 126 144 134 126 140 137 134 144 137 142 136 146 136 165 135 143 151 126 146 150 133 134 129 144 131 137 130 147 153 116 142 143 144 154 174 128 121 141 160 153 155 151 137 125 150 160 142 142 138 126 154 133 151 132 135 127 139 133 130 156 146 158 145 156 160 151 127 140 137 165 170 148 144 141 116 133 129 133 165 140 139 151 141 137 126 153 174 130 170 142 134 141 161 154 149 146 154 134 128 185 138 131 131 154 143 161 127 147 146 130 162 146 137 145 109 154 166 135 135 152 124 142 144 123 154 145 148 135 134 133 114 137 117 139 143 117 135 152 147 134 136 141 119 145 157 127 141 140 149 143 134 136 138 139 156 146 142 153 143 159 144 139 148 144 159 157 148 183 122 153 121 156 135 136 130 157 136 166 140 154 130 143 138 147 130 126 138 141 139 144 144 175 135 129 144 168 147 149 136 148 152 141 142 164 141 141 146 141 151 158 153 143 138 149 141 134 128 134 149 121 130 139 133 131 137 135 152 147 147 146 153 161 141 149 151 129 136 145 159 144 162 138 160 139 152 150 163 132 129 143 142 133 136 148 165 144 113 154 135 136 145 133 149 134 154 148 123 137 136 140 156 140 142 129 153 160 141 141 137 131 143 134 128 124 135 140 136 135 130 131 130 146 147 145 131 144 156 136 144 150 136 175 148 146 138 153 146 138 137 139 137 113 142 137 152 147 146 133 150 144 146 160 164 155 149 146 136 138 154 157 150 134 137 136 148 175 164 145 134 164 141 115 145 133 148 146 125 146 158 143 141 147 152 137 156 142 162 145 121 169 135 145 139 126 160 141 142 144 155 168 141 155 129 136 135 125 153 133 152 137 152 154 122 135 137 141 133 155 125 139 150 142 133 144 135 140 132 156 133 136 138 129 143 134 128 165 143 137 128 150 113 177 147 139 122 162 152 114 119 140 151 154 141 147 151 142 135 143 119 156 169 141 149 166 166 147 146 156 155 126 161 144 129 140 150 142 147 139 137 145 150 141 133 140 159 144 149 165 128 131 140 131 139 143 139 150 162 163 140 144 165 134 138 157 116 156 136 153 136 135 130 152 148 144 177 149 147 156 124 154 145 145 145 139 153 145 159 142 135 146 137 137 135 144 139 161 144 121 146 141 148 149 149 133 130 132 160 132 138 162 156 144 139 133 145 163 135 125 155 164 133 154 117 124 143 138 139 146 129 146 141 122 138 136 135 127 140 139 151 133 136 143 129 159 140 139 140 128 146 184 145 129 137 147 135 141 147 140 138 163 130 133 134 147 141 161 144 134 139 148 144 166 145 149 149 130 159 140 159 145 123 157 126 140 148 141 148 155 144 145 124 143 137 143 119 149 144 163 150 138 142 146 136 124 148 137 154 139 134 147 162 130 144 139 149 146 147 154 139 147 137 155 151 137 145 136 136 159 149 149 148 160 137 141 128 131 152 144 154 139 140 156 150 147 153 141 144 137 128 135 142 154 131 150 159 143 136 164 132 146 154 144 129 152 139 134 152 139 165 139 132 136 141 146 151 147 149 140 158 151 122 171 133 129 135 137 148 146 135 135 160 139 145 156 161 161 149 142 135 146 138 149 158 149 133 150 135 138 161 150 140 136 143 137 148 131 149 179 151 155 141 155 119 145 142 159 159 146 126 149 147 149 140 130 179 129 156 144 147 147 132 148 152 153 147 162 144 136 137 144 137 142 156 133 152 144 135 132 146 149 122 149 132 151 133 160 135 138 132 144 125 148 135 134 164 149 150 148 137 161 142 156 163 123 118 146 136 181 166 144 135 150 144 144 145 143 151 130 127 122 150 131 154 139 153 150 145 165 139 132 145 162 126 147 152 128 136 130 126 129 148 142 139 130 171 165 127 148 121 145 145 169 148 141 146 138 146 131 142 132 136 136 142 146 159 141 148 148 136 132 138 159 143 139 129 135 118 143 109 138 151 156 142 146 150 144 129 133 155 148 146 150 148 166 142 134 144 156 135 136 147 159 137 136 139 149 133 143 142 138 136 150 126 141 122 151 134 139 136 157 143 143 140 144 132 138 140 149 136 140 140 157 128 157 150 157 134 134 147 151 137 117 140 150 134 128 157 136 142 136 146 142 149 142 139 136 171 158 147 140 131 152 141 162 154 149 135 115 138 128 141 140 149 142 132 135 143 142 149 135 136 143 140 130 129 144 138 170 138 149 134 156 142 161 141 126 145 148 137 141 133 157 142 133 146 144 150 135 169 132 147 135 139 146 138 153 145 137 146 121 152 136 152 163 137 143 130 137 170 138 157 146 143 136 115 127 148 130 168 138 135 171 135 145 137 139 131 155 139 137 141 132 153 160 138 139 126 177 142 125 115 150 120 163 139 146 137 139 149 154 151 141 153 143 146 135 143 144 114 137 141 125 154 141 149 122 139 143 151 139 150 138 162 127 148 128 169 161 147 132 150 145 122 154 140 153 151 141 137 144 130 166 136 141 157 135 137 163 135 130 146 146 144 145 121 162 170 125 156 149 131 142 149 143 143 128 155 144 150 152 138 141 138 147 136 139 123 128 128 150 162 141 105 152 116 130 156 146 141 156 132 133 132 159 159 140 154 156 153 149 126 142 137 149 141 125 122 143 147 145 151 143 133 131 127 142 124 125 121 137 149 153 140 124 112 122 129 150 139 160 136 168 153 160 153 128 124 153 148 136 158 131 104 153 130 141 127 127 146 129 163 158 128 166 154 158 172 141 137 141 148 143 148 124 167 149 149 135 147 137 143 138 138 150 142 135 153 149 143 140 144 140 152 136 162 156 143 142 143 149 153 173 145 144 128 156 140 135 150 126 127 176 153 145 135 151 134 136 130 140 146 125 134 167 161 163 131 151 145 139 152 129 118 152 132 141 155 160 150 158 137 130 165 140 152 144 131 137 164 135 135 162 158 127 130 135 141 142 143 122 124 153 150 124 123 142 168 108 164 162 156 123 146 160 146 143 148 144 115 140 161 134 161 137 146 134 126 130 157 142 148 158 172 122 140 147 162 151 137 148 133 146 140 140 148 160 147 151 129 136 117 153 143 156 152 155 150 165 165 152 148 132 143 125 159 132 145 145 136 149 154 150 139 159 136 157 137 117 137 140 151 142 151 172 155 154 156 136 140 149 157 145 173 134 152 160 143 153 138 171 175 180 186 153 143 132 170 165 146 143 146 155 171 152 138 165 159 139 151 140 141 168 148 157 169 169 153 165 153 162 177 160 153 133 155 157 152 159 142 140 155 176 155 176 167 159 152 156 163 165 150 175 137 139 134 144 131 141 165 165 151 141 143 151 130 125 155 150 123 162 139 168 160 169 142 139 145 157 167 150 159 137 141 170 164 167 145 167 159 159 138 155 157 149 155 141 153 149 137 141 126 139 159 138 165 157 147 138 150 162 149 159 160 137 139 155 150 147 139 133 161 148 155 141 127 145 140 150 152 143 153 155 156 151 132 168 156 146 154 135 129 155 143 147 134 154 144 143 140 146 151 137 152 146 144 121 140 162 155 171 149 152 147 139 126 157 137 153 166 152 114 171 145 137 146 131 148 135 130 156 137 147 137 158 142 174 149 127 140 138 126 156 134 134 165 154 160 121 165 158 149 132 146 148 148 163 172 127 141 154 126 140 137 136 147 162 163 142 147 152 155 159 146 141 123 125 121 151 129 148 156 132 143 140 146 131 139 154 156 129 132 160 141 121 157 134 146 146 142 141 143 150 152 129 164 157 131 121 153 145 153 128 181 137 143 154 166 133 134 139 154 162 141 143 132 148 141 133 151 132 149 143 160 153 127 150 121 153 143 147 143 160 148 147 139 161 150 159 133 136 141 133 139 151 140 134 155 148 134 147 135 147 145 146 156 136 157 129 169 125 162 146 151 144 133 141 167 154 132 143 137 139 142 120 125 170 156 117 138 146 133 163 138 144 163 127 145 134 133 137 155 143 140 134 155 140 149 160 141 132 157 177 156 137 161 152 157 150 161 158 144 163 144 150 136 155 140 155 140 143 129 133 150 136 167 133 133 154 143 159 156 167 141 167 139 148 137 166 152 173 150 160 134 133 157 134 136 144 155 128 150 157 138 147 167 152 154 131 147 152 142 158 152 144 147 164 126 157 174 135 160 132 130 132 129 142 142 128 166 113 137 146 146 151 140 140 144 115 135 140 133 137 103 149 145 153 142 152 135 129 143 148 152 140 155 132 149 138 143 149 170 140 120 146 144 141 146 162 140 161 147 152 118 139 130 122 142 160 130 162 117 130 161 154 134 141 145 132 160 133 156 138 126 144 147 145 174 142 159 141 147 156 147 145 151 132 133 141 139 138 146 178 126 123 146 131 149 153 151 155 149 133 126 157 143 157 150 136 139 129 144 163 128 130 166 154 137 127 151 136 115 143 142 142 158 161 146 154 144 150 133 158 119 156 150 136 155 167 133 132 127 139 135 141 157 129 116 156 132 140 121 140 142 138 143 137 140 130 173 135 130 127 142 141 144 141 140 174 123 165 136 137 151 158 147 133 144 156 140 161 164 142 165 142 130 134 148 147 128 140 153 142 157 133 146 134 144 136 139 159 139 140 142 139 132 148 139 142 126 137 117 151 155 144 150 163 132 114 154 149 140 133 135 158 127 160 173 127 143 151 140 149 125 157 133 158 144 146 138 149 158 144 146 130 132 135 137 104 159 131 147 123 122 139 140 120 161 141 140 152 147 159 130 143 144 140 152 146 156 154 137 134 153 137 138 135 145 135 130 131 138 146 129 126 150 144 159 135 136 139 144 137 139 144 123 143 157 151 119 146 134 155 169 144 139 132 149 158 136 152 145 156 146 144 171 150 161 138 141 146 134 155 151 154 166 130 130 139 140 127 136 141 133 152 149 138 150 141 140 144 140 143 153 156 132 162 136 128 152 142 141 146 130 139 143 136 141 136 144 135 145 126 155 133 141 140 129 141 136 148 128 125 144 138 142 122 135 157 139 161 139 123 148 138 140 152 148 125 134 146 153 161 131 148 133 162 152 143 153 133 134 136 151 154 149 143 132 157 163 136 143 146 122 149 135 144 143 152 138 128 150 131 131 129 137 153 142 129 141 161 156 135 116 132 156 131 144 131 105 123 128 164 140 132 163 135 158 143 154 150 133 149 153 131 130 130 133 147 156 143 150 148 143 137 153 138 121 140 143 124 149 152 135 157 126 132 156 131 157 155 143 140 139 154 139 149 135 144 130 131 150 150 140 141 140 133 154 161 148 157 125 136 146 156 136 140 137 165 141 130 146 118 133 141 135 134 132 151 155 116 163 134 139 130 151 134 143 154 142 125 151 142 130 134 147 148 181 148 143 127 145 150 140 133 147 122 139 116 134 151 142 139 160 154 148 132 144 114 130 129 147 165 136 130 144 146 151 139 141 142 140 141 176 136 152 143 142 134 119 131 141 159 141 134 160 134 147 134 149 147 142 153 154 133 146 161 142 142 148 148 151 139 148 160 126 126 128 145 145 148 167 133 155 134 138 146 134 140 146 146 132 142 141 127 142 158 160 153 154 137 129 126 146 149 140 129 126 137 141 138 139 122 161 137 142 161 127 140 144 141 142 141 136 153 149 149 132 167 139 132 138 168 139 149 159 136 139 133 123 125 138 149 142 131 136 158 150 140 136 152 135 153 120 172 141 146 155 160 134 148 132 117 153 154 155 141 149 131 157 161 136 134 134 122 137 172 129 119 122 112 139 145 143 145 135 159 145 133 141 156 141 156 139 136 138 138 141 131 125 150 145 136 141 132 151 134 152 136 142 141 135 143 157 143 118 132 166 143 141 140 145 135 112 131 117 155 134 163 139 137 136 142 137 178 153 116 148 131 147 137 164 130 142 148 142 133 123 146 163 152 154 143 147 137 134 136 132 151 139 148 163 154 132 142 147 145 151 142 149 145 144 130 140 145 154 155 167 147 151 157 137 151 129 121 142 144 142 169 144 107 163 136 140 160 135 158 156 131 154 130 131 155 152 142 154 130 140 154 156 142 128 131 135 136 144 156 141 165 137 137 146 133 156 157 132 152 161 153 153 141 131 162 144 138 140 148 149 146 147 134 139 146 140 147 154 142 155 135 136 169 162 158 135 145 132 138 152 139 113 131 130 140 137 165 146 140 125 137 157 160 156 136 116 135 127 129 146 124 153 173 161 122 162 142 130 153 150 137 133 157 134 135 132 129 141 152 132 143 134 151 137 155 151 165 131 129 148 138 148 137 132 110 157 136 139 125 144 150 151 130 136 137 155 157 123 148 137 143 142 153 141 151 125 145 127 138 142 140 123 137 154 143 130 145 135 138 128 107 154 156 146 125 132 153 136 129 113 168 153 136 141 119 140 137 141 135 126 138 146 151 155 132 146 155 145 149 142 132 176 138 144 142 145 150 132 137</counts>
			</dataPoints>
		</scan>
	</xrdMeasurement>
</xrdMeasurements>