File: data/XRD/_misc/old/XG-750C/W6822-1A_absolute_2th-om_10-130deg_PIXscan_56min_2.xrdml
<xrdMeasurements xmlns="http://www.xrdml.com/XRDMeasurement/2.1" xmlns:xsi="http://www.w3.org/2001/XMLSchema-instance" xsi:schemaLocation="http://www.xrdml.com/XRDMeasurement/2.1 http://www.xrdml.com/XRDMeasurement/2.1/XRDMeasurement.xsd" status="Completed">
	<comment>
		<entry>Configuration=Factory configuration, Owner=User-1, Creation date=7/8/2013 4:01:53 PM</entry>
		<entry>Goniometer=PW3050/65 (Theta/2Theta); Minimum step size 2Theta:0.0001; Minimum step size Omega:0.0001</entry>
		<entry>Sample stage=MRD Cradle; Minimum step size Phi:0.01; Minimum step size Chi:0.01; Minimum step size X:0.01; Minimum step size Y:0.01; Minimum step size Z:0.001</entry>
		<entry>Diffractometer system=XPERT-PRO</entry>
		<entry>Measurement program=C:\PANalytical\Data Collector\Programs\Jorrit\2thom\_absolute_2th-om_10-130deg_PIXscan_56min.xrdmp, Identifier={15BCCF57-2807-42BD-B5B9-ECC0B3DC9284}</entry>
		<entry>Batch program=C:\PANalytical\Data Collector\Programs\SimonL\batch4x_2thom_10-130°_z9.1_x0,10,20,30_y0_57min.xrdmp, Identifier={EED9823A-2BEB-424C-9252-345C4EF2834A}</entry>
	</comment>
	<sample type="To be analyzed">
		<id></id>
		<name></name>
		<preparedBy></preparedBy>
	</sample>
	<xrdMeasurement measurementType="Scan" status="Completed" sampleMode="Reflection">
		<comment>
			<entry>_absolute_2th-om_10-130deg_PIXscan_56min</entry>
			<entry>PHD Lower Level = 4.83 (keV), PHD Upper Level = 11.27 (keV)</entry>
		</comment>
		<usedWavelength intended="K-Alpha 1">
			<kAlpha1 unit="Angstrom">1.5405980</kAlpha1>
			<kAlpha2 unit="Angstrom">1.5444260</kAlpha2>
			<kBeta unit="Angstrom">1.3922500</kBeta>
			<ratioKAlpha2KAlpha1>0.5000</ratioKAlpha2KAlpha1>
		</usedWavelength>
		<incidentBeamPath>
			<radius unit="mm">320.00</radius>
			<xRayTube id="1010048" name="Empyrean Cu LFF HR (9430 033 7310x) DK442154">
				<tension unit="kV">40.0</tension>
				<current unit="mA">40.0</current>
				<anodeMaterial>Cu</anodeMaterial>
				<focus type="Line">
					<length unit="mm">12.0</length>
					<width unit="mm">0.4</width>
					<takeOffAngle unit="deg">4.2</takeOffAngle>
				</focus>
			</xRayTube>
			<xRayMirror id="27010001" name="Inc. Beam Cu W/Si (parabolic MRD)" hybrid="false">
				<crystal type="Graded" shape="Parabolic">W/Si</crystal>
				<acceptanceAngle unit="deg">0.800</acceptanceAngle>
				<length unit="mm">60.0</length>
			</xRayMirror>
			<sollerSlit id="21010002" name="Soller slits 0.04 rad.">
				<opening unit="rad">0.0400</opening>
			</sollerSlit>
			<mask id="22030007" name="Fixed mask 2 mm">
				<distanceToSample unit="mm">220.00</distanceToSample>
				<width unit="mm">2.00</width>
			</mask>
			<divergenceSlit id="22010007" name="Fixed slit 1/8°" xsi:type="fixedDivergenceSlitType">
				<distanceToSample unit="mm">220.00</distanceToSample>
				<height unit="mm">0.19</height>
			</divergenceSlit>
		</incidentBeamPath>
		<diffractedBeamPath>
			<radius unit="mm">320.00</radius>
			<sollerSlit id="21010002" name="Soller slits 0.04 rad.">
				<opening unit="rad">0.0400</opening>
			</sollerSlit>
			<receivingSlit id="22010001" name="Fixed slit 4°">
				<height unit="mm">5.88</height>
			</receivingSlit>
			<detector id="7010017" name="PIXcel3D 1x1 detector" xsi:type="areaDetectorType">
				<phd unit="%">
					<lowerLevel>30.0</lowerLevel>
					<upperLevel>70.0</upperLevel>
				</phd>
				<mode>Scanning</mode>
				<activeChannelsEquatorial>255</activeChannelsEquatorial>
				<activeChannelsAxial>255</activeChannelsAxial>
				<pitchEquatorial unit="mm">0.05500</pitchEquatorial>
				<pitchAxial unit="mm">0.05500</pitchAxial>
				<readOutPeriod unit="seconds">0.135</readOutPeriod>
			</detector>
		</diffractedBeamPath>
		<scan appendNumber="0" mode="Continuous" scanAxis="2Theta-Omega" status="Completed">
			<header>
				<startTimeStamp>2024-09-04T11:28:58+02:00</startTimeStamp>
				<endTimeStamp>2024-09-04T12:25:04+02:00</endTimeStamp>
				<author>
					<name>PRO-MRD</name>
				</author>
				<source>
					<applicationSoftware version="6.1b">Data Collector</applicationSoftware>
					<instrumentControlSoftware version="7.0E 20130304">XPERT-PRO</instrumentControlSoftware>
					<instrumentID>0000000011142674</instrumentID>
				</source>
			</header>
			<dataPoints>
				<positions axis="2Theta" unit="deg">
					<startPosition>9.99826193</startPosition>
					<endPosition>129.99755682</endPosition>
				</positions>
				<positions axis="Omega" unit="deg">
					<startPosition>4.99913096</startPosition>
					<endPosition>64.99877841</endPosition>
				</positions>
				<positions axis="Phi" unit="deg">
					<commonPosition>0.00</commonPosition>
				</positions>
				<positions axis="Chi" unit="deg">
					<commonPosition>0.00</commonPosition>
				</positions>
				<positions axis="X" unit="mm">
					<commonPosition>10.00</commonPosition>
				</positions>
				<positions axis="Y" unit="mm">
					<commonPosition>0.00</commonPosition>
				</positions>
				<positions axis="Z" unit="mm">
					<commonPosition>9.100</commonPosition>
				</positions>
				<commonCountingTime unit="seconds">32.895</commonCountingTime>
				<counts 246 206 218 224 217 236 256 212 240 205 224 191 236 228 217 211 213 223 202 223 217 220 218 232 223 193 198 239 217 190 246 231 238 208 213 223 203 246 234 239 227 220 211 221 204 245 205 239 226 212 222 223 230 236 226 211 217 208 219 193 242 219 232 217 202 186 220 192 184 216 209 194 231 219 221 224 245 211 241 223 190 238 215 205 188 221 235 194 217 227 219 211 209 204 206 213 212 193 200 212 184 181 246 188 210 223 201 223 187 225 234 205 200 220 218 186 223 196 198 217 221 244 231 182 201 221 216 211 214 217 188 186 181 223 197 226 219 220 229 208 209 180 193 198 237 182 202 199 177 196 198 194 195 189 240 198 207 200 211 229 169 200 225 188 190 176 168 180 191 212 193 241 216 210 196 223 201 233 213 218 199 188 199 214 176 225 199 192 205 177 200 200 181 197 192 213 211 206 188 219 188 209 196 183 199 206 197 219 178 218 197 214 216 222 205 201 206 215 209 190 202 185 194 188 220 224 209 195 191 180 182 187 158 203 226 220 182 176 200 181 175 163 198 185 215 177 200 177 208 173 198 183 197 195 189 187 240 188 163 170 181 188 225 177 213 194 176 186 196 213 184 186 210 185 178 199 169 194 211 190 183 203 204 208 199 206 195 184 163 197 170 187 204 193 177 202 165 179 195 187 188 192 196 182 189 187 189 188 173 205 171 196 193 197 207 210 198 184 198 184 170 188 185 191 195 194 179 185 177 163 169 161 194 183 183 176 180 194 188 182 173 199 180 173 189 180 173 193 165 170 181 179 178 166 186 186 163 185 168 182 192 179 196 165 172 196 181 166 205 204 186 209 165 177 177 173 181 184 178 180 172 196 193 193 173 189 181 176 189 186 177 175 160 166 196 179 210 183 174 169 193 199 178 201 182 206 172 163 192 171 165 176 151 162 170 191 180 178 182 186 195 182 176 175 166 203 203 164 192 187 158 192 180 175 209 198 174 170 178 182 185 176 172 164 156 173 185 170 176 178 168 179 191 173 190 156 166 160 182 197 209 203 175 150 167 173 202 170 194 180 172 177 167 182 173 166 184 181 171 178 188 163 174 177 164 174 164 147 180 181 149 171 163 154 155 154 176 159 174 142 154 170 200 188 144 172 151 201 170 177 158 165 166 179 216 146 145 149 170 160 181 169 167 165 168 176 177 172 169 172 187 158 171 155 172 165 144 183 193 168 145 167 147 175 183 151 164 160 156 155 159 174 175 172 180 180 183 149 173 161 166 152 176 168 190 154 186 157 167 176 159 183 180 173 182 157 196 121 164 145 145 155 180 166 144 164 141 155 170 163 189 163 157 153 150 155 193 167 152 172 168 162 161 166 179 173 189 167 168 161 179 174 156 176 175 187 163 155 162 150 139 149 162 174 166 146 163 159 168 178 173 159 170 164 207 159 162 162 186 163 164 166 161 164 171 190 162 158 147 159 171 168 156 161 178 170 177 135 164 174 136 164 174 134 150 174 162 156 157 182 159 163 181 132 164 194 201 174 182 147 153 160 155 153 170 165 162 160 162 147 170 154 174 171 154 168 159 178 184 155 176 154 167 173 187 132 181 174 162 165 169 161 170 157 162 162 162 171 158 165 158 160 176 183 146 154 151 180 174 143 147 187 172 177 168 176 124 157 197 173 171 172 179 182 142 160 173 152 172 158 179 170 149 166 185 157 142 183 163 155 171 172 146 180 187 176 173 160 141 166 163 149 167 173 156 160 171 158 183 159 217 159 155 165 180 159 153 144 174 182 165 148 164 196 150 183 153 179 170 182 200 171 176 149 197 166 184 165 169 157 152 194 154 148 177 179 156 184 150 156 148 191 169 165 173 189 156 188 181 182 188 149 155 146 164 174 202 162 189 192 183 164 170 183 175 175 186 166 156 176 180 181 168 163 147 170 195 146 162 169 182 160 157 168 166 155 206 183 179 164 185 156 161 161 147 174 191 172 170 147 168 173 187 180 164 178 138 170 150 165 187 176 167 169 149 188 189 162 174 159 167 172 181 156 151 169 131 160 174 191 190 165 195 157 182 164 149 176 178 152 179 184 174 159 173 168 167 177 189 176 184 186 176 175 180 179 180 183 186 154 189 187 169 217 173 162 163 175 184 178 156 179 200 189 169 184 171 159 219 196 195 195 168 172 181 150 169 159 177 187 185 188 183 188 156 168 195 177 186 151 170 169 165 173 157 181 169 188 165 182 202 177 175 213 192 181 175 185 158 166 155 139 160 178 200 179 187 174 169 194 168 200 152 196 162 165 178 184 146 172 161 165 182 178 184 167 181 183 164 186 173 172 183 168 181 193 173 167 169 177 192 176 164 173 185 188 191 158 159 175 189 188 186 190 176 164 212 183 154 184 172 173 192 178 170 171 174 163 170 148 175 178 161 173 180 169 166 184 185 177 190 183 196 180 193 165 158 180 172 169 164 191 190 164 150 172 185 170 187 179 177 189 190 159 175 178 154 174 162 189 190 158 167 175 169 154 177 188 189 196 171 197 172 173 139 171 175 175 192 163 169 182 166 178 171 173 172 184 173 189 193 152 174 177 177 173 181 172 176 171 184 182 168 178 188 177 204 166 169 172 162 180 201 177 167 179 152 177 149 186 173 179 169 177 186 168 172 176 161 156 169 178 163 151 209 191 146 170 165 180 184 182 168 175 163 211 179 184 170 208 171 181 191 173 158 173 170 179 164 188 189 153 200 192 170 184 163 167 173 157 200 183 197 172 190 179 175 173 173 178 183 174 190 182 173 177 201 180 162 186 156 178 172 170 176 172 162 204 172 171 192 178 184 158 194 179 185 189 173 189 158 175 191 184 180 187 188 172 165 190 171 174 164 171 192 190 160 196 179 179 186 181 177 193 183 179 158 186 181 185 171 200 193 171 181 181 194 190 175 162 164 181 159 184 143 187 202 166 149 179 162 177 173 173 180 186 161 172 167 154 180 200 175 171 170 173 186 165 181 187 156 190 159 179 177 163 172 170 181 192 200 185 154 145 179 172 181 189 176 188 197 156 170 164 183 178 157 196 167 194 188 147 194 182 175 171 162 159 187 190 186 170 165 180 148 167 184 181 157 155 163 155 204 166 164 176 167 163 172 180 174 195 173 154 164 178 175 177 162 183 183 174 168 163 180 167 182 208 178 179 174 185 175 176 183 170 180 147 147 179 176 173 174 188 173 181 156 168 172 178 164 188 166 167 183 187 165 163 206 160 167 171 172 169 164 155 166 151 158 187 169 166 175 176 164 148 171 162 177 172 148 177 153 178 177 175 153 163 154 150 176 171 165 179 178 185 161 158 170 169 170 153 176 150 163 173 170 156 192 155 174 175 148 162 145 158 196 158 156 138 137 182 169 193 164 150 172 173 159 165 158 175 161 169 181 187 168 164 162 181 155 166 163 163 177 162 157 169 167 174 166 138 151 157 140 159 163 164 176 163 171 161 149 171 189 156 175 182 148 160 179 172 142 146 145 178 168 162 143 167 173 154 184 157 147 152 181 152 169 138 154 155 153 169 163 171 176 166 163 166 160 143 148 183 176 148 158 169 167 143 152 166 155 162 142 158 174 158 146 155 160 170 155 160 146 170 145 167 161 150 153 143 153 160 159 152 156 151 135 140 157 160 151 164 150 164 146 150 151 164 147 150 158 181 134 180 150 152 156 160 158 148 163 141 170 143 178 159 138 163 167 156 168 148 149 155 153 168 147 138 174 147 148 142 152 168 149 161 151 142 176 147 165 143 154 152 154 149 153 155 144 152 139 156 147 144 148 134 138 146 125 176 150 155 152 146 153 144 138 143 152 143 170 146 146 133 145 157 124 135 139 160 130 138 140 152 145 139 170 169 150 148 150 158 160 151 152 143 143 148 143 140 139 149 155 160 140 130 130 156 164 169 165 140 162 134 145 144 132 138 164 128 156 159 149 138 152 143 145 141 122 128 157 133 155 140 154 138 152 151 161 170 146 144 151 161 141 156 155 149 122 148 147 141 138 130 136 150 137 132 162 133 140 152 132 150 146 173 162 158 145 138 146 129 136 131 145 133 148 148 127 139 128 132 151 146 132 121 139 132 162 157 147 131 151 176 138 169 148 146 137 124 145 151 145 143 126 131 140 139 144 139 136 150 150 137 141 129 156 184 137 141 161 133 137 156 128 124 133 165 138 134 137 133 152 173 144 147 150 142 160 129 136 141 147 172 151 132 138 155 148 146 154 137 117 147 143 119 126 138 144 147 159 141 145 143 138 143 120 150 130 142 140 151 149 132 139 147 152 146 121 131 124 147 153 146 146 138 130 154 132 141 158 152 118 148 138 154 166 130 145 118 150 156 132 135 133 133 130 148 147 163 133 131 138 152 153 142 135 125 145 119 151 137 154 116 146 140 143 150 157 160 157 121 147 141 147 129 136 141 129 134 135 129 135 114 137 125 126 141 143 123 144 123 130 130 129 129 127 134 135 120 123 149 111 140 105 138 123 137 130 132 124 149 152 135 142 136 139 125 131 128 138 129 123 130 138 130 123 165 139 134 138 123 137 150 138 119 150 128 129 152 130 117 119 133 144 125 107 154 135 133 116 130 149 155 156 135 148 134 129 132 139 113 130 157 153 125 125 123 122 134 136 147 113 124 127 129 153 121 152 141 142 119 135 130 123 140 131 123 143 130 145 131 140 112 124 118 137 131 116 130 144 129 160 127 110 147 119 121 124 131 132 130 127 139 167 143 111 137 127 133 155 135 136 141 121 121 122 108 143 115 144 145 156 121 131 113 130 133 111 120 135 146 131 156 111 118 114 134 142 138 118 139 125 131 123 150 129 121 113 130 113 133 138 132 109 140 153 151 116 131 133 145 131 130 129 126 156 130 154 140 134 131 129 138 124 139 130 127 139 143 140 121 123 130 131 127 142 132 131 136 131 155 133 150 143 137 115 117 127 136 125 116 141 150 123 133 117 124 128 159 128 130 126 134 145 123 142 129 114 127 142 133 121 130 132 124 165 145 135 101 114 140 125 128 132 130 151 115 128 126 118 127 119 140 138 123 144 132 118 141 126 152 123 121 140 129 122 125 122 136 156 138 122 121 127 144 120 124 122 133 108 124 127 127 95 127 115 138 137 128 132 150 127 122 114 141 135 127 119 144 135 116 122 139 146 121 122 127 131 131 145 128 133 118 136 106 105 100 139 147 137 132 132 126 115 136 138 127 129 135 127 137 118 123 125 120 130 142 130 127 121 113 120 143 129 118 128 140 112 128 106 122 142 141 112 118 138 130 129 112 124 119 121 131 128 122 131 135 108 130 127 121 127 108 118 156 119 126 125 131 131 136 121 131 112 138 155 125 119 119 151 136 106 114 121 120 129 128 139 134 143 127 135 127 121 97 134 135 97 144 127 119 141 133 128 134 134 135 137 132 148 134 126 130 116 136 129 135 138 115 116 123 136 130 114 135 117 131 134 141 135 126 126 130 114 128 111 121 134 126 119 139 133 143 118 133 146 127 135 115 124 140 133 129 134 126 122 127 138 124 112 142 105 138 116 132 129 135 129 114 132 131 120 140 118 127 116 133 101 112 123 129 128 103 125 151 105 116 118 111 136 111 123 124 123 131 127 138 134 129 119 129 130 127 142 94 110 136 124 141 111 111 111 124 136 116 118 136 118 131 129 128 137 117 137 132 129 129 119 132 122 121 138 117 133 133 125 113 132 131 120 120 122 145 128 106 111 134 113 136 137 119 117 141 125 102 114 119 124 121 122 114 127 128 132 122 117 120 121 106 114 133 117 132 128 126 114 134 108 115 130 136 105 118 133 109 96 145 117 125 117 133 148 127 140 126 120 122 133 130 118 135 134 114 103 133 140 125 136 125 107 112 124 112 141 119 121 134 128 124 123 128 128 161 113 127 130 137 152 104 123 142 112 143 117 133 129 116 135 112 133 109 119 116 122 125 140 123 127 120 116 119 97 124 114 126 133 142 136 123 144 123 130 126 137 111 110 125 123 130 127 123 118 142 119 129 142 111 134 131 130 127 128 130 133 133 125 121 144 95 117 94 130 132 132 121 151 131 131 124 111 123 136 139 129 122 119 117 131 119 103 114 123 130 121 122 129 119 114 104 141 126 122 109 111 137 137 127 130 134 123 131 138 130 111 103 115 119 122 132 119 136 116 129 130 136 111 140 121 118 113 123 106 109 122 124 126 120 127 124 123 122 130 133 120 123 130 140 140 135 118 144 131 115 127 124 137 111 120 125 140 127 113 135 131 132 121 123 126 119 107 121 133 111 124 111 130 123 143 107 104 111 130 109 114 118 132 129 136 104 119 129 121 117 124 125 109 129 109 120 111 112 125 125 121 129 136 120 126 122 125 124 110 123 122 121 128 125 129 134 132 115 110 109 121 110 109 133 95 122 138 115 129 116 128 128 132 119 117 117 113 116 142 114 130 128 117 127 127 116 128 119 121 118 115 136 110 108 129 127 121 123 121 119 107 121 134 135 132 136 137 90 130 147 105 127 129 112 106 110 118 117 111 121 116 140 128 99 103 100 126 125 127 119 115 115 117 119 130 135 123 126 118 136 121 93 114 137 121 107 109 112 114 123 113 110 125 109 115 124 117 109 120 122 128 113 130 129 104 94 116 117 115 130 112 119 123 126 143 105 144 143 118 117 95 107 115 108 99 132 108 127 123 106 128 135 120 123 110 126 133 135 110 111 117 123 109 120 104 116 132 123 111 121 130 120 137 140 116 124 109 106 130 98 135 119 122 120 132 91 126 112 138 116 121 111 86 121 130 123 129 107 116 125 133 109 115 112 130 136 122 125 116 119 125 108 132 121 111 123 127 127 120 107 94 106 120 112 125 119 125 131 119 105 93 131 105 135 140 116 128 111 104 130 141 119 97 115 139 130 139 115 123 98 109 113 112 153 135 109 120 125 118 148 132 109 144 110 117 132 118 114 141 137 117 118 129 134 132 134 128 128 125 137 122 114 120 116 128 111 114 127 133 119 113 123 114 121 137 133 102 109 126 120 140 135 129 115 129 118 127 111 107 129 116 135 105 108 118 108 127 126 125 127 113 107 128 124 110 117 112 131 135 112 128 113 116 148 120 128 111 130 130 146 140 114 125 126 137 128 117 115 141 136 100 129 129 101 107 115 124 121 115 110 118 104 140 117 126 106 106 132 123 128 129 102 131 124 127 136 115 121 134 121 123 124 111 134 109 132 131 131 157 115 99 120 139 125 132 115 112 123 137 127 121 126 102 112 125 119 116 117 149 115 135 132 119 128 128 117 116 125 113 128 116 135 133 133 122 113 113 136 126 149 129 119 125 118 120 119 109 133 127 121 124 150 127 114 124 132 129 118 122 130 105 125 136 125 120 140 135 141 129 114 129 128 124 132 129 148 134 118 124 124 123 109 111 122 143 134 135 129 126 121 122 141 139 151 141 111 117 136 121 145 129 130 109 144 139 118 115 87 126 130 117 112 123 115 118 101 118 133 122 128 115 128 130 140 131 106 125 143 142 127 125 118 120 115 120 117 139 126 120 113 122 126 111 122 127 143 105 149 132 119 160 123 131 141 123 115 134 125 120 134 135 134 134 131 130 136 131 137 141 129 127 123 147 156 124 126 120 116 128 141 123 125 139 127 116 144 118 129 126 117 122 135 155 140 150 133 134 143 135 134 137 138 135 138 118 125 121 146 147 131 118 147 128 124 149 127 146 115 147 136 136 130 118 122 135 160 131 148 155 151 149 145 122 142 130 142 154 155 136 148 150 177 153 167 137 176 189 179 156 173 167 199 163 186 180 194 201 161 204 224 209 223 184 205 210 200 191 234 225 212 210 226 173 191 181 219 208 197 171 185 187 179 193 191 187 191 167 179 174 177 149 172 158 133 165 174 171 132 145 153 132 132 127 143 140 151 155 154 149 145 112 136 133 124 141 126 134 128 120 150 146 132 135 119 122 123 120 126 117 147 134 123 142 130 152 110 122 120 131 129 135 145 131 131 134 116 130 132 128 128 148 129 114 112 119 135 122 115 110 131 125 146 115 138 113 119 112 150 120 120 111 107 123 125 133 121 115 119 136 120 125 129 106 118 125 108 126 109 121 114 125 120 138 121 107 119 107 115 131 110 127 120 139 135 145 126 101 139 126 124 136 123 97 117 114 116 139 126 117 121 113 121 129 117 116 111 143 113 131 132 112 119 133 106 117 119 132 131 115 133 126 93 125 121 112 122 118 125 108 126 103 115 107 108 128 126 98 130 120 131 123 128 124 119 129 135 101 134 125 133 127 127 112 118 115 119 116 134 122 136 129 108 121 108 113 117 118 120 112 120 107 156 141 132 114 115 129 124 127 118 121 116 133 108 138 135 114 131 113 129 123 146 107 109 129 122 143 119 124 139 110 146 104 115 108 123 130 108 123 106 128 120 113 131 128 128 125 129 127 130 131 130 113 129 128 116 120 116 121 115 120 119 113 110 109 118 110 124 124 113 120 107 127 129 132 116 124 124 142 139 121 125 124 108 119 123 125 119 118 116 128 132 131 112 128 121 126 114 125 132 131 129 114 141 122 123 134 106 128 112 122 118 109 121 104 135 122 140 144 112 131 121 102 117 105 125 106 121 119 105 131 122 136 120 133 133 120 121 140 128 130 122 99 125 110 124 111 128 124 140 125 119 123 122 129 137 130 133 123 119 123 108 110 138 137 137 110 134 122 130 115 110 97 131 113 134 133 117 130 122 124 131 112 128 138 101 118 119 124 125 129 123 118 114 150 136 132 134 118 133 120 122 124 111 113 112 108 133 131 128 127 142 139 141 129 109 108 104 110 121 120 106 107 138 120 118 127 118 119 145 136 118 129 130 117 119 159 123 129 118 109 142 143 125 120 120 130 127 122 123 111 108 116 123 117 114 122 127 138 138 119 124 119 123 122 117 115 112 109 133 141 128 137 116 124 122 137 106 110 130 126 102 119 136 129 151 142 117 118 107 103 98 131 137 122 128 121 152 124 120 123 120 114 131 117 116 109 139 125 130 112 114 150 144 97 108 121 112 112 125 144 113 129 131 137 128 125 139 128 139 130 129 107 111 120 139 140 147 115 123 141 141 121 111 135 118 112 119 138 126 121 128 117 124 109 141 113 111 126 119 104 126 152 132 136 129 103 137 121 105 115 128 122 129 131 124 119 131 112 140 105 111 129 108 128 136 124 109 129 127 137 139 121 95 126 142 120 115 117 118 138 120 130 134 121 134 131 123 135 142 127 120 105 153 127 114 121 110 130 122 115 120 98 126 132 122 126 116 136 131 118 149 124 143 120 125 108 134 112 123 127 130 119 111 131 141 139 100 134 105 114 121 124 98 125 118 111 136 137 120 117 138 128 122 117 116 95 123 136 120 132 109 127 139 125 111 116 123 127 125 118 103 124 127 129 121 119 114 131 116 121 130 109 98 105 115 124 120 106 113 123 96 136 129 118 123 106 148 126 123 136 115 110 127 110 122 141 127 125 116 112 131 122 115 131 136 113 125 115 129 125 109 111 117 128 113 124 131 115 123 106 127 106 120 118 132 115 126 110 127 114 113 132 133 113 119 128 130 125 111 122 120 98 134 127 134 111 124 124 134 121 117 124 121 114 126 126 120 132 127 140 122 134 102 110 108 130 121 109 130 134 104 116 111 137 120 132 105 112 121 132 125 122 115 123 126 105 136 132 150 120 117 119 135 128 138 110 132 136 119 108 120 132 110 124 125 118 137 136 112 103 140 134 141 96 126 134 130 120 138 151 132 117 125 122 131 117 139 121 113 138 125 125 114 146 123 112 114 129 106 138 107 133 136 145 131 113 122 120 103 134 125 125 140 124 111 117 120 134 117 126 147 148 118 106 117 127 133 126 116 122 129 115 139 96 131 118 133 108 127 109 120 124 111 124 127 127 105 119 129 124 124 136 124 107 118 126 128 136 128 135 117 115 119 126 126 118 118 129 141 119 118 132 122 101 129 128 131 129 115 120 118 119 125 120 125 100 131 115 128 116 128 128 114 132 124 113 119 108 130 113 122 115 124 122 119 132 121 150 133 124 116 112 134 117 139 120 122 117 129 128 98 116 122 121 131 117 103 118 134 115 132 141 104 121 130 106 114 120 121 132 118 133 130 130 126 115 129 114 131 112 115 131 121 130 118 126 113 111 147 123 126 111 135 130 116 120 113 131 137 138 129 130 115 110 108 121 136 126 122 114 156 122 117 124 136 129 117 112 130 113 131 127 130 123 131 132 125 127 130 139 106 121 118 114 132 136 126 152 126 127 128 132 130 131 122 125 131 123 121 124 129 125 120 123 104 124 110 106 137 117 123 124 120 112 137 128 116 130 114 122 121 125 110 131 128 116 123 120 111 106 136 111 116 103 114 123 114 127 150 122 113 127 123 125 125 127 139 118 130 126 129 122 134 117 95 123 119 134 110 122 136 128 122 112 120 139 140 129 110 114 134 131 125 105 104 103 128 123 108 135 121 112 125 132 121 106 123 111 118 116 115 103 103 127 118 124 115 109 113 122 134 127 102 120 107 120 134 121 142 132 127 132 110 126 127 118 110 121 132 135 130 114 125 122 114 121 122 132 141 112 114 124 119 112 119 118 121 127 109 130 133 126 128 124 108 127 132 126 127 120 121 124 131 111 136 113 123 120 127 127 117 137 132 117 109 143 145 135 112 138 118 141 146 131 127 136 99 138 142 130 128 116 120 121 125 118 121 119 132 137 126 124 124 153 123 119 109 122 140 128 143 115 117 129 113 117 130 114 137 117 125 131 125 143 106 116 128 134 149 112 118 117 130 126 138 132 122 133 115 116 131 123 121 124 126 120 124 139 127 118 112 123 132 128 111 121 132 126 123 130 135 132 113 103 121 124 111 130 124 124 105 119 114 118 128 121 130 120 111 107 106 119 119 122 120 114 136 129 127 128 107 129 120 109 126 142 126 121 119 115 128 122 102 128 129 117 106 156 113 133 126 138 123 117 124 108 115 134 136 132 128 108 138 122 129 126 127 111 127 131 111 111 111 137 149 115 113 118 135 117 122 113 147 134 161 111 116 129 130 115 124 122 131 132 131 118 130 117 127 117 104 126 103 119 106 134 112 129 144 143 123 163 136 129 137 129 119 139 127 117 129 119 130 111 112 128 137 109 134 105 115 122 128 125 130 126 116 114 112 130 115 127 131 141 125 133 125 123 130 113 151 108 126 139 141 144 120 134 122 133 124 126 104 124 146 114 120 119 131 131 118 134 117 114 135 130 137 104 141 146 118 129 129 117 127 123 111 113 126 137 100 133 130 131 117 99 125 124 117 103 127 119 117 132 112 126 130 127 99 128 139 134 136 140 103 145 126 118 129 125 122 140 126 129 123 117 132 134 130 97 108 128 122 117 117 120 128 110 115 131 109 132 122 116 121 135 125 146 122 123 136 109 133 99 114 115 130 125 132 119 130 104 119 133 128 129 116 112 140 124 109 118 125 143 114 114 124 120 116 137 132 134 137 143 110 123 116 114 148 121 126 117 129 121 121 107 131 153 138 130 141 135 134 147 139 105 127 132 108 146 114 124 126 104 122 119 130 131 122 122 116 130 120 136 131 123 111 123 130 148 113 121 123 117 137 136 117 117 119 125 117 145 130 134 98 137 115 142 118 127 127 120 128 124 128 138 152 116 133 142 122 113 135 119 119 126 140 122 127 121 126 132 119 140 123 125 129 136 115 113 132 113 126 103 128 112 122 148 141 136 128 125 110 135 135 145 124 135 130 122 142 122 147 122 129 119 108 117 131 128 132 131 132 120 132 131 134 151 126 138 109 124 109 122 117 127 109 133 117 101 130 133 143 117 126 128 129 139 113 131 127 127 124 126 128 132 129 128 114 130 110 135 138 111 113 115 127 120 144 144 129 109 120 130 118 135 115 106 123 116 130 132 106 124 106 132 131 124 117 121 112 113 118 141 110 111 126 133 134 131 118 135 135 133 122 121 121 123 124 133 116 121 146 120 111 120 119 125 136 117 129 131 97 137 135 135 138 125 137 156 124 125 127 135 121 133 109 125 113 133 137 137 113 134 121 140 122 111 132 134 127 107 124 114 119 107 144 118 111 146 126 109 145 145 137 126 137 144 124 121 120 127 133 140 135 102 135 102 138 128 138 114 133 134 106 130 136 137 107 130 131 144 140 132 126 128 111 117 129 148 121 130 114 144 130 126 118 129 126 126 120 131 124 131 114 113 108 125 132 125 124 126 135 130 120 100 140 114 137 144 132 139 134 132 130 138 129 110 133 126 116 109 111 103 118 110 118 144 142 131 114 134 121 113 117 135 121 133 132 124 125 138 127 115 127 131 139 132 140 142 140 138 121 116 129 142 125 125 123 115 150 138 144 117 137 143 129 151 105 134 154 148 153 137 101 126 111 151 128 142 118 139 135 145 135 153 150 134 125 134 149 150 132 154 118 116 140 128 130 129 143 157 151 140 136 123 144 134 142 159 132 161 121 131 125 150 122 133 125 134 148 143 113 120 145 115 111 134 120 134 131 123 118 127 136 121 137 128 141 124 135 131 133 142 147 127 123 138 124 124 132 126 140 133 139 113 146 126 140 150 131 113 165 124 141 125 126 102 121 137 111 116 125 133 125 115 104 123 150 122 125 121 142 138 119 139 108 117 124 117 113 127 116 128 140 165 137 122 121 128 130 121 130 129 96 133 122 116 141 137 132 139 135 116 131 131 130 126 141 148 132 116 150 123 119 134 113 134 110 121 120 117 149 117 128 121 129 128 141 142 142 140 128 136 131 131 135 131 130 121 134 133 117 145 122 158 132 135 124 134 118 127 125 138 114 145 140 139 108 121 117 126 143 127 123 132 114 135 115 124 115 122 137 134 117 131 133 126 116 129 137 134 122 147 120 145 110 132 130 122 124 127 159 128 133 115 155 121 129 138 130 147 127 113 117 130 119 126 132 126 146 138 159 124 147 121 133 105 100 146 126 110 128 148 151 122 135 107 139 130 130 139 131 123 146 123 130 112 131 118 136 134 135 136 128 132 123 151 133 131 111 111 113 124 120 138 132 139 131 142 122 123 117 115 136 121 143 124 123 132 134 150 152 112 125 132 123 160 115 135 131 133 138 134 138 127 154 129 126 122 131 111 143 130 135 117 110 120 132 131 117 138 131 116 133 110 134 116 156 141 111 133 121 139 125 137 127 132 104 143 132 137 125 124 118 138 113 122 137 120 118 130 126 140 116 111 130 137 129 136 128 130 113 105 148 126 121 124 138 118 116 146 129 140 122 123 148 136 132 120 151 135 118 124 128 126 121 125 129 127 141 120 156 117 130 135 123 137 132 120 115 120 134 119 134 134 130 113 115 133 152 138 135 130 139 134 99 121 109 128 138 105 165 117 104 132 121 141 129 144 118 128 132 122 119 118 122 130 131 114 121 122 123 135 122 131 118 122 125 119 116 128 138 139 126 144 133 109 130 138 123 126 126 128 115 113 138 108 147 120 126 122 111 130 135 133 114 111 146 142 124 114 153 135 130 124 119 132 107 123 125 121 118 126 133 143 120 133 137 121 127 127 136 133 116 115 112 123 127 112 120 114 137 119 112 127 112 141 120 132 129 111 108 118 124 141 145 124 118 135 126 138 118 119 137 111 131 135 132 147 117 114 125 123 122 105 105 142 123 125 131 130 146 114 121 140 133 110 128 124 160 135 114 133 133 118 130 137 99 130 136 120 119 123 111 113 130 117 124 116 115 127 140 103 135 119 129 116 102 106 124 119 138 120 137 111 119 130 153 118 117 140 127 113 124 112 113 121 127 106 123 121 154 124 127 117 131 129 123 118 117 125 151 109 132 114 121 131 111 113 111 123 108 132 130 140 133 104 131 125 123 132 121 132 116 141 143 115 136 135 140 113 119 135 142 123 106 135 132 116 132 113 140 134 125 115 130 109 138 120 121 128 130 132 126 99 138 128 119 130 110 124 133 125 127 121 119 128 125 129 122 134 115 119 122 136 141 117 128 132 126 110 125 122 102 116 132 101 128 137 115 128 131 115 127 119 128 112 130 149 128 114 117 120 128 121 141 104 123 126 125 112 93 133 141 130 128 133 128 123 132 110 129 139 119 111 127 141 133 118 132 125 118 114 114 97 115 132 111 125 129 147 117 141 136 112 108 121 136 128 142 111 106 127 125 146 122 134 134 120 120 140 130 126 116 136 132 130 129 146 135 129 124 147 127 131 115 114 122 125 142 115 113 113 114 110 119 104 116 141 143 133 98 110 138 111 135 112 109 116 125 126 144 125 122 126 123 133 119 124 109 130 151 122 110 121 136 117 130 125 134 99 156 125 130 136 125 139 121 125 96 143 125 155 126 144 135 108 133 93 101 118 126 127 124 127 108 116 124 120 122 136 101 121 113 125 128 128 103 124 121 133 110 115 130 121 113 121 117 129 124 126 138 117 137 148 139 125 119 139 119 120 102 137 151 126 135 130 144 132 128 142 120 107 134 140 131 114 116 122 130 104 131 139 129 113 122 123 109 126 133 149 119 106 127 120 144 134 121 134 104 146 109 138 134 133 139 144 140 127 131 138 131 131 143 130 128 155 115 125 132 122 95 128 133 133 120 121 121 123 125 125 132 119 122 143 153 116 143 124 139 125 124 116 146 140 125 145 133 124 137 112 155 133 127 114 112 117 155 122 133 116 121 111 114 133 130 131 125 108 137 117 141 119 130 128 132 136 137 134 106 114 152 129 122 113 128 126 127 120 123 128 122 129 128 123 134 125 156 134 131 133 140 115 118 128 121 118 112 116 128 133 145 147 109 124 102 144 106 123 123 130 143 115 116 138 128 118 124 134 144 132 124 121 132 126 120 119 138 128 152 111 111 116 125 147 125 107 102 102 133 148 121 122 132 118 120 143 123 130 116 119 101 114 138 113 140 127 119 130 103 131 120 132 142 126 126 141 111 126 107 120 135 141 124 114 122 124 110 118 131 126 132 134 126 105 109 131 143 123 129 135 157 122 123 130 141 129 121 135 119 122 114 134 113 144 147 140 124 138 110 120 142 120 113 125 132 127 125 136 118 128 120 118 144 136 123 130 155 117 102 116 113 133 121 105 117 125 139 131 120 138 120 110 130 136 128 140 115 116 106 126 139 128 124 119 118 128 124 114 123 126 122 122 132 138 129 133 132 129 119 126 126 116 138 119 142 118 139 142 129 114 125 126 126 134 122 107 106 118 112 100 139 115 132 123 111 117 110 111 128 145 140 133 143 141 106 100 135 112 122 116 116 158 114 115 110 118 143 108 110 124 115 111 132 124 146 122 112 103 117 130 120 127 112 119 122 119 130 131 119 129 130 114 121 114 120 124 130 121 123 106 125 117 133 118 127 128 103 98 124 138 125 110 135 99 139 117 124 123 127 134 132 101 109 134 123 144 129 103 129 126 128 123 136 122 122 112 126 140 122 139 123 139 124 122 113 119 119 111 130 135 111 129 136 131 126 122 126 127 129 131 113 131 127 156 121 106 132 130 124 117 104 131 130 123 112 109 142 123 139 121 131 142 124 127 117 118 127 123 129 130 120 136 121 117 116 112 111 131 123 120 98 114 142 133 127 130 119 138 125 127 123 124 112 116 109 131 120 103 118 128 135 122 112 124 134 122 128 118 125 115 117 123 129 107 118 114 141 107 127 106 119 142 123 107 130 134 129 108 115 146 130 138 110 126 117 150 124 116 130 112 120 115 117 128 120 128 120 129 129 113 129 122 96 105 124 141 122 103 123 116 147 143 124 108 133 143 124 136 113 127 134 107 117 137 110 119 117 131 144 134 123 124 117 120 123 106 136 107 118 107 137 117 96 135 108 105 148 124 105 103 118 113 118 116 128 135 128 111 108 126 113 124 127 112 127 130 128 113 123 125 124 114 136 128 117 138 126 118 127 125 120 101 132 107 126 116 138 121 117 110 142 110 124 113 113 121 130 116 123 114 140 113 127 111 116 126 126 105 129 114 107 132 118 109 125 140 122 126 99 95 128 116 114 108 122 107 101 126 128 132 115 114 132 114 121 129 123 129 118 126 117 139 153 118 114 127 146 117 130 135 119 127 118 110 128 134 131 135 134 133 110 122 128 110 132 125 128 112 107 133 114 116 123 115 128 105 131 115 117 126 122 117 137 107 118 124 132 116 116 121 106 114 129 125 140 113 125 145 134 123 103 135 128 140 110 135 121 128 121 140 122 122 120 117 112 120 125 123 119 120 114 126 129 132 128 149 126 124 127 113 118 133 136 133 107 111 131 129 145 100 122 127 119 144 136 131 129 117 134 123 115 112 126 98 121 127 124 142 132 124 146 129 110 133 131 145 117 128 117 123 129 136 128 143 136 126 128 130 139 136 147 143 128 146 138 122 129 153 124 141 119 133 128 137 161 132 131 156 118 129 126 154 135 142 146 145 139 149 141 133 141 134 138 140 140 124 123 134 165 130 121 122 141 120 152 137 138 152 123 125 148 134 135 136 135 147 128 136 139 131 138 131 128 126 131 116 137 146 150 142 130 124 121 148 145 140 137 120 120 136 134 126 125 99 114 126 126 122 110 123 145 138 101 133 119 124 124 105 120 117 138 133 132 110 144 109 140 111 145 140 126 126 114 111 104 124 121 123 119 117 145 110 127 129 117 119 125 123 138 132 117 120 116 119 114 138 130 133 136 128 105 136 114 168 120 128 121 114 108 116 130 106 129 125 128 149 138 114 102 114 135 121 126 126 121 122 108 117 123 137 108 134 127 129 113 135 120 124 109 126 126 153 96 116 119 118 133 112 119 116 109 108 119 131 119 112 105 103 115 119 126 141 105 120 108 116 130 111 131 144 119 115 115 122 116 126 107 114 117 117 137 112 109 120 121 127 112 137 130 101 109 117 126 116 131 119 88 120 117 124 113 117 110 118 117 118 127 108 112 116 123 115 132 123 127 124 116 147 128 88 121 116 124 109 115 118 133 113 109 117 111 120 117 122 114 105 109 119 115 120 125 117 119 114 139 124 116 98 118 125 123 112 134 116 135 125 118 120 99 128 105 129 115 124 99 132 111 125 121 122 116 124 104 132 109 124 137 121 126 140 135 106 119 129 125 103 98 140 118 111 120 120 117 113 112 127 99 123 115 141 106 113 124 109 103 118 120 108 133 137 130 121 98 98 133 111 121 109 123 109 112 109 110 104 127 130 112 124 117 109 106 115 104 124 107 136 125 113 133 113 140 111 118 110 107 108 101 131 123 121 107 111 118 129 127 123 149 126 131 101 125 120 116 107 124 118 119 131 125 126 141 126 129 110 124 103 122 118 114 119 117 123 112 127 112 124 128 107 99 123 97 107 126 130 95 105 113 113 92 105 96 117 115 114 104 101 111 112 118 106 138 105 112 110 118 126 118 134 121 112 130 130 116 84 132 123 123 127 131 129 132 127 119 111 113 113 131 106 120 128 118 135 95 126 111 128 130 115 113 116 111 102 99 107 124 127 105 112 102 110 126 115 106 102 114 104 125 120 123 104 108 116 113 137 109 139 109 121 104 109 106 157 110 116 142 130 107 111 115 117 110 97 136 108 112 91 119 117 107 101 123 128 112 112 108 119 141 112 125 125 108 116 121 108 110 114 120 121 134 130 116 132 117 113 117 117 114 112 103 93 134 112 109 120 108 137 113 129 138 126 115 135 103 116 97 122 119 133 123 111 115 119 123 130 104 124 123 131 106 113 115 109 108 106 103 100 108 118 116 96 112 133 112 110 102 120 105 105 128 106 97 136 119 110 144 125 100 107 111 121 116 125 117 105 119 129 106 131 111 120 125 96 124 103 130 112 118 122 121 122 115 95 112 107 103 118 103 118 119 129 101 105 120 112 120 111 115 116 113 111 103 128 96 114 93 123 114 137 120 130 117 112 131 116 119 105 115 121 113 109 117 108 113 105 122 119 114 114 113 128 113 104 133 126 124 108 123 93 104 111 120 143 117 128 107 128 126 149 108 108 107 124 103 107 111 129 102 118 130 110 115 98 105 117 126 108 109 100 101 130 108 119 122 109 131 116 113 120 113 115 110 123 116 107 114 113 134 95 117 113 122 118 124 118 110 120 113 113 124 118 135 123 131 107 104 108 101 124 105 118 118 105 111 110 115 135 115 115 124 122 105 122 114 117 127 110 105 90 112 105 102 101 113 127 94 107 110 128 109 113 136 110 127 125 119 117 133 106 114 106 134 108 110 136 121 104 114 105 118 127 131 124 110 123 142 120 113 102 115 105 101 121 105 130 96 117 98 122 105 116 124 122 120 95 108 104 110 126 99 124 114 121 122 107 110 113 112 127 110 110 107 102 119 105 102 116 115 93 115 123 112 123 127 114 125 120 96 127 118 107 119 126 117 133 126 113 106 108 117 120 113 108 109 95 140 105 120 131 106 99 121 114 122 124 122 103 111 120 118 127 111 119 135 123 120 109 113 116 121 110 105 122 115 122 119 107 120 124 117 120 114 117 120 110 111 122 121 114 111 125 103 115 132 108 97 139 129 133 111 121 107 99 122 119 109 125 140 102 103 131 114 159 110 114 104 120 138 129 110 107 113 127 118 126 122 129 114 113 124 109 101 108 115 126 107 113 120 120 108 118 123 119 106 132 108 110 125 113 118 118 99 122 105 112 101 110 121 114 99 123 130 108 104 134 116 120 116 109 126 112 135 111 106 126 110 126 111 124 98 110 100 111 131 116 120 117 109 100 129 117 103 99 118 97 120 126 117 108 134 130 104 121 126 106 100 116 136 104 131 107 106 120 103 121 123 108 96 121 121 118 120 140 108 113 114 132 122 116 115 112 138 105 101 122 103 110 116 119 129 101 108 110 108 117 117 117 130 97 120 96 121 109 93 104 139 119 124 117 114 124 120 110 102 106 103 114 114 127 121 97 121 114 105 123 118 118 120 133 136 107 134 108 93 114 111 120 113 117 112 127 111 101 117 117 105 128 125 113 115 104 130 123 123 112 144 116 119 124 121 114 118 119 106 127 104 114 108 115 122 110 117 117 125 118 115 117 113 122 132 112 121 103 117 107 128 136 123 144 118 102 117 105 128 124 124 112 123 124 117 117 104 111 104 112 132 127 97 110 113 133 123 127 122 129 116 114 128 102 99 109 130 122 121 120 113 109 101 91 136 126 118 122 116 138 127 120 106 92 121 116 125 126 120 120 116 113 123 115 110 116 122 121 95 126 99 119 122 115 115 119 107 131 131 122 125 128 119 117 125 109 110 121 98 123 119 93 110 126 113 108 123 115 121 110 116 101 141 102 121 115 103 118 139 118 108 106 125 114 105 109 113 124 109 110 116 99 105 127 109 109 141 131 108 118 89 121 124 116 120 103 111 110 102 126 132 98 108 116 118 129 111 114 103 118 119 117 115 135 122 118 122 120 112 101 117 106 110 118 116 118 109 131 124 128 109 114 125 109 118 130 132 116 114 118 113 96 108 115 105 120 129 131 96 120 99 107 120 132 115 131 122 131 128 140 103 108 127 136 122 122 107 99 118 110 115 113 142 125 92 120 121 131 102 122 121 123 110 120 108 113 103 115 138 93 110 97 105 115 113 136 98 108 128 135 102 119 115 126 104 127 97 110 114 103 125 97 92 113 111 113 99 121 113 133 96 118 108 123 110 101 112 108 102 105 110 136 124 125 128 121 108 108 132 131 109 105 116 125 129 113 108 117 113 105 123 130 119 119 100 123 118 112 116 107 94 128 95 111 137 114 111 117 126 126 132 118 118 112 122 108 124 119 94 103 103 115 107 136 101 106 112 98 104 109 99 119 103 123 110 127 99 127 116 111 108 119 108 106 110 121 99 128 128 120 112 127 133 94 119 98 126 122 122 133 121 115 117 131 110 107 109 109 113 134 123 114 107 119 103 109 112 106 128 125 124 124 137 126 114 101 129 104 99 106 119 115 110 112 116 123 117 112 124 108 107 111 105 117 102 114 111 94 109 153 120 133 131 118 117 120 114 137 122 100 118 116 122 124 109 132 127 114 107 104 108 119 115 131 103 105 136 113 98 114 92 125 97 102 106 114 123 109 124 113 139 116 124 102 105 107 115 129 111 120 109 100 112 114 143 106 123 130 129 141 97 114 111 88 115 113 128 122 116 116 115 119 123 111 120 117 100 124 124 110 104 122 121 126 129 105 115 111 113 113 111 138 122 121 116 123 111 125 118 102 93 106 117 123 130 117 122 122 138 114 120 126 131 144 133 112 125 125 129 140 117 101 121 128 113 133 124 121 126 118 123 121 93 135 123 104 115 120 130 117 124 113 118 106 120 124 111 127 104 126 116 95 129 116 127 113 123 120 114 114 115 111 114 115 107 118 123 107 121 123 103 141 128 106 116 110 137 131 126 121 111 126 102 140 106 105 102 113 116 121 106 99 113 93 132 107 125 102 118 113 105 129 110 106 128 109 129 104 123 107 100 117 103 106 120 140 104 111 106 134 121 127 114 104 98 107 114 119 101 109 107 92 115 111 133 104 120 122 95 103 111 100 115 129 96 120 117 128 123 120 118 116 130 123 130 112 111 132 118 117 137 125 99 118 107 128 127 95 140 125 111 110 97 133 115 98 122 114 124 140 156 122 119 146 127 118 131 109 101 117 110 117 131 129 145 106 132 119 112 112 107 112 123 117 81 133 111 118 126 120 127 111 104 114 129 134 110 111 124 115 129 108 111 102 132 119 114 102 144 119 114 119 110 134 130 139 92 124 116 112 110 112 112 110 109 97 106 106 122 110 109 109 114 119 117 97 108 114 123 113 119 106 116 125 126 99 113 96 145 107 109 120 106 118 120 119 110 112 118 114 128 121 137 104 113 114 121 101 120 114 115 118 123 102 102 109 94 114 118 91 117 105 110 120 108 111 94 136 115 102 107 114 123 129 108 102 124 116 111 135 104 102 114 114 135 109 122 113 111 118 118 118 117 111 120 111 106 116 110 112 114 110 114 105 110 113 97 100 119 108 131 115 123 93 122 103 100 125 106 114 107 124 104 96 104 122 104 98 111 118 109 113 126 113 103 119 119 128 115 109 117 111 124 108 123 121 100 107 102 105 112 114 112 124 114 104 101 111 109 119 117 120 107 106 107 102 100 125 104 115 132 124 131 100 129 127 105 113 116 105 129 126 116 123 127 106 137 115 120 130 113 118 116 116 104 106 104 118 114 124 105 114 111 119 117 117 125 129 111 117 114 104 130 112 111 110 105 122 110 96 92 134 99 110 98 117 129 101 108 90 96 123 116 106 122 116 102 122 112 112 140 105 100 130 117 111 117 112 126 129 132 100 129 109 110 142 130 118 133 137 111 102 104 109 95 112 115 114 111 112 130 126 120 115 114 112 117 113 110 108 104 109 107 100 125 105 115 127 121 114 92 129 122 111 108 110 120 108 121 99 115 109 94 122 122 111 116 118 120 110 122 124 110 116 132 131 106 129 114 122 109 131 109 138 123 121 115 116 110 116 106 125 102 113 119 115 127 121 132 109 111 140 102 124 128 123 108 124 110 116 113 119 109 120 119 106 122 116 120 130 125 110 103 128 125 114 105 116 99 119 107 132 119 122 121 112 117 114 106 116 94 133 121 111 123 110 113 104 117 118 131 119 112 120 116 131 114 141 109 117 139 121 112 112 110 125 133 137 140 133 121 113 110 120 118 103 113 112 140 108 142 114 121 96 120 112 127 121 116 113 120 94 115 124 98 129 113 116 110 117 113 112 125 131 110 117 110 106 95 114 128 122 113 122 109 135 143 98 112 132 116 127 117 94 114 114 129 114 111 114 124 134 119 119 112 121 112 127 130 121 150 117 118 102 126 107 115 128 103 134 140 125 113 112 128 108 100 130 100 97 131 113 135 120 143 111 99 120 127 96 119 122 120 119 102 116 109 110 132 102 121 120 133 118 117 105 101 119 121 107 112 115 102 110 126 110 118 124 129 112 116 131 103 120 126 121 123 111 121 120 127 104 105 123 115 112 115 108 118 105 116 123 115 123 121 110 95 110 133 142 116 122 115 120 126 119 92 115 108 115 113 124 119 119 103 128 122 120 109 119 104 118 118 106 131 108 109 135 121 126 115 111 118 132 118 115 117 91 102 112 108 127 120 121 115 119 130 102 123 139 118 128 115 106 121 113 121 129 109 116 98 111 128 133 122 109 122 119 107 114 106 126 118 95 123 104 123 108 93 117 118 104 105 120 116 119 128 128 113 110 106 133 119 118 116 122 123 111 112 114 119 123 135 111 138 101 112 116 117 105 120 108 130 117 125 124 123 109 122 114 110 120 153 146 117 114 123 128 120 113 123 115 123 101 127 111 97 135 130 132 122 113 124 126 118 120 110 111 126 134 118 120 125 145 134 129 124 113 133 119 98 110 133 116 119 126 136 114 121 109 133 125 116 102 99 119 100 109 121 117 108 125 140 119 119 129 117 117 131 121 121 110 115 120 130 145 128 107 107 135 110 116 122 122 104 106 120 117 118 109 130 115 114 115 124 119 90 112 112 127 116 123 126 138 126 125 111 111 128 114 106 116 113 118 115 114 99 115 125 117 111 116 130 114 122 132 104 120 129 131 127 125 96 103 109 115 104 96 138 124 119 114 101 117 132 102 115 133 128 97 132 115 138 122 109 110 104 110 119 103 125 116 127 114 130 126 105 100 117 99 137 110 107 122 124 115 114 135 134 115 93 110 131 119 128 133 102 128 102 110 121 107 131 105 127 115 126 113 111 113 129 111 124 119 117 93 123 115 120 109 108 115 123 113 121 129 111 112 121 130 97 128 110 108 110 118 119 119 111 126 115 105 114 119 112 110 86 112 116 120 106 109 122 109 127 128 121 114 138 103 91 103 128 115 130 128 111 109 118 110 132 120 109 118 110 132 109 143 117 119 129 106 120 116 110 114 114 111 126 116 123 106 125 121 125 125 126 121 128 116 108 119 106 126 102 114 118 114 128 116 119 135 112 122 140 147 116 104 122 124 135 99 126 128 119 115 103 117 125 111 125 140 115 119 108 125 110 119 118 119 120 133 115 128 104 130 110 132 108 121 104 116 123 121 118 124 115 142 107 119 127 115 114 122 110 119 110 121 100 112 120 131 85 117 154 123 113 108 115 122 117 108 120 128 129 132 113 94 113 123 118 103 114 105 113 121 125 108 118 113 114 137 122 109 108 130 125 127 129 137 122 117 98 137 112 130 95 132 107 112 118 122 125 118 124 115 133 101 132 119 120 116 103 108 117 128 110 132 126 123 131 113 120 128 121 127 126 108 105 143 134 121 116 118 122 147 128 133 115 143 118 123 124 135 129 126 117 129 117 123 122 121 99 96 100 110 118 114 140 137 126 139 123 110 118 125 98 119 113 106 108 114 97 127 97 111 110 104 125 131 130 112 124 137 115 122 121 124 115 121 106 104 117 122 133 118 119 119 114 123 122 124 132 116 133 129 108 116 124 128 104 137 110 115 112 119 112 113 125 127 127 99 117 136 102 134 115 114 130 120 97 117 104 124 137 139 134 128 127 120 134 129 134 113 147 117 125 135 137 126 137 130 144 120 118 109 131 118 126 114 130 117 108 137 107 101 143 118 124 100 121 116 131 106 130 119 134 110 132 129 126 126 118 119 126 116 146 132 120 125 103 99 114 128 105 121 123 118 121 125 108 140 127 137 125 111 133 95 134 133 126 125 117 127 104 115 108 142 125 110 115 118 104 119 99 108 116 107 113 127 114 138 126 138 139 145 106 120 140 124 136 123 113 110 121 120 128 109 119 117 127 139 108 114 128 116 143 124 121 115 124 112 120 125 115 123 125 128 131 115 119 119 121 109 112 119 119 140 120 99 129 127 130 132 114 116 125 116 100 119 121 126 119 119 127 120 119 131 120 119 113 105 113 125 134 115 123 125 118 127 113 98 125 118 134 145 127 133 127 119 104 140 124 111 121 129 122 137 127 109 111 129 98 119 119 126 102 118 125 126 105 122 131 141 122 116 125 134 142 109 112 99 116 123 124 113 115 118 109 104 134 120 118 129 138 116 89 124 135 115 118 128 149 124 141 155 115 120 134 120 133 124 123 134 116 99 119 110 109 139 117 110 121 118 115 128 111 118 125 124 121 118 130 133 101 135 113 126 140 124 141 124 134 132 118 115 137 126 119 126 129 130 126 129 125 127 127 138 135 135 120 110 114 118 119 135 108 132 119 149 150 129 121 102 124 143 115 134 121 135 158 94 122 117 128 131 125 106 145 127 131 119 129 123 147 125 129 119 129 131 131 109 115 138 120 125 128 125 141 126 134 151 127 114 141 121 122 126 135 129 128 124 107 126 132 119 119 107 139 144 119 133 131 141 142 130 121 111 102 116 116 124 114 127 116 112 129 128 119 137 111 127 125 141 104 113 127 130 108 116 131 121 129 122 127 138 108 146 129 117 93 126 112 109 135 138 121 137 117 124 135 121 126 117 124 133 130 119 137 130 115 133 126 132 120 136 133 136 120 129 116 133 119 134 114 138 118 131 128 119 135 137 116 110 131 133 132 123 119 122 119 140 121 112 137 129 111 143 114 130 133 117 120 125 111 129 136 123 121 117 121 114 138 143 126 109 137 112 126 142 144 138 117 115 133 127 118 103 130 111 126 133 145 127 116 119 128 128 125 116 118 142 122 139 117 135 123 120 121 121 119 149 134 114 124 119 132 135 128 138 144 115 122 118 112 123 113 122 107 135 115 140 119 134 136 135 117 115 135 126 113 127 108 112 122 118 131 124 123 118 118 115 145 132 114 122 117 113 121 129 132 130 122 120 134 110 118 123 133 117 112 134 113 138 118 131 131 138 116 146 119 113 134 139 118 137 108 149 125 105 124 119 122 155 111 142 122 134 136 106 117 115 119 134 114 118 120 128 116 125 132 129 145 115 112 108 100 119 111 142 134 133 144 137 117 125 138 113 105 136 116 117 117 124 120 117 118 134 133 124 137 117 117 108 117 129 118 134 112 141 118 138 142 115 123 112 133 113 121 135 142 111 106 133 123 124 132 131 129 138 134 138 129 125 128 131 118 120 126 125 116 130 109 124 137 142 133 118 122 128 120 110 106 126 120 114 124 128 135 132 117 118 131 136 119 122 108 130 137 131 115 113 131 108 135 160 127 152 128 128 138 111 125 125 124 122 114 134 127 131 127 151 132 101 141 136 132 130 119 125 113 117 109 108 150 121 127 131 113 126 146 125 127 121 127 110 111 130 146 128 120 147 131 144 100 123 119 102 133 125 127 119 122 116 117 131 121 127 102 103 136 121 120 103 133 125 118 128 118 139 136 114 121 132 134 118 121 122 119 102 142 114 127 115 117 123 129 120 144 130 137 145 116 130 98 101 134 119 116 147 126 133 122 132 118 134 137 130 128 102 109 143 116 112 130 143 136 112 129 116 120 132 108 124 125 136 146 124 117 151 136 143 134 120 119 138 101 128 122 124 143 121 115 141 134 133 133 122 137 119 116 133 123 123 110 129 140 113 119 116 111 116 135 136 149 115 124 116 135 125 129 130 114 120 128 144 120 123 118 142 122 104 136 136 120 112 125 126 130 133 124 125 139 121 123 110 111 137 126 131 136 120 130 124 139 132 114 119 135 142 127 134 119 137 156 132 125 110 118 135 122 127 114 103 142 131 136 135 121 115 115 106 146 134 140 141 131 134 129 133 131 127 134 142 129 158 122 143 132 129 131 132 116 126 128 131 138 127 135 99 137 121 108 120 135 129 122 133 126 156 120 134 131 144 111 127 137 149 143 128 142 128 117 132 137 106 133 128 128 130 124 140 135 118 133 146 118 144 110 127 125 129 132 131 138 151 132 135 120 124 137 120 136 132 138 155 119 133 126 130 135 131 143 131 150 148 126 106 137 102 139 122 137 125 123 123 136 134 124 118 146 131 119 140 133 123 144 125 134 124 129 117 122 148 123 120 136 137 142 152 115 136 153 131 117 135 137 122 116 124 130 140 142 128 133 127 142 126 139 122 128 151 123 118 121 156 139 146 117 134 141 124 124 153 114 122 122 134 111 145 162 127 134 134 106 129 128 150 126 137 145 161 136 135 134 140 111 148 123 131 144 121 112 132 127 137 133 131 115 141 107 146 148 106 126 116 137 116 133 123 120 109 151 135 146 153 148 120 149 122 122 132 129 130 148 124 159 113 115 126 152 145 148 140 138 133 147 135 128 140 150 132 128 137 115 122 138 144 147 125 149 125 122 114 130 109 134 126 123 135 127 134 139 112 132 122 118 135 134 140 149 125 116 149 140 119 124 139 147 111 108 132 160 139 130 117 129 132 113 126 118 136 141 130 148 126 118 121 139 130 123 111 131 127 130 150 135 115 138 152 146 142 138 124 139 135 148 144 150 137 149 118 135 149 114 131 122 127 142 127 127 129 129 146 116 119 131 138 125 128 141 139 121 131 134 141 135 129 131 165 121 158 126 119 134 126 141 128 135 133 136 148 152 132 119 115 127 149 139 157 132 109 137 119 137 130 170 134 134 143 125 121 132 140 121 115 118 156 139 131 112 131 126 140 139 135 128 150 121 148 146 140 111 132 138 139 140 159 152 111 118 126 138 142 136 147 161 113 120 162 130 108 139 147 145 131 117 159 145 160 146 126 107 122 155 146 113 143 145 133 139 110 136 127 107 142 123 136 131 140 133 138 118 123 122 140 140 136 119 126 132 117 133 121 149 114 142 157 136 157 114 125 148 121 133 128 149 149 126 135 130 140 108 140 121 127 119 128 142 157 142 124 133 125 134 137 152 127 155 122 131 155 118 130 152 122 128 136 131 127 131 146 139 153 126 142 117 134 128 126 147 128 126 135 141 142 172 114 125 135 131 126 133 120 154 114 136 140 124 141 134 126 136 131 161 135 137 123 139 135 106 138 136 136 149 140 146 154 128 138 142 127 139 144 144 135 127 146 124 120 126 109 140 151 127 130 138 145 128 159 124 155 143 129 124 135 116 165 142 130 143 105 124 141 113 148 129 138 123 135 147 139 123 131 130 137 130 144 133 129 145 149 140 128 121 144 108 144 120 128 144 164 115 132 115 147 144 132 140 146 123 135 147 133 133 135 117 165 142 149 151 143 134 124 132 138 125 127 132 124 134 129 133 134 108 131 138 130 128 138 136 131 118 136 143 136 106 149 127 129 147 146 133 142 148 135 155 138 120 138 143 151 123 165 160 140 145 129 156 124 128 138 140 136 142 121 142 130 121 131 122 145 148 144 113 126 125 128 134 143 144 138 130 125 125 131 135 138 142 139 106 138 121 110 162 136 145 132 132 159 127 133 118 131 122 137 147 119 153 143 139 127 139 164 130 137 134 137 156 152 145 123 131 134 132 120 164 131 136 138 126 134 151</counts>
			</dataPoints>
		</scan>
	</xrdMeasurement>
</xrdMeasurements>