File: data/XRD/_misc/old/XG-750C/W6823-1A_absolute_2th-om_10-130deg_PIXscan_56min_3.xrdml
<xrdMeasurements xmlns="http://www.xrdml.com/XRDMeasurement/2.1" xmlns:xsi="http://www.w3.org/2001/XMLSchema-instance" xsi:schemaLocation="http://www.xrdml.com/XRDMeasurement/2.1 http://www.xrdml.com/XRDMeasurement/2.1/XRDMeasurement.xsd" status="Completed">
	<comment>
		<entry>Configuration=Factory configuration, Owner=User-1, Creation date=7/8/2013 4:01:53 PM</entry>
		<entry>Goniometer=PW3050/65 (Theta/2Theta); Minimum step size 2Theta:0.0001; Minimum step size Omega:0.0001</entry>
		<entry>Sample stage=MRD Cradle; Minimum step size Phi:0.01; Minimum step size Chi:0.01; Minimum step size X:0.01; Minimum step size Y:0.01; Minimum step size Z:0.001</entry>
		<entry>Diffractometer system=XPERT-PRO</entry>
		<entry>Measurement program=C:\PANalytical\Data Collector\Programs\Jorrit\2thom\_absolute_2th-om_10-130deg_PIXscan_56min.xrdmp, Identifier={15BCCF57-2807-42BD-B5B9-ECC0B3DC9284}</entry>
		<entry>Batch program=C:\PANalytical\Data Collector\Programs\SimonL\batch4x_2thom_10-130°_z9.1_x0,10,20,30_y0_57min.xrdmp, Identifier={EED9823A-2BEB-424C-9252-345C4EF2834A}</entry>
	</comment>
	<sample type="To be analyzed">
		<id></id>
		<name></name>
		<preparedBy></preparedBy>
	</sample>
	<xrdMeasurement measurementType="Scan" status="Completed" sampleMode="Reflection">
		<comment>
			<entry>_absolute_2th-om_10-130deg_PIXscan_56min</entry>
			<entry>PHD Lower Level = 4.83 (keV), PHD Upper Level = 11.27 (keV)</entry>
		</comment>
		<usedWavelength intended="K-Alpha 1">
			<kAlpha1 unit="Angstrom">1.5405980</kAlpha1>
			<kAlpha2 unit="Angstrom">1.5444260</kAlpha2>
			<kBeta unit="Angstrom">1.3922500</kBeta>
			<ratioKAlpha2KAlpha1>0.5000</ratioKAlpha2KAlpha1>
		</usedWavelength>
		<incidentBeamPath>
			<radius unit="mm">320.00</radius>
			<xRayTube id="1010048" name="Empyrean Cu LFF HR (9430 033 7310x) DK442154">
				<tension unit="kV">40.0</tension>
				<current unit="mA">40.0</current>
				<anodeMaterial>Cu</anodeMaterial>
				<focus type="Line">
					<length unit="mm">12.0</length>
					<width unit="mm">0.4</width>
					<takeOffAngle unit="deg">4.2</takeOffAngle>
				</focus>
			</xRayTube>
			<xRayMirror id="27010001" name="Inc. Beam Cu W/Si (parabolic MRD)" hybrid="false">
				<crystal type="Graded" shape="Parabolic">W/Si</crystal>
				<acceptanceAngle unit="deg">0.800</acceptanceAngle>
				<length unit="mm">60.0</length>
			</xRayMirror>
			<sollerSlit id="21010002" name="Soller slits 0.04 rad.">
				<opening unit="rad">0.0400</opening>
			</sollerSlit>
			<mask id="22030007" name="Fixed mask 2 mm">
				<distanceToSample unit="mm">220.00</distanceToSample>
				<width unit="mm">2.00</width>
			</mask>
			<divergenceSlit id="22010007" name="Fixed slit 1/8°" xsi:type="fixedDivergenceSlitType">
				<distanceToSample unit="mm">220.00</distanceToSample>
				<height unit="mm">0.19</height>
			</divergenceSlit>
		</incidentBeamPath>
		<diffractedBeamPath>
			<radius unit="mm">320.00</radius>
			<sollerSlit id="21010002" name="Soller slits 0.04 rad.">
				<opening unit="rad">0.0400</opening>
			</sollerSlit>
			<receivingSlit id="22010001" name="Fixed slit 4°">
				<height unit="mm">5.88</height>
			</receivingSlit>
			<detector id="7010017" name="PIXcel3D 1x1 detector" xsi:type="areaDetectorType">
				<phd unit="%">
					<lowerLevel>30.0</lowerLevel>
					<upperLevel>70.0</upperLevel>
				</phd>
				<mode>Scanning</mode>
				<activeChannelsEquatorial>255</activeChannelsEquatorial>
				<activeChannelsAxial>255</activeChannelsAxial>
				<pitchEquatorial unit="mm">0.05500</pitchEquatorial>
				<pitchAxial unit="mm">0.05500</pitchAxial>
				<readOutPeriod unit="seconds">0.135</readOutPeriod>
			</detector>
		</diffractedBeamPath>
		<scan appendNumber="0" mode="Continuous" scanAxis="2Theta-Omega" status="Completed">
			<header>
				<startTimeStamp>2024-09-04T12:25:35+02:00</startTimeStamp>
				<endTimeStamp>2024-09-04T13:21:41+02:00</endTimeStamp>
				<author>
					<name>PRO-MRD</name>
				</author>
				<source>
					<applicationSoftware version="6.1b">Data Collector</applicationSoftware>
					<instrumentControlSoftware version="7.0E 20130304">XPERT-PRO</instrumentControlSoftware>
					<instrumentID>0000000011142674</instrumentID>
				</source>
			</header>
			<dataPoints>
				<positions axis="2Theta" unit="deg">
					<startPosition>9.99826193</startPosition>
					<endPosition>129.99755682</endPosition>
				</positions>
				<positions axis="Omega" unit="deg">
					<startPosition>4.99913096</startPosition>
					<endPosition>64.99877841</endPosition>
				</positions>
				<positions axis="Phi" unit="deg">
					<commonPosition>0.00</commonPosition>
				</positions>
				<positions axis="Chi" unit="deg">
					<commonPosition>0.00</commonPosition>
				</positions>
				<positions axis="X" unit="mm">
					<commonPosition>20.00</commonPosition>
				</positions>
				<positions axis="Y" unit="mm">
					<commonPosition>0.00</commonPosition>
				</positions>
				<positions axis="Z" unit="mm">
					<commonPosition>9.100</commonPosition>
				</positions>
				<commonCountingTime unit="seconds">32.895</commonCountingTime>
				<counts 201 204 176 200 204 202 195 193 196 193 195 205 214 202 197 198 188 200 182 187 201 185 216 212 228 190 243 200 214 229 196 198 197 200 223 202 194 195 189 210 197 203 208 179 208 198 194 205 207 207 194 172 203 192 215 190 192 176 197 192 195 215 182 193 197 197 196 209 200 186 164 241 196 217 207 195 198 214 198 212 201 210 194 203 189 220 210 208 232 199 193 184 208 173 202 184 192 165 211 188 200 190 185 193 200 189 190 197 198 199 182 193 187 205 190 213 215 189 189 199 188 192 193 185 206 192 193 188 195 184 205 201 183 201 190 206 211 182 206 197 190 208 187 171 194 181 187 189 204 185 188 192 191 183 194 195 215 180 175 186 200 201 192 190 186 201 186 200 203 200 220 164 191 200 176 186 195 201 199 210 187 194 157 193 170 160 203 206 203 173 179 179 190 181 212 191 193 193 230 175 192 207 157 174 190 180 188 213 158 196 185 162 183 197 204 175 164 188 170 188 200 179 177 192 175 183 190 209 155 170 188 168 171 184 155 187 185 193 199 192 206 186 187 171 178 168 191 187 177 196 179 170 163 182 179 199 191 182 179 178 179 199 179 164 172 191 191 195 166 199 200 170 188 188 174 150 166 188 193 186 145 177 181 186 186 167 182 177 161 163 194 188 173 199 164 156 184 170 209 160 167 164 162 160 161 176 179 165 161 161 156 174 188 161 189 168 172 173 150 175 184 185 187 159 173 190 179 185 177 203 190 161 183 169 163 181 174 177 168 190 184 159 201 187 172 163 173 184 164 158 160 171 152 166 167 184 183 174 167 200 195 191 184 179 184 184 153 165 180 162 184 152 177 145 159 166 171 163 174 183 185 180 181 160 179 171 171 174 155 180 162 180 175 157 181 179 180 159 167 164 148 172 143 184 187 158 151 174 174 167 160 158 166 168 147 151 157 171 162 160 155 144 178 145 178 157 166 157 159 178 170 169 190 158 144 158 174 173 150 169 163 136 163 167 141 161 158 143 163 159 158 164 186 175 142 175 158 179 166 164 181 180 167 173 152 159 196 150 170 171 149 184 156 134 167 151 155 153 194 163 146 179 167 189 146 159 168 154 132 163 152 149 189 165 179 142 165 157 148 184 160 150 152 185 162 151 154 166 134 172 180 176 144 174 151 170 170 159 160 160 155 164 185 162 161 159 166 154 169 181 165 160 175 179 155 153 147 168 171 172 160 183 181 155 145 166 159 162 137 176 146 167 136 171 145 150 161 165 189 166 163 146 172 159 154 167 145 145 150 149 166 161 156 146 153 150 143 157 165 169 150 168 152 154 154 177 179 169 163 170 164 144 161 197 143 151 153 150 164 158 174 166 168 152 172 158 151 154 176 153 164 153 149 151 173 153 176 169 154 156 147 178 151 180 153 160 149 169 126 140 150 162 146 181 182 150 162 174 173 178 178 169 157 160 172 173 160 167 179 155 145 162 159 164 157 143 142 144 144 153 123 160 170 143 165 170 159 180 158 179 150 154 175 163 154 132 158 165 139 140 168 163 167 163 142 156 151 149 168 163 176 145 184 147 159 134 153 148 158 170 161 144 168 171 155 148 152 162 148 149 181 147 157 172 133 174 189 150 159 163 147 160 170 158 146 135 159 142 140 147 128 162 141 174 156 145 160 153 164 154 148 168 137 155 145 150 154 151 170 170 157 186 166 138 160 180 170 163 146 155 158 159 156 167 156 150 151 148 158 158 143 159 131 148 153 155 156 154 144 176 162 167 155 171 168 163 155 166 143 167 143 163 151 154 178 154 147 164 160 190 155 177 154 139 171 168 160 141 143 171 133 153 140 142 151 132 149 169 170 155 169 170 173 174 146 144 151 161 140 158 172 148 156 148 166 148 149 156 159 161 175 140 141 148 168 159 157 143 160 164 166 159 165 142 160 131 148 165 166 146 152 137 162 167 162 176 165 137 171 151 170 138 169 151 143 147 166 179 167 150 149 151 165 160 161 155 191 149 177 128 178 156 155 150 194 171 164 161 146 134 144 143 135 137 171 162 133 139 146 135 157 156 145 127 148 151 154 137 161 155 154 163 156 152 175 156 173 157 160 159 173 143 170 154 155 157 158 154 168 148 154 195 156 176 161 144 160 140 175 147 149 181 157 139 155 160 173 136 177 159 180 192 162 154 156 161 160 158 146 161 150 173 150 161 164 149 154 154 165 161 164 165 159 169 195 161 137 156 145 148 154 158 147 146 169 183 168 138 147 148 160 157 167 149 157 177 133 175 158 171 180 162 154 175 143 155 144 140 176 136 142 170 154 165 160 148 142 154 154 166 155 192 192 157 167 121 166 156 132 152 151 170 139 146 156 187 147 164 163 165 177 167 155 158 161 182 154 157 158 167 163 168 165 160 147 156 150 142 180 146 156 158 152 158 158 163 175 150 186 163 175 168 140 180 184 159 167 162 161 156 138 155 145 156 170 131 165 165 165 164 149 170 150 161 161 133 178 170 171 173 177 173 151 153 157 149 136 157 156 142 182 167 168 150 164 168 142 163 164 151 155 161 180 166 139 158 153 140 166 164 145 147 136 160 162 156 173 151 155 178 133 165 154 156 155 160 160 173 158 153 167 163 178 165 182 152 176 142 150 190 163 156 147 162 168 162 147 177 140 139 157 161 149 172 149 167 160 147 156 183 152 137 146 166 150 171 161 148 207 160 189 178 175 149 139 171 154 152 161 158 165 181 151 158 163 170 159 156 144 150 177 135 153 157 150 156 127 142 169 166 128 169 160 175 161 177 171 178 159 130 131 151 173 173 169 182 145 168 151 151 174 137 163 140 180 156 164 167 158 176 145 146 163 147 148 174 154 154 169 128 174 165 168 141 140 151 172 155 175 156 152 160 165 147 160 150 161 140 153 137 180 151 154 155 184 162 170 127 181 147 183 126 151 158 152 168 146 161 148 150 149 172 136 148 148 160 154 149 148 149 171 164 171 180 155 148 145 145 156 136 165 146 167 141 162 189 164 176 170 169 151 184 156 154 173 161 152 141 172 152 174 179 144 159 141 154 168 141 164 151 157 150 146 166 168 143 162 192 177 155 142 130 171 167 146 146 150 166 154 140 161 167 126 169 139 151 159 162 154 168 141 161 145 176 141 154 165 132 143 153 146 158 142 151 175 146 138 174 170 151 165 154 146 159 141 150 165 143 125 143 149 174 160 156 132 135 153 147 153 156 153 168 143 137 168 157 151 148 152 167 138 140 148 148 133 155 145 154 155 149 149 140 140 149 156 154 162 165 132 148 129 149 146 175 154 141 154 179 143 152 146 146 135 153 140 152 159 135 137 167 148 138 136 178 143 151 133 167 152 141 152 135 136 144 117 142 167 114 149 140 148 127 145 148 164 147 149 142 170 151 146 129 157 172 143 158 136 151 152 120 149 147 146 135 158 152 145 147 158 158 165 147 166 152 148 150 153 156 151 147 148 146 137 170 148 136 153 143 150 138 141 143 129 147 129 123 136 151 145 172 133 121 145 140 173 171 123 125 139 145 151 141 158 116 141 129 140 112 127 139 167 155 137 141 142 145 163 146 130 128 142 138 128 136 156 148 143 154 106 142 138 110 149 134 144 146 123 118 149 146 141 143 127 138 133 127 150 146 141 127 144 144 142 160 139 147 145 131 159 148 157 154 140 137 143 143 130 146 138 127 147 150 132 148 146 133 141 134 136 125 141 151 128 150 151 158 141 165 148 138 144 140 128 126 136 132 134 145 140 142 141 135 139 123 140 132 149 137 115 136 120 133 148 132 156 153 136 134 134 134 124 136 121 133 141 147 127 126 146 141 148 143 128 112 139 145 141 123 123 136 136 118 125 126 125 135 138 143 141 123 144 140 135 129 136 119 149 122 138 133 132 142 142 144 121 123 105 118 138 138 134 117 128 114 135 133 134 121 154 145 111 134 128 131 140 138 131 121 146 146 140 126 157 113 137 131 129 147 131 146 129 139 116 118 132 125 116 136 119 111 128 123 136 114 133 117 120 127 145 115 135 132 108 121 134 139 134 125 145 130 127 120 109 165 130 140 129 126 128 104 124 116 127 130 120 129 102 139 123 136 118 137 136 132 126 147 139 135 152 125 125 131 129 135 124 109 113 114 123 113 161 124 125 130 135 131 126 133 119 117 117 108 143 137 111 124 120 113 147 142 118 119 130 120 141 108 133 99 133 129 119 122 116 133 129 110 150 122 109 132 95 132 108 126 146 163 127 119 127 105 140 125 114 117 128 126 127 120 126 131 134 115 137 142 125 135 146 103 164 138 126 119 118 128 117 126 128 111 132 121 106 140 124 121 129 118 120 134 118 118 119 124 122 109 115 124 136 136 126 118 119 117 140 138 134 115 117 122 132 131 103 115 123 132 116 125 117 132 119 147 123 143 131 119 100 115 116 112 126 141 119 117 122 111 121 129 124 126 129 136 109 120 115 129 126 119 145 99 125 149 124 131 123 109 131 123 135 136 113 114 117 130 117 112 124 119 119 125 119 111 134 110 117 105 113 136 136 112 117 105 111 113 93 124 121 104 129 111 103 113 111 115 106 118 125 123 118 108 134 126 129 126 129 131 121 114 120 133 130 137 120 128 114 119 111 114 115 115 120 134 130 104 127 131 131 131 137 109 114 115 123 124 111 113 123 120 133 124 136 105 123 108 117 134 113 124 129 119 111 136 132 112 112 119 120 115 108 153 109 114 106 114 109 124 132 118 111 131 99 117 124 112 113 124 97 109 97 93 118 113 117 129 110 107 101 121 106 129 117 105 94 124 122 130 114 123 124 117 136 110 103 100 110 103 121 118 126 131 132 125 122 119 97 106 117 101 112 127 113 116 113 99 130 123 130 111 109 121 131 118 130 119 119 103 115 128 102 122 98 133 103 105 113 115 118 128 114 127 98 100 133 118 127 93 108 116 99 127 112 128 106 119 119 126 87 124 133 128 113 110 101 109 122 94 104 99 134 135 120 117 121 121 108 105 129 122 127 122 144 141 113 116 113 117 100 128 110 111 125 99 111 127 124 106 119 118 119 98 134 115 108 108 108 120 101 131 108 122 111 113 116 106 130 107 114 114 122 111 115 112 123 103 110 96 121 121 114 116 117 85 116 92 103 93 107 130 118 112 126 132 89 131 104 141 108 129 108 108 111 97 133 101 119 115 116 111 103 125 109 108 107 113 106 116 132 114 122 116 123 98 119 105 126 122 125 125 106 119 105 116 89 111 119 114 124 108 132 83 113 116 104 111 110 121 144 116 121 109 116 117 124 100 106 106 116 102 119 98 124 94 99 140 126 123 109 115 121 115 125 131 112 100 98 121 114 117 104 108 128 129 107 125 97 90 103 103 113 128 114 104 106 124 94 96 107 105 105 144 120 115 120 111 115 101 105 111 129 109 112 108 115 93 112 105 117 134 116 117 120 86 116 102 112 113 117 98 114 105 111 111 104 98 123 115 111 133 106 126 102 110 108 100 117 107 100 122 116 110 126 98 115 112 125 99 107 124 109 84 118 117 109 115 92 109 101 116 115 103 108 90 91 110 116 101 96 118 120 123 101 114 125 115 118 108 108 113 113 110 118 116 113 118 116 120 110 106 108 96 92 119 132 120 113 122 123 112 112 111 99 114 110 107 123 99 107 114 126 111 103 122 139 113 116 91 120 110 108 119 107 117 107 119 124 101 131 101 95 127 119 123 109 101 111 121 116 131 110 125 118 101 105 119 110 103 111 124 109 121 77 100 124 129 128 120 99 111 109 117 127 96 109 96 106 110 115 77 125 110 115 109 111 109 100 96 126 118 121 121 108 88 125 100 114 107 113 99 98 130 122 104 99 117 105 102 113 96 100 105 95 117 88 101 93 125 117 120 118 89 93 109 106 117 104 100 99 133 112 113 105 120 105 122 111 106 118 102 131 110 130 118 133 111 123 128 113 118 109 126 122 134 105 117 98 95 100 122 102 106 100 107 91 97 90 101 125 123 119 85 110 109 118 95 103 92 107 132 124 115 111 100 106 126 110 130 108 115 101 115 103 94 110 99 109 107 118 130 90 109 121 99 120 109 117 96 118 108 111 106 126 125 109 108 109 109 99 96 121 100 105 122 122 106 101 97 114 116 108 105 112 122 102 119 118 103 131 109 106 123 121 127 113 106 127 90 100 118 116 126 112 139 128 117 101 108 112 93 114 96 101 126 117 107 111 100 125 112 100 120 101 108 113 120 122 130 95 100 107 109 114 127 103 104 126 123 131 108 92 105 105 112 113 119 112 121 118 118 114 117 118 111 113 119 125 110 99 120 106 109 102 113 102 104 117 109 123 101 106 134 109 132 100 97 127 115 108 110 103 100 109 127 102 121 99 118 99 115 110 126 109 124 116 120 94 112 121 89 103 132 103 119 110 119 109 111 120 112 116 119 107 129 95 119 97 108 109 117 111 114 107 99 114 96 111 101 120 116 102 131 114 104 135 99 109 104 108 111 120 119 113 99 118 111 100 114 115 112 135 115 119 129 106 102 113 110 111 100 91 108 114 113 121 125 115 118 117 130 134 105 108 113 109 112 99 104 106 112 101 120 106 117 129 101 114 113 93 104 99 110 99 113 104 117 94 108 111 110 107 106 137 134 110 128 110 110 93 103 105 120 129 120 105 113 126 114 105 118 109 117 120 103 119 120 122 124 90 102 120 109 121 113 114 119 138 119 119 105 114 111 131 123 99 105 103 109 127 96 126 115 130 130 107 128 109 112 100 118 103 90 115 104 107 100 106 108 125 115 121 112 124 108 107 109 111 114 95 103 95 83 124 113 92 103 126 116 133 105 120 112 115 92 116 125 98 108 112 110 117 105 112 114 103 125 146 119 94 131 111 127 109 121 108 111 100 103 125 114 114 105 91 124 129 135 137 110 117 101 100 124 128 117 114 129 125 122 111 124 93 116 117 110 122 100 125 106 117 98 108 110 99 107 119 130 115 114 100 141 111 116 121 137 98 117 129 116 129 117 99 104 111 100 117 106 111 108 150 130 93 113 95 109 109 107 97 101 106 118 106 118 113 122 114 116 114 118 118 120 113 123 111 97 109 117 116 129 118 136 110 115 106 112 122 113 119 118 126 100 112 104 102 118 119 104 105 121 139 107 101 118 116 123 102 126 111 104 125 122 117 120 139 102 107 104 131 117 122 109 121 104 115 138 88 119 112 109 114 116 112 120 106 98 127 93 125 96 121 96 101 113 105 93 135 125 105 131 102 117 134 109 99 102 113 109 118 116 102 114 127 109 124 95 122 158 119 120 125 127 105 114 119 126 116 119 119 121 106 128 121 104 116 101 123 107 99 102 132 107 136 116 85 133 116 125 134 110 98 113 101 117 116 96 110 142 113 112 126 116 112 121 129 118 130 112 119 132 127 107 114 141 114 123 116 110 125 130 130 148 113 129 110 112 127 123 116 111 118 107 122 115 117 131 117 114 112 123 118 110 133 132 133 114 124 115 107 110 126 107 123 133 112 130 112 112 126 140 126 134 120 124 134 114 135 140 125 121 130 115 108 124 115 109 122 129 141 123 115 125 112 128 139 103 114 98 126 151 129 100 124 119 117 117 113 133 104 110 137 112 129 134 135 124 112 125 121 115 115 130 120 118 121 113 105 133 129 121 117 138 146 129 116 132 127 157 151 116 125 133 115 138 129 145 112 111 130 137 122 122 137 130 129 132 121 120 130 112 140 118 138 140 123 119 130 143 143 141 116 134 146 145 121 140 134 141 139 140 141 156 143 150 139 146 140 129 167 134 145 176 147 156 169 170 153 180 176 175 187 212 226 200 194 187 195 212 228 186 225 216 210 201 205 185 223 208 190 187 203 201 184 189 173 183 189 169 179 166 179 159 191 150 127 175 158 138 135 157 129 144 130 146 150 135 135 140 142 121 146 141 122 111 116 113 112 132 141 120 129 118 146 132 116 114 147 139 109 113 133 113 124 113 112 123 120 118 120 113 120 138 115 145 132 121 138 123 110 100 103 118 113 103 131 139 110 113 149 119 108 128 116 132 134 124 117 100 119 117 101 114 116 125 123 118 108 130 118 118 109 107 120 114 149 108 109 110 126 114 106 121 112 119 116 121 115 112 95 125 118 127 109 108 116 137 111 122 120 115 133 105 109 125 110 139 123 117 122 110 105 119 118 124 120 116 104 131 119 116 108 129 122 105 120 128 105 110 117 115 128 127 129 129 117 123 122 95 111 105 118 115 125 105 139 100 136 108 117 122 118 116 113 125 116 128 106 114 119 119 108 118 107 105 107 108 111 114 102 114 118 127 112 125 122 106 112 130 136 122 115 119 109 116 125 105 103 104 130 120 121 113 105 106 116 98 123 120 130 96 113 124 94 126 118 141 133 126 107 143 122 118 116 116 114 118 116 121 120 131 123 91 114 115 122 125 104 136 109 121 128 100 139 125 119 118 118 127 116 123 140 122 125 128 111 119 111 127 123 112 129 124 114 126 115 135 126 121 116 127 133 122 112 95 121 129 115 101 114 120 113 129 139 122 131 126 108 102 129 111 119 107 128 111 108 110 100 109 119 106 109 133 106 101 124 105 121 98 106 104 123 115 114 113 118 106 124 107 117 126 116 122 107 103 110 108 113 112 113 110 124 104 105 123 104 112 139 126 108 97 128 133 121 108 122 107 111 116 136 112 102 102 104 128 107 119 96 100 114 109 120 121 95 117 124 107 102 129 110 103 106 117 101 120 108 91 133 107 120 116 124 102 111 105 116 109 104 111 108 115 121 117 103 114 115 118 124 116 106 112 116 110 118 102 119 104 114 119 116 144 115 112 135 113 120 97 100 114 115 117 117 125 134 103 123 121 117 108 108 132 118 120 112 107 120 101 103 123 141 111 106 122 122 116 113 138 132 116 113 120 130 116 106 116 118 114 120 129 124 122 110 109 103 113 87 108 127 112 106 109 110 109 114 130 112 113 108 112 121 119 117 123 103 106 123 123 126 129 115 98 107 116 109 135 87 118 98 140 113 97 116 98 115 111 115 110 107 128 120 119 104 129 113 130 113 139 103 99 105 107 110 110 139 125 113 120 98 106 119 108 113 107 114 126 121 135 107 129 101 105 111 119 96 116 127 98 121 118 104 111 134 108 110 115 111 119 113 121 118 138 107 114 116 98 110 95 106 118 111 127 99 122 108 106 108 113 118 133 126 110 108 141 133 125 98 122 93 122 131 118 117 111 107 114 105 110 98 113 120 137 113 112 143 122 106 124 119 120 122 102 128 120 115 130 145 121 101 109 108 120 112 122 133 132 124 121 126 120 109 134 90 117 116 111 139 130 121 105 128 118 105 102 115 119 113 119 122 123 116 113 121 115 103 109 108 108 104 98 133 136 94 118 98 138 129 102 112 97 147 103 114 127 120 99 113 117 117 108 116 125 124 117 124 115 106 122 121 137 103 121 100 99 118 116 118 98 117 105 125 136 124 111 113 130 135 123 118 114 121 125 121 108 111 122 126 112 113 105 119 105 116 136 123 120 98 109 120 108 116 123 112 95 122 134 113 105 115 123 125 122 122 94 113 108 123 136 113 121 120 107 104 99 112 121 127 118 101 121 114 109 139 97 111 128 109 110 118 122 121 125 117 128 119 115 91 106 107 120 112 115 117 139 97 111 112 112 105 106 116 112 112 119 120 110 106 109 106 107 118 110 104 117 119 109 111 121 102 115 138 103 123 117 122 108 126 131 138 119 125 112 124 122 102 128 123 117 101 106 135 111 133 121 123 111 93 104 128 119 121 119 127 139 122 115 87 115 109 121 121 119 132 110 115 122 131 116 104 123 123 122 119 115 113 118 116 102 119 112 132 111 122 148 113 110 126 103 123 111 121 110 120 129 106 101 114 123 114 111 93 123 115 110 105 115 99 109 107 118 99 118 108 110 129 110 110 125 127 103 132 114 119 115 105 141 111 120 113 107 97 121 128 114 114 113 111 94 100 112 90 105 112 121 139 107 104 115 111 134 133 101 113 127 122 117 113 112 112 109 131 135 107 114 121 124 131 128 110 118 130 114 120 122 131 123 107 103 116 116 108 115 109 116 116 118 100 122 100 127 134 113 98 150 113 126 114 108 123 93 126 126 106 111 120 117 128 110 136 132 120 111 91 116 102 103 123 127 96 112 120 96 125 116 107 102 105 107 102 110 130 129 113 111 110 124 100 116 107 127 124 129 137 112 127 122 114 129 123 130 106 116 115 123 109 119 107 116 127 102 127 114 111 103 115 119 135 119 135 116 103 118 93 116 106 99 122 127 116 100 113 117 107 103 128 118 129 110 123 118 127 110 129 126 94 124 116 121 112 129 110 105 121 133 134 125 114 112 104 123 134 125 104 109 134 118 117 121 134 119 115 109 115 131 118 100 122 112 117 125 99 116 108 127 116 126 110 125 132 115 122 110 120 116 114 120 109 156 109 122 105 130 111 130 139 120 139 115 127 110 108 103 119 122 127 114 117 122 110 137 97 129 96 100 116 119 122 114 124 129 120 112 117 108 111 115 95 120 105 128 105 114 126 109 131 113 116 133 117 101 122 117 117 114 107 112 104 133 119 123 100 124 114 109 103 107 112 120 123 126 115 110 135 121 121 93 101 115 115 129 111 122 124 102 131 116 119 124 96 139 127 112 109 113 136 111 120 139 110 119 107 115 123 115 132 123 116 108 117 121 133 136 111 116 122 115 125 103 128 117 135 110 104 119 123 113 124 118 107 122 114 116 121 110 131 124 115 122 113 109 103 108 114 130 114 109 117 115 123 118 137 127 94 119 123 114 120 114 114 107 140 107 118 97 133 123 99 100 90 122 132 123 119 114 130 108 145 112 108 91 126 118 114 125 104 108 132 132 104 117 106 118 121 103 116 131 113 130 106 110 116 118 117 113 116 103 105 107 122 105 117 110 118 139 106 104 137 112 104 140 104 109 134 126 107 118 107 109 106 121 137 98 125 111 119 105 121 105 108 108 126 104 113 110 120 119 127 105 127 116 114 119 122 118 98 115 105 108 116 127 109 105 133 120 107 122 113 120 124 135 117 111 106 108 129 131 102 110 129 102 96 133 128 129 96 112 133 111 125 127 143 122 128 109 116 114 114 115 105 120 122 112 139 134 127 139 119 108 122 153 129 110 116 113 119 120 121 130 140 129 133 126 118 105 115 136 107 114 118 122 143 131 111 122 119 119 109 123 115 114 134 118 122 110 126 122 127 121 125 138 128 112 126 106 132 107 114 128 101 119 126 111 112 118 118 113 113 113 114 122 112 111 114 114 131 122 129 116 123 118 103 118 116 122 116 112 112 145 129 136 131 128 105 109 137 108 121 130 120 123 119 128 108 105 106 118 113 121 120 128 119 107 117 111 114 137 109 117 108 122 120 106 112 127 118 117 122 126 130 131 136 137 126 134 122 141 118 125 128 119 114 118 128 127 105 94 114 123 132 135 119 115 115 94 109 117 118 129 108 110 119 115 140 121 121 129 112 139 110 116 127 125 113 129 129 96 124 113 109 133 143 136 101 130 123 122 124 144 125 117 113 103 125 117 117 109 103 123 103 108 117 127 114 123 102 130 130 96 102 111 132 102 135 131 106 114 109 109 129 137 104 125 112 120 126 103 119 118 114 137 126 106 118 129 135 122 116 128 119 115 110 127 120 140 111 137 126 109 120 129 121 118 118 129 105 121 128 102 113 137 120 118 105 108 102 112 99 122 103 116 129 124 104 109 116 103 110 126 106 119 119 115 92 134 116 111 111 126 110 132 128 118 133 115 111 116 142 141 134 121 143 115 125 134 144 99 133 113 110 130 106 130 120 109 116 115 133 130 115 122 118 129 109 111 114 135 128 114 129 126 98 120 116 125 122 112 115 122 133 115 126 127 121 116 119 134 118 134 132 121 132 124 124 118 104 121 125 116 114 104 115 114 130 119 141 142 111 146 121 113 125 125 108 111 124 133 118 121 108 129 134 134 111 137 135 120 109 127 134 119 119 119 123 111 118 114 136 113 123 99 130 101 111 104 132 130 128 122 134 136 119 114 124 134 132 131 130 128 107 131 120 136 131 135 121 118 111 98 103 129 111 127 101 135 126 136 113 138 122 133 145 117 113 102 126 133 116 121 105 123 140 121 131 125 124 112 118 130 91 123 126 118 112 113 112 123 118 108 131 118 121 112 119 120 126 118 126 115 112 84 105 135 123 117 111 130 126 117 121 124 110 116 132 143 108 135 141 137 118 125 119 121 96 107 106 125 144 125 123 124 122 129 109 110 111 121 106 136 135 120 121 120 123 137 109 130 132 131 125 111 110 112 116 130 109 122 118 109 108 130 111 133 120 125 112 136 140 120 112 129 123 110 110 138 127 146 108 112 111 114 123 113 137 130 113 116 125 120 102 112 127 119 128 123 108 129 134 113 123 145 110 109 131 129 134 113 120 127 125 111 127 144 107 123 124 124 114 117 134 111 135 119 147 112 117 130 117 124 125 126 115 119 117 118 130 123 110 118 112 121 146 113 138 148 118 110 107 119 115 115 131 123 121 131 127 125 132 129 128 126 138 113 114 119 141 136 110 122 128 114 125 131 111 139 129 125 118 141 106 113 107 123 118 113 137 128 122 128 116 120 122 120 99 134 112 131 105 127 128 120 104 137 138 118 116 111 148 130 127 129 134 117 109 108 133 117 125 133 114 127 101 123 127 122 127 128 119 138 108 111 107 155 125 129 116 132 128 123 112 122 114 131 120 131 128 115 108 120 117 120 124 111 123 119 125 115 114 122 111 116 118 123 134 101 122 122 119 128 119 116 124 123 123 105 130 117 122 134 123 100 122 124 116 109 110 139 101 115 127 115 114 105 108 132 109 115 124 117 109 107 111 110 130 127 112 115 133 109 141 111 131 113 116 118 101 110 126 103 140 119 127 113 106 106 128 123 139 124 136 107 139 121 122 119 131 128 118 145 129 110 112 130 143 107 115 113 93 127 111 134 130 135 105 123 119 126 121 118 132 124 92 126 114 119 121 113 125 141 121 125 111 121 115 112 104 107 113 125 144 108 136 123 121 124 121 111 132 117 124 121 126 124 119 109 153 142 97 139 113 114 138 115 122 120 115 126 127 132 110 127 136 127 128 118 122 99 130 118 112 124 107 120 128 116 120 120 127 136 109 125 114 118 107 129 125 127 117 129 125 122 113 107 129 112 123 128 135 110 128 131 121 131 110 147 119 114 128 123 133 107 133 118 107 130 127 134 132 124 151 122 135 114 117 110 134 116 103 130 93 108 108 130 117 117 129 122 127 148 121 130 127 129 121 125 124 107 123 124 128 112 120 116 113 121 121 137 118 125 104 108 117 126 110 131 138 112 139 117 109 106 119 121 107 121 112 134 107 138 98 125 109 124 113 127 115 105 124 101 127 119 114 123 121 116 114 126 136 118 122 124 116 115 125 130 95 116 112 112 123 134 120 110 122 116 123 114 108 110 108 125 125 113 129 137 141 121 116 111 108 123 116 130 111 113 132 120 125 137 126 133 122 114 124 117 117 137 105 118 124 113 141 113 122 137 119 124 129 116 117 113 105 120 113 126 117 126 122 132 115 130 111 120 113 130 129 119 105 122 124 126 106 117 124 133 111 125 115 135 107 114 93 132 124 118 106 115 103 127 124 138 125 100 131 122 137 130 110 110 124 120 120 117 126 118 144 133 111 139 119 124 133 110 99 109 105 118 106 114 113 110 127 119 123 117 118 128 114 138 100 135 119 117 124 123 128 106 117 104 107 125 109 105 116 116 132 116 136 119 109 137 133 137 121 128 128 113 130 92 120 115 118 107 110 126 117 139 107 112 103 112 105 118 124 122 121 138 138 130 133 107 132 111 146 99 113 126 133 101 123 101 107 115 111 119 117 127 120 125 113 120 109 123 134 119 120 132 116 116 129 131 137 125 129 116 120 122 127 110 118 104 127 111 130 119 141 122 123 128 125 113 124 128 123 125 112 96 132 108 131 137 97 118 120 111 116 133 114 123 139 124 118 97 148 113 113 104 110 112 126 107 139 116 129 128 128 140 125 110 142 126 113 112 131 130 127 133 130 120 106 107 142 98 126 120 119 117 125 123 97 127 124 97 122 119 125 143 135 126 124 128 124 120 122 125 123 114 126 125 115 112 121 138 113 114 118 131 114 115 113 137 154 120 109 132 129 114 125 137 118 119 110 122 109 109 119 127 110 130 126 112 121 130 122 117 108 117 124 110 120 140 126 109 110 148 107 110 109 141 124 112 129 124 118 120 128 126 104 122 113 112 120 150 142 114 149 119 125 133 130 107 132 113 114 118 129 110 129 112 87 129 128 127 114 107 111 125 118 114 121 105 134 127 118 103 125 118 125 137 115 123 147 111 135 113 111 125 123 102 113 130 109 111 119 135 118 127 118 101 121 116 122 110 113 105 135 110 132 137 106 118 135 118 125 127 107 133 121 147 121 119 116 124 119 128 120 134 123 109 125 117 121 119 123 120 135 114 113 115 116 136 101 126 130 126 119 109 126 112 126 113 121 109 120 119 109 114 121 124 117 147 107 120 139 125 129 134 108 101 117 122 128 126 131 120 125 135 108 99 129 116 131 115 141 117 119 124 129 124 110 120 142 125 114 108 111 115 132 127 122 139 114 121 114 119 116 110 109 116 122 100 125 111 121 126 127 149 123 133 120 131 120 114 123 142 119 110 104 109 141 116 124 119 137 126 126 118 116 124 144 134 99 123 130 105 107 114 97 125 140 128 126 120 120 119 131 137 132 101 116 105 126 105 122 124 130 127 104 114 131 124 127 118 121 140 128 119 127 124 128 124 131 118 124 127 122 101 114 116 123 120 127 90 124 126 111 120 117 113 133 147 119 129 124 130 131 111 127 116 119 126 87 133 118 103 121 103 145 128 123 117 115 110 104 122 126 140 133 108 120 107 114 117 108 128 104 119 127 115 126 126 107 125 110 114 152 130 129 125 128 115 117 141 134 117 114 128 123 121 118 118 124 118 115 120 124 111 121 136 125 130 126 115 121 116 118 122 123 107 112 121 129 112 107 134 132 123 123 120 130 111 110 143 103 113 126 126 121 116 120 120 105 109 131 95 108 114 117 133 125 121 112 133 113 115 126 125 103 119 111 102 104 131 99 114 125 135 128 113 129 113 99 101 88 116 112 146 113 122 120 108 117 138 126 105 107 117 121 114 118 107 105 116 114 120 129 109 115 117 121 106 118 126 115 120 143 140 121 132 131 128 103 135 115 109 110 106 119 121 116 128 112 144 111 117 113 134 121 150 133 108 132 119 128 120 129 105 134 130 103 131 110 100 126 127 122 142 125 111 138 112 118 108 123 130 106 128 98 96 117 124 102 127 109 136 113 112 96 126 120 122 105 115 131 104 114 118 120 130 115 121 121 142 121 132 133 137 121 100 105 133 116 106 135 120 125 125 154 107 128 106 125 127 132 109 136 114 128 130 114 118 114 115 104 127 118 132 128 141 117 135 123 109 121 119 111 128 106 115 102 95 114 116 133 116 113 116 117 112 141 115 124 109 123 117 107 122 116 120 118 136 156 134 103 104 122 132 109 130 124 118 117 113 121 132 140 126 130 123 108 126 131 121 130 126 124 110 111 114 120 108 134 116 108 124 118 112 117 115 118 140 127 107 123 125 109 131 134 120 105 133 118 98 108 129 109 126 114 130 113 136 118 138 126 123 138 120 105 121 128 107 119 115 124 111 100 133 127 111 117 114 111 136 135 107 123 129 121 105 115 114 111 132 129 141 88 120 141 120 134 114 126 131 122 134 108 127 133 145 110 116 115 115 139 140 127 127 103 132 149 140 115 122 123 119 112 127 106 116 118 123 133 131 122 131 95 135 121 117 137 129 112 120 133 118 127 124 132 115 121 116 122 118 120 88 131 129 115 123 135 107 109 130 136 120 102 116 124 122 129 129 121 131 152 122 127 142 119 129 117 112 124 122 142 131 117 113 130 113 123 116 135 125 135 132 110 114 121 123 126 107 121 124 108 132 128 112 121 131 126 129 127 127 101 125 124 122 114 119 126 113 121 113 111 129 125 137 122 116 122 131 131 129 90 106 123 125 141 123 97 129 138 143 111 142 144 138 131 120 130 100 115 110 124 133 138 123 109 96 136 134 105 115 116 119 146 117 130 145 109 115 122 136 122 106 116 146 135 121 116 148 137 144 125 123 125 110 137 130 136 134 125 121 115 152 126 123 105 124 128 121 129 119 134 127 118 116 125 128 122 145 121 117 132 128 140 129 133 128 105 109 153 133 123 131 116 127 127 131 103 134 144 125 112 119 137 136 123 136 123 129 124 120 132 110 127 120 134 127 142 134 140 133 146 120 107 123 152 125 130 111 119 136 142 127 134 136 143 127 147 121 140 129 154 153 108 144 145 145 130 138 126 142 148 139 163 124 113 112 138 133 128 135 164 151 156 136 138 128 143 119 131 137 118 113 131 133 154 128 138 168 138 126 135 134 127 127 126 129 141 128 121 122 102 129 135 155 136 134 118 138 112 141 123 123 138 146 132 129 126 112 137 128 128 132 114 135 130 123 121 126 120 127 111 131 113 125 133 115 129 109 133 128 122 111 125 108 119 126 126 112 131 117 138 116 117 122 115 118 125 135 123 136 118 129 116 111 125 118 144 124 139 114 118 109 138 128 140 120 109 131 126 104 125 105 130 128 119 132 120 122 116 131 127 118 123 132 113 107 124 127 119 131 105 105 121 116 115 112 128 135 109 127 122 125 108 109 118 129 140 127 132 120 123 119 123 127 120 128 108 124 123 123 98 115 130 128 126 130 132 115 129 109 105 98 112 119 138 119 114 118 103 121 131 118 122 133 135 138 127 115 143 131 129 127 100 127 108 111 123 127 111 133 139 112 123 120 144 124 130 113 129 124 105 130 130 126 116 110 113 128 124 124 103 128 113 115 116 125 115 114 121 129 123 128 121 113 122 123 143 137 113 128 103 137 120 131 122 130 118 109 128 111 118 106 116 131 107 115 117 111 119 121 109 113 125 134 114 136 116 122 113 127 103 139 147 117 103 133 121 91 122 95 136 141 111 125 118 98 123 127 114 132 134 118 101 125 126 108 125 124 139 117 130 129 117 140 128 125 120 112 95 131 123 135 111 128 125 92 126 100 123 124 107 130 119 146 112 118 128 104 126 120 126 96 131 137 104 105 117 126 130 128 120 114 117 111 128 128 131 113 121 114 127 127 133 123 125 122 148 111 100 125 121 107 133 151 107 117 126 129 135 136 136 128 118 121 106 137 119 115 125 131 120 137 128 120 121 115 109 126 143 104 120 119 108 131 117 129 106 120 101 125 96 115 132 125 118 119 121 117 134 113 111 127 119 120 136 105 106 137 121 113 111 123 112 108 123 115 111 110 109 120 136 128 118 123 129 105 123 125 106 111 126 125 96 124 103 104 116 126 133 142 115 112 105 115 126 125 133 132 124 138 113 114 115 120 113 134 100 123 123 128 111 121 104 103 139 120 126 119 139 120 117 121 115 122 106 114 120 135 108 127 120 124 133 116 87 119 109 142 123 123 116 112 112 129 118 128 125 125 134 135 110 119 111 101 112 111 141 106 129 104 118 122 129 124 118 103 102 102 119 134 120 111 113 101 117 119 101 129 131 109 109 130 121 117 133 125 110 127 127 106 126 127 113 116 119 116 109 123 111 93 114 139 122 114 126 104 133 113 124 117 111 101 133 117 119 100 97 125 126 129 113 111 120 112 130 123 132 123 114 107 94 113 107 111 136 138 115 136 125 130 96 117 125 102 119 108 119 117 123 113 139 124 131 117 137 123 113 123 111 140 118 112 128 111 114 122 134 122 107 122 129 128 118 108 132 130 109 114 109 107 110 128 114 122 120 120 101 125 127 123 135 122 125 126 96 117 100 132 98 108 120 111 117 135 123 128 108 116 132 106 111 120 114 130 123 120 154 129 136 123 108 114 115 123 120 136 117 109 119 119 133 119 129 111 114 112 104 143 121 108 143 129 116 102 110 113 124 114 132 120 121 117 118 125 120 109 127 118 121 120 122 105 118 111 111 120 113 121 140 145 103 117 121 98 127 118 99 147 127 131 107 126 132 118 121 122 102 125 111 119 113 117 120 122 108 109 109 116 117 111 120 113 108 123 106 130 114 130 114 111 128 105 127 121 116 118 132 119 104 127 129 112 125 97 121 98 110 123 127 113 123 124 105 106 120 114 107 111 137 111 114 121 108 128 137 112 112 115 112 125 106 105 100 117 118 128 124 103 117 110 137 122 125 121 119 118 112 116 122 105 122 126 117 116 101 113 110 127 117 112 114 126 105 121 124 118 121 108 112 113 121 134 125 134 113 99 102 131 116 123 123 112 110 123 130 111 123 114 100 146 124 132 115 112 124 114 104 122 128 120 99 133 123 131 120 127 123 126 113 126 118 106 110 116 127 121 112 135 128 117 105 116 112 122 110 123 116 119 122 115 107 104 130 120 135 117 120 107 132 126 112 122 123 108 117 121 122 136 124 114 118 112 124 119 128 121 114 125 125 117 117 123 135 122 94 118 96 104 95 113 136 119 122 123 106 105 113 111 104 124 121 113 117 123 119 114 120 120 115 115 112 120 116 113 130 104 115 133 123 121 103 112 124 116 112 127 114 118 104 132 116 113 125 117 126 110 90 124 104 116 127 107 93 107 121 123 104 109 116 113 105 136 117 114 115 114 116 121 127 117 112 95 121 126 119 117 137 141 125 112 111 131 134 126 101 115 109 114 111 117 122 131 96 94 118 124 126 110 105 118 107 127 122 124 134 120 126 123 113 112 124 129 112 104 137 119 112 119 117 138 119 143 116 116 111 112 130 113 113 119 104 131 116 112 133 125 121 106 121 129 111 104 138 105 109 124 110 118 124 101 117 136 114 125 109 136 111 122 119 109 124 123 119 114 123 117 111 127 105 119 131 120 124 137 139 96 106 124 127 143 116 93 123 102 120 117 104 100 126 116 109 111 140 114 114 128 140 120 125 123 114 120 113 122 133 101 133 89 103 115 133 113 120 127 120 124 115 102 122 117 118 123 136 113 122 104 136 116 135 121 127 116 133 105 113 109 118 129 101 135 118 136 102 93 119 123 117 123 122 108 104 121 108 100 117 107 108 129 112 120 112 125 125 107 106 112 122 116 109 91 101 111 105 113 112 108 101 120 112 127 119 131 98 113 120 126 100 132 107 97 122 114 120 126 110 106 95 114 130 115 116 115 124 115 136 115 118 117 110 111 128 132 102 140 118 127 120 117 115 100 110 115 108 122 102 137 113 115 99 117 136 126 124 128 95 119 107 147 128 122 121 117 96 100 121 119 120 127 132 112 105 129 103 106 134 111 103 124 116 128 117 96 130 119 118 114 120 112 110 121 113 118 107 119 125 121 107 97 109 107 105 126 126 123 119 110 122 110 116 118 120 141 128 97 128 122 124 114 120 106 111 105 134 97 106 110 137 114 121 118 115 116 107 117 128 118 111 117 104 123 109 92 128 116 117 97 119 116 127 122 89 118 91 110 134 131 131 121 102 114 102 110 112 111 115 106 119 104 112 130 112 100 123 126 94 120 112 115 135 134 120 109 116 114 110 115 118 101 117 104 112 127 107 110 131 105 102 122 127 119 131 112 110 122 115 108 123 108 120 112 123 112 118 115 110 109 137 119 109 108 141 113 110 124 119 107 119 113 113 101 104 135 122 106 142 115 127 111 128 121 117 116 118 106 108 120 118 139 114 120 119 128 113 112 124 118 137 125 123 121 125 113 108 106 118 105 97 114 119 118 102 112 135 114 120 102 133 134 119 125 133 122 126 117 104 98 83 118 117 122 107 108 107 104 105 100 113 115 118 118 112 130 113 101 117 133 117 123 113 107 121 124 140 150 128 111 110 115 119 113 110 102 134 135 117 109 112 93 91 118 105 119 123 101 116 107 138 101 122 118 121 127 106 124 115 122 122 137 122 116 118 132 143 98 103 127 108 127 127 126 124 112 120 104 122 116 123 121 116 109 114 106 141 114 110 120 124 136 129 102 131 114 120 133 106 114 120 135 126 125 99 117 124 118 124 107 129 110 121 128 108 130 127 116 135 127 133 115 120 123 112 123 100 103 120 112 109 111 104 133 130 123 139 128 118 124 115 117 115 122 121 122 122 132 138 125 110 136 123 115 119 102 123 129 107 122 123 122 134 106 94 104 102 122 115 135 116 117 112 119 124 138 123 118 107 119 110 133 132 118 112 127 110 115 111 134 106 117 135 117 127 110 104 129 104 99 135 125 108 118 121 120 113 112 99 109 101 114 119 133 115 111 122 115 128 109 143 128 112 110 115 103 114 118 128 138 109 137 100 123 99 112 111 121 128 126 134 116 116 115 107 102 112 104 110 131 124 121 117 102 112 110 112 129 116 126 133 99 103 123 126 103 108 110 107 99 127 121 132 106 119 102 98 136 97 99 120 122 113 103 124 88 110 110 121 117 123 126 120 108 119 98 99 133 102 110 112 109 114 131 112 111 109 132 127 108 113 115 105 109 105 113 122 124 108 118 127 122 107 103 123 110 96 120 106 131 123 114 119 100 97 129 100 117 114 132 119 141 131 116 108 93 110 108 117 122 100 109 116 130 115 108 122 122 113 98 109 120 117 113 113 119 109 114 112 123 120 95 123 116 119 119 130 118 118 93 118 99 105 126 135 95 133 122 103 92 105 104 98 103 120 115 120 93 127 108 117 102 113 112 105 139 127 120 107 113 137 120 108 120 120 113 125 112 110 98 124 126 131 140 118 123 106 121 119 104 124 119 142 102 101 110 137 107 129 117 116 119 102 134 103 118 118 124 113 118 115 93 117 133 113 137 105 111 121 106 116 117 109 98 100 94 100 120 109 114 120 112 113 111 113 117 114 125 102 107 114 124 95 120 119 103 100 121 109 110 86 118 134 123 102 118 111 110 120 100 120 122 99 142 105 107 102 106 111 113 110 99 111 116 128 109 88 108 117 133 109 126 109 91 95 128 107 120 105 113 143 117 129 112 111 99 110 121 110 125 122 121 104 116 106 108 107 89 108 118 106 106 104 133 111 105 114 99 101 97 103 120 109 115 110 117 108 111 105 107 116 110 113 124 114 96 114 107 97 113 120 111 103 119 112 124 110 103 112 99 121 86 94 110 111 117 108 104 109 112 106 117 126 128 101 120 103 120 122 102 114 112 110 100 123 106 119 122 133 129 109 106 108 116 105 129 119 128 118 122 124 133 114 104 105 119 114 119 113 114 109 124 116 111 110 113 113 125 88 124 127 128 101 108 101 118 105 117 120 123 120 99 107 111 120 120 101 115 118 97 110 97 118 111 115 108 114 121 111 108 132 110 114 117 119 126 95 125 116 112 128 116 116 109 112 110 106 120 111 117 118 111 105 112 121 124 109 103 117 107 108 120 121 121 119 125 107 96 108 117 108 134 108 101 130 97 113 127 125 114 104 97 134 131 103 120 127 95 116 128 105 128 111 104 100 110 128 79 94 101 105 112 105 96 125 92 105 114 116 101 128 118 113 107 126 110 127 124 118 101 115 98 117 107 106 99 126 91 103 107 119 94 120 119 120 113 112 103 104 91 99 123 114 137 107 124 126 125 116 128 113 116 114 126 113 117 104 110 110 89 121 116 95 120 101 112 109 115 116 111 109 107 96 114 114 113 99 108 110 102 128 132 98 107 106 116 112 112 106 121 108 113 124 105 97 107 110 119 111 99 127 109 115 130 116 110 98 113 83 124 94 118 113 107 105 101 114 107 114 124 120 102 113 117 109 122 114 107 121 108 131 101 92 109 124 115 99 98 113 99 123 114 103 111 101 111 93 110 103 105 115 112 108 99 135 111 101 100 122 133 101 111 110 121 130 101 95 111 114 113 121 111 111 113 99 119 118 108 106 127 110 109 92 110 124 116 113 119 108 133 117 104 101 119 99 110 123 116 106 120 95 119 112 96 112 103 104 112 107 140 117 93 124 87 119 112 105 123 105 123 116 107 104 112 110 126 105 116 137 135 109 115 109 92 108 115 115 100 108 111 108 115 130 125 124 113 128 108 111 119 128 124 124 109 107 113 111 136 102 114 90 97 129 97 118 111 108 129 110 109 118 116 109 125 115 117 108 103 112 93 92 105 121 107 96 105 133 107 100 95 132 76 121 111 102 96 121 115 108 102 89 116 108 98 105 112 110 98 107 107 111 112 114 103 123 113 82 106 111 100 114 105 111 118 97 110 97 100 129 108 103 105 99 108 120 106 114 108 99 143 124 145 116 100 104 118 104 102 105 119 107 129 113 118 113 104 112 104 114 107 112 107 129 109 108 103 123 95 114 106 105 115 99 95 112 128 100 102 116 132 118 128 112 127 125 113 119 101 108 108 106 112 86 110 108 102 98 111 112 111 124 113 92 128 109 109 97 134 125 117 95 121 118 114 105 114 123 111 100 104 116 96 129 110 110 114 107 110 98 103 96 97 110 102 99 109 100 113 118 95 106 122 110 98 136 106 129 121 118 106 112 111 107 100 117 92 102 117 123 111 126 105 107 108 101 104 117 110 120 100 112 108 115 102 109 98 103 91 121 118 105 106 103 100 111 115 117 95 110 113 120 124 106 99 131 110 121 118 118 98 120 124 106 128 113 108 121 108 106 99 121 99 115 131 111 118 94 107 107 131 112 106 86 107 119 112 108 118 105 112 122 113 107 101 109 116 99 87 95 105 98 110 117 100 105 122 98 118 113 103 125 112 102 96 121 111 104 114 97 101 97 87 106 97 98 107 113 103 93 91 135 107 101 102 113 110 131 127 98 104 113 114 103 108 100 108 127 114 112 106 104 121 125 125 114 100 125 121 107 93 116 102 109 94 101 111 92 118 106 92 129 92 128 106 111 97 94 121 126 137 110 109 100 105 114 111 112 88 96 113 105 95 118 87 115 108 125 131 109 102 102 107 114 106 97 99 99 105 107 103 108 113 118 111 96 104 116 76 129 114 117 111 114 121 106 99 102 119 101 121 93 110 111 105 118 114 117 112 92 141 120 94 104 102 113 115 123 111 121 114 105 116 102 122 113 118 111 95 107 103 114 104 109 116 116 118 96 120 97 124 98 113 111 105 114 100 105 97 95 114 125 113 111 119 108 106 115 117 94 98 117 121 125 108 106 121 105 113 113 97 112 96 115 117 105 112 99 105 114 99 95 104 107 99 112 101 99 112 109 106 98 121 120 127 102 80 116 123 105 111 120 96 116 110 100 111 97 112 104 106 96 116 98 118 76 92 118 103 100 100 98 102 106 113 118 119 116 128 95 108 103 99 104 107 116 106 101 109 101 102 117 125 97 113 120 103 106 123 94 120 115 98 117 115 106 111 116 114 106 119 112 109 108 116 104 114 118 97 117 116 126 106 113 103 122 112 102 102 108 108 122 93 90 116 95 110 114 105 107 109 108 96 93 113 100 96 108 114 97 114 122 116 122 105 108 102 103 108 99 108 106 85 106 103 102 118 119 113 106 116 105 100 108 103 113 113 91 124 107 125 128 119 97 107 102 100 93 107 123 104 101 93 117 112 104 113 113 93 102 109 101 83 109 125 121 106 121 94 97 107 111 116 122 92 122 103 125 102 98 105 106 109 99 114 90 116 112 99 107 94 109 104 119 99 110 118 112 92 109 99 111 107 104 95 113 119 100 95 111 125 110 105 121 115 118 107 103 84 118 104 107 99 94 128 110 109 113 108 88 104 117 100 120 115 111 112 125 131 101 111 119 100 98 119 121 127 105 101 108 116 103 110 100 101 114 104 102 102 118 85 102 94 116 102 118 116 108 112 114 118 113 105 93 109 109 123 98 100 106 94 106 123 96 120 94 101 100 98 115 102 102 108 93 118 114 131 96 116 105 119 108 107 95 99 100 91 97 111 120 106 108 119 116 117 111 104 126 108 119 105 130 119 116 103 97 93 86 110 120 95 115 106 108 109 105 98 97 122 104 94 100 124 122 110 106 117 110 102 111 105 124 91 114 107 109 117 125 125 100 113 98 115 100 87 127 111 122 117 104 101 112 126 108 117 113 106 103 110 122 108 111 97 128 117 126 121 128 97 97 118 139 102 128 99 121 109 115 100 119 97 99 100 105 95 119 106 115 111 107 123 103 130 117 110 105 96 92 120 108 121 124 116 97 108 131 113 117 112 129 111 124 108 115 114 88 120 113 120 112 99 120 109 114 116 91 119 112 101 124 106 93 107 116 127 117 111 113 102 106 108 114 119 110 103 116 112 126 104 103 112 91 127 113 102 107 110 88 107 95 111 108 92 120 114 120 124 103 115 99 96 114 111 99 109 116 111 115 120 106 117 112 121 119 117 114 123 125 103 102 114 115 99 106 100 106 97 121 110 100 113 102 113 120 115 94 116 121 110 111 129 121 112 122 120 83 117 127 91 94 100 106 88 117 119 95 97 110 113 92 103 106 115 116 112 108 119 96 102 122 101 107 105 110 86 101 90 100 91 111 102 127 101 105 98 115 108 114 92 114 101 85 93 108 118 131 107 112 104 98 112 82 101 110 85 104 109 109 118 104 101 91 115 98 94 103 92 93 102 120 111 109 110 92 108 103 110 105 117 102 115 98 89 103 101 101 109 124 107 103 91 122 111 112 113 94 102 126 117 124 98 126 118 109 95 118 112 113 99 110 113 110 116 86 98 120 113 102 103 111 106 112 106 100 105 124 100 99 121 106 109 115 98 114 110 98 101 102 105 103 126 107 113 122 116 109 105 106 103 100 106 116 120 112 103 115 92 125 108 126 132 103 105 94 96 122 88 109 108 121 87 122 116 116 96 110 101 111 123 104 96 108 113 104 121 99 119 105 99 101 92 100 112 99 115 96 123 104 123 112 103 102 97 97 98 102 100 104 130 104 120 103 91 96 112 105 124 115 116 114 108 99 103 110 106 104 111 85 103 96 104 99 95 108 95 83 114 101 100 116 93 103 101 92 119 107 107 105 113 107 107 108 105 120 121 100 100 104 109 93 106 97 104 111 110 119 124 105 108 93 108 109 108 107 104 103 101 122 95 92 99 108 103 103 96 125 103 92 110 95 98 113 144 95 127 88 117 101 103 107 115 104 119 112 115 137 113 90 116 104 95 111 99 90 97 88 115 113 89 103 127 114 122 113 127 113 107 107 99 103 111 103 112 115 114 115 120 108 127 113 117 110 112 121 108 97 106 93 93 86 98 117 134 104 107 99 108 113 107 98 105 113 126 124 107 121 113 82 144 113 100 105 110 103 107 110 123 117 115 111 94 118 119 110 106 85 101 117 102 122 104 128 110 113 113 111 105 144 121 83 100 104 128 104 93 105 114 110 117 124 111 107 115 109 99 107 122 101 108 101 120 94 98 102 106 111 111 112 103 94 94 102 117 101 102 105 99 113 101 125 101 114 115 105 98 113 126 113 122 101 94 115 97 114 112 111 114 110 110 103 98 103 120 98 112 113 121 114 106 128 109 103 88 96 109 108 113 92 112 118 109 110 130 107 101 111 115 116 100 127 115 95 123 124 111 126 114 119 111 87 99 106 109 117 116 112 111 110 118 110 106 102 123 112 103 99 113 95 112 130 116 114 107 135 107 98 103 98 107 102 85 101 118 120 108 119 103 115 104 103 116 109 113 114 117 128 117 119 95 117 127 112 99 104 91 121 119 106 116 101 112 107 101 108 119 110 103 114 102 127 110 118 105 101 106 125 119 106 121 110 114 121 107 101 120 111 109 97 119 100 117 111 111 97 108 108 106 124 95 113 110 115 99 109 123 119 98 117 125 100 118 101 109 101 128 121 100 115 100 110 113 113 103 112 119 112 99 120 117 109 108 121 113 115 129 111 114 120 109 108 112 106 96 100 117 117 131 100 112 105 121 106 106 98 108 109 114 102 119 113 115 113 74 106 111 92 105 96 114 131 120 98 99 110 106 121 109 111 109 129 113 105 108 127 114 132 111 106 118 121 138 101 107 98 101 95 96 111 131 139 129 121 120 117 103 95 119 106 103 117 97 95 119 105 102 121 96 107 112 101 107 106 102 102 110 126 115 94 110 138 123 117 105 112 107 104 99 110 110 116 120 112 129 112 103 112 107 116 118 119 115 116 99 106 115 99 110 114 106 125 121 100 113 126 116 128 99 106 107 109 98 120 116 117 120 115 102 107 107 99 117 123 99 110 101 105 122 127 111 108 105 110 108 118 111 100 112 123 139 130 113 118 136 105 123 115 131 112 103 113 133 115 94 119 105 123 117 134 114 96 116 99 115 98 100 109 110 111 96 116 125 101 116 118 125 111 107 121 113 106 101 116 115 123 112 114 102 102 111 113 107 110 92 116 127 132 114 113 115 132 105 123 109 113 96 116 111 130 127 110 125 119 121 105 142 106 112 110 95 116 124 126 118 110 112 117 112 117 129 113 110 113 105 109 126 120 111 114 113 99 113 105 117 133 124 114 101 114 115 118 118 96 115 115 103 118 113 93 96 119 110 124 111 128 97 139 106 120 105 117 100 121 109 107 123 107 135 108 114 116 116 96 124 124 86 119 115 108 112 120 99 121 104 127 122 110 134 92 110 111 110 105 112 112 103 118 124 118 114 120 110 115 93 102 116 108 115 118 107 108 121 125 106 120 102 103 114 112 116 116 99 105 100 112 109 128 108 112 119 102 106 107 101 114 113 119 88 116 124 104 117 115 104 105 126 113 103 114 109 117 104 128 125 108 100 97 131 126 120 130 136 123 104 111 101 104 102 122 89 127 116 106 115 108 110 116 117 97 100 143 122 124 100 97 108 114 113 106 103 112 108 108 110 101 109 135 126 131 100 134 135 127 100 108 124 109 93 107 109 107 105 110 117 111 130 123 119 115 103 108 115 129 90 112 111 111 119 134 122 120 122 111 126 89 97 123 129 117 111 97 138 140 129 105 104 112 121 126 108 110 108 126 117 109 124 124 117 121 104 116 117 108 119 124 126 126 128 110 114 109 93 106 113 126 133 116 117 126 143 127 120 139 96 111 107 114 117 109 117 100 115 125 131 112 127 127 100 115 108 110 120 114 124 110 111 115 109 119 115 118 114 119 104 106 123 107 137 113 128 128 102 117 118 108 119 107 106 108 92 120 112 115 112 139 122 113 119 118 129 140 109 106 111 128 108 107 111 134 112 134 115 116 112 110 140 106 127 117 122 125 124 124 108 143 126 111 110 108 129 126 126 100 127 111 122 120 112 95 118 105 114 130 138 152 121 95 97 119 122 116 120 123 108 128 118 103 137 125 93 112 115 111 122 101 123 138 123 132 129 116 108 121 100 150 124 115 118 110 140 120 103 101 107 133 117 122 133</counts>
			</dataPoints>
		</scan>
	</xrdMeasurement>
</xrdMeasurements>