File: data/XRD/_misc/old/XG-750C/W6824-1A_absolute_2th-om_10-130deg_PIXscan_56min_4.xrdml
<xrdMeasurements xmlns="http://www.xrdml.com/XRDMeasurement/2.1" xmlns:xsi="http://www.w3.org/2001/XMLSchema-instance" xsi:schemaLocation="http://www.xrdml.com/XRDMeasurement/2.1 http://www.xrdml.com/XRDMeasurement/2.1/XRDMeasurement.xsd" status="Completed">
	<comment>
		<entry>Configuration=Factory configuration, Owner=User-1, Creation date=7/8/2013 4:01:53 PM</entry>
		<entry>Goniometer=PW3050/65 (Theta/2Theta); Minimum step size 2Theta:0.0001; Minimum step size Omega:0.0001</entry>
		<entry>Sample stage=MRD Cradle; Minimum step size Phi:0.01; Minimum step size Chi:0.01; Minimum step size X:0.01; Minimum step size Y:0.01; Minimum step size Z:0.001</entry>
		<entry>Diffractometer system=XPERT-PRO</entry>
		<entry>Measurement program=C:\PANalytical\Data Collector\Programs\Jorrit\2thom\_absolute_2th-om_10-130deg_PIXscan_56min.xrdmp, Identifier={15BCCF57-2807-42BD-B5B9-ECC0B3DC9284}</entry>
		<entry>Batch program=C:\PANalytical\Data Collector\Programs\SimonL\batch4x_2thom_10-130°_z9.1_x0,10,20,30_y0_57min.xrdmp, Identifier={EED9823A-2BEB-424C-9252-345C4EF2834A}</entry>
	</comment>
	<sample type="To be analyzed">
		<id></id>
		<name></name>
		<preparedBy></preparedBy>
	</sample>
	<xrdMeasurement measurementType="Scan" status="Completed" sampleMode="Reflection">
		<comment>
			<entry>_absolute_2th-om_10-130deg_PIXscan_56min</entry>
			<entry>PHD Lower Level = 4.83 (keV), PHD Upper Level = 11.27 (keV)</entry>
		</comment>
		<usedWavelength intended="K-Alpha 1">
			<kAlpha1 unit="Angstrom">1.5405980</kAlpha1>
			<kAlpha2 unit="Angstrom">1.5444260</kAlpha2>
			<kBeta unit="Angstrom">1.3922500</kBeta>
			<ratioKAlpha2KAlpha1>0.5000</ratioKAlpha2KAlpha1>
		</usedWavelength>
		<incidentBeamPath>
			<radius unit="mm">320.00</radius>
			<xRayTube id="1010048" name="Empyrean Cu LFF HR (9430 033 7310x) DK442154">
				<tension unit="kV">40.0</tension>
				<current unit="mA">40.0</current>
				<anodeMaterial>Cu</anodeMaterial>
				<focus type="Line">
					<length unit="mm">12.0</length>
					<width unit="mm">0.4</width>
					<takeOffAngle unit="deg">4.2</takeOffAngle>
				</focus>
			</xRayTube>
			<xRayMirror id="27010001" name="Inc. Beam Cu W/Si (parabolic MRD)" hybrid="false">
				<crystal type="Graded" shape="Parabolic">W/Si</crystal>
				<acceptanceAngle unit="deg">0.800</acceptanceAngle>
				<length unit="mm">60.0</length>
			</xRayMirror>
			<sollerSlit id="21010002" name="Soller slits 0.04 rad.">
				<opening unit="rad">0.0400</opening>
			</sollerSlit>
			<mask id="22030007" name="Fixed mask 2 mm">
				<distanceToSample unit="mm">220.00</distanceToSample>
				<width unit="mm">2.00</width>
			</mask>
			<divergenceSlit id="22010007" name="Fixed slit 1/8°" xsi:type="fixedDivergenceSlitType">
				<distanceToSample unit="mm">220.00</distanceToSample>
				<height unit="mm">0.19</height>
			</divergenceSlit>
		</incidentBeamPath>
		<diffractedBeamPath>
			<radius unit="mm">320.00</radius>
			<sollerSlit id="21010002" name="Soller slits 0.04 rad.">
				<opening unit="rad">0.0400</opening>
			</sollerSlit>
			<receivingSlit id="22010001" name="Fixed slit 4°">
				<height unit="mm">5.88</height>
			</receivingSlit>
			<detector id="7010017" name="PIXcel3D 1x1 detector" xsi:type="areaDetectorType">
				<phd unit="%">
					<lowerLevel>30.0</lowerLevel>
					<upperLevel>70.0</upperLevel>
				</phd>
				<mode>Scanning</mode>
				<activeChannelsEquatorial>255</activeChannelsEquatorial>
				<activeChannelsAxial>255</activeChannelsAxial>
				<pitchEquatorial unit="mm">0.05500</pitchEquatorial>
				<pitchAxial unit="mm">0.05500</pitchAxial>
				<readOutPeriod unit="seconds">0.135</readOutPeriod>
			</detector>
		</diffractedBeamPath>
		<scan appendNumber="0" mode="Continuous" scanAxis="2Theta-Omega" status="Completed">
			<header>
				<startTimeStamp>2024-09-04T13:22:12+02:00</startTimeStamp>
				<endTimeStamp>2024-09-04T14:18:18+02:00</endTimeStamp>
				<author>
					<name>PRO-MRD</name>
				</author>
				<source>
					<applicationSoftware version="6.1b">Data Collector</applicationSoftware>
					<instrumentControlSoftware version="7.0E 20130304">XPERT-PRO</instrumentControlSoftware>
					<instrumentID>0000000011142674</instrumentID>
				</source>
			</header>
			<dataPoints>
				<positions axis="2Theta" unit="deg">
					<startPosition>9.99826193</startPosition>
					<endPosition>129.99755682</endPosition>
				</positions>
				<positions axis="Omega" unit="deg">
					<startPosition>4.99913096</startPosition>
					<endPosition>64.99877841</endPosition>
				</positions>
				<positions axis="Phi" unit="deg">
					<commonPosition>0.00</commonPosition>
				</positions>
				<positions axis="Chi" unit="deg">
					<commonPosition>0.00</commonPosition>
				</positions>
				<positions axis="X" unit="mm">
					<commonPosition>30.00</commonPosition>
				</positions>
				<positions axis="Y" unit="mm">
					<commonPosition>0.00</commonPosition>
				</positions>
				<positions axis="Z" unit="mm">
					<commonPosition>9.100</commonPosition>
				</positions>
				<commonCountingTime unit="seconds">32.895</commonCountingTime>
				<counts 243 235 217 204 207 210 193 210 235 207 210 238 211 198 206 214 206 217 239 209 212 216 210 222 206 223 216 234 214 231 198 215 221 221 215 202 235 194 204 202 226 218 226 196 230 227 226 205 207 238 228 230 230 225 228 203 241 220 238 231 215 214 234 211 223 201 213 230 192 233 201 237 203 217 192 212 205 226 218 220 214 201 205 214 197 192 172 200 186 222 184 221 210 224 199 198 230 211 230 213 215 213 207 208 207 220 197 188 210 212 230 206 197 224 186 210 214 185 195 213 194 217 179 211 188 194 186 205 191 189 200 204 213 174 187 210 210 217 218 193 198 188 205 213 176 202 203 189 215 233 205 217 218 212 214 191 181 194 190 174 203 213 193 202 182 194 180 205 182 215 195 208 207 205 208 198 172 222 208 168 212 208 175 180 189 195 216 197 214 165 178 227 190 185 196 175 186 189 193 181 199 203 182 192 201 169 218 206 182 181 203 193 197 187 209 197 188 216 207 192 187 196 207 199 198 180 181 172 202 213 172 186 202 226 186 209 177 205 211 200 192 200 201 211 164 174 164 188 197 204 173 180 170 204 185 170 187 191 193 201 186 187 199 197 170 198 179 194 195 194 192 184 186 192 186 180 190 199 189 213 204 220 192 192 179 171 220 200 192 190 194 181 175 190 199 174 189 195 163 179 164 177 189 193 187 192 218 209 180 176 172 182 167 180 174 194 183 170 165 154 195 204 163 185 175 181 167 166 177 172 156 187 164 175 176 196 168 197 162 184 183 171 171 177 186 162 205 161 193 193 178 190 171 175 170 158 178 192 177 187 197 191 165 164 169 164 193 150 182 162 185 175 173 173 191 153 157 165 163 168 196 145 193 183 159 191 190 178 162 190 181 159 185 200 165 167 191 184 141 182 190 170 191 179 168 181 168 189 157 172 182 171 179 172 176 163 185 196 151 163 178 177 160 181 165 180 177 173 182 169 161 136 186 172 170 152 158 162 163 181 197 169 157 182 169 173 163 150 157 147 168 168 128 149 138 173 162 181 174 148 173 158 175 157 154 148 173 159 169 147 172 166 174 177 151 143 174 183 174 158 157 177 158 177 185 170 174 148 136 147 158 164 201 168 180 176 172 165 183 153 141 159 179 155 156 162 158 156 176 166 161 166 183 146 141 157 169 155 162 137 189 159 189 162 159 151 168 170 176 181 163 196 165 169 167 167 144 140 178 161 171 156 142 160 168 154 166 179 178 174 149 157 153 160 169 194 151 152 167 176 157 162 197 210 158 164 165 144 169 145 156 166 158 177 164 146 155 147 160 172 166 167 138 148 157 160 143 152 156 156 168 152 164 142 155 159 168 154 165 161 173 152 169 168 130 163 171 163 182 152 136 138 172 155 155 154 178 168 165 175 142 159 161 148 163 146 162 148 148 155 157 156 142 151 148 157 154 144 160 185 150 141 151 163 159 157 163 161 144 176 136 151 154 190 171 168 172 132 141 158 146 167 160 157 158 135 142 151 142 153 164 157 156 158 152 135 159 161 157 134 169 147 139 149 155 146 133 145 165 155 162 172 147 140 171 166 139 158 142 157 167 160 183 158 161 161 171 152 164 167 149 141 172 163 169 127 152 144 159 145 159 166 142 158 155 139 146 176 177 144 167 182 147 162 159 151 135 167 177 127 167 160 164 172 162 143 143 159 153 143 162 161 145 145 145 152 147 170 146 159 168 139 172 134 160 141 134 174 172 152 163 164 157 154 154 144 134 143 161 168 171 156 139 130 130 165 134 157 158 165 133 157 159 146 170 163 163 158 153 166 168 131 132 166 168 155 136 145 163 150 172 175 170 171 169 153 144 149 158 163 153 140 167 160 129 162 160 160 151 153 160 166 166 159 168 168 158 154 158 171 173 164 167 146 151 152 161 176 149 166 159 140 170 151 170 125 167 166 148 148 171 154 142 164 177 148 168 136 156 161 150 154 168 164 157 155 150 162 174 171 164 153 156 151 150 150 175 147 159 190 207 185 154 146 147 158 139 154 164 167 160 178 158 167 149 150 173 173 162 160 150 174 158 153 164 158 140 173 152 166 154 175 171 159 192 154 162 158 162 150 166 186 145 150 164 169 153 166 165 173 172 163 174 144 133 168 160 141 178 177 172 149 155 180 171 188 149 183 183 137 158 166 185 166 152 163 162 159 181 177 140 140 140 159 161 141 163 174 205 154 154 177 172 156 166 142 157 162 172 201 151 162 161 164 195 163 152 141 162 171 164 182 172 163 171 172 151 149 159 168 178 165 158 148 136 174 169 167 164 171 168 161 156 178 193 175 143 161 163 156 166 156 155 174 165 170 150 170 181 145 147 164 155 147 156 167 162 157 162 158 177 141 161 162 176 167 179 167 163 185 175 180 162 168 177 155 150 156 178 138 156 168 173 165 160 179 171 187 147 168 140 178 154 151 168 165 162 191 141 169 175 159 155 173 147 177 198 180 158 167 151 141 180 186 159 188 173 190 170 146 157 156 169 149 154 169 192 172 163 165 165 155 166 144 180 194 168 140 159 163 166 196 162 149 148 170 160 191 159 159 158 187 167 168 172 158 169 172 160 195 179 200 159 174 168 164 159 184 174 152 171 162 161 184 166 170 163 163 170 156 162 173 162 179 179 158 162 166 180 157 199 168 173 164 168 191 178 182 174 163 154 150 185 184 165 171 163 185 176 152 145 172 171 160 155 171 176 177 150 167 145 171 180 180 185 160 197 178 168 150 168 167 177 153 169 162 149 159 161 179 163 161 177 161 190 178 163 169 174 154 181 154 192 177 138 175 157 192 178 199 158 159 171 144 188 170 177 187 197 192 169 182 166 157 163 162 178 175 164 156 160 170 184 154 153 178 161 168 205 170 182 180 152 196 153 174 181 165 174 159 145 180 160 169 156 174 198 157 163 180 176 175 144 179 159 171 166 159 173 158 169 187 165 148 153 145 158 156 156 156 176 186 164 177 153 167 165 175 158 178 144 161 174 175 145 160 166 143 148 177 167 154 179 177 153 170 152 176 166 167 181 150 189 181 161 166 152 169 163 147 173 166 179 160 168 174 163 184 171 167 154 169 161 183 177 176 164 133 159 163 154 166 157 138 151 141 180 156 184 176 159 153 178 160 139 176 179 163 157 181 155 161 154 181 161 186 177 169 176 189 139 154 166 125 182 180 168 171 158 155 172 182 159 164 154 157 158 184 151 162 166 156 151 133 184 169 157 168 173 147 159 183 190 170 166 144 175 166 152 169 164 144 168 156 172 170 154 139 177 157 174 141 166 155 140 145 161 166 159 151 147 166 142 153 148 147 156 143 178 163 169 143 162 183 148 188 141 140 149 151 160 162 158 151 136 167 153 169 182 156 144 147 171 151 158 162 149 160 180 158 149 152 163 176 150 155 129 163 174 162 162 165 168 169 152 156 147 145 149 165 153 161 165 144 165 168 159 148 155 139 151 136 142 149 156 152 152 176 127 155 143 150 145 166 182 136 154 145 141 156 142 134 149 173 153 158 150 168 140 165 154 157 168 158 131 152 155 132 130 166 146 137 147 149 150 141 173 158 152 155 184 143 141 152 154 148 138 151 126 170 153 170 165 136 153 135 131 134 135 156 151 119 158 147 133 119 121 141 153 164 144 145 134 147 158 139 143 133 134 141 154 144 164 133 147 143 141 137 111 155 135 151 139 124 150 149 159 178 141 136 141 147 155 142 149 155 149 142 161 128 135 140 148 137 154 137 150 173 144 130 169 160 171 165 166 154 158 133 151 140 140 148 141 147 155 136 156 148 135 164 163 132 128 144 168 153 143 156 142 132 149 156 161 127 155 138 147 128 124 128 164 136 137 142 144 151 151 146 147 146 153 137 142 158 126 129 139 103 134 120 149 147 129 143 128 151 149 133 154 157 129 131 137 141 119 137 145 158 137 129 150 132 150 144 131 162 139 132 141 137 147 132 150 151 133 144 114 153 158 133 134 127 161 142 154 130 144 139 134 126 133 147 138 127 126 128 129 154 121 150 128 126 121 139 152 154 150 139 121 125 124 132 131 139 130 139 122 146 145 146 129 130 131 149 126 142 134 145 140 155 142 135 131 137 134 133 131 169 120 139 137 148 145 125 136 125 140 138 142 107 128 123 146 133 122 137 146 138 132 138 140 143 153 143 135 129 136 143 127 118 136 127 138 166 128 127 135 141 130 132 137 126 119 135 134 146 116 137 126 127 129 119 130 131 140 111 134 148 111 130 123 122 119 108 126 139 142 129 114 129 139 124 123 132 125 128 132 122 133 129 129 130 132 128 113 127 146 105 132 134 122 113 119 135 138 135 121 115 132 142 145 118 120 132 162 137 119 116 123 120 125 144 137 112 132 151 129 119 124 123 107 130 113 126 134 141 127 153 120 116 120 137 132 128 106 122 112 122 124 112 119 120 125 125 141 129 142 123 144 109 121 130 127 122 110 115 124 139 134 143 116 131 123 136 131 124 111 115 128 108 145 126 135 115 128 126 143 138 117 115 118 144 103 125 121 136 106 126 127 118 112 140 134 110 117 132 119 134 126 115 121 117 118 123 146 135 123 129 109 134 132 119 100 107 105 121 110 126 127 108 138 132 107 115 128 141 126 127 120 129 109 124 127 111 112 112 120 126 124 124 112 132 123 116 134 113 117 108 115 121 114 111 152 133 120 126 134 116 106 126 118 132 105 131 122 115 108 131 122 130 119 143 127 111 130 111 118 116 128 117 121 136 120 116 129 108 120 126 125 123 120 110 143 116 105 119 104 111 115 109 136 120 119 122 102 104 127 123 123 108 124 97 117 104 130 126 138 107 112 109 104 120 113 106 123 120 138 110 115 121 116 131 124 130 127 113 115 142 141 121 112 103 106 125 113 105 121 131 123 112 115 125 119 133 115 114 111 120 106 124 106 109 116 124 123 115 128 117 122 112 121 112 122 119 116 126 146 110 126 119 123 108 104 130 111 126 123 115 102 122 109 104 118 118 111 115 113 123 116 126 108 115 125 105 107 134 107 108 88 122 109 132 108 118 102 105 123 126 135 120 113 107 117 105 119 134 101 116 120 113 113 96 117 100 122 118 112 127 116 118 121 102 100 132 116 114 123 131 126 126 106 115 97 129 109 114 103 113 117 115 107 125 112 108 109 130 132 112 109 116 118 96 98 111 115 134 119 97 106 141 105 116 102 118 105 130 103 89 120 119 99 110 115 108 105 104 109 118 103 94 139 104 100 114 117 134 136 121 115 106 109 111 129 123 132 117 89 102 115 105 121 113 111 112 116 99 123 102 103 117 106 120 109 117 94 115 129 129 104 111 119 119 113 134 104 117 113 95 114 112 129 100 122 106 118 99 113 119 107 106 113 128 112 126 117 96 111 97 108 109 105 118 121 128 95 108 107 128 122 105 112 109 91 133 121 105 95 105 114 117 102 111 110 114 119 118 105 98 103 102 119 130 136 114 115 110 115 95 126 108 110 136 104 109 102 112 116 128 101 106 112 104 104 108 92 102 110 99 129 123 110 112 104 118 105 114 118 86 124 122 110 122 97 112 101 113 99 99 118 100 108 104 100 116 123 116 98 121 105 105 101 100 116 99 110 95 118 108 117 108 97 110 101 105 110 101 99 106 98 117 110 129 115 111 96 117 120 118 111 112 114 113 113 121 113 114 121 118 106 118 111 118 112 116 121 116 101 100 109 101 110 132 91 113 105 112 95 111 114 101 112 134 115 106 88 123 121 104 110 124 109 86 109 104 111 105 101 96 103 114 99 109 95 117 91 107 96 101 108 114 114 106 110 95 115 121 141 104 111 108 115 99 115 113 96 110 115 84 110 126 115 114 130 109 109 125 101 110 122 121 112 99 100 105 94 102 103 125 103 113 94 99 99 126 110 107 111 107 86 93 116 118 111 114 109 95 108 123 105 113 108 90 103 105 101 108 91 112 118 97 108 99 109 104 105 107 113 115 109 104 99 108 107 116 90 96 116 111 109 113 112 115 120 105 111 115 107 100 89 110 106 118 108 116 98 110 95 139 105 107 108 113 130 126 125 121 97 109 125 143 121 107 101 115 116 108 113 106 104 92 116 123 121 100 103 128 118 122 115 110 120 111 129 113 101 132 108 113 107 107 107 116 103 109 107 95 100 117 103 100 123 100 119 107 96 124 90 116 121 121 127 109 95 116 105 100 103 129 108 110 120 97 132 106 132 124 106 108 107 98 108 119 103 121 118 97 104 110 107 104 102 114 94 107 114 95 121 104 113 105 108 114 93 107 94 118 118 107 108 117 113 98 121 122 126 111 114 107 124 115 116 103 105 111 106 113 120 104 101 98 101 112 120 114 107 116 106 123 115 115 111 115 105 97 109 82 88 112 98 94 105 120 116 94 86 119 107 118 106 116 75 102 113 110 106 104 105 114 109 112 100 89 83 109 105 92 107 100 98 121 114 112 100 115 107 104 111 101 106 106 89 100 123 87 117 103 98 99 102 125 103 105 101 98 124 116 126 109 95 118 104 121 107 112 99 127 126 94 118 111 111 109 105 82 127 116 100 101 114 120 98 98 105 114 130 104 109 111 107 107 103 93 115 117 108 118 120 97 102 101 132 113 104 106 102 114 106 108 122 101 114 112 99 112 98 95 119 115 128 110 108 112 134 112 94 114 111 89 103 107 92 99 110 121 113 114 116 115 109 83 109 106 90 121 111 121 97 119 95 87 133 104 120 90 113 114 127 119 103 105 102 103 93 91 113 96 101 90 101 113 104 110 111 100 115 102 114 108 113 109 90 101 98 116 109 100 119 124 104 107 97 108 90 89 103 119 108 119 106 116 104 92 102 102 126 125 96 100 110 112 103 99 124 120 108 75 97 85 112 126 102 109 77 108 101 110 109 96 110 95 103 98 108 117 106 98 115 102 103 96 113 92 104 92 108 118 119 110 134 115 112 109 111 110 113 84 130 113 114 105 119 112 92 120 119 113 125 92 100 108 108 100 104 99 114 104 112 114 107 99 119 102 130 111 124 108 106 105 123 99 95 104 114 106 125 108 135 114 123 109 93 114 124 98 102 91 109 128 102 107 102 117 104 101 104 110 110 109 92 97 106 107 119 109 110 121 98 104 103 121 129 114 100 100 108 101 97 116 105 106 112 102 109 112 104 115 98 126 97 117 114 133 91 100 108 120 97 108 102 113 93 92 106 104 124 104 111 113 105 105 111 117 100 89 108 109 107 126 96 104 119 103 109 124 104 106 124 114 102 108 125 101 123 129 111 98 107 101 119 109 101 131 115 100 98 103 102 100 124 104 83 114 88 97 104 117 102 116 105 110 135 131 111 111 112 108 103 119 104 129 116 120 100 122 114 109 126 130 111 127 113 113 105 113 122 129 109 96 97 127 127 117 96 107 118 121 101 97 110 117 92 100 109 106 104 106 124 105 111 119 104 125 108 115 91 108 97 110 107 99 119 99 122 115 97 108 100 111 118 109 121 122 95 118 104 108 103 125 97 102 128 111 113 112 107 128 104 93 103 115 125 103 106 119 107 122 129 119 123 105 110 96 98 113 101 106 115 119 112 96 115 119 116 135 123 106 119 116 122 99 127 113 123 100 94 113 112 135 103 104 125 102 113 118 104 90 127 113 104 118 112 114 108 113 117 128 117 119 121 109 124 116 126 135 128 127 118 122 131 127 111 131 116 145 114 117 123 131 112 118 112 123 123 134 135 128 128 130 140 118 129 112 152 120 141 133 121 128 141 116 114 123 127 117 131 111 129 146 151 145 142 136 152 129 150 169 131 190 166 170 159 165 175 192 174 196 182 173 198 192 172 179 211 206 206 190 204 204 197 175 201 159 162 183 188 180 199 185 173 157 171 149 158 165 186 134 129 138 138 149 162 138 127 133 135 121 116 128 139 119 124 130 139 128 131 138 140 124 114 118 135 118 133 133 112 113 126 107 124 116 131 121 107 119 140 115 129 119 106 106 117 106 125 118 123 111 113 100 112 104 129 132 113 123 113 109 100 110 122 113 128 92 105 102 114 97 106 102 101 108 107 93 108 129 98 118 117 113 105 113 104 111 118 120 107 118 114 120 120 106 108 122 115 123 114 98 121 102 128 111 112 97 133 101 100 110 115 136 113 92 121 116 105 89 121 104 116 135 117 92 125 118 111 124 128 109 116 93 125 130 101 109 104 126 125 118 95 108 139 115 120 108 106 120 96 127 124 101 114 104 122 104 130 120 99 114 83 106 123 99 108 123 108 112 105 105 105 105 107 114 103 116 109 100 103 102 115 114 119 109 132 120 129 117 107 119 102 104 128 103 109 112 113 127 121 106 141 107 112 109 106 112 106 106 120 116 112 118 118 100 132 110 114 131 112 102 105 102 115 107 115 122 119 131 121 115 96 112 94 128 104 103 114 110 103 101 123 96 105 132 111 121 97 97 125 114 105 109 109 110 106 93 111 109 121 109 135 106 112 108 99 112 109 109 112 109 114 111 125 104 112 83 116 111 106 121 112 104 107 106 123 115 94 95 112 101 115 124 105 119 100 107 145 112 111 101 101 93 97 109 111 106 116 98 105 109 121 99 104 112 135 112 111 100 116 102 116 114 104 120 116 117 97 115 110 119 103 115 106 107 104 107 111 122 104 108 100 115 113 89 107 123 115 97 97 111 112 121 114 87 94 113 110 125 120 111 115 121 115 98 100 117 103 110 110 113 121 112 109 108 110 103 119 101 136 107 116 116 121 93 120 111 98 127 124 107 106 98 126 109 100 116 115 123 105 110 104 110 118 144 92 111 112 121 105 98 112 130 103 96 112 120 114 105 99 125 117 109 102 108 104 101 120 102 109 103 103 139 122 102 118 111 127 87 107 104 118 125 126 103 109 101 130 102 106 108 133 128 121 125 125 123 100 116 124 128 113 111 112 104 120 113 118 108 112 118 106 111 117 96 122 115 100 93 121 126 88 103 106 118 105 121 102 104 114 112 132 102 119 119 115 112 112 126 103 124 118 96 130 121 102 116 129 131 115 93 114 126 118 112 112 111 100 116 100 100 110 131 107 108 115 111 129 125 117 115 130 124 117 126 126 126 124 114 114 88 117 129 108 99 112 99 95 111 119 124 96 116 117 105 112 117 124 102 108 88 116 115 116 109 112 99 103 116 106 99 106 126 102 118 116 111 116 97 101 105 121 112 120 95 109 101 119 98 120 108 121 105 108 100 126 93 127 118 108 100 122 111 103 112 122 88 114 105 132 114 130 119 113 120 107 125 105 126 104 99 128 91 99 122 117 125 119 95 93 109 106 124 114 129 107 84 108 118 106 100 104 113 130 125 102 105 111 106 102 126 106 93 96 90 102 95 118 121 106 120 105 111 129 119 102 128 96 123 106 121 119 107 118 116 104 117 105 104 120 123 113 108 97 113 121 99 118 111 107 103 106 109 89 110 107 120 118 90 101 115 109 117 104 112 115 117 114 116 128 105 110 115 124 111 100 104 115 121 118 122 106 108 115 93 80 116 94 109 105 115 105 112 112 100 108 95 106 118 107 103 110 105 127 111 99 131 109 99 101 133 110 119 120 108 106 109 90 104 111 117 103 106 106 117 130 98 115 111 112 98 107 109 115 97 99 97 106 102 114 129 127 115 97 126 103 124 121 109 109 117 104 105 99 108 97 118 124 113 131 95 122 123 108 108 109 105 141 103 105 130 109 102 112 112 112 107 109 120 110 102 135 110 108 126 105 97 114 122 118 118 121 98 114 126 114 134 134 96 113 126 92 105 117 121 98 104 125 108 100 108 109 105 102 106 106 127 114 114 110 118 135 115 150 110 114 124 128 132 100 111 92 103 131 104 93 98 102 131 111 101 106 104 101 103 103 122 124 112 101 123 91 119 115 106 125 118 133 99 122 118 127 115 110 116 114 116 116 111 109 108 122 126 117 100 130 98 108 113 109 100 102 100 124 119 120 93 113 122 96 111 114 137 92 98 108 124 124 125 110 110 124 101 123 105 86 109 107 111 115 120 121 115 99 122 120 111 122 129 122 130 116 113 115 120 112 114 127 110 110 103 122 114 113 116 101 116 93 102 118 104 104 110 112 104 108 99 132 118 123 120 123 112 109 103 96 118 113 115 106 125 100 120 116 105 127 109 109 108 124 112 99 113 117 113 104 100 116 114 114 118 117 120 132 119 120 132 122 106 101 120 120 114 87 128 128 107 102 108 120 124 104 126 115 119 117 120 97 116 98 120 120 102 114 107 102 100 116 113 119 111 125 118 105 147 139 107 110 107 99 108 110 89 127 125 104 138 110 112 107 123 98 126 113 98 110 109 107 116 98 108 101 136 99 111 115 120 122 108 100 124 114 125 117 115 114 117 111 90 94 123 113 123 116 136 113 110 112 117 123 99 92 107 115 104 132 128 115 136 107 108 95 100 124 132 122 124 122 127 103 99 126 127 130 108 120 119 126 109 146 106 119 143 119 111 114 114 115 113 106 97 116 110 118 110 114 130 114 121 125 109 131 101 114 118 101 117 107 113 96 133 131 104 92 111 111 119 123 118 121 118 97 119 117 124 122 125 130 104 106 112 104 118 106 114 108 110 122 116 116 110 134 125 110 113 112 109 113 113 89 115 120 139 120 132 112 116 107 94 108 115 115 122 112 129 101 118 99 90 111 103 119 102 100 137 111 123 111 109 109 118 89 136 129 112 115 125 111 114 101 94 128 117 132 114 119 113 116 113 115 110 128 122 115 126 112 112 124 124 139 118 109 108 116 138 87 135 109 121 111 113 111 113 113 101 121 117 104 121 130 119 108 129 114 109 110 114 114 112 121 113 110 114 122 113 116 130 118 124 95 105 129 122 104 134 117 125 116 104 117 119 131 113 97 106 115 100 117 107 112 123 103 132 121 101 133 125 122 116 111 106 108 116 93 124 125 96 130 119 111 115 124 106 118 107 90 115 112 102 120 106 97 118 108 127 105 128 111 114 130 108 109 121 118 88 125 126 123 121 109 113 116 99 100 114 112 99 121 131 104 130 125 122 116 115 119 90 115 105 105 93 99 142 107 96 101 85 122 124 104 109 119 104 115 111 116 112 121 124 125 121 115 128 103 120 129 105 124 112 113 115 125 123 115 122 94 118 109 103 111 107 106 118 120 108 101 125 115 135 109 100 124 110 128 99 128 105 123 125 140 121 132 127 107 121 119 109 129 114 123 113 125 127 109 119 119 118 124 135 142 124 101 123 120 119 117 135 136 131 109 110 113 111 121 134 120 122 113 115 108 110 128 123 106 112 128 104 116 134 113 121 121 126 95 103 124 103 124 115 115 112 103 101 127 130 126 121 115 120 122 119 116 120 106 125 105 123 102 122 120 102 123 109 96 117 115 113 122 114 119 113 121 120 96 126 86 112 113 118 115 109 127 114 132 115 130 109 124 113 111 130 110 126 138 126 115 119 109 107 119 118 119 137 111 128 100 123 121 121 103 122 100 92 138 100 122 117 130 133 121 125 118 139 122 119 116 108 123 118 120 122 133 123 127 110 131 136 135 123 119 123 120 120 120 95 118 108 119 109 128 114 131 128 129 113 103 98 119 114 120 130 122 103 114 119 122 124 132 111 127 111 108 128 107 108 116 113 111 118 125 121 115 128 115 126 120 98 135 116 126 135 113 125 116 145 134 114 140 113 115 115 123 114 104 124 125 111 123 112 122 143 116 102 133 130 105 136 133 114 115 125 107 118 138 115 115 111 142 117 126 117 123 104 111 123 116 135 138 120 113 118 138 123 125 110 108 131 124 135 110 114 116 126 100 120 112 107 105 123 133 102 128 137 129 120 120 123 115 128 110 114 106 127 112 112 119 120 122 115 116 130 106 135 104 118 117 126 119 113 126 117 99 113 122 119 101 103 109 106 135 121 129 123 124 119 110 97 117 114 132 119 140 127 116 115 129 146 113 138 131 112 134 129 119 131 128 130 119 111 118 106 125 106 119 113 122 117 107 110 127 124 130 115 113 112 109 127 127 123 104 104 127 125 120 131 130 115 119 132 118 107 119 129 137 120 101 114 115 95 107 141 118 135 112 109 120 109 129 133 123 122 128 126 121 133 112 126 142 126 121 131 114 152 111 103 122 114 119 117 132 121 104 115 119 115 118 106 125 141 128 118 107 116 104 123 128 112 143 110 126 120 137 133 138 118 125 113 118 136 130 126 112 119 116 117 117 102 106 108 142 108 123 134 103 108 111 135 131 116 109 158 122 140 134 117 127 128 122 94 126 125 100 102 124 107 112 119 119 117 124 123 113 113 121 117 115 119 126 126 109 108 108 121 128 114 126 135 107 130 130 136 109 135 113 127 118 131 127 105 109 134 111 124 111 123 137 108 150 109 118 122 129 112 106 111 122 100 138 120 120 123 142 126 121 131 119 142 148 112 131 124 136 102 124 126 122 137 116 120 126 115 126 114 131 138 117 125 131 123 111 124 133 119 129 144 119 113 120 123 133 131 122 122 147 135 126 113 111 139 120 138 140 120 119 125 114 127 101 133 131 108 99 132 116 123 133 132 121 155 119 126 116 145 142 105 109 102 147 125 137 123 119 121 129 108 138 110 122 99 108 120 122 106 130 129 126 147 127 117 119 125 115 139 127 109 134 139 145 123 118 121 119 125 139 128 133 128 115 106 120 123 104 128 108 125 113 124 128 124 115 121 106 107 117 123 144 131 142 107 134 132 111 108 116 105 141 119 125 108 134 133 130 110 123 129 119 98 133 123 98 136 105 116 120 131 94 116 127 142 142 103 121 113 98 107 103 124 142 123 120 97 109 135 123 107 141 137 112 126 121 116 116 114 118 126 108 116 125 111 120 111 114 123 141 133 106 111 109 126 141 134 126 142 115 114 128 112 107 123 116 122 139 116 112 123 132 115 150 127 133 115 118 138 126 127 135 128 112 118 99 126 117 116 122 107 135 127 125 118 130 112 123 123 112 107 116 111 129 113 126 130 130 119 106 111 139 145 113 125 107 108 119 115 100 131 144 130 116 129 128 103 132 125 124 124 94 135 127 124 120 128 123 133 123 121 109 121 113 131 115 131 121 100 127 121 107 121 114 124 112 138 136 130 131 138 131 120 118 123 116 126 113 130 126 154 113 116 110 116 137 138 133 125 116 130 146 106 113 135 105 122 150 98 132 123 139 131 119 125 110 119 132 121 122 110 99 137 143 120 134 113 123 135 125 120 124 147 103 108 124 111 113 128 140 116 140 125 120 123 121 129 118 108 99 119 111 118 133 131 119 107 122 116 122 139 126 127 111 112 131 112 117 120 103 107 123 119 137 127 106 96 106 135 110 121 121 115 152 137 116 144 105 121 129 97 116 137 130 104 111 107 128 124 112 110 111 138 117 121 118 127 121 96 122 120 110 131 95 101 130 139 121 122 127 107 120 117 108 124 127 124 123 114 120 119 120 129 102 122 139 114 127 134 116 136 163 106 122 121 130 109 126 120 118 126 110 138 117 115 128 131 118 116 117 122 122 112 119 146 125 108 126 117 137 139 121 126 105 121 118 128 128 109 113 115 131 114 111 133 123 135 131 128 131 130 132 141 113 112 106 104 114 121 131 128 116 128 117 111 135 110 112 129 138 119 104 107 130 139 108 114 116 122 121 108 107 112 130 117 137 117 120 105 92 129 131 109 99 117 105 125 124 120 146 117 121 125 124 107 121 129 145 108 118 106 104 157 125 121 126 121 128 99 125 119 114 122 127 110 106 129 113 128 131 112 108 131 117 134 132 116 105 127 108 109 108 134 135 115 113 117 120 103 115 112 116 117 134 117 139 120 124 119 136 127 125 125 150 124 127 124 109 113 115 115 122 115 130 123 112 150 128 121 152 108 138 115 110 117 134 126 109 131 117 130 114 105 116 138 104 114 126 116 115 128 105 102 113 120 101 131 140 127 122 99 147 128 129 112 116 123 124 124 135 131 115 107 127 106 127 117 115 133 114 146 116 101 124 128 108 114 117 109 109 98 119 108 112 122 118 128 134 144 115 133 131 124 148 123 129 124 124 134 144 129 127 110 120 125 127 132 119 156 117 121 124 123 114 132 147 110 112 122 111 114 146 116 126 115 128 127 108 100 128 118 117 121 106 120 118 104 112 104 119 118 127 123 121 144 132 111 132 110 136 110 119 122 123 120 137 110 118 121 138 113 106 130 137 124 115 123 117 137 108 115 130 127 146 109 123 135 125 113 113 118 107 124 111 120 108 107 118 116 112 116 123 121 120 121 100 123 138 125 109 121 142 101 95 140 120 121 139 112 125 126 118 113 120 121 120 112 125 121 125 112 108 110 117 125 118 128 147 101 108 120 108 128 115 134 100 116 138 128 121 104 125 128 118 117 118 119 127 120 148 114 123 120 122 124 109 130 126 101 124 119 111 113 142 123 129 126 136 108 121 128 122 127 142 113 147 140 128 119 133 135 109 121 119 124 121 129 121 117 124 133 130 105 121 118 108 153 124 139 121 110 110 122 106 142 142 135 131 132 123 117 117 119 126 152 99 134 114 136 119 133 129 124 110 121 126 124 130 120 150 125 135 125 131 109 114 114 114 115 120 113 137 120 129 143 136 139 126 114 117 133 124 123 111 130 129 120 111 130 113 113 131 125 123 134 135 146 113 124 135 103 109 109 120 126 114 126 115 101 122 123 118 145 116 121 104 124 145 121 128 147 126 127 131 133 121 113 139 110 117 118 126 136 98 90 145 112 122 124 133 120 129 110 122 130 132 138 134 143 133 128 122 129 125 137 121 125 137 109 118 134 132 123 133 122 128 109 138 115 146 121 117 146 107 104 121 118 121 121 125 129 139 115 136 116 129 99 116 109 126 122 127 120 115 109 125 117 133 128 119 130 120 138 131 113 133 144 110 117 119 116 131 139 130 141 114 135 124 122 129 118 121 117 110 130 131 116 133 114 126 128 120 107 127 124 109 127 113 105 137 126 113 108 122 129 128 139 110 151 121 103 120 132 122 127 123 118 126 110 138 105 122 106 118 123 127 122 124 126 122 130 121 125 119 154 125 113 140 116 131 128 130 116 137 122 125 105 114 122 130 120 111 116 121 130 122 110 141 113 120 136 121 126 139 129 141 123 113 128 113 131 122 117 129 115 109 108 111 131 126 106 101 109 128 108 118 117 122 131 114 123 110 120 114 125 122 116 114 121 118 128 129 123 108 128 115 117 127 121 112 116 105 134 119 114 108 138 123 122 109 112 106 127 127 121 117 111 112 124 129 145 119 136 104 105 122 119 116 128 116 111 129 106 130 115 131 131 135 110 108 130 134 117 130 104 138 131 145 125 111 98 124 118 135 100 136 117 112 118 109 122 127 129 125 118 122 123 121 143 123 105 118 137 128 126 129 107 111 106 118 128 105 127 119 124 123 111 119 135 113 125 124 126 126 115 118 131 133 130 130 129 124 129 126 114 122 127 116 124 110 115 131 144 110 121 126 109 109 113 127 112 107 126 126 125 113 136 135 131 101 120 118 135 117 125 113 113 107 130 124 124 122 117 136 133 113 117 101 128 118 120 125 137 125 109 110 126 108 126 122 128 143 118 121 115 111 135 125 128 104 127 100 132 143 126 128 119 136 124 106 119 108 112 115 132 101 122 131 138 129 100 131 111 114 119 99 120 129 128 122 112 120 117 128 146 117 129 135 125 114 119 125 140 120 122 123 121 124 111 117 130 123 160 127 124 123 119 121 128 147 121 120 126 123 136 123 104 122 129 137 120 133 128 100 117 130 129 135 123 129 121 111 115 134 130 107 142 126 103 117 132 136 130 121 117 133 122 129 125 125 129 122 123 125 129 103 117 125 122 133 135 129 110 134 112 136 115 123 114 123 113 127 134 141 102 108 120 108 125 126 122 126 125 118 125 124 107 121 113 129 121 127 123 128 131 128 130 125 124 120 128 122 128 132 112 135 126 118 128 118 122 134 126 127 116 122 119 114 113 109 130 121 118 119 137 125 116 134 125 104 132 116 116 127 124 117 122 110 133 144 112 116 130 135 125 123 103 112 104 134 121 110 121 125 102 131 112 128 99 126 121 116 120 135 111 114 130 118 103 126 113 129 115 135 130 140 141 111 120 120 131 124 115 118 111 135 125 119 146 110 124 120 145 120 125 106 108 121 138 129 125 138 132 103 119 131 130 112 128 119 120 115 115 147 129 118 123 135 132 107 143 122 115 113 132 122 113 130 104 112 141 122 112 118 154 134 120 120 137 108 122 124 120 143 127 114 144 110 136 129 110 132 128 124 127 126 129 132 113 126 135 140 121 135 115 132 107 124 151 134 127 105 125 143 114 131 149 132 115 129 114 129 136 148 121 147 139 130 119 132 145 125 127 127 137 139 136 137 139 151 140 118 148 151 153 127 135 135 128 128 136 162 140 131 136 122 156 148 144 125 134 120 139 142 147 145 134 133 162 149 156 157 143 141 153 140 137 127 148 149 136 146 143 148 142 159 130 158 137 128 119 138 135 136 112 137 127 139 128 120 130 137 152 129 142 122 125 141 135 122 125 130 138 127 137 135 106 121 143 124 129 150 121 135 122 137 132 125 125 109 134 124 135 111 155 115 100 116 108 118 143 118 123 122 132 140 114 111 137 101 137 128 117 138 124 120 120 137 119 121 103 127 130 122 120 121 140 119 123 116 98 111 133 145 111 107 144 143 127 107 122 119 127 145 121 129 137 134 108 143 133 108 137 125 131 129 101 107 130 100 127 117 137 128 130 136 146 116 119 110 117 123 109 131 134 136 109 125 117 120 131 130 140 109 123 124 119 118 136 113 124 125 122 123 129 128 112 116 114 126 130 115 117 105 149 114 146 128 131 130 129 116 114 116 131 148 88 122 106 135 137 134 126 122 147 146 122 133 133 123 138 105 130 139 113 125 114 133 90 128 131 137 123 127 114 101 129 105 89 122 110 105 126 122 114 132 122 125 140 138 119 117 115 113 117 144 131 139 107 124 118 141 135 121 126 106 122 116 117 114 132 122 130 140 144 107 141 133 134 110 105 117 123 124 139 135 127 131 113 144 141 108 115 115 109 133 134 110 147 119 119 141 155 119 122 119 130 113 119 142 117 114 109 135 147 125 102 134 131 154 136 141 121 115 107 124 121 121 125 115 137 121 123 126 155 123 119 146 128 131 115 147 134 126 127 118 138 139 137 126 125 100 127 139 122 113 109 115 128 122 135 129 135 114 139 155 120 130 123 120 105 129 114 125 145 135 120 117 127 134 102 140 135 127 142 126 107 154 120 127 116 126 103 112 116 133 130 122 134 126 134 148 114 121 115 135 160 132 130 143 115 116 122 115 125 112 136 121 133 110 150 123 132 119 99 121 137 137 140 109 112 114 120 110 106 118 116 120 121 143 109 135 114 116 126 110 136 121 121 147 143 120 113 120 120 101 149 125 158 125 122 128 137 113 122 128 126 132 117 139 137 115 138 108 143 106 141 127 138 138 119 143 149 131 132 146 119 123 118 128 145 146 123 111 121 110 121 107 123 129 109 117 133 122 130 122 141 116 124 145 132 117 96 126 112 143 139 125 127 120 112 112 117 125 116 122 114 101 124 138 129 115 110 121 139 125 116 153 115 124 155 125 113 134 126 139 134 141 110 134 135 140 111 130 131 100 111 113 128 131 122 112 115 113 152 130 115 107 102 155 133 129 127 123 113 109 130 120 135 128 123 132 142 120 123 128 122 111 122 134 104 125 114 128 133 113 114 120 132 122 125 122 110 126 127 135 114 120 131 107 123 82 99 116 110 132 136 123 128 106 99 104 125 123 114 149 118 130 129 131 125 140 122 111 142 116 119 137 131 115 119 129 132 133 112 152 120 93 119 116 130 113 123 111 108 129 108 136 127 112 123 107 144 128 119 128 140 118 137 127 125 116 120 107 136 119 99 128 127 106 120 130 111 121 128 120 117 114 108 99 134 112 126 104 112 109 124 126 114 119 117 144 123 99 125 118 110 135 121 108 106 119 131 133 117 125 118 121 114 129 124 119 115 136 128 134 127 127 139 142 129 106 115 115 131 149 115 126 119 150 138 115 130 105 127 131 133 122 110 135 120 107 117 115 103 119 119 113 114 105 136 117 142 120 128 113 132 126 124 128 114 114 145 112 131 131 118 126 99 128 136 149 112 122 126 117 108 135 117 119 110 114 108 125 121 110 120 151 126 124 139 152 130 124 116 94 123 116 102 129 123 133 125 105 123 117 129 121 123 130 93 134 117 130 136 99 127 131 129 109 98 143 120 141 115 121 129 122 98 144 109 135 140 113 125 118 117 114 119 134 119 137 108 127 134 124 125 129 120 132 146 114 110 121 132 147 129 121 127 105 104 116 122 102 113 126 130 109 108 128 126 113 128 136 132 111 119 114 129 130 131 100 136 121 129 122 119 119 124 144 113 129 112 127 102 112 129 108 118 132 122 141 122 127 110 121 132 115 135 145 125 136 131 144 119 118 139 102 122 125 139 106 110 121 114 122 119 113 109 130 124 126 140 105 99 119 106 106 128 120 126 106 132 116 123 119 125 133 124 107 100 112 139 126 138 129 129 128 114 135 123 115 121 118 110 116 119 131 122 114 138 97 115 101 121 100 126 115 126 118 141 129 124 134 150 106 100 103 110 116 133 125 128 104 121 116 116 113 120 132 121 140 128 116 120 107 107 125 119 134 109 103 144 139 134 130 129 110 146 120 129 123 111 96 135 115 131 113 119 136 132 130 134 101 114 139 106 124 134 99 104 114 124 116 131 115 111 129 122 124 131 131 125 97 118 100 137 118 109 121 127 118 128 110 99 116 118 126 97 115 130 110 123 125 115 123 124 107 127 133 118 136 129 112 135 127 93 114 119 114 110 114 106 133 120 121 131 109 129 131 115 119 101 117 129 121 123 115 121 134 119 117 108 109 121 132 132 117 110 123 140 149 134 113 102 123 115 138 117 133 112 123 143 130 112 123 111 104 143 124 110 108 107 116 136 128 99 131 143 131 133 126 115 124 125 111 109 129 128 121 126 116 129 115 118 127 126 116 120 127 126 121 139 118 129 126 115 122 98 111 113 124 104 127 135 140 138 122 132 128 114 124 112 126 118 122 119 95 117 131 125 136 106 123 109 112 138 128 130 129 102 129 110 122 115 140 129 118 118 125 113 135 119 151 125 131 136 122 112 109 131 106 134 126 132 139 142 123 115 110 133 114 121 130 120 104 138 123 111 106 104 128 114 126 118 127 115 114 104 106 132 118 119 125 123 119 115 109 101 130 118 127 111 125 143 105 133 93 134 122 143 130 124 130 147 125 136 95 116 121 137 136 135 119 128 125 129 116 124 112 119 119 144 114 132 106 124 115 104 138 127 139 105 141 120 118 139 104 128 105 129 120 119 130 135 138 126 132 135 106 117 137 120 120 133 144 103 122 130 137 134 121 136 160 132 119 108 119 104 114 119 126 126 128 138 109 94 134 132 140 108 118 128 132 125 119 125 134 123 135 122 131 128 116 131 128 113 128 122 127 108 141 116 129 115 111 118 124 136 123 133 133 124 111 130 121 113 110 129 127 133 128 96 125 126 108 123 122 129 98 121 123 119 115 105 108 128 125 119 123 142 126 132 119 122 135 99 124 119 139 142 121 120 117 117 118 120 132 131 117 108 147 139 125 114 123 119 97 126 113 137 124 109 119 125 133 116 115 137 133 108 136 113 116 139 111 119 121 150 140 113 108 107 105 130 109 136 115 128 136 128 140 127 115 116 118 114 122 142 128 119 118 135 140 113 126 121 116 126 134 134 164 125 104 137 106 137 119 121 103 113 123 117 137 115 135 141 129 122 122 110 142 127 101 122 115 134 136 135 111 126 117 100 124 127 114 109 110 148 132 113 132 126 126 119 116 131 130 126 133 115 112 128 121 126 127 119 128 133 136 124 135 121 102 122 129 123 112 132 119 132 132 101 119 109 114 114 107 120 111 126 106 124 115 126 127 104 107 129 112 117 115 124 127 131 119 123 128 116 120 105 133 113 134 119 158 114 111 112 99 124 121 131 105 132 129 121 125 131 118 125 116 112 147 116 110 102 132 131 108 125 104 126 121 122 111 128 132 122 113 118 124 99 113 107 156 113 113 127 120 131 120 120 119 125 124 131 130 127 121 140 128 133 127 137 110 137 120 117 131 120 131 131 131 135 111 153 123 126 140 135 119 134 121 122 111 119 133 120 112 132 108 118 134 104 131 136 117 130 148 140 123 122 110 122 124 123 125 114 109 121 131 120 144 140 139 117 136 136 128 139 136 120 131 114 125 123 113 118 142 120 127 134 125 121 107 123 134 123 140 130 122 126 126 110 123 103 121 111 119 113 130 94 113 125 144 121 119 116 116 127 117 101 128 129 95 127 121 118 126 131 131 126 124 110 111 142 131 120 110 122 133 106 138 116 136 129 139 127 129 106 122 125 129 115 128 130 131 118 125 113 109 112 120 107 126 114 126 117 123 119 107 109 102 122 114 124 139 146 119 106 129 105 122 119 102 126 108 114 128 120 115 115 112 120 118 113 100 124 120 123 115 121 118 99 108 109 129 129 121 113 111 118 126 112 117 113 131 124 105 112 118 119 129 131 137 93 113 108 109 132 109 115 115 117 119 127 124 95 124 128 112 119 104 127 125 140 106 152 121 129 121 114 118 128 131 119 120 98 135 91 141 109 117 114 126 115 113 102 136 126 108 112 114 137 124 120 115 123 108 121 127 105 128 127 143 99 124 127 143 121 112 105 114 139 102 116 122 114 123 123 100 130 133 98 122 121 90 112 115 104 101 96 117 131 101 114 124 110 124 109 114 97 142 107 113 131 124 116 112 110 118 130 118 112 99 120 131 135 123 104 110 125 117 116 115 119 114 118 119 116 110 109 134 100 109 93 142 113 108 114 110 112 127 117 120 124 118 135 113 101 119 102 120 131 108 95 115 124 130 132 125 115 98 107 115 96 114 109 100 119 113 130 130 119 81 113 114 127 128 117 118 125 111 114 125 114 122 112 123 134 125 111 118 106 130 137 120 105 114 105 123 103 108 137 121 133 130 128 104 114 122 121 117 104 114 124 113 127 106 113 116 110 96 109 113 115 128 140 120 121 105 121 124 109 125 119 143 111 124 117 119 118 115 129 109 120 119 131 111 119 110 130 104 140 114 120 116 136 125 132 122 95 103 117 116 116 106 112 119 109 126 131 120 113 124 114 131 121 126 118 113 101 116 118 125 112 121 105 112 135 87 108 122 118 118 116 130 121 113 118 118 108 142 122 128 110 107 129 118 128 114 113 99 116 95 119 132 93 94 95 103 108 113 111 105 116 109 111 109 101 104 122 112 124 111 121 125 112 115 123 117 128 118 108 124 122 124 105 117 122 115 134 125 107 111 104 120 102 134 109 117 119 128 130 128 138 109 118 129 116 119 110 103 120 121 117 120 112 128 115 132 123 124 131 110 111 111 108 132 110 135 117 105 118 113 111 93 115 125 131 100 107 122 107 113 96 136 114 126 110 132 130 117 109 106 113 129 103 114 107 134 115 115 123 117 109 115 109 123 104 103 121 121 125 109 104 108 116 129 138 109 138 114 117 112 118 107 104 114 113 118 104 126 111 129 111 110 124 103 114 120 117 115 105 102 118 139 120 107 101 108 138 109 115 115 126 125 118 118 121 135 128 111 137 129 127 106 111 116 118 117 111 112 116 110 124 138 111 114 116 117 103 100 138 102 116 138 118 139 114 127 115 101 116 116 110 104 120 100 108 116 129 111 124 124 127 104 96 102 114 108 126 134 116 109 112 127 129 114 110 122 120 119 123 116 118 126 131 127 124 125 99 118 126 119 116 107 113 93 120 109 115 114 127 107 133 129 128 136 116 106 119 104 108 126 122 120 106 125 139 113 105 114 128 115 143 123 100 130 118 99 121 109 110 130 119 124 133 121 124 119 111 114 125 119 110 114 122 126 121 112 122 124 135 122 110 132 118 132 119 123 108 95 103 117 116 97 99 112 106 134 106 101 114 121 101 91 131 120 118 100 108 104 128 119 141 103 137 107 117 123 87 122 128 112 117 113 110 120 119 118 110 104 105 104 113 110 110 107 138 126 111 117 108 125 120 122 111 111 120 131 111 120 119 105 125 108 116 119 112 110 142 115 132 124 113 103 97 115 114 119 130 124 115 123 114 147 115 117 101 112 124 101 124 110 119 136 102 117 135 137 119 136 121 124 128 98 101 113 113 109 107 97 110 118 121 119 125 134 120 129 126 119 121 107 119 119 113 130 107 123 104 109 111 115 93 131 116 105 118 126 106 92 115 120 120 111 127 103 105 113 123 121 119 115 102 104 106 129 114 121 98 116 111 128 110 143 121 138 90 104 120 130 115 117 99 114 112 113 106 113 135 110 118 111 124 120 119 132 126 115 113 107 129 113 97 119 131 121 138 109 116 100 129 99 113 118 116 107 125 112 105 114 105 122 91 111 105 111 127 106 106 116 118 121 111 103 107 133 130 114 117 99 99 130 119 106 106 107 100 117 134 128 102 121 106 118 115 113 98 151 120 97 107 109 116 111 127 114 131 135 124 98 104 135 120 125 123 122 109 122 99 117 111 105 116 109 118 111 127 106 116 127 110 102 110 135 121 123 117 127 110 121 101 106 121 131 125 108 115 101 107 110 111 116 116 119 125 100 115 97 118 117 100 117 117 119 116 100 108 133 111 112 112 135 107 112 123 117 132 127 127 124 130 118 115 108 112 129 113 114 90 128 132 128 113 125 121 120 125 106 119 116 106 111 121 124 113 98 101 115 134 112 121 118 116 109 137 118 116 143 116 129 127 123 106 105 121 115 113 128 114 125 148 113 105 114 95 122 112 108 104 109 114 111 126 127 113 111 103 113 113 112 130 103 121 119 128 107 107 103 130 107 130 112 118 109 109 101 134 132 124 110 104 118 110 106 112 134 102 121 131 126 132 121 114 103 126 104 115 108 109 104 107 118 93 112 110 133 131 108 96 125 122 119 119 122 116 106 105 106 111 120 101 123 113 111 123 105 121 119 121 113 133 119 118 118 109 110 121 121 108 109 115 130 118 107 105 113 97 133 131 117 109 137 103 113 133 115 137 121 116 103 135 112 114 117 127 113 103 108 108 107 132 126 140 119 114 114 107 102 121 118 131 118 120 98 127 115 100 111 119 103 101 94 115 133 120 128 115 112 116 117 118 115 112 119 111 129 117 114 126 93 114 115 109 110 120 117 97 91 107 127 123 116 106 127 107 100 115 130 107 123 100 123 107 118 114 98 102 120 115 106 113 96 113 125 112 113 116 101 118 111 131 116 122 109 129 103 105 108 107 103 109 118 123 107 89 121 137 120 107 115 137 125 129 102 129 128 102 106 135 108 108 113 120 125 116 117 122 128 100 105 102 113 102 104 128 115 95 103 110 135 115 125 114 96 111 111 107 118 113 117 101 110 119 104 132 130 134 121 113 125 100 114 114 110 103 139 105 124 106 100 114 117 115 115 98 113 107 108 109 126 111 111 104 117 105 112 130 120 124 94 99 124 119 105 96 115 106 105 127 128 117 124 108 112 113 94 111 105 121 113 113 103 102 124 125 119 123 120 111 116 112 103 99 114 121 121 112 129 118 135 119 106 116 105 89 103 101 118 108 125 124 113 104 111 129 107 109 137 119 101 112 109 109 123 120 106 119 110 107 117 116 91 118 115 105 101 103 100 90 92 129 128 106 113 104 115 102 115 128 109 115 111 91 103 111 123 104 100 96 92 107 106 115 125 121 108 115 103 97 122 120 113 124 127 123 109 128 106 129 126 99 114 116 100 130 126 112 115 106 97 86 93 122 96 118 116 113 104 87 121 105 103 116 137 117 117 108 97 98 110 113 105 111 86 105 102 125 116 120 127 120 136 103 94 136 116 115 127 111 119 110 116 116 108 119 128 115 109 101 120 122 107 136 98 117 117 105 124 116 104 118 130 112 115 111 106 125 118 103 97 112 94 117 115 112 121 106 123 105 110 111 131 85 105 132 110 98 123 125 91 100 102 120 140 115 101 117 123 110 106 104 126 113 141 138 115 113 108 94 114 118 138 119 105 132 137 123 119 109 129 110 128 97 147 105 121 111 117 118 113 111 91 104 96 146 125 126 122 126 101 103 135 100 124 114 131 125 110 101 108 123 115 111 110 108 108 145 112 113 110 145 134 117 109 137 140 111 120 104 119 139 131 116 99 125 114 108 101 125 118 115 117 135 121 121 119 105 93 99 112 130 114 141 115 130 123 110 127 124 99 104 107 121 112 98 118 118 109 106 124 119 102 115 109 115 126 123 131 137 100 103 102 110 120 113 93 136 96 117 121 126 102 126 122 123 120 113 119 94 118 90 126 101 96 125 118 99 112 134 132 110 99 103 111 111 132 94 107 115 100 88 112 105 101 113 105 107 99 98 124 122 92 90 95 110 95 117 117 111 115 110 100 91 108 117 121 105 116 101 117 123 98 87 116 108 116 100 100 112 114 115 106 97 104 123 116 104 126 98 123 112 95 121 115 96 128 99 104 111 103 104 102 102 104 128 115 96 97 97 114 109 107 132 101 97 100 104 131 90 102 114 101 106 109 103 90 112 98 110 104 109 102 112 132 111 97 105 112 125 97 110 99 112 125 109 96 101 118 110 111 117 107 113 113 102 92 106 106 108 87 92 107 108 95 98 102 111 108 105 103 107 109 108 103 96 105 110 101 106 108 114 112 103 111 106 101 102 111 123 94 107 102 108 97 100 118 100 118 102 110 113 100 112 132 102 108 134 114 114 108 118 99 79 90 113 127 114 107 99 105 107 97 96 114 111 117 95 129 105 106 114 95 105 108 110 121 93 104 90 107 116 121 104 105 112 103 119 122 108 106 110 108 107 99 115 96 108 113 95 103 103 102 101 104 97 97 120 104 115 103 118 97 107 104 111 110 110 109 106 100 116 108 107 111 113 98 111 121 131 104 110 121 88 101 96 126 88 102 98 103 107 105 120 123 113 110 104 101 113 106 102 118 120 111 98 113 113 102 111 108 110 99 126 111 131 109 94 131 114 104 111 107 110 118 112 107 110 121 92 123 108 119 109 108 102 108 106 100 100 102 103 96 98 101 115 115 109 114 114 110 113 95 100 95 114 103 98 118 96 119 88 108 91 130 95 97 110 112 119 102 93 109 126 117 125 89 99 98 105 135 123 116 95 92 116 113 111 111 130 86 103 104 124 105 120 112 126 96 118 111 118 103 107 106 107 105 90 95 99 111 134 121 103 112 101 104 108 97 138 97 117 100 128 108 140 127 119 103 89 99 96 109 110 116 94 113 108 97 123 111 110 104 112 103 107 91 117 112 84 122 111 123 104 107 124 101 95 98 106 98 90 104 108 99 90 116 110 111 103 122 109 100 109 120 118 111 97 113 104 109 127 125 104 105 106 113 119 133 93 121 91 102 99 120 109 115 106 103 108 118 84 110 102 116 82 103 102 100 113 99 96 104 110 109 107 116 123 118 100 113 102 125 99 95 101 103 136 103 121 99 112 98 104 128 118 109 123 114 112 110 110 112 99 107 119 101 115 107 125 109 107 131 118 111 96 106 115 100 121 104 117 124 124 106 116 101 101 105 104 96 96 98 119 118 105 95 93 113 107 111 115 118 126 101 115 90 104 108 115 107 117 122 98 97 103 109 109 100 105 102 101 113 101 113 124 112 102 122 100 116 123 113 89 112 115 98 109 105 114 110 117 107 103 108 102 137 98 91 99 110 108 106 107 121 106 100 106 132 93 109 90 112 105 104 114 111 120 118 132 108 103 118 110 114 131 122 113 109 100 92 109 115 122 106 97 121 112 113 92 111 108 122 118 97 109 86 90 104 104 107 119 104 101 90 106 103 87 109 110 107 114 117 113 100 111 96 100 107 112 102 95 89 107 102 115 109 101 101 116 120 106 94 117 101 90 131 136 106 106 121 92 95 113 90 97 128 118 110 110 105 125 115 100 101 114 104 97 112 105 104 99 100 111 105 100 113 111 107 114 136 115 107 108 100 109 131 126 111 108 114 125 111 116 104 100 103 117 99 89 105 113 116 126 111 99 108 104 104 113 114 103 105 109 111 110 128 94 99 110 95 121 97 111 116 97 102 105 131 106 118 103 112 112 105 91 110 126 87 120 109 108 87 107 103 116 125 108 119 124 112 115 98 123 105 108 114 114 105 98 101 108 101 103 108 106 117 87 103 127 116 109 109 113 118 127 90 109 123 105 108 113 110 100 122 128 118 112 100 108 127 121 129 98 97 108 114 99 125 98 94 102 105 99 101 127 111 119 124 114 114 119 98 108 109 95 147 106 99 113 117 109 94 111 118 89 111 101 103 102 101 121 96 102 106 116 113 115 99 98 107 102 109 114 101 105 114 117 99 107 108 99 105 102 120 115 113 132 125 93 134 102 128 95 117 108 106 131 108 105 124 100 102 99 105 128 121 98 118 105 107 102 108 116 102 105 77 115 92 114 83 101 97 109 129 106 100 120 120 95 111 117 118 122 106 116 123 109 108 99 106 106 99 99 110 119 116 131 114 113 115 131 113 109 110 124 115 115 121 112 103 115 97 107 107 102 99 108 117 107 120 125 103 113 116 116 110 98 87 99 110 98 116 123 92 104 112 105 113 107 101 104 110 123 102 89 104 100 118 125 103 106 112 106 115 111 138 110 107 116 123 115 122 100 107 112 101 97 113 111 112 120 109 134 103 119 106 120 121 108 129 99 130 112 122 95 136 113 120 130 99 109 99 116 107 116 106 120 112 99 100 131 118 109 101 109 99 126 126 118 113 110 113 96 100 118 104 147 100 102 110 105 110 104 111 99 121 99 111 114 101 126 105 129 117 109 115 121 115 115 116 94 111 100 92 125 110 115 112 104 133 106 123 110 115 108 112 117 113 115 97 91 111 112 130 112 110 104 117 95 108 115 94 111 114 103 116 91 110 119 100 117 142 107 128 122 133 118 93 113 99 121 128 106 119 102 111 117 131 95 78 110 92 88 122 104 112 110 109 104 111 106 107 114 118 115 109 114 106 105 111 112 113 130 104 94 104 98 115 97 118 96 120 122 111 98 112 109 112 108 103 113 107 102 114 114 107 125 119 99 107 119 108 128 118 127 119 104 113 111 129 97 117 120 109 116 113 105 103 120 99 119 113 130 113 128 119 87 97 110 110 110 105 107 125 113 107 110 107 105 105 114 111 127 123 107 116 107 122 127 98 101 107 85 101 115 140 100 119 103 117 116 102 116 113 107 129 101 106 108 115 94 99 149 102 124 114 128 122 115 122 105 107 113 119 110 102 111 112 95 139 104 88 128 103 109 113 129 124 97 121 108 108 120</counts>
			</dataPoints>
		</scan>
	</xrdMeasurement>
</xrdMeasurements>