File: data/XRD/XG-Luft/XG-875/W6822-1D_XG_Luft_875.xrdml
<xrdMeasurements xmlns="http://www.xrdml.com/XRDMeasurement/2.1" xmlns:xsi="http://www.w3.org/2001/XMLSchema-instance" xsi:schemaLocation="http://www.xrdml.com/XRDMeasurement/2.1 http://www.xrdml.com/XRDMeasurement/2.1/XRDMeasurement.xsd" status="Completed">
	<comment>
		<entry>Configuration=Factory configuration, Owner=User-1, Creation date=7/8/2013 4:01:53 PM</entry>
		<entry>Goniometer=PW3050/65 (Theta/2Theta); Minimum step size 2Theta:0.0001; Minimum step size Omega:0.0001</entry>
		<entry>Sample stage=MRD Cradle; Minimum step size Phi:0.01; Minimum step size Chi:0.01; Minimum step size X:0.01; Minimum step size Y:0.01; Minimum step size Z:0.001</entry>
		<entry>Diffractometer system=XPERT-PRO</entry>
		<entry>Measurement program=C:\PANalytical\Data Collector\Programs\Jorrit\2thom\_absolute_2th-om_10-130deg_PIXscan_56min.xrdmp, Identifier={15BCCF57-2807-42BD-B5B9-ECC0B3DC9284}</entry>
		<entry>Batch program=C:\PANalytical\Data Collector\Programs\SimonL\batch6x_2thom_10-130°_z9.1_x0,10,20,30_y20,40_57min - Kopie.xrdmp, Identifier={8874E540-C3F4-4307-831A-CD55F073CDCD}</entry>
	</comment>
	<sample type="To be analyzed">
		<id></id>
		<name></name>
		<preparedBy></preparedBy>
	</sample>
	<xrdMeasurement measurementType="Scan" status="Completed" sampleMode="Reflection">
		<comment>
			<entry>_absolute_2th-om_10-130deg_PIXscan_56min</entry>
			<entry>PHD Lower Level = 4.83 (keV), PHD Upper Level = 11.27 (keV)</entry>
		</comment>
		<usedWavelength intended="K-Alpha 1">
			<kAlpha1 unit="Angstrom">1.5405980</kAlpha1>
			<kAlpha2 unit="Angstrom">1.5444260</kAlpha2>
			<kBeta unit="Angstrom">1.3922500</kBeta>
			<ratioKAlpha2KAlpha1>0.5000</ratioKAlpha2KAlpha1>
		</usedWavelength>
		<incidentBeamPath>
			<radius unit="mm">320.00</radius>
			<xRayTube id="1010048" name="Empyrean Cu LFF HR (9430 033 7310x) DK442154">
				<tension unit="kV">40.0</tension>
				<current unit="mA">40.0</current>
				<anodeMaterial>Cu</anodeMaterial>
				<focus type="Line">
					<length unit="mm">12.0</length>
					<width unit="mm">0.4</width>
					<takeOffAngle unit="deg">4.2</takeOffAngle>
				</focus>
			</xRayTube>
			<xRayMirror id="27010001" name="Inc. Beam Cu W/Si (parabolic MRD)" hybrid="false">
				<crystal type="Graded" shape="Parabolic">W/Si</crystal>
				<acceptanceAngle unit="deg">0.800</acceptanceAngle>
				<length unit="mm">60.0</length>
			</xRayMirror>
			<sollerSlit id="21010002" name="Soller slits 0.04 rad.">
				<opening unit="rad">0.0400</opening>
			</sollerSlit>
			<mask id="22030007" name="Fixed mask 2 mm">
				<distanceToSample unit="mm">220.00</distanceToSample>
				<width unit="mm">2.00</width>
			</mask>
			<divergenceSlit id="22010011" name="Fixed slit 1/32°" xsi:type="fixedDivergenceSlitType">
				<distanceToSample unit="mm">220.00</distanceToSample>
				<height unit="mm">0.05</height>
			</divergenceSlit>
		</incidentBeamPath>
		<diffractedBeamPath>
			<radius unit="mm">320.00</radius>
			<sollerSlit id="21010002" name="Soller slits 0.04 rad.">
				<opening unit="rad">0.0400</opening>
			</sollerSlit>
			<receivingSlit id="22010001" name="Fixed slit 4°">
				<height unit="mm">5.88</height>
			</receivingSlit>
			<detector id="7010017" name="PIXcel3D 1x1 detector" xsi:type="areaDetectorType">
				<phd unit="%">
					<lowerLevel>30.0</lowerLevel>
					<upperLevel>70.0</upperLevel>
				</phd>
				<mode>Scanning</mode>
				<activeChannelsEquatorial>255</activeChannelsEquatorial>
				<activeChannelsAxial>255</activeChannelsAxial>
				<pitchEquatorial unit="mm">0.05500</pitchEquatorial>
				<pitchAxial unit="mm">0.05500</pitchAxial>
				<readOutPeriod unit="seconds">0.135</readOutPeriod>
			</detector>
		</diffractedBeamPath>
		<scan appendNumber="0" mode="Continuous" scanAxis="2Theta-Omega" status="Completed">
			<header>
				<startTimeStamp>2024-10-30T21:13:50+01:00</startTimeStamp>
				<endTimeStamp>2024-10-30T22:09:56+01:00</endTimeStamp>
				<author>
					<name>PRO-MRD</name>
				</author>
				<source>
					<applicationSoftware version="6.1b">Data Collector</applicationSoftware>
					<instrumentControlSoftware version="7.0E 20130304">XPERT-PRO</instrumentControlSoftware>
					<instrumentID>0000000011142674</instrumentID>
				</source>
			</header>
			<dataPoints>
				<positions axis="2Theta" unit="deg">
					<startPosition>9.99826193</startPosition>
					<endPosition>129.99755682</endPosition>
				</positions>
				<positions axis="Omega" unit="deg">
					<startPosition>4.99913096</startPosition>
					<endPosition>64.99877841</endPosition>
				</positions>
				<positions axis="Phi" unit="deg">
					<commonPosition>0.00</commonPosition>
				</positions>
				<positions axis="Chi" unit="deg">
					<commonPosition>0.00</commonPosition>
				</positions>
				<positions axis="X" unit="mm">
					<commonPosition>10.00</commonPosition>
				</positions>
				<positions axis="Y" unit="mm">
					<commonPosition>0.00</commonPosition>
				</positions>
				<positions axis="Z" unit="mm">
					<commonPosition>9.100</commonPosition>
				</positions>
				<commonCountingTime unit="seconds">32.895</commonCountingTime>
				<counts 483 405 447 415 415 369 424 377 437 406 432 424 415 403 407 422 386 389 432 448 449 417 435 424 414 456 415 392 423 424 430 399 403 405 412 413 430 423 411 405 421 413 411 413 398 420 400 446 405 431 451 432 441 441 427 424 422 414 412 408 411 413 449 433 393 456 419 438 383 398 427 417 418 404 397 438 387 397 413 444 374 443 430 406 383 460 438 394 432 408 411 388 418 398 387 448 368 404 390 395 368 437 425 363 421 390 409 388 381 398 418 374 390 381 414 394 403 384 413 381 414 395 424 414 407 413 421 389 432 407 391 441 348 394 393 426 407 399 397 374 394 356 363 422 405 378 374 413 380 377 412 394 376 409 382 408 446 382 418 375 399 382 398 374 385 381 408 378 399 390 395 409 411 387 415 404 389 414 414 386 361 400 392 362 386 346 342 360 364 388 383 394 353 354 348 416 354 363 388 391 372 362 398 367 378 381 378 359 416 362 352 356 352 397 375 424 364 365 377 348 391 334 366 373 368 383 372 352 381 371 387 365 367 358 384 426 387 393 381 371 398 398 348 356 334 340 364 339 398 373 360 373 385 376 382 386 349 375 395 376 409 332 379 341 366 388 358 340 369 365 373 364 374 368 361 340 339 379 353 344 369 365 393 375 375 322 385 369 340 355 350 343 377 391 346 317 352 363 326 355 375 335 373 360 366 355 368 360 342 352 390 352 347 325 349 336 396 364 366 323 376 379 291 347 375 386 342 343 338 351 370 383 384 358 372 387 338 350 326 340 321 312 359 338 396 334 327 346 350 343 323 354 338 346 346 339 353 353 327 332 352 367 330 358 351 325 309 347 367 339 360 315 363 365 351 347 336 319 364 350 346 347 327 334 362 343 317 345 363 344 373 353 335 314 326 326 346 337 348 337 393 347 341 354 362 344 323 336 338 329 301 289 365 314 327 318 330 319 318 331 295 329 369 336 359 329 349 364 333 319 332 315 346 325 347 326 337 343 309 326 358 353 313 324 301 307 319 340 357 335 327 328 342 330 336 332 332 334 356 335 330 330 320 299 346 350 311 330 332 301 312 324 289 333 333 292 328 337 299 345 306 330 344 361 323 333 305 302 287 324 294 316 330 326 296 333 317 361 311 348 322 326 336 291 315 336 331 312 357 309 322 302 313 342 324 314 343 351 328 335 311 345 338 299 329 284 332 307 281 311 350 311 334 289 337 319 347 322 297 306 341 296 314 346 315 298 311 324 315 309 313 338 330 283 344 316 318 339 313 320 345 313 319 332 335 357 306 291 327 342 343 326 312 357 289 300 320 302 311 265 310 329 310 314 326 327 359 314 302 291 314 317 330 289 307 319 330 366 293 308 315 313 294 272 336 280 313 311 318 337 321 327 296 275 300 313 296 316 288 315 305 302 293 306 283 345 304 302 322 281 340 354 298 311 322 275 287 312 305 311 329 300 297 300 289 308 305 355 320 287 301 308 312 293 297 318 343 326 319 318 297 297 328 295 300 309 279 301 344 322 287 339 314 290 301 319 311 294 286 305 311 291 281 340 316 294 296 302 327 320 298 325 312 347 289 301 298 308 313 289 306 312 318 310 307 274 308 315 319 320 273 344 315 327 320 284 319 302 296 307 301 332 321 303 327 297 294 330 311 313 304 322 307 340 279 312 340 318 275 319 351 281 304 316 338 313 320 289 316 304 312 320 305 303 301 288 310 325 325 294 304 277 334 278 310 291 282 306 343 326 302 293 304 329 310 280 286 314 308 307 338 297 314 300 315 308 297 301 310 330 304 301 312 304 308 328 294 283 310 306 296 288 299 325 351 278 321 301 308 294 316 310 308 288 310 322 292 290 301 277 308 315 290 284 331 266 350 302 305 322 283 307 296 322 270 307 314 304 293 299 295 304 333 318 301 303 322 315 326 350 342 317 303 293 305 281 319 301 350 318 300 275 289 319 288 304 291 322 269 310 319 328 352 297 308 324 309 304 315 295 285 296 333 314 312 293 325 313 301 286 322 279 319 318 303 280 310 364 312 320 295 309 328 317 315 285 306 333 315 326 296 335 333 281 302 351 322 298 291 301 302 327 293 295 291 311 306 318 314 321 300 337 317 305 301 342 300 280 315 300 306 292 307 291 305 298 309 302 293 303 278 304 304 318 316 273 296 333 329 314 301 308 318 326 284 318 305 335 318 294 345 295 306 331 322 310 285 308 307 350 324 298 326 314 296 339 314 316 322 312 301 306 274 303 307 329 317 292 317 295 290 310 322 310 302 307 305 329 291 307 291 316 294 313 297 302 319 298 317 328 291 308 293 291 315 323 314 327 287 316 293 321 332 304 295 302 325 290 322 282 351 306 310 339 294 302 297 341 314 313 280 286 314 262 307 317 342 319 323 328 298 337 326 290 334 335 307 307 286 289 316 299 304 293 300 314 296 315 334 297 296 302 294 324 306 287 344 314 305 324 321 318 313 327 335 304 324 337 295 301 267 274 309 328 305 289 286 310 303 311 310 312 316 315 340 305 284 317 280 295 302 325 268 320 328 272 342 289 311 298 293 310 322 316 305 308 312 305 310 308 312 274 271 294 307 287 335 300 296 260 319 329 300 314 305 314 288 332 291 300 323 307 302 318 297 296 300 327 272 283 301 297 293 311 327 274 297 335 325 330 321 305 305 346 307 319 339 315 320 306 301 361 330 298 287 301 289 347 311 288 307 285 311 329 297 312 317 291 281 305 316 286 308 334 303 296 341 318 331 283 317 321 298 299 324 297 349 314 314 317 297 299 281 323 320 299 291 306 328 304 319 336 285 292 293 307 287 352 317 308 313 306 300 313 303 315 321 281 279 302 314 310 306 299 302 268 325 288 318 294 340 316 332 337 340 316 341 294 325 340 338 298 312 294 304 304 270 286 302 323 327 306 300 306 310 353 303 312 304 307 317 295 346 312 317 295 321 292 325 316 337 311 298 296 304 309 319 304 278 323 316 329 330 333 315 336 319 314 314 308 343 322 290 307 319 280 314 297 327 312 364 299 317 322 333 299 287 306 339 319 335 338 323 308 320 331 337 306 295 356 307 287 286 289 341 325 317 316 281 299 348 300 305 328 313 290 302 324 317 337 355 320 307 305 310 327 299 336 306 304 285 330 303 349 316 294 315 323 296 300 327 323 281 303 304 338 341 293 294 288 259 311 318 326 285 300 316 287 311 286 298 353 317 295 314 309 312 301 331 287 309 303 292 290 295 321 295 315 301 302 306 319 284 309 328 320 306 321 290 331 321 335 309 313 291 342 321 346 313 296 301 274 334 311 314 289 271 329 306 293 312 295 313 315 310 291 315 305 299 294 296 307 287 305 328 291 315 297 304 285 272 271 309 276 302 308 291 285 297 307 297 299 296 300 316 286 294 337 290 308 298 303 320 315 276 302 306 304 275 331 292 320 301 290 270 311 289 280 288 294 305 305 301 296 314 305 292 273 276 297 309 287 265 283 301 319 325 317 318 286 300 285 279 286 268 303 311 293 300 256 297 283 300 273 291 298 328 289 303 305 305 287 289 283 299 268 320 282 265 270 325 317 274 296 299 275 303 316 304 285 288 304 281 293 274 308 293 297 280 288 271 301 273 290 300 296 281 286 325 265 324 289 289 293 265 275 316 288 272 262 298 291 294 285 334 283 279 281 287 255 245 309 292 240 335 293 265 300 298 274 291 275 286 275 293 283 284 315 280 242 300 289 294 281 286 316 274 270 258 291 294 304 276 273 270 290 280 261 294 265 273 279 274 300 298 256 283 274 282 303 319 286 290 317 275 285 250 289 256 281 289 291 289 273 274 236 267 272 273 243 275 291 264 239 299 273 270 300 277 276 276 275 281 263 300 278 294 247 293 290 289 296 268 280 279 283 271 293 248 281 276 244 286 286 273 273 283 289 329 266 260 257 297 293 265 271 299 289 260 273 302 286 276 290 248 304 249 262 306 290 257 273 279 308 257 270 267 282 265 241 257 260 276 282 241 244 258 277 277 291 275 268 264 276 248 286 283 289 308 282 277 275 245 268 245 255 247 270 270 267 248 284 267 292 258 228 267 298 263 261 267 262 263 285 265 278 294 314 312 261 284 272 266 273 267 283 285 257 260 286 293 271 261 265 291 285 257 265 272 272 264 269 240 269 309 280 270 267 285 273 294 275 275 261 231 266 281 269 279 257 285 280 286 286 294 275 262 274 296 273 260 245 279 238 270 245 261 246 248 267 261 271 264 297 272 233 294 266 271 293 285 267 263 291 278 237 270 280 272 234 249 247 259 258 239 265 265 291 261 262 255 262 275 268 259 283 232 273 286 300 265 269 239 249 247 247 227 268 258 240 245 266 249 273 270 231 269 230 274 258 236 261 277 276 246 280 262 260 244 241 282 261 274 294 264 243 269 266 236 244 267 271 259 249 214 292 260 245 291 271 231 264 255 257 229 270 241 280 271 220 266 277 265 233 264 246 277 242 229 235 263 277 255 244 259 226 246 258 250 264 267 241 248 257 257 246 274 255 280 267 265 284 258 233 248 264 289 262 259 263 242 286 282 325 248 256 286 248 241 245 233 265 245 262 271 287 236 287 238 240 297 261 246 234 291 232 258 259 256 267 258 273 246 274 261 277 258 258 268 293 307 284 227 238 255 259 227 249 262 267 250 265 260 288 255 228 238 243 239 248 234 273 236 257 238 268 235 242 268 257 261 243 259 226 290 257 231 226 232 250 229 260 261 286 249 242 239 259 268 289 263 225 266 233 259 239 261 236 280 262 282 271 259 249 268 274 268 256 264 275 257 272 246 255 260 265 243 277 237 250 243 248 280 242 262 273 271 272 279 233 284 241 257 257 279 249 287 233 288 242 271 276 272 312 269 263 280 250 274 261 257 242 264 257 278 266 247 269 212 244 279 258 256 244 268 247 279 248 248 269 233 243 260 218 245 262 270 230 260 268 244 255 277 284 245 255 250 270 244 241 248 231 255 284 213 235 259 230 267 256 262 261 244 277 233 235 257 266 229 263 246 260 245 229 239 283 243 265 268 232 260 237 272 262 241 234 255 235 256 223 255 271 212 240 235 255 241 227 275 225 244 247 260 276 244 216 236 230 239 238 238 215 246 234 262 248 235 232 268 232 261 268 276 248 249 229 257 262 260 242 241 250 230 236 265 266 239 239 239 238 261 223 255 240 238 236 269 242 242 239 219 271 234 237 226 231 239 234 245 243 248 257 243 245 225 236 247 258 247 257 246 212 239 230 290 233 236 262 231 267 267 266 250 243 265 230 267 273 262 247 257 283 261 207 247 272 265 266 247 240 226 245 234 229 255 257 280 259 236 232 224 244 237 242 232 268 237 236 246 226 225 271 235 255 257 221 221 214 259 264 240 250 244 262 209 263 232 232 247 210 258 265 216 217 233 258 278 231 236 224 259 223 226 244 247 258 246 222 232 269 234 257 249 256 274 269 247 230 224 239 217 274 244 236 242 248 233 289 220 237 235 222 230 223 238 236 231 261 257 219 231 257 228 261 259 275 236 262 263 267 280 244 229 263 271 229 263 256 240 246 235 266 234 255 216 233 235 241 270 271 238 241 243 234 237 258 234 217 248 262 229 237 227 220 221 226 238 239 265 256 223 234 239 240 224 256 247 244 255 271 215 247 215 239 276 245 244 255 255 266 226 246 263 246 233 240 236 241 246 242 232 221 241 230 260 227 247 255 243 233 224 226 230 222 259 228 264 293 193 243 228 264 240 256 270 268 256 243 237 223 268 261 257 266 225 248 249 268 232 226 231 217 212 229 244 295 237 208 245 239 256 238 240 247 227 229 256 241 232 248 259 238 232 279 279 242 237 236 216 267 249 229 218 228 221 228 235 242 244 262 230 234 247 223 229 239 274 232 201 221 231 244 262 269 204 243 229 270 246 229 233 231 230 241 239 261 235 249 264 266 278 234 240 201 222 241 219 262 238 248 243 239 235 259 233 226 212 232 237 232 236 223 247 271 235 224 268 250 225 261 214 236 242 238 237 228 226 234 238 266 241 245 238 243 277 212 221 242 276 255 272 242 235 236 225 243 243 244 238 247 228 240 274 218 246 261 262 272 240 243 230 234 246 256 257 238 278 262 240 265 240 261 230 234 275 265 277 264 238 261 241 263 237 274 227 265 237 237 267 221 236 246 263 241 263 238 263 271 268 248 225 240 229 271 262 243 266 244 241 222 233 247 231 257 271 234 261 270 228 285 236 242 239 271 265 243 240 236 269 224 226 209 258 275 211 228 227 267 246 217 242 219 213 281 246 228 285 242 259 222 219 236 220 238 226 235 288 234 241 256 218 212 265 265 272 255 237 243 262 263 245 232 212 208 248 229 258 255 249 237 238 240 287 238 255 235 249 265 238 257 258 244 228 281 274 260 224 217 261 228 224 260 207 249 249 257 284 261 222 209 242 229 225 245 259 264 233 225 260 207 221 249 272 245 291 250 242 258 223 206 247 242 248 225 231 243 238 233 235 230 245 238 228 236 247 234 280 223 258 238 256 264 242 231 229 236 240 242 214 244 232 275 236 242 276 240 219 234 258 257 248 244 259 244 235 209 238 235 235 258 247 228 246 270 259 269 226 237 270 245 241 226 224 248 257 203 257 242 255 260 244 219 271 247 274 229 231 228 225 227 247 232 218 246 217 249 238 225 256 232 255 227 266 227 270 259 255 238 234 275 243 248 246 236 233 235 270 233 232 260 267 238 262 224 247 250 260 229 265 228 216 224 230 241 240 249 239 218 239 230 216 231 228 248 256 229 247 226 249 257 229 272 234 217 274 243 237 265 227 223 248 228 239 274 282 255 264 267 229 267 231 215 229 270 262 222 259 230 247 215 229 242 247 227 241 224 272 229 245 255 221 245 234 260 263 231 235 240 269 234 273 234 246 263 236 276 230 263 241 276 241 260 232 239 258 240 233 232 234 242 242 229 260 266 233 222 232 229 266 264 246 276 231 248 242 247 235 259 243 257 231 232 239 263 242 271 271 268 236 220 258 222 220 255 244 262 255 236 242 241 255 265 226 209 256 296 230 234 259 245 239 243 238 226 260 243 262 230 244 257 228 229 262 272 212 280 225 239 238 271 245 248 224 258 263 236 235 228 255 272 274 247 247 258 249 244 240 263 216 247 248 247 257 237 246 233 244 212 259 255 267 270 262 249 265 269 243 247 263 240 235 229 256 258 273 239 227 207 280 228 257 236 257 262 239 232 242 259 261 240 263 268 260 227 273 265 248 247 242 257 255 249 210 260 275 249 248 258 241 226 231 240 231 232 260 261 256 238 255 280 228 221 273 235 237 244 244 237 280 248 256 257 255 261 258 246 248 271 246 248 268 268 307 248 226 245 261 223 244 241 291 260 238 282 230 210 256 241 257 247 243 239 258 248 262 249 259 259 237 255 257 247 249 259 255 255 237 256 243 238 248 262 246 250 262 282 236 270 242 239 268 268 256 263 258 267 250 241 268 290 262 270 261 263 294 246 255 259 236 277 268 245 264 258 240 262 277 243 255 225 224 236 261 250 265 257 271 276 262 286 239 268 240 289 303 259 285 257 243 237 267 263 274 258 260 281 249 255 306 268 272 227 286 261 266 277 227 259 278 249 241 278 277 266 264 250 257 232 277 286 262 246 281 287 274 236 273 283 274 246 267 246 286 266 272 282 249 261 292 289 271 255 276 268 281 302 282 268 281 296 289 298 286 270 294 318 246 287 271 304 309 307 291 299 273 306 318 285 313 299 334 313 283 298 328 316 305 345 326 305 308 343 369 358 351 326 349 337 389 392 381 374 359 379 406 379 357 458 418 432 445 445 472 423 403 449 411 418 493 444 445 435 417 408 410 399 372 429 372 377 382 382 347 328 336 344 375 333 325 325 305 320 285 290 285 324 290 308 301 300 297 321 281 281 278 269 272 264 274 287 291 258 288 282 255 243 299 277 267 278 274 271 287 287 267 263 247 261 275 255 259 237 292 268 268 284 270 248 270 230 288 259 263 242 236 255 236 266 249 261 261 246 244 302 243 236 245 276 272 327 271 244 240 264 275 257 242 268 247 274 231 260 249 236 261 266 239 283 232 266 241 280 241 285 273 256 279 226 248 271 263 269 290 270 256 256 246 240 227 237 267 266 288 227 293 255 260 237 268 263 274 267 263 243 247 239 203 273 246 257 247 232 278 274 258 245 273 243 230 256 259 272 266 271 255 231 281 264 282 244 235 237 231 260 245 249 269 220 229 262 224 278 245 256 233 229 268 244 229 238 278 243 225 270 229 248 267 278 255 268 249 228 242 247 291 255 259 255 247 243 238 247 241 227 265 248 257 256 281 259 258 258 229 231 270 244 272 217 267 220 261 269 227 243 244 217 266 258 248 271 267 256 267 274 263 211 247 237 245 240 226 239 239 264 228 255 269 266 267 283 269 258 282 257 239 260 260 255 259 245 241 240 245 259 247 258 218 273 245 259 217 239 244 274 273 259 261 267 271 238 243 222 222 240 246 264 257 239 242 246 276 264 234 241 228 225 240 223 235 234 264 259 225 269 256 231 267 289 242 234 275 274 248 219 267 238 232 260 235 245 230 257 219 232 267 240 245 256 262 261 230 241 282 241 267 247 278 247 236 266 267 264 274 262 219 243 243 262 260 247 223 275 265 272 240 247 247 270 234 265 257 247 240 239 235 227 259 261 265 249 242 267 230 271 234 266 244 268 258 273 234 269 284 279 228 264 246 281 239 238 268 276 232 239 256 260 241 235 290 235 247 243 222 242 240 262 236 264 241 258 256 240 243 244 268 243 261 270 257 269 255 271 267 282 272 246 265 246 240 257 217 257 263 258 267 230 248 241 305 235 283 273 216 247 227 256 263 247 224 283 261 255 262 238 258 255 284 247 287 245 239 240 240 274 270 258 246 240 270 270 264 237 243 242 249 261 225 262 255 271 244 257 268 217 247 263 246 248 241 295 261 260 226 248 227 277 287 276 257 238 266 271 279 256 225 272 246 274 225 242 259 266 235 233 242 255 232 257 220 259 235 257 260 235 243 261 292 241 233 237 262 239 269 265 260 233 257 233 261 250 249 240 274 259 262 233 275 255 269 265 232 259 264 242 273 232 255 274 267 258 270 262 273 270 266 286 219 239 249 228 255 243 256 260 248 258 259 268 226 260 237 272 261 240 246 265 265 220 258 247 271 258 230 273 240 275 275 268 270 258 220 245 232 233 265 256 241 245 246 257 270 275 225 264 245 225 272 249 238 243 244 257 255 249 219 262 229 276 246 256 247 285 261 275 229 261 244 268 242 231 260 239 256 222 247 247 236 249 247 275 286 266 261 233 242 265 241 302 216 262 249 259 244 234 217 236 255 244 236 226 237 224 233 275 226 286 221 259 249 246 265 245 265 271 266 259 238 247 267 271 249 247 267 235 283 262 258 280 244 241 245 249 248 264 246 215 250 258 248 260 242 262 259 283 263 237 265 272 255 247 288 262 258 264 302 236 250 319 278 284 262 258 245 255 270 275 281 243 247 284 269 255 247 260 255 208 258 293 231 230 242 237 249 283 228 249 248 256 233 272 246 246 263 245 267 237 262 247 232 246 272 273 235 262 259 260 265 267 265 260 230 199 271 286 259 235 265 272 261 282 245 237 245 278 255 214 257 258 273 243 242 245 248 257 244 258 244 265 262 256 231 275 243 245 244 241 272 234 249 267 250 272 248 249 235 247 237 242 283 250 228 259 235 227 245 256 280 259 245 262 273 272 241 233 270 259 250 275 225 266 276 269 231 223 246 246 271 271 283 283 261 246 240 229 246 300 233 247 247 226 294 283 273 259 259 238 241 263 266 283 237 276 262 261 247 264 245 236 270 255 240 274 235 234 240 239 257 238 284 244 243 238 256 233 235 244 309 259 259 247 262 207 236 244 239 248 255 265 269 267 213 293 230 249 266 272 225 246 240 242 280 270 272 295 282 260 263 272 250 237 243 242 238 232 259 267 261 245 237 265 247 262 284 255 242 222 248 263 235 278 258 270 247 258 235 241 286 256 259 249 265 269 240 245 258 255 261 261 255 258 288 246 274 273 211 216 265 237 237 240 221 285 280 217 244 226 228 272 255 245 236 225 241 241 235 238 235 247 237 262 243 245 249 267 259 247 234 257 247 258 248 256 236 264 279 241 259 267 263 278 244 272 221 244 286 264 249 285 269 276 246 244 282 267 247 270 245 264 275 248 224 244 268 282 242 258 247 249 275 270 231 242 238 243 213 227 234 283 243 238 230 260 280 267 270 230 219 229 262 261 257 261 247 288 244 271 247 245 245 277 241 257 262 267 261 231 265 237 243 239 234 259 258 244 260 247 264 261 240 255 246 271 257 243 257 241 259 249 234 247 257 240 257 237 247 247 276 265 259 230 255 288 289 234 244 245 233 270 266 235 223 240 258 237 257 270 277 267 227 263 219 267 268 273 274 239 291 263 262 289 248 279 241 261 274 280 296 249 239 266 258 265 255 270 241 257 245 250 226 278 240 269 280 260 233 249 215 272 258 262 243 223 218 245 246 305 256 273 271 248 277 267 231 260 239 284 249 233 239 267 270 241 267 258 274 283 249 237 228 237 241 261 247 271 263 268 246 267 258 237 271 268 257 263 290 280 245 283 245 284 250 291 227 247 226 288 268 232 238 273 270 268 242 267 235 290 241 277 221 233 268 267 239 239 262 255 260 262 271 268 262 272 270 268 240 261 246 266 273 250 273 275 264 274 240 274 256 257 237 237 258 262 267 242 268 270 274 271 256 256 262 249 274 309 263 274 256 267 232 275 241 265 260 264 266 237 241 234 270 263 230 268 271 255 243 243 260 232 266 272 286 248 275 268 278 235 272 287 255 261 262 247 267 264 269 276 272 267 241 281 244 260 263 259 239 265 247 296 274 259 265 281 232 257 268 268 248 266 263 266 212 268 257 272 255 241 269 243 260 281 278 277 233 288 261 234 239 255 262 241 245 277 296 270 272 285 299 245 255 261 274 260 287 255 258 281 278 259 257 277 272 236 256 260 242 268 260 258 287 263 257 260 286 264 263 236 274 244 272 271 257 287 272 242 248 263 237 295 255 292 262 236 242 263 261 234 266 237 244 271 269 227 265 284 243 245 231 239 216 267 274 258 255 265 234 274 296 244 293 258 294 274 261 260 266 273 289 257 287 259 268 295 272 255 291 269 263 246 275 239 294 246 261 226 233 257 223 292 262 278 245 285 226 280 262 268 233 296 301 281 270 235 274 287 249 281 290 264 247 255 271 241 231 257 260 283 271 237 245 247 284 262 256 298 225 282 273 247 238 260 272 223 255 266 256 244 287 249 255 238 286 258 234 287 243 264 276 242 277 281 275 270 247 281 247 260 269 246 267 264 247 269 256 259 275 255 249 268 256 267 246 269 285 241 265 263 265 272 241 277 258 238 266 261 227 250 237 274 266 239 262 234 283 285 240 266 268 265 237 234 248 233 219 265 278 262 272 245 271 282 271 294 224 269 267 257 245 262 259 262 233 285 247 232 259 264 283 271 282 260 219 266 276 264 278 247 248 270 271 228 266 271 276 247 235 272 279 269 263 250 256 292 265 275 275 241 257 234 249 260 255 245 264 270 273 267 261 249 244 218 297 233 235 267 235 238 297 255 266 236 265 256 261 279 270 284 269 269 241 266 240 274 249 264 278 248 281 242 255 286 244 278 258 230 278 241 261 248 259 238 259 227 258 244 270 238 260 284 277 270 265 278 275 271 276 265 283 268 267 244 256 277 257 287 264 277 265 292 249 278 235 291 260 259 227 286 266 241 249 272 282 290 270 288 247 256 243 292 258 236 240 232 247 260 274 271 263 271 242 283 231 256 243 309 295 246 248 249 285 202 255 271 286 271 241 270 275 268 260 272 279 256 233 272 259 222 271 265 249 274 271 293 267 267 265 276 288 272 292 265 266 239 281 297 291 245 226 236 233 208 244 277 255 297 268 250 240 237 257 237 246 281 262 284 266 278 264 267 288 242 258 226 230 242 270 247 249 284 290 249 283 216 261 259 265 295 262 274 249 261 240 259 304 238 271 270 259 283 240 266 248 256 287 268 271 265 242 244 234 245 256 257 269 267 264 235 271 233 265 262 223 280 241 229 294 293 297 266 263 265 279 261 280 244 273 281 221 259 273 248 261 262 276 272 266 260 271 265 242 290 248 245 288 262 260 286 275 268 217 229 248 241 257 282 232 271 242 257 248 269 283 258 261 284 298 297 261 262 269 245 245 267 275 259 281 258 235 303 267 260 242 278 262 225 243 241 269 229 233 289 267 264 262 269 267 288 265 280 258 259 261 286 300 262 293 264 298 264 257 255 277 277 231 274 282 245 276 269 262 271 286 227 275 276 292 259 265 276 262 242 293 268 274 237 248 258 280 249 261 261 246 285 266 262 268 249 284 289 299 291 282 282 308 259 303 275 280 282 268 272 268 278 267 271 274 258 287 270 277 276 250 274 271 305 283 288 287 295 299 235 281 273 276 278 292 280 283 264 280 269 269 272 275 275 231 309 282 264 271 274 278 263 261 264 279 288 260 287 279 269 265 270 281 255 282 242 274 277 312 265 262 275 264 265 296 260 247 256 259 235 263 279 264 267 255 258 325 241 246 283 283 270 265 244 300 257 262 271 248 269 257 269 255 274 235 269 286 232 259 267 243 249 245 300 244 290 262 292 282 288 210 276 285 267 301 259 264 240 296 263 284 258 266 264 278 246 273 249 243 289 268 260 277 283 263 282 242 271 257 275 262 234 272 297 268 286 255 234 262 245 272 258 259 293 272 265 266 246 270 273 257 256 267 272 263 273 240 248 272 246 261 287 280 246 276 283 281 277 295 230 259 270 246 264 255 233 256 277 278 223 258 275 244 267 273 299 237 265 269 240 238 268 257 247 274 237 248 258 241 269 240 230 269 277 272 293 274 266 222 262 234 285 266 264 292 286 292 257 283 224 276 280 257 272 263 267 269 255 282 261 242 262 272 273 259 261 261 238 258 271 261 265 266 273 269 233 265 246 278 293 287 248 268 242 249 268 263 255 244 275 291 256 248 247 277 280 241 266 271 283 277 261 273 273 283 268 292 273 242 272 262 257 220 280 259 282 279 249 268 239 279 271 265 259 241 275 242 288 280 269 271 261 262 270 246 248 239 274 255 241 246 286 281 236 227 267 288 261 273 224 292 266 238 241 245 265 244 257 288 262 244 237 288 278 247 279 223 291 265 238 278 273 271 245 242 282 243 266 272 262 259 264 261 231 249 247 247 259 249 256 272 212 283 268 269 231 266 265 267 277 248 257 275 269 266 237 274 241 278 234 273 256 265 285 255 257 279 266 247 271 248 247 278 206 262 244 272 257 244 263 264 258 245 272 258 265 260 280 290 238 268 255 260 244 247 272 269 273 255 249 256 243 280 275 256 280 291 258 233 262 277 271 270 260 289 215 294 247 268 241 282 271 237 266 234 286 234 234 269 255 255 284 249 230 259 223 259 283 280 263 270 285 248 236 233 237 292 255 264 234 241 266 246 235 275 263 246 243 269 263 272 265 275 272 248 245 250 280 272 246 271 220 261 281 291 259 235 262 242 273 272 263 265 293 278 250 256 267 263 268 267 281 243 247 255 244 237 232 244 236 292 274 259 276 245 259 284 234 263 261 266 223 256 298 288 246 267 237 257 258 270 257 250 248 270 262 258 270 267 238 273 263 264 279 271 234 245 248 265 262 237 262 275 265 241 283 271 250 246 261 241 262 275 242 286 274 227 280 247 267 285 274 248 246 277 257 234 291 241 260 255 276 229 267 255 261 268 247 288 255 267 275 242 272 268 262 246 223 262 237 288 276 256 272 291 265 256 282 260 258 246 300 264 277 241 237 295 246 292 263 257 234 261 246 241 248 242 275 243 282 285 258 247 262 261 246 264 233 247 234 248 270 239 263 284 262 258 238 256 245 292 249 272 266 262 267 274 237 237 240 268 291 275 221 257 219 264 255 257 256 246 267 249 236 258 262 249 259 283 274 230 269 265 233 269 269 273 276 256 248 257 280 222 266 264 266 240 267 260 244 243 236 295 263 279 265 227 260 225 287 281 264 258 237 270 245 272 281 263 277 249 285 265 244 246 267 238 266 263 278 287 265 297 275 323 243 257 238 266 250 264 235 279 274 273 247 243 244 261 229 255 255 281 250 268 234 273 281 271 248 259 242 240 272 245 226 255 246 245 245 260 244 273 264 232 243 289 279 281 249 260 235 278 267 256 256 245 270 239 240 237 268 286 241 267 260 277 295 283 300 271 262 256 259 263 272 262 256 245 255 262 255 265 255 266 265 264 282 271 257 269 245 275 274 278 258 257 283 278 265 264 255 247 276 248 291 262 277 230 277 276 241 212 259 271 259 259 260 280 265 261 260 238 240 223 240 228 289 249 255 288 262 260 267 277 243 248 255 266 263 266 273 263 258 265 269 293 264 263 275 258 257 268 269 258 257 240 243 244 240 267 265 255 305 264 271 271 264 270 264 233 290 266 249 289 257 231 242 286 269 273 240 237 243 256 286 258 242 238 274 243 287 281 267 241 270 255 284 266 263 239 271 269 231 282 271 270 277 266 259 263 269 233 262 217 268 282 266 286 264 272 277 249 247 241 264 247 267 258 249 231 256 287 247 264 234 267 259 247 273 262 236 259 277 245 273 260 285 277 241 268 258 244 257 270 222 246 271 226 295 236 246 273 239 270 266 262 260 281 263 313 249 255 262 269 257 276 242 262 274 248 282 258 239 297 273 257 265 279 279 265 240 275 244 248 236 261 275 255 259 217 277 231 246 223 246 241 260 244 248 255 270 281 273 268 244 258 237 278 259 300 264 272 245 238 266 277 274 258 262 258 273 258 273 292 264 272 255 230 250 271 260 263 266 239 246 260 257 212 284 282 245 284 272 257 239 224 275 255 262 229 263 278 244 271 245 231 263 255 271 240 262 267 242 291 271 264 249 244 278 265 248 235 233 269 275 257 220 268 243 266 265 234 241 247 284 279 257 264 267 265 258 237 282 274 277 256 256 256 246 244 284 246 282 280 247 219 262 239 262 255 268 259 246 277 246 283 274 300 271 244 293 275 264 261 257 267 239 257 285 278 278 260 278 273 262 276 264 277 260 272 306 258 257 255 274 275 266 271 261 265 240 242 276 269 258 291 266 227 268 241 259 258 273 230 269 285 269 275 233 247 268 240 234 263 234 281 293 289 264 262 258 250 274 273 248 278 231 267 279 263 278 261 280 238 258 268 271 293 247 256 277 232 285 259 263 267 265 279 245 234 283 256 230 282 277 276 264 290 273 224 274 285 293 281 242 291 294 274 255 263 269 271 276 268 262 294 279 246 283 242 275 263 259 281 239 276 301 290 266 266 259 277 290 273 259 266 262 258 216 257 255 271 249 230 291 260 270 262 273 241 269 234 273 249 225 269 258 243 248 249 256 271 238 256 232 286 261 257 288 271 258 266 259 269 265 240 259 245 277 263 213 264 277 247 239 255 277 242 262 241 267 298 241 261 258 243 279 235 266 241 275 281 240 239 266 284 283 245 284 275 262 247 263 247 268 256 246 243 243 243 271 267 272 280 261 265 268 263 265 288 261 231 241 237 282 242 246 243 268 267 266 228 246 269 260 245 262 257 259 295 262 223 273 257 255 274 242 230 244 300 271 302 249 270 261 227 247 267 244 247 280 270 240 262 249 237 285 242 279 248 290 259 255 287 233 260 246 257 275 243 255 271 246 257 258 274 298 236 233 241 261 285 246 212 267 257 231 266 241 208 248 276 247 246 242 267 261 235 242 245 294 247 296 272 274 277 277 271 239 258 281 287 264 256 248 275 301 250 256 267 277 233 265 245 294 224 240 256 246 255 240 263 290 239 272 266 301 262 265 262 242 221 270 285 274 271 240 277 270 243 255 238 273 226 256 257 279 242 237 270 258 281 270 226 259 269 232 279 228 248 286 248 292 233 238 246 274 276 275 277 241 279 284 229 278 246 273 240 245 239 265 268 236 227 261 256 266 236 260 238 257 265 240 274 240 276 267 242 234 284 269 259 246 268 265 272 262 268 244 231 275 266 257 282 248 249 261 230 229 245 259 257 297 246 270 259 260 226 204 262 269 236 264 258 290 256 301 273 216 270 260 272 238 279 271 258 259 240 243 249 287 227 257 291 249 241 235 247 281 234 279 289 300 239 269 273 268 286 273 255 282 265 260 273 242 263 279 244 238 259 236 259 304 297 255 296 273 224 270 286 228 255 270 257 269 299 272 255 277 271 276 277 246 290 279 262 244 268 265 268 263 256 286 271 249 289 288 265 303 256 258 271 271 301 308 296 296 311 323 303 296 286 229 282 314 303 272 280 302 293 279 306 275 319 311 308 290 284 304 287 286 289 302 269 311 302 313 310 313 301 299 305 277 297 313 281 304 302 289 281 297 311 313 249 294 281 282 307 279 286 303 276 287 292 290 285 298 281 268 263 260 259 258 272 267 255 274 285 279 249 269 279 275 290 263 286 242 257 255 236 259 244 249 257 268 272 260 264 281 278 286 269 248 258 273 299 260 259 245 247 288 242 272 231 284 244 246 241 237 236 266 280 264 277 247 270 240 229 264 235 261 276 282 262 256 263 240 255 264 246 263 247 259 248 271 261 222 221 231 258 285 257 281 267 234 286 260 266 225 238 239 237 274 241 264 230 278 234 246 243 263 277 241 266 287 285 283 264 256 272 240 235 270 261 266 274 260 272 271 266 237 236 266 271 215 275 266 258 247 240 243 273 271 239 250 273 261 247 270 237 269 249 256 255 244 284 248 293 239 263 224 247 230 239 243 217 235 245 247 287 233 247 262 246 232 267 283 257 231 243 258 255 258 239 259 271 262 269 241 263 263 269 234 302 267 273 243 261 271 244 210 268 235 257 263 241 240 266 235 267 242 269 272 249 272 239 247 258 261 257 236 250 263 247 281 276 259 276 233 258 282 267 281 231 258 256 243 310 276 265 261 256 215 258 277 273 264 224 214 281 241 270 264 237 249 266 277 284 237 263 236 292 262 223 286 250 268 257 237 200 273 263 279 272 274 255 288 247 305 237 248 260 261 268 263 255 238 277 261 248 291 277 286 256 247 264 246 248 257 270 228 257 279 259 240 290 263 277 249 262 273 301 267 280 255 270 269 268 262 231 292 257 260 241 235 246 215 259 279 279 290 226 262 268 261 263 234 279 263 274 250 243 280 232 266 221 264 258 265 267 226 276 289 257 231 262 244 241 265 243 277 263 290 279 264 235 273 225 225 273 243 290 248 257 267 257 275 268 250 270 267 292 262 276 227 259 248 280 261 258 231 273 238 238 262 248 284 250 243 256 260 247 295 280 257 272 232 264 255 277 275 267 261 237 259 258 248 279 266 265 264 261 286 230 269 271 258 283 244 272 259 248 265 278 238 242 247 269 286 259 244 267 260 275 258 257 250 244 249 245 275 241 261 236 238 261 261 248 270 268 258 237 256 257 240 256 291 256 273 246 258 257 221 271 247 229 247 266 249 243 242 221 269 275 261 265 237 236 242 262 239 302 240 239 236 234 258 226 256 235 248 270 238 274 233 268 229 279 272 227 242 258 242 245 245 275 280 244 256 267 279 229 275 237 244 246 240 274 270 260 280 256 249 229 264 249 244 234 297 229 231 249 230 248 259 272 231 286 247 268 259 231 272 281 256 255 260 280 240 264 276 264 288 261 264 239 243 244 256 239 266 250 275 245 229 262 267 264 231 268 257 242 239 275 276 286 245 268 278 255 248 247 255 268 237 240 212 265 241 262 242 248 288 247 235 279 244 269 268 219 237 291 247 212 248 272 282 287 258 236 267 210 263 245 245 262 222 237 243 267 277 235 245 282 270 260 247 260 240 240 280 245 266 244 274 233 234 259 271 227 205 245 234 261 221 240 242 245 248 256 236 248 266 237 222 249 255 223 281 257 278 244 218 225 261 272 265 266 257 285 279 258 238 268 267 271 266 240 267 295 247 240 235 282 242 256 274 245 209 261 220 258 276 267 273 276 234 274 270 265 242 270 277 263 255 270 265 244 282 262 261 255 210 262 241 246 291 234 266 245 300 239 275 256 248 248 240 256 231 248 276 229 287 274 241 266 256 244 236 240 260 264 273 241 287 269 288 262 248 246 265 232 257 265 263 269 233 225 246 271 257 275 287 238 262 263 262 261 276 268 248 283 279 248 263 249 275 233 217 241 266 241 260 259 258 229 268 233 243 245 263 240 217 248 262 265 248 273 278 240 265 211 230 267 233 277 281 270 245 286 249 262 247 248 246 220 242 257 265 274 255 257 293 286 249 262 274 232 264 264 275 297 281 248 232 257 250 297 281 236 262 294 249 257 243 273 249 241 247 258 260 247 236 270 237 265 246 237 275 247 272 245 266 244 256 276 290 266 249 232 278 231 259 247 246 259 281 228 255 260 260 280 249 302 272 262 274 233 256 229 239 243 255 269 289 259 236 244 258 250 270 225 236 244 241 257 284 257 266 281 230 223 249 258 272 247 266 247 268 233 244 259 260 269 249 260 282 243 289 241 265 264 280 258 286 236 268 256 293 273 261 257 296 258 291 248 235 266 286 273 273 262 250 256 273 265 272 272 233 267 255 247 288 274 259 269 248 262 241 220 255 267 277 258 266 234 273 242 238 267 236 240 240 263 255 259 259 244 271 256 246 267 250 267 256 250 262 235 257 260 217 262 241 242 276 226 275 246 260 260 266 227 266 269 272 242 271 262 244 255 256 238 258 259 234 266 230 267 261 272 236 269 265 290 243 256 248 284 257 264 263 260 244 273 286 276 243 242 266 286 229 246 263 256 215 271 264 285 294 264 231 287 256 263 220 236 256 256 255 218 242 263 221 267 233 272 232 242 242 248 246 271 237 239 275 234 234 250 273 298 250 273 256 236 271 255 234 265 293 260 236 266 258 273 278 284 256 307 238 261 263 246 241 272 231 261 235 265 255 242 289 266 286 279 269 249 231 243 286 277 278 269 301 282 260 222 284 269 234 261 279 261 281 259 261 247 256 256 280 261 240 259 269 229 255 256 258 276 279 248 264 244 277 270 239 273 273 269 271 262 234 247 259 262 271 235 255 257 263 245 275 249 268 246 241 269 249 258 246 293 257 249 269 271 274 243 278 265 258 302 261 285 259 261 240 262 249 276 228 242 243 265 259 236 261 277 299 236 256 240 241 282 280 249 279 232 241 222 267 249 220 222 255 238 238 262 283 248 279 278 233 232 266 263 275 257 279 256 249 282 283 222 249 266 284 265 256 243 273 242 232 256 269 285 284 255 287 259 243 242 288 257 243 257 255 230 235 239 243 267 277 257 214 263 270 282 279 248 268 257 276 240 249 281 269 249 244 283 247 237 259 245 260 246 265 236 227 240 228 263 261 271 264 241 244 239 260 284 246 272 275 258 245 255 257 248 228 255 243 256 217 241 246 257 257 259 265 221 221 243 245 248 265 240 279 238 266 262 265 261 256 234 217 265 257 261 229 239 266 241 291 263 245 263 277 244 265 293 267 255 236 303 273 256 267 282 276 244 264 277 266 268 301 232 293 272 268 282 248 236 260 264 241 281 273 225 218 263 231 243 246 258 243 228 244 270 268 226 224 231 247 272 279 243 255 248 267 272 295 282 238 237 264 256 263 290 240 268 247 263 286 282 279 262 246 260 241 271 242 247 271 242 258 288 294 270 271 255 284 238 295 277 248 221 280 281 280 258 268 292 281 278 273 270 244 261 285 238 282 233 282 259 238 267 225 263 256 264 249 228 226 244 258 277 248 265 259 264 248 247 230 289 258 235 255 290 283 268 237 268 261 259 265 295 247 240 236 257 245 259 247 307 272 264 246 264 243 233 267 247 264 257 265 246 273 276 222 249 287 250 303 266 235 241 238 277 248 258 260 271 246 237 273 259 267 306 268 263 245 248 268 264 264 276 263 272 239 237 263 302 262 242 283 248 276 271 257 279 228 256 256 240 267 259 246 266 277 276 269 274 258 295 273 282 279 278 248 266 247 276 304 243 278 281 249 260 233 246 246 261 264 247 198 278 248 270 263 259 257 238 268 272 261 305 276 278 237 265 247 246 248 281 226 260 265 299 276 239 255 257 275 289 269 286 232 277 278 271 273 274 263 275 262 260 285 308 271 268 288 284 283 279 295 275 279 267 270 283 267 275 266 270 259 284 258 271 279 256 264 274 258 276 283 267 307 262 244 258 246 266 259 246 245 270 266 271 269 264 258 256 279 269 264 259 241 284 257 269 270 273 246 258 239 224 263 278 257 287 286 297 268 258 269 244 256 270 272 266 233 246 249 256 266 284 258 242 271 257 266 277 247 258 283 271 260 245 269 229 264 274 225 267 282 243 255 278 261 237 265 260 271 223 238 237 276 262 241 220 265 291 273 273 224 248 291 269 257 240 291 268 256 273 238 236 267 286 244 255 271 240 255 238 266 266 243 266 292 263 271 256 279 248 258 269 262 257 281 247 265 266 266 256 247 268 275 270 250 239 233 248 240 231 218 285 242 247 230 259 227 231 247 259 265 268 243 267 261 266 234 233 266 255 280 275 277 245 245 237 244 291 271 262 261 247 248 278 261 272 245 287 240 232 266 275 260 247 244 246 268 249 275 242 270 274 256 256 274 296 234 258 276 287 230 260 272 272 264 260 264 243 278 236 273 244 265 246 274 262 242 245 265 279 255 249 285 238 248 264 265 274 241 255 255 247 269 255 279 245 277 285 239 278 272 277 265 281 272 258 245 286 283 270 256 244 275 281 286 235 241 279 271 246 272 267 283 236 274 298 263 268 235 276 235 226 269 230 237 280 267 307 264 280 243 258 246 270 272 279 243 263 230 242 264 248 240 231 228 273 269 284 263 259 248 274 270 239 270 241 281 300 281 258 263 233 273 277 256 274 259 275 281 240 257 245 241 247 270 258 240 287 243 245 281 246 247 238 241 259 248 277 290 267 235 306 235 225 262 288 230 270 261 242 224 282 301 263 274 255 235 271 239 248 270 248 242 228 257 272 288 264 282 257 289 290 240 266 288 235 272 227 270 277 264 242 258 286 273 289 267 261 249 263 276 277 283 294 239 246 266 255 285 235 301 282 276 247 296 276 277 271 274 227 276 269 272 263 246 228 278 258 255 278 261 243 273 242 282 237 233 258 269 240 275 213 265 249 246 236 274 247 273 272 269 265 275 262 242 241 264 270 269 255 222 246 265 274 274 269 277 279 240 242 268 280 259 247 240 256 246 297 250 279 278 264 222 256 271 267 247 255 260 259 245 292 255 255 246 282 291 273 240 260 236 287 249 261 237 275 246 227 234 247 260 303 264 287 275 247 277 248 258 277 257 239 278 247 242 276 260 256 262 262 263 250 258 268 256 299 250 287 257 258 270 223 246 257 239 271 281 260 246 268 276 292 241 245 255 257 248 248 275 283 244 266 282 261 244 265 246 264 266 261 240 277 298 238 241 277 257 280 257 302 290 285 258 272 262 226 275 261 300 302 264 295 232 281 286 289 245 236 272 241 242 247 264 299 264 265 261 270 284 231 277 275 261 294 279 267 247 282 267 264 263 260 270 282 284 231 256 281 278 268 262 241 259 263 257 262 262 258 289 241 250 264 262 295 270 306 269 261 306 265 263 262 256 274 265 286 298 267 279 223 239 259 259 283 250 259 283 263 259 281 278 245 231 266 268 272 269 275 271 268 284 234 281 270 273 222 284 298 285 261 266 255 239 243 263 294 270 244 247 250 224 249 292 270 274 250 247 272 246 213 267 284 274 279 263 300 257 275 273 266 234 300 286 255 261 292 275 278 289 235 292 281 275 305 279 268 273 250 266 268 264 267 262 245 266 269 247 222 290 274 275 261 263 245 263 238 298 271 280 291 268 288 271 267 275 265 242 269 261 271 260 285 257 285 243 262 259 268 238 259 250 270 231 256 265 271 259 275 301 244 272 297 271 271 234 280 279 255 237 268 238 276 260 263 249 280 247 234 246 256 248 257 241 243 259 269 261 235 272 262 285 245 291 270 296 259 269 279 249 268 249 256 258 233 257 236 261 241 276 264 227 278 255 281 270 296 245 277 262 266 257 267 269 280 264 266 259 263 266 238 223 268 237 237 255 234 290 240 259 227 286 317 277 266 237 237 306 264 274 262 266 257 288 263 255 280 260 267 238 276 262 295 277 260 274 279 275 262 275 275 261 263 258 293 275 275 266 256 264 245 272 258 278 238 299 235 270 241 263 262 268 249 257 262 267 232 269 256 242 279 283 276 284 233 267 248 232 274 243 265 286 273 264 237 255 234 276 278 261 259 282 257 247 273 215 284 261 234 245 264 234 269 278 264 260 267 297 249 237 240 273 295 249 262 257 266 267 271 269 272 250 261 238 236 240 270 279 271 262 266 281 257 256 279 281 236 289 263 288 247 250 256 222 271 268 277 258 266 236 275 257 263 278 246 264 248 244 275 275 272 290 245 249 273 241 274 259 240 249 278 244 247 245 229 256 261 266 243 266 259 243 236 257 267 268 246 234 218 272 279 229 269 256 277 269 261 256 274 258 242 264 281 260 248 261 258 257 260 240 280 275 289 242 280 261 274 259 243 268 278 281 263 294 259 282 259 268 284 272 262 267 292 242 249 238 273 250 256 231 248 262 287 268 275 274 233 227 273 284 248 276 286 266 266 229 271 255 228 293 273 260 298 269 242 257 261 261 241 266 263 241 271 232 268 276 259 258 284 279 285 280 265 269 248 255 269 260 287 284 248 271 256 264 235 299 274 301 274 255 273 239 275 231 234 269 289 275 229 256 242 258 274 276 289 283 244 246 284 261 270 257 247 270 258 247 278 283 283 291 271 242 271 240 271 280 269 245 255 240 262 258 234 238 275 237 217 284 256 269 256 269 265 257 258 270 241 273 246 248 258 237 257 295 267 264 262 281 243 265 300 287 268 287 255 265 262 278 279 235 256 247 272 273 275 289 249 244 260 235 272 224 245 239 266 288 288 270 243 271 235 277 259 277 271 213 249 249 265 243 265 237 239 247 284 265 260 264 270 268 243 259 247 231 263 274 249 282 276 244 256 266 286 246 208 242 247 280 248 264 220 293 245 225 257 258 271 241 262 231 260 260 259 248 236 233 279 239 246 261 247 258 260 245 243 266 273 279 243 276 259 241 269 257 247 240 274 249 262 292 250 247 281 259 276 267 238 256 244 242 241 250 247 277 280 245 242 248 261 234 223 245 265 274 245 267 229 237 240 239 227 293 248 248 277 239 268 230 249 269 264 263 273 260 263 262 276 279 274 249 241 269 238 243 295 264 276 259 240 267 256 255 292 271 269 258 285 246 266 259 263 293 293 248 281 262 268 256 241 260 240 263 243 244 264 259 234 258 265 256 242 244 267 255 262 230 238 243 272 260 267 247 268 244 278 229 288 246 266 275 264 257 260 242 258 267 264 263 277 260 266 240 281 257 246 241 246 263 283 276 268 278 259 255 230 272 267 272 243 234 275 249 275 241 265 262 259 246 232 276 238 236 239 257 278 275 227 286 255 238 250 289 256 239 269 269 240 256 236 241 285 258 245 243 227 246 266 241 225 267 274 223 247 264 234 282 249 247 293 262 242 281 232 292 288 234 278 222 270 278 235 234 266 269 265 244 227 279 245 227 256 262 242 266 245 242 242 267 228 264 286 226 280 264 302 274 271 223 261 247 242 234 261 280 237 240 256 274 249 248 292 271 261 243 225 257 280 267 280 248 257 300 241 262 283 263 255 276 259 271 264 264 259 246 272 283 261 275 291 260 255 291 269 246 278 243 258 241 273 276 276 295 260 262 260 274 299 295 246 234 247 235 271 273 269 268 264 247 258 261 249 263 278 245 267 258 220 268 299 275 263 294 244 255 264 243 244 272 267 248 261 272 240 264 292 293 278 244 285 282 272 238 296 245 260 239 239 302 282 255 262 262 270 247 279 267 276 256 244 294 275 279 306 269 233 286 244 283 273 271 286 283 223 269 292 259 272 262 259 264 313 268 287 265 256 266 278 241 293 282 240 281 269 305 258 307 256 264 280 268 268 261 305 284 275 261 283 308 272 311 277 287 271 284 280 277 295 278 268 289 283 293 261 271 297 302 307 287 303 288 302 314 270 280 270 270 233 318 242 258 279 279 242 279 249 299 264 278 242 324 265 282 291 276 249 270 259 299 284 292 283 296 250 274 302 285 274 276 293 281 265 278 274 288 268 285 257 278 280 297 258 278 277 278 247 278 278 282 290 271 279 260 248 260 262 269 275 242 302 289 270 313 274 306 280 279 280 299 256 289 278 272 292 305 288 234 276 271 241 290 280 263 256 278 266 291 299 276 255 275 289 261 268 270 261 282 242 277 284 282 294 249 249 242 270 278 237 284 260 262 287 244 277 279 263 277 279 259 283 258 296 266 247 272 272 242 269 275 256 270 272 234 265 269 244 259 284 284 272 231 266 261 263 259 243 267 278 264 247 245 240 245 276 267 266 264 255 268 258 277 243 247 264 275 233 290 261 268 246 240 233 270 267 263 249 238 230 274 287 263 268 271 268 258 294 259 267 282 266 279 282 261 270 256 255 277 243 294 241 257 226 272 280 284 271 243 265 272 286 275 237 307 248 282 284 260 260 244 288 283 273 262 246 273 220 268 264 265 241 227 280 274 275 273 311 259 271 270 270 240 248 268 272 259 268 281 269 247 256 295 248 241 255 265 264 248 275 249 232 257 290 263 285 261 265 291 239 264 261 270 320 282 244 303 235 255 266 268 270 245 244 256 289 264 283 276 261 242 246 257 269 245 220 268 260 273 271 236 235 270 244 266 281 264 277 262 258 288 261 257 247 296 270 277 268 233 294 258 229 270 261 250 263 248 235 238 291 265 269 241 238 312 285 275 307 284 301 276 266 257 238 272 282 240 246 249 287 248 277 281 266 297 259 273 277 279 262 273 264 276 263 275 264 279 232 266 233 266 292 244 277 258 265 260 284 256 271 314 287 272 267 238 242 292 266 257 290 266 269 262 246 282 286 281 232 281 279 248 269 261 244 248 263 272 261 272 263 238 256 244 272 250 256 245 270 259 267 231 273 244 240 263 262 242 255 265 270 288 264 232 281 248 262 263 278 267 258 226 280 269 242 259 296 248 255 271 276 257 255 285 250 272 280 272 245 266 284 258 262 230 248 257 256 260 226 280 265 243 278 243 279 270 261 274 270 273 262 263 268 235 258 236 276 284 269 221 284 278 267 256 247 281 233 268 278 273 241 229 235 275 264 265 260 226 277 259 257 276 256 271 242 274 266 268 242 240 302 258 230 285 273 257 286 272 244 238 283 218 230 220 290 239 290 257 235 271 273 236 248 275 324 245 276 285 273 257 257 234 281 262 279 267 266 224 256 248 286 268 244 258 255 243 231 270 241 241 270 283 267 282 235 241 244 261 225 274 286 242 250 264 263 255 208 268 262 264 258 245 271 278 269 267 263 271 268 284 287 243 265 271 233 260 239 299 251 272 217 241 249 265 270 267 257 230 266 249 267 243 234 255 274 260 256 255 225 277 233 247 265 255 264 229 236 255 260 263 262 275 232 228 258 242 275 229 244 239 273 222 266 242 240 264 243 228 260 229 234 275 304 261 270 257 273 256 287 265 240 257 229 265 239 268 293 229 267 219 259 273 267 271 249 275 225 272 257 258 265 263 256 259 269 210 241 243 244 280 223 249 225 257 260 265 272 262 266 282 228 249 245 264 291 279 279 271 282 274 259 275 280 255 274 268 230 277 244 261 256 275 262 257 248 259 265 260 267 272 272 209 266 229 259 264 255 284 260 248 255 238 229 266 267 245 269 215 263 259 256 244 242 266 243 241 263 261 239 260 260 264 242 270 267 269 237 222 260 270 213 256 255 231 239 265 233 268 244 231 247 231 261 276 249 259 256 273 237 243 278 274 229 246 245 234 231 268 287 260 242 290 269 245 240 260 285 258 273 250 258 228 220 246 249 278 299 243 233 261 264 264 278 273 270 264 266 278 269 249 290 260 246 246 288 264 279 276 268 234 264 261 259 248 243 276 264 244 247 237 273 248 266 217 268 249 243 271 267 269 269 269 229 243 246 246 248 267 245 237 265 268 243 266 269 257 245 273 290 256 281 258 303 222 273 262 241 244 260 269 261 284 245 249 262 284 249 267 241 233 256 275 270 259 239 274 274 257 317 220 285 265 249 268 296 266 260 266 232 256 283 283 238 237 285 268 279 264 267 261 273 275 231 242 256 290 234 248 264 246 263 293 263 242 229 227 276 289 242 245 268 259 258 261 263 283 277 266 269 233 240 237 271 256 230 247 283 263 244 277 270 262 267 266 267 269 258 278 240 255 236 295 261 274 277 304 294 274 260 267 245 272 267 292 263 271 238 223 273 282 262 296 247 291 265 240 274 273 267 239 267 245 269 265 259 260 238 285 240 257 267 246 281 286 282 273 274 258 267 278 269 263 267 288 259 277 263 241 269 215 249 264 272 243 242 263 266 269 243 268 277 265 259 235 277 278 271 276 289 276 244 282 233 264 222 265 291 295 264 281 282 274 264 243 246 233 269 271 240 266 278 232 274 245 272 228 275 279 256 267 290 262 260 261 259 285 242 272 248 258 247 269 256 256 262 284 268 241 268 287 263 276 245 234 267 279 258 261 266 264 269 302 233 275 262 238 259 271 276 263 271 247 299 285 282 277 265 277 241 243 275 278 266 276 245 269 258 262 234 248 272 284 237 272 243 283 249 261 286 288 255 292 249 275 275 244 298 270 272 287 269 271 247 256 267 257 257 264 280 255 271 283 292 276 274 269 259 279 248 286 263 250 277 305 290 264 234 274 241 263 273 240 239 256 240 293 265 245 279 244 277 275 274 242 298 264 248 267 284 256 255 279 255 280 274 261 269 283 275 304 261 258 271 276 249 256 255 270 246 273 297 285 232 260 265 275 274 248 276 240 286 232 284 262 273 276 276 287 245 267 279 289 279 277 265 266 248 240 237 278 247 265 257 260 280 269 261 257 263 260 273 276 263 274 294 272 249 265 266 272 270 250 266 290 271 259 278 257 272 297 268 261 272 262 243 274 260 277 290 273 263 258 296 238 255 283 261 271 265 287 297 263 233 291 243 266 285 256 260 257 259 248 267 283 267 289 243 265 238 261 265 294 257 255 286 255 246 275 291 276 272 262 278 261 292 286 272 245 271 276 232 257 261 293 262 235 281 287 248 271 272 277 238 269 276 261 275 275 244 282 262 301 259 274 289 247 276 270 289 263 279 292 303 260 257 268 239 265</counts>
			</dataPoints>
		</scan>
	</xrdMeasurement>
</xrdMeasurements>