File: data/XRD/XG-Luft/XG-875/W6824-1D_XG_Luft_875.xrdml
<xrdMeasurements xmlns="http://www.xrdml.com/XRDMeasurement/2.1" xmlns:xsi="http://www.w3.org/2001/XMLSchema-instance" xsi:schemaLocation="http://www.xrdml.com/XRDMeasurement/2.1 http://www.xrdml.com/XRDMeasurement/2.1/XRDMeasurement.xsd" status="Completed">
	<comment>
		<entry>Configuration=Factory configuration, Owner=User-1, Creation date=7/8/2013 4:01:53 PM</entry>
		<entry>Goniometer=PW3050/65 (Theta/2Theta); Minimum step size 2Theta:0.0001; Minimum step size Omega:0.0001</entry>
		<entry>Sample stage=MRD Cradle; Minimum step size Phi:0.01; Minimum step size Chi:0.01; Minimum step size X:0.01; Minimum step size Y:0.01; Minimum step size Z:0.001</entry>
		<entry>Diffractometer system=XPERT-PRO</entry>
		<entry>Measurement program=C:\PANalytical\Data Collector\Programs\Jorrit\2thom\_absolute_2th-om_10-130deg_PIXscan_56min.xrdmp, Identifier={15BCCF57-2807-42BD-B5B9-ECC0B3DC9284}</entry>
		<entry>Batch program=C:\PANalytical\Data Collector\Programs\SimonL\batch6x_2thom_10-130°_z9.1_x0,10,20,30_y20,40_57min - Kopie.xrdmp, Identifier={8874E540-C3F4-4307-831A-CD55F073CDCD}</entry>
	</comment>
	<sample type="To be analyzed">
		<id></id>
		<name></name>
		<preparedBy></preparedBy>
	</sample>
	<xrdMeasurement measurementType="Scan" status="Completed" sampleMode="Reflection">
		<comment>
			<entry>_absolute_2th-om_10-130deg_PIXscan_56min</entry>
			<entry>PHD Lower Level = 4.83 (keV), PHD Upper Level = 11.27 (keV)</entry>
		</comment>
		<usedWavelength intended="K-Alpha 1">
			<kAlpha1 unit="Angstrom">1.5405980</kAlpha1>
			<kAlpha2 unit="Angstrom">1.5444260</kAlpha2>
			<kBeta unit="Angstrom">1.3922500</kBeta>
			<ratioKAlpha2KAlpha1>0.5000</ratioKAlpha2KAlpha1>
		</usedWavelength>
		<incidentBeamPath>
			<radius unit="mm">320.00</radius>
			<xRayTube id="1010048" name="Empyrean Cu LFF HR (9430 033 7310x) DK442154">
				<tension unit="kV">40.0</tension>
				<current unit="mA">40.0</current>
				<anodeMaterial>Cu</anodeMaterial>
				<focus type="Line">
					<length unit="mm">12.0</length>
					<width unit="mm">0.4</width>
					<takeOffAngle unit="deg">4.2</takeOffAngle>
				</focus>
			</xRayTube>
			<xRayMirror id="27010001" name="Inc. Beam Cu W/Si (parabolic MRD)" hybrid="false">
				<crystal type="Graded" shape="Parabolic">W/Si</crystal>
				<acceptanceAngle unit="deg">0.800</acceptanceAngle>
				<length unit="mm">60.0</length>
			</xRayMirror>
			<sollerSlit id="21010002" name="Soller slits 0.04 rad.">
				<opening unit="rad">0.0400</opening>
			</sollerSlit>
			<mask id="22030007" name="Fixed mask 2 mm">
				<distanceToSample unit="mm">220.00</distanceToSample>
				<width unit="mm">2.00</width>
			</mask>
			<divergenceSlit id="22010011" name="Fixed slit 1/32°" xsi:type="fixedDivergenceSlitType">
				<distanceToSample unit="mm">220.00</distanceToSample>
				<height unit="mm">0.05</height>
			</divergenceSlit>
		</incidentBeamPath>
		<diffractedBeamPath>
			<radius unit="mm">320.00</radius>
			<sollerSlit id="21010002" name="Soller slits 0.04 rad.">
				<opening unit="rad">0.0400</opening>
			</sollerSlit>
			<receivingSlit id="22010001" name="Fixed slit 4°">
				<height unit="mm">5.88</height>
			</receivingSlit>
			<detector id="7010017" name="PIXcel3D 1x1 detector" xsi:type="areaDetectorType">
				<phd unit="%">
					<lowerLevel>30.0</lowerLevel>
					<upperLevel>70.0</upperLevel>
				</phd>
				<mode>Scanning</mode>
				<activeChannelsEquatorial>255</activeChannelsEquatorial>
				<activeChannelsAxial>255</activeChannelsAxial>
				<pitchEquatorial unit="mm">0.05500</pitchEquatorial>
				<pitchAxial unit="mm">0.05500</pitchAxial>
				<readOutPeriod unit="seconds">0.135</readOutPeriod>
			</detector>
		</diffractedBeamPath>
		<scan appendNumber="0" mode="Continuous" scanAxis="2Theta-Omega" status="Completed">
			<header>
				<startTimeStamp>2024-10-30T23:07:04+01:00</startTimeStamp>
				<endTimeStamp>2024-10-31T00:03:10+01:00</endTimeStamp>
				<author>
					<name>PRO-MRD</name>
				</author>
				<source>
					<applicationSoftware version="6.1b">Data Collector</applicationSoftware>
					<instrumentControlSoftware version="7.0E 20130304">XPERT-PRO</instrumentControlSoftware>
					<instrumentID>0000000011142674</instrumentID>
				</source>
			</header>
			<dataPoints>
				<positions axis="2Theta" unit="deg">
					<startPosition>9.99826193</startPosition>
					<endPosition>129.99755682</endPosition>
				</positions>
				<positions axis="Omega" unit="deg">
					<startPosition>4.99913096</startPosition>
					<endPosition>64.99877841</endPosition>
				</positions>
				<positions axis="Phi" unit="deg">
					<commonPosition>0.00</commonPosition>
				</positions>
				<positions axis="Chi" unit="deg">
					<commonPosition>0.00</commonPosition>
				</positions>
				<positions axis="X" unit="mm">
					<commonPosition>30.00</commonPosition>
				</positions>
				<positions axis="Y" unit="mm">
					<commonPosition>0.00</commonPosition>
				</positions>
				<positions axis="Z" unit="mm">
					<commonPosition>9.100</commonPosition>
				</positions>
				<commonCountingTime unit="seconds">32.895</commonCountingTime>
				<counts 394 380 393 384 390 377 344 419 381 392 359 362 363 397 386 407 386 387 396 386 399 370 374 388 352 386 413 400 396 371 387 362 384 382 379 390 376 372 408 366 390 402 426 386 373 400 343 395 389 341 401 386 377 359 397 417 382 399 367 406 410 392 396 373 379 419 365 362 382 363 373 349 340 385 421 423 371 417 404 421 390 378 400 363 402 355 370 374 394 362 377 359 378 358 367 371 374 340 328 381 377 349 355 360 395 371 329 381 360 366 398 363 320 358 358 390 345 364 388 364 365 397 349 347 363 400 370 377 360 343 355 334 334 358 339 359 355 368 374 381 390 394 342 349 350 330 373 379 383 325 357 347 356 352 316 367 353 385 377 347 369 339 338 368 384 376 380 341 366 364 338 339 366 367 348 350 361 322 351 351 354 376 358 349 362 337 365 327 329 333 357 353 356 362 349 371 357 321 359 370 347 342 334 389 339 328 364 348 339 379 317 337 340 368 345 382 340 333 341 328 380 356 335 343 321 323 350 338 335 367 334 344 339 336 328 342 328 329 331 353 315 343 322 382 330 346 335 361 364 334 361 345 336 325 341 339 324 315 336 337 311 316 334 320 321 351 312 360 334 348 330 355 337 337 339 330 338 352 346 345 353 364 290 333 344 337 377 328 369 307 332 343 323 327 312 326 313 349 329 338 316 354 313 312 321 321 311 301 322 360 342 332 322 331 297 355 357 296 304 349 355 321 333 325 305 319 336 344 344 311 345 318 361 322 337 336 353 314 300 331 321 344 269 296 333 333 310 351 310 286 319 311 331 328 337 343 319 314 294 337 305 303 350 313 323 356 331 335 323 299 326 300 310 317 307 280 301 304 331 313 348 327 306 278 296 284 314 314 321 301 328 304 324 309 296 303 326 338 280 320 312 296 344 309 303 308 298 323 337 312 300 321 341 329 316 304 309 291 345 336 314 317 340 308 304 315 293 282 300 316 326 323 288 340 317 299 308 299 276 320 313 304 305 302 269 277 315 299 301 301 293 311 288 330 285 297 314 333 278 304 304 329 315 301 315 335 270 294 315 299 273 312 313 305 306 284 324 310 288 294 302 315 288 271 326 312 306 310 380 323 302 311 327 312 301 342 305 308 308 326 334 286 281 294 306 320 340 334 300 298 322 299 308 300 285 300 308 265 311 287 329 307 321 302 308 305 317 295 308 274 290 264 333 302 309 289 330 309 334 304 301 278 323 242 288 302 289 316 287 304 294 304 271 335 288 325 327 288 285 285 282 299 283 279 293 305 299 279 303 297 329 309 306 301 300 297 285 298 271 299 332 302 277 311 284 322 346 311 299 306 278 282 297 288 322 328 289 270 299 305 298 282 299 276 277 294 278 298 300 301 282 305 297 272 299 285 287 300 302 290 301 313 297 327 318 255 297 294 293 279 276 282 312 296 314 324 281 264 307 269 293 312 320 318 299 278 271 281 273 288 295 276 274 302 276 284 290 296 311 272 271 286 324 301 286 312 304 325 276 297 293 297 304 295 289 266 274 293 310 274 258 280 265 292 296 306 283 237 288 260 263 279 266 282 313 314 303 291 267 296 261 286 278 280 266 305 305 273 278 266 256 289 272 280 268 260 288 296 319 280 306 286 278 294 271 280 272 297 278 292 278 320 276 311 292 278 315 274 290 282 264 286 315 256 278 309 319 257 270 266 269 288 310 293 307 297 276 303 288 275 321 261 308 271 285 294 271 286 311 288 283 301 275 285 282 278 289 263 290 249 297 313 287 285 287 291 271 310 284 309 300 263 276 278 304 302 299 294 293 267 273 256 277 283 274 276 267 305 272 290 285 289 275 288 310 280 267 299 277 306 291 248 306 274 270 288 277 293 305 274 271 281 297 310 290 292 298 273 301 272 289 314 309 266 281 291 280 306 287 288 267 285 281 284 296 310 271 274 272 297 271 288 282 275 272 282 297 299 315 287 266 292 272 297 256 276 279 305 292 303 294 264 260 279 306 303 295 275 307 265 290 310 300 256 270 290 287 297 262 292 293 258 304 298 262 265 282 307 312 305 316 299 326 282 268 295 304 295 284 315 276 267 291 292 298 314 304 286 300 298 299 264 308 289 270 312 282 292 301 310 301 297 323 264 286 242 317 300 299 301 306 295 267 281 308 298 304 287 324 311 268 284 288 297 278 293 320 296 277 278 282 279 304 286 283 297 282 290 301 302 296 261 311 291 272 274 249 292 279 301 265 255 291 310 244 284 275 303 278 293 310 280 304 266 266 301 292 246 316 291 290 311 308 341 308 275 285 261 275 274 261 285 301 276 277 265 297 304 307 275 286 275 285 262 297 285 290 310 275 301 322 314 286 269 279 298 306 273 306 267 304 263 282 295 296 279 273 266 296 262 288 293 290 274 285 289 282 292 281 301 309 272 309 304 275 281 292 309 278 305 321 263 289 302 279 296 295 270 276 288 265 276 295 278 272 302 288 307 273 264 226 267 281 302 301 326 268 280 257 287 268 271 297 283 291 321 245 296 303 269 308 316 275 283 293 278 278 278 296 305 309 318 344 256 286 303 318 282 278 299 294 279 295 305 269 286 274 274 285 286 314 320 302 290 276 302 303 297 314 271 286 315 257 283 311 263 274 288 280 288 282 307 283 329 300 310 304 293 311 295 283 270 289 270 264 258 281 304 257 283 304 290 298 297 286 277 276 266 322 318 271 265 292 287 290 302 282 272 301 264 289 336 282 306 263 314 292 309 292 277 295 286 256 287 276 276 309 282 292 291 258 280 266 297 279 280 286 298 295 292 267 266 289 308 272 255 285 283 274 292 285 281 300 303 267 278 273 276 294 256 275 274 278 268 281 319 294 301 298 237 263 319 297 247 292 287 272 294 273 278 296 289 263 284 315 298 282 278 280 293 276 324 284 280 300 278 299 302 301 287 290 296 259 271 270 260 289 269 246 278 288 269 302 288 281 301 264 274 314 291 304 297 274 258 257 293 297 271 281 280 285 282 294 271 277 299 284 285 296 249 255 269 286 265 317 292 276 266 303 296 281 245 297 280 262 241 279 311 290 281 278 256 260 284 275 249 302 266 293 261 283 265 307 272 257 260 299 273 298 245 265 275 303 282 286 304 299 294 300 268 286 262 293 272 279 314 280 277 276 267 275 288 281 278 284 295 279 242 272 282 262 262 260 262 289 258 268 279 265 288 291 260 298 270 262 297 256 296 291 283 269 245 307 270 287 273 260 267 294 241 284 266 256 304 247 242 257 275 244 275 271 243 249 276 287 242 288 273 293 278 255 258 265 286 238 286 269 290 291 292 298 279 285 292 288 259 265 229 245 284 301 266 284 266 243 261 269 279 274 255 279 266 289 274 279 278 317 265 272 299 274 282 264 279 325 258 256 288 274 265 280 289 269 305 273 275 289 299 269 282 271 274 246 264 271 248 303 255 276 282 277 259 265 248 274 276 248 260 290 250 300 286 277 275 261 280 247 287 269 262 280 286 281 227 270 311 257 274 304 261 262 249 255 292 250 238 286 277 266 270 264 283 273 274 264 270 294 276 267 287 260 269 230 272 258 272 245 294 260 255 278 276 274 235 241 249 259 277 249 272 260 265 255 313 262 245 301 266 288 263 273 274 271 304 238 268 287 264 288 262 280 265 265 288 270 278 279 267 261 260 280 297 245 297 241 274 273 262 246 267 237 293 266 286 288 264 263 276 282 258 289 268 259 258 275 270 265 265 284 276 271 255 272 255 242 258 262 255 291 268 255 269 258 243 244 257 276 278 237 243 296 273 284 262 287 298 244 261 255 257 232 241 257 242 242 255 249 256 290 258 237 216 255 263 231 278 266 285 268 272 261 257 246 233 259 225 286 265 283 244 259 249 232 261 232 228 248 270 250 239 250 248 223 271 258 230 228 262 239 237 248 263 247 279 270 230 266 224 272 231 247 267 229 266 260 275 247 234 246 282 239 292 258 265 281 215 255 238 245 277 228 239 218 227 242 295 227 228 217 292 238 242 247 239 270 238 217 250 271 267 266 246 264 232 234 281 274 249 249 268 217 239 260 243 248 273 257 262 238 231 232 230 242 234 227 291 236 261 249 230 229 262 243 243 266 259 270 272 261 240 215 244 260 262 275 239 263 242 241 271 273 242 238 273 229 258 240 257 240 263 261 262 246 271 263 236 266 274 266 267 223 243 232 225 247 264 257 233 261 232 243 244 249 231 242 228 255 260 247 239 277 273 247 273 247 257 246 278 250 264 271 241 277 259 263 257 247 249 240 222 214 263 221 255 245 256 255 236 226 200 264 209 227 249 222 216 237 226 268 265 224 256 245 240 220 231 262 266 241 232 230 238 240 235 265 268 227 264 250 239 221 231 236 258 246 247 248 230 255 217 258 227 220 238 242 241 246 232 256 218 234 220 235 257 240 218 213 215 260 260 258 225 258 225 250 234 244 224 255 242 210 232 227 244 265 236 237 244 248 259 239 222 231 248 239 216 227 242 225 233 264 242 218 245 217 248 255 238 237 242 229 216 206 228 237 255 243 234 262 264 227 226 233 238 234 247 262 232 238 238 246 238 221 246 248 241 260 225 234 234 271 217 243 235 240 248 215 250 217 228 219 206 259 226 241 256 227 238 256 220 218 231 246 262 222 234 259 237 220 255 205 216 233 243 217 217 216 213 225 225 220 213 222 235 223 216 238 257 231 216 259 240 231 218 189 216 229 231 220 208 229 287 240 229 247 236 221 226 237 255 241 241 220 234 225 259 244 246 244 200 228 246 242 239 207 226 227 235 256 217 229 214 217 211 236 221 215 244 257 240 242 236 226 241 231 229 232 229 243 204 226 234 232 226 259 219 229 221 250 236 233 217 249 259 259 229 232 257 229 215 240 264 236 233 226 235 229 210 225 230 226 224 241 196 256 185 246 193 214 212 225 215 201 256 238 247 220 231 221 232 259 238 243 229 234 232 257 241 219 241 211 221 243 222 256 205 211 238 217 220 223 231 210 218 226 225 235 218 226 220 266 225 204 221 214 213 214 233 210 216 198 234 234 230 242 265 208 238 237 236 203 260 207 228 238 241 213 197 238 240 216 214 228 208 226 229 233 210 259 224 227 230 196 213 232 233 234 242 215 219 207 231 214 231 205 225 216 268 233 232 184 228 226 223 219 244 228 222 236 214 240 218 211 259 218 215 230 221 215 229 211 221 226 222 225 225 229 197 203 244 234 232 198 209 220 219 217 203 203 236 232 209 222 225 202 224 210 222 227 240 213 237 207 227 233 230 223 204 220 222 211 227 230 212 234 206 202 220 243 223 228 219 230 229 220 262 229 202 188 223 235 202 226 214 212 226 235 211 241 200 230 205 233 206 235 231 219 218 208 197 194 203 206 203 193 229 190 217 216 224 217 215 236 227 240 222 217 218 240 216 210 203 215 224 216 205 213 210 220 226 281 201 231 191 233 233 234 216 223 224 232 219 238 208 204 225 210 210 219 194 202 235 247 222 204 242 220 212 226 222 216 217 233 257 248 231 230 217 208 225 197 228 227 216 256 205 256 258 222 228 198 239 233 220 192 245 223 230 237 210 215 208 219 202 240 224 241 207 230 210 228 211 222 229 223 203 232 219 218 260 197 202 210 224 225 207 197 211 185 241 235 200 249 231 182 237 220 234 199 245 209 230 215 264 219 222 193 226 217 197 220 236 221 228 199 250 201 261 225 227 230 190 276 225 215 228 229 215 188 209 209 228 230 198 206 236 221 224 225 215 179 258 231 211 223 216 245 195 240 247 211 185 192 235 222 248 222 212 213 215 277 214 213 229 211 220 223 230 218 218 221 234 221 206 206 236 194 241 205 205 215 224 215 216 214 222 211 211 231 223 213 192 230 246 193 207 229 228 222 236 234 199 243 205 206 217 217 188 195 211 219 243 198 235 196 236 216 226 212 202 213 210 228 210 241 235 225 218 206 207 244 223 236 242 213 232 206 211 203 215 212 220 197 237 216 207 203 238 209 225 193 221 212 214 185 232 222 236 220 232 217 226 225 250 222 219 197 195 224 226 229 224 191 211 236 241 207 190 212 222 236 250 187 235 225 217 222 211 218 216 221 192 247 215 228 241 219 219 205 239 233 238 243 221 241 233 236 228 249 214 215 269 246 263 227 245 248 226 230 211 232 226 198 230 241 245 198 219 218 225 242 216 217 213 235 208 194 234 218 217 220 219 218 189 226 217 194 248 197 218 198 207 219 231 216 228 206 212 226 223 233 230 188 211 201 224 231 217 219 237 221 210 224 204 191 201 234 217 207 226 229 214 205 212 217 224 212 216 204 220 236 260 245 222 238 187 192 205 222 203 237 207 206 224 179 203 229 234 224 237 238 211 229 190 225 217 215 218 238 207 237 206 230 217 202 213 209 209 199 221 170 207 206 215 223 230 194 219 209 222 226 185 216 212 221 246 220 223 215 202 198 234 221 197 212 203 232 220 220 211 208 195 237 200 213 209 224 197 209 224 208 227 212 215 234 221 215 229 206 241 221 224 215 205 213 200 226 234 219 220 205 205 236 205 203 215 214 196 218 183 216 212 212 204 222 201 216 220 236 228 216 214 214 196 222 214 225 232 203 222 210 200 232 204 220 224 228 228 213 210 210 214 220 238 232 220 202 189 217 236 191 208 216 192 243 220 213 207 245 231 203 223 223 225 221 242 214 232 231 237 194 191 214 223 211 216 199 214 237 243 195 181 206 236 221 218 192 210 225 230 224 223 212 232 243 209 216 213 220 233 226 214 213 193 210 240 204 219 219 223 207 218 214 242 225 211 203 242 217 216 213 203 228 228 232 214 184 221 255 216 229 232 189 237 219 220 226 209 228 223 202 201 215 210 240 223 195 222 207 190 220 209 221 225 201 241 207 214 217 225 195 242 202 212 208 223 204 215 227 227 231 223 216 218 223 210 233 200 221 244 213 218 232 229 225 233 208 191 227 192 220 236 225 217 226 228 228 223 197 215 225 225 221 227 240 196 192 220 221 233 233 204 197 224 193 228 240 232 212 209 233 223 224 231 226 226 191 214 217 210 223 221 214 206 203 224 221 224 229 239 216 234 202 200 219 257 248 225 221 211 227 210 213 236 213 200 221 215 246 198 229 226 208 221 233 220 223 229 226 228 221 217 229 219 207 209 215 210 219 212 211 200 231 225 211 203 211 205 234 249 208 230 219 221 203 238 205 221 229 227 207 229 218 225 245 222 217 207 221 212 242 226 218 211 249 238 229 211 229 236 229 243 211 233 203 242 218 213 192 225 217 209 242 262 241 234 245 235 221 196 228 213 232 234 236 226 244 229 221 206 200 216 223 225 217 242 209 224 258 229 207 249 224 227 224 241 230 219 214 243 220 210 228 259 221 217 244 210 225 235 261 224 247 217 230 237 223 275 233 227 216 243 238 220 216 248 215 221 210 220 228 267 239 240 244 243 224 264 247 224 219 213 197 264 217 209 226 227 214 238 239 207 226 217 194 233 211 246 242 198 234 221 240 233 208 224 214 247 234 206 232 261 255 247 232 225 232 214 242 222 240 215 260 219 240 227 276 234 273 215 221 233 197 249 220 236 231 232 222 244 229 215 244 238 224 215 258 228 226 247 234 208 244 269 244 229 226 222 245 242 241 245 248 249 258 266 255 249 244 218 223 241 256 260 255 243 265 269 273 232 221 235 272 243 272 226 264 241 247 216 212 248 262 241 241 282 281 240 242 244 287 272 272 278 272 237 260 280 267 258 222 242 269 227 280 291 287 292 287 293 260 329 301 290 332 273 329 319 311 340 314 353 348 364 348 362 406 363 362 373 365 411 415 397 410 420 424 396 405 419 407 459 392 379 380 398 391 313 334 382 334 369 323 351 292 337 332 323 300 297 311 275 295 270 310 292 260 256 276 283 282 309 247 287 270 262 258 230 244 268 246 255 241 231 270 257 255 230 247 295 238 220 255 244 215 224 226 236 244 247 246 219 228 248 237 263 224 217 208 271 232 224 288 239 228 224 216 244 231 233 227 227 220 223 226 232 237 241 239 237 227 225 240 228 225 213 216 245 234 229 270 231 236 234 220 238 243 226 256 208 239 231 264 219 258 231 224 245 231 242 267 262 225 255 236 240 213 232 267 239 231 204 238 224 232 240 223 259 219 235 229 218 236 274 222 259 219 219 215 238 238 236 228 256 232 228 215 245 215 238 215 200 237 210 227 225 236 231 219 228 218 203 222 243 221 230 246 227 263 219 231 205 237 234 217 220 261 223 218 210 232 212 211 232 215 213 234 232 207 233 224 236 200 269 216 219 234 228 230 199 244 244 205 222 231 220 237 248 231 243 235 234 256 256 207 237 227 216 259 243 235 231 242 207 226 203 240 246 220 228 240 221 245 235 199 229 188 236 258 240 223 215 232 222 244 247 237 236 229 237 256 231 233 231 229 249 261 260 236 207 241 227 242 248 225 232 220 221 241 240 219 223 214 239 240 221 237 262 227 229 238 220 211 221 230 218 228 229 228 242 213 225 229 227 223 237 261 230 220 230 238 232 224 244 239 221 257 238 245 217 226 232 240 247 231 273 222 224 212 219 230 237 234 237 221 225 244 206 247 265 221 225 258 207 241 260 236 233 218 192 231 212 206 210 212 213 217 215 261 242 257 197 236 219 184 205 227 220 224 227 239 225 233 229 211 202 225 235 220 227 222 218 232 233 211 225 244 260 219 208 235 218 228 231 239 240 241 237 212 230 217 187 241 231 219 224 222 215 210 224 234 245 215 221 220 261 217 198 198 250 209 221 219 229 210 244 222 224 234 246 205 211 274 216 244 212 221 218 222 226 215 219 240 239 205 227 232 220 242 228 239 241 232 202 224 255 220 239 230 219 260 230 194 248 228 227 237 234 214 239 213 221 237 257 225 231 229 201 219 227 215 219 236 230 261 244 243 239 230 204 228 229 244 223 202 234 221 245 244 235 230 215 236 225 207 243 260 207 230 209 212 223 225 240 259 237 250 224 231 216 244 219 244 247 256 211 243 224 230 243 239 246 233 215 222 228 227 236 214 229 201 224 224 214 222 211 222 246 214 208 226 214 255 214 238 227 223 218 216 247 228 224 262 239 237 239 226 223 215 238 243 232 239 224 258 227 212 256 234 212 244 209 199 222 214 231 220 265 209 228 261 227 225 255 233 213 256 234 242 236 235 226 210 226 229 238 226 204 228 246 221 225 214 224 198 234 222 257 232 204 242 215 215 236 208 215 223 217 226 207 234 213 231 225 212 232 204 236 218 218 240 229 245 234 218 211 239 226 221 219 243 213 234 198 229 206 260 241 217 230 237 213 227 210 241 242 228 213 228 219 199 210 209 220 239 227 228 234 227 240 219 218 221 224 238 250 209 219 236 212 227 237 236 211 218 206 240 232 225 234 230 247 215 220 212 194 236 226 244 231 245 235 218 190 227 228 248 214 206 232 215 240 230 226 225 240 202 211 256 235 191 200 224 268 227 239 208 242 227 221 200 230 246 225 240 230 218 221 266 229 236 221 209 210 217 210 227 197 194 222 224 216 200 219 230 234 245 216 255 219 221 212 198 245 203 217 215 234 238 208 229 213 216 224 221 226 236 229 229 209 220 225 234 221 214 228 236 243 230 228 227 261 205 243 239 221 261 236 193 262 227 234 234 217 266 257 217 223 224 221 206 255 213 231 240 241 236 225 229 203 235 221 244 239 220 230 229 219 228 201 221 245 201 225 240 204 216 204 226 216 194 240 219 191 223 221 185 226 227 226 250 230 220 229 215 224 217 236 208 202 227 219 228 222 222 223 209 219 206 220 230 237 243 230 200 255 229 224 225 228 191 241 235 217 238 222 216 241 222 223 220 238 201 240 219 188 232 234 234 240 219 211 226 210 238 216 211 230 198 221 197 225 214 236 205 209 248 241 229 199 237 246 217 220 222 260 233 211 208 243 233 228 229 217 231 242 229 239 219 220 219 239 236 235 244 226 214 211 229 219 211 236 225 213 233 240 231 205 247 209 231 203 219 233 232 215 249 203 236 219 220 237 236 194 240 213 198 235 247 220 214 204 241 209 222 237 226 234 203 246 207 216 212 222 209 220 223 207 208 237 195 234 230 228 231 213 223 208 199 221 242 210 221 236 272 220 241 245 234 222 257 235 196 224 222 224 264 259 236 239 233 262 228 228 210 233 227 220 223 220 231 210 202 216 242 220 208 201 217 217 222 229 233 224 217 216 233 211 219 226 256 241 192 210 249 235 261 205 249 205 233 218 209 217 207 241 204 201 204 245 239 205 216 227 228 232 235 255 238 263 223 241 213 238 231 256 241 216 227 212 237 235 206 265 199 238 206 237 212 235 222 224 209 227 242 221 209 223 213 243 270 209 204 243 264 227 217 236 241 215 228 207 221 237 231 243 229 202 225 236 210 255 236 269 235 244 249 213 237 245 226 214 218 242 239 223 273 213 263 242 224 210 244 216 233 222 261 244 212 230 220 259 234 216 210 246 238 202 225 216 248 234 228 230 234 219 223 225 215 225 218 221 218 237 235 212 214 227 240 214 225 229 233 208 212 232 244 231 264 221 236 229 249 243 214 248 258 213 239 217 231 209 230 243 230 244 232 262 223 243 233 234 208 233 221 229 231 198 213 214 197 243 211 211 234 243 225 211 213 215 215 259 242 262 243 210 215 222 223 240 244 230 234 246 223 243 232 240 218 224 233 195 239 203 237 244 222 235 218 230 214 234 205 204 257 220 219 235 214 208 201 245 221 249 275 224 218 229 229 206 219 237 234 230 238 225 235 235 216 243 211 199 225 247 224 213 241 240 219 226 220 224 228 230 236 243 255 239 220 224 213 239 236 224 217 241 225 247 232 199 235 240 241 222 233 234 233 206 240 239 234 226 214 228 208 227 241 228 243 224 209 235 225 209 250 227 218 217 219 232 209 223 237 215 235 238 244 257 217 237 242 231 221 203 219 226 248 256 224 234 218 228 238 242 205 225 245 229 242 214 228 219 226 257 209 211 218 224 223 260 223 235 223 214 229 222 237 216 225 233 256 233 212 212 221 238 214 220 204 222 232 238 228 221 224 218 277 223 215 214 237 242 260 247 242 235 239 204 218 218 255 224 238 218 237 216 234 230 236 210 217 235 230 225 207 225 231 235 232 231 210 238 240 215 219 213 207 249 233 219 224 231 232 222 216 205 239 244 247 261 268 206 259 256 235 228 243 238 233 236 249 232 209 237 214 245 246 221 214 211 200 226 244 236 235 240 233 216 227 247 222 225 241 230 227 241 236 276 236 225 259 236 255 232 230 258 228 225 230 217 233 231 229 222 245 199 219 221 230 224 214 236 217 245 226 213 227 243 222 231 243 233 255 256 231 215 259 241 216 265 256 217 225 224 222 219 220 250 230 221 227 256 213 201 227 246 265 243 245 231 236 221 228 227 238 222 220 245 211 235 243 212 238 239 226 212 272 242 209 233 247 257 225 249 260 255 212 237 202 240 250 219 242 273 260 263 230 204 231 273 224 274 209 232 208 224 224 241 231 247 215 264 218 212 230 245 242 223 201 245 233 226 214 264 248 242 227 221 236 237 248 217 216 230 243 264 239 218 233 242 229 249 225 244 246 247 238 227 241 230 249 268 231 271 243 223 231 219 223 222 211 225 256 229 215 228 226 257 229 221 246 217 247 224 199 215 212 244 267 241 219 235 236 232 259 237 265 194 249 246 244 219 230 230 207 241 211 242 229 257 241 246 258 242 227 258 203 276 213 240 255 244 265 223 224 231 216 238 256 227 235 262 261 226 222 217 211 232 215 249 236 232 221 217 225 219 276 230 225 246 199 224 226 202 237 202 222 258 210 222 240 237 230 287 257 225 225 260 225 222 255 238 257 217 236 232 210 259 217 244 223 250 235 232 230 219 255 259 213 239 248 220 233 226 259 223 235 223 215 272 230 270 236 239 234 246 234 230 226 232 226 237 219 245 246 244 239 226 248 246 236 222 224 242 231 228 243 226 248 238 224 217 221 222 239 248 237 238 228 255 218 227 260 220 266 243 243 225 247 209 246 238 219 227 227 217 228 225 255 244 235 262 249 219 240 245 261 242 245 258 239 244 226 258 207 228 223 258 221 226 226 236 221 214 232 245 236 236 223 209 232 239 234 222 242 235 237 231 261 233 232 231 256 237 245 226 237 239 264 210 222 225 259 238 233 227 245 220 243 244 243 218 238 245 207 213 215 255 197 233 267 281 229 205 265 270 236 257 234 245 218 232 225 264 262 249 223 240 262 255 221 265 235 211 245 266 246 233 221 238 256 239 245 237 247 244 228 240 228 255 246 271 242 263 239 245 222 258 240 237 204 217 249 255 249 218 227 246 255 238 231 256 241 224 236 268 231 250 225 250 246 245 293 233 274 228 230 245 264 219 265 246 248 239 227 244 268 227 275 249 240 230 282 259 224 238 261 262 267 243 243 248 273 236 223 232 271 267 250 263 264 244 274 262 260 268 240 215 243 239 225 239 214 233 264 246 229 257 275 280 274 271 220 238 235 207 245 267 255 214 248 265 228 249 232 249 265 234 242 230 230 262 265 265 285 273 249 236 255 229 248 243 231 222 232 242 240 213 250 227 265 226 219 225 261 250 256 236 250 225 238 222 231 235 223 228 258 231 220 208 291 231 283 242 207 226 240 242 247 221 220 265 217 243 258 242 229 242 233 244 240 232 232 222 221 249 230 245 232 269 231 230 213 244 256 220 257 282 198 235 234 225 236 244 257 224 236 241 248 258 228 221 266 279 232 235 246 234 278 244 236 262 220 239 232 225 225 244 208 246 232 267 262 235 235 244 236 237 239 262 232 267 227 235 234 239 217 234 208 203 233 246 228 225 241 261 263 238 196 232 256 274 255 247 243 249 257 258 249 225 241 231 241 278 285 219 213 247 237 230 243 216 244 230 276 239 234 227 218 231 234 241 234 230 243 231 218 229 262 220 232 246 239 255 262 233 231 258 237 206 232 240 237 245 218 221 282 242 259 242 233 243 234 219 263 242 210 256 245 246 234 250 255 209 246 218 226 228 231 219 256 212 250 246 229 219 212 226 226 240 229 238 240 246 240 257 223 240 236 228 258 239 228 236 233 226 243 242 219 209 226 268 232 195 234 206 229 246 221 245 208 245 255 280 243 223 236 214 238 237 202 241 261 224 236 234 268 241 257 232 256 266 255 225 247 256 219 230 241 243 269 228 240 225 271 259 249 226 269 233 243 230 215 243 218 264 222 235 235 258 247 225 256 218 255 231 219 275 240 239 226 255 258 258 241 243 262 258 233 220 247 264 210 246 235 296 272 218 249 256 258 273 266 218 220 230 240 229 258 248 227 227 226 255 223 261 241 246 227 233 238 200 226 223 260 267 217 224 241 244 223 256 249 248 207 221 208 257 226 259 246 234 244 241 241 250 231 223 214 248 249 271 261 225 246 220 241 234 238 230 258 222 246 231 233 206 274 257 247 263 223 244 243 259 232 238 266 241 243 219 212 232 236 255 264 294 236 238 239 236 233 214 240 268 234 236 246 236 228 224 239 224 228 243 241 222 258 231 239 209 237 267 231 228 263 241 226 241 235 278 220 221 225 238 232 278 262 236 255 235 258 245 221 263 243 265 232 232 229 207 230 213 214 238 244 239 259 227 239 221 232 260 232 247 233 233 217 237 242 224 267 224 261 214 255 222 277 201 229 231 233 223 256 249 248 233 214 248 255 242 212 242 228 231 265 245 248 227 233 227 244 204 231 233 212 257 228 255 205 229 232 228 234 221 257 227 267 224 238 234 222 248 256 240 266 210 245 236 273 237 228 249 203 219 233 229 217 220 223 248 246 242 232 213 255 238 199 226 227 236 233 227 226 256 244 241 232 243 235 246 245 246 244 266 267 234 237 242 258 235 233 206 223 243 268 239 226 261 233 228 216 217 238 215 234 224 263 222 224 229 258 237 244 241 242 264 240 245 248 213 274 245 232 219 245 209 245 271 232 235 264 249 249 246 233 244 217 231 215 267 232 216 225 230 238 263 243 220 263 229 265 245 242 258 261 264 257 265 262 263 245 272 228 241 247 197 262 235 240 277 224 277 287 259 257 274 203 237 249 236 256 267 266 262 229 262 215 267 234 238 263 263 234 239 262 219 236 236 257 261 247 256 218 250 232 243 239 267 278 263 228 243 264 258 261 221 229 274 255 247 244 248 272 263 236 264 244 248 231 236 230 222 257 248 245 242 244 240 208 236 232 233 239 268 259 241 250 265 231 274 266 262 215 259 231 262 238 257 240 234 265 263 272 242 230 231 237 242 225 240 237 227 231 246 178 242 242 228 242 265 262 260 241 246 258 209 230 247 259 241 266 221 245 278 258 264 263 243 217 244 233 246 237 230 236 233 247 241 261 286 257 229 231 231 232 235 262 256 255 243 259 220 242 229 239 250 238 280 229 263 243 250 247 214 226 250 225 243 233 237 257 255 218 256 256 236 241 238 273 220 263 227 234 222 230 256 228 237 270 267 218 256 245 237 256 210 235 232 238 233 231 243 236 256 259 264 263 236 269 259 267 226 280 235 221 245 238 242 260 225 238 275 270 262 244 240 220 228 240 245 232 275 291 256 247 255 268 245 227 260 284 235 264 240 229 225 272 249 240 220 230 239 238 267 267 259 241 233 223 247 280 240 262 255 231 262 245 245 261 231 257 256 232 245 241 244 248 237 242 235 228 239 237 269 217 267 216 234 241 245 240 244 264 237 234 247 227 223 237 248 256 236 225 266 223 248 233 234 232 225 231 230 243 260 268 266 273 260 274 234 228 229 232 230 221 258 223 246 232 234 237 236 232 243 246 243 255 286 242 255 246 215 271 235 274 239 228 238 261 274 233 264 255 242 235 256 255 237 215 241 234 237 245 245 241 264 234 266 229 231 255 245 271 247 248 228 298 190 238 236 274 247 239 238 250 244 250 237 228 257 230 243 245 250 236 238 228 273 244 236 242 214 261 223 244 247 242 264 229 226 236 265 249 240 268 271 212 224 241 240 216 250 245 268 274 262 227 260 250 246 245 288 233 264 246 239 248 242 247 233 301 262 221 256 229 256 229 230 238 255 238 260 226 242 255 245 278 250 243 224 236 262 236 219 248 256 236 262 217 261 263 229 245 276 232 234 197 258 239 233 237 259 277 247 229 263 216 222 209 256 235 240 217 255 269 206 258 247 263 235 226 247 239 238 243 212 230 227 262 223 257 260 246 260 234 228 226 237 220 241 223 237 231 235 227 247 245 258 238 240 257 239 238 247 247 227 238 249 204 272 203 237 258 264 245 235 256 244 262 248 234 259 257 261 247 232 221 265 270 231 238 220 302 270 230 256 246 244 232 266 246 217 271 233 245 237 257 275 234 208 222 224 256 236 242 257 228 256 261 246 222 244 259 230 262 244 259 271 207 243 233 268 242 227 241 230 262 242 256 215 268 267 235 265 222 261 267 244 231 235 291 236 235 241 248 245 266 213 249 265 262 233 234 276 228 257 255 260 232 243 237 258 235 240 268 244 245 230 223 231 258 221 255 247 245 262 222 236 236 261 279 246 229 245 255 221 229 274 246 227 229 219 245 237 242 238 229 258 247 208 238 235 223 264 247 256 223 257 264 241 265 256 234 258 248 244 225 267 239 268 269 228 244 242 246 259 239 236 242 232 233 233 242 246 237 217 239 236 278 272 255 275 228 226 239 231 231 286 230 248 296 226 235 244 232 255 262 231 234 233 235 260 226 272 264 276 248 246 237 279 249 236 243 240 241 249 245 255 236 236 255 250 241 233 232 240 246 225 231 267 268 214 230 267 233 243 243 240 237 220 259 257 241 222 230 218 242 266 287 237 249 267 233 295 240 238 271 235 265 250 263 223 238 291 225 245 255 222 240 231 280 227 244 270 245 229 225 224 247 265 245 287 234 285 244 241 266 276 244 261 240 245 240 227 218 242 271 246 227 277 295 272 255 249 241 260 242 239 248 239 239 221 234 240 240 235 263 271 266 239 236 232 265 243 258 240 261 237 255 264 256 262 259 237 266 269 238 264 259 256 262 227 243 261 238 277 238 255 266 249 235 264 275 263 278 234 267 260 271 230 239 271 235 272 242 236 266 273 265 267 233 239 261 247 282 265 246 258 249 274 261 242 259 264 239 247 229 258 246 256 236 285 225 276 236 274 225 283 244 236 245 258 265 229 239 261 246 238 272 248 276 249 296 235 290 248 257 260 236 243 261 285 265 236 244 240 281 263 264 279 267 245 223 223 246 257 243 264 231 243 268 273 290 282 225 249 249 258 263 239 261 278 260 264 258 267 247 268 268 297 270 234 275 279 277 288 279 262 278 258 285 294 277 269 282 266 281 273 268 278 282 295 305 279 275 270 277 265 299 316 306 319 307 255 283 293 278 276 255 296 295 280 276 300 301 281 323 269 288 298 279 283 301 258 249 278 277 264 300 288 277 271 269 275 276 286 228 298 285 263 293 255 284 271 318 284 259 280 281 270 291 269 281 270 270 307 260 268 248 284 274 261 229 284 277 236 269 247 256 270 234 248 246 247 268 232 271 258 267 267 300 232 268 242 237 281 273 260 266 278 282 264 244 236 257 283 267 274 221 269 245 262 258 225 294 266 281 238 265 258 284 236 257 235 248 272 257 225 232 224 223 239 256 240 238 260 235 255 230 247 241 272 247 249 249 266 247 243 279 249 235 241 227 258 236 261 267 241 239 231 245 243 243 222 246 264 243 256 234 226 258 240 257 245 242 214 245 250 237 247 228 268 234 247 220 225 226 229 236 255 281 256 242 242 246 240 250 267 220 272 257 262 248 243 249 241 274 246 256 234 231 257 231 258 259 280 256 282 257 228 246 241 277 256 236 246 265 274 229 256 258 240 243 230 243 238 231 262 232 235 212 280 215 230 236 236 228 222 236 237 264 245 272 267 261 215 245 248 212 258 233 247 249 244 255 233 260 230 262 243 228 221 262 245 228 269 258 242 236 255 213 267 237 229 261 256 248 263 240 223 274 230 250 238 249 246 257 260 223 217 269 219 281 229 259 232 258 282 226 232 267 246 247 233 255 267 266 235 223 238 232 259 230 246 227 238 262 229 230 267 247 283 238 264 260 217 287 211 267 298 233 237 247 239 246 248 239 246 255 240 259 245 260 241 231 245 265 273 242 243 229 225 258 278 226 250 227 243 234 286 261 231 267 227 242 236 228 249 244 247 240 256 248 240 262 217 256 241 249 286 258 262 245 245 262 247 260 270 229 231 224 255 229 262 273 257 265 227 265 241 226 261 248 239 235 277 261 222 246 231 240 262 262 259 233 259 269 236 270 274 227 233 231 247 240 229 231 267 239 229 280 222 243 264 242 269 215 246 244 243 264 280 240 242 240 244 226 243 248 257 256 243 235 228 243 220 232 227 256 241 239 226 221 232 223 245 249 245 267 280 247 234 236 227 242 243 250 260 234 258 269 237 232 258 221 268 269 244 255 261 256 243 242 247 257 238 259 232 256 258 249 265 255 223 224 215 256 240 245 226 250 260 266 237 264 216 274 266 262 238 267 267 298 243 264 287 249 248 263 267 263 284 263 279 256 227 248 286 235 233 258 222 248 262 242 239 246 230 262 257 257 247 238 255 218 209 238 272 291 224 223 258 232 247 257 241 248 236 212 246 245 241 237 235 255 260 278 244 263 242 239 273 256 262 264 243 263 275 283 258 237 266 232 236 270 249 274 256 259 243 243 244 268 234 245 237 259 227 260 261 224 240 238 258 240 234 279 243 232 267 265 243 256 274 240 232 227 268 256 259 278 246 233 256 255 240 262 246 265 270 244 259 227 259 267 242 242 242 248 222 228 275 232 243 276 240 230 272 255 261 256 247 279 237 245 257 248 270 238 245 281 248 257 264 232 274 248 256 232 259 235 243 224 245 257 289 264 289 261 259 242 297 232 264 274 257 255 258 245 247 255 259 228 270 250 236 263 242 232 243 239 242 236 232 244 267 263 229 236 228 226 286 273 244 271 239 262 263 284 269 239 255 261 270 239 231 248 228 237 276 222 265 270 249 270 255 242 269 230 274 228 249 250 265 243 259 261 266 246 243 304 256 264 228 255 262 249 273 242 246 262 224 231 255 218 265 248 247 247 259 212 255 239 237 269 264 261 219 255 245 263 238 274 261 243 248 265 282 261 236 234 249 267 233 255 241 242 243 260 271 278 230 234 246 269 234 242 234 267 225 265 217 257 255 222 245 242 213 255 216 263 281 255 234 241 225 274 240 231 265 246 256 261 268 285 269 260 260 264 270 249 239 239 270 266 258 241 247 230 223 247 294 237 237 262 285 210 245 263 261 261 262 276 237 237 273 246 249 236 266 232 265 281 268 263 227 231 271 226 224 262 255 271 276 255 217 248 266 261 279 240 226 262 262 244 262 248 243 225 221 233 255 245 263 263 237 268 249 241 242 239 263 246 266 241 237 257 257 230 237 291 228 213 221 247 265 255 223 263 267 283 250 257 271 259 259 290 248 271 265 247 260 268 236 280 226 264 231 259 236 256 237 232 240 266 264 247 259 259 270 281 259 269 249 227 234 231 249 199 276 272 264 257 257 247 269 217 262 273 270 261 294 279 277 257 237 240 265 224 247 241 264 234 236 258 249 248 240 257 255 256 218 248 225 243 261 283 274 218 234 219 258 229 271 238 291 258 255 234 265 243 246 228 230 237 219 260 246 259 243 248 255 255 259 255 272 242 237 223 238 258 272 255 241 229 268 245 226 242 266 240 281 227 244 260 233 245 244 224 247 265 225 246 235 221 231 274 283 218 231 236 244 244 282 236 240 272 249 242 264 240 275 238 240 226 269 237 246 262 246 246 213 239 250 215 262 275 259 244 266 250 268 263 258 258 228 232 261 249 248 229 239 248 240 268 232 223 239 232 248 266 234 233 267 265 270 245 271 240 277 263 239 274 233 244 227 246 246 234 255 241 275 275 250 269 247 248 266 272 249 249 261 266 230 228 259 239 248 266 263 262 236 261 282 229 239 239 247 247 226 213 265 260 235 237 277 255 249 264 258 267 266 241 238 217 235 277 273 248 266 257 221 246 262 244 266 255 230 268 233 265 232 246 256 255 265 255 269 256 231 269 232 277 243 248 225 243 231 291 230 277 244 234 224 230 226 239 266 232 269 261 245 228 259 233 257 257 241 280 263 270 219 265 291 243 221 238 232 243 232 265 224 235 265 285 276 234 231 266 262 268 239 241 220 263 279 256 269 255 255 275 264 279 242 240 256 232 255 266 231 238 223 222 274 255 250 247 255 219 256 229 255 273 242 244 214 257 264 238 255 260 247 257 226 261 233 245 220 258 240 238 234 270 284 247 220 269 247 281 241 231 255 229 221 223 275 242 258 233 243 245 256 241 232 261 255 249 224 255 229 262 238 223 277 261 244 248 264 244 249 246 234 276 222 241 238 275 235 262 229 276 228 290 280 235 224 275 279 232 213 278 223 238 249 242 244 255 264 243 269 205 259 249 244 262 232 237 242 225 247 241 255 266 275 275 245 232 224 216 249 240 275 271 234 241 239 235 261 263 241 220 259 239 285 229 285 237 249 257 265 214 272 256 231 229 257 267 241 246 240 227 239 259 277 229 247 271 249 226 247 219 292 274 232 278 233 239 227 231 272 240 269 227 237 279 266 277 269 239 204 272 223 271 248 243 246 237 272 234 276 238 261 246 260 256 244 243 268 249 255 269 265 263 255 255 240 227 247 249 259 227 237 225 236 259 232 271 246 240 259 235 237 235 266 242 259 238 266 230 272 258 213 270 246 274 249 233 243 232 265 269 255 256 241 261 246 273 238 235 241 262 270 232 237 236 235 245 259 262 234 286 227 271 259 247 260 257 233 259 232 241 266 232 244 238 223 245 240 240 277 235 256 264 273 238 259 260 218 264 241 242 246 233 275 240 222 244 238 265 278 255 266 241 237 275 233 259 275 265 243 228 205 241 220 276 212 262 257 232 230 249 233 257 225 269 261 232 281 259 232 236 228 235 261 237 249 245 274 237 249 255 249 271 239 236 279 261 270 271 237 265 241 264 241 263 243 249 227 260 283 241 266 266 245 261 271 248 237 248 213 259 245 291 248 264 242 240 263 243 241 261 294 224 279 239 278 263 260 266 265 229 277 244 258 244 231 222 265 272 271 262 236 228 275 268 285 263 269 279 240 262 278 287 301 270 274 260 246 272 261 236 257 285 289 257 271 274 233 259 271 284 249 230 225 274 278 270 245 279 236 266 245 210 283 243 268 263 238 275 236 276 248 247 225 238 305 257 256 245 243 247 284 257 237 245 279 232 276 264 286 269 246 265 245 267 226 272 271 281 247 262 259 263 259 271 268 227 272 235 255 234 266 266 215 238 235 231 279 246 267 264 227 269 264 260 263 261 242 260 258 244 279 237 245 282 245 268 263 241 260 227 236 248 260 240 272 241 267 283 246 247 279 280 248 230 241 227 246 236 243 258 237 247 205 261 247 247 256 246 247 242 236 239 282 256 255 247 250 283 240 245 283 249 248 248 268 229 282 236 262 249 262 284 257 269 238 230 247 268 243 282 276 222 233 242 219 246 202 255 232 255 242 247 249 256 244 244 288 240 257 262 260 243 257 260 270 264 243 235 230 245 257 237 228 263 235 230 244 265 225 263 258 271 259 246 233 234 273 234 285 263 247 230 265 241 282 263 226 243 264 265 280 233 277 250 241 271 271 247 241 263 233 256 243 234 244 227 244 257 241 269 243 276 233 230 272 262 260 259 235 237 225 261 277 258 215 255 281 267 291 238 255 240 267 249 230 269 224 245 258 236 234 222 228 282 231 267 217 261 241 305 244 260 240 243 268 242 256 259 243 271 234 243 249 232 247 223 217 260 275 291 245 223 258 231 261 247 264 233 249 244 260 246 247 256 247 274 230 225 231 269 217 230 240 238 250 272 238 244 260 264 277 217 247 269 273 242 263 246 257 238 224 229 270 243 267 248 242 236 246 258 275 276 261 245 259 240 230 258 257 242 242 258 239 234 243 229 260 249 259 281 258 231 243 248 241 266 216 256 267 248 261 238 240 245 238 209 243 238 241 237 239 259 209 242 237 241 268 260 261 258 264 258 266 231 243 235 238 281 241 230 218 233 260 236 264 255 255 263 246 260 238 248 235 259 211 221 245 262 256 250 257 256 238 257 248 247 264 248 242 263 258 248 271 266 246 249 269 245 232 238 231 270 235 256 230 247 290 230 245 285 243 240 270 222 266 258 274 226 272 273 230 231 258 247 243 241 244 273 240 234 255 271 236 234 234 245 282 258 257 245 243 235 255 255 264 206 239 260 266 273 259 269 299 236 236 263 255 225 256 250 245 270 239 264 237 236 247 285 255 259 288 223 272 261 247 247 280 275 262 269 247 235 244 276 256 242 245 240 249 264 250 269 274 265 281 229 267 285 240 228 227 248 243 259 256 249 245 259 264 226 236 247 225 259 259 260 244 266 275 255 258 240 265 211 256 241 224 227 255 236 230 242 297 237 240 245 267 262 231 260 279 227 262 244 257 256 239 243 278 248 233 276 244 261 224 234 265 236 242 257 212 243 242 241 283 235 268 230 239 240 250 246 247 263 246 244 265 229 229 237 260 264 211 246 246 277 233 247 263 244 240 275 255 259 265 232 238 271 257 239 277 243 212 231 245 204 259 244 235 265 245 259 255 261 220 286 263 237 248 236 257 262 241 275 233 267 264 235 225 237 256 274 275 261 234 244 263 260 282 231 242 255 257 249 243 266 262 269 245 241 294 260 266 228 238 281 244 241 249 267 247 265 233 258 227 246 280 260 250 240 235 307 257 216 246 242 248 242 230 276 237 288 269 238 274 244 257 255 294 226 271 262 246 247 256 262 270 257 240 265 259 270 272 261 258 260 244 265 266 227 235 231 274 256 237 261 235 246 268 284 271 265 298 258 206 238 237 270 248 248 261 234 232 277 246 234 239 236 256 256 257 246 258 255 244 271 241 264 231 274 247 264 243 260 245 264 246 248 244 261 231 230 265 248 242 241 272 240 256 243 257 262 260 278 232 297 243 246 232 259 245 243 240 267 239 264 222 263 274 247 245 248 273 248 248 233 278 248 260 240 245 245 249 260 221 248 266 260 246 267 256 269 289 286 231 229 237 236 226 255 273 276 250 217 259 250 250 266 264 268 260 258 265 271 212 247 229 242 273 272 273 257 233 240 281 261 268 277 258 245 238 231 238 259 246 231 234 244 289 245 234 230 258 258 270 204 249 244 241 265 223 268 269 265 270 255 279 237 270 238 286 231 272 264 240 233 233 260 248 245 239 258 235 255 240 214 227 275 282 226 270 247 266 233 236 245 224 241 245 228 233 236 250 239 241 288 223 250 225 256 262 242 238 260 232 261 248 249 241 230 272 258 235 274 259 260 220 232 231 262 232 258 255 277 267 223 230 264 239 241 274 258 237 262 275 273 223 257 268 264 265 264 245 228 230 272 246 235 224 263 257 219 247 231 261 218 263 261 280 269 288 241 234 245 258 249 256 242 233 248 275 240 257 273 243 242 243 233 240 255 256 262 242 260 261 215 242 232 215 289 247 226 246 266 281 257 249 248 231 229 261 258 246 247 257 260 223 272 218 249 257 225 205 269 247 263 292 269 271 235 250 265 262 232 260 245 261 240 249 227 266 256 230 276 267 273 244 245 287 248 265 281 285 279 261 268 224 257 236 243 264 266 283 268 273 268 271 219 244 264 233 247 220 245 268 247 256 244 258 240 248 257 262 276 287 229 262 238 236 256 259 237 258 268 239 231 228 234 270 250 257 246 286 265 211 281 265 292 280 266 286 265 272 260 258 263 260 270 248 222 250 236 229 260 246 262 234 271 259 263 242 239 234 237 275 223 229 262 239 258 263 287 267 246 264 268 246 260 257 234 240 246 243 296 257 259 240 244 261 275 294 255 246 257 238 234 247 287 263 226 269 261 239 281 262 240 265 255 241 226 262 234 274 240 258 269 258 261 260 242 232 232 265 246 238 233 238 263 286 247 274 258 240 236 259 242 255 232 245 272 265 258 259 275 258 247 241 262 269 242 270 242 232 238 260 242 257 260 236 249 280 237 259 238 275 273 235 225 247 244 268 239 259 262 233 263 234 224 225 261 231 241 267 262 241 235 270 279 261 262 209 276 246 246 257 249 266 246 270 241 237 260 257 258 240 281 262 271 248 265 280 206 255 244 248 265 256 249 286 267 270 235 245 262 242 283 238 234 249 263 260 242 276 232 243 247 275 269 272 239 261 231 259 230 255 287 249 261 274 262 241 244 249 244 277 234 248 227 249 263 286 244 257 258 248 263 229 273 236 269 272 202 235 267 236 272 225 235 276 248 266 246 240 256 268 260 255 233 267 235 248 242 261 275 271 281 262 223 246 248 273 229 239 256 272 256 261 255 268 258 275 233 276 262 242 264 247 246 234 259 269 237 269 222 216 264 272 258 274 242 263 247 244 223 238 270 258 223 225 249 227 241 279 269 270 267 259 243 262 282 265 248 250 235 286 248 240 276 257 224 238 283 265 235 267 231 261 271 256 218 273 255 227 241 246 278 242 249 256 240 227 259 248 263 262 260 256 225 239 230 237 244 255 219 265 263 255 276 279 237 262 246 264 283 215 265 220 228 250 233 248 259 288 257 256 259 241 245 239 247 238 241 267 275 249 242 272 264 263 243 241 255 229 274 286 256 255 238 237 293 235 243 236 238 234 238 263 244 271 241 219 278 207 225 264 227 238 278 257 238 229 256 244 272 229 234 245 239 239 265 264 223 248 255 269 247 265 278 233 240 271 277 256 225 242 259 257 246 227 271 221 228 232 241 247 241 245 248 243 250 247 280 268 258 216 221 274 257 259 262 275 218 263 276 286 232 236 258 242 263 242 264 231 231 268 261 229 237 277 236 263 260 281 255 255 265 258 264 271 270 246 260 280 245 240 242 280 278 243 264 246 279 237 266 274 257 258 265 244 239 236 242 258 264 265 249 277 269 259 256 260 269 260 261 263 247 269 271 278 246 242 255 223 255 247 259 277 275 245 298 302 256 255 265 241 265 263 280 233 243 242 285 257 293 275 277 262 269 271 255 222 277 247 271 274 234 288 247 231 271 276 307 268 258 276 270 248 275 275 261 262 269 267 264 247 266 281 249 263 270 261 242 271 243 284 271 256 277 266 283 236 275 288 275 275 302 266 257 264 273 268 261 267 262 267 261 237 247 239 295 234 282 265 261 255 250 239 246 258 257 262 282 272 277 280 279 245 231 237 244 264 263 281 273 259 258 265 280 234 260 275 292 220 232 246 241 249 262 258 246 275 267 283 276 262 283 271 260 246 235 255 275 264 247 274 272 269 265 278 285 268 246 273 272 263 260 238 237 288 282 262 230 257 257 260 264 262 239 258 282 240 302 266 247 237 244 250 263 276 243 267 258 220 260 243 261 242 272 274 294 259 266 233 242 224 262 259 241 303 263 248 271 276 290 258 263 271 246 262 248 267 197 265 225 260 302 259 257 277 267 264 274 247 259 222 244 260 268 222 257 246 249 277 270 232 237 233 241 259 263 272 243 264 273 258 257 262 269 224 247 264 267 260 231 244 289 247 246 272 241 249 242 239 255 259 248 262 280 269 255 235 278 276 248 234 247 244 227 239 232 237 261 237 267 225 278 232 257 246 264 268 264 266 256 224 263 232 246 239 269 255 225 225 231 261 237 263 259 273 263 243 233 220 227 274 246 249 270 269 229 266 232 230 247 248 247 270 261 243 287 279 249 241 231 238 263 264 248 234 276 245 257 234 249 247 272 240 262 275 221 237 273 246 234 276 231 292 224 262 233 261 247 263 232 278 241 266 277 255 247 216 256 271 304 231 264 230 247 260 259 257 233 285 261 260 223 237 262 259 242 231 259 230 258 263 248 271 236 241 244 249 227 277 271 223 246 230 270 237 246 258 277 261 248 272 248 217 238 248 276 260 243 228 228 244 241 243 259 244 274 257 238 258 278 262 283 247 238 268 268 271 222 237 237 246 241 221 230 273 270 247 278 263 268 234 290 229 259 227 244 244 269 269 277 235 255 244 288 259 245 257 246 250 267 257 228 243 267 238 266 259 216 272 229 237 283 231 246 220 239 225 238 291 242 234 239 260 288 240 261 240 240 238 234 238 247 226 258 240 272 234 239 276 245 260 234 229 271 236 255 240 234 236 261 242 262 261 233 257 263 218 268 247 230 277 255 271 267 256 248 246 268 272 241 255 218 262 268 248 270 244 250 237 212 243 257 231 268 281 234 241 266 248 232 256 264 237 241 265 288 255 259 229 267 234 228 282 232 247 244 257 213 241 273 274 257 269 245 260 279 264 234 275 258 243 272 243 267 260 275 271 247 262 273 289 258 265 265 270 243 266 245 241 264 256 269 247 249 237 259 263 266 235 260 261 249 241 261 249 242 261 224 228 271 270 269 268 216 231 239 271 265 247 243 255 231 303 257 233 232 261 266 229 221 267 255 275 260 229 232 263 269 245 245 277 239 261 223 257 241 249 290 227 247 249 276 264 262 248 275 275 272 249 240 259 282 249 215 256 246 257 249 248 262 262 257 269 266 259 257 246 211 272 266 269 263 247 242 239 243 262 258 224 268 263 256 261 255 245 268 273 261 241 247 250 271 266 258 241 249 279 262 231 274 243 238 255 233 234 294 268 264 237 237 236 284 204 257 245 256 233 256 245 269 258 262 285 247 237 238 255 285 277 259 274 240 226 243 238 271 265 284 283 242 238 257 246 268 239 265 248 259 238 255 248 258 214 243 278 261 246 281 246 259 236 278 261 267 257 233 260 231 250 227 237 277 255 264 264 291 246 235 214 275 278 267 243 259 270 246 238 256 245 257 248 211 280 245 267 261 263 256 239 298 249 239 243 239 240 237 235 237 270 238 211 276 275 269 225 244 257 249 272 260 248 218 227 234 234 240 268 248 278 261 286 256 274 246 249 260 272 280 245 255 245 247 204 259 236 294 269 256 278 277 233 249 268 241 234 224 244 275 239 273 234 256 258 225 248 272 256 230 262 243 264 264 271 266 280 259 258 256 259 267 244 224 269 246 255 209 256 285 262 248 274 265 241 239 215 244 250 233 243 245 259 238 271 241 262 230 261 235 264 263 231 273 239 225 231 257 260 238 239 240 265 284 265 247 236 233 258 222 244 248 283 269 240 256 256 290 222 267 283 229 276 261 209 245 266 261 235 279 258 262 259 277 261 242 271 261 250 243 263 265 240 248 233 243 257 264 240 291 235 239 237 240 241 259 262 263 272 249 257 220 232 266 256 238 249 255 277 260 233 232 271 249 264 229 263 239 261 247 230 260 260 249 276 248 275 255 244 230 234 256 260 246 220 255 249 213 246 240 267 245 262 245 270 269 261 223 219 270 288 277 237 255 245 243 248 234 269 268 256 240 230 244 225 231 260 269 260 237 235 285 242 248 261 273 261 258 291 266 259 249 261 264 264 243 275 223 273 246 262 261 255 218 256 232 270 255 249 249 275 255 256 265 239 248 294 270 260 271 285 247 283 271 256 238 230 256 228 246 295 275 242 256 235 273 248 278 261 274 234 250 259 239 246 246 259 250 239 255 264 229 264 238 268 247 248 259 244 225 231 222 262 264 258 210 259 264 239 255 263 249 239 258 244 271 257 258 242 260 229 273 264 260 261 236 247 286 230 255 282 225 271 266 244 220 247 268 239 271 261 243 255 271 250 257 247 244 280 245 264 221 268 221 255 271 263 261 259 281 234 264 242 235 259 245 236 257 249 247 263 230 263 247 245 274 230 267 235 265 233 242 271 275 244 268 236 246 239 231 281 246 240 262 228 279 284 263 264 295 255 260 269 237 271 249 288 235 247 286 240 274 240 223 264 271 256 226 261 245 256 248 274 233 265 235 267 241 274 242 230 241 236 246 273 225 247 280 261 255 210 285 248 275 255 264 272 237 227 246 231 278 246 228 210 272 263 257 273 270 256 246 278 248 244 275 246 235 240 257 260 276 242 247 235 270 233 237 216 264 260 226 258 259 222 268 245 249 239 205 243 276 273 269 241 241 258 278 264 255 247 273 258 265 244 249 233 292 255 239 245 240 262 241 229 231 212 217 240 262 213 227 267 258 261 247 260 281 275 239 214 229 262 244 246 236 249 269 221 220 218 259 237 238 276 267 239 236 267 247 239 233 226 241 246 214 278 221 266 257 266 214 274 274 247 259 240 269 258 237 228 210 245 229 227 264 259 260 236 231 266 268 243 255 233 283 261 235 241 261 239 266 235</counts>
			</dataPoints>
		</scan>
	</xrdMeasurement>
</xrdMeasurements>