File: data/XRD/XG-Luft/XG-875/W6823-1D_XG_Luft_875.xrdml
<xrdMeasurements xmlns="http://www.xrdml.com/XRDMeasurement/2.1" xmlns:xsi="http://www.w3.org/2001/XMLSchema-instance" xsi:schemaLocation="http://www.xrdml.com/XRDMeasurement/2.1 http://www.xrdml.com/XRDMeasurement/2.1/XRDMeasurement.xsd" status="Completed">
	<comment>
		<entry>Configuration=Factory configuration, Owner=User-1, Creation date=7/8/2013 4:01:53 PM</entry>
		<entry>Goniometer=PW3050/65 (Theta/2Theta); Minimum step size 2Theta:0.0001; Minimum step size Omega:0.0001</entry>
		<entry>Sample stage=MRD Cradle; Minimum step size Phi:0.01; Minimum step size Chi:0.01; Minimum step size X:0.01; Minimum step size Y:0.01; Minimum step size Z:0.001</entry>
		<entry>Diffractometer system=XPERT-PRO</entry>
		<entry>Measurement program=C:\PANalytical\Data Collector\Programs\Jorrit\2thom\_absolute_2th-om_10-130deg_PIXscan_56min.xrdmp, Identifier={15BCCF57-2807-42BD-B5B9-ECC0B3DC9284}</entry>
		<entry>Batch program=C:\PANalytical\Data Collector\Programs\SimonL\batch6x_2thom_10-130°_z9.1_x0,10,20,30_y20,40_57min - Kopie.xrdmp, Identifier={8874E540-C3F4-4307-831A-CD55F073CDCD}</entry>
	</comment>
	<sample type="To be analyzed">
		<id></id>
		<name></name>
		<preparedBy></preparedBy>
	</sample>
	<xrdMeasurement measurementType="Scan" status="Completed" sampleMode="Reflection">
		<comment>
			<entry>_absolute_2th-om_10-130deg_PIXscan_56min</entry>
			<entry>PHD Lower Level = 4.83 (keV), PHD Upper Level = 11.27 (keV)</entry>
		</comment>
		<usedWavelength intended="K-Alpha 1">
			<kAlpha1 unit="Angstrom">1.5405980</kAlpha1>
			<kAlpha2 unit="Angstrom">1.5444260</kAlpha2>
			<kBeta unit="Angstrom">1.3922500</kBeta>
			<ratioKAlpha2KAlpha1>0.5000</ratioKAlpha2KAlpha1>
		</usedWavelength>
		<incidentBeamPath>
			<radius unit="mm">320.00</radius>
			<xRayTube id="1010048" name="Empyrean Cu LFF HR (9430 033 7310x) DK442154">
				<tension unit="kV">40.0</tension>
				<current unit="mA">40.0</current>
				<anodeMaterial>Cu</anodeMaterial>
				<focus type="Line">
					<length unit="mm">12.0</length>
					<width unit="mm">0.4</width>
					<takeOffAngle unit="deg">4.2</takeOffAngle>
				</focus>
			</xRayTube>
			<xRayMirror id="27010001" name="Inc. Beam Cu W/Si (parabolic MRD)" hybrid="false">
				<crystal type="Graded" shape="Parabolic">W/Si</crystal>
				<acceptanceAngle unit="deg">0.800</acceptanceAngle>
				<length unit="mm">60.0</length>
			</xRayMirror>
			<sollerSlit id="21010002" name="Soller slits 0.04 rad.">
				<opening unit="rad">0.0400</opening>
			</sollerSlit>
			<mask id="22030007" name="Fixed mask 2 mm">
				<distanceToSample unit="mm">220.00</distanceToSample>
				<width unit="mm">2.00</width>
			</mask>
			<divergenceSlit id="22010011" name="Fixed slit 1/32°" xsi:type="fixedDivergenceSlitType">
				<distanceToSample unit="mm">220.00</distanceToSample>
				<height unit="mm">0.05</height>
			</divergenceSlit>
		</incidentBeamPath>
		<diffractedBeamPath>
			<radius unit="mm">320.00</radius>
			<sollerSlit id="21010002" name="Soller slits 0.04 rad.">
				<opening unit="rad">0.0400</opening>
			</sollerSlit>
			<receivingSlit id="22010001" name="Fixed slit 4°">
				<height unit="mm">5.88</height>
			</receivingSlit>
			<detector id="7010017" name="PIXcel3D 1x1 detector" xsi:type="areaDetectorType">
				<phd unit="%">
					<lowerLevel>30.0</lowerLevel>
					<upperLevel>70.0</upperLevel>
				</phd>
				<mode>Scanning</mode>
				<activeChannelsEquatorial>255</activeChannelsEquatorial>
				<activeChannelsAxial>255</activeChannelsAxial>
				<pitchEquatorial unit="mm">0.05500</pitchEquatorial>
				<pitchAxial unit="mm">0.05500</pitchAxial>
				<readOutPeriod unit="seconds">0.135</readOutPeriod>
			</detector>
		</diffractedBeamPath>
		<scan appendNumber="0" mode="Continuous" scanAxis="2Theta-Omega" status="Completed">
			<header>
				<startTimeStamp>2024-10-30T22:10:27+01:00</startTimeStamp>
				<endTimeStamp>2024-10-30T23:06:33+01:00</endTimeStamp>
				<author>
					<name>PRO-MRD</name>
				</author>
				<source>
					<applicationSoftware version="6.1b">Data Collector</applicationSoftware>
					<instrumentControlSoftware version="7.0E 20130304">XPERT-PRO</instrumentControlSoftware>
					<instrumentID>0000000011142674</instrumentID>
				</source>
			</header>
			<dataPoints>
				<positions axis="2Theta" unit="deg">
					<startPosition>9.99826193</startPosition>
					<endPosition>129.99755682</endPosition>
				</positions>
				<positions axis="Omega" unit="deg">
					<startPosition>4.99913096</startPosition>
					<endPosition>64.99877841</endPosition>
				</positions>
				<positions axis="Phi" unit="deg">
					<commonPosition>0.00</commonPosition>
				</positions>
				<positions axis="Chi" unit="deg">
					<commonPosition>0.00</commonPosition>
				</positions>
				<positions axis="X" unit="mm">
					<commonPosition>20.00</commonPosition>
				</positions>
				<positions axis="Y" unit="mm">
					<commonPosition>0.00</commonPosition>
				</positions>
				<positions axis="Z" unit="mm">
					<commonPosition>9.100</commonPosition>
				</positions>
				<commonCountingTime unit="seconds">32.895</commonCountingTime>
				<counts 348 389 398 395 411 383 407 384 387 370 397 397 359 399 373 337 401 382 376 357 385 380 367 369 398 372 391 375 364 412 389 425 397 362 413 386 375 384 374 355 375 352 364 380 381 379 371 406 384 375 368 388 401 363 363 404 392 364 367 359 356 381 360 411 398 399 369 390 343 361 380 353 370 395 382 374 355 402 373 413 408 383 399 383 407 386 372 356 389 370 360 403 380 402 390 378 369 389 364 379 386 344 346 394 329 377 382 354 348 365 377 373 368 392 381 375 384 386 352 345 341 378 355 391 333 360 380 369 350 360 352 367 358 358 344 378 361 400 343 375 368 374 370 376 350 335 324 343 368 355 385 315 344 352 394 352 372 407 337 391 341 342 373 370 328 361 369 331 316 351 349 381 362 352 354 358 379 351 332 337 351 350 328 342 376 348 397 389 363 375 340 352 361 364 382 321 366 339 339 346 350 395 361 349 361 359 377 321 385 383 353 338 359 356 360 362 342 316 329 315 335 349 336 346 337 365 355 366 336 363 325 347 355 337 362 355 379 343 340 358 349 390 317 322 378 353 358 365 328 319 322 361 330 356 342 351 340 355 342 368 326 377 345 369 354 348 341 371 352 354 362 368 384 327 347 303 380 312 390 371 359 345 336 334 344 351 313 322 336 339 338 348 362 376 317 341 309 378 362 362 322 310 319 353 357 365 344 359 356 322 366 339 318 340 326 339 321 353 334 346 303 363 342 372 352 358 333 386 347 315 318 338 359 329 344 341 321 334 346 353 338 326 328 345 332 323 324 311 312 328 375 346 350 382 343 337 354 321 347 314 341 314 347 352 307 317 320 335 317 347 307 312 336 334 312 307 299 332 353 324 325 315 348 338 309 327 306 318 323 338 347 310 323 326 304 331 315 325 327 349 361 337 329 336 305 309 298 323 313 330 334 310 298 326 320 314 315 335 303 300 284 292 319 345 303 303 298 316 350 353 321 324 348 333 310 342 318 338 306 272 315 322 300 326 307 332 340 316 348 308 316 335 289 324 345 316 313 282 329 326 300 348 312 329 296 334 319 350 317 309 319 319 330 328 334 323 312 346 315 303 312 312 343 330 323 310 309 296 354 336 341 305 306 281 334 317 307 304 327 349 348 338 317 355 289 346 324 303 337 322 328 321 313 320 300 341 320 292 322 308 312 302 323 325 324 296 325 328 324 312 325 302 304 326 316 313 334 321 320 324 310 315 290 325 319 344 339 325 301 322 319 339 306 283 298 311 330 287 326 328 314 336 298 338 314 294 302 326 292 309 271 296 294 313 314 301 298 301 287 315 313 333 319 294 295 316 272 318 319 329 316 322 306 317 311 314 285 301 291 310 317 334 323 315 326 326 304 309 300 303 264 336 317 331 305 304 319 296 305 298 334 347 335 288 335 330 336 310 319 276 334 316 316 299 279 313 321 295 296 292 290 309 295 315 333 288 287 329 296 326 282 318 321 320 299 297 298 315 305 326 311 308 302 323 315 301 300 327 316 291 297 322 332 289 313 278 284 308 291 316 309 279 362 336 321 297 296 276 298 299 277 296 303 293 303 292 259 321 294 317 330 313 304 279 296 291 305 306 321 295 323 339 277 286 306 315 300 344 313 283 318 302 323 307 303 296 303 294 304 297 291 345 295 305 313 319 284 333 311 305 294 317 317 323 312 288 342 325 324 295 307 342 296 292 327 275 295 311 324 325 324 315 302 333 300 273 302 316 286 316 317 322 323 288 305 319 303 319 309 318 320 298 321 339 327 296 297 303 313 262 282 330 321 308 293 278 288 304 308 315 304 298 298 325 293 305 314 293 293 291 287 297 307 324 300 304 329 288 293 324 324 311 300 302 307 296 296 290 297 261 304 283 298 296 307 300 320 331 328 266 264 307 309 295 325 309 321 313 297 292 302 304 317 330 305 281 292 325 332 299 305 314 273 281 310 334 317 329 307 304 316 295 283 313 313 327 300 277 280 335 301 334 318 304 314 308 336 293 332 273 291 315 300 303 301 294 285 314 328 308 318 311 300 329 309 307 348 314 306 315 307 303 314 308 309 281 335 310 304 298 299 306 299 347 310 288 301 323 307 312 307 311 287 296 290 298 309 311 311 290 277 328 281 305 330 290 313 320 272 331 274 281 325 306 324 339 314 290 344 287 294 301 302 295 345 297 314 294 321 298 311 314 309 323 336 312 294 342 291 308 296 310 323 318 302 318 300 283 289 331 293 301 307 326 316 294 318 308 321 318 290 305 295 314 288 289 312 307 321 303 300 313 294 326 290 337 325 326 307 320 302 309 303 311 266 283 353 334 301 312 287 319 320 319 298 305 300 344 320 333 305 294 270 309 290 317 281 342 325 300 324 311 320 293 295 332 330 326 288 305 285 287 318 335 309 286 300 326 302 305 317 279 289 331 313 314 326 328 312 352 325 298 299 323 328 318 322 336 312 313 340 278 296 272 308 302 312 328 309 328 314 296 300 308 327 312 293 327 316 316 317 316 297 334 311 325 290 327 332 296 314 311 328 318 311 295 290 302 361 308 289 309 296 315 304 318 292 338 312 306 275 293 324 304 276 307 316 300 307 341 311 330 332 316 292 317 287 310 313 287 295 311 303 312 294 347 324 310 340 316 279 290 311 323 270 286 331 295 314 309 322 312 308 288 292 297 283 317 287 320 314 334 304 315 285 280 286 309 318 293 304 300 287 363 298 279 291 319 295 296 314 304 302 302 307 310 305 351 326 323 319 325 322 310 315 322 331 327 300 311 329 302 329 319 320 330 295 282 294 303 316 319 323 309 292 293 308 320 300 298 278 305 316 293 325 294 334 325 323 310 304 285 302 303 323 292 302 348 306 306 288 330 304 275 312 300 305 329 330 299 325 316 332 264 266 319 314 313 325 311 310 315 280 336 305 323 286 297 324 346 298 324 315 312 333 300 335 347 324 325 284 293 287 315 324 293 316 294 284 284 309 310 280 324 314 321 295 302 333 301 287 328 312 281 291 308 343 316 300 274 292 326 327 283 301 277 285 299 271 300 288 303 294 321 278 285 307 312 300 277 316 305 298 303 318 293 315 311 282 291 331 292 316 277 312 303 312 302 292 305 295 306 308 305 293 292 283 266 303 285 290 280 280 303 299 278 324 311 302 323 282 308 299 290 296 293 275 303 267 289 317 318 313 285 294 300 337 303 303 309 324 279 301 287 308 296 305 283 294 272 286 304 278 281 288 304 313 284 301 281 300 295 302 306 284 301 309 288 326 307 273 280 290 319 303 288 307 286 303 290 282 293 276 302 311 286 296 309 338 286 303 258 298 279 293 294 289 316 283 307 283 295 295 297 297 285 292 299 287 303 294 318 258 291 287 258 287 286 290 267 293 280 282 297 276 263 283 296 281 292 292 269 271 270 289 293 266 304 276 280 270 292 278 281 281 280 275 303 280 272 300 279 312 270 290 280 278 298 283 260 269 303 274 277 272 301 261 270 287 272 272 236 304 321 284 250 306 299 283 270 240 298 299 279 304 272 324 279 288 263 286 260 265 283 291 283 275 286 261 274 279 271 274 275 272 263 278 276 270 287 288 278 246 289 270 285 280 260 288 275 272 271 264 277 297 242 280 284 235 285 277 295 264 227 312 298 245 275 283 243 270 266 279 272 273 268 278 269 261 273 260 243 235 242 277 276 306 257 281 272 281 243 260 265 291 272 263 262 261 220 268 268 301 232 279 313 258 235 250 262 295 274 234 259 236 258 260 298 275 290 270 279 257 279 241 270 234 269 273 241 223 296 262 266 247 274 274 243 299 248 288 295 248 259 232 228 261 262 248 256 232 278 246 284 248 248 216 275 288 268 249 236 273 238 239 299 262 260 262 274 285 224 263 260 241 239 281 224 224 289 260 266 279 236 235 242 278 226 261 243 237 248 234 233 237 291 263 242 255 239 256 234 269 229 242 236 228 298 259 257 239 259 256 239 240 246 267 227 247 257 223 246 224 237 225 258 265 260 199 238 235 264 288 262 219 261 244 221 256 272 218 212 256 264 221 225 246 266 228 272 244 226 278 278 236 229 266 263 244 255 227 269 250 235 255 228 229 235 239 237 225 236 227 221 272 237 243 216 245 258 261 255 257 213 214 225 221 231 232 248 218 259 235 240 231 232 226 241 229 239 236 231 224 235 227 240 245 242 211 258 220 256 231 241 241 234 208 259 206 216 202 246 231 245 240 239 238 256 217 269 245 222 228 207 222 234 202 225 261 224 243 235 236 240 239 268 219 215 228 262 249 277 249 212 238 207 232 236 234 218 262 230 235 257 238 260 228 208 239 241 246 226 239 237 214 239 234 248 232 208 243 243 234 238 227 197 230 226 245 240 230 241 219 246 235 224 217 244 212 275 231 229 227 238 209 219 210 237 237 231 231 213 214 230 267 259 216 228 217 262 232 246 241 230 208 190 206 211 225 240 218 235 218 239 227 241 208 255 243 200 223 229 224 229 199 210 259 232 184 213 244 228 217 212 239 212 211 246 213 199 228 221 213 227 235 201 219 238 260 241 257 225 196 202 216 220 204 222 222 211 213 230 212 241 211 232 236 199 235 229 219 226 238 208 227 203 255 225 221 222 236 197 236 236 244 235 220 232 242 208 190 198 232 210 199 240 232 225 207 236 226 226 206 228 189 239 229 224 227 230 209 235 220 223 205 213 199 213 184 205 211 229 240 214 227 202 234 215 238 225 214 210 214 225 210 208 217 194 197 219 221 213 197 232 213 208 232 201 220 242 219 239 198 219 208 210 225 235 199 231 217 243 178 231 188 231 231 247 214 247 239 216 225 231 216 194 206 244 211 232 205 214 195 229 221 186 241 255 204 213 224 193 203 209 197 197 207 221 190 195 210 212 214 224 228 193 211 236 244 236 213 234 199 191 205 204 210 208 224 211 198 213 222 191 233 212 220 206 186 216 208 213 197 215 206 206 218 230 199 175 199 190 228 202 188 225 223 200 220 211 208 214 194 208 205 185 198 190 196 185 212 221 205 224 206 198 216 206 215 221 236 222 220 216 221 183 231 192 196 203 195 209 200 208 214 238 210 202 198 221 203 202 222 203 210 207 195 205 198 200 237 207 206 221 187 212 185 192 219 187 195 217 203 203 210 211 202 216 207 188 223 212 213 191 217 219 214 199 212 200 203 223 206 233 243 223 206 198 203 218 240 199 214 199 198 181 205 232 192 181 217 181 199 204 183 183 218 217 185 200 204 178 207 180 213 230 203 226 197 196 200 205 209 200 238 201 195 206 220 205 199 210 188 212 194 188 188 221 196 246 201 194 223 226 209 207 193 194 187 211 201 222 234 203 212 205 209 226 202 194 212 189 208 238 192 198 214 199 192 207 184 223 217 173 172 200 185 202 210 201 165 201 229 180 207 216 190 214 187 205 217 200 181 209 190 226 206 218 260 230 224 233 196 199 193 198 196 183 237 196 221 195 213 207 206 205 207 213 215 204 213 244 214 198 212 203 205 236 214 216 206 210 190 209 197 186 195 239 189 194 201 189 184 243 214 206 229 197 212 190 206 187 193 188 146 230 235 219 182 209 187 194 191 206 190 183 195 206 226 198 218 200 178 210 178 199 201 206 209 221 178 211 190 202 234 226 209 178 219 198 188 189 221 178 197 202 217 193 197 209 181 225 229 219 212 202 189 171 220 192 194 192 205 197 207 194 209 192 194 186 219 208 235 211 178 215 190 200 195 212 208 244 187 209 201 204 218 214 210 192 193 186 215 192 182 224 231 198 184 194 194 207 188 195 199 202 219 212 178 212 211 194 191 203 200 176 191 192 221 192 210 195 203 205 190 198 163 219 202 199 173 217 165 193 203 212 194 202 173 184 197 202 208 201 207 207 193 195 190 203 160 198 181 217 203 192 193 195 176 204 226 207 213 200 203 194 197 205 205 197 187 207 209 182 191 237 203 205 209 182 165 184 196 215 198 200 198 197 192 209 177 175 214 180 202 188 210 220 194 207 210 182 190 211 193 202 204 187 209 223 178 173 200 212 208 194 177 194 170 198 205 203 221 191 173 212 202 198 183 208 210 200 227 197 176 218 214 179 209 219 207 215 187 197 189 198 173 213 222 208 205 197 219 194 198 193 183 191 180 219 209 186 216 183 200 224 207 234 199 207 201 211 209 191 216 205 194 182 201 188 180 218 211 205 215 210 198 217 200 214 203 201 200 216 183 190 186 202 189 206 191 208 181 199 182 178 213 187 176 204 219 219 181 187 189 186 193 205 192 181 200 188 196 211 200 204 204 206 217 190 185 186 192 188 186 185 213 212 193 176 217 185 199 190 216 188 204 218 197 211 209 182 188 188 198 223 194 236 189 171 229 176 202 210 201 195 175 203 219 184 171 202 189 199 196 187 211 198 176 175 191 217 217 212 205 205 194 192 200 202 185 182 193 205 197 195 180 172 195 204 165 193 185 224 207 181 175 195 198 174 183 214 196 169 196 192 199 228 193 220 225 203 189 201 191 203 211 198 215 208 207 196 176 195 213 221 202 217 215 192 189 180 181 209 211 195 196 200 175 188 212 185 207 197 195 180 203 206 185 211 231 192 230 194 194 196 204 175 199 221 189 180 180 195 196 209 187 189 205 212 199 189 211 193 182 204 209 191 193 191 202 187 175 175 185 218 219 194 208 206 200 183 215 175 162 182 183 200 203 194 209 205 187 204 199 167 173 202 199 175 196 209 191 169 201 204 194 209 198 213 190 183 205 176 190 171 177 196 186 210 193 186 222 194 173 206 180 208 215 202 196 200 221 200 201 177 198 208 181 188 203 193 198 199 210 195 192 202 225 204 211 205 179 194 226 181 191 181 188 205 182 199 193 170 202 195 193 207 176 221 196 206 206 213 197 186 200 206 205 200 202 213 216 181 206 209 202 176 192 184 209 190 187 187 196 193 213 186 217 201 203 211 205 196 191 206 220 167 212 192 206 173 178 180 192 178 178 193 191 192 181 198 175 215 212 200 168 167 196 200 186 221 202 175 205 213 187 192 183 208 187 181 209 215 209 193 196 218 194 192 212 191 219 199 185 181 187 202 173 191 198 183 212 207 220 210 210 207 181 203 186 191 201 192 216 205 193 226 196 200 200 209 184 196 193 186 192 180 218 203 216 178 180 202 219 185 175 166 210 200 205 173 173 198 194 204 183 195 214 182 217 205 191 195 198 199 196 205 199 194 201 202 208 194 203 193 212 227 220 196 179 219 196 201 199 193 215 219 185 193 209 168 185 182 180 197 199 235 220 223 221 185 188 211 193 189 210 195 168 229 186 184 220 190 230 207 170 202 183 198 206 183 198 213 217 198 189 176 203 217 211 205 224 207 181 200 209 197 184 175 185 230 178 194 195 179 176 198 183 195 221 226 202 217 231 225 190 215 202 210 208 193 204 213 211 195 224 189 210 225 208 204 199 212 200 213 193 202 211 204 210 184 192 200 185 213 209 187 209 211 217 201 198 224 190 256 206 192 230 213 206 230 219 182 235 229 197 218 208 216 209 209 218 194 200 214 199 214 206 242 211 205 200 236 230 209 190 215 205 197 236 218 184 207 220 191 198 176 225 205 220 198 208 201 201 217 210 209 216 202 219 193 202 219 203 219 213 209 204 205 220 213 205 208 181 221 226 222 209 210 235 218 196 221 212 216 216 213 211 234 231 216 204 227 240 226 217 264 215 243 242 191 240 204 240 232 241 230 229 237 203 267 236 240 240 229 227 236 219 236 246 237 261 235 240 266 244 245 285 239 238 278 277 277 258 249 280 258 239 244 287 301 297 303 336 362 306 315 345 373 340 353 342 373 390 392 369 355 356 370 314 320 330 329 320 342 345 333 324 293 279 286 294 292 300 276 292 293 291 263 269 256 225 299 230 219 228 237 245 221 250 223 219 228 227 216 244 216 199 210 215 203 224 204 242 245 221 227 190 227 213 222 218 234 224 213 219 218 215 204 224 220 203 200 206 215 228 207 187 205 183 198 194 220 195 201 184 204 206 216 207 220 208 169 203 201 199 229 199 207 227 195 182 229 188 195 207 199 198 212 203 178 200 183 178 202 198 164 224 197 207 213 194 194 183 213 190 187 170 230 222 191 201 216 193 233 198 219 203 224 193 184 203 184 221 199 205 212 222 203 204 186 215 186 199 194 182 207 218 190 199 198 199 202 185 195 212 228 196 200 238 199 202 213 206 217 197 205 191 189 216 210 187 217 203 192 194 200 221 216 218 200 192 218 187 205 183 187 192 199 178 220 202 211 182 182 198 184 174 186 207 177 202 232 197 171 205 186 181 189 201 200 190 197 189 222 174 197 198 224 199 197 204 171 188 191 182 188 213 208 192 208 198 213 190 193 226 181 217 192 214 178 203 201 177 218 207 222 212 184 180 184 235 194 196 206 202 208 224 203 186 201 206 185 209 215 223 215 192 201 199 188 188 200 187 195 189 153 186 193 205 180 219 168 205 221 234 225 211 197 207 201 208 202 187 212 189 218 215 208 197 217 200 200 190 198 198 225 171 202 184 222 197 198 198 198 198 195 212 188 201 208 212 213 218 208 192 191 216 193 203 212 193 220 212 201 189 177 192 218 202 190 180 184 204 198 212 204 201 241 228 203 188 191 196 209 171 205 205 224 179 165 194 199 164 208 223 186 204 199 217 175 196 203 224 209 198 199 173 211 211 201 191 197 216 216 190 213 210 195 192 197 239 214 194 181 192 213 170 181 183 221 194 190 218 209 220 184 207 194 196 201 210 206 220 210 199 199 211 194 198 208 192 213 196 200 190 203 190 202 196 206 194 201 210 192 224 212 189 199 199 203 215 187 220 190 209 214 201 198 198 188 213 212 199 202 206 206 207 222 200 209 189 213 203 209 198 209 217 195 184 199 176 203 189 220 187 196 220 203 202 198 202 182 179 174 220 203 194 207 176 202 163 202 230 198 190 216 232 215 232 196 194 169 197 220 207 188 193 202 176 191 202 181 168 180 198 219 210 198 190 195 236 202 199 186 212 200 209 186 206 198 195 210 214 204 218 169 202 198 203 207 187 189 190 186 215 193 206 196 197 182 204 204 198 197 197 212 211 206 190 183 194 196 195 204 187 214 229 179 217 186 198 197 186 209 225 231 192 205 204 202 183 192 186 200 192 172 215 198 212 197 182 204 234 198 212 202 221 174 202 189 208 203 235 220 200 222 199 199 217 190 202 200 209 198 195 189 210 191 179 221 207 207 204 218 205 201 203 187 217 210 211 218 186 214 177 170 210 184 208 200 170 197 218 204 196 186 216 213 201 222 201 202 180 198 193 238 216 196 165 179 219 181 206 203 225 201 185 203 183 197 194 191 208 191 178 196 196 219 191 223 179 193 196 220 186 186 189 188 193 189 214 214 187 217 190 220 195 204 192 202 210 198 197 200 198 202 220 179 196 209 217 201 195 176 177 203 168 201 206 201 198 187 213 194 182 193 208 230 200 213 201 183 220 178 189 204 196 223 199 196 225 188 197 193 197 175 213 196 235 199 179 216 216 214 205 206 206 212 205 209 190 203 216 228 196 204 195 194 211 225 192 195 218 175 199 212 158 210 204 196 189 203 209 191 201 189 194 212 217 205 216 224 203 190 178 189 210 199 193 217 204 209 197 198 200 223 195 220 181 202 211 186 217 201 196 182 204 170 215 205 215 211 190 192 205 223 214 204 229 203 210 208 209 211 206 193 207 218 206 219 221 203 200 223 218 203 200 173 217 198 181 197 217 198 217 232 183 193 192 200 198 203 218 186 199 193 193 172 223 188 189 225 183 184 219 193 213 211 210 189 199 223 214 175 204 224 166 218 217 194 200 177 208 223 220 192 182 182 209 189 198 203 210 183 205 229 181 184 218 187 188 183 211 224 181 195 185 218 206 214 203 186 200 190 196 200 207 201 217 191 191 193 217 180 200 207 193 210 210 182 215 198 191 192 224 219 190 200 187 219 193 205 186 184 191 203 191 213 183 222 219 200 200 211 188 202 193 198 181 213 221 206 193 221 200 224 214 187 197 204 206 187 195 207 208 191 222 209 203 216 191 199 198 180 195 188 212 228 198 185 216 178 185 185 209 218 215 200 190 213 193 190 204 226 203 207 177 196 179 213 203 203 215 175 180 202 208 201 201 220 202 228 198 201 205 171 213 199 224 197 218 191 205 187 211 184 198 198 211 194 179 219 202 191 162 183 199 177 208 196 197 206 177 195 200 201 215 200 216 185 196 207 221 193 215 213 204 205 186 210 221 195 241 171 165 201 198 221 201 216 207 221 205 182 217 212 211 208 199 205 200 216 222 175 218 211 213 218 182 223 219 207 212 191 203 207 188 188 200 207 211 203 219 192 196 214 208 219 218 209 204 198 210 209 215 192 183 217 195 217 211 204 216 217 221 197 197 196 203 190 210 210 200 204 203 203 188 197 204 189 206 195 203 208 223 205 173 228 211 186 203 175 207 203 196 191 189 185 218 211 195 156 186 214 196 194 187 200 201 193 213 199 224 208 198 218 222 208 199 191 222 201 221 187 189 215 185 187 215 232 213 193 246 190 211 191 209 213 192 227 183 195 210 227 212 195 191 225 195 170 216 180 223 225 235 189 198 201 214 214 191 191 204 201 180 193 197 204 198 191 195 197 206 195 207 182 209 208 210 204 222 203 202 206 211 224 197 185 232 181 187 184 204 209 209 215 229 200 199 209 198 208 216 218 172 209 203 211 196 229 189 212 210 218 208 193 219 231 204 232 232 226 195 216 204 195 212 178 197 199 214 186 224 220 212 205 199 204 204 209 165 189 207 217 182 193 208 206 218 190 206 228 211 206 223 205 203 201 224 200 194 211 208 225 208 226 222 218 202 215 209 209 227 205 206 191 207 218 201 256 225 217 176 209 205 195 198 219 215 223 214 228 189 201 212 205 195 198 216 211 186 201 212 189 207 203 219 229 204 185 191 185 190 220 200 203 194 222 213 201 218 193 206 203 225 228 203 195 220 190 220 208 196 213 189 202 196 214 214 214 199 226 208 209 210 222 219 211 241 192 210 224 201 196 233 200 212 219 246 205 215 208 204 206 221 212 212 233 201 187 214 201 217 195 190 209 236 217 203 214 191 202 220 235 211 220 227 238 193 212 214 226 233 194 213 221 212 227 215 229 238 205 225 220 205 223 195 193 219 212 182 203 218 201 190 222 201 187 220 227 227 211 235 225 234 182 238 198 226 199 224 200 195 229 207 210 226 222 190 199 212 204 214 173 202 215 214 199 202 190 199 204 208 198 198 216 189 208 183 185 206 199 213 234 196 228 208 219 218 233 203 201 207 194 244 218 207 242 202 256 194 202 200 198 210 202 205 194 203 213 199 214 192 234 205 207 215 192 199 225 209 207 234 196 202 204 194 228 210 206 209 201 204 206 189 222 202 197 196 204 208 208 199 203 189 228 231 219 212 220 232 200 187 202 239 208 219 203 221 222 212 188 222 243 184 188 225 204 237 169 203 210 215 211 196 214 185 212 207 191 195 212 216 186 216 194 180 216 208 200 207 211 215 206 229 193 211 188 199 209 179 219 221 204 220 224 215 184 216 210 195 190 194 194 214 208 211 231 222 217 218 204 220 195 211 223 207 214 222 202 216 228 224 182 195 229 210 212 259 211 206 215 203 201 220 233 189 217 222 232 194 202 189 222 207 208 209 190 192 185 233 204 196 199 189 204 204 227 210 203 212 198 212 207 227 211 204 214 200 208 229 223 210 212 208 202 184 174 192 195 214 206 206 187 197 243 217 216 237 247 246 218 215 202 204 214 220 212 214 232 215 203 229 196 249 206 198 193 217 235 234 213 206 211 219 196 193 200 212 208 194 222 224 224 205 203 210 198 226 204 231 219 219 204 201 228 223 206 190 211 208 188 215 194 214 206 206 216 205 198 197 222 201 219 216 208 197 247 222 227 204 211 201 216 205 211 211 212 230 222 231 205 203 222 206 207 215 197 210 217 217 211 231 233 219 220 226 216 206 209 194 201 197 203 182 239 236 205 230 229 214 200 225 239 195 208 194 191 205 255 209 209 216 212 238 255 214 226 217 231 237 206 219 236 205 227 193 183 197 228 219 196 234 259 201 217 204 196 223 214 219 211 220 212 202 219 206 204 224 213 198 225 215 196 206 225 227 219 218 200 182 237 211 191 231 217 223 219 217 225 181 213 205 233 246 221 226 217 205 226 200 202 195 182 228 217 200 219 231 203 217 232 207 207 209 198 217 220 221 239 213 214 247 225 233 223 229 209 221 200 198 233 217 213 198 222 228 226 218 235 211 216 220 223 220 210 197 204 214 225 221 211 210 219 202 229 209 208 222 210 217 219 240 220 231 223 195 242 226 223 235 210 221 228 231 229 216 197 245 213 202 219 208 204 234 230 236 216 212 245 211 230 214 218 225 245 231 223 239 237 239 210 248 220 218 243 237 210 234 230 240 259 213 229 218 275 255 241 248 228 227 209 229 241 242 234 214 234 248 213 217 242 258 247 226 260 264 231 242 212 204 217 215 241 271 202 258 206 210 186 221 230 231 224 221 217 241 216 218 215 240 233 207 262 222 213 222 214 226 204 208 266 232 207 226 214 220 223 218 212 215 246 216 244 229 228 212 215 223 240 237 207 213 219 185 212 238 232 214 249 206 243 204 220 198 226 224 210 238 232 238 196 205 221 200 205 210 216 224 239 220 216 219 231 209 237 239 202 201 223 223 214 228 181 199 226 220 222 186 220 195 209 239 221 225 214 220 225 209 199 213 223 227 222 213 262 232 246 219 246 246 221 200 211 213 199 214 214 218 235 209 200 230 202 202 198 209 217 220 216 223 188 217 217 185 215 217 205 184 214 206 180 190 216 230 215 246 212 206 225 211 199 198 210 205 200 217 230 231 228 193 231 222 208 183 224 194 217 241 195 237 218 219 216 234 216 219 200 248 235 209 218 222 209 227 187 233 229 237 200 227 227 190 217 221 205 210 217 220 235 210 196 238 224 193 227 216 227 219 219 226 207 211 228 198 239 221 224 222 192 197 207 196 211 218 218 198 203 198 217 202 198 222 191 220 194 198 228 215 183 209 225 222 214 175 233 209 240 222 206 204 208 206 209 259 241 206 207 213 227 195 203 210 213 228 206 214 180 195 222 210 220 233 216 196 198 235 225 219 230 185 231 230 224 237 211 226 202 221 221 229 242 205 249 241 226 206 198 212 197 212 235 191 221 215 203 208 196 212 214 213 198 204 223 230 216 184 202 188 199 208 218 221 220 187 243 174 210 205 221 237 209 210 212 190 219 198 212 197 184 235 219 200 216 225 206 241 196 181 195 185 229 227 227 212 212 200 198 210 196 195 208 215 213 204 206 224 215 258 192 179 242 216 225 230 220 225 229 228 202 193 211 210 219 262 203 197 237 219 228 233 195 224 236 209 206 204 203 229 223 223 220 241 226 208 201 218 203 217 225 248 198 189 235 226 212 225 198 218 218 187 233 204 208 221 221 209 214 233 214 228 201 213 205 208 197 209 232 216 221 187 217 223 205 203 204 229 235 218 205 211 241 217 180 234 230 212 235 217 225 218 201 198 221 227 226 233 210 255 219 211 220 237 210 240 202 222 209 215 212 212 222 215 215 231 219 230 211 224 238 211 195 222 231 218 213 202 222 206 223 213 193 220 217 194 223 203 258 205 209 229 217 206 204 210 223 205 209 191 224 213 213 213 210 224 230 211 217 212 187 223 214 219 219 232 234 188 199 200 190 209 208 186 207 206 228 194 217 234 211 203 186 222 225 228 200 236 190 242 211 225 212 220 264 210 221 221 213 190 221 242 243 203 212 221 227 227 236 220 207 240 217 228 204 173 211 205 212 209 217 199 196 211 243 238 240 259 220 198 191 233 201 209 210 222 214 222 193 217 216 207 217 205 220 218 201 202 207 232 207 190 216 206 221 198 216 221 215 210 204 232 217 203 204 234 212 232 227 204 238 201 219 208 194 216 197 223 216 223 229 205 201 229 207 220 246 221 237 232 212 215 213 224 210 202 181 204 204 232 213 224 244 209 240 242 204 210 205 223 230 230 210 225 198 217 209 212 233 222 223 210 214 262 218 195 197 232 195 213 194 200 211 235 211 202 212 202 223 214 242 215 218 226 223 213 224 197 207 213 237 208 225 209 220 216 227 205 194 205 220 219 228 229 186 225 217 199 211 208 225 213 206 220 206 203 238 205 195 234 219 204 182 226 201 194 227 214 197 215 200 219 196 196 240 210 217 225 229 216 226 215 227 206 202 226 223 204 216 214 214 200 214 220 205 232 210 199 213 210 201 225 215 197 237 206 214 218 215 221 236 214 199 203 243 238 206 210 208 176 214 228 209 240 212 212 205 234 221 232 229 225 211 210 208 208 201 226 207 199 194 199 209 212 203 224 224 189 208 196 206 248 218 225 180 221 206 220 204 195 202 212 199 214 207 189 198 218 217 190 211 202 212 203 231 213 191 215 196 201 221 203 223 222 211 219 221 203 221 199 211 204 240 196 237 208 232 214 220 231 231 214 211 237 226 195 231 228 211 257 214 197 197 220 214 193 197 212 196 234 201 202 222 179 217 247 213 215 210 230 238 197 224 186 241 209 208 209 197 176 222 218 232 240 206 246 202 211 212 200 220 220 219 226 228 198 209 219 238 208 198 226 211 211 202 223 195 243 235 231 216 211 209 239 185 236 206 222 204 229 197 197 191 241 228 189 201 219 219 199 193 243 214 193 214 217 221 201 245 215 207 194 207 211 231 198 232 221 213 229 192 227 186 222 240 213 228 233 201 220 231 180 201 220 221 196 217 200 217 203 227 216 237 228 217 234 208 219 212 229 201 212 241 228 208 203 200 215 216 212 210 219 167 206 228 203 219 220 207 221 229 215 198 214 205 182 205 213 232 191 214 190 209 193 203 180 198 202 214 220 206 204 218 199 212 221 228 214 211 226 205 221 198 213 223 190 213 200 216 198 213 214 218 227 211 232 210 208 217 211 218 212 212 186 197 210 219 230 219 225 234 215 216 236 235 213 229 236 222 200 228 224 224 219 224 188 199 220 187 223 229 222 185 205 201 231 212 200 216 227 198 224 195 208 192 193 211 219 217 230 217 179 221 202 209 237 212 221 209 236 200 209 227 176 201 209 219 233 226 197 243 234 205 230 219 211 226 181 211 227 201 192 230 216 188 204 219 192 209 213 198 190 205 194 211 216 185 213 237 202 214 219 189 207 207 210 218 235 192 212 240 208 196 208 218 202 188 210 231 213 202 189 207 215 228 180 184 202 221 218 222 233 199 200 199 221 196 211 213 216 189 184 224 210 190 259 208 194 208 209 198 206 186 218 205 220 200 216 208 218 204 204 223 225 214 190 195 214 202 217 206 202 207 218 195 219 201 215 219 185 210 211 211 206 199 204 221 219 193 209 208 187 191 237 210 239 208 224 215 214 244 211 207 223 215 203 209 232 216 214 222 224 222 215 212 201 209 192 226 195 236 198 228 229 211 202 233 220 225 244 202 225 206 231 217 198 228 196 207 219 197 202 197 172 196 205 211 225 237 211 203 224 210 211 195 239 238 216 204 205 213 242 223 218 207 231 225 196 219 205 206 217 199 225 222 212 206 191 213 200 175 234 186 213 203 209 219 238 221 240 200 214 208 202 218 202 209 261 192 221 235 202 227 197 206 231 193 194 213 255 229 222 186 223 220 199 204 220 193 203 226 249 206 193 249 202 224 204 203 219 227 224 212 201 214 205 205 231 230 222 210 189 237 197 208 210 212 219 186 227 246 226 201 229 199 196 212 234 234 210 233 223 221 205 207 223 225 224 215 222 208 199 215 230 223 198 215 230 208 215 205 227 195 221 229 230 272 205 199 208 195 229 220 193 201 243 210 227 220 245 222 239 211 227 200 217 220 214 196 195 214 201 201 192 235 230 195 199 226 211 216 220 203 203 227 211 239 221 195 205 226 198 207 224 208 216 239 213 218 212 208 212 203 234 215 232 223 208 234 221 203 200 218 216 199 204 223 231 220 241 224 216 212 219 205 232 241 239 217 235 241 230 249 228 211 220 192 228 219 232 219 208 243 261 219 211 206 192 227 220 195 218 227 226 201 230 206 222 217 243 246 217 226 193 196 235 227 229 256 193 231 219 198 228 227 231 248 204 210 198 217 194 219 180 214 227 211 204 255 217 208 207 210 232 213 222 212 214 204 236 240 199 217 216 228 220 234 232 229 217 249 224 234 240 216 209 220 228 209 207 230 209 207 216 220 255 222 198 222 209 217 192 226 203 218 211 221 211 211 215 222 241 219 210 263 225 222 212 226 238 235 243 219 232 225 227 247 219 246 290 225 237 263 245 266 214 216 242 234 235 221 265 243 245 240 246 232 273 241 269 248 245 277 238 247 265 243 240 250 256 241 218 227 223 238 250 217 270 257 238 244 240 236 229 225 223 247 211 255 282 257 223 268 255 216 245 210 243 257 226 228 249 265 261 244 242 216 243 208 223 205 213 228 215 201 247 229 217 215 232 222 215 229 217 223 244 212 229 194 244 241 239 191 218 224 238 213 236 220 217 222 196 218 223 201 215 223 231 213 236 220 220 205 210 215 197 208 205 228 240 204 230 221 202 204 234 219 215 222 217 197 205 214 216 214 215 231 240 238 217 201 204 221 232 217 225 217 222 235 209 179 196 233 235 223 201 225 213 213 230 212 220 227 209 267 242 203 221 223 199 242 209 216 238 243 188 230 216 176 197 179 203 205 190 229 228 213 221 220 196 209 189 225 205 201 223 179 237 234 224 191 213 212 192 197 211 208 217 202 212 211 208 202 222 213 217 193 211 212 216 244 221 225 226 207 185 184 173 191 206 192 218 204 232 200 199 221 224 220 224 180 221 216 223 198 201 242 238 223 224 205 206 255 210 221 197 197 208 219 215 236 237 221 209 199 212 197 204 229 215 208 208 225 220 232 205 221 219 188 206 231 213 198 218 208 209 227 212 231 198 204 210 211 195 239 226 230 201 223 216 192 195 206 201 184 204 184 217 204 177 230 212 216 220 236 207 217 191 199 222 188 206 217 195 203 194 221 213 234 202 199 211 215 221 194 219 195 204 220 227 207 201 204 206 180 242 202 221 239 205 213 176 226 204 223 217 225 207 211 200 214 210 240 196 206 189 201 184 216 195 203 205 217 228 195 202 216 213 169 184 184 233 210 202 214 207 173 214 223 216 202 220 207 217 217 230 205 219 222 225 193 231 218 224 217 206 207 233 214 204 196 208 215 223 213 188 207 220 235 212 227 238 211 210 196 209 209 208 202 209 203 192 206 226 198 230 221 200 206 228 196 218 193 238 191 213 207 207 198 196 212 194 239 225 185 227 225 206 212 209 186 234 194 214 187 217 200 221 193 215 221 219 194 236 197 188 193 219 208 208 215 196 194 206 196 186 213 223 204 237 224 199 246 227 212 177 210 243 227 237 232 200 209 208 199 203 203 210 226 219 204 223 214 188 177 218 218 207 202 209 217 203 221 229 212 206 209 206 226 196 207 228 237 195 223 214 189 220 215 246 209 224 222 221 193 212 190 204 233 217 211 245 228 186 234 229 229 198 196 213 199 212 234 207 216 223 209 201 214 209 244 213 203 208 234 232 211 206 215 211 233 215 203 208 219 227 219 192 195 226 189 207 221 198 233 242 210 231 226 226 189 196 230 214 194 197 222 225 263 212 195 236 204 201 229 209 210 208 248 210 213 228 187 208 231 229 227 200 238 239 201 185 214 215 222 204 212 220 215 220 219 207 177 219 212 202 221 208 230 211 194 206 200 208 213 226 212 211 213 205 220 211 227 200 207 217 239 208 216 177 193 256 206 203 203 214 215 222 193 194 204 234 210 201 204 207 182 212 199 236 209 191 217 219 235 212 194 225 209 213 224 230 228 223 224 240 198 221 213 197 215 215 188 196 199 220 219 248 199 219 240 182 224 197 214 208 220 210 222 234 207 215 199 197 205 179 219 192 207 222 231 209 204 220 221 249 226 222 208 230 231 201 220 224 231 210 201 232 198 238 225 217 238 205 222 231 226 225 207 202 228 178 221 232 221 237 193 199 228 193 224 201 214 230 213 204 192 218 214 226 228 215 215 197 228 206 218 222 189 198 219 204 223 248 206 225 206 228 220 235 205 204 230 218 200 205 205 218 198 196 218 186 227 203 209 226 235 242 220 227 221 207 213 216 221 212 227 235 213 183 207 194 185 219 236 235 208 206 213 218 217 211 220 224 224 217 208 236 228 220 207 203 218 199 216 239 198 197 208 213 207 221 203 195 213 195 218 231 229 202 203 224 214 200 224 216 193 217 239 205 239 219 217 178 199 231 194 193 219 216 212 199 221 218 214 214 225 209 203 235 227 201 236 193 190 230 204 220 217 222 229 255 170 225 218 221 228 197 232 210 187 242 195 180 224 217 211 198 243 201 215 208 215 217 232 230 183 187 190 198 204 202 240 237 207 195 213 224 196 215 219 222 209 229 216 235 226 214 175 194 214 193 216 241 201 198 223 220 191 226 209 204 209 223 193 217 201 214 234 215 208 214 213 193 208 190 187 200 222 210 202 226 224 201 204 212 255 203 226 202 215 209 195 210 236 219 210 235 185 206 239 228 242 225 224 211 262 214 210 227 209 216 194 179 235 211 199 213 217 216 198 206 182 207 217 220 222 205 220 214 210 211 201 221 211 208 210 195 209 209 232 199 205 223 179 221 233 207 195 190 222 189 213 218 239 191 184 223 216 205 197 187 211 205 206 216 234 220 186 209 226 211 235 226 219 207 195 214 199 227 192 200 202 249 207 209 198 213 239 218 212 217 213 208 215 214 224 218 210 242 191 218 195 188 201 207 198 198 235 223 223 242 210 234 188 225 229 218 214 231 192 216 207 222 175 223 224 228 206 204 198 245 213 204 218 213 215 221 203 196 205 202 192 199 200 221 197 197 207 207 212 207 208 187 216 192 216 211 215 220 189 195 191 204 214 191 196 215 216 228 181 204 201 206 208 220 192 208 213 210 216 237 211 236 224 197 193 218 264 185 200 211 219 195 241 190 205 201 228 225 215 234 210 196 209 203 206 203 218 201 215 249 233 240 204 224 203 209 218 218 208 227 202 190 214 210 218 212 197 208 197 215 239 239 221 197 208 212 187 219 229 213 201 191 233 219 233 201 212 200 195 215 188 185 222 222 222 207 196 210 205 199 204 216 233 213 233 200 205 224 225 243 198 221 216 221 183 204 219 233 217 211 208 199 233 215 220 220 225 218 249 246 194 196 230 208 183 221 196 231 211 191 200 184 199 205 204 214 217 194 230 237 221 199 219 222 227 188 199 210 235 213 208 246 226 210 219 211 215 218 199 203 232 196 199 231 214 204 216 219 213 233 237 192 219 201 212 231 214 192 222 209 179 221 217 213 187 242 193 205 227 214 222 210 198 219 233 191 218 220 237 185 221 201 229 232 207 196 220 257 229 216 213 218 193 199 192 189 207 213 221 199 221 228 219 215 246 206 245 196 206 232 232 220 183 204 216 202 214 220 221 224 237 188 219 222 209 207 212 206 215 190 225 199 183 199 232 197 211 183 218 199 229 215 215 211 207 211 210 195 195 204 207 224 196 202 212 175 218 220 215 214 210 206 202 207 205 211 217 206 216 216 208 216 205 211 202 203 231 218 223 212 200 197 223 225 210 193 205 205 203 221 209 199 209 239 223 216 214 211 210 227 209 219 200 196 212 223 183 194 230 190 205 209 218 204 186 213 202 221 220 195 208 208 221 232 213 223 198 187 227 211 241 216 229 200 180 240 202 238 222 227 208 183 223 220 267 212 188 201 227 219 209 188 213 221 214 211 208 208 209 202 206 209 213 211 190 215 220 189 229 205 197 217 209 229 205 221 203 211 193 213 237 208 227 217 215 202 210 209 192 200 204 190 221 208 223 234 242 232 229 209 212 221 217 217 219 206 224 231 203 227 223 212 204 211 225 206 212 214 200 213 188 223 208 206 203 210 216 208 216 239 221 236 221 227 234 220 217 192 204 228 231 197 229 202 223 195 211 211 199 235 206 227 181 230 207 209 205 186 196 229 214 201 220 219 208 213 240 224 236 203 211 232 219 220 209 219 202 221 213 225 202 236 209 239 226 203 219 223 235 201 215 210 204 203 227 223 218 229 249 235 223 228 236 217 218 212 200 213 218 215 226 234 213 199 224 259 224 235 225 222 215 217 222 207 196 221 216 240 229 206 225 217 260 209 241 221 222 199 237 217 242 224 196 212 222 231 228 204 225 202 220 218 211 229 213 216 200 232 196 229 219 211 192 241 193 241 207 256 232 208 224 202 243 219 238 218 229 225 201 221 228 203 209 212 201 216 207 207 221 226 204 212 192 202 200 207 198 208 206 208 224 207 211 201 212 200 211 168 226 219 219 196 202 227 193 184 228 221 216 227 213 197 234 225 209 206 229 190 186 197 197 187 208 192 200 218 202 203 207 197 210 203 219 227 192 226 207 246 207 215 203 222 193 221 232 215 192 207 210 193 198 217 236 202 205 214 200 196 257 222 219 198 210 228 213 220 221 188 211 225 213 211 208 227 234 210 208 232 227 193 214 237 204 208 229 197 223 226 205 231 227 214 198 214 208 204 223 215 211 203 213 212 215 209 218 227 205 195 229 217 213 210 206 203 199 227 226 206 218 240 186 197 214 204 196 208 202 196 203 226 204 194 207 209 236 230 215 232 221 218 205 228 223 246 213 223 210 197 203 193 234 214 212 218 208 215 224 225 200 194 212 186 222 214 217 217 216 242 222 215 235 190 211 187 215 207 231 236 209 228 183 216 219 204 213 223 231 221 206 218 194 207 200 179 202 223 219 239 230 207 205 203 189 203 206 201 229 224 219 225 214 176 213 233 222 170 223 210 220 219 195 185 185 228 194 221 231 223 219 228 215 187 217 218 209 235 201 232 208 208 207 202 218 203 250 197 243 222 194 198 218 216 213 187 218 213 213 223 199 222 194 220 204 190 219 214 258 212 199 212 198 211 221 213 218 212 214 237 225 248 215 199 219 210 219 227 202 221 209 222 203 213 208 215 185 212 247 197 224 204 187 224 203 211 206 208 230 198 208 215 264 247 213 201 218 179 231 228 223 226 214 202 220 244 208 222 207 249 212 188 173 193 230 218 202 215 212 197 200 214 185 227 205 193 202 205 225 211 197 209 221 227 223 223 221 227 202 195 201 191 230 194 220 227 230 204 211 224 219 216 216 223 210 195 215 211 211 183 219 218 241 213 174 205 220 203 205 199 174 210 209 216 208 210 215 207 222 206 198 210 206 225 227 215 203 210 185 205 229 179 212 196 204 184 236 209 210 227 224 218 225 208 222 212 240 240 195 232 198 212 206 196 221 201 213 211 210 207 228 197 202 221 219 210 191 198 228 248 192 212 193 211 202 196 209 202 218 205 245 233 198 223 195 216 195 205 202 173 211 221 203 225 217 204 208 200 226 238 196 195 229 211 202 228 217 237 200 217 219 236 205 204 180 220 202 194 222 236 217 215 225 201 215 212 217 199 231 199 202 218 208 205 193 195 201 183 214 200 211 209 195 210 223 224 229 206 221 219 212 205 199 233 214 211 193 210 179 209 199 202 203 225 244 200 203 220 216 219 232 209 193 222 212 196 213 199 205 209 212 224 211 219 212 218 182 213 196 229 214 228 209 234 198 223 234 208 217 198 206 227 216 218 208 219 226 205 181 201 201 200 217 203 191 204 229 203 201 219 194 241 222 196 210 209 203 216 214 222 186 262 222 240 214 221 201 213 215 212 180 238 191 228 219 225 210 212 198 239 234 204 221 221 230 189 217 210 214 196 195 225 229 237 205 222 204 212 214 209 202 210 223 223 209 210 198 199 201 201 196 209 206 205 212 201 217 214 188 209 187 206 186 205 199 210 196 177 192 191 218 194 205 206 197 222 201 196 207 208 205 190 231 210 213 210 226 217 231 204 198 236 220 202 219 208 217 241 187 208 189 211 226 211 219 231 218 201 192 210 217 237 214 189 198 232 221 208 200 229 207 180 190 231 209 230 223 197 221 210 203 201 200 189 199 231 241 200 239 216 202 257 189 211 213 194 208 216 213 218 193 211 208 231 215 202 206 175 211 207 237 225 233 221 203 208 212 203 196 212 211 238 223 223 238 207 200 246 210 225 219 211 207 182 225 225 207 235 239 227 232 197 196 203 223 211 200 198 206 222 195 225 206 196 195 231 225 220 220 226 229 218 205 227 207 190 215 208 232 225 185 218 207 204 219 201 211 220 238 194 236 230 215 192 213 209 201 230 214 206 222 240 203 258 198 208 213 209 228 231 212 204 218 214 221 194 217 238 228 224 233 206 230 192 205 211 241 221 238 197 226 229 226 209 196 203 202 215 209 212 215 211 210 233 221 237 229 206 215 188 220 200 214 200 218 216 202 215 189 189 224 201 195 223 234 213 199 195 223 195 217 219 177 222 208 220 225 213 229 215 226 214 211 225 231 266 220 211 195 218 225 218 221 230 213 236 226 210 219 213 230 248 222 208 215 198 207 209 211 209 193 237 236 203 196 201 204 203 200 187 211 198 214 215 236 204 191 185 214 227 223 207 217 198 216 213 202 201 207 237 202 199 229 204 241 214 204 210 207 232 205 222 212 218 227 227 229 229 211 200 212 208 215 204 235 217 216 217 233 197 202 230 220 188 220 201 247 223 231 246 239 201 206 230 225 182 224 210 216 198 231 220 232 200 198 230 228 219 200 211 206 211 235 214 218 233 186 172 229 234 262 201 219 211 215 214 239 216 200 237 207 193 190 214 200 215 193 220 232 204 239 200 206 216 234 236 197 216 202 216 194 202 184 206 220 226 231 205 191 220 227 246 242 209 203 196 205 204 210 200 197 212 222 218 248 182 215 186 212 228 220 215 201 209 221 205 212 208 224 183 184 207 221 179 208 228 213 227 230 224 227 220 193 212 198 229 226 204 235 213 215 219 223 239 225 266 230 246 215 204 243 223 204 189 248 200 206 218 209 239 205 211 247 232 227 206 209 236 192 221 212 208 200 223 208 208 249 214 213 191 227 213 216 229 203 230 210 193 238 234 201 221 213 239 201 239 218 215 210 217 202 211 203 198 232 222 191 220 236 224 226 235 218 239 233 216 203 219 231 238 227 189 208 180 212 235 228 210 208 209 192 215 203 198 208 209 184 215 205 184 197 237 213 220 245 224 217 221 209 213 219 211 215 217 213 222 232 217 214 197 214 224 209 231 208 205 193 223 216 218 198 215 216 228 214 231 223 196 191 237 225 227 213 193 206 241 221 232 227 240 200 235 222 203 241 217 230 214 242 221 212 209 190 215 217 218 226 204 220 210 206 221 221 219 208 187 236 202 209 211 244 231 206 199 211 213 181 223 197 196 206 223 239 238 199 208 218 197 231 192 234 217 197 226 259 204 225 199 225 207 207 226 220 217 199 238 212 212 225 190 233 222 232 213 230 220 235 223 212 216 208 202 200 210 201 199 230 213 217 215 234 214 205 213 220 212 212 212 214 207 213 216 214 236 192 230 203 232 212 225 220 232 233 211 226 222 203 202 235 222 194 219 228 242 221 226 227 228 236 207 208 227 222 229 201 234 201 213 221 208 205 202 221 220 200 213 227 225 204 237 208 208 244 212 219 236 242 219 191 221 206 246 216 232 221 240 213 199 222 188 210 209 219 220 209 218 190 219 204 242 217 213 247 233 211 210 207 212 249 238 196 209 225 231 225 207 213 199 205 197 193 228 224 236 217 201 210 246 224 190 214 223 196 203 233 210 229 234 223 216 215 212 220 197 233 227 225 221 231 215 248 234 258 236 218 205 197 224 197 203 205 221 207 255 239 220 229 224 233 197 219 229 238 216 235 246 202 240 217 199 223 233 208 233 209 233 235 197 207 240 204 209 214 213 221 201 212 210 205 249 215 202 233 216 232 211 237 208 223 219 228 256 245 228 244 211 217 255 244 195 221 230 195 200 225 208 195 217 235 211 250 208 228 230 213 243 240 236 218 226 238 228 228 221 218 241 222 220 210 223 177 232 212 224 219 243 214 244 224 231 229 247 220 221 236 240 209 249 255 242 193 206 246 217 224 235 239 220 264 214 243 205 201 219 236 225 235 219 223 242 247 242 257 235 235 219 233 229 247 213 247 232 263 222 239 239 188 260 238 228 225 226 210 216 237 222 224 234 238 226 229 237 204 243 235 216 207 241 208 237 233 220 216 213 225 240 209 211 217 216 218 220 217 224 213 227 209 212 233 235 258 231 233 229 216 192 210 215 233 233 202 201 224 221 223 200 243 215 208 202 208 211 199 224 235 201 222 211 227 173 220 221 211 196 227 224 225 207 220 214 209 191 211 216 212 206 220 207 195 225 218 187 259 221 216 214 207 216 210 224 221 233 216 205 211 217 235 228 214 203 201 239 200 206 210 220 221 214 209 231 223 192 222 204 201 222 204 206 204 223 215 201 207 217 199 225 221 213 217 217 225 205 219 211 247 174 260 217 232 202 215 221 196 214 227 201 212 205 197 214 190 218 235 225 206 257 209 207 229 222 222 215 259 208 215 219 207 215 226 225 228 201 230 235 204 207 199 212 245 220 214 223 226 200 241 203 213 196 214 238 221 211 230 210 207 188 220 218 216 236 205 233 213 202 241 202 232 243 227 220 226 206 232 238 211 211 228 224 193 232 210 195 208 234 215 222 209 221 234 221 205 203 220 217 195 208 212 218 222 219 201 205 214 205 203 193 214 191 239 228 182 240 213 227 236 220 204 182 200 206 196 199 236 199 211 241 196 204 218 221 226 209 183 218 232 205 218 217 216 232 230 215 222 230 203 205 207 201 193 204 208 227 223 209 211 213 227 191 223 234 208 214 218 196 219 206 206 223 207 220 232 208 173 192 169 235 219 218 226 213 213 191 208 198 229 206 219 236 228 230 221 228 204 204 214 234 220 222 201 222 183 195 201 217 231 200 221 227 213 194 232 225 200 223 221 223 238 224 229 245 202 194 206 212 224 233 221 200 229 198 202 215 218 229 200 204 235 219 208 224 214 214 244 197 198 231 213 201 239 212 232 211 223 211 197 216 223 167 240 230 207 229 202 226 205 209 241 184 206 220 234 214 219 210 183 188 220 202 229 210 219 235 220 222 211 215 222 194 204 216 205 234 217 177 191 205 224 276 218 186 217 214 202 214 220 205 231 227 175 206 217 230 212 219 213 225 233 213 196 224 198 213 224 223 200 220 219 203 242 197 218 210 189 189 227 227 190 229 208 204 211 209 198 256 219 202 219 211 198 222 208 215 216 193 234 217 200 215 203 202 222 226 233 225 204 207 207 175 209 225 206 231 214 230 225 216 211 224 189 222 196 207 202 209 210 210 212 249 201 211 204 238 181 214 201 191 232 200 261 214 228 214 220 211 218 229 234 216 228 224 191 235 217 220 195 238 204 202 217 205 191 208 216 192 229 208 220 205 213 208 239 218 219 193 221 223 224 246 206 206 227 211 222 206 223 234 205 200 213 211 208 207 211 221 218 228 220 227 204 202 192 191 226 224 189 212 223 222 225 200 209 210 235 212 216 243 246 223 224 233 185 233 211 213 228 260 222 214 218 226 226 196 233 238 224 212 221 205 203 232 197 214 222 216 204 211 208 207 218 261 210 215 212 232 210 219 200 226 247 192 198 217 196 220 205 232 206 228 214 221 197 230 214 215 209 216 239 221 215 237 236 200 230 214 183 246 208 196 193 205 200 186 214 197 195 201 187 203 215 232 214 214 196 220 212 238 204 220 196 208 180 215 231 228 211 239 195 216 223 197 197 230 237 219 215 235 187 212 226 201 195 207 213 228 213 214 195 213 234 222 219 229 220 217 241 224 207 214 225 227 190 223 205 218 193 232 241 210 216 213 231 225 212 212 240 218 219 243 232 230 181 229 210 218 211 184 217 223 236 193 226 220 234 199 224 217 208 239 225 206 187 203 198 196 227 230 194 219 206 248 237 199 224 236 214 203 220 215 221 217 224 196 229 209 244 206 236 216 196 208 217 210 213 172 208 215 196 230 209 215 231 235 214 232 228 194 233 225 211 229 216 220 213 226 215 214 191 243 216 215 208 222 207 202 227 212 208 239 223 218 214 236 234 187 229 200 220 225 231 213 214 195 219 212 216 209 206 217 219 209 211 217 226 224 213 229 211 215 217 225 221 227 245 224 219 205 237 218 207 217 204 200 216 211 204 221 249 196 216 224 225 184 202 216 211 221 218 229 213 225 184 200 185 203 217 202 235 227 186 208 188 208 196 219 227 216 219 205 216 205 218 217 237 236 208 211 211 230 212 244 202 214 210 227 210 229 216 248 216 195 209 229 199 202 229 217 228 222 234 207 214 261 230 211 209 180 217 232 213 226 223 201 214 205 231 205 200 238 227 223 231 233 231 217 216 225 202 212 209 221 223 231 217 224 217 197 213 203 199 208 225 225 211 223 199 223 268 226 206 235 232 209 207 212 211 192 198 215 201 182 202 229 234 208 218 211 183 209 214 205 223 217 229 221 212 219 211 200 224 215 215 216 211 228 226 203 236 215 220 192 237 206 200 235 216 214 183 223 237 194 204 218 230 196 210 227 221 204 191 212 226 224 219 222 233 244 208 223 196 208 243 234 226 214 218 229 206 208 200 209 222 209 227 218 211 203 217 225 224 207 233 246 215 231 244 215 217 201 214 219 220 239 200 226 225 206 228 226 201 199 211 205 237 213 233 202 214 208 226 208 210 229 218 196 230 222 229 204 218 220 229 234 204 213 217 219 211 220 226 235 233 213 214 193 235 204 184 222 227 224 214 219 224 224 235 223 217 194 206 219 232 196 227 207 237 204 230 218 248 198 211 232 213 204 226 221 228 217 219 222 218 204 220 193 196 229 230 220 223 219 219 207 219 216 218 226 205 245 236 205 224 205 221 204 223 190 224 233 244 218 240 223 243 247 237 206 192 194 229 210 209 221 205 230 212 212 211 228 218 225 224 225 232 200 220 220 222 233 207 222 214 221 215 191 218 242 214 220 216 219 224 233 223 213 263 223 206 188 219 215 238 229 232 237 221 206 203 265 228 235 227 215 239 215 205 215 221 223 186 218 230 242 233 222 222 214 244 207 230 211 240 210 264 199 218 211 211 243 213 214 223 188 202 214 201 233 208 243 216 231 220 197 202 211 211 216 230 227 220 242 245 200 207 234 214 215 204 217 247 205 212 218 201 243 219 199 199 230 212 211 210 231 210 222 207 208 195 230 208 208 224 219 209 229 224</counts>
			</dataPoints>
		</scan>
	</xrdMeasurement>
</xrdMeasurements>