File: data/XRD/XG-Luft/XG-875/W6821-1D_XG_Luft_875.xrdml
<xrdMeasurements xmlns="http://www.xrdml.com/XRDMeasurement/2.1" xmlns:xsi="http://www.w3.org/2001/XMLSchema-instance" xsi:schemaLocation="http://www.xrdml.com/XRDMeasurement/2.1 http://www.xrdml.com/XRDMeasurement/2.1/XRDMeasurement.xsd" status="Completed">
	<comment>
		<entry>Configuration=Factory configuration, Owner=User-1, Creation date=7/8/2013 4:01:53 PM</entry>
		<entry>Goniometer=PW3050/65 (Theta/2Theta); Minimum step size 2Theta:0.0001; Minimum step size Omega:0.0001</entry>
		<entry>Sample stage=MRD Cradle; Minimum step size Phi:0.01; Minimum step size Chi:0.01; Minimum step size X:0.01; Minimum step size Y:0.01; Minimum step size Z:0.001</entry>
		<entry>Diffractometer system=XPERT-PRO</entry>
		<entry>Measurement program=C:\PANalytical\Data Collector\Programs\Jorrit\2thom\_absolute_2th-om_10-130deg_PIXscan_56min.xrdmp, Identifier={15BCCF57-2807-42BD-B5B9-ECC0B3DC9284}</entry>
		<entry>Batch program=C:\PANalytical\Data Collector\Programs\SimonL\batch6x_2thom_10-130°_z9.1_x0,10,20,30_y20,40_57min - Kopie.xrdmp, Identifier={8874E540-C3F4-4307-831A-CD55F073CDCD}</entry>
	</comment>
	<sample type="To be analyzed">
		<id></id>
		<name></name>
		<preparedBy></preparedBy>
	</sample>
	<xrdMeasurement measurementType="Scan" status="Completed" sampleMode="Reflection">
		<comment>
			<entry>_absolute_2th-om_10-130deg_PIXscan_56min</entry>
			<entry>PHD Lower Level = 4.83 (keV), PHD Upper Level = 11.27 (keV)</entry>
		</comment>
		<usedWavelength intended="K-Alpha 1">
			<kAlpha1 unit="Angstrom">1.5405980</kAlpha1>
			<kAlpha2 unit="Angstrom">1.5444260</kAlpha2>
			<kBeta unit="Angstrom">1.3922500</kBeta>
			<ratioKAlpha2KAlpha1>0.5000</ratioKAlpha2KAlpha1>
		</usedWavelength>
		<incidentBeamPath>
			<radius unit="mm">320.00</radius>
			<xRayTube id="1010048" name="Empyrean Cu LFF HR (9430 033 7310x) DK442154">
				<tension unit="kV">40.0</tension>
				<current unit="mA">40.0</current>
				<anodeMaterial>Cu</anodeMaterial>
				<focus type="Line">
					<length unit="mm">12.0</length>
					<width unit="mm">0.4</width>
					<takeOffAngle unit="deg">4.2</takeOffAngle>
				</focus>
			</xRayTube>
			<xRayMirror id="27010001" name="Inc. Beam Cu W/Si (parabolic MRD)" hybrid="false">
				<crystal type="Graded" shape="Parabolic">W/Si</crystal>
				<acceptanceAngle unit="deg">0.800</acceptanceAngle>
				<length unit="mm">60.0</length>
			</xRayMirror>
			<sollerSlit id="21010002" name="Soller slits 0.04 rad.">
				<opening unit="rad">0.0400</opening>
			</sollerSlit>
			<mask id="22030007" name="Fixed mask 2 mm">
				<distanceToSample unit="mm">220.00</distanceToSample>
				<width unit="mm">2.00</width>
			</mask>
			<divergenceSlit id="22010011" name="Fixed slit 1/32°" xsi:type="fixedDivergenceSlitType">
				<distanceToSample unit="mm">220.00</distanceToSample>
				<height unit="mm">0.05</height>
			</divergenceSlit>
		</incidentBeamPath>
		<diffractedBeamPath>
			<radius unit="mm">320.00</radius>
			<sollerSlit id="21010002" name="Soller slits 0.04 rad.">
				<opening unit="rad">0.0400</opening>
			</sollerSlit>
			<receivingSlit id="22010001" name="Fixed slit 4°">
				<height unit="mm">5.88</height>
			</receivingSlit>
			<detector id="7010017" name="PIXcel3D 1x1 detector" xsi:type="areaDetectorType">
				<phd unit="%">
					<lowerLevel>30.0</lowerLevel>
					<upperLevel>70.0</upperLevel>
				</phd>
				<mode>Scanning</mode>
				<activeChannelsEquatorial>255</activeChannelsEquatorial>
				<activeChannelsAxial>255</activeChannelsAxial>
				<pitchEquatorial unit="mm">0.05500</pitchEquatorial>
				<pitchAxial unit="mm">0.05500</pitchAxial>
				<readOutPeriod unit="seconds">0.135</readOutPeriod>
			</detector>
		</diffractedBeamPath>
		<scan appendNumber="0" mode="Continuous" scanAxis="2Theta-Omega" status="Completed">
			<header>
				<startTimeStamp>2024-10-30T20:17:14+01:00</startTimeStamp>
				<endTimeStamp>2024-10-30T21:13:19+01:00</endTimeStamp>
				<author>
					<name>PRO-MRD</name>
				</author>
				<source>
					<applicationSoftware version="6.1b">Data Collector</applicationSoftware>
					<instrumentControlSoftware version="7.0E 20130304">XPERT-PRO</instrumentControlSoftware>
					<instrumentID>0000000011142674</instrumentID>
				</source>
			</header>
			<dataPoints>
				<positions axis="2Theta" unit="deg">
					<startPosition>9.99826193</startPosition>
					<endPosition>129.99755682</endPosition>
				</positions>
				<positions axis="Omega" unit="deg">
					<startPosition>4.99913096</startPosition>
					<endPosition>64.99877841</endPosition>
				</positions>
				<positions axis="Phi" unit="deg">
					<commonPosition>0.00</commonPosition>
				</positions>
				<positions axis="Chi" unit="deg">
					<commonPosition>0.00</commonPosition>
				</positions>
				<positions axis="X" unit="mm">
					<commonPosition>0.00</commonPosition>
				</positions>
				<positions axis="Y" unit="mm">
					<commonPosition>0.00</commonPosition>
				</positions>
				<positions axis="Z" unit="mm">
					<commonPosition>9.100</commonPosition>
				</positions>
				<commonCountingTime unit="seconds">32.895</commonCountingTime>
				<counts 393 401 376 346 453 380 378 389 361 397 438 373 408 394 408 368 370 374 379 346 397 423 397 348 368 380 404 399 380 417 409 403 405 401 385 368 394 379 401 352 394 394 363 367 361 409 405 361 382 377 403 351 381 394 392 377 397 372 377 396 402 372 407 394 384 344 368 387 369 405 385 373 379 355 389 374 348 382 374 394 413 381 425 404 380 390 363 407 386 384 387 402 357 385 395 385 381 376 404 375 374 357 385 357 389 356 365 374 355 334 399 372 366 352 392 354 344 370 369 378 388 341 361 372 362 337 376 325 362 383 373 361 365 362 359 333 330 374 338 359 374 384 354 399 369 370 308 369 358 371 385 352 340 352 359 380 374 368 329 347 336 371 335 331 367 340 334 398 363 376 362 347 359 375 345 358 346 362 372 392 372 378 348 347 361 346 370 329 339 377 356 344 366 328 347 351 380 372 355 333 364 360 337 344 350 341 328 340 353 338 329 325 384 337 344 332 350 366 351 330 332 335 362 346 337 379 395 328 351 345 348 358 347 360 313 323 357 382 350 337 359 360 329 320 336 330 341 361 366 317 307 360 314 352 332 344 333 353 372 367 328 317 340 366 330 354 320 337 338 348 355 323 291 300 351 303 343 334 309 340 316 351 340 301 319 344 325 335 322 338 330 300 328 338 335 327 325 312 324 328 329 325 311 335 346 319 290 320 345 310 323 316 304 318 312 324 332 366 343 324 320 330 347 326 303 337 318 314 288 333 305 330 351 321 335 330 355 332 306 315 336 307 329 327 324 318 333 312 335 338 332 312 329 304 308 330 301 287 329 330 314 314 316 319 340 298 307 345 313 311 313 302 288 339 325 335 328 319 330 326 308 291 337 294 315 300 320 295 319 328 335 333 322 303 305 335 305 324 333 292 310 315 333 277 308 278 288 345 320 295 310 307 299 290 335 295 320 305 286 302 293 324 318 315 286 308 304 309 302 335 229 324 302 281 312 312 325 301 311 309 285 278 326 304 344 284 283 307 294 308 309 298 289 326 298 302 311 316 324 317 291 325 293 274 302 282 325 321 305 314 330 279 290 302 303 302 306 288 317 311 314 275 319 305 299 307 301 281 305 248 304 314 304 313 298 313 294 288 325 302 297 304 296 321 302 313 264 310 266 289 294 295 307 290 307 312 309 283 289 304 306 322 282 318 318 313 297 305 293 291 274 278 322 323 293 286 313 287 307 302 313 279 295 310 288 277 288 292 275 325 300 264 302 297 314 308 289 321 280 294 302 271 290 282 323 286 273 296 257 302 287 296 278 269 278 266 313 291 305 288 290 307 294 317 297 314 292 285 296 305 292 259 264 257 317 263 302 288 278 281 286 306 280 286 299 304 288 306 303 247 289 258 271 297 279 300 296 278 286 298 276 289 287 280 284 290 296 246 275 266 298 305 287 297 250 283 281 247 301 297 307 284 277 275 236 264 289 287 269 287 301 283 266 257 284 257 283 289 272 263 284 264 309 270 271 272 272 304 290 312 281 274 266 280 303 274 292 276 264 277 299 297 286 322 283 278 286 299 264 278 278 299 307 274 295 299 279 284 278 278 248 301 301 268 283 308 280 292 287 281 296 266 295 278 272 269 293 319 276 248 290 231 258 272 279 307 247 289 315 279 313 295 290 291 270 308 265 288 277 294 289 281 281 307 307 283 291 320 299 275 284 282 297 298 300 291 297 285 277 276 305 258 294 265 287 283 314 268 280 261 299 316 284 279 321 290 298 271 243 296 284 284 303 285 276 284 311 280 263 272 314 281 249 303 302 297 294 319 277 257 279 276 289 266 275 272 260 279 289 278 270 312 303 286 292 274 309 256 271 270 277 289 302 256 289 270 282 295 296 308 285 274 287 277 286 294 276 294 296 279 297 307 273 248 266 289 266 266 263 248 304 280 286 299 283 274 284 261 246 268 287 282 289 237 279 294 267 301 297 280 279 279 266 305 272 276 323 302 295 297 275 290 272 271 263 260 286 304 261 310 318 284 273 285 280 298 277 318 316 306 302 281 271 306 283 273 295 296 289 299 285 294 268 306 267 319 292 306 278 296 284 284 329 303 289 295 299 295 269 308 333 279 313 315 291 288 312 295 275 319 271 296 282 258 278 266 272 266 311 309 284 272 297 297 322 292 302 289 296 295 273 304 277 323 313 286 292 281 300 307 268 328 275 289 305 308 288 293 286 275 304 279 317 306 304 299 360 304 315 281 330 283 289 282 290 323 290 318 273 273 293 310 274 293 289 295 287 342 299 265 284 279 276 295 292 290 285 291 315 305 301 293 313 292 294 305 286 306 285 295 301 339 288 315 298 309 299 316 322 282 313 305 286 324 276 272 321 302 284 294 313 286 287 300 352 293 312 289 307 298 293 284 293 295 316 296 305 322 308 322 337 293 302 287 317 314 297 279 303 294 298 306 300 291 322 321 288 303 269 329 291 284 304 283 298 281 285 315 305 327 331 301 303 301 276 315 301 323 311 325 308 294 316 321 298 262 304 337 292 335 320 265 301 287 295 310 331 281 298 317 299 274 289 301 328 308 316 339 311 313 318 287 340 315 308 317 298 304 317 286 275 330 311 315 333 305 309 314 283 315 305 302 308 313 327 349 299 280 286 324 302 325 297 327 326 275 328 282 318 307 310 302 334 311 335 287 311 295 290 333 337 318 284 338 310 328 317 318 319 319 326 314 284 308 322 314 280 309 318 332 334 316 332 328 293 309 298 334 306 316 323 280 294 312 291 312 307 313 294 277 319 315 347 318 295 310 282 282 282 304 295 336 300 318 317 352 296 322 296 324 283 303 344 302 290 333 328 304 331 322 319 306 315 301 308 304 307 298 304 306 318 307 288 290 313 301 319 296 330 332 292 312 296 319 314 305 320 318 342 284 265 308 310 309 311 323 291 286 313 340 291 332 304 343 313 299 279 307 288 324 304 264 324 293 293 321 282 290 293 287 278 310 304 313 321 331 326 278 298 302 286 327 281 317 314 270 306 288 329 324 305 331 310 306 314 318 342 308 304 310 301 316 298 300 333 315 310 262 307 298 301 331 302 287 306 284 265 297 323 305 320 282 312 319 306 300 288 274 311 313 297 311 298 263 325 277 307 319 316 293 306 313 295 317 273 332 286 296 303 327 278 337 308 305 305 306 283 330 299 305 327 291 292 329 305 305 291 297 327 283 279 291 306 303 335 290 307 314 285 337 257 266 266 309 309 276 309 306 330 329 313 334 286 309 301 309 320 288 284 303 327 346 310 304 268 311 274 309 289 295 289 282 308 309 318 307 303 280 322 289 296 316 292 309 294 285 294 300 296 298 310 281 333 278 283 306 319 303 282 288 305 298 293 331 295 308 274 255 273 296 291 330 301 281 323 309 314 306 320 297 310 305 283 291 278 301 302 315 318 301 302 314 298 300 332 340 310 300 295 286 294 295 278 298 296 303 288 308 304 276 312 318 308 306 316 285 259 300 302 288 308 285 284 290 306 289 281 298 298 332 307 281 302 318 291 333 291 292 292 291 292 292 274 285 291 285 267 293 297 287 301 305 270 316 262 274 293 269 286 319 309 300 306 312 316 282 264 286 287 304 309 276 285 303 272 331 298 283 319 295 289 291 276 268 312 300 296 287 290 289 290 296 259 247 291 276 302 283 277 282 311 324 256 275 288 289 270 293 259 259 303 309 284 299 295 270 311 304 291 285 273 288 265 273 274 287 261 291 292 277 311 291 300 313 256 305 295 284 299 302 281 282 272 265 315 308 271 318 263 326 264 267 284 287 266 287 261 301 286 280 301 299 294 255 284 315 301 288 275 275 333 307 306 276 273 250 276 292 292 290 320 330 294 301 265 264 286 275 278 283 266 272 289 249 288 282 293 219 268 275 272 305 309 280 335 245 271 242 288 292 270 315 284 299 303 287 292 294 290 283 265 265 284 283 302 293 281 270 237 281 292 289 296 273 282 286 259 261 302 261 289 293 292 290 266 313 271 292 308 269 293 282 260 257 315 257 276 279 232 284 305 296 278 285 282 274 290 295 270 255 287 277 264 269 267 267 283 292 255 279 271 270 266 268 270 248 285 287 264 249 274 309 288 272 272 264 248 258 261 282 265 249 299 282 235 277 263 290 280 256 255 267 226 271 234 248 278 262 284 302 286 275 272 248 266 280 269 272 258 236 275 307 248 283 267 278 248 276 255 290 282 268 270 249 267 271 268 287 284 282 268 261 290 249 268 257 267 277 270 241 280 264 284 266 259 301 277 248 280 249 283 295 244 237 239 269 267 291 243 301 272 266 255 247 282 262 272 281 289 236 275 259 273 267 256 294 278 266 291 277 261 289 268 235 245 257 265 216 274 245 282 274 280 295 249 281 235 263 267 239 275 262 233 283 275 255 257 293 285 277 273 262 273 246 307 261 258 264 246 255 228 262 276 267 259 317 263 280 256 271 238 246 256 239 258 269 277 278 262 281 236 263 250 265 236 256 275 257 233 268 275 286 275 234 236 266 302 249 273 277 246 227 256 234 257 280 259 275 269 236 281 284 243 240 271 265 255 243 247 248 240 240 284 282 239 288 263 268 229 245 236 247 296 281 279 282 259 261 286 275 275 225 243 255 246 235 265 259 258 274 264 265 260 239 220 277 256 240 241 281 294 216 263 258 259 256 241 205 272 258 289 248 276 242 230 279 271 278 269 249 236 247 300 294 237 276 255 294 278 230 261 280 243 256 264 283 238 267 245 257 237 266 297 309 266 292 223 267 242 264 286 267 241 283 264 282 242 272 258 278 285 260 272 280 239 278 282 246 292 266 235 273 274 289 242 274 278 276 274 245 244 266 242 261 279 262 257 274 247 283 256 269 242 255 288 242 270 268 277 262 260 229 241 249 244 261 240 264 258 264 241 277 248 266 283 289 274 260 263 293 262 275 276 257 259 246 263 249 284 276 249 239 246 221 242 262 241 238 274 267 269 248 268 258 257 259 258 230 264 257 230 243 230 245 260 226 265 284 227 242 257 270 242 267 230 284 226 268 279 275 266 239 271 256 230 229 283 274 263 258 260 245 269 255 275 243 273 289 276 268 241 240 245 262 261 244 278 260 245 261 260 228 232 266 259 261 238 278 268 241 249 260 265 272 261 284 247 265 291 275 266 261 234 238 292 240 283 291 243 239 243 239 246 247 233 229 247 269 277 243 247 245 256 256 235 285 277 274 281 263 263 234 232 258 260 277 262 279 261 237 215 246 247 231 236 256 256 278 268 230 259 239 247 269 234 282 266 247 235 241 245 294 246 258 249 264 273 271 269 228 274 245 265 261 273 260 255 241 245 267 259 261 232 244 265 242 262 255 229 241 249 258 223 232 246 280 259 249 263 238 255 261 234 244 278 249 239 239 264 235 244 232 237 230 248 255 245 267 229 246 277 217 246 262 247 242 267 247 260 234 285 258 247 231 246 264 232 266 244 255 245 241 248 272 242 243 224 260 272 241 241 259 272 247 238 239 268 207 232 280 287 268 211 277 227 246 227 242 243 260 220 228 225 256 264 227 244 268 248 229 265 241 239 248 271 262 240 237 237 226 268 226 265 266 283 282 229 262 234 235 276 282 246 243 249 226 235 236 269 271 242 250 263 263 278 246 256 263 224 245 261 235 258 243 241 289 263 239 247 270 248 266 239 231 272 243 248 211 235 262 282 239 235 266 245 241 223 235 250 211 232 243 282 221 244 239 247 257 270 257 230 228 226 232 245 230 238 242 249 271 245 243 266 220 260 279 284 231 266 255 260 246 269 257 259 237 269 241 263 260 246 270 237 238 247 289 267 257 263 270 281 224 277 219 277 247 261 260 260 264 268 244 255 257 264 249 247 241 266 257 258 261 270 256 248 237 261 257 234 264 239 222 245 247 248 256 267 256 258 216 246 259 234 264 224 269 226 227 284 223 229 264 249 240 231 237 259 241 234 247 276 260 266 249 241 230 234 263 267 232 240 243 242 233 259 237 242 244 272 271 245 240 267 242 247 300 265 265 261 260 293 265 270 240 248 276 248 245 232 241 270 248 270 234 228 258 267 236 270 246 232 260 239 259 246 262 276 267 268 257 293 226 266 277 270 266 231 231 233 280 247 244 261 248 238 259 213 258 270 249 273 238 248 241 221 231 240 263 266 273 246 250 237 264 259 242 260 283 250 283 246 250 264 239 240 249 240 235 261 281 271 268 240 235 258 237 241 225 262 249 257 299 276 224 247 258 270 257 214 232 237 231 266 249 242 258 266 255 228 257 247 244 261 230 262 272 232 260 279 262 256 249 271 234 243 276 244 246 242 273 263 260 255 244 257 268 260 266 257 219 260 278 265 281 259 285 230 261 220 277 239 246 243 225 285 274 260 237 219 232 268 225 267 272 246 277 259 259 239 240 256 239 228 239 233 247 256 257 261 221 266 259 271 246 263 234 260 244 262 287 233 236 239 262 230 260 256 223 250 235 261 256 242 287 261 250 265 263 250 258 262 221 236 267 243 262 242 227 256 261 234 245 247 266 238 236 262 236 227 264 229 246 232 256 269 247 271 237 222 255 262 238 245 256 257 244 213 257 264 259 238 245 259 281 216 263 225 237 245 275 243 270 263 242 270 274 261 236 228 297 248 277 274 264 233 264 259 258 238 249 238 243 255 261 290 268 239 248 236 245 263 263 238 269 268 242 284 257 274 224 241 264 246 249 267 266 238 266 238 286 226 273 266 244 293 265 290 258 235 232 258 268 239 262 279 268 264 236 237 261 260 223 235 271 267 278 240 256 219 256 243 259 272 270 278 262 237 247 256 244 282 256 244 259 297 284 235 279 242 243 273 260 264 288 261 266 264 222 272 286 250 272 230 273 259 255 240 260 261 256 283 248 264 263 259 241 272 243 281 247 242 263 268 228 258 237 271 264 278 269 260 250 258 240 255 269 226 291 277 258 266 248 266 265 230 260 235 258 240 270 256 257 259 259 262 242 270 262 279 248 236 221 279 249 268 259 249 247 256 276 286 280 265 239 221 256 262 247 249 284 282 256 257 262 272 237 245 269 236 259 238 265 242 245 265 250 233 266 271 258 248 277 261 266 237 247 261 257 271 232 269 271 265 269 276 272 240 256 270 266 282 297 299 237 250 247 270 296 249 256 240 265 248 234 276 264 272 267 243 294 259 236 282 291 247 260 249 230 264 269 232 238 243 263 219 264 250 267 267 268 237 263 245 265 221 267 285 272 277 275 263 243 213 239 228 243 241 235 248 275 258 258 261 261 244 241 247 248 229 262 294 262 219 255 284 239 239 278 241 293 258 269 283 260 247 260 258 302 264 244 268 245 262 247 241 260 267 230 261 272 259 243 259 237 256 259 245 246 272 259 272 271 263 282 266 276 272 245 238 247 260 231 237 277 272 262 271 262 256 262 271 238 243 263 267 296 277 265 261 275 265 237 260 260 239 258 249 268 246 279 236 272 234 255 298 238 268 290 249 266 244 226 238 259 222 222 261 263 271 229 270 248 256 262 260 308 257 289 243 259 257 283 261 256 245 274 288 249 268 279 263 261 259 260 260 280 270 258 290 249 238 259 248 228 274 260 294 274 258 255 264 223 281 270 264 274 284 266 238 263 288 279 277 300 279 249 270 268 261 275 260 269 280 270 268 271 272 284 289 277 284 256 281 273 276 296 285 278 270 265 283 300 306 271 287 320 303 290 273 287 275 304 296 300 297 304 278 279 316 304 266 299 268 314 314 350 335 336 303 321 318 361 315 324 310 350 332 324 325 344 367 326 338 390 367 383 391 406 398 410 446 433 429 472 439 490 498 499 474 523 492 532 533 488 498 482 517 527 542 511 528 455 452 452 464 496 477 435 383 402 385 441 412 384 402 382 354 373 345 366 319 383 328 362 350 333 290 337 307 311 307 295 287 298 290 291 272 276 269 316 265 315 300 287 277 274 307 287 306 263 264 267 291 268 279 274 275 304 289 239 280 262 279 282 265 264 272 244 293 233 239 266 263 264 262 278 284 257 312 280 260 284 278 280 255 293 258 261 269 275 276 313 242 264 259 296 262 293 276 244 285 263 291 262 279 280 271 286 281 244 267 261 262 256 267 268 285 266 291 265 262 249 272 286 285 275 212 281 262 265 281 237 268 298 260 265 284 291 265 263 255 270 275 229 262 249 269 272 268 268 257 279 259 260 275 268 259 276 231 244 239 269 255 282 220 285 271 262 268 260 269 278 240 264 241 258 241 245 243 308 271 259 263 284 280 287 270 259 258 279 258 306 249 260 237 258 238 236 243 278 264 244 257 257 282 272 230 256 235 239 245 284 262 266 231 212 229 247 248 247 305 269 258 300 246 263 268 289 272 226 265 248 235 249 239 270 234 264 276 276 266 278 247 283 227 270 249 266 285 234 243 227 280 260 266 255 274 290 270 255 290 264 280 284 247 260 236 244 263 278 235 268 286 277 279 256 248 281 266 264 257 248 279 224 272 276 230 246 265 263 238 246 248 245 260 261 266 282 260 288 247 242 264 228 278 262 283 265 267 309 287 295 260 263 244 263 259 278 271 261 255 264 262 256 288 271 282 244 264 227 240 280 227 262 270 240 237 241 214 239 241 269 246 249 248 270 275 241 289 249 262 280 244 280 269 281 265 265 273 266 261 246 249 238 258 271 276 226 267 267 271 257 295 265 303 239 261 262 265 241 248 244 248 265 274 243 273 244 259 273 276 275 270 228 260 265 248 294 256 228 269 249 271 280 282 225 225 267 256 269 257 270 265 274 259 242 261 264 295 278 273 216 268 243 265 244 280 272 244 257 265 267 245 240 294 265 234 240 274 288 243 230 235 237 274 269 262 237 264 308 222 282 230 226 236 256 258 258 229 264 234 279 266 219 256 245 261 257 271 300 249 257 261 246 258 268 267 260 270 239 267 260 300 272 237 231 245 264 264 280 282 287 233 277 270 270 250 232 268 233 245 260 249 268 261 243 240 264 269 248 275 282 247 275 260 267 267 268 230 235 277 235 269 244 275 259 241 296 290 277 263 291 262 261 271 261 237 274 259 266 235 241 271 248 245 260 265 245 239 249 278 237 245 248 232 238 271 257 264 247 261 242 241 261 238 279 239 259 233 268 283 234 280 237 265 269 262 248 250 230 267 255 256 268 264 246 281 256 269 227 275 256 305 265 242 265 265 232 279 246 246 260 256 224 260 258 222 283 249 260 243 257 276 238 227 280 267 238 247 291 239 273 258 231 268 298 261 269 247 257 266 244 243 259 257 257 280 224 287 241 270 256 266 284 275 265 267 268 273 274 233 262 247 278 248 282 248 259 240 289 240 257 257 281 260 268 271 242 264 271 247 227 245 262 267 245 259 256 268 267 231 286 233 236 236 291 265 224 233 240 231 243 244 265 261 237 284 262 281 270 248 247 249 242 228 242 272 272 242 234 248 219 278 243 257 284 283 237 264 285 256 279 275 264 242 271 265 257 232 283 275 261 226 284 269 258 238 259 238 256 267 248 262 260 255 270 269 255 223 267 262 264 255 231 246 278 267 276 270 273 281 246 241 262 231 262 285 264 261 245 237 259 275 274 272 277 282 239 268 276 268 267 256 281 286 214 230 294 226 242 259 258 275 292 282 278 232 248 263 283 288 267 220 265 238 269 242 285 295 248 272 241 265 275 281 269 282 276 264 272 243 261 256 269 267 291 284 263 273 268 257 271 260 270 267 273 271 274 286 263 247 279 239 288 247 261 240 302 272 263 239 245 267 247 271 244 259 258 226 262 258 256 276 278 272 235 266 257 259 246 266 249 230 285 228 263 245 271 263 286 243 268 263 236 268 233 255 247 285 257 255 269 248 246 249 262 268 245 272 241 226 266 265 256 270 269 263 272 235 262 275 259 282 266 287 242 234 243 277 270 271 271 268 257 245 245 234 279 267 235 264 263 295 270 272 234 277 293 248 246 259 262 247 269 259 279 265 294 273 256 283 247 285 262 247 273 280 276 282 305 260 258 291 260 229 283 276 267 290 246 273 265 261 248 238 283 273 240 247 245 285 276 270 259 271 258 282 249 259 249 248 243 234 278 282 264 229 265 224 263 294 282 261 270 267 282 248 284 255 257 231 284 270 264 258 229 258 257 257 241 278 250 243 280 276 245 276 268 292 230 275 279 267 283 267 225 295 263 244 263 240 232 269 265 230 240 223 244 245 259 258 243 237 258 269 232 206 286 247 248 242 271 264 261 237 241 243 267 255 243 294 232 262 259 246 244 243 269 268 255 277 274 275 250 268 248 287 258 278 243 265 266 258 292 258 274 267 233 291 259 278 266 247 292 279 260 316 277 280 258 278 268 277 235 258 287 269 241 233 270 250 262 266 273 232 272 241 265 230 277 274 246 232 267 292 263 271 245 283 244 295 293 235 241 240 289 268 269 265 237 286 272 245 228 290 264 268 236 279 242 255 243 265 273 270 250 240 237 250 265 238 260 269 239 247 245 248 249 270 266 237 262 278 266 287 264 261 233 256 232 262 259 260 249 233 266 248 288 255 280 275 281 273 260 301 260 296 221 270 274 248 246 290 281 291 259 268 266 242 262 247 235 267 268 272 292 249 271 285 249 249 270 235 235 236 277 242 280 264 229 268 245 245 263 240 237 273 274 255 265 269 270 241 266 280 274 257 269 262 232 236 294 268 269 267 281 232 275 273 258 304 248 264 248 255 259 257 240 279 256 263 270 258 282 255 249 235 269 284 278 266 270 241 256 276 265 302 278 287 264 277 269 244 278 262 273 288 287 244 236 278 260 273 262 272 284 274 239 245 257 293 284 271 262 266 270 240 255 260 278 286 258 279 267 259 242 255 280 267 244 263 268 265 256 257 260 297 264 277 258 272 271 262 284 264 290 247 248 264 261 263 281 297 271 245 264 241 268 289 269 262 276 241 273 286 265 271 255 286 258 272 284 257 258 285 286 245 283 272 267 277 283 285 267 260 256 268 234 256 261 244 281 274 264 274 261 283 241 271 248 282 279 273 265 269 277 262 266 242 281 268 269 280 231 273 263 259 280 242 241 276 269 230 260 269 226 277 240 264 273 246 283 249 275 264 263 264 271 273 242 248 273 239 295 251 245 240 267 301 264 267 223 259 266 236 267 255 245 264 256 245 250 279 288 287 248 290 265 260 258 261 268 240 232 265 245 277 241 261 243 277 242 237 255 278 299 257 237 262 248 260 272 248 272 266 264 260 259 309 264 231 291 259 266 248 237 265 236 292 298 258 258 273 272 226 243 267 290 274 279 261 262 271 246 270 266 234 248 258 224 272 298 262 260 270 268 264 291 266 284 269 243 240 290 261 273 269 276 274 267 263 272 225 283 263 233 260 266 274 258 278 280 268 276 275 258 257 270 250 256 248 279 257 271 271 270 273 247 268 277 256 279 266 248 236 300 267 259 217 280 291 267 275 258 240 284 266 277 289 256 248 279 261 240 247 290 282 242 230 258 292 287 286 286 238 271 232 280 285 247 236 287 279 285 271 272 276 267 281 261 300 268 281 238 246 244 268 278 262 267 268 231 257 247 281 274 267 261 263 283 263 221 265 269 266 266 235 295 258 293 256 241 273 243 276 278 266 280 258 266 258 249 259 293 270 263 240 261 278 265 271 260 274 246 255 278 273 222 242 282 256 292 267 271 274 246 212 284 278 231 230 236 258 264 290 299 287 262 271 282 243 255 301 270 269 293 241 262 302 269 298 268 271 276 264 269 295 280 273 263 261 280 295 255 235 220 268 265 267 259 260 235 247 290 256 277 280 242 269 269 296 280 261 250 261 248 262 257 255 245 267 271 280 272 284 285 277 287 282 267 245 267 271 263 261 260 238 262 258 279 270 263 273 279 284 284 277 270 271 303 272 261 272 277 278 256 282 278 264 245 280 267 268 273 267 222 261 281 263 278 272 255 270 246 265 257 301 246 260 268 257 293 234 294 280 276 260 273 283 277 242 238 242 263 295 257 262 262 276 262 293 266 242 264 244 270 267 263 248 273 263 284 265 239 304 273 266 294 279 293 238 246 263 270 243 291 245 277 249 273 275 248 263 246 260 243 273 247 275 302 226 247 290 271 260 263 249 272 285 241 260 274 287 260 282 271 280 265 257 277 292 277 273 268 287 277 241 292 245 257 262 284 244 274 272 259 279 264 276 236 269 242 242 291 283 291 270 289 260 274 298 236 247 261 275 274 263 278 273 294 282 272 247 265 259 299 274 287 236 277 224 237 246 261 263 286 260 275 277 266 280 285 275 267 281 259 330 307 299 269 282 280 241 259 290 298 255 263 292 248 239 283 277 273 236 295 271 264 272 292 255 281 286 273 279 281 245 298 270 281 290 274 299 283 298 268 318 291 267 285 303 259 264 271 293 279 278 230 274 276 299 296 277 303 292 272 261 267 304 322 293 312 263 274 283 263 306 278 327 298 268 299 294 337 282 265 289 268 281 337 330 324 281 295 304 292 271 294 302 307 289 273 277 292 291 260 285 276 297 290 296 307 305 279 309 279 262 271 278 266 275 286 283 306 280 282 282 290 289 265 277 264 271 291 262 294 298 241 264 289 269 285 283 288 262 275 245 245 323 288 263 318 283 286 257 276 241 308 287 266 288 297 274 265 291 248 270 261 289 264 281 256 278 293 292 264 294 268 268 257 241 279 263 283 271 298 274 256 281 233 279 299 289 282 307 275 259 265 274 271 264 280 259 274 284 239 300 291 293 274 270 275 287 300 281 260 262 262 258 290 294 270 260 269 258 261 267 289 287 280 245 239 243 260 262 265 284 302 280 286 249 277 268 295 259 279 285 282 294 281 297 296 272 289 246 278 282 266 276 279 282 276 272 267 250 248 298 285 262 279 308 275 309 258 295 267 249 312 273 298 267 242 302 263 257 302 275 272 291 261 266 242 279 265 319 277 278 287 264 296 271 291 281 256 289 299 291 249 306 243 278 282 273 271 290 293 291 278 264 296 258 273 269 296 271 295 291 262 276 273 303 287 271 312 260 257 290 283 236 279 265 270 259 257 278 271 270 285 261 263 288 286 294 307 275 246 266 285 270 285 279 296 286 274 302 248 286 249 268 276 285 318 268 261 250 279 246 285 273 297 315 279 260 317 293 249 271 271 246 267 304 245 262 247 258 271 271 249 261 262 280 234 287 255 316 236 281 281 269 268 278 261 267 262 292 300 282 272 282 281 270 279 286 268 280 255 294 288 283 272 272 292 288 265 292 275 264 273 291 281 256 289 302 302 278 259 270 265 299 295 261 320 273 269 294 301 260 280 269 239 265 271 296 258 269 278 285 256 259 274 261 300 301 314 278 280 260 295 284 266 272 287 247 267 261 283 263 292 300 271 283 275 265 297 272 256 274 257 277 292 263 269 296 259 288 282 287 293 285 277 250 276 296 266 272 277 274 278 319 268 305 265 270 270 275 285 271 292 274 292 280 293 247 284 289 257 328 241 266 286 269 260 267 300 278 289 298 272 289 260 285 292 270 276 266 270 246 302 256 282 260 275 265 278 266 295 308 269 266 268 267 289 269 268 280 237 270 263 281 264 296 294 266 290 290 278 273 288 274 305 242 289 269 271 255 284 308 266 263 309 304 300 279 283 265 282 261 260 247 291 267 261 258 289 294 286 259 297 258 304 292 259 298 296 303 272 292 288 261 295 278 287 259 269 264 259 278 260 263 295 311 286 288 270 255 283 276 294 279 275 280 240 247 257 261 262 263 260 266 265 257 283 245 282 286 278 271 274 247 278 294 268 247 286 316 261 283 313 276 300 259 267 258 293 298 266 261 274 244 276 271 291 273 239 270 256 293 290 275 272 275 262 246 287 290 243 288 232 280 271 268 266 269 298 242 271 256 266 244 287 309 267 276 270 294 299 241 285 265 282 259 285 269 285 294 275 236 272 257 292 264 280 256 264 285 243 272 279 273 255 247 270 294 269 280 280 264 287 256 256 264 256 297 300 246 275 276 264 271 266 291 280 285 237 271 247 239 270 266 263 286 265 281 257 257 281 267 279 301 262 239 282 279 287 273 293 270 262 268 273 279 248 257 291 260 273 268 286 292 285 291 248 304 238 269 259 266 243 280 262 296 266 248 274 262 300 270 267 279 280 270 289 297 268 292 291 246 266 257 265 268 307 303 301 283 264 246 268 286 271 276 241 271 292 289 265 258 305 264 295 281 290 299 280 278 306 257 258 265 274 279 278 279 285 263 291 275 258 281 269 287 260 272 288 283 297 261 296 268 279 223 277 257 263 265 275 275 266 296 274 271 275 271 279 266 257 272 263 284 301 272 224 295 279 261 268 283 286 246 314 250 248 283 279 266 290 278 285 266 273 260 265 280 269 244 257 245 284 240 263 266 243 266 273 269 295 265 240 286 283 308 295 311 238 276 279 242 262 279 285 280 226 231 277 279 284 261 311 246 287 248 286 285 264 267 282 296 241 266 294 261 261 261 248 288 288 233 243 269 277 270 275 272 283 239 277 270 291 282 249 250 276 268 256 269 257 255 273 294 272 262 276 290 261 290 289 258 276 263 273 263 269 267 277 278 270 272 264 264 259 255 278 265 272 263 271 284 258 258 247 261 260 291 284 276 281 259 288 275 265 274 278 269 275 275 242 277 256 295 299 274 283 255 282 248 237 263 298 282 265 241 311 293 265 257 245 327 282 260 270 300 282 307 279 260 270 261 241 271 268 300 280 266 261 244 271 267 257 283 282 283 289 273 267 284 285 279 297 269 266 267 262 257 273 277 295 297 315 289 279 270 276 269 294 281 283 263 278 277 283 326 268 288 255 231 273 285 304 242 313 282 286 267 296 259 279 267 305 288 257 291 268 243 268 277 270 289 277 263 279 276 289 320 259 294 249 309 268 255 275 280 311 270 304 249 280 255 323 267 284 304 278 263 292 297 281 285 270 297 261 285 278 272 294 273 295 267 266 265 294 264 258 291 274 288 275 255 240 239 302 263 271 265 287 282 289 266 266 260 278 274 273 272 300 270 282 273 293 287 275 284 282 296 261 278 286 276 260 292 269 256 285 292 267 271 244 296 285 311 264 288 280 262 288 308 268 290 277 285 278 291 286 242 258 294 257 273 272 273 299 276 247 273 304 255 275 296 265 263 290 281 258 272 297 248 247 280 240 261 278 273 266 264 270 291 270 288 271 280 271 292 293 276 270 266 295 247 267 245 279 265 259 275 235 290 280 278 277 255 256 276 245 263 256 283 275 283 269 246 265 288 278 293 260 304 280 293 294 277 271 291 271 297 282 268 276 271 269 285 278 317 266 269 297 277 299 262 269 293 264 276 233 279 279 315 263 313 268 266 283 273 280 266 236 292 320 280 302 268 234 296 265 276 269 295 284 273 283 276 285 242 264 274 273 238 259 278 277 285 281 302 286 229 291 275 265 304 303 246 256 258 236 291 265 287 276 238 305 292 271 261 286 271 312 272 258 290 282 275 262 247 265 261 282 236 278 263 259 304 283 295 275 312 258 281 264 294 282 277 295 290 264 267 277 255 292 293 248 272 306 300 265 273 297 246 261 266 265 304 274 281 266 232 304 290 269 281 291 240 263 282 266 279 264 262 260 290 270 264 312 293 281 297 310 278 276 276 289 279 284 305 263 260 288 266 273 290 267 263 305 259 262 270 274 275 305 274 290 246 257 269 273 285 288 276 258 268 294 280 299 262 238 292 235 264 267 245 273 283 281 290 283 256 309 280 270 237 229 259 313 277 296 275 264 274 280 278 242 271 265 297 281 281 241 286 267 284 305 242 286 235 274 274 314 265 319 232 271 283 287 280 279 276 272 262 266 274 286 247 240 249 266 287 281 282 267 286 268 286 306 270 297 289 289 269 212 288 264 277 265 265 300 285 261 271 274 270 289 275 279 259 272 267 268 276 244 276 263 255 281 285 278 242 268 291 280 298 261 250 265 236 278 265 258 264 271 290 275 267 272 274 276 264 281 273 277 304 266 280 276 280 284 275 279 260 278 293 258 288 276 274 297 259 286 293 238 276 284 238 276 293 261 268 276 265 258 278 293 286 277 269 275 318 273 268 270 262 311 265 265 265 262 263 260 276 267 282 287 261 261 281 291 257 272 274 299 266 239 276 290 255 280 283 289 263 288 266 231 271 295 298 276 273 242 298 268 248 275 268 275 297 309 277 298 259 270 321 243 265 305 297 295 280 264 272 308 295 286 301 277 300 287 304 283 274 257 288 305 288 280 267 285 292 263 297 259 279 310 263 287 265 292 297 271 266 285 262 261 277 304 280 307 273 290 276 298 274 289 268 290 313 280 256 272 292 259 296 273 283 285 289 309 303 266 287 262 303 290 270 280 305 302 256 302 309 315 315 342 311 283 329 291 308 302 336 302 287 291 315 284 308 288 306 334 302 299 310 320 337 347 324 324 303 311 302 316 313 334 336 341 309 295 309 314 314 320 333 289 308 306 299 318 326 315 283 302 327 349 324 334 363 295 265 312 311 305 266 301 296 301 306 302 270 303 319 305 275 280 295 279 298 304 273 267 285 268 271 268 281 266 268 291 315 250 270 275 250 331 261 296 278 279 304 246 246 286 256 300 264 282 307 257 290 290 303 277 297 278 291 296 250 276 303 302 278 243 226 242 291 297 268 242 295 248 274 256 290 264 238 284 274 282 278 283 265 270 274 266 255 281 249 282 246 272 276 266 240 262 272 282 294 262 271 260 246 268 272 258 260 268 265 272 274 303 268 263 278 264 256 265 258 272 267 259 268 314 268 267 262 286 299 298 281 257 267 238 278 263 270 283 277 275 276 283 282 244 273 308 255 305 277 248 277 269 258 270 257 278 276 281 270 259 262 231 263 268 309 283 258 280 258 293 280 263 270 249 271 282 237 277 266 259 299 297 281 256 293 285 265 277 258 269 258 294 242 297 274 264 263 274 285 278 305 255 245 299 282 293 241 291 283 271 244 258 276 276 260 266 235 257 301 263 273 255 275 261 292 247 258 275 298 278 245 289 281 286 283 246 272 263 275 290 263 278 243 279 301 259 278 284 295 263 275 261 279 293 264 258 281 302 278 268 256 316 273 258 284 258 284 250 273 248 268 245 266 289 269 258 273 285 241 258 269 276 306 223 295 277 287 241 281 276 287 242 249 265 258 262 287 246 292 301 280 269 281 255 306 279 232 261 289 273 259 264 255 285 256 265 270 255 278 265 289 235 277 267 288 289 267 244 269 262 269 269 260 246 268 240 272 264 247 257 245 264 274 281 258 275 268 263 276 261 271 258 276 304 280 303 283 235 238 263 268 276 256 247 267 279 241 267 288 275 274 271 277 238 283 258 231 257 246 273 290 267 240 257 261 268 256 258 241 275 258 280 275 285 261 283 277 222 279 280 266 279 267 233 266 247 276 241 265 273 272 267 297 269 269 288 268 267 260 249 269 239 264 256 289 271 283 283 282 286 285 317 265 295 272 258 271 289 292 278 271 296 264 231 246 269 287 275 259 266 305 241 238 268 260 272 243 278 284 258 238 286 276 260 270 247 246 245 255 266 264 278 280 286 279 258 266 256 269 267 301 267 267 265 247 275 301 267 261 267 276 239 280 279 237 279 237 304 239 277 263 285 263 257 267 256 284 276 245 270 285 281 279 262 271 272 276 264 275 255 279 260 255 233 272 278 278 256 245 282 266 258 278 258 283 239 267 279 263 236 276 220 287 256 287 282 240 256 257 276 263 261 261 263 249 292 241 291 273 268 274 266 229 291 294 245 271 273 233 283 246 268 238 247 289 262 225 271 267 242 266 267 266 270 280 272 273 264 256 262 263 281 272 285 278 244 266 268 266 261 260 285 228 273 221 268 262 288 255 289 268 279 233 268 264 274 258 283 258 282 259 269 255 256 270 275 281 221 297 256 266 244 250 258 238 256 272 264 276 238 278 285 218 290 281 292 280 260 231 260 235 291 259 274 268 265 270 268 297 287 240 293 241 287 285 262 270 269 285 261 261 255 271 274 266 295 272 238 290 282 250 247 281 256 272 244 280 263 294 291 280 270 281 271 296 272 268 279 255 275 260 288 258 261 245 277 282 260 272 241 247 281 265 257 267 265 241 288 287 277 303 256 240 287 292 261 264 278 245 266 274 288 257 259 284 284 280 237 262 284 260 260 240 326 262 270 292 259 283 269 249 271 293 266 248 272 280 274 280 302 273 277 274 260 276 280 243 239 262 281 298 297 249 286 266 296 291 268 275 234 260 276 266 285 274 260 268 258 262 274 292 288 243 278 280 278 274 266 284 250 272 274 226 272 283 234 287 260 293 239 263 270 249 243 258 267 269 261 245 270 245 269 249 240 249 278 247 276 266 279 259 261 265 293 293 304 286 288 278 247 275 250 222 243 272 274 296 290 263 222 275 263 258 287 262 275 268 269 272 295 245 282 261 260 222 285 295 285 264 266 278 268 244 292 249 235 243 263 273 217 291 301 293 283 240 282 285 268 260 302 279 278 286 258 291 269 273 289 290 260 278 274 280 296 242 263 266 240 269 271 270 290 272 261 271 255 288 269 262 255 268 263 275 262 242 238 270 273 262 269 277 307 276 282 274 264 271 262 295 278 287 270 249 272 297 278 249 277 265 284 271 295 271 248 248 271 226 265 266 284 260 263 258 275 261 269 275 250 286 274 266 286 275 294 268 265 261 286 255 304 235 245 257 238 243 293 275 259 267 273 260 278 244 267 286 268 260 293 257 265 257 262 273 246 255 266 267 248 266 271 259 259 279 293 280 296 249 278 278 261 261 259 284 298 257 238 294 262 280 279 281 270 284 286 310 258 269 276 274 263 288 271 274 263 276 239 282 274 269 255 245 300 226 280 261 273 234 272 266 269 268 278 283 230 291 286 237 249 264 272 279 268 297 266 314 256 272 298 286 274 258 291 284 266 290 268 287 272 268 255 232 307 283 272 245 270 280 236 280 287 263 281 263 301 278 247 269 257 243 270 269 273 261 246 296 222 260 266 282 241 232 255 268 267 266 268 269 269 275 277 275 250 303 274 262 264 281 260 268 303 300 242 293 260 275 279 312 260 268 261 275 240 290 287 279 273 281 255 262 261 263 250 270 302 243 264 255 299 263 279 267 283 261 269 266 259 263 274 256 258 285 268 302 258 255 269 273 277 265 257 259 277 271 305 232 257 277 234 243 266 284 284 263 271 263 276 244 281 307 259 262 281 266 307 276 280 261 281 262 264 238 243 259 258 275 286 293 228 258 292 228 264 280 264 289 275 262 298 277 249 259 244 278 266 276 302 259 261 266 230 280 259 268 275 304 266 262 261 286 274 303 264 271 270 292 263 224 261 288 243 267 259 264 261 275 242 268 258 275 278 259 270 261 249 272 268 243 279 246 272 284 300 267 264 274 271 273 255 277 283 259 229 276 275 264 271 270 256 260 246 274 273 238 247 276 294 264 321 267 279 231 269 246 272 264 262 258 272 276 259 240 265 300 249 262 281 273 266 239 279 282 279 238 265 276 271 288 269 242 278 284 264 269 273 278 276 277 295 271 278 229 262 248 276 242 285 278 235 260 283 277 270 269 261 279 249 287 284 255 267 278 268 273 245 258 225 272 240 269 287 265 274 247 259 284 275 220 233 243 266 243 268 240 267 261 255 276 282 288 261 268 245 250 270 260 285 241 273 259 241 290 260 271 295 284 261 280 262 269 287 239 225 246 260 266 246 262 259 262 287 243 275 263 283 272 302 235 306 262 260 268 247 315 245 247 274 279 258 250 303 269 265 261 269 278 277 275 280 273 268 257 255 248 283 284 259 277 263 262 237 261 276 279 270 224 286 249 249 257 244 270 291 276 269 279 265 255 266 257 300 270 283 224 287 266 270 279 284 273 263 267 232 285 302 260 300 260 245 291 276 299 302 272 269 273 277 271 277 275 269 268 274 297 299 263 266 267 256 228 242 249 279 242 267 265 262 279 277 276 270 303 273 247 229 242 275 269 262 268 271 277 283 247 275 272 265 258 281 249 256 273 256 258 273 259 269 258 286 309 288 264 282 276 257 265 247 259 278 285 282 265 293 283 263 280 275 303 284 284 299 282 219 265 260 244 279 259 278 268 313 246 296 284 244 290 294 271 292 275 260 259 267 245 278 283 305 263 295 267 256 268 266 290 268 296 290 277 292 243 275 280 261 259 284 285 297 270 259 301 294 260 263 300 272 280 287 293 300 293 299 287 285 308 278 276 259 259 301 267 296 286 306 271 302 267 293 278 288 293 276 301 290 278 275 274 295 281 303 273 256 280 273 289 291 293 277 260 284 273 277 284 265 261 255 279 310 288 288 278 266 296 279 288 285 269 292 284 278 288 288 313 264 316 258 295 280 266 280 302 260 291 271 273 284 285 257 290 291 292 285 278 280 296 280 243 280 302 278 276 300 284 257 288 256 264 285 290 300 295 290 249 256 281 257 262 269 273 298 264 293 283 265 286 269 293 282 265 277 259 311 283 249 260 272 256 246 298 261 266 257 289 286 289 271 278 283 246 263 274 246 296 258 275 295 291 237 270 287 268 294 290 245 290 281 285 307 271 281 255 269 260 288 229 232 260 267 294 281 280 246 261 300 262 256 264 294 301 287 286 261 293 299 285 276 314 289 275 275 295 295 285 265 284 274 300 240 274 288 274 248 282 273 263 290 280 243 291 296 270 312 262 289 268 278 281 306 255 269 256 264 257 242 276 259 276 283 284 249 266 264 285 295 257 266 302 277 276 257 295 295 266 249 274 275 246 255 281 286 258 283 291 279 261 237 297 259 281 264 291 286 277 266 245 278 255 268 241 262 282 247 271 279 263 264 271 277 277 275 271 269 241 270 274 263 283 258 240 260 269 280 291 250 297 262 276 285 286 285 288 284 276 276 265 290 285 266 271 303 283 275 288 297 297 294 270 270 247 261 275 270 276 286 289 286 265 279 271 283 274 278 295 268 238 296 266 241 292 256 285 281 279 257 284 268 261 290 263 277 296 277 265 260 275 284 250 299 246 239 274 277 278 275 294 266 293 264 245 282 286 305 293 293 323 275 289 292 306 288 272 264 273 246 280 295 287 279 287 288 274 277 270 283 276 289 283 285 284 275 290 289 271 300 265 282 291 282 298 317 277 242 299 298 260 274 291 271 278 293 268 257 308 300 260 264 275 294 284 279 269 273 271 294 281 280 287 282 268 269 290 277 301 287 284 273 294 280 284 289 243 286 289 265 304 278 279 312 292 288 263 273 247 289 264 288 245 279 261 308 319 246 268 266 278 295 266 247 245 285 240 268 280 301 279 282 282 294 247 284 299 258 273 317 272 265 263 273 274 304 260 269 256 282 265 271 257 265 260 273 263 294 283 272 270 268 250 275 287 263 271 256 278 265 278 286 275 277 288 274 273 260 267 267 278 286 282 268 314 291 258 265 293 289 262 263 283 262 286 298 299 308 293 260 268 270 285 280 286 290 265 263 274 278 248 272 269 294 276 269 317 260 272 260 282 239 245 278 266 278 240 275 282 271 272 268 291 279 305 276 279 268 267 273 287 286 255 270 273 274 275 289 284 260 274 228 288 241 267 305 276 296 270 275 282 262 268 290 282 274 315 266 283 282 247 312 248 282 263 261 269 260 260 283 274 268 270 275 290 258 267 276 280 239 292 241 246 268 285 256 288 308 307 279 284 236 272 268 264 248 266 264 274 273 295 286 269 240 285 258 290 248 289 270 266 217 283 295 255 273 249 269 259 299 270 283 260 240 234 284 285 287 268 275 286 263 270 263 262 286 241 288 259 289 265 265 241 270 287 275 285 268 309 275 275 288 271 285 248 302 262 258 270 271 270 279 265 286 233 297 271 285 286 255 271 264 295 294 281 262 261 291 262 278 246 300 270 297 263 298 275 260 280 280 255 273 276 257 292 257 274 258 268 238 242 265 265 270 280 291 296 273 290 261 273 244 271 306 272 282 260 291 290 264 266 267 265 283 284 265 287 265 286 262 256 265 270 284 267 275 256 263 279 275 265 279 274 260 296 292 298 260 236 244 284 290 285 307 245 270 276 270 271 268 284 279 274 261 287 257 329 280 267 311 271 260 289 280 310 261 263 246 272 280 312 287 294 295 280 302 297 307 294 297 283 272 274 295 303 278 280 295 264 274 288 278 274 300 289 301 249 318 258 268 297 284 307 294 275 266 301 270 259 268 268 269 284 269 280 244 284 288 296 284 281 287 284 277 288 279 247 285 243 303 271 296 280 225 285 277 284 265 297 294 261 269 270 277 282 288 250 281 284 280 279 233 284 289 255 278 267 224 274 265 282 293 269 275 287 290 275 286 272 293 283 230 282 274 288 278 275 271 296 287 232 266 236 242 310 267 283 295 294 274 288 286 275 294 283 301 270 291 281 279 288 289 272 277 292 241 318 279 276 286 288 271 292 292 270 263 300 248 271 268 273 267 267 291 294 276 264 279 311 297 284 297 284 312 286 271 283 269 272 278 258 274 301 287 274 268 262 283 265 268 255 235 292 291 266 267 274 293 266 299 277 262 295 274 287 292 247 279 284 278 289 285 268 294 298 273 285 264 288 265 279 303 276 291 278 288 274 277 290 263 243 294 260 239 290 284 270 288 297 255 301 286 270 266 292 289 264 275 276 236 315 286 278 267 304 275 279 284 289 276 263 244 292 279 267 264 293 249 283 299 289 264 266 278 260 286 297 286 282 260 264 287 248 263 269 284 285 280 310 267 297 269 287 318 241 291 283 293 263 274 281 264 299 239 257 279 258 277 283 268 298 290 261 270 290 269 279 260 286 291 263 284 267 283 266 273 264 258 272 293 256 266 269 259 260 274 300 304 284 302 273 291 285 272 263 246 277 266 282 247 261 270 273 302 291 277 297 286 264 293 277 294 298 301 257 271 272 286 304 288 245 301 277 274 308 277 273 281 272 249 313 298 272 258 284 272 258 299 286 247 299 266 232 231 240 268 261 281 285 255 291 279 282 257 285 266 272 271 279 256 279 240 262 289 246 287 268 272 284 266 248 273 260 279 247 280 258 258 274 256 297 278 260 255 277 292 264 273 292 265 233 267 256 246 261 284 248 258 245 290 271 292 274 298 267 282 238 301 269 283 260 237 279 272 304 259 295 277 281 306 270 236 271 267 269 286 248 262 295 246 261 238 287 286 286 276 259 257 263 314 293 256 273 283 290 264 249 246 293 302 267 265 269 268 249 255 231 291 255 260 267 274 287 259 231 277 282 277 307 285 277 258 263 270 265 264 306 274 269 265 272 262 269 272 274 273 279 286 303 299 289 275 261 265 277 285 248 262 264 267 244 313 299 256 268 280 233 264 313 298 235 290 262 258 268 260 241 244 244 285 285 268 272 242 281 301 255 255 288 280 257 289 264 283 281 282 272 233 268 267 268 255 287 261 276 256 266 249 262 261 269 269 280 246 256 258 292 230 248 283 263 270 279 242 269 249 277 290 287 266 280 277 249 275 282 271 267 280 257 289 281 267 284 289 274 272 285 249 285 266 271 269 312 295 261 278 284 232 266 255 262 278 292 259 263 269 256 275 264 234 248 272 261 289 248 246 255 265 260 268 258 305 239 256 244 224 269 281 241 275 276 279 292 246 290 284 306 287 258 268 265 277 283 286 289 245 240 269 270 289 229 276 278 287 281 271 244 275 262 278 263 271 257 287 250 307 294 272 287 268 255 286 267 238 296 245 271 266 288 284 269 279 271 281 243 257 298 266 242 250 272 272 257 277 274 306 266 260 280 246 279 284 264 288 270 271 260 293 290 294 265 284 300 273 266 236 258 274 237 274 265 258 280 303 287 269 292 297 266 290 293 288 301 265 274 277 270 282 233 264 265 267 261 261 260 271 329 280 280 255 255 296 302 283 270 291 272 272 276 259 273 284 276 273 285 262 283 279 250 234 271 257 255 247 266 258 285 296 291 286 280 291 285 275 274 280 244 271 280 258 281 262 261 273 287 274 281 287 294 320 289 264 264 286 262 296 282 280 265 271 312 290 300 284 318 306 272 283 264 288 281 281 285 309 295 282 268 247 266 278 231 275 317 266 270 269 274 285 308 285 292 298 281 278 283 292 275 262 301 315 282 264 283 306 294 304 313 304 294 277 300 314 281 311 279 316 265 282 296 316 277 282 296 266 303 288 268 300 277 313 287 298 321 276 282 276 282 284 296 268 273 289 299 296 318 303 272 292 305 269 287 294 270 285 307 314 255 273 302 273 272 264 329 302 291 278 269 283 261 285 310 290 295 300 287 267 316 283 283 279 285 282 315 290 307 297 268 291 268 319 290 277 282 264 289 277 294 301 288 281 279 296 249 286 287 279 301 285 272 275 279 291 260 273 334 261 283 256 280 306 270 277 272 282 300 288 263 242 280 241 280 240 291 264 271 265 275 291 307 276 311 264 271 299 302 280 278 271 292 287 265 269 271 282 268 290 314 275 289 280 276 282 289 281 299 299 303 285 312 287 279 249 286 314 277 272 281 247 294 296 320 296 288 286 286 283 283 292 284 257 242 285 280 318 296 261 267 294 278 272 275 272 289 276 261 260 309 258 283 299 246 297 317 286 305 284 297 291 300 261 289 298 291 291 299 277 257 308 264 287 276 264 290 296 261 294 264 284 301 262 269 274 270 277 288 262 310 286 300 273 266 266 243 297 262 274 289 288 278 246 285 299 264 286 284 277 270 288 277 306 263 293 282 304 292 271 331 282 277 278 297 262 289 285 295 312 266 276 311 283 266 263 284 301 271 337 277 281 289 291 268 290 298 298 283 307 272 275 289 273 308 287 300 289 301 287 292 240 245 273 269 280 291 283 257 262 276 265 273 268 296 267 316 267 287 288 283 301 268 268 310 307 281 303 302 283 268 330 286 268 274 282 272 283 293 256 271 282 311 273 272 261 312 284 261 293 299 304 289 269 299 290 280 268 311 272 274 289 264 271 294 283 291 264 292 308 292 273 269 276 293 272 281 308 282 284 320 310 288 257 274 274 267 257 239 290 299 284 268 306 271 271 301 264 256 260 293 295 295 263 275 299 272 283 277 302 299 279 271 288 299 268 287 267 264 260 281 279 268 287 294 278 267 263 277 288 272 277 267 285 294 277 257 283 289 287 282 310 286 272 276 303 265 267 301 271 272 271 280 298 268 285 258 271 290 290 280 293 283 280 292 284 268 262 258 273 275 306 271 287 255 276 285 270 264 282 297 283 317 274 293 293 261 300 262 301 273 280 227 290 276 280 335 295 308 248 261 268 279 297 278 301 279 276 279 291 272 282 264 283 321 297 256 310 267 247 268 264 279 263 282 277 261 290 281 277 247 275 295 271 261 267 275 290 248 273 287 273 291 283 316 267 283 287 301 282 282 243 274 261 276 256 292 279 280 315 239 249 289 273 270 276 309 303 244 283 288 289 264 281 310 277 278 285 301 269 288 227 266 241 250 279 268 249 275 258 266 278 265 280 281 269 300 289 314 288 301 280 265 285 262 288 292 278 292 286 286 231 313 292 280 305 287 237 271 288 307 277 296 302 280 292 268 285 267 282 268 282 296 305 280 289 246 255 242 322 271 271 265 290 304 294 266 263 285 268 261 273 272 246 286 275 298 275 288 318 263 284 280 312 288 298 263 275 274 261 270 286 272 271 291 298 285 268 292 238 244 284 276 241 297 282 305 290 272 293 267 302 313 288 309 306 287 294 280 277 235 262 279 295 258 290 293 287 295 273 290 303 272 244 272 272 266 294 298 308 273 294 238 309 268 274 284 297 280 261 258 280 279 289 300 266 268 271 257 277 269 271 285 278 228 281 266 298 282 314 283 296 305 303 297 269 309 274 280 260 261 284 267 270 290 269 302 268 295 297 331 263 271 297 279 288 277 270 282 265 282 260 287 260 282 276 295 278 280 286 265 299 277 284 288 309 264 282 276 267 264 263 283 278 294 260 268 265 273 275 256 261 275 281 256 303 278 279 273 282 281 326 269 308 274 283 265 273 263 300 281 292 264 257 279 300 276 262 282 256 266 291 292 285 258 299 289 275 274 282 287 285 273 278 262 288 283 306 272 290 279 274 297 273 285 267 274 295 261 297 295 287 281 267 280 264 273 295 287 283 308 270 284 241 275 313 307 297 291 279 300 268 268 266 271 316 264 275 278 284 308 282 302 257 266 266 277 275 293 286 298 286 289 276 244 226 267 294 296 278 304 269 278 284 296 302 276 285 306 287 293 263 276 304 278 282 291 278 304 265 287 264 326 283 310 290 293 291 259 273 287 289 318 271 275 315 290 286 275 296 270 287 283 286 292 284 270 300 268 316 281 304 278 269 256 289 300 279 270 310 259 221 280 279 284 297 288 289 298 271 298 297 299 231 316 282 260 283 322 298 264 293 262 290 278 294 279 290 260 283 272 243 265 309 292 272 257 274 260 279 277 273 296 281 279 289 317 293 292 268 291 280 280 245 274 278 290 267 265 289 313 274 296 291 249 304 274 283 282 282 279 314 281 289 301 269 276 278 285 282 289 303 261 256 246 301 292 296 290 293 303 287 273 285 283 247 282 255 283 270 288 290 279 286 284 294 259 288 297 286 265 314 270 283 273 291 273 263 267 282 283 291 264 299 277 289 270 264 324 270 283 282 264 290 307 259 292 287 280 272 308 287 303 258 265 284 298 272 274 275 269 285 307 265 269 265 298 301 276 295 300 277 287 275 260 275 291 245 308 260 231 263 331 305 277 305 278 248 275 272 294 279 275 277 300 283 313 246 286 304 281 277 273 302 277 250 314 275 306 295 289 263 246 286 283 280 285 305 313 270 263 287 311 266 282 287 290 302 295 267 325 281 297 287 310 249 244 280 296 257 291 270 310 289 258 298 291 264 272 312 297 306 297 283 288 300 300 302 260 322 261 277 266 223 262 299 294 277 274 310 262 287 333 261 259 272 281 303 292 268 282 259 230 298 283 294 301 274 293 275 298 313 246 275 264 266 272 282 310 274 282 255 271 301 293 304 304 292 287 255 304 282 329 299 292 329 302 260 284 270 283 303 268 300 312 278 269 262 277 286 294 283 268 283 291 265 257 270 280 269 299 260 264 285 297 263 288 305 278 300 296 284 255 264 285 311 273 275 271 273 280 277 309 295 306 284 268 308 281 274 279 287 296 273 272 262 322 309 260 277 269 261 244 275 298 249 303 266 267 281 275 279 249 284 270 290 287 266 276 277 289 262 306 285 302 281 280 285 283 312 265 287 269 255 294 235 309 272 276 293 270 298 286 293 273 250 260 241 291 292 279 279 263 289 286 282 270 308 265 277 256 281 269 265 291 291 280 299 279 304 267 265 295 267 275 292 273 280 319 266 258 274 277 277 284 307</counts>
			</dataPoints>
		</scan>
	</xrdMeasurement>
</xrdMeasurements>