File: data/XRD/XG-Vakuum/XG-800/W6822-1C_XG_Vakuum_800.xrdml
<xrdMeasurements xmlns="http://www.xrdml.com/XRDMeasurement/2.1" xmlns:xsi="http://www.w3.org/2001/XMLSchema-instance" xsi:schemaLocation="http://www.xrdml.com/XRDMeasurement/2.1 http://www.xrdml.com/XRDMeasurement/2.1/XRDMeasurement.xsd" status="Completed">
	<comment>
		<entry>Configuration=Factory configuration, Owner=User-1, Creation date=7/8/2013 4:01:53 PM</entry>
		<entry>Goniometer=PW3050/65 (Theta/2Theta); Minimum step size 2Theta:0.0001; Minimum step size Omega:0.0001</entry>
		<entry>Sample stage=MRD Cradle; Minimum step size Phi:0.01; Minimum step size Chi:0.01; Minimum step size X:0.01; Minimum step size Y:0.01; Minimum step size Z:0.001</entry>
		<entry>Diffractometer system=XPERT-PRO</entry>
		<entry>Measurement program=C:\PANalytical\Data Collector\Programs\Jorrit\2thom\_absolute_2th-om_10-130deg_PIXscan_56min.xrdmp, Identifier={15BCCF57-2807-42BD-B5B9-ECC0B3DC9284}</entry>
		<entry>Batch program=C:\PANalytical\Data Collector\Programs\SimonL\batch3x_2thom_10-130°_z9.1_x0,10,20_y0_57min.xrdmp, Identifier={1E956750-2741-41FB-B242-F9B1C20E21A8}</entry>
	</comment>
	<sample type="To be analyzed">
		<id></id>
		<name></name>
		<preparedBy></preparedBy>
	</sample>
	<xrdMeasurement measurementType="Scan" status="Completed" sampleMode="Reflection">
		<comment>
			<entry>_absolute_2th-om_10-130deg_PIXscan_56min</entry>
			<entry>PHD Lower Level = 4.83 (keV), PHD Upper Level = 11.27 (keV)</entry>
		</comment>
		<usedWavelength intended="K-Alpha 1">
			<kAlpha1 unit="Angstrom">1.5405980</kAlpha1>
			<kAlpha2 unit="Angstrom">1.5444260</kAlpha2>
			<kBeta unit="Angstrom">1.3922500</kBeta>
			<ratioKAlpha2KAlpha1>0.5000</ratioKAlpha2KAlpha1>
		</usedWavelength>
		<incidentBeamPath>
			<radius unit="mm">320.00</radius>
			<xRayTube id="1010048" name="Empyrean Cu LFF HR (9430 033 7310x) DK442154">
				<tension unit="kV">40.0</tension>
				<current unit="mA">40.0</current>
				<anodeMaterial>Cu</anodeMaterial>
				<focus type="Line">
					<length unit="mm">12.0</length>
					<width unit="mm">0.4</width>
					<takeOffAngle unit="deg">4.2</takeOffAngle>
				</focus>
			</xRayTube>
			<xRayMirror id="27010001" name="Inc. Beam Cu W/Si (parabolic MRD)" hybrid="false">
				<crystal type="Graded" shape="Parabolic">W/Si</crystal>
				<acceptanceAngle unit="deg">0.800</acceptanceAngle>
				<length unit="mm">60.0</length>
			</xRayMirror>
			<sollerSlit id="21010002" name="Soller slits 0.04 rad.">
				<opening unit="rad">0.0400</opening>
			</sollerSlit>
			<mask id="22030008" name="Fixed mask 4 mm">
				<distanceToSample unit="mm">220.00</distanceToSample>
				<width unit="mm">4.00</width>
			</mask>
			<divergenceSlit id="22010007" name="Fixed slit 1/8°" xsi:type="fixedDivergenceSlitType">
				<distanceToSample unit="mm">220.00</distanceToSample>
				<height unit="mm">0.19</height>
			</divergenceSlit>
		</incidentBeamPath>
		<diffractedBeamPath>
			<radius unit="mm">320.00</radius>
			<sollerSlit id="21010002" name="Soller slits 0.04 rad.">
				<opening unit="rad">0.0400</opening>
			</sollerSlit>
			<receivingSlit id="22010001" name="Fixed slit 4°">
				<height unit="mm">5.88</height>
			</receivingSlit>
			<detector id="7010017" name="PIXcel3D 1x1 detector" xsi:type="areaDetectorType">
				<phd unit="%">
					<lowerLevel>30.0</lowerLevel>
					<upperLevel>70.0</upperLevel>
				</phd>
				<mode>Scanning</mode>
				<activeChannelsEquatorial>255</activeChannelsEquatorial>
				<activeChannelsAxial>255</activeChannelsAxial>
				<pitchEquatorial unit="mm">0.05500</pitchEquatorial>
				<pitchAxial unit="mm">0.05500</pitchAxial>
				<readOutPeriod unit="seconds">0.135</readOutPeriod>
			</detector>
		</diffractedBeamPath>
		<scan appendNumber="0" mode="Continuous" scanAxis="2Theta-Omega" status="Completed">
			<header>
				<startTimeStamp>2024-10-15T11:56:22+02:00</startTimeStamp>
				<endTimeStamp>2024-10-15T12:52:27+02:00</endTimeStamp>
				<author>
					<name>PRO-MRD</name>
				</author>
				<source>
					<applicationSoftware version="6.1b">Data Collector</applicationSoftware>
					<instrumentControlSoftware version="7.0E 20130304">XPERT-PRO</instrumentControlSoftware>
					<instrumentID>0000000011142674</instrumentID>
				</source>
			</header>
			<dataPoints>
				<positions axis="2Theta" unit="deg">
					<startPosition>9.99826193</startPosition>
					<endPosition>129.99755682</endPosition>
				</positions>
				<positions axis="Omega" unit="deg">
					<startPosition>4.99913096</startPosition>
					<endPosition>64.99877841</endPosition>
				</positions>
				<positions axis="Phi" unit="deg">
					<commonPosition>0.00</commonPosition>
				</positions>
				<positions axis="Chi" unit="deg">
					<commonPosition>0.00</commonPosition>
				</positions>
				<positions axis="X" unit="mm">
					<commonPosition>10.00</commonPosition>
				</positions>
				<positions axis="Y" unit="mm">
					<commonPosition>0.00</commonPosition>
				</positions>
				<positions axis="Z" unit="mm">
					<commonPosition>9.100</commonPosition>
				</positions>
				<commonCountingTime unit="seconds">32.895</commonCountingTime>
				<counts 458 457 473 456 455 441 463 435 434 496 479 447 440 463 451 473 478 449 439 438 428 476 464 469 459 440 443 485 523 490 467 471 477 481 449 473 443 507 501 489 470 504 512 469 462 516 478 483 501 450 481 488 517 540 527 475 451 481 461 460 476 464 466 467 469 456 500 438 449 436 449 491 444 477 442 449 437 462 501 435 474 464 457 431 449 429 451 432 442 455 400 449 476 458 425 431 430 400 428 419 434 447 419 459 420 445 411 430 433 428 421 439 431 417 470 429 391 475 456 413 432 431 446 462 455 430 415 411 442 395 428 444 441 427 412 465 424 426 437 449 451 448 388 412 431 410 437 475 447 454 441 428 421 403 456 428 413 426 391 417 452 415 392 406 456 446 426 385 437 440 397 377 441 430 422 426 448 406 445 443 428 383 396 414 377 386 439 409 436 398 369 449 438 454 383 413 464 408 383 404 421 418 406 398 440 391 429 407 398 427 425 424 405 393 402 396 427 395 422 395 397 403 402 391 401 399 414 390 406 396 380 373 397 417 403 410 437 387 418 422 409 422 418 385 411 378 404 414 386 409 380 401 400 390 368 414 365 394 390 409 426 367 403 391 388 399 403 394 426 368 387 457 380 397 408 383 412 362 351 398 386 391 361 398 412 381 356 414 421 386 349 399 399 413 369 405 350 397 409 408 371 383 379 376 357 380 376 385 388 375 380 388 383 389 365 360 359 410 361 362 396 370 412 388 377 410 350 383 385 386 339 355 388 378 361 357 371 366 357 342 399 361 358 352 410 388 369 359 365 347 392 357 347 374 363 365 376 319 327 416 359 345 387 382 348 372 335 393 367 405 333 386 342 373 379 372 383 309 381 389 373 367 364 358 378 359 358 371 338 353 345 326 334 372 373 327 351 340 387 361 356 397 391 343 371 364 352 343 353 347 337 363 364 337 348 342 346 369 322 339 360 367 337 357 366 326 355 347 347 382 358 353 363 360 350 328 324 345 356 321 325 358 315 361 357 342 316 302 373 358 349 348 394 325 347 373 372 321 364 363 315 342 357 341 354 357 348 329 346 359 336 335 365 335 314 334 364 355 345 336 324 321 335 321 308 334 340 361 342 333 297 329 347 336 336 307 384 351 358 348 362 317 335 345 339 337 319 395 314 345 336 355 336 359 332 351 340 306 323 322 323 396 357 307 334 330 322 353 377 322 342 342 341 335 341 339 325 327 362 312 337 317 323 348 316 311 339 352 340 330 323 323 338 316 324 329 321 333 308 359 332 358 334 339 344 321 316 305 345 348 310 318 315 353 349 324 353 320 359 318 328 344 321 309 299 324 309 356 336 344 336 298 309 329 312 327 316 332 313 324 352 332 305 371 305 351 310 322 326 301 306 341 310 313 343 322 335 348 311 295 331 318 293 313 327 301 348 321 330 339 346 325 320 340 321 308 345 295 296 281 295 333 326 324 343 310 336 336 321 313 309 335 341 334 296 302 310 318 333 319 344 334 278 337 322 350 329 299 344 344 324 331 311 351 334 325 297 324 315 318 324 326 309 332 341 316 292 338 326 305 320 326 274 319 332 325 314 300 333 323 316 331 312 312 311 327 329 353 312 314 326 309 331 284 300 322 347 326 318 335 321 338 334 293 320 307 313 328 313 291 328 365 313 346 309 319 328 277 333 330 307 350 361 347 317 349 337 316 339 340 310 312 359 310 321 329 353 329 343 323 316 287 331 293 341 343 314 328 320 330 287 304 319 306 367 314 333 333 305 294 351 315 309 294 335 332 298 322 328 311 282 294 306 305 316 354 366 363 303 349 379 309 325 319 354 313 298 322 314 316 333 321 300 331 336 331 318 265 293 312 340 339 293 352 325 325 329 306 315 364 325 324 290 345 308 339 312 318 316 319 322 297 336 326 317 302 327 316 331 331 327 309 325 307 324 319 289 328 312 319 282 337 336 329 320 346 287 346 323 350 332 343 326 317 371 334 319 338 319 323 342 287 314 310 324 318 320 304 297 282 360 311 312 334 319 316 341 335 326 355 351 368 330 312 299 315 343 339 351 333 358 347 322 330 338 302 364 328 350 292 353 331 311 307 314 335 323 345 319 370 335 317 338 340 331 373 329 321 322 327 310 314 284 302 336 330 306 338 373 361 311 332 325 318 319 332 363 310 352 352 297 320 314 325 326 341 333 353 333 345 333 346 347 324 344 338 355 323 362 339 358 328 331 344 350 328 329 355 321 342 344 329 359 277 318 314 346 356 348 348 325 334 326 324 321 336 324 302 330 397 319 328 311 345 322 315 345 322 315 303 360 349 348 322 354 324 309 312 329 334 329 316 331 316 344 340 335 346 325 346 324 339 328 337 326 343 304 315 307 332 292 360 312 346 336 360 317 344 341 315 361 311 322 316 295 338 345 359 361 325 369 308 335 344 347 386 320 358 317 307 316 323 332 356 318 344 310 302 338 309 319 332 331 327 323 340 368 316 322 334 334 335 328 343 349 319 332 316 346 340 330 326 326 322 328 346 314 333 295 329 334 345 323 327 329 357 328 375 333 359 353 368 346 352 322 317 302 325 329 317 296 330 316 344 351 309 354 339 319 368 316 327 284 349 323 324 351 342 343 300 327 327 332 378 317 349 335 355 355 357 321 341 317 363 322 356 371 354 359 320 302 363 331 340 317 360 322 331 354 342 322 348 353 340 328 375 334 330 334 330 349 333 308 310 353 335 335 345 328 391 360 344 323 340 343 328 357 335 337 366 334 318 331 330 341 332 366 339 366 346 350 331 313 339 339 331 328 339 293 339 337 333 346 377 334 319 352 338 313 333 341 359 324 336 346 316 352 359 316 338 359 317 335 340 319 318 324 323 338 301 306 359 335 347 331 354 332 353 366 336 311 354 334 295 311 323 330 334 310 335 318 323 363 343 324 346 369 353 312 337 344 343 324 338 333 316 339 311 350 334 343 323 355 323 292 315 346 324 328 328 349 320 331 363 339 301 328 311 333 318 339 334 334 342 308 287 305 339 315 322 303 305 308 344 357 306 320 323 351 355 330 321 293 305 330 327 306 358 297 345 299 297 329 317 310 301 313 324 307 310 291 326 321 343 323 291 315 323 331 322 327 335 342 322 335 346 358 329 298 320 325 302 325 334 322 322 298 311 336 327 309 315 343 322 316 350 312 364 324 334 301 293 309 328 331 323 296 299 328 347 338 354 330 326 315 320 324 338 326 322 329 352 355 343 309 291 332 338 328 324 302 323 345 293 307 317 295 308 339 310 321 310 340 321 300 362 309 325 307 317 310 315 332 294 286 317 296 326 327 320 297 325 341 284 310 298 317 303 303 330 296 316 298 289 310 315 316 303 293 295 317 333 319 303 306 300 302 293 314 303 290 331 333 318 300 328 303 324 284 306 319 323 303 297 311 312 319 289 293 303 343 332 301 296 309 311 290 319 278 310 310 290 321 281 275 328 292 306 322 311 305 300 322 301 287 286 291 280 324 291 361 330 321 295 305 325 309 312 327 277 316 314 283 309 293 301 307 306 291 302 305 324 338 301 322 294 307 329 291 284 307 298 307 287 305 319 301 324 337 320 284 294 284 274 320 285 273 320 336 297 278 308 324 301 271 297 295 272 342 272 304 316 322 298 307 285 334 314 308 299 299 304 300 325 298 286 320 316 290 287 301 317 280 290 283 307 288 304 326 298 274 299 324 315 293 274 296 288 306 297 282 291 297 286 276 292 289 302 313 268 277 275 276 270 319 294 310 297 304 284 310 309 287 281 307 314 274 309 265 296 307 316 281 294 289 279 285 290 321 295 297 300 289 255 314 336 271 301 294 328 305 312 301 306 274 286 301 259 284 309 281 285 298 287 267 297 306 303 295 305 268 303 277 297 310 276 304 284 281 286 300 265 291 277 285 294 243 298 299 302 276 277 306 248 289 322 320 278 293 288 268 263 255 284 273 291 292 290 298 300 267 282 265 311 284 281 281 304 292 282 287 229 297 263 280 298 261 299 293 302 279 277 273 299 279 303 265 292 276 298 283 293 271 279 300 308 302 303 278 279 259 283 317 294 286 314 284 270 265 308 297 296 277 278 288 266 296 275 298 282 282 289 268 291 317 278 250 285 285 255 263 294 284 274 285 274 287 292 291 274 297 280 286 242 296 280 266 271 295 293 290 285 290 307 269 268 257 256 284 285 288 280 286 295 284 281 283 275 269 265 260 278 278 273 255 263 289 287 298 297 275 299 287 281 280 290 280 267 284 249 289 245 262 261 264 291 266 275 291 293 298 242 269 268 275 265 221 267 256 259 282 242 309 280 264 288 257 294 271 282 290 280 263 264 235 265 258 279 290 256 266 288 240 262 278 315 289 269 261 285 264 262 280 274 263 291 256 274 321 244 295 287 297 261 299 289 285 261 257 320 286 279 264 262 263 288 277 242 317 236 262 271 273 261 266 260 249 281 275 276 283 279 242 261 294 306 276 271 256 282 273 246 255 262 266 261 259 269 272 230 269 266 274 287 293 258 265 272 271 255 258 247 264 278 283 278 277 287 257 270 284 284 274 248 271 248 238 282 259 289 272 290 264 291 277 267 245 258 247 258 289 226 256 294 263 268 260 277 268 294 255 240 275 279 245 241 269 283 265 257 230 234 260 278 260 295 249 287 284 274 265 276 255 263 259 274 241 288 266 283 239 287 235 224 268 274 248 256 276 284 260 243 246 265 248 250 235 269 273 275 276 287 244 232 262 246 263 266 246 246 273 262 246 279 221 248 263 269 263 274 232 293 268 270 265 243 276 240 288 265 241 221 241 238 286 257 263 265 284 259 266 244 287 246 259 269 278 255 241 241 262 263 261 267 289 244 241 241 245 256 264 276 260 270 256 270 262 248 240 271 250 272 263 276 255 266 259 264 270 249 261 242 255 257 281 236 244 225 242 283 303 275 250 279 258 248 247 212 239 258 272 265 234 235 285 231 268 248 249 276 234 238 248 241 282 247 273 288 231 260 238 278 238 271 239 267 263 248 244 220 261 275 269 258 257 235 204 211 233 250 258 248 234 259 241 236 231 233 239 268 234 272 248 235 260 247 235 244 248 233 270 266 267 262 236 207 237 272 277 243 263 274 271 268 222 234 261 263 261 242 227 245 264 250 256 247 242 247 263 278 269 258 223 250 257 250 247 236 257 227 248 221 237 235 227 268 242 258 256 219 234 259 230 259 270 242 241 269 248 269 245 229 224 274 264 249 247 231 258 257 281 245 260 233 258 228 229 246 243 236 268 246 231 245 233 270 237 236 257 207 219 257 236 239 268 269 245 243 243 249 246 232 240 291 224 269 230 233 246 248 230 237 264 222 246 213 214 226 229 246 231 245 261 241 231 264 247 231 240 244 280 225 261 277 242 257 243 258 247 226 241 223 235 266 218 237 237 211 214 244 270 237 238 239 227 239 274 234 243 241 237 229 228 255 246 229 234 226 266 224 225 230 262 240 245 236 241 223 236 235 262 236 272 240 246 222 265 229 246 264 224 238 229 255 235 223 259 214 284 216 256 228 244 236 229 240 237 263 242 231 216 264 243 228 231 257 227 261 262 230 239 223 258 217 247 238 227 229 247 237 232 220 227 244 227 241 229 222 221 234 233 261 260 239 241 222 228 216 215 234 236 243 280 237 259 227 258 256 241 234 274 249 217 221 244 229 224 232 247 220 221 256 233 213 278 245 225 260 246 274 238 225 240 226 220 244 244 227 247 246 222 230 245 234 249 264 241 248 226 231 241 277 239 240 270 227 255 239 235 214 224 239 241 234 261 230 230 249 280 261 256 204 248 228 236 222 231 239 268 257 232 212 224 233 235 235 270 248 234 234 260 193 257 216 233 249 256 245 235 238 249 219 232 236 215 242 231 210 277 232 226 243 246 230 271 239 249 270 236 234 267 284 217 243 266 264 234 228 256 222 249 258 228 257 245 247 230 230 261 228 242 236 255 222 235 223 266 258 238 246 241 232 222 228 241 248 291 233 267 241 259 261 243 225 242 275 231 240 238 240 208 235 242 269 229 244 264 235 245 242 265 244 231 206 215 248 264 240 248 226 259 231 227 248 257 219 215 240 226 245 226 244 242 229 232 241 245 262 264 231 225 249 255 234 227 240 225 226 267 217 249 255 247 239 259 244 239 233 238 256 239 239 260 228 239 220 235 217 221 231 261 232 225 220 249 242 246 240 234 205 235 215 245 244 226 232 282 273 228 282 237 226 218 245 268 238 231 222 263 238 239 256 264 255 239 215 247 216 231 241 229 207 242 239 236 217 232 245 241 245 255 244 222 240 244 229 223 231 216 237 241 227 240 240 234 259 229 260 276 274 217 236 218 248 240 233 242 241 234 258 238 226 229 216 219 236 237 219 239 267 247 240 216 267 231 223 227 241 240 225 222 225 227 238 232 250 225 228 239 236 262 240 216 232 259 209 220 234 237 228 214 229 239 243 194 264 248 265 239 233 245 237 234 239 255 238 215 262 199 215 220 250 214 241 260 256 259 257 232 258 241 248 232 250 263 255 229 240 218 226 240 273 224 214 210 245 233 213 220 235 258 242 259 209 257 238 260 235 241 248 236 227 237 256 195 225 264 238 222 230 228 236 262 259 240 229 229 222 234 244 223 260 232 232 203 239 230 233 222 240 218 256 228 223 223 246 259 226 219 259 215 226 216 236 212 247 243 229 230 275 236 225 262 214 239 233 242 239 227 262 228 238 233 209 239 241 243 203 240 243 203 263 216 238 199 204 237 216 262 271 248 210 227 206 243 237 231 224 233 207 234 224 209 227 211 267 262 235 235 256 235 237 227 245 244 235 245 243 242 220 220 257 222 234 237 243 232 270 231 247 211 289 202 243 232 246 241 236 214 226 223 222 228 261 242 256 218 226 237 186 236 224 262 241 240 245 236 239 256 229 225 238 244 229 226 234 228 235 214 247 239 218 215 231 210 219 242 239 247 237 236 218 233 235 257 255 223 247 217 243 207 243 263 241 228 231 221 212 207 259 226 240 263 213 225 239 229 229 234 232 231 212 241 232 246 234 225 235 249 281 236 233 237 264 202 262 228 228 232 206 246 221 239 267 220 236 236 236 256 235 249 238 247 221 235 206 221 248 240 240 221 237 221 264 238 209 245 220 255 219 226 229 244 203 236 222 236 239 231 261 234 237 260 243 250 211 236 232 229 242 242 230 233 224 272 257 233 240 248 218 247 242 238 246 233 223 219 221 240 242 247 198 234 236 249 233 226 212 269 216 243 267 248 232 233 249 259 232 261 226 220 261 256 226 231 189 241 232 248 249 233 255 234 246 225 256 222 223 248 213 267 212 222 235 230 235 248 228 246 260 240 230 242 224 256 249 233 240 225 237 255 267 243 245 267 260 267 238 245 211 257 229 224 199 237 249 256 236 229 257 228 247 258 281 231 247 267 237 248 233 248 238 220 243 227 246 258 246 233 220 233 241 270 216 264 233 248 261 220 210 239 284 249 292 219 241 242 236 260 218 247 244 239 234 256 233 237 245 276 239 225 247 258 225 264 259 274 271 244 244 247 230 267 255 277 257 241 209 247 281 242 256 244 235 247 235 272 257 242 228 236 236 271 288 244 283 257 261 248 256 258 269 258 246 276 272 261 276 232 234 232 242 263 240 256 227 243 248 236 278 271 247 265 281 227 222 249 263 293 287 244 245 255 270 267 230 262 235 282 259 265 281 293 247 283 271 283 269 256 256 233 289 279 288 269 237 296 314 292 297 263 322 285 300 360 289 310 273 302 304 331 324 301 342 304 307 351 321 346 344 375 351 386 384 375 409 380 384 418 402 424 407 394 393 419 441 431 403 419 427 378 386 390 379 369 368 373 366 353 375 350 348 293 349 333 283 326 324 317 317 325 257 313 302 286 282 290 257 270 283 305 289 233 286 280 287 266 260 247 230 249 238 282 243 239 239 241 247 271 247 279 234 238 238 237 236 247 231 241 268 236 288 244 238 233 236 258 240 242 221 243 224 258 237 221 223 259 206 216 248 227 250 235 246 296 240 232 260 245 280 229 248 228 267 239 276 234 219 265 247 208 244 216 246 268 226 244 223 246 241 257 234 237 241 255 230 274 236 279 240 211 222 212 234 225 209 244 235 226 256 247 227 239 211 228 234 245 274 241 227 257 240 242 290 238 247 241 222 235 285 242 230 236 229 236 257 231 233 220 248 255 238 214 267 225 265 246 243 238 228 235 240 247 234 262 228 261 269 243 234 232 209 245 227 261 241 240 215 198 237 238 223 242 247 219 246 242 256 250 240 232 240 229 269 243 223 264 272 243 273 238 190 244 247 229 235 245 225 228 243 242 210 260 278 237 256 221 265 237 234 256 234 245 249 225 247 212 237 236 241 244 229 257 240 224 205 234 264 207 228 260 235 245 239 235 275 236 262 232 230 266 267 245 222 275 262 223 227 210 221 194 226 221 243 231 242 233 226 210 225 220 270 231 246 245 248 237 256 261 217 229 225 221 228 245 243 218 256 264 234 226 228 215 237 238 234 228 242 262 243 193 273 262 231 243 233 266 248 230 222 244 229 211 264 235 239 265 267 229 219 228 244 232 238 228 249 240 232 238 226 272 223 234 240 246 255 249 222 220 239 242 236 239 229 235 219 225 239 256 224 232 237 228 215 259 249 261 211 230 223 241 249 208 250 237 222 232 231 240 229 242 258 233 243 249 222 210 221 236 232 224 228 235 234 239 255 243 209 214 232 231 225 263 226 263 246 217 225 218 233 205 214 241 240 225 255 214 234 240 258 216 271 245 238 197 244 242 219 220 237 244 241 234 212 246 210 215 219 216 236 232 221 246 233 257 215 203 234 223 233 215 247 217 240 224 249 225 226 222 266 231 250 250 244 216 230 223 233 226 233 239 243 273 217 230 223 217 244 233 225 223 212 244 264 265 232 249 260 220 268 270 211 217 261 241 233 241 216 241 246 246 203 243 228 225 206 259 242 227 234 213 220 235 234 255 220 224 238 224 224 214 243 224 223 232 244 248 234 265 257 215 213 231 203 201 214 206 219 228 239 230 201 242 215 241 241 227 226 217 237 267 263 220 240 228 216 247 213 226 244 218 231 247 203 237 263 229 244 260 223 265 228 246 215 275 198 202 255 225 237 264 213 221 202 250 243 234 222 240 227 230 230 244 232 230 266 235 212 240 214 229 239 239 242 259 244 237 241 243 238 259 228 243 255 226 245 225 228 207 289 219 224 233 241 214 206 245 223 218 258 225 229 214 237 229 213 238 241 224 249 216 241 239 232 232 224 230 213 201 262 235 236 222 249 232 250 230 223 229 212 199 217 223 220 223 238 225 209 210 233 214 247 233 235 216 235 210 217 233 246 215 228 217 221 248 226 228 255 264 248 220 232 231 246 217 232 222 219 214 230 229 231 210 231 234 276 242 238 247 219 232 222 200 244 210 234 214 235 237 237 280 217 240 223 194 246 242 239 227 222 237 224 213 266 219 227 221 235 245 218 227 198 232 246 220 235 224 224 239 230 220 225 223 202 243 263 260 244 244 227 242 239 236 224 261 226 240 201 235 237 229 247 215 222 223 271 237 243 259 237 228 221 224 258 224 233 215 256 232 269 230 237 201 224 244 256 228 244 223 260 214 213 235 235 215 227 232 235 232 240 222 224 246 245 234 222 227 256 238 243 229 199 264 230 241 230 248 246 213 280 239 220 233 224 240 222 245 204 242 240 222 236 249 233 219 258 246 214 238 233 248 262 226 224 237 229 246 231 231 214 242 228 257 221 244 214 233 231 229 241 219 231 200 220 235 258 260 234 239 257 230 225 228 210 212 235 223 221 215 226 208 235 209 220 211 232 209 240 235 261 233 239 233 224 214 219 223 212 224 239 265 240 237 217 240 200 211 219 240 228 247 208 215 228 261 238 228 235 256 255 229 222 221 193 245 217 269 238 218 249 226 246 231 259 243 219 204 246 222 226 222 223 238 229 229 273 264 224 277 199 243 263 223 222 244 239 224 268 242 237 226 214 234 204 240 224 229 259 225 287 263 247 244 217 229 207 232 262 238 248 249 232 249 224 210 256 244 225 231 220 222 222 219 263 241 238 211 246 226 223 242 224 222 232 208 225 244 255 214 237 217 245 234 247 217 220 207 226 256 211 222 218 255 228 227 263 257 257 242 212 249 259 240 242 234 283 268 245 211 221 242 223 221 260 229 270 245 218 247 242 242 225 272 209 226 220 241 222 255 243 211 229 268 206 230 224 237 235 207 239 236 261 223 229 242 236 244 237 215 224 208 222 228 226 224 246 265 234 246 247 237 275 223 204 246 229 236 229 245 213 261 223 218 224 226 230 201 235 239 223 236 223 211 245 208 266 237 241 236 234 258 216 271 236 230 220 235 225 240 277 207 243 268 261 256 231 229 228 268 233 222 221 239 233 214 236 239 227 256 238 244 246 227 233 258 221 249 236 272 225 232 255 244 232 250 229 206 230 243 243 210 231 214 239 236 212 228 230 224 244 256 231 220 230 242 205 262 226 242 215 219 249 226 235 265 240 228 235 259 233 229 229 221 267 210 240 218 240 222 239 231 227 206 246 239 239 229 236 226 230 241 232 248 262 222 219 237 231 243 226 236 248 243 227 230 222 230 225 255 243 233 218 232 208 274 239 214 257 241 260 269 224 214 237 235 233 266 223 233 264 235 258 268 211 226 217 235 225 229 226 231 209 260 249 227 228 200 268 249 262 257 223 210 217 264 216 220 234 234 217 235 229 240 234 226 231 235 223 231 244 237 233 231 219 272 230 227 248 228 215 237 227 219 256 239 237 227 232 228 235 203 225 216 235 232 264 230 256 247 225 242 232 235 246 231 230 246 236 228 224 232 245 228 235 255 238 268 245 242 211 228 211 235 231 236 223 212 263 258 268 230 204 246 240 235 226 249 225 255 235 244 231 242 247 230 247 231 269 221 236 238 220 223 238 220 229 229 243 229 234 190 233 243 257 236 236 199 233 219 198 230 222 246 261 213 213 211 211 264 218 225 230 221 230 243 244 239 228 241 228 231 219 242 225 243 209 257 266 245 260 245 239 236 263 210 224 243 234 259 262 260 276 257 223 235 235 222 231 218 258 262 239 248 230 233 214 230 234 231 224 232 245 212 245 193 258 249 228 234 238 242 237 227 225 241 242 230 265 214 231 240 214 265 269 235 236 246 238 240 269 258 224 222 223 208 248 223 217 213 247 247 248 200 211 206 259 275 262 248 237 209 231 257 233 276 236 270 269 242 259 269 258 260 237 246 232 246 233 260 272 247 236 231 231 232 220 241 227 256 223 240 245 237 218 234 242 228 218 239 236 246 238 240 243 257 227 246 267 209 224 228 256 201 239 270 231 229 232 260 248 244 231 257 231 230 236 227 228 239 221 217 281 195 231 220 259 235 223 235 240 256 201 229 224 217 256 226 238 231 262 228 232 257 244 248 222 224 218 208 225 244 235 228 216 214 249 246 238 236 230 234 235 233 260 232 222 238 232 273 279 237 240 224 236 258 244 272 229 247 225 227 221 244 231 217 233 247 238 225 243 255 232 236 244 242 237 233 257 227 236 266 242 263 218 213 276 249 239 255 235 228 228 227 221 260 234 226 231 249 269 224 225 240 232 245 242 230 226 247 238 219 240 247 218 222 239 230 205 217 234 259 231 229 259 200 228 219 231 256 228 227 267 247 257 233 243 241 239 243 242 218 236 249 247 237 239 224 224 217 217 271 222 234 219 228 257 258 261 245 271 228 229 245 225 237 245 222 226 264 223 265 237 246 259 246 217 240 231 231 241 227 236 237 226 224 260 266 230 235 246 245 236 240 216 260 229 265 231 281 261 236 237 208 262 245 222 281 223 278 235 269 241 239 212 242 218 230 266 230 226 245 243 208 226 236 259 206 220 248 239 221 246 244 271 280 220 255 233 267 244 236 223 197 261 258 263 242 262 237 272 259 258 244 227 230 235 234 265 302 244 220 218 229 257 256 260 217 240 250 269 236 235 247 218 228 237 236 239 234 241 234 238 231 228 227 272 244 216 245 214 256 237 228 279 227 235 206 214 239 238 242 248 241 257 246 248 235 232 248 237 234 243 264 259 220 232 240 268 255 240 217 222 244 255 230 226 281 259 247 263 258 264 260 242 227 274 257 235 271 234 241 235 262 241 261 273 263 233 239 234 257 245 237 238 237 239 267 242 256 233 273 237 235 256 263 236 239 261 233 244 247 235 268 269 240 241 232 242 258 226 259 227 229 263 245 275 247 227 226 231 231 247 282 222 277 256 237 241 278 248 230 240 250 282 259 263 258 244 226 249 242 258 268 261 261 237 266 223 255 255 267 243 238 245 209 258 239 258 234 272 232 233 247 244 267 283 235 266 234 237 255 232 277 273 255 243 276 247 266 273 277 262 265 266 288 226 256 244 261 276 250 234 263 294 221 293 278 263 256 265 263 260 267 265 225 279 281 236 246 258 237 244 247 283 245 281 284 262 278 255 255 243 263 264 246 226 268 291 223 240 240 246 255 264 239 264 247 260 243 237 272 232 261 249 259 219 283 258 216 241 256 240 268 233 243 243 277 260 240 267 276 243 256 214 231 272 239 237 238 248 232 260 241 243 242 241 249 233 263 231 237 246 226 240 231 281 235 260 225 233 236 260 284 242 235 240 280 220 227 241 239 244 233 255 232 243 261 226 256 272 241 223 228 261 242 262 214 246 236 270 225 236 232 263 264 227 247 246 265 286 278 258 234 227 247 210 259 232 240 261 220 259 234 240 255 216 256 234 222 239 229 236 244 231 227 264 233 245 216 256 242 233 260 235 241 260 258 229 260 271 240 242 218 263 256 240 274 235 241 262 275 203 233 246 227 242 243 246 263 264 255 257 219 237 257 242 235 235 262 266 238 247 206 238 227 218 230 240 238 273 267 241 243 221 238 230 239 236 247 237 205 237 240 250 247 257 232 233 233 241 223 227 245 244 206 245 243 258 262 264 229 260 260 243 222 226 237 247 209 242 229 242 216 218 232 244 231 243 259 233 264 219 226 262 263 237 255 225 240 208 269 258 234 255 240 290 207 235 230 245 241 262 236 241 263 242 235 239 260 241 243 246 244 269 244 249 229 280 248 248 264 245 255 263 245 255 222 263 235 236 266 271 255 247 263 237 240 240 236 261 260 275 255 229 241 280 297 245 233 231 256 218 227 243 236 244 257 260 234 262 239 269 212 237 255 244 243 257 264 276 279 271 249 247 264 239 241 277 240 220 240 238 231 230 264 244 267 233 264 234 233 231 299 246 209 258 213 266 262 240 256 256 272 234 233 272 227 244 272 236 255 232 237 248 262 240 198 268 244 234 219 237 234 287 203 238 219 220 226 258 225 234 260 273 227 255 240 228 239 221 214 286 228 259 259 221 248 262 232 241 248 230 248 232 245 251 261 237 234 244 235 240 256 232 244 258 235 233 238 268 221 205 265 243 246 226 236 274 235 243 221 255 241 263 223 232 235 238 248 237 226 225 238 247 219 245 230 234 225 239 237 247 234 267 233 215 223 260 246 272 213 226 257 233 282 241 260 229 240 241 259 222 246 260 225 238 255 250 267 281 240 256 237 241 270 226 265 237 257 263 262 265 222 215 239 226 263 248 227 232 259 248 237 212 228 219 262 264 259 227 243 245 275 266 202 232 249 244 241 282 242 255 229 238 208 236 264 232 266 249 260 238 236 246 239 242 236 220 255 235 235 247 223 267 232 234 228 231 255 223 255 237 231 268 224 267 264 265 205 270 215 238 232 209 224 257 249 267 226 216 244 231 224 229 259 222 234 243 286 242 202 242 244 231 265 234 270 216 216 249 264 247 257 232 241 240 226 234 265 256 265 231 256 259 256 244 219 223 242 240 242 233 265 222 257 257 258 243 221 206 245 243 219 226 244 242 220 268 228 255 228 258 241 231 255 273 233 220 218 239 280 249 234 225 224 258 246 213 249 231 243 246 240 213 231 232 262 235 239 255 247 275 263 269 213 243 234 262 200 237 262 221 240 237 266 248 236 237 255 275 264 259 265 215 244 240 238 218 243 237 232 228 247 270 231 246 271 263 232 225 247 256 225 278 259 217 261 237 225 240 225 231 236 272 244 262 250 217 215 225 236 242 243 247 268 268 256 225 235 240 239 260 240 266 257 247 257 206 246 256 237 235 242 240 274 244 224 235 238 256 241 229 255 225 224 269 221 274 231 220 238 245 242 266 247 245 230 235 271 224 277 186 263 264 234 242 240 264 237 245 218 267 266 245 236 261 235 271 261 260 301 269 229 260 222 250 236 203 236 227 242 249 248 238 256 279 236 233 234 228 266 245 262 218 232 250 245 236 238 247 238 221 246 233 257 215 221 243 262 204 219 267 248 228 214 261 249 232 234 264 239 255 262 255 243 247 244 259 280 264 256 240 223 278 222 235 259 229 236 257 239 219 240 244 243 225 224 247 213 241 232 243 243 234 268 214 242 238 240 230 268 244 248 268 271 242 204 236 231 232 259 267 236 241 222 247 230 233 224 285 278 281 235 212 236 237 246 248 222 234 226 247 220 235 246 242 247 258 231 229 259 241 247 225 258 265 226 260 216 233 259 246 224 229 267 228 233 248 239 238 243 243 258 222 228 265 238 211 233 249 243 234 238 245 259 244 213 259 237 224 244 255 259 270 256 211 237 202 237 259 228 261 226 245 199 228 228 250 232 234 243 270 243 245 264 226 246 246 244 262 235 231 258 227 247 255 231 229 237 229 270 237 227 239 274 257 213 231 230 213 241 249 250 232 263 250 224 261 239 258 262 247 246 271 273 212 258 257 247 236 232 233 266 266 279 266 272 259 280 246 250 248 262 240 256 223 236 233 270 225 271 247 258 221 214 269 232 242 258 236 225 233 268 237 243 274 270 274 243 275 231 233 227 263 244 230 257 235 263 234 227 240 227 238 242 222 242 229 236 265 257 256 222 229 244 236 242 210 260 240 243 265 238 261 268 213 240 246 223 262 246 262 241 231 237 262 228 242 230 258 258 232 221 261 271 244 207 227 240 230 249 245 227 222 225 218 225 220 225 223 246 240 262 245 272 250 238 258 230 234 241 215 231 242 218 262 244 228 237 245 231 219 262 233 272 264 255 286 230 242 235 222 234 191 230 276 268 213 235 247 248 227 234 263 262 213 220 242 283 255 230 246 241 272 259 276 238 241 202 260 262 265 238 227 220 219 274 255 232 233 224 232 233 235 269 238 265 246 218 266 225 240 269 247 261 235 204 248 256 283 243 233 257 245 258 214 255 227 230 237 215 240 223 244 215 238 211 232 268 229 240 240 247 224 228 225 249 228 263 224 228 260 261 225 247 263 220 221 232 247 206 233 233 217 265 240 219 256 224 226 256 221 215 244 266 241 238 218 265 248 236 244 249 249 211 268 258 265 223 231 231 225 257 249 241 234 267 277 248 247 219 241 268 230 246 237 217 237 223 246 232 242 243 228 243 230 230 276 248 266 247 234 221 211 258 255 283 230 199 220 243 239 226 262 255 227 226 248 271 239 242 230 236 245 269 247 224 229 265 225 264 237 246 232 261 216 242 248 260 239 248 209 263 228 236 224 259 247 260 224 257 243 280 222 217 189 259 247 238 225 222 256 255 215 233 232 242 232 236 245 221 266 271 259 249 241 229 236 227 255 221 198 240 237 245 228 267 241 256 244 235 235 219 227 223 234 235 216 235 265 215 232 217 199 223 233 231 249 230 202 236 220 228 242 263 256 219 255 257 240 245 224 259 219 231 223 195 235 243 243 249 236 246 220 244 218 221 230 224 216 246 220 244 245 220 234 221 272 242 228 222 255 246 216 242 243 237 235 272 258 247 247 276 227 247 226 225 217 259 240 223 245 234 230 246 239 239 236 233 244 213 267 259 241 220 255 249 233 217 222 216 245 234 240 221 262 261 242 234 223 235 226 264 255 263 272 242 232 229 233 208 204 196 212 235 186 240 237 250 222 279 236 228 235 247 249 247 233 214 240 285 238 245 214 245 261 223 287 220 243 249 249 235 234 266 246 237 241 246 248 215 215 261 246 228 224 198 217 245 260 237 242 291 238 214 265 235 241 246 211 217 203 262 236 217 218 237 215 231 264 243 224 245 229 222 262 267 239 229 246 231 250 256 272 231 227 237 265 238 231 238 243 227 235 245 203 257 217 242 214 245 240 255 238 266 270 226 249 255 231 229 257 222 243 228 270 222 279 247 236 245 242 247 261 257 230 238 212 270 264 244 260 258 222 229 224 239 230 274 290 255 259 232 242 226 259 279 246 232 268 228 261 264 232 256 275 264 270 283 225 244 242 255 242 259 262 267 261 240 272 277 260 259 242 289 283 278 243 322 257 266 327 270 272 244 246 285 285 268 279 291 279 268 306 270 276 249 288 288 316 264 308 275 239 279 270 275 260 283 275 301 270 267 301 298 287 290 281 279 293 273 288 270 250 270 310 262 283 271 255 289 272 297 276 221 292 276 241 234 242 267 236 245 247 268 268 266 255 222 275 259 273 270 246 230 268 239 258 256 257 238 234 237 278 259 259 243 246 233 265 231 291 240 223 262 247 274 260 240 223 219 237 203 234 270 237 240 262 242 250 256 238 298 226 244 230 226 229 242 234 214 263 255 240 270 268 249 219 255 227 231 266 222 235 255 271 226 223 223 262 231 218 227 217 258 228 261 219 265 233 250 258 238 223 266 227 239 277 230 238 265 229 256 266 224 273 239 245 241 268 212 239 243 222 237 246 221 222 241 249 227 262 246 255 266 256 245 222 245 281 203 262 240 285 258 244 221 220 230 236 233 265 238 233 236 246 247 246 243 260 229 238 235 282 223 236 219 217 279 247 248 246 256 230 230 240 255 229 242 246 257 206 216 275 249 244 233 240 239 231 220 245 232 240 234 198 236 247 231 275 209 256 244 217 226 186 235 240 265 248 228 240 261 232 244 241 221 272 237 215 236 231 232 248 211 227 264 227 256 248 267 227 224 262 228 258 275 222 244 218 256 240 239 224 265 238 233 231 257 274 221 247 241 208 246 220 213 226 208 229 242 242 240 231 202 238 222 221 208 221 259 236 235 269 213 236 232 203 229 213 256 227 222 224 261 228 226 230 235 223 238 218 233 238 246 265 214 247 215 241 229 218 236 215 225 245 221 250 262 247 261 248 238 226 236 249 270 227 224 237 217 229 213 240 203 208 234 235 225 242 244 213 223 242 222 219 245 237 222 233 258 257 235 233 222 214 244 231 225 255 241 238 242 242 235 219 243 232 228 242 210 245 209 231 236 257 206 242 271 262 227 248 201 215 239 255 205 235 231 258 258 255 246 230 258 234 241 221 215 246 223 234 223 221 234 238 219 239 265 226 222 185 218 239 246 228 204 237 239 235 231 264 228 226 202 244 229 227 268 226 239 219 192 230 261 242 231 261 228 229 274 237 238 258 214 222 259 231 212 210 243 239 231 231 233 240 244 222 257 228 226 238 227 217 263 234 229 213 217 204 230 229 235 259 235 263 259 271 264 216 222 209 241 224 206 239 223 240 231 220 241 243 226 228 242 235 225 197 237 263 220 240 226 247 237 229 211 262 250 247 240 216 256 212 236 239 246 196 256 219 230 263 249 264 238 258 233 226 276 245 238 255 232 237 231 239 231 257 227 195 227 239 233 230 227 234 274 262 221 223 217 235 234 213 238 210 220 208 224 237 255 230 249 239 238 238 241 256 192 237 239 229 231 222 226 238 212 261 256 243 244 232 241 226 244 221 218 207 232 230 240 264 232 223 208 243 241 247 222 228 232 262 209 251 235 216 218 224 245 242 242 279 235 231 217 255 218 235 237 205 229 205 233 235 238 229 207 237 259 231 244 226 223 232 208 237 222 244 229 227 230 263 243 221 249 222 243 235 246 229 212 240 257 241 248 211 216 226 232 234 228 206 229 239 222 260 260 232 209 218 261 232 238 233 224 240 249 214 222 234 232 238 225 240 247 226 261 248 212 236 221 265 232 213 241 239 229 236 249 239 247 239 219 242 258 239 258 224 214 223 224 216 236 234 234 229 200 233 227 215 250 258 236 258 233 231 229 219 237 229 203 240 241 239 228 222 221 226 205 213 246 240 234 229 229 226 230 245 237 214 224 256 205 249 224 257 231 208 226 208 248 234 219 229 231 236 245 228 195 272 207 233 255 239 231 233 243 224 212 245 225 242 239 259 234 220 228 231 224 232 240 210 267 226 245 244 244 218 259 224 235 226 228 221 217 265 203 241 217 227 207 237 213 234 221 246 246 240 219 262 239 237 232 228 255 242 216 220 248 224 231 211 228 244 267 245 221 245 241 266 240 234 224 241 256 222 240 196 256 231 256 225 227 247 243 257 234 235 238 217 215 245 206 228 227 242 243 236 243 220 224 256 223 256 246 238 220 241 260 229 236 267 189 270 236 223 214 212 217 229 244 206 229 243 246 248 187 232 246 236 230 202 233 206 270 221 265 212 229 225 282 245 212 241 216 218 239 222 248 247 187 228 190 225 229 231 236 263 236 217 231 222 238 225 236 226 230 208 225 229 259 256 195 266 244 231 219 225 234 242 225 236 239 241 256 219 257 261 233 261 228 244 238 259 240 227 228 221 230 220 239 248 247 244 209 237 244 267 229 216 231 266 243 204 236 233 226 227 217 243 233 219 266 257 218 225 239 260 222 232 230 229 218 235 233 218 245 237 219 223 235 217 257 227 247 220 207 246 215 239 235 258 196 221 216 238 244 265 231 237 223 227 228 243 255 258 265 214 231 211 245 261 233 228 242 214 224 222 231 264 249 232 227 229 234 258 231 227 238 213 223 257 233 226 214 265 201 228 268 238 222 245 225 234 244 234 228 264 238 227 219 279 257 248 249 236 247 273 237 232 244 243 259 286 261 219 197 222 271 238 228 227 220 213 215 235 224 239 237 221 239 205 272 236 235 226 240 232 226 243 243 237 246 218 245 220 239 217 219 250 231 238 232 207 222 239 230 244 241 217 250 216 217 239 193 239 270 261 219 236 242 241 219 219 239 268 258 231 233 229 250 218 261 212 228 235 257 223 212 257 220 222 256 218 266 241 263 260 212 239 240 220 230 234 257 240 232 215 221 235 264 266 247 222 227 240 246 222 243 233 231 233 228 231 239 224 238 242 236 218 231 237 237 271 243 219 237 229 243 219 228 238 266 234 232 229 224 240 242 235 195 258 239 236 237 235 207 227 227 231 229 230 211 230 245 243 207 230 255 212 256 263 228 237 218 248 277 231 242 226 237 256 259 217 247 243 232 232 227 236 239 245 232 228 222 239 224 238 231 214 234 267 225 226 221 206 242 222 224 232 226 236 223 217 202 267 237 235 221 239 270 259 212 242 250 226 220 255 245 214 214 245 225 218 228 245 241 242 231 214 222 238 220 211 212 223 218 248 250 208 245 230 223 234 227 232 213 237 207 219 227 248 222 261 238 207 209 222 190 237 268 248 262 234 241 212 226 249 232 225 223 232 233 232 224 265 200 226 230 211 264 239 243 234 247 228 224 235 203 215 226 210 255 226 264 227 225 205 245 245 232 235 217 215 233 244 232 230 244 192 241 221 262 269 227 234 205 229 246 246 238 233 225 235 220 219 202 239 237 238 256 243 234 225 223 223 274 243 240 228 225 271 215 245 239 234 230 222 260 204 236 232 244 233 230 211 230 219 242 224 246 233 211 221 226 213 234 223 224 232 227 233 194 232 214 228 208 242 211 244 208 230 235 220 210 222 212 235 226 209 220 194 214 242 232 208 223 258 258 236 213 212 230 269 220 218 217 222 232 224 218 217 231 221 261 237 244 250 230 232 264 229 229 219 227 232 256 261 222 239 200 248 225 212 242 229 233 232 235 237 220 226 216 228 234 243 227 235 235 229 215 241 214 212 248 256 241 203 245 225 207 213 231 274 258 240 242 226 259 239 228 249 209 246 232 229 249 235 241 239 228 256 237 220 220 260 246 220 215 234 225 249 237 238 210 275 245 248 241 234 241 238 264 245 225 239 236 218 223 222 230 234 217 223 260 198 249 234 229 224 226 271 207 235 258 230 241 235 237 219 262 220 229 235 224 244 224 246 235 247 262 279 257 231 277 239 237 244 279 225 228 246 226 207 215 230 217 244 239 246 242 257 245 229 265 267 242 236 246 258 211 248 232 235 261 282 256 243 240 209 239 261 233 261 245 247 225 212 260 243 222 248 239 247 268 267 217 259 260 263 256 263 259 263 232 228 238 243 249 274 218 222 261 243 268 265 236 248 281 222 240 242 223 261 265 230 224 267 220 226 245 224 255 223 257 263 232 227 256 244 244 227 269 223 220 213 233 261 244 236 265 234 272 221 227 223 244 255 218 211 266 240 267 238 260 249 238 235 264 236 243 229 210 221 224 246 225 275 210 248 213 244 274 243 235 261 198 229 230 241 249 231 235 242 257 230 225 237 221 231 234 224 215 258 244 218 242 214 240 248 235 274 226 238 261 248 225 263 222 237 263 256 239 244 235 241 212 235 240 238 219 246 246 228 232 238 219 255 232 211 213 256 211 233 239 274 229 228 261 244 222 223 242 236 246 231 261 214 235 256 208 242 247 233 223 227 230 249 260 224 257 238 240 283 228 267 267 221 263 247 220 224 259 258 222 243 229 236 233 240 217 230 260 225 261 204 238 216 236 259 225 243 232 203 239 236 272 239 264 224 214 248 224 223 235 242 273 238 257 217 231 208 259 220 256 217 255 255 211 225 242 216 246 228 230 247 258 231 248 235 229 246 216 227 232 226 205 216 231 192 225 227 225 233 230 248 238 239 227 220 218 235 241 227 233 229 256 235 235 227 248 279 246 234 220 230 245 255 219 260 242 249 243 210 224 233 268 239 222 232 262 230 235 230 255 228 247 257 220 265 272 242 237 232 243 230 245 234 217 241 244 231 244 270 243 274 257 231 240 249 246 268 246 230 250 228 231 241 256 219 226 225 259 213 264 257 226 220 229 262 239 232 245 246 244 256 207 230 277 219 239 239 248 235 241 231 233 245 245 227 230 234 234 228 246 237 256 246 264 238 233 248 217 229 259 270 235 255 233 218 228 232 227 241 220 237 243 210 229 225 231 242 242 238 220 232 241 236 280 239 239 225 231 241 225 244 242 221 245 247 223 218 220 241 233 223 218 229 260 243 232 261 266 227 242 247 260 240 247 255 245 214 240 241 238 245 224 242 245 279 242 229 233 234 260 230 259 260 247 245 218 227 241 237 263 229 250 215 248 221 235 238 269 259 248 273 227 241 225 237 263 241 236 228 237 226 273 247 234 235 229 268 238 216 234 257 245 267 230 221 244 233 242 265 222 257 231 259 230 258 247 266 226 227 240 242 235 235 258 266 248 244 215 213 264 246 230 217 263 246 227 276 255 257 275 271 229 232 220 243 238 256 226 248 241 256 233 241 238 244 240 237 235 225 256 262 237 248 236 248 223 223 233 248 228 240 218 248 258 231 226 245 265 256 248 244 247 250 247 229 292 273 240 233 246 266 217 237 247 216 233 245 231 225 235 260 241 238 261 266 264 223 216 237 223 258 237 243 245 261 211 240 226 280 261 226 235 225 219 238 274 219 246 220 237 258 224 236 246 226 209 246 239 237 277 241 237 249 257 280 272 244 246 238 239 227 247 213 230 235 258 241 227 245 239 246 271 248 262 250 245 241 240 231 246 239 244 237 249 207 210 240 230 244 234 212 249 229 233 236 211 245 245 267 203 255 261 224 241 229 218 271 243 230 218 223 239 264 260 255 246 270 256 230 260 248 233 243 226 231 244 225 224 233 237 211 216 246 240 232 227 240 219 232 244 243 247 275 242 219 233 238 273 228 228 295 234 236 233 230 228 257 216 229 242 260 243 229 277 228 219 212 238 243 237 233 234 248 202 243 233 230 215 243 238 235 224 229 228 242 256 242 241 218 239 241 232 220 224 238 274 222 258 255 229 247 256 258 236 238 190 204 249 223 239 244 262 242 234 233 231 235 225 241 243 215 209 255 257 237 234 228 223 235 243 240 250 247 226 265 211 224 219 242 230 232 223 201 235 225 241 226 233 234 259 238 258 234 233 256 230 212 205 247 239 237 226 214 229 224 268 214 205 244 230 201 229 269 233 257 234 243 218 215 232 236 236 256 232 229 225 225 228 225 260 237 212 243 234 242 239 216 261 246 241 216 245 223 235 246 235 258 225 259 215 228 219 238 228 206 255 235 228 227 244 243 241 227 214 245 237 233 234 262 241 245 237 223 227 245 231 255 226 237 209 219 217 218 247 247 236 236 258 223 265 222 240 245 256 263 220 250 250 244 228 243 227 234 244 257 235 256 226 216 244 237 255 240 255 246 236 255 243 230 239 228 231 268 231 278 230 245 244 245 264 241 235 236 243 192 238 235 246 233 224 214 219 248 236 268 222 267 233 237 230 226 217 215 261 268 255 272 229 228 225 221 246 206 269 209 238 208 243 260 246 227 262 242 261 218 216 234 230 237 235 242 216 224 245 255 242 242 213 229 231 263 247 217 195 228 228 245 255 236 242 236 246 216 248 235 206 204 241 224 238 245 273 230 261 231 235 249 232 239 240 250 228 233 229 260 238 225 214 234 239 246 229 218 267 238 276 224 249 218 249 256 242 227 234 266 227 248 229 215 228 244 271 249 260 238 256 242 221 224 241 256 226 256 235 224 268 249 223 227 250 272 237 216 232 205 223 260 222 225 218 260 232 231 210 259 209 242 246 235 228 230 241 194 230 256 228 218 220 244 247 255 234 258 268 209 229 260 228 230 243 235 248 214 226 221 243 264 221 257 247 261 247 260 226 238 209 264 223 226 243 226 225 262 226 222 229 266 257 246 258 241 236 239 250 262 218 266 236 243 262 227 239 279 215 215 285 266 227 224 247 227 250 207 238 248 271 263 236 231 248 223 242 242 234 234 239 232 255 236 237 236 272 249 255 288 228 232 264 228 238 222 230 250 260 238 257 274 264 240 229 255 211 250 233 244 260 208 238 245 257 223 246 260 221 266 255 222 246 236 224 236 259 248 229 269 230 228 220 246 223 248 240 261 221 245 257 219 259 259 217 234 240 274 222 217 266 237 235 206 244 208 245 255 239 247 232 255 243 257 224 209 238 212 238 215 244 239 279 238 229 224 201 241 266 218 232 239 233 218 263 262 229 232 242 267 236 233 243 240 247 246 235 244 244 259 272 243 206 244 223 246 232 228 245 235 218 217 255 239 217 205 256 237 245 221 229 245 220 256 238 243 246 225 228 235 217 278 260 272 226 242 250 259 223 225 265 236 247 240 237 227 287 223 256 265 224 232 247 227 225 245 239 255 232 237 229 243 235 243 231 245 233 240 222 234 263 230 266 227 234 230 227 228 229 244 236 240 225 221 246 217 220 264 285 246 264 255 246 231 243 222 244 255 263 257 229 222 236 227 278 258 278 234 225 223 244 219 226 246 256 231 246 221 226 237 245 243 262 256 235 226 247 226 224 262 242 220 235 219 235 263 229 236 221 236 259 234 246 225 229 263 214 256 220 244 262 234 226 230 230 234 247 246 264 214 213 244 235 238 263 216 258 222 225 231 242 227 223 269 223 233 244 237 221 239 247 243 219 240 226 234 208 255 244 258 243 226 215 267 241 226 220 272 223 199 230 244 236 261 220 237 239 235 244 239 245 224 238 220 232 255 235 245 225 229 230 246 234 274 239 244 227 216 225 257 258 258 242 225 246 230 235 219 222 274 249 260 213 217 261 246 240 223 259 207 268 255 243 236 245 232 216 229 226 245 231 263 202 248 262 230 238 244 230 240 264 214 208 216 228 251 261 232 226 243 228 238 265 234 248 233 238 237 245 248 244 230 243 228 274 228 222 234 222 249 226 239 250 227 239 256 243 265 247 259 214 271 239 230 229 217 230 264 258 211 224 221 255 243 234 231 250 244 227 226 271 242 216 228 215 274 234 282 259 272 234 245 245 240 243 235 233 234 240 234 259 247 257 237 259 271 220 245 242 275 225 240 237 282 246 216 237 266 264 236 281 249 223 259 246 227 272 272 270 260 242 231 238 247 226 246 258 238 266 239 239 267 282 214 234 215 262 237 262 255 274 244 271 231 238 244 235 263 220 277 238 231 259 229 243 238 273 242 269 240 286 260 268 287 246 223 277 229 232 240 236 264 273 230 271 257 261 247 275 272 233 241 245 237 237 260 262 233 227 249 273 265 234 263 265 271 274 246 287 241 243 263 248 248 261 246 283 244 265 272 247 257 265 231 262 220 260 255 257 240 237 240 245 243 295 226 278 260 258 240 228 249 237 213 275 225 243 239 242 241 241 244 258 232 245 284 255 285 236 269 236 211 249 240 241 265 261 218 245 238 213 269 228 219 244 236 238 215 256 227 237 236 243 218 238 236 262 224 229 234 264 229 239 219 225 259 233 258 246 256 276 235 247 222 234 211 261 245 267 233 234 264 234 241 229 230 250 220 245 216 265 218 218 238 258 210 220 243 228 245 233 245 220 235 229 224 230 208 233 216 235 234 270 268 245 247 236 236 247 243 265 260 231 212 230 233 235 223 224 212 232 265 262 249 242 259 271 246 257 246 265 241 263 196 228 213 261 257 272 217 255 240 230 238 215 245 214 225 232 231 216 247 220 249 237 258 242 255 266 246 261 234 240 246 231 249 277 232 235 235 256 201 230 239 221 283 241 238 235 231 240 216 239 259 234 233 266 247 216 227 260 240 228 229 274 265 222 264 209 220 230 225 243 227 234 232 234 246 234 262 261 246 263 275 230 226 247 249 263 233 229 202 270 237 245 236 231 262 238 240 247 222 256 223 231 196 255 224 236 236 260 226 196 256 229 257 266 236 212 217 235 249 221 245 214 243 223 218 223 219 239 230 228 268 263 211 235 214 228 248 247 248 241 219 238 224 214 238 244 242 234 255 231 226 241 228 259 220 208 228 233 237 260 248 243 242 244 228 223 202 222 264 240 227 241 225 260 228 236 282 240 256 246 268 221 215 240 231 228 228 279 244 234 227 229 238 244 245 212 241 241 272 239 240 237 226 248 239 225 210 241 238 225 246 222 210 234 216 214 218 225 220 228 266 240 225 231 245 201 231 260 257 219 227 237 236 243 246 225 261 221 223 242 237 239 237 265 250 271 237 243 248 242 232 231 219 236 240 267 263 200 229 240 222 221 270 218 216 238 237 281 248 258 225 242 264 210 228 228 263 244 257 263 249 237 275 233 248 259 241 236 227 257 271 267 235 226 245 219 222 228 220 219 242 217 196 227 243 211 248 247 228 226 234 216 248 257 263 273 262 221 215 217 232 263 227 212 240 230 257 226 231 231 204 208 250 249 246 246 240 248 230 230 241 220 239 207 228 215 256 223 265 244 259 239 248 224 225 244 238 257 211 228 215 224 241 223 246 245 278 263 235 242 224 273 214 245 240 275 247 221 202 239 244 227 227 226 249 222 277 242 264 237 221 255 241 238 231 227 240 235 212 215 268 223 244 244 272 246 225 258 237 260 236 217 222 236 246 232 255 228 236 239 261 231 227 245 256 239 210 261 230 268 214 216 250 249 211 248 238 231 260 239 235 241 245 235 234 240 211 241 235 243 259 246 227 227 218 235 215 245 243 232 233 245 258 244 216 233 270 239 256 214 230 246 261 248 256 224 247 230 242 229 239 229 239 210 224 250 233 234 256 212 266 232 221 255 240 245 221 236 244 277 223 266 219 240 229 236 265 242 263 226 255 239 239 225 259 242 245 247 237 238 262 237 242 266 266 286 231 219 264 268 267 262 233 236 222 279 242 237 260 239 231 234 229 241 255 264 268 286 255 263 223 258 249 237 256 255 230 239 229 225 238 262 215 225 239 263 241 267 271 271 230 234 240 239 241 234 259 244 271 246 256 234 249 267 270 272 262 231 277 231 236 226 232 262 240 283 229 237 235 240 247 255 243 244 229 249 244 221 232 248 248 238 245 233 258 271 242 229 256 262 258 237 261 245 248 241 245 233 273 256 204 271 237 249 242 261 229 256 256 268 223 273 266 226 249 240 233 208 279 259 263 245 240 247 245 274 217 255 227 234 235 246 246 263 269 234 244 279 240 211 255 237 234 259 246 278 264 238 235 223 244 241 246 237 293 266 260 257 273 235 270 278 275 263 242 280 275 256 237 246 263 269 266 262 241 222 245 255 264 235 267 223 259 265 229 241 246 283 267 280 236 265 246 283 230 258 229 229 227 274 246 288 256 276 267 287 270 259 234 260 266 239 240 290 243 255 267 265 233 258 266 255 280 259 226 235 255 231 248 243 256 265 255 244 273 232 259 240 258 282 230 243 258 261 238 249 238 257 250 234 266 230 245 259 273 277 256 217 247 270 225 245 266 269 230 275 255 257 234 234 275 271 284 220 240 268 286 273 257 268 231 245 238 278 255 239 262 269 249 262 239 239 240 227 295 226 293 227 256 262 266 218 275 260 232 277 270 261 241 243 290 259 256 269 261 259 265 239 291 259 264 274 228 278 260 234 255 256 272 235 228 282 267 264 277 232 223 264 261 270 247 249 248 224 273 235 261 274 256 223 279 260 258 261 280 296 260 256 272 239 267 258 243 275 261 234 283 288 220 272 255 244 279 257 268 266 272 271 264 227 232 247 273 276 238 266 234 238 236 234 228 267 221 266 244 232 263 264 243 267 249 246 240 284 278 257 259 262 260 260 281 270 246 255 282 236 264 261 277 256 261 269 259 258 277 228 244 247 256 275 263 260 258 265 272 276 242 246 293 263 259 234 240 297 246 257 242 235 278 241 261 232 235 272 263 261 268 231 242 265 263 265 259 231 240 241 255 236 257 264 249 235 238 280 238 259 259 278 212 264 269 271 235 256 223 263 272 236 269 257 268 276 226 241 281 227 270 242 250 258 261 261 278 238 233 246 284 302 277 289 248 276 262 233 276 262 262 264 264 258 289 245 250 276 269 267 263 271 233 224 258 280 243 246 285 257 241 246 262 263 235 259 274 257 261 257 265 248 245 279 262 243 263 242 284 248 237 241 260 287 246 239 237 258 264 263 279 241 259 231 272 235 217 229 237 228 246 262 260 258 265 271 242 257 241 246 245 297 264 244 271 258 272 263 286 232 223 266 229 228 258 231 271 221 245 268 259 235 257 248 258 257 243 270 238 227 271 246 216 265 228 277 260 242 231 244 262 249 285 262 255 249 272 246 229 232 262 267 259 266 246 218 240 257 278 288 244 246 259 280 270 264 261 270 243 298 237 268 256 246 269 280 246 256 202 264 244 272 269 292 283 248 229</counts>
			</dataPoints>
		</scan>
	</xrdMeasurement>
</xrdMeasurements>