File: data/XRD/XG-Vakuum/XG-800/W6821-1C_XG_Vakuum_800.xrdml
<xrdMeasurements xmlns="http://www.xrdml.com/XRDMeasurement/2.1" xmlns:xsi="http://www.w3.org/2001/XMLSchema-instance" xsi:schemaLocation="http://www.xrdml.com/XRDMeasurement/2.1 http://www.xrdml.com/XRDMeasurement/2.1/XRDMeasurement.xsd" status="Completed">
	<comment>
		<entry>Configuration=Factory configuration, Owner=User-1, Creation date=7/8/2013 4:01:53 PM</entry>
		<entry>Goniometer=PW3050/65 (Theta/2Theta); Minimum step size 2Theta:0.0001; Minimum step size Omega:0.0001</entry>
		<entry>Sample stage=MRD Cradle; Minimum step size Phi:0.01; Minimum step size Chi:0.01; Minimum step size X:0.01; Minimum step size Y:0.01; Minimum step size Z:0.001</entry>
		<entry>Diffractometer system=XPERT-PRO</entry>
		<entry>Measurement program=C:\PANalytical\Data Collector\Programs\Jorrit\2thom\_absolute_2th-om_10-130deg_PIXscan_56min.xrdmp, Identifier={15BCCF57-2807-42BD-B5B9-ECC0B3DC9284}</entry>
		<entry>Batch program=C:\PANalytical\Data Collector\Programs\SimonL\batch3x_2thom_10-130°_z9.1_x0,10,20_y0_57min.xrdmp, Identifier={1E956750-2741-41FB-B242-F9B1C20E21A8}</entry>
	</comment>
	<sample type="To be analyzed">
		<id></id>
		<name></name>
		<preparedBy></preparedBy>
	</sample>
	<xrdMeasurement measurementType="Scan" status="Completed" sampleMode="Reflection">
		<comment>
			<entry>_absolute_2th-om_10-130deg_PIXscan_56min</entry>
			<entry>PHD Lower Level = 4.83 (keV), PHD Upper Level = 11.27 (keV)</entry>
		</comment>
		<usedWavelength intended="K-Alpha 1">
			<kAlpha1 unit="Angstrom">1.5405980</kAlpha1>
			<kAlpha2 unit="Angstrom">1.5444260</kAlpha2>
			<kBeta unit="Angstrom">1.3922500</kBeta>
			<ratioKAlpha2KAlpha1>0.5000</ratioKAlpha2KAlpha1>
		</usedWavelength>
		<incidentBeamPath>
			<radius unit="mm">320.00</radius>
			<xRayTube id="1010048" name="Empyrean Cu LFF HR (9430 033 7310x) DK442154">
				<tension unit="kV">40.0</tension>
				<current unit="mA">40.0</current>
				<anodeMaterial>Cu</anodeMaterial>
				<focus type="Line">
					<length unit="mm">12.0</length>
					<width unit="mm">0.4</width>
					<takeOffAngle unit="deg">4.2</takeOffAngle>
				</focus>
			</xRayTube>
			<xRayMirror id="27010001" name="Inc. Beam Cu W/Si (parabolic MRD)" hybrid="false">
				<crystal type="Graded" shape="Parabolic">W/Si</crystal>
				<acceptanceAngle unit="deg">0.800</acceptanceAngle>
				<length unit="mm">60.0</length>
			</xRayMirror>
			<sollerSlit id="21010002" name="Soller slits 0.04 rad.">
				<opening unit="rad">0.0400</opening>
			</sollerSlit>
			<mask id="22030008" name="Fixed mask 4 mm">
				<distanceToSample unit="mm">220.00</distanceToSample>
				<width unit="mm">4.00</width>
			</mask>
			<divergenceSlit id="22010007" name="Fixed slit 1/8°" xsi:type="fixedDivergenceSlitType">
				<distanceToSample unit="mm">220.00</distanceToSample>
				<height unit="mm">0.19</height>
			</divergenceSlit>
		</incidentBeamPath>
		<diffractedBeamPath>
			<radius unit="mm">320.00</radius>
			<sollerSlit id="21010002" name="Soller slits 0.04 rad.">
				<opening unit="rad">0.0400</opening>
			</sollerSlit>
			<receivingSlit id="22010001" name="Fixed slit 4°">
				<height unit="mm">5.88</height>
			</receivingSlit>
			<detector id="7010017" name="PIXcel3D 1x1 detector" xsi:type="areaDetectorType">
				<phd unit="%">
					<lowerLevel>30.0</lowerLevel>
					<upperLevel>70.0</upperLevel>
				</phd>
				<mode>Scanning</mode>
				<activeChannelsEquatorial>255</activeChannelsEquatorial>
				<activeChannelsAxial>255</activeChannelsAxial>
				<pitchEquatorial unit="mm">0.05500</pitchEquatorial>
				<pitchAxial unit="mm">0.05500</pitchAxial>
				<readOutPeriod unit="seconds">0.135</readOutPeriod>
			</detector>
		</diffractedBeamPath>
		<scan appendNumber="0" mode="Continuous" scanAxis="2Theta-Omega" status="Completed">
			<header>
				<startTimeStamp>2024-10-15T10:59:47+02:00</startTimeStamp>
				<endTimeStamp>2024-10-15T11:55:50+02:00</endTimeStamp>
				<author>
					<name>PRO-MRD</name>
				</author>
				<source>
					<applicationSoftware version="6.1b">Data Collector</applicationSoftware>
					<instrumentControlSoftware version="7.0E 20130304">XPERT-PRO</instrumentControlSoftware>
					<instrumentID>0000000011142674</instrumentID>
				</source>
			</header>
			<dataPoints>
				<positions axis="2Theta" unit="deg">
					<startPosition>9.99826193</startPosition>
					<endPosition>129.99755682</endPosition>
				</positions>
				<positions axis="Omega" unit="deg">
					<startPosition>4.99913096</startPosition>
					<endPosition>64.99877841</endPosition>
				</positions>
				<positions axis="Phi" unit="deg">
					<commonPosition>0.00</commonPosition>
				</positions>
				<positions axis="Chi" unit="deg">
					<commonPosition>0.00</commonPosition>
				</positions>
				<positions axis="X" unit="mm">
					<commonPosition>0.00</commonPosition>
				</positions>
				<positions axis="Y" unit="mm">
					<commonPosition>0.00</commonPosition>
				</positions>
				<positions axis="Z" unit="mm">
					<commonPosition>9.100</commonPosition>
				</positions>
				<commonCountingTime unit="seconds">32.895</commonCountingTime>
				<counts 407 407 428 462 427 437 460 447 422 442 412 422 421 446 442 448 434 424 429 445 439 418 432 426 386 398 430 410 424 418 374 441 390 405 448 447 446 468 426 423 398 420 421 420 454 403 390 379 418 396 412 420 450 379 396 416 398 397 424 400 404 402 418 395 402 393 406 393 405 414 412 415 432 402 417 405 416 394 408 422 403 426 412 445 448 389 414 373 419 433 400 413 424 419 388 421 393 413 419 446 451 427 431 384 389 406 421 445 416 385 397 363 372 391 388 359 408 415 350 388 389 401 409 378 398 427 372 379 408 414 436 403 383 406 387 416 418 411 413 409 396 397 400 416 421 345 359 380 378 399 388 385 386 395 389 382 408 381 373 421 368 375 393 404 397 392 413 377 360 391 381 384 408 382 353 346 430 373 399 395 384 365 389 406 365 386 382 403 381 355 382 403 369 387 371 373 342 394 373 357 358 367 349 393 360 347 397 359 384 382 359 358 356 376 395 390 393 361 376 362 385 388 382 362 380 358 375 405 360 377 413 346 360 370 348 381 376 350 423 366 352 360 357 362 378 376 350 363 367 383 364 341 344 358 391 329 365 405 338 362 391 385 337 376 387 337 321 375 374 337 355 345 378 370 389 360 359 362 363 375 329 375 380 323 346 359 349 356 370 369 378 335 368 378 360 360 394 365 333 347 355 363 333 403 337 342 384 374 361 378 321 380 341 351 382 364 368 361 341 377 349 347 352 329 365 390 349 372 324 365 363 378 317 384 371 325 356 365 324 391 322 385 372 363 364 368 363 344 334 357 346 339 351 332 360 311 331 342 357 337 339 362 336 343 373 312 318 355 354 339 365 338 371 331 311 340 351 337 343 344 334 357 328 338 347 324 345 313 369 320 339 322 309 327 314 366 349 310 328 358 366 314 317 330 323 332 344 322 315 352 331 287 314 336 340 333 338 343 335 348 352 316 306 302 309 324 312 317 335 359 362 294 320 335 337 350 332 322 344 304 319 342 310 375 338 312 344 313 301 309 334 342 340 332 296 351 348 295 329 332 318 337 330 337 331 352 325 322 312 306 330 312 330 299 313 344 328 314 339 304 315 281 322 297 313 325 337 315 306 331 333 338 327 325 328 320 350 358 346 293 321 322 329 324 319 298 323 345 305 338 351 349 311 323 309 301 320 331 315 317 308 319 310 287 318 343 335 316 282 332 336 292 293 305 295 308 335 311 294 314 298 284 308 326 303 279 315 340 319 344 309 310 302 318 342 297 314 320 312 274 301 313 302 290 318 318 317 320 291 340 329 284 324 286 324 330 318 319 321 354 320 305 310 341 302 293 293 324 313 316 307 319 293 353 322 292 300 308 291 307 299 337 334 297 322 322 285 329 296 315 290 308 314 350 299 308 314 322 320 288 316 298 291 313 318 303 299 299 311 295 321 354 294 309 339 314 295 282 319 292 329 289 290 315 309 315 337 328 305 294 308 319 287 299 302 270 308 296 286 332 292 319 323 305 333 293 309 315 313 303 304 334 268 312 315 306 312 296 306 302 314 305 307 315 331 334 329 316 273 337 286 300 336 288 309 308 300 304 323 321 275 310 316 347 286 292 320 302 321 324 286 305 300 319 317 342 316 283 295 308 314 311 324 288 306 330 302 307 296 304 322 304 272 337 336 291 330 325 333 304 296 297 292 335 303 286 326 313 314 311 323 283 319 318 296 302 320 318 318 336 313 283 314 311 279 304 324 282 326 318 325 257 272 327 314 305 326 316 311 291 295 298 306 313 299 301 294 322 326 320 317 343 307 303 277 309 305 335 298 283 313 323 326 274 297 309 295 314 325 294 268 300 328 299 297 303 266 300 290 282 299 300 293 313 306 304 305 317 344 298 323 327 309 323 292 311 281 314 337 314 305 303 313 348 337 288 310 338 316 292 317 335 295 335 326 291 312 330 345 307 340 301 322 308 348 316 316 318 310 312 269 296 313 324 319 333 325 300 331 305 312 296 284 273 318 298 318 332 318 308 328 302 304 308 327 322 317 317 325 323 314 286 303 297 317 310 305 307 347 308 325 308 312 303 337 312 333 312 330 296 332 310 333 297 311 306 313 340 307 302 317 339 310 315 334 322 325 279 330 303 361 307 344 297 299 336 322 302 306 320 314 316 330 341 327 322 317 342 317 331 324 326 304 301 277 333 315 317 330 364 326 332 324 302 352 309 330 325 338 349 321 323 332 336 345 309 315 318 348 336 277 339 315 340 320 315 369 328 323 306 318 331 324 319 298 308 325 309 327 336 322 342 341 318 323 343 311 340 311 332 289 313 354 310 316 324 325 302 352 330 304 350 306 336 356 343 348 326 313 303 311 316 323 351 315 330 308 328 337 350 327 331 335 332 339 354 329 298 297 311 326 341 329 301 319 337 375 332 355 351 314 340 346 322 339 318 328 333 341 316 355 308 326 340 295 333 327 315 355 322 333 334 323 342 338 346 318 337 357 341 337 313 338 359 325 359 327 309 332 336 319 305 322 321 339 361 334 342 336 327 359 343 343 351 331 331 325 289 315 324 356 319 297 346 329 300 334 364 336 302 312 343 322 338 335 342 334 346 301 349 318 337 303 325 370 337 354 366 328 311 330 323 357 320 338 347 320 347 354 343 331 337 357 347 355 378 328 342 338 333 359 356 324 340 312 345 313 342 326 351 319 363 361 360 342 354 319 311 338 332 347 315 350 337 337 337 379 318 322 335 316 367 314 331 315 328 342 352 341 328 337 327 335 353 336 331 332 306 353 326 366 329 359 337 338 337 314 329 352 365 354 303 370 352 324 327 342 298 369 335 323 314 335 330 313 351 330 309 357 317 345 335 375 335 383 340 324 313 310 329 355 313 326 341 317 325 288 303 321 355 283 346 322 338 322 351 293 345 328 355 349 331 349 347 328 320 321 322 354 365 350 358 326 321 332 310 345 369 365 338 331 334 338 359 344 335 378 342 333 340 363 351 331 347 341 304 310 310 313 350 306 317 316 313 321 333 322 302 347 335 356 370 382 360 319 332 342 330 356 330 324 319 332 361 334 353 352 335 325 372 302 335 319 324 355 320 329 346 346 342 320 323 294 325 343 308 328 339 264 336 322 320 383 315 354 332 330 345 314 302 334 348 324 333 327 302 311 333 332 356 319 344 319 334 308 334 325 316 339 303 349 342 364 357 347 309 321 338 322 330 358 346 319 333 348 330 371 339 316 315 336 316 329 333 320 337 327 302 327 357 311 320 317 311 311 334 322 340 356 303 337 325 324 363 340 318 319 347 349 289 332 348 321 351 306 310 339 315 330 298 336 356 327 306 328 311 338 306 349 319 328 328 302 316 331 320 336 328 324 322 343 358 318 346 294 317 333 353 320 336 298 318 341 311 299 331 317 312 318 317 306 297 327 336 307 288 296 289 296 281 307 311 291 297 318 332 318 315 351 322 300 309 342 326 339 323 288 319 323 310 304 332 326 315 307 306 296 291 317 313 286 314 318 324 300 317 331 283 338 311 320 273 301 280 307 301 312 319 319 309 309 333 319 331 347 290 317 335 300 319 315 335 338 327 320 305 307 296 293 308 335 297 283 300 341 292 306 305 329 311 296 315 292 307 318 311 302 324 319 349 295 291 302 324 325 301 302 317 313 332 306 303 325 302 322 353 325 327 312 317 328 309 314 290 328 329 317 321 309 298 318 308 348 326 287 313 278 289 288 309 315 328 292 300 285 314 274 294 303 296 311 314 312 307 311 325 318 290 303 315 326 305 314 302 304 297 313 301 302 308 305 295 290 331 313 320 299 303 353 312 307 277 287 290 285 308 303 330 299 305 302 249 282 290 321 330 305 311 282 289 330 287 285 308 336 285 303 278 303 296 261 321 283 300 301 302 320 312 321 303 305 306 331 287 313 335 325 272 267 310 298 305 296 306 267 296 275 271 299 317 322 294 321 293 269 310 277 287 277 316 291 291 297 291 299 288 284 304 296 319 287 302 286 303 314 280 282 236 292 290 291 287 281 274 273 291 305 266 293 308 300 299 295 302 282 304 309 302 282 290 270 279 274 310 291 273 277 273 278 298 286 299 287 302 301 299 280 276 301 280 260 263 319 272 276 292 300 295 305 262 279 278 309 292 288 300 306 287 290 279 283 295 296 278 282 309 306 278 259 291 246 269 282 289 278 309 301 272 277 312 269 288 244 302 297 260 255 298 302 306 270 279 324 274 296 288 278 306 291 317 298 278 268 282 288 288 302 281 281 287 273 290 260 274 288 262 269 268 280 275 282 273 289 281 307 317 304 275 268 266 248 288 268 290 278 279 268 277 289 273 292 287 273 300 287 276 325 311 295 287 284 300 270 297 320 288 257 288 243 297 279 280 275 267 295 280 278 269 280 272 303 289 262 319 239 296 277 287 268 266 274 282 295 275 282 291 310 295 284 266 262 284 262 242 285 297 255 277 279 234 237 264 280 265 243 295 286 271 284 271 282 290 283 286 282 272 278 245 275 275 264 296 247 238 247 278 268 284 295 291 300 278 247 273 283 290 237 286 286 269 293 255 262 269 266 304 271 274 257 265 267 266 272 262 269 271 242 310 263 302 278 272 263 275 271 291 292 267 316 284 289 272 244 263 267 283 269 296 274 265 281 266 232 240 294 245 269 237 287 265 267 282 261 277 259 268 259 259 249 274 266 284 292 268 227 245 276 256 260 273 271 285 270 278 291 269 296 241 243 281 312 258 281 281 270 255 269 273 294 247 234 256 249 279 281 259 310 262 278 230 244 260 277 308 248 273 264 265 232 246 265 267 271 266 288 259 245 297 289 246 256 225 296 271 267 284 274 244 247 308 235 260 256 224 288 280 263 265 238 263 238 228 288 265 248 240 249 283 286 272 263 243 258 271 271 268 267 235 249 263 268 271 238 301 276 276 292 245 265 279 236 262 248 260 271 298 261 271 246 258 268 290 257 255 268 288 272 264 255 264 231 316 269 243 259 262 265 270 237 268 259 283 256 259 239 245 281 267 256 266 257 278 283 231 264 245 274 244 255 235 247 256 269 267 247 266 260 267 280 264 284 258 277 270 305 259 247 286 282 260 274 260 244 239 282 255 280 260 232 247 268 225 250 278 257 255 269 238 291 270 246 266 263 272 264 262 250 264 247 270 238 260 279 277 268 279 265 249 258 274 255 293 256 234 290 282 236 258 255 255 237 247 270 227 262 271 245 246 264 279 288 247 299 235 270 270 231 237 287 265 240 261 206 274 241 264 230 255 249 247 261 248 235 283 273 234 275 261 269 248 255 270 239 250 248 249 273 238 271 260 261 247 257 272 259 235 257 229 279 272 237 267 255 263 278 223 267 232 237 263 239 256 237 255 296 272 241 242 266 238 275 264 239 279 246 257 276 260 260 259 230 234 232 259 271 259 283 256 235 249 231 268 249 264 230 256 226 250 263 258 216 263 238 260 272 232 247 244 244 258 263 258 275 233 259 271 233 237 243 280 241 262 239 273 248 234 215 263 257 257 227 265 267 247 261 259 270 275 234 223 234 260 284 280 263 266 262 275 268 282 279 279 273 248 244 261 264 218 282 264 269 255 270 260 255 263 276 243 267 226 234 226 273 266 236 224 249 250 270 228 274 278 248 265 258 263 264 249 239 258 232 232 227 274 286 270 287 241 249 249 249 269 271 309 246 259 239 259 249 245 218 242 240 244 258 270 223 283 243 260 279 283 240 241 248 238 263 243 260 233 206 224 256 271 272 237 245 258 272 233 256 231 237 263 266 234 221 272 248 255 263 247 241 239 266 268 243 221 240 236 247 245 261 246 299 249 278 241 267 231 239 255 291 216 277 230 241 258 268 242 267 243 262 240 266 260 240 262 238 272 233 239 244 262 245 213 236 204 266 249 258 257 277 212 292 220 264 276 265 271 257 229 215 241 238 281 231 234 227 264 223 258 228 248 265 223 267 268 260 257 268 247 243 266 227 233 244 247 266 242 266 247 247 275 257 232 283 223 237 217 231 228 236 236 288 257 276 222 218 255 236 241 233 244 237 257 236 267 235 248 250 255 233 237 257 248 231 282 242 282 237 283 225 234 234 232 248 265 243 222 265 260 238 249 235 233 229 244 241 226 245 242 246 271 260 227 266 257 238 220 226 241 246 244 262 237 263 263 265 213 275 243 257 255 244 265 237 276 242 272 228 230 245 277 237 238 262 255 229 242 235 249 234 257 245 258 241 247 270 245 219 266 260 219 281 259 228 229 238 235 249 224 261 239 236 245 243 238 228 291 266 231 260 233 268 225 258 230 243 255 245 260 249 250 239 273 249 261 243 273 292 275 228 244 215 235 267 307 266 219 239 263 236 261 220 268 247 227 256 248 258 248 245 248 249 243 234 259 242 268 256 282 236 264 233 248 228 238 224 247 228 242 242 245 244 256 239 229 238 233 260 244 232 261 240 232 242 231 248 237 233 241 249 241 241 246 241 225 236 243 250 246 241 264 268 219 226 267 259 256 248 223 241 226 263 283 283 274 212 258 292 234 271 272 226 247 235 245 217 270 248 233 266 267 255 221 231 246 246 243 271 256 270 246 222 239 231 235 226 228 219 243 259 233 275 260 239 217 272 238 239 249 234 235 236 228 270 243 270 243 223 241 249 246 241 247 243 262 257 265 236 232 217 242 223 274 273 245 255 259 225 264 234 218 220 261 248 238 223 238 221 249 225 225 236 238 241 262 263 240 260 264 227 265 224 258 232 247 262 249 276 221 239 247 265 230 276 236 243 271 263 258 256 247 243 227 249 268 267 229 232 244 227 228 259 271 239 230 214 234 245 266 261 224 260 274 226 259 258 246 240 256 264 246 236 225 227 272 246 256 247 249 262 223 247 262 273 268 258 232 257 249 289 275 262 241 213 255 229 239 238 231 276 275 237 209 235 259 244 268 227 259 292 246 273 245 232 237 235 230 235 241 234 261 242 227 237 260 249 221 237 270 265 277 265 259 260 230 256 220 225 247 275 237 239 244 242 257 231 243 228 234 268 267 277 225 241 243 239 228 259 256 242 224 244 266 262 247 240 291 235 225 273 222 243 249 276 261 266 234 265 274 249 255 221 235 267 235 235 263 256 237 245 282 248 227 256 249 215 225 264 236 237 218 219 262 261 255 224 201 257 227 259 242 247 245 233 267 222 268 272 257 259 266 260 242 265 243 238 250 212 226 239 244 261 214 262 231 261 224 261 259 247 266 261 240 235 230 259 264 272 269 248 246 269 233 244 230 263 231 233 256 260 259 260 240 248 234 264 237 257 226 274 229 262 228 246 225 238 255 267 232 237 255 258 236 257 248 244 273 247 277 262 264 259 266 271 225 243 270 231 270 205 262 261 219 229 268 245 231 274 266 236 247 274 262 237 265 245 272 263 273 234 275 260 271 272 269 235 286 265 257 244 255 230 248 274 257 225 287 279 239 241 245 279 283 233 256 236 280 229 259 272 244 247 271 255 226 257 286 256 257 244 263 227 286 276 243 265 285 239 244 274 238 303 263 260 259 268 266 245 275 234 285 262 276 273 259 286 247 289 271 281 277 244 246 268 263 266 240 255 268 280 261 268 260 268 232 272 289 276 279 258 246 244 235 286 263 256 219 258 286 243 232 239 297 281 271 264 294 259 309 271 264 274 249 247 284 255 263 271 265 283 286 286 273 273 271 266 266 260 291 287 260 291 276 276 244 269 294 269 296 276 267 278 314 296 268 296 304 290 303 308 281 279 293 329 294 310 299 293 327 328 295 326 326 347 335 320 324 322 338 334 377 327 355 376 348 382 372 393 381 399 419 436 440 427 471 427 454 473 519 472 475 489 490 484 453 456 428 454 475 457 475 440 434 421 383 407 365 383 376 353 332 385 361 338 343 350 324 322 348 291 310 290 318 295 288 301 285 315 305 266 284 297 264 301 280 294 269 270 288 293 246 258 259 231 258 244 232 281 268 281 245 283 258 312 318 260 277 278 241 269 263 258 277 288 277 258 288 262 237 263 244 295 261 272 219 263 244 258 232 269 266 259 268 290 257 235 268 234 266 242 242 270 248 242 263 275 285 292 244 285 218 244 213 273 232 245 256 258 258 244 247 238 234 233 224 290 228 248 261 239 249 280 259 256 273 220 243 264 259 241 246 227 242 263 281 232 268 241 245 261 242 220 226 270 255 247 265 216 240 261 245 279 228 224 249 225 248 247 256 242 262 263 231 245 270 232 239 232 264 263 228 235 249 243 228 238 267 262 249 233 237 237 236 263 266 227 277 234 255 281 284 256 232 248 224 255 270 225 234 261 232 231 261 262 213 225 248 278 234 260 247 262 255 247 248 235 276 275 276 263 256 261 238 264 269 258 285 236 236 272 239 269 275 218 217 232 240 255 239 231 260 243 238 232 228 277 264 229 233 236 232 272 266 272 248 241 276 233 226 259 264 235 260 248 256 277 262 269 232 238 272 248 272 250 239 268 263 255 280 285 258 257 257 228 237 274 230 287 249 225 248 257 266 248 261 263 280 232 259 224 231 258 248 255 260 246 236 267 220 257 234 273 236 232 248 262 226 234 241 222 264 265 221 239 232 223 242 247 271 271 235 244 269 265 256 236 242 210 237 234 227 249 256 256 299 235 226 266 276 289 241 243 248 239 235 256 275 239 248 225 269 241 246 263 264 239 248 275 261 280 277 231 230 258 244 236 260 237 231 270 264 215 247 243 261 230 239 205 256 269 241 207 285 237 258 267 283 241 209 248 246 266 250 261 284 257 255 217 260 248 245 216 242 281 209 236 233 237 257 255 236 257 232 237 264 273 246 260 238 231 262 275 236 262 244 245 247 231 248 267 272 268 281 245 267 267 260 240 242 239 231 248 224 211 265 255 275 247 280 255 235 229 250 257 248 228 234 255 244 246 222 245 269 242 242 232 270 271 238 284 259 244 241 262 237 248 249 235 272 260 228 231 237 263 247 259 236 234 243 276 261 266 228 268 261 247 234 271 231 238 231 237 275 224 263 245 219 266 247 232 241 256 250 219 247 238 212 246 236 260 257 246 239 256 231 225 227 245 270 258 285 246 258 239 257 227 230 220 256 232 234 236 287 266 215 239 263 243 244 242 238 246 267 228 244 238 230 223 237 259 267 255 259 263 230 228 218 221 272 237 227 247 244 233 241 260 266 242 219 238 238 261 228 209 210 263 262 226 260 243 269 237 239 239 238 248 235 248 266 228 242 267 231 256 259 217 218 232 219 229 236 224 212 231 239 261 223 224 263 241 276 248 235 244 258 229 261 216 235 240 241 241 228 221 294 259 226 212 237 226 259 261 270 239 225 215 263 256 245 242 261 279 265 231 278 270 225 240 207 234 244 261 227 208 248 230 263 244 257 226 233 249 227 231 242 246 255 232 234 273 262 237 246 256 216 278 260 228 245 236 210 236 213 280 239 213 259 237 228 232 233 231 262 256 255 231 230 264 248 217 234 230 236 274 270 247 237 264 263 239 275 257 247 269 214 265 230 240 229 221 257 216 291 255 243 244 245 239 226 267 235 240 240 224 225 230 246 240 233 247 222 238 231 259 229 250 265 249 266 233 261 228 246 262 286 236 245 233 230 230 240 228 259 243 230 241 194 209 274 218 277 257 245 258 246 257 250 237 229 232 243 240 232 262 245 255 247 242 229 255 246 255 249 262 264 229 238 242 258 240 243 257 255 228 237 230 265 243 229 241 208 256 231 226 233 272 245 229 220 259 243 255 262 249 260 241 244 263 227 266 210 258 243 218 247 262 233 266 227 261 219 222 248 236 229 238 234 215 247 284 261 241 222 211 263 273 216 225 243 228 266 243 258 226 239 250 246 232 264 228 279 238 216 239 239 231 264 223 225 259 232 259 236 257 271 259 213 234 245 269 237 246 216 269 250 259 249 222 211 249 250 259 241 266 237 245 228 222 229 215 212 286 264 269 229 246 228 241 224 257 241 271 246 236 217 273 250 232 246 229 266 221 247 263 233 244 260 225 236 238 230 240 220 264 232 264 240 266 246 228 241 245 225 263 274 249 220 248 239 218 262 217 260 227 239 213 229 223 257 249 295 274 269 229 238 262 225 222 232 245 232 249 247 226 243 246 256 242 243 250 237 218 217 274 256 231 225 233 246 247 228 235 237 220 239 245 248 263 231 270 223 241 234 238 243 228 212 234 239 222 237 228 243 240 209 256 224 239 239 240 236 231 219 267 249 250 264 262 266 246 270 237 214 258 223 236 268 230 238 223 279 213 221 231 216 217 189 224 232 230 211 228 235 260 214 241 243 233 241 205 233 261 232 220 218 215 262 272 235 241 222 277 240 256 249 259 235 247 260 245 235 257 269 264 257 222 245 262 243 235 263 223 247 243 264 268 237 236 258 243 265 221 229 208 221 264 227 262 258 226 214 220 258 243 229 257 245 240 249 248 227 255 237 223 255 234 234 259 263 230 257 260 260 234 274 241 248 234 275 248 222 241 235 232 238 228 255 225 244 238 247 240 221 232 238 255 213 243 236 240 241 237 239 211 260 235 263 231 274 246 238 257 256 270 269 256 245 235 231 234 250 260 223 248 267 243 261 246 245 235 290 240 227 224 231 262 257 241 265 233 222 263 266 247 260 240 261 232 242 237 226 234 247 211 261 299 231 289 236 258 240 239 226 228 226 242 245 210 234 228 201 257 218 239 256 260 229 228 239 273 238 222 237 225 234 230 215 229 228 215 258 238 246 247 220 232 248 216 233 265 239 234 228 235 219 247 238 255 247 237 238 208 257 232 223 227 231 269 258 262 265 225 240 256 228 259 246 238 261 226 264 231 241 242 235 267 263 238 241 237 227 238 244 214 234 214 242 246 227 221 226 226 235 231 219 243 226 276 226 274 238 270 247 264 206 250 238 242 211 241 204 210 247 219 249 222 248 229 255 267 236 241 264 228 240 249 224 239 232 264 232 231 243 214 245 239 273 226 262 265 235 283 255 265 244 243 257 264 249 237 259 244 239 207 236 241 233 261 230 259 233 250 242 229 210 257 218 228 248 232 231 266 234 241 261 262 280 241 257 283 263 229 246 226 258 234 239 230 260 241 269 261 229 220 239 246 245 244 260 239 238 243 232 256 238 235 207 228 255 272 225 213 259 228 238 222 222 218 236 234 269 224 232 256 268 224 232 220 239 223 263 262 239 256 238 260 257 241 225 232 235 234 223 217 222 245 241 265 231 245 263 262 231 230 257 242 274 267 224 242 261 258 205 239 268 238 266 283 239 238 238 225 247 204 209 234 229 238 239 240 227 232 237 271 214 240 213 243 243 246 238 229 238 264 239 234 258 260 235 241 230 261 265 234 217 249 244 248 208 271 238 232 205 263 243 260 243 231 256 242 214 236 204 243 225 238 241 239 249 236 232 246 263 242 270 219 239 245 233 238 246 229 259 231 241 263 225 259 211 222 266 239 267 259 246 229 231 238 241 246 245 238 255 237 219 243 228 213 243 236 242 203 206 222 233 229 255 259 237 237 237 242 237 307 203 215 243 208 223 255 258 219 244 227 240 216 271 235 229 226 234 232 227 209 217 245 238 259 228 255 228 237 220 216 230 238 244 262 258 242 242 218 240 258 231 236 229 235 219 226 238 246 238 208 235 255 240 266 257 232 225 259 213 241 255 231 238 219 265 244 224 234 244 245 258 264 242 222 219 226 234 215 232 224 266 244 256 238 236 240 298 218 245 263 244 217 239 216 263 274 260 195 262 237 265 238 267 236 268 228 234 249 282 226 228 237 261 258 268 245 282 217 222 204 236 240 231 219 234 257 226 249 234 225 234 244 271 226 209 256 256 232 244 243 256 216 263 246 245 240 247 226 225 291 242 228 248 248 239 228 246 229 229 222 231 226 219 259 232 235 232 264 242 224 228 242 235 230 223 234 257 234 222 226 263 223 255 256 221 232 240 256 234 282 239 273 219 238 236 243 247 257 240 257 222 255 246 222 260 238 275 248 264 240 239 243 259 229 217 249 257 231 232 255 270 208 264 248 238 234 224 228 243 294 257 256 242 230 238 237 278 259 234 242 245 232 249 232 239 244 233 233 239 265 245 208 248 240 228 223 249 271 238 243 261 223 234 257 269 231 260 255 245 230 239 245 248 225 263 220 272 269 215 240 239 224 237 239 230 272 267 217 220 214 207 236 281 226 281 243 247 245 264 224 258 222 242 218 232 229 290 242 218 245 240 242 237 282 237 237 261 273 226 257 239 232 241 266 245 262 245 261 234 229 272 283 239 236 241 219 227 247 230 241 263 277 229 267 231 237 266 273 267 249 231 246 268 249 255 215 227 236 264 219 240 244 240 231 284 249 243 261 225 245 268 235 270 274 279 264 226 269 280 248 257 248 227 273 286 242 279 258 247 228 235 248 287 239 245 241 267 242 269 245 260 266 236 258 281 249 258 274 266 285 269 257 266 228 282 272 276 283 276 224 271 288 245 274 301 272 281 267 246 249 270 263 280 272 261 279 241 224 244 240 241 271 285 255 311 260 283 236 269 269 240 250 268 268 232 262 243 229 257 247 259 261 241 260 248 240 223 265 255 261 265 274 271 248 233 278 258 243 241 280 232 262 267 230 234 283 255 213 263 264 238 269 266 263 229 261 240 226 257 260 237 267 239 255 246 258 225 248 257 248 229 257 219 244 237 222 273 261 247 279 271 287 265 242 247 275 235 244 213 238 246 272 276 255 231 237 224 262 256 265 255 260 229 248 226 249 227 272 258 238 237 259 270 255 234 268 226 242 223 227 238 275 261 242 268 231 270 234 229 241 261 248 239 257 255 233 233 233 239 249 244 256 217 246 247 276 233 244 245 239 261 249 273 236 246 250 237 272 238 231 232 257 234 257 225 272 243 223 244 232 235 242 224 265 269 211 264 229 224 247 249 233 273 266 265 293 240 258 216 225 224 260 221 247 249 229 247 264 256 245 224 236 263 263 256 229 239 261 256 268 238 237 259 265 286 231 264 245 214 248 231 227 246 232 219 243 272 239 236 232 239 261 244 249 240 262 242 266 243 247 255 268 229 239 241 236 263 255 259 255 227 257 244 239 258 236 243 240 275 240 263 258 259 235 245 284 267 247 247 244 244 276 272 248 271 256 256 283 233 247 225 230 241 261 238 235 257 240 239 291 258 227 224 297 256 273 263 280 267 243 256 222 229 260 241 272 242 272 249 234 223 269 215 263 273 266 274 271 230 262 245 228 227 229 245 279 282 239 256 247 260 267 257 229 266 207 238 270 238 269 244 244 248 238 242 227 285 247 243 247 236 233 282 235 272 230 233 233 222 238 236 244 228 276 244 228 280 241 232 240 260 238 255 276 263 241 212 236 239 240 219 247 267 226 255 274 247 263 249 242 287 236 238 211 247 279 216 225 236 259 247 221 233 243 248 274 243 277 219 244 288 231 243 263 234 234 262 275 236 260 280 285 246 267 238 282 238 239 231 265 246 266 264 215 240 255 246 242 267 268 215 234 226 231 272 238 228 268 257 228 257 273 258 240 244 241 229 270 239 237 242 258 260 237 236 255 240 227 235 267 219 244 238 240 241 273 231 209 291 239 231 237 235 224 255 231 258 246 279 243 243 229 249 236 215 270 266 242 268 235 241 248 221 220 261 255 219 232 244 222 232 284 224 245 237 257 223 244 257 256 268 263 270 239 260 235 255 247 243 257 234 247 222 236 255 234 266 250 279 255 214 285 259 241 210 223 267 263 243 219 241 240 257 246 267 216 258 255 216 257 255 255 248 276 225 238 220 217 239 222 247 237 265 220 249 221 250 257 276 240 245 246 242 258 258 261 211 264 224 237 241 250 219 255 229 263 257 233 243 241 243 229 256 245 226 259 259 229 272 220 259 285 239 235 200 236 229 233 243 265 239 204 247 264 239 258 233 241 240 247 245 242 259 257 220 222 276 259 215 245 228 271 257 247 234 235 232 268 261 241 274 258 237 241 275 219 249 266 233 256 233 212 256 237 226 228 219 256 240 241 265 243 246 236 257 248 239 241 230 256 224 261 257 275 244 231 234 243 285 257 238 271 244 244 249 263 279 225 273 238 211 203 243 232 273 256 262 248 230 238 228 233 264 235 242 262 222 263 223 267 235 245 274 223 206 222 268 231 245 229 261 265 256 241 221 264 227 246 260 259 242 274 256 218 292 266 267 243 271 232 248 246 248 271 243 276 230 210 259 258 230 277 236 238 237 215 229 244 227 274 258 213 261 233 242 275 239 231 235 221 236 223 238 265 231 232 258 232 246 276 234 267 223 208 229 247 267 241 257 264 239 239 233 239 247 233 222 260 242 245 266 239 281 218 245 222 226 229 261 228 236 259 261 236 250 234 241 236 233 213 236 233 275 249 259 257 235 272 235 247 234 271 270 230 224 222 236 247 228 240 225 241 227 270 248 248 257 240 263 234 229 235 228 248 269 235 232 261 238 221 223 246 227 213 260 235 240 291 270 255 235 269 232 241 240 208 243 248 265 213 228 229 261 239 273 230 258 218 245 269 269 287 240 229 266 259 221 225 247 236 260 244 261 235 265 259 231 243 208 247 270 233 240 259 241 243 222 241 272 241 225 268 244 245 241 235 263 246 245 241 260 238 255 263 242 270 241 246 246 246 232 250 221 229 276 278 223 264 238 242 259 243 234 264 244 257 257 255 227 233 260 271 232 266 271 272 214 273 229 240 272 255 257 246 264 229 255 244 256 263 239 239 240 262 274 255 239 240 226 256 259 236 236 258 237 242 218 283 230 243 247 249 269 238 288 242 215 238 226 242 265 247 258 243 236 211 229 226 237 238 237 230 240 259 268 257 232 243 230 248 261 240 263 238 238 257 257 259 233 249 227 235 247 235 242 216 235 227 234 290 248 219 230 261 278 256 222 268 263 228 235 259 224 226 226 226 223 223 272 255 209 270 265 278 241 230 244 233 225 238 226 239 239 232 206 225 216 263 260 224 258 240 296 244 233 230 245 248 268 204 240 268 249 250 255 283 234 236 278 230 246 220 270 277 226 221 247 242 209 220 219 231 262 242 256 241 232 233 260 268 272 276 286 248 235 215 280 239 243 235 243 227 273 231 225 240 242 262 236 231 248 255 232 250 240 230 236 247 245 238 246 256 226 269 266 249 268 244 242 220 280 266 247 249 248 242 258 247 242 260 230 256 258 263 232 244 247 239 232 216 247 273 267 260 238 219 212 263 225 229 241 261 238 258 240 227 215 221 228 246 226 233 221 259 242 231 263 222 208 225 227 208 235 217 246 233 261 235 264 255 222 269 231 222 238 225 271 268 246 213 238 245 284 230 239 209 269 274 211 217 217 213 246 218 248 278 230 235 261 240 243 268 287 232 258 249 226 235 238 258 264 230 286 255 235 227 269 215 221 241 237 241 249 241 206 236 239 228 229 232 230 241 257 223 209 232 226 250 231 212 221 257 246 235 275 226 246 245 220 226 257 263 246 239 232 258 215 248 239 245 227 235 258 242 235 246 231 289 247 245 216 274 246 247 196 231 210 231 229 248 256 231 208 235 240 234 221 264 235 223 263 263 232 228 256 269 239 241 267 227 247 234 233 208 239 234 256 246 249 241 244 255 238 215 246 279 262 270 260 247 266 245 233 233 201 228 255 244 245 267 228 237 278 237 244 238 249 249 245 216 235 234 243 233 249 270 232 245 241 237 240 231 216 245 275 271 239 224 268 241 244 281 247 229 215 236 266 228 269 258 239 240 246 255 224 235 236 249 260 257 241 231 234 260 230 236 236 247 256 210 225 260 255 208 234 240 233 227 278 277 245 242 243 240 269 267 229 227 227 225 234 227 222 228 261 224 264 274 277 249 237 233 230 258 276 236 241 238 282 236 267 261 241 219 233 245 233 255 231 255 247 213 235 266 241 234 237 230 241 212 255 255 230 242 241 245 229 234 266 243 239 243 217 244 248 223 263 231 223 255 232 238 230 246 238 223 247 266 242 264 222 245 257 220 247 256 261 264 257 268 244 272 216 286 218 263 240 230 230 257 273 266 280 240 237 236 241 243 247 256 250 242 260 260 246 234 268 258 284 245 236 255 237 260 242 266 233 265 231 256 229 198 257 250 277 267 292 248 237 215 264 243 284 229 228 259 241 232 224 235 226 245 271 233 247 259 259 237 276 214 231 259 240 265 271 286 233 228 266 264 258 247 281 221 259 229 272 246 235 238 260 239 245 240 303 268 269 259 228 244 267 248 228 267 256 259 241 276 257 265 273 237 240 288 257 270 228 273 274 234 261 240 293 260 241 279 279 236 258 230 234 243 263 226 258 268 269 285 266 264 247 268 272 288 263 261 257 287 276 284 247 260 247 264 262 277 288 242 284 268 294 275 296 278 265 265 277 285 317 294 260 287 309 271 289 266 299 277 295 286 270 260 290 266 288 286 302 296 296 293 273 311 292 315 276 268 302 243 281 294 265 286 304 277 280 248 271 270 284 266 255 291 270 298 302 279 267 248 262 249 282 269 227 271 256 238 255 234 265 275 244 263 270 264 282 270 244 271 283 248 247 275 218 239 263 241 275 266 226 274 231 256 264 270 235 271 242 263 234 264 249 244 228 235 259 256 258 249 273 261 243 259 284 281 261 240 242 267 231 229 268 221 249 247 243 265 262 239 229 267 232 228 219 231 249 228 247 268 244 236 244 272 250 262 243 218 262 225 231 244 215 284 245 238 237 238 256 259 225 239 240 245 243 240 270 256 223 260 238 272 261 237 250 224 240 246 257 223 241 247 242 267 249 231 206 239 239 232 255 266 208 269 215 240 235 246 218 246 289 263 227 248 229 224 262 209 265 240 195 235 243 219 257 242 272 243 261 225 243 202 240 248 230 236 255 235 225 237 248 212 247 235 221 273 214 223 237 238 274 262 240 239 232 225 246 233 229 237 235 212 212 256 233 242 211 217 248 258 230 237 224 228 248 259 223 218 237 236 234 239 225 213 236 255 213 257 242 228 246 216 242 224 234 244 227 204 231 230 261 247 245 220 255 220 227 262 238 280 233 215 235 244 257 248 229 235 244 243 222 247 240 237 230 248 234 213 271 236 256 255 249 256 244 231 235 229 213 233 256 196 224 257 261 259 228 234 249 238 230 236 243 237 233 227 230 259 224 268 227 216 268 216 237 244 245 247 259 241 231 233 242 245 246 245 217 223 272 238 224 270 242 216 234 224 276 234 264 236 239 236 242 230 220 239 222 250 257 263 241 272 246 240 220 243 245 260 240 240 229 242 226 238 229 262 246 223 233 239 245 238 240 242 279 241 255 245 225 235 226 241 243 209 230 263 248 227 227 239 225 268 246 234 222 258 235 265 237 225 262 212 266 235 225 243 236 226 265 247 235 243 260 238 247 246 218 248 224 243 248 268 237 262 222 241 215 262 275 265 245 247 233 233 244 234 233 248 246 186 277 238 218 245 261 255 236 255 222 202 240 238 229 246 234 236 256 275 236 230 243 250 230 227 228 245 229 249 237 261 237 236 258 261 240 225 232 264 230 226 238 234 244 246 237 243 235 247 260 239 226 223 231 257 255 260 248 214 260 245 232 219 232 248 255 236 220 223 279 239 228 229 272 233 209 263 228 266 221 218 263 225 256 227 241 233 255 225 276 235 295 227 230 234 233 223 261 230 247 264 277 246 269 258 220 258 222 217 231 218 220 232 258 223 247 246 234 211 238 248 242 250 233 246 248 233 269 239 229 257 243 237 203 248 237 237 266 240 249 292 247 243 238 203 201 277 231 237 225 231 243 234 238 227 220 242 230 229 241 213 264 213 227 230 243 245 244 257 236 233 240 239 289 229 232 229 261 261 263 233 275 233 264 264 271 222 249 248 256 241 248 257 226 230 256 247 240 223 244 238 234 244 245 223 232 265 219 226 228 262 249 245 235 217 234 242 229 248 248 234 232 242 227 231 247 238 227 261 242 238 240 242 234 236 265 227 257 233 229 239 238 235 257 255 238 245 256 219 273 247 245 258 223 260 233 218 217 226 261 238 271 240 222 259 245 239 272 250 247 259 237 229 240 235 223 249 256 261 245 246 245 231 237 239 235 225 248 223 277 239 258 230 231 222 245 256 266 241 267 229 239 217 237 228 249 232 242 267 248 231 248 264 238 265 265 256 288 243 248 244 260 224 257 234 226 219 219 209 244 218 272 222 258 250 240 273 241 237 209 276 274 240 233 260 236 242 218 234 240 285 257 242 264 235 234 277 262 277 247 257 229 273 241 257 228 256 216 235 230 233 241 249 235 235 237 240 235 262 262 246 259 231 225 236 233 227 246 259 230 245 233 236 256 230 239 236 224 242 242 263 211 229 229 267 234 220 248 271 238 272 245 228 238 273 240 207 255 249 245 246 218 246 259 255 247 263 241 263 227 242 256 221 243 267 229 236 226 256 245 237 219 244 221 265 223 227 258 247 292 231 231 240 281 221 238 244 260 246 256 233 206 234 260 235 218 231 239 235 264 243 259 271 240 263 250 227 225 259 228 240 259 223 206 236 238 244 264 257 229 234 248 246 271 271 242 244 270 239 198 246 237 219 231 247 240 265 226 260 239 247 232 248 245 244 266 231 257 233 235 249 250 246 261 227 274 250 222 255 221 236 247 246 244 215 223 248 227 271 215 233 256 260 241 228 233 255 246 264 224 264 244 239 243 224 229 255 247 264 250 268 233 287 228 214 277 275 288 281 248 232 243 245 217 247 249 216 245 220 226 259 265 227 270 255 246 241 236 220 263 284 265 226 216 256 233 268 276 238 242 219 246 208 231 220 225 271 239 264 261 227 245 233 230 226 199 249 264 229 262 231 241 237 278 235 210 258 237 229 256 223 269 278 212 268 232 246 228 237 263 218 206 217 274 246 245 259 285 237 236 245 228 234 278 241 232 221 232 276 232 246 273 222 235 282 258 232 237 264 241 257 248 236 249 239 266 260 246 231 231 249 267 268 270 243 260 264 244 219 230 234 266 260 244 259 241 275 243 241 262 257 246 249 231 293 234 304 231 211 258 232 234 221 247 258 225 238 229 225 235 249 241 248 223 249 267 239 227 273 245 268 264 247 265 259 262 204 236 246 238 239 215 243 268 279 276 240 231 225 241 260 272 235 242 259 223 235 243 264 265 240 234 239 250 234 261 267 243 260 223 273 244 248 245 235 264 259 273 244 257 267 245 230 230 267 218 274 262 268 240 245 271 240 244 246 276 286 267 255 247 242 260 260 220 230 241 264 229 263 261 241 268 244 229 257 255 260 220 261 271 222 237 225 255 247 270 224 212 240 213 278 234 233 247 247 223 242 239 232 233 260 232 237 233 237 247 237 291 291 244 226 269 240 240 259 231 230 263 258 224 258 215 250 267 239 232 248 217 231 234 235 241 257 256 227 223 242 235 278 241 258 259 242 232 219 230 226 243 226 234 248 244 279 275 239 235 207 257 265 222 291 263 232 236 246 240 231 256 272 231 255 260 244 256 249 243 235 198 234 245 257 246 267 262 216 265 241 244 248 237 261 225 245 249 216 232 235 234 202 264 260 249 256 238 272 259 263 286 233 258 226 229 224 245 227 230 234 228 215 242 258 272 248 207 233 220 263 237 260 249 245 211 237 240 267 248 255 264 269 200 234 245 221 257 255 260 245 267 241 249 260 214 264 262 248 232 255 262 243 225 255 250 284 215 278 277 240 222 245 244 228 222 225 256 223 230 268 224 250 225 245 242 235 235 244 224 261 234 238 243 257 226 245 227 222 257 240 227 259 227 266 231 211 246 248 268 240 226 234 249 245 219 255 240 226 223 247 246 278 235 228 230 241 247 208 248 225 224 239 262 229 268 235 217 264 225 218 228 272 240 225 220 234 256 224 263 206 235 241 243 237 211 244 221 269 234 266 273 218 238 246 238 228 238 268 230 227 236 276 236 212 241 228 236 243 245 269 269 225 247 259 246 227 260 266 264 260 260 243 234 234 256 247 250 268 269 267 219 247 257 270 242 243 257 223 249 235 221 236 217 258 232 244 243 234 242 258 240 220 224 237 242 247 234 238 217 194 276 232 241 203 233 242 288 263 264 246 266 238 263 260 268 248 249 235 265 249 273 234 241 255 240 249 232 230 238 232 195 231 247 239 236 274 248 242 247 260 244 248 259 286 239 209 263 263 246 265 256 220 234 283 229 244 225 265 244 239 262 216 267 243 242 230 278 241 240 307 232 237 255 259 261 238 257 288 272 261 238 261 229 235 273 240 248 243 263 278 241 238 265 236 243 258 233 241 217 232 247 248 234 248 231 241 265 230 255 241 258 246 261 244 239 230 241 244 261 258 255 238 267 242 235 218 260 285 232 239 272 246 247 238 242 267 255 239 237 228 257 257 226 231 223 261 259 264 256 259 237 237 229 261 249 206 275 240 245 237 234 269 256 264 244 264 226 257 234 247 246 239 239 246 233 258 233 239 239 221 256 221 238 235 223 237 231 238 213 249 257 248 235 256 266 229 265 227 248 262 228 238 231 258 239 231 262 211 215 286 304 232 248 242 240 249 258 239 224 258 238 257 269 240 237 245 265 241 227 235 237 248 244 241 256 265 257 249 228 227 224 239 248 240 236 275 282 256 219 256 247 258 209 261 259 242 257 237 244 261 227 286 238 257 239 221 248 274 233 222 237 248 286 241 222 246 217 216 262 246 245 220 260 256 272 241 222 244 249 270 256 271 218 266 244 259 256 242 240 241 227 257 239 274 231 269 244 246 241 199 237 256 258 223 263 272 221 264 223 246 262 260 248 268 256 264 221 241 269 255 225 259 250 239 260 259 238 273 267 247 242 222 239 260 231 204 258 239 247 219 236 238 249 262 225 243 223 243 261 233 238 228 262 238 271 240 255 243 246 273 265 248 246 271 240 241 266 225 231 247 237 237 225 260 223 268 245 228 223 243 263 262 243 243 260 244 238 209 262 238 271 243 257 239 237 247 225 266 223 259 246 244 232 227 276 244 226 265 231 261 249 258 226 240 270 249 261 250 255 266 262 258 256 224 235 233 230 275 263 256 266 264 214 233 244 233 245 229 244 243 225 243 228 258 287 236 270 233 215 232 211 272 272 228 255 233 260 243 243 267 285 282 244 230 267 236 232 258 257 231 220 284 240 268 265 247 240 262 244 246 279 239 279 242 264 266 263 265 257 218 255 276 245 211 250 232 255 239 259 249 231 235 257 255 256 260 264 266 242 238 238 249 249 228 244 276 216 239 259 258 258 232 244 237 270 221 205 246 242 262 263 255 240 245 245 272 276 222 222 222 255 244 232 244 227 224 259 258 256 262 247 233 261 255 219 236 229 243 239 242 249 217 271 244 235 244 239 257 233 242 274 247 242 259 275 228 261 256 227 276 255 248 226 234 263 229 274 235 256 229 224 247 227 275 269 221 246 264 242 235 242 268 246 214 233 265 256 234 280 226 228 220 271 246 224 231 225 242 264 257 240 276 235 224 248 236 247 269 226 265 239 224 298 262 240 269 241 270 260 233 284 269 267 246 230 244 265 248 239 227 245 236 271 276 232 220 247 301 240 214 226 259 245 266 241 232 225 231 259 256 249 255 227 235 220 239 238 262 269 235 239 238 238 264 286 246 232 217 226 234 271 277 211 247 228 256 262 237 215 237 228 239 260 245 261 255 239 240 261 243 245 226 232 246 208 276 229 210 256 247 226 230 245 278 230 238 255 256 230 245 270 271 257 243 270 233 250 226 242 242 221 201 234 238 270 271 271 235 270 225 239 258 246 228 225 249 231 230 238 272 236 203 255 262 234 225 284 244 234 222 239 246 218 257 221 248 239 246 246 241 238 238 213 257 237 237 235 243 258 257 217 220 256 246 222 248 218 264 221 242 243 258 244 257 255 248 243 244 204 267 227 242 274 265 248 237 224 221 214 226 260 228 276 240 222 224 280 222 230 258 232 241 231 246 233 229 233 232 274 257 191 188 246 221 277 242 243 229 235 250 279 268 264 244 219 226 239 235 263 222 240 264 238 219 273 236 285 247 272 240 244 285 234 242 246 239 240 231 249 224 237 234 241 241 217 240 243 221 207 229 213 240 223 228 221 233 230 240 274 222 222 257 246 272 249 222 263 225 244 245 246 212 247 247 232 258 262 229 213 233 228 221 241 260 249 264 248 267 273 262 228 248 227 266 242 235 230 246 238 258 247 255 267 247 224 245 239 246 216 228 235 274 272 215 219 233 243 259 227 240 228 221 256 238 278 235 262 259 238 242 241 243 263 247 266 227 223 271 244 233 224 237 246 257 247 229 231 228 260 271 266 270 245 275 241 241 280 258 285 259 267 271 249 249 267 204 269 230 237 220 236 237 247 277 233 232 233 245 247 247 250 264 261 235 269 269 284 258 233 266 234 247 241 256 243 250 246 223 217 275 233 212 249 229 221 223 265 245 249 270 230 249 263 258 244 264 262 232 258 280 237 268 294 268 245 234 215 292 243 206 273 258 266 247 264 231 226 236 239 258 240 223 275 240 271 243 243 220 286 257 256 265 242 238 230 244 259 261 238 229 265 242 271 239 264 265 222 261 279 220 255 249 246 278 243 234 241 245 295 282 262 237 245 219 277 259 231 243 275 231 236 241 268 259 232 220 241 257 282 225 278 272 259 264 247 270 270 230 264 266 243 259 257 264 269 259 262 240 264 240 262 259 232 258 261 272 235 300 241 240 236 232 256 255 249 282 239 261 247 259 263 275 275 226 289 247 222 256 270 280 237 255 242 265 244 278 261 261 234 267 227 242 255 239 239 238 267 237 230 264 246 226 243 243 291 243 244 261 272 242 234 283 262 265 250 263 237 264 256 285 223 264 218 233 277 243 241 284 269 248 267 249 268 234 263 237 283 257 246 290 232 237 232 235 284 245 241 261 260 246 224 245 246 285 240 268 263 226 261 236 262 204 239 247 232 264 283 255 272 235 283 233 255 279 261 235 235 224 245 246 265 277 246 258 222 259 240 218 255 257 246 249 220 271 265 239 237 232 263 238 237 209 256 241 258 255 230 239 261 215 235 241 265 239 257 244 222 256 241 228 268 247 222 270 289 235 230 249 272 229 248 243 282 218 238 237 274 220 272 264 222 246 245 237 270 245 262 263 268 301 227 240 264 236 261 243 248 261 247 263 229 228 219 244 236 271 269 295 272 248 225 250 249 284 216 258 224 234 249 251 268 242 307 227 261 281 249 256 262 256 229 261 285 258 246 271 234 247 241 263 232 234 260 301 274 269 235 234 265 267 284 226 216 229 258 256 267 237 227 280 247 237 240 271 276 235 231 262 229 232 249 268 259 229 229 246 273 228 259 229 266 247 270 265 269 266 241 242 264 222 273 241 239 274 241 248 277 235 295 263 278 258 273 233 248 260 247 224 245 239 267 247 232 234 238 266 255 267 237 265 243 243 266 237 244 276 231 268 234 287 218 281 265 239 230 249 269 285 247 244 241 241 280 235 287 268 258 246 236 236 255 265 262 261 265 239 293 257 234 269 237 269 243 249 277 268 236 273 268 285 272 267 263 247 265 266 235 244 269 230 263 229 257 223 258 256 236 261 231 236 256 259 291 263 271 275 258 235 248 232 248 264 238 241 218 270 261 260 233 255 260 262 270 237 247 271 248 255 244 285 246 270 274 248 265 265 269 247 268 224 255 276 287 284 242 224 237 255 256 273 246 241 249 237 271 248 265 255 246 230 245 289 245 247 256 255 272 270 234 257 257 239 286 240 232 264 259 259 270 270 235 256 262 247 214 279 279 260 217 237 255 266 272 273 266 298 232 275 249 229 250 274 268 269 268 268 274 277 291 244 242 265 263 263 274 255 273 246 270 241 270 284 260 243 227 236 269 241 263 229 232 286 247 265 236 235 249 265 260 281 246 265 243 257 285 245 268 276 241 277 263 284 247 265 226 248 276 257 268 274 255 261 266 285 292 257 260 279 239 238 299 263 264 264 265 271 257 247 286 257 288 278 285 262 245 256 244 265 267 265 234 271 264 274 263 265 295 256 270 292 267 258 259 264 271 255 262 279 259 293 297 264 267 228 274 256 265 271 264 283 271 255 258 275 261 310 240 281 258 285 279 275 300 291 266 258 284 302 284 276 274 248 244 303 273 276 308 319 246 273 278 294 263 272 295 274 246 264 228 272 293 288 284 229 288 273 291 290 271 262 243 282 271 277 287 289 258 278 267 259 267 262 266 234 298 277 286 309 268 260 258 274 291 267 275 281 285 270 265 248 243 270 286 260 278 249 259 287 266 271 282 272 270 293 284 265 265 286 216 265 273 265 261 242 262 264 273 270 298 277 293 260 275 260 270 258 262 314 267 265 271 261 275 270 241 248 276 264 259 259 262 267 261 247 303 276 260 275 249 267 259 268 242 240 271 277 240 263 271 257 272 259 281 284 296 243 246 263 259 262 241 269 261 243 278 236 282 216 265 241 256 279 255 261 239 267 243 236 269 278 247 268 239 245 244 235 239 245 269 289 201 280 244 259 302 256 259 261 223 243 266 271 270 261 244 257 278 273 276 260 262 267 235 270 268 274 245 231 267 247 263 248 283 241 282 247 262 244 244 260 286 267 256 255 261 256 243 239 243 255 305 229 236 249 262 259 242 246 264 256 278 240 267 269 275 259 244 268 279 262 256 277 261 275 285 274 246 240 259 262 283 237 232 284 245 215 230 244 255 250 261 259 244 245 240 249 221 285 247 272 223 258 244 265 246 248 221 273 242 249 268 265 261 240 256 243 264 269 269 279 259 298 219 240 281 241 265 233 244 249 247 249 240 284 239 223 264 243 246 276 270 257 241 261 276 301 249 240 231 260 283 215 270 241 281 255 241 267 257 256 238 230 242 243 236 245 236 234 268 242 247 250 234 257 256 247 220 206 268 269 271 234 242 258 246 249 261 271 239 243 260 225 267 264 270 258 267 245 256 270 259 255 227 233 227 240 214 255 262 245 279 237 244 268 260 246 240 277 273 235 243 259 261 238 263 246 274 278 239 247 236 240 284 243 262 283 257 269 231 263 269 300 248 270 224 267 279 261 213 281 265 240 282 285 246 279 242 239 275 266 278 248 239 239 235 257 266 268 226 282 230 221 239 277 235 261 261 265 281 262 246 257 246 280 241 249 271 271 243 260 224 285 265 287 250 288 265 241 220 228 238 256 245 279 235 261 259 255 255 279 240 225 245 235 284 270 301 240 255 303 279 289 257 223 259 271 292 240 269 262 281 264 263 287 239 319 240 256 244 262 268 228 240 275 260 261 269 258 262 265 276 259 285 247 258 285 245 240 249 264 274 245 255 265 285 267 276 274 255 284 243 256 268 262 277 275 264 281 249 231 272 249 235 266 250 260 238 258 261 284 247 258 259 234 276 255 240 246 267 256 277 237 241 241 274 244 261 247 248 291 246 273 273 243 274 242 249 228 222 279 269 256 238 275 229 269 260 300 270 255 248 255 262 240 280 268 264 236 258 236 220 277 264 245 273 260 292 249 235 268 245 269 238 239 238 245 258 246 244 271 291 256 244 256 233 273 231 284 268 284 262 258 277 268 238 283 275 258 249 265 277 255 268 264 248 256 255 263 256 268 236 248 288 234 262 264 262 247 269 261 284 267 235 240 279 265 277 249 225 276 278 228 275 245 264 239 237 213 237 258 264 222 263 288 283 243 257 245 268 261 283 240 291 224 240 266 255 230 259 243 223 257 269 239 277 260 291 259 269 278 235 272 237 265 293 256 228 241 220 236 269 271 257 249 227 279 272 226 242 233 249 233 261 205 242 279 243 283 262 261 263 240 242 274 274 267 260 256 259 267 233 264 307 263 262 241 264 227 262 242 270 285 275 257 246 277 284 256 249 256 273 237 281 244 229 245 241 249 244 272 237 289 266 250 268 237 244 267 270 266 270 239 240 257 259 255 231 230 274 268 260 239 244 258 241 236 266 261 265 261 265 243 256 272 259 225 249 291 228 237 269 271 268 260 242 247 292 246 243 267 246 256 261 259 270 247 235 243 255 258 260 234 285 258 247 299 275 280 267 259 285 256 268 258 276 256 275 271 225 242 275 236 247 221 229 258 283 263 239 262 258 260 262 223 257 282 269 255 279 243 248 259 238 250 286 238 231 285 248 259 275 260 279 239 268 257 292 272 256 265 224 263 258 238 224 243 248 258 246 297 240 259 268 270 286 228 232 261 257 247 256 283 258 258 260 257 249 244 274 258 230 243 261 244 275 265 263 264 266 246 225 272 256 247 274 230 269 272 239 238 265 267 245 280 277 270 273 304 262 239 248 255 262 258 264 255 261 260 259 258 273 279 260 222 260 261 293 308 247 250 232 265 234 274 285 257 233 278 268 279 267 283 256 260 237 262 258 270 246 248 280 235 294 268 266 229 276 257 228 272 248 248 292 270 277 278 255 246 263 240 248 263 239 239 265 266 259 247 229 226 292 229 281 243 307 265 279 266 228 261 271 273 274 234 235 257 258 267 264 246 267 238 267 270 250 249 275 241 277 249 273 268 266 248 246 222 218 265 263 266 282 267 261 243 260 285 261 266 258 267 246 257 267 268 255 268 262 259 270 276 274 261 285 263 263 264 236 259 283 258 256 259 275 268 246 245 289 259 229 273 297 269 248 261 258 266 248 279 296 280 242 267 259 247 267 293 249 245 284 262 267 280 230 224 229 256 240 285 230 259 261 288 276 258 260 272 264 278 272 240 282 306 227 239 235 286 233 264 272 308 255 291 277 257 234 233 246 257 258 262 281 264 281 249 273 267 241 244 249 230 248 224 283 258 269 246 264 234 257 267 271 271 255 263 289 299 286 220 262 261 227 240 281 246 242 266 238 262 232 288 272 267 269 247 236 284 267 274 272 267 276 262 274 242 259 233 260 274 257 247 266 272 270 270 272 282 261 220 268 268 276 279 271 266 266 273 273 258 263 280 297 255 263 256 230 245 259 241 263 239 279 261 247 267 259 245 273 258 273 233 264 228 241 262 284 269 226 272 263 246 257 290 261 240 257 262 305 247 277 262 271 261 244 261 303 278 276 270 256 237 259 260 242 247 275 277 270 248 266 284 286 258 236 272 272 261 233 270 261 273 245 248 262 272 237 250 258 238 270 289 268 256 255 257 255 285 281 240 271 271 276 234 278 279 236 257 287 263 281 295 239 222 259 260 256 223 260 238 250 281 257 262 222 275 246 269 256 277 281 238 243 247 278 244 262 260 240 261 233 267 258 266 247 244 258 269 286 236 267 267 270 238 257 256 265 226 304 258 258 238 241 268 265 261 271 260 283 267 278 263 248 237 276 283 262 248 269 255 238 246 235 273 277 272 262 257 263 286 277 264 245 267 274 268 272</counts>
			</dataPoints>
		</scan>
	</xrdMeasurement>
</xrdMeasurements>