File: data/XRD/XG-Vakuum/XG-800/W6824-1C_XG_Vakuum_800.xrdml
<xrdMeasurements xmlns="http://www.xrdml.com/XRDMeasurement/2.1" xmlns:xsi="http://www.w3.org/2001/XMLSchema-instance" xsi:schemaLocation="http://www.xrdml.com/XRDMeasurement/2.1 http://www.xrdml.com/XRDMeasurement/2.1/XRDMeasurement.xsd" status="Completed">
	<comment>
		<entry>Configuration=Factory configuration, Owner=User-1, Creation date=7/8/2013 4:01:53 PM</entry>
		<entry>Goniometer=PW3050/65 (Theta/2Theta); Minimum step size 2Theta:0.0001; Minimum step size Omega:0.0001</entry>
		<entry>Sample stage=MRD Cradle; Minimum step size Phi:0.01; Minimum step size Chi:0.01; Minimum step size X:0.01; Minimum step size Y:0.01; Minimum step size Z:0.001</entry>
		<entry>Diffractometer system=XPERT-PRO</entry>
		<entry>Measurement program=C:\PANalytical\Data Collector\Programs\Jorrit\2thom\_absolute_2th-om_10-130deg_PIXscan_56min.xrdmp, Identifier={15BCCF57-2807-42BD-B5B9-ECC0B3DC9284}</entry>
		<entry>Batch program=C:\PANalytical\Data Collector\Programs\SimonL\batch3x_2thom_10-130°_z9.1_x0,10,20_y0_57min.xrdmp, Identifier={1E956750-2741-41FB-B242-F9B1C20E21A8}</entry>
	</comment>
	<sample type="To be analyzed">
		<id></id>
		<name></name>
		<preparedBy></preparedBy>
	</sample>
	<xrdMeasurement measurementType="Scan" status="Completed" sampleMode="Reflection">
		<comment>
			<entry>_absolute_2th-om_10-130deg_PIXscan_56min</entry>
			<entry>PHD Lower Level = 4.83 (keV), PHD Upper Level = 11.27 (keV)</entry>
		</comment>
		<usedWavelength intended="K-Alpha 1">
			<kAlpha1 unit="Angstrom">1.5405980</kAlpha1>
			<kAlpha2 unit="Angstrom">1.5444260</kAlpha2>
			<kBeta unit="Angstrom">1.3922500</kBeta>
			<ratioKAlpha2KAlpha1>0.5000</ratioKAlpha2KAlpha1>
		</usedWavelength>
		<incidentBeamPath>
			<radius unit="mm">320.00</radius>
			<xRayTube id="1010048" name="Empyrean Cu LFF HR (9430 033 7310x) DK442154">
				<tension unit="kV">40.0</tension>
				<current unit="mA">40.0</current>
				<anodeMaterial>Cu</anodeMaterial>
				<focus type="Line">
					<length unit="mm">12.0</length>
					<width unit="mm">0.4</width>
					<takeOffAngle unit="deg">4.2</takeOffAngle>
				</focus>
			</xRayTube>
			<xRayMirror id="27010001" name="Inc. Beam Cu W/Si (parabolic MRD)" hybrid="false">
				<crystal type="Graded" shape="Parabolic">W/Si</crystal>
				<acceptanceAngle unit="deg">0.800</acceptanceAngle>
				<length unit="mm">60.0</length>
			</xRayMirror>
			<sollerSlit id="21010002" name="Soller slits 0.04 rad.">
				<opening unit="rad">0.0400</opening>
			</sollerSlit>
			<mask id="22030008" name="Fixed mask 4 mm">
				<distanceToSample unit="mm">220.00</distanceToSample>
				<width unit="mm">4.00</width>
			</mask>
			<divergenceSlit id="22010007" name="Fixed slit 1/8°" xsi:type="fixedDivergenceSlitType">
				<distanceToSample unit="mm">220.00</distanceToSample>
				<height unit="mm">0.19</height>
			</divergenceSlit>
		</incidentBeamPath>
		<diffractedBeamPath>
			<radius unit="mm">320.00</radius>
			<sollerSlit id="21010002" name="Soller slits 0.04 rad.">
				<opening unit="rad">0.0400</opening>
			</sollerSlit>
			<receivingSlit id="22010001" name="Fixed slit 4°">
				<height unit="mm">5.88</height>
			</receivingSlit>
			<detector id="7010017" name="PIXcel3D 1x1 detector" xsi:type="areaDetectorType">
				<phd unit="%">
					<lowerLevel>30.0</lowerLevel>
					<upperLevel>70.0</upperLevel>
				</phd>
				<mode>Scanning</mode>
				<activeChannelsEquatorial>255</activeChannelsEquatorial>
				<activeChannelsAxial>255</activeChannelsAxial>
				<pitchEquatorial unit="mm">0.05500</pitchEquatorial>
				<pitchAxial unit="mm">0.05500</pitchAxial>
				<readOutPeriod unit="seconds">0.135</readOutPeriod>
			</detector>
		</diffractedBeamPath>
		<scan appendNumber="0" mode="Continuous" scanAxis="2Theta-Omega" status="Completed">
			<header>
				<startTimeStamp>2024-10-15T12:52:58+02:00</startTimeStamp>
				<endTimeStamp>2024-10-15T13:49:04+02:00</endTimeStamp>
				<author>
					<name>PRO-MRD</name>
				</author>
				<source>
					<applicationSoftware version="6.1b">Data Collector</applicationSoftware>
					<instrumentControlSoftware version="7.0E 20130304">XPERT-PRO</instrumentControlSoftware>
					<instrumentID>0000000011142674</instrumentID>
				</source>
			</header>
			<dataPoints>
				<positions axis="2Theta" unit="deg">
					<startPosition>9.99826193</startPosition>
					<endPosition>129.99755682</endPosition>
				</positions>
				<positions axis="Omega" unit="deg">
					<startPosition>4.99913096</startPosition>
					<endPosition>64.99877841</endPosition>
				</positions>
				<positions axis="Phi" unit="deg">
					<commonPosition>0.00</commonPosition>
				</positions>
				<positions axis="Chi" unit="deg">
					<commonPosition>0.00</commonPosition>
				</positions>
				<positions axis="X" unit="mm">
					<commonPosition>20.00</commonPosition>
				</positions>
				<positions axis="Y" unit="mm">
					<commonPosition>0.00</commonPosition>
				</positions>
				<positions axis="Z" unit="mm">
					<commonPosition>9.100</commonPosition>
				</positions>
				<commonCountingTime unit="seconds">32.895</commonCountingTime>
				<counts 386 412 411 412 409 407 399 406 365 429 421 381 388 406 390 394 380 378 393 429 413 381 399 390 406 391 352 413 399 387 399 367 392 394 383 423 404 399 415 383 454 395 373 419 426 416 422 422 413 439 422 395 388 403 392 401 456 390 370 421 398 388 449 403 393 367 436 416 403 369 414 360 381 409 385 368 376 383 342 391 353 383 395 382 406 380 363 409 373 392 409 398 377 354 371 367 392 388 372 355 379 384 355 352 416 376 389 370 378 348 365 376 405 410 383 353 363 392 381 366 361 372 389 375 376 376 364 368 350 364 361 361 394 358 375 367 371 383 325 364 394 366 356 366 362 375 389 384 371 371 390 359 377 356 353 363 364 356 418 364 356 333 362 389 413 369 403 368 352 345 351 362 357 340 334 330 360 376 356 377 381 352 363 350 383 359 348 387 335 344 349 358 341 350 363 359 332 393 335 354 374 336 365 355 336 388 386 352 368 343 337 318 365 344 366 337 343 358 382 335 353 333 349 392 386 339 375 389 365 388 348 374 369 322 361 346 363 360 326 355 322 313 379 333 382 343 365 341 347 371 334 354 328 359 360 323 348 340 344 376 357 322 339 346 340 361 329 354 341 344 374 355 334 360 327 347 350 347 345 328 366 344 334 352 318 339 363 346 351 335 340 340 327 371 315 334 338 307 332 309 369 302 347 355 355 321 348 363 334 352 342 343 323 337 318 343 359 359 327 325 359 341 322 334 335 352 333 337 333 382 330 337 292 342 384 320 319 331 323 333 342 317 330 291 341 358 342 323 322 342 342 319 359 326 346 358 338 341 299 345 323 342 315 326 314 370 330 364 311 318 337 339 337 339 345 352 346 310 332 295 319 317 336 342 325 315 365 339 347 307 337 315 326 318 316 341 269 320 349 317 285 329 356 309 322 326 346 289 328 298 338 315 296 337 319 309 348 304 315 272 329 341 325 331 333 341 327 324 309 325 306 329 294 287 303 326 322 310 314 319 295 308 320 301 281 313 359 324 297 308 308 289 304 321 318 303 298 341 304 309 311 323 316 352 297 295 321 323 308 303 306 356 355 318 301 321 322 286 293 325 308 328 307 301 302 325 315 331 330 315 297 296 303 282 339 325 318 321 303 324 323 305 289 313 339 311 304 285 296 306 293 287 310 306 300 310 308 336 326 284 286 283 313 302 307 312 318 276 311 296 264 314 322 321 271 276 276 305 289 296 301 281 299 284 297 312 308 302 307 306 313 266 280 285 270 306 288 277 291 301 290 335 292 337 273 330 283 279 299 286 288 300 340 279 301 293 307 284 309 311 279 301 280 282 308 312 267 306 274 283 304 295 287 297 281 314 304 295 280 290 255 294 332 315 308 294 286 304 313 288 291 296 272 310 311 280 324 326 314 283 291 279 311 292 281 283 277 298 305 267 298 306 279 309 288 301 302 290 266 289 293 275 305 311 275 312 319 280 300 287 278 294 312 298 286 288 297 311 275 273 298 313 295 322 265 297 314 294 302 318 295 300 283 309 267 270 307 300 318 303 298 274 306 299 304 287 298 306 288 293 294 287 286 279 279 297 331 311 337 280 279 262 300 280 299 264 320 291 292 295 291 292 290 300 267 301 281 301 289 318 283 291 288 296 294 316 265 242 301 306 330 267 311 301 271 258 272 291 286 281 282 297 300 289 303 298 298 260 313 296 293 281 312 307 270 270 273 303 258 258 284 275 304 261 266 307 266 264 293 266 287 288 299 285 287 324 282 274 286 308 279 294 275 283 280 330 283 281 292 279 292 277 265 298 298 298 291 298 285 283 273 263 298 286 273 275 276 280 246 266 283 268 310 310 279 296 267 308 294 283 298 279 265 300 285 259 302 293 304 287 320 272 310 271 292 240 245 277 289 286 301 279 262 274 273 316 289 284 324 283 285 284 270 288 268 279 277 246 306 272 264 255 300 292 246 307 282 288 284 289 276 277 285 268 297 281 291 308 271 269 274 289 255 277 297 283 276 282 290 290 288 300 290 305 266 265 268 293 278 297 276 311 295 240 269 297 272 281 275 256 273 305 280 277 265 270 310 263 296 288 303 275 292 292 299 300 264 270 274 296 257 310 278 285 286 287 243 287 286 276 296 290 259 281 292 261 292 285 288 285 288 277 269 302 277 282 290 291 296 262 302 304 298 288 285 293 290 297 295 301 259 288 283 297 272 285 299 283 282 264 258 302 259 268 300 299 260 309 265 315 286 293 281 311 285 284 280 277 259 274 262 279 266 329 293 284 313 236 290 268 308 286 303 290 298 270 255 281 270 275 268 299 289 269 291 279 310 296 264 283 271 283 322 290 282 278 273 291 276 299 295 292 283 275 295 242 309 279 333 264 297 316 319 294 278 300 276 295 265 303 286 286 304 297 316 327 297 285 284 306 304 315 299 303 314 301 271 287 291 333 315 294 291 288 328 276 275 302 272 280 289 303 306 260 312 301 284 298 273 278 294 293 342 304 281 302 296 284 302 277 307 318 286 300 307 309 279 285 341 290 305 311 305 306 312 310 268 304 296 267 326 296 276 284 281 272 281 298 311 291 294 332 305 332 308 306 303 309 281 287 292 262 297 290 302 301 317 277 282 265 295 255 321 323 276 245 268 309 290 336 301 296 299 297 287 271 277 294 300 286 296 290 312 326 307 331 297 312 324 285 310 277 329 312 294 324 283 308 291 303 328 322 297 297 305 318 319 331 315 304 306 299 285 316 301 287 294 284 298 271 328 294 256 278 291 281 295 286 304 299 289 318 297 271 297 288 298 287 301 272 288 293 284 310 272 259 306 285 286 279 321 263 291 310 264 300 302 309 332 281 288 320 272 296 284 321 318 324 308 325 301 306 284 267 306 308 315 319 289 306 310 323 303 280 245 315 280 298 329 284 306 310 332 325 270 295 330 318 311 309 314 295 295 293 296 282 301 272 316 315 263 275 329 274 304 296 304 281 306 294 307 306 289 281 341 267 291 313 279 284 295 300 306 301 295 269 306 316 311 282 283 307 341 309 288 329 310 264 290 287 329 286 314 307 285 326 277 268 279 307 285 286 290 308 278 311 285 290 287 288 317 323 323 320 286 292 303 288 283 262 292 265 271 295 299 300 289 279 292 309 315 300 290 317 309 284 311 277 299 281 301 304 284 324 310 269 303 296 288 269 315 312 265 304 285 292 280 309 294 316 261 264 295 279 318 276 269 279 279 295 300 305 269 310 263 302 264 294 277 313 279 303 267 303 313 271 258 265 283 261 286 290 285 314 300 306 256 292 290 294 274 288 289 292 291 272 296 291 248 288 265 292 293 318 305 293 278 283 284 283 276 303 265 284 288 299 301 315 293 291 262 279 263 306 258 257 302 294 280 321 305 274 234 320 259 295 271 313 238 259 298 272 284 279 267 259 262 291 298 288 289 280 291 278 287 278 296 228 273 290 275 261 269 310 294 263 256 263 286 269 301 282 281 257 288 285 271 314 274 269 271 276 294 271 299 265 285 316 305 291 260 286 315 232 283 266 273 278 285 241 264 290 237 273 298 272 265 279 271 294 289 280 291 284 284 289 268 271 249 242 278 271 273 277 264 275 291 282 244 266 247 262 244 286 278 275 297 261 267 280 260 234 265 277 282 263 274 272 276 273 295 274 264 277 270 285 235 272 240 262 234 261 277 255 263 258 293 282 287 282 255 278 244 282 274 225 276 287 234 285 271 232 243 287 255 259 269 257 283 300 247 232 283 276 280 261 287 274 272 275 287 243 222 229 241 216 239 256 240 275 294 269 242 263 267 268 256 243 234 242 242 240 262 257 256 260 259 246 256 245 263 271 242 266 255 250 255 242 226 256 277 236 239 267 264 239 264 264 245 279 268 294 271 259 261 273 261 276 258 244 230 235 268 270 220 222 255 226 263 277 258 246 244 247 274 258 261 235 247 263 277 270 243 265 247 238 239 277 232 234 249 235 257 239 264 228 215 267 267 205 258 260 273 246 259 263 227 255 246 276 268 249 269 268 223 240 257 220 221 227 261 247 258 260 259 258 259 263 269 278 229 274 247 257 236 250 224 200 260 240 272 260 227 243 239 243 243 249 256 219 260 228 231 283 242 249 228 237 238 242 216 241 232 245 264 234 247 242 231 228 214 260 215 220 247 236 272 271 264 270 260 256 241 256 233 247 238 267 235 217 235 255 224 258 247 270 258 231 175 221 238 219 262 217 238 256 222 246 234 238 227 268 261 240 220 228 267 270 272 229 246 239 240 228 242 227 230 264 228 271 225 255 256 236 217 216 214 246 256 240 233 255 225 237 266 225 271 215 218 220 229 234 224 220 248 213 244 222 224 246 241 260 223 207 243 224 242 248 234 238 243 258 270 238 208 228 216 221 244 222 197 250 222 231 240 241 256 241 233 222 262 227 223 234 244 215 207 232 233 220 224 201 234 226 235 226 235 234 240 227 217 207 219 232 228 223 215 264 201 225 200 228 232 208 212 220 248 224 238 230 208 239 211 222 220 223 215 210 224 222 258 221 220 231 244 228 235 227 256 210 232 222 216 232 208 226 237 230 231 233 235 227 249 245 219 208 240 235 210 230 223 197 240 271 231 213 216 242 239 202 208 211 217 224 198 203 234 206 213 209 227 195 209 206 247 246 259 241 263 237 219 222 246 234 217 217 258 228 231 233 243 256 232 204 205 231 234 222 242 193 224 229 210 261 208 215 232 221 213 222 229 230 222 226 192 219 203 212 226 228 236 263 199 210 232 242 215 239 238 208 242 218 223 218 239 229 218 214 226 181 197 259 203 219 217 219 216 232 237 218 232 229 238 205 222 235 220 222 239 232 219 211 235 215 221 209 226 227 214 226 237 246 225 213 225 236 195 219 221 210 221 220 212 247 219 226 259 215 192 204 237 218 244 217 234 202 267 241 231 233 214 180 231 208 213 213 232 216 242 220 258 236 221 226 226 234 219 214 222 230 216 238 223 215 215 204 226 218 198 215 213 276 199 196 225 243 209 223 231 248 212 204 219 241 197 241 221 228 219 222 234 203 182 234 221 262 178 217 211 229 227 207 208 211 222 228 214 248 201 222 214 216 217 207 219 228 189 215 213 233 213 215 240 193 204 221 219 205 204 221 198 226 264 197 241 202 225 231 214 230 226 244 206 234 219 209 210 264 245 232 228 208 236 211 218 205 196 176 230 221 198 214 222 220 211 211 191 228 214 232 225 209 207 205 218 260 198 231 192 192 217 224 198 220 240 202 202 233 201 198 232 207 180 233 233 228 204 200 221 213 228 224 237 200 189 209 233 225 220 196 235 209 186 195 214 227 207 187 226 212 200 225 223 220 192 223 241 215 222 210 229 200 203 215 217 212 216 186 213 219 219 217 210 204 220 234 204 215 199 244 243 221 231 217 214 211 181 212 227 205 229 225 226 212 180 232 223 206 202 196 232 208 236 211 199 211 229 220 201 231 236 196 215 207 247 223 223 219 204 194 207 177 201 202 229 208 228 210 216 214 199 213 205 214 188 213 213 218 204 206 222 227 204 213 186 203 181 218 210 224 199 209 202 197 212 207 219 211 199 210 226 230 221 241 197 198 211 211 203 208 217 217 191 195 197 221 193 218 220 208 200 196 204 216 192 184 207 203 194 198 213 192 229 223 211 221 224 203 204 206 226 200 229 200 210 210 190 209 199 210 203 206 196 211 218 209 217 209 218 198 203 218 193 204 207 215 199 232 220 232 228 197 202 216 208 213 195 232 208 204 216 212 200 225 201 218 215 210 215 228 200 216 186 228 203 188 213 213 206 214 220 224 184 199 182 204 196 209 201 207 198 243 204 210 197 203 189 215 211 202 219 193 243 205 218 190 193 183 194 209 200 193 210 199 194 214 191 207 203 196 198 206 181 179 213 222 210 215 208 200 209 193 200 203 222 181 204 213 212 187 223 184 180 188 217 198 199 186 211 236 220 189 214 191 207 229 220 193 236 213 205 218 184 187 219 197 203 203 234 218 233 188 195 225 207 187 200 200 232 191 194 183 200 194 209 199 212 192 224 207 191 190 202 224 176 219 196 214 217 202 213 208 183 184 209 218 209 218 191 211 199 190 206 217 210 202 200 193 194 192 216 202 221 209 226 211 197 192 201 216 185 219 192 224 221 205 199 196 177 224 200 200 208 220 215 203 191 190 199 211 182 196 216 182 185 214 189 220 198 225 187 206 203 193 213 193 191 186 202 201 199 178 205 195 227 206 194 192 205 197 199 215 212 215 179 213 180 218 241 177 211 209 218 196 214 176 212 184 193 193 228 200 196 193 213 234 235 192 198 223 192 183 202 214 192 209 224 212 177 224 214 214 213 219 206 199 203 211 208 180 172 203 227 198 192 195 227 222 187 175 216 201 189 218 189 212 187 210 206 213 198 207 188 204 195 216 191 176 195 205 161 179 193 187 219 208 209 205 227 192 180 211 211 188 185 207 185 190 187 219 196 198 200 199 193 191 227 230 197 176 230 198 229 202 221 198 202 207 206 210 203 183 199 202 205 214 191 189 192 198 208 219 200 205 201 208 209 200 205 215 212 208 204 205 190 232 198 195 197 189 206 193 191 179 188 195 200 202 187 216 184 208 169 196 195 192 232 208 176 210 224 200 229 203 218 214 200 192 200 188 184 191 215 199 212 205 203 225 197 243 219 191 200 214 205 205 192 217 206 214 199 220 198 199 184 219 193 209 179 199 220 190 185 188 212 205 192 205 208 226 225 222 215 192 217 200 199 201 189 202 208 228 230 187 224 198 211 197 205 221 193 214 192 209 183 205 187 195 227 218 191 200 211 195 188 220 204 211 213 195 230 182 199 210 204 230 190 231 196 233 201 214 223 171 208 210 235 218 218 184 185 201 212 204 204 206 187 213 213 205 219 206 175 216 202 206 230 217 186 187 211 183 176 212 208 198 209 202 215 208 189 175 218 201 200 218 212 203 200 201 204 211 183 185 196 195 201 207 225 233 195 207 202 215 223 187 218 225 220 228 195 203 207 225 214 176 227 181 228 212 207 204 200 207 208 181 234 220 232 194 214 231 208 179 221 182 200 216 202 193 219 208 208 195 212 213 201 214 197 233 191 210 183 201 200 198 219 188 193 227 209 197 223 229 213 218 225 216 218 200 204 213 224 214 211 218 199 201 228 215 187 209 211 216 224 208 236 190 187 225 210 224 188 215 220 241 225 200 218 243 192 197 209 183 216 213 222 214 210 204 223 203 215 226 228 213 190 235 198 206 209 195 206 215 239 193 213 213 222 216 188 209 212 247 219 181 216 201 222 203 213 214 197 194 226 226 232 215 209 199 211 228 207 234 185 231 195 188 203 268 193 210 229 223 238 226 225 204 263 210 207 243 205 167 214 214 191 233 223 228 207 263 220 211 223 214 235 198 217 223 207 228 212 223 217 199 246 219 226 212 255 218 227 188 203 210 205 207 210 206 206 219 210 225 227 238 242 217 228 234 204 211 223 222 214 211 204 229 212 213 205 206 226 222 241 212 231 208 241 228 196 233 217 222 204 235 232 192 214 217 214 217 222 221 221 216 214 242 201 230 213 229 244 260 231 232 261 226 220 233 201 239 201 218 236 234 242 242 191 225 266 219 258 191 231 211 222 220 257 255 213 249 225 250 203 236 207 210 230 221 203 227 239 232 256 209 239 198 264 232 258 231 265 232 241 237 237 232 263 243 247 242 246 235 247 225 272 228 212 235 227 270 264 241 215 247 211 244 267 259 281 279 247 285 255 273 255 238 263 277 273 270 267 273 283 293 303 308 296 315 300 304 324 349 342 327 335 352 364 345 359 339 375 361 386 370 374 357 369 362 361 386 330 360 344 341 317 305 355 324 316 335 298 329 311 303 289 271 291 273 270 274 282 268 284 239 277 291 259 248 269 264 224 236 230 224 247 268 237 246 216 267 232 209 257 230 241 258 223 223 221 231 226 210 214 222 241 215 226 210 232 218 232 222 219 244 196 211 235 230 225 189 241 235 239 218 214 219 218 214 227 217 208 213 233 215 222 207 191 191 214 246 205 229 210 241 225 231 215 214 193 210 222 221 213 217 215 211 225 270 210 206 201 233 232 187 227 213 234 205 207 214 217 226 189 235 222 207 206 207 199 230 212 213 226 212 219 227 199 190 221 212 230 183 209 206 215 260 212 206 203 203 220 221 221 242 236 205 200 235 204 225 192 213 204 215 220 226 210 218 198 248 212 223 202 213 190 197 208 194 222 211 217 198 209 201 243 208 202 257 218 207 212 228 196 202 234 235 233 219 220 212 211 217 214 198 208 199 204 208 217 216 203 201 211 185 204 220 193 205 215 200 218 209 211 204 201 212 211 190 198 250 190 215 213 220 227 213 202 206 194 218 216 196 191 200 217 186 204 188 208 210 205 223 238 226 225 189 222 213 217 209 202 212 218 192 230 191 227 190 209 226 204 212 213 206 234 200 209 190 224 216 202 233 227 225 208 215 213 214 213 237 198 189 230 228 215 236 212 222 194 192 224 205 230 221 208 228 198 224 213 213 214 238 223 232 217 207 216 206 197 204 211 220 211 206 200 208 200 199 209 199 228 198 218 214 209 216 208 199 194 199 208 232 209 211 212 207 181 235 203 196 218 228 199 208 220 205 225 207 218 194 232 195 219 224 212 223 191 228 206 211 185 196 207 238 197 194 215 216 228 210 186 190 229 203 194 232 209 263 198 258 218 210 208 212 214 220 190 216 250 198 220 213 222 227 173 218 189 203 204 213 209 218 219 209 229 210 235 217 235 229 224 207 226 195 213 198 219 194 193 197 175 220 219 197 212 203 221 245 204 201 182 227 198 190 179 215 199 206 224 194 237 205 196 205 207 221 211 209 215 194 198 214 222 200 193 216 209 219 231 203 233 203 196 199 205 224 215 224 198 204 210 204 215 202 200 206 232 175 194 213 229 228 219 194 228 238 213 220 191 226 222 226 181 195 231 207 208 187 224 202 201 218 220 215 223 176 208 184 186 203 196 213 190 238 210 205 213 202 203 171 236 214 208 207 197 213 192 206 194 197 225 219 214 207 235 204 236 208 201 182 209 203 220 218 204 194 217 208 214 215 200 226 212 210 204 208 256 222 188 226 212 190 220 209 199 224 196 197 228 203 208 205 210 198 214 202 220 220 207 224 183 205 192 211 184 213 176 227 170 193 203 215 204 218 224 199 211 255 180 234 199 197 203 229 213 230 210 218 202 204 221 209 232 228 219 226 219 219 174 234 228 202 196 230 219 208 207 168 211 205 206 191 210 226 215 188 207 233 218 221 226 202 215 202 232 217 236 227 205 218 191 212 208 231 221 215 218 199 187 213 228 266 214 205 199 191 230 221 200 211 243 218 220 230 198 189 202 214 204 215 219 231 202 231 209 212 217 218 205 205 217 220 227 184 238 217 242 217 218 197 229 213 193 221 204 219 219 231 204 222 229 210 208 242 215 229 233 235 208 243 181 196 237 219 234 224 213 210 213 216 211 222 210 226 206 200 229 191 204 235 203 221 231 211 201 214 258 203 206 217 229 205 219 232 257 234 212 216 231 198 216 199 201 209 211 209 216 204 195 209 201 200 212 234 189 214 223 222 212 202 218 234 207 220 177 217 193 205 236 201 214 223 201 230 202 212 213 194 208 221 204 205 242 228 207 232 218 232 216 246 196 215 177 209 198 206 208 190 216 188 224 225 219 206 197 220 230 228 205 242 229 192 211 192 220 232 217 201 207 224 232 201 186 232 208 215 197 221 214 225 215 231 227 223 234 223 223 219 202 196 243 225 206 229 214 228 216 214 224 208 238 225 204 215 218 222 234 223 209 195 222 237 233 199 206 210 216 230 214 224 211 218 191 200 207 219 218 232 215 207 240 199 220 195 202 249 224 194 228 235 214 213 230 234 203 208 203 223 224 227 217 223 233 241 218 249 219 217 221 197 198 214 237 203 212 201 216 229 234 239 231 212 201 226 240 209 239 222 209 202 177 216 245 219 215 229 201 242 225 204 233 217 257 194 219 238 209 213 217 218 206 212 214 226 256 225 197 206 206 215 204 228 233 220 195 204 233 205 225 216 266 215 210 213 229 238 208 207 222 212 204 218 228 218 229 211 232 217 199 229 216 223 220 220 242 217 238 220 193 217 229 225 205 198 236 263 206 184 237 211 223 225 212 234 199 191 198 201 212 233 222 206 217 231 199 223 221 203 207 204 225 240 226 234 209 226 213 231 227 232 220 210 241 234 197 229 207 211 243 244 244 211 209 248 207 210 237 216 230 201 220 205 217 197 218 239 236 200 232 228 208 213 218 203 223 205 244 217 233 220 220 224 217 213 238 219 223 219 219 209 214 212 198 214 190 237 208 262 245 224 205 229 231 207 218 218 188 202 217 208 217 203 240 217 212 227 218 268 226 231 222 233 241 219 194 219 227 200 215 256 244 218 230 226 228 221 236 203 208 209 214 216 224 222 216 223 209 230 218 229 230 220 223 224 221 204 217 205 207 200 227 214 217 216 226 211 223 234 233 234 207 219 199 223 231 202 220 209 229 215 209 235 227 225 223 238 222 217 238 218 209 222 219 248 220 200 218 242 205 227 209 225 223 194 239 237 266 215 211 209 196 216 216 211 215 218 197 232 212 212 195 242 213 213 213 223 242 227 184 222 232 222 228 245 214 193 216 215 188 258 192 227 220 203 226 207 215 223 221 208 224 205 211 240 225 232 234 194 221 199 209 198 245 213 204 190 235 205 216 217 248 221 220 204 249 226 233 271 224 229 244 227 203 238 239 236 241 227 223 211 224 234 209 209 215 203 229 245 220 203 229 205 247 243 229 223 215 222 221 221 216 248 233 214 207 208 230 219 209 217 255 220 211 206 202 219 240 209 191 204 216 240 200 216 202 210 215 214 216 195 231 207 192 210 228 238 231 207 231 218 229 219 222 227 215 242 217 222 222 214 200 238 218 223 230 234 225 227 214 213 222 231 219 230 208 218 227 231 224 244 220 213 220 241 226 241 220 233 209 221 257 211 200 222 208 221 218 235 224 232 227 240 209 217 212 241 221 241 214 227 208 224 219 196 213 219 231 187 234 227 224 216 245 223 195 219 204 231 188 261 226 186 215 210 228 232 236 211 242 249 229 242 258 244 247 207 211 212 215 225 230 233 199 221 218 235 228 206 231 222 217 236 229 209 219 206 235 247 197 207 220 230 222 238 234 231 224 226 205 230 221 243 225 220 226 247 222 240 247 196 206 215 248 202 224 248 232 243 208 259 235 227 245 220 238 243 224 232 226 214 227 214 213 197 220 213 217 235 224 230 206 216 221 249 233 224 213 228 210 224 224 227 215 220 234 239 208 206 227 224 219 235 237 217 214 232 227 246 197 227 225 221 255 202 245 215 202 230 245 228 234 217 203 201 233 220 227 238 222 200 232 242 264 241 211 246 234 218 223 220 218 219 246 220 215 215 216 238 228 239 213 246 240 237 209 195 223 218 215 210 233 256 232 224 217 183 215 209 228 230 247 214 216 217 235 215 215 233 226 212 227 241 219 224 229 238 230 209 210 210 242 240 223 213 212 232 214 238 255 218 211 243 222 211 240 218 211 244 235 231 233 240 223 241 227 233 244 264 236 214 221 245 232 223 242 224 190 220 234 227 220 245 205 208 241 221 238 239 247 262 233 195 232 215 203 224 217 239 235 218 227 220 243 237 257 256 203 228 244 222 248 229 226 225 265 222 234 226 222 210 233 249 241 220 245 237 244 231 216 229 210 237 205 231 256 230 228 237 247 208 260 216 211 224 242 223 269 213 248 214 227 226 220 228 258 247 228 244 213 241 223 215 255 223 255 226 244 236 209 255 237 198 221 223 260 265 224 235 272 242 213 223 216 229 208 207 233 247 204 237 199 233 205 234 220 215 224 222 245 244 215 228 221 229 255 238 244 240 223 290 217 221 248 234 240 193 234 217 216 216 227 260 223 247 226 246 221 223 244 260 192 240 230 222 210 250 235 219 244 223 236 239 208 214 249 238 243 228 213 227 242 228 236 229 223 239 213 213 228 223 233 211 239 227 266 232 241 203 218 233 219 206 234 224 230 204 230 220 210 217 228 227 243 258 218 231 220 249 257 212 228 231 195 247 255 222 227 210 220 248 237 226 228 228 228 218 236 232 216 235 258 222 231 238 215 199 255 224 222 268 211 255 195 240 211 233 250 222 245 219 205 231 242 208 247 224 257 228 207 250 217 260 245 255 245 229 233 242 258 213 249 209 221 232 223 234 245 210 248 224 216 207 215 233 259 237 227 223 228 224 231 268 230 236 229 235 203 235 212 221 229 223 232 276 232 231 241 222 214 233 224 227 238 261 233 240 241 214 231 204 234 228 221 237 219 211 281 238 232 258 230 249 229 218 219 233 246 255 279 245 217 228 221 244 271 237 236 225 235 233 234 237 202 227 233 234 225 247 226 247 244 232 230 239 231 226 231 236 264 246 255 233 241 236 248 274 247 259 231 260 236 248 231 232 238 219 240 240 243 218 255 245 239 227 217 208 244 225 229 256 242 260 232 233 257 248 232 239 247 239 225 224 255 241 245 237 262 229 245 248 229 232 239 238 242 215 246 203 233 229 235 242 228 235 241 248 231 220 223 239 230 216 238 257 212 228 212 227 249 241 229 229 248 219 217 260 194 238 222 217 236 240 264 227 244 249 192 239 245 226 277 221 217 209 275 221 225 234 205 205 231 224 238 228 231 215 215 231 239 224 242 228 216 226 221 222 259 232 220 222 239 219 199 235 250 235 205 190 232 231 220 276 223 218 236 238 227 217 227 267 205 216 228 241 268 234 233 228 209 269 205 225 198 229 179 241 217 248 230 264 240 223 260 208 225 208 212 227 225 247 223 216 248 248 205 238 199 220 204 222 211 223 215 217 225 227 243 223 213 242 225 238 221 259 228 217 217 207 223 236 263 255 220 238 208 216 250 213 236 231 235 237 237 211 228 247 223 262 226 220 223 247 223 220 208 232 213 224 243 274 216 238 234 212 246 222 220 215 216 222 235 227 182 220 208 257 246 218 235 201 217 230 215 209 230 207 249 235 250 245 226 247 220 256 217 217 204 223 248 224 212 240 245 219 242 246 225 219 244 218 224 234 207 227 225 230 260 249 227 227 197 239 233 239 241 236 244 224 227 225 261 209 221 241 235 229 229 195 265 231 223 247 234 266 205 226 255 233 245 218 232 223 224 243 234 208 241 249 225 217 229 239 220 228 206 239 244 227 225 221 224 219 221 216 225 237 201 230 224 225 230 222 226 227 232 235 233 211 256 216 223 229 194 225 218 211 231 266 210 216 215 243 236 260 226 240 225 223 216 230 213 236 232 204 228 221 232 226 225 231 218 222 258 234 228 241 237 215 221 261 268 217 200 185 211 246 264 249 241 260 206 210 247 220 268 213 212 228 230 187 258 230 215 227 235 225 209 223 245 231 228 226 218 220 209 201 257 220 222 214 218 227 242 242 270 206 234 239 230 236 219 229 229 201 224 207 229 233 239 236 216 226 235 220 244 242 206 221 190 241 217 220 204 229 212 259 242 228 221 233 215 231 216 210 245 211 197 213 243 234 224 238 231 282 218 227 242 217 215 240 213 232 222 197 242 236 229 243 219 214 234 240 237 241 232 210 211 223 197 237 231 229 230 232 239 256 223 224 201 209 234 235 236 209 218 239 240 221 205 222 231 226 219 219 245 231 223 204 215 219 229 239 213 207 233 242 218 195 211 223 243 220 250 216 228 256 228 215 223 208 245 241 203 234 208 243 224 245 225 196 223 208 263 244 225 235 240 242 244 220 242 246 279 215 217 225 236 235 262 226 197 218 234 229 233 199 249 219 232 227 241 216 216 240 215 224 222 234 226 242 225 207 241 236 256 222 243 248 218 231 245 246 216 243 220 204 234 215 215 244 263 230 209 226 242 231 227 218 257 204 212 228 256 242 193 209 244 227 220 232 235 237 229 224 235 217 235 219 240 242 240 225 213 204 216 231 205 231 263 238 212 221 208 228 226 214 209 244 225 258 221 210 224 238 210 227 262 256 217 242 232 240 242 220 205 225 242 247 229 215 239 191 200 227 198 233 238 205 226 270 207 234 205 212 221 228 216 218 238 227 232 214 226 234 244 223 244 234 244 221 207 232 219 215 222 217 224 207 225 196 239 242 221 207 248 237 218 256 222 224 248 242 231 225 273 217 204 226 237 242 228 225 232 224 216 257 211 238 229 231 229 232 228 274 237 201 224 226 208 230 222 233 243 227 229 250 212 232 249 212 229 211 201 206 249 214 225 209 228 231 266 213 227 214 230 214 225 224 227 211 239 224 243 203 226 222 244 218 216 245 227 243 271 234 245 260 260 207 245 214 214 257 221 209 209 214 255 225 228 206 218 219 232 229 220 230 206 241 223 255 223 221 232 232 218 196 242 221 202 218 247 222 211 225 238 228 222 227 217 205 215 249 237 224 263 259 228 209 235 242 261 204 237 199 233 239 231 228 223 247 193 219 230 230 245 233 264 242 230 216 248 245 198 194 214 198 223 246 228 237 263 256 235 248 226 224 222 237 229 219 241 231 218 265 249 220 197 229 231 230 217 207 226 237 224 244 216 227 212 237 216 230 246 219 248 217 241 220 238 227 208 230 201 203 279 218 234 237 223 211 238 234 237 224 204 244 211 214 209 231 242 222 240 239 189 240 182 208 216 237 226 207 238 232 220 235 213 221 234 209 214 230 222 226 185 199 238 240 207 231 236 216 229 215 240 237 228 223 209 235 240 213 224 247 211 210 243 231 249 204 233 214 255 230 241 202 217 241 245 223 231 195 272 219 215 232 210 243 223 223 216 227 213 228 237 243 225 233 270 238 224 208 214 199 231 246 206 241 229 235 245 220 234 242 242 218 264 236 224 229 240 221 220 208 234 260 229 192 229 234 222 237 241 268 234 229 225 220 216 256 232 234 205 209 213 233 237 220 217 231 264 226 213 224 240 218 239 227 225 191 218 218 239 201 244 235 242 245 233 219 202 240 225 238 249 249 240 244 212 244 262 232 204 230 220 209 239 199 241 234 246 211 244 212 221 230 205 220 244 246 222 237 222 229 257 227 227 218 219 214 225 231 225 219 224 244 205 210 217 217 231 208 243 216 247 240 233 242 220 238 210 196 213 259 212 227 220 221 242 201 229 246 213 202 212 215 225 223 202 226 221 243 240 279 218 244 224 218 229 221 224 247 233 237 222 214 213 212 225 234 237 220 206 217 224 239 221 235 246 242 207 199 233 233 226 235 231 243 204 256 256 234 230 217 225 231 224 213 244 219 207 210 221 227 231 234 213 227 224 222 261 224 195 243 211 219 228 243 220 195 213 230 216 208 225 219 219 227 233 193 209 240 229 218 239 198 234 240 227 201 223 225 204 205 208 224 245 230 209 206 229 240 230 226 218 203 235 244 211 242 206 222 257 216 209 250 230 222 250 212 250 227 232 223 238 218 195 219 226 221 257 258 237 200 223 227 226 194 241 197 212 232 238 232 215 204 231 217 210 211 228 218 231 217 209 230 242 233 213 229 207 221 225 217 207 223 203 201 198 235 225 225 201 216 193 242 212 216 211 231 208 209 217 231 235 203 220 231 222 244 197 195 208 237 234 230 203 234 242 213 227 246 238 220 224 229 239 219 176 247 243 256 270 210 236 219 219 233 222 225 226 194 214 240 212 214 218 259 224 223 214 222 218 234 224 209 218 231 234 241 198 239 236 256 212 223 220 213 215 238 228 231 202 236 212 260 216 213 234 210 223 255 208 203 242 255 233 236 233 256 224 199 195 231 214 239 220 212 226 213 233 223 226 240 242 223 220 229 225 218 221 241 229 211 229 234 220 237 222 211 205 260 208 229 223 233 231 245 237 206 225 219 221 230 205 225 213 245 213 237 231 228 226 255 225 206 247 249 211 223 212 223 217 242 204 206 231 236 196 234 235 225 202 196 201 228 224 246 233 220 223 223 224 234 226 216 218 193 233 223 246 230 244 233 212 194 182 233 198 235 197 218 222 216 206 213 226 208 220 204 249 235 223 257 214 222 232 217 204 210 205 260 239 225 225 186 234 221 209 217 241 234 257 243 241 245 213 226 224 231 270 222 200 218 208 230 213 257 230 223 246 227 221 229 191 220 246 212 194 246 226 249 221 208 225 225 242 201 230 238 228 202 223 214 266 210 210 216 268 197 281 217 221 241 261 223 241 219 213 215 239 238 219 212 216 232 217 236 219 241 205 235 242 219 263 202 232 214 244 217 217 238 246 233 220 233 257 236 267 240 213 243 231 225 236 268 243 255 244 238 271 245 275 242 244 237 217 235 233 235 250 223 261 243 230 279 272 241 268 284 261 248 263 244 273 259 224 295 313 278 269 258 257 293 237 282 315 231 270 288 257 259 239 244 229 270 280 274 228 267 267 264 233 240 239 228 220 259 262 231 264 232 236 220 225 270 236 230 235 246 258 258 218 267 210 241 244 261 221 266 232 234 261 240 242 239 261 197 245 270 244 231 227 213 234 239 231 216 224 248 235 215 222 242 215 245 195 233 230 222 224 227 229 265 224 235 244 242 233 220 221 242 231 233 236 218 241 249 238 224 239 224 231 264 226 233 215 217 242 207 232 240 229 219 235 231 235 231 227 207 236 249 240 255 241 227 224 206 231 223 225 205 230 220 231 213 256 226 227 233 226 213 218 242 226 231 214 216 262 238 218 204 247 227 207 209 199 233 200 237 232 226 242 232 223 239 210 244 232 221 227 216 218 221 228 217 215 221 187 202 201 233 263 230 238 238 215 242 202 264 233 231 229 234 261 241 218 225 249 201 230 255 230 269 215 238 247 236 212 230 224 217 231 241 215 194 265 214 213 208 226 256 241 198 218 230 223 211 246 237 236 237 210 192 231 223 235 238 244 232 236 231 200 220 238 203 243 230 222 212 219 208 237 218 209 231 220 250 226 217 246 241 219 221 208 217 237 222 201 232 257 230 215 215 236 212 234 247 263 213 216 218 227 266 212 242 247 205 216 235 222 247 242 243 225 236 225 240 238 225 228 232 210 231 245 248 231 211 231 214 258 228 258 230 209 194 235 232 204 229 228 228 219 221 212 250 229 214 230 219 220 212 248 235 231 218 195 226 236 227 220 235 214 223 230 264 262 216 232 248 260 216 244 222 225 230 194 223 245 235 230 234 208 231 213 218 231 206 220 207 200 219 222 239 228 230 232 220 235 222 219 219 233 219 226 234 207 216 217 249 212 246 221 221 215 205 214 215 223 202 205 223 230 261 211 226 216 235 211 245 241 211 220 225 226 243 223 233 223 210 249 205 224 260 231 228 242 206 236 215 208 221 232 191 245 262 212 243 245 263 226 248 211 201 258 228 219 215 190 260 211 242 233 213 209 220 215 219 220 237 220 258 199 242 207 260 235 228 201 220 216 233 218 225 231 226 213 226 229 225 197 218 228 237 246 220 228 243 214 214 217 239 246 240 216 194 219 236 245 227 242 205 212 217 227 200 222 223 234 246 249 220 237 224 191 235 218 261 242 228 229 208 241 223 239 241 237 243 239 222 206 214 227 227 233 232 209 204 192 212 213 239 221 228 203 241 225 237 223 221 226 206 223 241 205 236 232 242 235 209 235 242 218 225 224 229 209 226 227 216 234 235 201 233 226 228 223 218 212 220 241 231 256 230 242 232 217 207 221 224 223 215 226 195 261 236 217 212 229 213 226 218 213 216 200 208 218 209 209 233 218 224 200 226 238 221 244 224 235 194 236 208 232 225 236 239 209 236 230 234 210 237 227 219 248 219 247 212 248 206 227 228 234 231 226 231 238 206 205 220 218 229 216 237 220 224 255 231 194 213 199 216 228 225 198 222 228 221 240 209 221 219 203 225 240 208 214 225 226 258 215 238 213 236 212 227 226 212 238 207 216 242 229 214 240 245 208 233 220 222 232 202 219 240 227 210 200 240 226 236 232 206 214 239 213 216 202 218 232 227 231 227 233 263 203 239 222 224 219 203 241 214 225 221 205 215 227 186 219 220 190 233 213 248 215 203 172 207 255 226 231 250 217 203 255 192 216 233 205 178 236 233 199 230 231 218 206 209 222 215 226 221 230 229 227 222 206 232 222 228 231 219 215 216 220 240 218 228 230 218 232 238 234 220 233 214 221 205 241 212 214 211 188 235 226 229 255 230 244 216 241 225 216 221 218 247 184 203 250 216 185 207 233 212 234 199 190 209 226 234 206 203 213 207 218 235 222 248 228 223 189 238 232 235 222 234 226 235 245 212 209 228 218 210 202 210 212 207 231 219 225 191 216 216 210 199 237 190 215 223 221 196 216 200 236 218 220 243 230 215 226 218 219 215 228 207 219 212 221 230 215 220 222 219 220 225 201 218 224 211 219 216 231 212 237 220 198 211 220 212 230 202 220 256 241 243 217 223 216 196 238 224 224 213 226 235 235 227 214 223 207 220 206 226 209 209 230 216 230 226 221 213 219 200 206 184 239 203 244 216 233 232 202 225 227 260 222 211 190 215 216 240 235 218 211 219 180 257 204 202 211 231 214 218 225 207 222 227 203 212 231 217 225 210 248 203 233 235 233 202 203 206 219 215 217 222 210 244 215 207 233 211 229 223 222 219 225 234 232 217 220 228 200 195 227 260 216 205 210 206 212 240 201 215 202 207 225 208 215 219 210 221 218 197 223 219 231 215 208 220 213 201 230 204 199 206 245 206 208 212 226 224 209 209 263 240 224 171 222 213 201 232 222 238 222 219 215 259 215 225 255 233 198 222 221 214 221 231 210 219 224 211 208 224 187 206 219 231 213 223 186 198 248 208 204 193 223 215 243 219 210 227 240 247 211 209 204 227 207 241 218 235 226 235 224 194 215 202 228 219 222 223 215 241 191 198 228 206 214 238 219 194 198 233 210 231 218 202 222 211 206 220 225 221 228 224 225 214 213 225 207 223 210 227 201 229 212 213 239 219 230 239 215 262 216 220 209 242 209 220 239 226 196 202 217 225 235 227 216 240 203 240 235 234 222 218 215 221 238 214 199 215 220 233 232 246 190 241 203 209 214 236 209 209 223 236 209 195 222 220 218 229 231 215 231 214 255 271 219 219 210 238 242 223 203 217 223 249 212 218 209 212 234 235 221 241 227 223 205 213 218 227 237 219 220 214 225 235 213 223 227 209 218 239 215 237 210 256 237 212 205 226 209 232 232 233 229 229 212 201 224 221 230 177 243 222 214 217 239 224 247 217 244 206 233 232 212 205 211 233 228 231 220 216 197 214 213 239 240 246 242 215 220 218 257 271 230 235 205 215 211 220 209 223 244 203 239 187 225 242 230 222 207 237 215 248 227 226 232 246 222 217 233 239 220 231 217 265 226 213 249 225 213 240 220 241 224 198 217 248 255 233 208 240 216 247 235 216 214 231 239 211 225 256 210 243 207 222 246 239 219 223 223 212 226 218 235 246 210 236 203 226 228 230 222 218 214 231 203 225 228 229 237 212 222 241 217 225 226 212 212 193 236 209 234 224 216 232 223 205 222 227 239 209 263 223 240 234 223 232 234 215 221 197 222 204 237 235 223 229 217 216 229 222 255 208 224 210 218 233 233 218 243 214 234 205 223 222 230 204 216 209 211 227 230 206 203 256 211 226 222 229 212 214 223 222 215 227 233 225 238 239 227 208 207 229 238 232 220 228 209 216 228 208 222 243 213 214 218 222 210 221 246 213 209 236 214 214 196 224 206 226 225 194 209 228 204 233 218 203 212 231 214 232 203 215 231 204 203 234 229 229 196 220 228 202 216 215 228 215 240 236 246 207 217 216 208 238 214 218 239 210 212 227 225 219 221 203 238 245 214 242 231 226 241 226 223 233 211 220 227 244 216 263 203 220 216 205 224 229 221 219 245 222 229 231 235 228 220 217 209 237 231 226 230 210 201 211 223 214 223 193 210 211 217 235 248 194 208 225 243 233 210 211 242 216 215 189 197 256 220 205 211 227 219 227 268 227 228 213 217 218 207 258 213 268 195 227 232 243 212 228 218 222 210 236 233 233 226 217 246 213 227 226 212 232 224 262 200 230 222 215 227 225 214 224 211 225 229 215 233 205 244 214 260 232 210 237 248 220 228 236 248 246 237 234 227 249 235 220 218 235 215 256 237 208 232 216 273 220 242 237 234 225 220 198 225 232 225 202 225 237 229 219 259 246 245 220 204 242 230 247 233 227 224 245 217 229 224 240 214 226 207 233 228 217 216 244 256 241 224 260 220 236 217 248 233 213 229 220 236 227 243 229 226 213 239 218 255 231 243 227 227 230 221 203 258 271 228 244 227 233 210 250 189 218 225 244 218 231 243 195 213 224 236 222 229 219 215 216 212 237 241 233 229 215 205 201 242 214 217 230 203 224 227 225 232 212 230 236 235 211 218 238 214 202 220 232 244 204 206 204 264 205 200 227 228 231 216 211 226 234 260 223 231 217 241 236 213 220 273 233 194 220 225 213 236 213 211 227 229 217 208 225 220 216 218 187 216 277 202 218 222 199 226 213 256 247 224 229 231 244 222 228 225 232 215 218 230 233 223 232 235 237 201 222 211 242 226 233 198 217 223 224 216 212 244 208 191 204 241 245 221 240 219 228 217 218 186 222 236 218 219 210 228 225 213 218 216 206 214 215 249 231 232 217 246 229 229 217 226 218 230 233 192 233 258 228 225 239 222 208 234 247 211 211 202 215 234 220 204 234 226 237 238 222 200 226 261 245 229 218 188 208 211 227 243 242 259 207 234 238 208 259 227 208 236 240 225 227 245 213 230 207 218 239 240 224 205 196 262 223 236 228 191 208 210 275 221 244 236 214 221 237 244 209 226 229 221 229 227 220 208 222 209 214 207 224 226 230 248 221 214 210 225 233 211 207 233 231 226 235 220 206 215 210 221 224 203 219 233 258 229 225 227 234 238 205 239 237 259 235 240 243 222 198 234 234 220 221 241 220 226 221 228 236 213 232 213 229 222 248 222 226 240 215 220 242 213 237 243 209 243 234 216 215 258 218 230 255 239 262 223 222 214 226 236 212 199 224 218 245 214 231 236 229 239 204 230 227 211 241 202 222 233 240 220 225 209 223 226 241 216 227 218 231 209 219 230 212 229 237 212 219 223 206 244 216 265 215 220 215 239 239 239 197 229 221 225 244 210 230 193 210 250 231 226 227 200 240 222 213 205 229 199 227 207 204 204 220 204 202 221 234 234 240 221 263 222 241 259 226 219 231 224 215 258 232 223 199 226 242 239 260 231 211 224 231 222 205 229 223 217 218 223 225 218 228 219 207 233 198 223 212 202 227 248 189 223 207 218 206 237 204 206 195 237 220 239 228 234 209 234 212 222 226 235 223 197 208 226 210 216 211 211 219 262 218 202 222 203 229 240 216 236 209 214 237 197 225 208 217 209 204 195 219 217 239 219 241 248 215 235 249 231 204 243 255 230 210 218 203 228 210 249 221 227 212 213 249 223 217 201 207 201 202 248 244 221 233 238 204 249 237 235 215 216 213 216 225 222 208 215 200 235 205 209 225 243 238 216 230 186 229 224 212 239 230 211 235 219 237 224 187 245 201 259 210 229 237 234 231 238 234 233 233 222 209 226 246 201 212 221 238 227 217 241 212 198 219 211 219 217 213 195 226 229 236 222 208 221 189 234 221 216 212 209 236 205 217 234 243 249 207 221 203 223 243 204 207 223 239 247 189 214 248 220 214 195 232 229 240 218 216 208 202 218 205 228 235 192 188 211 212 208 204 207 218 224 234 204 249 212 233 237 250 242 248 202 226 230 215 192 207 235 223 210 240 206 233 222 194 234 223 234 231 203 206 213 202 212 202 222 229 231 208 246 212 223 243 213 241 217 193 188 235 210 193 242 210 237 208 188 249 217 218 208 259 209 223 206 223 226 243 227 242 222 231 215 204 225 235 195 203 197 238 219 226 207 218 226 216 197 217 212 193 215 242 242 209 216 210 182 213 189 199 227 214 248 189 230 225 217 230 200 216 231 230 228 231 210 232 198 234 221 223 239 236 238 223 237 232 237 231 211 227 192 216 263 197 249 194 210 207 201 234 212 218 215 203 228 208 216 201 204 224 223 230 219 203 224 232 213 208 245 233 186 233 237 215 229 205 207 228 211 213 232 230 201 212 212 217 216 238 245 221 219 207 205 215 228 228 218 197 225 218 201 232 211 217 193 216 228 224 216 205 232 220 215 202 237 220 213 191 231 221 187 224 211 203 214 215 217 207 222 227 237 199 215 201 210 223 221 206 224 222 216 227 210 211 228 196 228 220 233 231 218 218 225 227 241 204 223 213 215 235 206 230 206 203 203 190 211 230 226 236 205 202 243 214 226 228 233 245 214 234 244 222 223 206 201 208 206 210 229 219 220 187 241 220 197 205 213 200 209 220 195 213 229 216 203 190 230 249 208 237 193 193 196 226 199 228 226 211 219 212 216 202 210 210 223 236 227 196 258 232 191 260 211 197 271 244 217 210 259 226 197 210 217 207 220 218 209 230 237 203 208 207 244 215 228 206 237 240 209 202 201 220 218 204 225 206 206 197 181 218 239 191 195 211 249 230 187 218 241 242 220 227 229 205 205 216 222 214 233 196 233 216 222 263 218 233 257 225 218 201 210 233 225 209 212 241 218 228 224 225 210 218 218 220 204 201 207 207 205 248 218 212 214 235 211 221 242 242 208 214 221 229 214 230 221 207 237 235 194 220 211 239 240 195 212 261 209 226 214 240 215 208 247 219 197 212 199 236 246 165 224 222 215 246 207 214 217 221 228 221 225 232 219 233 196 216 228 208 223 222 179 230 223 224 224 215 217 208 221 217 242 241 215 255 208 222 221 200 202 191 239 215 231 196 214 227 228 217 203 225 210 206 236 222 225 233 235 226 215 226 215 223 219 257 229 206 221 213 225 226 221 235 213 194 177 196 219 215 248 186 219 229 219 241 228 232 215 210 220 207 209 237 223 225 197 215 238 219 195 226 226 202 236 203 218 188 207 216 213 221 216 221 216 202 183 213 237 219 214 222 218 210 225 228 236 257 217 230 200 248 249 224 229 229 236 214 208 268 207 228 225 245 228 219 234 237 241 224 216 257 221 220 234 231 235 224 266 220 198 235 210 237 237 213 235 220 227 221 223 207 231 196 219 215 224 205 241 193 202 216 244 243 237 225 222 222 234 239 210 210 222 202 232 261 219 230 192 218 231 201 210 227 216 190 235 211 199 236 218 227 228 227 215 204 230 207 234 204 219 222 197 261 221 206 207 206 213 204 187 221 239 255 238 222 179 224 217 219 217 219 229 231 233 207 237 220 233 241 247 219 227 205 240 227 184 239 218 222 231 207 213 227 208 222 199 184 217 228 213 188 229 214 230 242 238 243 228 231 225 241 237 238 212 228 262 243 230 231 207 213 239 235 216 219 222 229 217 229 234 219 241 245 231 228 210 240 209 221 217 213 232 248 225 215 238 207 211 223 233 222 223 223 214 231 238 226 207 215 224 217 230 221 182 261 214 219 238 235 204 221 219 209 208 235 214 230 219 190 218 210 211 211 225 205 212 232 238 234 223 224 279 229 236 220 224 232 211 245 223 223 236 229 228 201 210 219 239 202 250 227 196 224 230 228 188 223 214 244 242 201 237 219 206 233 199 219 227 221 207 209 232 209 214 234 209 208 222 215 228 202 207 225 215 246 249 219 224 205 221 240 212 225 219 229 213 228 227 233 223 239 216 214 223 230 256 225 229 230 198 232 223 208 229 233 208 231 217 239 261 245 227 233 189 239 223 210 223 230 217 217 224 185 247 215 211 236 216 190 222 223 204 229 226 212 231 238 222 216 219 211 233 225 227 197 258 233 221 201 216 231 258 227 264 208 231 210 229 214 224 222 230 218 217 210 186 233 233 229 218 234 205 220 231 237 205 244 238 214 206 261 213 222 240 203 195 236 245 213 216 227 233 248 213 218 198 231 229 228 222 211 209 249 211 232 212 234 241 233 233 231 218 230 230 238 217 221 224 219 231 225 237 222 239 242 232 225 228 246 237 226 241 231 210 209 229 232 231 245 288 229 237 245 228 211 246 249 248 242 243 227 241 206 210 224 230 237 221 246 245 259 232 242 248 258 247 233 225 221 271 199 234 229 261 226 213 255 263 215 259 226 260 255 273 229 261 259 233 234 261 232 207 219 244 238 240 269 231 212 221 243 262 220 255 242 193 228 256 234 246 215 233 234 212 221 236 223 228 239 220 224 233 232 259 237 225 215 234 237 223 238 224 218 230 243 228 237 208 198 230 209 239 236 206 216 213 262 219 226 248 236 237 215 220 222 225 223 197 247 224 222 217 231 208 207 218 226 261 221 241 210 218 231 220 189 220 233 199 233 218 204 223 258 245 194 238 220 226 240 256 211 228 248 243 221 210 221 232 219 217 248 211 217 220 234 204 232 234 205 239 198 230 225 256 228 218 219 218 242 237 203 213 249 216 227 231 248 228 201 216 201 231 228 201 222 232 201 239 222 215 242 237 228 227 228 245 217 207 204 203 172 202 236 214 205 229 258 203 194 232 244 210 208 265 209 216 213 219 222 237 226 259 236 247 218 218 247 211 224 207 236 222 222 215 261 214 239 223 216 235 242 200 228 263 195 237 216 244 249 205 234 231 264 226 231 241 210 203 219 234 257 245 210 228 231 227 225 221 205 222 222 221 246 232 232 215 230 218 235 238 224 233 209 198 219 205 234 241 264 185 231 233 230 206 246 222 235 229 232 230 204 204 212 194 187 216 203 216 227 226 234 203 226 217 214 210 219 228 240 204 242 239 237 231 224 220 228 209 214 230 204 208 221 212 244 215 225 235 215 211 231 220 219 235 211 209 240 214 230 212 211 224 227 213 214 216 223 229 216 231 217 216 227 224 189 190 218 205 222 211 216 240 216 209 231 225 227 225 232 235 205 230 226 232 222 229 175 212 191 237 239 233 195 224 190 227 219 205 238 216 213 208 232 228 233 211 241 218 189 198 222 255 235 217 226 226 206 241 198 206 187 227 219 245 198 238 218 209 197 208 234 216 221 241 207 215 227 186 203 218 213 235 225 206 236 214 215 230 244 201 209 190 227 233 229 241 233 203 227 204 208 225 223 246 265 200 211 220 211 237 216 245 237 232 216 220 235 225 221 220 220 219 208 236 214 221 235 247 245 229 210 234 211 231 197 206 220 232 235 201 204 197 218 203 230 262 220 233 217 220 247 227 205 242 182 241 199 207 227 239 197 240 265 211 221 239 193 227 205 241 223 220 224 236 233 216 213 221 214 235 256 220 221 210 207 212 262 227 211 227 255 230 245 230 221 219 207 206 207 204 219 226 215 227 242 231 219 229 201 214 233 224 217 227 247 215 191 230 227 239 225 222 202 217 222 199 227 219 196 219 248 198 220 227 216 212 209 218 213 219 227 224 216 234 228 224 232 227 207 225 217 199 212 223 226 202 235 228 249 230 217 211 231 224 245 231 234 237 233 230 245 235 240 257 234 247 230 207 215 231 230 236 196 229 202 233 212 241 232 227 234 212 255 210 205 230 219 209 224 237 224 224 208 227 221 218 219 207 222 214 235 221 208 209 264 239 220 222 210 241 201 221 256 216 224 260 217 219 244 226 223 236 229 228 220 201 257 233 256 201 194 216 198 236 218 219 238 222 217 216 238 200 217 239 261 220 226 235 223 213 228 189 212 198 224 219 223 230 223 227 225 233 210 265 236 242 214 221 243 224 232 213 213 248 199 200 209 217 246 240 231 232 219 216 228 236 218 217 239 220 214 226 232 210 237 232 229 221 224 210 234 238 219 221 230 193 228 225 205 208 209 229 195 217 203 243 247 244 211 213 239 249 237 217 212 206 257 228 221 255 234 212 211 229 225 213 226 215 217 205 221 203 217 230 228 247 231 222 217 206 221 212 219 236 200 257 223 209 257 248 197 231 218 231 245 241 210 227 227 257 237 232 194 235 223 216 275 225 214 228 203 249 216 197 228 243 226 234 215 250 218 194 226 248 227 238 231 210 221 245 271 219 193 218 228 209 238 211 233 222 226 239 221 245 224 202 263 226 210 216 227 235 202 226 210 202 215 219 217 235 214 201 208 215 261 242 214 232 177 244 215 211 201 207 228 234 223 217 270 222 242 236 257 238 227 224 219 214 229 223 210 214 247 224 201 216 235 220 233 225 230 216 196 228 227 242 200 224 229 256 255 239 230 219 232 232 236 222 235 228 204 228 232 233 230 243 215 205 225 266 220 224 256 224 209 230 222 214 215 223 223 199 217 219 221 223 249 226 218 219 226 234 232 231 224 219 249 263 216 235 212 225 231 230 234 207 205 214 238 235 249 238 244 241 236 229 231 258 201 223 245 221 241 224 222 241 248 205 229 213 211 265 218 228 231 216 235 219 195 232 244 204 221 244 232 214 223 210 234 232 262 225 264 201 220 231 229 202 262 208 208 264 250 258 205 261 230 219 242 242 242 229 229 209 234 226 228 230 208 243 244 224 224 200 212 203 216 225 236 240 211 225 236 240 223 241 203 249 219 218 201 237 216 197 235 237 216 237 229 225 259 245 274 262 238 225 238 209 203 213 219 215 219 203 230 249 242 241 213 230 237 233 209 267 222 236 259 214 234 233 221 229 215 236 230 223 246 218 235 215 233 245 216 260 236 218 228 228 230 219 234 241 238 209 201 233 263 204 260 240 226 237 234 238 221 216 237 224 226 229 210 220 239 187 245 204 228 245 226 233 222 234 241 247 238 214 233 235 228 249 223 242 199 233 249 256 218 229 231 222 214 222 264 234 211 201 219 213 219 240 238 217 228 220 230 232 207 209 226 223 199 225 242 225 217 242 247 244 200 199 232 220 207 234 220 225 203 228 231 227 228 236 266 248 236 214 260 220 219 221 216 239 227 218 223 226 219 239 239 207 236 222 232 231 223 233 245 224 230 221 228 217 231 217 221 217 212 208 204 248 221 210 234 230 237 222 245 244 211 216 241 242 216 205 255 191 223 223 227 243 228 200 242 212 236 212 228 239 221 223 246 234 257 215 223 257 213 235 248 235 237 224 246 227 221 179 219 223 233 227 229 235 239 189 235 221 238 217 248 243 218 217 214 235 230 199 228 208 221 266 234 233 203 227 225 233 239 242 241 214 223 209 234 225 223 212 190 238 237 255 208 217 216 241 240 223 236 227 225 209 238 240 246 233 230 217 215 237 227 183 209 234 218 234 218 232 233 231 229 196 208 221 236 238 237 228 216 211 195 234 205 226 224 248 245 214 239 236 209</counts>
			</dataPoints>
		</scan>
	</xrdMeasurement>
</xrdMeasurements>