File: data/XRD/XG-Luft/XG-750/W6822-1D_XG_Luft_750.xrdml
<xrdMeasurements xmlns="http://www.xrdml.com/XRDMeasurement/2.1" xmlns:xsi="http://www.w3.org/2001/XMLSchema-instance" xsi:schemaLocation="http://www.xrdml.com/XRDMeasurement/2.1 http://www.xrdml.com/XRDMeasurement/2.1/XRDMeasurement.xsd" status="Completed">
	<comment>
		<entry>Configuration=Factory configuration, Owner=User-1, Creation date=7/8/2013 4:01:53 PM</entry>
		<entry>Goniometer=PW3050/65 (Theta/2Theta); Minimum step size 2Theta:0.0001; Minimum step size Omega:0.0001</entry>
		<entry>Sample stage=MRD Cradle; Minimum step size Phi:0.01; Minimum step size Chi:0.01; Minimum step size X:0.01; Minimum step size Y:0.01; Minimum step size Z:0.001</entry>
		<entry>Diffractometer system=XPERT-PRO</entry>
		<entry>Measurement program=C:\PANalytical\Data Collector\Programs\Jorrit\2thom\_absolute_2th-om_10-130deg_PIXscan_56min.xrdmp, Identifier={15BCCF57-2807-42BD-B5B9-ECC0B3DC9284}</entry>
		<entry>Batch program=C:\PANalytical\Data Collector\Programs\SimonL\batch6x_2thom_10-130°_z9.1_x0,10,20,30_y20,40_57min - Kopie.xrdmp, Identifier={8874E540-C3F4-4307-831A-CD55F073CDCD}</entry>
	</comment>
	<sample type="To be analyzed">
		<id></id>
		<name></name>
		<preparedBy></preparedBy>
	</sample>
	<xrdMeasurement measurementType="Scan" status="Completed" sampleMode="Reflection">
		<comment>
			<entry>_absolute_2th-om_10-130deg_PIXscan_56min</entry>
			<entry>PHD Lower Level = 4.83 (keV), PHD Upper Level = 11.27 (keV)</entry>
		</comment>
		<usedWavelength intended="K-Alpha 1">
			<kAlpha1 unit="Angstrom">1.5405980</kAlpha1>
			<kAlpha2 unit="Angstrom">1.5444260</kAlpha2>
			<kBeta unit="Angstrom">1.3922500</kBeta>
			<ratioKAlpha2KAlpha1>0.5000</ratioKAlpha2KAlpha1>
		</usedWavelength>
		<incidentBeamPath>
			<radius unit="mm">320.00</radius>
			<xRayTube id="1010048" name="Empyrean Cu LFF HR (9430 033 7310x) DK442154">
				<tension unit="kV">40.0</tension>
				<current unit="mA">40.0</current>
				<anodeMaterial>Cu</anodeMaterial>
				<focus type="Line">
					<length unit="mm">12.0</length>
					<width unit="mm">0.4</width>
					<takeOffAngle unit="deg">4.2</takeOffAngle>
				</focus>
			</xRayTube>
			<xRayMirror id="27010001" name="Inc. Beam Cu W/Si (parabolic MRD)" hybrid="false">
				<crystal type="Graded" shape="Parabolic">W/Si</crystal>
				<acceptanceAngle unit="deg">0.800</acceptanceAngle>
				<length unit="mm">60.0</length>
			</xRayMirror>
			<sollerSlit id="21010002" name="Soller slits 0.04 rad.">
				<opening unit="rad">0.0400</opening>
			</sollerSlit>
			<mask id="22030007" name="Fixed mask 2 mm">
				<distanceToSample unit="mm">220.00</distanceToSample>
				<width unit="mm">2.00</width>
			</mask>
			<divergenceSlit id="22010007" name="Fixed slit 1/8°" xsi:type="fixedDivergenceSlitType">
				<distanceToSample unit="mm">220.00</distanceToSample>
				<height unit="mm">0.19</height>
			</divergenceSlit>
		</incidentBeamPath>
		<diffractedBeamPath>
			<radius unit="mm">320.00</radius>
			<sollerSlit id="21010002" name="Soller slits 0.04 rad.">
				<opening unit="rad">0.0400</opening>
			</sollerSlit>
			<receivingSlit id="22010001" name="Fixed slit 4°">
				<height unit="mm">5.88</height>
			</receivingSlit>
			<detector id="7010017" name="PIXcel3D 1x1 detector" xsi:type="areaDetectorType">
				<phd unit="%">
					<lowerLevel>30.0</lowerLevel>
					<upperLevel>70.0</upperLevel>
				</phd>
				<mode>Scanning</mode>
				<activeChannelsEquatorial>255</activeChannelsEquatorial>
				<activeChannelsAxial>255</activeChannelsAxial>
				<pitchEquatorial unit="mm">0.05500</pitchEquatorial>
				<pitchAxial unit="mm">0.05500</pitchAxial>
				<readOutPeriod unit="seconds">0.135</readOutPeriod>
			</detector>
		</diffractedBeamPath>
		<scan appendNumber="0" mode="Continuous" scanAxis="2Theta-Omega" status="Completed">
			<header>
				<startTimeStamp>2024-10-25T20:04:47+02:00</startTimeStamp>
				<endTimeStamp>2024-10-25T21:00:53+02:00</endTimeStamp>
				<author>
					<name>PRO-MRD</name>
				</author>
				<source>
					<applicationSoftware version="6.1b">Data Collector</applicationSoftware>
					<instrumentControlSoftware version="7.0E 20130304">XPERT-PRO</instrumentControlSoftware>
					<instrumentID>0000000011142674</instrumentID>
				</source>
			</header>
			<dataPoints>
				<positions axis="2Theta" unit="deg">
					<startPosition>9.99826193</startPosition>
					<endPosition>129.99755682</endPosition>
				</positions>
				<positions axis="Omega" unit="deg">
					<startPosition>4.99913096</startPosition>
					<endPosition>64.99877841</endPosition>
				</positions>
				<positions axis="Phi" unit="deg">
					<commonPosition>0.00</commonPosition>
				</positions>
				<positions axis="Chi" unit="deg">
					<commonPosition>0.00</commonPosition>
				</positions>
				<positions axis="X" unit="mm">
					<commonPosition>10.00</commonPosition>
				</positions>
				<positions axis="Y" unit="mm">
					<commonPosition>0.00</commonPosition>
				</positions>
				<positions axis="Z" unit="mm">
					<commonPosition>9.100</commonPosition>
				</positions>
				<commonCountingTime unit="seconds">32.895</commonCountingTime>
				<counts 414 425 410 425 415 456 419 398 402 413 411 372 417 407 446 405 414 401 397 419 384 420 432 441 422 409 380 449 435 440 398 419 432 447 435 413 402 429 436 442 422 441 408 407 466 395 413 394 432 434 388 443 402 409 444 408 401 430 421 420 435 410 417 397 403 388 415 415 421 414 396 444 390 396 408 395 446 422 383 433 402 411 390 411 395 410 418 376 400 389 389 405 383 401 420 423 377 412 431 371 387 418 387 422 400 375 385 414 456 418 427 396 386 384 377 388 407 400 388 398 389 366 373 399 370 351 410 377 391 374 399 404 415 422 350 375 421 378 422 396 374 390 401 373 368 359 368 385 393 373 322 372 365 411 400 382 377 438 352 374 430 407 406 401 384 363 392 386 389 350 387 366 404 342 350 382 381 379 379 375 389 370 396 375 366 364 382 405 364 367 363 406 389 373 397 386 345 373 377 379 375 384 386 361 360 368 367 400 391 367 379 379 377 371 351 345 374 404 370 354 367 352 375 331 387 346 361 343 383 386 343 351 409 377 421 359 350 354 371 352 328 376 344 349 335 407 380 347 342 376 356 389 358 346 373 336 352 322 384 362 384 317 374 355 382 358 371 423 380 341 387 393 327 351 329 354 348 337 367 335 366 362 351 375 351 362 350 345 345 350 343 337 351 357 360 336 351 354 359 365 332 364 377 336 377 340 364 359 390 336 346 338 363 331 379 354 320 319 359 343 353 356 349 377 347 339 360 382 347 358 349 310 298 334 342 360 340 330 329 321 335 324 343 319 311 342 337 310 319 331 348 338 337 358 314 358 331 339 363 329 342 362 318 352 341 359 319 310 346 347 358 354 303 324 325 347 314 356 355 337 304 326 329 305 317 323 336 343 301 338 305 341 332 329 325 323 330 354 349 347 323 309 327 327 320 328 317 322 340 328 324 350 371 322 362 350 300 335 313 333 316 328 319 318 289 352 333 320 293 336 346 338 357 332 341 330 321 320 318 324 307 338 322 335 342 322 311 286 303 345 324 306 304 327 326 365 321 320 300 359 318 316 306 324 279 320 318 343 333 354 299 321 348 315 331 330 307 343 331 293 310 300 356 300 314 328 345 337 314 321 300 310 296 314 272 330 327 317 337 321 339 335 306 354 324 292 281 294 337 303 286 315 310 317 320 327 317 308 302 304 268 342 322 312 327 315 331 300 310 310 285 311 313 292 309 319 292 350 268 307 319 337 328 307 316 321 308 331 300 266 347 331 295 298 310 291 318 319 303 322 312 336 268 306 299 279 338 306 308 291 289 301 295 295 302 333 325 338 296 326 321 282 311 322 295 326 334 310 300 315 305 271 337 330 297 319 301 330 307 311 307 297 332 299 317 277 299 316 292 273 300 309 323 289 304 314 292 301 332 307 264 308 332 273 299 273 298 314 293 295 281 314 294 299 289 332 270 284 323 308 346 297 323 304 296 295 319 284 302 324 283 302 319 302 305 298 302 320 307 321 270 319 307 307 286 316 257 319 310 246 261 290 333 328 290 319 310 312 293 294 304 311 304 305 296 318 292 279 303 323 293 293 298 320 292 274 303 288 323 291 279 305 304 282 289 283 300 306 288 296 275 310 316 287 302 303 319 301 321 298 291 309 291 262 316 302 312 265 302 325 342 298 285 285 282 292 288 291 310 284 271 302 291 326 309 308 273 287 288 322 316 324 293 327 319 290 289 302 291 320 306 285 305 309 266 269 291 290 321 317 281 270 310 312 300 292 336 302 310 317 295 280 325 311 288 320 303 299 282 299 295 303 294 289 309 310 307 311 270 294 306 294 298 320 306 305 292 308 301 295 295 286 312 294 299 290 288 311 267 283 278 276 323 295 289 306 300 306 298 282 316 271 324 262 294 303 282 276 300 314 326 310 309 288 325 286 322 293 305 300 302 290 278 342 294 302 309 297 298 290 297 292 304 293 320 287 296 328 296 310 322 308 271 307 273 302 306 302 281 311 307 313 308 322 301 304 280 270 313 267 295 323 294 296 318 283 304 297 298 260 305 314 301 318 319 339 301 298 316 298 302 326 297 317 331 342 318 301 316 323 281 340 321 321 309 298 323 328 305 301 305 301 295 299 282 293 299 289 329 288 293 300 309 314 303 276 325 302 316 278 307 308 316 286 312 278 293 300 305 308 334 329 336 304 281 292 303 299 330 314 327 345 291 307 324 282 312 288 304 302 311 314 299 302 311 312 296 347 314 292 284 281 310 307 321 273 304 296 285 326 306 335 305 306 302 337 302 290 300 315 313 275 306 321 300 304 308 302 317 323 329 306 285 320 324 240 302 299 295 286 249 327 306 287 306 279 298 312 281 300 297 289 277 312 299 289 287 316 317 288 294 301 288 318 341 319 272 325 286 290 317 312 269 282 295 293 309 308 310 299 306 319 299 301 314 313 335 285 313 289 321 308 275 301 332 306 316 318 312 324 324 304 294 312 314 313 326 290 317 305 290 287 306 288 311 314 315 333 335 303 313 329 298 294 321 293 335 269 302 308 290 266 332 355 366 312 321 292 302 282 308 328 311 274 300 297 311 326 342 291 303 314 313 324 291 292 338 308 300 301 317 297 303 298 306 308 291 330 319 282 298 312 310 299 322 307 335 322 284 324 294 321 345 311 304 303 301 289 304 326 288 315 323 316 276 339 329 305 285 322 319 298 306 313 286 336 322 323 332 326 332 324 316 285 298 291 337 322 315 311 301 301 311 349 295 308 306 317 324 317 316 299 296 309 271 292 322 320 365 295 270 320 315 316 315 319 306 296 277 340 289 319 322 302 316 300 300 306 285 272 297 338 297 296 321 305 300 281 315 314 304 282 299 308 303 305 354 312 294 316 315 320 316 307 301 315 336 313 281 313 325 318 327 295 303 312 283 283 334 310 319 314 327 319 309 323 304 297 297 296 328 322 295 284 324 318 314 287 332 314 301 314 303 312 309 330 285 318 312 333 290 312 319 329 289 341 343 296 333 305 304 306 308 315 323 307 319 264 320 291 289 313 315 300 304 299 328 283 309 286 298 318 311 300 289 298 278 307 306 321 290 279 319 333 296 334 309 306 318 306 331 356 303 324 289 298 317 311 309 306 275 317 302 294 296 301 300 334 292 287 330 281 302 308 320 312 305 321 320 287 294 327 311 308 328 339 323 301 305 268 279 345 317 318 325 315 307 311 292 312 310 288 283 295 308 280 307 310 319 303 279 272 307 299 326 282 274 301 279 315 304 286 306 291 311 276 295 311 287 295 280 280 343 298 267 304 284 310 300 287 323 290 334 281 283 261 292 310 318 310 293 294 296 289 293 315 283 293 310 295 256 282 315 287 300 299 280 294 296 287 311 320 293 313 288 291 259 316 289 286 289 342 278 267 293 319 302 301 303 307 301 324 281 309 276 281 307 290 277 321 297 276 301 274 322 285 302 271 283 296 307 296 300 298 320 267 321 303 314 308 318 307 283 298 296 267 283 287 279 301 306 308 284 293 283 309 316 287 301 288 294 292 281 288 311 281 292 297 306 303 281 288 261 294 299 287 293 258 269 302 294 299 270 275 281 297 288 272 302 279 293 301 279 291 273 322 286 275 293 285 275 280 295 288 295 296 291 276 309 263 301 274 286 282 305 284 263 282 299 289 258 267 305 277 278 268 309 286 316 265 268 293 276 292 256 288 287 310 276 261 278 302 280 266 288 260 260 296 261 276 249 298 266 282 282 279 266 302 305 284 286 265 297 308 246 261 273 275 268 301 269 306 258 274 278 262 301 274 295 272 249 293 322 269 293 249 260 297 301 238 256 241 292 271 273 299 263 309 238 272 292 263 281 231 314 290 288 288 267 288 289 257 269 271 276 297 297 246 244 293 285 304 284 273 271 270 284 267 293 244 248 245 284 259 281 286 247 234 282 289 268 265 243 291 240 294 267 294 306 264 266 294 261 259 265 285 292 259 278 264 272 279 281 268 248 269 297 268 295 261 278 263 295 268 275 238 260 268 249 275 270 260 289 277 249 263 232 265 271 263 300 284 276 291 264 284 268 273 272 264 231 266 272 249 308 265 256 310 245 240 223 237 259 262 275 259 265 277 269 231 266 263 255 290 257 261 275 264 246 275 265 250 245 278 268 265 271 258 274 284 232 271 282 228 273 260 243 281 234 277 280 264 241 287 280 267 255 259 262 261 263 240 273 274 274 249 270 294 263 227 241 236 245 221 277 230 282 308 237 265 257 256 267 260 266 248 239 249 268 270 285 275 241 269 260 247 226 261 275 246 246 234 237 245 236 248 222 229 274 262 245 222 240 245 263 256 272 268 235 270 242 257 273 223 269 236 274 244 245 257 221 260 231 240 242 269 268 270 238 241 257 245 240 258 272 272 229 220 246 244 236 265 259 247 249 235 282 236 239 238 239 265 237 256 262 263 213 262 264 246 237 263 242 248 248 223 259 245 232 247 225 289 264 263 236 255 274 247 284 228 249 247 243 264 228 226 246 226 278 263 244 249 221 237 234 216 240 229 223 261 274 273 237 273 237 241 236 233 227 269 249 261 231 261 229 234 247 267 245 276 273 259 238 243 243 222 247 258 213 238 263 233 237 237 234 240 249 231 257 220 261 231 257 223 231 268 237 257 261 234 225 266 230 249 243 239 222 255 227 241 243 210 228 259 240 224 237 227 230 230 205 237 257 238 286 241 246 231 248 239 226 234 228 247 222 234 257 260 244 241 260 268 236 257 232 219 230 216 241 265 214 217 258 231 246 250 237 245 244 267 257 230 272 233 242 267 245 235 234 276 232 255 225 237 245 230 240 231 242 226 270 280 221 223 240 242 262 265 238 242 287 246 262 208 243 244 233 271 269 267 259 261 250 267 263 282 231 283 259 272 263 233 237 261 248 245 257 270 246 228 249 268 264 263 221 263 286 261 214 260 248 229 231 237 210 236 231 247 214 247 219 214 231 238 241 236 238 234 243 255 229 234 191 276 266 264 239 235 222 235 249 246 245 220 246 243 229 222 258 248 229 282 265 243 223 248 226 237 237 234 231 223 245 215 226 226 268 247 226 239 265 245 259 220 229 215 243 215 225 238 244 222 215 225 224 217 256 232 219 229 246 203 239 210 261 223 235 249 228 214 264 228 258 217 246 261 225 242 234 214 235 230 226 208 233 235 210 245 214 209 211 244 220 204 275 220 221 231 225 236 226 208 233 245 203 249 221 205 228 232 260 201 235 233 219 209 227 244 216 246 220 240 213 224 230 249 249 215 220 262 213 220 243 233 224 229 229 236 223 268 235 259 263 248 242 227 196 228 219 272 236 208 235 241 236 219 243 234 229 199 225 205 224 221 213 203 269 245 234 246 241 232 246 227 217 232 240 264 225 241 249 233 234 228 211 225 215 222 215 219 239 216 240 219 194 244 235 240 234 263 241 239 230 223 245 227 243 236 221 201 223 233 210 229 215 231 210 233 225 226 226 225 231 221 242 215 191 220 218 230 232 211 234 202 224 218 225 224 246 219 225 231 262 246 246 223 221 225 202 207 212 245 228 230 215 248 225 227 211 225 220 225 241 235 211 268 245 193 227 224 225 211 228 204 224 233 209 248 200 259 215 205 229 221 230 215 209 214 213 190 242 236 229 225 213 224 206 246 227 208 234 209 271 211 220 224 255 260 210 215 223 197 220 237 233 220 232 261 232 218 205 235 222 227 255 218 214 222 232 204 217 242 232 241 218 220 225 207 223 208 222 260 216 218 219 241 210 208 206 219 232 223 232 216 213 208 228 209 223 231 220 211 230 225 227 213 235 216 238 215 189 226 270 220 236 206 210 232 220 202 229 210 232 209 240 217 240 201 230 221 209 216 225 245 216 228 210 212 220 218 196 205 229 226 232 232 223 228 207 279 223 240 218 196 259 219 214 243 234 223 207 201 197 256 220 203 186 220 222 204 236 242 212 193 258 221 265 234 233 195 228 210 224 227 222 219 218 218 218 228 233 199 231 265 219 236 231 201 220 230 225 240 226 226 206 247 237 258 260 239 201 217 238 224 238 187 219 220 223 235 213 222 247 183 213 236 229 239 227 269 184 237 242 234 240 234 194 246 216 230 222 224 232 223 225 207 226 236 211 261 216 232 222 244 227 231 243 224 284 260 234 247 233 231 219 217 241 233 230 237 241 239 213 215 227 208 218 232 223 233 236 220 235 248 206 238 229 256 227 219 230 239 235 228 275 235 210 206 233 231 220 212 247 248 220 216 225 219 214 217 235 216 235 278 214 225 225 206 227 226 240 213 212 225 229 222 206 222 197 213 230 213 229 221 246 206 204 193 225 208 213 207 225 196 224 225 212 209 224 232 202 237 233 229 215 208 243 230 241 208 211 233 219 201 190 190 243 220 226 204 198 216 216 235 188 229 229 227 199 214 236 219 203 200 249 233 198 212 225 224 214 241 215 209 201 236 248 185 249 237 211 229 213 216 210 199 230 191 200 188 226 224 214 241 205 219 261 230 216 202 220 219 230 222 222 235 216 229 222 218 194 230 226 222 212 217 207 210 221 227 215 208 209 208 226 237 210 212 222 247 236 191 226 224 208 205 221 246 212 227 224 226 225 221 244 212 227 204 228 217 202 192 203 212 209 211 225 226 219 218 198 224 210 231 221 229 215 228 237 209 236 228 216 190 215 204 233 203 244 230 215 217 209 214 214 227 240 228 224 211 225 204 247 205 215 243 208 220 196 214 235 199 219 199 236 220 223 223 224 234 235 214 193 237 209 201 238 220 229 232 212 225 231 210 245 228 232 222 203 214 224 227 228 228 211 218 220 225 218 223 225 217 244 238 221 220 237 205 213 216 213 213 212 215 212 237 204 217 241 205 239 231 222 199 202 214 218 228 200 216 216 218 187 201 231 213 233 213 223 243 218 183 196 204 187 201 227 201 209 204 217 206 200 222 231 241 209 232 227 229 218 208 206 209 201 186 213 229 238 217 236 226 207 236 221 214 214 213 216 230 227 213 223 219 216 221 219 205 208 205 217 227 233 212 209 212 228 204 199 212 221 265 203 207 236 217 219 204 192 229 227 243 206 249 204 193 236 212 225 198 229 228 243 220 210 187 200 230 222 212 227 192 216 201 213 195 214 192 217 208 222 212 208 224 226 241 186 208 239 223 268 227 215 204 197 242 216 243 217 227 233 221 235 237 228 202 203 219 223 213 198 230 210 199 230 204 223 231 233 239 213 198 236 221 255 167 217 231 201 226 219 246 232 231 222 195 208 240 245 255 203 217 207 257 208 199 242 204 237 222 209 223 216 270 228 222 230 233 213 212 265 234 218 212 214 249 227 225 238 244 241 248 234 214 214 208 208 190 212 216 224 226 198 233 209 204 225 234 211 223 224 234 236 230 222 212 224 225 226 222 207 192 205 192 227 244 236 229 211 226 230 224 227 202 227 234 224 200 237 222 237 192 208 200 234 207 207 212 222 220 199 181 217 214 260 205 196 220 189 225 208 215 232 215 216 228 215 226 243 245 228 190 221 216 194 201 218 234 202 217 248 235 210 260 246 244 233 188 211 234 218 244 223 241 233 239 232 250 241 238 237 211 231 206 197 227 258 238 232 226 211 271 229 245 219 240 223 239 255 222 216 223 268 241 209 249 205 211 211 234 220 241 239 240 219 229 274 240 240 236 230 225 232 217 235 245 237 239 220 250 234 257 248 271 249 257 235 243 224 257 266 262 257 266 230 240 248 242 264 297 258 248 263 250 235 264 269 268 244 243 260 240 280 284 262 303 271 279 276 282 288 270 273 265 314 313 300 319 319 308 352 298 329 335 334 357 376 400 375 364 391 382 378 420 400 409 381 412 402 370 404 409 369 378 386 394 363 324 357 324 334 301 311 323 314 325 329 292 260 272 310 273 265 257 245 264 249 228 285 241 270 270 263 244 241 264 233 243 265 246 206 231 236 224 262 260 229 237 230 246 224 220 245 236 229 244 241 227 217 239 241 245 241 212 215 233 246 244 260 209 210 250 203 198 241 230 220 246 209 238 236 241 234 215 204 203 205 240 235 210 240 209 228 247 200 249 225 198 226 239 225 206 227 236 242 216 210 216 241 249 204 189 228 243 236 228 255 227 218 217 227 199 228 218 243 239 213 231 241 224 233 220 243 237 201 216 217 237 232 230 230 201 241 209 215 211 242 231 213 220 227 223 269 241 228 233 204 216 215 218 221 216 242 232 221 212 225 232 226 211 207 227 213 223 229 222 231 200 232 209 193 221 210 258 230 234 236 215 211 245 207 231 214 219 264 208 227 208 212 218 228 228 237 207 243 230 208 236 200 212 215 225 210 201 225 210 200 213 215 217 235 239 247 223 198 199 221 217 206 232 208 202 246 259 235 238 224 218 219 194 242 230 196 224 210 199 214 220 243 246 190 227 212 215 223 227 234 231 227 202 214 232 222 243 219 210 228 224 235 230 238 224 237 231 228 212 224 221 247 219 211 218 195 241 233 225 215 215 214 268 216 211 234 232 211 195 186 220 203 213 243 267 230 213 231 216 236 197 219 234 198 210 220 224 223 234 244 224 228 220 226 224 218 195 243 223 202 219 206 235 198 231 222 227 190 227 209 225 192 230 221 249 237 226 239 203 225 222 213 238 242 233 219 228 212 194 245 222 184 222 227 192 246 201 214 203 234 232 237 213 216 215 228 211 213 224 257 196 212 226 237 244 213 219 195 212 222 225 241 231 223 241 213 225 188 218 230 220 227 220 212 230 212 225 237 230 226 219 215 258 237 244 223 218 235 239 242 214 216 208 228 217 225 214 244 266 238 225 225 232 231 215 230 227 230 235 255 258 218 225 209 205 222 242 225 210 228 188 273 231 227 243 213 228 229 218 248 240 221 236 224 223 237 220 239 236 256 212 223 232 222 226 246 242 203 223 199 233 219 239 232 238 225 218 238 241 212 219 228 211 239 208 275 231 232 226 234 215 206 216 219 206 263 210 228 217 219 203 230 219 218 223 220 219 230 237 228 243 234 243 215 237 218 229 217 233 238 206 227 230 193 260 222 226 207 231 246 205 247 228 229 214 244 221 230 220 221 208 213 219 231 210 224 222 215 206 237 226 212 209 258 202 208 235 218 224 225 193 195 218 216 217 214 231 227 223 231 202 231 235 258 243 211 259 237 224 238 234 216 217 213 211 213 196 216 235 226 242 227 203 228 205 239 227 227 209 225 218 184 232 228 224 190 227 211 246 225 230 223 227 245 215 237 236 220 226 227 199 209 222 210 211 223 229 227 231 223 222 208 212 221 228 245 202 216 195 216 249 227 207 212 208 240 231 212 258 230 219 228 245 245 225 288 215 232 221 208 227 232 211 219 249 222 218 232 210 231 190 232 207 237 233 221 232 226 241 220 222 221 219 243 225 232 203 216 224 234 226 219 218 199 209 209 229 206 229 212 236 223 242 206 209 228 232 232 234 224 215 240 237 229 212 212 214 244 233 210 216 241 236 235 199 239 240 220 224 200 211 260 247 219 197 223 246 206 255 227 246 213 216 206 217 238 233 234 257 233 223 233 188 233 223 234 211 225 237 231 246 237 228 230 216 223 260 213 205 218 230 219 225 238 206 211 247 236 263 214 248 232 230 212 240 234 228 218 248 233 210 213 223 259 268 236 245 209 211 232 235 210 231 172 218 196 222 224 210 247 216 235 239 228 217 226 258 225 237 263 229 206 256 202 222 213 222 255 274 218 230 234 225 220 201 238 198 270 224 217 229 232 238 238 220 226 232 226 225 207 227 223 220 226 216 239 210 228 205 231 187 210 208 214 193 233 235 214 195 215 220 203 219 235 228 224 216 259 230 237 237 231 213 232 221 225 204 220 200 235 209 231 236 212 235 227 222 214 228 214 215 219 232 212 210 236 205 213 231 202 226 213 230 230 233 243 203 235 239 232 193 199 216 244 239 241 239 223 229 218 239 220 246 225 264 219 224 217 238 218 230 204 226 221 219 234 231 229 216 200 213 221 240 225 210 269 241 210 221 222 212 260 208 220 233 226 218 223 217 229 206 212 220 239 214 226 203 222 235 237 234 255 218 241 249 242 228 240 227 196 250 245 207 247 226 231 262 220 214 246 249 215 247 229 236 221 223 248 239 222 221 239 226 213 233 212 234 230 214 212 204 218 220 206 214 237 225 212 237 242 239 217 212 242 225 215 218 212 225 216 232 243 240 274 215 238 223 225 202 223 213 238 216 243 208 234 196 241 196 233 207 223 198 190 240 238 229 227 225 228 210 231 267 210 206 245 198 228 233 248 204 214 229 235 213 221 195 221 219 217 212 208 235 210 233 215 224 283 187 236 216 235 224 240 223 226 224 217 218 223 205 210 206 205 239 203 222 231 199 216 229 223 217 219 212 232 242 217 222 257 226 222 206 238 196 222 225 207 218 192 239 232 223 217 242 226 222 216 227 238 236 179 212 256 230 222 235 220 222 222 218 231 221 248 206 210 261 216 208 227 211 216 225 242 230 229 236 243 214 211 220 229 230 208 218 228 210 207 204 236 217 196 219 208 211 225 222 197 222 249 215 214 224 214 255 250 221 237 213 234 243 231 231 222 226 217 220 228 245 221 227 202 194 215 203 222 193 233 227 209 214 228 216 245 220 210 229 217 206 201 222 227 214 220 234 271 223 220 225 220 227 207 218 214 227 255 225 208 229 201 221 210 211 237 226 205 233 236 229 228 201 219 216 220 238 218 225 180 204 199 223 220 226 239 209 228 197 227 242 205 216 230 195 267 261 201 217 217 256 230 214 214 212 231 209 237 216 216 229 234 223 188 203 233 239 235 214 219 223 235 218 226 237 227 205 214 212 208 242 213 208 210 203 215 240 206 240 243 205 247 272 215 216 211 213 231 227 196 236 224 230 230 239 238 236 229 238 207 225 241 244 215 234 212 209 250 224 198 228 214 195 256 221 216 226 246 263 227 239 213 231 217 186 217 240 222 217 228 223 219 230 220 232 223 242 225 225 227 242 242 243 218 244 228 237 234 224 242 228 205 206 209 237 215 213 246 259 225 223 222 227 214 195 257 249 209 214 207 208 247 246 225 216 257 233 223 233 221 240 229 218 231 219 201 225 241 219 221 219 215 217 197 236 241 223 218 207 219 225 235 212 241 217 229 223 199 237 213 216 237 220 213 232 205 238 231 203 259 230 238 249 243 212 199 213 262 227 218 235 230 214 242 241 233 248 244 203 203 226 208 230 213 218 237 222 220 213 208 235 235 209 218 214 204 211 223 244 226 231 242 205 228 229 222 210 243 230 244 236 229 232 212 232 224 232 236 205 241 218 214 246 225 220 227 232 212 238 225 209 243 217 224 233 213 227 229 225 231 218 210 194 210 231 216 210 237 226 214 210 257 236 236 212 235 231 232 232 211 233 225 230 226 247 208 206 224 195 225 228 213 227 222 193 228 239 212 276 273 214 237 234 218 245 230 246 209 239 192 231 216 213 228 262 203 203 230 237 215 209 222 207 238 220 220 239 210 240 223 225 212 208 220 217 231 240 221 236 214 238 238 200 240 203 242 224 211 236 227 235 261 233 249 218 255 240 244 233 201 236 211 207 235 212 231 241 220 213 227 244 235 233 261 205 219 205 218 265 230 223 234 228 237 215 218 223 231 211 242 217 233 226 237 226 221 246 231 208 249 204 219 222 206 222 220 244 220 239 208 207 231 222 258 234 232 224 207 236 260 219 244 227 259 224 220 205 227 264 207 208 232 197 221 225 208 226 226 256 221 250 211 255 214 259 224 238 238 214 230 240 227 226 229 235 232 232 229 220 212 232 246 230 234 221 236 237 240 191 219 211 235 205 238 223 246 236 219 239 210 233 233 235 219 222 229 248 225 233 225 241 222 230 222 237 221 220 260 218 210 237 222 219 228 240 227 246 216 207 244 244 207 227 262 215 235 239 213 229 246 226 263 257 237 265 243 234 215 249 240 234 235 242 216 207 228 233 237 243 225 260 246 228 237 231 233 258 235 243 223 196 232 236 230 234 236 236 231 259 240 229 188 225 221 257 213 211 248 250 211 259 243 255 216 195 233 218 242 242 234 238 246 235 209 190 262 216 216 259 246 238 245 269 227 214 218 231 229 243 237 223 233 215 216 219 224 237 212 197 233 202 232 236 217 239 257 243 238 269 236 234 219 214 234 241 199 241 230 262 248 239 264 232 232 238 243 245 248 232 246 227 229 214 242 221 233 225 212 213 223 215 224 245 222 246 221 226 247 280 243 220 210 237 237 236 195 211 244 218 225 261 227 202 231 227 212 263 205 238 230 237 226 238 249 261 248 234 208 260 277 229 223 256 241 256 230 239 222 258 231 222 231 231 260 235 269 231 234 249 212 247 248 215 270 236 234 262 215 229 226 244 219 284 262 264 262 266 228 228 246 264 264 226 247 230 219 234 232 282 240 241 241 246 230 230 225 221 271 261 235 290 282 214 246 262 258 257 276 242 259 241 270 240 215 258 227 221 245 226 241 248 226 234 215 247 235 249 274 241 241 214 226 226 264 232 241 249 222 224 249 234 241 222 239 246 261 217 273 229 240 240 247 248 226 220 260 262 229 248 220 258 244 234 230 247 218 228 228 224 225 243 225 262 222 239 214 236 257 223 230 222 241 277 266 220 243 243 239 246 214 230 245 210 269 232 217 246 213 235 272 228 229 230 264 261 249 241 223 197 246 221 244 209 234 234 266 250 211 216 239 240 236 219 207 250 266 218 238 239 234 213 248 230 238 232 239 230 207 229 226 224 233 220 243 240 230 257 218 232 265 238 249 207 216 246 219 223 234 211 222 232 229 231 264 238 222 233 209 240 208 214 226 225 239 233 203 234 231 224 199 248 247 248 244 202 212 235 219 226 231 231 237 261 238 248 236 231 221 230 259 224 266 225 225 227 231 240 242 245 227 246 232 209 237 226 215 221 235 223 255 199 235 227 271 225 232 230 212 232 216 208 267 257 249 226 223 240 230 208 207 240 209 228 249 224 229 235 213 230 249 232 207 210 264 220 224 232 236 246 217 241 231 243 242 244 218 214 246 264 240 219 240 243 209 234 230 238 229 237 225 233 214 259 230 234 247 236 234 220 231 245 236 241 224 228 181 258 215 237 245 218 208 224 235 256 218 232 214 225 240 221 235 283 229 234 217 236 239 226 242 256 245 238 233 225 240 237 238 225 236 234 246 250 230 222 229 264 213 235 214 210 213 222 236 238 237 236 209 209 246 203 221 231 219 240 255 246 235 219 207 218 226 231 267 233 244 237 240 234 240 239 226 219 207 225 225 232 256 239 235 230 243 212 235 203 245 228 218 239 202 244 228 240 203 223 218 241 222 260 224 226 201 194 237 245 221 221 226 240 215 242 226 214 269 225 238 231 217 209 246 244 244 217 235 222 261 215 213 214 200 224 239 233 223 224 235 221 244 208 227 229 205 233 238 205 218 249 206 227 219 228 231 259 225 239 228 246 216 225 232 228 241 231 235 225 223 225 248 258 217 213 218 206 227 223 224 217 226 200 223 241 223 245 210 214 237 219 221 244 256 255 199 225 235 216 218 210 206 231 216 198 228 224 224 210 243 231 238 235 244 230 225 239 257 248 230 212 237 237 201 246 239 241 213 214 209 248 220 215 209 211 199 220 208 239 269 211 223 214 242 248 226 240 233 212 235 214 213 232 232 200 230 208 245 242 227 228 220 217 197 228 216 208 237 217 222 222 214 225 222 221 235 210 235 225 229 221 225 216 235 241 238 233 230 223 201 232 202 241 218 236 228 225 232 226 201 288 225 262 212 198 219 226 238 242 237 222 238 231 212 245 226 207 230 234 210 205 228 225 215 204 207 231 239 243 236 198 258 211 240 221 236 221 246 237 230 226 237 221 219 226 230 204 218 219 214 237 223 207 260 221 222 216 229 205 243 227 212 212 216 205 219 242 234 193 223 230 242 205 208 245 213 231 238 229 209 223 234 196 236 220 242 228 191 249 244 231 231 232 228 208 205 231 222 220 243 198 214 234 206 227 238 239 211 227 262 249 215 255 250 241 222 226 258 221 239 226 219 240 255 210 222 258 204 232 219 242 237 223 210 261 227 227 226 211 229 236 216 240 231 246 188 220 224 243 229 259 239 244 226 232 231 220 231 231 206 217 238 246 218 237 195 224 242 242 241 205 222 234 226 203 233 204 218 247 235 221 217 229 217 215 238 240 200 236 239 211 236 267 239 214 226 235 222 217 222 260 214 223 235 216 203 238 248 203 214 243 210 243 242 233 216 228 235 229 268 216 245 239 222 215 222 200 216 206 249 218 231 234 209 211 234 245 233 229 237 228 200 217 225 203 242 230 188 241 219 255 261 218 259 235 240 229 257 214 233 245 204 235 195 192 212 202 256 234 225 202 241 206 221 238 212 216 193 230 241 255 216 237 216 266 235 234 242 224 221 222 228 216 239 204 205 239 232 202 222 245 244 222 216 237 212 245 225 221 238 219 236 234 249 189 215 227 218 221 231 233 227 223 245 246 234 218 228 262 216 223 209 240 235 206 235 238 243 225 216 225 217 214 211 236 227 221 227 235 200 246 205 218 233 241 215 246 205 197 235 249 232 233 245 216 214 247 204 209 237 212 207 248 240 242 217 242 209 235 206 228 219 237 224 205 223 210 227 215 215 236 204 248 215 212 234 231 215 262 222 230 234 216 238 236 240 239 200 224 226 209 233 238 238 231 217 205 211 196 203 274 220 240 224 196 228 230 221 211 204 218 229 215 217 214 186 231 225 217 182 218 199 214 238 213 222 228 220 225 248 206 198 230 226 244 232 234 242 188 238 225 231 226 229 218 214 224 221 241 234 258 218 259 234 227 256 226 222 217 214 218 222 241 235 242 204 246 215 220 210 227 247 213 225 243 216 223 228 262 218 244 228 196 245 217 236 237 198 229 232 235 248 220 235 222 210 243 244 231 231 241 222 230 232 235 197 233 214 214 224 207 225 214 215 217 232 240 224 229 246 198 236 219 235 236 227 217 238 211 215 224 227 216 211 214 220 218 240 220 230 234 244 232 246 233 231 213 229 208 219 268 232 209 213 233 216 232 239 228 237 219 244 213 214 215 232 222 230 223 206 201 214 237 231 210 216 204 209 217 220 268 206 244 228 241 231 230 243 230 222 231 203 207 213 218 237 238 266 197 226 228 219 248 227 227 257 204 206 242 231 222 227 218 226 242 217 202 227 238 249 210 225 232 223 213 240 240 241 214 227 233 256 223 214 248 232 203 263 218 226 224 223 220 222 234 215 231 222 267 231 232 236 197 228 203 260 217 248 232 241 218 209 214 229 207 246 230 213 204 226 207 228 271 226 213 205 243 225 230 225 245 235 233 255 208 234 244 209 225 220 239 227 210 229 201 231 231 205 237 241 202 190 233 228 210 237 206 243 238 218 237 242 243 215 215 227 248 242 222 215 221 197 221 221 200 237 212 205 205 241 244 207 227 214 238 221 214 202 237 229 223 225 229 230 203 220 205 220 229 225 218 220 230 219 248 242 226 213 209 223 229 234 215 249 228 226 233 218 200 218 226 222 227 213 232 196 203 222 209 237 221 228 222 225 222 237 215 223 209 223 240 231 248 245 213 238 209 232 221 234 223 232 209 261 219 237 217 200 229 260 210 205 239 208 232 205 228 223 245 247 245 220 222 237 235 215 210 208 226 215 219 183 234 228 208 220 250 236 238 204 276 201 224 258 219 226 218 219 199 241 230 208 236 240 199 228 231 221 222 204 216 222 217 225 235 230 222 233 240 217 249 237 264 195 224 236 228 240 210 221 226 226 211 220 264 228 197 214 224 244 217 190 228 214 201 220 219 221 207 234 225 238 241 227 215 169 228 221 219 225 225 230 222 255 234 258 181 203 236 212 201 239 211 175 220 247 207 212 216 232 240 217 217 223 216 232 205 240 220 194 223 205 204 218 228 200 212 244 208 239 237 231 222 229 249 237 241 242 209 207 209 214 211 246 204 224 230 231 207 230 237 218 225 222 230 215 217 218 229 226 184 240 241 209 193 233 215 235 209 205 219 247 223 233 198 228 235 260 240 195 218 216 227 202 211 249 236 236 227 205 219 235 241 196 266 221 196 257 200 245 220 224 224 203 233 231 204 235 215 239 245 235 228 240 224 232 213 232 203 224 200 238 244 215 225 209 244 205 228 203 230 213 225 237 214 194 233 229 219 228 240 224 213 200 244 235 250 233 225 242 223 239 215 222 246 236 260 241 225 195 219 234 217 248 230 220 235 225 238 224 263 230 259 229 214 275 234 221 244 205 222 234 222 263 215 244 226 232 233 248 228 215 259 212 225 235 233 239 218 275 219 246 221 226 263 270 235 266 220 263 265 272 246 232 241 226 218 266 218 229 233 243 255 226 267 257 256 232 272 270 296 257 281 255 268 256 246 283 257 240 277 268 262 273 228 232 247 243 241 259 233 255 232 235 263 291 231 243 218 241 233 244 264 248 231 232 255 213 227 259 244 239 232 239 231 279 229 264 236 230 232 214 232 257 241 275 247 218 227 210 229 221 235 212 208 180 246 227 240 230 229 259 222 230 209 206 236 225 219 234 234 241 230 216 238 270 230 185 204 234 221 224 210 232 219 199 239 220 205 208 224 238 227 243 261 212 225 206 211 217 215 201 219 220 206 227 218 225 209 220 247 211 265 212 226 208 225 221 224 207 216 234 244 216 213 213 219 218 239 232 212 223 211 223 249 222 246 217 223 226 212 188 241 229 210 192 224 225 261 240 222 228 204 223 201 255 212 207 236 190 199 241 218 217 198 214 202 229 224 217 212 183 217 224 217 239 212 213 213 225 203 204 218 200 206 246 236 214 214 233 218 233 198 227 190 220 225 218 204 221 196 243 206 220 245 195 242 237 219 207 201 199 245 192 233 200 183 231 228 201 200 201 205 231 196 210 237 236 178 221 226 255 238 232 222 197 238 202 233 225 204 221 210 237 233 210 237 208 202 206 235 229 199 211 210 209 210 222 222 189 209 229 215 230 238 196 203 227 211 216 208 206 221 229 198 204 201 216 218 194 218 232 195 243 217 218 237 226 242 211 233 229 217 219 214 195 206 240 218 248 214 223 239 225 216 205 221 214 235 227 223 216 255 237 211 206 232 216 203 218 221 214 223 204 215 227 245 212 195 231 214 178 239 226 217 236 233 189 220 243 223 201 224 256 211 200 207 241 231 225 221 202 200 199 218 218 265 207 220 212 225 218 233 255 217 219 220 220 227 224 233 203 210 206 206 202 211 197 221 220 201 227 228 215 209 222 202 207 246 184 216 209 212 230 231 209 246 206 210 217 211 225 234 216 216 242 203 216 203 218 232 244 216 201 215 227 232 238 202 264 219 216 188 247 219 213 227 233 218 212 220 215 238 204 228 200 228 238 215 205 215 212 227 195 200 235 200 181 206 227 211 192 227 212 198 216 202 210 221 213 224 237 222 228 218 215 221 208 203 227 219 210 220 221 208 211 211 221 198 247 223 206 220 217 207 238 187 213 191 207 229 227 229 211 224 196 225 249 218 229 215 208 211 195 246 223 242 212 218 195 197 217 216 202 216 210 217 198 194 203 214 207 200 212 210 239 219 185 237 228 225 203 213 196 196 228 203 235 217 205 224 239 201 236 236 217 229 236 205 239 221 208 214 227 221 244 202 219 243 211 208 230 205 206 240 220 206 218 222 199 214 229 237 209 246 197 227 211 195 238 212 223 219 234 233 202 220 222 207 207 246 216 198 207 208 227 202 245 216 198 212 214 213 212 195 228 236 197 229 226 216 215 235 208 228 243 204 217 228 208 224 179 235 192 190 230 221 193 208 247 237 217 213 221 211 225 222 238 223 235 204 219 190 205 229 231 235 236 229 226 237 202 210 227 210 203 237 212 225 222 203 212 229 232 236 225 212 202 219 225 246 216 226 224 228 227 200 232 225 241 226 204 216 202 235 216 231 211 237 234 205 230 221 226 222 230 213 221 218 220 204 190 210 231 214 226 222 212 228 230 200 201 236 219 203 213 229 196 237 213 218 221 225 228 207 208 237 222 241 226 239 232 218 235 220 198 204 205 213 220 225 227 225 234 217 244 232 234 227 209 232 209 200 227 235 235 226 248 222 197 207 216 240 214 204 207 223 239 219 217 217 210 210 248 230 234 232 195 233 217 222 222 222 236 219 241 228 213 221 218 217 205 231 216 198 211 217 238 228 239 217 199 237 213 185 194 199 225 241 207 233 236 232 220 228 240 233 211 194 229 237 215 225 237 220 217 218 230 204 223 221 214 233 222 227 223 219 216 216 208 229 244 245 206 237 219 205 215 211 235 203 223 215 205 225 221 219 201 236 217 217 217 190 213 234 244 205 223 187 213 206 203 227 220 207 220 214 210 210 227 229 212 208 200 246 229 222 223 214 196 217 225 210 221 205 226 203 230 215 222 223 207 217 200 213 213 222 231 211 226 224 240 239 233 237 206 202 230 217 219 235 213 219 225 230 207 211 212 224 204 223 207 224 218 220 235 223 226 192 249 240 219 213 211 223 223 242 256 218 216 237 194 219 204 207 189 227 235 206 228 217 213 213 222 207 222 209 200 229 229 231 210 243 217 196 221 188 194 223 225 230 222 258 188 223 216 240 235 212 232 221 227 224 216 203 212 222 203 198 224 236 205 229 208 224 185 204 196 219 203 244 214 202 211 198 221 226 206 199 208 222 210 217 196 208 241 204 217 225 240 234 233 247 245 208 230 229 219 248 223 228 235 193 239 233 230 211 218 206 209 221 221 199 187 220 207 211 215 201 209 195 193 206 232 233 213 210 224 225 230 234 223 196 218 226 209 214 205 200 214 241 216 224 207 194 214 224 207 247 203 203 215 232 203 239 202 214 225 230 232 200 220 196 217 219 221 206 225 202 199 218 207 219 232 229 225 224 245 210 211 212 214 214 236 210 204 200 215 221 210 211 218 222 214 211 223 213 211 214 234 227 211 207 204 210 210 227 234 197 222 202 198 219 204 198 228 224 226 255 198 196 223 238 219 213 212 198 222 214 202 212 241 221 212 229 214 206 219 212 219 205 184 226 212 218 205 228 224 202 199 218 194 222 211 235 238 212 207 224 206 242 229 217 206 229 227 214 224 229 220 211 238 206 226 227 238 215 210 210 199 222 196 231 202 209 230 206 212 222 202 215 218 199 242 201 217 208 219 216 203 201 209 204 212 226 230 222 228 227 231 259 210 244 219 202 212 212 215 220 225 222 236 211 221 206 215 210 203 184 225 216 196 226 202 206 223 219 221 230 205 241 215 196 245 236 215 213 219 235 206 194 244 249 217 235 211 214 214 246 230 211 223 214 229 209 202 221 226 206 209 209 220 217 234 210 213 214 213 210 212 220 234 214 205 222 240 217 204 233 241 220 194 225 235 236 230 208 227 221 202 208 234 215 217 227 221 206 237 234 212 216 205 211 215 213 218 229 240 229 201 243 221 222 230 230 210 212 211 215 199 238 213 204 205 235 181 208 228 228 227 212 221 214 199 238 232 249 230 219 232 219 203 259 228 219 233 208 197 247 228 209 229 208 209 212 209 209 222 233 227 198 201 210 260 230 222 220 214 233 216 230 209 214 211 220 208 207 191 205 214 241 219 212 237 241 207 227 208 226 201 193 204 226 211 198 205 225 221 255 225 224 232 238 233 221 220 239 226 218 212 198 227 196 203 228 225 207 211 201 231 234 187 219 244 255 263 231 216 222 212 206 213 225 239 247 210 204 211 213 235 231 191 220 228 226 215 197 218 212 201 233 256 226 237 218 225 210 219 216 221 211 211 210 217 220 200 229 216 202 237 230 207 217 234 227 202 219 229 223 246 209 216 220 226 216 231 208 223 198 226 225 211 204 229 204 206 210 262 218 237 203 214 210 247 211 227 235 233 246 232 231 225 225 201 223 199 213 219 226 216 224 242 236 235 261 227 220 217 209 221 214 214 224 235 239 213 222 201 279 214 226 238 219 211 243 230 224 223 227 223 228 204 226 236 222 231 213 214 210 190 215 240 259 235 231 201 215 230 216 237 208 215 215 262 228 214 209 213 224 228 219 227 223 202 244 196 228 262 241 227 255 226 224 235 205 222 231 235 215 232 204 219 229 245 242 196 221 211 210 221 277 224 223 217 243 218 262 201 232 215 223 220 216 216 255 248 236 233 244 219 213 200 247 238 263 197 214 237 238 239 233 203 231 234 221 201 238 195 237 207 232 225 200 233 232 262 256 237 217 248 212 225 216 227 228 221 236 225 229 241 234 205 224 212 200 221 227 229 219 206 227 258 215 229 221 229 247 215 229 216 196 234 226 213 201 264 198 222 213 237 220 229 227 222 192 216 217 228 217 219 226 226 257 221 231 212 209 232 234 214 244 235 188 219 229 235 213 230 219 243 228 225 225 219 212 208 239 215 214 225 218 198 223 246 221 219 234 216 206 189 222 232 218 211 217 225 219 223 208 222 234 208 212 226 219 228 202 218 191 219 218 258 211 207 255 240 238 233 217 246 223 249 228 208 227 227 194 232 232 241 196 219 218 230 203 219 224 226 218 229 207 245 259 211 245 216 215 224 223 215 229 186 217 212 217 232 222 221 221 197 216 189 246 208 229 197 231 207 210 200 208 225 262 194 217 232 236 203 198 221 216 205 249 221 223 243 202 215 213 221 237 229 182 232 203 235 207 234 225 201 213 239 227 220 229 204 229 220 249 210 211 223 218 240 241 228 240 246 196 215 238 233 209 261 225 194 227 216 210 212 215 227 212 204 210 232 219 209 223 247 222 188 210 230 223 213 194 215 174 211 215 231 241 212 243 216 207 235 204 231 211 213 223 246 230 236 246 213 220 224 218 225 193 226 227 214 228 232 222 213 245 264 235 215 197 233 220 194 207 235 225 223 222 235 238 241 217 208 206 239 222 219 259 240 266 212 231 221 237 227 205 204 245 223 229 221 211 223 220 232 222 222 219 210 209 248 215 220 209 231 210 236 223 213 245 211 231 219 216 227 244 237 225 217 208 204 213 205 241 208 203 239 232 228 211 233 204 224 195 221 207 225 239 227 222 225 258 213 212 237 212 243 231 219 229 199 212 184 265 258 214 217 224 227 223 226 215 226 220 232 227 211 232 223 223 215 211 210 225 218 245 223 231 209 219 220 225 227 228 221 212 240 244 214 212 225 203 272 224 217 240 196 218 239 228 233 221 208 233 242 246 206 225 208 216 226 214 221 207 211 224 222 210 210 203 221 219 236 212 205 214 205 220 218 231 242 215 218 222 212 242 231 219 233 205 230 217 229 228 218 206 228 216 209 223 229 183 202 220 216 222 249 198 233 219 190 215 232 222 200 218 213 229 195 228 234 238 217 250 213 231 225 215 220 204 210 244 212 232 231 228 207 208 221 214 210 223 232 233 228 208 221 217 215 248 226 220 231 225 220 211 215 187 242 238 199 236 222 212 235 232 214 235 236 209 226 237 220 234 209 214 238 221 225 233 221 170 228 209 193 260 247 224 208 201 224 238 219 213 216 224 215 218 218 220 224 238 233 225 210 231 237 233 242 211 198 221 195 197 245 211 201 255 223 239 212 247 227 208 234 220 235 207 217 232 233 217 231 206 216 221 213 229 237 217 266 241 218 257 221 221 198 269 215 223 229 224 247 214 217 242 221 206 194 211 229 246 234 213 214 223 224 205 221 217 226 215 202 217 209 223 195 232 228 243 222 227 235 208 237 235 245 209 213 222 227 238 219 205 238 212 228 220 214 219 247 235 229 226 244 206 200 232 227 215 209 215 248 229 201 214 257 204 215 257 225 205 226 236 217 238 224 221 225 192 209 200 196 208 214 220 234 232 239 209 228 230 239 213 211 192 196 195 231 215 223 262 199 228 216 209 249 226 223 214 222 228 226 238 231 196 235 215 256 216 217 216 249 221 236 222 194 237 239 219 230 203 221 190 236 234 216 209 237 223 222 193 217 196 227 228 210 215 191 229 227 214 225 236 233 247 224 216 219 219 255 227 219 232 227 222 241 208 230 200 237 213 231 247 243 217 227 225 258 205 211 234 231 235 215 215 237 213 238 182 247 195 219 244 199 248 225 221 224 210 223 187 246 237 219 203 224 203 239 212 218 213 248 220 241 208 222 190 232 201 204 206 216 215 226 223 199 207 221 226 246 205 235 212 199 236 214 228 220 206 228 221 236 218 217 218 223 194 214 227 242 205 218 230 221 212 229 233 218 217 223 228 231 220 202 219 234 218 260 235 193 229 233 226 228 261 229 234 222 239 222 198 224 235 227 200 241 222 236 200 244 217 213 195 217 217 231 217 238 205 232 227 209 225 224 222 218 228 220 214 201 227 182 224 230 210 220 214 211 207 237 261 220 217 216 214 230 206 229 257 216 227 213 215 224 217 224 221 230 219 221 216 227 263 242 233 195 209 234 221 221 214 184 224 244 222 223 219 218 217 219 201 196 257 195 196 229 227 231 239 242 210 196 217 221 214 214 229 218 216 216 222 209 208 217 220 195 194 221 207 205 215 214 198 200 222 204 228 202 185 228 218 231 230 192 205 206 207 219 206 204 240 209 228 256 229 225 222 233 200 219 205 220 233 240 235 211 231 235 196 229 212 230 229 238 230 227 207 208 227 220 238 236 213 221 221 209 239 214 225 221 232 250 208 229 249 212 222 227 212 228 219 237 229 216 220 227 204 202 232 261 212 199 227 220 228 222 211 218 188 225 243 257 211 218 225 234 218 209 256 209 187 200 222 227 224 231 244 216 262 212 248 224 208 223 241 231 210 228 220 223 221 204 230 222 225 217 216 229 235 193 208 222 215 199 186 233 217 202 214 233 209 238 223 221 218 219 201 210 231 223 230 229 243 246 216 232 237 216 229 215 257 219 229 222 239 232 207 238 262 227 227 217 262 224 227 221 212 223 230 215 221 224 231 214 222 210 205 230 233 225 191 213 237 224 218 236 217 211 212 217 208 221 229 273 241 210 265 188 205 206 221 236 218 201 225 218 226 204 203 232 219 215 209 216 210 232 217 206 256 222 203 216 227 234 228 202 245 226 230 195 226 218 221 209 218 238 234 218 228 233 245 214 222 231 226 239 210 239 267 217 231 222 223 240 210 187 213 234 200 275 227 263 208 216 204 215 242 243 197 210 230 221 212 214 238 223 216 198 220 213 242 218 204 255 235 227 292 215 243 224 241 238 233 221 268 233 211 192 238 226 217 216 223 213 185 229 219 214 242 235 242 235 234 233 221 192 219 219 207 226 221 234 217 226 233 218 241 248 232 226 224 239 228 207 220 205 208 208 240 203 218 223 225 202 229 237 262 215 220 218 255 205 206 225 237 198 214 236 244 209 214 228 211 239 228 194 224 214 271 208 191 210 205 235 205 204 257 219 214 231 222 224 214 221 245 229 263 238 200 204 213 226 232 217 207 240 225 224 218 242 203 215 224 200 249 211 221 226 218 203 241 224 230 214 221 238 225 224 212 231 218 205 230 233 213 230 206 243 189 227 237 231 222 215 231 222 212 224 211 206 237 226 224 238 213 219 227 234 208 226 259 258 229 237 216 223 207 220 223 216 262 229 200 247 212 210 195 210 230 241 240 219 231 213 203 205 209 206 218 203 205 231 228 213 217 208 206 226 214 219 226 235 226 191 215 214 228 176 236 237 238 233 235 215 196 226 186 198 213 190 224 226 216 215 234 217 225 220 238 236 233 216 229 212 244 201 193 242 256 205 237 228 266 220 235 263 203 222 225 217 226 209 217 212 232 231 186 222 231 242 201 218 206 240 218 240 199 248 215 222 221 235 256 225 216 198 205 198 225 206 202 205 235 231 207 243 237 231 198 250 238 223 220 234 227 223 225 224 241 241 222 234 230 228 209 238 225 233 222 224 240 227 225 228 221 213 230 220 225 232 236 224 216 223 212 248 188 211 239 240 239 195 249 226 214 239 208 210 243 227 219 233 214 217 230 263 209 205 216 238 195 218 267 237 225 221 233 237 234 231 220 246 232 231 219 211 227 240 250 245 227 233 216 218 212 218 233 240 203 212 257 226 230 212 229 204 224 242 237 261 232 235 215 197 215 229 259 247 249 278 257 225 235 265 268 216 290 237 241 239 237 269 261 276 216 232 260 231 210 233 240 229 249 234 264 220 229 219 204 204 228 244 235 257 224 235 238 216 245 238 200 242 257 215 208 199 275 209 239 239 249 231 240 238 247 223 205 213 246 243 235 235 209 240 216 223 228 244 260 229 235 234 257 246 244 264 280 264 230 246 227 223 236 228 231 241 228 247 208 227 257 239 242 243 224 249 238 237 238 234 263 227 264 229 217 230 232 216 236 221 227 229 223 239 244 225 243 231 256 221 229 228 223 217 256 233 221 216 210 203 260 214 233 247 217 229 209 230 239 239 217 225 231 222 205 226 216 240 248 217 227 220 201 242 209 218 226 230 231 233 217 210 274 204 218 191 237 232 248 218 216 233 236 226 242 215 209 236 257 219 215 219 209 230 259 228 215 230 206 270 274 226 210 229 214 225 242 218 212 233 229 214 226 249 219 190 236 232 235 214 235 216 222 233 240 213 217 203 244 249 243 211 231 205 230 223 207 218 226 241 210 243 228 225 221 219 223 227 242 200 218 227 227 220 216 236 263 208 213 245 211 216 201 238 214 213 230 215 215 231 241 233 234 234 241 224 232 222 226 247 224 215 221 228 236 232 213 182 215 229 213 245 214 237 232 243 210 230 187 226 218 204 223 220 239 219 247 191 267 202 239 226 235 258 223 234 213 204 197 226 220 225 234 241 202 214 213 257 215 200 244 204 255 238 213 203 209 208 200 245 209 243 216 224 216 213 235 237 216 236 235 222 233 209 240 227 231 230 210 204 238 235 234 225 214 228 215 221 248 231 263 213 225 238 238 198 256 219 242 244 231 223 234 234 207 242 236 239 246 219 208 231 224 238 203 261 234 219 209 231 219 221 216 237 256 216 224 227 235 229 210 218 211 223 201 232 267 230 208 227 218 234 233 205 233 235 246 232 225 207 238 225 224 244 240 248 223 206 211 216 213 225 227 211 237 228 204 213 226 249 233 264 219 229 230 234 260 245 225 264 233 214 235 228 226 237 204 263 220 239 256 232 238 213 228 208 210 224 226 229 262 233 221 225 196 248 235 216 211 205 228 233 242 225 231 240 227 206 233 259 195 244 242 216 275 230 230 223 220 243 245 233 265 218 221 219 244 228 218 244 220 219 229 223 236 234 233 215 229 223 221 211 258 241 225 227 233 233 213 241 234 214 234 230 230 260 210 244 247 207 266 238 224 232 200 236 234 233 223 211 221 209 231 260 222 238 211 255 240 225 209 194 235 260 212 246 247 221 243 240 219 229 245 213 229 281 239 219 203 211 235 228 276 218 239 221 206 226 230 257 237 195 211 225 225 222 216 211 217 241 231 240 228 222 227 223 231 213 237 240 234 215 231 196 226 227 249 230 267 196 211 237 200 240 233 203 231 219 231 209 240 213 235 217 222 213 234 228 229 261 217 216 228 237 258 230 195 244 229 227 225 230 246 243 242 204 231 226 248 203 232 218 245 230 224 235 219 216 210 237 218 213 231 230 246 235 230 229 235 233 210 239 215 227 217 237 202 257 229 267 222 212 221 223 245 212 238 211 241 212 242 192 219 209 218 221 238 228 225 226 220 203 208 237 217 218 204 233 232 214 255 257 210 221 234 225 216 215 226 226 221 239 222 218 229 246 198 220 231 197 227 246 218 233 210 210 225 236 208 236 220 249 257 223 247 222 243 260 199 227 220 210 225 225 225 224 221 212 264 212 238 243 233 217 241 241 213 243 228 232 220 223 219 219 216 217 218 260 201 225 240 239 264 201 208 228 229 207 247 244 223 263 263 259 237 227 241 233 230 220 216 231 222 200 199 229 239 201 199 218 248 224 227 223 206 267 225 224 234 231 198 232 267 237 234 244 216 246 231 233 209 223 217 221 216 220 213 239 235 263 214 209 244 232 238 235 216 238 206 226 231 199 231 244 224 230 224 224 219 216 235 226 243 236 230 238 225 233 200 238 225 208 221 232 193 260 214 245 231 222 256 227 237 239 209 222 244 223 211 233 215 225 261 259 240 234 240 215 217 249 219 240 209 275 233 242 232 229 217 231 245 231 227 248 239 244 234 217 260 223 220 240 229 222 237 240 216 232 205 217 214 243 243 220 259 200 227 210 231 238 218 232 256 202 255 208 214 226 238 267 245 235 224 240 216 221 244 209 260 235 201 229 213 241 235 229 219 224 221 238 233 241 272 234 245 209 260 232 282 237 234 217 238 212 210 211 223 221 235 248 270 284 217 205 234 216 211 218 228 229 232 233 208 208 230 218 216 245 237 272 223 226 227 210 241 227 231 216 232 226 249 234 230 230 227 241 237 227 255 235 235 220 238 240 237 249 232 208 235 235 241 226 232 233 233 249 242 226 218 236 230 229 239 236 236 222 246 214 237 238 223 225 258 270 236 212 227 230 246 262 214 216 210 216 227 206 261 260 203 267 193 248 235 256 246 226 241 260 236 241 219 205 217 233 198 208 239 213 186 200 246 222 270 234 261 226 257 221 229 237 245 241 232 227 219 239 265 229 237 237 235 267 218 199 222 234 217 258 218 214 214 249 236 239 235 265 230 199 243 236 214 218 239 213 233 218 240 223 224 213 211 240 233 216 224 231 191 234 271 225 237 220 222 234 235 214 233 243 228 228 221 245 222 234 245 259 274 240 224 246 238 242 256 225 225 233 234 216 214 227 246 217 227 256 214 257 238 198 231 241 242 196 225 219 219 216 235 237 201 238 255 223 235 232 226 226 262 244 190 232 217 246 227 225 243 250 215 217 236 258 229 217 238 221 231 245 235 218 216 244 237 229 236 233 260 200 228 220 255 232 210 234 248 241 234 231 242 245 238 230 228 218 244 227 257 240 236 214 242 229 213 255 246 249 212 226 212 225 240 212 212 265 225 234 233 207 242 223 243 220 221 228 237 238 214 236 215 241 235 247 262 242 222 224 223 224 225 215 256 245 231 248 226 222 256 219 196 262 219 247 261 238 180 239 260 214 214 250 238 209 245 233 226 227 260 227 216 243 264 233 233 240 248 262 213 264 212 237 232 226 263 241 228 266 243 209 230 258 238 243 242 256 236 229 240 226 228 225 238 224 192 231 231 214 227 223 220 243 234 215 232 248 229 229 271 213 219 227 226 257 221 241 221 229 242 222 213 236 220 264 233 242 237 229 212 219 271 245 185 240 249 215 267 223 226 257 226 226 230 205 247 213 230 234 241 217 248 258 266</counts>
			</dataPoints>
		</scan>
	</xrdMeasurement>
</xrdMeasurements>