File: data/XRD/XG-Luft/XG-750/W6821-1D_XG_Luft_750.xrdml
<xrdMeasurements xmlns="http://www.xrdml.com/XRDMeasurement/2.1" xmlns:xsi="http://www.w3.org/2001/XMLSchema-instance" xsi:schemaLocation="http://www.xrdml.com/XRDMeasurement/2.1 http://www.xrdml.com/XRDMeasurement/2.1/XRDMeasurement.xsd" status="Completed">
	<comment>
		<entry>Configuration=Factory configuration, Owner=User-1, Creation date=7/8/2013 4:01:53 PM</entry>
		<entry>Goniometer=PW3050/65 (Theta/2Theta); Minimum step size 2Theta:0.0001; Minimum step size Omega:0.0001</entry>
		<entry>Sample stage=MRD Cradle; Minimum step size Phi:0.01; Minimum step size Chi:0.01; Minimum step size X:0.01; Minimum step size Y:0.01; Minimum step size Z:0.001</entry>
		<entry>Diffractometer system=XPERT-PRO</entry>
		<entry>Measurement program=C:\PANalytical\Data Collector\Programs\Jorrit\2thom\_absolute_2th-om_10-130deg_PIXscan_56min.xrdmp, Identifier={15BCCF57-2807-42BD-B5B9-ECC0B3DC9284}</entry>
		<entry>Batch program=C:\PANalytical\Data Collector\Programs\SimonL\batch6x_2thom_10-130°_z9.1_x0,10,20,30_y20,40_57min - Kopie.xrdmp, Identifier={8874E540-C3F4-4307-831A-CD55F073CDCD}</entry>
	</comment>
	<sample type="To be analyzed">
		<id></id>
		<name></name>
		<preparedBy></preparedBy>
	</sample>
	<xrdMeasurement measurementType="Scan" status="Completed" sampleMode="Reflection">
		<comment>
			<entry>_absolute_2th-om_10-130deg_PIXscan_56min</entry>
			<entry>PHD Lower Level = 4.83 (keV), PHD Upper Level = 11.27 (keV)</entry>
		</comment>
		<usedWavelength intended="K-Alpha 1">
			<kAlpha1 unit="Angstrom">1.5405980</kAlpha1>
			<kAlpha2 unit="Angstrom">1.5444260</kAlpha2>
			<kBeta unit="Angstrom">1.3922500</kBeta>
			<ratioKAlpha2KAlpha1>0.5000</ratioKAlpha2KAlpha1>
		</usedWavelength>
		<incidentBeamPath>
			<radius unit="mm">320.00</radius>
			<xRayTube id="1010048" name="Empyrean Cu LFF HR (9430 033 7310x) DK442154">
				<tension unit="kV">40.0</tension>
				<current unit="mA">40.0</current>
				<anodeMaterial>Cu</anodeMaterial>
				<focus type="Line">
					<length unit="mm">12.0</length>
					<width unit="mm">0.4</width>
					<takeOffAngle unit="deg">4.2</takeOffAngle>
				</focus>
			</xRayTube>
			<xRayMirror id="27010001" name="Inc. Beam Cu W/Si (parabolic MRD)" hybrid="false">
				<crystal type="Graded" shape="Parabolic">W/Si</crystal>
				<acceptanceAngle unit="deg">0.800</acceptanceAngle>
				<length unit="mm">60.0</length>
			</xRayMirror>
			<sollerSlit id="21010002" name="Soller slits 0.04 rad.">
				<opening unit="rad">0.0400</opening>
			</sollerSlit>
			<mask id="22030007" name="Fixed mask 2 mm">
				<distanceToSample unit="mm">220.00</distanceToSample>
				<width unit="mm">2.00</width>
			</mask>
			<divergenceSlit id="22010007" name="Fixed slit 1/8°" xsi:type="fixedDivergenceSlitType">
				<distanceToSample unit="mm">220.00</distanceToSample>
				<height unit="mm">0.19</height>
			</divergenceSlit>
		</incidentBeamPath>
		<diffractedBeamPath>
			<radius unit="mm">320.00</radius>
			<sollerSlit id="21010002" name="Soller slits 0.04 rad.">
				<opening unit="rad">0.0400</opening>
			</sollerSlit>
			<receivingSlit id="22010001" name="Fixed slit 4°">
				<height unit="mm">5.88</height>
			</receivingSlit>
			<detector id="7010017" name="PIXcel3D 1x1 detector" xsi:type="areaDetectorType">
				<phd unit="%">
					<lowerLevel>30.0</lowerLevel>
					<upperLevel>70.0</upperLevel>
				</phd>
				<mode>Scanning</mode>
				<activeChannelsEquatorial>255</activeChannelsEquatorial>
				<activeChannelsAxial>255</activeChannelsAxial>
				<pitchEquatorial unit="mm">0.05500</pitchEquatorial>
				<pitchAxial unit="mm">0.05500</pitchAxial>
				<readOutPeriod unit="seconds">0.135</readOutPeriod>
			</detector>
		</diffractedBeamPath>
		<scan appendNumber="0" mode="Continuous" scanAxis="2Theta-Omega" status="Completed">
			<header>
				<startTimeStamp>2024-10-25T19:08:13+02:00</startTimeStamp>
				<endTimeStamp>2024-10-25T20:04:16+02:00</endTimeStamp>
				<author>
					<name>PRO-MRD</name>
				</author>
				<source>
					<applicationSoftware version="6.1b">Data Collector</applicationSoftware>
					<instrumentControlSoftware version="7.0E 20130304">XPERT-PRO</instrumentControlSoftware>
					<instrumentID>0000000011142674</instrumentID>
				</source>
			</header>
			<dataPoints>
				<positions axis="2Theta" unit="deg">
					<startPosition>9.99826193</startPosition>
					<endPosition>129.99755682</endPosition>
				</positions>
				<positions axis="Omega" unit="deg">
					<startPosition>4.99913096</startPosition>
					<endPosition>64.99877841</endPosition>
				</positions>
				<positions axis="Phi" unit="deg">
					<commonPosition>0.00</commonPosition>
				</positions>
				<positions axis="Chi" unit="deg">
					<commonPosition>0.00</commonPosition>
				</positions>
				<positions axis="X" unit="mm">
					<commonPosition>0.00</commonPosition>
				</positions>
				<positions axis="Y" unit="mm">
					<commonPosition>0.00</commonPosition>
				</positions>
				<positions axis="Z" unit="mm">
					<commonPosition>9.100</commonPosition>
				</positions>
				<commonCountingTime unit="seconds">32.895</commonCountingTime>
				<counts 443 428 398 428 462 415 442 425 413 430 476 442 425 396 405 452 447 463 425 450 406 380 429 402 395 392 432 404 431 405 426 423 425 398 441 445 410 417 439 430 416 453 426 396 454 462 404 421 430 418 389 421 419 374 405 385 423 390 407 396 386 403 413 416 430 390 405 408 403 383 411 434 407 412 411 421 426 394 422 403 405 391 436 380 419 400 441 405 453 428 398 382 367 408 420 440 419 397 394 413 421 438 362 425 413 388 377 363 388 400 399 391 392 431 415 381 437 399 381 381 378 415 395 408 400 395 368 395 362 394 378 415 366 398 432 408 422 417 410 429 405 384 357 423 372 385 397 397 361 397 395 403 414 370 367 401 410 410 400 396 375 375 416 351 364 401 417 375 372 393 437 364 378 406 384 384 390 379 398 361 380 342 394 366 361 383 398 396 377 392 351 431 370 390 369 374 372 365 373 385 379 354 361 403 364 354 385 417 395 377 373 381 388 404 408 380 412 371 383 368 350 331 428 356 356 358 398 406 390 359 385 403 399 373 365 344 318 349 335 348 351 360 382 366 370 375 353 382 380 382 384 395 376 372 388 386 386 386 372 358 353 358 355 350 372 366 396 361 389 362 349 376 366 348 338 364 404 358 353 368 360 395 337 371 339 357 355 349 386 341 366 350 337 372 374 365 358 362 360 339 351 351 364 349 357 354 359 330 336 364 359 346 383 350 344 338 336 347 376 356 363 326 344 324 327 333 336 347 388 376 358 360 351 354 349 315 319 335 347 365 339 353 365 319 307 330 377 337 367 350 353 332 353 333 362 329 353 337 356 356 348 342 352 353 355 360 312 340 361 354 303 346 319 340 314 333 320 334 356 349 359 326 347 325 335 347 365 334 348 345 334 318 323 383 334 344 345 337 351 332 311 321 359 320 353 331 371 310 334 329 308 325 352 318 357 337 359 326 333 321 348 324 305 347 374 336 363 353 327 342 329 342 299 341 317 326 327 360 359 342 315 333 344 326 338 316 318 330 360 372 313 325 336 326 311 316 337 331 320 339 342 313 317 336 347 328 324 336 329 329 315 313 365 333 322 319 363 318 318 319 328 345 296 310 329 333 323 306 289 354 326 353 357 322 328 337 337 325 344 316 307 294 317 325 333 307 325 308 330 319 342 327 322 269 309 289 301 336 297 350 297 330 324 315 315 320 289 313 325 332 349 296 299 321 319 305 288 335 329 308 326 333 290 295 300 317 309 333 314 281 305 306 312 338 330 309 310 305 308 319 305 290 312 309 307 289 297 333 304 332 290 308 307 303 304 310 304 277 296 339 321 303 309 314 318 300 312 273 300 333 286 306 337 290 314 329 294 352 290 328 270 317 267 316 308 293 302 342 326 318 326 302 285 301 315 291 339 305 340 310 333 325 282 301 296 300 322 310 335 303 313 339 298 275 299 320 283 314 304 308 312 320 305 325 325 299 309 315 291 306 283 319 284 313 287 291 316 309 317 293 320 321 300 329 296 324 313 307 307 310 293 317 269 296 305 307 276 317 330 277 334 300 291 320 345 304 287 321 358 280 310 325 308 307 305 304 281 338 294 299 331 314 335 306 322 286 335 301 311 321 304 268 276 282 309 308 319 306 326 331 330 304 295 268 315 275 304 296 307 285 283 294 291 340 294 278 300 307 307 313 298 309 328 318 299 313 288 340 275 310 321 313 297 322 321 286 335 308 290 303 298 314 329 296 305 286 305 321 309 307 320 325 304 306 272 308 305 270 297 312 324 291 351 304 288 285 330 298 323 305 255 339 305 308 324 323 343 327 291 287 317 279 352 309 336 341 301 313 300 310 337 310 323 300 285 316 312 306 298 302 289 325 267 326 299 260 331 312 301 322 326 306 293 299 313 295 317 335 327 339 311 299 326 322 336 348 302 296 303 331 338 322 298 273 339 321 302 281 317 303 314 284 302 328 328 274 311 318 324 325 297 301 333 301 305 310 323 325 307 315 291 306 293 331 287 308 295 325 324 299 312 339 326 320 322 322 320 316 315 328 323 337 330 304 301 356 298 329 350 292 277 320 336 285 304 301 300 311 293 313 310 326 304 359 315 285 307 335 286 316 308 290 326 302 331 344 322 294 298 320 344 354 325 294 307 321 315 313 309 262 343 352 271 297 334 332 297 327 285 341 303 322 324 341 291 329 292 335 305 327 348 301 320 309 279 276 296 334 306 324 297 303 367 348 295 306 321 318 323 317 321 278 332 324 318 301 353 313 271 302 329 297 307 294 325 328 306 303 343 318 304 321 331 362 322 325 305 328 293 322 301 303 317 304 319 320 307 311 342 310 308 279 329 283 277 324 317 325 317 314 309 338 331 308 300 352 322 282 308 300 301 344 338 300 282 296 320 325 312 319 328 294 310 321 313 313 340 329 331 339 313 315 300 328 292 316 314 322 327 306 334 348 325 293 319 311 350 320 341 287 307 337 306 323 336 336 331 327 309 310 325 288 326 348 353 341 341 322 311 346 287 316 285 327 298 318 319 342 304 300 314 285 335 336 346 328 312 285 320 333 319 320 302 312 330 311 316 334 313 338 340 307 331 310 313 296 331 318 305 345 331 327 307 343 286 297 320 315 334 309 314 320 317 329 293 308 323 333 315 312 344 323 334 317 329 320 315 333 306 321 322 309 325 319 320 317 318 356 324 343 325 335 329 343 286 358 325 341 335 347 320 321 315 343 356 319 310 302 335 313 310 327 323 330 344 317 335 357 344 322 330 299 338 335 339 336 307 315 347 333 293 323 348 341 320 275 357 343 297 329 345 344 346 285 317 318 345 365 321 320 338 328 338 344 328 336 339 343 313 306 312 326 295 319 320 325 311 320 345 323 326 298 286 337 339 308 296 302 329 296 349 302 327 311 294 349 373 305 318 300 276 350 298 344 309 331 327 304 313 325 304 343 370 324 339 305 316 318 339 331 321 317 275 297 307 322 328 325 306 320 337 345 341 299 331 343 302 334 323 328 307 301 327 340 311 305 318 339 325 314 294 320 334 322 314 294 327 318 326 322 306 315 352 340 336 316 310 339 309 298 307 334 315 334 326 353 315 329 311 302 334 308 302 334 329 359 315 332 303 306 314 278 326 342 324 286 350 326 303 340 346 323 334 287 318 300 325 304 302 337 316 303 303 299 327 315 321 288 298 293 302 313 307 349 309 311 298 293 298 293 352 299 284 291 310 285 306 305 330 322 355 311 303 299 315 337 303 285 317 307 321 340 318 318 318 306 369 310 339 316 308 334 317 322 259 299 331 316 312 285 332 309 298 290 313 347 313 322 296 310 319 348 311 310 368 328 321 328 286 333 296 338 294 321 312 321 316 291 309 296 295 306 331 310 306 311 275 285 317 296 316 351 330 332 312 311 337 280 322 304 299 303 287 300 299 297 301 292 307 300 303 294 325 302 320 305 310 272 312 260 316 313 323 296 297 301 319 280 294 312 256 282 328 264 294 347 328 306 292 309 308 318 287 322 292 303 321 316 312 307 298 292 270 292 333 293 325 290 308 277 284 306 308 308 303 307 310 317 298 296 279 305 282 306 293 317 268 321 283 292 304 290 327 259 295 261 312 288 282 330 280 301 302 331 304 258 264 289 305 287 309 298 357 336 279 286 313 281 271 297 263 285 288 332 312 288 311 297 300 295 306 277 286 321 294 265 309 332 281 312 308 288 281 279 295 331 293 292 288 301 259 276 314 295 289 306 331 268 289 282 298 327 311 301 289 295 301 300 304 299 294 289 291 271 277 279 272 277 261 272 312 267 314 295 311 282 303 307 293 271 313 287 282 287 304 313 285 310 285 301 278 300 323 313 285 314 298 310 282 294 301 320 285 267 285 323 304 275 291 286 294 284 296 282 298 289 312 300 275 330 249 300 265 264 286 299 259 265 274 282 297 288 317 246 282 303 258 295 247 282 302 281 242 278 243 292 305 314 290 291 306 287 299 291 291 284 287 257 262 275 315 312 287 260 306 276 282 280 279 281 286 267 312 284 266 306 274 269 248 270 278 280 259 298 272 274 271 286 264 282 293 258 295 255 274 307 303 279 294 276 248 300 304 287 276 288 283 307 270 261 265 299 291 268 281 319 289 274 310 240 284 249 280 257 291 314 240 289 304 268 271 279 277 300 275 247 260 293 256 298 259 289 287 294 288 268 295 260 282 296 299 290 298 279 244 265 308 296 248 298 282 294 282 281 284 292 302 259 234 255 274 266 248 296 276 276 275 302 261 278 246 300 280 225 255 267 309 276 297 280 292 263 286 269 258 249 302 282 248 273 284 271 257 291 270 290 269 258 290 276 261 263 242 221 259 260 283 281 263 263 267 296 272 281 295 271 238 315 267 235 266 272 257 288 236 259 273 262 317 273 259 259 267 280 282 249 268 294 282 268 262 292 292 250 264 248 284 219 276 258 255 245 267 268 273 275 263 282 278 264 290 265 300 282 286 263 278 261 241 260 238 303 266 271 243 218 274 284 245 256 263 265 274 278 255 272 284 266 272 237 290 274 273 268 276 271 269 263 275 237 279 272 270 264 240 264 246 263 262 272 240 259 272 259 247 261 271 292 262 265 281 272 295 257 248 286 267 302 257 265 305 272 260 257 268 259 265 245 293 277 255 248 265 295 271 258 231 246 226 288 265 266 259 235 294 238 234 273 259 265 267 240 274 274 259 240 294 260 258 247 280 233 265 276 257 271 263 276 261 280 234 242 268 247 233 278 240 247 244 264 267 262 256 238 260 283 240 232 231 268 285 234 279 223 265 274 287 277 245 248 250 259 243 275 261 261 245 269 278 263 261 284 231 273 275 276 240 286 292 264 288 273 268 264 274 283 256 257 271 279 264 299 263 242 293 281 244 269 266 219 271 248 255 224 277 270 276 257 275 274 268 288 232 247 262 258 269 262 242 290 260 231 274 272 269 288 229 266 241 268 224 248 249 230 237 226 282 235 239 275 279 265 267 258 250 267 260 275 265 259 241 300 276 244 240 275 270 272 237 238 249 250 255 295 238 263 264 248 284 271 262 249 266 268 237 217 217 243 272 247 287 265 242 283 224 257 277 230 259 240 234 248 274 255 238 246 297 246 267 295 272 264 266 224 264 236 268 280 242 242 282 242 268 249 261 267 261 291 238 266 225 259 247 227 243 219 266 262 237 266 278 226 246 262 235 265 260 232 255 259 260 274 246 249 268 230 258 258 279 240 239 288 259 272 270 257 239 240 244 259 247 275 274 235 244 246 261 265 262 273 240 265 279 244 211 243 249 265 263 238 268 259 245 229 239 245 228 270 265 257 240 230 257 269 259 233 217 246 245 273 228 242 267 234 270 255 242 245 276 231 249 245 233 257 261 258 238 245 221 228 243 249 240 279 264 235 233 262 242 242 256 246 260 256 257 267 267 244 283 235 228 261 272 261 272 247 247 244 249 246 267 226 228 236 230 212 245 255 256 247 258 262 258 274 239 242 259 255 256 259 255 244 228 236 230 240 269 240 258 257 242 268 260 238 258 238 230 234 232 259 259 227 234 236 261 261 244 243 265 298 255 243 239 238 225 241 271 238 261 244 235 246 260 228 241 247 255 223 265 257 265 240 249 227 234 226 256 248 249 237 261 269 228 230 245 256 237 233 272 239 286 257 243 261 242 231 227 224 229 237 274 245 263 223 262 228 263 231 265 264 246 270 235 241 244 244 232 249 226 279 232 234 215 229 250 231 266 268 239 247 264 222 276 238 229 270 263 271 261 257 222 259 261 243 235 261 267 257 237 281 276 244 281 229 269 238 257 246 222 264 230 249 243 245 242 262 244 245 255 258 264 233 261 261 245 236 219 237 216 262 248 285 237 229 239 242 218 232 234 242 256 233 263 208 283 262 248 262 261 229 224 259 275 256 222 231 235 267 284 261 279 220 236 272 229 242 238 248 238 233 262 260 266 262 227 279 229 282 249 259 229 265 273 249 222 243 240 259 232 238 238 220 255 257 261 259 233 249 262 261 235 245 226 233 239 232 239 216 246 226 270 235 226 276 261 234 223 261 248 230 257 239 246 267 249 260 238 240 219 271 230 249 240 233 249 256 242 271 243 245 230 265 244 256 232 261 229 280 245 245 233 260 236 243 260 242 260 242 274 235 249 299 259 243 264 237 285 271 264 242 266 248 240 249 232 282 264 266 248 258 258 271 236 265 239 242 225 223 272 269 256 247 240 266 256 239 220 276 213 219 273 238 281 240 243 245 235 247 242 244 265 243 263 232 259 243 278 267 235 239 243 241 266 239 228 258 243 237 244 234 257 244 264 226 229 263 221 217 223 235 242 236 262 230 240 234 235 242 239 268 231 213 301 248 244 255 246 240 228 213 262 243 278 231 265 266 290 258 244 226 248 216 243 261 235 223 240 258 233 234 213 256 266 258 248 281 246 272 255 235 266 233 236 233 241 222 247 235 267 250 213 266 231 220 255 271 204 242 268 245 240 225 249 233 264 273 210 249 269 262 227 248 246 271 242 234 216 258 231 222 234 270 231 240 259 260 245 231 245 276 241 271 267 243 256 213 229 247 245 215 275 225 228 244 257 257 240 224 228 257 255 225 236 225 264 240 231 239 211 204 238 258 250 218 243 257 223 256 234 275 249 269 228 242 243 248 229 246 216 246 233 242 246 262 259 232 248 232 236 242 205 263 248 230 221 262 245 249 244 261 279 238 266 243 229 249 263 245 222 245 237 241 244 248 212 240 233 249 244 246 238 235 237 235 261 265 236 248 267 236 237 286 256 228 239 218 225 234 262 241 219 236 247 226 246 261 223 278 246 238 245 230 198 227 266 260 234 246 234 229 240 223 242 297 255 237 256 264 228 265 232 241 261 243 242 261 248 241 230 270 241 256 247 273 279 204 248 218 244 237 238 234 235 238 222 243 275 248 231 264 246 233 221 242 234 230 235 265 240 245 242 262 248 255 234 261 211 213 245 221 236 210 263 230 230 269 245 262 219 239 244 278 237 246 224 258 213 239 285 263 256 247 256 261 240 264 263 218 229 266 266 240 240 229 248 248 241 238 239 248 277 223 257 250 256 281 281 259 233 259 248 243 242 273 239 221 256 275 236 279 234 257 267 226 281 216 256 234 268 249 231 229 248 258 242 231 247 268 232 246 286 241 238 255 232 240 240 246 234 235 239 268 250 234 268 233 233 230 238 264 224 248 239 226 256 247 255 257 294 244 245 244 281 255 238 258 271 267 238 261 272 221 270 283 246 249 237 278 226 230 263 269 236 271 274 267 268 231 238 233 195 227 224 255 223 268 224 213 248 262 272 242 268 284 237 268 237 223 257 270 216 245 272 284 261 260 257 267 243 276 244 266 273 261 255 246 256 278 257 237 230 246 248 271 262 238 236 259 240 242 267 241 264 240 277 244 283 293 239 220 264 259 276 248 262 245 272 238 281 247 233 233 264 217 257 262 289 245 239 238 239 212 238 280 246 271 237 285 247 228 237 241 230 282 245 270 264 272 245 244 243 238 249 267 258 295 233 259 236 232 249 277 247 234 240 222 235 247 247 281 261 259 257 279 235 271 235 243 218 262 279 247 268 296 285 281 274 261 247 299 279 243 284 288 285 268 286 269 265 280 243 256 273 263 261 280 258 264 293 295 249 275 296 282 276 263 261 261 266 257 280 267 297 261 296 276 281 291 277 250 248 243 265 279 235 299 278 297 291 275 297 287 284 301 259 296 310 296 311 300 273 280 325 295 291 322 305 305 309 294 322 304 318 282 354 309 289 316 335 336 341 335 320 346 334 375 359 368 391 416 388 378 379 415 456 441 488 472 482 418 468 506 487 461 465 512 470 499 484 460 440 491 465 465 449 430 416 416 414 392 401 412 383 390 348 383 349 333 345 323 331 324 322 301 336 305 301 300 307 316 302 326 281 282 273 281 284 245 308 271 268 278 257 268 248 255 292 283 245 232 272 272 274 282 243 267 263 277 273 235 258 265 276 246 274 288 234 231 250 270 248 280 262 249 248 262 257 261 247 285 275 240 291 239 225 229 249 243 277 248 243 249 257 245 256 239 258 268 266 242 271 244 216 273 268 245 238 261 274 281 268 258 293 262 248 265 245 241 243 229 280 218 239 272 262 204 291 290 222 259 241 267 269 281 266 248 240 240 247 235 225 272 266 278 277 231 235 246 235 289 231 219 248 263 266 245 260 259 257 258 294 255 241 276 229 261 268 275 256 256 217 255 278 256 246 240 248 238 299 248 262 244 257 242 230 239 248 238 246 247 265 236 265 219 303 228 231 242 261 250 248 267 268 274 270 263 245 218 237 239 243 270 223 272 264 289 226 271 241 276 235 255 225 241 277 256 259 269 275 246 248 256 270 258 239 255 218 239 236 291 239 236 240 244 264 257 259 240 248 261 228 260 243 259 261 236 303 261 271 275 231 255 247 232 277 269 266 266 257 247 238 228 267 215 235 255 269 244 298 235 263 248 257 248 247 258 243 242 225 261 241 257 263 267 261 229 223 244 215 223 259 282 260 222 267 261 224 248 220 255 241 267 244 263 264 277 272 227 260 243 250 247 255 258 262 237 212 241 234 247 244 256 260 244 220 227 259 243 223 262 263 275 257 275 227 260 242 228 247 282 235 259 249 217 227 273 265 248 244 243 278 268 207 230 244 238 241 234 229 249 237 269 221 259 263 277 274 247 257 242 260 255 240 243 243 225 260 243 285 261 260 242 214 257 275 247 261 224 266 270 256 236 273 259 244 282 257 278 259 246 241 277 272 264 240 242 247 276 272 264 244 244 245 258 232 237 232 257 240 255 237 270 264 290 243 273 259 255 236 239 238 259 257 241 260 276 255 273 242 277 259 274 263 275 222 267 270 230 256 249 267 211 250 272 229 227 267 246 259 256 274 227 240 211 306 245 257 240 242 257 255 246 231 241 262 250 235 255 263 243 255 256 237 255 236 259 241 240 281 257 256 225 255 234 243 260 244 231 287 245 246 276 235 270 233 231 240 216 223 274 239 242 255 230 267 235 264 249 256 265 255 259 242 262 258 248 241 229 249 226 240 237 247 228 233 233 241 288 255 240 236 248 262 268 284 263 240 262 217 247 256 245 247 273 238 238 273 262 285 242 242 274 220 228 263 269 228 283 262 225 292 272 239 248 274 249 226 243 246 258 279 249 235 240 250 272 216 280 241 234 273 281 236 240 284 256 255 259 293 265 248 240 237 272 244 275 273 262 235 250 242 247 290 227 256 262 236 223 261 244 250 259 266 262 267 276 277 274 259 246 248 250 265 268 265 263 271 232 260 242 234 230 242 262 239 263 273 255 263 269 239 265 224 272 256 270 234 279 205 230 232 264 257 259 250 243 231 258 233 234 234 243 248 265 256 245 265 246 259 269 269 284 240 261 234 264 259 257 232 232 272 241 284 281 264 247 236 278 243 240 265 215 292 268 267 256 255 247 272 271 269 220 263 240 239 267 249 271 242 227 259 241 267 256 228 278 260 259 256 275 277 223 255 266 273 266 240 272 223 259 274 272 250 231 248 273 243 247 241 244 262 259 244 262 266 250 224 238 243 277 247 287 240 274 229 238 248 265 258 233 244 268 240 281 276 232 264 229 263 280 221 267 244 280 243 258 213 236 248 264 248 263 259 260 249 241 231 276 272 234 230 259 242 275 234 228 271 247 236 224 264 265 239 248 225 267 244 237 271 246 294 246 265 234 260 227 274 278 269 269 230 263 235 268 259 233 267 261 263 278 248 236 258 239 257 232 217 232 273 286 240 268 247 259 260 233 239 248 219 281 259 203 231 229 266 243 266 239 247 258 279 241 305 268 237 229 269 262 270 286 226 236 269 268 233 241 242 245 240 228 231 249 226 261 224 277 265 219 264 234 238 257 268 230 234 222 266 242 255 281 275 244 270 261 275 241 249 218 244 232 232 290 243 234 261 259 246 256 213 256 264 228 244 246 237 270 247 261 229 260 232 236 246 241 239 247 243 262 249 246 237 233 241 243 231 227 262 256 240 281 244 266 266 242 257 222 238 244 237 288 237 229 222 268 249 244 256 259 228 238 242 224 223 244 258 266 219 240 263 220 267 237 261 240 256 263 217 269 219 236 227 232 269 280 255 264 271 236 259 243 243 241 214 237 272 232 237 257 265 268 261 222 237 248 263 262 261 257 258 232 217 219 223 261 222 237 273 237 269 258 260 287 229 236 245 241 210 237 272 230 219 272 242 228 245 247 234 270 248 237 243 228 243 244 239 246 257 295 232 272 255 267 242 217 238 263 260 274 260 280 230 269 288 249 255 255 274 255 208 223 280 243 232 285 248 270 244 261 237 245 223 274 234 238 267 259 238 236 268 243 237 232 231 246 262 257 240 231 275 257 238 247 229 243 259 260 262 270 264 233 242 230 242 263 289 260 258 263 213 247 228 270 247 280 236 268 237 287 256 284 268 218 260 243 247 235 260 249 261 258 260 235 248 249 223 256 273 261 255 259 215 239 260 236 263 261 266 247 259 208 267 240 234 239 255 256 247 266 242 247 280 270 234 257 258 245 300 277 221 261 255 265 267 264 277 233 264 263 245 242 241 246 248 231 243 262 237 257 245 238 258 257 246 247 271 224 270 255 237 260 281 248 260 234 257 239 236 261 260 273 273 259 232 264 242 238 259 278 248 247 242 260 263 263 244 265 227 228 245 284 245 230 245 263 239 223 260 209 257 274 248 277 247 225 278 222 204 273 240 256 259 226 268 240 255 268 246 231 247 236 240 243 244 241 248 268 230 245 236 249 264 237 211 238 245 217 270 246 256 246 227 246 260 244 234 245 271 242 247 240 240 240 271 262 261 273 247 244 243 260 255 214 279 228 246 258 213 246 234 259 261 227 238 258 263 243 239 264 233 245 272 239 237 224 262 229 281 222 239 270 257 266 273 239 240 242 228 274 248 244 260 257 231 228 243 249 276 236 262 228 274 244 258 264 246 278 238 249 230 279 272 266 248 271 274 242 240 259 243 249 273 239 248 264 269 271 265 258 279 263 272 283 236 277 255 243 261 262 248 282 249 255 244 249 258 239 249 259 280 258 266 274 243 237 246 217 281 237 218 238 260 283 262 287 229 215 240 247 236 244 258 218 263 217 247 246 255 229 259 229 292 233 247 260 267 271 249 216 266 261 288 278 276 221 276 243 269 289 266 297 224 265 228 264 255 243 286 258 230 255 237 247 246 234 280 259 258 281 272 280 265 263 256 245 236 241 279 291 246 249 280 249 245 248 244 255 266 241 259 264 225 239 297 237 260 279 242 245 272 268 244 226 293 258 246 228 264 244 248 255 242 283 234 256 260 245 259 264 249 266 243 263 210 238 238 247 275 283 246 248 235 294 245 275 227 269 261 255 255 296 256 255 255 271 290 222 246 224 260 242 235 245 237 277 273 246 237 266 227 230 242 272 247 259 247 235 260 265 247 234 261 256 274 244 233 239 258 225 260 238 256 258 223 248 237 246 269 267 240 258 237 264 268 257 270 242 262 248 279 279 255 249 226 255 263 273 240 263 241 212 277 238 241 223 261 256 257 262 309 283 290 263 265 267 238 250 236 222 276 263 243 276 263 273 234 259 232 241 224 269 235 260 241 270 258 228 287 259 270 262 301 248 260 222 243 238 260 264 232 271 273 267 246 277 246 225 245 249 276 244 220 234 235 271 245 225 261 264 259 232 272 243 234 242 242 272 284 281 297 258 293 271 267 275 243 299 284 278 264 261 275 236 245 285 267 263 263 247 248 225 270 255 233 271 280 257 261 273 261 246 297 257 263 257 248 244 268 274 265 256 241 262 302 247 247 263 242 283 270 267 229 282 276 213 246 260 249 272 243 274 298 274 245 278 277 271 269 272 255 243 260 246 277 261 262 276 280 277 288 285 264 248 274 248 264 247 255 258 280 248 286 257 249 286 249 265 241 270 243 260 243 245 272 261 281 224 250 275 273 255 246 270 249 264 244 255 261 231 247 239 241 277 257 270 266 246 271 234 237 241 295 247 240 247 260 241 271 262 274 264 245 259 271 273 262 255 271 243 265 269 277 261 275 265 245 268 277 238 280 241 244 270 259 240 263 264 274 263 263 232 291 238 284 271 258 240 259 273 268 258 227 247 237 268 274 274 263 248 263 262 270 249 246 255 249 261 240 308 233 273 278 232 239 266 247 256 247 251 229 279 262 270 261 255 262 263 240 230 275 256 298 234 271 248 274 262 248 257 247 279 276 236 224 291 237 239 246 256 267 233 271 236 283 256 273 272 255 257 258 277 255 303 272 270 279 248 256 276 258 226 267 255 285 275 270 257 286 265 272 277 275 274 293 240 259 280 257 229 245 279 231 267 242 283 235 275 264 277 285 249 279 272 260 261 262 296 284 300 288 290 291 270 270 307 301 262 278 266 238 242 278 280 272 281 261 289 243 305 298 304 295 309 256 255 290 289 282 285 278 261 298 281 296 264 272 272 268 268 271 275 269 291 273 267 255 258 287 276 237 265 274 237 260 245 313 291 256 280 322 239 304 310 280 274 240 269 230 249 263 259 258 277 275 266 244 277 246 237 274 240 243 238 222 269 278 260 248 261 267 294 271 283 281 266 249 242 276 237 311 249 290 277 272 241 265 230 248 267 269 261 246 270 258 280 288 258 262 239 246 267 250 248 228 272 247 261 272 243 282 273 242 270 227 264 289 249 261 264 260 267 244 260 248 277 271 242 236 257 270 274 278 245 282 282 274 275 261 262 270 234 258 274 261 234 235 258 245 245 248 248 233 297 258 266 256 273 249 292 280 231 275 264 241 273 246 264 237 249 247 276 270 256 261 295 259 258 237 280 259 257 245 255 303 243 239 263 256 256 248 239 269 235 266 238 258 261 238 264 235 248 269 257 266 266 271 267 287 269 288 232 280 269 247 292 266 259 275 262 290 275 245 235 268 268 245 248 248 325 258 260 271 292 228 256 279 244 272 230 219 237 238 243 262 275 229 256 266 243 247 225 267 255 274 257 261 260 264 269 262 280 239 288 237 258 239 277 246 243 261 234 237 260 274 259 281 232 242 261 247 263 256 255 272 266 258 263 267 303 255 268 248 246 280 275 233 249 227 257 237 247 292 264 255 262 264 267 264 235 277 282 257 282 256 308 235 257 272 246 283 241 257 261 272 278 241 262 226 258 269 238 249 259 248 255 276 243 268 255 231 289 250 276 249 248 249 223 274 260 267 280 262 270 250 290 272 261 282 262 244 275 303 242 283 309 256 264 282 264 285 265 258 220 237 242 267 231 289 243 265 267 241 236 259 272 241 242 247 235 247 258 282 285 241 261 240 275 267 259 244 256 282 256 265 277 262 245 241 282 268 263 277 262 246 245 274 260 282 236 229 275 268 247 277 220 280 278 263 298 257 247 231 263 247 249 268 261 270 269 250 225 265 244 294 266 268 255 242 247 273 249 222 262 297 273 257 269 264 294 275 266 242 239 268 256 261 281 245 247 218 250 228 269 244 246 216 249 242 245 239 285 277 308 241 282 229 232 278 243 263 237 247 262 241 238 269 241 274 248 264 238 221 240 242 245 285 246 242 269 284 291 255 267 258 237 273 287 267 258 242 274 262 298 233 255 257 245 261 258 248 279 244 237 257 262 244 243 263 247 226 269 256 260 273 275 275 268 220 234 260 259 236 271 226 255 247 247 243 223 256 239 235 219 242 266 249 264 268 271 238 234 257 244 250 233 262 242 272 273 239 298 249 244 242 231 276 236 227 242 275 281 239 240 227 231 256 224 259 263 250 230 263 223 243 270 285 234 281 240 273 244 224 255 264 248 237 259 241 240 258 249 239 211 317 282 266 257 249 242 275 271 259 301 236 262 259 239 259 236 245 262 283 258 267 249 229 269 214 266 286 258 249 260 261 278 221 232 260 248 271 247 258 263 234 222 269 243 238 269 282 237 245 256 267 273 275 232 247 259 245 239 261 232 269 245 261 244 245 234 267 264 217 264 241 260 258 264 268 288 273 244 264 247 241 245 247 233 257 228 240 240 231 265 247 260 249 248 285 245 242 262 216 245 255 255 261 271 291 209 270 256 265 258 246 243 233 273 269 273 261 249 279 263 245 242 238 260 220 269 271 264 268 257 246 257 251 244 256 222 258 225 266 256 208 264 277 244 270 262 266 245 275 272 247 222 220 261 220 250 263 262 219 215 231 256 227 280 245 257 240 285 282 247 240 265 237 247 263 248 247 213 270 227 227 258 246 267 229 266 232 256 277 257 249 244 285 250 271 280 264 237 237 263 262 258 255 249 259 260 260 263 276 228 279 244 263 263 221 248 241 261 256 231 255 256 269 256 270 229 259 248 255 246 269 226 265 245 242 281 249 263 240 273 238 278 265 256 243 214 260 249 263 302 228 250 232 281 235 266 246 246 257 226 227 268 243 230 260 256 245 247 260 220 257 236 217 281 245 234 237 280 261 276 265 241 250 239 267 256 274 234 220 244 233 247 275 242 249 255 262 266 236 240 261 226 266 264 256 226 232 232 217 275 246 255 243 228 236 276 244 262 259 271 264 275 260 261 225 277 269 219 268 242 265 250 247 246 224 231 244 262 238 232 268 227 228 248 263 262 268 239 285 267 220 271 284 232 285 261 293 266 213 274 246 261 241 270 236 241 259 266 261 275 246 265 237 269 288 239 243 271 273 242 269 278 269 236 226 275 275 235 275 246 248 255 268 273 224 241 241 267 247 257 255 273 255 238 247 216 276 249 272 245 240 266 283 250 256 242 250 286 256 260 276 238 240 235 265 292 249 275 246 238 256 262 271 260 294 262 276 257 227 243 233 260 293 256 238 255 236 264 289 268 268 245 226 246 241 256 235 246 257 239 268 206 243 259 271 277 248 263 259 239 246 238 244 222 260 269 227 239 284 267 245 238 256 248 250 265 258 247 242 275 270 271 276 258 226 266 266 229 271 245 232 276 256 272 248 217 267 262 256 259 261 255 238 260 258 284 237 262 230 298 243 266 282 239 249 278 277 261 233 256 246 261 257 276 247 261 259 249 259 261 280 225 281 294 267 226 277 256 267 265 276 273 233 227 265 271 260 258 237 285 256 265 258 237 225 272 259 242 260 242 259 226 249 263 228 229 255 255 270 267 225 275 248 265 264 271 257 268 278 280 248 248 260 289 285 272 240 239 255 244 257 278 279 272 257 271 242 257 250 244 219 269 282 246 233 266 264 230 257 270 261 241 263 248 265 231 259 261 226 262 263 261 247 262 280 263 235 267 282 273 257 256 232 272 245 265 274 243 299 285 270 290 264 266 264 274 241 262 242 259 289 256 249 226 261 244 272 278 262 263 249 286 271 257 256 271 269 285 278 282 287 264 270 242 259 227 247 244 289 247 262 242 249 271 247 264 232 262 249 301 265 232 257 261 238 241 233 288 264 268 261 267 283 258 257 233 269 257 246 233 277 245 244 268 245 244 247 259 221 260 256 275 269 260 247 257 236 280 250 291 265 258 258 257 271 265 234 257 283 232 241 210 249 279 219 248 231 224 234 273 263 290 265 271 257 277 256 238 247 275 259 255 240 275 272 264 268 290 259 259 284 258 248 260 267 261 263 242 270 255 241 255 288 243 261 266 271 257 285 270 225 279 225 285 280 260 242 237 268 258 255 272 244 243 272 278 268 262 238 237 239 237 240 250 257 235 272 271 239 299 241 272 257 224 225 248 263 247 276 283 274 280 268 272 281 246 228 260 259 255 275 242 272 316 261 236 236 237 271 244 246 271 265 229 218 286 284 269 288 247 241 268 250 276 243 225 244 249 261 260 262 258 277 232 238 257 286 255 265 229 232 249 262 261 228 270 266 273 264 233 285 248 246 230 261 245 286 248 280 210 255 275 284 244 270 264 293 274 272 261 297 278 264 208 248 260 249 276 250 275 259 277 286 238 269 284 247 241 255 268 257 271 260 250 258 273 259 240 272 261 239 230 271 248 246 259 248 268 227 266 242 231 247 267 262 269 271 295 250 260 262 232 221 248 247 277 263 260 259 213 268 242 243 237 231 281 285 284 263 262 241 242 257 269 258 274 292 268 232 261 276 236 273 250 245 263 244 241 264 248 240 263 276 242 305 273 265 256 272 258 230 235 231 247 261 276 270 230 221 258 302 262 293 203 228 304 293 261 277 265 264 227 282 260 242 287 268 275 250 241 278 241 292 262 256 247 246 244 261 287 243 263 241 256 283 260 266 280 244 258 296 257 278 273 265 256 274 259 263 241 272 227 232 265 246 291 245 255 270 267 243 266 248 284 259 284 277 291 271 259 272 262 264 270 292 295 278 240 296 262 272 245 293 314 300 268 278 259 268 305 267 286 264 275 269 272 296 286 303 284 286 296 292 291 288 287 304 298 302 291 284 280 275 304 286 271 292 293 288 288 324 309 280 312 309 280 298 293 323 302 286 287 292 308 312 293 292 325 281 271 309 267 262 301 292 260 269 288 276 282 260 306 247 271 265 278 278 287 267 305 305 262 285 267 294 269 268 267 273 282 263 280 289 284 294 257 255 293 274 301 274 299 268 245 232 265 225 233 259 247 249 299 269 238 288 266 259 269 238 227 247 249 271 292 272 236 265 256 255 257 214 250 286 240 247 272 237 266 211 255 245 245 241 266 261 249 255 267 300 214 235 269 227 234 225 234 238 246 220 270 273 222 258 235 248 232 263 226 248 288 260 290 277 243 285 236 248 232 238 276 229 286 245 255 234 241 237 246 223 230 271 279 232 258 255 244 261 257 255 210 257 246 283 277 248 267 277 255 263 274 263 262 248 261 223 250 235 248 247 245 277 274 263 277 291 255 233 283 263 267 267 264 276 275 260 298 258 272 234 264 274 268 248 255 241 264 279 237 262 276 257 239 287 279 277 270 268 289 264 267 245 257 283 265 249 230 233 257 297 262 273 243 267 263 281 247 276 274 236 224 272 248 262 260 264 234 241 243 234 224 241 258 236 263 249 274 275 242 236 249 246 274 246 247 217 259 261 243 258 227 238 245 260 260 241 242 261 276 257 223 273 277 259 246 216 244 250 263 264 236 271 235 237 285 282 216 247 314 257 256 267 229 280 259 238 234 233 242 224 255 245 255 236 243 292 255 243 259 279 248 239 287 283 274 239 222 259 285 269 258 282 270 257 255 227 236 279 258 249 264 250 218 237 261 231 237 262 244 263 271 277 220 265 240 269 248 250 256 241 264 240 264 291 294 291 270 239 239 263 257 234 229 270 249 279 244 249 222 259 273 266 257 281 260 262 280 289 274 273 260 248 259 256 269 248 246 249 223 230 265 247 239 271 255 275 260 271 282 284 226 242 243 233 234 273 282 263 228 235 247 262 248 264 282 229 265 246 229 262 243 229 232 272 223 276 241 271 274 263 248 221 269 260 261 282 268 259 249 272 231 229 269 244 265 245 260 273 209 255 246 261 241 270 217 245 235 247 237 278 225 258 269 237 273 255 237 256 220 257 239 243 248 231 266 243 269 242 244 244 267 235 238 230 244 247 268 255 236 263 257 248 247 274 223 246 262 235 248 258 237 264 256 245 283 258 237 248 239 292 248 247 273 273 244 276 227 239 230 255 233 257 213 277 220 236 300 255 268 246 227 257 264 247 270 227 284 267 239 237 275 246 258 244 274 237 227 247 261 266 267 250 273 271 274 232 237 240 227 244 257 266 258 241 259 234 244 244 265 277 259 242 236 270 219 241 262 265 255 249 256 229 240 280 277 266 258 256 242 224 273 226 267 242 281 222 282 270 243 248 267 250 262 244 281 206 240 242 232 231 272 297 260 239 235 231 262 241 244 272 291 246 271 249 262 256 261 231 288 232 241 274 249 281 219 280 258 266 244 240 237 272 268 248 276 230 264 241 260 242 223 267 259 284 245 265 261 231 293 235 236 242 272 282 258 240 276 263 279 255 234 234 240 258 262 259 247 244 235 266 268 235 261 229 247 247 239 242 260 255 221 244 293 243 230 261 235 247 240 243 288 257 292 270 276 262 272 240 272 241 255 239 247 243 249 259 240 250 259 266 237 263 255 258 235 224 275 279 233 249 242 239 278 243 245 237 255 226 237 280 265 243 256 273 241 287 275 300 246 243 259 234 238 287 276 242 257 287 237 260 278 241 279 257 235 255 262 314 244 262 270 264 263 290 241 243 256 299 241 237 263 259 266 265 234 231 281 248 276 233 272 259 232 262 245 241 264 249 278 258 260 237 272 290 269 246 246 266 294 264 240 226 266 260 259 245 261 269 268 245 286 260 255 227 229 275 271 258 217 243 243 250 255 241 255 230 286 242 292 260 246 259 277 278 271 232 236 279 236 245 278 236 264 315 246 244 238 277 256 242 277 250 238 236 262 264 220 275 261 264 257 268 242 247 232 256 240 255 260 256 227 247 226 266 272 245 276 248 270 264 249 259 255 260 261 265 273 256 244 261 263 258 276 260 234 259 276 215 292 259 264 260 247 259 272 244 258 256 262 264 285 235 280 227 231 221 267 265 238 241 255 281 276 233 228 258 246 263 263 289 264 236 248 263 278 287 267 260 261 241 260 259 236 234 283 302 263 243 271 257 261 284 210 276 258 273 241 277 241 239 249 238 258 267 260 243 272 233 242 248 280 277 257 263 272 286 226 270 230 236 240 245 271 269 279 215 262 234 277 273 290 275 244 278 245 243 256 265 273 263 247 262 268 257 290 270 260 247 241 255 249 274 262 269 244 264 279 257 269 249 247 262 245 217 238 276 263 249 261 257 241 247 258 223 266 263 231 265 259 244 255 261 273 236 229 235 282 268 300 272 245 229 263 248 264 278 264 239 263 244 300 259 258 233 242 265 265 232 274 277 228 236 257 263 265 248 269 236 280 229 301 238 249 237 269 272 272 232 276 261 276 277 272 263 278 280 276 260 257 268 250 249 241 288 282 240 241 243 264 240 266 274 278 276 242 242 273 242 239 255 261 262 245 249 282 288 247 269 258 248 215 258 259 281 255 284 261 269 268 280 245 287 238 271 258 258 250 256 249 243 262 247 261 255 256 259 233 262 258 258 290 265 243 259 242 228 248 261 270 243 257 231 269 273 305 236 269 249 257 246 222 260 266 243 246 238 238 240 224 232 273 272 267 284 243 249 239 257 234 243 259 257 237 272 242 277 245 258 263 244 264 239 268 264 262 271 243 228 227 233 243 246 283 241 236 241 238 266 264 229 245 247 239 238 270 266 257 263 265 269 270 231 256 266 294 243 296 264 261 289 280 268 224 233 246 242 260 243 248 236 241 267 260 255 218 240 245 289 210 267 275 280 256 261 268 276 244 283 239 247 269 261 288 288 260 249 209 231 248 285 272 262 245 259 250 287 275 259 267 267 268 295 267 229 270 239 267 232 230 236 248 257 274 281 249 211 270 262 247 265 248 231 281 272 257 245 247 267 267 286 243 263 229 249 271 256 239 240 258 285 237 248 243 265 259 269 240 261 269 236 278 303 247 273 235 255 223 268 292 259 226 240 222 264 244 243 249 243 267 249 266 235 232 261 259 270 272 244 270 248 229 239 259 260 232 260 233 261 286 243 232 242 242 263 271 289 230 249 246 241 265 280 233 217 286 266 284 237 256 242 267 259 264 269 268 257 257 284 281 270 266 285 285 238 239 269 235 244 235 275 246 240 222 242 243 256 248 263 282 257 256 224 225 239 277 285 223 239 272 240 226 255 256 238 262 255 227 248 245 229 221 289 249 268 267 246 263 257 260 267 260 235 276 237 277 257 233 264 236 241 240 226 244 269 247 233 248 258 278 267 273 281 279 268 234 258 235 246 274 248 261 290 225 247 248 242 270 266 259 259 274 269 265 261 280 247 267 245 272 239 248 241 267 239 246 274 265 287 232 278 272 242 229 240 274 248 267 267 291 297 262 243 245 233 262 311 230 275 278 278 250 232 287 225 238 258 260 281 240 270 258 220 231 243 270 278 291 263 234 262 288 259 225 250 260 257 264 284 268 275 274 269 221 285 258 261 274 259 229 246 259 250 240 261 249 240 232 264 237 269 255 284 263 238 243 273 259 274 270 261 234 272 260 282 249 278 306 269 240 259 250 212 281 275 275 296 276 236 260 281 261 260 285 272 225 281 245 244 266 267 275 266 248 257 255 273 284 273 271 231 243 243 279 266 278 246 292 273 262 255 238 273 271 264 248 281 275 250 261 232 281 299 256 272 281 262 286 270 258 296 284 256 267 247 259 248 286 280 258 283 264 235 268 258 262 271 249 260 266 260 260 271 240 277 269 296 279 230 247 228 269 245 260 244 267 268 248 280 247 277 258 273 247 262 293 266 279 273 281 261 264 245 298 245 259 272 241 259 273 232 267 274 246 273 245 232 246 249 283 245 256 256 271 273 277 231 272 288 269 273 263 278 280 274 263 246 231 277 276 264 245 239 246 272 265 259 260 256 262 273 241 245 270 255 263 275 243 249 248 260 265 267 247 232 260 244 241 250 222 249 235 242 274 247 256 302 313 277 255 231 247 264 273 240 248 240 245 269 245 247 246 284 264 261 224 266 274 266 262 257 221 232 284 236 269 260 238 255 240 238 248 228 256 255 240 263 266 266 256 272 275 260 264 236 221 243 278 305 269 256 260 255 261 255 234 275 272 269 259 276 249 271 260 246 268 225 255 258 260 286 260 272 259 257 265 232 245 279 287 243 256 258 238 268 257 275 257 232 237 237 268 270 242 261 277 269 219 276 263 232 239 259 242 231 271 264 272 258 249 256 267 242 277 275 237 256 234 261 264 243 259 257 272 242 278 244 268 237 278 226 235 246 294 241 260 264 277 240 277 235 269 266 247 218 263 246 239 248 259 287 236 271 274 280 285 268 279 294 272 267 267 242 271 224 266 304 260 277 270 273 248 220 295 272 276 249 286 243 232 268 275 258 283 224 221 234 296 270 243 234 248 256 273 260 292 237 237 265 244 239 275 277 259 280 243 239 290 243 247 284 244 255 255 295 245 242 257 258 267 236 271 277 237 231 293 239 266 258 243 270 259 267 262 284 221 283 272 297 282 273 243 264 243 266 244 266 276 244 268 248 247 284 245 237 255 256 247 216 274 238 245 279 281 265 261 242 257 262 247 245 272 267 255 236 279 246 258 245 270 283 264 263 260 279 268 239 261 277 257 245 266 263 267 234 259 243 247 264 268 255 265 237 230 277 259 271 236 255 286 248 289 260 288 249 268 286 247 261 304 300 272 260 272 265 278 255 255 262 249 209 284 256 262 274 287 260 268 257 246 267 294 273 232 257 269 264 292 274 242 262 266 262 262 267 265 241 282 267 275 275 247 272 271 257 247 257 268 275 285 219 259 274 232 260 273 266 264 242 273 270 261 274 267 249 248 244 236 262 234 274 234 272 233 247 249 305 267 225 243 271 215 268 282 288 250 270 235 257 244 250 268 255 260 277 260 276 259 265 245 248 273 262 281 244 246 279 270 272 271 267 245 234 266 235 259 276 216 284 277 270 263 260 277 249 262 275 248 281 262 250 265 260 248 284 233 250 271 246 281 233 244 239 289 268 273 238 231 273 227 257 281 247 273 257 232 247 246 268 289 272 223 258 264 244 266 262 271 249 237 272 257 271 272 234 274 236 278 244 241 269 282 236 272 258 267 261 265 239 239 282 250 277 227 270 256 248 265 264 260 263 233 283 225 281 270 227 277 260 283 276 288 255 260 261 264 278 280 257 225 259 264 244 241 264 242 262 242 267 267 266 217 241 244 285 275 236 280 272 268 270 272 237 273 269 257 222 258 272 249 231 266 266 262 227 264 241 242 279 239 273 262 281 276 232 225 245 280 266 246 265 257 259 241 267 244 223 288 285 246 258 238 267 232 260 263 257 260 255 272 274 255 247 240 266 244 280 239 265 255 268 258 258 267 261 243 256 233 259 267 228 240 255 244 261 264 243 275 227 260 268 266 273 276 223 262 237 271 280 269 255 214 259 242 259 258 231 290 230 260 269 286 284 275 257 263 261 255 238 260 273 258 263 267 255 259 243 261 272 263 295 242 291 243 264 244 234 246 255 248 302 282 298 270 263 243 233 262 246 256 276 274 282 230 243 266 233 233 249 232 265 284 283 240 296 267 262 255 267 269 267 271 236 264 270 279 259 242 264 263 256 280 246 238 289 268 269 227 230 240 288 263 243 245 258 260 231 273 239 245 282 275 243 281 243 286 239 290 265 233 239 272 280 296 237 282 241 240 269 284 260 262 269 248 287 272 227 255 256 243 233 268 291 245 263 238 272 243 238 261 272 266 248 226 232 258 246 244 247 258 259 230 269 272 262 283 255 291 239 280 271 266 260 259 248 268 268 245 260 241 243 238 248 268 266 236 243 233 233 244 225 244 258 258 245 280 256 265 238 264 255 266 241 266 274 239 243 259 244 236 248 275 227 243 288 248 279 247 265 241 243 262 237 264 243 272 242 234 256 268 267 234 265 282 271 293 241 266 230 211 260 233 264 258 259 237 267 269 262 231 280 241 237 255 256 255 225 268 247 236 267 272 241 245 235 248 286 260 243 244 240 277 289 243 278 235 270 274 238 256 286 241 247 264 262 246 245 260 258 257 282 269 255 230 282 249 240 246 240 277 266 238 259 274 255 245 261 264 258 272 258 255 265 245 237 234 257 241 271 261 272 234 264 243 217 266 246 241 267 247 237 276 268 259 277 239 259 249 264 283 273 241 255 246 270 243 286 246 285 241 243 256 276 236 276 227 271 259 246 255 238 250 273 281 226 244 283 246 276 239 274 265 255 238 229 236 277 256 268 259 260 268 262 269 272 264 235 266 246 243 255 248 249 280 244 255 227 279 218 239 301 214 283 269 276 237 274 275 234 270 292 280 237 273 258 291 261 263 283 243 257 227 248 301 264 264 276 267 269 260 260 296 235 256 261 239 248 263 240 277 263 258 247 265 259 307 277 263 246 241 263 276 270 258 255 262 256 244 238 257 273 239 257 265 268 277 244 279 285 268 248 246 271 278 261 285 277 288 279 248 246 255 246 282 259 283 281 262 273 243 265 274 260 262 256 242 280 275 294 237 238 266 235 258 244 257 240 265 262 235 248 247 248 248 273 249 285 237 238 246 285 248 261 226 255 263 268 261 266 267 274 275 244 277 243 288 281 271 240 248 258 240 235 272 272 247 290 241 258 268 273 245 250 249 268 250 282 235 274 263 234 259 236 268 276 268 264 258 258 276 256 275 228 245 262 244 258 248 264 283 236 226 263 248 280 239 268 238 288 257 261 244 260 262 250 247 270 279 234 273 262 244 283 226 258 232 240 268 248 282 287 277 238 240 275 247 274 259 264 286 271 267 241 295 235 243 244 224 267 278 256 242 234 262 262 295 276 257 283 280 238 260 259 245 263 257 264 245 266 270 265 240 261 227 242 250 241 241 245 241 256 265 260 222 270 289 256 241 271 264 283 257 245 246 273 284 275 287 281 259 249 265 266 255 249 268 300 245 280 267 249 257 283 264 238 256 255 272 269 256 242 275 239 263 299 260 241 273 272 276 267 240 272 276 219 272 257 244 243 269 274 273 271 244 235 227 267 275 265 230 265 269 258 295 250 270 259 246 260 258 276 250 276 246 273 268 266 265 285 266 273 266 279 281 276 258 276 271 259 269 286 259 279 282 265 213 288 256 246 284 266 267 264 247 270 270 236 261 218 306 277 240 279 249 228 266 245 274 234 259 264 256 248 282 261 274 234 242 255 243 293 264 229 283 277 260 275 234 238 256 281 269 280 235 230 265 240 237 249 293 261 240 279 289 247 258 267 283 264 267 305 262 283 232 266 293 263 256 272 283 234 274 284 274 249 268 299 273 272 258 227 239 267 246 302 264 267 243 283 258 275 292 272 218 274 287 244 268 289 245 278 295 272 284 256 255 272 284 307 246 234 282 262 267 271 267 246 246 292 242 234 284 277 278 271 295 270 302 290 278 244 237 248 257 264 267 269 284 256 258 297 275 292 264 243 235 279 275 283 289 272 248 260 259 233 259 225 260 239 265 266 284 271 289 255 284 287 281 281 291 294 269 241 249 259 293 237 270 259 286 247 258 283 272 288 256 258 274 239 283 273 294 290 290 301 245 290 298 288 265 277 264 296 255 304 289 304 311 243 289 294 275 269 277 261 285 231 284 296 277 248 265 309 286 283 293 286 271 294 245 274 295 304 283 239 282 299 283 267 271 242 279 285 236 293 280 258 266 269 266 288 276 302 264 271 282 284 279 291 294 277 306 290 272 288 273 266 273 273 287 294 248 297 267 265 289 274 249 294 300 275 271 271 263 277 287 281 255 272 282 239 267 261 272 277 274 250 290 274 279 226 276 262 272 232 267 263 281 245 231 261 269 257 259 256 291 266 226 250 265 245 259 299 236 264 256 260 272 280 247 257 245 276 244 262 278 288 271 269 288 249 262 275 249 286 273 281 268 289 291 276 290 263 269 276 270 243 293 272 255 242 277 277 262 260 256 276 238 237 296 268 281 265 297 248 270 291 281 269 266 262 232 258 269 279 255 260 223 255 260 263 268 287 239 224 255 295 276 258 268 263 273 267 299 237 302 262 275 270 262 278 265 273 272 248 259 287 232 266 245 236 269 273 267 260 231 239 299 260 247 249 256 259 279 269 223 249 246 236 256 255 274 274 231 270 234 244 281 280 280 277 259 260 236 267 273 257 256 256 267 271 273 257 257 234 287 289 277 272 274 236 265 264 271 294 255 268 275 243 255 275 274 260 259 262 261 278 241 243 274 263 239 257 289 260 284 272 240 265 227 260 260 294 238 274 273 285 256 271 250 258 286 256 268 258 243 278 247 237 284 298 245 264 291 278 290 295 264 260 271 243 267 275 274 274 228 265 263 243 271 293 275 264 256 278 288 269 284 267 284 272 248 261 266 259 240 262 273 239 257 243 273 257 277 243 268 265 259 240 257 263 247 257 283 244 249 248 275 256 255 256 263 267 281 247 285 260 241 242 256 245 262 269 275 260 281 244 247 271 292 238 264 271 283 246 284 281 265 285 248 256 289 275 259 266 231 276 266 268 240 305 250 286 268 262 221 260 285 268 260 287 257 278 241 245 259 245 277 287 272 293 243 245 267 267 270 275 262 294 229 268 247 275 279 273 256 265 303 282 232 229 262 266 233 299 256 268 249 225 265 282 229 224 268 265 260 257 256 263 262 227 231 277 234 256 266 276 286 270 232 248 269 284 237 298 299 238 245 269 266 230 225 259 245 256 273 284 287 269 241 256 238 273 240 269 273 222 273 239 264 265 236 237 268 248 274 284 279 212 257 265 282 267 270 281 244 282 282 245 284 267 262 260 245 239 264 257 242 260 269 282 279 241 265 281 265 270 236 302 270 273 245 223 275 244 232 241 261 264 248 258 238 261 264 270 283 246 268 262 242 262 258 247 274 259 242 287 261 264 273 263 246 246 249 264 238 272 264 279 258 246 281 264 255 225 237 226 274 266 217 223 266 264 281 245 263 272 238 273 278 246 231 259 261 270 272 262 241 258 269 259 278 255 226 258 289 239 259 243 262 231 249 238 243 266 276 271 227 271 267 223 263 228 275 283 266 276 239 286 229 245 266 236 261 237 246 241 223 255 261 232 261 255 230 242 278 273 247 233 266 283 245 294 238 296 212 238 224 260 240 269 275 223 269 268 268 296 258 283 274 270 288 243 222 243 247 235 258 263 275 233 246 235 230 241 293 248 245 258 257 260 271 225 261 238 263 275 291 276 256 263 270 270 225 244 241 240 258 258 249 278 231 238 267 244 242 284 247 249 249 281 263 242 286 272 262 246 259 273 257 234 266 264 267 261 271 273 244 288 259 287 273 241 264 292 264 267 266 255 235 262 265 269 271 290 273 257 276 268 263 270 269 264 290 265 246 237 261 286 268 239 241 249 243 260 244 271 279 248 256 270 266 259 264 247 250 266 255 270 239 243 272 262 233 258 276 248 267 239 285 263 260 233 284 262 277 275 216 258 233 237 231 225 266 276 250 257 272 241 250 250 237 261 272 256 275 240 284 239 234 256 258 265 239 270 241 256 267 240 244 263 247 276 236 279 268 261 268 248 217 270 278 240 282 226 269 282 284 244 235 277 260 264 257 263 266 285 227 266 243 278 256 238 261 258 262 268 261 264 236 229 307 234 269 278 268 249 264 243 284 265 258 239 242 274 235 245 231 282 237 224 227 267 279 267 267 273 290 260 269 262 238 233 281 271 243 255 234 236 228 276 272 243 258 290 260 257 245 230 260 247 249 238 257 246 240 264 263 278 244 261 237 256 268 265 240 270 273 227 272 235 266 264 275 264 238 234 261 259 264 235 257 269 258 255 268 264 266 242 266 262 275 268 272 258 276 268 232 271 288 262 262 264 281 264 256 267 245 258 264 245 280 255 256 262 219 243 243 259 260 280 258 270 236 255 275 287 314 268 267 271 275 241 269 255 270 280 260 258 274 243 309 234 224 234 269 270 242 273 274 226 246 277 285 239 260 287 267 260 276 269 269 228 263 246 273 280 273 228 302 281 286 290 249 239 279 265 269 235 258 221 271 268 257 281 258 271 255 278 244 262 265 239 261 277 271 257 274 260 272 234 230 273 263 239 265 279 264 272 271 240 302 267 273 277 235 261 243 278 277 291 270 248 213 236 267 258 282 260 258 260 243 245 271 245 226 276 285 267 244 246 240 266 258 262 249 262 280 276 257 277 243 235 281 279 265 288 258 268 242 255 278 236 276 242 276 240 248 258 277 276 248 244 244 239 233 261 268 264 239 269 237 290 281 241 247 236 277 256 249 269 265 248 270 258 255 261 270 281 244 263 263 264 278 248 295 229 302 291 307 262 246 272 256 226 249 256 242 271 270 285 265 272 266 302 229 276 244 288 240 237 277 269 289 278 247 272 262 234 268 240 213 262 291 229 222 267 277 279 261 268 277 264 248 264 265 257 273 274 279 283 243 279 272 231 277 267 239 227 245 246 284 282 232 265 264 256 243 244 266 262 273 271 274 249 245 261 261 269 277 269 291 247 287 274 242 268 290 269 270 297 235 268 267 280 239 272 279 229 271 238 307 282 280 278 282 263 280 298 270 269 286 271 285 287 267 228 255 271 243 270 264 264 264 246 270 222 247 239 259 242 268 257 233 265 287 278 255 242 279 249 259 246 303 231 217 265 244 266 289 229 248 240 268 265 279 248 226 271 261 226 255 264 255 256 243 262 283 285 277 274 227 277 265 277 246 263 239 266 255 255 276 271 256 246 246 299 256 279 304 239 240 279 246 225 231 258 278 278 272 229 261 280 273 271 278 261 281 258 241 256 239 246 234 286 288</counts>
			</dataPoints>
		</scan>
	</xrdMeasurement>
</xrdMeasurements>