File: data/XRD/XG-Luft/XG-750/W6824-1D_XG_Luft_750.xrdml
<xrdMeasurements xmlns="http://www.xrdml.com/XRDMeasurement/2.1" xmlns:xsi="http://www.w3.org/2001/XMLSchema-instance" xsi:schemaLocation="http://www.xrdml.com/XRDMeasurement/2.1 http://www.xrdml.com/XRDMeasurement/2.1/XRDMeasurement.xsd" status="Completed">
	<comment>
		<entry>Configuration=Factory configuration, Owner=User-1, Creation date=7/8/2013 4:01:53 PM</entry>
		<entry>Goniometer=PW3050/65 (Theta/2Theta); Minimum step size 2Theta:0.0001; Minimum step size Omega:0.0001</entry>
		<entry>Sample stage=MRD Cradle; Minimum step size Phi:0.01; Minimum step size Chi:0.01; Minimum step size X:0.01; Minimum step size Y:0.01; Minimum step size Z:0.001</entry>
		<entry>Diffractometer system=XPERT-PRO</entry>
		<entry>Measurement program=C:\PANalytical\Data Collector\Programs\Jorrit\2thom\_absolute_2th-om_10-130deg_PIXscan_56min.xrdmp, Identifier={15BCCF57-2807-42BD-B5B9-ECC0B3DC9284}</entry>
		<entry>Batch program=C:\PANalytical\Data Collector\Programs\SimonL\batch6x_2thom_10-130°_z9.1_x0,10,20,30_y20,40_57min - Kopie.xrdmp, Identifier={8874E540-C3F4-4307-831A-CD55F073CDCD}</entry>
	</comment>
	<sample type="To be analyzed">
		<id></id>
		<name></name>
		<preparedBy></preparedBy>
	</sample>
	<xrdMeasurement measurementType="Scan" status="Completed" sampleMode="Reflection">
		<comment>
			<entry>_absolute_2th-om_10-130deg_PIXscan_56min</entry>
			<entry>PHD Lower Level = 4.83 (keV), PHD Upper Level = 11.27 (keV)</entry>
		</comment>
		<usedWavelength intended="K-Alpha 1">
			<kAlpha1 unit="Angstrom">1.5405980</kAlpha1>
			<kAlpha2 unit="Angstrom">1.5444260</kAlpha2>
			<kBeta unit="Angstrom">1.3922500</kBeta>
			<ratioKAlpha2KAlpha1>0.5000</ratioKAlpha2KAlpha1>
		</usedWavelength>
		<incidentBeamPath>
			<radius unit="mm">320.00</radius>
			<xRayTube id="1010048" name="Empyrean Cu LFF HR (9430 033 7310x) DK442154">
				<tension unit="kV">40.0</tension>
				<current unit="mA">40.0</current>
				<anodeMaterial>Cu</anodeMaterial>
				<focus type="Line">
					<length unit="mm">12.0</length>
					<width unit="mm">0.4</width>
					<takeOffAngle unit="deg">4.2</takeOffAngle>
				</focus>
			</xRayTube>
			<xRayMirror id="27010001" name="Inc. Beam Cu W/Si (parabolic MRD)" hybrid="false">
				<crystal type="Graded" shape="Parabolic">W/Si</crystal>
				<acceptanceAngle unit="deg">0.800</acceptanceAngle>
				<length unit="mm">60.0</length>
			</xRayMirror>
			<sollerSlit id="21010002" name="Soller slits 0.04 rad.">
				<opening unit="rad">0.0400</opening>
			</sollerSlit>
			<mask id="22030007" name="Fixed mask 2 mm">
				<distanceToSample unit="mm">220.00</distanceToSample>
				<width unit="mm">2.00</width>
			</mask>
			<divergenceSlit id="22010007" name="Fixed slit 1/8°" xsi:type="fixedDivergenceSlitType">
				<distanceToSample unit="mm">220.00</distanceToSample>
				<height unit="mm">0.19</height>
			</divergenceSlit>
		</incidentBeamPath>
		<diffractedBeamPath>
			<radius unit="mm">320.00</radius>
			<sollerSlit id="21010002" name="Soller slits 0.04 rad.">
				<opening unit="rad">0.0400</opening>
			</sollerSlit>
			<receivingSlit id="22010001" name="Fixed slit 4°">
				<height unit="mm">5.88</height>
			</receivingSlit>
			<detector id="7010017" name="PIXcel3D 1x1 detector" xsi:type="areaDetectorType">
				<phd unit="%">
					<lowerLevel>30.0</lowerLevel>
					<upperLevel>70.0</upperLevel>
				</phd>
				<mode>Scanning</mode>
				<activeChannelsEquatorial>255</activeChannelsEquatorial>
				<activeChannelsAxial>255</activeChannelsAxial>
				<pitchEquatorial unit="mm">0.05500</pitchEquatorial>
				<pitchAxial unit="mm">0.05500</pitchAxial>
				<readOutPeriod unit="seconds">0.135</readOutPeriod>
			</detector>
		</diffractedBeamPath>
		<scan appendNumber="0" mode="Continuous" scanAxis="2Theta-Omega" status="Completed">
			<header>
				<startTimeStamp>2024-10-25T21:58:01+02:00</startTimeStamp>
				<endTimeStamp>2024-10-25T22:54:06+02:00</endTimeStamp>
				<author>
					<name>PRO-MRD</name>
				</author>
				<source>
					<applicationSoftware version="6.1b">Data Collector</applicationSoftware>
					<instrumentControlSoftware version="7.0E 20130304">XPERT-PRO</instrumentControlSoftware>
					<instrumentID>0000000011142674</instrumentID>
				</source>
			</header>
			<dataPoints>
				<positions axis="2Theta" unit="deg">
					<startPosition>9.99826193</startPosition>
					<endPosition>129.99755682</endPosition>
				</positions>
				<positions axis="Omega" unit="deg">
					<startPosition>4.99913096</startPosition>
					<endPosition>64.99877841</endPosition>
				</positions>
				<positions axis="Phi" unit="deg">
					<commonPosition>0.00</commonPosition>
				</positions>
				<positions axis="Chi" unit="deg">
					<commonPosition>0.00</commonPosition>
				</positions>
				<positions axis="X" unit="mm">
					<commonPosition>30.00</commonPosition>
				</positions>
				<positions axis="Y" unit="mm">
					<commonPosition>0.00</commonPosition>
				</positions>
				<positions axis="Z" unit="mm">
					<commonPosition>9.100</commonPosition>
				</positions>
				<commonCountingTime unit="seconds">32.895</commonCountingTime>
				<counts 408 391 351 384 391 401 397 390 421 367 379 363 415 341 406 419 373 390 411 367 367 372 420 385 384 450 415 385 402 386 374 397 402 398 395 394 412 402 408 344 357 385 387 415 400 388 414 383 395 402 400 358 362 396 415 386 410 364 414 396 405 347 351 392 387 398 375 357 342 408 355 359 409 374 406 368 408 385 370 360 400 380 345 411 411 349 384 359 393 411 393 399 411 399 357 355 378 348 366 401 364 348 385 358 367 360 368 377 362 383 352 334 355 357 384 370 399 387 382 378 348 377 375 391 354 352 346 341 365 396 347 369 372 365 348 370 366 362 389 337 363 325 391 368 378 404 382 386 348 363 360 390 341 376 393 337 333 352 348 390 364 350 340 370 360 354 344 350 336 375 339 341 337 336 360 384 354 355 384 344 366 353 386 361 355 344 342 374 330 400 384 389 331 355 318 348 335 337 326 347 361 325 356 330 340 364 374 334 361 365 359 351 343 359 359 356 322 340 326 312 324 341 370 327 361 349 353 350 349 362 369 353 365 346 363 324 331 349 319 377 336 350 332 338 333 302 312 332 348 350 320 351 332 325 347 345 336 341 326 327 366 313 395 347 341 366 344 333 324 335 321 319 365 342 311 356 353 362 318 353 330 341 325 354 319 346 333 355 328 329 348 337 331 338 339 358 334 346 364 340 343 345 310 340 335 343 338 324 330 318 354 344 340 325 359 292 320 333 320 365 334 311 354 317 320 326 356 339 315 324 304 302 313 305 331 338 318 325 316 318 338 326 303 339 352 358 313 326 297 308 289 316 302 353 306 335 341 319 294 288 321 308 322 302 331 323 357 296 312 316 317 328 315 341 354 311 297 293 281 281 299 298 333 305 335 293 355 304 316 312 304 332 319 324 314 298 333 321 349 337 336 314 332 314 315 326 335 315 344 331 286 304 302 323 302 333 318 285 315 316 300 305 310 303 313 335 301 303 309 283 299 319 327 309 335 303 315 313 295 306 301 307 336 297 296 340 288 306 294 300 327 331 281 293 306 320 330 316 305 280 314 311 302 298 290 279 308 303 306 291 310 309 309 281 275 270 324 302 273 300 283 300 330 311 269 321 313 299 299 281 279 303 315 298 267 306 298 281 285 287 306 261 291 297 303 292 283 310 304 301 273 298 293 289 312 314 315 280 330 313 310 274 320 282 318 272 314 307 301 293 275 311 304 281 300 297 281 298 300 301 301 291 278 308 307 272 294 322 260 292 268 279 277 308 282 284 312 285 293 304 286 261 284 279 268 316 274 279 301 291 291 308 267 291 307 273 293 285 313 281 270 299 274 311 269 300 302 305 291 303 307 304 287 293 299 288 282 270 290 299 287 286 290 271 277 324 309 271 285 295 262 293 288 276 293 307 266 288 286 283 267 273 311 286 268 275 264 265 283 287 283 322 267 296 300 301 294 307 277 273 302 301 279 299 269 267 276 279 271 309 318 287 269 281 280 284 265 277 272 286 292 271 274 286 281 276 279 260 283 265 268 289 298 266 288 283 250 271 279 270 284 259 286 294 278 270 297 287 257 267 290 285 305 231 309 285 275 273 280 275 318 291 264 321 268 273 296 294 289 293 243 256 273 286 271 270 267 272 287 281 273 264 274 287 284 289 282 264 282 286 322 267 302 275 292 299 279 263 295 311 250 294 297 306 299 293 281 273 272 268 286 289 320 266 277 263 269 241 293 306 264 288 281 301 305 264 283 292 279 303 287 291 275 294 304 249 267 255 286 255 280 281 274 269 257 317 295 272 295 285 279 270 302 293 275 273 242 266 259 295 271 295 285 276 272 264 276 246 287 293 291 247 283 307 285 279 275 292 262 277 265 271 241 289 295 294 268 265 274 279 260 281 248 287 273 283 305 284 279 295 328 277 300 287 271 271 266 298 272 262 304 274 268 314 273 299 274 262 285 308 293 298 305 282 319 280 284 282 275 272 282 272 293 275 277 283 242 310 282 295 272 290 268 241 262 278 283 286 314 255 281 287 289 248 255 267 284 295 292 306 315 303 291 266 320 268 286 258 303 302 270 284 284 293 285 277 292 283 288 281 277 315 294 296 280 276 292 285 299 317 281 274 273 296 285 257 309 266 316 304 284 245 240 273 283 275 315 303 274 297 285 300 287 287 297 303 301 284 322 313 294 276 296 262 256 296 285 283 305 248 284 264 290 280 319 296 270 299 274 308 281 256 266 281 300 277 249 290 279 318 297 278 276 289 260 294 290 291 309 297 310 265 293 305 276 269 243 270 312 294 299 292 312 292 286 277 267 308 324 313 294 297 282 270 291 312 280 266 340 306 295 289 265 303 287 297 292 310 286 272 308 293 307 305 286 291 259 282 263 301 291 246 283 286 249 291 294 274 286 260 285 312 278 287 257 307 284 309 306 275 284 307 305 286 290 299 298 325 287 288 287 302 284 262 311 323 320 293 273 302 296 276 290 298 289 281 304 300 297 283 319 268 287 295 319 309 281 279 286 307 328 281 272 295 288 291 323 309 286 296 300 293 279 278 281 293 297 256 273 302 290 295 308 283 305 278 305 284 317 284 268 293 262 314 262 271 290 283 271 292 306 305 304 284 297 325 288 331 295 283 306 289 280 299 289 282 278 270 277 322 277 318 284 287 293 298 313 315 256 311 298 297 316 302 302 273 304 282 282 291 277 285 281 275 282 272 291 303 282 272 278 305 300 294 283 340 295 288 284 298 274 313 278 290 295 271 268 336 314 293 312 318 325 310 248 315 276 270 280 328 299 282 279 285 279 276 268 286 296 303 314 288 275 290 274 281 301 298 327 289 301 321 276 270 299 314 310 299 293 292 308 295 295 262 305 294 285 247 308 293 278 315 285 290 298 286 302 284 303 307 303 320 282 309 296 307 314 247 307 301 308 291 285 291 286 315 291 313 279 309 346 320 293 287 301 271 304 284 295 303 287 290 307 278 287 289 277 281 311 269 269 300 295 307 283 292 298 294 319 308 314 305 290 259 307 258 278 314 283 321 293 293 291 306 308 280 295 300 271 293 260 283 297 300 273 284 295 296 272 318 265 284 303 272 282 301 274 284 273 302 273 276 302 256 272 277 293 304 279 285 289 261 276 306 265 267 297 289 320 278 289 281 292 316 263 279 277 263 291 274 288 256 284 285 294 302 275 307 230 290 281 294 297 298 283 241 306 259 273 277 291 314 317 277 295 263 303 267 273 273 331 290 287 271 277 274 291 295 293 277 297 284 292 276 255 296 295 270 268 242 276 299 298 283 294 290 285 305 298 267 228 281 264 288 256 271 277 270 309 261 283 290 259 273 249 285 306 281 269 269 280 268 265 312 268 299 284 259 272 283 294 297 257 282 268 289 281 294 246 280 246 267 262 277 258 286 300 280 264 266 303 278 275 264 271 274 278 302 273 281 277 248 257 294 278 285 264 292 266 286 276 276 281 276 240 268 269 257 296 267 276 279 271 304 264 288 285 266 274 267 249 269 284 288 276 290 280 284 270 279 228 283 285 240 272 276 232 235 271 308 283 292 250 258 264 259 261 264 283 262 272 280 269 240 273 263 279 260 301 283 268 262 277 291 289 277 272 280 289 260 260 275 270 273 241 226 255 262 280 268 271 277 267 280 232 258 270 264 263 279 301 233 265 269 238 285 256 270 248 274 269 255 255 255 298 267 257 279 271 290 244 237 275 259 264 261 228 248 261 256 239 267 265 273 258 246 255 225 241 286 231 229 263 258 246 237 247 247 234 246 237 237 283 262 224 258 244 261 243 208 247 274 222 265 229 235 269 243 286 267 241 228 270 237 263 240 300 229 285 242 285 249 227 238 249 264 259 221 258 265 238 235 244 240 243 271 263 217 284 264 240 275 272 240 256 261 265 256 257 241 241 242 255 273 233 270 266 268 231 277 246 240 261 224 277 219 264 271 241 215 262 246 273 234 244 238 258 248 279 265 256 232 230 235 237 270 231 258 268 226 258 270 228 278 269 246 232 258 232 234 234 224 224 260 264 258 224 226 236 248 260 217 248 275 237 213 242 237 228 266 264 235 257 241 271 228 266 223 282 274 272 273 241 261 278 218 233 255 241 231 227 228 242 229 257 232 256 235 257 275 248 269 261 239 235 246 283 247 263 242 239 229 258 223 230 236 235 209 246 213 226 233 242 260 246 282 245 225 226 230 216 221 221 227 243 213 222 248 227 231 261 263 231 249 247 230 219 228 256 269 236 265 231 273 222 278 267 241 269 230 228 232 216 236 246 238 256 223 224 223 237 222 212 259 205 264 225 266 242 246 245 247 234 229 250 256 266 247 231 241 239 245 247 225 210 269 225 262 284 275 225 247 214 263 248 242 234 231 225 244 221 245 217 246 224 238 263 240 234 224 240 239 219 214 234 212 228 201 241 245 222 256 234 216 217 235 231 248 215 240 246 238 243 255 220 228 237 239 224 200 238 211 211 207 242 263 262 219 250 248 221 248 214 258 246 216 223 219 224 241 244 239 262 232 245 235 235 216 216 196 239 239 234 231 193 238 217 232 216 221 267 240 229 257 256 211 230 210 235 229 245 239 224 258 230 239 235 239 245 215 214 236 208 225 197 220 208 241 210 238 245 236 231 224 222 223 218 220 242 240 216 238 214 230 230 189 234 230 232 221 219 217 245 243 232 230 196 227 213 229 233 221 222 230 227 211 205 219 258 219 227 235 217 232 255 222 231 229 229 210 205 243 210 217 194 227 226 238 224 234 228 233 220 205 214 238 218 219 222 243 255 224 258 208 234 224 268 241 255 244 270 237 246 212 211 223 203 203 219 261 245 227 207 255 234 238 229 236 272 234 222 211 266 213 247 228 234 240 211 223 232 213 231 247 236 208 228 226 236 241 240 220 243 219 201 243 207 229 216 210 223 246 232 220 205 235 197 201 222 209 243 272 233 226 234 221 227 224 228 224 233 257 222 212 232 205 232 232 208 223 234 222 228 227 222 201 196 218 217 219 250 228 212 260 213 208 206 219 233 237 213 220 215 204 210 194 236 237 196 226 223 235 187 224 212 247 234 239 222 221 214 233 220 227 200 208 218 238 213 231 263 211 205 229 212 242 199 222 231 210 239 230 206 198 216 217 228 239 219 226 228 219 232 231 209 236 225 236 240 204 224 201 232 200 178 259 208 234 206 239 239 217 243 230 228 216 240 215 210 207 226 178 218 209 223 231 220 241 230 224 260 232 205 221 216 229 224 204 225 246 241 229 216 210 173 204 218 212 208 241 185 241 231 202 214 218 235 236 209 212 214 182 216 202 202 212 233 228 198 193 224 225 261 213 181 236 206 217 229 222 245 210 224 203 235 228 228 214 200 244 221 198 204 237 225 217 237 242 232 217 195 189 211 231 210 210 233 239 235 227 214 219 229 218 228 212 214 216 214 199 199 214 247 226 229 206 243 232 214 224 234 219 212 232 216 215 208 227 201 216 234 222 203 226 185 190 227 227 216 208 229 205 214 217 235 209 219 194 249 218 225 224 206 248 220 221 232 203 231 231 222 202 211 188 227 218 219 227 218 216 237 238 207 239 216 213 224 211 205 223 228 236 222 183 234 233 230 194 217 190 204 199 204 210 229 226 213 236 235 221 221 207 241 194 223 217 199 210 204 188 212 207 255 189 226 221 222 224 214 225 245 225 232 214 199 238 214 221 201 219 221 196 199 217 226 222 208 217 211 214 213 204 197 231 208 179 222 195 205 218 170 224 225 205 223 186 231 214 220 223 205 214 208 209 217 201 219 207 228 215 214 177 192 222 212 219 222 215 223 213 239 208 236 204 218 238 213 228 226 219 198 197 193 224 191 226 217 225 222 223 193 218 225 208 219 205 240 201 216 224 186 211 218 185 245 227 240 218 218 231 200 210 217 219 204 222 194 201 222 204 210 197 201 226 216 201 222 220 220 201 232 199 225 217 206 200 214 222 206 202 203 229 213 215 220 239 206 197 187 239 231 182 240 201 186 219 214 201 212 207 227 220 224 236 216 222 232 203 205 206 215 218 225 184 238 189 216 224 215 233 238 211 216 209 204 230 224 189 223 213 204 218 205 215 211 201 220 197 216 195 228 229 210 212 267 201 197 225 204 231 208 212 211 227 270 211 234 242 225 238 219 241 238 221 261 206 230 257 235 258 221 231 275 225 238 212 203 228 224 219 236 215 231 192 203 231 217 228 200 196 228 235 236 227 228 209 202 208 223 249 222 224 213 237 202 210 223 210 212 223 223 228 191 221 224 212 202 206 186 218 196 182 228 236 204 243 199 187 199 203 222 218 203 238 205 230 187 203 225 209 215 214 212 198 220 195 190 197 200 196 199 194 220 203 211 196 220 191 240 220 234 184 207 210 197 161 219 214 192 198 218 194 226 219 193 219 220 209 195 206 200 209 214 203 215 203 206 203 228 236 199 194 209 208 206 240 201 211 208 209 206 198 203 212 228 209 211 216 214 217 211 205 194 195 222 220 198 208 193 198 229 199 227 193 216 221 210 240 217 229 198 218 231 222 198 224 219 204 217 205 223 194 225 235 236 216 191 197 230 196 211 222 205 228 219 206 226 218 227 241 240 246 195 204 193 203 224 217 217 203 219 215 209 211 184 219 217 215 213 203 220 214 209 191 199 212 206 219 232 200 192 186 184 209 214 205 194 216 199 223 213 199 231 225 212 209 221 213 198 225 219 205 186 184 209 193 192 192 197 176 194 209 210 215 194 193 223 193 198 214 212 209 172 208 200 216 240 229 225 206 213 216 209 214 209 228 214 214 198 212 201 217 233 220 197 233 196 210 226 202 203 203 230 222 200 211 203 229 194 210 227 223 223 220 184 217 201 192 217 226 208 222 233 216 230 231 197 218 211 228 210 188 209 208 195 220 197 209 207 224 190 241 224 211 197 196 233 203 205 218 222 207 204 232 215 220 188 231 194 205 207 214 219 201 192 182 218 209 207 238 210 217 196 201 241 187 215 224 231 205 202 234 196 219 209 206 201 208 202 201 201 219 200 215 230 207 207 215 210 210 200 216 208 193 208 240 224 228 187 198 217 205 204 213 223 207 234 223 207 199 182 216 216 227 230 208 218 190 228 234 215 213 191 185 211 207 220 232 204 215 231 217 215 218 232 214 188 217 206 212 203 216 182 200 234 228 219 195 225 216 216 223 195 217 216 207 223 207 209 216 213 206 201 226 229 217 199 202 213 230 202 239 211 204 217 196 232 228 198 216 218 214 222 212 216 228 233 211 228 205 228 198 212 230 219 231 229 217 196 231 199 217 202 206 208 197 220 203 208 208 262 225 209 215 200 236 236 219 229 222 229 216 214 224 214 230 223 201 227 223 239 189 218 202 205 229 193 227 214 210 230 215 248 230 223 257 217 208 213 193 255 226 203 212 199 236 219 213 213 222 192 228 223 267 209 222 224 209 194 228 200 229 207 200 204 233 215 208 237 209 207 224 208 218 206 241 218 221 204 230 209 212 219 216 232 198 225 205 193 229 257 234 246 213 203 231 225 255 220 224 209 202 198 227 211 233 227 214 219 239 213 203 228 227 218 222 222 204 210 194 221 220 224 211 209 220 248 225 217 216 219 232 211 222 235 226 219 230 269 209 225 237 200 219 233 206 219 227 249 217 264 225 220 221 217 213 223 208 216 221 219 216 244 228 206 230 214 246 224 222 220 232 255 239 245 236 208 270 231 201 227 242 248 257 274 237 267 262 263 235 257 233 239 273 256 279 244 268 224 256 241 289 237 257 249 274 278 281 239 299 291 275 294 284 301 302 291 295 314 293 299 339 336 327 333 325 319 392 362 390 359 359 420 373 421 370 393 353 379 397 350 385 399 357 386 389 364 336 327 328 355 339 347 350 331 274 318 300 301 288 261 296 264 292 281 287 277 288 243 249 275 242 223 257 230 231 278 259 234 205 269 244 274 226 219 235 246 216 228 243 228 225 234 208 226 219 236 214 226 244 249 221 249 229 231 206 223 211 223 240 213 224 216 235 220 223 245 206 211 230 232 235 242 236 206 210 234 207 202 208 227 183 215 214 230 232 262 214 234 228 237 205 219 200 219 236 179 196 238 207 207 203 220 208 211 217 218 221 198 192 214 214 220 235 227 203 238 203 221 225 195 207 218 228 230 219 190 219 208 216 217 222 240 228 231 217 186 222 196 218 179 236 221 212 221 205 203 243 223 216 204 213 237 209 223 216 225 231 186 223 241 214 219 233 206 225 199 228 210 229 259 205 190 206 208 201 224 210 220 210 239 209 216 191 237 223 221 227 219 209 226 219 223 242 240 213 218 211 229 199 236 205 201 220 216 218 222 206 207 232 214 211 217 210 222 218 233 209 229 234 216 206 230 198 218 220 243 220 201 220 200 202 208 215 195 217 203 218 212 210 256 242 198 196 227 209 224 217 234 230 220 228 226 220 221 203 183 200 195 231 219 219 202 223 193 210 227 183 206 227 227 236 219 226 220 216 209 212 222 207 184 236 207 219 199 206 210 214 248 204 204 215 222 222 214 201 213 218 221 208 222 227 217 222 203 227 213 238 225 203 213 226 217 213 235 227 221 246 220 223 194 210 190 191 208 208 210 224 206 196 188 232 232 218 180 202 237 215 226 228 217 222 218 212 238 231 182 244 248 206 223 211 218 220 236 216 212 246 205 210 225 241 196 257 204 227 219 229 212 216 204 244 202 226 212 186 199 201 232 221 202 201 197 204 221 231 199 224 236 219 238 217 209 186 209 213 225 213 221 208 226 201 214 207 198 223 188 240 258 226 176 195 216 238 218 225 233 217 232 207 205 227 230 198 238 216 218 215 234 181 223 223 231 203 228 201 226 239 216 211 210 220 217 240 212 257 230 197 220 221 214 230 218 234 227 216 259 223 219 203 225 240 211 203 235 236 226 200 190 210 214 194 244 216 245 203 234 213 193 211 245 229 227 238 205 236 206 219 243 240 238 215 203 219 224 199 210 216 211 227 188 218 229 217 245 247 213 232 240 205 234 238 220 215 228 239 180 208 217 212 217 248 219 229 224 207 241 225 224 220 198 220 222 235 230 224 215 219 235 235 217 233 222 213 237 216 187 227 212 237 219 229 229 239 215 214 212 219 198 209 225 229 228 233 232 222 207 193 203 219 203 196 220 218 224 219 229 194 229 223 205 232 205 228 235 229 217 212 226 209 225 208 214 247 212 204 214 245 244 216 220 221 228 214 234 232 246 214 213 234 222 222 233 226 224 198 220 217 217 235 206 194 219 229 198 213 224 226 218 235 215 226 216 224 200 239 225 211 217 216 245 223 194 203 184 224 200 227 222 230 209 225 232 225 218 240 226 192 183 201 223 214 221 200 214 213 226 224 198 237 199 215 226 191 232 237 230 204 226 208 227 223 216 238 249 220 223 221 239 211 235 196 184 225 201 201 235 219 214 232 214 228 221 220 242 201 214 232 208 237 206 238 232 243 194 196 235 213 215 235 234 238 230 193 221 204 220 224 221 219 225 204 222 228 221 243 216 227 230 192 200 222 203 203 240 224 218 217 205 229 214 190 236 200 217 216 243 218 194 207 213 218 207 197 230 213 227 203 188 222 222 220 214 239 218 211 217 223 232 243 248 238 260 220 259 210 216 198 206 228 188 258 239 204 211 231 216 250 238 228 223 217 214 224 210 200 227 194 220 192 211 218 244 243 203 195 228 210 263 203 243 248 234 214 210 230 207 179 211 205 200 226 224 210 205 203 226 216 234 204 197 216 217 223 241 211 215 206 245 193 191 202 219 227 246 199 236 226 239 210 227 234 215 199 240 207 216 226 220 193 223 193 232 223 210 206 221 204 236 216 208 235 225 228 222 221 214 215 214 233 246 222 223 234 248 255 229 225 214 220 248 224 215 224 214 232 223 233 218 176 193 265 199 208 228 224 239 202 200 240 222 238 224 227 229 274 226 239 240 223 217 195 229 207 228 231 198 228 226 232 198 223 215 211 210 209 214 209 207 207 241 232 208 245 247 196 263 224 224 212 222 204 191 257 238 238 241 226 218 217 213 223 222 229 221 213 221 218 222 220 224 216 225 224 226 225 212 257 207 227 205 201 227 226 214 214 226 215 221 234 203 262 233 233 201 211 237 231 256 255 228 217 219 222 210 227 215 212 218 234 238 218 227 204 214 203 223 220 248 231 222 199 229 230 202 231 225 229 195 247 234 240 234 229 233 223 191 218 236 201 239 225 227 219 216 208 203 226 203 212 239 197 213 238 236 208 237 214 221 220 222 216 235 238 237 238 207 236 229 214 181 206 239 195 210 257 207 223 230 257 221 209 216 237 213 215 216 226 234 232 215 205 218 192 205 202 228 243 216 218 220 216 221 244 202 223 234 210 215 234 224 194 217 203 197 186 244 213 210 214 225 215 208 213 211 213 217 212 219 221 199 228 205 246 223 207 255 188 223 210 229 214 235 210 206 212 262 212 216 216 243 227 240 239 239 219 237 216 215 208 240 221 226 231 218 199 204 229 219 222 225 217 237 234 237 195 226 230 201 233 238 228 234 210 233 224 241 229 216 230 233 214 228 202 249 236 246 199 269 202 201 210 198 247 224 217 207 192 239 221 226 244 220 222 232 211 233 234 220 239 231 215 232 212 199 215 255 203 224 220 211 213 217 215 222 214 226 187 238 228 220 239 242 196 230 221 215 230 211 193 221 214 216 225 215 224 228 225 255 237 255 205 194 221 271 218 233 229 239 233 224 222 198 184 220 200 222 237 188 225 220 215 229 224 200 207 226 223 239 208 237 209 213 210 207 233 223 249 214 260 222 227 206 217 224 215 207 207 190 214 208 215 209 208 203 220 221 216 218 197 207 224 233 208 238 220 204 221 225 218 231 232 246 246 213 227 222 233 239 241 223 221 202 234 199 199 228 237 231 211 237 217 213 216 214 214 209 218 225 235 188 215 226 210 204 247 242 266 230 220 217 232 202 238 233 224 231 227 227 204 222 203 211 210 218 244 211 191 224 237 224 223 214 230 220 228 212 239 225 244 233 244 229 223 223 236 206 186 215 201 224 229 210 262 242 205 237 221 232 245 208 229 219 199 219 215 215 264 216 213 247 227 231 281 213 235 206 262 266 212 234 231 240 238 223 201 217 204 225 182 215 231 204 208 255 199 199 230 248 235 229 201 223 220 226 213 207 205 233 227 229 235 210 235 201 225 230 206 248 222 217 204 211 202 224 195 223 240 227 203 208 224 233 215 227 215 259 227 233 222 235 234 214 221 205 247 241 224 207 226 218 219 208 240 234 224 223 219 242 231 226 247 243 217 202 215 234 239 198 212 199 207 220 248 205 243 226 228 239 226 232 206 198 236 214 216 220 232 205 227 212 213 241 210 236 217 237 205 213 209 265 220 213 238 235 229 232 229 257 246 233 239 223 220 235 238 219 219 220 241 238 233 220 224 222 222 195 225 209 207 229 237 205 216 227 218 236 206 221 205 194 259 207 216 234 212 249 198 181 236 223 193 220 221 201 227 227 218 224 216 204 229 231 280 207 218 224 271 240 226 221 216 215 256 226 218 240 206 243 244 235 228 209 220 226 248 217 245 238 207 225 218 229 239 222 239 227 244 225 225 245 235 196 211 207 261 244 221 249 231 266 213 229 249 207 215 231 233 232 215 214 225 211 201 241 220 216 209 224 193 202 204 207 213 207 231 239 232 211 223 234 230 255 227 243 233 230 217 240 216 221 265 221 212 208 228 242 219 222 242 235 240 224 236 206 199 201 202 246 250 221 221 259 209 245 235 192 203 232 207 225 200 215 197 221 219 206 235 215 235 224 208 233 199 237 206 224 242 232 241 239 213 235 258 229 272 235 213 232 217 233 220 255 208 213 235 243 224 216 221 203 219 232 231 225 215 226 218 221 222 204 201 238 266 241 229 210 219 223 224 235 235 225 206 221 223 208 213 241 226 220 209 243 260 214 226 201 218 221 248 233 230 219 187 220 229 223 248 207 213 234 202 246 216 246 258 211 242 193 226 225 213 218 221 221 220 215 241 263 236 230 205 214 223 255 220 238 229 256 246 200 225 214 200 243 205 228 235 221 239 219 228 216 215 217 225 246 244 222 232 219 220 217 227 228 197 234 267 235 238 225 243 247 215 247 219 228 219 250 220 212 216 235 218 201 234 203 231 267 222 223 207 231 228 214 240 228 219 262 216 237 231 228 220 249 231 232 225 210 235 209 229 220 202 226 236 240 218 229 265 213 222 259 260 201 220 269 217 231 221 230 226 199 217 226 203 272 228 228 229 229 222 219 260 232 233 258 231 228 222 262 224 225 243 260 234 227 222 214 236 238 214 233 257 255 229 238 257 256 210 271 269 244 214 231 215 224 212 244 232 218 239 239 231 230 250 233 224 240 235 245 224 215 249 243 248 224 240 233 257 278 226 248 223 283 213 234 249 231 248 244 231 272 230 246 217 239 223 240 249 227 232 240 234 248 242 209 272 255 233 234 209 284 226 218 242 258 255 226 273 231 215 239 258 224 210 255 233 212 222 227 217 231 264 221 298 227 236 222 229 240 209 222 221 226 215 232 220 214 225 233 214 225 244 241 244 241 212 232 225 232 212 232 238 234 226 233 220 246 239 242 237 214 243 224 239 267 207 247 259 218 225 204 203 229 227 269 223 218 265 244 226 226 262 258 234 230 267 257 228 223 204 241 233 268 203 217 212 245 227 241 237 202 231 232 243 247 242 220 200 248 262 224 225 221 233 233 227 204 210 217 212 233 227 259 234 212 237 227 241 212 251 220 234 218 261 223 247 257 212 241 221 223 222 216 226 211 269 218 237 222 213 225 206 211 245 237 238 206 212 218 220 223 217 236 211 267 238 214 239 228 240 232 218 231 238 244 243 230 223 244 257 247 239 234 230 223 218 206 225 227 226 231 266 216 208 218 226 203 231 204 217 230 210 230 195 234 220 207 227 231 234 224 259 205 217 219 218 245 189 236 212 220 208 248 234 234 245 236 227 229 211 214 241 249 216 222 243 211 230 244 259 246 226 206 214 208 205 246 208 242 229 226 222 215 204 243 202 227 236 221 230 237 212 245 256 226 242 231 211 211 226 216 234 231 198 194 270 243 242 233 233 231 224 203 218 226 247 238 240 245 242 221 228 214 227 205 229 212 205 234 206 216 232 221 226 232 216 245 227 221 257 225 208 239 237 222 245 240 212 230 201 269 220 241 238 199 233 205 233 226 236 213 212 235 229 216 216 242 239 205 220 217 213 235 236 218 246 226 226 219 200 244 218 228 263 213 198 238 231 225 248 216 243 243 241 210 213 220 210 224 216 211 233 240 246 208 259 205 220 241 212 235 212 225 220 201 238 238 222 228 246 214 240 211 198 212 242 234 222 242 214 230 260 237 208 233 226 219 223 223 218 217 232 239 212 217 231 221 250 236 209 262 234 205 242 237 231 263 259 233 225 209 243 212 240 261 218 230 239 221 215 234 247 231 208 225 245 210 230 235 241 255 247 260 221 223 241 271 209 261 226 224 213 232 221 242 215 241 245 245 249 271 194 218 233 242 207 229 215 197 217 231 228 229 211 258 218 211 246 194 223 219 270 214 225 220 231 239 246 215 222 216 234 220 216 246 209 240 233 211 220 228 215 229 208 219 213 263 261 231 220 236 219 228 228 256 237 207 215 220 218 242 240 235 209 238 255 219 202 238 221 202 221 202 229 218 230 235 223 240 246 234 236 230 220 266 230 234 229 223 222 201 220 200 241 190 224 217 237 264 226 277 244 249 234 211 222 241 214 222 217 217 206 203 240 207 222 220 204 224 243 214 228 229 217 246 230 222 204 245 214 256 215 198 274 225 232 221 218 226 216 225 236 208 193 257 238 218 236 207 232 245 230 244 229 231 231 226 227 241 221 237 210 236 215 230 236 222 230 223 221 218 239 205 241 263 246 216 265 219 223 194 210 221 205 218 245 215 263 215 239 228 222 264 214 226 238 215 220 234 230 233 236 248 243 238 216 232 233 217 234 261 191 219 203 244 219 204 242 227 224 212 226 214 224 255 258 227 205 216 245 206 228 216 232 238 214 220 213 257 228 218 239 223 234 211 233 240 206 220 228 229 233 234 232 245 226 235 233 223 223 247 218 203 227 232 238 222 230 233 230 243 226 246 262 244 234 237 242 221 233 231 227 223 230 237 216 233 208 245 218 209 250 226 217 213 233 235 238 256 255 268 244 226 225 219 262 220 233 211 249 211 244 220 224 233 241 223 229 241 235 226 215 213 229 241 209 259 258 243 212 269 205 219 247 255 266 220 220 220 212 222 249 234 235 223 260 219 231 226 204 245 215 236 239 261 265 243 211 243 223 236 237 222 232 227 227 234 239 226 206 242 231 222 225 211 213 225 236 224 237 196 257 201 220 218 176 263 249 224 235 211 269 219 228 220 236 234 233 244 249 221 268 237 236 243 239 256 231 207 211 223 235 241 230 224 248 222 232 225 218 242 236 243 242 228 268 256 240 240 229 219 241 258 236 216 207 217 258 237 221 232 240 263 237 242 223 246 216 232 227 216 219 205 237 275 228 214 237 231 222 233 217 237 229 240 234 239 206 261 222 265 207 248 217 256 202 247 228 221 241 241 225 231 223 231 229 221 265 224 235 229 239 213 262 238 234 200 219 242 223 230 263 232 247 279 224 225 271 218 215 244 220 238 234 215 268 233 239 220 231 237 235 210 219 220 274 235 239 264 218 228 240 239 202 220 227 199 224 226 206 202 222 227 228 238 228 223 230 223 243 226 230 200 228 248 222 202 236 236 234 224 228 250 206 241 240 225 226 232 239 257 278 228 218 208 232 255 238 225 219 203 205 227 248 238 226 235 267 217 227 259 228 260 237 224 245 247 249 241 237 233 220 238 239 219 237 235 223 231 260 233 255 245 234 224 240 262 240 245 234 205 228 242 206 225 274 260 240 222 207 233 230 227 224 225 211 245 242 216 211 240 235 222 248 225 249 271 234 227 240 236 269 228 258 226 215 228 224 245 241 225 240 257 222 215 230 217 228 229 243 237 215 246 210 243 246 216 229 202 233 241 256 237 241 238 216 257 238 248 207 239 235 205 245 227 231 264 223 210 268 203 261 255 238 230 218 248 266 245 223 256 226 220 240 235 271 244 239 223 234 222 214 230 258 243 255 220 232 248 230 229 224 224 234 286 265 238 221 222 239 232 236 235 261 263 264 227 230 249 270 217 276 257 243 247 242 242 255 238 222 249 234 234 222 232 269 226 233 257 224 213 230 218 269 238 234 262 244 232 209 229 210 223 203 265 237 267 239 218 234 240 245 219 237 221 236 247 230 255 263 245 248 230 239 239 212 236 256 256 236 236 238 238 195 255 233 257 219 219 247 248 222 225 223 204 241 276 236 264 255 228 233 221 242 257 231 257 223 256 245 286 275 239 267 264 241 244 220 228 241 232 234 212 247 228 248 218 242 229 215 242 218 271 231 194 244 270 266 243 234 228 221 259 228 247 218 239 267 232 246 257 259 257 232 248 247 256 247 263 228 239 228 260 245 236 244 247 231 257 234 207 244 216 243 244 234 262 238 225 250 225 213 223 231 234 228 227 256 226 216 228 233 222 261 269 247 236 255 245 242 228 241 223 236 256 227 245 218 242 247 256 234 236 233 213 220 231 229 236 216 245 242 224 229 229 230 238 238 245 240 230 229 248 236 277 203 264 258 235 219 246 257 229 241 218 219 230 267 226 234 256 257 263 245 219 232 245 230 238 260 223 233 223 233 255 271 237 238 262 217 244 278 234 223 239 250 249 248 184 241 233 241 217 246 235 226 237 249 239 239 226 229 230 227 233 220 207 234 261 256 280 231 230 248 235 276 236 235 239 268 258 228 219 220 236 233 236 243 236 248 215 249 204 249 215 255 220 250 249 226 232 232 242 260 241 284 216 235 237 240 226 262 209 247 240 239 237 263 202 238 215 261 236 227 265 263 246 234 246 231 233 260 222 230 258 264 249 250 243 241 249 210 242 260 246 223 230 237 213 255 263 265 234 263 256 243 234 248 235 235 263 222 229 236 221 239 268 204 230 227 236 232 243 222 243 245 295 230 234 246 232 249 244 255 237 245 256 257 247 222 230 234 212 238 238 246 250 213 271 255 257 217 227 222 225 272 219 220 229 258 270 247 259 229 217 232 213 240 237 255 201 233 234 256 236 214 241 233 242 257 232 249 245 227 256 256 243 224 246 231 257 244 231 244 242 261 238 260 248 229 225 244 268 246 239 222 257 231 212 212 230 257 239 236 260 235 233 281 256 270 239 248 246 265 283 256 282 248 256 270 249 280 261 265 260 244 233 245 236 225 283 259 226 274 274 241 270 273 266 246 247 272 267 277 274 242 279 267 243 273 280 280 259 270 243 282 238 286 266 248 274 276 268 291 277 272 278 266 276 301 291 273 278 266 288 261 267 277 243 282 285 260 233 279 267 237 275 275 273 234 244 257 263 261 236 282 269 263 262 276 247 231 261 257 239 276 256 255 256 238 265 274 257 240 239 269 246 227 256 238 269 262 236 228 257 238 276 296 241 247 230 221 234 258 236 225 260 226 222 256 237 226 262 232 214 220 240 239 240 242 237 239 266 234 276 231 235 245 285 267 231 239 194 246 245 239 231 250 258 266 248 227 255 241 241 242 219 219 220 242 234 221 272 215 279 227 224 243 243 226 243 235 244 234 255 249 246 239 235 231 245 227 243 273 216 248 241 241 240 256 239 249 229 244 228 237 220 228 241 248 218 234 255 236 217 237 248 219 237 261 243 247 250 262 263 216 236 241 242 221 205 268 291 248 249 237 258 248 218 216 227 229 238 210 267 220 230 244 240 233 223 233 269 220 255 234 240 223 244 220 223 214 237 225 221 219 238 255 244 244 215 243 265 234 227 226 223 222 247 224 270 226 226 228 239 248 228 237 223 196 234 234 221 230 239 209 226 224 236 224 228 223 202 229 274 231 232 277 215 237 220 227 218 247 226 217 185 196 228 246 242 213 210 226 217 237 261 234 216 245 263 242 260 204 242 240 259 208 234 239 225 266 244 232 228 206 245 238 241 241 206 222 237 233 215 236 237 246 244 263 216 235 235 216 242 246 218 241 241 265 243 199 233 205 236 249 218 245 196 256 235 240 233 232 231 233 216 221 222 238 215 227 221 215 219 241 224 216 223 238 270 192 226 240 223 214 212 226 244 226 212 247 218 265 221 230 209 249 208 259 241 209 225 214 239 239 240 217 247 217 244 238 223 228 187 208 226 238 214 242 232 239 209 221 226 228 207 218 233 230 238 264 221 225 214 221 235 241 243 215 245 255 246 229 238 247 225 229 225 215 226 207 222 243 226 221 241 249 235 225 220 249 225 234 216 228 238 224 268 213 218 197 245 225 209 226 223 228 201 209 221 234 238 236 229 219 230 204 233 233 236 207 220 273 203 228 214 229 266 239 249 227 230 240 241 244 217 226 215 234 226 216 218 226 229 223 249 264 227 217 227 257 223 214 236 223 225 257 224 240 241 215 218 229 205 220 240 244 249 211 216 240 199 215 222 221 244 215 245 210 246 222 208 237 234 220 195 237 227 203 216 231 221 259 227 246 227 239 245 226 235 261 229 266 240 228 237 209 214 215 241 210 233 223 225 220 220 213 255 223 243 226 244 243 215 220 225 250 227 228 230 243 230 225 246 220 213 236 228 221 237 226 239 221 232 257 228 220 212 258 224 208 221 227 242 255 219 208 241 226 257 225 224 229 222 241 211 224 203 200 237 245 207 232 228 234 218 239 232 227 222 223 240 270 241 235 236 236 238 224 247 215 218 243 215 235 233 231 225 211 203 241 215 237 197 222 236 234 227 239 242 218 228 230 246 259 219 199 237 223 243 240 240 230 229 204 259 185 233 242 207 233 221 255 230 216 243 239 225 185 263 240 200 237 212 237 232 211 223 221 197 222 204 223 257 226 234 192 196 237 241 243 241 227 192 220 240 198 261 211 226 239 224 201 243 210 223 247 224 225 230 216 207 232 259 217 207 220 227 240 207 236 268 215 229 223 214 208 235 218 230 227 218 233 238 197 224 202 236 197 205 208 213 220 198 231 210 249 250 214 239 196 239 227 198 195 210 231 212 243 234 239 210 234 215 187 221 225 213 232 220 235 221 240 244 243 223 259 235 224 237 247 215 240 240 224 228 240 255 249 241 244 212 233 222 247 217 198 193 242 212 218 197 247 228 235 242 230 228 232 229 214 233 263 223 257 237 237 250 225 225 205 216 210 243 257 218 229 257 202 207 225 215 199 213 232 227 239 222 247 226 200 234 213 207 216 210 230 244 259 209 228 261 248 225 248 238 244 243 204 246 212 219 217 230 232 246 229 275 230 224 248 215 227 256 241 205 211 203 241 217 209 275 224 235 233 229 231 225 235 226 225 231 239 231 268 233 219 240 214 259 233 239 228 222 217 225 231 235 228 256 236 212 198 207 217 235 232 246 214 247 212 214 210 208 207 239 227 222 229 267 225 217 211 231 207 239 228 205 229 233 276 224 247 237 206 229 220 207 208 248 213 197 224 219 209 221 220 227 222 248 244 213 242 243 227 233 247 228 230 219 248 219 225 202 236 256 205 223 239 258 245 220 226 234 239 229 248 267 228 258 233 220 219 268 246 265 223 242 226 237 240 222 226 201 244 192 235 225 226 220 208 221 214 237 264 216 214 262 223 236 185 238 226 222 229 221 242 220 242 244 212 233 237 245 216 265 200 245 219 241 216 233 237 238 227 229 235 247 200 223 230 232 208 234 230 225 236 220 220 269 259 234 231 203 243 215 213 219 243 210 230 213 218 273 246 224 240 248 235 217 226 218 228 231 208 235 213 248 222 218 204 240 259 231 222 229 218 222 230 235 212 240 249 238 213 223 245 228 244 258 216 240 217 244 243 214 218 237 230 240 204 233 221 214 235 206 206 238 224 219 222 233 241 222 242 227 214 244 216 232 239 213 245 241 241 197 224 244 240 207 234 249 233 212 231 240 238 194 235 255 208 238 212 235 216 223 213 235 227 241 231 219 243 200 217 235 220 201 225 256 238 239 244 225 218 242 219 225 274 230 238 227 240 231 225 239 234 224 243 234 258 218 228 212 249 231 240 233 206 233 221 242 242 217 244 207 225 221 237 233 200 230 197 213 203 231 229 229 243 233 228 233 214 225 217 209 246 243 229 238 229 221 231 250 237 235 242 197 207 233 236 227 231 206 189 233 235 225 229 236 237 286 234 230 260 262 256 244 267 228 220 213 237 231 216 231 232 194 212 240 228 221 239 246 219 217 204 220 228 229 218 232 209 224 215 220 238 224 208 234 227 208 233 233 260 232 237 236 227 226 235 188 244 249 233 217 220 215 242 227 230 234 242 211 209 217 236 233 237 226 246 273 236 227 214 235 236 233 232 224 245 235 260 219 237 203 239 239 232 235 275 245 207 218 232 217 246 229 231 212 222 222 231 222 221 225 223 216 259 222 213 208 211 241 224 211 227 248 239 227 246 220 209 197 237 227 228 223 224 216 240 216 228 215 235 234 201 249 231 205 203 217 238 215 227 236 207 229 256 234 234 200 221 237 220 226 219 263 242 236 228 245 216 209 220 266 230 238 239 237 245 234 268 264 225 228 245 229 234 236 225 197 198 224 237 219 224 229 218 240 230 214 232 234 212 204 239 222 233 210 233 249 255 212 214 249 242 257 231 213 272 214 249 240 247 258 236 217 244 222 248 234 222 214 233 214 228 216 230 227 218 255 246 238 222 221 229 235 242 240 220 255 244 189 223 234 218 226 217 241 236 231 218 233 245 228 214 237 211 249 235 226 240 231 224 233 227 262 219 232 240 233 238 243 205 217 222 238 235 231 216 226 257 234 212 225 245 226 229 210 219 230 239 229 243 234 206 207 244 227 245 247 219 226 249 231 237 216 238 197 224 199 229 236 265 213 213 243 260 241 272 233 223 234 221 218 234 215 238 255 224 233 233 241 260 240 264 229 225 237 215 219 231 235 212 243 211 250 227 229 240 229 234 229 228 242 227 232 215 217 237 233 226 234 230 223 235 209 245 210 239 230 270 229 212 255 237 220 224 213 237 222 224 257 239 230 231 249 245 246 242 234 235 223 241 260 255 248 242 221 207 225 242 217 236 256 257 241 233 233 229 228 233 271 278 234 221 235 245 238 258 232 262 260 285 242 238 245 261 255 278 230 235 245 257 237 244 239 258 225 247 223 233 234 225 244 239 257 214 204 264 212 212 269 259 276 244 226 219 249 247 224 249 241 245 240 230 276 226 225 234 240 224 220 242 258 255 240 266 206 258 243 223 248 230 233 248 239 231 249 249 240 234 240 233 221 259 241 248 225 221 231 231 228 234 223 246 233 218 260 245 232 249 230 237 224 238 217 224 245 203 260 225 262 234 234 224 235 247 239 226 244 249 216 214 211 237 242 235 249 225 239 219 234 246 208 242 222 238 259 248 218 221 245 228 244 230 247 220 225 247 243 283 231 241 224 234 230 202 227 261 242 255 223 247 221 238 234 226 236 241 260 237 244 219 227 239 227 211 238 213 225 241 238 243 236 221 245 245 223 231 217 196 247 245 215 262 213 236 235 242 228 246 230 230 215 212 241 218 214 233 218 215 228 244 244 215 219 218 233 236 220 242 223 233 242 244 258 259 232 236 249 224 245 243 215 233 228 222 233 239 228 192 213 243 216 239 229 245 244 220 245 224 263 247 223 233 236 234 225 231 244 207 238 228 240 232 243 210 225 223 223 232 231 242 234 256 228 279 239 209 261 214 256 208 268 280 234 208 234 234 277 232 233 221 248 262 222 210 238 213 249 244 215 245 227 261 237 232 262 258 266 247 246 244 265 212 210 230 244 262 234 215 227 247 261 211 230 231 220 213 245 246 232 233 208 238 230 231 217 220 269 200 232 219 234 256 245 237 243 227 238 249 238 228 237 214 234 232 233 269 210 209 212 205 228 232 247 244 242 244 217 247 221 227 224 222 238 217 201 206 233 261 220 222 257 250 226 265 220 246 249 231 225 223 239 212 230 249 214 213 232 217 233 255 216 236 260 238 247 213 256 225 231 238 235 240 274 211 245 259 245 247 241 261 210 227 228 259 232 222 208 239 224 266 230 228 227 261 212 234 209 248 238 193 219 219 265 213 275 223 245 245 223 231 257 226 234 266 235 229 226 226 223 219 217 232 242 228 228 248 233 220 225 242 226 224 226 218 228 217 242 242 219 234 248 278 207 245 243 242 228 260 207 229 263 217 237 239 240 232 234 234 256 232 231 201 225 242 264 243 239 239 218 242 223 221 213 225 214 223 210 230 232 235 242 240 235 256 196 234 220 243 236 237 265 242 237 226 240 230 223 203 230 214 210 225 216 214 217 246 256 204 258 260 237 219 222 236 207 212 235 234 215 256 207 230 269 229 248 219 241 232 215 223 216 202 235 210 218 242 227 216 231 242 238 218 200 244 248 227 230 236 236 264 220 217 226 210 260 233 229 239 226 241 245 230 197 236 241 235 262 223 212 224 241 222 244 237 242 227 223 248 231 257 236 245 240 220 218 238 231 241 211 217 227 223 245 236 221 234 209 244 210 236 232 194 248 239 231 238 225 235 210 240 228 248 238 229 223 229 246 238 211 226 227 247 255 257 238 206 243 227 233 209 232 244 226 235 219 225 243 247 222 239 247 249 257 221 258 236 233 235 260 224 229 224 239 223 226 249 226 236 203 217 237 207 258 221 236 230 190 265 237 233 211 210 232 215 208 225 245 230 262 203 224 228 257 236 247 261 216 230 229 232 224 226 248 240 240 214 220 227 230 268 225 220 236 245 219 231 230 215 237 219 221 241 235 218 221 223 263 238 242 236 221 224 226 236 211 241 246 209 243 216 232 199 222 239 231 238 236 237 238 239 256 250 193 221 263 234 265 232 232 209 223 247 216 217 218 234 218 210 233 232 227 247 260 229 243 224 221 222 242 264 237 255 217 243 210 255 260 227 233 218 238 225 207 209 242 221 228 223 234 247 208 225 265 269 244 231 238 235 230 219 247 231 230 217 224 227 231 224 240 257 236 259 227 227 240 234 215 227 211 216 213 199 230 223 203 257 232 245 229 246 246 214 233 219 240 238 242 239 223 261 240 276 241 228 231 207 218 208 221 207 242 237 266 219 244 212 226 223 222 231 257 226 213 230 217 225 240 237 216 238 238 240 220 285 223 228 239 234 229 242 233 220 221 247 235 260 216 235 217 239 237 238 224 219 240 220 216 244 259 237 200 240 215 243 243 239 228 222 239 227 261 219 209 221 236 214 228 232 227 267 232 237 232 240 233 232 244 276 226 243 259 202 221 263 233 222 207 220 230 222 242 214 216 205 242 234 229 210 212 255 231 213 241 230 246 229 232 233 238 222 214 239 264 227 239 233 222 246 230 236 231 259 222 234 240 237 208 211 239 210 224 231 197 232 230 244 218 246 196 223 213 234 231 213 229 223 211 258 198 250 255 218 223 240 222 249 213 229 205 223 187 240 233 222 227 211 256 216 255 224 215 257 211 227 241 238 228 269 227 215 249 239 226 261 244 215 239 256 230 211 231 234 244 213 237 218 205 211 256 231 218 207 228 283 247 220 227 241 238 242 237 192 216 202 197 237 202 232 246 261 262 235 203 248 230 227 262 234 222 234 224 226 263 263 220 223 225 234 244 267 236 234 245 245 234 201 221 221 241 207 240 243 237 234 227 244 216 232 203 241 240 238 228 241 221 231 208 230 222 209 225 225 224 212 241 228 256 226 260 218 226 245 214 220 238 214 248 229 218 219 227 215 226 220 232 227 213 210 234 207 236 227 222 228 221 200 199 222 214 238 225 232 219 230 229 216 218 230 249 208 235 221 230 238 258 230 236 247 226 226 218 220 242 256 236 212 235 271 219 221 223 223 222 209 250 219 203 217 266 242 227 228 222 231 245 274 215 232 243 221 206 225 256 214 220 245 241 239 216 227 212 237 227 233 255 265 218 261 231 215 238 231 223 182 228 230 215 242 257 266 225 227 255 272 260 229 243 247 259 250 234 238 233 234 229 220 224 226 207 228 266 220 268 218 260 212 228 245 246 214 234 241 242 227 258 243 259 230 247 240 239 200 230 229 243 225 219 240 218 231 209 211 215 240 249 236 203 255 213 273 230 233 240 202 248 256 220 200 250 240 229 267 247 249 217 246 233 235 224 229 215 222 210 231 214 242 259 221 207 234 243 249 238 231 217 236 225 243 258 246 216 263 244 269 229 233 246 236 262 213 238 216 236 229 230 266 217 220 196 227 230 232 262 228 237 225 224 228 221 242 229 255 222 215 261 238 214 257 210 241 206 193 236 239 235 236 226 205 240 224 249 240 232 235 241 220 220 241 238 244 212 243 216 222 264 213 238 232 218 227 224 220 237 256 263 241 244 211 246 206 263 255 247 231 238 229 272 229 222 223 240 246 242 235 264 231 258 216 205 228 239 259 236 223 232 240 221 257 234 198 240 225 222 262 230 221 245 240 236 270 241 240 245 229 247 230 206 248 261 217 258 239 223 220 239 229 232 238 241 213 234 239 219 248 228 236 241 234 244 226 227 243 213 228 248 224 240 228 223 210 233 225 217 237 205 236 212 225 258 228 242 222 205 236 231 268 244 227 236 255 216 225 257 221 278 240 231 249 219 223 209 264 214 208 261 240 231 218 256 263 214 236 238 238 231 244 218 230 237 212 262 205 262 210 203 261 229 260 237 282 213 268 207 245 238 225 237 258 236 242 231 225 222 256 223 262 231 240 212 227 234 216 246 237 245 231 234 196 223 248 234 215 235 232 241 243 243 247 237 244 229 262 262 233 267 232 259 223 226 227 290 248 270 231 232 235 257 225 219 276 248 228 269 222 225 238 261 274 222 220 246 261 204 226 273 244 237 243 237 234 245 220 239 240 249 278 244 240 242 231 240 244 220 243 213 231 220 265 226 245 246 236 225 228 245 248 256 267 286 238 222 235 233 218 237 255 247 231 200 245 274 265 230 250 267 259 244 240 244 260 240 233 227 250 259 265 280 240 235 241 248 265 231 236 216 277 270 260 255 256 226 225 256 212 263 248 256 231 255 255 241 243 268 239 267 246 241 261 260 245 266 233 241 247 257 269 273 248 245 237 247 246 273 238 259 239 275 217 246 264 239 240 261 242 241 242 279 243 203 244 227 247 276 241 266 257 214 256 239 220 222 276 246 222 265 278 257 212 255 267 269 237 262 228 266 246 243 263 255 234 239 276 234 227 233 231 256 227 258 233 229 226 236 266 259 263 208 234 248 248 215 238 261 256 230 255 264 269 217 264 256 227 218 247 274 256 235 213 255 235 266 223 222 239 228 244 225 218 238 255 225 226 236 249 245 256 211 247 292 238 224 226 249 274 268 235 238 242 229 232 268 244 234 274 230 211 241 226 244 247 223 240 238 244 259 222 219 247 212 255 256 239 239 211 218 257 259 270 231 244 245 228 265 248 250 265 205 256 240 256 259 240 235 237 225 232 218 234 259 268 239 241 268 274 247 244 224 212 221 276 237 243 249 220 208 240 270 267 243 238 218 217 221 238 229 236 227 259 216 261 221 226 249 225 241 244 257 220 232 227 216 259 270 221 232 240 240 230 255 222 229 273 231 238 243 265 266 260 223 246 229 210 240 242 241 233 225 195 220 207 211 236 220 227 223 217 226 230 234 243 229 231 271 263 243 248 215 232 226 229 224 258 241 201 232 229 239 225 241 229 241 217 223 265 235 232 236 236 259 227 267 255 247 290 235 249 222 234 238 237 246 239 233 232 242 232 263 206 230 247 250 228 235 222 238 235 221 215 240 231 227 230 227 256 216 256 207 259 225 266 238 234 238 212 286 257 246 285 234 228 266 220 227 213 283 212 231 239 231 258 206 223 230 257 240 226 223 235 231 258 225 224 265 246 247 221 239 241 266 275 222 263 275 235 243 212 227 225 225 244 246 230 221 244 243 242 232 246 241 234 265 238 234 233 233 221 240 243 265 248 197 246 230 234 223 226 232 224 231 227 223 249 222 219 270 239 247 231 231 238 232 234 247 225 226 275 258 215 242 242 248 219 234 242 247 243 244 224 234 231 238 267 238 265 247 239 225 229 235 232 277 238 240 232 221 238 222 286 245 229 240 219 270 257 241 256 238 247 242 245 231 231 230 255 230 242 235 236 222 243 211 217 231 247 236 238 231 243 228 226 221 231 229 233 228 232 236 224 232 255 227 259 258 256 227 237 223 260 220 239 232 240 235 208 232 222 218 239 237 266 237 249 213 237 230 216 232 236 216 256 232 222 226 245 260 240 243 250 275 225 229 238 235 239 242 209 212 216 220 223 235 226 240 248 263 232 237 213 201 258 218 231 242 241 226 216 219 220 249 223 228 221 234 242 248 202 264 214 255 248 232 245 218 223 246 260 232 236 242 234 214 226 269 240 227 258 241 245 211 222 242 229 218 225 241 227 268 233 237 228 212 261 232 258 231 269 227 240 225 221 220 210 219 241 234 211 227 233 238 226 249 234 263 245 244 200 235 247 246 256 255 238 236 219 277 235 234 248 236 209 237 227 258 225 221 272 214 237 232 220 226 224 221 224 222 243 223 258 233 229 230 259 195 287 235 248 238 234 268 232 216 238 244 221 202 235 229 227 206 216 228 267 237 228 212 223 192 230 227 246 234 247 214 238 237 228 227 231 202 233 230 230 227 224 224 201 246 265 229 214 268 256 238 205 217 243 233 218 217 235 239 239 243 240 225 256 266 224 239 226 256 204 240 230 246 234 219 233 225 221 229 243 242 235 248 260 271 229 239 259 224 247 243 237 249 226 208 264 222 229 246 219 221 231 236 229 247 239 218 221 228 232 246 221 244 218 258 268 257 248 245 228 236 224 234 242 245 220 213 241 227 237 260 233 264 246 193 228 219 230 238 225 192 218 211 234 211 211 224 218 249 275 233 264 246 210 283 224 233 243 228 224 233 233 228 231 223 235 257 241 265 246 210 240 240 243 211 229 221 227 270 232 241 218 240 221 222 236 241 231 227 216 259 221 260 249 256 231 234 241 245 257 209 262 255 225 256 221 235 247 215 217 276 259 215 234 240 232 244 234 214 220 247 227 224 246 245 233 239 238 242 246 225 226 193 233 222 242 260 234 250 233 207 221 229 257 257 233 261 258 242 222 244 216 258 230 243 230 249 247 234 267 221 240 217 239 217 257 230 232 234 244 243 236 217 256 246 232 260 219 238 285 225 221 224 224 240 255 242 236 211 230 224 225 226 216 234 265 241 248 256 260 241 243 268 261 256 231 231 249 238 246 220 230 262 223 270 230 219 248 235 248 227 203 233 210 261 234 259 212 265 224 241 207 269 240 242 237 224 241 220 238 206 224 247 234 233 271 220 230 259 246 225 220 259 237 238 272 243 224 227 229 215 234 205 232 236 266 234 235 213 248 232 239 230 212 227 249 219 258 241 262 246 250 236 238 231 255 237 239 236 230 223 225 246 222 228 225 234 244 245 248 256 240 241 236 267 256 218 244 259 256 207 266 240 217 258 224 230 236 257 239 226 222 208 233 240 239 235 226 237 238 246 215 220 262 257 222 239 231 258 223 238 236 227 230 238 235 228 265 230 242 259 258 214 223 234 219 230 214 230 230 240 222 216 241 235 269 229 228 234 225 231 221 235 249 249 221 220 248 226 234 231 265 240 258 231 233 237 223 259 222 245 223 238 255 227 224 220 227 234 274 234 238 245 220 230 240 241 216 202 247 244 228 242 230 234 219 228 257 225 234 218 225 258 236 237 244 248 234 230 257 223 256 225 217 216 242 225 200 232 244 241 228 237 214 217 221 223 246 245 224 236 233 263 217 204 217 234 233 249 213 220 255 207 229 236 234 229 241 258 249 232 231 199 240 217 233 257 229 238 259 230 248 241 239 224 222 267 221 224 237 229 255 240 257 227 225 209 192 205 220 257 215 226 215 229 217 233 219 226 242 216 219 236 260 247 204 238 234 241 246 231 233 210 245 210 232 266 221 246 230 264 237 221 217 232 217 237 227 277 221 228 231 216 211 224 232 236 221 241 233 222 215 229 234 248 216 235 256 236 199 232 231 218 237 218 227 214 228 246 215 240 230 238 234 234 261 268 225 248 244 274 220 241 202 225 204 233 239 227 240 236 232 232 257 203 211 245 237 241 236 232 255 231 223 206 220 235 217 220 251 261 206 200 263 232 220 213 233 223 216 208 221 240 217 246 234 246 221 206 238 241 232 241 220 216 255 216 212 234 216 264 228 228 247 231 238</counts>
			</dataPoints>
		</scan>
	</xrdMeasurement>
</xrdMeasurements>