File: data/XRD/XG-Luft/XG-750/W6823-1D_XG_Luft_750.xrdml
<xrdMeasurements xmlns="http://www.xrdml.com/XRDMeasurement/2.1" xmlns:xsi="http://www.w3.org/2001/XMLSchema-instance" xsi:schemaLocation="http://www.xrdml.com/XRDMeasurement/2.1 http://www.xrdml.com/XRDMeasurement/2.1/XRDMeasurement.xsd" status="Completed">
	<comment>
		<entry>Configuration=Factory configuration, Owner=User-1, Creation date=7/8/2013 4:01:53 PM</entry>
		<entry>Goniometer=PW3050/65 (Theta/2Theta); Minimum step size 2Theta:0.0001; Minimum step size Omega:0.0001</entry>
		<entry>Sample stage=MRD Cradle; Minimum step size Phi:0.01; Minimum step size Chi:0.01; Minimum step size X:0.01; Minimum step size Y:0.01; Minimum step size Z:0.001</entry>
		<entry>Diffractometer system=XPERT-PRO</entry>
		<entry>Measurement program=C:\PANalytical\Data Collector\Programs\Jorrit\2thom\_absolute_2th-om_10-130deg_PIXscan_56min.xrdmp, Identifier={15BCCF57-2807-42BD-B5B9-ECC0B3DC9284}</entry>
		<entry>Batch program=C:\PANalytical\Data Collector\Programs\SimonL\batch6x_2thom_10-130°_z9.1_x0,10,20,30_y20,40_57min - Kopie.xrdmp, Identifier={8874E540-C3F4-4307-831A-CD55F073CDCD}</entry>
	</comment>
	<sample type="To be analyzed">
		<id></id>
		<name></name>
		<preparedBy></preparedBy>
	</sample>
	<xrdMeasurement measurementType="Scan" status="Completed" sampleMode="Reflection">
		<comment>
			<entry>_absolute_2th-om_10-130deg_PIXscan_56min</entry>
			<entry>PHD Lower Level = 4.83 (keV), PHD Upper Level = 11.27 (keV)</entry>
		</comment>
		<usedWavelength intended="K-Alpha 1">
			<kAlpha1 unit="Angstrom">1.5405980</kAlpha1>
			<kAlpha2 unit="Angstrom">1.5444260</kAlpha2>
			<kBeta unit="Angstrom">1.3922500</kBeta>
			<ratioKAlpha2KAlpha1>0.5000</ratioKAlpha2KAlpha1>
		</usedWavelength>
		<incidentBeamPath>
			<radius unit="mm">320.00</radius>
			<xRayTube id="1010048" name="Empyrean Cu LFF HR (9430 033 7310x) DK442154">
				<tension unit="kV">40.0</tension>
				<current unit="mA">40.0</current>
				<anodeMaterial>Cu</anodeMaterial>
				<focus type="Line">
					<length unit="mm">12.0</length>
					<width unit="mm">0.4</width>
					<takeOffAngle unit="deg">4.2</takeOffAngle>
				</focus>
			</xRayTube>
			<xRayMirror id="27010001" name="Inc. Beam Cu W/Si (parabolic MRD)" hybrid="false">
				<crystal type="Graded" shape="Parabolic">W/Si</crystal>
				<acceptanceAngle unit="deg">0.800</acceptanceAngle>
				<length unit="mm">60.0</length>
			</xRayMirror>
			<sollerSlit id="21010002" name="Soller slits 0.04 rad.">
				<opening unit="rad">0.0400</opening>
			</sollerSlit>
			<mask id="22030007" name="Fixed mask 2 mm">
				<distanceToSample unit="mm">220.00</distanceToSample>
				<width unit="mm">2.00</width>
			</mask>
			<divergenceSlit id="22010007" name="Fixed slit 1/8°" xsi:type="fixedDivergenceSlitType">
				<distanceToSample unit="mm">220.00</distanceToSample>
				<height unit="mm">0.19</height>
			</divergenceSlit>
		</incidentBeamPath>
		<diffractedBeamPath>
			<radius unit="mm">320.00</radius>
			<sollerSlit id="21010002" name="Soller slits 0.04 rad.">
				<opening unit="rad">0.0400</opening>
			</sollerSlit>
			<receivingSlit id="22010001" name="Fixed slit 4°">
				<height unit="mm">5.88</height>
			</receivingSlit>
			<detector id="7010017" name="PIXcel3D 1x1 detector" xsi:type="areaDetectorType">
				<phd unit="%">
					<lowerLevel>30.0</lowerLevel>
					<upperLevel>70.0</upperLevel>
				</phd>
				<mode>Scanning</mode>
				<activeChannelsEquatorial>255</activeChannelsEquatorial>
				<activeChannelsAxial>255</activeChannelsAxial>
				<pitchEquatorial unit="mm">0.05500</pitchEquatorial>
				<pitchAxial unit="mm">0.05500</pitchAxial>
				<readOutPeriod unit="seconds">0.135</readOutPeriod>
			</detector>
		</diffractedBeamPath>
		<scan appendNumber="0" mode="Continuous" scanAxis="2Theta-Omega" status="Completed">
			<header>
				<startTimeStamp>2024-10-25T21:01:24+02:00</startTimeStamp>
				<endTimeStamp>2024-10-25T21:57:30+02:00</endTimeStamp>
				<author>
					<name>PRO-MRD</name>
				</author>
				<source>
					<applicationSoftware version="6.1b">Data Collector</applicationSoftware>
					<instrumentControlSoftware version="7.0E 20130304">XPERT-PRO</instrumentControlSoftware>
					<instrumentID>0000000011142674</instrumentID>
				</source>
			</header>
			<dataPoints>
				<positions axis="2Theta" unit="deg">
					<startPosition>9.99826193</startPosition>
					<endPosition>129.99755682</endPosition>
				</positions>
				<positions axis="Omega" unit="deg">
					<startPosition>4.99913096</startPosition>
					<endPosition>64.99877841</endPosition>
				</positions>
				<positions axis="Phi" unit="deg">
					<commonPosition>0.00</commonPosition>
				</positions>
				<positions axis="Chi" unit="deg">
					<commonPosition>0.00</commonPosition>
				</positions>
				<positions axis="X" unit="mm">
					<commonPosition>20.00</commonPosition>
				</positions>
				<positions axis="Y" unit="mm">
					<commonPosition>0.00</commonPosition>
				</positions>
				<positions axis="Z" unit="mm">
					<commonPosition>9.100</commonPosition>
				</positions>
				<commonCountingTime unit="seconds">32.895</commonCountingTime>
				<counts 394 394 368 393 361 368 383 357 372 373 372 345 382 377 351 361 387 340 368 318 355 353 342 350 389 345 356 392 362 371 420 355 354 352 336 367 366 345 377 371 353 361 392 354 371 379 397 363 343 387 359 367 358 351 400 362 365 375 381 375 352 364 349 342 365 366 366 351 397 349 358 370 347 378 349 337 385 353 351 334 369 334 327 348 345 365 346 398 363 385 367 348 342 349 348 373 373 329 345 300 351 359 377 388 348 363 363 358 344 352 319 358 361 367 328 342 382 345 353 341 349 343 348 342 342 355 377 358 338 358 311 314 338 329 315 354 359 354 316 347 355 322 352 349 320 351 387 347 363 354 369 349 358 346 335 363 347 329 356 381 343 354 369 363 332 314 332 346 341 337 356 386 321 341 312 362 352 334 333 337 361 352 333 327 342 333 309 362 330 345 336 301 328 340 343 386 335 333 358 334 331 307 363 356 338 369 300 349 320 343 349 356 361 313 340 359 347 350 364 343 342 312 332 349 331 314 359 343 341 319 361 337 337 328 334 337 367 337 317 339 291 376 315 341 345 343 329 349 344 325 325 308 282 346 320 317 326 335 309 350 331 308 363 343 338 322 314 334 328 327 334 347 329 305 342 315 317 324 317 317 364 322 339 316 309 323 306 326 324 346 336 313 340 310 313 302 351 326 313 309 332 308 330 314 321 324 296 293 299 315 312 270 308 284 305 327 322 276 317 306 363 301 338 311 336 333 310 335 316 309 315 298 293 328 309 339 304 295 320 295 304 319 309 309 311 326 323 320 324 334 304 318 333 307 297 315 321 343 307 313 323 319 301 310 328 301 325 298 338 306 266 274 317 325 298 293 310 301 324 321 323 313 313 301 318 303 330 294 308 283 304 279 291 285 293 281 316 295 315 309 285 298 308 320 316 309 324 280 327 316 277 296 305 284 313 284 294 306 330 319 344 292 259 304 318 301 311 308 285 281 303 304 301 312 307 274 280 300 283 281 315 274 267 282 289 261 302 288 313 303 315 308 336 265 282 285 294 285 285 289 317 294 304 292 316 298 273 314 250 281 320 283 282 303 283 295 319 302 291 293 309 310 306 308 280 284 292 296 259 274 306 287 302 285 286 280 290 281 298 318 308 294 311 301 312 263 319 264 308 276 267 267 276 307 270 273 266 288 277 294 289 246 304 290 296 305 287 271 289 265 297 314 281 305 280 291 270 274 292 258 266 306 277 283 316 291 285 306 284 268 272 301 312 294 266 273 275 266 275 328 265 314 275 278 268 263 275 238 278 284 291 289 245 272 275 258 279 296 288 275 246 277 268 305 271 298 300 283 238 269 278 287 264 278 264 276 271 277 270 289 256 282 278 294 284 296 266 284 278 256 308 272 271 297 273 268 286 257 280 256 275 281 286 284 298 271 272 284 292 299 257 287 273 274 267 282 247 274 269 280 249 281 279 258 297 264 262 290 288 272 285 261 261 274 276 262 267 284 244 298 277 275 267 270 294 290 269 267 281 301 286 268 267 243 298 278 286 244 279 290 258 260 255 268 275 278 266 248 272 289 301 282 276 282 311 279 257 266 272 268 232 267 258 272 255 293 271 285 271 288 267 295 277 248 292 279 256 259 269 285 277 264 267 284 290 242 238 272 282 242 260 267 262 265 301 309 291 294 277 247 270 293 262 269 292 285 259 260 279 273 279 297 272 263 274 245 282 256 299 276 269 294 278 273 282 273 240 305 272 269 266 258 260 282 259 292 278 299 298 278 311 273 277 296 284 245 281 300 259 255 256 282 273 274 297 286 313 264 272 248 220 287 272 259 255 272 264 270 246 280 270 289 260 231 277 298 272 274 262 278 290 264 276 288 270 287 283 276 242 277 257 264 259 238 304 263 278 279 258 258 277 270 274 297 295 270 283 260 284 264 297 243 248 281 270 269 299 274 295 295 292 281 308 280 290 280 264 269 272 275 257 287 297 280 288 275 267 288 247 263 262 275 262 310 232 297 275 267 266 274 296 270 274 301 309 262 250 280 269 264 268 273 298 280 265 279 276 291 283 280 246 277 243 271 305 232 263 248 270 270 279 279 247 281 259 294 308 281 238 289 293 287 313 242 276 286 279 265 256 260 285 244 278 243 288 256 303 244 287 286 267 301 273 288 288 277 240 275 287 301 288 260 273 289 260 266 281 308 285 276 284 273 308 275 297 308 282 274 260 274 264 300 266 272 273 269 296 296 267 264 286 284 291 275 262 281 329 275 272 244 307 300 270 280 247 296 274 255 284 268 269 259 274 305 303 317 258 292 277 244 244 291 268 278 316 274 266 274 276 271 278 272 274 286 286 290 269 285 299 302 292 293 259 295 291 290 292 271 274 282 293 264 281 282 284 290 275 277 280 271 282 292 293 320 249 283 272 269 292 302 280 268 271 309 282 279 286 268 280 257 314 278 261 296 285 289 286 284 269 269 273 282 281 295 293 279 291 273 292 293 283 300 287 314 278 284 271 307 270 275 263 286 280 299 279 290 303 307 288 281 283 321 293 302 295 265 298 277 295 307 266 278 290 314 266 289 312 275 295 288 301 290 262 286 277 297 286 276 278 289 306 295 276 307 262 284 283 309 310 276 270 287 317 263 309 284 299 297 296 280 272 300 273 303 301 305 291 290 256 244 270 266 262 255 278 281 277 258 282 289 267 325 298 292 292 268 326 276 303 295 265 248 315 280 291 283 276 274 269 289 280 280 280 286 264 268 323 271 336 289 297 267 296 262 289 266 299 290 271 263 280 288 281 303 269 267 296 280 273 306 296 275 284 285 300 287 305 290 290 285 314 282 296 328 301 264 278 304 330 285 275 303 265 294 299 282 267 296 261 278 324 307 292 294 283 275 297 315 304 281 306 295 286 301 300 298 270 282 274 295 271 272 302 295 261 280 288 256 305 286 321 267 302 296 301 281 279 301 244 282 290 335 272 299 302 276 259 281 270 276 281 318 297 278 263 283 283 264 280 311 309 260 299 263 302 256 279 301 278 304 336 275 288 292 256 316 258 279 266 290 281 336 308 286 268 284 283 257 262 305 288 293 323 282 271 298 272 282 291 326 277 272 257 264 274 293 248 284 273 290 278 260 293 285 297 283 288 307 269 273 287 263 302 296 278 292 322 255 257 302 269 289 297 277 265 296 313 246 268 274 277 274 281 275 280 292 270 261 280 268 285 273 262 267 303 259 288 265 275 280 292 242 291 255 280 302 287 285 243 273 272 305 238 306 285 270 287 275 283 284 273 275 273 271 266 267 294 259 287 265 283 242 271 289 279 262 272 249 271 286 289 284 262 266 271 271 258 298 263 261 269 266 239 261 267 275 243 290 283 280 259 270 293 248 248 264 282 263 261 277 276 285 299 247 267 256 263 237 285 280 223 298 234 277 229 282 274 269 310 301 260 233 275 235 272 297 268 277 277 266 275 239 263 258 220 272 255 312 295 275 261 238 297 236 267 255 293 266 264 270 273 284 257 268 274 257 282 235 265 295 266 268 263 247 249 267 272 247 261 243 262 300 255 244 243 271 224 283 286 272 268 248 271 290 280 258 248 237 262 256 241 273 280 262 271 238 228 271 220 270 256 240 238 262 275 277 255 249 263 264 270 270 278 271 262 247 263 224 241 265 272 239 232 240 247 258 259 225 267 229 249 244 247 264 237 241 232 239 248 233 232 240 245 237 227 268 239 226 223 233 246 234 267 260 273 212 223 265 240 250 266 211 238 236 256 232 267 255 243 217 209 227 243 230 247 221 241 261 249 249 241 250 259 230 246 232 257 231 276 241 247 220 231 204 246 242 243 267 218 243 243 246 239 241 218 237 255 239 273 237 220 269 227 241 221 232 211 230 259 237 246 244 247 276 228 247 246 233 227 260 235 226 222 268 228 237 262 231 233 242 236 238 237 260 225 222 231 242 258 257 232 266 227 249 223 229 238 265 246 237 231 223 245 235 257 258 213 260 225 255 248 232 220 225 236 246 233 240 247 207 226 232 243 260 250 248 242 233 239 229 216 231 229 232 214 247 183 234 223 232 233 229 197 239 234 220 233 232 234 200 206 242 232 225 233 225 227 220 214 222 235 239 210 228 285 212 205 193 265 208 216 248 214 214 226 217 231 222 233 207 216 218 245 236 218 223 237 212 216 227 236 204 247 229 227 218 236 239 202 219 224 238 212 235 233 213 230 220 232 225 220 219 207 205 223 216 203 216 217 244 237 216 207 223 219 216 217 209 220 234 217 216 210 215 220 245 245 197 235 236 205 227 242 209 227 237 210 216 200 225 211 229 205 222 215 220 197 202 218 196 194 226 213 222 210 231 217 231 208 195 179 196 222 217 229 223 207 197 219 236 208 234 235 203 225 189 199 229 232 230 218 201 201 207 217 199 224 202 222 205 217 218 224 213 206 195 240 230 241 193 221 215 219 218 210 235 214 191 242 218 181 202 230 209 201 203 208 211 189 196 218 211 187 229 201 211 207 210 197 202 188 193 222 249 223 214 208 225 211 189 208 190 202 229 230 186 209 218 219 213 170 210 176 223 228 206 212 201 211 194 206 220 222 223 181 189 214 222 200 215 210 201 196 199 200 226 195 218 224 229 213 204 207 215 225 222 207 238 226 223 208 216 192 223 214 216 183 202 232 209 213 222 207 218 239 207 186 213 202 208 194 216 200 216 244 205 183 218 221 228 199 218 216 177 206 223 219 231 206 216 198 226 196 197 218 197 210 189 215 188 179 182 207 174 204 225 202 201 211 193 184 212 197 198 209 218 209 202 199 199 197 207 209 193 215 215 190 257 198 213 202 207 170 201 207 214 216 212 197 219 179 212 216 192 218 196 180 210 207 203 226 180 190 192 199 208 210 178 245 200 211 217 207 188 196 179 181 196 186 183 201 186 201 202 177 180 186 201 219 223 212 203 188 234 204 203 201 202 205 210 200 213 211 199 200 211 202 170 223 198 204 201 196 204 220 206 196 205 197 188 209 191 204 200 216 189 187 184 186 196 168 206 215 178 198 203 220 219 198 206 213 214 197 171 209 178 169 188 202 188 198 186 218 197 195 217 187 208 192 173 207 188 205 196 182 180 177 183 194 212 199 214 189 227 190 209 201 197 179 206 214 181 192 197 205 190 189 178 193 182 180 197 202 209 185 183 175 192 227 188 200 198 182 153 183 180 189 191 183 185 181 180 178 205 173 224 199 184 223 202 189 196 188 189 200 207 185 182 198 187 205 199 187 233 207 200 173 202 170 190 188 181 189 184 190 192 219 179 183 195 191 206 201 180 202 184 186 188 193 190 176 175 200 183 172 188 213 167 192 202 179 176 213 177 193 189 207 193 188 163 201 191 199 181 188 180 192 186 209 202 183 191 197 184 185 193 177 203 170 202 192 197 175 174 204 210 192 177 193 179 191 188 172 206 198 182 178 171 198 180 178 190 201 183 211 186 195 201 207 194 163 187 185 171 181 175 167 188 172 192 164 195 184 188 212 205 199 181 192 199 182 187 184 217 200 203 201 211 179 192 199 187 183 193 196 189 198 197 170 179 187 183 179 187 176 172 191 212 193 195 183 217 205 188 203 198 185 185 184 210 200 191 201 170 190 195 173 165 169 188 202 188 168 206 194 209 201 190 186 156 190 173 183 192 185 176 189 192 185 198 191 186 198 179 200 193 170 198 197 162 187 223 192 197 196 206 208 200 190 191 150 207 191 183 199 166 176 177 202 220 168 185 209 158 206 191 170 184 200 207 181 189 183 181 182 188 193 187 169 185 181 200 187 189 189 224 224 166 171 177 194 169 182 177 186 197 176 189 203 190 166 191 175 187 189 174 187 205 154 153 189 195 198 205 207 204 176 192 198 197 175 176 213 199 198 191 179 185 180 180 187 195 188 171 194 163 172 177 197 172 178 167 187 173 164 194 183 166 179 189 198 191 169 183 202 174 170 170 199 183 172 186 171 181 190 175 186 216 172 180 185 195 189 195 189 179 176 216 183 166 193 186 160 184 164 170 197 219 187 191 184 203 190 176 178 185 184 185 180 190 175 183 190 203 194 185 157 167 185 202 185 157 200 188 204 191 173 194 187 174 191 199 183 203 191 208 202 161 187 176 201 202 210 188 194 183 190 206 216 150 199 212 192 202 191 180 182 193 198 192 176 187 198 214 146 189 189 173 176 183 177 194 180 163 217 196 177 204 186 191 176 173 185 182 180 171 175 189 196 164 182 159 184 176 171 193 156 197 179 184 186 181 165 211 185 170 200 162 187 214 164 214 177 194 202 168 187 186 196 181 193 188 196 146 207 174 162 197 185 159 178 174 182 182 181 216 169 174 196 192 173 179 190 173 171 166 181 176 187 182 182 194 172 169 202 174 173 187 181 170 198 186 193 179 189 149 171 162 175 176 205 161 201 177 176 188 181 194 180 183 203 183 182 185 205 160 188 176 186 154 184 166 187 182 194 173 187 200 195 161 176 203 170 205 185 181 187 201 183 170 176 167 171 181 192 178 188 178 161 188 185 172 161 178 205 184 184 200 183 209 186 191 187 199 190 165 184 187 173 179 182 168 188 162 172 181 205 180 170 208 188 200 163 185 203 193 186 189 194 166 186 203 177 194 170 152 186 180 201 171 178 171 183 196 190 177 194 173 196 173 175 153 181 194 177 171 180 172 198 184 174 178 188 168 175 208 215 187 187 183 201 185 178 202 190 183 156 162 184 183 200 189 191 174 182 185 189 180 184 211 179 177 177 167 181 180 185 178 197 183 187 182 190 199 169 182 185 167 170 193 195 185 169 159 191 208 167 197 188 173 197 162 172 187 183 196 197 170 210 183 196 196 180 192 169 182 176 174 180 213 196 184 184 198 186 195 192 176 175 211 164 181 157 185 211 182 174 188 183 200 163 196 183 203 196 198 176 174 169 169 165 193 211 197 199 193 172 206 173 165 172 191 193 200 201 208 191 167 145 187 175 179 186 187 186 187 203 200 156 174 204 196 203 175 197 188 189 214 194 195 183 178 185 172 199 179 174 178 175 205 200 202 176 177 169 176 168 203 180 190 180 159 181 178 197 170 194 186 200 146 169 177 208 195 177 163 187 188 186 183 176 192 163 173 194 164 200 179 203 203 176 203 181 202 172 199 196 172 182 179 174 202 180 195 211 171 189 196 207 182 214 190 193 177 197 212 210 165 225 181 185 180 180 180 177 195 198 184 180 190 189 175 198 177 170 191 180 189 180 197 153 197 210 206 177 204 203 178 187 191 206 190 182 177 176 189 196 182 196 177 188 200 188 195 190 166 178 172 182 218 184 206 190 192 169 211 216 190 186 209 183 203 205 208 185 195 180 217 182 195 203 205 197 205 171 171 164 196 227 187 202 178 190 193 207 220 177 194 183 194 184 177 208 188 189 189 193 189 187 197 189 199 187 213 169 194 179 187 196 199 172 194 203 204 171 211 207 192 198 206 202 198 200 183 198 191 180 198 194 210 198 198 198 211 205 190 212 198 223 204 209 200 207 196 220 224 224 219 223 213 217 223 211 227 216 200 239 220 208 217 217 207 197 225 199 195 197 202 191 202 232 217 199 182 214 192 226 205 193 190 199 203 189 191 198 218 189 189 217 216 183 198 213 191 201 208 204 233 220 216 207 206 185 196 205 206 186 183 211 178 214 198 193 183 226 207 204 161 211 225 192 215 213 210 229 208 206 212 213 219 202 193 190 220 207 223 228 214 207 202 224 203 210 246 217 211 232 229 219 250 229 244 241 209 229 196 222 220 261 262 229 218 266 265 256 240 259 246 248 306 290 235 282 275 264 291 291 297 297 319 301 345 333 352 336 342 335 353 330 326 322 324 306 317 312 369 326 281 289 296 290 272 282 276 263 300 261 269 258 273 218 229 263 246 223 218 223 247 229 186 215 266 245 218 202 222 205 238 219 186 212 207 218 198 230 208 206 209 223 211 207 201 206 220 215 218 186 197 209 190 184 217 220 185 199 189 194 186 186 211 231 177 202 199 195 201 218 186 173 189 207 225 200 195 202 194 194 209 200 214 189 209 202 208 179 193 198 214 201 161 196 165 210 206 209 212 206 209 197 191 176 184 193 228 176 182 163 190 206 223 177 168 186 193 211 205 187 220 196 185 186 188 195 188 227 191 210 182 192 187 231 165 212 186 206 182 183 206 206 172 191 195 188 201 192 206 204 180 206 171 201 178 186 171 192 195 208 187 199 202 208 184 187 192 181 209 186 192 202 183 184 188 206 214 199 201 190 198 222 168 172 180 179 200 214 202 209 181 173 196 188 196 195 165 209 186 194 184 200 201 198 198 203 212 212 203 209 178 211 194 197 195 196 203 189 168 184 219 190 193 186 204 209 171 206 203 187 184 203 195 185 201 196 200 196 177 223 206 199 173 187 207 206 192 198 183 188 200 220 183 194 199 184 174 202 181 183 170 192 187 197 208 192 184 168 195 188 183 217 187 184 198 187 169 195 195 210 207 192 187 186 189 164 183 196 190 186 204 182 203 171 191 205 193 194 199 201 209 159 209 189 211 190 208 203 196 202 207 202 178 186 182 191 171 218 220 196 183 186 202 189 188 214 184 180 178 188 201 193 184 199 206 175 204 206 196 185 226 176 213 188 188 181 196 195 191 182 200 163 209 211 207 173 213 192 186 201 207 199 204 214 196 208 205 226 198 176 208 181 216 202 191 180 221 205 183 179 184 189 188 175 216 170 216 210 180 192 181 208 208 198 187 210 197 195 185 210 190 205 181 174 213 220 184 173 164 198 194 215 171 186 198 211 176 188 174 184 193 179 205 187 198 184 180 180 181 184 194 180 208 215 174 194 185 183 201 212 175 184 191 197 184 200 186 204 174 190 179 197 194 201 181 205 199 205 200 172 187 206 209 204 172 182 206 191 194 205 201 205 182 175 208 201 196 194 201 206 169 186 215 172 187 189 202 174 211 197 195 187 206 203 196 174 181 190 190 205 201 201 222 205 201 187 186 202 206 204 171 202 237 205 189 183 181 200 171 190 178 195 199 202 184 185 188 192 199 160 205 193 185 202 207 192 198 195 181 222 179 195 226 203 189 187 184 205 170 200 201 217 205 223 184 211 158 218 177 199 177 192 221 198 198 176 178 203 196 182 192 200 203 165 197 182 213 202 196 180 201 194 208 190 217 218 206 199 202 191 201 220 204 186 183 223 220 198 187 190 190 207 174 201 181 215 177 193 216 201 200 195 220 221 211 205 211 166 189 198 204 200 216 223 199 194 171 185 189 191 173 195 186 200 179 188 194 202 214 216 192 188 193 202 212 185 207 177 216 170 204 200 208 186 196 188 205 197 187 199 181 189 156 175 181 186 200 174 186 199 177 196 196 165 203 203 207 183 207 197 177 181 184 206 192 195 184 190 170 203 211 205 206 193 191 176 194 195 171 185 181 191 196 184 190 197 224 186 192 196 195 198 190 194 188 188 197 215 192 205 205 202 198 185 214 195 190 199 192 198 215 201 197 197 204 202 201 188 184 193 212 214 200 183 236 205 153 218 199 198 177 185 194 209 204 197 193 193 183 207 177 221 199 217 227 173 199 198 196 200 177 218 189 181 201 182 183 195 194 201 191 198 188 213 176 198 209 205 216 189 154 178 196 221 201 192 181 176 189 177 200 186 200 184 196 209 188 226 189 180 216 201 189 194 185 191 212 199 201 196 172 170 189 182 206 204 198 201 202 214 191 171 210 211 199 173 208 205 191 186 185 193 179 162 200 219 218 196 188 183 197 192 207 206 191 179 184 198 180 189 193 191 222 176 188 181 185 211 198 212 202 187 204 206 167 184 204 154 200 173 226 204 170 185 197 200 200 189 176 190 184 211 187 212 218 201 191 161 227 187 216 228 198 200 225 188 187 215 210 194 193 195 204 201 191 199 192 194 192 191 183 198 195 174 172 191 217 177 202 186 192 197 182 207 175 205 193 190 223 222 167 192 208 206 223 189 178 202 189 195 187 175 196 206 180 198 183 190 211 209 209 209 181 223 181 195 185 201 200 196 227 221 176 212 212 197 182 196 173 211 181 221 200 187 218 183 212 204 196 188 210 191 222 220 212 200 189 209 206 188 199 218 196 198 182 192 208 195 187 191 204 224 202 191 199 219 185 179 194 181 200 176 210 203 205 191 204 198 154 191 188 196 214 198 212 215 170 228 192 185 191 189 168 179 198 200 199 185 208 197 207 198 191 196 193 190 194 194 188 197 168 192 209 226 186 200 160 171 204 202 190 193 179 192 214 195 188 187 221 220 188 210 201 196 211 185 204 188 200 156 210 175 156 174 181 216 176 218 229 188 193 177 179 177 206 193 176 206 213 181 171 194 170 197 198 193 207 223 176 225 192 206 187 203 212 192 200 201 188 202 202 211 193 189 190 189 179 188 176 187 197 185 204 187 210 186 208 203 200 195 214 211 204 186 187 196 243 193 210 178 175 183 198 186 198 192 220 181 195 190 184 201 211 187 205 209 206 193 205 186 197 206 186 209 209 192 201 196 193 186 204 207 203 183 198 188 198 195 235 198 209 205 205 213 174 214 172 199 192 220 185 200 179 192 163 204 198 208 195 211 186 188 219 174 200 210 174 189 185 208 202 176 213 203 194 197 186 217 228 198 194 193 199 191 215 193 195 201 191 194 187 179 178 214 202 206 204 185 169 199 166 227 211 203 202 177 222 195 193 186 198 201 196 205 182 186 196 197 202 202 208 204 177 217 193 185 179 219 194 178 180 209 174 194 208 180 234 207 164 195 173 193 192 212 187 204 221 201 199 204 221 200 188 190 193 201 198 198 205 214 199 193 222 199 199 194 202 216 194 200 181 198 179 215 193 209 206 189 215 200 200 177 179 196 200 188 205 187 207 196 171 186 185 219 197 178 212 184 206 186 180 214 173 216 172 177 187 182 182 187 197 177 203 193 182 190 182 217 201 216 198 197 167 167 200 199 178 202 196 226 177 201 216 217 197 198 205 195 183 189 200 196 190 198 175 187 211 181 214 190 200 199 209 186 208 193 193 203 176 200 208 175 206 187 173 197 182 196 224 197 188 184 204 194 179 194 213 221 183 212 183 176 213 195 193 217 189 209 199 194 208 186 202 187 174 201 178 202 166 212 208 195 181 208 189 189 203 200 229 200 200 184 185 179 190 196 207 191 199 188 214 191 212 186 191 219 192 198 188 174 194 194 202 201 172 200 197 197 183 198 213 188 213 182 181 185 192 196 202 208 182 204 204 210 205 206 202 178 194 188 189 196 223 206 206 218 217 191 196 167 187 203 177 199 191 194 192 189 182 195 185 188 212 198 204 219 194 201 171 215 211 191 188 191 197 193 213 219 209 180 208 162 183 180 192 220 198 174 215 201 182 193 200 227 213 185 194 196 224 196 201 171 203 179 206 195 200 206 222 179 208 198 202 200 204 199 193 175 188 180 191 197 196 207 221 243 198 216 195 186 195 190 200 188 213 186 234 184 177 216 166 213 199 187 212 229 180 190 193 171 190 205 183 208 219 195 182 199 167 183 207 174 186 203 200 218 200 197 166 205 189 197 202 173 197 174 183 192 224 201 200 180 192 228 235 176 197 213 178 194 226 204 239 196 182 195 211 170 186 193 187 184 211 181 195 191 175 180 189 211 231 200 170 211 204 198 198 192 191 187 184 223 193 195 177 212 190 211 196 207 198 187 196 215 199 193 209 191 178 204 209 214 211 224 204 198 182 197 189 190 204 203 203 222 212 198 200 199 223 211 192 193 190 196 217 192 193 205 202 211 188 182 203 185 187 180 192 207 189 203 202 193 199 187 214 181 189 206 195 218 187 188 208 203 202 191 211 160 179 194 237 205 202 205 211 195 201 201 193 187 209 186 221 190 217 200 209 194 201 186 215 203 205 203 200 211 198 206 200 201 223 216 223 188 216 202 177 171 211 216 184 214 164 181 185 190 211 196 202 226 212 189 214 208 194 201 201 188 195 194 183 160 197 176 202 212 203 211 197 200 204 177 192 184 190 195 176 196 202 190 208 204 199 183 203 195 220 210 176 202 205 209 203 230 200 196 208 194 207 203 219 198 193 241 198 214 224 221 197 216 197 192 184 163 221 187 222 186 192 193 216 205 181 208 212 194 198 199 220 217 182 188 207 225 203 205 197 213 198 226 210 197 177 200 189 196 235 191 219 220 214 181 201 236 244 227 190 222 195 223 202 215 210 208 212 198 194 184 207 197 210 217 222 201 203 211 207 201 203 225 209 193 195 206 208 209 193 207 183 191 205 205 208 217 211 224 185 226 190 187 182 211 208 208 191 212 191 188 207 190 222 195 198 225 180 223 223 203 190 184 187 210 206 195 184 210 184 214 207 190 186 196 189 185 238 208 224 208 202 199 205 221 190 188 190 199 191 221 205 223 166 187 204 206 212 212 182 225 215 207 216 204 190 216 194 208 202 209 198 195 210 224 217 191 219 204 233 215 275 205 215 241 199 204 239 181 205 210 161 217 192 237 201 225 234 210 220 196 194 226 212 204 230 209 213 215 199 204 227 199 220 214 218 196 201 198 195 202 207 203 208 197 208 209 184 185 206 216 210 207 206 186 184 196 215 205 228 180 210 210 195 191 217 213 219 173 221 206 205 180 207 206 203 218 215 211 192 177 232 193 208 179 188 215 194 232 190 179 199 187 193 196 172 224 201 211 214 212 213 189 179 204 192 187 207 193 213 187 201 204 205 206 198 203 180 175 195 185 196 208 205 202 237 187 192 207 199 193 203 191 239 188 203 177 181 201 224 191 221 206 199 185 214 192 196 212 216 199 192 193 186 217 193 199 183 187 201 191 200 209 190 215 222 217 183 178 207 199 193 182 195 190 209 179 201 203 212 234 218 206 178 210 212 189 190 196 213 187 210 197 200 176 197 187 180 204 194 196 209 179 192 205 215 200 197 198 187 201 197 215 215 184 197 212 208 196 181 218 199 205 198 190 215 210 205 204 218 196 226 189 213 205 213 216 195 198 191 212 234 206 199 186 205 208 196 197 215 199 205 189 189 190 212 215 197 203 204 214 209 193 201 195 206 236 199 195 179 172 207 222 188 185 215 201 194 202 196 211 211 231 184 175 190 213 184 210 185 206 202 222 207 212 195 195 218 214 204 216 188 185 189 200 196 197 198 195 231 206 209 202 208 202 212 185 202 193 206 199 205 196 205 199 201 195 192 196 211 180 208 225 179 207 201 194 184 227 201 200 206 201 225 189 204 226 198 193 227 214 181 237 174 211 201 192 201 184 199 204 192 193 200 195 221 211 209 211 218 197 229 164 191 184 227 191 185 178 206 213 207 191 201 225 198 209 215 201 212 173 179 208 179 188 197 216 194 192 210 188 188 206 196 226 198 204 185 193 212 194 225 226 211 207 187 217 211 202 194 216 190 195 206 196 200 185 203 215 199 190 197 213 200 227 221 201 197 196 181 225 209 214 210 187 208 211 198 201 206 189 229 211 191 197 213 197 173 204 218 199 194 190 190 197 218 212 189 224 168 215 178 181 196 196 188 190 172 186 188 221 202 186 195 210 199 180 211 204 199 198 191 207 198 218 184 224 204 213 222 211 221 202 203 205 192 210 199 233 218 186 232 223 212 211 193 206 222 189 243 188 199 213 210 205 205 214 210 186 196 209 219 205 216 185 213 209 199 206 192 209 240 207 184 180 207 209 171 224 200 205 219 179 193 168 192 206 181 192 188 229 196 179 202 183 189 216 199 215 196 196 212 203 213 213 226 201 188 199 204 201 195 177 202 194 217 203 181 177 230 194 204 202 231 202 191 186 202 207 221 198 217 215 217 198 207 184 215 210 200 193 184 214 213 201 208 209 205 222 217 205 175 219 199 194 237 223 198 196 174 197 192 198 190 187 164 206 218 200 201 233 215 184 182 188 216 204 206 209 198 211 189 178 186 211 222 219 214 192 223 206 220 209 175 211 170 212 179 190 204 202 193 223 210 194 216 213 232 209 185 172 203 183 202 206 191 194 210 193 187 204 209 179 189 178 201 204 198 226 194 190 196 215 204 214 182 211 195 198 214 199 200 211 201 186 213 196 196 198 188 213 191 189 205 219 228 200 201 194 225 194 173 195 199 228 217 221 195 197 201 205 199 230 184 209 200 207 198 203 176 213 208 208 215 200 205 213 219 215 194 221 191 233 171 209 205 221 188 183 198 219 219 212 189 226 206 184 208 217 202 202 210 199 217 214 196 213 180 200 203 179 217 192 215 224 208 182 216 207 224 202 200 200 195 223 218 178 212 190 193 220 213 215 179 212 204 181 186 205 196 212 219 224 202 211 209 183 189 190 218 195 215 210 194 224 199 197 178 216 193 185 206 240 179 184 228 199 198 202 223 205 214 219 180 225 209 229 207 218 214 195 206 175 193 199 199 192 214 192 220 203 203 185 219 208 235 215 179 202 204 203 217 200 172 210 201 208 212 197 192 168 190 202 210 192 219 203 194 201 191 181 187 196 186 208 200 202 205 204 199 220 184 218 198 187 202 195 233 203 222 206 203 219 216 201 203 175 191 217 211 212 196 213 203 195 194 190 184 205 185 205 189 180 246 208 196 204 209 222 207 189 201 194 205 195 240 199 186 222 205 193 208 193 200 216 195 225 192 192 217 227 213 190 202 223 216 226 202 180 195 211 198 196 188 181 187 192 207 190 207 209 219 193 236 216 198 202 212 212 211 232 214 183 204 226 182 231 213 199 215 182 213 234 186 207 197 203 210 204 149 220 189 228 207 202 203 210 190 194 211 194 216 204 222 197 233 201 184 187 214 208 195 197 209 196 201 212 208 224 203 211 213 200 209 185 211 209 174 221 191 204 193 174 210 185 203 205 215 209 239 190 208 218 239 208 230 204 190 198 196 230 195 197 217 222 197 212 209 195 177 242 183 193 203 184 198 214 243 200 189 197 215 222 187 213 200 207 217 206 208 221 190 200 207 206 210 198 205 205 211 223 197 177 191 219 205 204 211 189 194 205 216 197 226 190 202 217 180 200 187 193 228 212 180 205 173 220 194 210 224 203 225 173 174 214 210 201 211 229 180 193 190 199 214 225 204 221 217 194 207 236 196 191 221 201 196 218 200 208 185 180 210 188 166 175 222 184 198 233 212 189 216 192 186 198 173 178 225 221 177 199 190 184 184 199 204 200 187 217 224 201 213 201 191 204 180 204 194 218 203 217 178 201 206 217 216 210 215 234 188 178 218 193 197 202 229 199 212 210 211 204 186 213 185 172 203 194 211 199 189 226 196 183 202 209 190 221 187 193 184 216 213 220 224 182 210 184 221 182 191 204 195 192 213 234 187 203 203 224 183 212 204 209 184 195 242 214 180 195 200 197 201 180 220 170 199 182 196 182 171 235 215 204 220 198 192 210 199 198 209 201 198 189 208 199 192 198 209 181 215 225 209 172 193 184 213 189 190 171 200 181 200 178 201 200 214 223 191 197 174 189 191 197 175 191 211 197 230 186 187 196 217 211 183 219 211 200 181 203 207 183 179 204 215 199 217 184 212 216 200 172 195 220 224 195 202 217 202 193 185 205 219 213 179 183 193 197 211 197 195 193 210 192 188 184 196 201 206 212 198 184 184 173 203 222 185 191 176 204 227 224 199 228 205 212 180 200 213 205 209 208 202 187 202 209 210 204 178 189 197 226 224 207 206 199 185 225 187 198 206 209 189 189 208 234 213 189 213 189 208 221 231 229 187 207 196 202 185 191 202 208 202 208 197 173 207 203 190 219 235 193 200 213 204 184 182 198 208 206 182 186 175 201 190 214 206 205 199 199 205 181 204 200 199 210 183 188 201 217 214 205 211 177 207 213 202 217 194 194 189 218 223 195 199 175 220 182 206 187 199 208 220 195 199 208 198 208 213 220 187 220 184 209 197 200 201 207 219 190 175 197 180 225 229 231 193 185 228 168 194 220 200 202 194 222 202 224 206 190 191 189 192 211 187 179 207 214 226 213 223 207 196 182 186 209 186 183 213 170 218 203 195 200 200 178 198 195 203 207 206 182 200 226 197 172 194 184 218 213 193 185 216 221 196 189 188 213 212 217 202 196 211 188 222 234 207 226 223 187 200 206 167 218 212 207 175 189 202 205 215 199 212 192 210 201 195 194 174 199 201 211 203 238 208 197 198 207 179 207 189 222 206 184 204 195 202 198 229 215 226 200 174 204 202 216 220 201 205 200 207 195 192 186 199 175 192 203 213 216 207 183 195 210 189 185 191 195 216 192 185 226 194 192 208 234 191 211 178 222 191 198 214 220 186 211 214 210 243 201 218 241 200 208 220 195 225 221 201 212 217 212 239 191 239 193 197 242 194 201 211 232 206 210 208 197 191 212 220 207 212 224 237 267 211 232 242 219 219 210 210 234 231 237 244 241 222 202 222 227 230 211 195 249 248 238 217 238 207 210 212 221 212 235 223 262 226 231 217 211 233 227 219 216 228 226 238 239 243 225 242 228 220 219 203 219 216 196 205 227 184 195 215 180 189 214 226 213 215 242 234 218 198 204 242 209 205 206 220 192 242 223 201 210 215 215 187 215 177 195 219 213 193 195 214 208 179 186 193 177 206 230 190 184 240 202 211 206 208 215 192 209 187 187 180 185 200 203 220 199 221 207 201 180 204 203 200 209 223 209 215 224 216 223 199 237 207 192 224 206 191 223 200 189 207 188 214 209 169 223 208 218 203 206 197 192 174 210 209 211 196 191 205 192 209 202 187 223 197 186 229 198 199 198 205 213 197 185 205 191 206 195 201 216 228 202 184 182 188 200 207 192 192 195 174 184 201 188 191 188 194 190 197 193 187 178 194 187 197 197 203 198 185 179 200 171 200 195 200 220 204 208 197 205 200 208 190 187 210 190 208 209 197 164 201 193 200 193 187 191 193 210 191 194 205 205 188 204 185 228 193 209 195 202 199 205 191 202 228 187 206 216 188 210 186 176 192 190 202 188 173 196 199 198 204 200 183 220 197 213 185 208 212 189 201 207 215 204 197 175 193 181 205 188 219 190 206 203 219 217 204 190 194 185 216 208 165 200 215 195 195 191 208 193 186 171 180 196 208 209 187 203 200 204 191 181 211 192 201 237 185 187 211 195 205 180 192 175 193 208 213 239 173 192 198 184 213 189 195 208 215 213 183 189 213 207 191 198 178 201 216 207 184 220 208 197 226 194 169 195 174 193 196 212 191 208 192 196 178 231 205 186 184 203 203 205 211 198 194 197 194 180 182 195 184 199 172 198 214 197 210 177 192 178 167 214 196 198 208 194 189 187 160 173 205 196 195 198 209 213 189 206 209 198 189 221 218 192 177 204 191 207 186 179 203 189 219 216 196 226 203 195 182 185 216 213 212 193 210 220 199 200 206 189 207 227 176 198 174 185 203 202 193 193 204 176 170 217 200 206 195 222 197 201 204 194 206 194 200 169 168 223 201 172 185 173 181 147 193 207 200 203 198 214 193 189 180 207 193 192 187 198 210 208 200 164 205 207 206 198 198 184 188 196 196 184 204 190 188 220 211 171 167 233 218 219 178 175 172 216 217 206 187 175 207 185 212 198 185 204 176 198 193 180 207 188 186 213 171 191 182 196 186 182 203 210 194 199 177 216 190 195 190 219 205 183 202 193 192 170 192 194 212 222 194 197 203 188 199 195 215 242 206 188 189 211 208 206 204 195 194 184 206 196 206 188 202 185 195 196 195 189 178 214 197 210 219 193 184 214 198 184 234 211 198 195 172 175 210 198 194 222 189 183 187 179 179 187 217 194 187 193 195 202 205 208 189 200 219 200 191 204 191 171 183 203 188 180 179 245 194 201 207 201 202 190 164 191 208 200 187 220 189 227 227 208 183 208 185 180 187 191 196 192 193 187 170 208 207 196 193 185 205 192 184 190 189 241 204 187 194 182 173 181 211 177 203 199 190 166 183 192 177 199 197 221 179 199 199 199 191 213 216 195 182 192 196 197 192 206 188 199 193 201 199 189 211 188 191 154 180 188 192 191 209 193 188 208 202 185 202 202 183 190 201 196 194 198 198 203 206 182 193 232 184 200 214 190 199 209 198 179 193 191 190 183 200 212 197 177 182 185 196 187 181 196 177 215 209 209 192 179 177 177 195 187 192 207 197 208 166 185 208 173 195 162 212 203 191 203 191 193 198 193 233 204 204 198 189 186 181 173 178 188 196 172 214 191 200 199 204 191 192 216 183 181 174 176 188 201 206 186 193 176 179 190 184 189 199 181 168 217 198 177 189 213 172 184 198 166 194 168 194 199 221 200 209 189 168 176 194 202 190 181 204 215 170 189 176 200 208 181 198 188 200 210 217 189 192 194 212 193 173 175 182 229 196 180 196 205 188 181 185 169 209 192 181 224 191 158 177 174 187 196 184 188 213 206 208 178 178 178 205 206 159 191 183 180 197 204 187 175 217 207 193 199 180 182 221 186 186 202 212 192 177 190 214 210 192 200 186 187 163 189 186 194 224 200 168 173 203 222 179 200 208 178 208 178 176 183 199 214 220 180 214 205 185 168 185 186 171 185 195 175 201 175 192 213 184 173 194 206 184 178 205 204 192 194 178 211 194 193 188 190 183 168 193 187 165 191 198 200 171 202 202 203 183 214 198 188 200 177 192 201 199 180 201 176 214 216 196 164 196 195 189 187 194 207 191 201 180 175 175 184 187 199 190 199 172 209 197 209 201 180 179 191 187 173 202 184 172 203 172 206 203 177 210 195 178 208 173 206 198 191 192 185 190 179 197 207 197 193 194 185 187 166 177 190 198 192 186 183 191 190 176 186 210 199 172 185 191 174 178 192 195 203 191 195 202 214 171 194 179 183 193 193 170 201 172 182 183 166 190 181 196 192 191 182 210 198 198 198 207 202 175 185 196 199 198 181 187 179 192 175 202 195 206 214 187 210 191 188 196 215 206 182 198 173 178 217 187 199 208 191 197 200 173 171 177 215 190 195 187 182 212 189 182 203 183 181 190 205 203 192 181 202 180 193 181 193 199 179 179 195 190 189 178 188 220 192 187 191 208 184 188 173 187 185 172 179 171 178 200 200 203 188 175 181 204 194 205 182 182 174 163 170 204 192 207 191 185 217 177 205 226 164 196 232 172 183 189 195 199 201 220 191 183 191 187 201 187 188 193 198 180 191 224 202 173 183 186 183 192 186 185 200 208 189 175 174 185 186 186 195 178 207 190 159 200 194 191 207 207 196 201 190 198 188 190 192 182 189 190 183 192 182 194 177 173 187 156 183 203 180 185 189 174 202 182 201 196 205 198 185 199 199 207 202 187 207 221 208 180 160 173 168 186 215 191 209 221 229 202 186 157 175 178 219 197 187 202 205 202 190 180 197 194 199 199 217 167 196 219 190 180 194 205 194 193 186 158 210 197 184 204 163 193 179 197 174 178 187 183 184 188 212 212 194 175 172 185 176 179 195 182 199 218 214 205 210 193 189 194 200 178 200 203 192 199 195 188 181 215 208 201 190 183 229 191 230 172 209 193 181 183 192 205 186 167 167 204 184 200 200 197 205 173 208 184 190 177 219 197 193 182 189 167 198 197 208 176 213 182 190 205 171 213 173 197 161 206 207 176 191 207 200 176 220 201 179 206 197 207 209 194 181 212 209 167 197 188 193 204 199 169 201 166 191 192 197 186 183 194 193 175 192 197 176 204 176 213 206 184 199 198 194 199 198 189 203 160 181 196 190 171 188 191 180 190 188 187 190 205 201 173 181 201 179 210 181 179 202 187 188 193 183 160 202 194 177 187 206 183 180 205 193 191 191 207 183 188 187 181 181 185 192 199 192 169 187 184 193 223 179 195 193 177 194 183 241 181 186 203 193 168 208 193 183 213 203 197 223 185 194 191 194 185 198 183 191 163 233 220 208 191 202 192 202 174 185 167 175 177 193 204 205 182 197 187 175 214 200 186 243 222 182 197 193 199 232 171 170 208 179 198 208 207 190 186 182 207 185 194 195 186 212 198 182 185 183 166 192 195 193 228 211 191 199 200 197 183 204 196 179 198 199 205 198 208 176 186 188 187 203 211 199 219 208 197 213 205 202 157 193 169 189 171 212 205 174 165 211 187 198 186 181 182 180 221 199 193 210 188 207 205 213 197 211 192 186 197 232 211 210 220 195 202 188 194 179 207 194 202 198 205 207 197 197 196 211 181 187 199 218 211 221 225 221 162 198 225 226 231 195 204 197 167 237 185 202 193 208 205 180 212 207 185 227 168 184 191 206 201 201 218 200 196 189 214 192 198 186 185 190 184 155 198 202 208 189 209 189 177 193 219 194 199 207 190 203 190 211 178 176 172 201 191 182 194 203 212 185 168 198 217 205 230 210 197 177 199 157 205 185 185 175 208 180 213 216 177 174 201 165 190 211 224 203 185 196 180 232 208 200 192 206 202 205 203 197 183 182 189 191 188 174 184 198 192 194 208 213 184 174 178 177 197 218 182 165 207 169 204 168 188 205 201 187 214 213 200 197 182 186 208 225 167 190 200 195 174 198 182 202 167 202 173 201 210 207 202 191 193 188 218 206 171 191 169 177 215 181 167 173 222 190 185 178 181 182 201 197 186 221 205 178 214 198 179 194 201 190 189 217 204 202 184 191 174 186 177 184 177 198 213 165 189 199 197 215 215 211 204 185 188 184 210 195 207 182 188 188 200 189 200 186 217 171 187 169 193 189 175 166 192 212 196 184 199 200 188 187 169 210 214 214 216 190 178 183 199 209 191 187 182 164 208 171 179 181 206 171 183 173 231 193 190 191 183 187 191 187 184 182 189 199 188 185 197 203 198 186 175 192 190 176 190 193 186 192 197 207 183 181 175 215 188 196 183 192 200 184 189 172 179 172 181 184 199 195 184 187 183 172 185 181 196 195 176 200 180 207 201 200 193 210 183 173 176 195 188 173 182 189 193 194 207 217 214 177 196 171 204 194 178 202 185 196 194 190 163 222 202 206 189 209 200 181 190 179 186 180 201 198 172 182 183 218 223 190 189 170 191 182 190 182 198 166 186 208 164 204 177 173 231 220 214 194 207 208 168 188 196 166 205 199 187 195 193 190 172 194 209 209 185 195 173 209 200 202 189 167 188 210 197 187 204 185 191 194 166 209 175 195 193 181 177 213 188 179 176 180 193 191 163 203 213 178 180 201 238 192 197 182 217 216 207 209 162 193 183 220 178 206 198 190 173 200 186 181 196 172 199 198 182 186 206 187 192 171 167 205 204 191 219 177 192 198 198 207 182 188 187 220 193 183 182 178 165 216 188 195 209 192 175 188 190 191 180 198 197 174 192 183 186 189 184 206 205 160 193 189 212 230 175 184 205 184 209 183 198 197 180 186 175 205 180 179 168 195 208 182 205 210 194 190 213 198 197 192 181 210 206 193 210 216 196 192 191 187 194 207 196 180 197 191 178 185 185 198 175 183 191 206 187 193 174 180 189 210 188 205 192 192 203 163 185 188 193 197 182 173 215 178 182 207 208 200 168 182 220 195 206 179 173 172 186 203 177 194 207 186 183 191 187 194 186 169 204 194 206 191 178 184 202 198 176 180 161 199 217 199 200 212 209 182 212 209 185 191 189 180 176 194 193 176 200 171 192 202 197 197 214 195 202 182 184 210 197 198 176 203 166 211 209 179 210 193 187 204 192 191 173 189 209 195 164 176 187 181 224 201 217 196 194 215 196 221 196 194 188 205 165 190 199 188 168 179 182 192 181 218 183 204 187 173 196 198 163 182 197 195 181 193 194 199 183 185 177 196 196 202 180 201 185 194 199 190 195 214 204 220 186 212 216 182 192 175 212 198 206 193 182 202 182 192 196 188 203 199 165 179 209 184 212 184 198 205 183 194 210 203 227 177 182 206 204 217 196 184 193 187 160 233 181 175 191 206 191 188 202 181 178 221 183 193 179 212 203 179 179 196 181 174 189 216 193 195 205 198 200 190 183 174 191 222 192 174 207 188 212 198 189 179 163 167 170 202 204 195 188 208 192 192 200 210 205 204 220 180 214 200 193 186 172 209 190 200 195 199 204 185 184 187 177 201 174 200 212 190 197 185 177 195 197 209 184 201 188 146 197 187 192 222 177 199 208 217 175 211 196 194 193 191 207 195 186 205 185 178 180 207 176 202 212 187 182 171 177 199 186 187 200 171 197 211 196 211 188 166 195 194 196 179 167 170 185 217 202 185 194 182 191 199 178 191 188 197 200 190 205 194 219 190 194 224 194 201 195 188 201 175 223 177 186 176 197 185 184 199 191 186 184 170 199 174 200 222 176 193 185 207 182 196 202 197 175 202 167 191 187 188 165 213 190 196 176 213 192 197 183 190 198 182 208 193 172 195 196 185 200 200 185 166 200 178 205 192 164 187 186 193 175 195 195 178 185 193 187 174 175 184 192 202 192 194 214 187 194 204 233 194 185 216 218 181 185 191 197 192 183 169 200 183 188 188 184 175 196 183 192 219 180 185 176 190 183 195 192 167 201 195 210 155 184 184 209 188 191 184 202 208 200 208 168 226 209 208 195 200 196 179 176 202 192 196 174 183 189 200 215 186 187 188 180 179 173 204 178 172 164 203 192 191 187 194 215 185 220 198 201 173 205 187 188 196 214 192 184 186 186 203 191 186 187 197 204 197 197 179 197 198 171 165 161 178 220 188 187 202 171 180 209 197 187 175 195 193 172 202 179 197 204 182 186 202 180 210 179 211 175 202 207 204 205 166 171 172 193 205 224 183 210 190 201 200 184 194 200 187 185 189 190 175 189 184 197 210 186 182 186 186 189 218 181 179 198 204 183 200 187 188 177 180 195 174 185 192 186 198 198 177 189 170 192 186 211 181 209 196 189 176 171 199 172 183 169 210 187 167 195 198 173 207 181 182 172 173 174 198 184 202 202 158 162 198 192 207 199 190 189 211 176 178 182 166 186 175 185 180 194 197 188 165 180 189 187 186 178 183 183 195 195 180 189 185 211 180 212 185 184 193 184 199 185 207 197 183 211 181 178 174 160 203 183 194 176 188 190 197 217 195 180 169 211 204 204 198 209 208 195 192 177 221 172 209 195 195 197 165 181 195 186 188 170 176 178 187 174 211 177 213 208 193 180 180 213 195 180 203 178 205 171 196 215 178 172 207 181 203 202 192 187 207 142 154 195 181 182 197 174 173 187 188 189 203 202 213 180 195 190 217 195 165 205 195 197 220 183 227 197 191 182 206 212 210 205 189 191 159 180 170 207 200 212 206 180 174 186 181 196 185 191 217 183 204 189 187 140 207 200 190 193 193 180 180 165 189 212 176 194 204 229 168 190 179 178 191 180 201 202 187 186 182 191 185 235 213 193 189 179 215 179 178 197 181 214 181 188 171 186 179 185 184 202 188 182 189 206 162 207 193 197 212 196 178 206 174 199 198 196 210 190 195 207 194 181 184 179 192 193 194 187 175 184 192 191 179 182 171 177 188 200 207 188 190 204 176 193 160 173 182 161 192 207 202 191 178 206 180 214 206 190 181 197 194 172 191 187 180 199 199 202 202 209 208 217 160 212 191 204 200 182 196 205 188 190 157 180 180 196 214 169 197 201 201 202 159 182 204 193 197 180 165 206 171 182 183 180 198 202 167 195 207 197 199 192 175 199 180 208 205 198 195 202 193 178 184 195 181 196 192 194 175 181 214 181 165 169 200 194 192 209 174 184 216 194 208 179 218 205 213 190 177 207 218 177 193 193 179 209 199 212 192 199 217 206 180 184 215 195 208 184 178 209 197 183 171 198 177 180 201 182 188 193 193 190 195 172 208 178 184 188 175 190 204 178 218 188 206 177 205 204 172 186 189 191 175 189 159 177 214 176 184 220 174 195 205 198 209 222 219 170 174 223 197 182 201 232 201 190 228 186 224 214 167 211 188 193 206 204 208 181 201 182 204 203 202 217 187 200 181 183 209 175 192 202 198 192 213 164 175 195 227 202 186 193 183 206 207 180 208 203 175 217 195 197 228 182 214 192 191 203 221 202 212 215 204 207 177 172 216 191 209 200 193 229 188 183 222 203 209 210 179 207 215 184 196 188 191 185 200 198 200 213 185 193 193 204 188 218 198 193 200 184 204 193 182 189 205 213 188 212 216 197 229 191 226 190 193 201 210 197 191 187 212 187 188 219 208 194 224 229 203 237 229 223 180 191 201 216 196 211 243 172 209 205 205 215 179 192 204 187 193 223 196 187 200 196 221 203 202 195 198 210 202 224 193 192 214 217 202 210 214 200 192 199 202 192 206 208 215 213 204 220 187 184 217 194 196 216 208 217 203 186 195 183 192 175 214 206 215 190 211 219 201 208 200 190 226 205 185 232 200 192 177 202 212 231 188 186 178 203 174 213 195 211 187 211 178 187 204 207 167 206 196 188 193 207 192 193 184 210 205 213 226 197 179 174 199 187 207 187 198 200 186 175 185 209 191 195 200 212 208 182 190 211 208 185 193 206 214 187 200 194 196 201 206 198 205 191 183 211 210 194 199 209 197 194 205 193 182 176 215 204 189 196 164 194 191 188 232 199 190 187 198 177 198 195 196 175 211 183 177 192 179 216 180 215 173 184 183 214 210 200 208 189 184 186 184 201 193 177 181 188 185 176 184 187 165 189 202 203 194 189 191 200 173 211 163 210 191 195 191 188 197 179 200 193 200 191 172 193 182 204 202 216 186 178 197 194 188 190 170 197 179 208 196 195 182 202 168 159 180 173 185 173 180 176 198 196 187 213 173 169 190 189 197 172 200 146 191 208 201 202 193 210 181 201 205 221 187 179 172 191 191 188 192 171 204 187 217 205 194 196 200 214 215 204 174 203 202 165 226 198 186 199 196 192 168 206 207 214 199 203 183 184 187 173 195 188 183 202 187 186 196 191 175 160 203 178 202 211 198 179 198 190 176 195 172 206 185 184 190 203 218 175 188 186 172 171 197 188 224 186 210 186 178 195 205 172 171 193 183 192 193 182 208 188 192 188 179 184 180 179 208 208 200 192 209 200 187 181 190 197 192 189 199 208 188 190 185 172 200 195 176 175 194 226 180 160 225 190 187 189 195 194 187 209 197 172 170 213 194 193 196 166 215 199 215 192 185 202 221 181 192 186 191 173 173 214 194 194 210 173 205 217 192 227 200 178 213 196 194 197 201 193 193 206 200 188 201 192 182 174 196 213 175 207 214 178 198 201 202 188 192 181 188 206 174 191 203 189 221 191 180 195 209 204 198 199 203 182 187 193 192 212 190 208 187 194 186 186 205 190 196 187 227 171 191 199 206 208 201 191 185 195 221 174 190 197 212 186 182 180 189 188 193 192 173 189 186 199 206 203 202 210 197 182 219 192 204 195 192 189 207 193 182 191 198 189 182 225 176 199 196 196 198 186 186 199 192 183 219 162 185 192 196 184 182 208 192 200 203 198 190 200 187 182 170 207 193 205 165 193 189 176 212 185 175 199 211 155 201 187 199 180 194 181 211 178 188 203 193 170 199 205 191 200 187 195 206 189 190 167 192 186 212 173 199 204 213 199 183 197 211 164 213 205 160 203 197 224 196 208 190 179 206 195 181 203 205 181 195 206 167 185 174 172 194 188 209 175 189 194 196 190 175 191 208 201 181 190 186 189 188 174 209 191 205 199 198 203 190 188 198 187 197 206 189 209 190 177 172 189 195 190 206 203 197 172 184 197 204 186 210 202 185 194 167 198 176 199 209 184 193 179 169 210 202 196 194 211 184 205 182 189 211 173 198 183 196 191 208 193 172 188 202 182 189 215 201 202 221 198 195 182 214 185 202 193 170 191 189 188 176 188 166 216 195 187 210 185 188 222 197 192 190 190 182 187 185 176 202 185 199 215 193 181 222 175 177 199 199 191 203 211 194 206 203 205 198 207 211 179 216 204 188 186 187 183 203 190 181 177 195 210 180 190 187 188 162 176 205 186 201 200 196 199 186 193 206 192 243 222 223 202 193 190 199 205 196 203 189 200 197 173 200 206 193 210 185 204 197 213 216 209 200 187 206 204 179 205 215 206 176 179 218 199 193 195 177 206 213 192 198 174 193 189 214 204 197 202 191 191 184 185 180 215 199 179 187 208 203 201 200 198 197 202 184 177 191 203 201 201 195 201 178 189 184 201 194 205 190 175 187 193 190 206 188 193 190 206 213 191 175 172 189 202 202 166 195 220 207 182 194 171 190 207 194 178 227 184 198 214 187 210 206 204 173 229 189 185 209 191 208 191 177 185 197 178 186 208 196 194 181 158 178 213 192 169 187 202 175 190 197 191 196 181 201 183 201 211 184 171 219 205 197 191 198 204 180 211 215 202 208 203 207 193 215 192 194 178 206 213 200 190 181 195 201 177 172 204 176 176 204 202 205 198 195 197 191 174 207 214 196 181 177 209 201 194 210 197 218 194 172 197 198 193 196 203 194 173 200 170 169 181 193 194 209 180 188 203 213 200 192 176 186 218 200 198 209 183 176 191 213 208 194 199 201 194 161 209 212 180 196 200 186 198 198 194 217 208 187 191 185 211 194 189 193 173 198 204 175 198 210 193 206 182 193 200 186 197 195 187 199 177 192 181 193 178 203 149 187 222 183 190 220 208 204 201 201 214 194 185 203 170 190 202 175 192 198 182 190 202 168 179 199 168 165 188 199 194 185 187 200 203 174 214 211 219 184 204 193 185 191 215 213 195 201 172 224 192 185 212 191 197 191 167 183 205 214 201 211 206 203 192 176 180 200 179 186 205 215 171 215 214 199 190 214 191 194 209 198 175 209 176 198 193 200 233 209 201 207 197 184 200 176 187 173 186 200 204 188 215 186 202 222 207 203 193 213 160 210 191 201 213 196 188 220 203 187 197 209 183 198 199 210 223 200 195 188 189 192 188 197 188 209 175 230 203 201 184 197 201 191 186 197 161 203 180 190 206 178 203 187 185 202 178 220 204 197 180 187 186 181 197 197 194 189 200 192 187 180 207 188 192 213 215 196 229 175 222 179 188 200 200 191 176 179 202 179 212 196 174 186 190 212 178 189 197 186 219 202 179 189 197 186 173 197 195 182 190 190 202 194 203 220 198 174 178 187 184 210 189 185 213 203 186 196 189 192 175 208 195 209 190 198 186 191 184 191 236 166 192 204 178 188 217 201 192 201 189 186 190 173 214 194 189 191 203 187 197 197 200 162 191 212 190 182 197 230 189 196 213 174 180 200 165 207 213 201 183 200 205 202 198 168 154 183 205 187 192 200 209 197 179 237 190 200 191 187 172 181 199 211 191 185 188 179 210 192 198 234 179 198 194 206 201 200 176 180 194 160 171 189 197 180 185 197 171 207 178 210 180 190 186 199 202 170 213 164 182</counts>
			</dataPoints>
		</scan>
	</xrdMeasurement>
</xrdMeasurements>