File: data/XRD/XG-Vakuum/XG-pre/W6823-1C_XG_Vakuum_pre.xrdml
<xrdMeasurements xmlns="http://www.xrdml.com/XRDMeasurement/2.1" xmlns:xsi="http://www.w3.org/2001/XMLSchema-instance" xsi:schemaLocation="http://www.xrdml.com/XRDMeasurement/2.1 http://www.xrdml.com/XRDMeasurement/2.1/XRDMeasurement.xsd" status="Completed">
	<comment>
		<entry>Configuration=Factory configuration, Owner=User-1, Creation date=7/8/2013 4:01:53 PM</entry>
		<entry>Goniometer=PW3050/65 (Theta/2Theta); Minimum step size 2Theta:0.0001; Minimum step size Omega:0.0001</entry>
		<entry>Sample stage=MRD Cradle; Minimum step size Phi:0.01; Minimum step size Chi:0.01; Minimum step size X:0.01; Minimum step size Y:0.01; Minimum step size Z:0.001</entry>
		<entry>Diffractometer system=XPERT-PRO</entry>
		<entry>Measurement program=C:\PANalytical\Data Collector\Programs\Jorrit\2thom\_absolute_2th-om_10-130deg_PIXscan_56min.xrdmp, Identifier={15BCCF57-2807-42BD-B5B9-ECC0B3DC9284}</entry>
		<entry>Batch program=C:\PANalytical\Data Collector\Programs\SimonL\batch8x_2thom_10-130°_z9.1_x0,10,20,30_y20,30,40,50_57min.xrdmp, Identifier={9A1B954C-70C5-4DE2-A2B5-D0000261ED0F}</entry>
	</comment>
	<sample type="To be analyzed">
		<id></id>
		<name></name>
		<preparedBy></preparedBy>
	</sample>
	<xrdMeasurement measurementType="Scan" status="Completed" sampleMode="Reflection">
		<comment>
			<entry>_absolute_2th-om_10-130deg_PIXscan_56min</entry>
			<entry>PHD Lower Level = 4.83 (keV), PHD Upper Level = 11.27 (keV)</entry>
		</comment>
		<usedWavelength intended="K-Alpha 1">
			<kAlpha1 unit="Angstrom">1.5405980</kAlpha1>
			<kAlpha2 unit="Angstrom">1.5444260</kAlpha2>
			<kBeta unit="Angstrom">1.3922500</kBeta>
			<ratioKAlpha2KAlpha1>0.5000</ratioKAlpha2KAlpha1>
		</usedWavelength>
		<incidentBeamPath>
			<radius unit="mm">320.00</radius>
			<xRayTube id="1010048" name="Empyrean Cu LFF HR (9430 033 7310x) DK442154">
				<tension unit="kV">40.0</tension>
				<current unit="mA">40.0</current>
				<anodeMaterial>Cu</anodeMaterial>
				<focus type="Line">
					<length unit="mm">12.0</length>
					<width unit="mm">0.4</width>
					<takeOffAngle unit="deg">4.2</takeOffAngle>
				</focus>
			</xRayTube>
			<xRayMirror id="27010001" name="Inc. Beam Cu W/Si (parabolic MRD)" hybrid="false">
				<crystal type="Graded" shape="Parabolic">W/Si</crystal>
				<acceptanceAngle unit="deg">0.800</acceptanceAngle>
				<length unit="mm">60.0</length>
			</xRayMirror>
			<sollerSlit id="21010002" name="Soller slits 0.04 rad.">
				<opening unit="rad">0.0400</opening>
			</sollerSlit>
			<mask id="22030008" name="Fixed mask 4 mm">
				<distanceToSample unit="mm">220.00</distanceToSample>
				<width unit="mm">4.00</width>
			</mask>
			<divergenceSlit id="22010007" name="Fixed slit 1/8°" xsi:type="fixedDivergenceSlitType">
				<distanceToSample unit="mm">220.00</distanceToSample>
				<height unit="mm">0.19</height>
			</divergenceSlit>
		</incidentBeamPath>
		<diffractedBeamPath>
			<radius unit="mm">320.00</radius>
			<sollerSlit id="21010002" name="Soller slits 0.04 rad.">
				<opening unit="rad">0.0400</opening>
			</sollerSlit>
			<receivingSlit id="22010001" name="Fixed slit 4°">
				<height unit="mm">5.88</height>
			</receivingSlit>
			<detector id="7010017" name="PIXcel3D 1x1 detector" xsi:type="areaDetectorType">
				<phd unit="%">
					<lowerLevel>30.0</lowerLevel>
					<upperLevel>70.0</upperLevel>
				</phd>
				<mode>Scanning</mode>
				<activeChannelsEquatorial>255</activeChannelsEquatorial>
				<activeChannelsAxial>255</activeChannelsAxial>
				<pitchEquatorial unit="mm">0.05500</pitchEquatorial>
				<pitchAxial unit="mm">0.05500</pitchAxial>
				<readOutPeriod unit="seconds">0.135</readOutPeriod>
			</detector>
		</diffractedBeamPath>
		<scan appendNumber="0" mode="Continuous" scanAxis="2Theta-Omega" status="Completed">
			<header>
				<startTimeStamp>2024-10-04T09:21:20+02:00</startTimeStamp>
				<endTimeStamp>2024-10-04T10:17:26+02:00</endTimeStamp>
				<author>
					<name>PRO-MRD</name>
				</author>
				<source>
					<applicationSoftware version="6.1b">Data Collector</applicationSoftware>
					<instrumentControlSoftware version="7.0E 20130304">XPERT-PRO</instrumentControlSoftware>
					<instrumentID>0000000011142674</instrumentID>
				</source>
			</header>
			<dataPoints>
				<positions axis="2Theta" unit="deg">
					<startPosition>9.99826193</startPosition>
					<endPosition>129.99755682</endPosition>
				</positions>
				<positions axis="Omega" unit="deg">
					<startPosition>4.99913096</startPosition>
					<endPosition>64.99877841</endPosition>
				</positions>
				<positions axis="Phi" unit="deg">
					<commonPosition>0.00</commonPosition>
				</positions>
				<positions axis="Chi" unit="deg">
					<commonPosition>0.00</commonPosition>
				</positions>
				<positions axis="X" unit="mm">
					<commonPosition>20.00</commonPosition>
				</positions>
				<positions axis="Y" unit="mm">
					<commonPosition>0.00</commonPosition>
				</positions>
				<positions axis="Z" unit="mm">
					<commonPosition>9.100</commonPosition>
				</positions>
				<commonCountingTime unit="seconds">32.895</commonCountingTime>
				<counts 405 441 404 380 428 423 401 383 426 399 393 439 376 411 427 421 388 396 412 371 430 436 407 406 417 416 406 395 391 420 421 378 426 432 437 396 424 453 402 416 406 414 396 443 413 409 460 402 395 431 445 454 431 454 402 410 428 440 408 387 372 408 396 373 445 389 400 392 396 432 383 437 399 375 378 418 406 398 394 423 403 400 398 398 382 429 394 410 379 401 390 388 408 431 405 387 411 394 422 389 402 379 400 405 370 370 393 400 405 381 390 404 413 424 417 408 388 393 399 377 379 389 377 418 398 362 364 414 410 373 407 440 378 390 411 399 405 359 378 425 393 371 358 400 390 398 389 410 430 415 379 401 351 399 383 374 380 386 390 391 375 389 366 371 433 376 384 388 385 385 405 394 377 359 394 412 374 378 371 414 393 426 385 410 359 396 402 397 374 381 413 388 382 388 425 396 403 387 411 387 391 350 421 384 389 388 384 385 373 360 370 394 410 369 378 367 400 373 371 391 359 440 397 397 368 340 383 365 375 355 382 395 373 398 351 359 396 345 343 399 337 377 409 388 373 364 375 361 384 408 374 377 394 423 373 395 340 392 320 378 392 379 373 388 373 368 404 394 367 412 397 366 385 389 366 369 382 393 371 371 441 377 344 385 378 373 353 377 384 318 367 334 356 361 373 346 334 362 378 364 411 362 377 346 383 356 389 363 359 353 342 371 354 372 374 382 341 334 353 330 354 349 364 365 337 362 370 382 383 361 389 331 371 340 350 348 375 376 372 380 394 338 393 357 363 360 348 338 355 350 375 339 375 318 370 343 340 326 338 360 355 385 363 350 346 365 327 335 353 339 389 390 372 356 375 364 341 357 388 323 369 345 362 333 332 358 367 353 354 348 360 361 334 334 336 337 345 338 359 363 329 358 347 332 371 363 295 388 356 325 311 332 355 350 349 350 323 323 323 349 343 353 351 371 305 311 398 330 345 340 347 345 323 322 323 366 365 328 352 355 322 351 340 332 348 356 340 296 318 334 349 331 320 359 304 338 343 351 320 373 356 358 371 346 333 310 344 312 340 328 371 317 365 355 316 333 346 337 326 360 351 297 337 327 360 366 350 343 335 326 367 351 341 326 368 343 320 364 351 340 364 319 343 333 336 317 325 367 360 314 322 305 326 335 308 320 348 345 331 317 330 329 353 316 343 338 328 347 357 344 294 343 322 313 371 350 318 328 339 326 324 342 333 359 336 347 333 341 349 365 334 301 368 357 317 326 317 330 316 336 328 305 314 331 355 309 319 339 357 330 335 321 304 327 306 326 343 319 344 314 318 281 339 341 319 340 330 320 345 307 321 307 339 305 322 311 308 319 341 319 323 284 335 335 315 298 374 336 329 321 307 321 348 339 343 330 321 330 324 323 328 319 355 330 346 339 367 328 322 341 327 310 317 316 326 315 373 312 329 383 344 310 302 299 315 326 340 330 310 343 343 320 334 318 297 307 340 325 355 320 325 344 351 320 327 334 316 351 345 313 341 340 329 334 314 319 315 305 295 317 345 282 312 324 324 335 330 310 302 310 339 338 350 319 310 356 327 335 360 307 302 304 337 292 324 331 359 359 354 341 302 316 305 300 281 313 336 337 333 355 319 303 318 320 345 353 330 339 332 347 313 301 364 345 355 322 331 326 298 366 342 321 352 323 301 301 315 318 313 316 352 374 369 334 349 319 310 333 351 304 358 342 354 310 330 325 315 289 299 336 320 330 352 308 313 319 351 328 325 329 308 338 329 341 349 333 307 328 345 341 346 330 317 356 324 345 335 332 342 312 349 329 325 328 311 360 363 362 333 333 329 335 351 352 319 348 321 351 334 328 358 331 339 322 350 348 343 370 339 327 366 354 333 327 341 352 337 343 353 325 359 331 391 358 345 336 360 372 344 325 332 366 351 325 328 379 332 343 355 352 312 335 330 341 332 332 358 315 338 324 332 317 331 322 325 345 353 344 324 370 342 347 347 326 344 366 349 335 314 342 334 339 295 338 310 324 323 340 345 365 356 329 321 325 332 339 334 356 337 317 346 382 310 327 339 342 403 365 349 326 366 340 387 351 379 357 334 345 320 347 334 326 368 369 311 349 331 352 339 360 366 377 290 344 301 331 340 349 364 349 333 356 320 362 326 361 386 341 347 359 362 354 349 370 336 354 346 365 358 362 316 356 396 327 341 370 329 313 334 348 318 375 364 320 328 355 379 345 351 340 325 353 319 339 336 351 319 344 353 340 327 333 355 339 331 370 358 358 342 315 366 344 382 306 329 366 306 327 335 337 387 304 329 338 347 349 338 371 298 351 337 343 365 382 347 362 327 351 367 370 354 341 338 368 334 338 326 338 335 361 311 321 315 358 339 357 322 339 352 355 364 364 332 311 381 378 325 311 341 306 339 343 325 357 346 355 356 352 329 351 333 381 322 318 363 349 352 337 345 330 370 326 348 328 336 346 304 315 350 392 326 349 353 369 324 327 385 374 345 327 336 360 315 365 361 335 327 358 359 338 367 369 365 364 340 357 339 368 366 357 337 336 362 327 345 356 349 346 367 303 341 316 345 361 357 343 331 390 362 364 349 352 335 343 347 347 342 337 310 337 343 370 350 363 380 375 360 320 343 332 360 340 357 370 322 348 342 363 351 385 355 357 334 365 359 343 360 367 325 359 356 335 365 345 354 333 321 343 360 351 341 342 348 325 358 383 350 333 358 357 319 355 373 343 366 346 337 372 360 348 339 336 376 333 315 323 363 363 354 345 340 325 324 359 361 374 324 366 342 353 327 375 350 373 341 364 360 333 356 333 355 362 372 352 378 353 348 383 370 354 327 326 365 367 374 345 376 369 344 349 343 319 313 335 323 322 343 354 340 332 338 351 370 347 380 356 356 362 367 351 334 364 378 339 337 359 344 361 379 380 351 359 331 360 357 311 356 368 384 343 310 362 335 349 370 350 340 320 327 365 385 348 382 358 342 341 359 327 351 336 322 328 349 302 343 358 346 352 359 351 343 337 358 350 352 356 357 353 355 365 366 374 369 378 348 381 354 328 324 338 350 330 319 332 363 331 344 341 374 337 326 348 349 302 341 340 359 362 314 342 355 354 338 343 341 345 327 298 328 358 358 352 340 365 371 366 359 332 358 355 379 361 337 304 355 368 351 372 337 359 324 357 356 328 346 337 334 350 339 361 365 327 338 328 351 358 331 341 325 331 375 336 333 323 346 332 321 350 355 341 352 338 353 327 339 303 368 355 346 324 333 316 338 376 374 317 381 355 350 351 360 336 352 369 361 354 347 348 351 331 332 357 335 313 316 356 301 352 338 348 329 306 332 389 343 318 347 332 378 347 319 328 341 348 339 295 368 322 328 336 362 340 323 350 311 360 338 332 346 314 348 322 305 332 311 356 334 332 323 322 313 330 343 305 340 368 350 341 342 363 375 340 383 269 321 334 313 323 341 345 333 326 295 296 333 319 351 335 321 327 343 300 314 342 330 307 316 318 335 291 346 343 350 301 316 306 336 334 342 324 304 308 325 330 324 339 337 283 318 314 342 324 319 311 346 321 315 324 349 335 301 330 313 322 319 322 308 327 320 297 316 334 315 328 329 319 316 296 307 311 312 323 338 324 292 335 315 304 321 278 315 319 332 329 315 308 337 306 359 317 319 314 305 296 312 324 319 306 293 339 321 315 305 307 304 329 274 303 307 286 293 312 332 333 295 318 291 322 318 294 322 279 304 292 342 317 311 317 328 302 341 287 312 330 309 264 305 302 301 321 286 240 343 318 300 296 277 299 294 296 286 312 301 295 294 327 306 284 317 293 322 334 289 259 310 279 275 280 330 316 293 300 316 287 303 287 336 339 289 304 307 303 311 292 290 286 284 283 292 282 286 310 269 343 297 284 309 299 280 279 288 314 315 306 283 280 287 328 312 286 262 267 293 277 299 272 318 317 283 282 280 291 309 312 272 297 266 277 320 269 292 316 280 296 261 300 317 307 246 280 309 276 266 286 287 307 287 271 244 290 242 294 308 247 291 290 312 328 299 298 290 308 284 324 309 296 278 272 303 283 305 286 247 286 249 269 279 295 292 300 303 289 297 260 279 285 271 284 261 286 268 323 285 277 276 288 280 276 272 255 264 294 291 316 278 300 275 293 269 302 302 305 287 305 282 323 266 270 302 289 298 300 304 278 262 280 262 299 238 281 281 282 302 282 293 279 286 320 255 295 265 323 294 304 273 266 284 268 266 280 278 291 300 294 275 285 268 293 279 286 275 277 294 268 249 268 256 255 269 297 260 268 279 261 266 283 273 245 247 261 264 295 276 246 280 261 284 264 280 272 249 285 223 237 272 283 258 240 258 261 297 287 257 256 275 280 266 298 288 278 267 264 272 299 244 273 286 250 284 263 249 261 241 245 284 259 263 274 242 260 237 248 232 231 260 267 257 240 286 288 242 261 281 274 271 293 273 284 256 270 261 259 246 272 247 247 293 266 244 227 288 260 275 267 280 281 276 240 263 241 290 269 241 238 250 259 301 243 240 236 228 257 234 247 257 262 263 261 245 270 258 268 244 244 276 245 262 275 257 235 260 263 256 235 241 223 220 247 262 226 246 242 237 243 235 224 266 243 261 268 269 247 229 266 246 239 246 259 261 263 247 259 257 235 244 234 261 239 256 240 275 273 226 281 261 261 242 234 259 276 240 237 287 268 244 244 301 270 216 265 234 242 266 255 261 292 238 236 223 284 258 235 257 250 265 237 258 262 249 222 269 244 246 266 267 235 243 219 249 245 248 236 260 233 226 208 214 223 242 241 269 240 259 266 238 279 248 219 240 263 231 223 236 269 228 256 232 241 257 242 229 246 234 269 222 249 260 224 227 256 216 239 263 256 250 275 228 222 220 215 229 266 248 244 257 269 227 242 242 248 262 221 221 269 239 258 212 270 238 259 244 220 238 245 239 239 223 219 249 230 240 266 244 256 261 228 258 227 271 240 238 215 240 226 259 232 273 245 233 246 223 235 232 244 259 229 204 260 212 231 249 269 212 268 241 257 234 237 256 231 265 259 229 221 224 218 231 283 258 264 263 219 230 236 237 283 223 210 225 205 265 216 261 231 259 244 225 249 260 227 232 259 255 261 220 206 228 232 234 207 262 237 271 270 212 229 236 236 224 229 235 266 265 230 238 238 218 243 225 260 245 263 200 233 210 237 243 257 226 242 223 225 206 273 213 231 237 223 270 218 250 236 266 256 225 265 234 200 230 217 244 246 226 280 226 215 274 221 243 223 235 235 248 250 263 223 242 256 229 244 250 256 250 228 246 230 243 245 209 235 217 243 247 240 219 235 234 236 236 233 179 262 228 218 219 216 271 242 244 256 214 257 239 246 274 261 227 240 240 228 232 218 237 231 244 225 222 214 235 258 224 223 220 222 272 227 247 214 233 261 241 225 225 231 222 241 213 244 232 200 233 245 242 227 230 232 226 219 248 209 240 215 235 226 218 221 244 234 221 247 240 238 240 240 238 226 238 225 221 240 230 230 262 206 226 244 240 213 223 246 219 232 237 223 235 234 239 228 225 207 246 242 230 239 232 228 277 230 201 203 204 195 214 240 219 210 238 228 212 214 248 250 245 213 233 241 237 219 215 238 241 193 242 208 240 202 225 235 220 242 218 236 219 242 222 221 234 213 240 242 221 232 203 219 241 236 243 210 217 236 217 223 245 232 240 200 242 213 205 229 255 219 221 237 218 200 255 230 223 224 239 220 241 221 236 211 238 232 215 208 244 218 258 240 232 225 230 237 227 223 230 202 221 220 222 259 225 235 215 232 205 218 227 231 242 207 209 237 224 218 215 231 196 228 230 211 242 256 221 226 213 202 228 240 213 233 213 228 219 231 204 229 213 233 231 230 249 241 196 229 231 209 189 234 229 199 231 218 242 216 235 235 210 208 204 264 214 228 257 221 204 215 203 248 246 238 226 231 232 215 266 240 238 226 231 218 222 207 222 219 230 231 213 246 209 245 218 207 219 220 211 230 211 192 226 215 211 214 219 233 214 200 249 230 220 239 225 225 231 271 207 237 209 195 267 193 261 236 227 208 261 203 221 205 234 230 223 198 215 218 232 221 223 191 245 237 222 255 248 224 228 207 213 249 234 221 218 215 230 266 222 229 227 265 233 247 215 195 229 226 194 213 240 231 234 229 212 226 227 218 232 231 237 198 221 234 224 249 202 218 241 229 193 245 248 245 235 223 236 222 227 256 257 236 227 234 189 250 220 210 249 219 263 199 263 200 234 233 219 237 208 212 221 240 232 259 213 226 229 219 221 237 237 227 224 204 224 227 225 234 243 228 219 225 225 219 243 213 219 234 231 231 217 211 231 219 225 201 228 217 213 246 256 217 218 217 225 237 199 202 232 222 241 215 238 207 190 234 246 224 229 224 210 224 229 243 239 215 195 223 201 219 220 240 216 195 239 227 239 213 230 239 225 231 208 227 207 206 231 228 207 217 228 219 233 227 213 231 224 238 200 211 200 224 219 227 225 256 186 240 230 233 227 232 228 238 215 228 227 216 226 239 247 212 235 230 240 187 217 221 203 228 204 227 240 204 210 206 209 239 185 211 239 222 205 231 236 259 217 206 272 202 208 250 210 235 227 212 209 228 215 246 226 219 198 244 220 243 214 195 221 212 243 225 224 235 211 219 228 236 240 211 208 220 211 225 198 265 225 230 227 210 213 228 226 230 233 223 216 232 239 214 205 220 229 211 221 201 241 221 210 213 207 250 223 216 220 222 216 217 233 224 222 230 242 278 220 247 219 240 227 213 219 230 235 239 214 234 219 200 211 237 213 216 213 228 216 202 206 210 249 208 241 257 240 207 225 225 233 238 218 218 236 238 232 245 219 208 221 221 208 240 239 236 225 229 231 242 260 211 223 232 226 262 239 226 225 214 219 203 235 226 228 267 241 229 244 207 255 222 218 233 258 237 237 240 229 210 223 229 232 210 221 240 241 237 229 239 229 243 224 225 229 247 238 226 213 226 223 223 214 234 241 203 259 230 223 277 214 211 197 234 242 246 228 241 258 268 235 232 276 226 258 232 227 218 228 221 242 205 225 198 226 233 221 219 273 258 232 226 215 209 205 203 268 229 230 214 237 221 267 233 218 236 243 224 213 220 231 232 235 225 256 243 223 230 218 255 220 239 260 259 241 239 230 237 235 207 238 204 223 215 226 221 226 234 241 237 234 191 256 220 220 218 246 227 232 202 229 202 214 226 221 232 215 211 211 209 238 226 231 220 226 237 206 233 213 218 211 217 219 240 232 228 248 216 243 237 245 234 226 200 210 215 215 214 229 241 217 268 218 189 220 218 241 236 215 215 236 206 236 220 247 234 235 259 231 230 226 231 239 262 208 250 245 244 239 228 234 225 217 212 235 245 216 262 245 188 233 246 236 203 218 222 215 192 231 240 262 211 240 242 260 262 263 227 243 211 239 241 274 264 244 248 240 258 215 242 246 245 221 226 246 231 243 241 236 247 245 244 243 243 240 219 256 248 229 220 244 246 238 230 219 234 259 234 258 267 242 250 264 264 209 238 237 245 280 227 266 262 218 237 244 224 221 264 260 223 250 226 261 255 246 234 234 238 233 261 231 257 263 266 230 286 265 248 247 286 265 236 272 224 204 246 278 229 236 243 241 257 234 219 275 259 239 248 266 275 234 266 262 269 291 276 258 262 247 303 265 256 275 276 241 286 283 255 274 286 280 260 265 280 261 296 278 286 288 292 271 310 330 306 314 297 336 299 314 304 331 323 352 326 349 343 354 384 390 351 389 383 381 407 388 399 371 413 417 399 360 408 437 408 403 371 391 363 366 367 360 374 330 364 308 333 336 331 347 326 307 329 294 277 311 285 276 294 281 256 301 257 272 273 286 281 261 263 283 234 260 235 255 221 247 232 241 246 262 268 203 255 239 247 269 256 241 238 255 240 230 275 278 246 242 233 233 246 263 236 219 227 237 233 243 229 237 249 240 257 256 216 236 244 225 215 208 239 248 231 227 234 218 249 258 212 248 247 216 258 220 214 238 223 242 220 221 242 241 255 242 213 238 238 262 210 218 230 215 216 211 218 219 237 234 260 268 206 248 259 221 224 257 231 226 193 202 231 227 235 239 238 213 246 230 243 244 213 238 231 228 245 256 213 230 216 224 238 229 238 219 228 230 217 206 239 239 225 228 232 221 219 246 225 238 232 240 265 209 237 247 238 250 220 216 224 228 245 218 215 221 219 227 227 205 235 227 246 241 248 246 239 214 230 231 236 218 233 217 257 222 240 205 236 204 236 236 241 247 216 205 215 201 204 235 208 215 227 227 218 225 233 214 216 237 271 261 249 225 207 249 256 233 247 234 224 216 238 225 226 244 267 216 224 244 223 221 255 231 231 244 234 220 240 242 231 231 228 208 238 204 223 232 234 203 227 238 269 217 228 214 236 217 209 208 246 246 208 235 248 222 208 232 230 248 227 227 227 248 261 226 214 216 218 214 223 236 215 228 240 227 222 248 235 244 210 191 223 240 235 209 209 213 228 271 264 201 222 273 202 230 237 240 215 215 209 228 213 216 240 231 212 230 217 244 244 232 236 197 238 219 213 217 228 224 211 235 221 224 237 221 239 248 194 233 256 240 204 238 230 231 269 216 218 207 229 259 235 244 247 248 246 260 208 212 229 215 263 230 223 217 239 210 237 234 214 236 236 221 262 228 203 204 222 194 222 235 237 238 239 238 230 242 215 239 231 218 248 255 260 257 247 232 243 233 200 243 218 256 239 208 258 214 248 215 217 232 242 242 245 216 226 236 221 213 225 194 228 231 208 241 243 238 249 233 226 247 228 212 236 222 220 225 224 263 244 226 232 225 214 199 219 225 203 228 228 237 220 238 239 233 206 236 240 226 215 259 209 234 209 227 224 238 246 237 209 224 232 239 231 221 229 241 230 241 216 226 249 236 225 265 225 227 230 198 207 236 218 257 245 219 244 229 225 270 233 218 219 233 229 238 232 211 233 244 267 260 219 196 232 213 233 250 219 229 219 249 232 207 213 225 242 240 242 236 213 231 249 263 237 232 232 222 223 242 213 230 259 273 245 235 225 227 240 232 242 214 214 245 224 246 207 239 236 229 226 268 220 234 214 230 273 212 201 234 225 235 219 261 257 225 224 239 221 246 201 295 238 234 213 231 220 246 223 227 237 230 237 232 246 225 240 206 241 258 226 217 215 210 229 228 240 240 236 229 255 223 216 222 199 243 221 198 208 249 237 241 241 230 230 214 226 238 230 272 246 225 208 235 269 272 255 245 213 232 195 227 228 208 206 230 210 222 226 218 256 229 240 240 208 225 211 226 231 233 225 272 259 230 243 226 248 232 259 249 246 232 228 268 220 246 233 239 219 227 264 234 209 233 217 207 232 241 247 241 227 217 241 244 222 234 213 213 222 235 240 268 257 267 269 222 229 260 223 231 256 240 220 231 236 246 236 267 236 258 216 260 245 227 235 239 222 246 230 226 239 271 246 220 212 206 231 209 234 230 216 212 221 228 242 211 235 205 232 217 243 243 259 237 244 235 234 236 265 239 230 226 218 220 222 235 239 235 223 238 259 246 211 245 242 243 237 232 248 202 231 220 232 249 234 282 237 221 240 227 201 266 224 248 206 245 235 268 248 234 231 224 213 262 232 234 230 214 249 219 220 231 227 256 258 211 209 256 232 212 244 208 213 241 225 215 206 201 244 224 225 260 266 256 226 219 223 249 250 248 226 229 235 247 212 222 243 259 271 215 225 222 237 227 241 237 228 216 198 205 232 234 247 282 226 209 242 258 223 243 224 281 219 221 223 238 212 240 202 241 231 222 242 225 216 222 266 238 236 198 234 222 278 243 221 260 238 228 217 232 230 274 258 221 213 229 243 235 225 235 218 247 262 240 272 207 237 234 222 221 230 247 257 237 278 238 209 224 255 241 230 208 239 239 231 231 240 227 215 258 211 207 237 211 232 269 234 212 227 205 231 203 242 208 217 213 206 226 223 257 261 212 230 235 242 259 248 229 242 237 225 233 230 239 217 216 208 217 223 275 203 237 260 210 222 260 209 220 212 269 215 235 239 227 217 240 247 256 230 220 235 217 249 212 241 274 236 222 227 257 249 222 220 227 218 214 230 211 259 245 210 239 245 226 246 235 231 232 223 260 232 238 239 226 225 227 261 239 215 239 233 225 263 231 242 259 238 214 238 222 236 227 239 233 235 207 246 263 239 212 227 223 224 225 262 247 222 237 241 229 222 249 236 242 213 232 228 237 207 256 202 213 219 240 256 223 226 235 261 242 239 236 204 262 260 240 232 250 245 234 239 216 216 244 234 220 225 227 258 219 204 256 216 234 272 273 238 233 215 232 243 232 229 228 230 238 230 230 233 238 241 259 259 221 224 261 266 198 222 235 256 249 266 222 258 222 224 219 242 187 264 243 216 222 248 217 211 217 244 227 266 228 220 242 244 227 236 234 238 217 232 228 231 216 267 213 261 259 228 209 267 265 234 223 243 233 208 265 206 249 237 242 224 233 222 220 226 256 257 238 223 240 274 233 221 212 250 228 247 231 244 235 219 224 255 211 236 236 201 224 265 224 223 214 242 262 247 219 271 243 256 217 276 208 259 274 231 219 206 229 212 217 238 240 283 227 249 213 231 227 247 231 279 209 211 239 206 221 237 213 233 226 217 245 231 228 249 230 247 258 241 266 219 270 255 216 273 241 218 238 218 272 239 239 261 218 248 215 242 247 227 240 244 230 212 223 244 233 219 226 246 233 231 245 232 217 265 231 205 240 245 229 264 224 237 226 238 239 283 241 246 232 232 235 222 262 227 191 247 225 235 241 220 230 233 227 218 233 227 223 234 230 229 222 223 233 229 244 218 230 245 266 246 237 249 237 243 234 203 232 255 263 220 221 261 235 227 228 237 202 210 211 258 218 231 222 255 210 239 266 232 238 261 210 246 231 235 259 239 286 240 237 240 223 222 261 225 229 250 231 249 248 244 276 216 223 269 224 225 248 239 239 237 241 239 244 213 248 232 266 247 268 247 246 217 233 238 247 235 250 234 249 243 217 203 223 244 225 226 246 219 241 237 240 258 205 284 240 243 226 246 243 231 212 266 255 224 250 249 220 259 246 244 202 246 236 221 220 226 238 262 227 240 248 222 265 230 230 235 236 229 226 243 231 274 255 230 218 220 240 243 229 233 227 230 218 233 236 243 247 244 229 256 235 243 243 212 232 238 255 226 237 220 223 259 245 227 245 280 239 262 269 223 244 232 235 229 232 230 223 214 249 248 225 241 246 239 249 235 212 243 247 237 258 243 239 258 229 231 247 246 239 225 211 258 212 240 245 201 230 219 244 237 222 219 236 241 237 247 234 205 262 248 262 240 221 238 219 198 203 225 227 236 234 243 226 233 220 236 241 222 207 258 215 238 237 259 228 217 236 233 240 237 262 235 248 246 236 242 240 249 255 237 237 217 235 266 230 233 237 255 262 240 272 228 235 214 237 272 207 210 203 249 268 222 215 235 237 241 237 218 206 225 221 213 263 258 283 240 215 232 241 236 213 257 230 266 249 217 231 246 249 214 247 242 262 232 237 222 243 220 243 237 255 243 243 244 218 229 236 232 229 230 223 244 240 225 231 232 231 215 220 243 269 231 216 243 228 228 247 255 246 226 237 232 241 230 245 248 245 225 261 225 282 237 237 216 219 236 250 234 231 227 234 239 215 236 244 242 275 221 248 235 234 244 196 225 267 208 197 235 235 246 258 285 229 243 261 260 242 263 225 187 227 243 242 239 235 265 235 213 248 240 249 218 221 226 247 239 242 244 213 238 230 235 241 238 234 262 262 230 238 264 236 265 236 241 255 242 248 235 248 222 216 217 229 226 225 240 260 240 256 237 259 227 243 243 222 247 239 239 238 248 218 242 243 222 233 257 249 258 244 216 236 234 232 231 230 269 217 257 249 242 239 260 248 241 247 287 234 198 248 249 256 226 244 222 255 264 258 241 234 235 224 227 249 262 218 225 232 240 245 262 245 226 226 268 273 255 237 217 243 247 240 244 242 228 235 235 238 241 225 270 225 216 214 241 234 239 259 256 267 237 227 242 231 242 257 225 261 225 266 213 221 261 259 234 259 243 244 273 265 245 240 259 223 233 230 237 249 244 270 241 280 223 270 248 248 248 247 259 267 222 259 240 247 247 262 231 271 262 219 250 236 263 213 244 227 272 223 248 271 275 272 219 263 257 270 269 224 256 247 227 233 241 245 281 272 256 239 240 240 233 240 249 246 245 218 217 237 227 231 217 259 269 258 260 239 257 266 272 233 237 283 233 268 269 261 241 250 274 244 256 280 268 243 219 241 225 262 235 228 299 247 260 241 247 233 263 290 238 237 235 242 274 268 241 247 287 264 247 282 266 227 257 260 226 277 230 263 264 268 242 265 245 278 240 266 269 270 277 231 260 243 249 245 270 242 281 227 257 272 255 248 284 270 256 278 272 263 293 259 240 273 265 257 283 246 255 238 255 232 266 234 232 249 263 278 244 247 236 247 294 265 275 225 234 276 267 245 267 260 236 249 228 255 236 279 271 235 234 257 264 221 229 264 223 246 248 255 247 242 237 249 258 227 236 263 262 263 270 249 261 242 257 250 270 264 265 261 255 230 235 248 241 244 245 245 260 240 258 245 244 231 262 237 270 231 259 279 258 264 241 227 246 281 243 259 240 248 237 286 236 238 260 237 240 223 249 268 239 233 256 219 258 266 263 277 248 288 234 283 263 277 274 280 247 268 232 246 229 238 245 257 263 269 255 272 265 265 246 263 246 237 195 268 279 241 240 273 260 277 235 263 262 263 255 257 240 260 242 262 269 256 226 236 249 261 247 226 240 239 237 276 263 247 212 227 243 233 242 245 241 258 234 259 217 264 268 260 231 283 242 225 242 241 278 279 244 246 233 220 247 217 225 238 269 262 241 262 244 239 234 256 255 230 255 225 249 272 268 249 263 270 250 231 257 238 237 239 232 226 282 281 268 221 235 259 243 261 267 242 261 256 239 227 277 250 244 213 274 286 243 233 276 245 237 238 265 241 255 242 264 247 274 243 262 239 241 222 286 262 249 271 261 255 247 265 273 244 259 269 255 235 236 242 239 271 258 223 244 239 267 260 246 248 256 284 226 235 245 273 269 245 244 248 243 243 257 242 235 259 258 223 257 257 229 262 255 240 242 246 267 256 220 244 234 231 207 225 233 268 236 227 260 268 231 261 238 241 241 261 243 249 233 289 275 298 258 255 246 248 262 257 236 294 277 235 256 234 267 245 265 273 227 236 264 259 265 220 242 265 269 288 257 229 227 257 259 230 238 248 228 280 270 261 263 275 245 235 284 230 275 244 248 248 249 240 255 275 260 226 236 258 273 225 219 263 273 227 248 230 224 256 260 245 220 246 261 240 229 255 279 258 259 291 215 246 245 250 249 228 248 281 247 264 256 264 256 246 224 236 255 266 255 265 257 243 270 259 257 236 243 234 243 258 237 263 272 236 241 265 229 270 258 248 258 255 247 258 239 227 234 277 244 248 260 242 229 262 247 248 244 236 249 259 248 255 255 270 232 258 244 267 261 237 227 289 216 240 235 263 242 264 237 272 257 222 219 230 268 269 235 246 249 270 265 256 263 246 229 224 232 245 256 229 240 226 264 223 285 247 260 246 239 239 279 279 256 233 261 259 218 257 268 229 238 255 278 239 276 237 267 259 257 272 268 240 239 268 229 279 271 249 250 248 224 241 248 256 247 271 221 243 269 259 229 266 242 240 212 239 249 284 264 256 239 238 233 228 261 237 255 246 249 240 263 243 240 249 268 268 266 246 271 258 227 250 261 247 240 246 265 243 263 267 227 239 260 229 242 241 241 239 262 265 259 260 242 241 298 243 249 229 238 258 243 238 215 266 238 261 246 279 279 243 268 237 238 224 265 274 236 245 259 274 273 279 262 245 256 242 239 264 227 242 255 250 229 246 276 238 258 242 249 273 234 264 267 275 291 264 282 226 228 240 249 246 255 280 279 261 267 257 248 265 232 241 270 255 246 273 222 231 246 247 267 263 248 233 257 277 260 238 255 265 216 268 255 234 276 272 244 276 259 228 259 258 238 272 285 267 237 246 241 256 260 256 231 215 239 267 258 245 221 212 280 269 266 242 219 263 257 259 225 273 218 257 246 258 243 304 228 261 257 236 268 291 258 263 244 233 241 229 263 259 261 208 238 282 287 230 248 243 223 235 266 258 246 250 269 279 264 255 260 215 256 263 257 245 275 272 277 258 249 237 261 242 246 246 239 271 224 245 283 238 258 231 257 266 270 248 260 236 257 280 256 241 260 226 235 223 260 243 262 280 262 269 247 261 250 202 237 241 259 257 249 264 247 255 257 267 237 293 249 268 242 220 267 261 256 236 272 235 239 232 259 229 281 240 257 258 231 258 249 260 256 212 257 261 255 260 244 234 225 264 247 269 228 265 232 256 260 265 248 268 223 255 224 257 238 243 244 228 229 279 267 266 249 262 230 281 314 230 256 264 261 244 241 276 248 248 261 268 244 237 279 236 275 248 238 258 262 229 271 260 255 266 240 224 217 247 273 260 247 281 241 269 219 284 277 248 216 271 256 249 235 280 256 262 256 239 286 265 283 263 247 246 302 274 285 236 241 239 264 262 288 256 260 261 239 260 212 238 239 295 270 258 260 274 236 268 255 249 242 257 241 256 265 233 244 256 276 258 238 241 246 239 263 263 233 264 267 263 250 278 247 257 231 261 247 239 235 247 286 255 255 275 274 266 267 255 241 258 258 280 264 278 249 249 234 244 255 272 268 242 227 271 267 266 265 280 287 234 264 261 236 272 230 246 231 239 205 260 263 241 241 244 230 241 256 247 238 266 257 239 264 246 267 245 247 216 268 232 284 257 273 296 278 279 249 273 250 276 234 281 272 266 222 264 246 236 247 272 238 259 288 229 245 231 275 244 259 273 237 244 272 245 260 279 260 247 247 260 265 236 262 242 247 271 255 230 248 261 230 258 263 235 228 241 270 244 249 208 256 235 266 262 278 233 243 232 290 221 237 264 243 267 270 243 241 229 265 247 229 212 247 240 248 246 243 235 230 246 255 249 271 287 233 242 280 276 283 249 261 256 259 233 247 238 239 262 248 255 261 274 261 268 266 226 267 258 208 262 271 257 264 259 258 286 278 245 279 277 257 262 285 236 288 233 241 270 245 260 276 229 257 243 259 277 269 222 255 246 248 231 278 258 290 237 265 232 264 258 282 235 232 256 248 293 266 260 236 247 269 294 281 291 255 274 256 255 240 278 242 241 261 241 274 248 228 255 259 264 240 270 261 262 300 255 221 285 262 279 258 245 247 245 262 263 270 274 270 280 236 243 257 282 247 227 257 246 258 267 244 229 261 222 249 255 266 244 241 264 235 250 226 248 233 261 274 259 241 264 220 248 237 296 226 260 263 268 288 268 245 243 235 260 244 270 237 234 256 241 284 264 262 233 240 272 272 263 217 264 277 246 262 269 257 262 233 232 270 263 272 257 255 240 248 296 257 282 267 247 279 279 231 245 264 276 233 248 275 265 236 264 246 266 234 244 263 241 271 272 261 262 276 235 275 222 247 245 267 275 233 287 248 242 269 287 258 273 247 265 249 224 263 266 231 272 235 266 282 233 273 264 237 273 261 248 229 255 267 241 283 229 241 231 246 256 240 286 263 277 242 262 258 227 242 278 257 241 243 295 279 247 262 249 236 263 255 277 280 238 246 256 235 237 240 273 269 269 300 256 267 248 262 238 255 261 238 236 246 271 258 270 263 246 290 248 258 245 231 258 264 240 260 240 312 246 257 235 264 247 255 255 302 274 264 264 237 244 262 277 302 236 237 270 259 272 249 229 245 273 250 248 238 234 250 242 238 240 265 271 240 265 255 255 255 276 264 278 237 270 270 256 273 248 238 256 244 286 270 294 265 242 242 268 260 248 271 256 281 273 236 234 293 274 274 270 269 238 224 246 266 264 292 246 234 248 240 256 265 264 275 265 268 249 270 261 268 258 283 239 262 237 267 249 270 245 260 258 295 311 293 245 234 232 268 243 244 265 262 265 241 240 239 257 234 265 255 249 234 261 260 232 255 265 256 272 260 223 243 262 257 283 239 292 233 287 239 275 264 261 247 247 271 270 234 275 240 239 288 257 272 285 283 242 256 244 278 274 229 266 239 268 272 260 320 260 239 244 286 237 271 260 260 261 233 299 285 275 261 273 273 286 269 259 265 266 256 294 270 316 300 268 268 283 270 301 287 307 279 272 287 264 257 264 288 278 299 277 283 277 265 265 256 308 279 270 280 279 278 309 278 291 304 270 307 302 265 277 353 262 295 277 321 303 286 275 270 258 282 260 270 287 295 279 281 299 289 269 271 239 287 271 328 274 279 311 283 283 276 307 279 269 295 288 290 287 285 246 285 265 303 264 294 273 240 243 296 229 269 271 269 297 244 264 267 274 264 259 257 272 277 301 247 280 287 276 295 239 272 258 264 267 240 293 266 259 264 260 237 261 247 231 275 239 246 285 241 281 246 266 261 291 258 273 282 281 259 240 227 233 257 265 245 274 285 257 239 258 255 248 273 243 264 248 260 281 261 266 277 262 269 238 247 218 278 240 262 256 235 280 238 268 255 270 242 260 259 279 270 239 243 239 261 246 246 215 238 271 239 226 281 244 262 237 258 285 233 256 265 283 268 255 287 261 244 243 227 244 266 247 261 269 241 241 260 255 282 231 239 262 268 243 261 228 259 245 248 274 270 235 289 236 238 235 250 229 298 263 260 280 219 259 246 278 256 264 222 220 273 248 269 243 213 235 227 274 258 249 240 268 216 238 255 256 244 259 236 236 270 245 271 231 267 243 283 259 234 260 238 234 246 221 267 227 234 242 241 255 243 224 256 278 233 272 257 258 279 247 281 264 267 220 257 244 256 272 243 242 259 257 258 247 256 259 250 245 256 260 235 264 259 248 266 260 248 234 248 264 265 275 219 211 242 241 281 277 234 272 239 249 257 240 248 247 263 233 231 267 268 236 243 237 247 246 243 259 242 259 236 230 258 227 263 234 232 230 241 239 275 268 240 246 261 268 239 260 266 239 242 242 236 245 246 255 243 265 288 243 273 264 230 248 245 242 281 280 255 226 233 244 265 236 232 229 287 228 234 259 279 278 265 259 249 272 217 223 211 247 264 280 270 298 264 227 263 218 228 265 216 260 263 239 244 225 270 220 263 221 247 249 289 257 260 229 256 245 247 239 256 257 266 233 244 268 283 239 287 256 220 240 280 227 260 270 258 279 268 223 237 247 267 242 277 261 242 265 256 244 232 247 267 258 246 225 266 278 258 233 247 263 260 257 282 275 281 256 288 244 242 249 233 264 227 282 276 248 237 266 266 258 245 246 247 259 258 255 240 245 262 270 272 257 225 270 288 235 250 264 265 265 245 279 276 243 245 286 273 273 230 242 257 255 247 222 240 248 245 240 225 237 261 241 269 247 276 228 287 267 276 235 264 231 237 239 244 236 273 258 257 237 258 294 226 233 245 275 250 267 255 239 248 259 271 232 256 243 269 271 278 245 274 249 260 247 236 234 277 277 230 247 241 256 240 222 283 272 239 270 244 309 255 246 269 261 273 275 245 243 266 287 265 234 270 259 247 231 276 228 274 272 255 249 256 260 225 263 242 261 272 247 224 280 226 243 231 240 238 256 269 234 240 248 245 283 240 241 241 247 255 271 244 270 258 257 236 258 260 283 263 241 233 266 247 228 261 289 274 240 223 280 279 266 263 264 244 242 257 263 275 273 234 255 265 255 229 255 245 242 224 229 256 243 227 273 263 266 259 289 227 239 240 246 250 269 272 278 279 292 271 241 264 218 255 264 242 248 243 260 244 235 256 261 285 248 269 247 232 272 247 247 266 240 237 272 250 237 269 244 297 263 266 246 256 260 255 259 228 193 260 249 260 274 239 290 242 290 238 235 255 223 255 259 264 242 247 275 238 245 260 266 298 269 276 273 263 256 224 255 248 273 271 234 256 281 227 276 247 262 282 270 241 242 267 295 281 243 257 256 258 271 255 226 246 258 277 265 263 257 248 272 266 281 247 267 284 239 240 265 263 246 237 268 246 264 274 245 246 241 270 249 240 240 260 263 224 241 244 239 260 244 240 234 238 248 264 240 245 281 230 272 220 236 249 263 265 269 265 226 258 261 249 273 221 283 250 219 261 241 263 240 260 234 248 261 291 257 258 247 245 262 273 263 246 264 238 235 246 281 243 230 284 282 266 224 258 235 262 266 247 242 224 268 264 263 249 272 240 236 236 241 234 230 259 246 244 241 240 272 241 259 238 266 237 246 271 269 273 217 227 263 247 268 265 275 260 244 222 246 273 227 244 281 231 226 262 241 266 239 240 246 236 243 258 259 245 266 265 236 249 245 234 248 241 212 246 247 232 271 256 244 222 267 269 255 257 248 280 259 231 233 267 260 248 262 248 263 238 268 206 267 245 233 243 276 217 272 248 245 272 259 261 267 233 258 256 274 266 256 247 248 255 239 248 260 271 262 277 228 239 247 259 215 233 240 258 264 229 271 265 278 279 247 242 236 233 294 232 248 267 257 249 282 245 242 214 239 266 244 247 278 238 247 240 242 266 255 230 255 271 249 285 233 238 256 235 270 266 264 260 238 290 248 240 239 234 258 271 225 269 257 255 243 235 242 239 284 221 245 242 259 256 272 286 239 236 261 278 235 245 243 241 264 250 230 259 257 240 226 241 261 265 288 255 271 244 259 256 263 222 240 231 261 289 278 261 249 279 250 247 257 272 272 268 269 255 283 241 241 256 263 255 260 222 280 272 268 279 270 261 245 271 238 220 246 255 284 269 267 232 256 260 268 248 242 247 247 267 232 257 256 256 229 255 249 270 244 247 267 239 259 257 207 269 228 232 245 246 241 233 247 270 247 219 246 262 244 250 277 256 263 277 234 229 244 242 241 241 262 242 275 248 244 237 279 250 256 241 268 238 281 281 276 272 238 262 232 280 243 237 230 240 264 256 264 245 231 275 234 230 242 249 276 226 229 273 275 234 265 234 226 215 232 255 239 236 275 246 216 255 257 271 266 255 276 272 247 243 237 247 226 269 237 232 246 274 237 266 257 257 264 257 245 234 277 287 261 235 256 239 278 247 247 236 239 275 220 238 274 264 237 235 232 227 257 216 239 263 287 243 259 266 280 260 283 257 257 227 258 244 250 240 217 263 255 248 225 255 230 236 234 238 278 260 257 234 228 226 269 245 259 215 268 229 265 244 222 239 242 245 246 242 264 229 260 270 288 270 260 262 248 242 241 279 261 262 243 258 242 265 235 236 245 239 262 266 283 264 257 266 289 238 290 244 257 279 276 249 279 233 238 287 245 268 244 234 247 228 242 236 242 229 234 296 261 231 236 264 255 260 259 247 234 256 248 270 244 239 238 234 246 256 237 249 258 262 280 236 197 279 288 261 215 280 230 262 235 230 244 242 241 233 228 275 261 280 241 279 215 244 239 258 261 234 202 263 269 237 260 242 268 236 232 236 268 224 244 224 282 263 229 259 236 255 230 262 236 270 226 247 261 248 247 225 264 248 244 270 258 236 260 256 221 239 245 230 238 263 247 228 206 265 266 264 247 272 260 274 248 211 240 264 240 259 229 243 235 267 246 251 244 255 247 240 268 240 257 238 255 237 263 210 264 261 247 243 243 271 259 237 263 244 249 283 258 231 238 244 248 274 243 243 257 238 240 257 240 247 231 259 281 265 263 234 273 270 272 263 262 229 241 249 250 281 270 270 244 238 277 256 259 231 262 273 297 256 271 249 249 260 262 247 238 274 219 244 271 243 238 271 259 246 246 275 269 245 283 240 240 256 241 292 257 238 273 225 246 230 229 235 284 241 241 240 246 235 242 258 256 243 255 257 273 267 227 286 256 276 278 262 240 294 289 236 239 258 257 221 263 258 240 286 263 243 233 265 261 266 233 268 245 274 277 272 244 257 255 270 245 285 245 264 278 265 291 249 215 240 257 275 266 233 262 271 271 268 241 275 263 245 245 271 270 232 245 261 271 267 255 241 268 275 271 273 278 244 257 280 274 228 257 245 269 279 237 275 264 261 279 246 273 247 303 271 286 275 247 241 233 243 263 243 264 279 258 279 246 292 261 263 258 292 267 239 235 263 247 260 228 236 287 283 232 262 265 274 275 267 236 231 273 270 261 266 277 243 273 240 234 223 311 297 244 265 242 279 266 238 255 259 236 257 265 268 268 282 256 279 272 239 258 242 255 245 283 216 236 245 283 288 222 247 242 244 245 292 264 283 262 261 247 264 263 273 245 258 273 242 234 243 312 245 248 261 246 266 263 234 273 247 294 244 268 224 240 245 267 284 241 248 306 265 274 260 231 247 243 237 266 268 227 261 221 241 274 246 238 233 247 231 282 249 270 248 266 275 266 292 247 263 297 241 237 257 240 256 256 275 240 247 250 232 243 264 273 248 265 243 242 264 237 239 236 243 256 263 264 241 265 256 271 264 240 256 235 239 259 237 266 262 299 235 226 277 261 243 258 274 260 264 261 242 271 213 258 258 243 246 269 249 272 239 272 242 238 217 255 269 258 239 250 260 240 250 246 273 257 261 270 226 263 270 247 270 283 268 277 234 265 241 266 236 276 240 266 245 227 287 260 237 230 241 222 234 238 260 241 241 257 245 229 268 256 248 232 255 271 271 255 243 226 276 234 244 245 226 241 284 255 246 248 255 292 275 270 242 266 279 275 281 221 219 241 243 226 238 238 235 285 273 249 239 245 222 269 227 278 268 245 268 255 286 231 249 219 248 266 262 239 241 264 278 244 217 277 268 256 239 259 242 247 255 231 262 286 272 281 266 255 241 242 256 235 237 229 240 278 248 237 242 233 258 218 279 257 264 247 260 264 229 282 234 248 237 269 280 246 248 260 236 247 268 244 242 277 216 265 235 271 235 243 244 247 221 289 258 265 242 241 269 247 282 240 236 228 263 239 283 242 277 265 236 257 278 231 296 258 255 239 267 272 245 248 229 235 256 260 257 213 243 256 235 259 256 247 241 232 233 270 233 264 241 280 245 261 265 242 250 279 255 220 264 224 267 262 235 273 233 243 243 247 260 241 241 266 271 240 234 230 262 243 259 240 243 271 246 242 247 259 256 243 225 261 229 260 260 261 243 259 278 260 295 232 222 298 278 273 241 230 273 242 272 260 234 226 244 276 237 257 258 233 255 286 247 256 255 225 265 282 235 266 216 270 236 270 243 260 263 270 240 260 236 236 256 233 241 267 247 262 229 257 234 284 260 280 285 268 261 266 245 260 239 257 247 269 279 270 268 243 238 248 286 247 271 225 247 248 247 244 241 271 237 261 225 235 266 270 255 244 268 290 272 220 261 235 261 248 244 237 260 256 261 243 262 267 283 264 267 274 239 241 238 256 242 304 260 268 275 204 259 285 227 280 258 243 261 242 279 243 284 260 267 250 271 271 241 265 263 262 245 255 246 250 261 269 270 229 257 235 296 281 232 264 269 266 267 239 262 240 258 234 263 240 268 284 277 234 242 255 234 243 227 246 259 207 249 237 261 237 289 261 243 229 233 255 258 279 238 260 243 242 260 258 255 226 280 282 263 242 263 245 249 241 263 269 259 241 259 234 212 235 263 255 245 261 247 262 257 262 256 264 266 267 256 262 261 266 256 220 262 259 260 229 272 234 290 247 279 269 255 270 284 258 246 275 280 261 270 276 256 268 246 260 281 262 233 257 266 226 244 241 256 218 230 249 226 225 224 246 248 243 256 264 267 233 270 266 242 242 271 224 221 243 281 247 234 260 265 280 267 240 250 279 247 276 250 272 306 233 265 250 270 228 236 245 258 245 244 260 226 257 272 243 240 269 275 227 247 249 259 285 247 257 234 258 256 263 250 222 260 244 243 266 258 296 273 244 284 236 258 231 247 297 231 243 238 276 238 250 246 296 249 213 235 283 228 259 273 250 266 223 247 246 240 271 246 234 260 261 245 247 246 302 242 222 268 246 248 243 304 241 257 266 233 268 237 273 294 237 230 264 236 263 291 270 235 242 238 270 265 256 227 260 249 245 269 246 232 244 233 284 255 248 266 242 257 256 256 277 248 261 244 220 220 264 232 238 235 271 236 296 260 249 240 244 272 262 285 228 247 257 246 247 244 275 258 263 243 242 231 243 247 239 234 210 249 224 236 242 232 226 235 258 233 273 244 237 258 245 230 221 240 264 248 248 275 233 238 255 268 237 242 269 261 255 230 279 270 261 244 256 223 226 223 274 264 255 278 297 266 255 257 246 248 233 216 224 260 273 276 283 247 258 242 247 214 288 239 260 242 249 245 249 242 262 266 255 238 238 245 243 243 258 246 259 248 230 273 245 235 249 287 273 266 264 245 262 231 238 281 280 233 275 255 266 245 265 247 265 218 256 239 229 265 259 240 279 232 261 238 238 264 232 266 262 271 264 244 263 249 234 245 241 234 235 248 237 266 258 261 230 243 257 244 241 272 273 235 218 232 238 267 256 243 243 258 238 271 228 260 233 271 246 236 281 225 263 233 227 261 279 215 289 242 245 245 232 277 236 240 260 237 273 273 240 282 264 246 275 260 202 248 239 225 249 241 243 246 241 238 262 249 231 236 247 248 268 245 277 277 241 281 236 275 255 245 263 271 265 256 227 243 297 224 261 242 249 259 243 235 257 233 268 242 246 224 262 269 237 293 224 258 246 273 289 257 257 265 257 261 243 255 261 258 246 244 282 240 273 269 233 245 271 236 256 244 234 263 264 249 245 267 240 265 258 262 249 272 256 281 218 259 264 226 271 257 236 268 239 236 235 230 262 259 260 238 256 248 272 262 260 247 276 262 243 288 256 256 274 247 245 257 234 255 245 242 226 247 260 273 261 237 242 265 287 272 247 256 223 279 242 249 266 240 275 238 281 234 212 245 205 265 263 266 271 248 229 232 272 258 255 266 278 242 270 233 230 240 221 269 244 259 270 231 249 260 223 271 262 213 241 248 238 231 226 227 276 277 271 256 240 261 242 245 239 286 245 284 265 222 239 244 246 276 244 256 238 257 262 262 268 274 261 280 281 239 246 240 261 277 247 230 236 272 245 240 237 257 269 270 234 244 245 244 228 268 241 245 248 268 247 237 239 260 270 260 255 269 275 260 243 289 270 234 243 231 218 249 259 255 275 230 271 283 247 244 246 258 302 272 276 272 288 287 275 270 256 258 243 258 248 274 237 262 261 230 263 246 287 246 265 287 256 241 268 260 244 270 263 258 231 267 293 261 286 241 233 258 282 241 229 244 242 233 262 246 230 244 222 245 238 230 221 263 241 225 220 248 274 229 247 281 278 221 237 242 255 276 260 241 243 232 237 273 290 248 255 248 230 263 245 259 233 276 244 256 235 262 266 244 236 275 257 257 248 213 230 245 242 243 259 247 298 243 238 231 265 274 272 245 275 240 256 263 261 277 281 243 219 217 279 232 272 278 243 255 245 259 280 273 273 239 257 241 232 224 292 263 228 256 267 266 281 246 278 268 227 262 244 234 268 238 247 225 222 271 268 290 234 247 244 248 274 249 230 265 247 249 262 235 243 232 270 244 243 229 300 235 274 241 236 260 244 256 248 256 235 249 271 260 263 239 238 237 227 277 257 270 244 255 238 259 228 270 268 265 290 261 233 260 259 236 238 263 241 243 259 215 234 234 255 246 289 268 224 242 226 274 275 260 265 236 293 236 257 258 259 268 225 269 257 259 262 267 264 231 239 244 221 260 234 243 262 239 240 244 272 270 243 265 261 242 258 248 248 244 238 281 258 255 240 283 233 276 229 237 257 265 221 263 237 248 255 275 235 259 238 263 286 283 235 250 224 270 272 259 270 256 248 246 244 296 279 217 260 308 298 271 218 267 265 244 262 261 271 241 279 266 261 260 235 218 238 260 284 255 239 223 248 260 261 260 293 284 259 269 268 246 249 227 280 263 249 260 270 257 239 264 276 240 243 273 248 255 277 277 255 263 284 243 262 289 245 240 281 257 260 263 268 272 260 259 241 292 245 306 277 269 287 271 280 243 260 276 288 242 261 268 268 244 287 232 264 256 242 273 259 240 266 272 242 241 276 269 239 283 258 280 264 260 267 223 295 245 264 271 289 243 226 237 247 266 263 291 255 248 248 248 260 268 263 282 291 271 232 271 260 311 273 260 273 231 248 272 268 275 268 270 260 290 238 248 250 272 267 259 272 271 255 268 262 266 272 257 257 260 271 256 235 256 226 285 266 298 263 276 238 238 241 268 267 272 238 259 238 244 273 241 237 268 244 273 266 268 264 278 226 272 221 243 257 260 264 247 275 210 259 237 256 248 277 283 240 265 263 250 266 240 235 255 289 231 281 239 234 270 236 267 244 264 261 263 266 279 260 285 273 239 267 256 245 244 211 240 265 234 242 265 248 255 232 267 264 244 268 276 273 250 213 236 245 262 272 237 271 234 232 247 236 230 237 289 255 249 232 257 255 229 250 271 224 247 275 234 238 276 270 226 255 232 237 274 260 279 267 269 257 245 236 271 264 269 241 267 256 256 275 292 273 257 223 244 255 249 276 257 250 264 244 233 275 263 247 248 218 248 260 245 274 266 258 249 287 264 266 256 226 301 249 247 266 239 242 284 234 307 246 236 221 275 269 255 237 242 256 224 239 273 232 247 255 236 243 236 243 240 242 223 210 279 258 234 257 262 242 243 229 237 244 234 257 246 246 246 239 250 238 244 241 270 270 229 236 247 256 238 265 243 270 231 259 224 250 234 261 262 241 230 232 235 228 271 266 269 228 238 288 248 259 275 292 262 222 245 223 244 263 260 243 255 259 249 232 261 255 231 247 261 227 269 237 273 244 242 268 226 256 246 268 243 239 237 258 262 238 275 243 236 246 262 242 246 278 259 234 257 236 248 276 244 220 244 255 261 268 270 293 249 287 249 277 214 235 257 226 266 248 262 244 240 244 277 221 245 245 266 264 218 240 230 242 228 265 236 245 262 258 263 248 269 266 249 235 249 244 269 223 266 241 261 263 245 233 260 229 267 241 246 225 262 243 220 265 240 234 256 256 246 241 249 243 241 241 268 257 245 248 243 267 247 248 228 247 266 241 247 240 208 264 223 242 264 246 258 269 247 240 261 261 266 259 235 213 227 262 258 240 244 218 268 271 287 260 248 264 245 228 231 296 232 267 262 277 293 282 255 288 242 249 262 242 278 278 238 241 273 268 233 214 241 234 280 236 236 262 242 214 286 256 223 284 264 258 259 274 213 238 266 265 236 272 250 261 245 298 264 245 238 287 248 249 230 256 247 267 225 289 214 235 228 260 244 276 222 273 233 230 270 270 242 261 261 256 262 266 260 245 260 286 240 249 236 247 260 245 224 241 277 259 236 237 225 275 274 257 247 227 271 241 242 284 233 274 264 249 229 265 243 234 264 277 229 260 249 259 249 256 236 264 279 243 234 250 272 246 266 217 216 227 234 234 242 263 244 240 257 236 249 258 256 264 249 244 265 265 230 241 266 262 231 236 241 246 231 257 242 221 249 233 229 256 269 259 261 243 260 263 264 270 258 247 255 255 239 266 245 225 275 290 232 249 232 259 234 211 261 270 271 222 224 243 237 265 255 269 276 242 267 249 236 226 242 228 228 247 270 246 262 239 264 273 260 260 219 232 243 261 242 266 288 244 248 245 274 232 236 242 263 248 242 234 260 264 259 263 259 245 230 237 266 232 303 238 262 246 279 248 267 243 277 233 224 271 271 256 229 239 279 256 219 284 242 218 241 250 281 244 278 243 228 263 255 258 275 255 240 242 266 231 282 248 246 228 238 241 265 285 250 262 264 244 246 246 276 218 244 226 274 261 271 245 269 264 259 238 258 271 255 246 257 262 266 258 263 256 264 259 229 284 269 258 201 213 249 256 227 265 255 268 220 283 275 272 221 268 266 247 276 281 225 262 233 238 222 266 301 227 237 268 237 216 237 240 249 244 249 236 264 264 210 234 261 260 267 261 262 257 273 229 256 249 238 284 266 242 280 295 268 240 260 244 225 234 242 262 280 229 272 255 236 258 268 247 205 239 234 262 275 231 250 256 273 228 268 248 268 256 243 240 290 237 274 232 266 255 257 239 239 246 235 243 232 239 299 258 244 250 259 245 273 266 227 243 221 217 263 267 276 231 243 279 257 268 248 278 242 248 231 278 263 260 233 238 289 284 268 249 249 244 258 246 283 238 247 240 240 229 219 241 226 268 256 258 261 268 257 231 284 245 225 238 282 246 260 246 238 263 234 235 263 235 262 244 258 266 256 237 263 255 256 231 242 281 286 270 270 259 245 243 237 272 293 270 246 260 242 230 240 262 268 240 298 272 248 267 275 248 232 276 275 257 236 258 282 250 283 255 236 256 276 249 247 270 222 250 257 247 249 279 242 277 272 246 255 267 232 277 276 266 258 247 238 255 273 255 247 238 265 255 261 278 244 263 247 258 232 262 274 248 248 255 283 272 277 228 235 270 240 272 271 245 248 240 243 242 235 280 267 244 288 264 263 236 243 273 270 278 260 234 237 246 220 266 245 289 277 246 262 262 238 218 261 250 259 259 264 277 230 273 272 247 248 244 258 262 273 238 255 282 267 241 273 273 234 260 286 241 281 266 235 270 258 280 238 241 260 241 293 227 240 266 280 290 258 267 249 256 245 266 266 237 246 262 263 269 268 228 267 274 258 275 290 238 238 269 271 237 257 235 256 220 249 287 289 261 240 264 285 273 258 288 249 221 232 275 263 284 277 256 256 306 246 267 290 261 272 244 228 232 274 270 232 257 238 244 228 210 235 266 264 264 268 244 248 268 277 240 241 278 276 270 281 257 229 257 269 250 267 226 230 255 279 259 273 269 284 235 274 230 257 221 262 255 259 268 260 220 258 285 263 284 241 239 260 278 232 292 274 305 272 259 214 248 302 257 246 263 259 286 257 266 262 231 274 249 265 259 269 248 262 237 271 261 242 278 269 276 276 247 235 280 245 267 268 266 278 237 250 263 261 280 283 247 289 269 248 255 267 260 247 243 303 266 288 261 279 266 243 262 239 248 269 288 268 269 265 233 291 267 259 227 262 274 241 233 246 222 246 269 245 245 270 235 261 241 272 220 268 273 238 244 262 261 288 273 280 289 269 234 223 236 267 270 259 245 241 244 256 256 280 261 270 263 257 246 268 261 291 286 280</counts>
			</dataPoints>
		</scan>
	</xrdMeasurement>
</xrdMeasurements>