File: data/XRD/XG-Vakuum/XG-pre/W6824-1C_XG_Vakuum_pre.xrdml
<xrdMeasurements xmlns="http://www.xrdml.com/XRDMeasurement/2.1" xmlns:xsi="http://www.w3.org/2001/XMLSchema-instance" xsi:schemaLocation="http://www.xrdml.com/XRDMeasurement/2.1 http://www.xrdml.com/XRDMeasurement/2.1/XRDMeasurement.xsd" status="Completed">
	<comment>
		<entry>Configuration=Factory configuration, Owner=User-1, Creation date=7/8/2013 4:01:53 PM</entry>
		<entry>Goniometer=PW3050/65 (Theta/2Theta); Minimum step size 2Theta:0.0001; Minimum step size Omega:0.0001</entry>
		<entry>Sample stage=MRD Cradle; Minimum step size Phi:0.01; Minimum step size Chi:0.01; Minimum step size X:0.01; Minimum step size Y:0.01; Minimum step size Z:0.001</entry>
		<entry>Diffractometer system=XPERT-PRO</entry>
		<entry>Measurement program=C:\PANalytical\Data Collector\Programs\Jorrit\2thom\_absolute_2th-om_10-130deg_PIXscan_56min.xrdmp, Identifier={15BCCF57-2807-42BD-B5B9-ECC0B3DC9284}</entry>
		<entry>Batch program=C:\PANalytical\Data Collector\Programs\SimonL\batch8x_2thom_10-130°_z9.1_x0,10,20,30_y20,30,40,50_57min.xrdmp, Identifier={9A1B954C-70C5-4DE2-A2B5-D0000261ED0F}</entry>
	</comment>
	<sample type="To be analyzed">
		<id></id>
		<name></name>
		<preparedBy></preparedBy>
	</sample>
	<xrdMeasurement measurementType="Scan" status="Completed" sampleMode="Reflection">
		<comment>
			<entry>_absolute_2th-om_10-130deg_PIXscan_56min</entry>
			<entry>PHD Lower Level = 4.83 (keV), PHD Upper Level = 11.27 (keV)</entry>
		</comment>
		<usedWavelength intended="K-Alpha 1">
			<kAlpha1 unit="Angstrom">1.5405980</kAlpha1>
			<kAlpha2 unit="Angstrom">1.5444260</kAlpha2>
			<kBeta unit="Angstrom">1.3922500</kBeta>
			<ratioKAlpha2KAlpha1>0.5000</ratioKAlpha2KAlpha1>
		</usedWavelength>
		<incidentBeamPath>
			<radius unit="mm">320.00</radius>
			<xRayTube id="1010048" name="Empyrean Cu LFF HR (9430 033 7310x) DK442154">
				<tension unit="kV">40.0</tension>
				<current unit="mA">40.0</current>
				<anodeMaterial>Cu</anodeMaterial>
				<focus type="Line">
					<length unit="mm">12.0</length>
					<width unit="mm">0.4</width>
					<takeOffAngle unit="deg">4.2</takeOffAngle>
				</focus>
			</xRayTube>
			<xRayMirror id="27010001" name="Inc. Beam Cu W/Si (parabolic MRD)" hybrid="false">
				<crystal type="Graded" shape="Parabolic">W/Si</crystal>
				<acceptanceAngle unit="deg">0.800</acceptanceAngle>
				<length unit="mm">60.0</length>
			</xRayMirror>
			<sollerSlit id="21010002" name="Soller slits 0.04 rad.">
				<opening unit="rad">0.0400</opening>
			</sollerSlit>
			<mask id="22030008" name="Fixed mask 4 mm">
				<distanceToSample unit="mm">220.00</distanceToSample>
				<width unit="mm">4.00</width>
			</mask>
			<divergenceSlit id="22010007" name="Fixed slit 1/8°" xsi:type="fixedDivergenceSlitType">
				<distanceToSample unit="mm">220.00</distanceToSample>
				<height unit="mm">0.19</height>
			</divergenceSlit>
		</incidentBeamPath>
		<diffractedBeamPath>
			<radius unit="mm">320.00</radius>
			<sollerSlit id="21010002" name="Soller slits 0.04 rad.">
				<opening unit="rad">0.0400</opening>
			</sollerSlit>
			<receivingSlit id="22010001" name="Fixed slit 4°">
				<height unit="mm">5.88</height>
			</receivingSlit>
			<detector id="7010017" name="PIXcel3D 1x1 detector" xsi:type="areaDetectorType">
				<phd unit="%">
					<lowerLevel>30.0</lowerLevel>
					<upperLevel>70.0</upperLevel>
				</phd>
				<mode>Scanning</mode>
				<activeChannelsEquatorial>255</activeChannelsEquatorial>
				<activeChannelsAxial>255</activeChannelsAxial>
				<pitchEquatorial unit="mm">0.05500</pitchEquatorial>
				<pitchAxial unit="mm">0.05500</pitchAxial>
				<readOutPeriod unit="seconds">0.135</readOutPeriod>
			</detector>
		</diffractedBeamPath>
		<scan appendNumber="0" mode="Continuous" scanAxis="2Theta-Omega" status="Completed">
			<header>
				<startTimeStamp>2024-10-04T10:17:56+02:00</startTimeStamp>
				<endTimeStamp>2024-10-04T11:14:02+02:00</endTimeStamp>
				<author>
					<name>PRO-MRD</name>
				</author>
				<source>
					<applicationSoftware version="6.1b">Data Collector</applicationSoftware>
					<instrumentControlSoftware version="7.0E 20130304">XPERT-PRO</instrumentControlSoftware>
					<instrumentID>0000000011142674</instrumentID>
				</source>
			</header>
			<dataPoints>
				<positions axis="2Theta" unit="deg">
					<startPosition>9.99826193</startPosition>
					<endPosition>129.99755682</endPosition>
				</positions>
				<positions axis="Omega" unit="deg">
					<startPosition>4.99913096</startPosition>
					<endPosition>64.99877841</endPosition>
				</positions>
				<positions axis="Phi" unit="deg">
					<commonPosition>0.00</commonPosition>
				</positions>
				<positions axis="Chi" unit="deg">
					<commonPosition>0.00</commonPosition>
				</positions>
				<positions axis="X" unit="mm">
					<commonPosition>30.00</commonPosition>
				</positions>
				<positions axis="Y" unit="mm">
					<commonPosition>0.00</commonPosition>
				</positions>
				<positions axis="Z" unit="mm">
					<commonPosition>9.100</commonPosition>
				</positions>
				<commonCountingTime unit="seconds">32.895</commonCountingTime>
				<counts 441 470 448 431 449 429 389 412 448 470 433 425 437 391 415 448 449 469 431 443 459 396 432 469 468 424 467 412 430 425 459 431 472 465 445 419 473 433 487 478 444 493 480 487 439 494 470 449 464 474 450 463 457 480 480 445 456 443 445 439 454 434 472 478 394 432 462 465 462 467 470 431 424 435 434 441 434 416 455 454 432 409 392 414 421 417 440 443 456 463 419 421 436 405 416 446 434 441 375 419 432 410 420 391 436 433 409 406 458 420 440 408 412 417 415 423 397 411 432 401 453 419 405 403 431 428 412 386 420 439 398 421 444 399 457 385 424 393 384 443 415 419 411 453 433 405 420 396 407 421 382 386 382 392 459 421 419 396 399 381 378 414 407 442 412 394 383 409 435 423 386 379 426 416 408 388 424 360 402 415 374 409 410 409 387 431 409 389 382 441 403 417 428 437 411 429 444 367 412 403 407 399 404 443 423 389 393 414 407 371 407 403 390 400 400 408 401 423 384 378 407 402 404 387 405 418 401 396 358 408 381 423 392 381 376 412 422 396 408 369 402 388 381 417 365 383 439 382 403 379 396 412 376 399 394 396 393 429 367 395 411 391 370 415 409 382 377 383 363 381 426 391 414 419 382 377 363 407 393 386 424 425 389 403 405 377 394 386 358 374 395 416 351 364 375 396 398 396 363 365 407 403 386 427 379 366 392 365 380 378 396 394 368 400 401 374 394 388 407 376 405 383 401 360 393 388 363 438 326 358 356 386 380 371 352 362 359 371 378 354 384 372 391 375 355 419 387 404 404 396 402 357 376 389 381 382 354 385 376 344 374 357 344 341 380 362 397 379 384 353 368 334 406 364 368 368 393 352 366 366 396 368 350 403 349 340 348 358 361 372 370 337 364 387 345 408 409 373 389 378 366 442 375 373 381 357 376 370 344 341 351 360 382 377 376 367 375 363 378 355 364 357 373 361 364 348 359 323 335 380 353 350 351 362 367 356 354 368 346 358 363 348 372 359 324 341 376 366 361 349 311 364 363 372 348 369 366 331 332 368 350 375 364 372 319 373 348 359 367 324 309 354 357 350 363 339 353 324 354 364 331 379 366 307 341 344 347 354 345 370 340 345 356 373 313 356 386 352 320 329 362 343 383 365 348 328 352 322 317 335 320 378 355 365 375 353 314 343 306 338 367 320 354 356 350 338 348 301 330 355 379 345 327 332 335 381 332 329 368 361 342 360 346 352 354 319 327 349 336 383 331 348 320 342 362 342 295 344 294 343 300 312 344 312 307 317 340 365 352 363 308 345 312 340 364 367 342 335 346 318 332 335 305 300 311 343 344 306 342 345 334 332 320 315 309 344 297 329 342 331 328 314 340 328 345 344 347 354 344 346 343 295 313 350 323 331 340 340 323 299 332 333 354 303 338 320 318 302 303 339 299 310 360 337 351 335 323 352 342 285 307 350 332 328 315 326 359 336 319 345 330 325 329 331 312 350 322 322 350 336 304 331 276 274 289 324 319 336 320 316 316 335 314 316 345 346 291 303 333 334 353 330 336 345 337 326 333 317 345 352 330 365 323 290 325 301 323 300 287 348 348 332 305 325 322 333 321 313 294 325 318 323 334 368 315 346 342 340 339 300 332 342 327 342 317 351 322 312 316 300 367 343 319 309 345 357 322 324 333 300 323 293 334 340 310 305 311 354 300 325 307 317 309 313 362 324 305 322 328 328 340 319 327 298 274 315 311 325 311 361 332 322 324 353 306 331 294 314 330 322 336 303 307 286 338 270 303 296 334 326 279 328 295 317 301 328 289 321 331 311 360 316 347 355 305 313 338 330 325 316 330 322 301 322 322 320 307 304 285 323 319 330 306 291 297 333 333 326 302 324 328 296 331 301 294 346 308 309 322 334 325 319 319 343 302 301 345 340 299 303 317 339 305 315 302 340 319 330 316 306 313 311 295 337 288 331 291 326 303 286 300 315 334 353 323 318 287 312 314 333 302 280 329 298 330 322 357 325 317 314 325 328 336 336 317 309 320 343 340 295 320 334 331 324 306 307 336 332 343 315 350 321 347 317 312 318 298 281 321 311 369 335 358 338 326 334 306 294 337 349 318 348 324 312 309 324 336 330 344 332 360 343 341 343 294 330 352 340 304 334 349 334 317 331 358 304 317 316 365 339 338 316 324 315 344 324 354 331 311 325 325 317 348 311 362 316 320 336 342 347 327 316 332 320 337 317 349 322 328 323 343 321 316 327 280 301 301 295 355 359 340 323 356 319 351 347 322 352 350 317 311 324 357 325 338 344 335 345 339 320 287 369 275 316 299 326 313 370 322 357 317 314 311 328 360 326 333 342 349 328 312 327 329 331 324 314 318 339 355 313 354 336 307 304 325 350 342 338 340 315 312 347 316 347 367 340 321 346 333 352 318 330 328 342 334 305 337 359 322 342 291 349 363 307 367 350 356 336 357 340 347 358 331 329 358 321 327 324 355 323 348 326 342 379 341 300 358 347 349 371 334 330 339 342 318 290 343 340 313 355 342 337 312 340 338 311 348 303 358 348 315 370 355 330 368 339 308 371 337 311 310 316 349 322 327 309 312 355 325 333 333 343 321 302 352 353 304 320 317 373 370 324 327 346 359 356 341 361 342 327 364 330 352 333 348 339 346 331 334 361 358 316 345 350 353 325 348 328 330 320 379 362 342 330 352 344 346 330 347 345 361 369 374 346 355 353 342 325 352 342 318 335 364 346 349 363 375 323 342 327 317 355 360 340 330 347 317 336 331 333 358 353 338 329 338 312 360 329 358 329 319 363 317 343 335 331 329 328 356 375 318 333 333 351 337 343 327 347 337 336 341 336 373 363 342 359 331 331 378 332 373 333 333 336 336 321 330 328 337 363 346 372 326 328 346 332 349 342 337 350 390 356 333 367 348 332 347 337 372 351 345 322 325 346 332 360 323 342 325 311 304 340 345 311 337 292 339 355 349 333 304 340 335 321 322 312 305 364 340 351 346 303 333 301 362 345 334 307 313 352 317 330 354 344 310 326 350 347 290 329 315 319 336 324 345 365 358 348 318 303 321 360 335 311 313 375 318 340 343 335 336 363 344 305 327 297 321 370 333 316 310 339 342 338 346 307 345 291 332 342 339 332 319 331 319 356 332 318 380 316 334 335 318 349 309 316 313 349 324 324 326 302 322 318 328 331 317 319 331 296 305 357 344 313 331 336 306 358 321 350 321 329 368 329 300 299 289 272 325 333 327 342 307 310 335 281 304 319 348 312 314 324 328 298 302 299 294 314 334 331 317 301 344 317 306 325 331 357 309 311 327 302 325 314 320 333 333 359 313 331 348 348 310 316 319 314 288 311 329 346 292 342 351 345 319 291 319 323 335 322 314 304 283 291 302 278 313 302 289 281 299 329 302 291 335 308 303 292 307 319 319 318 300 345 296 298 299 302 326 282 296 325 331 311 264 309 306 283 294 299 310 323 326 285 319 246 334 290 279 329 316 304 319 309 295 313 320 285 300 271 304 292 324 310 311 294 301 267 320 295 282 301 289 297 312 298 294 307 310 309 304 305 314 295 331 309 303 278 319 286 323 295 312 294 284 298 268 287 319 297 292 302 306 286 290 311 276 298 278 284 297 281 292 324 276 301 286 281 290 286 294 331 304 292 283 298 307 302 286 296 279 285 311 301 286 308 314 271 305 294 285 291 281 303 285 286 279 291 270 314 267 304 305 303 298 257 294 300 248 256 311 276 287 298 259 276 279 274 302 267 279 288 326 282 278 283 274 270 292 292 267 300 277 275 299 275 266 292 292 296 270 287 333 273 287 298 288 265 299 262 271 281 325 278 284 274 303 265 271 273 284 259 287 277 264 286 312 274 281 290 288 290 306 279 264 244 244 263 291 274 257 277 308 249 243 248 283 276 277 277 282 308 265 262 286 248 309 265 272 273 262 275 261 275 273 278 264 288 274 301 266 263 281 261 267 285 283 296 234 285 288 269 288 296 281 286 294 274 267 285 249 245 272 234 274 284 276 261 285 273 248 287 283 231 269 291 261 236 287 258 284 287 260 270 267 276 249 260 284 286 248 263 301 270 285 266 264 258 250 289 283 274 268 264 292 262 258 283 259 287 267 258 291 280 260 241 257 244 232 247 285 248 289 239 260 239 289 283 274 278 259 219 292 265 284 267 260 264 257 267 257 288 259 264 287 267 272 250 277 246 255 263 268 233 268 243 255 237 242 235 262 242 266 233 262 237 222 247 298 269 288 244 256 270 238 237 246 249 222 260 264 285 269 272 281 257 233 249 241 262 266 263 259 255 237 242 263 228 228 238 225 263 264 282 202 264 259 242 258 234 217 225 279 261 283 235 256 239 259 238 247 264 236 269 244 260 223 258 238 298 267 268 235 284 232 260 273 266 267 246 236 245 273 237 233 227 234 259 248 243 236 242 221 232 243 224 256 260 258 224 237 266 243 244 258 255 233 224 256 246 249 212 210 229 225 222 245 260 243 249 244 243 258 266 258 228 228 258 237 223 281 266 258 255 245 241 261 223 243 266 259 263 257 246 272 239 216 261 261 235 248 223 272 230 241 225 260 255 234 243 208 248 220 243 232 221 296 228 227 220 208 225 242 246 230 241 233 235 266 245 258 227 238 229 217 224 240 229 235 237 233 224 272 260 214 228 227 228 248 237 258 232 245 255 241 240 233 244 247 245 232 226 238 203 230 266 231 213 245 234 258 236 238 258 262 232 247 245 210 245 240 239 245 239 222 223 209 249 225 228 210 261 289 226 210 279 228 228 205 241 229 256 224 213 222 265 229 249 220 243 255 221 224 221 220 240 214 227 196 197 257 234 240 214 231 244 216 259 226 224 259 247 225 244 217 224 238 225 211 219 228 229 225 232 262 227 223 225 227 246 240 217 241 228 232 230 239 234 195 235 208 232 238 243 234 236 241 240 201 216 238 255 232 225 231 233 227 229 249 230 212 236 248 225 217 255 227 239 213 257 269 241 215 231 213 204 222 222 225 250 223 237 220 218 210 224 232 229 226 226 240 209 276 238 228 226 238 276 230 241 212 233 224 182 227 236 234 234 267 240 221 246 237 245 241 226 237 226 232 226 248 219 264 219 232 218 228 235 226 231 220 242 245 221 242 223 221 209 242 229 223 221 243 245 272 231 236 213 255 218 235 239 221 244 235 211 266 221 204 214 219 214 198 234 227 262 241 204 211 235 223 245 217 239 209 247 200 207 212 233 223 223 215 204 240 219 229 243 218 210 227 224 218 230 200 228 215 233 226 200 211 206 226 234 210 230 206 218 219 221 221 244 223 202 234 220 234 218 222 212 239 229 217 237 244 260 232 239 225 209 222 241 226 211 241 231 207 235 205 229 257 231 206 213 228 230 214 245 214 220 218 204 226 223 213 199 213 214 231 222 208 242 240 217 223 241 220 218 222 224 217 241 245 230 238 232 193 231 219 204 239 247 227 233 215 229 237 215 206 231 247 222 218 216 217 212 223 235 200 228 198 211 215 204 257 219 230 226 224 239 230 237 215 228 218 220 215 211 206 236 228 216 225 195 228 228 206 239 238 235 240 215 246 212 220 246 194 197 233 208 206 211 224 212 182 228 228 219 255 224 255 240 229 195 211 220 261 234 239 207 218 214 212 212 196 223 224 202 206 219 217 230 201 210 228 238 224 257 221 224 218 217 207 224 213 229 231 226 230 212 199 227 244 238 225 200 223 223 223 202 263 190 227 212 205 231 220 218 215 213 235 233 238 246 233 232 235 232 215 216 219 206 205 242 205 216 232 216 212 263 202 227 210 205 228 212 230 206 220 208 231 223 225 216 231 210 227 223 223 213 212 244 215 246 209 233 189 219 212 190 207 233 206 213 226 194 246 198 188 214 198 221 229 219 197 209 246 213 232 196 225 209 202 217 185 205 171 193 226 191 238 210 212 228 210 268 226 210 221 217 221 222 224 245 232 246 247 230 219 194 238 224 218 227 207 231 247 265 206 223 201 215 194 218 204 208 229 218 196 213 241 232 238 190 229 223 229 233 213 200 232 244 203 217 211 218 229 241 198 216 213 202 203 202 244 222 221 243 219 230 207 188 225 203 214 206 234 241 225 222 256 191 218 239 222 220 221 203 212 229 219 231 231 245 206 221 198 225 228 242 194 227 207 207 214 193 193 201 229 218 217 245 198 213 195 223 208 184 227 224 210 187 196 218 212 200 209 210 229 261 231 194 255 238 234 197 222 232 209 235 215 193 193 227 227 237 212 191 229 238 195 223 209 215 202 184 239 183 255 216 191 228 193 187 219 231 204 204 223 224 230 204 212 206 202 215 234 218 219 203 216 216 198 214 237 179 230 250 217 180 194 229 179 222 236 197 207 203 225 216 222 198 214 200 187 224 231 225 198 218 218 186 209 212 194 236 215 215 227 223 194 212 204 190 211 210 196 216 187 222 222 213 225 198 207 177 204 204 203 210 200 190 222 209 218 217 192 197 206 223 199 227 197 204 216 216 210 207 214 216 196 190 203 184 205 205 218 208 188 218 234 210 231 217 248 222 212 190 212 192 209 194 243 217 212 208 211 226 209 208 200 200 200 204 203 203 233 198 235 196 220 186 197 211 190 229 213 225 233 208 209 194 216 205 218 187 214 208 196 244 233 215 204 234 214 205 226 210 208 191 232 212 220 203 217 204 208 243 209 230 213 195 236 203 207 227 228 194 202 221 230 237 206 208 194 221 209 211 241 203 187 198 204 242 190 214 203 201 185 218 219 200 181 219 208 209 213 208 211 218 190 242 200 216 217 207 220 196 196 199 210 166 187 192 197 219 205 185 203 206 191 202 233 227 215 247 218 229 193 211 199 209 208 236 225 217 230 223 222 211 231 202 225 194 223 222 194 188 212 207 216 225 220 203 205 190 222 212 197 230 231 226 217 226 184 222 195 211 226 223 214 217 224 225 202 188 207 208 220 230 204 222 213 236 212 234 220 209 203 189 208 173 199 204 220 215 231 199 226 225 240 190 207 198 205 200 202 202 215 224 214 217 220 225 255 215 205 209 184 222 224 214 228 221 205 228 222 210 216 218 195 226 245 209 241 259 202 213 224 228 245 230 221 224 211 235 206 207 203 201 231 220 234 217 227 206 217 236 221 225 231 222 216 221 229 223 246 212 202 197 218 223 238 228 212 212 212 211 226 226 213 226 202 195 217 216 227 247 228 224 234 240 225 208 221 211 235 229 227 188 215 233 213 224 208 222 197 239 206 233 219 225 236 230 204 224 205 216 223 230 231 207 243 203 231 217 255 212 204 183 213 207 205 194 216 209 203 218 239 257 242 206 233 180 232 212 203 203 212 201 209 217 221 227 235 202 213 236 215 224 248 205 232 215 224 218 213 193 214 218 232 221 220 212 206 219 213 259 226 194 216 249 218 211 220 219 207 218 212 230 203 213 229 202 216 213 233 227 225 234 240 222 212 233 214 225 215 215 213 227 211 226 195 217 224 240 238 192 198 212 204 236 222 196 231 206 224 202 212 218 240 210 227 246 213 240 231 194 243 212 212 209 237 213 233 245 223 248 215 219 226 221 226 229 221 237 239 218 231 230 265 233 247 184 246 215 221 225 212 211 220 242 246 234 226 222 244 225 222 219 249 195 216 233 238 234 210 271 212 235 226 228 238 261 255 236 215 225 257 224 239 250 226 233 227 206 244 205 225 217 271 272 239 238 256 238 246 241 236 230 213 250 219 264 244 245 270 245 305 279 267 257 235 246 294 240 267 299 268 261 273 316 271 279 298 286 291 290 281 283 341 277 318 313 326 339 396 366 341 335 382 365 386 384 367 378 399 380 384 393 391 382 333 347 346 322 352 318 333 331 317 305 312 270 314 294 282 302 274 273 268 286 289 299 231 262 268 265 268 249 240 241 240 229 238 241 218 226 230 230 236 232 242 255 255 231 224 249 230 234 236 246 230 221 228 224 229 223 222 219 217 238 214 247 246 203 219 208 203 234 231 217 208 240 206 207 209 229 224 190 226 229 214 222 218 215 217 200 243 199 245 199 233 219 231 219 236 211 215 213 237 232 221 238 194 208 223 224 234 209 235 188 231 225 228 197 218 216 235 196 219 245 226 205 221 217 217 221 231 229 229 207 226 218 213 238 217 234 221 215 196 247 183 227 203 201 231 231 201 218 231 217 218 203 208 227 185 215 231 186 181 223 216 217 212 242 220 215 232 226 190 224 229 233 209 235 224 177 189 221 232 214 218 219 216 213 202 208 212 199 227 227 200 244 240 214 200 225 196 203 219 205 217 211 215 257 220 211 214 217 195 219 257 200 219 193 204 213 174 205 199 233 217 219 222 204 196 220 248 231 219 212 223 232 194 212 212 198 227 239 201 219 238 209 202 214 224 224 211 221 224 227 222 189 221 203 199 213 227 228 199 225 229 193 218 190 213 231 211 223 214 211 259 221 202 236 237 226 222 222 217 205 223 222 204 215 229 195 201 217 216 234 214 207 214 201 217 230 222 208 227 227 232 223 212 199 204 224 229 210 231 230 213 226 234 210 231 224 223 241 243 223 213 209 193 208 224 224 223 203 213 204 222 232 188 217 226 226 211 213 209 204 186 212 202 238 215 192 248 216 212 213 228 198 241 201 214 202 220 203 224 210 219 228 228 219 207 208 205 226 235 214 221 179 218 242 218 218 201 200 233 240 220 230 222 237 213 231 219 207 220 215 206 217 215 228 209 198 210 212 199 226 227 207 217 238 221 231 214 221 223 224 236 217 217 234 202 214 187 226 216 214 201 248 221 225 213 202 208 207 220 198 231 209 209 227 236 193 180 200 240 216 214 221 220 224 196 214 225 213 204 236 217 229 214 202 194 176 215 229 228 210 213 209 199 221 223 213 222 226 193 205 212 224 208 220 238 200 226 234 228 213 204 213 208 228 233 196 177 193 213 223 242 212 227 239 227 205 201 219 200 235 208 200 221 242 237 201 198 224 205 207 200 226 250 213 236 220 227 238 215 218 194 217 240 231 200 212 217 217 221 196 203 190 220 228 218 198 218 202 234 224 207 189 215 219 234 221 256 202 222 201 227 220 219 217 241 214 206 215 233 259 221 208 216 225 217 220 211 200 204 243 210 231 200 218 207 221 215 197 233 241 193 196 255 224 208 219 211 232 213 236 192 223 211 219 199 217 234 217 209 211 238 214 204 220 224 256 222 209 204 209 213 233 206 248 223 223 227 236 187 217 216 227 209 191 202 200 224 239 209 200 214 216 226 200 232 232 238 233 230 203 230 196 192 212 240 235 209 212 220 198 219 219 210 194 192 211 233 222 205 220 201 221 232 214 209 219 218 214 209 222 244 212 208 214 213 219 230 182 212 232 225 211 215 226 215 207 227 234 218 195 189 221 192 206 218 240 222 209 228 240 220 200 228 208 233 206 221 211 223 229 209 200 222 186 190 192 212 205 224 215 217 224 213 221 204 242 206 209 243 240 208 229 203 214 206 225 214 233 217 227 208 246 213 204 229 244 235 228 195 230 246 241 204 214 199 212 214 238 216 208 213 229 227 237 204 206 258 229 228 236 223 224 231 216 222 215 205 222 239 232 201 205 234 217 222 196 201 223 207 211 224 225 255 238 240 219 195 200 229 220 183 204 225 206 201 226 207 228 209 206 214 227 196 233 204 211 198 210 225 192 202 212 210 233 203 209 220 246 191 233 212 198 207 202 212 230 226 215 243 238 228 200 244 202 219 209 213 205 228 212 225 235 214 218 235 214 222 230 229 202 224 230 217 208 226 227 210 241 220 216 204 245 195 243 211 204 200 220 207 241 217 204 213 206 217 231 220 204 224 231 234 232 193 230 229 245 232 224 206 227 196 212 220 221 193 229 250 203 226 206 239 225 220 218 226 215 209 215 200 198 227 223 218 208 192 221 198 231 206 185 247 210 188 194 229 215 201 230 225 208 216 215 218 201 224 221 231 219 224 207 228 236 218 223 202 201 229 215 234 228 235 224 193 230 224 229 220 201 207 188 219 209 189 232 226 227 212 226 197 243 223 203 225 207 232 206 200 239 232 213 212 218 217 205 220 208 208 203 232 194 209 197 206 206 214 215 213 202 218 226 227 234 209 214 240 229 208 235 216 238 208 205 207 226 215 230 204 230 231 198 214 214 192 203 189 192 194 229 216 199 217 219 214 228 213 216 209 217 200 227 223 230 255 225 223 220 202 206 215 214 220 219 231 203 235 210 240 210 226 181 227 232 243 201 209 217 208 249 234 207 215 220 222 232 211 221 205 237 237 226 202 225 205 199 192 188 229 225 223 219 207 207 222 204 195 231 218 207 242 213 199 216 242 216 217 227 201 216 219 244 230 208 193 207 248 222 229 207 208 216 220 212 215 225 232 213 209 218 189 203 192 221 215 202 223 232 198 221 203 219 234 208 218 207 210 222 203 223 216 189 204 215 218 243 199 218 216 229 200 205 206 236 209 205 229 210 246 204 218 241 214 215 212 215 243 186 202 231 176 207 213 222 204 231 209 221 225 227 211 212 237 224 217 223 241 208 244 215 199 231 220 216 203 232 226 214 201 205 238 217 216 216 217 221 198 190 220 216 211 212 220 211 219 218 212 202 201 208 223 209 231 208 188 225 217 235 209 230 225 230 230 214 219 233 217 198 194 230 210 203 221 245 214 210 212 202 221 197 197 184 220 210 244 224 217 217 216 217 198 189 218 198 207 202 208 220 220 210 208 221 218 223 209 207 204 222 217 223 188 216 210 217 223 224 241 211 217 216 200 233 208 209 207 236 227 202 227 215 219 201 219 218 216 194 217 224 203 223 227 237 208 212 220 208 230 200 187 195 227 191 165 194 210 220 223 221 219 226 212 212 227 215 214 234 223 198 197 214 231 240 245 208 218 220 202 222 226 234 227 186 239 195 213 222 243 208 232 232 208 241 213 179 212 194 226 195 221 211 223 208 226 203 209 208 249 227 210 227 217 262 221 226 226 224 222 221 210 209 224 198 203 197 202 187 231 208 228 211 217 236 213 223 218 223 193 208 224 210 230 245 224 211 225 206 234 202 230 230 237 228 215 210 210 222 199 221 214 219 208 213 219 236 229 208 202 229 215 215 219 228 203 201 196 219 212 218 215 190 210 222 244 222 229 203 216 203 204 216 217 198 220 228 196 224 201 236 213 222 266 219 201 209 239 235 221 211 226 198 267 221 212 195 210 204 213 221 226 209 208 204 227 219 226 208 225 213 241 213 218 246 201 218 228 225 217 214 231 199 193 209 227 222 202 196 195 209 201 208 193 217 220 215 196 241 238 202 195 194 208 246 211 203 227 212 227 243 214 243 211 200 183 212 205 204 230 171 220 239 215 210 217 220 222 218 199 202 256 211 207 218 217 226 221 238 223 244 237 212 207 233 199 245 205 243 240 229 224 218 239 232 205 211 176 198 219 211 211 227 230 217 219 210 217 231 233 218 214 217 215 206 224 183 199 222 222 222 204 202 236 223 225 218 199 230 221 221 247 235 237 213 216 242 216 159 262 243 241 202 201 194 209 210 198 196 233 225 212 198 205 214 209 201 212 229 234 200 217 235 215 203 196 228 228 230 219 211 215 217 213 212 229 241 232 235 242 205 248 225 213 231 228 217 204 236 204 227 213 213 214 249 221 203 227 221 233 224 214 229 231 263 244 202 226 267 211 245 247 208 236 227 232 234 207 226 247 215 231 235 200 230 239 262 224 232 234 228 237 213 202 219 233 260 216 216 238 196 255 263 240 232 232 219 242 226 217 216 203 198 223 202 230 212 244 231 213 223 222 233 229 221 230 205 223 230 242 260 207 222 225 233 213 245 207 247 224 212 228 206 226 220 215 211 213 223 223 234 237 209 243 221 204 236 220 206 211 237 230 230 240 218 224 208 220 226 191 247 224 212 220 209 204 209 215 258 215 248 232 237 216 217 230 232 221 203 257 211 205 190 228 242 219 209 217 213 218 203 216 208 221 209 210 216 248 226 238 217 244 234 198 213 203 237 199 238 234 222 233 239 241 232 203 260 234 203 219 205 226 219 235 220 217 224 221 238 228 232 201 226 225 224 231 223 242 209 246 211 233 231 206 257 223 235 205 256 215 237 243 224 214 215 242 226 218 211 223 236 229 234 212 240 240 238 216 214 243 247 209 212 226 270 226 238 229 234 200 246 239 219 229 241 239 255 233 235 225 234 223 250 235 232 210 239 223 223 239 246 228 234 243 230 233 217 241 222 219 243 245 222 242 221 223 222 222 212 260 212 234 241 218 223 226 202 258 239 214 235 247 228 227 244 217 245 216 233 246 203 222 213 208 243 229 239 235 228 258 243 235 209 247 229 231 243 203 231 220 205 213 256 196 240 211 235 234 233 263 227 235 214 207 222 247 235 236 223 228 242 233 234 238 231 230 230 236 240 233 199 249 223 258 217 264 210 240 221 246 261 216 230 216 225 244 242 211 245 230 237 235 205 270 221 244 259 241 274 210 262 231 228 223 225 239 235 247 249 218 209 234 262 226 232 236 223 231 240 214 239 240 239 231 207 249 236 236 259 221 199 224 224 237 274 223 230 227 206 243 238 261 245 242 236 208 225 232 255 211 232 217 227 224 222 238 221 195 211 239 219 265 221 255 227 219 203 216 213 230 231 229 233 256 232 231 231 238 201 245 214 234 233 232 218 224 219 233 230 224 246 213 220 205 219 202 231 204 173 232 228 259 236 233 247 244 226 207 219 243 205 233 233 205 219 211 229 178 225 221 213 240 225 229 233 233 232 231 222 227 216 220 211 209 202 192 228 239 231 191 229 244 213 239 200 227 259 238 232 206 229 227 214 232 234 235 231 214 239 209 248 220 247 236 194 243 222 215 228 238 206 224 240 229 233 218 233 262 227 242 214 210 233 217 228 237 235 247 197 202 222 247 235 224 231 235 244 198 218 235 220 270 205 248 247 220 214 209 230 208 230 237 230 203 225 242 229 217 219 204 199 233 203 223 206 225 240 217 240 229 239 230 216 221 210 235 249 231 268 244 234 241 240 221 223 229 199 194 236 231 242 209 234 243 265 216 223 231 230 238 231 225 200 230 212 212 224 207 243 227 238 191 216 241 216 207 215 235 219 242 237 230 223 243 212 239 238 213 243 278 221 205 239 238 220 232 267 239 229 224 232 228 231 224 214 217 216 230 209 231 239 226 214 242 232 214 248 211 255 246 214 235 245 222 206 240 202 255 208 225 219 240 224 217 229 239 202 221 223 212 196 209 204 190 238 243 225 217 234 224 219 236 221 224 247 234 213 205 229 234 235 234 231 207 213 238 230 213 201 206 217 240 213 264 224 220 210 232 203 233 222 279 239 224 236 206 210 283 212 239 221 220 225 215 210 227 193 259 205 238 228 233 226 207 241 211 218 268 247 245 245 213 223 234 227 248 246 210 242 243 219 244 220 222 215 223 264 232 238 196 225 217 215 211 228 208 219 196 234 267 273 239 224 233 207 228 224 234 229 200 240 225 225 223 232 203 217 256 247 222 246 216 229 244 213 223 243 249 231 240 232 224 227 221 243 220 230 221 216 206 244 223 224 227 220 239 268 244 197 215 233 247 226 239 225 245 193 229 223 220 242 177 226 247 230 211 195 207 234 234 239 210 233 210 216 258 200 245 196 216 255 225 204 227 221 237 192 236 218 243 243 228 226 207 240 211 200 234 197 229 235 226 231 206 227 265 211 237 212 232 224 245 222 226 206 231 223 224 217 228 233 227 222 236 240 260 264 234 242 221 241 236 217 233 219 235 227 208 233 197 264 212 222 200 225 206 211 233 249 214 221 217 249 242 243 205 222 244 216 218 244 219 217 247 216 217 225 247 225 218 187 229 215 219 235 229 201 217 209 213 228 259 227 223 222 228 217 247 221 193 239 208 233 206 209 213 216 215 236 208 209 201 216 255 232 228 217 228 219 216 211 255 204 249 223 216 206 244 213 228 223 234 218 257 259 233 224 223 228 232 222 256 209 216 243 224 223 218 260 256 231 236 246 235 212 215 243 241 209 221 237 235 229 215 218 226 208 209 224 226 222 226 234 217 240 246 223 225 228 225 225 257 238 241 236 220 225 209 214 247 240 217 224 240 204 237 218 217 223 239 213 227 215 231 222 232 205 231 225 229 220 216 233 217 271 229 232 245 261 234 234 234 261 220 230 261 216 241 241 192 223 243 227 233 272 255 219 249 211 213 231 220 201 222 244 224 222 192 211 217 231 247 239 268 219 214 219 187 238 233 224 219 220 222 235 223 213 233 246 208 211 224 245 250 230 219 225 221 234 246 195 232 218 233 263 223 226 224 219 223 215 227 242 220 209 230 214 247 226 231 212 213 224 231 220 259 203 220 204 242 230 207 249 224 222 240 230 261 238 197 241 202 226 215 202 242 218 215 210 222 235 226 217 211 226 234 234 198 235 244 239 222 220 223 213 219 224 237 240 231 235 247 241 235 230 262 234 235 241 225 242 198 258 233 215 211 258 260 266 231 219 249 204 242 211 241 233 220 260 237 235 200 239 201 243 249 239 226 224 218 227 217 220 222 209 216 263 216 257 224 240 234 238 226 231 241 259 226 233 240 218 233 263 226 213 225 225 226 230 219 222 232 220 263 234 212 237 219 220 227 237 232 225 256 217 249 233 246 216 244 227 211 235 242 225 227 229 210 219 230 232 226 225 231 231 224 240 222 230 270 218 221 226 231 226 242 234 239 259 218 224 219 235 216 214 227 266 243 243 222 231 232 245 238 235 273 231 222 235 191 232 224 199 233 260 222 235 241 232 224 236 242 232 239 237 237 244 225 277 217 235 236 214 227 249 227 213 223 232 215 238 219 240 223 207 231 219 210 243 221 247 214 228 219 274 240 247 225 184 234 242 234 217 237 232 225 245 227 261 231 198 231 203 244 219 237 230 208 224 215 261 225 216 240 238 255 261 239 229 232 215 221 217 228 226 237 228 204 215 234 248 226 245 234 243 242 241 231 242 186 192 232 230 221 205 243 223 207 228 248 263 199 216 228 240 244 231 228 220 238 200 229 247 249 229 222 221 238 231 230 257 208 240 235 241 245 249 217 256 210 245 232 233 232 238 234 244 208 221 223 231 201 218 220 248 222 263 220 228 225 243 217 249 230 259 241 221 225 236 286 217 228 238 243 235 220 224 230 203 228 212 240 212 237 230 226 230 218 226 200 218 238 217 205 226 225 225 264 247 231 236 227 236 233 258 230 221 276 266 230 219 233 266 223 235 201 211 241 268 229 225 235 245 233 236 231 245 229 220 241 265 248 244 239 232 237 233 211 232 233 236 219 232 228 215 199 246 207 217 216 214 215 259 249 233 244 214 231 224 227 245 249 241 272 241 242 233 231 232 234 245 222 245 237 266 236 244 239 213 228 240 220 207 237 244 260 229 233 226 257 229 256 237 213 233 217 223 237 235 231 195 237 215 231 211 224 219 214 227 205 242 228 258 232 256 219 255 227 209 202 237 224 228 221 218 217 226 198 228 223 227 271 233 227 225 208 215 235 220 218 249 229 203 210 202 233 237 238 228 204 214 229 244 228 223 238 198 216 214 203 228 217 216 222 235 237 217 202 206 233 223 199 227 204 220 232 193 227 232 227 238 234 221 220 232 209 226 214 258 208 257 240 220 245 214 261 225 216 219 240 236 229 213 209 207 217 216 221 233 207 214 245 202 248 220 229 232 217 255 255 234 256 227 246 257 219 240 235 228 257 213 249 205 221 208 257 229 230 256 198 235 209 235 237 235 207 236 234 241 265 201 241 214 245 234 219 238 235 236 234 247 239 222 240 208 223 237 219 240 246 223 242 198 242 220 225 228 221 264 238 222 235 234 239 232 214 238 221 232 206 222 224 264 220 229 269 227 228 222 205 236 245 208 220 235 218 231 248 220 249 222 243 207 225 256 216 227 222 233 212 218 224 194 215 219 249 221 218 215 230 228 232 227 236 248 218 217 202 257 233 239 214 232 270 239 238 240 229 230 192 221 268 219 212 230 218 240 226 234 237 268 264 221 233 240 225 245 201 245 242 238 234 216 208 225 248 238 225 248 219 255 259 223 232 234 239 239 225 217 215 231 210 211 256 227 216 208 243 193 257 231 233 203 218 234 241 216 230 234 187 231 198 208 222 242 237 226 197 230 240 226 228 219 255 234 221 271 235 241 204 263 229 260 229 256 211 239 215 225 243 242 222 199 223 219 233 240 236 267 240 223 212 218 207 231 235 228 266 216 212 244 258 243 209 239 221 224 255 237 248 260 239 227 242 257 237 257 245 215 245 231 229 226 231 216 228 226 215 233 255 226 243 222 242 230 217 202 255 234 264 210 265 232 247 249 223 238 240 267 270 249 234 237 264 255 271 245 267 248 277 281 248 239 268 284 276 265 275 231 275 259 255 261 264 256 257 268 233 272 245 234 293 289 279 233 266 265 264 233 242 275 278 265 248 269 249 257 255 244 275 248 249 226 242 256 263 247 260 255 240 233 265 257 242 243 243 220 208 245 234 231 226 222 221 238 236 229 219 200 223 243 263 199 263 264 220 216 243 207 210 262 216 233 219 221 231 237 222 232 235 244 219 245 233 218 235 248 229 235 235 206 238 221 214 233 214 221 232 201 236 230 213 263 240 283 215 211 230 232 217 261 213 227 243 214 256 236 236 226 207 229 228 246 208 260 222 243 236 215 219 217 255 229 238 229 240 232 218 258 234 233 233 228 221 214 240 230 231 225 227 225 220 231 264 233 217 239 231 225 226 245 209 232 244 240 233 238 211 208 217 262 240 222 273 227 217 228 226 236 236 229 220 210 213 221 243 221 218 248 220 231 215 228 245 228 238 211 206 214 220 257 220 218 239 239 234 222 228 229 212 250 229 236 223 228 228 212 218 257 231 247 235 214 225 230 233 213 238 246 245 224 224 204 240 259 245 213 226 221 237 216 208 240 243 226 271 233 241 235 211 224 205 210 228 213 237 239 217 268 231 211 217 231 240 204 232 222 218 243 215 239 222 239 212 216 211 246 210 243 231 234 255 237 227 239 238 223 217 228 240 226 246 236 236 239 228 217 259 233 206 201 228 247 228 262 236 229 231 198 214 246 239 235 222 234 219 237 214 260 244 201 262 256 208 234 222 225 257 233 257 230 239 232 223 201 228 230 235 205 219 234 227 236 209 229 213 223 225 227 239 245 232 224 197 244 238 233 234 222 240 228 243 241 222 220 234 205 239 257 220 261 217 268 208 223 212 213 227 225 225 232 227 242 233 231 225 223 242 242 232 204 242 208 244 195 266 206 200 215 207 245 207 237 222 257 238 238 278 224 246 242 239 247 241 265 222 235 244 228 233 227 219 239 218 256 227 224 241 246 223 246 231 266 221 237 239 246 228 242 248 277 235 233 240 225 204 200 235 235 201 240 222 225 219 204 219 219 257 223 243 225 208 223 218 216 243 200 250 231 178 216 243 211 236 217 243 246 240 233 222 250 200 227 233 237 232 231 236 206 232 250 233 214 234 241 231 197 233 209 231 208 207 231 214 226 223 246 237 241 222 217 234 209 240 230 199 248 230 234 221 222 225 235 235 241 198 256 220 231 245 206 196 202 218 214 236 224 227 236 208 231 230 256 213 225 228 220 205 228 245 212 180 235 244 201 257 219 262 235 213 242 220 242 217 215 225 236 236 237 228 242 227 206 208 232 228 225 230 242 223 210 239 270 213 245 226 231 227 247 198 211 236 223 235 210 227 217 249 202 259 240 245 203 222 240 232 223 229 186 212 227 224 237 240 215 245 226 208 227 227 233 204 243 232 228 199 273 227 277 244 223 231 209 228 241 247 228 209 222 207 217 264 258 217 261 220 255 210 236 220 243 222 211 195 234 215 219 263 234 221 204 204 240 216 215 243 238 214 222 242 205 207 230 220 242 202 233 205 231 222 208 185 215 237 234 238 199 231 278 239 224 266 212 227 216 247 215 245 209 257 231 203 203 231 237 231 227 241 228 225 238 267 221 204 231 206 207 221 225 224 222 240 224 233 214 223 242 233 214 228 225 257 210 246 245 218 229 219 233 208 244 234 212 217 235 223 242 204 225 202 223 220 233 214 234 238 207 239 223 233 249 238 264 246 240 219 234 203 230 229 226 224 257 234 216 239 224 236 224 242 231 222 235 260 232 227 231 232 225 235 235 203 231 199 226 205 234 235 217 246 257 226 235 239 215 233 213 235 237 221 222 213 210 232 227 202 243 235 225 231 229 226 229 224 222 240 241 272 211 241 256 207 231 236 219 225 249 200 221 216 221 260 249 236 225 248 193 222 219 218 227 225 230 219 248 231 232 229 214 196 190 221 247 221 231 231 207 212 215 268 231 247 228 258 271 227 231 226 230 235 225 227 263 210 218 218 244 236 230 233 230 256 227 245 223 235 215 221 226 213 222 242 204 230 216 217 265 207 247 238 266 220 245 220 214 243 259 218 219 248 215 209 218 210 225 241 248 205 259 186 192 205 226 232 232 211 212 231 247 269 245 221 256 226 221 226 260 247 235 222 212 218 207 236 242 214 247 208 221 204 242 220 212 230 237 259 210 209 231 236 239 203 238 233 226 239 239 211 247 218 203 232 227 221 233 244 265 221 232 204 232 213 236 228 232 224 241 249 185 206 215 208 229 255 241 218 239 260 221 221 240 218 215 242 219 233 224 239 221 215 218 221 236 257 238 208 228 234 228 230 200 226 236 255 235 242 236 244 234 226 238 244 204 222 247 219 220 219 230 230 213 218 221 244 217 220 221 219 198 223 239 227 204 214 207 224 248 246 220 245 263 243 217 227 216 227 224 261 228 265 233 248 232 247 201 217 248 221 245 265 243 229 218 219 275 218 232 242 231 239 222 225 217 225 223 198 239 211 230 201 223 235 221 249 219 211 239 205 225 224 248 246 248 188 262 244 233 240 228 211 217 236 247 258 223 225 238 274 222 243 233 203 231 228 230 232 244 224 223 219 224 258 197 230 230 241 243 221 218 231 224 212 214 244 224 192 226 242 222 231 219 202 262 206 225 233 199 237 229 239 239 236 227 187 226 207 227 224 260 205 217 242 226 228 223 234 218 213 234 248 204 272 244 230 191 226 208 271 257 263 260 248 249 258 227 223 230 224 230 237 220 225 228 242 227 221 228 197 206 233 241 220 256 220 192 227 238 219 247 215 239 262 240 244 211 237 246 240 211 225 205 200 242 210 232 245 242 243 239 258 247 212 220 224 208 243 267 231 259 233 223 242 227 219 231 255 242 238 248 209 222 262 241 247 235 255 227 250 233 276 245 229 225 221 229 242 230 226 214 211 211 223 250 230 255 266 227 220 244 265 217 260 233 236 243 209 245 235 213 237 259 232 216 224 216 227 244 223 229 216 263 235 261 257 248 225 247 215 239 223 234 202 236 210 222 247 209 220 236 258 238 220 228 204 273 237 225 237 233 229 227 271 238 217 235 248 219 230 236 223 226 243 232 232 240 223 225 246 224 263 223 245 235 244 210 213 226 270 248 248 240 242 225 255 220 259 223 241 238 230 216 239 232 261 229 235 255 201 228 248 238 246 260 223 243 228 229 255 237 256 223 239 227 236 201 239 257 242 206 237 231 212 246 246 243 212 232 241 215 211 231 224 214 223 212 223 230 229 220 245 244 232 261 226 209 236 230 227 246 240 221 236 244 245 238 215 234 233 261 228 241 220 255 234 212 212 226 216 233 232 218 227 205 241 226 213 239 265 221 204 241 236 257 229 241 213 224 235 233 257 246 228 244 226 248 245 226 240 237 241 217 255 236 235 228 231 244 236 237 208 258 240 247 232 214 233 228 246 229 255 265 246 228 256 228 218 232 237 233 233 236 226 245 258 241 248 240 212 235 233 246 260 239 242 234 239 256 241 220 221 212 256 224 246 230 227 236 233 219 215 225 248 263 228 227 267 201 241 232 205 233 217 224 247 222 245 237 197 223 202 214 258 235 236 241 243 267 243 246 247 263 242 249 258 244 211 236 233 240 237 223 227 229 222 233 219 247 261 231 231 246 269 238 236 230 272 233 248 229 243 238 196 247 241 227 236 229 239 238 244 207 262 225 200 216 268 218 235 206 261 234 259 238 248 245 243 229 222 236 256 272 241 236 234 242 237 269 246 236 234 228 229 227 237 230 240 242 255 246 256 229 248 240 262 216 244 228 257 225 246 262 225 243 258 269 256 238 238 212 238 238 233 229 257 221 269 269 263 259 246 238 261 232 236 242 226 235 240 257 260 245 260 224 217 245 220 234 249 261 241 248 205 238 278 261 205 265 255 221 255 264 229 249 255 225 247 222 257 263 225 230 216 256 236 236 240 224 232 211 242 215 262 225 237 230 224 233 261 211 231 247 213 219 247 220 233 202 257 248 244 223 246 265 235 257 213 217 241 248 221 224 231 241 236 248 229 209 236 199 231 268 247 225 228 233 247 217 269 228 227 241 237 242 255 235 239 241 220 238 212 229 223 237 224 256 223 219 236 205 215 201 214 228 204 207 263 223 242 235 259 231 210 240 223 205 212 195 216 225 238 268 249 241 286 211 230 222 235 242 234 197 218 211 246 241 229 223 246 238 241 232 212 243 239 260 238 235 255 246 231 235 236 234 199 246 228 233 262 267 213 220 223 213 238 222 239 235 244 244 219 219 238 233 241 224 220 224 259 278 237 222 261 216 247 219 209 216 211 229 223 233 220 230 249 231 243 195 235 210 233 245 250 223 238 247 238 226 226 212 241 232 256 222 233 246 246 261 236 248 222 212 236 236 232 262 212 247 211 230 234 220 190 216 249 234 235 225 233 212 234 239 267 197 229 245 231 221 228 241 214 235 212 223 241 213 220 240 219 220 246 219 245 231 237 224 235 258 224 246 277 227 237 229 259 230 227 248 258 249 229 260 213 217 237 238 220 268 229 216 227 216 235 208 241 262 249 218 244 241 221 255 231 230 247 235 255 232 212 217 246 212 220 218 244 265 195 204 244 207 247 225 233 233 218 245 275 221 243 212 236 237 238 239 231 228 236 226 231 241 211 260 226 229 240 230 235 230 241 210 242 198 193 209 237 239 225 204 221 239 211 233 233 228 255 222 240 208 228 264 226 214 236 227 231 256 204 220 196 213 237 243 185 241 247 229 215 209 213 235 233 244 204 209 229 244 248 195 247 224 223 263 229 225 215 213 224 212 234 223 221 256 244 234 236 231 269 215 235 230 224 197 228 215 227 228 243 228 261 232 211 222 229 226 240 230 220 226 233 238 229 229 242 239 234 216 225 243 210 215 233 256 209 227 193 219 232 257 258 211 212 245 236 228 236 258 231 236 237 222 234 260 212 223 241 230 235 237 225 256 220 221 229 258 224 230 231 200 246 218 231 211 228 216 238 202 248 229 261 234 235 231 258 243 226 208 223 232 205 224 215 245 229 220 243 260 231 215 257 230 269 246 255 209 260 244 221 224 215 234 205 277 216 255 258 234 232 240 236 256 241 231 205 213 241 235 219 219 211 226 228 232 277 237 234 223 217 233 247 215 224 215 266 236 227 243 218 256 224 227 291 234 271 246 221 207 263 203 210 220 268 193 264 247 229 247 217 233 227 226 240 231 236 209 259 235 256 219 278 221 225 224 215 208 255 228 238 228 207 238 232 233 233 205 259 264 231 243 210 207 243 211 230 235 241 216 236 240 231 224 215 206 236 220 238 249 226 229 219 234 256 206 230 260 234 257 221 230 236 219 236 258 260 235 216 223 226 221 260 214 228 243 216 241 205 234 211 260 210 249 260 259 237 227 219 261 233 233 258 203 221 219 214 209 231 229 233 248 188 244 221 224 238 244 231 218 228 249 236 238 216 261 231 219 219 213 239 241 248 217 247 209 247 213 229 232 227 211 220 228 224 236 233 260 241 231 241 239 220 249 242 258 258 225 226 243 249 215 219 214 222 230 233 205 231 227 239 224 222 214 232 265 226 232 246 228 234 221 249 238 217 243 241 231 280 218 245 219 230 228 218 236 236 239 198 212 234 259 240 247 240 218 215 222 231 237 219 220 241 283 230 216 263 218 220 221 232 221 273 243 243 221 263 241 241 242 220 255 223 205 237 264 240 239 262 226 274 242 246 229 258 232 249 237 244 239 256 229 205 245 244 256 229 270 238 240 193 222 219 216 201 238 241 271 266 236 230 239 221 264 236 196 238 215 243 266 219 217 275 216 241 260 233 232 240 244 236 220 232 232 229 210 240 228 263 218 238 219 273 198 202 223 236 248 238 234 212 229 227 219 236 249 241 210 222 226 227 240 230 239 255 224 224 247 239 231 232 247 213 231 220 209 228 229 233 217 247 257 224 245 242 228 258 217 222 271 244 239 210 224 260 239 216 271 226 245 255 229 232 263 216 214 212 234 219 258 209 247 208 228 226 234 219 232 247 265 219 235 232 241 212 207 202 216 231 228 248 238 222 245 241 226 223 238 242 218 230 242 229 258 232 239 221 246 242 232 238 217 211 245 217 214 222 236 211 207 214 237 231 247 239 239 243 248 224 228 222 244 221 237 242 234 231 239 234 246 222 243 230 259 202 259 247 223 231 223 257 241 218 229 233 216 269 211 218 224 213 215 243 241 237 209 244 217 240 232 224 228 197 247 245 217 268 242 210 233 238 236 219 235 248 265 232 204 213 222 210 259 217 231 241 230 236 231 243 226 248 211 223 245 219 246 225 230 258 228 217 209 188 232 225 216 240 216 232 225 255 213 228 210 233 235 225 239 213 226 247 227 291 224 226 223 222 222 232 238 230 201 243 225 235 255 250 239 215 239 268 236 203 241 230 235 238 255 225 214 227 269 236 242 214 210 245 217 233 241 246 241 232 233 257 248 235 255 207 239 228 206 223 230 223 227 249 237 260 227 226 263 215 243 234 238 228 216 214 236 238 256 265 215 193 228 230 224 281 223 256 243 223 215 234 233 236 229 206 234 258 237 214 243 222 274 196 221 247 230 230 224 222 222 217 262 201 220 255 242 222 225 215 239 235 256 226 218 218 265 215 211 247 222 237 238 236 220 229 236 236 256 233 227 255 255 227 224 235 229 245 214 199 242 210 214 227 244 231 239 242 246 232 214 249 201 234 213 232 226 279 216 239 235 240 230 228 234 219 266 237 246 228 213 239 231 225 235 241 207 201 233 215 249 225 211 228 229 238 235 245 225 243 217 232 229 238 212 219 260 226 248 222 205 239 201 232 227 218 215 209 221 236 239 217 230 237 243 226 212 239 212 272 242 224 235 273 235 199 233 216 237 223 216 228 237 232 220 250 245 214 255 233 255 258 237 234 259 229 242 224 290 237 222 258 230 229 236 231 220 235 240 219 227 230 228 230 238 212 217 235 211 234 233 242 206 211 255 239 245 207 239 220 238 200 212 259 213 240 221 276 243 241 247 210 230 243 191 220 215 245 259 207 225 234 237 216 236 236 218 232 244 226 266 220 210 257 216 219 236 199 239 235 226 231 192 262 213 239 221 206 207 235 224 226 232 232 220 228 231 222 221 220 231 249 224 215 205 221 262 247 262 222 213 255 227 230 240 213 272 270 260 216 210 240 220 209 231 213 206 208 219 219 232 233 234 250 235 243 245 235 225 216 235 233 263 248 203 233 203 277 201 245 209 235 232 235 205 238 258 215 273 257 225 246 235 262 236 256 221 215 235 234 262 224 222 202 242 209 219 211 217 227 225 210 241 229 219 210 241 278 256 266 212 224 247 209 226 241 222 261 204 234 246 237 243 215 218 216 240 237 240 215 223 226 265 247 232 225 230 206 244 239 219 234 247 205 239 206 235 242 226 225 244 243 232 241 248 265 220 217 235 209 244 223 245 246 213 218 259 209 233 225 267 233 218 247 278 226 236 250 213 247 267 245 225 240 205 257 217 240 230 227 221 238 242 246 267 233 215 242 230 235 234 255 223 245 235 261 241 231 235 225 217 245 238 230 236 229 234 225 259 206 261 244 268 221 244 233 248 246 232 256 227 216 207 233 241 257 243 230 230 259 241 245 246 210 225 222 234 229 233 234 227 233 214 230 244 228 230 226 238 257 264 244 270 234 230 228 248 212 226 248 225 256 230 262 262 228 260 235 248 246 299 261 225 229 257 249 249 246 263 279 236 244 255 256 225 243 239 269 228 257 262 262 225 227 257 233 260 249 266 261 231 258 242 277 227 201 228 222 247 223 286 224 231 216 233 239 265 239 248 255 215 249 264 261 243 241 267 233 242 233 231 245 270 237 256 244 245 246 257 235 215 249 262 264 243 236 231 241 224 213 214 255 257 234 231 262 264 229 237 222 255 239 260 238 234 239 225 246 225 246 263 233 215 234 234 218 241 246 262 206 259 217 271 258 270 264 236 227 209 232 261 203 228 249 249 242 240 234 219 242 229 225 248 235 241 241 217 221 239 259 248 214 257 259 229 243 234 230 236 221 255 222 226 238 262 274 256 260 227 228 232 215 238 228 222 243 255 279 238 242 232 217 262 255 255 213 235 246 236 268 213 248 264 262 228 219 224 215 230 243 198 235 215 246 232 215 241 211 220 243 227 214 249 227 220 219 202 232 272 203 236 224 212 255 219 223 260 237 213 217 214 211 279 236 193 242 198 232 211 222 227 219 241 241 215 232 233 222 236 234 233 217 227 239 228 230 212 224 218 271 228 234 238 233 236 211 224 225 263 229 230 218 228 225 229 207 223 214 217 244 243 212 232 246 217 265 244 215 232 216 220 239 241 233 247 236 234 240 256 229 234 216 232 216 244 226 234 233 239 272 216 221 236 226 256 229 237 225 227 228 228 257 221 206 248 249 243 247 249 243 211 262 257 233 216 209 224 218 232 212 214 267 246 214 255 220 223 232 201 214 222 261 212 229 238 241 229 221 222 212 232 215 247 237 228 230 231 244 205 236 221 272 217 237 230 230 236 232 219 225 222 228 225 227 217 236 234 255 234 217 198 237 214 235 241 255 224 218 237 247 239 229 228 217 240 230 221 222 229 255 227 218 230 205 247 228 232 204 219 216 216 246 240 256 209 255 238 231 205 242 217 229 218 238 258 220 244 261 226 223 212 228 224 248 233 211 191 242 240 231 233 236 218 222 226 230 223 208 236 226 195 201 210 226 233 234 237 234 235 248 237 259 206 225 228 232 248 226 226 244 223 209 226 214 223 228 224 212 250 255 266 225 227 218 235 237 234 224 236 209 218 233 234 228 268 223 226 246 259 214 198 260 215 248 267 207 230 257 230 244 258 220 247 220 228 230 214 221 258 225 247 223 255 245 200 219 227 207 243 218 245 239 260 222 218 242 235 232 220 208 210 248 214 216 219 231 220 226 236 201 257 203 245 244 215 205 237 232 255 245 235 249 255 202 233 225 226 230 234 212 245 218 214 203 232 217 233 230 238 218 218 227 217 234 259 218 224 205 207 237 245 222 229 232 219 211 220 231 217 231 224 235 249 226 233 213 220 242 221 232 230 263 217 210 266 230 235 220 226 246 231 234 232 201 210 224 265 236 230 233 200 235 230 218 242 238 224 219 230 217 241 235 234 219 256 203 235 226 230 229 240 235 214 225 239 238 230 221 231 222 262 235 256 216 211 231 225 217 229 260 243 212 219 227 245 214 235 241 208 215 236 215 220 236 210 229 227 257 202 217 203 205 226 210 210 220 227 231 236 274 217 241 245 229 233 260 226 219 236 224 244 209 219 214 241 241 246 198 237 191 218 228 239 212 222 229 234 229 234 210 236 232 213 236 219 211 208 217 257 244 223 210 241 220 228 240 218 213 210 243 245 216 193 202 217 227 230 219 233 211 216 278 199 234 239 210 215 221 241 228 211 226 219 245 212 238 218 188 211 222 244 208 236 221 225 240 246 219 222 221 232 233 249 234 215 247 239 238 217 235 234 211 241 245 228 238 229 217 226 235 242 200 217 226 245 216 218 245 222 217 241 235 228 240 217 212 269 200 249 209 193 219 201 225 212 206 237 223 219 208 229 260 215 214 215 235 225 221 245 233 231 213 272 182 213 234 216 273 230 226 225 221 231 210 248 239 197 222 222 205 234 221 226 215 247 238 225 234 226 236 221 222 242 215 221 248 260 209 218 230 224 225 226 209 238 214 227 234 237 256 220 211 199 195 207 217 241 186 221 216 219 240 210 237 219 227 208 216 211 221 227 211 214 235 214 237 242 221 204 234 227 200 233 260 223 208 225 237 236 198 223 202 215 230 206 223 224 197 223 240 258 208 241 238 220 249 231 208 214 230 232 212 201 234 229 244 221 216 228 225 188 225 222 231 207 223 217 258 215 239 258 243 244 220 226 239 222 216 213 197 236 215 219 229 224 239 218 197 210 222 209 198 225 209 245 222 246 200 230 214 213 224 213 214 217 221 221 223 223 230 257 219 223 241 174 218 236 248 237 236 212 224 243 225 204 238 222 232 218 206 232 225 210 196 214 238 237 233 222 223 242 176 220 225 214 235 222 209 240 216 219 237 221 231 217 227 241 222 213 231 258 238 213 248 207 226 215 256 224 224 196 223 270 226 216 223 218 249 225 232 219 228 243 226 223 229 230 216 219 202 217 211 211 218 214 226 248 218 228 231 243 209 229 235 247 213 195 238 220 222 213 233 232 217 219 216 213 203 215 227 186 206 213 228 222 241 210 218 243 228 223 207 210 221 208 225 230 206 193 202 222 186 216 218 217 218 229 200 220 224 216 237 237 224 207 214 231 228 225 194 204 228 188 215 236 210 213 209 237 221 236 210 232 209 239 220 233 219 225 248 235 232 224 226 229 209 226 200 227 235 233 202 218 230 216 193 224 198 219 241 230 221 236 222 210 197 260 223 228 216 212 207 237 234 211 227 218 230 240 210 222 255 215 228 245 212 226 244 224 231 229 228 226 226 210 235 191 218 217 216 222 259 218 217 222 224 242 230 239 261 214 217 236 203 212 218 203 225 202 213 222 215 239 226 240 234 203 238 245 215 230 232 213 208 235 218 255 258 247 248 206 210 198 247 222 217 209 236 200 217 205 232 223 219 206 211 221 229 258 210 238 214 245 225 246 225 231 211 212 229 248 208 220 232 242 196 234 257 227 237 223 195 222 226 223 210 187 214 205 226 229 271 243 215 216 228 233 227 223 231 213 199 227 233 218 231 215 240 220 215 239 219 225 226 228 229 206 239 217 223 228 211 206 248 202 224 219 236 212 220 219 202 223 192 210 228 247 223 238 200 231 240 220 238 219 206 261 225 264 222 261 225 201 211 258 244 236 240 204 231 243 248 215 262 239 232 232 258 224 218 250 231 230 233 256 222 260 226 224 222 241</counts>
			</dataPoints>
		</scan>
	</xrdMeasurement>
</xrdMeasurements>