File: data/XRD/XG-Vakuum/XG-pre/W6822-1C_XG_Vakuum_pre.xrdml
<xrdMeasurements xmlns="http://www.xrdml.com/XRDMeasurement/2.1" xmlns:xsi="http://www.w3.org/2001/XMLSchema-instance" xsi:schemaLocation="http://www.xrdml.com/XRDMeasurement/2.1 http://www.xrdml.com/XRDMeasurement/2.1/XRDMeasurement.xsd" status="Completed">
	<comment>
		<entry>Configuration=Factory configuration, Owner=User-1, Creation date=7/8/2013 4:01:53 PM</entry>
		<entry>Goniometer=PW3050/65 (Theta/2Theta); Minimum step size 2Theta:0.0001; Minimum step size Omega:0.0001</entry>
		<entry>Sample stage=MRD Cradle; Minimum step size Phi:0.01; Minimum step size Chi:0.01; Minimum step size X:0.01; Minimum step size Y:0.01; Minimum step size Z:0.001</entry>
		<entry>Diffractometer system=XPERT-PRO</entry>
		<entry>Measurement program=C:\PANalytical\Data Collector\Programs\Jorrit\2thom\_absolute_2th-om_10-130deg_PIXscan_56min.xrdmp, Identifier={15BCCF57-2807-42BD-B5B9-ECC0B3DC9284}</entry>
		<entry>Batch program=C:\PANalytical\Data Collector\Programs\SimonL\batch8x_2thom_10-130°_z9.1_x0,10,20,30_y20,30,40,50_57min.xrdmp, Identifier={9A1B954C-70C5-4DE2-A2B5-D0000261ED0F}</entry>
	</comment>
	<sample type="To be analyzed">
		<id></id>
		<name></name>
		<preparedBy></preparedBy>
	</sample>
	<xrdMeasurement measurementType="Scan" status="Completed" sampleMode="Reflection">
		<comment>
			<entry>_absolute_2th-om_10-130deg_PIXscan_56min</entry>
			<entry>PHD Lower Level = 4.83 (keV), PHD Upper Level = 11.27 (keV)</entry>
		</comment>
		<usedWavelength intended="K-Alpha 1">
			<kAlpha1 unit="Angstrom">1.5405980</kAlpha1>
			<kAlpha2 unit="Angstrom">1.5444260</kAlpha2>
			<kBeta unit="Angstrom">1.3922500</kBeta>
			<ratioKAlpha2KAlpha1>0.5000</ratioKAlpha2KAlpha1>
		</usedWavelength>
		<incidentBeamPath>
			<radius unit="mm">320.00</radius>
			<xRayTube id="1010048" name="Empyrean Cu LFF HR (9430 033 7310x) DK442154">
				<tension unit="kV">40.0</tension>
				<current unit="mA">40.0</current>
				<anodeMaterial>Cu</anodeMaterial>
				<focus type="Line">
					<length unit="mm">12.0</length>
					<width unit="mm">0.4</width>
					<takeOffAngle unit="deg">4.2</takeOffAngle>
				</focus>
			</xRayTube>
			<xRayMirror id="27010001" name="Inc. Beam Cu W/Si (parabolic MRD)" hybrid="false">
				<crystal type="Graded" shape="Parabolic">W/Si</crystal>
				<acceptanceAngle unit="deg">0.800</acceptanceAngle>
				<length unit="mm">60.0</length>
			</xRayMirror>
			<sollerSlit id="21010002" name="Soller slits 0.04 rad.">
				<opening unit="rad">0.0400</opening>
			</sollerSlit>
			<mask id="22030008" name="Fixed mask 4 mm">
				<distanceToSample unit="mm">220.00</distanceToSample>
				<width unit="mm">4.00</width>
			</mask>
			<divergenceSlit id="22010007" name="Fixed slit 1/8°" xsi:type="fixedDivergenceSlitType">
				<distanceToSample unit="mm">220.00</distanceToSample>
				<height unit="mm">0.19</height>
			</divergenceSlit>
		</incidentBeamPath>
		<diffractedBeamPath>
			<radius unit="mm">320.00</radius>
			<sollerSlit id="21010002" name="Soller slits 0.04 rad.">
				<opening unit="rad">0.0400</opening>
			</sollerSlit>
			<receivingSlit id="22010001" name="Fixed slit 4°">
				<height unit="mm">5.88</height>
			</receivingSlit>
			<detector id="7010017" name="PIXcel3D 1x1 detector" xsi:type="areaDetectorType">
				<phd unit="%">
					<lowerLevel>30.0</lowerLevel>
					<upperLevel>70.0</upperLevel>
				</phd>
				<mode>Scanning</mode>
				<activeChannelsEquatorial>255</activeChannelsEquatorial>
				<activeChannelsAxial>255</activeChannelsAxial>
				<pitchEquatorial unit="mm">0.05500</pitchEquatorial>
				<pitchAxial unit="mm">0.05500</pitchAxial>
				<readOutPeriod unit="seconds">0.135</readOutPeriod>
			</detector>
		</diffractedBeamPath>
		<scan appendNumber="0" mode="Continuous" scanAxis="2Theta-Omega" status="Completed">
			<header>
				<startTimeStamp>2024-10-04T08:24:43+02:00</startTimeStamp>
				<endTimeStamp>2024-10-04T09:20:49+02:00</endTimeStamp>
				<author>
					<name>PRO-MRD</name>
				</author>
				<source>
					<applicationSoftware version="6.1b">Data Collector</applicationSoftware>
					<instrumentControlSoftware version="7.0E 20130304">XPERT-PRO</instrumentControlSoftware>
					<instrumentID>0000000011142674</instrumentID>
				</source>
			</header>
			<dataPoints>
				<positions axis="2Theta" unit="deg">
					<startPosition>9.99826193</startPosition>
					<endPosition>129.99755682</endPosition>
				</positions>
				<positions axis="Omega" unit="deg">
					<startPosition>4.99913096</startPosition>
					<endPosition>64.99877841</endPosition>
				</positions>
				<positions axis="Phi" unit="deg">
					<commonPosition>0.00</commonPosition>
				</positions>
				<positions axis="Chi" unit="deg">
					<commonPosition>0.00</commonPosition>
				</positions>
				<positions axis="X" unit="mm">
					<commonPosition>10.00</commonPosition>
				</positions>
				<positions axis="Y" unit="mm">
					<commonPosition>0.00</commonPosition>
				</positions>
				<positions axis="Z" unit="mm">
					<commonPosition>9.100</commonPosition>
				</positions>
				<commonCountingTime unit="seconds">32.895</commonCountingTime>
				<counts 453 459 471 417 451 391 466 435 477 440 480 447 482 461 455 498 474 470 478 474 447 465 484 477 467 507 460 482 415 455 464 461 461 473 453 421 448 444 443 424 507 456 482 481 484 469 469 464 435 435 459 459 472 519 453 480 444 490 454 422 445 476 454 458 463 430 425 451 440 431 462 468 426 443 423 466 444 430 469 471 448 446 439 450 441 426 411 490 393 427 398 476 412 434 452 431 416 466 428 417 434 434 450 394 436 425 424 401 453 416 421 405 436 437 425 465 427 475 431 439 445 442 407 452 418 421 444 425 418 407 436 453 444 433 434 382 425 451 403 445 433 407 430 395 420 468 428 394 449 454 411 420 441 454 448 409 433 442 415 460 404 419 427 422 412 445 382 431 449 386 411 430 462 430 469 401 398 408 462 411 421 423 420 381 410 437 373 386 411 418 396 403 428 417 393 433 424 388 424 413 436 416 436 414 405 409 429 436 415 387 416 383 399 384 399 401 417 446 404 363 399 415 403 372 406 402 411 430 425 398 417 408 401 417 395 425 412 428 420 399 409 413 373 403 414 389 404 384 392 391 403 436 405 440 399 418 416 393 375 416 422 418 383 422 406 399 409 409 435 399 388 420 380 411 425 423 359 388 409 411 421 382 368 398 380 394 396 368 369 421 386 414 365 429 393 360 333 365 396 385 435 410 367 402 352 400 385 385 359 391 390 397 386 407 372 355 420 366 407 438 369 381 367 393 374 401 377 397 370 416 414 410 375 369 386 365 369 392 407 386 354 390 400 360 398 370 409 358 366 383 411 353 387 359 396 392 384 385 392 391 411 396 402 342 382 405 385 395 379 368 341 385 380 337 370 387 351 382 342 345 388 356 364 399 358 346 383 363 354 361 395 340 380 343 357 379 389 357 382 360 370 370 340 382 358 372 351 386 381 356 363 351 358 352 331 355 396 363 362 356 387 390 358 366 365 363 358 338 321 367 370 356 375 366 362 364 354 379 413 380 314 378 348 377 356 365 338 365 343 366 362 351 358 355 354 364 348 347 328 379 373 316 349 368 365 382 373 402 329 414 347 360 372 379 357 360 359 354 405 326 346 381 339 382 386 350 385 354 362 358 341 369 345 336 357 386 354 361 382 382 371 348 346 347 328 359 391 343 372 350 370 323 348 333 372 348 345 345 364 397 349 355 357 355 338 363 345 360 316 364 338 366 365 345 374 362 328 381 378 335 346 362 382 372 389 312 330 336 336 351 364 329 360 360 335 321 343 334 329 320 331 360 363 356 315 350 347 333 350 357 311 349 364 327 341 360 333 330 335 331 327 351 332 324 332 358 369 354 361 345 354 346 370 357 320 329 296 323 339 367 335 349 313 341 357 330 351 320 337 347 349 321 357 332 355 364 317 334 329 352 290 358 341 357 337 324 335 343 300 342 355 361 353 272 354 311 331 314 355 352 356 316 381 358 365 348 348 316 356 337 348 317 340 341 324 330 346 347 332 326 323 349 339 357 390 318 354 356 347 329 332 340 328 318 355 319 334 339 340 338 341 317 314 359 318 375 331 314 380 363 325 331 294 320 327 334 363 317 350 350 358 360 343 361 318 331 353 335 367 325 331 325 315 347 344 335 342 326 323 335 352 311 328 332 332 310 349 294 335 340 347 324 355 359 341 313 331 306 320 354 334 368 287 323 331 337 331 325 364 351 321 359 361 341 334 352 364 293 371 301 320 363 326 332 366 349 315 342 345 310 339 339 290 331 342 373 291 364 350 320 366 316 338 361 329 310 301 318 334 359 358 341 341 323 316 342 368 354 358 328 334 320 340 313 332 347 296 312 353 351 303 348 353 311 312 348 334 286 330 346 317 338 320 344 326 338 337 344 352 336 303 301 351 343 343 312 316 320 322 312 315 325 343 342 344 354 332 314 307 338 312 337 313 327 300 329 350 343 347 315 339 337 348 322 356 347 321 294 329 313 354 289 329 344 349 329 339 343 307 360 338 356 359 336 303 328 307 343 322 313 350 348 351 321 347 301 318 307 327 328 314 334 328 327 350 345 340 307 325 352 342 346 315 332 335 323 341 341 352 314 302 342 361 331 312 330 322 311 341 325 335 307 352 338 319 348 340 305 334 330 329 283 337 338 312 334 351 357 356 346 397 325 341 328 332 320 317 343 341 302 343 338 324 345 341 319 334 321 329 351 336 295 343 359 309 307 327 323 346 326 325 349 333 332 374 328 340 379 334 326 338 305 364 281 349 351 309 371 353 370 356 329 323 336 344 332 309 345 341 337 334 358 330 336 356 340 340 308 336 324 343 322 362 335 342 318 323 345 349 331 333 356 337 343 366 319 324 335 337 328 330 363 386 368 314 321 377 348 354 341 332 343 372 332 323 357 345 354 357 343 329 361 317 348 356 380 307 332 346 324 352 370 362 349 359 355 344 364 318 357 339 362 348 314 344 319 370 376 329 335 314 356 334 303 337 329 377 336 375 338 377 326 350 331 351 363 367 334 336 364 358 360 362 368 359 363 348 359 350 322 380 338 333 321 328 343 365 346 343 365 335 340 341 304 339 347 376 361 327 354 329 367 352 339 352 330 327 338 351 352 373 361 363 338 325 346 352 346 361 348 349 347 325 351 379 343 380 337 320 342 372 347 329 356 341 321 374 335 366 361 343 326 367 369 329 359 353 331 340 353 359 327 336 352 300 361 356 327 332 347 355 329 320 355 363 391 375 377 364 334 330 297 336 348 339 378 339 398 336 352 324 320 339 376 308 346 343 338 336 357 337 338 357 347 340 358 340 342 363 329 321 358 418 360 326 376 351 349 350 351 372 351 362 369 362 360 346 340 384 361 360 322 374 314 343 348 325 364 351 324 331 363 363 347 332 347 327 314 315 342 368 337 371 365 378 339 378 389 337 341 313 335 344 274 345 352 371 345 353 320 345 358 341 349 369 378 329 359 350 373 347 341 324 298 345 330 334 318 333 361 342 329 339 318 328 328 346 349 351 347 370 368 309 347 331 359 372 373 350 355 379 355 379 335 348 321 355 331 345 351 349 335 327 355 338 351 349 367 343 350 343 327 314 352 334 370 388 346 334 321 338 325 344 325 338 323 302 328 360 321 316 314 354 343 326 309 328 334 319 321 367 318 339 345 338 320 343 343 336 369 327 314 348 339 316 369 329 339 334 346 359 344 347 366 300 337 330 345 313 343 354 344 351 318 352 318 351 343 349 356 344 338 345 363 306 328 313 341 354 331 332 308 343 301 331 320 316 309 316 286 327 321 345 329 296 320 294 334 312 327 308 344 359 319 322 315 331 316 276 327 327 311 349 331 335 324 335 339 351 337 353 339 330 344 322 336 319 345 297 325 328 357 330 311 315 297 301 293 382 332 316 378 318 337 307 313 334 317 310 345 311 328 299 312 307 340 310 331 331 304 352 321 325 352 337 329 302 313 297 320 315 326 323 360 345 319 309 318 319 319 314 329 313 307 338 321 306 316 285 327 322 301 367 310 304 302 291 279 316 298 298 341 287 313 315 314 297 308 320 283 295 321 338 326 326 300 296 324 304 339 287 302 309 308 263 333 309 285 298 303 304 341 328 325 320 307 313 335 292 333 284 334 294 297 326 309 301 319 305 285 304 335 292 327 295 271 302 323 340 334 356 299 340 288 311 310 317 305 322 301 308 298 306 297 293 310 349 306 305 295 298 307 338 292 279 314 322 311 352 304 321 290 287 317 305 282 325 303 283 265 294 325 294 310 268 307 306 281 325 297 300 264 302 295 274 293 276 289 265 295 293 283 291 275 301 299 294 274 278 280 307 307 298 289 310 306 322 334 289 297 291 289 306 277 284 289 274 285 293 307 291 306 298 295 306 297 282 287 298 285 287 300 319 289 275 311 306 293 297 283 296 294 298 278 276 278 269 292 297 299 315 266 245 314 276 283 321 275 293 311 292 320 281 274 296 265 333 287 292 249 283 290 283 274 274 268 263 318 266 305 311 310 286 305 307 295 296 265 291 265 299 287 241 271 269 302 290 241 270 278 285 234 268 304 283 302 301 294 306 306 277 275 285 256 301 286 288 297 277 261 282 298 283 291 268 272 267 271 289 297 277 289 280 280 268 271 283 277 273 256 262 287 277 264 292 302 276 297 295 294 265 236 298 271 284 269 279 280 272 284 269 277 257 281 241 277 288 246 273 287 261 285 272 264 273 278 268 290 243 269 239 276 263 263 269 303 256 266 266 270 258 259 288 277 275 287 284 247 242 255 292 261 256 240 275 256 243 275 278 247 273 276 247 270 270 281 261 244 263 257 291 293 277 260 267 263 282 247 289 243 244 256 249 255 262 278 256 269 269 268 291 269 248 247 269 278 272 258 256 274 237 280 268 271 234 281 299 266 261 261 240 276 263 239 249 277 239 271 259 256 270 270 282 256 285 285 242 266 259 271 258 287 286 257 283 236 242 261 270 261 247 272 291 280 264 270 257 288 255 285 269 249 241 280 244 262 263 265 231 240 288 262 276 257 257 269 292 245 255 272 196 279 272 246 286 237 262 242 261 239 274 263 273 273 266 248 282 248 243 269 272 243 271 278 259 210 272 265 256 255 239 249 259 269 264 268 276 259 249 263 238 226 268 272 238 248 248 243 226 257 256 234 277 237 231 231 258 239 268 272 274 219 242 263 232 258 237 262 248 272 245 245 242 229 268 256 264 245 229 244 273 238 247 261 256 284 275 217 224 246 260 269 259 268 278 223 234 241 260 262 264 239 238 260 255 241 257 259 274 241 230 247 261 241 264 239 235 248 243 230 255 256 256 243 264 257 230 245 259 234 281 249 244 243 271 282 239 210 239 271 270 246 255 238 233 248 242 255 210 271 280 276 216 243 243 234 245 256 256 223 243 239 236 247 232 245 229 249 257 265 230 247 257 247 267 244 238 267 234 232 247 248 282 260 239 221 248 263 296 240 266 234 264 246 258 220 278 262 249 266 224 248 265 211 263 239 224 248 218 220 218 224 255 263 249 282 270 260 242 223 244 259 238 237 238 224 229 250 257 231 210 229 227 255 243 245 231 243 242 241 233 216 246 227 279 227 230 263 209 220 244 215 209 235 222 276 272 236 256 236 241 238 244 245 241 280 243 247 215 268 235 256 247 233 224 223 217 242 199 221 239 239 257 256 249 219 228 237 225 241 229 261 229 247 235 229 235 207 217 261 221 261 216 240 223 248 236 220 242 259 228 227 233 226 236 250 240 214 226 246 239 229 261 230 214 240 214 246 240 227 239 236 249 236 242 235 240 243 258 242 216 222 247 216 244 236 225 256 239 225 241 202 207 228 255 232 223 230 267 256 232 230 229 228 235 215 232 210 262 266 225 216 267 212 224 232 212 246 221 250 205 229 250 236 224 232 226 232 226 215 218 223 236 239 238 232 223 237 242 210 257 230 230 231 237 238 265 221 217 214 220 216 238 232 232 232 245 243 222 242 234 239 223 231 244 224 242 229 233 232 266 245 217 232 223 219 214 224 206 236 245 233 222 215 211 244 224 235 256 232 233 230 216 245 224 230 245 235 231 241 227 214 263 231 219 234 225 221 235 246 228 247 227 237 220 220 239 224 243 172 228 232 211 218 224 220 224 222 229 236 209 244 216 235 255 234 216 246 273 237 237 270 229 244 228 230 256 244 232 273 256 219 237 229 205 195 236 228 203 218 248 218 244 237 224 221 258 233 247 236 229 227 221 220 224 226 221 203 221 243 223 206 232 208 260 220 239 234 218 213 228 235 241 243 220 240 231 226 235 246 203 221 240 247 221 242 213 225 209 264 258 221 233 224 247 234 236 219 214 207 202 221 236 217 234 229 223 222 227 235 222 230 229 234 230 234 257 218 222 230 210 220 222 215 207 212 226 208 224 242 217 233 241 211 255 234 212 221 198 233 217 232 219 234 265 224 222 210 231 235 242 259 216 225 237 220 215 222 244 217 228 220 234 237 230 245 240 227 258 209 217 243 217 233 256 222 241 231 222 232 202 209 226 224 224 259 229 204 239 233 242 222 217 228 227 219 216 195 226 208 227 233 222 236 210 250 217 209 201 242 213 268 202 235 218 208 211 239 220 226 235 228 256 218 210 203 225 232 204 214 228 227 197 230 232 216 236 213 237 212 227 233 234 220 208 228 258 231 199 212 242 224 230 233 203 233 212 233 228 219 221 214 224 245 224 231 231 247 202 195 225 242 210 240 200 207 225 230 232 198 225 208 229 209 215 194 233 215 222 206 229 207 229 220 243 192 217 229 228 227 214 216 219 218 227 210 214 206 224 217 199 200 204 232 242 223 209 223 212 184 215 219 228 189 239 223 246 204 255 225 239 207 209 229 234 215 232 198 225 242 200 221 215 227 209 210 222 217 194 216 227 215 212 209 224 228 194 209 247 203 222 187 231 224 226 211 211 215 209 230 223 215 226 199 225 212 210 217 219 220 203 221 259 243 225 206 272 213 194 235 227 239 208 233 193 207 236 223 241 223 228 210 218 217 199 189 222 211 210 245 202 206 194 218 209 223 238 213 206 214 211 236 233 225 225 198 219 221 208 243 196 189 217 266 240 216 232 236 259 195 181 245 226 218 219 217 226 210 206 237 227 245 219 223 224 260 217 210 256 216 223 209 193 226 231 240 206 193 221 226 212 232 230 212 188 224 212 221 237 223 213 222 242 250 202 205 217 206 232 214 240 233 197 215 246 220 245 234 193 215 219 262 213 214 223 220 248 221 210 224 217 221 236 209 214 220 218 261 208 238 243 242 213 226 210 225 232 236 201 214 230 230 196 211 201 209 219 217 226 213 205 222 219 208 231 239 230 205 221 233 229 222 203 210 238 218 273 230 225 230 207 209 228 236 230 226 238 209 199 232 246 208 224 220 214 215 224 239 210 194 256 266 194 230 225 216 224 217 232 215 205 213 211 225 236 214 240 204 231 233 245 244 261 213 217 210 238 226 212 239 209 242 235 244 227 220 224 217 202 224 241 238 245 244 217 239 200 228 207 227 198 241 215 228 237 227 256 267 213 232 245 237 213 227 227 208 218 226 245 221 248 227 232 236 247 238 235 245 255 211 231 227 249 242 198 260 239 223 231 227 239 258 235 226 206 233 237 214 240 237 219 230 246 226 261 218 235 226 233 241 220 230 271 236 255 209 241 260 211 217 234 258 230 241 231 233 243 216 214 244 228 229 226 217 209 225 227 236 221 222 241 219 244 236 220 245 236 222 237 260 238 222 197 214 235 246 218 242 226 219 241 221 210 215 237 246 219 229 219 222 216 211 224 215 227 247 260 209 217 233 257 239 217 244 286 257 242 233 203 256 247 241 231 219 236 257 220 257 237 256 245 215 248 269 237 222 242 239 227 240 217 228 256 233 216 211 234 257 208 222 259 232 205 226 237 220 242 218 224 241 218 232 233 233 247 217 228 256 232 220 207 217 278 199 259 212 241 233 228 229 217 247 244 217 235 218 213 227 228 214 224 228 229 235 216 206 238 239 240 231 229 230 209 237 227 225 231 215 207 230 225 217 220 211 234 228 241 261 257 221 231 223 218 235 225 228 235 246 225 217 240 216 238 239 261 237 221 229 224 231 224 205 238 229 220 266 231 218 247 269 264 264 259 261 215 232 260 261 240 238 238 218 219 261 246 244 218 219 269 228 255 258 240 246 262 242 249 225 249 236 276 249 234 243 268 257 247 272 232 227 284 232 244 277 235 263 245 264 247 264 259 226 232 270 241 274 256 247 274 299 282 281 299 261 257 261 306 302 270 288 298 319 327 320 287 319 357 319 327 335 322 343 329 353 399 403 347 346 344 367 350 388 392 393 393 363 364 363 404 403 386 348 364 352 339 365 356 356 346 340 368 326 309 306 325 314 295 275 270 281 304 283 273 262 262 291 281 264 237 321 261 258 283 255 230 261 266 242 249 234 248 225 246 255 232 223 239 238 234 233 223 262 245 235 214 222 258 267 248 235 245 258 243 247 226 232 237 248 223 238 223 243 274 262 258 218 205 259 226 198 210 261 220 249 210 233 216 228 218 233 220 232 241 249 246 259 218 220 268 241 236 229 244 212 204 237 224 213 263 234 239 239 226 209 196 218 208 222 222 219 212 236 233 227 231 221 239 221 223 248 220 216 217 230 231 236 240 217 230 222 225 235 223 232 237 223 224 241 223 230 262 228 236 229 224 222 237 242 216 222 231 233 237 249 248 218 242 236 209 238 230 195 215 237 238 204 241 239 211 216 242 222 219 223 210 261 208 220 223 236 222 247 230 210 214 230 257 227 237 237 219 235 222 210 226 215 230 240 259 212 220 245 209 243 224 274 230 203 204 244 220 221 242 222 218 246 242 241 208 238 214 250 202 206 218 233 239 247 221 203 212 233 226 230 217 226 244 216 227 263 230 218 218 201 236 277 210 222 210 227 242 235 232 219 224 215 228 232 239 216 224 215 223 214 247 263 203 233 228 243 230 224 234 221 218 257 228 233 212 245 196 206 223 213 207 233 238 214 245 260 239 219 238 234 207 231 233 228 241 249 224 264 232 211 262 224 210 225 224 220 240 236 239 217 232 211 238 226 228 234 224 221 223 237 223 214 243 241 219 244 228 238 256 230 244 235 247 220 237 224 255 217 239 231 220 247 232 257 230 244 217 225 192 246 244 221 206 245 242 235 206 222 255 233 236 213 228 227 242 207 209 241 237 261 225 223 231 236 233 234 215 244 255 206 230 234 228 223 224 229 185 231 219 221 236 244 196 227 246 221 236 263 263 250 237 258 209 215 216 242 214 258 233 246 232 228 250 236 247 242 211 228 214 231 219 239 232 228 229 232 244 259 224 217 249 224 261 248 246 237 225 222 215 244 209 225 231 225 219 211 195 257 219 245 220 206 220 213 263 213 233 227 243 228 238 212 233 238 244 230 245 220 215 269 227 212 188 244 258 226 212 238 240 229 223 198 225 212 250 213 222 214 212 206 262 244 233 224 221 227 236 229 233 221 215 195 242 217 259 239 202 230 260 234 231 236 256 225 230 216 234 243 222 232 219 233 213 275 267 237 216 218 201 230 233 232 218 233 201 221 248 223 218 216 265 246 242 257 223 230 222 221 226 235 224 224 217 205 236 197 248 234 243 237 215 209 227 261 228 250 220 236 216 238 200 231 217 257 223 270 234 224 214 228 212 217 211 247 243 209 241 230 230 246 199 221 233 224 221 261 224 240 231 245 225 239 229 243 216 209 225 239 217 208 248 238 231 243 232 230 246 217 202 232 244 231 209 205 223 245 216 238 235 226 233 255 233 226 240 213 236 248 218 233 273 223 233 246 200 243 207 230 248 204 231 221 201 223 266 219 230 218 232 220 243 231 233 210 233 223 236 237 212 241 242 250 238 229 216 227 232 218 240 192 206 215 221 210 226 197 227 230 218 223 202 227 215 225 234 230 239 224 225 222 214 235 204 230 205 236 205 260 219 239 229 215 215 222 210 240 225 220 237 221 245 247 208 222 209 221 185 220 199 211 196 230 215 247 233 226 208 212 218 224 212 230 210 213 238 220 237 225 225 213 216 216 219 219 215 205 207 232 207 208 220 231 216 221 242 234 235 241 208 207 226 216 224 231 186 238 239 215 230 238 231 210 237 256 215 224 236 230 191 238 233 249 233 235 238 199 207 213 233 239 205 212 199 219 214 231 219 226 225 215 261 220 231 239 232 193 199 222 225 221 232 219 215 215 239 210 222 218 233 199 232 228 209 216 237 221 229 225 216 267 232 222 216 225 246 218 249 238 235 214 240 212 216 244 238 195 208 234 208 229 227 225 203 236 221 239 245 236 203 222 267 224 241 219 230 240 207 231 219 233 210 211 213 224 221 217 232 229 207 233 193 232 199 226 232 230 208 228 242 199 273 214 243 228 231 220 206 218 206 218 227 203 188 213 217 217 242 233 224 228 236 208 235 220 238 229 209 212 192 225 216 227 202 237 208 214 221 216 207 238 224 207 231 247 210 239 206 226 214 232 215 248 228 241 231 227 234 222 223 181 230 197 243 244 233 221 233 229 231 190 219 245 214 243 209 197 215 221 221 240 227 216 212 207 227 226 213 213 215 261 243 215 242 222 232 235 235 219 245 261 242 223 243 213 230 208 216 206 224 209 207 215 235 209 216 210 230 224 199 238 219 221 218 218 233 214 224 218 219 213 213 220 247 221 212 232 212 276 224 214 240 245 244 220 231 232 225 206 249 224 229 226 242 200 214 218 219 215 244 226 204 231 231 218 207 217 232 213 203 223 202 229 230 227 223 225 233 214 192 221 227 206 209 223 246 238 237 220 221 189 223 236 202 256 232 221 238 198 214 237 217 198 238 232 204 242 235 247 245 207 214 234 225 232 202 223 238 226 211 231 220 264 220 219 216 236 220 229 256 228 243 221 219 217 242 225 222 236 242 228 211 211 225 216 260 183 216 219 213 249 234 213 227 205 229 232 204 214 214 237 213 214 231 226 224 213 228 216 233 227 210 227 269 249 191 213 203 247 207 204 205 204 246 220 233 220 207 235 219 209 237 232 217 230 219 226 215 224 230 227 226 220 230 198 226 235 261 214 220 213 257 244 218 223 240 234 237 230 217 242 239 218 227 214 212 226 212 225 265 174 230 226 213 229 261 225 206 243 242 219 189 270 234 210 210 237 247 213 207 217 182 233 194 244 241 245 221 245 224 213 212 230 247 244 210 229 216 214 232 219 230 237 232 223 238 212 234 202 214 220 245 215 259 238 230 215 226 207 233 240 204 241 219 246 239 222 237 240 221 224 222 234 221 221 240 231 221 242 238 229 217 199 236 231 228 259 239 248 197 246 231 204 216 274 203 241 207 217 228 239 234 224 213 234 232 230 228 222 232 234 232 231 260 216 228 233 224 206 240 256 260 225 245 229 239 232 239 214 211 237 221 240 209 215 223 236 245 264 239 255 222 249 223 239 217 220 237 206 229 231 265 214 222 227 208 192 213 227 221 223 236 218 238 244 209 239 262 244 211 229 232 275 216 227 246 226 209 217 226 223 229 243 218 224 188 211 192 222 198 225 178 221 238 239 234 241 229 237 224 210 215 233 231 240 231 209 229 260 189 262 242 214 219 222 212 234 220 228 219 224 189 238 221 224 213 261 214 234 237 230 238 229 215 239 226 238 231 216 209 197 222 236 242 234 228 229 207 241 232 231 244 262 216 234 258 236 236 237 210 224 232 242 244 222 232 221 214 255 222 237 227 221 207 259 223 228 245 227 225 200 205 229 221 221 241 260 209 246 229 206 225 234 225 207 225 225 241 206 239 211 235 211 223 225 234 240 232 225 208 238 267 213 219 256 233 264 227 199 241 237 243 212 213 216 211 229 231 210 245 212 225 218 231 226 201 237 237 220 229 236 232 199 225 224 202 256 249 183 225 214 241 221 257 237 238 207 243 242 227 238 223 242 229 214 244 234 230 235 234 244 207 216 221 243 212 235 219 237 236 208 221 227 219 207 237 211 223 242 243 233 239 220 265 241 226 262 228 210 261 227 227 238 232 243 244 226 266 230 246 239 245 233 272 257 241 207 234 221 231 260 240 224 239 221 266 227 233 227 226 247 264 266 244 228 255 273 235 235 263 238 266 234 239 228 230 249 222 219 264 242 223 236 234 225 260 228 217 245 205 239 229 231 237 230 224 232 227 259 246 217 236 210 227 234 205 256 239 242 228 237 221 207 228 232 236 229 224 236 221 222 236 244 241 207 247 239 232 215 243 226 259 246 228 229 216 242 212 237 237 241 228 230 202 241 269 223 213 237 217 235 228 240 244 231 220 229 192 238 209 202 223 202 236 256 221 207 233 229 229 235 243 234 218 242 237 250 217 238 231 218 214 231 222 238 233 241 241 259 244 220 243 239 231 207 242 241 240 295 203 230 223 217 221 231 218 221 244 234 226 221 225 213 223 217 221 222 210 246 228 202 233 228 260 262 226 234 228 225 256 194 232 241 264 237 215 220 235 237 176 230 245 231 225 244 267 231 294 245 248 232 226 220 231 256 211 209 201 230 238 237 243 214 225 248 218 244 223 211 216 241 259 234 241 222 233 214 233 220 244 258 234 215 208 248 223 214 244 264 226 224 259 272 210 239 256 221 236 232 227 268 229 243 245 231 227 262 227 265 226 225 248 235 222 236 243 245 204 239 238 220 246 263 219 208 214 255 234 233 202 202 213 226 227 202 269 225 257 233 220 241 261 220 226 245 223 245 230 221 230 261 241 226 229 242 211 239 232 247 242 247 214 219 231 263 238 247 255 235 259 220 218 221 224 235 242 221 240 255 218 262 240 255 241 224 267 238 221 228 224 229 276 249 258 239 235 228 217 216 228 222 228 236 255 261 261 244 228 208 231 235 239 207 257 222 288 211 232 248 220 239 209 222 216 224 259 267 264 237 222 224 246 247 245 242 234 268 221 256 219 228 238 244 255 250 256 238 246 234 240 229 276 241 217 240 248 240 234 240 260 232 242 232 276 234 281 256 215 230 242 246 237 266 228 234 257 249 243 231 264 243 229 256 223 219 248 245 202 233 235 245 226 243 243 229 204 240 222 222 221 219 237 215 237 257 260 237 247 238 230 233 268 223 248 249 238 261 244 206 238 218 220 241 256 225 220 260 232 240 263 230 213 236 233 227 235 269 231 245 211 236 235 213 216 239 231 226 269 263 225 223 214 278 231 187 242 245 234 234 236 231 212 228 234 240 222 210 236 275 261 242 241 198 235 238 214 237 240 210 246 238 236 217 258 221 221 228 257 248 211 215 211 215 243 242 258 226 209 226 216 230 236 246 227 227 255 232 207 239 249 225 196 238 242 229 229 245 257 210 235 208 210 247 234 239 264 218 223 212 228 218 220 236 261 202 231 232 233 195 219 220 238 256 237 222 233 205 209 214 264 239 231 236 230 240 242 258 242 242 213 228 213 265 206 211 217 214 227 239 208 242 212 236 190 203 237 231 262 209 225 237 194 220 247 227 240 232 237 211 213 231 240 224 234 218 243 258 235 209 212 230 207 219 233 211 270 219 219 240 247 240 231 249 238 274 214 218 209 224 242 242 232 247 231 220 255 233 222 245 192 228 220 239 226 243 231 248 241 235 229 222 196 249 236 236 229 218 192 263 221 189 235 236 235 264 216 209 222 221 224 224 233 225 211 236 242 246 245 227 218 237 240 242 242 268 231 206 243 216 222 259 225 233 234 243 228 225 223 237 202 265 236 269 217 195 212 270 234 210 220 224 219 248 239 245 237 223 238 230 212 236 266 247 213 223 249 231 213 215 237 217 218 237 234 232 227 228 241 230 211 217 242 263 248 212 219 257 226 203 226 198 245 218 263 210 240 225 215 226 226 267 243 230 222 215 211 219 238 220 229 248 216 242 228 214 225 231 225 216 255 225 230 229 219 224 220 227 210 218 249 235 204 223 263 256 239 234 264 203 241 211 233 224 228 248 235 228 217 195 231 229 215 224 232 214 212 218 248 238 236 235 227 214 240 237 227 215 210 238 230 243 205 234 220 226 232 220 222 249 218 216 234 234 246 208 241 243 230 248 230 231 223 219 216 236 222 263 235 226 268 214 242 236 247 264 213 207 213 216 211 242 226 220 246 246 203 215 260 216 215 216 218 227 233 243 238 216 211 236 258 229 237 222 240 263 234 217 221 220 245 199 226 243 245 223 219 225 244 222 219 238 190 223 241 208 224 229 221 230 221 231 217 219 221 200 226 211 212 234 246 238 221 256 207 239 229 238 230 205 238 231 219 239 225 259 221 203 211 212 237 236 211 231 257 215 239 228 211 235 217 240 241 235 244 240 211 246 224 238 259 250 191 235 233 234 239 206 262 244 228 283 205 208 232 231 218 227 249 213 219 242 241 198 223 226 231 218 228 230 232 222 227 241 211 248 225 217 214 246 262 215 241 211 241 216 225 256 229 211 260 228 263 230 261 222 224 211 258 216 214 256 228 257 230 220 239 236 228 233 238 236 231 241 214 204 225 222 243 250 236 257 211 218 219 237 223 246 229 230 219 255 209 231 233 233 257 211 215 222 233 226 231 249 218 224 198 226 240 216 213 224 211 208 237 263 218 203 227 230 230 224 249 235 231 238 256 247 232 204 231 240 244 262 239 240 222 214 227 195 256 228 226 247 206 246 243 210 232 219 215 235 220 222 264 214 192 214 208 220 231 244 224 205 205 237 209 228 215 232 209 241 229 237 225 209 220 213 216 215 229 247 256 231 232 250 209 204 215 258 231 237 218 213 233 232 247 278 235 238 243 223 221 226 223 239 216 232 213 246 268 258 225 246 226 249 223 221 240 224 255 230 236 218 225 235 208 226 236 192 238 197 233 220 208 196 214 225 201 221 216 264 205 202 218 212 216 212 208 212 235 226 224 240 232 227 238 222 221 203 216 201 234 211 243 234 198 213 203 245 238 236 240 248 217 228 248 214 233 231 240 213 224 221 234 231 243 230 235 222 226 245 242 234 268 239 229 237 213 272 200 218 212 211 209 227 239 188 194 231 218 244 210 222 207 269 228 255 195 231 224 212 217 211 221 233 245 229 240 231 222 249 243 249 229 245 240 217 235 206 226 235 233 224 246 206 208 234 221 223 194 247 215 227 223 218 212 211 226 261 229 213 217 239 218 227 196 232 212 249 222 203 216 239 217 227 212 243 257 247 224 247 220 213 218 227 260 231 202 238 217 244 232 237 235 213 218 235 198 224 234 229 211 200 244 235 205 230 207 206 232 211 208 234 226 209 225 209 229 238 200 245 239 222 221 226 223 234 236 236 249 236 219 219 258 266 224 233 223 234 230 219 230 216 203 225 228 237 196 214 231 221 227 196 247 217 201 213 243 225 233 229 215 238 212 204 215 229 238 231 190 220 241 240 243 240 242 191 229 220 223 231 229 223 220 244 216 214 191 197 273 231 212 232 240 237 235 246 207 276 248 208 234 221 241 214 216 219 240 216 193 238 200 247 216 213 225 244 221 241 195 228 222 232 227 229 211 227 206 216 219 207 213 223 249 230 232 228 231 214 223 198 225 196 230 241 228 226 211 178 257 219 202 216 184 217 213 217 211 230 267 234 209 228 192 212 204 212 236 204 220 222 243 244 225 204 236 229 184 230 216 213 241 215 223 220 232 258 218 248 244 230 241 217 223 198 227 225 210 234 235 230 230 201 222 198 213 196 218 226 223 246 237 227 219 230 232 227 227 230 199 227 277 213 241 224 208 217 222 211 245 236 234 194 225 213 248 234 236 204 198 227 219 214 237 211 247 232 223 214 193 214 206 218 222 226 229 215 188 212 231 222 213 276 257 239 208 222 219 218 203 217 227 266 227 213 233 210 235 227 235 230 234 216 215 224 265 221 225 238 228 209 236 237 265 197 261 213 236 219 200 229 218 226 211 229 245 232 219 199 216 228 232 224 225 209 225 221 224 203 234 198 221 222 233 242 241 241 208 221 230 223 220 224 219 220 224 235 232 229 231 216 226 245 204 213 217 239 257 225 195 236 237 217 222 239 221 225 242 258 234 214 210 197 230 238 223 230 216 226 209 244 215 236 228 206 204 230 235 209 208 208 228 217 240 227 218 212 235 229 208 218 228 207 229 214 206 219 236 241 242 228 223 208 226 234 210 237 205 203 214 224 222 245 197 213 204 207 255 199 245 227 228 239 232 217 250 205 220 261 212 211 194 219 209 224 224 239 207 261 233 199 214 242 209 237 233 202 227 227 235 244 232 218 246 208 230 230 228 234 222 220 239 221 233 219 197 210 218 228 233 187 233 238 214 218 226 238 225 191 230 225 244 241 199 236 230 249 208 236 215 228 216 193 214 261 228 237 196 224 213 200 223 207 233 222 248 234 244 259 229 230 224 205 214 233 224 206 219 213 236 202 241 264 212 267 231 218 214 248 209 239 210 228 227 209 249 240 229 208 226 223 229 216 212 223 214 220 231 224 222 218 195 213 202 211 246 227 231 239 231 237 200 245 235 228 222 216 215 218 225 233 200 233 237 222 227 237 217 195 218 230 233 222 230 227 210 213 237 224 236 227 207 205 220 217 217 217 230 200 212 236 222 212 227 257 204 227 211 231 232 226 218 197 208 228 234 209 236 211 248 209 247 210 227 227 232 246 239 214 249 229 233 223 217 235 208 266 218 234 238 207 234 221 209 265 241 245 219 227 223 232 235 217 216 255 211 205 273 211 218 226 240 247 234 249 235 223 247 209 245 220 207 214 233 231 203 215 246 226 270 223 243 199 255 230 231 218 227 222 228 240 210 231 229 193 222 223 201 228 226 227 226 250 237 255 233 245 221 239 230 222 240 226 230 249 225 263 263 223 214 236 256 264 265 228 258 250 240 231 260 256 240 213 258 248 217 261 259 260 246 242 300 292 261 245 257 273 250 256 264 234 228 260 249 272 225 240 256 238 293 267 274 267 233 247 267 235 237 236 222 281 225 248 242 214 233 246 291 232 259 261 244 235 259 215 246 241 285 223 247 237 221 243 223 257 234 258 230 207 228 217 231 248 258 228 225 223 229 227 243 223 224 246 234 220 235 206 248 235 226 225 222 225 264 225 261 220 239 221 240 234 232 217 231 237 216 212 235 283 229 219 228 240 236 208 249 206 255 229 213 264 195 230 213 216 198 227 223 236 259 230 209 218 201 228 218 249 226 239 242 204 208 215 200 193 241 216 212 233 229 215 243 257 239 235 225 208 260 231 227 264 233 241 234 221 229 174 237 220 208 236 222 217 217 191 220 238 226 210 215 238 211 205 211 214 217 224 216 218 233 228 207 206 248 199 236 212 220 247 237 233 235 242 195 240 220 234 191 211 215 232 221 221 220 184 202 206 232 208 222 202 217 238 214 204 255 209 213 211 212 209 232 228 236 207 218 236 225 208 238 202 227 237 208 229 213 231 228 217 194 218 205 196 250 205 211 212 248 216 220 221 229 233 193 188 218 220 191 231 207 209 227 209 223 230 215 206 232 175 243 211 222 209 206 205 236 219 175 234 216 205 213 213 234 201 229 205 228 221 213 215 205 228 219 185 188 215 212 214 226 187 267 213 195 212 213 231 238 194 189 238 216 194 207 199 196 225 209 217 217 213 198 197 225 212 231 209 212 206 201 212 204 217 206 210 229 203 219 216 236 213 216 228 227 215 196 222 241 255 237 230 234 201 207 209 238 237 215 210 263 246 208 202 217 210 214 196 213 241 238 243 223 209 184 191 218 204 222 225 213 208 224 236 230 216 186 199 216 230 219 234 187 207 232 207 246 204 225 223 216 201 217 217 202 204 208 222 214 210 232 225 213 224 249 232 198 228 215 212 188 202 225 200 201 201 227 224 209 233 202 257 218 240 210 214 216 210 209 203 230 234 221 203 217 230 210 228 220 190 212 234 201 209 223 200 214 221 268 210 199 221 232 212 219 234 221 238 212 223 269 203 226 207 218 196 234 185 209 212 228 230 255 234 201 195 231 217 219 190 189 193 260 220 226 213 208 218 216 233 220 195 227 219 228 221 204 238 223 214 226 220 224 220 199 214 228 177 211 229 221 210 223 226 218 231 227 232 231 227 218 221 208 205 222 220 245 205 233 217 209 211 192 240 224 207 215 193 246 221 204 215 215 218 211 210 199 206 209 240 195 256 208 233 178 219 230 199 224 243 224 231 195 182 214 234 270 200 229 178 220 200 220 207 231 220 221 232 240 233 224 193 189 210 237 239 205 218 201 225 211 220 240 225 248 231 231 220 221 215 216 237 219 209 225 231 217 212 211 200 241 207 195 196 217 209 242 214 184 219 256 219 214 189 197 209 214 207 201 221 187 204 205 206 192 225 232 237 201 234 236 240 208 215 196 197 215 217 213 213 262 205 223 221 217 227 206 201 203 224 203 228 191 219 183 223 229 210 207 228 220 196 225 212 219 191 214 220 213 244 212 207 216 226 236 210 207 206 233 218 199 208 207 225 245 217 223 212 189 226 225 198 244 231 215 204 213 220 219 222 220 233 203 201 179 183 225 238 213 211 187 218 216 217 213 208 240 262 222 223 241 212 228 193 223 220 202 201 197 200 223 218 209 212 263 200 210 210 213 197 200 241 223 215 203 223 220 172 207 238 210 188 243 231 230 217 207 224 220 237 231 232 222 226 205 223 209 276 208 201 219 214 213 205 196 209 226 215 209 193 196 228 181 231 215 210 214 209 194 208 184 223 234 199 211 208 216 225 209 215 225 218 202 200 216 206 197 235 187 203 221 230 224 225 232 220 215 207 214 217 200 226 210 249 224 213 220 204 177 213 194 209 191 227 229 234 198 225 219 243 242 219 209 213 210 226 212 214 213 185 197 218 219 200 211 225 216 207 200 204 219 207 196 195 197 228 212 201 187 210 223 221 195 207 213 226 203 229 197 204 223 229 210 209 224 256 240 216 216 222 207 202 205 180 219 226 198 231 220 220 215 218 190 217 184 194 194 205 248 221 201 188 193 218 210 214 233 226 192 224 194 218 202 200 217 219 202 243 239 229 198 190 229 210 207 208 230 211 212 221 218 214 234 216 193 210 203 200 227 210 221 212 204 221 196 195 200 209 190 200 228 204 212 214 204 189 201 230 239 203 218 232 201 203 197 216 243 215 237 207 206 196 213 192 216 209 219 202 197 194 202 184 189 201 187 212 191 192 209 205 213 191 197 219 244 208 237 199 191 186 227 228 219 194 217 238 180 213 236 191 211 231 214 223 205 188 222 207 216 237 188 222 200 226 196 211 198 218 190 214 223 186 199 220 206 247 219 210 197 182 206 193 228 203 232 217 213 222 191 202 218 222 216 206 230 228 181 198 210 194 198 204 214 209 187 222 209 226 217 235 240 210 214 224 190 229 218 216 186 192 209 207 207 211 201 185 190 220 218 218 234 226 186 189 200 212 181 206 227 195 193 217 201 195 237 218 212 206 179 221 198 197 197 206 218 209 218 195 202 222 184 177 209 198 206 218 220 213 224 192 208 209 221 217 229 228 223 193 231 211 201 200 204 206 203 215 236 205 223 209 215 212 223 202 220 211 211 209 186 229 230 222 210 217 206 214 205 199 201 206 191 208 204 216 202 221 238 191 212 222 224 221 202 221 199 214 225 207 220 209 196 204 208 244 229 217 215 216 209 204 195 191 207 206 206 180 212 234 202 226 211 193 222 207 207 189 220 230 228 193 197 211 202 209 217 238 211 210 232 214 226 199 201 209 215 211 226 233 198 211 212 198 230 193 209 199 202 213 201 242 191 185 192 213 208 206 208 235 179 271 204 181 197 217 255 226 202 196 219 201 207 192 214 208 209 211 207 224 215 196 197 210 230 238 198 211 216 196 193 221 224 200 228 226 228 236 214 233 196 212 224 208 208 202 211 213 228 207 216 207 198 205 220 203 223 207 204 211 214 212 203 212 226 211 206 221 201 219 210 226 218 231 219 204 179 203 239 217 180 207 197 215 215 216 212 203 194 222 207 186 196 217 212 200 214 211 228 234 199 199 226 209 205 201 218 229 215 206 232 231 212 224 203 231 234 224 210 222 198 201 203 204 192 192 195 246 206 183 193 205 225 227 200 207 187 205 213 217 188 198 232 215 205 203 207 184 216 230 218 207 206 193 219 213 223 205 219 198 201 226 218 211 215 213 226 184 225 227 214 200 221 219 220 240 215 187 241 227 187 223 212 195 184 221 224 235 237 201 212 234 216 205 211 220 171 215 207 217 246 220 220 203 197 193 219 202 220 227 199 216 213 212 204 218 223 226 191 196 202 197 241 231 210 219 209 198 203 226 211 235 220 181 202 218 219 239 222 201 209 233 210 204 214 195 167 207 214 208 196 232 212 231 199 205 217 225 209 249 238 212 212 208 201 200 222 219 209 209 180 218 210 197 189 205 205 209 225 218 206 190 225 226 235 222 199 228 218 204 204 207 212 212 191 195 220 234 226 213 205 222 205 208 221 201 213 203 210 239 221 201 222 204 226 221 210 230 200 208 214 219 234 235 210 227 255 204 198 226 206 198 226 194 189 221 256 229 205 222 219 204 218 205 204 205 165 206 209 195 190 243 208 223 208 225 221 205 210 204 219 206 230 202 206 231 224 220 197 203 213 199 216 184 221 212 217 210 255 225 208 220 236 212 204 210 198 228 212 229 216 224 225 247 197 225 214 221 221 221 224 212 216 208 200 266 205 211 223 255 230 216 223 209 238 211 199 224 221 224 192 199 202 219 216 221 256 202 208 204 230 210 222 246 217 220 225 238 227 246 195 231 223 225 233 256 226 227 223 218 205 233 223 234 238 255 205 220 197 215 202 227 204 188 207 234 225 201 218 214 209 200 211 223 219 231 208 224 209 222 195 219 209 209 228 224 208 217 205 219 208 205 218 214 204 222 212 205 208 216 210 202 232 205 192 208 220 199 211 224 193 225 197 190 186 219 233 209 244 233 247 245 224 181 184 207 220 233 212 231 195 219 221 223 221 212 216 222 207 221 195 214 201 225 213 219 197 209 177 224 203 212 230 198 194 205 217 215 176 216 202 225 195 224 222 188 209 246 230 198 203 213 205 241 228 204 210 208 207 223 221 216 196 195 218 199 225 216 214 221 221 222 199 222 237 221 227 192 215 227 202 215 194 196 214 216 229 214 220 217 200 230 186 202 203 199 234 215 214 207 221 198 223 215 211 222 208 217 215 225 234 208 230 217 197 215 217 231 220 209 214 230 223 199 208 192 232 188 224 223 214 221 217 203 214 242 190 197 204 240 207 194 195 223 240 224 208 242 222 193 193 216 232 204 223 188 214 206 211 228 226 238 221 197 212 228 195 205 213 215 219 240 201 222 198 205 217 214 229 208 202 206 210 211 200 209 185 211 230 224 211 211 204 212 211 205 228 214 218 229 237 207 233 192 198 191 214 199 223 226 226 208 197 238 258 217 200 201 230 212 199 216 189 217 234 223 207 178 213 217 243 231 208 210 196 230 202 207 242 230 211 212 219 203 217 207 209 199 179 188 209 200 217 218 230 227 198 222 208 215 200 189 215 193 227 181 225 216 215 205 216 191 227 207 203 214 213 213 206 232 238 223 225 195 244 213 215 213 219 224 208 232 216 210 219 224 245 178 238 225 200 206 200 227 226 223 223 217 231 194 227 197 218 196 209 218 194 199 200 217 200 225 209 187 200 221 214 202 197 207 235 210 216 204 223 219 188 223 204 185 207 203 217 234 207 203 192 219 211 219 214 242 203 221 216 214 202 215 196 205 200 211 232 225 224 231 220 212 210 194 214 207 197 199 204 235 211 219 229 195 228 212 223 197 226 247 227 206 199 209 202 214 210 248 212 194 205 222 198 235 222 187 219 199 199 198 226 221 206 205 232 221 215 222 207 224 204 205 200 202 208 218 192 192 233 202 228 229 208 231 191 219 208 204 213 233 192 217 197 206 203 207 226 209 199 232 199 214 185 247 193 222 204 221 243 210 207 212 201 201 223 200 214 228 224 213 199 203 236 212 219 218 208 213 224 204 236 190 203 223 199 226 216 220 206 207 220 225 217 220 218 207 182 218 214 218 212 214 198 197 207 228 235 215 216 211 220 191 201 236 214 229 244 209 230 220 224 235 214 207 207 230 234 215 215 196 208 206 221 221 212 207 240 207 216 217 239 213 192 232 216 220 218 236 203 203 213 208 186 208 222 171 208 212 203 229 213 219 234 196 207 224 231 216 224 220 228 232 222 208 217 218 203 214 219 221 206 197 211 205 239 224 196 222 198 192 215 226 198 233 211 237 219 234 225 231 210 193 236 224 216 197 235 243 228 193 221 240 206 207 206 198 230 181 226 240 217 231 228 201 208 220 200 197 200 203 197 217 202 208 227 216 218 216 203 217 242 189 187 203 200 199 215 225 237 194 238 199 214 211 206 199 245 192 222 233 236 217 226 223 192 207 228 233 195 218 219 209 205 185 211 211 195 204 210 195 215 210 230 263 209 191 222 211 203 215 223 225 184 221 216 236 215 213 210 227 209 227 239 205 234 205 232 210 222 222 205 222 227 216 245 238 201 206 210 225 217 232 230 198 230 227 237 226 214 222 218 215 222 213 202 217 225 222 217 226 207 204 191 190 223 215 244 220 204 236 232 225 232 203 212 222 208 204 212 246 207 229 227 221 244 201 197 229 192 203 224 207 231 215 218 204 239 208 222 235 232 228 222 229 231 224 237 238 232 212 231 244 222 207 259 204 187 222 221 185 204 208 196 205 224 209 224 223 196 226 212 256 202 215 227 208 210 224 231 226 207 226 187 210 210 229 214 211 214 224 272 249 233 222 201 258 233 186 237 220 220 218 214 244 208 209 201 224 209 209 234 243 224 197 203 210 210 212 249 211 198 242 226 222 223 238 212 226 245 240 204 230 235 207 239 199 214 206 222 208 206 209 206 216 233 213 212 210 203 216 247 234 213 202 222 194 199 211 227 206 247 216 222 216 204 218 231 207 222 225 228 205 209 248 206 215 241 210 206 249 262 212 232 221 192 215 239 217 208 187 246 228 221 231 231 248 206 198 223 226 210 215 218 238 213 233 212 196 243 222 226 191 218 214 216 217 222 229 213 227 244 211 213 210 209 230 223 188 218 220 243 261 232 193 235 226 219 249 233 216 229 192 231 226 211 226 217 220 225 229 231 203 219 216 211 232 209 186 223 210 230 229 226 200 219 215 236 225 192 217 208 207 208 208 205 210 217 198 235 228 218 225 228 225 228 226 240 178 223 194 248 224 224 203 230 184 227 232 216 235 249 225 248 230 217 188 200 221 220 241 190 194 212 234 217 238 218 224 222 214 231 197 213 223 200 212 217 193 213 250 240 236 226 203 222 206 207 199 241 221 216 238 211 232 228 201 191 238 257 214 229 190 262 226 203 224 215 219 227 228 210 202 196 215 197 217 194 220 214 234 217 228 208 221 202 220 263 223 216 210 215 220 194 235 195 227 203 229 224 239 219 207 222 209 239 211 210 209 225 199 211 238 217 225 207 227 220 206 215 225 230 199 218 212 202 216 200 221 230 247 214 221 227 220 207 230 218 217 226 240 205 213 234 189 209 263 230 217 209 229 210 205 203 236 189 209 211 248 228 199 244 224 191 212 230 198 190 216 209 210 212 225 228 212 237 201 220 247 208 220 210 215 224 209 243 193 241 205 232 213 246 222 218 212 223 260 242 211 218 231 212 241 214 235 234 211 218 243 219 219 214 262 198 221 236 222 222 177 213 193 205 202 232 218 231 220 225 229 217 222 257 227 218 212 223 205 207 189 231 231 203 204 233 218 233 259 194 210 197 228 230 244 224 224 219 211 222 221 221 225 242 217 235 221 202 199 236 211 207 214 219 213 230 218 197 214 223 233 218 200 248 193 236 227 214 197 234 220 215 248 233 266 223 247 216 238 202 235 227 229 197 208 232 261 220 200 234 227 222 213 206 220 219 229 216 228 237 222 207 231 237 213 243 198 216 222 193 227 203 188 235 185 241 226 224 223 225 227 198 197 208 245 248 202 223 244 197 217 223 191 211 230 200 213 222 221 231 232 230 206 222 209 223 207 229 243 217 214 218 229 223 224 220 205 210 216 228 216 234 222 209 223 223 203 213 195 206 248 232 248 223 201 213 219 249 207 234 262 219 210 226 224 206 229 236 239 239 236 212 210 224 237 222 223 238 242 223 225 222 187 239 238 217 242 230 200 238 229 212 218 260 227 239 234 249 223 210 242 221 234 221 214 224 258 226 232 200 203 223 210 243 244 237 239 204 231 237 232 222 219 227 219 223 206 221 221 226 221 225 230 230 237 231 223 230 195 194 246 227 224 235 209 214 213 272 234 211 246 248 225 227 241 190 233 220 217 229 205 210 233 193 279 235 237 217 219 262 214 215 247 222 193 228 217 228 210 234 219 233 224 215 248 228 219 199 245 234 226 231 235 233 266 244 222 242 229 221 228 221 237 207 214 218 242 236 198 258 217 203 236 232 214 237 214 248 239 235 221 234 211 224 239 248 233 239 230 226 244 217 226 225 257 245 196 230 213 262 269 247 216 234 236 225 275 243 242 214 215 220 215 233 225 267 218 208 260 269 226 226 269 267 216 261 218 259 220 216 204 218 239 233 274 257 240 230 235 221 248 237 229 218 273 248 237 259 206 236 220 259 226 243 234 235 223 257 242 229 233 235 248 273 233 275 226 224 239 212 225 218 247 257 241 243 222 245 232 223 215 224 247 233 235 232 225 247 219 235 231 233 232 275 231 222 221 231 217 237 240 255 261 232 217 233 263 242 276 262 236 229 233 237 241 234 239 224 231 229 236 224 234 237 231 220 225 263 236 245 271 221 223 248 231 238 231 236 243 247 220 266 239 211 224 224 230 230 229 217 226 216 220 213 255 229 235 231 205 224 230 235 211 220 235 239 232 235 230 224 244 211 260 230 241 257 232 225 236 221 222 246 225 208 217 218 247 227 223 242 234 262 223 220 218 223 249 227 240 214 228 234 242 227 224 234 224 214 232 227 239 268 227 211 229 235 225 240 238 236 233 247 228 220 229 226 233 215 236 267 223 233 245 224 231 211 227 237 234 203 217 217 236 204 219 232 217 205 222 221 233 220 203 265 232 247 212 223 196 229 225 231 227 225 206 233 210 220 225 224 268 222 245 236 240 218 246 221 221 234 212 220 223 203 217 240 232 256 242 223 249 221 207 256 247 222 225 219 221 230 239 220 225 224 237 218 188 222 220 240 196 225 232 200 215 224 209 226 226 211 243 228 224 227 239 255 228 216 225 214 225 234 236 224 233 228 223 238 202 211 244 226 243 236 221 234 248 222 227 215 229 215 218 244 222 238 222 244 236 222 241 233 228 213 199 238 225 220 204 232 235 247 224 213 216 215 249 225 205 205 226 233 227 209 228 235 235 246 232 209 259 228 224 230 222 216 211 219 227 221 222 234 220 227 198 242 224 235 228 217 236 218 231 222 240 246 235 193 210 213 212 202 234 236 218 237 231 219 217 219 223 216 238 201 223 224 278 224 236 202 234 199 263 187 201 218 223 243 219 241 238 224 224 215 220 222 216 225 247 239 213 216 231 242 215 212 239 219 222 208 231 186 225 228 255 229 217 214 198 224 224 214 228 232 207 237 243 220 212 225 220 215 218 195 201 228 224 205 232 214 196 203 242 217 232 256 238 237 219 209 225 229 220 228 243 195 272 234 201 218 230 210 188 225 213 216 216 215 230 260 209 223 220 247 245 216 209 234 225 217 280 224 202 217 203 227 255 211 210 240 228 196 243 246 238 199 217 235 238 217 224 224 229 226 227 228 204 215 226 201 231 244 234 207 217 224 217 247 268 234 237 218 239 226 226 206 277 221 223 247 214 200 224 238 237 224 245 236 230 238 242 211 227 220 208 246 244 218 228 226 231 214 210 192 222 210 225 235 209 225 205 229 220 237 234 207 223 233 209 240 217 229 221 224 255 226 208 248 218 226 258 224 227 202 236 229 246 217 234 218 244 192 227 235 216 224 255 236 213 237 224 259 210 203 204 209 210 231 226 217 216 223 223 223 259 217 220 220 201 234 247 211 222 205 214 236 209 232 221 223 231 235 232 211 244 222 217 245 202 220 219 212 214 242 231 220 212 247 217 236 214 236 243 198 240 230 226 207 237 213 234 248 227 203 185 240 238 215 239 226 203 227 285 243 237 238 216 225 228 219 216 210 208 187 212 225 232 246 214 219 197 210 239 226 216 230 226 222 231 226 218 232 246 236 213 216 226 223 233 226 195 230 214 256 229 214 237 255 214 197 223 247 222 218 258 229 235 219 242 220 233 234 213 225 244 224 219 233 247 222 230 227 231 241 219 243 233 217 235 220 258 213 219 216 212 258 231 214 223 216 207 221 192 242 223 216 271 217 256 220 237 202 233 218 207 233 245 199 223 228 247 230 263 221 200 215 233 221 219 228 231 234 243 209 241 222 209 230 223 224 214 229 228 239 232 233 205 218 197 226 257 218 216 214 235 235 247 223 226 202 242 229 245 237 248 229 258 210 258 224 225 220 226 202 214 234 230 255 240 226 233 227 225 246 235 244 244 225 230 236 219 216 225 226 235 225 218 257 229 212 223 229 221 218 236 219 255 229 245 246 226 229 229 219 243 225 245 230 227 222 242 218 242 248 226 226 218 237 205 240 233 232 241 245 244 224 215 236 234 263 237 241 240 228 216 248 232 243 231 223 235 217 239 247 260 241 232 219 228 264 187 223 244 227 217 235 212 255 223 222 243 219 217 238 210 247 223 239 244 195 245 234 226 225 203 219 238 257 260 214 232 227 226 243 226 261 244 235 237 209 223 243 229 230 229 214 266 241 205 218 237 234 237 232 237 233 210 229 227 221 235 244 203 237 258 236 241 225 218 234 255 241 189 240 227 243 214 262 235 292 226 233 230 237 239 218 234 206 257 217 243 230 241 219 266 215 245 236 237 272 242 224 235 216 256 261 234 233 217 234 230 228 214 223 248 221 268 231 237 223 243 232 220 226 235 210 233 244 211 246 246 261 249 238 226 224 224 236 220 248 203 215 229 249 219 235 215 246 239 244 258 239 267 239 236 247 266 247 272 197 240 220 266 240 216 228 216 247 240 232 214 256 244 223 229 255 240 202 232 268 223 218 210 232 228 227 266 234 233 240 262 221 231 233 215 248 221 217 237 215 227 233 237 229 231 198 242 238 224 237 226 257 233 232 227 220 223 249 230 272 250 222 226 220 234 226 195 224 213 213 220 237 222 220 206 223 224 229 209 232 214 243 235 209 233 225 238 232 217 226 238 217 250 219 221 213 259 243 231 286 261 227 218 255 222 202 227 239 257 241 281 246 234 219 256 219 236 220 260 237 237 242 237 228 208 221 234 225 232 246 236 261 240 241 229 232 223 249 235 248 198 210 215 227 230 231 242 224 214 239 266 236 224 212 245 268 245 248 246 238 230 241 232 250 236 214 263 250 243 226 241 242 232 222 228 275 235 237 223 215 238 211 247 223 235 221 246 233 256 244 236 240 235 258 288 210 233 210 240 228 228 233 255 233 228 248 273 221 234 225 243 237 221 239 239 210 245 221 256 229 229 233 258 263 240 239 231 211 235 226 264 256 229 218 241 241 266 230 225 220 255 217 238 248 238 216 234 260 235 233 231 231 258 225 248 217 213 213 227 226 282 264 220 212 230 240 219 220 260 259 248 237 246 246 236 256 269 220 210 226 263 242 238 262 215 227 233 248 259 244 210 237 248 244 239 220 236 226 240 224 212 242 231 226 256 214 256 279 231 227 247 224 232 233 236 214 272 231 231 236 272 261 230 256 225 255 236 234 249 246 233 259 239</counts>
			</dataPoints>
		</scan>
	</xrdMeasurement>
</xrdMeasurements>