File: data/XRD/XG-Vakuum/XG-pre/W6821-1C_XG_Vakuum_pre.xrdml
<xrdMeasurements xmlns="http://www.xrdml.com/XRDMeasurement/2.1" xmlns:xsi="http://www.w3.org/2001/XMLSchema-instance" xsi:schemaLocation="http://www.xrdml.com/XRDMeasurement/2.1 http://www.xrdml.com/XRDMeasurement/2.1/XRDMeasurement.xsd" status="Completed">
	<comment>
		<entry>Configuration=Factory configuration, Owner=User-1, Creation date=7/8/2013 4:01:53 PM</entry>
		<entry>Goniometer=PW3050/65 (Theta/2Theta); Minimum step size 2Theta:0.0001; Minimum step size Omega:0.0001</entry>
		<entry>Sample stage=MRD Cradle; Minimum step size Phi:0.01; Minimum step size Chi:0.01; Minimum step size X:0.01; Minimum step size Y:0.01; Minimum step size Z:0.001</entry>
		<entry>Diffractometer system=XPERT-PRO</entry>
		<entry>Measurement program=C:\PANalytical\Data Collector\Programs\Jorrit\2thom\_absolute_2th-om_10-130deg_PIXscan_56min.xrdmp, Identifier={15BCCF57-2807-42BD-B5B9-ECC0B3DC9284}</entry>
		<entry>Batch program=C:\PANalytical\Data Collector\Programs\SimonL\batch8x_2thom_10-130°_z9.1_x0,10,20,30_y20,30,40,50_57min.xrdmp, Identifier={9A1B954C-70C5-4DE2-A2B5-D0000261ED0F}</entry>
	</comment>
	<sample type="To be analyzed">
		<id></id>
		<name></name>
		<preparedBy></preparedBy>
	</sample>
	<xrdMeasurement measurementType="Scan" status="Completed" sampleMode="Reflection">
		<comment>
			<entry>_absolute_2th-om_10-130deg_PIXscan_56min</entry>
			<entry>PHD Lower Level = 4.83 (keV), PHD Upper Level = 11.27 (keV)</entry>
		</comment>
		<usedWavelength intended="K-Alpha 1">
			<kAlpha1 unit="Angstrom">1.5405980</kAlpha1>
			<kAlpha2 unit="Angstrom">1.5444260</kAlpha2>
			<kBeta unit="Angstrom">1.3922500</kBeta>
			<ratioKAlpha2KAlpha1>0.5000</ratioKAlpha2KAlpha1>
		</usedWavelength>
		<incidentBeamPath>
			<radius unit="mm">320.00</radius>
			<xRayTube id="1010048" name="Empyrean Cu LFF HR (9430 033 7310x) DK442154">
				<tension unit="kV">40.0</tension>
				<current unit="mA">40.0</current>
				<anodeMaterial>Cu</anodeMaterial>
				<focus type="Line">
					<length unit="mm">12.0</length>
					<width unit="mm">0.4</width>
					<takeOffAngle unit="deg">4.2</takeOffAngle>
				</focus>
			</xRayTube>
			<xRayMirror id="27010001" name="Inc. Beam Cu W/Si (parabolic MRD)" hybrid="false">
				<crystal type="Graded" shape="Parabolic">W/Si</crystal>
				<acceptanceAngle unit="deg">0.800</acceptanceAngle>
				<length unit="mm">60.0</length>
			</xRayMirror>
			<sollerSlit id="21010002" name="Soller slits 0.04 rad.">
				<opening unit="rad">0.0400</opening>
			</sollerSlit>
			<mask id="22030008" name="Fixed mask 4 mm">
				<distanceToSample unit="mm">220.00</distanceToSample>
				<width unit="mm">4.00</width>
			</mask>
			<divergenceSlit id="22010007" name="Fixed slit 1/8°" xsi:type="fixedDivergenceSlitType">
				<distanceToSample unit="mm">220.00</distanceToSample>
				<height unit="mm">0.19</height>
			</divergenceSlit>
		</incidentBeamPath>
		<diffractedBeamPath>
			<radius unit="mm">320.00</radius>
			<sollerSlit id="21010002" name="Soller slits 0.04 rad.">
				<opening unit="rad">0.0400</opening>
			</sollerSlit>
			<receivingSlit id="22010001" name="Fixed slit 4°">
				<height unit="mm">5.88</height>
			</receivingSlit>
			<detector id="7010017" name="PIXcel3D 1x1 detector" xsi:type="areaDetectorType">
				<phd unit="%">
					<lowerLevel>30.0</lowerLevel>
					<upperLevel>70.0</upperLevel>
				</phd>
				<mode>Scanning</mode>
				<activeChannelsEquatorial>255</activeChannelsEquatorial>
				<activeChannelsAxial>255</activeChannelsAxial>
				<pitchEquatorial unit="mm">0.05500</pitchEquatorial>
				<pitchAxial unit="mm">0.05500</pitchAxial>
				<readOutPeriod unit="seconds">0.135</readOutPeriod>
			</detector>
		</diffractedBeamPath>
		<scan appendNumber="0" mode="Continuous" scanAxis="2Theta-Omega" status="Completed">
			<header>
				<startTimeStamp>2024-10-04T07:28:08+02:00</startTimeStamp>
				<endTimeStamp>2024-10-04T08:24:12+02:00</endTimeStamp>
				<author>
					<name>PRO-MRD</name>
				</author>
				<source>
					<applicationSoftware version="6.1b">Data Collector</applicationSoftware>
					<instrumentControlSoftware version="7.0E 20130304">XPERT-PRO</instrumentControlSoftware>
					<instrumentID>0000000011142674</instrumentID>
				</source>
			</header>
			<dataPoints>
				<positions axis="2Theta" unit="deg">
					<startPosition>9.99826193</startPosition>
					<endPosition>129.99755682</endPosition>
				</positions>
				<positions axis="Omega" unit="deg">
					<startPosition>4.99913096</startPosition>
					<endPosition>64.99877841</endPosition>
				</positions>
				<positions axis="Phi" unit="deg">
					<commonPosition>0.00</commonPosition>
				</positions>
				<positions axis="Chi" unit="deg">
					<commonPosition>0.00</commonPosition>
				</positions>
				<positions axis="X" unit="mm">
					<commonPosition>0.00</commonPosition>
				</positions>
				<positions axis="Y" unit="mm">
					<commonPosition>0.00</commonPosition>
				</positions>
				<positions axis="Z" unit="mm">
					<commonPosition>9.100</commonPosition>
				</positions>
				<commonCountingTime unit="seconds">32.895</commonCountingTime>
				<counts 459 446 454 447 433 439 421 420 483 475 438 428 450 453 455 418 489 399 427 405 447 428 417 446 417 418 396 424 453 430 419 409 440 418 488 407 412 459 472 442 455 420 472 431 419 420 416 432 425 402 402 436 470 454 479 421 466 402 406 396 460 403 401 424 449 467 438 413 476 452 450 421 426 409 416 409 417 410 430 388 404 433 427 409 459 434 432 412 413 391 408 411 408 415 409 420 386 411 411 379 417 409 413 415 399 404 415 402 415 446 399 438 415 378 403 392 412 421 419 457 391 387 411 443 410 393 397 407 417 411 392 394 401 434 405 405 411 404 422 446 412 407 418 433 401 385 393 381 403 385 399 424 375 398 397 417 414 363 399 367 373 382 409 390 376 380 370 385 403 438 392 409 404 405 407 426 404 371 420 389 368 381 408 383 397 388 428 407 384 379 414 360 392 403 392 349 353 351 440 402 414 382 389 398 389 388 380 407 380 367 382 396 343 372 403 393 409 409 385 360 392 382 423 388 392 379 376 363 360 400 394 346 409 375 352 386 369 399 397 398 404 371 398 388 396 362 373 386 370 372 373 337 374 384 376 360 360 339 424 384 352 357 410 381 357 367 358 360 377 365 349 398 327 370 398 362 365 368 358 378 348 381 351 367 364 346 389 361 369 385 320 386 377 367 346 368 378 384 373 376 365 368 367 371 394 361 364 379 349 386 368 337 339 348 362 356 392 322 387 356 330 361 332 355 338 372 355 379 380 375 383 366 375 382 361 364 391 363 352 344 411 343 386 339 369 377 308 337 331 363 368 309 354 355 342 342 340 343 366 322 341 346 369 346 383 367 351 360 350 355 346 365 349 349 348 381 340 366 355 317 330 336 304 363 318 368 358 319 354 335 350 343 385 381 352 320 357 354 369 340 353 349 359 338 342 326 335 346 342 336 357 374 392 368 332 317 331 345 299 297 324 361 364 333 341 353 325 348 332 347 336 358 329 332 333 315 329 362 340 326 331 334 346 349 332 322 366 336 343 352 306 313 342 326 328 327 323 328 345 378 333 329 319 341 328 346 311 323 344 339 360 332 320 313 357 369 329 329 327 336 370 359 286 342 311 342 338 356 327 307 326 331 356 341 341 338 347 316 307 306 344 323 325 329 339 330 346 338 358 302 345 329 343 323 298 317 359 323 328 349 317 343 310 325 329 355 320 296 325 302 331 293 327 338 309 293 340 316 364 300 327 291 319 360 334 303 315 318 333 308 326 340 338 335 333 350 312 302 269 316 332 328 339 310 304 322 324 303 332 342 311 329 302 313 322 292 331 317 308 313 328 295 328 345 341 297 302 337 340 289 349 319 298 321 328 292 307 297 291 306 293 309 283 355 338 344 301 273 317 317 300 289 244 326 307 332 322 310 297 310 332 283 329 294 318 315 343 326 330 337 312 298 325 338 325 324 352 306 338 326 315 302 305 309 331 337 324 324 328 333 329 278 323 322 311 275 328 293 304 308 335 313 291 277 340 309 318 287 300 320 327 350 301 330 306 303 340 324 337 317 314 328 365 311 279 291 287 322 305 324 328 305 344 318 297 309 298 305 329 296 282 353 297 325 319 321 281 313 334 316 321 288 317 323 307 302 306 324 317 330 340 291 316 299 315 276 313 347 290 325 325 325 326 347 324 305 316 302 327 312 299 318 321 338 312 325 296 294 307 278 296 311 307 303 307 357 319 302 293 324 326 326 327 308 317 333 357 318 317 337 306 295 291 307 287 344 342 306 347 325 303 318 284 302 323 306 354 331 283 317 326 298 323 335 326 313 300 303 342 306 281 320 332 283 310 356 308 321 336 341 313 315 325 298 304 314 309 322 316 325 339 317 308 312 319 318 302 323 353 308 278 305 337 319 297 337 328 335 341 311 305 317 326 331 297 317 347 328 311 333 328 340 313 331 273 318 329 329 312 346 310 301 294 355 311 345 322 349 340 294 346 335 307 294 318 313 334 310 333 321 295 301 317 315 309 298 329 358 339 352 341 326 341 318 308 296 306 301 322 350 340 310 323 314 344 325 320 307 296 311 319 353 314 338 329 314 317 338 332 318 331 286 300 311 331 321 353 332 308 300 324 310 337 297 328 323 304 332 310 335 347 329 286 300 329 307 302 348 325 327 309 320 323 343 339 344 330 309 338 293 312 332 320 326 363 329 356 311 373 338 325 337 326 325 304 330 340 305 336 307 325 330 307 303 315 340 300 335 298 354 329 331 364 362 339 324 300 345 352 324 358 370 336 322 336 327 297 304 338 314 320 305 325 288 315 336 353 318 344 330 312 327 341 291 342 342 329 316 316 358 319 348 315 347 379 314 332 316 348 324 342 294 299 323 367 318 357 326 329 380 342 316 356 350 328 314 359 319 326 324 326 314 339 337 321 336 327 320 315 352 331 346 329 336 315 319 338 359 305 342 336 366 363 300 354 371 324 338 324 326 344 364 361 343 361 330 323 338 326 344 322 317 308 308 335 366 349 363 337 324 332 343 350 332 323 316 344 331 361 344 345 307 350 338 344 373 314 356 355 342 331 345 356 336 344 364 340 347 332 346 322 348 325 348 314 354 322 357 296 344 346 368 347 364 379 330 299 360 353 358 346 340 329 329 341 348 326 336 331 322 327 343 355 373 373 352 326 319 370 352 328 335 291 342 324 353 335 307 336 321 339 333 357 365 343 354 359 350 332 343 350 333 319 375 360 330 323 349 333 342 309 341 354 312 324 364 344 372 334 339 311 349 352 361 319 358 343 324 291 319 345 325 327 358 361 320 308 302 346 347 349 336 329 355 330 352 346 338 332 369 349 342 338 320 331 336 361 342 367 336 364 365 323 343 359 320 346 335 338 328 339 358 337 328 318 341 367 334 351 365 321 326 360 351 313 345 333 338 359 356 337 349 332 356 335 349 354 348 351 380 345 341 346 336 347 317 345 344 331 361 358 343 333 325 338 338 398 336 359 361 321 330 383 327 366 361 369 350 381 333 355 357 338 349 334 365 306 325 325 348 348 344 342 321 354 334 359 310 348 339 290 352 331 364 348 329 326 323 353 373 349 353 348 356 356 346 310 350 357 340 346 338 336 323 337 338 350 367 321 354 352 354 324 346 343 326 334 375 321 341 341 334 352 334 300 344 336 323 318 340 327 315 304 335 322 347 338 335 334 352 339 329 368 307 343 336 311 402 315 328 366 361 350 341 350 327 393 342 302 332 303 314 332 356 311 344 317 356 346 336 317 362 353 359 326 321 320 318 333 354 324 317 324 356 329 323 358 356 334 306 340 333 303 346 320 316 356 330 370 342 354 364 329 360 320 313 329 304 336 317 304 323 320 337 338 357 319 331 321 340 314 311 321 342 328 317 315 317 315 339 347 349 319 355 309 322 295 331 335 343 344 332 330 367 312 314 314 341 322 321 350 354 331 314 311 319 309 320 336 372 330 301 348 315 318 323 339 312 333 280 359 331 345 318 294 297 314 341 331 330 321 330 337 339 311 352 299 322 309 299 315 325 341 293 323 344 328 357 329 321 309 305 328 307 346 300 336 344 335 312 319 322 304 316 319 343 312 319 331 317 326 321 325 311 333 331 330 333 321 338 311 341 303 319 303 324 341 295 276 347 332 318 326 333 298 280 353 305 281 335 303 349 282 314 282 356 302 291 302 312 306 310 300 323 305 350 283 306 302 325 335 317 323 379 306 295 308 343 324 320 316 309 298 344 292 287 297 318 261 312 296 315 296 350 293 288 318 318 334 333 305 307 343 315 296 301 315 303 299 332 312 285 309 331 315 324 264 285 331 276 334 324 316 336 311 306 290 309 326 319 274 345 334 340 318 287 302 270 286 286 324 291 265 331 310 301 263 321 302 293 296 281 332 300 308 314 325 337 307 290 312 308 294 278 296 333 273 271 299 329 308 323 265 308 295 287 319 326 304 306 308 301 285 292 305 295 306 289 310 275 285 305 313 323 271 334 309 264 282 286 296 293 314 295 294 305 291 284 298 284 294 293 263 322 277 329 280 311 313 314 306 320 288 313 304 312 313 291 282 280 282 304 297 301 303 271 307 294 322 315 268 278 317 245 280 302 308 287 288 280 292 280 285 299 285 293 311 285 304 282 261 291 302 291 280 289 307 285 306 304 312 277 308 292 287 302 273 292 314 294 274 300 308 315 275 308 298 294 278 291 293 292 332 306 280 265 301 272 284 293 289 286 283 310 291 285 274 272 324 287 296 294 277 285 278 275 279 335 287 303 312 293 290 271 267 298 277 290 293 276 303 279 276 291 273 267 263 265 303 279 289 288 261 264 323 294 285 298 283 301 281 287 285 271 289 255 268 295 284 295 307 267 267 299 264 311 274 256 313 277 243 294 267 302 276 274 271 264 278 291 285 288 310 243 261 296 291 296 269 267 304 285 293 292 293 286 300 258 248 229 258 282 302 293 272 274 278 269 304 299 284 281 304 261 302 304 304 278 318 268 278 305 288 282 256 271 241 241 275 263 282 266 229 294 244 281 241 291 255 278 297 264 244 303 295 275 285 301 284 290 283 284 272 305 262 301 296 285 287 285 297 276 285 239 248 297 311 300 291 274 260 247 270 258 302 312 265 279 301 283 285 274 287 277 266 293 276 315 283 292 305 248 270 274 249 276 295 269 287 263 292 249 249 303 249 293 288 286 287 244 297 308 275 285 281 294 267 246 280 270 260 244 295 258 227 263 247 273 286 263 267 266 292 229 270 278 274 277 257 272 279 267 295 300 292 269 285 257 278 266 270 274 292 266 262 273 267 274 276 272 293 284 274 289 277 263 264 284 283 230 270 270 273 280 269 267 290 293 248 266 265 277 292 285 264 269 289 259 246 265 268 284 238 256 242 278 285 280 267 282 265 278 242 271 286 236 279 246 264 269 297 255 277 229 283 259 312 255 277 278 263 279 275 273 257 258 257 263 298 281 282 267 266 278 267 283 271 270 288 268 263 257 273 276 283 285 260 245 261 273 266 269 237 264 273 242 231 275 282 249 258 263 261 232 281 280 245 239 268 278 239 268 261 256 260 235 261 292 250 247 256 281 286 266 249 277 273 276 276 244 282 242 243 255 248 261 255 260 245 245 293 225 287 247 278 287 275 293 256 248 256 294 232 274 287 256 267 241 276 283 278 241 218 301 281 269 285 269 278 245 248 240 246 278 289 258 234 262 249 233 274 240 247 272 217 240 279 260 309 274 237 266 257 249 266 246 248 258 247 269 263 278 272 285 241 282 246 274 284 264 267 246 227 260 282 240 240 278 278 260 270 247 237 246 244 260 236 262 234 282 258 269 264 239 256 258 237 264 256 235 244 243 264 269 224 264 255 294 269 278 260 262 279 273 270 255 242 257 261 247 239 293 246 240 249 266 245 233 262 263 243 262 238 242 237 263 272 269 241 264 234 276 245 221 283 258 268 233 281 248 257 235 266 249 274 247 269 233 240 245 243 247 222 263 260 263 239 246 246 279 243 261 239 264 234 232 261 231 250 247 263 277 239 270 278 226 291 256 255 260 244 244 272 279 241 243 258 267 223 230 245 265 280 256 278 286 266 269 228 263 282 277 268 270 257 245 271 299 274 249 295 260 262 267 244 228 245 248 266 264 228 248 281 274 236 218 249 290 268 240 290 258 261 260 249 268 275 243 272 230 265 228 258 255 246 256 244 272 244 256 255 276 234 270 214 294 247 255 240 246 310 243 246 271 257 243 256 258 266 238 223 250 235 283 219 261 269 229 236 246 262 280 260 261 245 257 223 238 288 270 266 271 263 240 240 243 274 237 248 214 277 271 239 230 260 242 233 268 233 234 261 220 236 264 248 219 216 278 270 257 223 240 249 232 269 249 250 263 256 239 256 280 271 256 226 268 268 268 233 259 235 258 263 265 270 261 258 248 278 249 257 242 279 242 226 242 223 260 276 262 238 247 274 268 240 237 244 280 268 232 246 276 255 281 239 246 277 230 259 273 278 267 258 269 249 286 257 287 280 230 240 263 282 235 245 267 249 230 239 246 257 258 238 231 270 259 216 256 236 244 238 256 271 246 232 246 258 247 267 276 249 248 249 240 239 280 277 278 257 248 275 244 233 245 261 232 273 239 269 249 232 268 259 284 249 248 227 238 260 248 256 235 203 225 257 257 247 233 278 214 244 264 236 226 289 276 248 244 214 262 239 241 262 263 246 243 264 238 246 232 259 265 240 279 210 222 259 224 287 230 237 273 274 266 248 228 211 279 247 260 233 239 230 269 234 272 243 230 244 237 263 229 226 240 241 260 259 256 237 239 242 247 277 233 231 260 273 268 276 234 255 270 248 266 272 246 242 231 229 250 263 246 221 233 225 260 197 248 241 273 262 239 283 234 247 269 202 228 244 217 280 246 260 235 275 270 217 233 236 260 230 234 266 274 265 257 279 249 212 235 218 246 230 229 246 263 221 224 263 260 276 276 242 264 267 234 250 249 268 247 230 229 261 221 243 231 265 224 233 255 232 264 233 223 268 228 229 249 231 259 213 262 228 237 238 244 248 242 261 240 234 260 233 250 248 243 247 232 232 247 271 212 246 257 244 235 240 222 244 265 238 229 234 260 250 237 243 233 233 263 241 218 262 283 257 225 259 268 255 246 226 249 234 265 241 227 228 260 244 232 238 274 228 275 241 226 267 241 282 227 280 248 222 236 248 283 214 240 266 256 231 261 260 255 226 246 214 257 259 242 232 245 238 238 255 256 243 244 222 260 237 235 208 237 248 234 227 259 247 257 258 255 226 262 251 265 248 222 246 221 243 228 278 261 264 258 245 244 236 237 236 232 246 236 239 240 233 225 213 207 264 217 265 280 237 230 215 223 225 225 225 234 267 261 266 274 236 221 228 249 211 228 225 267 241 264 244 267 247 216 268 274 243 245 255 237 272 236 234 276 216 261 235 278 233 271 260 233 232 276 256 236 248 263 233 240 214 256 272 257 261 240 272 256 245 230 265 263 248 242 232 273 264 214 255 238 242 278 276 271 246 217 236 249 258 267 262 219 265 256 234 264 236 249 226 269 248 255 258 240 247 261 255 279 271 269 247 245 276 256 265 260 248 280 258 275 267 275 249 277 268 262 280 282 282 272 244 262 271 268 236 239 267 269 246 284 248 243 270 278 282 256 238 245 268 244 265 245 236 248 243 270 262 271 258 258 273 261 282 260 260 264 259 237 257 276 269 266 258 231 230 223 270 255 230 261 234 266 292 225 241 270 255 268 268 262 238 243 241 261 292 289 248 276 256 235 257 242 234 256 275 263 243 266 265 266 280 267 264 284 259 242 244 265 228 244 213 238 271 235 238 272 245 271 277 258 266 276 256 258 268 235 266 289 245 273 268 279 279 276 281 275 234 261 239 244 243 265 241 229 282 255 246 266 287 258 275 276 235 286 264 236 249 279 256 244 248 272 261 255 211 260 257 290 260 212 239 266 256 213 255 242 265 239 246 242 280 265 232 312 259 255 257 257 257 279 261 240 264 232 220 255 268 270 269 279 273 266 270 263 235 249 267 227 247 265 258 238 266 255 263 284 241 225 277 258 271 266 259 273 280 277 275 279 264 267 232 245 255 239 248 232 264 241 277 263 275 270 262 241 285 283 260 284 273 264 274 258 234 289 258 296 287 276 243 290 269 279 284 283 281 278 276 280 268 278 258 309 288 277 249 273 296 282 299 276 289 271 267 281 304 243 294 269 287 299 301 286 278 291 317 266 281 307 292 310 291 320 294 290 275 300 337 328 301 354 364 301 326 330 332 353 348 316 333 340 365 360 370 404 394 421 434 432 440 487 428 489 454 514 494 472 507 506 509 533 513 492 478 462 476 500 460 429 409 444 440 401 428 424 409 393 384 362 336 367 353 364 354 347 335 327 331 325 320 319 295 294 294 335 303 280 287 295 283 287 306 272 302 299 262 286 287 262 283 288 275 260 277 277 276 284 289 273 282 295 293 234 284 260 249 229 276 289 285 267 266 262 279 293 272 266 248 247 263 234 271 285 258 260 236 269 276 226 290 281 247 261 272 271 261 266 273 261 259 243 290 249 261 272 283 244 245 270 266 277 266 280 229 303 244 263 235 257 263 215 311 267 263 278 276 242 245 247 283 245 274 305 266 245 271 225 232 264 297 249 245 273 228 259 246 246 243 272 265 245 262 260 236 278 250 275 243 221 245 270 255 257 265 261 263 268 284 268 256 262 272 256 257 266 229 238 242 261 263 246 255 259 286 262 239 247 279 227 268 255 245 265 256 256 258 275 259 242 262 238 246 263 271 269 240 279 257 257 243 243 229 276 289 292 275 240 269 265 273 257 270 291 276 284 267 263 257 263 241 268 266 247 237 256 249 242 244 272 275 269 247 259 267 240 265 275 255 292 272 233 248 249 257 236 274 260 279 276 257 221 276 229 248 249 244 259 259 234 262 267 263 278 241 246 261 268 269 249 243 244 269 247 241 222 255 226 245 270 228 280 261 245 238 269 283 268 237 257 248 233 271 287 235 276 275 256 271 271 236 246 269 232 264 248 286 267 244 268 275 243 250 245 256 291 228 270 268 247 263 266 260 270 246 296 261 274 260 273 282 235 242 265 278 259 258 256 246 265 249 247 271 241 257 243 258 236 243 236 285 266 234 246 291 266 273 264 218 262 266 234 247 238 269 266 261 263 237 249 278 237 261 283 287 248 260 275 237 230 277 262 264 267 273 274 297 279 268 249 269 236 273 273 244 239 288 291 276 257 240 222 295 282 244 266 248 238 230 268 263 281 250 257 274 286 210 283 262 262 214 265 257 238 290 262 256 265 243 229 269 257 260 281 274 297 258 259 288 245 277 243 227 256 264 255 225 242 259 268 249 244 258 258 283 257 255 278 218 268 244 271 276 256 256 248 268 270 285 228 268 247 245 282 290 259 233 286 265 255 231 232 232 232 277 238 266 246 220 240 272 248 269 268 264 225 270 269 269 274 248 284 273 256 279 263 246 272 245 238 240 231 236 249 215 270 246 263 218 286 259 262 249 227 261 268 264 256 290 291 264 277 279 226 265 234 238 240 246 246 262 281 248 250 258 276 256 249 243 258 242 256 269 222 247 248 241 277 245 258 235 257 262 243 227 284 270 221 247 240 266 266 224 223 247 228 262 229 240 276 241 249 242 273 255 247 282 266 265 231 260 231 269 241 258 235 244 264 250 242 257 230 260 259 247 258 255 282 242 261 242 264 285 268 224 262 262 239 247 263 241 269 261 264 269 274 262 269 259 275 267 244 239 256 276 248 238 241 242 248 268 232 231 260 277 228 269 281 240 241 273 218 224 259 243 266 222 255 270 255 230 269 271 229 231 257 231 259 260 277 265 274 265 269 262 247 222 231 248 236 231 204 247 241 274 246 283 247 237 278 260 248 233 260 268 208 249 271 276 257 262 240 247 238 239 240 272 233 293 262 265 275 258 262 257 269 277 241 229 245 258 234 233 265 258 235 236 281 300 268 244 280 278 243 222 279 267 224 237 235 256 244 221 232 240 242 258 238 285 244 263 256 236 266 261 292 279 230 238 266 280 243 250 242 263 249 241 247 256 263 284 231 265 257 269 250 239 240 249 294 267 243 259 243 249 267 274 232 279 241 261 280 246 261 259 260 238 280 280 256 273 268 234 261 273 259 246 272 268 263 276 249 269 235 266 236 239 269 273 287 265 247 241 250 240 246 262 240 241 284 235 237 240 242 271 230 236 257 246 267 229 246 272 230 270 234 225 223 247 258 229 232 258 266 291 249 256 249 273 245 266 267 293 227 256 218 280 247 228 293 238 266 265 262 270 247 263 261 245 267 277 233 232 232 282 218 245 248 240 273 247 261 225 268 278 269 266 267 292 237 269 263 226 233 263 244 271 266 281 255 270 262 257 244 258 255 230 270 243 237 221 226 284 256 262 280 240 255 255 235 289 265 257 248 278 269 263 243 238 265 263 241 258 229 257 249 250 276 241 264 247 301 255 267 262 243 265 240 243 239 266 270 259 250 239 261 270 266 231 237 235 235 246 248 272 258 232 258 255 224 268 272 247 205 230 259 266 226 273 226 244 272 259 244 214 247 272 239 242 249 234 255 244 261 283 267 262 215 224 258 279 266 256 275 272 275 259 261 247 265 274 231 266 255 246 244 242 270 289 229 265 236 247 225 220 247 232 218 255 257 236 258 257 273 191 272 264 258 255 232 228 283 245 271 281 238 243 274 232 227 242 273 250 247 261 261 281 215 232 280 247 239 232 274 260 272 232 277 279 232 256 249 215 231 257 269 245 263 261 296 234 266 263 257 233 262 265 233 258 248 271 263 277 259 264 260 247 283 259 243 277 249 243 249 263 223 232 292 225 246 259 294 269 242 231 259 275 264 265 262 247 270 236 247 246 258 274 284 242 197 265 247 233 244 230 266 264 245 276 237 260 270 227 260 244 244 236 274 215 265 281 240 246 250 245 258 269 263 248 230 247 259 237 272 292 261 255 259 260 266 226 221 276 264 244 256 269 259 238 283 262 279 245 267 263 298 264 245 224 265 248 227 265 263 284 264 247 280 249 257 231 244 258 262 263 265 234 281 258 245 279 233 266 226 279 230 243 267 231 255 262 269 269 246 289 242 225 264 243 248 246 264 281 263 259 266 265 269 282 259 258 273 271 239 242 275 243 286 264 290 246 274 267 246 284 242 276 277 267 241 276 234 239 249 223 267 268 269 272 248 233 263 279 233 262 268 259 237 239 260 239 243 225 220 269 264 274 232 269 261 246 266 293 263 261 294 244 273 250 265 256 250 233 228 265 260 227 244 229 260 264 237 247 289 271 266 221 230 256 235 283 217 256 227 305 247 264 270 255 268 242 256 195 273 265 280 258 240 275 263 266 268 256 272 293 232 249 244 307 261 274 275 247 256 262 274 259 242 276 287 272 281 255 262 288 255 259 285 271 255 234 221 255 224 240 243 233 263 263 264 256 265 246 245 249 289 262 273 261 233 235 271 241 274 272 264 273 265 248 276 269 233 271 255 287 275 261 277 242 269 261 249 236 270 265 241 263 268 258 293 276 286 238 245 246 267 299 272 233 244 274 274 275 260 263 277 227 260 268 275 279 297 281 279 241 242 277 219 270 230 296 263 261 277 271 273 240 276 243 258 256 279 244 290 277 247 282 276 260 256 286 238 248 242 257 248 274 282 255 257 288 222 247 289 291 250 245 249 292 258 242 263 263 265 256 274 257 230 287 264 268 258 248 279 258 241 270 283 255 275 244 261 237 255 262 263 246 239 259 263 278 226 280 256 268 277 222 298 261 275 272 296 274 278 272 240 289 236 229 271 284 276 266 272 285 267 243 262 260 280 236 263 259 242 281 265 281 240 265 268 247 291 259 262 265 249 232 239 293 240 273 243 262 236 277 258 235 232 258 274 219 241 264 265 270 244 231 260 258 275 301 242 255 284 247 246 258 227 285 246 233 272 263 242 246 270 270 233 244 264 283 262 248 271 264 255 292 271 273 245 258 255 263 280 239 238 282 292 243 247 245 288 216 268 234 255 267 239 206 264 276 287 267 286 232 275 242 243 238 272 238 278 249 269 299 250 214 270 256 257 267 273 256 283 269 259 294 243 279 247 259 262 237 260 277 246 278 293 293 281 244 262 273 264 269 286 289 274 288 247 268 247 224 270 230 271 241 239 280 249 259 275 274 268 255 241 284 279 271 260 286 267 264 258 261 250 279 276 269 215 245 240 281 258 259 275 246 271 286 278 262 239 300 264 261 269 279 232 258 255 267 266 278 242 244 267 260 228 266 273 273 259 237 236 267 264 246 273 280 245 260 228 278 257 259 226 238 278 276 242 234 281 246 260 222 250 265 260 242 266 246 243 287 261 287 264 233 231 264 297 259 249 273 280 265 257 266 248 256 240 241 237 263 248 260 245 258 268 255 257 280 295 276 258 231 248 262 244 272 246 261 237 277 263 285 259 262 257 237 239 267 277 260 292 239 294 247 256 268 239 256 260 225 221 266 272 277 246 271 271 228 284 266 256 270 237 287 262 264 269 224 264 274 236 264 242 267 270 281 267 236 264 267 270 263 256 238 236 286 242 262 256 262 267 243 244 245 275 257 250 221 271 286 266 270 255 257 268 250 207 277 280 263 223 255 276 234 256 275 285 260 274 255 226 296 242 274 286 249 256 255 273 289 262 274 274 278 250 247 268 281 269 259 274 281 234 256 270 280 255 248 244 259 266 276 262 263 256 266 268 294 249 280 269 241 257 274 237 273 271 284 291 250 257 256 287 282 279 249 291 279 233 238 247 245 249 281 246 227 264 288 271 268 286 277 246 271 262 246 277 266 283 248 265 270 281 256 247 277 279 313 261 257 258 261 273 255 248 286 227 287 282 273 277 280 261 261 295 276 298 276 288 277 262 278 221 271 293 265 272 268 301 286 293 301 296 265 260 308 286 286 276 308 302 284 282 273 280 302 289 275 288 267 306 290 274 238 263 273 279 263 280 292 318 282 263 265 304 287 274 287 281 268 291 242 259 256 249 270 247 271 231 289 292 274 271 237 265 309 275 260 261 229 273 282 284 287 271 287 269 296 281 280 288 268 244 281 303 237 247 298 300 240 278 302 266 257 296 269 278 271 280 256 270 263 289 267 273 240 233 265 243 275 274 240 260 246 304 271 267 248 275 278 286 284 248 280 245 215 245 261 278 269 255 283 271 242 236 258 257 263 255 276 244 281 263 272 246 289 260 273 250 257 240 261 261 272 281 248 295 246 262 232 258 238 260 261 249 261 283 236 265 266 280 234 269 289 241 240 279 243 248 271 249 282 258 235 256 287 266 261 255 293 265 267 291 226 239 240 277 286 243 246 260 257 237 256 302 261 260 267 267 224 318 279 268 258 261 244 258 263 274 246 249 271 258 270 245 260 255 274 287 245 271 276 281 262 258 268 269 258 260 274 246 288 263 236 260 272 284 272 232 276 271 263 257 291 291 279 263 234 260 247 286 260 230 260 267 237 278 227 272 248 268 246 258 273 256 261 265 241 249 297 300 249 263 264 277 287 260 259 260 259 236 283 242 279 263 263 294 264 255 274 241 229 259 278 263 275 246 289 274 293 298 243 264 272 256 242 242 286 275 244 264 270 256 279 258 237 248 273 275 257 280 273 274 268 274 275 272 270 274 246 288 240 297 258 281 265 245 280 234 263 267 233 256 257 257 283 239 241 263 274 262 277 278 280 263 249 247 265 225 257 273 265 270 259 247 280 247 290 279 240 249 282 261 268 246 267 213 282 242 258 259 267 300 218 267 279 262 267 270 304 259 273 272 257 268 277 247 266 268 257 271 277 295 281 239 255 277 280 285 267 273 256 276 262 255 267 273 282 278 276 273 241 248 240 234 242 276 234 263 236 258 257 241 283 256 248 282 265 259 261 273 232 272 282 263 240 265 269 242 268 276 238 257 292 283 236 265 262 242 258 246 267 244 242 272 249 245 233 284 261 247 249 269 255 259 247 265 276 249 250 276 259 285 243 287 256 239 255 274 226 255 274 277 276 231 279 242 235 273 274 241 279 271 257 262 278 273 246 260 244 256 243 276 286 242 272 274 259 277 233 244 248 263 248 259 262 264 271 288 264 246 218 240 267 232 269 247 295 246 279 281 275 255 282 240 281 281 255 232 249 270 279 243 278 258 269 256 258 277 259 266 278 248 209 233 234 230 293 285 236 262 257 272 249 248 257 264 243 275 295 257 234 243 267 257 239 256 234 264 290 264 283 324 249 260 283 280 267 276 250 249 258 262 225 246 233 298 283 249 288 246 263 247 236 213 274 295 282 261 285 269 270 228 265 267 255 248 269 263 291 248 255 268 255 248 291 262 271 266 240 276 261 232 263 275 235 259 234 257 238 276 256 275 276 239 241 255 244 240 244 247 271 289 260 239 245 275 277 239 232 279 228 276 279 262 241 262 267 277 267 258 260 247 235 233 247 299 306 248 236 238 289 255 264 258 276 265 261 257 304 260 300 237 267 270 247 262 268 239 239 243 233 264 267 285 306 227 273 266 260 279 278 242 279 282 266 265 285 238 242 249 228 263 258 268 256 286 235 262 242 287 288 261 256 273 271 264 276 272 293 243 283 218 264 268 270 259 262 248 242 249 245 248 272 274 256 244 263 265 249 282 270 265 248 234 267 258 237 248 263 234 248 261 232 292 268 288 269 267 269 268 285 279 230 267 279 290 269 274 293 248 264 241 247 266 297 262 283 241 288 278 266 281 267 279 259 283 264 272 249 255 295 277 244 255 249 294 272 267 237 288 233 261 238 235 244 284 249 224 224 259 264 281 276 223 260 264 277 248 282 271 278 263 269 293 262 249 247 246 240 245 282 246 235 262 265 293 271 256 250 258 259 267 262 290 281 279 228 256 259 247 265 247 263 230 266 277 262 258 244 265 237 275 276 242 249 269 269 260 295 219 269 260 236 260 241 260 238 290 267 243 245 268 265 272 287 248 277 241 243 241 258 247 248 239 268 270 265 282 248 266 295 256 266 222 237 248 262 279 248 272 272 248 230 248 292 264 242 258 265 273 243 261 250 244 238 258 259 279 300 220 258 261 273 201 285 245 275 262 268 256 296 245 267 281 271 241 280 233 280 239 231 246 240 224 239 258 255 261 247 246 271 261 270 260 266 236 273 259 262 256 256 269 250 240 270 280 239 245 228 273 261 275 269 279 273 255 270 291 210 229 237 265 246 227 299 275 241 269 270 282 283 222 246 258 248 249 261 289 267 284 242 241 270 257 243 274 280 260 237 281 256 281 290 265 255 237 260 280 262 255 260 243 245 283 290 264 255 232 243 241 237 246 282 220 244 291 268 220 281 238 292 263 221 277 268 299 260 222 256 282 279 245 280 257 244 268 263 273 276 236 232 249 271 285 266 264 235 273 258 279 260 293 248 260 272 271 240 263 215 242 270 272 276 276 266 267 255 263 272 234 237 238 272 275 281 282 281 258 266 278 273 256 245 237 282 276 256 275 250 273 234 276 259 243 218 276 269 212 295 267 258 287 276 259 284 244 240 258 273 259 260 245 249 288 250 269 259 264 272 276 262 269 261 273 302 278 231 262 273 256 222 271 248 237 280 234 261 256 271 260 300 263 240 289 287 271 286 279 256 277 270 261 258 247 286 290 273 263 265 264 230 276 262 279 245 244 282 269 238 243 230 281 245 244 255 234 244 260 268 248 267 261 261 248 242 268 284 270 268 261 265 289 257 282 246 272 233 269 248 242 267 239 237 274 263 227 262 249 272 239 268 257 246 260 232 249 278 257 259 255 244 249 239 236 282 265 297 267 243 270 290 258 237 245 238 284 260 246 278 268 292 273 235 248 257 265 291 283 261 262 246 267 262 258 275 279 260 264 241 258 271 291 259 257 261 291 269 279 227 277 300 225 258 247 248 249 242 242 270 301 274 262 265 234 274 263 285 289 223 268 260 286 248 261 243 260 246 260 265 286 241 265 266 294 246 291 288 244 225 249 207 240 266 269 264 260 270 267 288 289 247 262 242 258 263 259 262 261 234 256 281 243 230 238 245 244 262 246 265 241 224 281 276 246 218 258 245 264 265 257 258 268 272 273 283 273 222 256 241 244 278 258 263 263 279 248 278 321 279 239 228 242 265 264 275 269 298 270 262 248 234 242 261 255 244 276 263 261 258 283 259 262 265 238 277 267 239 255 244 232 267 283 294 234 205 264 260 264 284 273 290 230 307 264 247 266 268 239 245 276 264 256 235 245 256 260 248 256 267 259 249 268 247 271 275 268 240 260 266 267 268 271 249 272 270 258 249 234 260 281 265 223 266 279 247 260 263 222 244 274 266 274 232 232 264 277 259 260 234 248 261 285 261 267 237 237 226 255 292 258 261 272 272 272 288 237 267 276 249 273 243 290 314 245 267 255 284 241 271 260 266 270 273 237 257 272 233 249 279 235 279 270 292 263 291 242 260 242 242 263 260 229 247 235 294 290 299 268 286 281 293 243 284 267 266 238 260 283 256 267 267 277 282 283 240 264 265 223 270 278 233 248 287 248 232 255 268 249 243 272 276 248 290 261 273 243 275 268 241 260 256 303 261 269 285 262 287 266 245 276 230 237 264 309 287 241 292 266 274 243 264 243 284 263 236 256 263 258 259 286 266 260 297 268 283 240 312 246 267 280 245 281 256 284 239 241 265 237 275 221 262 247 288 250 261 256 288 278 289 258 264 235 267 269 268 234 263 265 247 276 256 291 260 306 257 283 246 270 249 285 274 262 273 258 300 298 271 276 278 286 256 239 263 282 282 261 279 292 264 277 259 282 273 288 267 271 267 307 291 287 299 302 286 330 279 279 318 318 280 279 248 287 295 292 314 287 310 287 285 313 279 298 304 311 312 296 321 297 314 287 311 313 259 320 287 302 299 306 308 305 318 318 326 282 315 293 304 293 323 341 308 293 287 295 302 300 298 302 294 312 303 310 306 279 311 316 298 281 243 294 272 284 278 297 285 291 292 282 240 287 292 281 274 280 248 299 260 257 291 270 255 263 238 262 281 255 288 244 257 248 292 282 257 249 291 270 259 278 280 262 273 257 284 263 229 267 228 261 290 266 290 247 280 262 257 286 312 269 263 259 245 283 272 276 246 286 275 286 262 282 255 256 293 283 263 248 264 248 246 262 281 221 274 271 257 291 256 239 282 257 266 260 239 262 265 277 255 247 264 274 263 271 300 244 236 281 262 267 260 262 240 266 267 262 290 247 248 255 266 306 270 259 267 224 235 243 278 232 235 265 231 267 246 274 291 262 284 277 276 267 246 275 266 266 257 270 258 224 256 236 268 272 234 258 292 244 258 283 240 270 230 245 256 244 255 230 269 296 260 260 282 283 277 239 263 223 281 276 273 285 269 272 289 266 263 273 258 263 261 273 290 257 232 250 258 264 286 277 262 261 231 266 278 280 257 294 218 224 215 296 243 277 272 293 236 279 279 284 264 248 276 265 239 293 276 258 274 273 291 243 240 247 290 287 256 234 216 261 223 261 246 239 257 274 256 264 281 306 262 283 256 259 246 263 241 231 239 289 264 265 258 278 261 236 262 260 235 256 260 280 228 266 276 275 285 257 263 264 248 267 262 277 228 242 248 260 248 257 269 272 220 235 261 239 264 270 235 256 257 246 274 243 264 258 248 266 240 264 267 255 265 242 223 264 245 263 262 260 267 278 283 277 240 271 212 296 288 256 268 261 248 257 266 238 291 266 246 282 240 261 246 249 258 282 247 257 259 293 233 244 293 267 242 257 243 242 272 249 284 282 236 259 255 255 230 263 255 237 290 225 281 262 278 259 240 290 285 248 233 255 283 245 237 231 262 273 256 269 281 249 255 287 256 247 267 243 265 258 262 246 241 248 278 237 277 240 275 246 238 278 277 261 261 249 275 278 261 278 287 269 255 231 265 286 256 274 277 263 274 263 262 264 259 237 236 261 262 248 248 247 271 270 226 296 275 268 247 265 275 264 238 221 279 281 227 237 261 247 257 259 242 205 260 287 247 248 258 255 256 285 285 292 242 247 275 268 248 247 273 231 242 255 266 235 226 257 261 258 284 260 301 275 262 280 258 267 225 256 262 261 239 260 243 243 241 255 250 272 287 243 274 234 274 269 242 244 260 263 255 240 241 256 267 242 267 271 289 280 240 312 249 266 241 274 289 276 271 275 278 238 258 268 264 273 231 271 274 234 260 260 246 292 235 267 243 261 286 218 230 279 241 245 241 233 271 268 258 277 255 264 249 246 230 239 267 246 285 256 242 242 279 273 244 234 260 272 280 260 261 269 243 256 274 257 263 276 242 231 233 270 241 242 262 279 263 243 240 257 274 273 276 223 288 250 239 256 239 227 255 284 271 245 236 274 265 278 306 239 261 267 263 281 265 268 269 246 272 256 247 260 217 280 237 261 223 274 266 258 256 225 233 265 257 248 228 236 240 290 274 262 267 241 240 257 275 221 213 257 266 241 237 218 240 271 241 266 275 238 261 264 232 281 294 259 224 270 238 261 237 264 268 248 262 243 273 245 233 242 244 247 239 237 245 249 229 267 222 222 247 239 277 250 286 240 243 267 274 257 263 243 228 263 298 256 248 278 264 238 264 280 257 233 283 261 260 243 259 236 233 244 246 238 257 241 259 287 210 262 267 267 256 279 269 243 248 242 265 226 245 229 238 264 257 262 259 267 244 245 249 259 245 250 288 264 272 267 249 275 248 265 257 242 243 267 241 260 262 244 249 231 238 260 268 264 280 243 259 264 259 285 258 265 271 259 244 260 250 258 271 230 262 256 279 226 298 258 255 231 237 241 255 243 257 201 274 273 260 256 298 238 244 269 269 232 255 230 276 240 220 224 242 261 262 248 269 249 249 227 238 261 225 257 247 225 266 266 276 224 258 256 237 281 237 263 215 236 239 272 286 244 260 223 263 277 259 243 236 241 236 272 268 267 280 270 267 249 258 277 246 267 225 276 283 243 244 238 266 240 257 288 245 270 237 257 268 246 242 249 262 264 267 261 260 280 223 230 240 297 270 222 249 247 243 227 247 223 243 234 237 273 264 268 273 258 260 241 244 269 229 244 275 268 258 267 264 233 264 256 232 283 266 247 277 272 270 269 264 246 239 257 258 288 240 271 259 247 248 270 267 219 247 224 262 265 247 235 268 231 257 274 248 274 247 242 266 257 283 264 244 258 258 231 283 248 261 228 218 261 240 258 269 231 247 260 260 262 241 241 259 262 260 244 239 273 274 244 276 242 296 239 261 269 268 271 242 261 230 231 265 240 284 275 236 247 226 260 280 285 283 270 304 236 274 244 266 285 260 272 269 264 265 277 236 257 259 247 233 241 264 276 274 266 261 267 231 256 246 238 310 270 248 231 249 243 259 227 228 266 284 256 239 270 242 270 274 266 247 274 247 263 269 242 260 249 244 225 259 236 247 249 236 283 264 249 255 255 234 239 274 261 226 274 268 245 242 261 236 234 236 247 269 294 273 244 261 259 296 266 232 295 228 263 265 233 271 250 294 259 287 256 270 258 264 228 242 243 242 270 262 239 266 255 267 261 219 276 260 267 273 268 228 265 226 261 255 241 264 263 276 243 274 295 266 239 265 267 267 237 234 272 270 233 242 226 278 264 287 245 262 271 245 271 229 236 259 240 262 243 222 265 262 270 260 247 247 269 255 266 261 255 244 242 259 264 273 205 255 263 272 264 240 286 211 261 276 275 265 259 259 276 255 264 249 249 256 229 257 278 268 284 280 260 226 258 279 260 273 233 272 246 241 246 231 298 247 244 230 263 255 243 238 268 258 281 290 240 244 250 272 270 241 264 240 258 267 267 270 242 239 272 266 263 264 268 263 241 284 277 249 255 263 270 259 256 258 272 227 262 289 280 221 274 262 267 263 269 248 274 234 259 268 245 261 266 275 272 236 232 260 241 260 250 241 241 269 228 274 257 234 241 230 259 291 269 281 212 257 264 236 241 269 256 240 248 245 267 279 234 216 287 242 277 239 256 248 274 242 289 237 240 264 248 280 311 259 262 215 247 270 268 270 247 261 292 222 261 266 259 224 266 259 294 257 272 289 261 276 271 249 263 244 258 280 246 281 263 287 237 269 241 264 234 248 271 263 262 258 244 232 250 288 257 291 220 304 263 262 249 260 268 248 255 278 261 267 262 257 280 242 269 233 280 243 245 247 275 243 237 239 240 246 268 246 268 272 230 268 276 256 240 221 265 282 279 276 259 239 227 246 268 225 228 238 231 260 232 266 225 257 242 275 256 268 217 260 229 259 226 239 234 283 244 244 255 267 258 236 257 292 265 239 284 271 248 244 223 277 244 239 263 256 246 260 255 223 294 259 268 246 271 256 270 247 281 229 273 240 272 282 275 256 258 237 275 260 229 245 256 282 225 286 266 262 260 242 235 263 262 264 274 244 269 258 267 268 265 272 280 263 225 264 265 274 247 240 264 238 244 263 261 242 273 268 276 257 248 294 258 288 278 280 231 280 249 286 264 266 296 261 273 258 286 236 247 248 281 266 271 266 285 267 262 249 213 309 271 249 277 239 267 275 285 279 233 276 262 239 259 248 247 247 258 269 279 238 282 278 278 275 246 260 227 267 268 286 268 259 274 259 310 267 272 272 285 269 243 261 274 281 263 250 289 258 248 298 265 283 241 264 276 281 285 267 272 291 265 270 249 274 245 248 277 283 266 273 246 299 293 269 280 291 270 260 237 260 256 239 270 286 288 234 277 258 232 236 247 291 257 289 275 272 248 242 241 256 260 305 281 277 227 260 280 242 272 230 285 241 236 297 262 261 278 247 261 274 284 276 258 280 262 268 235 266 266 264 259 244 241 242 246 240 262 288 263 231 259 282 262 245 303 259 233 239 289 248 279 276 240 281 280 259 275 221 271 267 231 265 278 281 274 246 263 283 279 263 235 255 246 257 238 256 257 273 247 238 246 242 229 274 281 290 257 279 262 296 255 256 226 230 220 241 249 233 229 262 259 258 228 281 273 257 237 260 244 246 273 247 247 229 258 259 292 238 245 232 256 268 248 225 274 275 219 237 229 256 267 249 247 293 231 264 242 257 231 257 308 260 223 266 259 261 243 260 256 239 233 249 245 231 248 256 243 271 249 238 256 270 266 246 255 255 256 260 263 243 281 286 267 228 273 221 264 241 235 238 271 236 273 259 247 229 234 255 262 195 259 247 226 269 280 248 256 265 241 241 230 259 245 210 264 260 217 241 237 255 233 270 262 238 238 276 270 263 255 280 240 274 222 255 268 278 295 280 272 236 229 255 255 231 243 257 260 262 242 273 241 218 237 248 280 275 257 256 244 240 277 242 256 262 239 268 234 268 240 257 238 265 247 257 258 264 277 237 255 245 256 275 268 232 243 268 245 263 233 247 299 246 266 240 270 246 245 247 231 267 245 271 244 266 247 261 240 261 244 239 237 260 224 262 230 257 278 256 285 250 242 259 237 264 233 261 242 274 260 240 262 236 235 267 244 277 238 246 246 249 223 273 228 230 233 293 228 263 224 279 260 244 243 274 270 240 220 222 247 260 262 293 277 249 236 258 239 243 231 237 238 238 268 243 236 238 271 246 228 263 248 234 264 238 249 256 246 249 261 284 270 246 259 269 276 273 246 238 268 259 257 226 261 240 279 235 250 272 275 244 232 265 249 233 278 241 271 233 229 245 226 255 258 265 296 263 275 272 241 270 242 272 239 255 237 242 245 247 250 260 245 262 241 269 276 247 266 238 241 282 247 269 257 236 260 241 256 255 230 240 228 278 256 232 241 224 249 243 255 256 273 257 273 236 296 236 268 300 246 273 272 257 258 259 258 256 260 264 271 260 240 248 259 221 233 260 264 264 246 245 293 278 257 227 231 231 232 258 237 284 277 236 271 278 249 273 275 277 242 256 258 242 277 271 274 276 243 249 274 278 278 275 283 247 238 255 280 274 280 247 238 244 282 216 239 259 270 228 248 245 265 264 257 261 226 262 265 261 270 273 248 233 229 257 269 277 245 306 258 269 241 277 267 243 244 246 289 270 235 240 267 262 266 261 242 300 296 247 227 237 282 233 258 256 263 278 255 284 226 242 268 257 259 228 223 242 250 255 257 258 259 274 277 278 270 269 237 273 244 256 267 257 262 238 221 245 288 260 277 270 277 259 258 276 260 246 248 263 242 268 268 276 255 272 271 238 276 274 267 278 265 285 276 282 286 285 259 281 258 276 288 291 267 286 260 280 246 246 271 264 247 264 255 229 258 271 261 275 279 295 259 235 262 242 224 264 236 264 261 256 257 271 291 269 255 234 290 240 227 256 274 258 267 226 255 235 256 246 225 244 260 266 276 230 260 265 245 257 256 266 262 257 246 228 240 242 261 269 259 249 291 291 264 245 272 248 260 291 241 275 256 244 242 256 255 246 234 247 256 259 274 284 242 230 245 265 268 258 264 239 272 257 250 228 264 258 281 268 255 269 256 264 264 270 259 285 255 217 261 230 278 255 233 282 298 232 243 244 275 250 248 255 263 256 272 241 244 241 268 235 282 275 234 285 264 270 246 230 286 267 232 248 226 247 231 300 243 263 268 267 268 268 265 276 267 246 239 276 238 278 248 239 259 247 270 265 274 269 260 246 269 244 241 266 244 265 227 263 263 276 255 241 282 234 259 280 280 262 248 224 233 235 267 265 244 271 284 241 271 260 242 282 268 214 249 231 247 271 262 273 281 243 262 248 272 249 238 239 261 292 237 246 239 220 248 246 239 269 262 296 269 275 256 261 229 277 233 266 231 263 236 272 258 239 243 249 262 259 256 278 264 255 279 258 255 241 292 249 231 274 281 288 294 240 259 235 267 269 268 289 247 286 257 283 231 261 237 270 268 246 246 264 235 242 246 261 249 303 231 238 273 234 266 261 270 265 234 274 278 272 264 270 265 258 246 262 257 268 282 265 264 249 230 260 283 246 239 277 247 272 265 243 238 260 221 284 291 230 266 230 267 241 282 239 265 272 269 281 247 294 268 240 265 268 229 218 258 268 258 257 263 274 273 240 285 245 238 255 239 258 277 274 260 263 239 241 256 280 244 264 229 263 276 274 244 256 258 286 248 247 247 240 259 228 227 240 230 264 245 264 250 261 268 248 256 256 284 237 255 284 268 238 263 265 287 241 263 227 256 270 255 247 225 278 244 241 245 248 298 236 227 227 241 261 246 232 239 257 286 268 235 237 232 264 263 274 263 283 258 263 240 265 256 257 290 266 250 248 233 260 242 270 250 257 287 248 233 283 279 260 257 275 229 267 240 244 270 246 279 247 258 259 264 241 289 282 259 260 250 269 292 220 264 244 228 232 196 282 278 234 264 290 266 228 237 283 271 267 288 288 265 237 233 259 264 255 249 262 285 270 234 256 258 262 272 264 212 259 248 269 240 259 269 233 273 288 258 248 243 237 269 286 219 226 263 277 241 266 255 235 289 248 273 255 279 270 272 238 262 281 225 279 264 286 266 226 265 249 229 238 237 279 235 240 242 240 239 243 292 243 263 266 275 240 250 278 237 225 278 287 223 242 302 268 257 267 262 281 241 280 284 271 267 240 239 266 279 264 280 258 246 279 269 262 266 278 266 236 274 246 234 264 218 285 257 278 277 246 255 285 259 249 240 269 257 268 261 246 263 281 279 248 269 264 262 232 272 263 261 274 245 236 278 242 235 235 269 237 271 247 276 258 273 256 281 280 293 266 250 255 258 262 288 242 259 268 295 267 264 272 260 245 236 287 257 263 268 235 276 278 261 256 240 256 314 241 244 260 256 262 258 272 242 260 263 264 266 250 260 261 248 294 244 243 265 267 286 263 223 231 271 286 249 245 265 267 238 259 257 262 259 266 265 245 224 246 255 268 234 240 246 269 246 260 262 232 246 261 243 256 247 226 290 239 248 231 230 242 280 245 289 265 281 257 260 242 277 255 274 220 267 277 255 247 255 280 257 255 223 233 269 275 258 261 239 284 292 249 271 263 231 246 294 281 248 226 262 266 241 269 264 271 249 258 261 286 281 231 235 297 236 258 256 240 275 246 255 269 268 280 230 258 237 241 237 275 262 258 265 228 264 264 263 261 259 258 243 263 262 262 257 262 275 268 265 234 270 231 282 246 269 280 242 238 256 256 243 276 244 270 255 237 267 241 279 265 223 283 258 233 298 280 246 249 244 263 275 239 258 263 262 271 273 218 264 277 272 297 270 265 264 259 249 260 242 258 243 280 260 275 271 250 249 258 283 284 247 246 270 282 262 239 264 236 281 248 242 233 260 246 249 286 255 274 232 283 257 278 243 262 281 269 255 280 269 247 244 221 294 240 262 236 257 244 263 282 274 256 262 237 241 240 269 243 236 243 239 223 220 260 237 272 231 250 255 279 264 269 265 258 275 249 268 267 289 261 312 259 262 258 272 226 255 247 249 275 237 266 282 233 297 256 241 269 301 283 259 290 259 274 246 263 263 267 262 270 266 264 272 279 273 274 283 283 268 305 257 268 288 275 257 245 276 273 280 260 265 263 271 273 268 267 270 264 265 277 257 275 286 234 281 284 242 299 257 288 270 258 277 273 279 298 292 278 285 298 313 279 285 288 290 263 315 274 283 271 281 274 271 287 323 282 279 303 259 293 291 290 280 287 271 288 273 295 310 244 278 259 274 299 286 292 268 304 275 247 277 269 291 274 280 265 262 273 268 248 309 282 291 247 267 275 276 255 275 263 270 255 276 276 245 273 268 308 303 282 248 277 243 289 230 273 243 269 255 264 276 284 291 276 287 242 263 237 265 237 271 265 249 258 257 264 259 267 236 255 303 245 266 271 271 266 268 264 287 243 268 277 293 273 283 271 281 261 287 258 246 269 255 258 237 238 266 286 283 237 239 249 248 260 240 249 228 260 268 260 244 276 246 281 242 265 261 245 261 246 291 267 243 242 266 263 259 257 232 278 270 239 271 256 257 270 271 271 235 255 249 242 248 267 245 259 273 274 280 256 271 276 243 257 268 244 273 248 255 283 269 248 234 227 238 296 306 278 305 249 268 263 265 276 255 271 232 245 244 257 237 257 298 274 280 238 271 247 261 246 245 248 274 266 236 278 260 244 279 248 242 261 275 308 258 232 271 275 280 274 238 246 269 248 266 230 296 267 269 231 245 262 265 256 267 271 267 267 257 260 276 266 249 275 285 242 276 231 250 261 277 262 256 294 256 262 249 250 267 250 272 212 255 235 294 287 264 279 242 247 272 261 280 238 280 249 261 262 261 235 273 265 265 266 266 242 241 301 258 269 277 261 273 232 233 258 242 277 248 231 284 267 257 246 244 257 261 248 267 265 265 262 298 262 265 270 273 275 249 289 261 250 260 260 268 238 271 231 286 248 243 249 265 268 256 256 229 267 284 260 263 234 247 255 265 247 269 279 278 248 286 279 230 279 250 276 260 286 238 272 236 226 264 275 240 285 239 265 265 277 229 270 276 258 269 269 259 235 261 278 284 243 261 243 283 264 279 257 247 263 245 265 290 248 256 271 238 277 267 257 241 241 243 261 266 280 272 267 261 240 263 278 287 259 273 249 234 248 280 250 256 257 260 259 283 256 288 222 257 264 271 283 268 259 279 226 258 237 282 269 277 249 216 269 236 271 238 284 267 284 261 242 270 282 241 271 236 248 246 264 257 270 267 238 268 268 270 237 264 258 245 231 274 259 275 288 239 259 269 301 226 271 283 268 261 263 272 281 239 276 263 239 243 250 255 260 258 241 242 269 257 262 249 283 293 242 304 295 266 284 264 260 283 288 237 246 255 248 239 268 243 247 258 277 267 270 249 228 244 268 240 233 244 272 241 239 259 232 259 243 290 236 274 241 256 294 244 281 246 276 257 260 245 234 277 249 275 269 262 246 244 271 291 247 268 279 267 288 227 273 265 288 270 234 279 267 260 290 260 282 267 259 266 260 246 278 273 274 246 274 273 234 238 279 282 249 234 265 258 242 292 266 250 256 274 265 310 246 268 280 244 306 243 259 249 257 275 268 299 258 267 284 256 256 272 246 309 232 225 260 270 267 227 279 262 257 241 269 239 233 258 256 247 277 260 269 262 277 273 263 273 248 257 281 265 224 274 260 272 280 270 282 270 285 293 258 238 243 262 225 279 230 281 267 241 234 246 261 277 260 241 264 268 281 246 269 242 266 275 279 262 245 266 241 258 270 248 258 283 258 247 257 271 231 287 235 262 258 284 234 264 259 273 270 234 255 240 264 242 245 268 292 237 259 293 268 233 263 262 282 256 258 262 274 263 243 226 263 248 229 272 267 281 265 264 293 249 264 271 306 261 268 282 263 232 271 229 268 289 261 286 244 264 237 260 266 244 239 295 272 268 277 265 279 259 257 264 271 264 242 258 279 260 258 272 261 277 272 257 257 285 264 266 256 299 240 290 243 257 257 242 271 236 264 263 239 274 243 263 248 274 265 266 241 266 284 266 260 267 265 260 256 264 241 288 248 235 279 238 267 247 258 259 257 265 244 275 245 267 262 292 280 265 258 291 243 272 238 260 238 260 247 272 257 285 248 260 267 237 208 264 302 283 293 262 235 232 243 255 248 247 275 257 275 277 277 274 277 240 280 274 265 242 210 256 256 272 271 250 259 282 271 281 240 269 246 269 262 226 300 258 243 238 245 273 265 249 246 262 270 261 249 272 240 246 266 260 273 277 258 284 258 236 264 280 245 276 258 265 247 238 285 236 275 282 257 248 269 294 272 276 287 249 273 238 259 267 207 244 237 265 256 262 294 238 244 249 270 262 269 272 268 259 261 260 250 240 244 248 256 248 256 242 269 296 270 262 256 269 297 241 268 239 270 260 268 285 276 222 256 264 263 262 272 241 273 259 224 298 278 266 278 264 268 283 248 242 301 264 270 232 247 264 277 262 238 239 256 228 284 232 246 260 273 280 236 297 275 269 237 248 218 247 264 263 267 244 260 265 269 265 258 255 296 279 270 284 270 290 249 234 286 268 231 267 266 257 237 239 255 266 239 246 269 247 264 291 268 281 264 226 270 245 297 241 242 245 267 247 264 260 269 264 273 278 283 301 266 265 268 260 261 278 272 235 244 258 227 274 309 259 276 271 274 268 247 256 262 267 263 271 281 233 264 262 261 255 241 262 259 280 247 227 269 269 265 272 275 267 258 242 263 267 257 271 243 235 274 269 259 240 273 238 268 263 238 257 246 236 258 274 283 223 255 256 241 258 259 263 238 291 264 226 247 234 236 285 267 277 265 238 264 245 237 260 265 242 289 249 237 243 268 272 241 237 250 244 264 244 264 268 245 282 272 262 267 258 242 262 244 288 281 271 259 280 255 268 234 263 266 301 247 256 201 286 232 245 263 268 249 270 247 260 260 265 269 259 245 262 281 231 258 263 281 263 243 270 245 256 283 245 265 232 270 270 280 262 258 257 241 260 259 245 248 280 301 255 246 260 246 258 248 215 286 248 243 264 268 279 273 266 277 246 270 260 280 261 258 234 223 290 258 255 245 264 274 274 269 238 260 273 269 249 239 234 242 241 280 261 281 249 269 242 220 280 247 262 241 259 227 270 261 291 265 271 281 268 248 286 261 260 271 277 236 261 239 243 249 274 250 262 270 268 220 274 272 266 293 279 238 261 255 265 245 256 244 263 285 246 248 246 280 241 234 267 289 273 273 259 230 289 280 223 268 284 228 260 245 257 273 240 255 250 237 238 302 236 277 295 260 263 233 257 283 260 209 247 263 278 262 264 243 280 266 244 264 240 289 266 263 273 273 239 258 276 283 277 266 266 241 280 246 246 291 300 247 265</counts>
			</dataPoints>
		</scan>
	</xrdMeasurement>
</xrdMeasurements>