File: data/XRD/_misc/old/XG-600C/_absolute_2th-om_10-130deg_PIXscan_56min_4.xrdml
<xrdMeasurements xmlns="http://www.xrdml.com/XRDMeasurement/2.1" xmlns:xsi="http://www.w3.org/2001/XMLSchema-instance" xsi:schemaLocation="http://www.xrdml.com/XRDMeasurement/2.1 http://www.xrdml.com/XRDMeasurement/2.1/XRDMeasurement.xsd" status="Completed">
	<comment>
		<entry>Configuration=Factory configuration, Owner=User-1, Creation date=7/8/2013 4:01:53 PM</entry>
		<entry>Goniometer=PW3050/65 (Theta/2Theta); Minimum step size 2Theta:0.0001; Minimum step size Omega:0.0001</entry>
		<entry>Sample stage=MRD Cradle; Minimum step size Phi:0.01; Minimum step size Chi:0.01; Minimum step size X:0.01; Minimum step size Y:0.01; Minimum step size Z:0.001</entry>
		<entry>Diffractometer system=XPERT-PRO</entry>
		<entry>Measurement program=C:\PANalytical\Data Collector\Programs\Jorrit\2thom\_absolute_2th-om_10-130deg_PIXscan_56min.xrdmp, Identifier={15BCCF57-2807-42BD-B5B9-ECC0B3DC9284}</entry>
		<entry>Batch program=C:\PANalytical\Data Collector\Programs\SimonL\batch4x_2thom_10-130°_z9.1_x0,10,20,30_y0_57min.xrdmp, Identifier={EED9823A-2BEB-424C-9252-345C4EF2834A}</entry>
	</comment>
	<sample type="To be analyzed">
		<id></id>
		<name></name>
		<preparedBy></preparedBy>
	</sample>
	<xrdMeasurement measurementType="Scan" status="Completed" sampleMode="Reflection">
		<comment>
			<entry>_absolute_2th-om_10-130deg_PIXscan_56min</entry>
			<entry>PHD Lower Level = 4.83 (keV), PHD Upper Level = 11.27 (keV)</entry>
		</comment>
		<usedWavelength intended="K-Alpha 1">
			<kAlpha1 unit="Angstrom">1.5405980</kAlpha1>
			<kAlpha2 unit="Angstrom">1.5444260</kAlpha2>
			<kBeta unit="Angstrom">1.3922500</kBeta>
			<ratioKAlpha2KAlpha1>0.5000</ratioKAlpha2KAlpha1>
		</usedWavelength>
		<incidentBeamPath>
			<radius unit="mm">320.00</radius>
			<xRayTube id="1010048" name="Empyrean Cu LFF HR (9430 033 7310x) DK442154">
				<tension unit="kV">40.0</tension>
				<current unit="mA">40.0</current>
				<anodeMaterial>Cu</anodeMaterial>
				<focus type="Line">
					<length unit="mm">12.0</length>
					<width unit="mm">0.4</width>
					<takeOffAngle unit="deg">4.2</takeOffAngle>
				</focus>
			</xRayTube>
			<xRayMirror id="27010001" name="Inc. Beam Cu W/Si (parabolic MRD)" hybrid="false">
				<crystal type="Graded" shape="Parabolic">W/Si</crystal>
				<acceptanceAngle unit="deg">0.800</acceptanceAngle>
				<length unit="mm">60.0</length>
			</xRayMirror>
			<sollerSlit id="21010002" name="Soller slits 0.04 rad.">
				<opening unit="rad">0.0400</opening>
			</sollerSlit>
			<mask id="22030007" name="Fixed mask 2 mm">
				<distanceToSample unit="mm">220.00</distanceToSample>
				<width unit="mm">2.00</width>
			</mask>
			<divergenceSlit id="22010007" name="Fixed slit 1/8°" xsi:type="fixedDivergenceSlitType">
				<distanceToSample unit="mm">220.00</distanceToSample>
				<height unit="mm">0.19</height>
			</divergenceSlit>
		</incidentBeamPath>
		<diffractedBeamPath>
			<radius unit="mm">320.00</radius>
			<sollerSlit id="21010002" name="Soller slits 0.04 rad.">
				<opening unit="rad">0.0400</opening>
			</sollerSlit>
			<receivingSlit id="22010001" name="Fixed slit 4°">
				<height unit="mm">5.88</height>
			</receivingSlit>
			<detector id="7010017" name="PIXcel3D 1x1 detector" xsi:type="areaDetectorType">
				<phd unit="%">
					<lowerLevel>30.0</lowerLevel>
					<upperLevel>70.0</upperLevel>
				</phd>
				<mode>Scanning</mode>
				<activeChannelsEquatorial>255</activeChannelsEquatorial>
				<activeChannelsAxial>255</activeChannelsAxial>
				<pitchEquatorial unit="mm">0.05500</pitchEquatorial>
				<pitchAxial unit="mm">0.05500</pitchAxial>
				<readOutPeriod unit="seconds">0.135</readOutPeriod>
			</detector>
		</diffractedBeamPath>
		<scan appendNumber="0" mode="Continuous" scanAxis="2Theta-Omega" status="Completed">
			<header>
				<startTimeStamp>2024-08-27T18:43:10+02:00</startTimeStamp>
				<endTimeStamp>2024-08-27T19:39:17+02:00</endTimeStamp>
				<author>
					<name>PRO-MRD</name>
				</author>
				<source>
					<applicationSoftware version="6.1b">Data Collector</applicationSoftware>
					<instrumentControlSoftware version="7.0E 20130304">XPERT-PRO</instrumentControlSoftware>
					<instrumentID>0000000011142674</instrumentID>
				</source>
			</header>
			<dataPoints>
				<positions axis="2Theta" unit="deg">
					<startPosition>9.99826193</startPosition>
					<endPosition>129.99755682</endPosition>
				</positions>
				<positions axis="Omega" unit="deg">
					<startPosition>4.99913096</startPosition>
					<endPosition>64.99877841</endPosition>
				</positions>
				<positions axis="Phi" unit="deg">
					<commonPosition>0.00</commonPosition>
				</positions>
				<positions axis="Chi" unit="deg">
					<commonPosition>0.00</commonPosition>
				</positions>
				<positions axis="X" unit="mm">
					<commonPosition>30.00</commonPosition>
				</positions>
				<positions axis="Y" unit="mm">
					<commonPosition>0.00</commonPosition>
				</positions>
				<positions axis="Z" unit="mm">
					<commonPosition>9.100</commonPosition>
				</positions>
				<commonCountingTime unit="seconds">32.895</commonCountingTime>
				<counts 215 227 220 216 204 182 201 223 201 231 198 209 211 197 209 204 232 200 200 196 226 213 237 227 200 206 185 210 226 206 206 214 180 190 225 198 235 207 200 212 207 214 204 228 255 224 231 241 224 241 232 232 209 240 225 220 203 243 209 209 202 206 221 197 245 219 204 227 204 224 200 179 214 213 210 221 213 218 228 224 189 226 196 202 196 216 190 233 210 212 196 171 216 203 219 212 223 189 200 205 210 192 205 203 214 224 213 199 186 210 214 212 215 221 206 194 186 187 218 223 194 191 203 208 188 187 205 202 196 212 181 183 198 173 195 204 205 200 203 196 210 179 190 220 209 205 181 212 200 192 218 182 216 188 198 189 197 199 209 204 195 200 196 184 184 207 202 189 195 242 214 176 198 211 186 193 204 207 162 196 198 200 205 180 184 200 199 191 198 190 210 201 208 184 189 169 211 189 207 213 187 184 202 190 196 183 197 202 180 204 194 214 193 190 180 187 184 206 215 184 179 180 198 183 189 174 187 186 177 191 183 209 189 197 213 205 182 228 198 190 199 184 189 177 176 171 168 198 182 218 180 205 202 198 156 204 207 182 204 184 196 199 198 208 203 210 191 186 187 211 173 198 220 186 193 166 174 201 179 173 208 195 185 204 219 194 184 199 205 195 192 195 200 189 186 193 199 183 195 195 192 177 196 176 183 183 193 198 192 187 161 179 208 197 165 173 181 182 189 172 188 188 202 147 195 194 194 185 195 193 186 177 197 179 155 187 203 194 194 188 165 195 183 170 192 187 195 184 179 176 175 192 181 186 179 168 178 179 197 174 162 174 187 192 181 166 175 157 167 188 202 214 171 176 174 185 175 163 183 178 196 201 174 160 165 180 207 185 178 186 176 191 168 168 191 165 163 181 196 174 183 175 169 169 168 173 181 176 191 186 166 192 164 173 189 190 164 202 151 163 176 170 165 188 158 174 171 181 179 187 183 189 157 191 164 175 196 178 163 171 189 201 170 168 183 171 203 151 200 162 170 176 163 175 175 177 169 179 170 172 173 176 187 139 175 153 189 188 187 195 167 173 167 166 174 160 179 184 167 172 175 153 170 155 156 173 174 183 172 203 188 174 182 167 174 166 159 178 162 167 179 173 168 183 154 185 169 166 175 169 140 167 169 143 159 163 189 189 158 152 188 171 165 162 157 171 169 185 163 159 168 162 177 140 172 165 163 162 160 153 158 148 157 161 157 143 164 161 168 173 142 140 183 180 157 164 180 185 186 160 169 171 178 163 165 183 163 174 165 182 147 174 151 176 177 144 187 170 174 164 182 172 153 185 196 152 172 176 164 160 154 154 171 167 166 160 165 164 154 151 171 149 192 141 162 167 158 167 175 159 166 150 153 165 175 191 160 159 182 166 172 151 162 165 179 168 195 167 165 151 154 173 151 179 180 141 133 163 189 159 182 149 167 182 167 160 149 145 154 164 169 175 162 179 158 181 165 142 163 151 172 166 141 155 168 162 163 172 161 157 158 148 167 159 187 132 179 177 183 157 191 166 155 154 158 152 164 157 143 150 150 157 165 156 173 169 158 165 154 143 163 160 218 169 192 173 174 167 180 153 177 135 175 161 166 159 160 154 169 148 151 164 142 161 163 155 197 173 171 152 160 148 187 175 147 163 173 165 176 135 145 151 163 174 181 176 157 150 175 187 167 166 165 155 162 145 170 163 143 165 162 168 150 178 173 167 182 167 155 157 164 172 164 165 132 185 161 160 175 148 170 167 171 153 167 174 154 142 152 154 138 186 191 150 161 166 185 166 170 165 168 172 171 164 168 172 167 152 183 173 155 157 157 172 170 172 173 159 146 155 161 160 162 125 161 154 186 184 198 167 178 152 167 179 167 173 154 146 153 182 167 157 174 145 138 148 168 167 193 143 169 188 154 165 163 150 152 171 166 184 175 139 183 139 183 171 159 152 171 170 183 164 171 174 165 160 156 168 160 157 176 160 169 178 134 160 155 142 152 172 171 144 161 177 179 165 172 165 155 167 184 207 178 193 191 179 171 173 177 180 168 177 141 148 160 174 159 170 158 162 147 182 180 164 182 163 167 146 169 167 163 155 158 180 150 153 153 177 177 182 174 182 198 184 183 182 169 178 160 154 196 166 179 156 162 184 166 169 161 155 174 186 164 172 169 146 186 171 179 165 174 145 146 165 140 159 167 157 169 159 164 170 174 170 168 195 145 162 166 168 164 173 168 153 160 193 167 156 173 161 149 180 156 161 167 168 156 158 142 153 151 173 173 154 159 167 161 165 165 181 156 175 167 178 161 176 165 162 177 143 176 172 187 171 179 141 148 188 162 173 189 187 161 186 165 158 186 180 171 182 178 170 177 171 172 187 171 182 161 173 172 168 143 151 189 176 191 147 165 153 165 172 175 154 170 154 177 181 159 178 189 161 181 161 168 169 164 157 168 183 152 163 169 163 152 167 186 185 158 175 171 169 176 156 163 181 180 162 167 188 158 162 185 185 180 187 169 172 177 156 162 178 170 178 176 174 188 187 159 178 189 191 152 178 187 152 183 169 149 169 169 172 177 179 158 174 174 192 176 166 174 157 169 184 169 170 142 173 176 220 190 184 181 150 170 172 167 192 158 198 168 150 191 193 169 183 158 180 186 169 155 182 163 174 200 159 184 170 170 197 166 146 172 173 170 196 155 158 198 181 164 163 164 170 155 194 205 165 196 176 185 179 170 169 193 161 172 176 180 181 182 184 166 190 192 180 183 189 161 165 182 185 156 180 194 190 189 162 186 175 147 156 190 177 173 181 176 161 172 175 151 170 156 163 167 155 151 166 172 174 189 161 162 167 163 163 172 178 187 164 183 184 176 174 175 159 169 179 162 173 163 161 167 180 174 191 191 159 178 164 171 169 177 186 176 180 168 179 187 182 155 142 178 161 157 181 166 162 147 160 162 167 154 143 166 169 173 157 168 177 150 180 182 174 184 185 159 166 167 178 158 188 194 204 179 168 164 160 160 172 170 184 188 141 173 172 172 163 167 185 185 171 160 178 175 160 146 201 157 160 154 188 134 158 164 145 154 162 169 153 166 140 146 177 161 182 169 176 169 165 156 182 162 164 150 187 160 202 188 177 153 152 181 146 158 177 149 133 171 155 144 155 143 175 181 169 158 152 184 168 160 169 147 180 159 166 171 159 153 187 178 160 172 166 154 164 165 187 165 158 144 151 157 170 157 186 152 154 173 151 147 192 149 139 157 171 149 157 170 166 151 187 174 162 163 153 171 176 156 157 171 143 151 174 145 158 158 154 163 183 175 158 161 150 174 161 145 145 169 176 143 173 149 173 158 163 177 176 179 152 149 158 183 156 165 179 172 158 139 174 138 190 168 154 180 179 165 150 151 152 137 158 136 163 147 150 161 161 151 161 156 153 173 150 176 167 188 170 157 147 150 172 152 167 163 156 164 159 195 163 154 170 149 176 160 169 171 149 164 150 174 159 175 159 168 181 135 156 153 153 155 141 152 144 156 168 184 147 142 143 165 162 164 157 163 151 161 144 180 163 169 150 167 160 168 156 174 164 155 168 168 160 166 174 153 161 158 156 134 164 161 170 171 150 180 156 140 150 152 141 121 148 149 151 147 152 155 145 159 153 141 153 162 157 164 178 144 150 142 170 166 162 132 152 155 153 141 180 143 148 173 146 144 163 163 161 146 169 152 158 129 161 149 145 168 153 139 169 148 158 134 147 152 138 151 169 126 140 161 155 148 130 132 140 147 146 159 154 144 157 151 149 152 156 144 154 152 149 157 138 159 154 162 144 141 138 157 150 154 153 164 156 151 147 154 136 158 148 147 137 149 162 157 171 135 148 149 173 127 131 150 131 164 155 154 149 141 147 168 148 155 147 145 163 149 162 138 139 157 172 148 123 136 158 132 156 139 148 143 148 165 179 159 132 158 143 168 152 156 139 147 162 133 136 140 152 140 151 152 147 129 149 149 127 162 137 146 137 126 136 138 137 154 145 153 149 135 148 144 147 111 160 130 150 141 152 166 164 152 136 143 147 145 133 156 151 134 144 145 135 153 145 148 155 129 139 151 115 146 150 122 154 131 147 139 160 134 125 159 128 124 132 143 134 132 152 123 137 150 142 145 143 134 137 147 153 130 160 140 138 133 138 154 136 149 126 122 134 155 128 166 138 112 135 116 131 149 132 160 120 161 161 141 145 136 128 138 118 152 145 144 134 107 140 141 121 145 156 158 135 148 147 157 114 139 157 124 157 133 138 140 135 137 124 146 129 134 133 142 131 145 135 130 133 105 130 143 145 126 116 120 136 131 133 127 142 128 138 145 133 136 124 154 150 142 149 131 141 122 139 113 133 133 139 118 148 139 138 144 169 133 159 124 142 125 119 135 124 139 125 128 132 117 129 124 121 124 131 140 105 136 128 149 136 147 163 136 140 117 143 129 159 131 127 117 149 128 128 133 149 121 115 155 153 131 143 140 135 125 139 131 135 121 148 124 143 135 140 128 134 125 118 126 107 107 123 141 155 120 148 138 128 138 128 117 111 111 135 142 145 142 137 148 137 135 115 129 115 151 123 136 144 127 130 128 134 126 127 145 118 120 134 134 106 123 151 103 139 122 125 129 117 134 134 114 147 119 133 126 106 132 157 139 112 121 130 121 130 151 123 119 108 131 132 149 140 122 115 128 135 133 135 147 151 109 136 131 132 141 132 120 115 147 130 127 145 124 125 136 147 144 138 118 120 125 139 133 133 125 134 134 128 130 136 132 150 118 109 115 120 129 116 133 126 121 128 120 127 137 137 129 136 138 126 121 122 139 127 153 121 129 123 111 125 102 118 135 150 131 120 120 136 140 142 151 111 135 133 140 118 127 113 111 124 128 124 125 114 112 116 136 127 151 114 146 141 131 135 132 149 138 127 129 142 140 119 119 129 122 131 104 110 113 134 118 135 151 125 133 120 83 137 130 133 143 135 125 136 134 132 117 132 118 106 138 129 122 115 118 119 141 108 141 141 143 127 127 127 135 154 124 106 114 110 112 113 136 137 137 145 126 136 101 136 120 116 112 102 104 121 135 123 112 138 123 125 127 122 117 140 123 118 122 144 97 125 125 137 125 141 114 110 132 123 127 104 136 134 132 107 126 108 128 125 126 115 111 123 124 114 115 124 101 126 130 122 134 130 124 131 115 111 109 123 128 119 118 96 127 110 119 126 120 117 122 107 110 135 118 128 119 109 128 142 131 118 128 129 119 114 124 109 125 126 109 110 130 118 113 106 96 142 118 112 109 116 142 118 121 123 106 127 124 109 116 118 138 134 131 109 138 142 136 116 136 110 120 111 131 126 135 119 110 125 120 112 134 105 128 126 126 107 104 132 106 132 124 111 111 128 116 139 110 113 122 128 113 126 120 114 137 113 131 113 110 121 106 109 125 104 112 130 119 113 123 117 116 128 131 115 101 128 114 127 122 124 114 120 103 111 113 113 125 104 135 115 120 125 130 107 140 117 124 128 129 116 120 123 95 128 101 113 100 107 106 113 105 123 126 104 113 124 117 117 133 109 142 118 127 106 101 113 120 129 112 123 103 116 120 129 132 98 129 102 108 114 125 108 112 114 117 107 134 136 119 125 128 113 120 127 120 125 114 124 137 119 107 107 119 118 100 113 130 117 114 108 112 120 121 81 120 122 119 137 107 128 119 135 106 105 105 119 106 128 117 106 114 128 112 106 113 116 119 110 132 103 126 110 111 115 127 104 118 121 123 122 106 113 116 121 102 147 141 107 124 117 105 129 142 106 131 112 128 117 126 111 126 122 104 107 119 113 113 109 118 110 125 115 119 116 113 97 105 105 104 119 106 106 116 111 114 115 135 112 111 110 129 130 105 110 123 113 120 113 120 128 115 134 118 142 107 113 115 127 106 117 114 116 118 120 124 116 113 132 110 132 102 115 123 119 103 114 133 112 106 105 115 125 131 115 123 125 120 101 124 116 117 131 116 126 124 122 121 112 120 122 119 137 122 96 109 126 135 112 118 120 119 133 118 107 108 125 123 110 113 104 107 115 120 112 113 104 89 116 113 115 110 133 120 114 101 110 116 139 109 106 116 121 113 125 117 134 111 116 125 116 133 112 110 109 142 103 123 105 128 130 108 121 118 92 128 111 117 118 103 113 110 126 112 128 113 108 114 117 107 126 112 116 117 120 109 112 117 112 116 125 126 111 112 120 106 129 123 127 107 106 126 138 107 118 135 131 123 117 122 121 122 121 121 106 111 121 114 109 126 121 113 132 138 101 113 121 131 108 133 126 118 121 130 108 100 111 113 118 122 127 116 111 114 124 115 125 108 111 110 123 120 101 113 108 107 119 106 127 104 137 111 124 117 117 119 113 119 108 120 116 118 122 117 121 123 128 112 128 129 131 122 137 115 121 108 101 106 104 128 138 125 117 118 120 118 120 109 122 116 134 121 113 132 109 133 98 96 108 109 126 121 131 108 136 110 130 102 118 107 94 109 122 103 110 125 106 123 106 115 115 118 124 116 120 117 110 102 104 132 138 106 104 111 103 122 129 102 115 119 109 115 129 102 92 113 116 127 93 116 127 111 102 126 101 107 107 131 134 106 130 132 125 108 106 105 107 113 107 128 134 112 115 106 101 99 106 120 110 148 114 107 119 118 135 131 106 111 114 100 123 119 127 102 108 90 110 133 113 116 133 118 120 101 116 109 110 135 106 100 122 118 116 108 140 129 95 121 102 110 120 128 124 125 109 125 131 107 114 112 126 114 114 115 110 124 118 134 99 116 111 113 102 116 126 117 128 114 93 109 106 103 124 116 123 115 109 114 103 115 111 120 107 106 125 127 99 106 126 107 101 135 116 132 122 133 104 124 127 120 120 116 125 107 141 109 109 121 113 120 94 122 118 99 123 94 104 106 108 91 127 101 118 98 97 123 106 127 137 137 120 129 117 134 113 126 109 103 108 114 109 124 110 124 129 117 135 104 130 120 119 117 111 119 124 103 118 131 121 105 81 108 103 137 127 125 101 105 130 116 129 100 136 108 106 117 114 124 124 119 96 107 112 114 121 123 116 134 134 122 103 117 105 120 117 118 114 113 143 118 118 134 120 129 126 115 120 117 118 123 127 117 114 126 114 128 105 122 129 134 100 127 131 122 100 111 114 117 111 126 124 108 131 114 100 106 119 124 131 126 107 124 114 111 116 129 107 101 93 102 125 136 110 122 95 125 108 122 105 112 137 142 147 135 129 99 118 112 125 111 129 132 128 138 119 142 104 106 104 99 122 129 130 118 104 119 119 125 131 109 117 117 105 127 103 118 108 113 126 119 116 111 128 118 88 113 98 119 115 136 118 95 109 115 120 121 122 111 146 138 132 104 119 124 117 141 125 132 130 140 126 119 114 102 96 133 125 114 123 129 119 110 101 112 112 118 119 119 116 109 116 107 128 126 121 130 109 114 127 129 113 96 125 122 120 115 121 107 126 118 113 127 152 124 124 117 111 114 113 112 110 111 121 129 112 115 114 137 112 123 122 124 107 115 129 118 107 116 112 141 95 118 114 117 111 127 120 125 126 136 122 112 109 117 111 109 112 112 138 125 124 110 119 131 116 122 131 124 127 126 106 125 123 144 126 153 120 133 136 132 123 128 138 124 139 138 133 129 125 137 128 130 133 132 138 133 151 117 142 151 127 131 145 114 133 133 141 138 117 130 130 139 144 142 133 162 123 142 115 138 142 144 146 143 140 134 127 145 131 167 154 155 142 160 172 143 142 147 163 160 179 184 172 182 173 165 191 190 149 202 199 193 207 210 221 229 255 194 211 213 261 226 235 240 223 221 234 228 228 196 206 195 192 216 181 188 199 192 173 203 190 187 181 180 158 185 166 181 145 155 150 173 128 140 128 144 129 144 137 157 154 151 136 143 126 165 126 152 131 135 124 146 133 165 120 128 127 107 145 130 117 126 108 122 108 121 129 127 135 134 114 136 142 121 127 133 119 141 105 123 143 113 123 103 134 119 148 129 119 112 117 124 121 129 127 131 120 116 130 107 121 131 133 127 139 118 138 138 122 121 117 143 137 138 100 120 123 120 103 126 131 127 125 111 139 124 116 116 118 99 135 126 130 133 137 127 134 133 124 146 137 122 117 127 107 136 129 109 107 130 151 120 123 125 124 129 120 136 121 118 133 114 131 114 116 132 126 134 124 111 121 137 140 131 129 125 137 121 108 119 121 122 128 119 134 116 129 135 144 111 127 111 99 133 117 134 132 144 116 120 130 135 111 128 157 122 147 126 127 129 115 123 126 130 141 128 136 133 117 116 130 110 109 117 130 118 119 135 119 127 120 126 114 122 120 123 121 128 102 121 108 125 126 132 136 119 131 128 136 138 125 117 108 145 131 111 117 157 113 115 116 123 115 133 127 111 113 122 121 134 117 128 134 116 117 134 136 124 106 134 125 114 130 117 131 116 118 117 130 118 114 127 122 121 118 121 123 131 132 115 123 129 102 121 132 138 126 146 123 132 127 142 114 118 115 139 134 118 140 135 138 104 131 144 129 113 132 129 133 108 125 124 136 133 136 109 120 115 103 107 135 129 114 127 117 125 131 124 146 123 121 107 120 112 109 120 141 121 138 125 117 124 116 123 123 117 124 120 107 114 135 117 116 144 110 111 137 132 130 123 119 121 128 132 122 127 139 130 117 123 125 122 134 97 142 114 123 131 134 142 134 119 124 119 128 116 140 163 116 127 138 135 136 113 120 140 114 123 116 114 107 115 109 137 107 117 145 124 147 111 135 118 117 141 116 135 112 120 126 119 144 121 130 123 130 106 127 136 115 128 124 118 130 126 116 138 122 125 110 112 106 141 127 124 111 118 132 120 127 103 105 130 119 115 117 129 117 130 106 126 135 114 123 136 118 133 125 131 126 131 119 132 117 104 100 122 123 108 123 113 115 123 127 132 119 139 110 126 123 116 130 104 116 132 133 135 107 124 126 119 118 111 144 131 110 113 135 109 131 154 130 123 135 116 126 143 144 114 119 133 108 111 118 119 127 129 123 126 131 127 117 116 139 139 129 116 122 122 100 111 143 134 134 122 115 127 134 117 121 108 125 140 130 117 123 140 110 134 125 123 109 131 102 109 128 126 133 111 121 127 137 121 140 135 129 112 126 133 118 125 117 107 114 113 134 118 129 107 136 129 103 121 134 129 132 108 120 116 122 138 127 122 122 123 111 125 104 123 142 123 114 144 132 126 114 129 125 117 132 125 120 109 104 106 131 132 118 107 136 121 131 102 111 105 119 122 137 120 138 145 145 135 123 120 114 124 127 120 121 119 137 103 131 139 127 118 132 128 114 121 117 124 116 119 113 131 127 115 136 123 115 119 130 116 117 137 136 131 113 132 125 123 136 135 112 126 121 150 122 118 132 125 110 145 136 136 130 117 116 120 128 130 124 124 122 147 124 126 120 133 134 135 143 132 128 112 111 129 113 143 133 129 112 132 122 138 136 114 122 122 131 135 126 115 129 133 123 122 151 115 146 109 128 109 128 115 137 120 122 123 116 132 108 149 114 128 124 123 155 113 109 104 111 131 113 134 125 129 137 118 129 114 144 132 115 123 139 124 125 135 135 133 122 100 122 116 104 131 127 134 132 118 131 136 139 126 117 111 129 120 117 132 132 130 125 123 124 112 118 134 130 124 95 111 121 138 128 111 114 124 123 129 125 129 133 145 127 95 109 131 116 119 124 117 134 133 109 129 138 121 134 131 139 133 140 143 144 156 154 125 109 126 130 109 133 113 119 106 129 126 134 126 139 128 112 115 139 115 113 108 128 139 129 119 139 126 140 123 114 128 131 118 124 126 125 126 100 137 130 140 126 144 139 114 113 129 127 130 113 127 144 139 131 126 121 122 118 147 151 141 115 121 137 108 118 132 139 148 114 115 127 127 102 120 118 118 125 143 136 151 91 116 129 128 116 108 119 157 148 136 128 143 124 145 127 124 126 131 102 134 111 145 128 114 110 128 120 125 126 112 133 150 125 122 118 133 104 126 150 133 116 123 123 122 136 141 113 115 126 113 146 134 135 126 114 139 119 123 133 122 118 140 136 151 130 126 117 126 128 146 129 135 144 129 120 130 123 138 127 118 114 130 160 128 142 121 118 110 124 124 115 128 132 131 114 130 120 131 143 115 128 113 113 104 142 141 135 115 117 136 137 122 136 136 106 140 129 143 145 112 125 129 116 130 112 110 128 120 119 143 115 122 126 141 111 124 117 136 91 110 111 137 130 113 152 137 129 122 143 136 123 137 138 154 127 127 129 116 119 118 127 163 127 130 124 125 128 136 145 144 127 112 124 130 112 122 150 99 113 126 127 138 122 125 138 128 117 122 142 137 139 128 131 126 142 120 142 143 123 146 135 137 105 139 112 145 133 134 114 108 128 134 126 138 115 118 139 131 142 131 115 131 118 144 124 128 149 129 119 132 127 153 138 114 121 131 125 120 142 124 143 117 127 129 111 122 136 130 102 140 156 121 111 131 145 117 110 137 136 124 121 148 128 132 126 126 137 122 117 132 119 131 149 133 127 105 117 145 116 127 124 128 119 131 129 121 118 120 151 151 128 112 128 124 127 117 131 112 126 147 143 128 135 144 139 133 145 138 126 140 127 110 135 151 145 126 115 130 136 137 123 133 143 139 118 120 148 127 126 116 128 114 138 134 143 165 118 139 122 136 151 157 125 123 138 129 153 128 150 136 125 134 137 116 136 115 116 113 108 126 138 113 111 133 129 110 113 145 132 129 130 141 110 129 136 144 124 145 146 132 128 150 132 137 124 155 138 138 132 129 137 144 142 127 130 149 133 150 121 123 132 153 115 146 132 114 144 127 140 117 127 129 118 121 121 123 115 123 122 143 118 130 130 130 138 127 134 136 142 116 115 153 152 109 147 146 135 143 141 104 107 113 128 126 144 138 114 143 108 117 128 123 132 136 116 131 120 125 141 139 140 146 113 115 130 160 127 107 116 130 125 143 122 102 126 135 132 123 138 125 138 129 138 133 138 133 126 119 133 129 126 139 156 128 124 128 130 144 141 139 123 142 116 142 135 134 143 128 130 124 155 123 156 111 138 118 144 129 135 141 130 139 133 144 140 130 123 121 141 107 139 138 138 129 153 112 135 117 133 125 169 141 121 131 138 120 147 136 120 137 131 149 142 140 122 156 145 130 133 143 126 139 151 154 129 122 127 132 132 124 148 132 142 124 122 148 134 137 124 129 140 127 138 128 119 131 134 139 127 146 140 144 157 149 112 136 145 146 145 129 136 127 146 120 138 135 146 122 133 138 136 141 149 132 145 133 138 129 129 130 120 118 144 142 146 140 109 122 130 140 133 125 133 133 149 120 121 144 126 129 133 139 149 120 134 138 135 114 114 136 138 122 122 131 111 160 146 139 130 128 146 130 136 148 129 121 125 120 125 138 130 135 148 117 118 147 130 147 153 129 134 128 145 128 125 137 143 137 115 130 135 112 130 118 133 142 136 117 132 155 138 140 123 150 126 119 143 144 145 122 128 166 109 126 137 149 126 146 118 127 136 141 120 135 133 126 147 124 122 115 117 129 147 146 135 139 124 127 122 134 113 124 136 122 134 130 138 128 133 149 144 148 134 131 143 134 108 132 143 138 123 125 110 144 145 123 140 149 147 113 133 133 129 144 127 141 156 137 139 135 135 124 118 149 110 141 133 154 135 127 130 145 135 139 154 137 136 124 127 110 160 128 178 144 147 137 135 136 131 121 141 140 127 148 143 130 130 126 137 153 130 134 133 123 139 144 144 125 129 146 124 132 124 123 141 157 127 135 131 119 135 138 149 128 146 139 137 107 126 115 113 132 113 140 140 156 121 123 97 150 119 126 151 118 120 143 132 128 100 133 143 138 133 115 121 131 146 115 111 138 139 133 134 148 131 143 146 136 137 155 131 126 143 136 113 128 158 141 123 149 137 131 177 138 126 122 129 116 139 133 156 132 149 120 121 135 121 150 147 144 129 123 133 134 117 155 145 124 128 129 144 140 133 126 159 135 140 124 126 144 159 141 123 150 136 128 123 121 131 151 144 130 140 143 144 151 125 134 139 147 124 120 129 144 133 148 149 131 148 105 148 131 135 139 129 134 130 127 131 146 122 124 157 120 116 124 140 129 143 139 149 132 131 141 138 128 123 134 149 139 152 148 141 115 156 122 132 152 128 151 126 146 130 150 149 138 146 136 129 146 127 139 148 149 147 154 162 163 131 128 126 140 163 135 137 117 119 136 131 136 140 140 161 136 152 136 159 131 131 149 128 133 126 143 140 142 129 142 146 128 134 133 131 136 133 147 145 151 129 98 140 147 130 144 124 151 135 144 133 167 120 121 140 136 136 132 138 122 162 143 158 139 148 136 135 143 158 136 152 132 152 152 144 142 145 128 160 149 160 142 140 153 146 157 152 155 142 133 163 132 144 138 159 155 153 157 161 133 135 130 131 144 143 143 127 131 141 143 145 127 133 136 151 129 139 128 173 156 158 139 150 147 158 163 134 165 154 156 144 146 141 139 127 139 142 139 129 139 126 127 154 149 137 133 126 136 131 137 127 145 143 137 150 131 150 158 132 156 134 142 136 132 154 154 137 131 148 134 126 117 154 134 138 145 168 141 132 131 136 141 138 143 140 148 141 133 138 153 150 143 137 141 143 130 162 145 151 151 158 147 134 153 140 142 122 130 150 140 136 136 141 132 130 123 147 134 136 171 148 134 147 146 128 134 152 140 139 152 138 137 148 138 152 142 134 133 127 129 133 142 143 133 157 137 157 137 131 144 139 132 144 148 133 119 137 146 138 151 140 131 142 149 145 150 147 132 125 143 159 133 130 125 120 146 146 138 158 132 150 131 155 133 141 161 140 134 150 146 143 131 139 161 146 131 128 148 132 153 131 149 138 125 135 144 118 133 138 133 135 123 147 126 143 139 144 143 150 157 137 132 150 141 171 144 140 130 132 138 136 145 124 161 144 133 121 157 128 147 129 119 121 140 148 114 148 151 147 145 138 133 127 152 128 146 133 136 137 151 132 146 142 141 119 145 132 152 146 119 136 165 143 128 113 137 145 146 150 147 131 149 132 145 120 158 129 126 135 142 146 140 130 165 119 125 172 137 120 157 153 128 141 146 138 129 161 147 128 140 149 126 133 146 147 123 154 154 146 148 155 154 133 123 132 121 138 149 143 150 139 116 137 134 138 158 149 126 146 131 125 138 136 139 154 154 142 131 153 150 144 140 147 154 155 130 144 142 151 122 175 130 167 146 138 158 141 137 135 107 139 148 124 132 131 157 155 136 139 143 143 126 155 142 143 144 162 174 161 149 156 135 126 123 138 164 164 120 133 129 129 156 136 123 136 126 133 129 130 152 123 148 135 137 142 148 130 125 119 145 168 140 133 138 131 140 147 127 131 147 129 139 138 148 158 114 134 165 125 151 140 141 117 118 144 140 142 181 151 139 138 148 131 149 155 145 152 117 134 138 136 150 131 153 115 147 131 150 138 129 145 127 163 152 137 126 134 142 118 160 140 120 127 157 120 136 147 124 138 119 150 135 141 130 142 157 141 145 151 129 176 162 132 154 145 138 138 142 143 152 144 129 151 134 150 141 118 137 138 157 139 136 144 144 127 155 145 169 130 141 147 134 149 132 152 130 151 142 164 125 130 130 133 158 153 143 156 132 131 144 148 133 143 146 153 140 158 120 155 143 129 139 143 143 146 116 150 131 134 139 152 121 147 133 147 152 127 156 120 159 128 143 133 155 156 126 146 139 142 155 154 164 133 143 148 116 140 129 132 139 130 141 146 146 142 156 168 138 127 152 152 134 148 138 139 148 148 147 135 145 149 134 144 142 140 130 138 117 157 144 158 129 150 141 142 138 127 151 135 146 140 146 140 166 145 151 138 138 151 150 139 157 157 130 140 141 136 158 125 131 112 146 136 137 144 128 137 155 127 137 135 147 148 138 158 139 150 141 136 147 133 151 140 151 160 137 151 152 150 148 135 136 155 154 127 137 146 163 144 141 133 152 146 145 139 142 135 136 144 163 145 146 132 119 159 143 157 157 144 124 147 133 155 148 109 147 152 136 153 154 140 123 129 127 132 135 131 133 138 148 139 159 130 150 133 140 149 136 138 117 155 144 131 145 134 138 150 127 123 186 162 126 143 131 151 128 152 136 138 146 145 144 140 154 141 154 167 141 157 147 160 137 142 141 157 148 150 133 158 124 137 123 138 135 124 143 124 139 149 140 172 129 157 146 139 157 146 136 140 148 141 145 133 141 117 142 149 127 136 161 145 139 155 133 151 136 162 146 159 114 139 152 142 118 123 159 146 140 140 139 127 138 175 124 124 148 143 154 153 136 151 142 138 145 118 142 155 146 136 143 122 134 143 138 141 145 136 144 129 119 139 140 140 157 146 136 125 133 135 137 156 166 142 146 138 155 160 137 140 146 147 127 153 148 128 133 148 138 150 131 134 139 146 130 141 157 138 124 134 121 166 148 145 128 131 137 162 170 135 145 145 153 143 131 143 171 137 138 135 152 140 153 140 147 162 157 153 133 136 144 121 146 136 120 147 135 126 147 141 134 159 148 139 155 142 143 142 146 129 154 150 158 134 131 154 123 143 128 150 128 164 122 117 129 140 143 148 137 145 122 139 158 163 144 134 131 126 137 154 128 121 126 142 161 141 146 155 168 131 134 143 151 129 149 138 129 144 145 130 126 158 131 161 127 145 157 139 149 147 161 135 130 129 150 131 138 122 131 146 147 139 150 144 126 140 159 146 135 130 137 137 141 135 164 151 156 150 124 144 143 144 138 133 122 156 128 142 128 127 146 165 137 137 127 140 134 119 141 136 124 162 132 125 145 144 153 110 129 143 133 137 131 144 132 146 153 113 147 130 129 136 128 141 147 156 137 138 146 162 155 129 133 135 171 149 150 158 141 122 153 135 153 135 130 133 142 154 142 146 135 122 132 124 124 143 133 144 157 140 145 152 137 144 136 141 137 132 139 139 151 134 148 164 143 133 132 141 132 152 170 150 117 136 128 136 162 128 126 161 158 142 124 143 171 140 140 142 132 136 129 147 151 152 151 131 157 139 151 136 122 139 160 148 161 134 125 128 111 145 153 152 145 144 137 144 136 165 144 144 155 131 139 139 139 133 138 131 143 136 135 154 141 143 143 158 139 126 131 156 133 143 139 124 139 128 147 121 148 141 144 161 145 154 164 144 147 138 117 131 152 138 152 139 140 135 131 139 149 136 123 150 130 154 148 149 132 157 147 149 134 138 139 127 141 141 120 165 148 126 142 128 124 147 123 127 144 148 151 144 133 130 164 149 148 146 149 137 148 121 140 127 137 126 152 160 150 149 136 131 148 151 135 158 152 129 151 156 143 140 143 147 136 123 179 138 150 132 138 144 147 142 147 113 148 125 135 168 135 137 149 154 142 130 134 130 151 137 144 112 129 142 122 169 150 142 148 150 142 131 133 129 148 156 156 158 130 158 147 158 154 163 162 135 158 132 139 159 161 171 134 139 175 139 150 145 154 118 154 151 135 139 148 144 164 120 155 141 144 160 154 158 162 158 153 139 142 163 141 152 155 137 140 126 130 136 130 138 136 140 146 114 135 160 160 146 156 155 146 145 151 161 150 149 151 155 147 137 141 141 145 144 136 143 150 153 137 155 132 171 159 147 151 139 119 138 143 153 134 161 155 160 144 128 129 153 151 150 159 143 138 168 154 165 150 150 154 141 160 128 167 151 139 173 134 152 157 143 154 139 163 143 156 131 142 141 127 119 154 142 129 155 147 180 144 119 157 144 128 153 171 144 130 133 147 150 125 144 137 145 147 137 119 154 183 148 135 158 157 136 156 146 128 129 158 147 157 157 132 125 142 153 147 159 172 150 132 120 163 133 148 143 146 171 151 151 145 165 133 156 153 122 137 148 146 145 150 135 139 166 146 118 132 138 145 161 146 143 152 152 148 133 149 139 152 129 151 140 137 148 158 144 147 158 159 153 161 148 135 126 153 158 133 145 151 132 126 130 144 127 169 177 136 139 148 152 139 153 156 150 135 163 145 145 146 151 135 142 162 154 140 135 151 141 146 136 151 154 140 147 145 161 142 146 142 126 130 138 146 158 162 140 143 131 167 142 173 154 129 153 138 164 130 130 128 154 151 150 138 155 180 128 131 130 146 146 158 138 124 153 159 132 168 147 147 139 138 149 145 156 158 146 146 138 155 136 142 152 162 156 157 137 147 155 143 140 146 152 132 152 156 151 133 155 138 148 140 159 151 168 135 137 175 170 138 148 143 141 157 143 144 149 157 132 177 170 159 166 161 152 173 163 151 143 152 175 176 173 150 168 176 170 165 167 160 159 168 167 154 169 169 182 169 159 153 178 155 173 180 165 158 180 180 178 165 145 164 152 190 155 177 162 146 174 161 164 167 185 151 162 150 156 149 170 149 164 187 144 150 197 150 184 161 168 150 155 166 161 186 180 134 143 151 165 151 151 155 150 142 154 158 155 167 186 150 147 145 149 146 156 145 172 157 139 145 132 137 140 154 152 140 163 152 172 165 166 163 156 149 132 168 168 159 133 145 120 163 155 172 162 146 125 151 146 156 137 137 142 138 157 149 153 155 160 171 154 133 143 171 144 162 130 135 113 153 149 129 139 141 136 155 129 139 130 148 156 171 129 141 156 149 149 155 159 132 136 156 137 142 150 125 139 135 143 128 149 147 147 132 141 126 136 159 137 148 138 134 146 144 130 156 147 146 142 160 170 129 127 159 143 154 177 155 151 156 152 130 153 140 161 162 135 161 131 137 131 143 157 152 139 138 153 140 154 150 131 156 140 151 129 129 120 144 151 151 155 145 134 156 143 160 147 142 144 179 155 136 131 146 165 142 158 158 156 155 146 172 130 147 127 150 125 145 163 171 152 139 140 140 174 143 166 148 139 155 144 151 158 148 160 149 141 134 144 139 141 138 138 154 125 158 153 173 157 142 157 137 148 148 145 156 127 149 156 156 145 145 144 158 158 130 122 117 135 146 139 142 145 140 132 126 149 168 157 143 146 156 138 147 136 168 160 151 139 154 151 142 137 151 146 153 139 130 156 123 156 126 142 124 129 151 150 145 129 148 131 147 143 147 141 154 135 138 134 146 135 131 156 140 145 148 140 137 157 136 153 135 131 139 139 135 148 161 161 151 135 127 143 123 156 140 167 132 133 172 133 136 149 144 138 148 159 151 137 155 120 152 137 132 140 146 130 149 156 151 154 151 127 144 146 153 138 147 149 131 153 149 150 156 144 138 137 152 132 148 178 142 142 150 148 151 124 151 136 140 139 160 145 144 129 137 140 155 123 135 133 136 154 145 159 137 135 156 146 142 131 146 132 138 133 152 143 145 137 145 149 145 155 149 157 164 175 166 146 149 137 135 143 134 157 141 143 151 136 127 141 142 136 136 147 140 147 148 132 159 163 159 133 151 148 145 143 143 141 141 135 127 150 164 141 173 150 144 144 153 135 154 150 124 154 137 154 147 156 156 150 177 148 156 121 125 137 135 146 156 149 144 149 146 142 146 153 162 150 153 149 148 146 151 137 154 145 145 150 142 137 133 158 162 157 163 127 138 155 149 151 141 144 136 133 159 135 156 148 155 161 143 123 144 150 145 138 156 170 143 140 150 126 144 150 135 173 122 149 141 137 132 142 151 134 138 129 125 165 145 154 138 146 138 148 145 146 153 127 126 153 151 162 137 161 169 165 137 143 155 154 128 167 147 140 147 143 150 151 132 154 153 149 169 139 146 142 131 155 155 135 140 139 141 160 154 140 151 155 132 132 140 137 136 144 149 133 126 163 150 125 142 134 137 128 145 153 154 127 146 142 143 141 159 146 146 125 147 144 147 149 151 160 139 142 134 161 154 149 153 131 156 134 136 150 142 144 137 157 115 143 144 146 164 140 142 145 131 134 169 155 151 147 141 128 152 132 143 151 145 130 165 136 144 144 138 144 135 142 132 151 166 136 149 145 139 158 144 167 132 152 142 140 131 158 125 131 146 143 147 118 156 131 161 146 138 168 160 131 176 151 146 136 149 148 134 109 156 153 137 133 153 143 150 137 159 129 138 164 131 136 161 157 133 153 134 144 166 153 162 128 138 157 140 136 141 151 156 143 154 133 148 154 131 140 136 148 160 157 141 143 134 141 148 155 137 133 140 158 151 157 135 154 134 124 144 144 166 161 141 143 142 120 161 138 155 141 151 167 162 137 124 161 134 149 152 130 144 120 122 136 140 160 132 120 151 127 156 124 142 130 141 157 126 145 141 149 154 153 140 135 148 155 142 156 142 152 157 127 130 130 141 142 145 161 151 146 146 150 149 104 125 144 143 129 136 139 127 128 150 152 153 144 149 120 126 141 139 154 169 153 142 141 153 153 129 118 147 160 153 138 134 152 141 171 143 142 133 135 141 164 151 151 132 144 124 150 158 138 165 139 152 147 145 136 103 152 131 155 145 121 144 155 146 150 174 145 153 123 166 150 146 161 134 119 147 147 124 143 143 146 120 132 138 152 151 156 143 153 134 138 151 149 135 136 150 159 175 150 128 142 140 137 149 147 152 137 138 151 151 138 158 147 140 162 142 151 129 147 132 128 143 133 156 140 123 133 152 158 150 123 160 151 166 145 148 144 141 111 147 163 144 140 146 140 158 138 158 162 130 118 149 140 138 133 140 139 140 163 152 143 144 144 140 138 142 147 140 160 139 154 139 155 126 133 143 140 169 135 158 114 125 137 150 156 150 149 145 150 137 138 130 125 136 148 129 157 123 151 158 130 157 129 144 132 150 127 147 130 137 119 140 147 135 127 145 136 127 144 131 131 139 124 162 125 141 150 148 137 140 115 157 148 167 148 148 147 122 141 148 166 181 141 158 138 152 146 123 168 143 148 151 156 164 129 138 180 141 123 149 136 115 108 149 131 133 140 151 157 115 124 136 131 143 133 149 155 152 135 132 143 141 155 148 137 140 120 144 157 163 132 147 129 141 148 144 159 147 153 151 158 159 159 123 145 152 150 134 133 138 139 155 142 138 134 151 160 157 135 139 131 128 138 150 122 133 129 168 146 148 148 145 128 152 131 127 143 135 152 140 137 161 136 154 128 128 146 142 118 146 160 142 142 164 134 143 124 132 137 155 160 127 137 125 147 143 141 155 131 145 141 151 143 150 130 144 153 156 129 127 158 154 140 123 132 130 146 150 143 154 119 141 146 130 126 126 145 134 137 154 153 156 157 137 147 141 150 145 136 122 144 137 135 133 137 146 142 153 142 172 132 155 157 148 139 161 129 156 157 158 140 154 149 125 149 137 135 160 142 146 146 142 126 162 144 153 132 133 123 147 117 133 154 149 162 122 135 115 141 149 152 147 132 123 143 160 169 146 134 143 172 150 131 129 131 145 142 146 149 137 152 151 144 174 123 152 135 127 153 142 134 140 144 147 138 161 139 141 154 134 126 128 150 155 135 139 142 134 147 148 136 133 147 132 147 151 155 132 129 122 141 149 134 131 141 150 150 128 127 131 149 137 126 138 158 148 139 145 112 125 149 141 140 146 155 148 145 143 153 118 163 160 159 159 151 152 155 158 139 147 155 156 142 146 152 166 136 138 180 159 166 123 155 172 155 158 154 166 157 134 155 143 132 145 145 134 135 146 150 154 143 135 139 151 126 129 138 135 144 143 132 171 153 132 159 152 144 149 132 151 150 170 138 154 148 158 155 143 111 146 143 114 149 138 149 133 147 165 120 149 136 141 137 137 134 150 133 155 149 153 152 146 135 141 146 153 147 131 173 127 129 149 141 139 160 159 150 130 143 140 133 158 151 137 140 119 156 149 136 164 140 164 134 129 159 150 144 142 151 155 164 142 151 149 146 141 128 147 141 142 161 150 139 122 132 146 163 150 148 138 131 163 161 147 145 124 157 133 138 142 171 162 138 147 155 152 172 147 169 148 141 127 163 134 126 161 152 137 140 151 131 146 139 146 151 146 142 146 162 137 158 156 148 175 129 117 125 160 149 145 123 157 173 158 143 136 149 155 160 163 177 152 138 155 151 136 165 152 140 156 151 161 158 138 158 152 139 142 125 136 160 174 147 141 121 166 159 149 144 157 172 167 162 149 156 176 149 149 142 143 160 130 160 148 145 133 159 161 169 133 135 145 153 136 177 131 149 152 137 156 157 155 132 144 168 150 160 162 136 142 155 162 154 155 155 154 144 125 152 147 144 143 139 169 121 154 149 135 157 152 143 147 148 147 144 159 165 143 157 131 151 154 142 174 160 152 138 134 154 137 148 168 139 151 143 151 153 165 143 128 132 158 139 165 159 141 147 155 169 148 145 168 135 168 161 144 155 161 147 157 139 135 133 138 155 156 163 149 149 150 146 140 154 134 142 131 146 152 160 115 155 148 146 117 150 151 163 129 126 136 136 144 132 155 129 170 163 143 153 138 137 152 128 154 147 174 151 147 155 144 146 140 124 144 144 131 143 145 164 158 164 139 150 140 112 148 172 137 141 159 140 154 133 148 144 157 139 130 145 159 147 137 136 126 158 124 147 155 134 153 160 138 120 166 150 129 161 140 145 128 150 141 142 144 129 162 140 146 149 136 171 126 146 144 122 141 139 138 141 167 139 149 146 143 145 135 149 160 148 166 151 141 154 164 144 153 148 137 132 156 140 136 137 164 147 154 157 150 161 134 143 163 127 128 154 178 127 142 158 141 119 120 150 152 159 135 138 149 152 155 135 156 168 145 147 140 138 112 157 161 153 125 139 133 130 144 156 148 148 130 153 139 155 147 138 156 152 151 140 140 146 120 156 155 152 178 144 149 148 135 154 167 137 150 141 150 156 153 152 132 131 139 147 140 151 135 140 143 141 149 165 158 124 142 145 149 132 149 138 150 142 151 145 108 136 159 155 137 145 151 144 153 149 157 138 144 151 151 125 140 142 142 148 147 144 145 110 171 154 160 164 138 147 147 155 144 133 153 147 167 147 148 133 139 154 147 152 135 142 142 130 172 158 148 155 147 158 164 155 135 144 133 147 135 159 141 145 138 142 155 132 150 143 151 129 163 165 161 146 154 137 151 131 130 158 155 131 126 147 133 155 132 142 159 129 158 141 165 146 168 143 147 151 134 149 135 152 144 136 159 133 148 130 164 147 143 145 161 157 144 157 146 135 157 146 160 159 150 141 139 151 141 163 141 158 148 140 158 154 128 130 142 139 126 136 164 142 144 139 126 145 146 158 141 121 156 131 140 174 138 150 157 163 158 139 144 137 140 133 156 148 170 138 151 141 145 148 156 154 133 155 148 145 151 130 138 137 164 145 164 163 177 142 130 145 159 153 138 149 142 161 150 136 149 120 133 172 139 144 138 133 125 146 125 142 143 152 142 123 152 130 129 137 151 151 152 149 158 124 152 138 155 141 136 156 170 148 143 147 144 143 131 170 138 138 152 151 139 160 146 130 151 143 143 152 141 153 136 150 138 146 139 130 155 141 134 137 156 129 126 149 163 143 133 171 127 155 159 135 157 151 137 145 144 143 140 161 140 152 142 153 152 150 142 166 149 140 139 137 154 175 160 134 159 141 150 143 142 165 153 139 171 178 139 154 152 169 171 147 148 147 130 124 163 152 152 140 167 165 158 145 131 145 137 148 148 149 135 142 167 171 157 144 151 141 150 136 146 147 155 162 158 144 162 139 142 145 137 150 121 147 150 147 147 155 139 132 157 143 154 137 142 143 143 138 148 151 123 148 159 150 144 159 153 151 134 160 166 143 136 137 149 143 143 158 154 141 142 158 151 145 154 153 144 141 152 133 132 165 166 146 152 130 159 157 140 109 134 148 165 148 148 150 158 142 143 144 144 157 154 155 166 147 127 152 171 147 154 164 153 149 163 170 122 137 138 146 139 154 144 120 161 139 136 138 164 151 154 113 148 154 132 165 116 165 167 152 186 156 140 127 116 182 133 159 160 143 141 140 148 137 143 152 168 159 151 141 160 136 181 161 139 156 155 146 145 152 154 144 150 147 152 145 138 160 175 138 142 169 155 144 155 138 161 159 137 155 136 136 155 146 158 146 152 161 166 125 160 155 132 152 149 173 135 141 160 163 152 150 134 149 148 153 154 156 164 129 137 154 169 147 144 139 160 169 143 161 163 144 157 145 144 130 130 130 144 139 160 158 129 152 145 161 126 157 139 139 145 170 130 146 162 163 149 123 153 147 165 131 152 157 130 156 145 162 130 134 140 134 149 140 193 127 176 151 167 131 120 152 134 152 142 140 135 153 126 145 135 140 136 140 132 144 140 153 140 151 141 149 117 139 153 130 155 139 150 139 152 161 128 129 144 155 154 161 140 159 179 156 145 160 151 169 152 136 161 155 149 152 153 142 152 140 142 143 158 139 137 145 158 163 152 142 132 143 146 137 161 135 150 147 164 127 150 146 151 158 143 156 141 153 149 157 150 163 162 125 158 154 143 135 158 155 137 154 164 144 155 136 120 139 176 138 143 142 145 157 141 135 158 160 154 162 146 154 152 149 141 149 136 130 122 140 131 168 173 144 149 138 129 164 116 141 168 142 141 135 143 159 149 156 158 156 144 123 123 119 137 125 144 111 140 139 138 151 134 148 138 158 145 139 148 161 127 130 176 159 129 145 139 149 136 148 160 136 136 144 145 153 152 145 139 142 154 129 151 149 146 144 156 163 131 121 133 141 152 122 173 166 152 124 154 150 139 168 135 146 158 162 139 139 153 123 149 174 150 159 147 149 139 151 145 140 154 136 137 163 151 165 148 151 139 176 156 132 136 158 133 147 134 153 135 138 152 162 154 146 131 141 136 145 126 147 143 134 146 127 131 147 157 142 155 141 163 148 152 127 154 138 121 164 136 136 125 144 119 143 146 166 153 161 143 169 130 131 137 148 141 158 120 150 134 156 170 146 140 136 144 155 142 161 140 146 136 121 144 143 122 148 139 146 137 128 155 161 139 144 142 150 150 162 136 169 151 152 131 157 132 130 165 128 168 151 132 144 154 147 145 105 170 145 114 154 159 140 155 145 159 140 129 149 125 155 174 142 137 141 156 124 157 131 155 132 148 130 152 119 139 172 153 151 136 128 133 122 143 137 145 151 132 147 142 140 144 142 139 150 139 135 162 145 146 140 145 142 133 148 154 165 132 150 124 155 131 156 158 138 157 129 130 148 136 163 145 150 154 150 143 146 152 153 147 167 138 147 144 128 154 127 131 127 132 146 137 138 130 138 136 126 166 155 144 137 152 134 147 150 141 130 149 158 147 143 154 120 135 147 138 114 139 131 133 142 149 154 158 153 167 146 155 119 142 151 158 142 156 123 118 152 150 144 148 144 128 140 158 148 138 141 146 145 139 151 171 154 154 156 163 125 146 144 134 130 149 129 121 155 131 154 147 142 160 160 139 139 148 116 123 142 155 128 138 144 145 152 113 135 155 148 151 144 137 151 154 156 135 159 134 144 135 146 151 133 156 161 129 133 142 161 160 154 149 135 150 158 146 141 141 140 137 141 149 150 146 152 159 150 139 170 144 166 128 150 150 130 140 150 151 151 147 164 123 142 134 130 131 141 153 133 158 165 121 161 139 141 149 136 135 132 162 147 146 153 154 145 162 136 156 145 164 155 134 150 148 152 134 143 142 124 140 158 157 132 150 157 129 152 135 129 150 161 133 135 135 138 157 144 144 151 119 145 150 141 153 141 156 130 137 141 136 136 138 155 155 138 147 152 135 146 135 152 138 157 132 142 167 146 152 140 158 142 117 151 141 148 148 129 144 171 138 140 145 153 144 153 137 163 137 137 125 145 130 150 134 148 154 173 133 124 152 154 133 148 150 148 150 145 145 172 156 135 170 152 137 143 142 145 145 162 122 172 143 145 149 137 142 152 151 145 158 142 131 118 148 134 158 166 165 168 156 138 149 153 134 166 151 162 155 140 159 129 162 147 156 169 126 149 129 135 122 151 136 155 128 156 147 137 139 138 160 147 142 165 142 150 151 147 164 173 137 142 152 133 143 143 163 147 141 160 154 153 171 139 138 142 147 143 132 145 125 140 164 140 157 151 159 151 158 177 158 131 140 140 148 157 142 137 151 155 128 147 145 148 166 150 138 142 135 150 136 151 142 158 155 162 148 168 181 146 165 129 163 159 146 146 160 164 140 168 137 158 145 161 136 162 162 173 141 157 158 147 140 147 161 175 147 150 129 170 152 161 159 142 131 171 151 125 156 130 148 164 144 136 133 151 138 142 142 139 126 162 171 128 125 153 147 178 138 131 159 143 149 148 138 146 166 147 136 156 137 145 166 151 154 129 161 147 155 148 163 127 143 163 134 141 153 131 169 129 142 129 132 167 146 129 134 140 137 165 139 160 164 162 180 143 156 152 156 147 143 150 128 152 161 159 152 145 164 132 139 165 128 151 159 149 142 150 120 145 148 152 138 154 149 147 126 132 153 145 152 145 138 144 135 142 143 170 138 146 159 161 133 157 129 134 139 138 150 184 124 147 148 131 133 149 128 137 146 128 143 155 151 159 136 143 133 142 142 125 156 133 134 168 165 162 137 123 147 168 132 137 140 149 132 148 126 129 157 134 138 145 157 136 187 137 149 124 134 138 164 156 139 146 141 125 167 154 141 151 123 152 162 146 124 150 156 137 139 138 160 143 135 160 137 142 169 135 149 146 139 134 161 117 134 153 150 158 135 144 154 144 145 142 128 145 154 123 136 139 145 128 134 144 146 140 136 128 151 139 139 137 128 132 159 135 126 133 138 134 151 153 141 142 143 148 142 133 130 151 147 124 163 125 122 165 157 150 152 149 138 158 150 161 138 146 140 164 143 163 140 169 154 151 143 162 139 128 143 139 138 140 126 156 130 147 127 148 131 146 136 135 134 147 150 125 159 157 131 154 145 121 156 138 142 156 166 133 144 149 157 151 146 143 133 149 154 155 147 143 137 136 157 140 136 152 175 142 154 113 140 121 136 134 167 154 143 135 148 141 143 128 130 157 137 160 139 132 137 145 124 149 118 151 138 157 140 142 120 156 144 152 136 140 140 154 158 144 157 136 135 123 129 131 128 164 149 129 147 156 143 112 148 142 130 151 151 139 138 130 147 129 123 147 166 152 143 151 137 145 153 128 148 151 148 149 172 133 152 149 145 146 163 151 149 144 156 163 142 152 143 176 129 109 139 155 127 145 147 152 144 151 169 156 163 156 139 141 160 173 135 158 144 157 150 139 141 132 142 139 151 142 142 139 135 144 155 149 161 141 137 132 157 135 136 133 147 153 131 126 127 145 129 140 132 158 130 145 123 141 139 139 136 146 150 158 135 145 156 160 157 159 149 155 137 136 137 148 135 156 156 136 132 149 119 119 157 147 152 127 130 148 135 157 154 154 144 152 159 150 139 144 144 149 141 143 127 123 149 120 148 127 139 119 159 152 126 130 150 123 157 135 146 141 145 146 144 151 158 131 153 133 165 139 147 142 139 145 126 114 141 159 140 141 148 162 155 132 141 153 134 138 129 133 121 134 134 167 142 158 141 130 123 112 163 146 135 149 175 142 150 127 139 160 145 157 146 132 150 150 134 137 129 139 151 173 133 134 146 153 135 158 124 135 115 142 141 133 131 156 135 148 162 151 165 136 133 150 142 106 130 154 125 133 128 143 148 131 148 148 126 150 177 136 137 153 145 125 142 145 142 132 153 129 134 166 138 157 140 139 136 165 127 157 147 122 137 142 128 125 150 155 130 134 158 136 119 159 120 149 147 134 131 144 136 146 136 128 133 139 130 160 115 159 131 147 130 141 157 144 149 138 151 142 147 147 139 129 153 164 131 144 160 116 153 149 140 150 142 127 138 145 123 125 153 141 132 157 115 152 140 118 147 155 151 149 125 131 134 137 142 134 125 148 117 144 143 167 136 133 132 144 131 133 152 136 129 130 124 145 137 123 141 119 127 151 126 144 160 139 158 160 151 138 136 133 133 137 140 153 142 127 132 140 142 122 127 142 138 138 146 138 126 147 134 138 136 120 168 134 148 145 121 149 147 139 139 142 151 146 139 133 122 130 136 134 136 132 141 139 125 146 140 146 135 144 148 168 136 135 136 148 125 124 132 160 125 132 148 153 122 138 136 129 174 122 137 136 141 138 129 153 146 134 138 136 130 143 143 152 122 125 143 137 137 144 164 139 144 145 142 128 124 137 134 108 136 160 152 145 144 133 136 149 134 161 138 177 155 154 120 136 144 180 139 152 125 137 131 148 147 117 134 126 135 163 154 137 148 129 144 126 137 139 133 135 113 138 147 128 168 129 143 141 133 132 112 160 152 140 139 148 124 134 135 150 174 135 135 139 143 135 148 142 143 150 155 145 156 129 139 136 164 137 130 151 157 136 162 175 131 123 149 148 124 152 130 143 139 138 152 131 143 148 131 133 160 169 120 128 133 156 148 144 151 139 123 160 123 127 140 117 132 104 135 131 132 144 144 144 135 126 132 131 159 152 130 129 148 148 120 158 155 141 138 150 171 156 128 163 131 114 148 147 142 140 139 137 127 142 128 153 142 134 130 133 143 148 140 133 116 133 151 146 157 169 155 122 146 168 120 141 132 132 135 134 137 162 160 157 147 126 148 143 123 130 134 127 149 144 147 140 152 140 129 161 144 131 149 140 131 149 128 146 137 146 148 138 136 132 121 154 123 130 146 137 146 140 156 126 136 137 142 130 130 158 121 135 126 139 117 145 162 134 121 146 145 148 144 130 146 146 147 131 147 135 159 143 146 140 139 130 163 124 130 140 134 144 144 147 128 128 140 130 150 136 124 138 150 140 147 139 145 142 133 147 118 154 127 154 148 130 134 119 147 144 137 138 157 123 151 151 145 148 144 119 128 136 129 127 134 115 156 149 146 138 142 166 148 146 132 139 151 139 126 144 151 133 142 133 133 148 135 142 138 136 128 158 167 117 147 150 136 157 136 145 185 135 134 133 127 124 134 130 148 134 134 158 153 116 130 143 131 126 125 137 128 133 136 174 150 147 148 148 143 146 144 143 128 153 149 148 131 147 160 136 142 129 117 119 129 148 146 129 151 132 152 139 114 135 151 127 123 138 156 156 108 150 151 108 124 146 138 148 135 135 131 143 143 127 143 160 140 146 156 145 161 153 153 161 129 145 145 119 137 137 133 139 142 139 151 130 147 125 150 157 131 124 169 145 137 140 143 132 140 144 129 145 136 129 154 145 140 148 152 141 140 160 135 137 120 113 162 156 125 142 162 133 123 136 150 124 126 105 131 141 127 149 149 147</counts>
			</dataPoints>
		</scan>
	</xrdMeasurement>
</xrdMeasurements>