File: data/XRD/_misc/old/XG-600C/_absolute_2th-om_10-130deg_PIXscan_56min_2.xrdml
<xrdMeasurements xmlns="http://www.xrdml.com/XRDMeasurement/2.1" xmlns:xsi="http://www.w3.org/2001/XMLSchema-instance" xsi:schemaLocation="http://www.xrdml.com/XRDMeasurement/2.1 http://www.xrdml.com/XRDMeasurement/2.1/XRDMeasurement.xsd" status="Completed">
	<comment>
		<entry>Configuration=Factory configuration, Owner=User-1, Creation date=7/8/2013 4:01:53 PM</entry>
		<entry>Goniometer=PW3050/65 (Theta/2Theta); Minimum step size 2Theta:0.0001; Minimum step size Omega:0.0001</entry>
		<entry>Sample stage=MRD Cradle; Minimum step size Phi:0.01; Minimum step size Chi:0.01; Minimum step size X:0.01; Minimum step size Y:0.01; Minimum step size Z:0.001</entry>
		<entry>Diffractometer system=XPERT-PRO</entry>
		<entry>Measurement program=C:\PANalytical\Data Collector\Programs\Jorrit\2thom\_absolute_2th-om_10-130deg_PIXscan_56min.xrdmp, Identifier={15BCCF57-2807-42BD-B5B9-ECC0B3DC9284}</entry>
		<entry>Batch program=C:\PANalytical\Data Collector\Programs\SimonL\batch4x_2thom_10-130°_z9.1_x0,10,20,30_y0_57min.xrdmp, Identifier={EED9823A-2BEB-424C-9252-345C4EF2834A}</entry>
	</comment>
	<sample type="To be analyzed">
		<id></id>
		<name></name>
		<preparedBy></preparedBy>
	</sample>
	<xrdMeasurement measurementType="Scan" status="Completed" sampleMode="Reflection">
		<comment>
			<entry>_absolute_2th-om_10-130deg_PIXscan_56min</entry>
			<entry>PHD Lower Level = 4.83 (keV), PHD Upper Level = 11.27 (keV)</entry>
		</comment>
		<usedWavelength intended="K-Alpha 1">
			<kAlpha1 unit="Angstrom">1.5405980</kAlpha1>
			<kAlpha2 unit="Angstrom">1.5444260</kAlpha2>
			<kBeta unit="Angstrom">1.3922500</kBeta>
			<ratioKAlpha2KAlpha1>0.5000</ratioKAlpha2KAlpha1>
		</usedWavelength>
		<incidentBeamPath>
			<radius unit="mm">320.00</radius>
			<xRayTube id="1010048" name="Empyrean Cu LFF HR (9430 033 7310x) DK442154">
				<tension unit="kV">40.0</tension>
				<current unit="mA">40.0</current>
				<anodeMaterial>Cu</anodeMaterial>
				<focus type="Line">
					<length unit="mm">12.0</length>
					<width unit="mm">0.4</width>
					<takeOffAngle unit="deg">4.2</takeOffAngle>
				</focus>
			</xRayTube>
			<xRayMirror id="27010001" name="Inc. Beam Cu W/Si (parabolic MRD)" hybrid="false">
				<crystal type="Graded" shape="Parabolic">W/Si</crystal>
				<acceptanceAngle unit="deg">0.800</acceptanceAngle>
				<length unit="mm">60.0</length>
			</xRayMirror>
			<sollerSlit id="21010002" name="Soller slits 0.04 rad.">
				<opening unit="rad">0.0400</opening>
			</sollerSlit>
			<mask id="22030007" name="Fixed mask 2 mm">
				<distanceToSample unit="mm">220.00</distanceToSample>
				<width unit="mm">2.00</width>
			</mask>
			<divergenceSlit id="22010007" name="Fixed slit 1/8°" xsi:type="fixedDivergenceSlitType">
				<distanceToSample unit="mm">220.00</distanceToSample>
				<height unit="mm">0.19</height>
			</divergenceSlit>
		</incidentBeamPath>
		<diffractedBeamPath>
			<radius unit="mm">320.00</radius>
			<sollerSlit id="21010002" name="Soller slits 0.04 rad.">
				<opening unit="rad">0.0400</opening>
			</sollerSlit>
			<receivingSlit id="22010001" name="Fixed slit 4°">
				<height unit="mm">5.88</height>
			</receivingSlit>
			<detector id="7010017" name="PIXcel3D 1x1 detector" xsi:type="areaDetectorType">
				<phd unit="%">
					<lowerLevel>30.0</lowerLevel>
					<upperLevel>70.0</upperLevel>
				</phd>
				<mode>Scanning</mode>
				<activeChannelsEquatorial>255</activeChannelsEquatorial>
				<activeChannelsAxial>255</activeChannelsAxial>
				<pitchEquatorial unit="mm">0.05500</pitchEquatorial>
				<pitchAxial unit="mm">0.05500</pitchAxial>
				<readOutPeriod unit="seconds">0.135</readOutPeriod>
			</detector>
		</diffractedBeamPath>
		<scan appendNumber="0" mode="Continuous" scanAxis="2Theta-Omega" status="Completed">
			<header>
				<startTimeStamp>2024-08-27T16:49:57+02:00</startTimeStamp>
				<endTimeStamp>2024-08-27T17:46:03+02:00</endTimeStamp>
				<author>
					<name>PRO-MRD</name>
				</author>
				<source>
					<applicationSoftware version="6.1b">Data Collector</applicationSoftware>
					<instrumentControlSoftware version="7.0E 20130304">XPERT-PRO</instrumentControlSoftware>
					<instrumentID>0000000011142674</instrumentID>
				</source>
			</header>
			<dataPoints>
				<positions axis="2Theta" unit="deg">
					<startPosition>9.99826193</startPosition>
					<endPosition>129.99755682</endPosition>
				</positions>
				<positions axis="Omega" unit="deg">
					<startPosition>4.99913096</startPosition>
					<endPosition>64.99877841</endPosition>
				</positions>
				<positions axis="Phi" unit="deg">
					<commonPosition>0.00</commonPosition>
				</positions>
				<positions axis="Chi" unit="deg">
					<commonPosition>0.00</commonPosition>
				</positions>
				<positions axis="X" unit="mm">
					<commonPosition>10.00</commonPosition>
				</positions>
				<positions axis="Y" unit="mm">
					<commonPosition>0.00</commonPosition>
				</positions>
				<positions axis="Z" unit="mm">
					<commonPosition>9.100</commonPosition>
				</positions>
				<commonCountingTime unit="seconds">32.895</commonCountingTime>
				<counts 210 230 241 217 239 240 196 199 239 220 238 226 238 227 229 239 249 232 200 218 210 218 235 236 218 216 226 240 222 231 218 237 224 240 225 225 248 218 224 255 242 227 227 224 223 243 212 238 243 237 232 224 228 225 237 213 247 239 259 265 212 226 193 193 204 241 206 222 217 243 261 233 218 238 224 243 248 227 202 202 216 230 229 218 202 204 214 239 223 174 219 201 198 220 240 211 226 218 219 179 227 212 212 211 231 244 244 216 211 207 221 233 181 215 233 210 221 197 225 190 213 210 213 212 209 188 208 223 186 216 208 211 217 188 197 223 193 209 232 227 198 214 197 225 185 228 241 224 219 178 221 217 204 185 204 227 216 187 194 237 201 221 203 201 192 219 212 230 232 210 216 193 197 222 192 195 190 206 205 207 223 204 201 192 185 200 185 211 213 194 235 164 197 207 210 211 210 209 205 210 218 190 227 224 169 212 216 202 203 208 186 212 203 194 196 180 192 235 213 193 222 219 177 203 169 215 195 208 204 189 182 206 182 206 199 195 200 211 232 210 189 230 185 200 229 186 189 188 238 196 200 177 199 213 202 209 204 207 191 175 196 191 227 186 177 192 201 184 231 196 202 198 206 200 210 200 199 203 192 201 197 181 173 220 174 188 187 181 197 215 189 185 202 193 199 193 205 208 196 158 212 195 180 174 178 194 188 193 188 178 175 169 203 210 206 190 193 177 192 198 187 180 216 170 187 180 186 205 182 171 180 172 177 192 191 193 197 187 158 202 198 197 181 189 201 171 183 212 154 184 204 190 177 171 175 160 156 214 167 179 197 158 186 205 166 172 160 193 215 185 186 187 190 195 189 181 173 190 193 182 167 180 178 184 210 166 201 176 173 188 195 179 186 182 177 181 176 171 187 183 203 164 183 182 172 187 178 199 182 184 182 178 137 181 181 186 196 158 192 199 162 175 161 176 200 182 168 172 181 190 216 172 193 197 170 140 166 172 169 171 183 181 187 180 171 171 166 150 169 167 185 182 182 172 182 184 179 185 178 164 188 171 152 153 173 160 178 182 176 181 164 185 189 162 179 189 185 178 182 184 192 170 178 145 188 154 175 188 169 214 177 195 157 178 193 146 164 167 164 174 155 184 140 173 171 154 158 175 170 171 178 186 174 163 147 177 183 176 154 181 172 154 170 163 173 174 175 159 192 166 173 175 183 146 192 156 178 151 145 184 163 176 187 170 168 184 180 158 181 165 192 158 163 174 141 169 147 155 163 185 165 176 170 146 184 161 154 140 147 157 167 136 156 165 191 179 157 157 171 175 154 179 160 163 150 161 146 156 169 169 196 166 162 166 176 175 154 190 159 157 163 154 168 180 162 161 155 147 154 173 161 181 152 191 172 143 158 196 195 147 153 159 163 167 162 157 172 168 155 157 167 156 167 163 148 168 160 144 151 161 164 175 160 174 145 147 185 162 157 165 138 164 177 162 167 180 174 165 164 162 164 172 168 164 162 139 161 187 156 146 150 170 185 167 152 145 150 186 160 154 156 152 163 165 156 164 153 172 159 170 161 161 162 161 160 152 154 143 147 163 167 150 143 143 203 184 155 152 155 169 164 125 156 177 155 161 152 172 152 152 167 185 156 156 135 157 175 147 173 160 184 176 168 181 169 147 181 190 136 165 146 149 148 165 157 150 166 154 158 180 168 176 171 160 150 146 167 150 146 164 160 155 184 167 154 149 157 156 177 184 145 164 173 151 167 163 166 170 140 154 153 145 168 160 157 160 151 156 160 161 156 125 161 157 172 178 131 184 158 156 157 158 154 183 162 180 149 164 156 181 169 173 154 153 181 161 156 149 175 155 161 145 157 170 132 156 154 167 184 168 163 166 164 149 160 160 137 139 161 118 162 165 132 152 151 191 139 147 164 173 151 154 161 150 155 154 152 141 170 174 151 175 177 157 188 163 161 175 176 167 131 176 168 162 152 168 142 163 148 155 164 136 164 155 155 165 163 175 162 173 150 162 154 151 154 166 174 161 154 164 133 141 141 173 175 175 156 148 130 140 165 156 168 154 168 171 152 163 172 150 167 169 186 155 145 162 170 173 161 188 143 166 156 151 179 154 173 156 155 179 167 172 148 155 169 155 167 141 193 160 165 155 155 154 172 158 160 170 175 162 164 171 135 167 149 147 174 155 143 139 160 173 177 177 167 168 160 127 160 165 176 178 160 157 148 143 155 155 180 156 141 169 164 183 174 156 181 180 147 173 176 138 175 147 171 153 159 155 170 176 179 173 162 157 208 188 181 145 156 162 154 161 166 162 162 176 148 173 165 137 168 166 169 147 145 147 175 179 154 167 158 156 161 170 185 169 186 174 172 179 144 143 148 150 161 175 130 148 196 167 153 165 175 158 156 180 168 170 174 172 173 166 186 177 154 170 183 166 168 180 161 172 200 171 155 164 142 174 176 172 165 175 184 155 167 182 157 186 180 164 172 176 169 174 155 172 172 164 194 159 161 153 146 169 178 158 147 191 156 175 173 185 157 187 179 176 157 166 190 149 193 182 169 156 187 176 197 182 165 145 177 167 177 165 164 162 145 167 203 176 169 181 155 150 186 179 176 198 169 172 168 169 195 171 173 197 176 169 167 175 189 177 181 186 182 163 147 165 191 184 188 151 153 188 165 188 174 167 169 182 165 164 194 192 156 161 148 180 180 155 179 180 176 158 164 179 197 156 144 163 167 145 177 176 175 154 186 170 190 164 191 168 177 177 141 175 171 160 164 165 171 176 177 193 173 165 180 166 174 153 177 188 178 168 164 152 163 167 156 161 180 173 169 196 182 197 169 169 175 192 197 171 180 172 170 168 174 192 147 172 156 209 159 165 164 187 195 163 162 158 153 162 180 186 153 153 179 178 172 188 167 174 175 170 149 153 166 184 175 188 160 157 171 180 156 173 170 172 218 171 193 187 172 178 182 175 171 138 173 162 168 179 161 163 174 159 181 196 153 183 150 177 158 182 187 171 185 190 168 179 167 158 183 161 184 159 185 197 155 172 142 152 180 144 164 172 158 176 172 167 188 187 161 177 153 168 159 163 176 166 190 182 178 200 181 167 185 154 181 161 181 160 139 177 155 159 167 162 180 186 164 189 156 174 165 153 163 175 175 176 160 160 164 153 166 151 151 156 176 172 176 168 154 192 179 167 183 194 205 184 142 150 160 187 175 183 173 182 165 158 168 152 161 141 191 152 169 162 166 159 172 177 193 170 173 167 171 162 165 167 168 173 176 161 174 185 161 167 183 169 175 171 158 169 137 181 182 181 140 147 170 174 178 160 163 165 171 149 182 154 170 170 151 199 167 171 159 169 171 148 155 166 166 166 177 171 203 173 154 161 152 182 154 175 179 150 171 165 149 155 168 154 163 168 185 156 149 157 182 154 168 175 181 149 153 168 192 196 169 164 162 169 171 193 170 160 136 128 153 155 158 157 160 154 138 167 174 161 152 168 179 166 156 150 144 134 173 153 153 182 180 165 157 157 153 166 157 172 152 158 151 154 166 168 187 158 153 145 147 167 177 176 134 143 165 138 162 159 155 180 186 174 149 180 170 166 176 160 155 177 162 148 158 171 130 179 168 166 167 175 147 143 162 150 166 139 161 164 136 154 185 174 148 167 156 153 168 179 148 173 178 187 161 166 170 139 177 153 159 162 150 174 162 158 142 165 142 170 158 172 159 145 188 184 131 170 170 159 148 172 164 158 163 151 159 160 159 155 146 168 138 156 138 150 163 154 167 168 161 166 150 132 137 168 142 142 143 152 141 155 163 167 155 160 137 150 166 155 142 164 176 155 131 133 149 167 152 151 162 153 163 159 150 164 169 151 140 147 154 153 170 158 134 166 165 151 131 147 137 157 170 171 160 154 133 152 145 166 149 130 155 143 162 147 154 148 159 155 142 162 136 128 145 162 150 132 153 163 133 166 148 140 149 143 151 155 155 157 147 129 146 163 155 127 160 152 132 157 146 142 148 153 157 164 145 143 156 136 154 129 138 163 164 174 145 164 130 147 159 153 147 144 142 154 138 149 155 125 127 140 154 164 146 157 161 139 151 138 151 166 158 131 147 142 153 144 150 144 142 126 150 148 147 139 155 156 163 135 161 155 148 137 155 153 152 159 152 160 135 140 128 138 161 145 134 151 154 163 161 137 130 150 160 150 147 136 124 146 146 156 132 161 149 162 146 135 150 133 153 148 133 136 133 144 153 139 157 153 141 127 156 150 135 155 149 139 132 142 137 150 132 124 147 152 139 149 141 149 162 145 152 156 164 152 155 140 157 155 134 142 115 143 160 160 136 143 134 149 136 130 143 150 162 135 142 139 143 151 152 150 145 147 137 132 124 143 127 129 135 141 174 154 133 152 142 134 148 141 125 143 138 157 165 152 156 133 137 158 142 151 156 146 151 155 127 147 147 144 135 134 140 119 148 148 132 159 156 131 151 137 144 119 138 130 160 124 123 135 123 137 132 149 148 147 138 143 116 137 127 140 159 135 125 165 146 108 159 150 140 134 141 116 134 116 142 148 129 130 148 151 148 124 129 137 123 152 140 167 160 137 145 133 131 110 133 147 135 150 131 146 142 143 147 139 130 140 138 151 142 154 133 155 117 142 160 133 149 151 147 122 148 134 124 125 145 139 139 148 134 145 123 153 143 126 141 143 156 151 134 115 149 154 124 136 135 157 161 173 113 136 129 137 143 160 151 139 163 136 119 113 142 136 145 155 148 129 139 107 134 149 164 145 141 147 148 153 146 131 140 140 135 129 162 122 135 139 149 131 128 127 126 127 134 146 149 113 139 133 125 145 168 112 127 126 120 138 155 131 147 137 144 135 147 120 127 141 135 132 135 130 123 154 120 144 160 126 147 141 141 137 156 133 142 149 154 125 149 133 131 125 131 139 115 146 131 146 140 121 143 128 153 130 154 154 128 155 126 150 150 140 135 145 147 135 138 124 129 122 161 127 143 161 147 137 133 134 141 133 142 142 159 134 130 134 132 130 125 147 138 129 135 123 130 137 150 139 142 129 137 142 157 150 126 142 125 137 133 134 133 141 138 130 111 129 131 134 133 123 118 137 147 108 151 129 162 126 123 131 133 137 138 152 123 147 140 134 138 137 130 127 161 136 125 114 117 144 108 152 138 141 125 132 133 111 119 126 122 140 137 137 109 136 140 129 136 116 158 134 147 128 148 116 140 132 112 143 138 156 142 130 130 133 129 114 115 144 149 133 132 136 148 125 140 142 134 134 119 121 138 131 125 126 128 134 141 159 132 135 127 143 147 120 116 135 124 122 129 138 135 144 141 129 131 142 117 128 149 129 140 107 129 152 126 115 141 143 136 105 115 118 140 139 138 150 120 120 127 135 114 124 140 137 139 131 135 116 108 143 138 145 141 121 156 115 144 129 136 153 139 130 134 123 132 132 136 132 129 136 126 137 130 130 131 126 113 124 154 125 137 105 134 132 116 126 152 129 146 132 130 146 138 148 131 132 124 147 129 141 145 122 128 95 129 140 123 141 116 127 120 118 143 153 150 138 131 132 129 129 131 125 138 124 127 137 133 130 113 133 131 137 148 130 141 113 149 135 141 129 151 130 146 129 115 132 137 104 103 119 130 139 120 125 132 119 114 143 140 154 139 137 117 125 147 126 145 136 139 113 126 135 125 130 106 118 153 147 127 130 112 126 145 129 138 120 128 136 119 136 137 119 132 135 144 133 122 143 121 129 121 131 113 130 120 144 146 132 113 126 126 139 138 164 139 106 121 146 116 134 145 125 123 134 153 151 147 139 129 158 124 138 133 129 139 118 127 134 128 135 134 147 137 119 122 127 131 138 108 117 128 117 144 134 118 138 125 128 130 127 110 121 119 152 142 118 133 147 113 123 140 121 119 165 143 111 126 131 153 150 149 139 127 144 144 115 138 126 130 156 152 148 130 122 127 132 119 130 149 116 144 131 136 148 131 115 145 123 141 131 131 129 141 159 135 143 133 135 152 133 137 136 113 129 133 135 133 141 135 129 142 149 128 128 125 141 159 137 127 124 128 152 144 130 118 121 134 131 134 137 130 114 146 164 119 132 134 135 126 132 121 152 139 140 129 132 124 150 149 122 145 125 135 122 121 130 142 131 125 133 141 138 151 134 147 122 130 152 125 126 120 116 142 122 120 122 140 133 127 124 140 143 133 151 131 149 145 156 133 144 138 151 148 138 104 118 126 128 135 121 143 144 133 140 116 129 142 117 139 124 149 112 142 146 129 109 115 127 140 161 141 119 140 142 132 155 150 137 124 132 117 121 143 127 136 143 137 121 115 138 130 132 132 142 130 146 157 147 143 120 135 139 132 148 159 121 128 153 134 132 126 140 104 114 135 138 168 116 136 144 139 145 120 138 137 121 129 117 133 136 135 115 136 138 151 129 126 131 127 121 124 151 141 125 136 123 119 110 147 149 141 133 117 127 123 154 135 136 127 159 123 116 135 124 128 143 138 147 144 119 155 132 152 121 112 143 116 144 124 107 129 124 151 143 137 117 118 137 131 132 121 129 131 125 131 154 124 123 129 141 105 137 117 144 141 126 117 136 149 156 154 141 151 117 141 115 131 148 143 152 127 115 122 138 155 126 121 127 143 139 124 132 134 118 134 140 122 143 142 154 126 122 142 141 128 127 139 130 127 143 134 142 143 127 136 101 146 137 127 136 141 117 132 137 119 123 121 130 133 116 129 123 136 154 144 124 137 149 145 113 136 113 135 135 138 140 144 125 113 138 138 156 128 129 118 119 148 133 140 139 137 147 126 154 160 114 128 140 157 124 141 125 129 148 133 115 120 137 144 131 147 146 156 126 157 116 125 130 152 133 139 137 153 117 156 147 117 134 119 136 118 126 130 143 123 123 143 157 157 147 138 141 147 129 154 140 138 137 149 147 178 128 130 117 153 119 125 131 132 155 143 120 133 138 133 132 156 133 143 118 133 143 145 148 129 142 139 129 151 159 143 130 130 141 133 166 122 144 138 153 142 132 124 146 149 148 121 127 119 136 121 136 121 123 110 145 133 122 134 151 141 133 136 135 133 118 152 152 155 140 133 112 147 122 126 145 153 144 149 115 143 134 149 134 151 143 134 156 125 143 128 145 145 114 140 145 169 130 138 142 132 140 126 128 137 147 159 127 125 128 131 151 128 154 122 136 145 132 140 149 133 113 128 166 132 123 137 131 126 145 144 121 157 141 117 130 134 162 125 149 159 126 139 143 149 133 149 131 131 127 118 124 130 141 139 121 125 146 134 134 163 142 137 145 147 152 130 131 145 140 148 149 142 149 131 139 152 138 143 140 149 138 125 126 144 145 137 153 162 136 149 135 122 126 132 130 144 144 137 139 121 141 129 153 140 141 129 129 151 130 131 163 165 152 124 156 146 142 113 134 130 153 129 142 125 138 141 139 139 131 138 147 137 143 164 134 129 150 138 142 136 144 148 111 144 144 131 146 156 126 141 147 130 146 145 149 140 127 148 135 134 150 147 145 148 118 138 152 133 149 129 148 138 142 123 123 150 141 152 140 128 140 144 147 141 172 151 137 138 148 129 148 152 142 134 127 152 135 158 133 126 161 155 142 142 165 133 149 149 141 162 143 129 126 141 137 160 128 134 158 160 132 149 139 142 153 137 129 137 161 152 153 163 142 157 148 147 140 169 158 158 172 159 151 153 164 170 160 164 169 161 166 151 157 145 166 162 173 157 162 179 155 161 159 178 177 156 169 183 176 187 183 183 202 205 186 181 177 203 185 178 195 205 199 198 246 224 225 230 264 235 237 225 269 257 269 235 238 241 258 265 240 235 239 235 237 209 210 222 220 204 216 215 200 194 177 187 190 187 196 179 152 194 176 149 154 181 179 162 162 189 145 178 139 137 172 182 164 173 141 142 165 161 180 152 173 123 140 150 152 157 159 144 148 158 134 157 180 146 144 145 150 139 146 142 140 154 131 157 120 132 161 138 134 142 138 146 150 154 142 153 147 161 136 143 131 144 122 143 150 141 126 162 126 118 134 137 126 127 153 145 127 152 140 127 133 138 151 139 154 164 148 137 144 137 144 128 132 150 153 143 175 153 136 119 148 143 151 150 140 131 146 127 145 122 142 136 128 132 145 155 123 152 130 140 148 150 141 126 118 137 144 151 149 139 136 135 129 154 135 117 128 177 155 141 149 156 134 142 153 148 143 150 162 130 154 151 125 124 153 160 151 149 136 135 141 122 130 151 126 126 132 129 137 145 141 127 143 139 152 145 134 134 127 145 151 124 146 131 127 139 128 142 142 136 149 151 165 145 135 141 128 163 151 155 140 118 136 138 139 131 125 145 140 154 133 124 132 149 155 136 119 132 143 123 143 138 133 159 123 137 148 148 136 112 142 115 129 147 125 122 159 145 148 135 138 155 132 120 138 114 141 142 132 166 149 151 136 139 130 146 138 144 139 117 154 161 135 136 124 145 139 115 138 138 124 120 145 135 166 164 125 138 143 128 122 149 144 126 124 144 137 139 122 140 128 132 116 154 126 123 159 143 122 180 158 137 115 165 121 147 172 152 151 133 130 110 143 125 126 149 139 127 140 130 142 124 116 153 148 136 138 154 143 118 146 134 99 129 137 142 151 145 147 142 132 126 124 140 136 125 149 136 130 151 128 131 138 127 151 142 136 158 123 148 139 129 133 161 135 155 141 136 133 125 146 136 127 149 119 135 153 134 130 158 126 139 140 150 154 154 176 138 138 128 136 120 130 157 138 144 150 125 137 145 144 141 128 157 157 141 144 128 156 131 147 146 130 138 154 122 127 148 131 134 139 148 141 128 131 123 135 107 148 150 117 112 133 133 119 125 154 134 132 140 143 112 141 155 163 135 126 122 145 144 150 144 147 151 130 134 152 133 136 134 148 158 127 129 141 108 154 122 142 126 111 128 160 144 147 129 125 131 138 144 134 149 143 122 147 119 150 140 141 146 133 142 119 138 150 136 125 154 165 123 126 147 135 147 148 109 134 127 149 150 125 119 129 145 145 150 131 135 130 132 136 160 133 132 151 144 127 142 135 154 151 142 145 138 158 149 140 119 158 147 137 128 143 158 139 145 171 122 140 154 139 161 133 143 166 132 138 130 143 149 138 139 137 144 127 155 166 145 121 145 131 150 156 131 149 142 149 155 147 139 153 146 119 139 142 130 124 138 137 137 163 141 153 124 158 124 142 130 111 135 151 125 149 136 135 135 138 143 154 139 144 144 141 129 128 165 148 124 132 141 124 129 150 132 132 150 133 130 137 147 121 144 133 122 131 173 143 143 143 148 122 133 129 143 150 143 156 127 133 128 133 130 142 125 124 136 136 138 137 149 126 131 143 148 155 159 143 134 149 147 133 104 125 156 129 120 120 146 131 146 134 142 132 127 150 152 174 148 152 145 136 136 153 135 134 137 143 136 142 123 136 125 128 148 137 145 119 133 121 129 132 147 141 129 143 143 153 155 141 144 149 138 131 157 152 156 131 151 137 142 143 152 154 138 160 143 127 155 124 139 151 134 140 149 124 160 137 126 129 137 134 156 129 127 150 137 140 146 149 140 122 140 131 156 138 127 148 160 119 132 150 127 138 155 134 151 144 153 129 140 132 141 133 144 157 175 122 143 127 139 141 126 136 140 125 144 125 153 134 141 141 138 150 134 139 131 120 136 143 117 144 120 134 153 158 136 130 145 145 138 137 120 120 140 140 142 127 122 126 128 130 149 158 128 159 124 162 132 143 128 145 132 137 147 134 151 126 144 125 132 150 112 143 151 132 130 143 148 157 122 134 148 149 139 162 141 133 148 132 152 158 143 130 135 166 147 156 125 138 147 138 143 143 145 140 134 157 128 145 137 135 151 155 124 144 152 125 130 133 166 128 118 141 143 128 136 141 152 128 146 155 131 130 106 134 133 139 186 137 113 144 144 149 166 129 136 145 161 153 131 149 130 143 140 150 162 126 141 131 144 143 150 151 124 117 123 138 138 153 138 134 140 144 119 158 151 131 144 147 142 149 136 147 154 164 138 154 145 113 167 135 160 153 161 138 135 156 136 138 150 139 149 156 137 134 141 151 143 118 139 159 124 149 134 146 132 143 160 135 125 139 146 154 152 137 125 142 161 141 153 134 150 130 116 135 136 154 120 127 141 151 132 132 152 131 161 130 141 143 168 117 131 124 134 141 129 142 161 146 138 156 153 165 165 162 146 124 148 146 144 126 144 131 124 120 141 152 146 136 134 101 141 156 123 162 146 143 131 153 162 164 125 144 116 151 133 142 141 130 137 159 128 139 156 145 155 150 153 163 126 153 144 122 144 129 169 160 154 154 125 138 146 138 125 144 141 146 145 135 147 135 170 150 134 164 121 133 113 138 144 140 141 145 164 126 149 142 136 133 130 120 131 134 133 135 126 161 151 134 146 119 135 160 158 164 142 145 145 155 136 136 141 139 133 137 149 140 129 134 125 145 144 153 145 150 155 152 136 122 177 131 168 135 134 126 153 132 135 126 136 146 150 158 132 160 125 140 144 142 152 145 145 162 140 148 138 144 138 144 119 143 148 168 140 168 155 120 135 134 132 150 147 126 131 139 139 144 145 131 122 131 156 131 138 145 154 143 158 148 133 140 139 136 150 143 134 138 149 146 142 131 142 141 149 140 121 141 139 122 146 151 133 168 144 157 146 136 154 146 163 129 137 136 132 142 147 147 148 109 135 134 137 137 151 169 144 156 126 146 155 151 151 134 142 143 143 153 146 116 169 127 135 141 135 154 145 139 136 153 153 143 138 149 138 150 128 146 146 142 146 137 140 142 149 142 156 146 142 150 146 151 142 131 142 138 177 146 144 132 174 150 127 130 137 146 156 134 116 151 143 129 156 131 144 131 136 147 140 127 144 136 156 133 129 137 159 186 147 141 159 139 158 153 155 148 150 129 153 150 145 156 119 141 154 124 169 150 141 155 153 158 131 127 154 147 139 133 133 144 160 159 150 153 125 142 169 132 152 122 127 139 122 133 152 146 160 133 156 170 163 127 144 138 146 150 144 162 171 127 162 150 121 135 132 146 172 152 143 138 145 148 141 134 147 126 155 148 142 142 142 117 138 149 160 155 135 130 124 138 136 135 138 139 135 160 137 121 153 147 162 148 130 160 141 136 149 132 150 141 147 138 149 138 132 150 158 136 139 139 138 152 144 152 143 163 132 147 146 172 123 155 138 130 144 147 167 134 126 143 152 146 152 158 143 154 122 155 134 147 142 129 158 137 141 128 149 144 116 155 139 147 141 134 127 151 146 140 149 138 141 149 150 140 157 133 160 143 159 163 129 135 139 151 150 146 121 122 142 144 150 123 151 143 131 145 147 147 149 169 151 144 153 153 151 137 150 150 147 129 135 150 167 136 161 132 145 132 133 131 149 142 186 132 183 133 145 169 159 143 175 145 158 144 165 175 131 153 157 158 143 161 177 135 171 155 154 139 140 147 148 152 141 156 138 168 155 149 154 118 136 137 139 163 165 145 158 155 144 150 153 150 144 146 154 136 143 162 158 133 129 134 148 149 140 127 127 172 149 177 140 162 150 142 145 143 115 150 148 139 118 164 138 129 142 148 153 147 165 148 145 152 130 148 155 132 157 145 159 139 136 156 143 145 138 148 158 122 151 144 150 164 133 143 152 135 128 145 147 134 129 130 123 165 140 157 165 142 140 145 162 153 173 123 159 135 153 143 165 149 154 163 145 150 135 159 136 150 142 127 167 149 137 145 151 139 159 128 125 136 168 139 151 139 143 139 133 160 148 135 156 164 148 152 146 155 144 137 167 133 151 152 131 162 158 166 127 161 128 142 140 145 138 147 150 136 125 170 134 154 139 141 126 153 159 161 166 137 140 149 131 156 154 149 146 153 138 127 137 143 154 153 165 142 152 147 144 140 157 154 142 111 128 163 158 156 139 126 174 138 164 147 155 154 153 170 130 145 150 141 131 156 140 157 139 127 133 172 138 133 159 142 156 131 134 169 143 135 137 144 145 165 145 149 143 146 168 145 157 127 136 168 156 152 162 141 133 138 171 144 143 149 145 139 148 183 146 140 162 180 143 183 144 144 138 157 129 138 128 142 143 137 151 135 154 163 136 175 135 146 159 133 174 170 159 150 143 158 152 153 162 143 146 146 152 148 165 139 135 137 157 155 156 146 146 149 133 149 123 155 151 150 156 133 139 138 142 155 119 135 168 127 146 155 150 146 145 150 156 154 146 156 161 141 178 156 151 156 176 157 151 150 132 162 148 148 148 154 140 146 164 148 154 151 160 162 173 155 142 139 147 143 157 130 136 146 154 135 143 160 135 151 164 159 149 148 152 131 135 132 171 162 161 143 161 165 150 142 157 158 147 163 128 161 157 156 165 149 165 137 132 173 162 149 172 168 151 169 150 157 157 164 141 155 145 161 155 134 153 161 154 164 162 166 149 158 142 155 143 164 166 169 148 147 184 163 146 152 163 164 157 158 147 160 166 170 156 155 149 163 159 161 134 160 155 160 162 149 151 152 125 142 151 137 163 160 169 143 170 150 138 163 148 166 163 154 147 134 145 139 140 160 148 179 157 126 137 132 149 170 183 155 126 139 155 161 163 144 138 145 130 137 165 148 132 152 152 157 163 138 160 150 155 159 144 150 131 148 133 137 149 135 143 148 138 145 142 161 141 161 133 149 145 157 127 170 148 158 146 144 146 162 138 143 144 159 145 158 132 151 157 150 145 149 141 140 165 159 132 159 151 154 146 147 132 147 172 167 142 169 161 166 157 159 157 151 148 154 157 138 161 135 160 134 138 151 142 161 164 156 143 160 161 153 166 143 134 158 148 188 145 165 163 130 144 134 158 149 155 151 158 145 160 154 127 182 139 145 139 143 127 143 153 150 137 156 158 142 142 138 152 154 147 143 148 153 149 132 166 141 152 154 150 131 149 138 136 140 162 159 133 124 150 132 150 145 132 154 155 143 145 138 158 157 164 159 126 166 152 163 148 133 142 139 146 162 141 164 144 141 150 147 140 155 118 142 130 142 134 139 166 153 169 157 142 130 158 157 114 140 153 126 157 140 135 138 135 171 142 143 138 146 152 153 150 132 137 144 150 159 167 131 144 156 126 139 153 135 152 158 134 129 158 127 168 154 148 136 146 148 146 149 151 163 139 158 156 150 124 157 156 150 148 140 142 147 135 150 137 159 170 170 139 144 154 170 133 138 140 157 139 163 173 145 128 155 157 122 135 157 153 159 108 159 134 129 140 146 155 165 160 185 169 172 141 143 149 145 147 126 143 122 130 136 160 146 158 148 162 140 147 155 152 149 151 136 154 142 155 167 163 138 146 157 140 139 174 160 146 156 142 155 139 143 140 155 135 135 148 154 143 154 153 166 129 139 156 145 144 133 158 110 142 146 145 141 137 140 139 112 140 141 173 142 152 169 147 138 172 139 147 129 133 133 134 159 148 161 136 147 143 160 152 148 145 149 139 152 170 161 180 136 151 133 147 142 160 122 167 152 136 137 162 145 141 148 155 151 145 151 124 177 170 173 145 152 135 144 138 152 145 154 147 141 154 146 144 147 155 167 156 143 146 134 151 170 151 150 140 115 143 141 164 161 160 148 124 139 152 151 138 147 144 143 153 128 126 154 150 141 155 141 132 149 146 138 161 139 147 126 153 161 131 140 138 149 137 156 162 133 157 136 138 148 137 179 181 165 134 161 140 134 151 142 162 141 142 131 161 150 156 143 139 134 165 144 155 155 150 151 141 139 158 156 116 138 146 158 122 147 162 138 132 165 152 139 157 135 156 155 145 161 124 132 172 160 120 149 134 152 155 141 171 143 168 148 153 130 138 150 136 124 154 153 134 141 139 159 126 164 162 148 138 133 144 142 151 136 137 157 172 151 160 120 134 137 153 130 133 133 143 161 125 147 167 155 144 126 145 116 175 151 160 132 166 166 152 148 132 161 155 153 155 150 123 139 132 152 147 150 151 151 153 166 154 151 125 152 138 140 143 151 160 132 152 148 138 120 136 152 152 141 154 137 145 146 158 136 136 160 161 155 145 139 117 140 133 163 125 173 152 148 141 131 167 133 164 145 146 138 144 164 155 168 169 158 150 152 155 139 149 153 125 132 159 146 156 163 156 145 128 147 139 148 144 150 138 143 160 124 125 143 145 146 147 141 150 158 153 155 139 139 146 144 156 130 149 142 138 162 136 118 137 170 123 144 164 136 137 169 145 146 138 133 147 162 147 150 142 148 148 126 148 137 133 154 154 160 152 144 141 155 152 148 154 154 137 131 139 144 153 150 152 156 146 149 144 155 147 153 139 137 139 155 137 149 151 160 158 128 174 141 157 136 144 144 150 146 151 140 172 153 141 156 142 162 169 160 171 127 167 154 151 151 151 130 137 173 140 150 140 134 161 137 148 143 154 158 146 138 133 115 155 133 143 154 160 167 149 131 138 152 146 134 148 141 150 141 161 142 145 146 164 149 147 164 132 137 146 126 139 161 145 133 167 119 129 137 155 152 150 140 154 140 136 127 146 146 138 146 154 133 134 149 132 150 173 163 147 139 136 155 158 142 155 135 145 142 126 159 159 156 157 147 136 137 154 158 145 173 143 148 135 144 154 164 157 132 139 144 152 157 152 142 153 145 159 156 138 143 152 148 171 156 128 162 153 173 146 149 166 156 145 152 141 156 137 142 142 157 142 177 151 138 149 170 151 139 132 161 134 146 147 138 162 171 187 135 155 155 139 150 156 141 174 151 127 136 155 145 142 123 149 146 161 133 149 156 153 154 139 154 145 166 138 130 153 143 142 133 148 156 150 129 122 165 142 144 143 154 161 151 140 146 147 138 155 148 138 147 141 135 142 130 152 178 145 158 145 160 145 144 154 150 154 131 157 155 141 159 154 157 154 145 149 134 150 128 141 143 135 136 163 142 142 146 140 141 160 164 159 151 146 151 153 155 130 156 141 133 162 164 129 158 137 165 142 166 161 143 148 148 159 147 135 135 127 162 142 149 141 133 161 140 150 145 155 174 159 149 119 125 156 148 146 147 140 138 140 162 143 138 128 162 156 138 149 135 158 179 157 137 160 141 152 136 132 156 152 136 145 133 140 151 139 150 137 150 148 131 144 123 145 145 137 139 134 138 136 126 122 139 162 139 138 145 158 178 140 128 149 138 142 142 147 136 143 130 140 151 140 146 149 147 160 165 154 141 127 131 152 131 154 154 148 140 131 143 135 131 155 142 109 154 153 146 145 161 138 144 166 137 137 155 170 132 137 147 145 152 161 129 155 155 149 148 156 153 170 152 135 148 161 147 143 143 140 135 127 135 124 155 144 158 146 129 149 148 146 152 143 148 164 150 136 133 145 156 145 138 137 162 125 158 146 156 161 148 130 153 151 143 131 116 143 118 169 139 156 139 158 159 152 170 148 140 153 156 147 129 134 158 149 159 140 137 128 146 131 134 175 140 155 125 163 137 146 144 147 139 141 125 155 125 137 145 157 167 153 139 146 137 141 128 145 152 162 145 143 148 141 155 134 150 134 148 153 152 144 139 160 135 135 167 144 168 136 136 149 158 146 128 148 154 133 130 156 132 139 127 139 131 138 135 138 169 138 158 158 140 142 161 143 150 143 144 157 147 120 159 159 140 149 159 145 146 159 144 157 135 126 156 133 146 147 153 162 120 147 128 141 137 140 143 149 136 159 156 160 148 139 137 155 152 139 141 114 126 145 152 139 134 171 153 131 161 146 147 148 145 151 128 140 132 142 136 157 130 146 134 151 130 156 151 147 141 132 114 175 136 137 165 161 143 148 136 144 140 160 158 159 146 128 163 145 138 162 137 150 135 129 136 147 156 153 157 135 153 150 147 129 141 158 176 125 138 124 139 151 162 147 136 160 158 132 165 147 137 142 144 129 135 127 127 142 160 135 129 160 171 150 155 163 130 150 139 149 158 143 144 150 129 142 144 142 130 136 164 134 124 138 135 123 149 145 144 144 153 167 144 162 158 132 163 155 168 146 156 158 128 168 154 145 136 158 153 111 148 147 173 149 139 144 144 149 123 154 131 154 169 153 159 146 132 139 140 170 159 137 164 135 132 145 144 137 129 122 150 170 127 165 122 146 134 167 142 156 136 148 142 150 162 148 148 143 164 126 151 134 160 177 148 147 143 154 149 139 172 155 145 150 149 124 144 152 154 141 154 169 152 141 139 141 135 159 170 145 144 141 190 155 158 156 138 175 134 176 149 141 155 156 172 163 154 153 162 161 159 149 146 145 154 148 143 130 158 152 143 174 156 150 163 154 151 153 157 172 164 168 145 157 120 172 164 149 157 143 156 143 161 187 163 149 161 156 160 169 140 159 156 168 176 170 161 161 156 171 156 154 159 184 162 155 172 162 146 192 166 152 157 151 176 171 168 155 173 158 174 162 154 155 154 159 167 141 163 176 168 165 164 160 177 147 171 132 172 160 138 148 168 148 144 151 164 148 157 191 144 145 163 147 132 150 143 161 149 160 134 172 157 156 149 148 141 144 120 150 173 142 143 135 143 138 134 162 155 154 138 143 135 131 155 145 153 172 152 148 144 152 167 156 128 142 148 173 142 158 146 122 129 141 141 155 145 145 139 157 157 127 125 133 137 167 118 129 167 140 141 135 142 142 147 129 153 138 149 150 133 134 151 129 146 146 134 129 166 149 132 167 148 161 153 166 144 153 137 141 139 153 143 141 144 153 142 143 138 143 139 129 148 157 146 152 174 123 146 133 146 159 144 131 135 156 160 160 142 176 125 159 140 133 144 129 162 121 154 141 147 136 136 129 134 165 136 128 144 163 137 129 145 174 117 141 139 135 162 140 132 159 164 136 145 174 156 151 123 125 140 130 144 142 139 162 136 159 165 141 142 161 162 145 137 156 140 120 139 134 149 148 144 141 142 137 156 150 150 141 171 139 145 139 141 159 158 139 144 123 140 146 143 144 128 125 157 126 161 136 165 136 139 161 160 148 128 159 159 148 149 127 136 130 134 150 142 161 160 158 138 138 144 142 132 147 145 131 156 138 134 150 156 133 155 148 133 146 144 152 152 144 141 137 146 152 153 154 114 130 145 136 131 135 144 148 133 136 122 138 139 148 152 136 147 122 135 146 129 135 145 141 157 137 161 174 159 128 137 144 120 120 139 125 144 149 130 130 155 133 173 158 148 156 147 139 145 133 142 131 144 128 155 138 129 135 125 130 145 167 114 125 150 134 143 146 135 132 159 162 138 156 121 111 156 143 163 137 148 146 158 147 131 125 138 144 148 142 145 152 133 156 173 138 150 142 149 160 144 134 127 133 147 158 132 123 128 168 140 152 138 155 164 156 129 154 131 135 119 146 138 150 133 140 133 130 144 144 144 139 121 161 144 160 155 123 134 159 139 142 124 155 150 128 148 145 138 149 131 146 120 134 132 145 163 131 164 141 139 134 128 131 150 134 158 143 145 150 137 150 157 135 155 147 161 119 148 158 112 142 138 142 146 135 143 135 137 135 128 125 141 152 126 159 138 140 141 140 137 139 142 153 153 137 146 149 142 137 151 132 159 146 139 133 175 144 122 135 144 165 140 132 136 129 133 122 147 138 136 151 141 142 144 147 154 142 142 131 139 141 133 152 155 129 132 140 160 146 120 122 153 142 119 146 149 147 158 132 135 148 139 148 145 144 138 145 120 133 141 156 142 144 158 142 125 132 126 130 173 136 140 164 134 134 130 146 125 161 146 129 151 130 144 126 139 139 151 136 144 155 150 148 139 136 135 131 146 144 141 162 124 129 143 134 133 125 148 130 155 134 149 138 155 143 139 137 128 149 134 147 148 132 135 147 126 150 121 159 135 141 150 132 131 129 136 157 146 140 157 152 168 157 122 157 148 147 146 135 137 126 147 142 140 134 156 176 170 133 117 125 143 114 151 144 164 139 142 161 142 147 111 144 135 136 127 120 133 151 150 140 144 136 127 143 136 154 140 137 162 132 171 145 150 137 135 122 126 145 141 132 151 156 143 136 124 142 145 139 146 127 157 137 152 145 137 165 143 134 144 168 145 120 124 119 151 121 119 151 155 132 137 118 132 149 133 155 133 132 167 137 149 129 130 137 133 148 132 143 151 142 156 120 138 139 151 114 146 147 134 143 147 142 122 130 157 142 143 129 150 141 143 147 135 144 163 139 131 124 156 134 131 142 133 150 149 144 180 143 155 149 152 134 125 146 157 147 144 146 157 139 147 123 144 137 162 160 149 139 169 127 138 143 127 150 154 143 136 126 149 143 145 138 149 150 129 147 165 151 142 153 146 137 145 136 125 134 137 159 140 146 136 139 152 155 138 142 126 154 145 134 153 146 160 145 142 148 137 136 159 123 129 149 118 152 136 128 132 152 159 168 149 122 141 134 145 137 130 128 131 153 140 150 142 167 133 141 156 151 148 126 164 165 150 127 135 147 139 124 141 144 171 144 144 161 130 137 123 140 143 146 134 136 144 138 134 136 159 135 143 139 142 144 178 145 145 151 118 147 141 135 166 154 146 144 133 146 155 135 168 124 166 127 159 122 135 151 135 132 127 141 121 136 156 131 119 155 128 132 154 165 136 140 132 131 139 135 164 140 135 154 123 157 147 131 137 145 142 139 144 142 172 134 156 133 157 127 137 131 159 131 151 137 135 133 134 141 160 150 113 127 149 150 131 126 145 126 149 148 120 132 144 157 150 143 138 148 160 135 138 143 163 126 139 147 157 146 158 149 145 128 124 134 131 121 135 154 140 144 165 142 143 129 144 142 138 130 149 156 153 147 119 155 139 140 172 141 169 135 131 157 141 113 130 161 141 136 142 138 144 152 120 141 130 163 140 134 153 148 166 147 137 125 138 153 124 159 153 153 133 160 121 144 149 143 133 145 148 132 146 148 142 150 141 133 156 130 160 162 144 128 131 151 152 142 113 134 150 142 147 141 121 139 157 147 129 145 140 138 137 137 144 143 154 135 127 135 130 149 134 131 144 151 134 125 136 155 142 146 119 141 149 119 135 136 138 156 144 177 137 147 124 141 143 144 152 162 132 152 145 151 173 135 159 121 133 151 137 137 155 126 150 159 137 156 131 148 134 158 151 157 138 118 151 142 139 145 147 152 128 158 138 150 131 146 133 130 141 152 154 143 126 145 173 172 164 165 135 117 140 136 137 153 141 145 146 151 148 149 133 131 139 160 193 157 149 127 167 133 157 165 136 136 144 145 139 148 127 164 134 141 144 137 148 130 139 137 141 159 144 145 130 146 135 156 129 143 148 130 162 136 140 150 155 134 138 137 152 130 144 171 147 152 153 154 148 138 146 143 137 157 135 140 146 130 138 153 148 135 155 139 135 154 122 141 160 138 139 130 178 140 159 146 143 115 148 148 143 142 135 127 147 133 159 141 132 158 116 136 143 123 146 143 152 129 142 159 153 107 143 133 135 145 150 147 141 144 139 149 130 154 142 131 139 143 160 141 144 147 150 125 125 161 110 132 142 161 129 169 147 133 143 137 132 140 154 167 142 174 174 154 143 158 138 148 150 152 137 140 157 145 123 123 142 146 151 124 158 140 137 128 142 141 161 140 148 132 138 135 166 159 124 130 170 129 159 133 133 133 139 137 138 121 142 143 140 153 151 144 135 143 150 133 148 135 127 139 120 154 136 144 137 123 136 141 131 135 139 117 145 146 140 142 152 123 138 146 154 148 142 121 137 128 141 169 129 135 154 123 147 136 153 138 155 152 150 143 129 148 121 166 157 149 150 136 153 135 136 129 123 166 138 135 155 138 152 142 124 124 154 138 145 133 168 127 157 130 135 156 154 158 141 127 141 152 151 142 150 164 149 146 151 132 158 148 149 148 157 149 113 152 152 157 141 145 144 152 153 160 155 116 118 138 135 149 134 144 149 158 143 160 132 147 135 153 160 154 143 137 168 142 128 126 159 155 151 135 122 127 150 169 136 162 147 140 143 127 148 147 153 148 143 145 149 150 143 118 134 155 134 145 127 152 144 130 143 160 147 152 131 153 156 135 129 158 160 144 174 136 150 136 150 148 150 129 179 151 167 132 155 151 156 143 148 142 112 179 147 151 130 138 154 153 182 157 176 137 153 152 137 150 151 152 152 143 179 158 141 129 134 131 156 165 146 145 144 143 158 149 145 148 146 157 135 164 169 131 169 145 149 142 141 153 152 149 173 160 140 160 160 160 133 157 133 139 153 157 158 134 125 132 133 149 137 171 166 141 155 119 148 156 148 167 153 139 145 153 146 135 141 152 162 143 152 148 132 153 137 162 158 156 128 140 152 130 147 136 163 149 167 167 145 135 146 142 151 137 134 149 168 141 154 155 150 129 139 144 135 160 149 131 164 141 142 157 131 170 155 141 146 151 123 132 126 161 159 150 145 146 145 151 158 136 110 133 134 131 135 140 173 138 146 128 135 153 149 154 142 134 162 134 122 124 138 150 152 132 144 153 152 197 161 134 134 125 135 152 144 146 153 146 141 136 124 161 150 143 131 145 162 116 138 134 143 158 128 160 152 142 142 149 141 129 140 152 153 155 161 125 146 112 141 131 122 145 154 154 149 146 123 129 125 131 145 133 150 149 145 140 143 151 153 156 126 135 111 139 141 146 158 143 134 130 152 154 137 156 126 163 129 146 147 140 144 147 148 130 148 147 138 143 147 122 137 134 168 150 126 135 141 135 139 132 142 154 139 141 137 135 143 155 145 132 144 116 163 136 136 143 138 144 157 142 131 123 151 121 154 142 129 151 154 123 135 155 157 177 154 132 149 133 149 141 139 135 135 129 145 146 128 136 147 144 152 149 141 147 120 140 137 157 162 139 150 140 134 144 148 142 123 141 171 142 137 165 140 141 166 138 137 159 152 148 151 159 144 134 151 146 138 144 147 159 110 146 138 145 125 148 163 125 135 137 148 152 126 148 158 166 132 139 131 123 141 132 149 146 143 170 152 126 153 127 134 147 132 128 153 136 150 147 145 158 151 126 144 143 151 148 148 161 128 140 129 127 131 143 117 127 142 142 145 135 168 149 146 130 148 156 130 149 127 139 134 132 163 135 140 150 133 123 161 141 150 156 153 147 153 117 148 150 138 165 162 155 150 136 131 137 136 152 152 149 143 150 143 135 147 144 152 150 148 141 149 135 166 160 165 153 154 138 149 161 136 146 159 152 147 144 132 167 160 132 148 144 150 142 144 143 130 140 133 152 142 137 137 152 178 155 161 123 149 150 178 133 132 133 147 143 140 136 142 145 151 155 145 131 159 151 124 151 138 149 146 122 134 147 129 132 159 140 144 159 149 173 141 138 133 133 149 123 126 142 145 143 141 166 127 162 141 119 147 111 134 128 140 144 154 129 153 157 140 141 158 170 136 149 120 142 157 167 152 162 142 139 135 131 131 159 145 168 141 139 132 148 131 131 125 161 137 143 155 134 154 141 142 142 159 153 131 134 139 141 135 150 149 134 138 161 145 138 148 126 131 137 131 137 144 138 155 164 142 148 140 130 144 126 173 156 153 143 127 130 146 147 153 136 146 165 130 166 152 125 139 140 157 147 136 181 136 139 158 158 141 156 180 149 131 136 141 147 132 139 149 150 134 121 142 155 147 150 164 139 143 149 139 162 151 145 126 149 136 161 128 130 153 133 151 152 125 138 152 118 139 153 152 147 151 144 158 130 148 159 151 148 134 130 126 138 155 133 137 158 159 149 156 140 160 129 152 130 154 131 145 147 151 136 132 134 130 158 156 140 134 176 149 140 141 127 138 129 131 154 153 149 163 149 146 140 145 123 148 113 155 136 186 161 139 157 146 154 141 150 146 151 129 144 167 153 157 154 141 135 137 147 126 137 156 131 134 147 126 135 144 133 141 160 139 138 127 141 182 136 141 135 147 141 148 151 138 154 149 146 158 135 147 133 137 153 140 148 156 155 127 150 161 142 129 139 146 147 158 165 139 151 165 136 154 142 147 129 138 139 146 143 141 139 129 162 119 136 135 137 129 143 157 145 144 137 126 123 141 125 135 126 144 149 139 127 154 137 129 128 146 143 143 135 154 140 149 143 143 144 159 147 146 144 154 150 134 127 113 127 130 142 160 145 150 133 127 125 159 143 141 134 134 142 161 117 127 152 179 131 134 136 139 133 148 141 160 149 149 131 142 161 140 130 141 135 138 135 149 151 147 148 157 155 150 136 133 136 133 126 135 146 159 165 143 156 142 139 159 150 140 140 150 165 146 153 156 138 143 122 136 146 156 116 148 157 130 151 143 148 147 144 130 147 157 140 155 157 143 163 141 111 145 153 129 135 130 150 143 128 141 150 143 164 147 132 143 132 135 152 151 148 147 144 154 152 121 150 136 152 149 135 137 132 144 133 140 161 124 112 142 163 136 142 119 137 149 133 134 156 144 146 146 134 156 112 141 129 144 152 141 120 138 142 147 121 123 146 127 146 149 162 149 139 122 161 130 155 161 138 137 132 162 166 114 132 149 117 130 146 142 144 141 136 165 143 150 122 162 145 151 126 137 132 138 155 157 146 131 153 151 136 134 136 154 121 151 157 149 133 146 123 142 142 133 139 158 133 136 136 143 129 169 134 147 147 130 163 150 145 148 134 147 126 129 144 132 149 146 125 110 146 154 143 145 150 153 151 134 157 131 132 163 154 116 160 125 156 148 139 149 139 164 133 160 138 161 151 117 144 143 120 150 142 140 143 122 160 164 178 128 135 141 126 154 121 120 133 157 129 146 124 154 136 150 137 153 127 145 129 139 142 155 148 110 132 114 154 122 153 145 152 151 124 136 158 142 161 130 139 150 157 118 148 143 141 163 151 137 168 136 128 138 147 166 133 127 137 131 156 131 143 152 123 142 121 146 151 164 121 174 138 145 158 150 139 137 138 138 124 127 131 132 127 123 141 152 156 128 150 150 130 131 117 138 132 142 138 156 141 152 159 120 146 119 157 129 161 127 161 126 155 144 138 144 148 140 144 145 130 131 136 135 133 160 135 152 161 135 139 136 149 148 139 138 124 141 122 139 149 152 138 139 131 130 106 141 140 139 141 150 145 148 142 132 157 112 147 122 140 141 144 133 146 152 150 143 136 159 125 140 141 146 147 143 154 117 147 154 152 120 151 141 147 125 116 134 158 135 140 110 141 137 150 131 141 140 167 161 139 153 134 148 133 138 156 134 136 142 162 150 137 137 151 154 151 139 139 141 151 166 138 127 161 140 144 122 149 149 104 146 146 117 156 135 139 159 115 135 147 171 141 120 147 153 132 148 152 135 144 149 149 131 121 146 125 122 147 165 145 136 116 139 127 157 150 147 149 141 143 173 134 149 148 143 133 161 121 161 143 135 139 158 152 118 147 141 135 166 137 134 140 142 143 160 141 116 145 154 152 133 143 147 116 138 147 144 148 133 136 120 152 173 137 150 149 156 126 149 145 149 144 142 128 151 151 131 135 156 153 143 143 141 147 140 125 141 130 160 151 147 142 132 150 130 146 131 127 146 155 153 145 130 131 139 132 148 129 167 124 146 139 124 139 148 156 152 147 129 147 143 141 163 151 143 145 147 161 136 141 147 173 135 125 127 140 135 130 149 136 129 164 142 143 140 128 134 149 150 121 121 143 137 154 137 117 152 151 115 145 163 124 162 149 146 144 147 151 145 134 145 150 143 157 123 128 128 133 118 144 153 138 150 114 147 139 140 138 140 166 144 131 140 139 135 138 155 126 145 161 147 139 139 120 123 150 151 137 131 141 139 142 123 137 140 149 143 146 146 135 172 153 155 119 122 155 146 137 155 132 138 151 143 130 154 166 169 136 141 137 131 140 135 135 122 143 156 166 143 151 134 166 128 141 143 140 165 162 161 139 144 144 132 132 162 151 139 161 143 156 119 129 134 156 160 122 149 120 143 151 150 139 123 133 156 133 151 150 138 165 138 156 147 128 131 143 144 148 170 142 141 147 137 160 167 151 122 134 129 117 142 149 128 147 130 138 151 155 172 132 148 140 139 148 143 147 174 146 154 142 164 140 145 151 150 168 145 125 138 143 137 127 150 158 147 163 136 146 139 153 144 153 141 134 158 142 127 176 156 138 152 128 144 150 153 133 142 140 151 139 164 132 132 116 122 139 160 157 133 148 145 151 157 167 142 159 135 159 158 147 142 133 163 147 143 151 140 128 154 152 135 136 170 150 149 125 147 163 137 134 140 164 150 138 136 161 142 154 147 161 145 144 138 134 164 168 138 126 134 141 140 154 149 144 154 147 134 135 162 142 153 156 134 158 113 116 137 163 156 155 141 144 163 136 130 147 140 133 143 158 117 155 157 137 150 168 134 132 144 132 123 155 142 165 138 135 143 147 133 136 157 130 142 131 132 148 149 125 117 176 143 136 145 165 150 138 152 127 167 130 129 146 133 141 152 161 153 112 125 137 130 156 140 144 149 132 152 132 145 171 144 131 145 159 158 120 152 138 134 148 154 163 142 151 137 155 159 130 112 147 139 145 148 136 139 148 130 145 128 147 149 142 136 116 160 150 150 146 148 138 148 148 123 138 134 116 130 144 139 134 147 129 135 140 157 149 145 139 142 149 132 162 129 157 121 172 156 129 129 153 150 153 151 136 131 137 138 142 137 157 125 169 133 156 124 147 136 146 120 152 133 137 144 131 139 147 152 142 131 141 130 146 144 123 151 154 119 154 167 128 153 152 136 149 153 134 143 137 172 162 122 141 144 131 128 132 150 150 162 147 149 143 140 112 132 135 138 167 137 131 147 159 145 131 133 150 135 153 157 132 157 139 143 134 140 137 128 127 130 147 169 144 143 147 151 138 153 152 141 140 147 148 140 142 127 121 140 158 149 164 154 113 134 124 120 136 148 130 144 152 148 146 115 150 145 163 143 153 142 139 132 145 141 128 133 156 150 170 143 151 133 138 146 155 122 161 142 122 141 133 158 161 124 132 163 141 144 150 137 150 119 147 152 142 143 142 120 142 117 151 134 149 130 146 148 152 133 153 150 138 124 145 143 126 150 142 124 155 136 150 132 157 155 164 143 131 141 129 147 128 144 157 161 140 139 145 144 162 120 147 124 165 128 149 134 161 160 145 133 145 125 129 157 146 165 131 148 142 167 147 138 153 125 130 137 136 142 155 143 119 147 148 141 140 144 148 151 133 141 159 141 141 155 137 146 152 139 133 139 135 151 158 150 120 122 137 145 132 115 124 154 156 149 146 144 145 166 138 141 140 123 140 154 162 131 136 162 126 123 111 145 130 156 158 129 146 135 149 130 140 154 156 151 156 127 122 129 144 134 134 135 151 151 145 144 153 132 138 139 142 147 153 127 149 144 147 138 141 131 131 139 133 128 140 145 130 145 154 140 144 142 135 160 153 125 142 123 145 165 130 143 143 139 141 152 132 154 136 136 123 124 145 129 132 145 139 141 137 131 128 145 147 110 129 110 151 150 136 130 151 150 133 142 128 160 154 125 138 143 124 135 154 138 152 137 131 146 137 114 126 144 134 152 138 129 127 135 134 149 130 153 139 136 140 141 147 137 147 149 144 137 142 135 129 124 131 143 146 165 161 125 149 128 139 142 145 154 145 137 141 142 150 111 138 156 140 144 129 154 141 144 143 162 138 146 129 130 141 130 157 148 157 158 141 148 130 154 115 144 152 152 130 153 149 136 153 133 144 133 153 138 124 136 144 144 136 142 141 124 148 132 128 140 139 149 138 137 166 148 159 131 132 146 118 131 151 133 126 124 146 152 121 141 154 150 151 155 139 137 140 133 143 143 132 149 130 143 133 143 155 148 121 168 138 157 149 132 134 150 158 139 151 150 139 137 113 140 130 158 142 139 132 161 155 151 142 150 138 150 118 122 149 126 147 146 140 137 133 121 144 142 128 145 127 149 133 138 140 130 128 142 122 122 141 140 119 141 160 157 135 129 137 154 142 132 149 171 159 159 150 151 143 135 128 119 148 137 146 130 113 145 138 132 145 136 143 143 151 113 159 144 148 158 160 141 141 125 153 129 128 145 130 166 151 137 149 119 151 146 150 146 141 131 160 145 156 155 168 134 119 149 133 145 148 122 150 141 141 158 141 132 136 148 154 129 138 161 137 138 169 145 138 151 129 160 154 140 162 152 149 139 152 140 133 119 147 150 152 144 140 145 141 130 149 125 148 143 123 142 140 145 146 136 153 138 153 147 153 122 141 141 152 145 148 132 154 136 142 146 146 155 138 138 152 132 140 147 148 145 128 129 141 144 133 140 147 132 132 126 135 141 125 128 126 144 142 142 165 152 138 144 141 152 126 145 170 128 159 155 157 129 139 152 150 138 123 175 144 147 130 140 150 155 142 144 151 134 156 126 134 161 159 147 135 145 142 151 153 142 139 159 150 141 142 161 124 150 135 168 137 145 137 149 123 126 164 131 149 148 143 136 149 138 129 149 152 145 145 163 153 154 160 147 145 146 137 159 131 142 161 157 104 123 126 144 118 133 138 144 129 144 139 149 145 156 137 147 136 152 153 160 155 133 141 152 143 137 133 147 154 135 133 152 138 143 147 145 150 138 128 132 150 156 153 140 145 150 162 136 134 164 131 135 173 147 144 133 134 164 149 157 157 146 133 144 139 155 160 154 145 123 161 120 122 152 160 152 144 147 128 162 139 131 130 179 162 155 144 146 141 122 147 147 158 154 136 149 143 145 150 139 148 153 164 146 151 147 149 154 138 136 154 144 149 136 144 141 141 137 129 138 143 140 163 135 145 113 144 138 165 162 132 136 136 116 161 154 150 125 141 138 146 171 142 140 137 156 142 138 135 150 130 153 125 162 150 139 144 145 150 160 168 130 145 142 137 144 145 159 125 153 160 150 143 130 127 136 167 146 134 141 147 133 144 168 162 122 151 165 151 141 131 129 168 138 138 131 148 163 145 166 136 120 160 154 133 148 147 140 140 157 148 152 153 138 153 153 173 161 123 158 157 151 136 147 148 131 159 144 159 156 143 155 173 169 163 160 148 140 129 148 155 151 144 119 143 138 157 132 137 158 146 154 144 140 156 157 124 149 158 142 154 143 146 141 171 139 148 154 156 153 151 169 159 161 129 133 152 142 144 133 127 156 164 141 146 155 138 139 158 138 149 162 145 144 144 142 144 158 142 156 168 152 162 153 140 155 150 158 155 148 146 139 128 149 154 135 170 147 171 146 137 161 137 144 135 111 142 155 161 134 142 151 153 150 142 150 151 160 156 155 146 143 139 135 151 148 121 154 168 138 138 138 144 133 131 137 166 153 164 146 146 136 174 126 160 134 137 143 142 147 139 147 146 148</counts>
			</dataPoints>
		</scan>
	</xrdMeasurement>
</xrdMeasurements>