File: data/XRD/_misc/old/XG-600C/_absolute_2th-om_10-100deg_PIXscan_8min_1.xrdml
<xrdMeasurements xmlns="http://www.xrdml.com/XRDMeasurement/2.1" xmlns:xsi="http://www.w3.org/2001/XMLSchema-instance" xsi:schemaLocation="http://www.xrdml.com/XRDMeasurement/2.1 http://www.xrdml.com/XRDMeasurement/2.1/XRDMeasurement.xsd" status="Completed">
	<comment>
		<entry>Configuration=Factory configuration, Owner=User-1, Creation date=7/8/2013 4:01:53 PM</entry>
		<entry>Goniometer=PW3050/65 (Theta/2Theta); Minimum step size 2Theta:0.0001; Minimum step size Omega:0.0001</entry>
		<entry>Sample stage=MRD Cradle; Minimum step size Phi:0.01; Minimum step size Chi:0.01; Minimum step size X:0.01; Minimum step size Y:0.01; Minimum step size Z:0.001</entry>
		<entry>Diffractometer system=XPERT-PRO</entry>
		<entry>Measurement program=C:\PANalytical\Data Collector\Programs\Clemens\2theta-omega\_absolute_2th-om_10-100deg_PIXscan_8min.xrdmp, Identifier={00DFCB65-BA93-4D94-A0AE-F2C5E880D205}</entry>
		<entry>Batch program=C:\PANalytical\Data Collector\Programs\SimonL\batch1x_2thom_10-130°_z9.1_x0y0_57min.xrdmp, Identifier={C4A964FD-AE47-4955-93AF-5095CB3C4D5C}</entry>
	</comment>
	<sample type="To be analyzed">
		<id></id>
		<name></name>
		<preparedBy></preparedBy>
	</sample>
	<xrdMeasurement measurementType="Scan" status="Completed" sampleMode="Reflection">
		<comment>
			<entry>2theta-omega 10-100 deg PIXscan 13min</entry>
			<entry>PHD Lower Level = 4.83 (keV), PHD Upper Level = 11.27 (keV)</entry>
		</comment>
		<usedWavelength intended="K-Alpha 1">
			<kAlpha1 unit="Angstrom">1.5405980</kAlpha1>
			<kAlpha2 unit="Angstrom">1.5444260</kAlpha2>
			<kBeta unit="Angstrom">1.3922500</kBeta>
			<ratioKAlpha2KAlpha1>0.5000</ratioKAlpha2KAlpha1>
		</usedWavelength>
		<incidentBeamPath>
			<radius unit="mm">320.00</radius>
			<xRayTube id="1010048" name="Empyrean Cu LFF HR (9430 033 7310x) DK442154">
				<tension unit="kV">40.0</tension>
				<current unit="mA">40.0</current>
				<anodeMaterial>Cu</anodeMaterial>
				<focus type="Line">
					<length unit="mm">12.0</length>
					<width unit="mm">0.4</width>
					<takeOffAngle unit="deg">4.2</takeOffAngle>
				</focus>
			</xRayTube>
			<xRayMirror id="27010001" name="Inc. Beam Cu W/Si (parabolic MRD)" hybrid="false">
				<crystal type="Graded" shape="Parabolic">W/Si</crystal>
				<acceptanceAngle unit="deg">0.800</acceptanceAngle>
				<length unit="mm">60.0</length>
			</xRayMirror>
			<sollerSlit id="21010002" name="Soller slits 0.04 rad.">
				<opening unit="rad">0.0400</opening>
			</sollerSlit>
			<mask id="22030007" name="Fixed mask 2 mm">
				<distanceToSample unit="mm">220.00</distanceToSample>
				<width unit="mm">2.00</width>
			</mask>
			<divergenceSlit id="22010007" name="Fixed slit 1/8°" xsi:type="fixedDivergenceSlitType">
				<distanceToSample unit="mm">220.00</distanceToSample>
				<height unit="mm">0.19</height>
			</divergenceSlit>
		</incidentBeamPath>
		<diffractedBeamPath>
			<radius unit="mm">320.00</radius>
			<sollerSlit id="21010002" name="Soller slits 0.04 rad.">
				<opening unit="rad">0.0400</opening>
			</sollerSlit>
			<receivingSlit id="22010001" name="Fixed slit 4°">
				<height unit="mm">5.88</height>
			</receivingSlit>
			<detector id="7010017" name="PIXcel3D 1x1 detector" xsi:type="areaDetectorType">
				<phd unit="%">
					<lowerLevel>30.0</lowerLevel>
					<upperLevel>70.0</upperLevel>
				</phd>
				<mode>Scanning</mode>
				<activeChannelsEquatorial>255</activeChannelsEquatorial>
				<activeChannelsAxial>255</activeChannelsAxial>
				<pitchEquatorial unit="mm">0.05500</pitchEquatorial>
				<pitchAxial unit="mm">0.05500</pitchAxial>
				<readOutPeriod unit="seconds">0.025</readOutPeriod>
			</detector>
		</diffractedBeamPath>
		<scan appendNumber="0" mode="Continuous" scanAxis="2Theta-Omega" status="Completed">
			<header>
				<startTimeStamp>2024-08-27T15:09:29+02:00</startTimeStamp>
				<endTimeStamp>2024-08-27T15:17:26+02:00</endTimeStamp>
				<author>
					<name>PRO-MRD</name>
				</author>
				<source>
					<applicationSoftware version="6.1b">Data Collector</applicationSoftware>
					<instrumentControlSoftware version="7.0E 20130304">XPERT-PRO</instrumentControlSoftware>
					<instrumentID>0000000011142674</instrumentID>
				</source>
			</header>
			<dataPoints>
				<positions axis="2Theta" unit="deg">
					<startPosition>10.00446193</startPosition>
					<endPosition>99.99777828</endPosition>
				</positions>
				<positions axis="Omega" unit="deg">
					<startPosition>5.00223096</startPosition>
					<endPosition>49.99888914</endPosition>
				</positions>
				<positions axis="Phi" unit="deg">
					<commonPosition>0.00</commonPosition>
				</positions>
				<positions axis="Chi" unit="deg">
					<commonPosition>0.00</commonPosition>
				</positions>
				<positions axis="X" unit="mm">
					<commonPosition>0.00</commonPosition>
				</positions>
				<positions axis="Y" unit="mm">
					<commonPosition>0.00</commonPosition>
				</positions>
				<positions axis="Z" unit="mm">
					<commonPosition>9.100</commonPosition>
				</positions>
				<commonCountingTime unit="seconds">4.845</commonCountingTime>
				<counts 31 36 29 21 27 31 38 20 26 17 32 34 36 32 24 34 29 26 34 30 27 38 41 40 30 43 31 33 20 35 38 30 31 29 28 36 25 23 37 38 32 32 20 30 24 36 18 36 28 32 29 31 23 29 42 46 28 23 32 31 37 39 42 27 24 28 30 37 33 28 21 31 25 26 32 24 26 33 36 30 29 27 25 42 33 32 33 27 37 31 23 25 34 30 37 32 24 31 24 38 25 32 52 23 28 25 33 30 34 36 30 32 29 35 32 35 24 28 31 24 29 32 27 30 31 41 18 37 20 33 37 28 26 32 19 31 28 28 25 37 30 24 31 36 27 30 25 40 24 29 26 31 32 21 34 26 35 25 30 33 23 35 26 31 40 33 17 29 22 20 25 28 28 23 31 31 29 22 30 32 30 26 25 28 33 29 36 34 33 21 31 24 35 19 33 32 33 25 20 24 22 31 38 28 28 25 30 38 24 28 29 23 26 24 30 34 20 31 26 36 20 26 25 28 26 21 30 31 37 27 24 23 27 33 34 26 27 23 29 22 32 36 27 38 31 29 24 30 30 14 26 30 32 34 19 34 23 29 24 26 32 23 28 29 17 29 18 30 35 26 23 26 31 27 26 17 28 30 24 25 17 34 29 31 28 29 31 30 23 25 16 24 28 30 21 22 15 26 28 30 24 34 30 21 21 33 22 28 25 20 28 22 24 28 26 26 31 18 20 19 27 24 32 24 29 23 28 31 25 20 21 25 30 22 32 22 33 29 20 33 26 24 20 29 31 22 25 22 26 25 22 31 28 26 27 18 22 27 24 23 25 26 19 28 17 21 26 28 24 31 28 34 24 22 22 27 18 23 24 22 31 17 21 19 24 30 22 28 16 24 24 17 18 15 27 22 31 26 16 19 25 27 25 18 30 24 19 26 21 17 21 16 29 25 24 21 30 20 19 21 28 17 21 23 25 30 25 25 27 26 23 32 23 23 16 27 17 28 17 24 24 16 22 18 23 18 29 22 30 26 25 20 26 27 25 19 24 21 24 20 21 25 30 24 18 24 19 32 27 23 24 24 18 19 17 20 26 21 19 22 17 22 32 25 32 26 25 26 22 19 20 16 16 20 21 20 26 20 41 20 23 23 29 17 28 25 19 22 27 20 19 20 20 20 18 23 17 25 22 40 19 18 27 22 21 27 22 23 28 18 26 21 20 21 25 22 28 11 31 29 27 21 18 28 25 22 18 23 17 21 20 31 27 23 20 26 20 25 22 15 22 30 15 22 22 36 16 24 18 23 26 21 18 28 23 21 21 20 29 33 22 21 22 20 14 24 22 15 21 23 20 20 15 18 21 21 23 21 36 27 24 32 20 24 16 23 28 34 19 28 31 21 21 20 24 14 25 19 16 18 18 28 23 23 27 24 17 22 21 21 23 28 21 25 28 17 19 23 19 16 25 22 22 28 17 18 23 17 27 26 24 24 22 26 21 28 23 17 31 15 28 24 26 24 17 19 27 14 18 19 24 28 19 34 25 23 21 25 25 16 27 30 15 20 21 18 35 18 21 24 25 20 32 22 25 27 30 25 17 25 21 17 30 32 31 19 23 19 24 16 29 25 19 30 24 17 33 17 21 24 22 16 26 28 20 19 27 21 26 21 19 18 19 22 24 25 25 30 24 26 28 21 27 17 25 20 28 22 27 22 19 26 20 33 26 23 17 13 22 33 21 25 17 22 20 20 31 16 27 12 20 30 14 21 28 18 20 22 24 32 17 20 19 13 23 14 29 26 25 25 17 24 17 26 28 23 25 17 23 23 20 26 17 21 32 15 17 19 13 15 23 21 23 23 31 20 22 24 13 27 20 24 21 29 29 26 34 21 21 20 22 15 19 23 25 14 23 27 25 32 22 20 29 24 19 25 26 29 27 22 19 18 25 29 24 25 23 27 21 27 19 20 21 18 23 23 18 27 35 20 37 24 11 32 22 17 20 21 10 26 23 25 17 12 25 23 19 21 14 23 20 18 29 31 18 23 25 24 12 30 21 27 21 28 16 23 30 23 26 21 32 19 26 33 22 30 20 23 26 21 27 26 12 18 28 25 37 14 16 19 23 20 24 28 21 29 33 20 18 21 27 26 23 18 28 28 21 24 14 30 21 31 20 21 25 21 26 22 19 23 22 17 19 18 23 18 17 19 21 22 19 21 18 20 35 22 24 17 22 23 12 28 29 29 27 16 23 20 20 25 13 24 16 23 15 13 23 24 26 29 21 27 21 24 17 17 30 27 31 18 18 15 25 23 27 20 27 23 17 19 14 28 20 32 18 18 25 20 31 25 25 25 20 22 19 25 21 28 24 21 25 31 17 23 31 24 12 26 20 22 16 32 26 31 24 29 18 25 19 24 23 22 23 21 26 15 31 14 21 24 32 23 21 19 17 24 19 22 13 23 23 25 14 26 25 30 26 18 16 22 18 24 28 27 19 19 28 20 24 19 20 17 21 18 24 21 31 16 21 28 16 24 26 24 20 26 21 23 28 21 20 23 20 23 23 16 15 25 20 25 18 24 24 16 23 19 19 24 28 30 20 26 19 30 33 30 28 29 23 24 20 17 37 22 24 27 21 21 25 30 23 27 22 15 28 25 28 24 21 34 18 24 21 27 25 18 26 26 19 20 28 16 22 25 24 25 30 17 18 24 23 22 25 37 21 17 21 21 28 22 25 31 21 30 24 29 27 21 23 27 25 26 17 25 22 25 26 24 21 26 23 31 23 18 16 19 17 25 22 26 34 28 18 30 25 34 30 27 24 23 25 32 19 15 21 30 33 25 24 19 18 18 22 37 19 26 24 22 27 34 16 22 28 20 21 27 37 29 27 19 16 20 23 28 26 28 18 34 23 21 19 24 23 34 17 26 20 23 25 29 23 27 26 25 25 31 30 27 25 16 30 29 18 21 22 32 24 31 21 28 34 23 32 31 33 37 18 24 30 23 17 15 27 29 21 25 15 18 15 29 33 32 32 30 8 25 16 23 28 31 28 30 21 29 22 27 26 27 21 25 26 22 34 25 18 25 21 24 25 11 21 20 19 26 21 28 19 25 26 20 23 17 20 25 25 23 24 18 23 21 26 21 24 20 15 38 18 34 27 25 11 17 17 23 26 28 27 31 25 21 32 21 22 21 22 21 15 21 20 18 35 25 21 28 20 21 21 25 24 19 15 32 25 30 19 21 12 21 19 21 27 21 25 22 29 29 20 24 13 32 19 22 23 24 38 25 20 26 22 19 18 26 14 22 23 30 15 23 26 19 23 28 27 31 28 24 23 27 25 24 17 26 26 17 30 28 24 21 22 24 24 17 22 20 16 22 26 24 27 38 28 24 21 21 15 14 22 23 29 15 13 19 24 22 18 18 30 21 25 20 26 26 26 35 25 20 29 18 16 20 14 21 26 16 18 21 31 21 17 24 15 19 26 19 27 29 16 16 26 24 20 22 20 16 35 22 16 19 21 19 18 29 20 33 27 21 30 24 15 20 23 12 19 29 15 23 26 27 27 31 18 29 13 19 21 18 26 13 26 13 19 23 24 14 29 13 20 13 32 29 26 23 22 29 21 21 25 17 20 26 21 18 18 19 20 27 31 23 23 14 18 26 30 26 17 19 20 23 19 19 28 16 28 21 19 22 19 28 22 21 22 25 24 17 22 21 21 24 18 14 17 30 25 14 26 19 23 19 31 15 17 18 24 20 15 21 25 17 29 26 18 26 18 18 17 19 24 22 13 16 24 18 21 27 14 16 20 11 21 17 20 13 18 25 22 26 17 20 23 28 20 18 16 20 27 22 26 17 17 17 19 28 24 23 21 20 14 28 22 22 24 20 16 25 23 28 22 30 23 22 25 22 24 22 22 17 17 20 15 26 25 19 28 24 27 28 23 25 16 22 21 25 23 19 24 17 19 23 20 25 22 27 25 22 21 25 23 18 19 24 23 14 23 23 23 18 26 18 26 19 15 18 23 10 17 18 22 18 23 23 21 30 15 15 25 22 21 21 20 20 22 23 18 20 24 24 16 19 16 19 22 19 20 21 17 17 22 25 20 24 21 23 16 21 14 22 15 16 19 18 24 10 23 24 15 26 21 24 20 16 26 15 21 23 18 14 19 18 18 17 15 20 26 20 22 21 16 21 19 22 25 31 19 23 33 27 21 17 25 19 31 17 16 23 25 22 26 17 18 29 19 19 23 15 19 24 19 21 23 21 29 27 19 25 19 22 28 22 18 25 21 17 22 18 25 17 27 14 20 22 20 13 16 18 13 21 15 31 13 18 20 14 26 24 27 32 22 17 22 20 20 20 20 26 11 22 18 15 16 19 20 22 23 20 18 23 26 18 18 21 16 17 13 26 17 31 17 20 21 18 21 22 11 18 22 22 15 21 20 22 16 17 20 20 20 15 15 21 18 22 23 21 19 22 16 22 23 17 15 26 12 18 16 16 27 12 25 15 21 19 22 22 17 24 21 27 21 19 23 19 14 21 14 16 18 15 21 21 21 18 22 22 23 18 21 16 20 14 26 22 20 18 12 23 22 21 9 13 27 19 18 21 22 19 14 20 21 25 31 13 20 16 20 25 26 17 15 20 12 19 24 13 21 13 20 18 23 22 26 19 15 19 24 20 21 11 18 16 20 16 20 16 9 16 19 19 23 16 21 23 16 17 19 22 19 24 22 17 19 17 19 11 24 13 16 23 27 29 17 20 17 9 17 9 23 16 21 23 14 18 14 15 15 20 22 16 25 18 21 30 20 25 26 24 23 17 16 18 17 25 23 18 11 25 29 22 19 14 18 24 18 18 21 20 22 20 17 19 18 27 20 24 26 16 18 14 19 18 15 17 22 19 17 18 11 25 10 18 17 29 19 22 20 15 18 21 18 18 20 18 22 18 14 16 21 14 22 17 16 19 23 19 17 20 23 25 14 17 28 20 21 25 20 22 18 20 23 18 19 22 16 21 14 17 27 16 13 23 18 23 15 18 20 16 19 24 14 19 12 16 20 16 23 17 16 22 20 23 13 15 19 14 11 21 23 19 13 17 23 18 24 15 20 24 19 19 20 18 21 29 12 19 8 22 18 14 27 12 14 20 25 21 17 23 15 14 24 12 13 23 22 28 17 21 22 17 26 15 22 31 18 19 17 10 20 13 22 16 26 20 18 15 13 12 18 17 20 24 15 16 24 26 20 19 16 18 19 15 15 15 23 17 20 26 16 24 18 20 19 25 11 8 37 17 20 23 24 14 23 13 10 13 17 18 15 15 9 15 17 17 21 22 21 13 19 14 14 23 20 21 13 18 12 21 20 26 27 20 13 23 18 13 17 29 21 16 27 20 19 25 18 24 21 26 22 17 17 14 21 20 21 17 28 23 21 18 17 24 14 14 14 13 21 12 18 22 23 21 21 15 24 20 24 19 24 14 20 17 16 27 18 21 17 26 16 21 17 13 20 19 19 13 17 20 13 19 22 16 16 22 16 20 16 19 16 20 20 15 19 19 17 17 18 17 22 24 15 20 16 20 20 20 18 15 18 24 15 17 17 14 16 21 18 22 23 20 21 21 26 22 16 18 21 22 19 22 15 17 19 23 13 14 15 23 23 23 17 26 16 18 23 12 17 16 26 9 27 20 16 17 17 17 16 15 17 14 17 16 25 17 18 13 19 20 22 14 21 26 19 17 18 16 24 19 20 21 16 18 26 15 22 20 19 18 17 15 17 23 23 24 19 15 11 17 25 20 20 17 16 17 16 15 11 24 20 17 27 19 20 13 19 13 17 20 22 20 12 17 14 21 17 16 17 26 17 22 8 22 13 14 22 15 11 12 23 25 17 18 22 18 9 25 14 21 23 12 19 23 24 26 20 21 15 23 20 27 15 24 14 15 20 18 19 19 28 26 21 15 26 25 14 8 12 22 13 20 26 20 23 26 22 16 19 17 15 23 19 18 22 19 6 24 20 24 16 18 17 25 14 16 13 17 19 16 19 20 19 15 26 26 24 23 23 21 22 22 25 14 22 17 21 20 18 21 23 13 20 21 22 14 20 18 14 13 13 18 23 18 25 31 22 16 19 25 20 21 24 19 13 25 27 14 17 19 19 12 18 24 15 23 19 16 10 14 20 17 15 17 11 18 25 17 16 28 23 22 16 26 14 18 24 19 20 20 18 22 13 17 15 26 23 12 14 20 18 17 19 17 15 18 18 21 20 16 11 21 22 19 24 17 20 17 11 28 17 15 17 26 17 29 18 22 14 20 7 31 20 21 26 19 23 22 13 20 23 20 20 17 17 21 16 14 20 23 20 14 18 13 20 21 19 13 20 22 26 17 18 17 19 20 28 13 19 22 21 21 24 32 16 21 17 24 23 11 17 16 20 30 20 27 18 19 24 17 18 21 17 22 16 18 18 22 17 18 32 19 18 14 23 19 13 25 15 19 23 18 19 18 17 17 17 26 16 22 21 17 12 25 19 16 15 23 16 20 10 15 14 12 19 14 17 16 24 13 16 16 21 21 16 27 19 18 20 23 18 15 12 19 20 27 15 16 23 22 18 25 15 17 19 26 18 15 17 23 15 16 24 16 13 26 22 19 16 19 20 14 23 10 17 12 24 9 20 17 19 17 24 18 20 9 27 24 25 16 22 17 14 13 16 12 15 15 17 16 20 16 21 17 17 21 17 20 14 10 24 21 15 27 18 13 19 19 30 23 17 13 12 18 18 22 25 28 14 24 18 26 10 25 14 14 16 15 24 18 14 14 24 24 23 30 23 13 19 21 16 25 18 17 21 20 19 16 14 23 14 15 14 15 16 20 16 17 19 19 23 17 28 18 17 21 15 26 14 15 21 17 23 19 24 25 17 21 13 13 16 17 15 19 15 17 26 16 17 15 16 13 22 22 17 26 19 18 29 11 18 19 15 16 17 14 17 16 18 19 23 15 28 16 13 21 16 16 24 17 22 19 17 17 18 16 30 14 13 20 13 14 16 21 13 20 24 21 8 23 14 24 15 20 19 12 16 16 21 16 19 16 14 19 22 19 16 21 17 17 12 18 20 22 26 19 20 21 17 29 13 20 21 9 25 19 22 14 23 18 21 14 15 17 21 23 15 15 17 14 23 23 19 23 19 19 27 15 7 23 18 23 13 22 18 15 29 15 23 28 18 17 21 15 24 21 21 15 9 21 17 19 11 13 14 32 14 21 14 19 18 15 16 17 22 19 17 15 20 17 22 16 16 19 29 21 16 20 13 19 22 31 14 17 25 21 15 20 8 11 19 23 23 20 25 18 24 19 13 17 29 26 20 11 11 19 12 25 17 25 17 20 19 20 22 14 15 23 17 22 18 16 16 17 17 18 21 19 23 16 13 16 21 17 25 13 25 15 19 17 21 21 12 26 24 17 22 13 22 21 15 21 12 19 11 21 24 16 17 27 15 25 22 14 17 22 11 14 28 16 20 24 28 23 19 16 22 22 22 22 22 18 18 17 19 16 16 19 16 17 20 22 22 23 25 27 32 15 23 33 24 15 20 20 26 13 18 16 17 12 25 22 17 25 23 22 10 12 17 18 14 21 21 16 19 23 18 16 22 18 20 22 14 12 21 18 12 23 25 21 29 20 16 18 10 16 19 31 19 23 18 21 27 23 15 16 21 23 24 13 24 23 18 15 19 13 25 18 27 15 19 21 23 23 22 22 18 19 12 18 30 18 24 27 24 25 20 27 19 19 23 24 20 18 22 16 24 26 20 25 27 23 14 21 29 22 33 20 17 25 16 25 19 31 24 22 24 29 30 27 26 28 44 33 30 33 39 45 33 33 31 31 29 27 37 33 50 44 32 39 42 34 41 32 45 37 40 27 43 35 44 26 33 20 38 35 31 34 20 32 28 26 30 31 22 34 29 20 20 24 15 27 22 21 25 10 27 30 21 12 21 20 16 23 15 26 18 18 13 19 18 18 29 20 21 23 23 16 20 14 12 16 20 19 21 22 22 24 16 27 16 21 19 27 19 25 21 20 21 17 16 23 19 17 21 25 24 26 18 10 20 26 17 21 23 25 14 16 18 18 14 18 23 23 19 16 16 18 18 28 25 17 26 29 25 24 25 16 18 16 21 21 19 24 14 22 14 24 20 25 20 22 18 14 18 17 17 28 24 29 18 14 14 20 16 23 10 14 23 15 21 12 21 25 22 17 22 23 13 27 14 15 19 15 18 21 14 21 24 22 19 24 16 18 23 17 14 13 19 15 19 18 17 12 18 22 23 21 19 13 20 18 20 21 16 21 19 26 18 24 16 16 23 19 13 19 10 15 20 15 18 18 23 23 22 22 21 20 16 23 23 26 18 19 20 16 22 17 20 24 18 18 24 28 21 15 17 26 27 17 21 14 18 22 21 23 17 17 17 18 19 23 14 18 21 19 29 20 22 25 18 16 11 18 17 29 21 23 21 12 22 22 21 13 17 17 26 24 17 17 20 14 9 17 23 11 17 23 25 22 14 19 27 21 19 27 23 16 19 25 16 18 20 22 23 16 18 26 21 24 15 21 25 12 15 23 20 23 17 13 17 16 17 19 20 20 25 27 24 14 13 11 19 20 19 14 18 18 16 18 22 23 17 13 30 21 20 12 30 19 20 21 14 17 23 21 25 21 23 18 17 18 19 22 17 24 21 8 24 32 27 16 21 11 11 23 27 15 16 11 18 15 18 13 16 17 13 25 26 16 20 18 31 19 18 24 21 9 18 22 29 14 17 15 17 18 15 16 25 20 22 10 16 20 10 19 17 13 20 25 26 8 25 18 28 27 18 17 17 17 25 22 33 19 15 18 17 19 18 20 20 13 16 20 24 17 19 19 22 16 20 18 26 17 29 13 28 19 20 10 16 22 23 24 26 18 12 16 24 18 16 12 24 25 15 17 21 22 25 15 18 21 17 19 16 16 18 18 26 19 13 21 20 19 20 24 22 14 16 19 15 17 17 19 22 17 27 18 18 19 27 18 12 19 21 21 24 28 18 23 17 13 11 16 21 21 14 18 13 20 13 15 15 17 17 19 24 26 19 12 12 12 16 17 18 24 25 14 21 17 24 26 14 20 23 15 19 22 28 10 21 18 17 21 18 12 16 14 12 22 17 20 19 15 24 19 16 15 17 18 30 11 19 16 20 27 18 21 20 16 27 14 19 11 19 16 23 15 11 21 20 25 22 23 18 12 23 20 23 21 14 22 19 19 23 18 24 26 24 19 19 23 16 22 23 16 22 19 16 29 25 16 18 29 12 23 22 19 15 18 19 16 22 26 14 23 21 19 13 18 19 11 17 21 15 16 21 28 13 15 16 16 19 22 26 15 20 18 21 25 23 19 27 16 22 10 19 18 21 22 23 14 18 19 9 18 23 22 20 21 15 18 24 10 12 22 23 23 22 13 25 24 19 21 19 24 23 25 14 26 13 17 24 12 19 18 13 17 21 22 19 19 17 14 19 21 22 20 19 15 22 20 12 29 20 16 17 21 23 21 27 16 25 18 17 18 20 21 18 23 25 11 27 24 16 25 24 18 17 18 15 19 19 23 18 21 24 20 19 25 14 14 16 20 20 24 18 21 19 24 16 27 32 22 27 13 18 16 23 26 19 18 23 10 23 23 18 14 23 17 22 13 24 20 20 15 24 23 21 15 21 15 16 24 12 21 21 21 24 22 17 17 25 19 11 21 13 23 18 21 19 22 21 20 17 24 15 13 14 22 19 22 25 18 19 23 16 18 25 19 19 25 19 9 14 25 19 12 21 17 16 24 18 16 20 31 14 16 22 20 21 24 15 22 22 19 21 26 26 26 15 23 20 22 18 14 25 26 20 14 17 20 26 21 18 21 25 24 22 17 16 28 15 24 22 22 26 20 23 16 20 17 20 20 21 18 18 15 15 20 25 24 21 22 17 22 19 21 13 20 22 19 28 21 20 17 14 21 15 33 18 16 17 19 18 20 16 19 17 19 20 20 20 20 24 12 14 29 19 20 21 22 19 22 19 21 20 16 9 16 19 18 22 17 26 23 22 18 19 23 19 20 22 18 27 19 14 24 24 28 15 19 15 22 14 19 15 24 17 17 20 25 22 21 14 16 18 19 21 15 10 25 30 22 18 16 19 16 23 13 27 22 23 22 15 21 19 22 15 30 24 20 22 18 14 15 14 20 17 22 21 29 21 18 22 14 6 18 14 26 26 18 18 23 18 17 20 22 16 14 29 21 25 17 13 10 24 19 19 17 14 15 26 15 23 22 22 21 11 19 9 13 17 29 20 20 18 26 21 19 15 19 9 19 23 22 23 29 19 14 18 14 12 15 29 14 21 15 20 23 22 17 20 20 21 18 28 21 32 19 19 24 26 23 24 20 15 19 19 14 20 24 20 22 11 23 18 14 11 13 23 15 21 25 19 16 26 21 18 19 22 20 21 18 16 15 15 15 18 22 20 17 10 12 21 22 19 15 13 19 18 22 10 14 13 17 26 19 12 20 16 20 22 19 31 17 21 20 28 17 19 22 18 16 25 15 18 26 26 18 17 19 31 22 13 23 19 18 19 17 26 17 18 23 17 19 23 23 21 22 18 15 21 22 17 20 27 29 13 15 19 16 19 17 27 21 23 27 26 22 19 21 22 24 25 21 16 20 20 19 17 20 18 25 21 11 17 14 17 20 15 22 13 18 20 16 18 25 20 9 23 16 22 28 26 22 21 14 9 15 21 24 12 22 18 19 20 22 22 22 20 20 22 21 19 19 19 29 20 17 11 15 17 19 14 18 25 19 23 17 28 20 22 19 11 23 25 24 20 28 19 16 16 20 16 20 27 24 17 18 18 22 19 22 22 18 20 25 19 19 19 14 11 19 12 22 19 14 25 22 14 19 24 17 33 20 18 25 28 15 18 14 20 20 17 14 13 22 20 25 13 22 13 17 29 11 24 16 18 30 22 23 15 14 22 24 21 15 20 14 18 26 25 17 17 22 16 22 27 27 31 20 19 22 16 16 24 25 19 21 18 26 21 26 25 24 24 19 20 16 15 19 18 11 15 15 21 21 14 20 21 20 19 13 22 23 17 15 17 19 20 17 21 20 21 22 18 28 26 16 17 18 20 19 19 22 22 25 19 19 26 21 18 21 23 16 17 20 12 21 26 18 29 22 14 14 20 14 21 20 21 20 19 26 25 24 24 15 19 20 12 15 13 19 24 23 22 19 18 21 17 23 19 21 21 11 24 28 24 27 28 18 16 19 21 31 17 12 19 19 19 25 28 12 13 23 26 20 16 30 19 23 13 16 16 19 20 20 19 25 20 20 22 17 15 27 16 24 19 26 19 27 21 25 20 19 26 15 24 18 21 27 24 12 21 15 19 13 25 13 25 13 21 23 18 20 24 14 19 17 18 27 13 26 14 21 13 16 16 21 20 20 13 14 8 23 20 17 20 19 18 13 17 20 17 29 24 22 12 20 18 15 27 22 23 18 19 24 27 21 14 23 23 24 20 24 15 17 24 24 12 23 22 21 28 19 24 21 21 26 19 23 21 30 29 20 18 25 15 22 19 20 25 10 26 21 27 15 27 21 25 14 26 23 24 17 20 35 22 16 18 26 13 25 15 16 23 17 27 13 17 20 16 19 24 16 19 23 14 16 16 26 22 19 13 21 19 18 20 22 24 17 16 17 32 16 15 21 23 28 22 21 14 18 32 19 19 20 31 15 26 19 24 18 19 17 18 20 18 23 19 19 23 17 25 13 22 20 18 20 24 19 18 19 26 19 19 21 18 21 16 17 18 25 24 22 21 18 12 29 15 21 29 14 18 22 16 19 23 22 24 21 17 13 17 14 20 21 19 20 16 31 27 19 21 29 21 29 20 24 30 21 21 29 19 25 23 26 26 28 24 21 23 30 17 17 17 15 22 20 30 22 29 19 15 14 15 19 18 20 16 18 25 19 21 15 29 26 25 13 27 16 20 18 27 23 16 17 22 21 19 24 22 19 25 15 21 24 21 13 21 17 24 14 20 16 15 28 24 18 29 19 21 18 21 25 14 25 19 24 34 14 24 24 24 16 22 25 24 23 17 14 20 15 18 17 15 25 16 17 17 19 13 17 23 20 28 27 24 14 20 18 21 23 19 26 14 22 17 21 22 20 16 15 27 24 16 34 22 22 20 23 25 23 27 14 19 28 13 18 14 23 23 20 12 19 20 20 22 18 26 16 27 24 19 21 19 22 15 18 23 18 15 23 19 18 12 18 15 19 27 22 19 18 17 20 27 25 18 25 32 23 14 14 24 13 12 24 27 20 17 18 19 22 23 25 18 14 19 17 20 18 22 27 17 13 18 22 22 26 11 17 23 23 20 20 29 20 26 17 14 30 14 25 21 18 18 9 20 18 19 19 18 28 24 15 19 15 23 28 21 22 28 11 23 23 16 23 18 26 22 18 17 15 19 25 21 15 18 29 22 30 15 18 25 27 21 15 28 25 20 24 23 27 22 10 20 25 16 23 20 17 31 22 23 19 28 24 26 30 26 30 25 18 30 21 31 21 24 27 18 21 23 27 26 20 28 21 18 23 17 17 19 20 21 21 25 15 22 18 20 21 23 17 25 19 26 15 16 22 26 21 23 20 17 28 21 23 13 20 21 17 18 19 16 27 33 27 18 14 19 24 19 40 17 20 18 17 20 19 21 14 18 14 27 22 33 25 19 23 11 22 24 22 15 21 23 18 27 16 24 18 25 26 28 20 22 23 26 19 30 21 21 21 22 21 19 11 19 28 19 26 23 21 14 14 15 12 25 20 24 16 27 28 16 18 20 15 19 29 15 25 23 15 20 17 13 16 15 16 22 20 18 21 14 19 24 19 24 19 18 25 19 20 20 20 25 23 26 15 21 25 25 19 18 12 18 20 32 20 28 22 22 22 21 23 13 23 14 19 24 18 17 19 19 21 26 14 18 16 18 18 20 22 21 24 24 29 14 19 30 23 19 23 16 18 22 26 19 25 23 18 17 22 22 20 15 20 16 26 21 18 22 28 21 17 13 21 14 13 10 25 21 16 18 11 19 26 18 17 18 20 17 21 26 27 17 18 10 18 28 17 35 15 19 22 15 23 21 19 26 31 23 24 21 15 18 19 21 25 22 15 22 20 17 14 20 24 15 21 15 17 21 24 15 21 22 20 20 17 25 12 20 19 17 17 23 15 19 19 21 22 20 24 19 25 20 19 19 21 15 23 18 18 10 28 21 25 30 24 22 22 17 17 20 19 23 22 25 17 19 18 24 14 17 17 22 29 14 12 14 14 21 20 16 22 20 25 19 19 20 17 14 26 17 22 19 22 19 24 22 21 19 24 21 29 17 11 19 20 21 14 14 18 28 20 16 24 27 19 20 26 14 19 20 11 18 15 26 23 20 28 26 25 22 24 16 24 27 16 21 17 23 19 19 32 26 28 17 15 20 24 25 27 17 24 18 20 18 29 28 20 20 16 20 22 10 16 16 19 16 19 21 24 20 20 19 15 15 27 23 18 18 20 28 17 13 18 23 18 24 23 17 18 23 26 17 18 19 16 26 23 17 25 22 30 13 14 23 15 25 22 20 15 27 22 28 20 19 13 21 24 16 22 15 10 15 25 15 24 23 14 16 26 24 14 22 28 22 22 22 14 22 12 19 16 23 28 23 30 23 24 19 17 17 22 19 25 18 22 18 21 18 21 24 26 13 22 24 23 29 22 11 14 23 16 17 18 24 16 16 20 20 20 19 18 20 11 18 20 14 31 17 17 30 25 20 18 24 24 17 15 19 20 31 19 16 17 23 13 17 12 26 20 27 17 12 22 18 16 15 19 9 21 18 21 23 19 23 15 30 17 22 22 23 13 28 23 13 15 15 20 18 24 19 14 25 20 17 18 19 10 18 23 24 19 23 31 20 18 13 15 17 16 17 14 26 20 23 21 17 11 19 18 14 18 21 18 22 17 24 33 13 25 20 17 15 17 18 21 23 25 21 22 13 20 19 19 20 22 14 13 24 28 23 28 18 18 16 21 23 22 23 14 18 12 16 20 16 18 24 24 25 14 15 20 22 17 16 27 18 20 19 23 15 14 18 15 21 24 22 24 24 19 21 18 23 18 24 13 22 20 17 23 18 24 17 19 12 16 18 16 16 21 20 22 23 18 26 16 23 19 26 24 20 20 26 22 14 22 18 17 24 23 20 18 19 22 18 22 22 30 21 21 30 11 21 22 21 26 16 24 14 21 15 20 23 21 25 19 29 18 18 25 18 21 17 13 22 17 19 18 17 18 21 12 17 29 18 19 15 21 19 26 20 22 18 21 24 28 19 14 11 21 18 14 25 27 12 20 27 32 15 11 20 16 31 17 17 15 25 26 20 15 24 14 12 17 19 21 23 29 21 14 26 17 15 13 26 16 19 19 22 17 17 21 24 20 22 10 16 32 20 18 20 21 26 32 19 12 19 23 24 20 29 21 20 18 23 23 23 17 20 17 30 18 12 18 23 27 16 20 21 16 20 17 18 22 20 18 26 21 15 19 23 16 14 20 21 19 18 17 20 26 14 32 17 19 30 19 21 23 24 20 24 24 16 12 21 22 25 11 20 11 28 22 18 19 15 14 24 20 22 10 22 17 17 30 22 17 27 22 16 18 26 14 20 16 27 13 26 11 20 33 22 23 25 19 22 25 25 24 17 27 30 13 14 19 15 15 22 26 18 25 29 16 24 24 16 14 16 18 20 26 19 24 18 25 18 23 24 18 17 17 18 15 19 21 19 29 20 17 20 23 15 20 18 16 23 23 16 17 14 13 26 22 19 18 16 27 17 21 25 26 20 25 21 17 23 21 22 12 27 16 13 19 30 16 19 16 21 14 23 22 27 18 16 25 16 15 20 19 25 20 25 22 19 16 18 21 14 20 27 18 26 37 20 15 24 13 16 21 24 19 13 24 22 22 25 23 11 12 19 26 28 20 22 28 16 23 18 22 13 27 19 20 16 19 17 16 16 19 14 22 22 17 17 25 23 21 13 18 35 24 23 25 22 17 18 20 14 13 20 23 24 15 16 30 18 19 17 24 24 13 16 19 17 22 15 26 24 20 19 19 15 17 27 35 20 32 21 18 23 19 20 21 23 26 18 18 26 21 23 21 17 20 15 22 24 12 20 13 13 27 17 17 26 23 19 20 23 26 16 30 20 15 26 17 19 20 20 20 19 28 15 23 17 24 22 28 14 24 38 15 21 27 16 19 16 17 22 20 24 18 22 30 17 13 17 22 29 26 24 32 17 25 29 22 19 21 17 21 22 17 25 24 22 23 18 29 18 20 17 27 19 23 18 23 15 23 18 21 17 16 21 23 8 22 21 17 18 20 21 19 29 20 25 21 12 21 17 18 21 25 16 19 23 21 14 16 19 17 11 20 23 27 20 18 23 22 20 15 17 23 26 18 27 17 18 13 16 18 20 21 27 16 22 13 20 16 11 15 23 24 19 22 20 21 17 22 21 21 23 22 17 30 28 25 19 25 20 22 19 16 22 25 12 19 17 18 20 19 17 23 17 16 21 23 20 20 21 23 26 21 23 17 20 16 14 20 14 16 27 24 20 23 18 16 18 21 18 23 21 22 13 23 26 20 33 14 25 16 23 29 12 18 21 31 21 16 17 17 25 17 26 18 22 14 23 18 19 21 19 17 18 23 24 22 11 20 34 15 24 25 14 24 20 22 22 20 29 13 27 17 21 24 26 23 17 13 24 22 21 18 22 15 20 23 20 27 19 17 19 25 22 17 17 17 22 16 22 17 19 19 23 21 13 16 20 22 19 26 20 21 19 26 18 20 18 25 21 14 16 16 24 20 22 21 22 29 30 14 15 25 19 24 21 25 30 19 17 25 15 19 22 30 25 24 24 17 18 25 22 13 20 21 10 16 27 14 13 21 25 21 21 17 19 15 21 20 13 10 14 22 23 16 21 21 27 20 20 29 12 23 22 16 16 24 19 24 16 19 21 24 16 25 19 13 17 16 24 16 18 15 17 23 27 14 15 26 16 21 22 24 23 22 28 18 15 19 19 24 25 14 20 22 22 18 12 19 32 24 25 22 24 24 13 19 16 25 13 29 30 25 22 14 20 27 21 14 17 22 30 11 29 24 12 23 18 16 20 20 18 24 12 15 28 18 24 24 30 22 14 14 18 19 24 16 17 23 21 23 16 27 20 25 19 21 20 19 23 17 21 20 16 16 9 33 21 24 18 16 16 17 25 20 22 22 35 24 25 20 10 22 24 14 25 14 20 19 23 18 15 25 20 25 25 18 21 23 25 25 20 12 20 11 22 24 20 22 20 29 28 31 23 21 24 16 19 12 25 26 18 19 27 16 20 22 26 20 20 27 22 22 22 25 22 22 22 15 17 19 23 20 21 22 30 17 23 24 20 15 26 28 21 25 28 26 23 21 19 27 30 19 31 22 18 31 18 25 25 23 25 20 33 17 18 21 30 25 22 24 23 21 24 22 16 17 19 23 28 28 34 30 16 22 17 30 20 26 23 20 20 33 17 25 25 24 19 24 23 25 29 30 16 27 20 25 21 19 11 27 29 17 27 21 19 17 16 17 20 19 24 21 17 19 21 21 16 21 25 16 16 22 21 22 19 16 18 24 11 20 23 24 26 17 31 22 19 32 13 23 13 16 20 21 19 26 13 21 26 18 20 20 24 27 26 18 16 21 28 19 21 19 21 23 19 18 19 33 16 17 14 19 20 19 30 17 20 9 17 20 16 26 29 25 20 19 17 21 17 22 27 16 23 15 22 22 22 26 19 19 21 19 26 20 21 17 18 26 26 25 20 23 17 14 10 18 19 18 12 26 20 20 17 17 23 18 9 23 21 18 21 15 18 24 19 21 25 18 22 28 25 15 14 20 25 26 23 10 18 16 18 19 17 15 17 20 19 9 18 23 15 26 16 18 11 23 20 23 12 23 20 20 17 27 14 19 24 18 16 30 19 17 20 26 18 19 16 17 20 18 25 8 14 17 30 28 17 19 17 18 22 26 32 13 25 14 17 17 23 23 22 26 18 18 19 19 21 16 17 19 18 26 16 20 17 16 18 26 28 23 19 17 16 28 21 20 29 24 12 25 29 26 20 16 21 15 12 22 20 20 18 15 20 21 25 19 19 13 17 16 25 16 19 28 14 14 23 19 17 26 20 23 23 16 18 13 29 15 24 16 29 16 23 16 20 20 20 18 21 21 12 20 17 20 22 14 14 22 27 14 19 20 17 14 18 15 15 14 23 21 21 17 23 19 22 19 18 23 24 13 21 25 27 15 21 22 19 23 17 13 27 18 15 20 16 16 16 19 30 18 16 19 24 24 16 19 26 21 24 22 12 16 22 22 21 11 13 25 24 22 17 18 18 22 19 23 25 21 20 22 20 26 9 26 16 15 22 23 19 19 21 25 20 19 27 20 27 23 19 16 18 23 22 16 22 17 25 21 17 22 22 17 16 18 24 20 23 21 18 12 22 22 19 19 16 21 15 17 19 19 27 21 13 16 20 16 23 24 18 23 27 21 23 16 18 24 16 24 16 18 28 28 19 21 20 18 23 18 18 14 19 22 25 9 27 23 18 23 24 26 21 21 15 28 14 25 23 27 26 26 17 19 12 12 26 29 15 26 23 19 16 24 16 17 20 25 17 16 17 22 15 19 16 22 18 28 25 25 15 18 15 16 23 21 15 20 23 15 18 16 17 13 20 18 25 19 27 17 23 16 17 25 13 16 27 15 21 24 20 13 19 22 26 18 22 27 24 12 21 11 15 12 11 13 21 19 16 18 16 23 9 13 22 21 20 20 20 21 26 30 21 25 11 24 16 23 22 21 17 20 18 22 21 18 25 21 18 27 16 13 17 17 26 26 24 20 14 19 20 13 24 18 19 21 17 15 18 18 19 22 12 21 16 16 17 12 20 21 21 10 23 13 19 21 25 25 23 22 19 13 23 24 25 18 17 16 24 21 25 16 26 15 20 21 33 21 19 23 20 16 25 11 27 13 18 19 15 20 25 18 22 13 19 15 11 27 23 17 25 21 17 24 28 16 23 19 20 16 14 20 17 23 22 18 28 10 21 28 17 18 19 17 16 23 16 20 14 9 20 26 17 23 30 21 16 19 20 15 18 18 27 22 8 17 22 19 15 14 18 26 15 24 17 11 13 26 21 21 19 23 19 23 18 25 25 25 23 20 17 21 16 14 12 20 17 22 16 24 26 15 21 23 15 22 14 23 23 21 21 18 17 25 21 14 16 24 23 18 16 18 24 12 21 16 21 24 24 18 24 18 21 27 22 12 22 15 14 23 15 10 25 17 20 16 15 15 21 21 24 17 16 27 20 27 15 19 10 23 23 25 22 21 19 22 26 25 23 23 21 18 16 17 17 18 11 24 29 17 17 18 17 24 15 18 24 16 22 18 12 19 16 25 21 23 22 18 18 9 21 15 12 21 11 14 21 17 23 18 19 19 22 18 21 13 11 20 20 30 27 25 22 22 18 16 15 16 14 22 17 18 14 14 26 15 23 28 11 17 23 23 25 20 14 9 29 19 23 20 26 21 27 21 27 25 20 13 16 24 18 24 22 28 18 19 18 15 21 21 25 15 17 24 20 24 20 25 26 19 12 27 24 19 15 25 13 18 17 16 23 20 22 26 21 23 21 16 20 14 20 19 23 14 14 18 14 27 26 15 18 18 23 29 21 26 17 22 20 24 22 18 17 18 15 12 22 16 17 16 21 32 15 24 14 27 15 17 19 13 16 19 20 18 31 25 19 16 14 26 18 21 19 26 24 19 22 25 21 13 26 13 20 29 28 21 19 22 22 21 14 17 16 26 18 21 14 17 15 25 20 28 28 18 27 16 15 17 17 15 27 18 22 31 20 25 21 23 23 20 14 21 21 22 23 13 22 25 19 26 13 19 19 17 19 19 18 13 21 19 20 32 20 20 14 20 20 23 16 23 22 24 23 20 13 27 20 12 22 16 16 23 19 26 25 23 24 20 24 16 22 19 23 24 12 16 18 20 16 15 26 19 21 20 25 14 8 17 16 33 14 25 13 24 16 8 13 15 16 17 23 22 17 19 21 28 20 15 13 22 27 25 23 17 18 23 19 20 13 19 22 9 22 27 20 26 22 31 26 15 20 20 29 23 18 15 25 11 21 20 24 23 12 28 30 16 17 21 23 16 34 13 18 16 28 25 9 16 17 21 12 25 10 14 25 19 17 19 19 19 24 17 19 16 20 13 17 20 28 27 19 19 25 24 19 17 16 23 24 24 31 20 15 20 19 13 27 19 15 21 17 17 19 24 19 16 22 14 20 22 21 26 21 12 23 18 19 20 21 18 12 24 26 22 29 21 25 20 18 20 28 17 21 24 16 22 20 21 24 17 22 18 19 16 14 29 19 20 20 19 16 16 16 20 14 18 23 23 16 18 25 22 23 16 12 29 17 27 21 27 22 13 20 17 17 14 23 24 22 18 15 22 12 19 27 17 22 16 18 23 28 13 18 19 23 11 27 16 16 15 19 32 19 24 19 20 24 24 23 17 18 21 16 23 28 19 22 23 26 19 22 20 18 23 19 18 21 21 22 21 23 21 25 26 22 25 22 12 16 22 20 19 20 21 24 21 22 21 10 20 24 23 23 14 19 25 19 17 19 24 21 20 23 21 22 32 16 22 15 20 19 10 21 14 20 15 20 17 22 27 28 20 16 22 22 17 15 27 26 18 21 16 25 11 23 21 23 22 15 25 18 25 25 18 13 19 22 18 27 21 19 10 24 20 21 19 22 26 22 15 23 19 17 22 28 30 26 22 22 17 20 26 24 15 24 18 21 20 20 13 19 20 16 22 22 11 18 28 21 19 17 20 21 17 13 18 18 14 16 23 22 22 29 12 18 23 22 14 27 19 23 18 17 23 15 26 21 18 15 20 24 17 15 13 14 23 23 19 25 18 15 28 21 14 35 18 22 26 15 13 24 23 18 16 18 17 21 14 17 22 17 28 20 23 21 19 20 26 30 21 29 23 19 22 15 27 19 21 27 24 29 21 17 18 23 20 19 29 18 14 19 20 18 19 23 15 21 27 18 18 22 28 21 18 26 25 16 16 13 22 21 24 22 24 17 19 14 17 18 17 23 23 20 17 28 18 18 16 18 23 22 23 14 23 15 16 21 19 22 14 17 35 17 32 20 20 26 19 18 21 24 26 17 20 16 18 23 29 31 18 19 29 22 22 22 24 16 11 15 22 29 21 16 21 16 15 23 20 24 16 21 18 17 23 20 15 23 17 19 16 18 25 29 15 21 21 23 8 18 13 13 27 32 20 22 16 24 24 29 22 26 22 28 26 21 30 21 17 21 16 18 16 26 19 21 24 22 22 20 25 23 28 19 18 12 19 16 20 17 19 19 21 17 17 19 17 21 15 23 24 23 16 21 23 24 23 25 19 16 17 17 11 22 17 21 12 19 20 20 15 17 19 24 22 23 26 18 17 23 31 15 16 15 15 21 26 20 25 23 27 24 22 19 15 17 17 25 17 17 19 25 15 22 22 22</counts>
			</dataPoints>
		</scan>
	</xrdMeasurement>
</xrdMeasurements>