File: data/XRD/_misc/old/XG-600C/_absolute_2th-om_10-130deg_PIXscan_56min_3.xrdml
<xrdMeasurements xmlns="http://www.xrdml.com/XRDMeasurement/2.1" xmlns:xsi="http://www.w3.org/2001/XMLSchema-instance" xsi:schemaLocation="http://www.xrdml.com/XRDMeasurement/2.1 http://www.xrdml.com/XRDMeasurement/2.1/XRDMeasurement.xsd" status="Completed">
	<comment>
		<entry>Configuration=Factory configuration, Owner=User-1, Creation date=7/8/2013 4:01:53 PM</entry>
		<entry>Goniometer=PW3050/65 (Theta/2Theta); Minimum step size 2Theta:0.0001; Minimum step size Omega:0.0001</entry>
		<entry>Sample stage=MRD Cradle; Minimum step size Phi:0.01; Minimum step size Chi:0.01; Minimum step size X:0.01; Minimum step size Y:0.01; Minimum step size Z:0.001</entry>
		<entry>Diffractometer system=XPERT-PRO</entry>
		<entry>Measurement program=C:\PANalytical\Data Collector\Programs\Jorrit\2thom\_absolute_2th-om_10-130deg_PIXscan_56min.xrdmp, Identifier={15BCCF57-2807-42BD-B5B9-ECC0B3DC9284}</entry>
		<entry>Batch program=C:\PANalytical\Data Collector\Programs\SimonL\batch4x_2thom_10-130°_z9.1_x0,10,20,30_y0_57min.xrdmp, Identifier={EED9823A-2BEB-424C-9252-345C4EF2834A}</entry>
	</comment>
	<sample type="To be analyzed">
		<id></id>
		<name></name>
		<preparedBy></preparedBy>
	</sample>
	<xrdMeasurement measurementType="Scan" status="Completed" sampleMode="Reflection">
		<comment>
			<entry>_absolute_2th-om_10-130deg_PIXscan_56min</entry>
			<entry>PHD Lower Level = 4.83 (keV), PHD Upper Level = 11.27 (keV)</entry>
		</comment>
		<usedWavelength intended="K-Alpha 1">
			<kAlpha1 unit="Angstrom">1.5405980</kAlpha1>
			<kAlpha2 unit="Angstrom">1.5444260</kAlpha2>
			<kBeta unit="Angstrom">1.3922500</kBeta>
			<ratioKAlpha2KAlpha1>0.5000</ratioKAlpha2KAlpha1>
		</usedWavelength>
		<incidentBeamPath>
			<radius unit="mm">320.00</radius>
			<xRayTube id="1010048" name="Empyrean Cu LFF HR (9430 033 7310x) DK442154">
				<tension unit="kV">40.0</tension>
				<current unit="mA">40.0</current>
				<anodeMaterial>Cu</anodeMaterial>
				<focus type="Line">
					<length unit="mm">12.0</length>
					<width unit="mm">0.4</width>
					<takeOffAngle unit="deg">4.2</takeOffAngle>
				</focus>
			</xRayTube>
			<xRayMirror id="27010001" name="Inc. Beam Cu W/Si (parabolic MRD)" hybrid="false">
				<crystal type="Graded" shape="Parabolic">W/Si</crystal>
				<acceptanceAngle unit="deg">0.800</acceptanceAngle>
				<length unit="mm">60.0</length>
			</xRayMirror>
			<sollerSlit id="21010002" name="Soller slits 0.04 rad.">
				<opening unit="rad">0.0400</opening>
			</sollerSlit>
			<mask id="22030007" name="Fixed mask 2 mm">
				<distanceToSample unit="mm">220.00</distanceToSample>
				<width unit="mm">2.00</width>
			</mask>
			<divergenceSlit id="22010007" name="Fixed slit 1/8°" xsi:type="fixedDivergenceSlitType">
				<distanceToSample unit="mm">220.00</distanceToSample>
				<height unit="mm">0.19</height>
			</divergenceSlit>
		</incidentBeamPath>
		<diffractedBeamPath>
			<radius unit="mm">320.00</radius>
			<sollerSlit id="21010002" name="Soller slits 0.04 rad.">
				<opening unit="rad">0.0400</opening>
			</sollerSlit>
			<receivingSlit id="22010001" name="Fixed slit 4°">
				<height unit="mm">5.88</height>
			</receivingSlit>
			<detector id="7010017" name="PIXcel3D 1x1 detector" xsi:type="areaDetectorType">
				<phd unit="%">
					<lowerLevel>30.0</lowerLevel>
					<upperLevel>70.0</upperLevel>
				</phd>
				<mode>Scanning</mode>
				<activeChannelsEquatorial>255</activeChannelsEquatorial>
				<activeChannelsAxial>255</activeChannelsAxial>
				<pitchEquatorial unit="mm">0.05500</pitchEquatorial>
				<pitchAxial unit="mm">0.05500</pitchAxial>
				<readOutPeriod unit="seconds">0.135</readOutPeriod>
			</detector>
		</diffractedBeamPath>
		<scan appendNumber="0" mode="Continuous" scanAxis="2Theta-Omega" status="Completed">
			<header>
				<startTimeStamp>2024-08-27T17:46:34+02:00</startTimeStamp>
				<endTimeStamp>2024-08-27T18:42:40+02:00</endTimeStamp>
				<author>
					<name>PRO-MRD</name>
				</author>
				<source>
					<applicationSoftware version="6.1b">Data Collector</applicationSoftware>
					<instrumentControlSoftware version="7.0E 20130304">XPERT-PRO</instrumentControlSoftware>
					<instrumentID>0000000011142674</instrumentID>
				</source>
			</header>
			<dataPoints>
				<positions axis="2Theta" unit="deg">
					<startPosition>9.99826193</startPosition>
					<endPosition>129.99755682</endPosition>
				</positions>
				<positions axis="Omega" unit="deg">
					<startPosition>4.99913096</startPosition>
					<endPosition>64.99877841</endPosition>
				</positions>
				<positions axis="Phi" unit="deg">
					<commonPosition>0.00</commonPosition>
				</positions>
				<positions axis="Chi" unit="deg">
					<commonPosition>0.00</commonPosition>
				</positions>
				<positions axis="X" unit="mm">
					<commonPosition>20.00</commonPosition>
				</positions>
				<positions axis="Y" unit="mm">
					<commonPosition>0.00</commonPosition>
				</positions>
				<positions axis="Z" unit="mm">
					<commonPosition>9.100</commonPosition>
				</positions>
				<commonCountingTime unit="seconds">32.895</commonCountingTime>
				<counts 202 215 205 227 181 209 181 202 208 219 185 173 195 204 199 207 224 205 214 189 223 196 208 225 208 210 185 199 208 193 211 202 203 204 208 237 226 175 230 218 228 191 180 198 214 238 203 197 195 201 222 193 234 186 210 230 190 193 193 214 196 202 218 202 200 206 196 202 193 211 217 192 208 219 205 196 207 183 205 201 215 189 211 193 189 200 212 192 211 196 213 209 206 180 212 183 212 184 230 212 226 219 178 216 194 211 207 213 207 179 182 201 179 189 194 210 193 206 195 177 191 184 193 178 189 213 191 185 203 190 174 224 199 190 196 189 195 192 218 220 167 199 198 180 184 224 201 186 207 195 207 210 198 179 202 197 192 200 173 189 190 179 190 196 209 193 188 214 211 168 184 199 182 210 199 195 185 213 197 190 213 197 177 189 197 187 192 228 205 201 189 168 190 219 171 194 185 218 193 200 216 179 183 200 191 203 186 179 200 208 216 188 205 189 177 178 185 183 177 191 162 211 189 200 197 197 205 169 188 191 214 216 171 164 194 200 181 186 167 201 199 165 190 156 208 199 177 193 189 169 154 179 202 196 194 175 192 163 188 174 179 165 199 208 171 179 167 198 171 204 180 203 199 198 203 174 184 189 195 181 183 164 215 175 186 170 156 188 178 179 178 178 194 171 179 200 174 190 173 201 172 173 184 152 166 201 174 175 201 169 183 171 153 177 201 176 184 204 188 172 179 196 177 179 185 184 145 183 180 180 182 172 180 188 191 202 170 160 203 185 177 166 179 203 177 186 172 179 180 170 152 182 164 178 193 169 177 183 174 161 169 178 166 184 172 186 205 163 208 162 166 155 185 168 165 181 174 181 172 160 165 172 161 162 185 169 186 181 202 184 181 181 169 195 209 193 174 177 162 157 181 155 196 163 178 166 169 171 165 167 196 151 161 178 189 186 199 174 171 188 146 196 181 175 168 173 170 184 175 172 181 150 164 172 168 169 159 172 168 169 145 163 160 163 150 156 177 159 143 185 171 163 175 144 180 169 167 196 172 169 179 157 128 170 165 157 161 178 174 148 166 171 203 165 162 155 166 176 185 173 181 160 169 186 195 156 180 176 170 164 157 152 169 167 186 164 174 184 179 171 176 168 162 153 161 157 145 181 162 156 179 167 177 178 172 146 164 156 164 163 164 152 175 177 172 153 151 169 158 168 165 173 172 172 172 159 168 189 160 176 152 146 180 173 168 154 154 168 145 174 138 170 171 158 156 158 173 146 168 187 171 162 168 153 155 161 167 177 147 149 151 169 185 162 135 169 165 152 158 155 178 181 174 168 175 170 150 201 169 171 138 149 172 168 191 165 151 176 176 166 141 166 172 172 189 178 153 162 153 181 177 155 166 176 121 153 160 151 162 144 174 180 158 144 162 174 148 151 159 160 163 145 147 158 177 158 153 157 170 174 174 149 175 144 160 151 152 154 150 149 173 160 162 166 163 158 174 144 152 143 160 140 157 150 150 151 143 155 170 170 146 141 165 150 141 147 152 159 157 159 185 150 164 155 166 158 139 142 164 144 137 169 148 148 160 143 147 153 162 160 161 160 175 175 161 160 157 175 167 167 129 148 167 135 145 152 166 169 169 160 162 174 168 153 138 148 152 133 154 162 137 163 153 148 152 150 142 145 132 166 187 184 153 125 139 174 171 148 147 174 148 154 149 169 137 149 178 151 143 161 157 152 162 161 164 135 153 158 165 140 184 157 173 174 149 148 154 184 178 174 151 145 146 139 147 174 156 147 141 176 197 152 158 155 150 166 165 177 151 158 177 153 179 141 141 144 167 146 163 127 145 141 140 138 136 144 144 167 143 158 173 182 151 154 157 144 169 152 162 168 137 154 169 166 154 128 160 175 152 146 204 151 131 168 164 112 166 149 142 163 165 141 171 138 128 160 161 167 169 156 149 157 143 159 153 141 159 157 157 166 146 172 157 157 164 161 137 146 144 173 153 187 165 149 153 153 153 163 160 173 158 148 149 157 170 155 153 185 166 171 164 155 150 148 154 133 158 158 143 141 136 173 141 165 159 149 167 150 175 145 163 164 153 161 155 151 145 163 171 157 182 164 157 156 147 156 154 142 168 158 180 143 148 170 143 172 178 170 151 164 166 131 163 157 150 177 168 152 161 173 162 153 152 147 162 168 145 145 174 165 154 160 137 163 149 160 149 168 163 140 162 189 162 162 144 135 156 170 164 155 136 154 152 187 169 151 161 149 159 156 162 158 153 171 150 145 167 169 151 152 169 165 169 163 144 157 170 138 164 141 168 177 156 165 144 158 178 173 154 153 163 172 151 171 177 157 160 139 156 160 149 163 155 160 152 161 174 146 165 144 165 191 187 165 160 159 189 151 164 150 150 159 164 167 161 168 165 158 160 181 186 180 177 166 141 152 181 172 173 147 167 158 143 158 162 175 173 159 166 170 138 147 158 157 146 163 155 158 163 197 129 182 176 165 165 174 168 152 177 140 151 159 184 167 147 161 159 163 173 133 162 155 183 128 162 162 157 177 165 140 167 159 169 154 162 170 147 171 164 147 164 166 162 172 137 164 181 151 173 141 177 168 164 167 159 154 163 170 173 174 157 139 167 165 156 178 168 168 151 169 169 170 149 181 153 170 164 161 169 159 174 156 150 161 147 175 170 168 166 148 175 171 150 138 173 158 153 161 166 157 157 175 168 148 150 175 181 156 158 180 173 181 169 150 164 151 160 158 161 179 174 167 168 171 163 160 150 171 161 159 168 156 162 141 154 166 165 168 172 179 158 168 171 163 156 186 150 154 168 169 151 187 167 158 155 154 182 154 165 147 171 171 175 172 162 194 152 172 158 151 141 171 146 173 187 153 142 165 148 157 144 160 149 156 178 159 200 158 155 169 161 177 160 171 159 169 159 158 171 150 157 148 174 166 163 185 174 180 149 154 146 147 155 162 140 165 154 176 150 157 157 156 162 170 160 145 156 150 155 159 174 136 156 172 149 163 163 146 177 152 158 158 158 158 155 163 162 169 152 156 137 173 170 159 169 156 162 178 178 162 176 175 171 154 154 164 149 151 152 162 151 155 156 162 149 147 163 159 160 151 162 149 164 156 164 158 166 174 155 158 162 167 155 157 155 159 149 138 131 168 131 149 166 161 153 174 166 161 146 150 152 144 156 155 148 158 183 138 167 164 150 137 184 146 171 153 172 155 146 175 173 162 136 160 154 153 146 137 164 143 141 166 172 134 156 144 140 165 148 145 168 177 150 160 144 143 135 145 166 138 143 164 161 169 143 182 136 157 160 158 168 151 183 169 133 162 149 151 148 151 187 179 143 153 149 159 160 161 153 172 148 157 161 158 141 155 148 149 166 163 162 129 162 162 171 153 163 171 155 156 151 134 173 138 166 128 134 148 181 173 156 136 148 150 165 174 134 154 150 152 147 168 149 145 167 162 142 147 154 168 141 152 152 134 131 165 149 139 159 135 153 154 149 151 150 159 140 145 153 151 136 159 126 137 151 139 136 141 162 149 135 140 151 147 145 137 133 172 159 156 143 129 146 146 134 152 154 164 139 171 138 126 141 146 148 146 144 150 146 161 150 155 166 117 124 148 135 132 131 177 163 130 151 164 149 140 133 142 161 160 137 150 161 149 151 147 162 157 139 138 121 158 143 147 155 137 145 121 127 146 164 141 129 148 163 149 132 118 136 150 153 143 133 128 137 146 167 154 126 122 163 155 147 125 129 135 121 140 126 147 128 144 155 120 149 141 136 157 154 122 139 143 142 132 129 161 146 138 148 129 141 151 136 144 135 152 140 145 145 142 136 127 141 149 134 138 142 148 130 132 136 134 121 139 126 129 129 149 125 133 126 137 141 141 136 136 162 151 152 128 157 125 119 137 132 138 135 142 143 142 119 150 132 140 149 125 112 117 155 136 132 134 129 143 139 147 118 103 132 133 127 134 134 125 131 127 116 148 101 136 116 145 140 145 115 146 145 130 140 127 149 127 141 111 121 145 131 114 143 120 152 144 126 141 126 126 139 111 151 133 128 111 138 148 133 126 136 124 143 120 141 151 120 109 136 129 162 119 129 149 124 139 133 117 146 111 121 140 127 120 133 134 142 129 134 118 135 129 148 155 147 131 122 124 132 112 126 152 132 114 123 151 128 118 126 118 129 140 135 128 132 114 140 128 118 135 111 148 135 127 119 135 126 144 126 109 134 125 138 116 142 114 135 117 126 130 133 120 140 138 129 138 126 138 124 141 124 150 136 121 123 140 115 123 135 123 138 123 130 104 133 129 139 125 123 115 131 109 137 139 127 123 109 147 146 113 139 126 118 126 125 126 135 132 137 103 123 150 108 116 135 136 118 131 112 112 116 137 128 136 120 133 126 128 119 122 131 104 112 106 127 149 135 124 132 131 121 118 154 111 126 121 136 141 134 106 111 122 123 130 142 131 136 124 139 134 131 111 120 130 129 139 115 108 135 128 126 131 117 138 120 118 130 129 131 117 141 125 120 112 128 104 125 138 124 123 106 122 127 116 141 128 136 110 126 127 115 131 130 132 108 117 136 109 107 95 115 117 125 145 96 135 125 126 115 127 124 128 146 116 118 119 115 114 114 134 121 125 122 144 140 121 120 124 132 122 128 96 139 120 123 124 112 132 110 121 130 128 120 141 130 111 129 122 119 119 113 133 146 102 129 108 144 148 112 125 125 140 119 108 127 125 117 133 129 125 120 114 114 117 143 121 115 127 144 119 128 134 131 115 120 111 143 132 117 129 108 125 138 125 130 123 153 104 104 145 140 132 117 135 109 109 124 110 140 120 132 128 109 104 121 123 109 124 123 124 104 130 117 131 117 147 99 123 117 107 120 132 127 129 118 109 134 124 103 112 124 117 106 115 105 126 131 120 134 101 107 113 133 105 111 135 115 114 89 124 122 128 119 136 104 115 132 111 136 127 127 150 99 124 116 100 118 121 114 123 111 101 137 124 114 144 125 116 121 129 114 118 101 125 112 122 120 133 120 150 133 112 136 112 126 124 108 114 113 140 111 119 141 113 138 115 131 103 109 126 103 122 114 113 121 122 108 117 115 90 126 124 142 128 118 111 122 103 120 142 109 124 121 110 119 122 109 111 113 104 126 124 121 130 123 139 110 126 129 107 104 127 113 124 117 124 128 124 116 126 143 124 131 119 113 122 117 130 122 110 107 118 108 119 111 126 124 126 129 126 114 116 131 130 121 122 99 129 123 99 119 127 110 125 141 114 124 115 116 108 96 109 111 135 111 103 105 127 124 121 130 116 103 134 106 107 139 124 125 128 129 97 114 118 137 170 135 117 117 127 125 126 120 100 117 124 130 99 122 121 116 124 127 131 110 139 106 118 114 127 108 112 130 113 147 114 116 97 122 128 114 110 110 120 116 125 140 135 109 141 112 97 116 133 132 123 133 110 116 126 128 109 117 113 110 136 124 119 115 151 126 128 114 116 130 117 137 113 109 133 118 134 125 117 101 117 125 109 129 123 131 134 118 134 121 124 126 96 129 113 121 121 112 128 123 115 96 113 134 121 121 125 117 113 106 120 124 123 137 140 128 127 104 148 121 138 129 99 127 123 95 121 114 114 120 114 116 119 107 115 127 123 115 109 129 124 125 125 132 120 119 133 115 106 115 122 133 108 117 111 137 120 122 137 125 116 136 129 114 131 136 127 130 119 127 109 89 122 97 119 119 128 116 126 122 138 123 130 130 122 89 117 111 109 121 124 144 119 117 124 137 131 133 126 122 132 120 98 120 126 117 124 113 114 107 135 127 122 128 116 119 118 138 120 140 124 109 123 146 119 121 117 123 143 133 123 137 97 132 99 125 121 121 116 122 124 119 122 128 125 104 99 108 113 105 97 100 126 115 108 150 125 114 111 129 110 100 138 102 126 93 114 154 114 121 139 100 133 143 117 124 108 119 110 102 115 112 117 120 121 127 118 112 129 113 128 128 108 116 121 115 126 117 128 108 114 120 129 113 118 118 116 120 108 136 117 130 119 120 116 122 112 118 116 136 142 116 151 110 118 147 121 135 116 136 133 126 125 112 124 113 109 115 118 119 116 131 108 132 104 122 108 118 114 121 127 134 130 117 109 130 173 130 103 95 144 118 129 102 156 120 133 129 121 114 133 130 128 119 127 114 121 138 121 116 138 139 103 106 131 124 132 114 130 128 139 130 119 119 124 117 117 128 125 128 121 132 114 139 133 122 126 111 127 124 124 107 127 130 120 148 123 126 106 118 93 124 112 136 115 100 120 108 104 123 105 101 131 104 110 136 124 116 120 126 115 109 119 135 113 120 126 118 113 117 129 107 124 101 118 121 105 112 121 115 130 131 127 110 126 106 136 125 117 119 91 108 118 117 121 131 101 115 120 112 134 91 114 135 126 120 115 108 110 130 120 121 130 117 134 119 115 118 124 105 121 112 149 118 112 126 115 131 134 129 118 122 111 136 110 118 122 127 109 120 120 130 145 119 119 143 119 96 118 142 128 124 114 101 124 130 117 117 124 122 118 128 116 94 126 116 121 121 128 122 96 100 113 136 126 131 114 113 125 107 147 117 101 117 113 129 118 133 129 131 132 136 110 106 130 99 110 128 124 126 128 121 142 119 115 128 139 144 132 123 135 134 119 134 137 112 126 134 114 126 117 129 112 117 110 129 122 122 135 113 112 111 124 133 128 131 123 127 130 117 133 119 120 124 121 107 124 124 96 118 107 115 112 108 120 112 116 122 136 111 129 127 114 127 99 111 125 136 140 111 127 119 135 134 131 138 115 112 141 97 133 96 126 125 115 131 128 121 136 121 119 124 122 115 120 122 120 110 114 116 98 139 100 126 128 116 137 124 116 117 120 124 130 114 127 127 123 127 129 126 126 118 100 145 123 115 102 142 139 108 115 111 121 108 124 108 128 148 105 147 121 107 139 130 122 138 96 110 129 114 118 119 119 128 128 131 130 120 107 111 121 124 134 102 124 133 118 113 127 115 107 125 130 132 109 153 121 135 103 130 113 107 116 128 130 119 128 138 137 124 120 138 130 131 129 119 124 136 129 129 131 134 104 124 137 124 128 141 114 114 113 138 117 142 127 138 116 124 113 133 110 127 118 133 95 117 128 136 131 136 118 107 121 126 135 130 122 120 123 110 122 132 121 130 114 118 132 134 146 128 117 144 121 133 126 146 139 123 136 128 111 108 127 129 145 116 131 127 134 125 128 120 121 109 111 142 132 126 122 132 122 128 124 149 125 101 131 115 138 132 107 114 112 137 115 123 129 143 135 141 128 127 115 114 108 116 116 130 117 128 116 132 130 133 109 123 125 139 122 116 107 141 112 135 125 117 136 128 126 128 132 130 128 120 137 129 106 141 139 130 144 134 120 130 120 140 124 128 141 118 134 136 134 135 131 101 136 131 135 113 142 129 122 129 108 142 139 129 117 123 133 139 153 118 154 122 129 131 122 130 124 118 135 136 144 136 127 145 121 122 135 142 119 152 151 149 133 133 148 112 121 162 118 150 123 123 144 143 146 132 119 131 143 131 130 132 152 142 131 136 143 156 135 146 136 142 148 149 148 133 117 149 117 125 144 165 143 153 129 135 141 136 126 126 148 138 124 163 131 144 144 128 137 158 153 124 151 129 150 130 124 152 147 155 136 132 142 162 144 123 118 124 147 141 128 135 153 145 146 152 160 155 155 161 126 144 135 145 146 157 159 155 162 146 160 157 157 152 141 160 168 161 147 174 166 162 158 144 167 183 152 169 179 180 171 167 182 195 204 208 176 191 182 210 237 217 218 226 232 224 197 232 239 245 239 247 270 258 242 210 219 216 259 211 247 208 211 239 202 184 168 190 187 198 159 180 194 167 154 172 167 184 165 149 176 168 142 158 142 155 147 140 152 139 153 159 169 146 146 141 132 140 133 133 132 149 144 140 128 140 138 129 145 164 134 145 123 126 140 132 135 138 140 147 145 126 128 156 132 141 131 133 121 142 140 117 120 131 127 131 118 153 132 119 137 127 145 127 138 139 131 130 132 145 144 133 132 130 142 154 137 125 138 124 128 125 127 141 132 128 136 120 119 139 137 128 119 145 134 121 153 141 124 135 132 135 114 117 122 131 128 132 165 115 129 116 123 121 111 137 132 119 136 125 138 135 134 123 142 131 110 124 137 131 126 126 140 129 130 105 128 128 139 116 138 142 121 125 117 138 127 115 120 131 145 114 143 126 136 126 132 131 140 137 123 143 133 133 139 165 148 129 104 139 136 141 138 123 133 129 148 154 134 148 133 149 133 139 123 124 140 130 141 150 125 127 117 130 138 121 135 151 129 117 137 132 113 134 128 120 130 148 123 134 132 135 131 127 125 126 127 128 149 133 148 115 129 119 127 132 150 124 129 120 137 127 128 129 148 128 137 116 130 121 132 143 138 136 163 121 133 120 105 125 129 136 133 137 134 127 124 130 138 141 123 142 112 129 119 111 140 138 124 131 120 115 130 151 117 131 131 145 111 119 134 148 118 140 133 115 131 130 156 126 154 127 131 131 144 126 125 132 136 143 133 119 140 113 130 130 150 114 121 126 154 109 113 143 129 138 136 139 131 139 113 145 143 131 132 131 125 148 127 132 143 108 139 146 130 121 145 120 163 121 106 122 145 142 143 125 130 123 161 134 116 152 143 112 145 144 123 142 131 137 146 140 124 129 133 112 134 137 130 148 145 126 123 120 145 148 136 141 133 126 127 135 133 122 147 133 132 137 139 119 142 135 134 132 118 131 158 129 116 134 166 128 114 139 136 146 124 138 130 140 115 124 142 145 142 147 123 137 131 141 119 146 140 128 116 126 131 131 123 128 120 140 135 121 142 139 149 134 135 131 143 121 134 140 133 144 143 139 131 138 130 133 150 119 143 135 154 140 109 110 142 130 145 129 140 123 136 154 106 128 131 132 135 119 121 119 125 137 128 144 119 133 126 124 134 133 139 142 125 128 129 123 124 129 124 120 130 122 112 130 153 114 115 150 130 125 118 144 117 129 139 154 116 133 139 127 145 116 131 122 136 137 107 140 123 131 128 105 152 133 121 142 130 100 126 116 131 131 131 156 146 134 136 160 109 124 130 136 125 127 146 113 140 135 134 140 124 128 143 142 158 129 138 100 132 128 126 132 157 118 151 121 137 131 112 145 145 119 121 140 139 129 115 123 138 152 108 135 144 140 123 141 144 142 122 136 118 132 135 140 135 136 147 124 124 118 136 138 122 135 132 136 138 127 131 123 122 137 134 127 131 130 135 122 131 118 130 119 132 128 104 131 103 127 131 118 120 125 142 135 131 126 134 141 134 130 120 129 127 142 140 162 122 139 141 118 125 133 155 149 114 138 135 130 124 142 138 146 130 141 140 118 142 118 120 134 121 129 129 135 117 134 136 128 116 99 135 139 148 144 139 135 150 141 145 121 130 133 125 142 129 142 130 135 156 130 135 133 139 146 133 149 159 135 137 131 116 128 164 146 133 124 138 133 150 154 147 133 127 133 155 123 145 122 139 136 147 139 138 125 135 141 123 162 145 137 103 159 158 116 129 133 148 129 130 109 142 117 149 132 122 125 150 113 154 147 139 132 140 138 165 130 118 152 132 123 138 122 120 143 135 142 130 134 125 122 138 137 140 134 141 130 139 139 163 133 123 153 139 142 133 135 126 146 132 121 122 138 139 171 128 137 134 148 136 154 125 139 132 145 154 139 150 138 133 123 124 136 141 127 137 119 150 131 132 134 144 139 141 126 135 134 134 113 123 145 130 141 145 150 110 118 134 129 134 131 140 126 134 126 143 151 136 138 138 143 129 120 139 142 123 156 121 148 132 134 135 132 142 137 136 136 129 149 140 130 151 145 142 118 125 126 131 109 124 152 142 124 143 141 121 146 143 120 136 135 140 133 165 119 115 122 151 113 127 111 141 149 147 138 115 134 131 132 148 138 127 124 129 138 133 125 149 115 126 146 115 140 134 154 126 152 146 126 144 112 145 144 147 121 122 118 154 129 120 153 121 116 146 131 158 138 169 124 138 137 157 128 129 149 132 134 130 134 123 123 158 135 135 141 121 133 150 156 122 138 124 142 146 129 135 122 152 146 132 139 120 153 154 132 152 108 134 138 136 133 133 129 131 143 122 117 137 144 141 142 136 114 133 143 119 136 160 143 143 152 110 138 123 132 124 134 125 140 138 159 146 134 151 142 133 131 148 135 123 138 134 117 144 139 144 139 114 146 135 126 132 131 137 137 120 139 141 129 149 115 159 143 135 128 113 144 139 140 122 127 125 123 148 130 141 131 143 154 121 129 141 125 107 122 99 144 156 141 126 119 143 151 133 121 148 138 165 107 143 126 127 125 139 147 140 126 141 139 145 124 137 134 130 126 132 129 127 143 137 122 126 121 130 145 130 144 135 144 141 150 126 139 132 123 129 136 156 143 137 116 139 106 127 148 121 153 145 140 126 122 144 128 142 136 134 141 140 126 130 126 151 125 146 149 135 134 127 139 132 128 149 140 139 124 137 142 129 122 124 148 134 135 124 129 136 148 151 167 133 146 141 118 139 130 139 137 134 139 120 137 150 134 157 125 113 148 124 141 155 125 149 136 153 136 151 128 143 126 143 143 154 148 141 126 164 141 127 120 130 146 149 140 131 151 117 153 131 102 145 129 117 149 135 137 132 116 141 147 126 145 134 126 149 136 144 126 133 125 130 151 144 147 126 158 125 125 132 134 137 152 141 138 124 153 125 145 120 128 128 142 131 134 139 129 150 151 151 143 159 145 126 151 152 152 137 131 125 141 148 143 132 136 142 126 130 164 139 149 114 127 132 157 136 144 148 152 125 131 134 121 130 155 126 130 173 151 123 130 132 152 132 129 147 135 155 148 146 143 132 133 133 119 127 132 147 133 142 133 124 137 137 134 140 115 151 151 138 139 154 139 132 142 115 132 105 156 116 133 157 131 149 151 145 144 159 159 145 133 124 139 121 144 107 116 137 124 142 141 128 129 157 128 147 131 137 122 136 119 151 136 155 127 125 139 139 135 132 122 133 155 154 154 106 134 117 129 136 160 144 145 129 151 118 134 148 141 132 142 135 133 131 162 132 131 128 134 148 138 120 158 134 158 129 135 140 152 150 137 138 121 133 158 140 130 124 147 139 114 139 117 146 150 156 132 165 141 129 126 154 136 143 144 122 146 144 163 151 138 131 126 125 129 136 161 141 142 150 142 160 135 136 139 145 144 143 139 142 134 158 135 114 131 154 144 133 136 151 153 129 138 151 144 157 142 150 136 153 127 154 132 137 131 137 171 132 134 144 146 136 145 159 140 155 140 122 163 131 157 130 124 143 157 131 153 154 140 132 135 164 154 132 132 123 139 131 152 139 123 142 153 118 141 138 131 158 138 152 141 139 147 134 143 152 150 136 114 158 127 137 140 136 136 131 148 123 125 121 134 146 140 147 160 133 130 132 134 126 131 148 166 151 151 117 152 144 146 161 135 153 146 158 127 125 141 165 151 132 139 128 127 140 124 140 134 158 142 153 148 133 139 132 144 128 137 120 143 138 142 134 131 116 149 127 170 144 149 143 162 149 144 144 147 163 151 139 153 138 147 125 134 137 152 155 129 138 126 150 153 130 134 125 121 148 142 132 154 128 126 137 114 138 153 138 132 136 127 145 127 151 134 130 136 167 138 148 138 133 138 155 133 123 154 141 132 143 127 141 140 157 155 140 137 135 123 169 138 152 141 168 152 142 116 127 124 139 153 161 141 129 142 150 138 149 146 119 136 132 141 129 144 126 124 162 130 141 150 158 143 121 147 131 131 146 132 137 150 156 115 143 138 137 140 142 157 145 141 148 153 153 141 153 136 126 145 156 135 163 159 151 142 149 136 129 134 125 142 163 142 142 158 124 131 152 160 147 127 159 142 156 137 129 123 141 143 143 143 136 148 143 126 143 145 147 161 153 135 133 171 155 124 139 143 156 129 151 140 164 123 142 134 136 144 167 147 130 130 151 112 144 139 135 124 145 145 168 133 140 142 148 156 141 154 159 143 144 145 124 151 162 155 145 144 156 134 164 144 140 141 134 130 139 144 134 136 119 125 128 130 156 154 143 128 149 152 153 147 133 152 124 133 136 130 151 119 150 130 156 144 165 145 144 159 147 133 128 136 149 155 153 152 135 139 148 140 157 164 176 178 157 137 150 130 139 129 161 135 100 127 140 141 159 150 139 133 148 150 160 154 154 133 150 153 166 139 137 138 157 142 145 158 146 156 139 152 132 127 135 159 146 128 135 150 149 161 136 126 169 130 161 141 167 135 154 159 155 177 154 140 142 138 153 136 131 155 148 141 148 153 148 129 170 146 146 151 144 148 144 142 148 138 154 158 155 151 165 147 152 152 161 132 176 155 154 160 144 133 159 139 147 155 149 147 152 119 144 135 155 172 157 127 155 162 181 175 145 158 148 166 147 174 139 169 156 155 159 152 132 177 166 135 146 152 132 150 149 170 133 122 157 158 138 161 158 159 141 143 140 146 193 145 150 134 161 163 145 156 147 161 166 142 148 136 125 142 129 145 142 140 154 151 170 141 156 180 137 150 163 149 159 137 136 145 141 158 158 137 129 135 152 162 136 132 148 151 143 158 173 154 143 157 151 154 142 150 137 139 151 142 143 151 148 159 127 175 140 147 132 150 153 141 167 163 122 168 140 136 154 145 154 144 142 138 134 144 134 156 144 136 132 164 151 117 129 140 140 146 146 140 153 152 157 147 149 160 146 182 137 165 153 144 139 139 145 133 144 143 126 143 140 138 137 130 144 135 135 158 146 118 151 146 127 156 161 139 129 150 144 142 176 149 144 162 152 155 153 146 146 140 130 119 148 157 150 137 168 151 143 150 139 156 126 134 141 115 134 167 158 131 134 148 157 170 137 148 143 151 153 138 151 152 143 138 149 147 140 129 147 161 146 132 138 144 166 137 154 140 172 123 156 137 140 136 139 154 142 161 139 147 142 174 159 154 157 137 164 157 142 141 115 137 133 154 164 131 129 141 134 162 155 156 153 146 157 156 163 139 146 141 137 148 155 158 160 150 129 136 147 178 136 172 153 158 153 160 156 132 148 129 156 141 153 156 124 158 149 146 151 161 134 142 137 153 142 155 151 150 131 142 150 167 120 158 138 159 150 154 157 135 150 151 142 146 158 136 167 140 144 146 137 165 128 152 148 136 148 155 131 164 137 144 142 141 134 142 143 154 138 154 144 140 150 157 130 155 169 166 128 143 142 124 145 165 151 173 142 139 144 125 169 150 133 144 125 135 127 136 150 141 154 150 149 136 151 153 151 156 141 129 158 153 147 167 150 155 148 126 128 152 157 151 157 150 139 130 166 164 142 152 130 148 130 143 154 149 156 138 128 130 136 140 128 144 149 131 136 144 157 160 140 140 149 147 135 131 182 166 141 149 132 159 142 170 159 155 157 137 133 146 150 132 148 155 146 150 159 168 132 144 146 156 151 157 134 139 161 134 180 160 175 149 160 145 140 135 131 130 164 132 156 130 143 151 145 133 160 132 152 130 162 166 167 135 152 145 125 180 149 132 138 152 167 156 147 143 159 152 153 146 143 144 156 139 147 171 153 135 145 156 152 152 152 148 153 147 122 136 148 163 153 150 147 149 155 168 156 168 175 132 154 151 124 147 140 140 147 152 168 138 140 137 137 120 153 135 118 138 123 153 172 149 148 164 159 127 151 163 152 164 148 144 139 144 134 176 133 164 124 150 158 183 155 141 165 159 134 154 164 154 144 141 139 131 145 130 129 139 151 141 122 158 151 149 157 146 137 132 147 145 146 144 139 158 164 139 152 157 146 132 130 141 141 156 172 151 157 146 140 139 148 144 128 119 174 145 170 156 144 158 149 140 137 183 144 153 151 150 153 138 133 130 133 137 158 145 147 143 163 137 148 151 156 142 149 148 112 153 132 146 153 166 139 130 134 151 159 144 160 144 155 133 140 145 137 137 145 151 142 137 140 147 138 161 143 147 131 157 147 152 131 139 153 152 145 155 140 129 137 166 141 151 133 145 159 139 136 137 144 162 126 142 144 140 134 161 134 134 141 143 141 157 131 144 170 159 140 154 158 156 165 170 147 145 139 131 127 160 130 149 143 134 169 166 143 153 134 158 154 135 168 129 146 142 158 148 139 136 141 154 144 120 136 152 123 128 148 146 135 139 154 139 138 153 151 150 142 152 153 146 132 171 128 150 167 136 156 164 155 144 148 127 132 138 149 141 165 146 138 154 140 137 156 153 134 160 137 137 155 162 151 164 165 172 155 150 145 135 144 156 139 151 135 140 136 144 154 139 160 152 159 133 140 128 143 145 171 145 137 156 146 128 159 134 130 151 140 151 124 143 174 154 137 143 156 145 168 136 152 145 139 142 143 130 155 145 151 127 150 155 159 149 157 171 144 110 164 152 150 160 134 142 150 154 136 148 155 148 126 142 146 160 149 140 132 132 160 137 145 117 158 156 156 149 161 150 155 129 148 147 154 142 130 166 138 140 141 153 137 147 137 132 166 167 131 165 150 153 142 141 133 143 164 144 142 141 131 142 145 152 141 154 159 165 138 168 140 165 145 143 145 153 139 147 124 145 150 165 157 114 121 123 157 138 172 162 146 133 128 141 150 160 162 158 131 163 150 159 146 131 139 155 156 147 135 150 130 134 150 141 128 138 163 148 164 148 139 165 153 164 144 134 122 157 155 136 155 151 147 159 125 162 146 157 145 151 162 146 136 130 151 158 121 133 171 141 139 121 126 140 145 118 144 170 160 166 161 146 129 147 151 157 153 166 130 132 141 148 144 146 147 163 163 149 126 161 151 168 133 118 161 156 149 147 144 149 145 133 154 161 146 160 134 155 160 137 153 142 151 158 162 131 147 151 125 153 155 147 159 157 151 138 154 146 158 132 136 127 151 133 171 133 149 159 126 147 135 159 141 148 158 132 123 150 126 146 145 141 113 121 157 170 152 154 132 149 144 154 176 152 157 149 139 159 148 151 150 132 141 140 145 174 136 159 143 129 159 138 145 132 169 144 135 140 140 163 161 133 173 141 126 139 150 142 149 123 128 158 149 148 144 151 147 150 149 137 152 147 142 147 143 137 156 140 158 149 148 144 157 139 153 132 139 143 152 150 140 146 129 149 146 139 175 159 152 154 152 165 144 132 135 165 154 135 140 162 140 152 146 146 143 145 133 148 162 143 147 149 147 139 155 137 167 140 143 155 151 153 157 141 148 131 151 168 145 147 140 149 153 155 142 158 148 163 126 157 165 157 159 139 141 152 144 146 155 154 135 157 147 158 127 144 135 143 157 144 147 159 139 169 169 153 141 163 129 162 131 162 146 127 159 125 148 148 129 145 149 154 127 131 162 145 149 174 143 156 154 159 160 157 170 157 163 175 143 150 152 155 157 137 141 145 151 159 151 151 167 152 143 128 155 152 160 156 166 176 156 139 138 149 150 154 154 125 146 143 152 146 156 151 141 157 150 159 130 143 136 142 148 147 144 146 130 136 139 141 151 152 131 158 159 144 143 170 138 166 160 137 169 164 156 155 149 153 171 159 151 152 152 155 151 142 153 140 144 162 153 158 153 132 167 154 154 146 166 161 159 150 142 150 125 154 154 148 149 152 166 134 146 160 148 149 146 172 147 135 153 135 166 160 170 160 142 153 166 153 161 136 153 139 166 160 160 161 158 168 145 152 156 147 151 157 133 141 151 143 136 150 152 140 158 152 150 134 154 161 151 140 146 145 122 143 155 142 181 152 132 126 158 141 146 138 166 159 158 158 159 141 155 147 170 163 150 154 159 169 160 152 156 144 153 146 158 147 144 143 142 166 164 150 177 177 135 153 148 120 153 159 164 157 131 155 160 149 147 143 134 149 149 156 175 153 156 178 166 136 156 165 141 177 155 154 127 156 176 137 146 157 122 130 160 173 173 154 157 141 177 149 146 136 170 163 156 150 171 139 150 125 152 148 138 136 148 145 155 160 179 145 168 160 132 146 134 162 157 162 142 139 143 151 151 163 146 150 135 141 159 163 142 125 146 144 137 143 162 159 171 158 175 155 171 154 144 141 170 153 172 166 168 167 168 175 153 144 166 173 165 144 152 173 156 154 170 169 158 160 139 132 153 152 173 165 180 170 159 159 169 130 128 136 154 139 171 137 151 172 162 143 135 136 161 160 155 154 190 164 166 153 159 181 172 151 138 143 159 159 158 145 166 169 159 163 158 173 154 160 175 158 158 185 158 179 142 173 146 167 152 164 159 153 144 159 156 169 167 177 176 138 160 178 155 165 167 166 158 167 167 163 174 154 165 168 190 158 186 179 177 179 170 152 159 146 150 190 165 175 168 176 170 157 188 163 166 171 157 168 177 168 194 179 147 167 165 178 166 180 196 184 152 171 176 178 143 193 170 149 179 156 150 168 181 183 174 155 173 177 177 160 178 182 160 177 182 180 174 166 177 168 151 163 162 171 166 196 160 139 150 168 157 147 171 160 168 169 164 175 162 160 158 167 168 163 168 175 146 159 167 151 165 158 147 154 153 152 157 183 145 169 146 189 151 157 142 167 143 169 139 163 152 139 149 146 173 157 152 151 134 144 139 148 136 151 138 164 177 162 149 150 137 151 177 137 137 161 164 151 160 144 153 156 138 162 140 171 135 145 144 146 139 150 170 135 156 140 162 148 171 143 154 152 152 148 128 147 148 158 129 152 153 151 177 110 171 149 154 151 155 144 159 160 160 142 158 136 156 144 149 128 151 136 158 143 142 173 157 145 131 160 146 151 141 137 143 156 158 158 142 168 148 142 143 127 160 144 148 173 130 171 142 159 163 154 161 150 170 158 147 158 139 151 122 147 145 130 150 163 158 126 154 166 146 148 142 166 151 164 152 147 155 142 141 153 151 148 165 161 147 141 143 157 139 133 133 167 172 144 137 131 143 150 147 164 145 151 160 142 152 126 159 148 143 140 175 158 160 136 153 176 156 143 157 152 163 133 146 145 128 148 148 150 145 147 144 134 149 177 157 141 140 147 141 128 151 149 142 151 145 174 134 136 138 155 144 170 144 140 162 149 137 154 167 146 141 153 174 163 176 143 142 148 137 157 131 143 170 179 146 180 168 147 140 158 142 145 169 171 162 155 154 142 158 164 159 167 157 153 153 120 125 139 152 160 157 167 164 158 145 153 154 142 154 146 139 148 148 138 173 153 135 143 173 147 142 146 118 154 134 164 166 154 148 143 147 154 156 162 142 140 153 163 149 142 140 142 148 147 152 153 155 155 155 169 144 145 122 132 150 135 140 172 155 146 139 146 168 169 151 154 140 150 134 168 164 163 143 139 147 156 155 159 157 161 166 128 148 167 143 155 148 160 135 141 156 151 164 168 180 149 144 168 128 155 131 151 160 132 135 126 185 139 139 158 155 163 145 144 164 177 171 168 139 158 152 138 143 147 136 162 146 163 139 159 144 183 137 143 167 169 148 138 145 132 160 116 145 149 135 146 155 148 158 154 160 154 154 147 143 134 154 142 136 150 160 152 158 155 147 153 136 151 148 139 153 144 153 156 129 161 141 141 148 128 152 138 165 146 144 142 136 128 143 144 155 160 145 145 165 140 163 169 141 164 186 144 144 182 142 150 152 146 129 154 170 142 167 157 138 153 151 152 143 137 153 144 136 152 144 141 175 144 162 134 152 138 171 147 124 159 161 149 157 161 147 138 131 164 143 144 157 162 152 132 142 163 158 147 140 156 127 130 155 134 157 135 147 149 139 146 158 147 159 160 173 148 152 173 162 154 127 153 135 160 132 152 135 159 147 120 141 151 151 154 132 141 137 154 157 142 129 150 156 151 151 143 159 170 132 126 145 150 144 146 143 154 158 163 158 153 167 136 143 155 163 157 156 143 160 158 138 138 186 133 132 152 133 151 140 148 135 131 175 156 156 171 141 144 175 132 137 140 164 143 156 142 149 151 163 165 149 159 158 182 162 150 136 150 129 158 158 143 164 135 146 150 179 158 142 147 137 167 132 136 155 153 153 136 152 148 125 180 171 139 154 157 138 146 166 147 136 152 162 170 136 152 132 169 142 149 122 137 154 141 137 134 147 156 147 134 154 158 167 137 134 148 136 138 163 145 167 176 174 135 134 122 132 150 156 148 137 158 128 154 134 134 166 150 158 145 141 160 140 158 156 141 149 147 149 148 169 145 183 142 150 142 141 158 132 130 143 155 161 136 154 151 159 145 139 151 140 156 154 126 126 149 135 142 127 145 152 143 125 167 140 123 168 135 170 138 142 139 147 148 126 158 146 165 143 161 161 157 160 139 153 151 156 135 156 153 146 123 150 143 161 134 151 145 131 139 119 140 165 146 167 148 147 143 167 159 142 138 157 140 144 143 162 154 140 148 137 154 152 158 151 130 140 142 148 143 164 153 143 149 146 161 153 139 119 164 146 157 148 173 141 146 141 147 144 136 141 143 153 137 132 129 143 127 169 142 147 131 153 151 156 150 171 130 139 166 131 106 159 161 150 163 123 132 140 161 154 147 122 153 126 143 131 143 154 140 146 144 153 157 151 133 157 156 142 155 151 171 143 137 151 148 145 136 142 145 132 138 133 133 150 143 153 127 138 135 145 140 135 155 133 148 150 153 152 149 136 153 140 171 151 135 142 166 160 155 149 128 158 143 147 149 167 142 132 157 150 139 138 166 125 139 149 144 179 164 153 145 168 146 162 117 149 148 182 125 138 144 136 148 171 142 131 147 158 169 160 139 140 127 157 130 135 179 130 132 155 137 155 138 134 180 149 127 158 152 132 140 131 151 159 148 132 153 133 154 133 137 140 148 132 120 142 168 150 144 162 145 142 144 143 128 148 135 118 142 153 155 165 147 153 165 146 152 142 143 154 142 148 171 156 163 160 132 157 128 133 143 137 131 134 136 149 159 145 150 168 152 143 135 135 157 138 146 139 130 137 166 170 165 127 144 144 143 145 137 133 151 132 147 147 123 153 150 152 155 125 144 139 135 152 166 148 156 140 132 143 157 169 167 172 152 149 147 165 153 143 156 124 166 147 154 160 151 139 143 141 126 169 161 147 165 154 144 133 137 164 130 152 149 127 138 135 151 137 134 135 125 163 124 161 162 139 155 156 149 144 149 135 143 147 151 156 127 139 176 136 154 148 170 156 125 145 133 127 138 144 154 139 128 145 143 158 157 145 131 141 133 153 142 124 148 139 139 149 160 133 155 140 113 154 154 132 154 149 176 141 139 163 153 178 148 140 147 169 145 132 136 159 146 135 133 130 150 133 144 149 155 148 149 150 152 155 142 141 156 148 157 154 146 165 146 163 157 131 143 158 146 161 162 144 148 140 145 152 142 149 153 159 144 149 133 164 171 172 159 144 166 148 134 148 141 153 161 164 155 123 138 148 144 130 153 127 152 155 155 136 138 143 144 166 163 152 155 126 153 162 156 146 157 142 170 148 154 147 158 138 142 135 165 154 151 146 161 153 173 137 131 138 155 145 143 143 158 134 168 140 132 155 151 155 133 160 164 158 149 137 141 140 135 132 140 144 158 164 181 133 139 138 144 170 153 161 155 137 152 188 138 131 157 156 134 145 141 149 139 142 166 168 140 151 152 154 138 147 149 157 151 140 137 137 169 141 160 135 125 148 143 150 146 153 149 136 127 150 151 133 143 164 140 144 141 158 153 135 140 148 140 149 140 135 142 156 154 147 144 162 154 156 166 154 142 159 142 149 164 131 139 154 145 175 148 154 159 173 172 156 138 157 183 158 139 133 132 156 148 150 165 177 131 146 144 160 146 188 156 168 139 143 169 121 154 149 138 134 154 139 176 154 159 144 115 144 142 126 141 147 153 153 156 140 176 141 130 142 144 144 157 158 127 135 141 154 136 166 156 139 158 156 149 131 147 129 159 158 134 151 161 162 135 139 141 136 142 157 141 140 154 133 147 167 143 137 138 156 149 164 149 158 155 147 152 154 156 148 145 165 125 157 147 161 140 161 147 149 161 157 133 186 132 168 150 129 154 162 146 167 151 136 139 150 175 164 158 158 169 126 127 151 145 151 160 164 149 146 152 129 158 124 181 151 153 151 137 155 149 153 151 143 162 126 156 161 149 149 135 165 144 166 156 128 159 162 134 146 161 146 155 147 150 136 148 168 130 171 140 177 149 157 171 157 146 155 152 163 165 148 145 137 155 159 146 130 128 168 142 157 148 152 158 145 153 170 172 144 160 155 167 157 147 170 137 142 160 153 162 157 160 158 153 132 137 162 129 147 163 152 157 155 140 157 152 152 172 184 141 140 143 148 170 145 150 141 160 169 147 170 163 148 152 124 144 151 149 163 165 164 140 169 138 144 152 144 155 161 151 150 133 160 132 139 149 132 138 155 168 161 150 165 140 142 136 126 164 166 165 146 147 136 147 157 158 142 151 164 148 134 132 140 166 145 135 131 161 161 154 159 146 151 163 167 150 157 147 148 139 136 148 155 122 136 157 141 146 151 164 152 146 163 161 126 141 135 141 149 158 149 156 147 165 152 156 144 122 169 162 154 143 162 152 147 129 139 139 135 136 185 152 148 155 142 162 141 144 145 142 144 162 148 154 131 156 148 166 150 175 175 152 174 137 138 157 156 164 152 148 134 136 157 136 139 150 157 134 144 147 153 178 174 150 136 127 163 153 152 174 178 151 174 164 151 126 176 150 134 146 149 147 148 158 146 149 169 137 149 153 155 156 132 165 156 137 135 161 163 137 151 149 166 148 155 158 133 136 143 168 142 145 132 143 150 145 135 144 161 150 143 152 156 137 155 162 149 147 148 139 151 153 159 154 167 141 145 160 141 149 156 146 166 137 124 140 146 133 150 154 177 164 141 168 160 159 136 164 132 157 142 119 151 133 139 160 138 135 159 143 163 144 138 157 153 170 133 157 164 166 147 139 155 160 155 156 141 154 135 159 160 146 157 144 148 150 155 146 139 161 140 133 153 143 145 160 154 142 153 152 136 152 154 137 145 159 150 142 140 140 147 143 137 161 129 163 133 159 141 174 140 149 149 158 156 146 126 145 150 140 140 166 134 146 157 165 140 141 138 151 161 141 141 145 146 164 142 174 146 150 151 162 144 157 135 144 153 163 156 133 167 139 142 157 145 136 144 151 151 156 149 135 152 136 159 146 145 168 136 152 143 139 135 134 154 142 138 153 140 137 158 150 120 146 152 169 156 137 137 145 151 146 154 142 141 146 135 135 163 156 143 151 151 155 151 154 120 140 132 153 149 144 159 153 156 146 164 155 147 128 149 160 155 149 131 152 145 157 131 139 170 137 142 147 135 143 142 151 145 147 141 160 167 145 137 128 143 157 158 165 168 144 156 140 177 134 152 146 153 152 155 167 144 151 131 137 155 134 147 141 148 157 153 144 149 172 161 160 132 142 151 170 137 140 141 135 118 147 133 154 133 156 156 149 152 143 129 170 138 159 143 163 164 135 165 136 137 155 143 159 159 152 129 133 161 168 156 171 152 159 147 134 129 149 146 129 162 149 155 174 175 154 145 133 131 162 159 130 130 161 144 148 142 166 127 157 127 131 168 145 121 145 149 154 142 153 144 136 128 163 144 123 136 143 156 131 140 141 141 170 146 171 143 133 154 158 129 141 161 161 159 132 156 141 183 160 152 143 153 149 142 140 158 151 135 166 144 148 148 161 153 132 166 142 153 136 155 143 149 136 140 161 148 147 170 140 142 173 157 155 149 137 153 118 139 136 147 165 146 158 147 142 167 150 146 142 137 144 145 152 140 148 133 140 163 175 166 144 165 139 141 154 167 141 134 147 165 152 155 153 162 148 167 152 172 166 153 152 130 132 147 146 168 152 166 151 153 146 175 143 161 121 135 160 137 127 152 146 161 142 140 147 166 154 154 153 142 148 152 144 146 148 150 148 154 165 146 161 144 141 148 137 152 156 142 142 139 166 152 160 142 180 168 131 153 166 148 151 133 165 149 167 150 147 132 160 149 138 155 167 160 161 126 149 149 130 140 128 111 159 153 152 153 131 152 151 141 140 177 155 157 169 156 163 164 149 170 143 142 167 161 153 156 142 154 134 143 146 177 154 156 139 166 165 123 169 147 134 140 141 162 176 149 154 143 129 144 131 157 131 150 170 149 154 151 149 164 160 143 139 168 156 148 167 132 151 140 147 146 151 161 157 174 162 128 129 163 154 149 137 159 137 174 141 157 158 145 142 162 152 149 156 167 150 145 146 146 127 156 152 155 172 177 169 147 148 144 136 132 140 151 129 184 154 148 141 164 152 147 158 143 140 155 154 171 142 144 135 158 162 151 147 154 145 163 131 145 144 144 131 146 153 169 134 145 152 161 141 160 153 143 169 160 149 160 151 135 129 154 132 155 167 166 149 150 159 123 157 155 177 144 148 137 155 142 160 170 153 156 131 146 141 162 146 138 152 148 152 124 154 142 136 141 144 140 141 137 162 151 146 181 147 153 168 147 159 172 164 142 154 141 152 146 135 151 156 146 170 159 155 141 154 137 171 148 155 141 142 145 157 148 153 150 152 150 122 143 141 148 169 159 144 162 156 142 151 146 126 136 144 161 148 157 149 160 165 135 145 145 141 151 166 147 142 157 155 144 169 128 153 157 169 156 146 130 161 135 167 169 145 158 163 147 144 135 141 151 144 152 148 162 149 140 132 163 146 147 173 144 147 137 147 145 116 147 140 147 175 136 140 150 145 169 141 136 160 170 168 134 158 154 148 159 134 153 151 147 149 140 117 140 144 147 145 159 137 150 169 154 163 115 139 157 156 136 160 169 171 150 161 173 164 148 158 140 142 142 134 155 118 129 161 162 155 143 146 158 180 161 141 157 168 151 158 141 148 153 159 157 143 156 164 173 170 143 150 167 153 163 155 131 143 157 153 157 151 170 144 163 141 158 147 137 144 161 142 165 155 167 152 152 151 156 135 149 146 163 130 154 159 146 154 151 153 127 137 158 141 161 162 139 144 163 166 163 142 125 142 150 133 144 126 147 145 137 172 141 162 154 151 128 147 134 153 150 146 163 160 167 174 154 140 147 133 144 154 148 132 165 154 128 168 150 141 148 146 158 146 152 148 180 157 132 124 152 145 146 140 147 139 159 128 120 152 151 147 156 154 149 142 170 163 159 151 139 172 147 154 166 147 141 167 141 166 149 156 125 157 169 151 135 146 148 157 151 163 143 144 147 139 137 147 147 152 160 149 147 143 157 158 159 155 158 164 145 155 151 142 143 163 157 146 176 146 144 157 116 167 148 156 174 131 145 140 150 163 183 171 141 148 173 141 159 146 145 164 146 148 138 150 136 135 154 147 152 135 147 143 166 146 137 126 137 146 134 138 153 153 157 159 142 159 155 173 162 141 156 137 165 146 153 149 152 150 159 128 167 110 131 151 150 163 158 152 160 134 169 143 154 151 159 165 154 144 133 139 135 161 169 169 143 143 123 137 155 166 138 161 187 135 149 152 143 154 150 160 141 158 128 154 159 128 148 153 161 146 150 132 135 153 134 149 149 142 156 162 147 187 135 128 141 149 168 145 156 144 146 154 138 146 159 158 149 124 144 151 152 171 153 136 148 142 152 130 156 184 135 140 147 137 160 144 157 160 151 168 137 141 147 139 180 148 145 144 125 140 135 125 145 153 166 155 158 159 127 169 134 159 151 147 145 151 149 142 155 148 127 146 145 135 142 144 153 136 152 114 143 143 141 144 152 162 155 149 138 166 128 153 125 148 150 158 170 148 152 145 154 149 161 147 151 159 153 159 146 164 141 157 129 157 152 138 149 139 159 141 146 157 148 148 143 128 150 165 153 156 144 131 139 144 161 170 164 154 141 146 169 137 144 161 167 175 137 137 135 146 135 123 159 121 163 168 149 139 153 146 161 176 126 150 166 147 131 165 160 142 161 158 150 135 152 157 162 156 158 148 132 143 170 150 147 151 144 143 162 160 149 148 174 159 153 172 142 142 147 150 150 167 172 165 141 155 164 138 151 159 166 177 165 144 164 152 160 156 155 160 161 157 166 137 151 153 158 163 148 158 151 149 165 157 159 142 163 128 165 171 144 146 143 149 148 177 154 161 138 140 120 188 166 154 148 180 152 178 180 157 153 137 164 149 141 135 147 176 147 154 144 145 141 178 145 169 159 180 147 174 131 154 157 130 168 159 167 148 151 151 137 162 162 162 179 150 157 151 156 144 143 146 156 165 156 138 144 161 139 142 156 157 152 139 156 158 156 161 143 153 151 160 169 136 154 159 154 162 140 144 167 149 154 150 149 143 154 129 164 170 148 135 144 142 134 140 141 159 157 143 153 156 137 139 160 146 141 153 159 161 161 165 142 137 148 164 168 151 148 164 155 151 163 149 159 171 151 157 154 152 133 156 131 144 161 133 142 145 146 160 140 168 146 164 119 142 145 148 110 142 159 138 153 134 163 143 149 136 144 170 131 161 160 134 145 149 150 158 159 150 162 134 150 158 141 144 151 156 162 154 142 133 155 144 161 148 146 177 165 153 157 152 152 151 158 154 151 147 156 169 153 140 158 149 157 157 130 147 160 133 132 168 172 140 140 146 164 144 154 157 171 140 153 148 136 140 158 149 149 153 159 168 148 124 176 135 168 152 136 160 139 175 138 144 168 141 127 153 137 148 138 137 147 149 151 130 135 151 149 154 144 146 151 137 146 142 129 153 180 144 152 139 163 124 146 135 166 156 133 149 145 143 163 160 124 142 133 137 165 152 158 130 149 139 132 161 150 120 159 137 164 138 149 160 165 126 145 142 146 147 135 138 152 146 153 147 166 146 150 182 147 153 141 171 152 146 181 165 159 144 161 147 157 164 159 137 143 140 148 164 155 142 152 150 157 148 157 147 160 131 142 170 167 151 140 151 153 174 138 133 152 131 133 147 149 136 160 136 145 126 143 144 123 152 151 153 155 167 147 137 143 136 150 153 151 159 140 157 148 144 159 135 152 128 130 169 145 139 146 132 153 139 146 174 123 144 151 140 137 131 152 138 151 157 147 153 161 144 145 139 139 153 151 152 151 155 160 153 164 163 138 149 149 151 143 156 153 139 135 145 134 164 148 166 141 156 150 142 145 138 158 147 145 162 132 154 143 150 134 152 161 148 159 150 151 124 153 142 157 146 168 175 139 139 186 154 133 134 138 132 153 109 144 146 134 144 143 153 141 169 141 153 153 150 136 142 131 156 148 159 138 136 170 153 155 140 146 142 124 168 131 151 152 147 140 119 144 170 136 129 144 160 146 155 141 140 133 151 148 166 137 160 147 135 150 130 165 147 170 143 154 150 148 158 159 150 157 149 143 133 144 144 161 171 123 151 131 145 153 130 146 157 154 154 129 149 136 149 145 149 112 155 167 150 152 150 152 157 137 166 147 163 147 152 159 126 149 172 147 125 151 158 137 147 132 147 159 165 169 129 147 143 164 154 143 143 140 152 190 151 132 144 128 143 147 160 132 147 144 143 137 153 142 162 160 150 170 153 148 152 157 144 145 149 149 154 143 151 148 139 155 140 161 162 174 162 146 152 165 153 130 154 167 137 151 145 126 150 156 155 140 173 136 172 160 154 163 145 173 157 141 141 142 144 152 154 142 146 146 137 139 124 161 141 170 153 148 139 131 166 144 132 154 150 167 145 173 177 159 145 155 156 151 156 157 145 159 142 147 156 167 145 153 150 141 118 142 147 158 155 149 143 147 127 134 129 150 127 145 141 145 167 122 149 169 126 131 158 155 172 151 162 117 158 158 148 144 145 161 142 130 161 157 147 172 131 170 141 161 158 142 148 159 142 147 156 137 112 163 119 147 151 163 168 158 157 134 160 136 151 166 157 169 121 160 137 142 145 151 117 125 151 136 140 138 149 134 139 157 159 166 162 133 148 145 154 170 151 147 149 149 160 171 135 135 169 146 144 142 165 164 154 163 142 157 151 176 153 160 133 154 136 164 133 134 150 149 169 158 171 155 168 171 138 159 150 165 162 168 153 122 149 146 156 183 154 182 147 142 161 131 139 161 151 143 144 153 136 155 139 148 139 154 173 160 185 167 142 155 162 152 130 144 162 137 143 148 147 164 151 135 149 150 140 159 143 169 143 140 156 158 147 149 134 148 164 148 138 154 119 146 165 149 148 151 156 149 131 143 139 157 166 148 146 125 152 147 163 139 141 123 133 138 147 157 150 176 143 147 158 158 150 152 141 156 136 135 150 132 167 147 141 148 125 151 138 157 145 143 149 148 143 137 145 145 136 146 164 133 157 137 145 143 147 162 146 158 127 143 150 152 144 157 164 157 139 159 134 145 140 177 149 146 156 136 138 145 166 136 161 143 164 141 146 158 154 145 164 129 160 151 158 154 140 176 155 130 151 167 137 134 173 138 138 173 145 150 161 151 117 149 137 165 146 160 154 161 146 130 152 124 163 145 131 143 173 142 170 186 147 156 172 147 147 138 146 153 154 130 145 167 158 130 150 140 130 180 120 161 145 159 148 169 146 142 161 153 193 148 151 161 169 132 178 159 138 143 138 166 150 165 171 168 116 142 148 157 164 177 147 150 140 127 135 156 181 155 140 125 139 157 160 144 129 132 160 127 153 136 150 140 147 142 155 160 152 161 118 141 146 148 156 158 134 142 154 143 149 160 147 136 160 146 149 131 174 148 153 131 133 158 144 127 184 125 155 145 135 159 143 149 157 125 114 149 143 148 146 152 168 137 144 158 148 141 135 150 149 154 158 145 147 137 162 161 143 150 146 148 136 142 147 149 169 173 160 160 159 147 145 150 146 143 136 165 163 151 132 131 149 160 159 161 144 145 149 145 127 141 147 141 158 156 134 149 150 158 138 149 138 144 149 155 144 146 150 138 146 147 150 168 155 148 152 167 156 154 137 129 165 144 149 141 155 137 129 172 130 137 172 141 149 130 141 153 149 147 137 135 141 136 143 145 160 154 155 151 178 144 152 165 144 172 158 150 132 144 155 165 147 147 154 175 170 160 151 147 143 157 169 155 158 160 137 200 154 141 148 125 147 169 164 150 143 144 161 152 159 152 157 159 149 156 145 170 134 153 144 144 143 152 118 148 148 171 130 150 153 149 152 143 148 150 132 155 127 171 148 148 146 141 151 146 144 141 143 166 160 151 147 178 140 152 157 140 119 143 152 146 166 144 142 165 160 145 154 141 152 143 166 155 149 161 150 140 153 135 135 165 160 150 166 154 164 131 151 138 133 143 134 151 135 127 167 149 159 168 142 140 157 150 146 168 141 150 159 147 149 150 159 172 156 166</counts>
			</dataPoints>
		</scan>
	</xrdMeasurement>
</xrdMeasurements>