File: data/XRD/_misc/old/XG-600C/_absolute_2th-om_10-130deg_PIXscan_56min_1.xrdml
<xrdMeasurements xmlns="http://www.xrdml.com/XRDMeasurement/2.1" xmlns:xsi="http://www.w3.org/2001/XMLSchema-instance" xsi:schemaLocation="http://www.xrdml.com/XRDMeasurement/2.1 http://www.xrdml.com/XRDMeasurement/2.1/XRDMeasurement.xsd" status="Completed">
	<comment>
		<entry>Configuration=Factory configuration, Owner=User-1, Creation date=7/8/2013 4:01:53 PM</entry>
		<entry>Goniometer=PW3050/65 (Theta/2Theta); Minimum step size 2Theta:0.0001; Minimum step size Omega:0.0001</entry>
		<entry>Sample stage=MRD Cradle; Minimum step size Phi:0.01; Minimum step size Chi:0.01; Minimum step size X:0.01; Minimum step size Y:0.01; Minimum step size Z:0.001</entry>
		<entry>Diffractometer system=XPERT-PRO</entry>
		<entry>Measurement program=C:\PANalytical\Data Collector\Programs\Jorrit\2thom\_absolute_2th-om_10-130deg_PIXscan_56min.xrdmp, Identifier={15BCCF57-2807-42BD-B5B9-ECC0B3DC9284}</entry>
		<entry>Batch program=C:\PANalytical\Data Collector\Programs\SimonL\batch4x_2thom_10-130°_z9.1_x0,10,20,30_y0_57min.xrdmp, Identifier={EED9823A-2BEB-424C-9252-345C4EF2834A}</entry>
	</comment>
	<sample type="To be analyzed">
		<id></id>
		<name></name>
		<preparedBy></preparedBy>
	</sample>
	<xrdMeasurement measurementType="Scan" status="Completed" sampleMode="Reflection">
		<comment>
			<entry>_absolute_2th-om_10-130deg_PIXscan_56min</entry>
			<entry>PHD Lower Level = 4.83 (keV), PHD Upper Level = 11.27 (keV)</entry>
		</comment>
		<usedWavelength intended="K-Alpha 1">
			<kAlpha1 unit="Angstrom">1.5405980</kAlpha1>
			<kAlpha2 unit="Angstrom">1.5444260</kAlpha2>
			<kBeta unit="Angstrom">1.3922500</kBeta>
			<ratioKAlpha2KAlpha1>0.5000</ratioKAlpha2KAlpha1>
		</usedWavelength>
		<incidentBeamPath>
			<radius unit="mm">320.00</radius>
			<xRayTube id="1010048" name="Empyrean Cu LFF HR (9430 033 7310x) DK442154">
				<tension unit="kV">40.0</tension>
				<current unit="mA">40.0</current>
				<anodeMaterial>Cu</anodeMaterial>
				<focus type="Line">
					<length unit="mm">12.0</length>
					<width unit="mm">0.4</width>
					<takeOffAngle unit="deg">4.2</takeOffAngle>
				</focus>
			</xRayTube>
			<xRayMirror id="27010001" name="Inc. Beam Cu W/Si (parabolic MRD)" hybrid="false">
				<crystal type="Graded" shape="Parabolic">W/Si</crystal>
				<acceptanceAngle unit="deg">0.800</acceptanceAngle>
				<length unit="mm">60.0</length>
			</xRayMirror>
			<sollerSlit id="21010002" name="Soller slits 0.04 rad.">
				<opening unit="rad">0.0400</opening>
			</sollerSlit>
			<mask id="22030007" name="Fixed mask 2 mm">
				<distanceToSample unit="mm">220.00</distanceToSample>
				<width unit="mm">2.00</width>
			</mask>
			<divergenceSlit id="22010007" name="Fixed slit 1/8°" xsi:type="fixedDivergenceSlitType">
				<distanceToSample unit="mm">220.00</distanceToSample>
				<height unit="mm">0.19</height>
			</divergenceSlit>
		</incidentBeamPath>
		<diffractedBeamPath>
			<radius unit="mm">320.00</radius>
			<sollerSlit id="21010002" name="Soller slits 0.04 rad.">
				<opening unit="rad">0.0400</opening>
			</sollerSlit>
			<receivingSlit id="22010001" name="Fixed slit 4°">
				<height unit="mm">5.88</height>
			</receivingSlit>
			<detector id="7010017" name="PIXcel3D 1x1 detector" xsi:type="areaDetectorType">
				<phd unit="%">
					<lowerLevel>30.0</lowerLevel>
					<upperLevel>70.0</upperLevel>
				</phd>
				<mode>Scanning</mode>
				<activeChannelsEquatorial>255</activeChannelsEquatorial>
				<activeChannelsAxial>255</activeChannelsAxial>
				<pitchEquatorial unit="mm">0.05500</pitchEquatorial>
				<pitchAxial unit="mm">0.05500</pitchAxial>
				<readOutPeriod unit="seconds">0.135</readOutPeriod>
			</detector>
		</diffractedBeamPath>
		<scan appendNumber="0" mode="Continuous" scanAxis="2Theta-Omega" status="Completed">
			<header>
				<startTimeStamp>2024-08-27T15:53:19+02:00</startTimeStamp>
				<endTimeStamp>2024-08-27T16:49:26+02:00</endTimeStamp>
				<author>
					<name>PRO-MRD</name>
				</author>
				<source>
					<applicationSoftware version="6.1b">Data Collector</applicationSoftware>
					<instrumentControlSoftware version="7.0E 20130304">XPERT-PRO</instrumentControlSoftware>
					<instrumentID>0000000011142674</instrumentID>
				</source>
			</header>
			<dataPoints>
				<positions axis="2Theta" unit="deg">
					<startPosition>9.99826193</startPosition>
					<endPosition>129.99755682</endPosition>
				</positions>
				<positions axis="Omega" unit="deg">
					<startPosition>4.99913096</startPosition>
					<endPosition>64.99877841</endPosition>
				</positions>
				<positions axis="Phi" unit="deg">
					<commonPosition>0.00</commonPosition>
				</positions>
				<positions axis="Chi" unit="deg">
					<commonPosition>0.00</commonPosition>
				</positions>
				<positions axis="X" unit="mm">
					<commonPosition>0.00</commonPosition>
				</positions>
				<positions axis="Y" unit="mm">
					<commonPosition>0.00</commonPosition>
				</positions>
				<positions axis="Z" unit="mm">
					<commonPosition>9.100</commonPosition>
				</positions>
				<commonCountingTime unit="seconds">32.895</commonCountingTime>
				<counts 232 221 203 209 188 217 236 232 220 222 228 231 214 216 234 225 237 224 231 211 220 232 198 223 221 219 197 211 230 209 207 189 198 238 208 194 220 209 231 217 230 204 230 200 221 208 180 205 235 192 224 219 211 231 235 217 197 219 195 185 195 208 202 199 216 229 205 223 225 200 235 204 207 216 197 232 200 200 221 194 212 198 195 192 212 202 214 205 203 228 209 188 202 206 207 211 211 216 208 235 218 217 197 198 236 206 210 212 203 198 229 201 209 201 203 206 197 226 200 186 214 203 223 208 208 197 201 226 198 173 191 182 194 206 213 196 218 212 210 187 228 219 179 180 178 206 168 194 189 193 217 210 186 227 204 188 208 188 199 194 187 179 186 183 206 207 184 176 198 187 183 211 168 194 214 186 203 190 179 174 188 205 207 203 188 193 179 204 212 219 192 183 194 199 203 192 214 195 200 182 186 215 180 175 181 173 202 189 180 191 201 225 193 173 168 195 163 181 187 175 178 214 185 214 169 185 186 186 180 207 193 215 177 184 186 181 188 167 171 176 208 172 180 192 187 216 195 170 187 197 209 190 177 171 170 210 172 179 183 181 179 180 184 183 179 190 187 202 188 178 175 167 179 193 161 195 195 187 196 197 166 208 174 156 173 185 156 183 178 189 189 182 162 180 165 165 174 166 182 199 175 174 180 187 169 173 167 190 149 198 187 187 171 174 165 174 177 184 163 163 153 159 171 221 180 183 190 178 187 159 194 165 185 152 183 193 180 188 199 176 172 182 178 182 183 177 163 201 164 163 160 162 168 171 186 161 174 176 196 151 176 182 156 164 163 151 191 162 195 175 181 168 178 181 178 163 186 174 165 159 183 174 176 177 153 175 176 173 155 170 167 181 170 145 151 167 155 152 158 176 147 166 180 165 187 188 169 190 173 159 180 172 150 166 163 166 159 158 155 158 172 176 160 178 160 169 158 136 178 163 185 175 156 187 174 155 157 174 166 174 175 182 188 166 164 172 188 159 172 176 177 159 173 172 186 152 166 168 162 159 161 147 173 160 181 175 154 168 165 190 168 159 154 175 145 155 171 201 153 173 155 182 155 152 174 153 164 166 173 153 161 147 187 147 165 157 155 179 154 131 151 173 160 164 158 157 183 154 158 160 182 162 169 149 161 172 149 157 158 171 167 165 153 141 158 167 180 190 152 171 177 162 148 161 160 162 186 167 144 160 170 145 160 170 151 159 165 164 144 172 151 135 155 163 158 151 148 157 160 142 166 154 141 160 144 156 132 166 157 161 163 188 162 141 138 154 164 164 168 186 160 177 142 142 156 172 167 162 155 155 171 179 165 151 154 168 167 173 160 155 173 169 126 164 167 159 181 120 155 168 161 155 171 158 165 169 164 148 163 151 151 161 155 167 161 137 172 142 146 156 169 168 168 153 153 142 155 155 164 156 193 154 160 138 168 138 158 136 179 169 151 153 170 172 174 174 172 171 157 155 170 166 162 148 171 173 185 139 174 141 135 166 128 161 154 166 139 157 157 177 172 156 178 165 164 167 156 137 150 169 152 175 149 150 136 176 160 169 148 170 145 160 135 161 162 164 141 151 170 172 174 159 162 146 153 172 171 162 162 149 150 165 146 152 158 160 153 158 161 162 151 169 148 157 158 171 156 148 164 182 141 146 168 171 155 165 188 168 161 157 164 179 147 163 159 162 144 151 161 165 154 154 173 145 140 162 163 163 160 157 170 152 146 151 167 151 151 153 156 167 194 191 141 164 141 162 152 157 160 160 163 175 144 155 149 159 132 144 154 167 152 154 141 153 157 152 173 151 153 169 168 151 165 156 167 172 140 165 162 185 160 158 163 162 161 153 191 173 145 160 176 150 140 172 154 162 171 146 166 143 174 154 158 155 150 166 177 147 158 164 180 165 185 157 150 147 155 193 155 157 174 176 165 149 158 165 150 155 167 170 163 174 165 161 152 165 175 151 147 173 163 167 151 166 160 161 168 178 183 166 171 155 141 155 170 126 153 164 161 182 162 154 159 166 162 149 167 147 135 166 128 191 173 180 169 162 146 163 164 160 156 177 165 162 154 182 168 176 149 167 178 162 159 159 168 168 150 152 136 148 173 156 166 168 160 191 159 170 160 169 168 136 156 193 158 149 142 170 174 152 155 191 186 154 163 182 185 180 161 151 165 150 161 177 175 162 147 173 161 161 161 162 180 175 169 149 202 162 162 162 166 162 182 157 191 164 156 161 168 140 176 158 171 167 176 151 171 166 166 161 171 171 180 167 165 154 169 177 181 173 164 179 151 186 165 181 179 160 165 201 166 165 154 158 161 170 150 177 171 183 159 161 175 161 181 195 176 167 168 164 161 167 160 171 173 163 181 188 180 188 182 170 158 163 170 187 165 183 134 185 181 171 190 180 185 177 169 157 163 164 150 182 178 161 132 163 170 168 165 188 167 156 182 172 175 176 177 164 136 162 164 193 173 161 181 186 174 195 166 180 204 153 188 164 188 160 169 169 180 170 167 181 162 172 175 165 150 186 149 159 164 175 170 194 200 157 165 172 158 171 162 180 168 171 166 158 168 200 156 185 174 180 152 172 170 175 181 170 164 177 166 184 167 156 187 168 167 173 159 177 177 171 172 171 165 158 153 196 174 183 162 184 188 182 175 163 170 154 171 178 158 173 174 176 161 186 161 182 187 166 139 166 153 185 177 169 172 147 161 169 177 170 173 187 157 179 180 192 183 163 175 173 180 208 171 169 168 191 178 169 184 139 197 176 155 193 202 176 151 171 173 174 156 171 181 187 187 183 181 182 155 187 169 166 165 186 171 176 155 168 166 186 182 195 179 172 164 169 176 178 182 177 166 154 161 168 169 185 195 186 175 171 166 188 191 168 191 173 174 160 189 165 188 146 161 184 176 180 194 176 174 173 152 173 174 153 183 184 167 175 163 201 164 159 166 190 145 169 170 177 184 170 165 185 167 188 158 172 182 177 170 157 180 173 173 187 188 179 167 176 146 176 175 179 165 176 185 176 181 187 187 198 192 172 187 162 181 172 162 179 175 153 174 165 163 164 156 176 187 183 181 181 150 188 186 184 168 185 172 154 177 156 153 142 170 170 151 151 177 165 165 198 189 178 165 179 180 166 162 160 184 155 171 151 149 169 196 160 176 169 167 174 187 168 170 193 181 159 167 170 171 168 178 164 178 169 157 182 191 167 166 166 165 183 175 182 179 162 168 168 168 155 177 173 154 151 152 179 179 139 170 151 173 148 162 179 151 133 163 156 160 180 171 176 170 155 180 152 161 168 194 179 169 161 168 170 147 166 188 174 128 172 179 145 183 174 164 174 148 167 182 180 174 158 179 180 178 166 167 165 157 155 186 172 146 164 194 167 174 158 186 166 156 162 167 161 159 182 163 167 175 187 176 160 174 152 156 165 183 156 178 172 182 167 150 158 150 148 189 163 182 160 145 164 169 155 142 146 160 140 151 148 177 161 150 179 166 156 169 155 169 178 153 195 159 153 160 162 165 149 140 174 164 164 160 165 155 119 159 157 173 156 155 172 153 154 160 134 154 148 162 186 147 169 165 127 153 157 147 148 154 155 151 153 155 187 163 136 150 139 156 154 136 167 156 158 181 148 146 130 154 177 156 155 157 159 150 172 164 149 149 142 166 130 155 159 162 166 168 153 169 143 160 146 184 162 133 142 138 147 164 175 166 164 142 183 171 138 155 159 159 148 171 158 173 141 154 165 181 159 166 159 151 155 172 129 158 155 139 161 131 160 145 150 150 129 137 161 154 139 147 168 143 152 197 155 150 131 145 143 135 170 163 147 153 171 141 155 158 166 157 173 135 152 160 135 172 125 147 159 150 142 152 135 160 170 143 153 161 153 155 165 158 155 171 158 166 153 167 163 156 158 162 155 167 140 150 146 156 127 168 151 160 153 140 149 156 130 151 147 166 153 132 165 156 138 155 149 162 148 148 159 147 138 135 141 154 157 149 169 150 153 135 149 153 159 127 132 151 159 140 144 139 144 161 139 137 162 146 146 147 169 153 153 154 141 133 151 160 146 156 150 159 141 148 157 142 132 152 167 162 144 139 126 143 131 155 154 142 119 137 152 142 125 168 132 147 132 158 147 137 156 162 142 134 162 169 150 149 147 145 144 146 149 146 160 131 164 142 146 161 139 128 157 132 146 162 164 147 112 139 156 135 131 149 134 143 129 150 144 135 154 144 149 161 149 157 128 160 161 141 160 137 167 130 157 153 158 136 152 162 162 133 149 144 147 152 154 150 145 147 162 148 138 140 171 133 134 145 163 152 139 157 146 155 152 144 159 115 166 150 152 175 134 137 141 168 150 147 149 148 140 152 145 138 144 131 130 137 140 167 135 149 129 151 144 139 141 130 165 136 153 134 140 150 142 140 188 135 172 149 149 143 158 152 165 158 143 153 140 146 143 132 146 138 145 141 139 122 138 129 170 144 135 145 152 145 123 159 134 158 147 140 139 157 134 137 142 153 168 140 119 150 149 159 147 134 135 143 120 139 165 146 154 136 141 142 137 129 131 157 110 164 149 148 144 154 137 165 148 152 144 134 142 129 134 147 147 121 133 133 131 152 144 146 166 164 135 141 147 131 138 134 142 165 141 150 141 158 135 137 133 150 156 146 153 133 142 128 127 135 134 121 145 148 138 140 128 138 136 134 147 135 124 148 131 136 136 127 145 119 139 126 125 153 152 140 130 141 141 133 149 135 141 128 151 118 152 124 131 127 141 124 128 138 147 129 144 131 134 155 145 135 144 154 151 126 152 154 145 128 142 136 152 149 130 148 124 123 142 124 131 166 153 152 158 132 134 128 133 165 139 138 133 142 138 153 140 130 163 155 147 140 135 122 142 139 140 144 137 145 143 132 131 152 141 118 130 146 132 156 138 152 156 128 149 130 136 151 141 146 149 136 145 141 143 122 129 133 138 130 162 131 151 125 152 144 129 122 139 151 152 127 130 148 127 126 158 126 122 131 127 159 140 148 141 126 143 149 137 136 134 152 133 123 136 136 142 143 147 136 120 130 104 133 149 142 138 142 125 131 127 142 131 129 137 155 126 124 144 124 140 121 121 142 125 135 127 136 149 132 140 144 126 126 127 136 145 153 157 150 132 149 137 135 133 154 129 123 133 136 124 133 119 145 141 130 160 147 138 126 121 131 141 119 135 157 133 127 133 123 154 118 164 131 139 139 136 137 110 133 136 143 136 144 135 147 133 142 111 149 144 136 136 135 141 144 139 139 141 135 132 127 131 145 131 130 126 148 122 131 133 121 145 115 132 111 123 132 136 134 132 134 164 143 134 122 143 138 140 150 155 118 115 131 143 140 128 125 118 116 126 149 123 116 112 122 131 139 138 144 146 122 147 155 152 113 117 146 135 127 117 145 150 133 137 125 122 118 130 125 135 127 153 133 125 140 149 125 148 129 126 136 141 132 130 119 130 128 126 123 139 144 127 138 126 131 118 145 152 126 149 148 141 134 153 140 142 138 134 141 125 157 124 125 128 171 140 148 151 165 134 147 143 149 139 141 126 118 119 123 136 134 124 141 116 134 128 133 138 119 150 108 137 119 134 130 132 124 135 138 126 113 152 131 124 147 149 143 139 127 156 138 147 137 145 124 121 122 150 142 114 141 131 119 132 124 141 133 132 125 129 143 148 155 121 161 122 150 109 129 113 156 154 134 123 143 134 133 134 121 123 161 124 139 139 136 145 134 135 134 150 133 138 127 138 138 118 141 130 123 128 137 133 151 128 135 118 131 141 127 136 122 154 120 129 126 152 130 100 154 132 133 117 122 141 147 131 151 162 125 161 121 156 142 128 121 141 143 138 143 140 134 122 127 146 126 123 104 142 140 139 164 131 136 118 136 139 140 126 158 134 121 143 148 150 153 155 128 138 120 139 139 146 115 146 134 133 145 125 140 126 146 165 137 157 131 164 130 124 148 150 156 146 144 141 152 141 141 134 136 144 141 134 135 154 132 148 134 128 140 145 144 137 128 138 135 137 118 127 112 123 145 117 141 152 121 146 143 133 134 137 133 154 134 129 147 138 149 121 153 135 122 176 136 128 134 136 128 139 132 124 141 161 138 139 137 135 121 155 142 133 137 134 131 147 141 131 155 136 133 108 126 122 144 136 127 139 124 143 108 133 122 128 141 139 115 146 125 132 148 140 123 144 138 137 120 134 157 138 142 123 129 145 127 118 130 138 123 132 133 131 123 116 140 132 124 146 113 148 147 138 146 126 133 134 142 119 123 144 135 136 145 138 133 138 135 144 129 141 149 133 140 152 118 140 140 131 146 151 142 144 149 121 124 130 134 144 147 113 118 129 140 120 134 145 140 138 128 132 144 135 141 130 123 133 138 132 126 139 113 143 133 134 139 151 126 133 148 117 137 136 132 145 146 123 129 144 131 128 138 116 125 122 133 133 141 138 138 129 141 130 125 122 130 118 154 134 130 137 135 124 124 120 104 124 133 118 138 122 122 150 123 126 140 130 171 128 119 140 153 138 129 137 133 123 142 135 125 147 130 129 126 139 140 108 140 138 132 138 131 122 132 125 134 132 139 140 127 144 145 145 133 133 148 133 107 116 133 130 139 146 118 159 143 146 130 138 127 135 97 138 126 124 123 150 131 141 133 146 124 165 132 136 141 124 137 138 157 144 133 129 149 141 136 141 143 137 128 132 137 159 136 144 130 157 126 147 154 131 117 152 160 141 137 132 131 160 135 123 151 120 128 163 119 131 144 143 132 156 137 142 151 115 148 141 133 152 147 138 118 141 124 128 148 123 123 133 149 141 133 130 123 133 133 157 131 137 138 141 144 128 140 128 155 123 137 121 142 132 131 128 136 124 142 149 128 143 132 135 155 141 140 132 145 131 148 143 124 165 136 144 141 162 123 130 135 130 143 156 138 114 132 137 136 133 123 124 147 123 118 147 140 151 158 148 127 133 159 141 118 131 142 148 129 132 135 146 151 139 151 134 137 134 128 139 163 125 125 122 127 151 146 104 141 136 134 123 143 133 141 131 153 150 146 139 123 139 140 136 151 142 142 147 138 155 148 157 148 152 151 133 129 130 149 126 139 125 153 150 144 143 146 155 125 131 131 153 144 155 121 121 144 133 143 145 146 141 138 124 122 154 138 143 126 131 136 121 136 149 142 125 154 138 153 165 130 138 134 133 170 137 129 135 141 128 147 145 123 154 131 141 141 153 141 128 132 140 164 166 136 137 124 136 130 147 147 150 154 135 135 114 156 151 133 132 118 132 134 143 154 150 138 149 150 129 149 139 167 147 127 126 139 136 158 135 132 173 146 131 151 138 134 140 151 153 137 134 131 134 120 136 138 145 151 120 138 155 142 151 117 159 125 140 138 132 151 126 127 118 145 149 147 143 156 133 147 121 146 141 119 164 129 160 150 150 169 155 135 136 152 123 160 156 135 128 126 120 130 158 143 138 161 135 154 130 150 149 146 163 126 163 141 137 130 154 136 140 128 128 137 156 127 122 133 149 137 151 150 158 140 168 153 142 150 149 137 143 125 146 123 142 152 139 131 158 139 169 136 155 143 137 128 131 126 156 140 149 147 174 132 156 130 139 162 129 143 157 158 138 137 156 140 149 141 160 145 146 146 140 163 156 154 140 175 146 166 147 145 157 149 152 152 176 143 149 149 173 143 158 154 154 153 151 131 149 162 154 166 128 144 155 174 152 190 137 156 184 170 156 137 176 185 185 170 180 157 168 186 192 201 209 200 184 193 213 214 193 217 223 194 231 247 234 264 227 246 285 276 279 272 263 283 272 278 262 307 267 271 289 266 237 256 225 235 247 224 232 215 215 218 217 217 201 191 223 192 190 160 185 165 182 166 174 169 174 156 141 163 166 171 162 175 172 182 154 146 148 169 136 150 143 151 153 170 152 130 148 147 124 148 159 137 128 144 157 159 146 147 141 145 149 141 135 137 118 136 146 136 127 155 137 161 166 147 165 149 144 136 136 123 118 135 152 122 130 138 145 136 132 124 142 144 145 128 118 152 139 151 133 153 149 145 115 142 145 142 130 125 136 147 136 157 125 129 155 137 143 119 145 119 125 135 144 146 147 138 147 149 135 138 125 135 140 141 129 167 130 121 122 125 139 141 125 145 146 126 130 138 154 138 133 153 145 150 149 128 160 148 139 154 138 133 144 127 125 130 153 153 137 145 161 150 133 143 134 139 135 146 144 145 139 151 140 139 147 135 143 141 134 133 133 125 148 134 130 140 129 136 139 128 141 132 144 135 153 127 123 142 130 130 156 131 135 138 141 132 138 138 127 134 125 126 134 136 154 129 145 141 138 148 126 136 145 142 137 143 147 147 139 129 147 127 136 127 121 137 136 156 114 137 133 144 131 129 144 118 146 133 116 139 138 147 166 135 126 133 146 141 142 138 143 141 116 139 144 171 133 114 145 138 155 127 137 118 141 133 106 140 150 153 127 161 134 143 128 121 142 147 149 130 141 111 125 148 121 118 135 118 136 135 141 128 153 139 134 125 122 143 140 140 123 139 149 142 152 135 131 146 124 128 141 148 138 146 136 152 125 130 134 132 149 143 148 154 136 116 166 125 136 120 109 133 148 150 141 140 125 152 149 159 137 145 139 123 139 138 145 133 146 150 131 125 130 142 128 112 140 136 149 148 142 132 128 128 134 123 140 135 135 152 142 157 123 139 146 154 136 149 136 147 117 130 153 137 149 143 128 152 140 126 142 152 111 136 143 129 132 124 120 141 143 138 142 137 143 119 127 132 137 147 145 131 113 126 116 147 141 126 137 143 130 149 137 125 153 147 133 130 139 131 137 155 129 132 139 130 131 126 154 136 160 124 138 122 155 131 139 135 137 129 135 134 142 135 128 144 134 134 139 136 136 150 125 152 135 143 152 140 146 161 129 126 131 137 118 147 138 152 145 138 150 150 140 158 147 126 134 154 139 160 133 135 138 137 147 122 144 138 129 146 144 145 134 149 140 142 117 120 160 122 142 159 155 156 141 123 160 142 156 143 138 125 114 140 137 133 137 124 151 112 134 129 150 115 125 135 127 146 136 118 130 144 128 139 140 150 135 124 111 129 138 143 156 142 142 138 144 116 154 134 124 137 129 149 166 126 134 152 128 146 128 143 157 139 151 142 135 118 130 155 158 137 140 135 147 123 136 134 113 132 140 138 139 142 150 133 139 150 126 149 152 142 133 126 142 146 131 136 138 150 141 131 129 121 126 131 136 132 145 133 124 129 143 142 143 141 141 139 145 128 141 141 122 138 120 131 154 141 131 136 144 128 147 151 130 123 138 144 144 133 141 132 129 121 127 124 121 137 127 129 156 121 127 128 114 136 138 169 125 148 158 135 154 126 119 143 147 127 130 125 132 153 143 148 124 137 127 137 130 140 130 151 142 133 139 137 134 146 125 125 128 174 146 161 145 154 115 132 144 115 132 154 142 145 141 145 123 108 152 129 136 151 141 120 135 166 136 146 118 130 127 134 154 139 132 125 136 136 141 142 120 140 148 131 146 160 135 124 134 128 150 131 134 135 140 160 143 131 143 139 139 121 148 131 131 145 127 146 131 130 117 157 140 136 127 125 139 119 158 128 149 132 152 150 131 138 117 116 136 134 115 126 152 130 125 127 151 132 142 137 138 141 146 160 165 133 137 132 137 116 141 143 139 140 129 147 145 136 145 142 136 117 122 144 138 126 139 161 137 128 135 138 139 139 138 154 142 142 134 116 115 123 140 128 138 138 151 117 135 128 144 105 136 124 150 123 129 124 144 120 146 115 115 132 148 122 149 144 142 164 136 145 140 150 125 145 136 129 143 142 140 146 131 139 150 165 132 135 124 142 138 133 124 136 137 149 127 131 149 124 123 142 141 136 121 135 143 157 155 147 141 123 130 132 138 125 153 133 109 154 129 155 126 139 129 138 116 124 131 132 129 114 148 129 139 159 130 139 127 134 141 133 139 130 131 156 141 134 115 139 139 133 117 168 154 126 134 136 142 143 136 146 150 146 127 120 139 136 126 125 129 134 137 151 131 157 137 151 149 139 121 153 113 133 139 136 138 151 141 119 136 133 124 129 156 132 132 133 160 147 133 135 137 141 151 144 148 160 138 115 144 141 135 149 145 136 132 121 142 139 138 123 133 106 149 141 132 97 144 121 135 133 124 148 148 137 141 124 149 136 129 136 143 139 136 145 165 121 133 149 157 137 118 139 130 135 116 157 147 131 142 113 123 145 135 141 135 153 116 147 134 144 147 117 144 138 119 127 133 144 145 139 148 141 164 120 144 150 148 140 133 158 132 126 161 143 136 137 148 132 150 125 149 142 151 113 145 129 138 128 123 141 142 129 121 143 156 157 124 140 135 145 150 142 129 138 153 126 144 119 130 125 129 142 123 128 144 115 134 133 166 131 151 120 119 140 135 133 145 149 138 145 149 151 138 131 137 124 127 124 127 137 126 142 131 136 144 148 139 126 148 132 125 141 148 122 164 136 119 129 126 149 146 143 102 147 133 157 135 159 134 133 138 126 107 128 150 138 155 146 148 149 131 141 130 123 140 160 127 139 138 131 145 155 119 129 139 150 147 130 150 154 127 121 128 135 123 134 133 124 142 145 132 113 155 149 139 122 144 153 148 142 133 135 136 157 140 147 125 136 138 134 146 136 123 137 125 123 145 130 117 137 148 149 152 139 129 159 154 156 138 128 142 132 135 109 133 139 120 127 132 129 142 132 141 132 142 151 136 146 140 150 152 131 131 159 147 138 153 146 160 128 134 122 131 135 127 144 144 139 128 125 138 135 133 132 161 134 126 119 138 123 121 129 142 124 132 142 139 135 143 125 151 151 133 123 150 146 138 149 142 136 133 116 131 128 147 147 141 137 140 124 142 111 130 132 131 138 121 121 152 138 122 135 137 124 133 138 143 167 142 169 147 127 151 113 136 151 142 140 152 130 118 143 137 129 132 133 120 133 147 158 144 147 119 133 130 134 135 146 118 141 142 147 149 123 137 150 144 129 140 145 156 142 133 133 136 150 152 148 124 151 150 147 139 130 139 145 144 127 141 134 136 145 135 152 136 130 142 147 156 133 153 152 146 136 151 127 107 144 135 157 136 127 126 141 146 141 148 139 138 135 143 139 145 143 150 136 144 142 132 112 122 148 137 138 146 149 139 147 127 130 153 141 169 131 123 111 155 138 125 131 162 141 144 140 126 157 172 140 129 140 133 134 137 143 134 132 132 129 134 134 116 139 140 137 144 142 127 145 129 128 156 140 138 159 143 150 144 146 119 143 131 150 124 139 148 138 150 135 141 140 148 129 147 124 182 140 151 158 121 161 161 131 150 125 149 129 148 137 143 124 146 148 142 161 114 163 128 154 165 139 140 131 125 137 146 156 136 142 170 131 152 138 134 133 133 150 134 117 129 153 140 130 124 140 138 145 112 154 120 152 138 154 126 154 138 134 138 161 133 118 139 125 138 151 148 142 160 144 145 132 120 123 140 133 128 136 137 150 137 143 133 156 144 138 123 140 156 128 147 165 135 153 143 136 145 133 152 135 114 151 135 141 129 157 128 159 144 133 142 142 142 163 135 138 144 139 149 143 143 148 132 140 132 140 151 131 123 146 150 157 145 142 122 144 126 151 151 148 146 125 153 129 142 154 129 132 163 128 133 160 123 130 119 158 147 148 125 148 149 133 142 145 157 138 143 131 150 129 152 147 141 144 124 126 157 151 140 149 158 141 158 136 162 148 138 157 148 127 148 137 141 150 135 134 140 125 135 143 142 129 141 169 153 115 115 127 124 154 136 144 159 138 152 141 157 142 139 149 153 173 132 128 157 152 139 138 135 130 121 126 152 139 140 123 136 129 138 165 141 125 142 135 138 154 140 143 122 148 134 133 164 139 155 143 153 152 127 140 134 113 156 143 155 148 150 141 142 115 127 141 149 143 141 147 127 167 149 131 149 144 132 152 129 137 159 122 148 162 136 147 144 145 123 171 159 163 161 132 130 138 135 131 152 140 149 133 119 143 160 144 139 137 134 125 126 154 129 139 132 151 165 137 149 133 143 143 153 146 153 149 114 155 125 136 154 128 129 139 137 149 139 128 139 130 145 168 134 153 134 141 149 140 149 130 121 144 131 137 121 137 157 163 167 147 128 155 147 152 132 125 119 151 138 149 143 138 143 186 132 157 146 120 147 147 148 146 154 129 155 138 138 158 148 150 135 140 141 133 133 159 131 138 144 124 158 146 142 133 138 161 171 171 156 150 144 133 140 156 148 151 134 137 160 137 149 130 136 126 148 136 161 135 142 177 130 153 140 159 153 142 149 134 148 160 141 146 131 143 155 153 141 145 136 169 155 153 153 148 148 179 159 145 156 154 153 154 161 150 145 146 152 149 145 142 137 176 169 145 143 134 168 171 160 147 166 156 148 160 153 121 156 157 150 158 160 141 157 142 154 146 185 157 152 165 162 173 138 139 146 144 155 164 144 142 153 144 164 136 162 123 162 168 156 158 135 148 142 147 108 140 160 164 142 154 143 131 123 145 156 163 135 162 138 131 142 133 148 133 162 162 152 141 151 126 132 161 126 143 138 141 154 145 145 138 126 149 150 160 138 142 141 147 127 131 140 161 129 141 155 144 154 143 124 133 133 150 134 135 153 138 142 130 134 158 140 124 122 156 141 123 144 145 139 148 148 135 124 158 160 140 139 115 153 138 138 128 133 134 140 145 146 160 155 136 148 157 163 140 121 137 132 149 152 147 133 151 160 154 147 143 146 130 140 119 142 132 127 143 132 132 145 139 140 137 125 140 130 137 149 138 127 149 145 126 152 152 135 133 161 153 131 141 143 172 149 147 149 141 144 149 130 154 151 147 127 130 144 140 146 147 136 124 143 145 131 138 143 148 140 150 120 144 135 151 169 141 152 143 155 158 120 142 133 121 132 126 145 140 144 129 159 130 159 126 129 151 136 134 136 120 137 165 132 141 152 140 151 151 138 123 141 130 142 147 152 120 125 130 148 160 125 142 153 117 145 156 135 132 138 135 132 150 121 143 130 136 148 124 134 149 148 126 136 133 161 136 148 147 140 133 160 128 116 133 119 134 124 148 105 147 144 148 139 134 145 152 149 141 134 147 137 141 128 129 142 149 141 139 134 162 157 158 137 141 129 129 168 142 144 142 129 145 175 117 150 160 132 127 136 151 171 153 143 160 135 141 134 169 162 162 151 145 141 161 158 137 126 156 157 153 140 127 132 138 174 140 151 139 141 142 142 126 155 155 148 152 121 164 160 138 145 136 135 152 156 166 145 124 132 155 140 164 167 154 133 117 135 153 150 145 132 140 148 128 140 139 182 136 138 120 134 150 150 144 152 151 146 127 128 141 149 149 147 128 147 151 133 150 117 121 131 128 147 116 146 136 150 122 145 135 147 130 121 136 132 156 148 147 126 160 118 120 134 125 130 134 159 151 145 143 135 146 176 168 144 148 141 153 145 135 147 155 135 139 139 150 140 149 125 132 136 150 149 155 132 136 144 133 150 145 157 133 142 157 155 141 146 120 149 147 150 145 163 140 145 139 140 145 130 170 144 153 148 143 131 144 150 139 129 141 144 142 145 141 134 133 152 149 138 125 133 158 135 128 144 159 141 152 123 132 144 143 142 143 136 145 151 129 160 136 147 143 141 163 152 159 150 137 129 162 127 152 122 142 152 127 165 156 148 163 163 163 145 129 143 145 165 152 136 153 108 155 132 121 146 138 143 124 128 140 119 153 131 138 139 145 152 137 153 139 121 142 154 155 145 131 158 151 133 135 144 148 141 141 140 139 163 143 123 134 150 126 133 132 144 124 149 134 149 153 135 165 157 149 152 143 126 143 152 141 117 146 158 157 155 159 159 152 147 130 139 131 156 134 138 150 139 146 147 138 150 170 130 131 159 179 156 130 158 150 137 140 133 135 174 156 141 154 156 145 141 133 143 125 149 123 139 127 143 147 146 134 152 141 137 153 140 145 173 122 149 130 136 142 135 138 150 152 150 147 122 134 139 138 145 159 171 137 154 168 149 131 148 136 182 159 154 126 154 143 150 150 140 142 136 147 127 150 113 148 142 143 136 141 143 146 134 144 155 136 145 139 149 153 122 152 126 132 145 158 158 146 136 175 150 165 146 152 129 135 162 154 163 130 146 155 137 115 136 141 139 160 147 158 151 125 134 158 149 124 151 135 150 142 129 156 133 145 137 149 127 148 149 143 150 155 175 145 117 136 174 140 137 133 145 141 126 133 137 132 152 145 143 149 154 150 134 149 152 132 138 138 140 147 145 151 140 144 141 123 147 126 131 154 145 143 138 142 154 139 146 159 141 145 152 149 164 135 136 154 156 146 142 159 151 153 132 148 149 151 143 142 153 156 142 150 147 130 139 120 169 138 142 130 134 145 136 138 155 143 146 160 150 131 150 132 162 152 153 186 158 143 137 130 151 140 139 157 157 138 133 151 156 164 139 148 140 154 140 127 130 137 133 145 153 124 146 141 141 138 143 155 128 149 133 136 146 136 144 153 138 148 159 105 142 138 144 136 133 142 161 161 155 125 146 139 134 130 129 157 153 150 139 145 141 154 165 138 142 106 143 132 149 134 131 144 155 135 133 153 147 142 139 127 158 151 138 130 158 146 139 124 141 153 124 142 154 151 151 166 171 158 155 129 123 135 129 134 148 159 154 136 149 158 148 135 124 130 143 153 130 144 149 139 153 149 140 155 124 128 140 147 141 152 156 155 129 130 141 150 156 146 130 151 142 159 133 127 149 128 160 150 152 149 136 129 143 136 129 154 131 137 147 126 141 148 140 142 114 148 134 139 152 157 154 142 158 149 137 129 133 125 128 130 143 155 152 140 141 156 144 138 150 139 143 117 147 144 134 138 135 123 150 168 142 150 134 154 147 143 147 145 140 132 162 158 158 137 129 130 118 161 165 152 181 158 152 147 130 133 157 115 149 152 141 129 157 146 129 136 130 135 123 164 136 151 115 162 135 153 144 164 160 142 110 136 144 145 136 150 169 143 155 132 139 134 148 130 137 142 143 129 144 165 145 157 131 137 158 159 149 125 154 170 153 155 140 135 126 144 144 155 150 138 130 138 153 151 150 138 119 127 142 149 134 159 138 142 131 132 148 155 146 120 136 140 144 139 140 154 141 140 157 125 133 147 142 164 130 138 137 153 139 166 135 153 134 131 120 132 148 169 159 134 126 163 154 143 139 124 143 156 130 156 144 135 134 128 141 145 168 128 140 133 158 123 153 157 138 138 149 146 159 158 126 142 141 139 143 138 174 160 160 162 137 149 129 140 152 139 135 174 128 139 147 166 153 152 167 154 147 133 128 147 162 136 153 139 142 144 140 138 152 126 150 147 143 121 157 158 139 137 158 131 165 121 126 148 130 149 140 144 133 157 127 142 162 134 157 152 143 124 157 141 143 145 136 146 164 165 128 134 143 129 159 147 122 147 145 150 128 145 156 141 156 139 149 154 142 150 135 138 154 133 136 131 163 145 144 130 138 165 160 144 137 140 144 155 159 171 145 145 154 136 138 155 150 166 150 143 149 142 149 126 142 146 140 148 157 128 156 143 169 166 148 152 157 126 140 147 139 135 144 144 128 127 159 132 131 145 153 134 129 163 149 156 152 151 163 135 140 147 151 134 145 152 140 124 129 140 153 142 138 140 160 143 132 151 169 156 141 148 143 156 153 150 137 154 126 164 165 135 127 133 143 175 170 153 162 159 175 121 135 127 137 133 140 149 132 160 131 147 128 147 162 135 166 167 139 162 158 133 146 148 148 159 142 130 161 131 156 159 145 144 133 171 157 133 160 138 156 145 154 173 160 157 132 138 161 150 131 151 141 158 145 150 140 126 130 143 154 154 154 156 132 140 125 146 153 142 149 146 160 153 152 147 147 136 141 133 145 152 128 128 153 129 163 146 158 156 148 140 164 149 145 148 149 140 158 138 154 156 143 131 140 153 144 145 144 144 146 147 148 129 158 151 161 144 119 132 161 121 137 157 148 134 140 161 143 144 155 142 144 157 145 146 167 131 125 157 142 151 154 125 146 158 154 134 146 162 155 159 142 136 166 163 154 157 160 146 155 140 157 134 152 111 149 141 155 161 131 136 155 162 146 156 164 170 154 130 150 148 138 147 140 134 163 158 148 155 174 146 143 140 139 161 142 138 140 141 144 147 147 139 150 130 156 163 140 140 154 149 127 161 137 139 170 173 143 145 158 144 163 154 166 159 156 154 153 152 174 147 159 152 152 149 147 144 158 129 144 151 166 183 173 163 131 141 154 142 158 159 168 174 153 139 162 159 172 158 165 149 162 173 200 182 171 135 167 153 170 159 163 147 174 181 172 193 162 156 166 170 187 165 191 166 165 160 169 192 176 189 170 156 202 177 169 177 163 154 155 145 178 159 161 169 160 164 182 183 169 150 177 157 162 138 165 149 164 148 160 151 170 166 154 156 150 151 156 164 164 156 156 151 168 169 142 146 143 146 153 158 143 162 143 146 144 150 147 145 147 178 155 143 137 137 149 135 140 152 134 172 129 139 164 157 134 153 129 140 138 147 134 150 161 151 156 154 140 167 134 159 163 148 149 141 166 123 147 151 158 152 140 157 158 159 146 160 148 125 149 133 159 157 152 167 155 127 138 148 150 143 179 128 133 140 155 140 148 160 152 156 131 147 129 142 141 139 126 134 145 151 161 133 158 151 130 148 162 139 145 149 144 134 157 144 151 135 147 142 143 155 129 145 142 152 156 160 141 154 143 143 153 152 152 143 151 170 138 133 151 146 151 149 140 147 140 140 152 138 136 152 133 146 165 147 151 164 156 136 143 171 165 150 136 172 165 132 159 132 118 132 147 138 159 136 152 145 139 140 152 140 149 156 150 134 129 143 125 143 163 137 132 147 127 135 172 183 139 148 149 131 164 143 141 155 140 174 129 143 153 162 182 148 143 138 152 133 116 157 158 157 156 138 134 134 157 126 124 137 174 170 142 137 135 136 140 148 141 131 134 150 147 139 143 162 124 128 150 144 161 143 146 142 145 158 126 149 120 135 152 139 159 146 148 129 147 119 135 135 158 129 125 160 168 127 138 144 162 143 145 169 145 140 134 123 151 120 147 144 147 133 121 149 123 160 163 148 147 134 146 129 134 148 157 161 171 157 141 163 141 144 150 158 142 144 133 148 137 143 135 137 137 116 135 141 152 163 161 138 149 141 135 161 145 147 145 143 112 151 131 114 146 163 134 136 152 114 134 132 138 150 138 160 136 139 131 119 152 156 145 144 128 128 152 135 128 154 141 132 114 128 144 131 137 140 141 141 140 163 130 162 143 155 135 141 148 126 156 152 125 125 123 135 154 142 134 152 132 138 152 146 156 145 124 166 144 135 134 143 136 137 167 120 145 146 135 171 144 140 130 138 149 141 124 122 144 125 140 139 160 163 146 144 137 144 144 148 150 148 142 150 131 140 136 135 134 141 134 129 125 154 151 145 140 139 147 141 137 158 128 142 136 136 134 138 168 160 130 154 137 136 128 122 136 141 130 130 151 142 131 138 123 124 164 152 137 144 144 125 154 120 133 162 138 139 139 137 136 145 155 121 139 143 157 137 128 151 144 168 139 138 147 152 141 139 166 144 148 136 116 130 131 142 164 150 151 129 133 136 165 162 152 130 145 161 138 134 144 148 167 144 139 131 123 150 129 150 132 150 153 127 131 160 151 133 148 138 141 153 148 143 134 148 127 147 172 144 142 159 141 131 149 130 138 146 139 152 138 145 151 168 148 148 133 144 172 163 138 151 151 146 150 127 156 141 151 144 126 131 142 155 124 141 168 148 126 134 123 168 136 139 154 137 150 120 145 118 134 132 157 148 140 147 138 129 147 129 131 148 141 138 157 133 142 152 142 137 138 163 127 142 142 159 136 133 142 152 160 134 120 144 144 157 143 137 136 116 135 155 150 168 144 138 140 145 133 155 132 143 152 150 148 164 152 159 131 125 161 156 158 142 135 153 140 135 135 181 150 136 133 138 133 142 141 164 126 148 159 136 145 137 157 153 135 132 144 151 152 135 133 135 133 137 146 124 139 130 132 146 126 143 148 153 156 137 137 137 141 139 159 135 136 148 152 136 150 149 132 140 137 129 124 135 135 120 156 158 138 160 131 140 154 114 143 137 139 140 141 145 154 111 148 136 136 177 152 134 130 132 149 145 146 135 130 141 135 130 134 152 146 158 114 136 134 134 168 142 142 142 133 123 144 138 118 138 154 153 122 151 141 151 121 146 138 149 131 143 123 133 141 151 151 156 150 127 133 136 155 134 137 138 143 136 126 127 128 135 136 155 153 137 128 148 137 132 114 132 150 148 130 132 146 143 135 145 127 120 140 142 131 165 127 135 127 145 137 129 149 152 125 124 128 149 138 146 135 145 145 137 152 138 151 145 114 132 119 133 141 138 150 163 139 147 144 147 146 128 132 135 139 151 129 154 145 148 128 158 142 135 144 144 126 132 145 156 123 150 139 126 146 146 144 144 123 145 152 154 150 144 151 146 154 143 156 134 112 138 132 134 134 136 130 141 128 139 147 133 154 127 151 167 127 147 127 145 160 140 121 142 128 135 160 141 139 139 151 134 141 144 134 140 128 117 143 169 176 133 136 129 134 121 154 148 140 130 171 151 132 158 140 141 136 132 138 137 137 141 129 133 164 134 127 151 126 139 138 136 149 146 136 139 142 151 154 128 143 150 142 154 135 149 144 157 141 137 137 140 120 139 126 157 131 130 131 119 155 142 124 144 138 143 133 128 151 144 139 136 160 169 135 122 158 142 160 145 136 116 151 125 154 118 141 144 141 147 131 130 143 153 151 156 140 154 140 141 123 135 164 122 125 148 142 126 155 143 143 138 130 176 138 156 128 123 131 139 141 155 147 128 133 135 127 129 131 134 149 138 140 139 152 133 148 130 145 149 128 143 144 162 141 135 147 154 161 150 130 137 144 128 142 149 141 146 133 144 164 133 156 154 162 130 149 140 127 141 147 153 123 131 135 157 144 134 144 128 148 157 131 144 133 157 128 147 144 132 121 146 140 121 134 151 140 145 156 140 136 142 151 170 145 127 132 151 139 148 155 127 131 143 139 176 144 151 142 151 149 131 153 138 140 156 130 156 125 152 149 137 136 132 157 155 134 145 144 170 157 142 131 138 131 152 138 153 129 151 142 159 149 157 140 127 123 145 145 143 142 152 138 152 133 128 166 156 128 140 144 137 152 131 143 132 151 140 182 151 128 144 139 141 139 126 148 140 147 145 151 149 142 128 136 130 145 155 149 145 140 134 134 129 133 137 141 143 148 152 146 153 152 115 135 154 168 140 146 140 148 134 143 125 134 134 130 158 147 133 148 136 148 153 121 146 144 140 155 130 142 146 137 147 140 131 146 139 157 125 141 131 145 141 153 139 154 159 143 148 149 138 131 126 142 136 139 147 127 128 155 117 166 144 155 151 132 125 144 137 134 145 159 136 124 131 162 117 151 142 141 152 149 135 137 138 134 143 119 159 133 169 131 150 148 133 141 150 148 161 154 133 134 157 128 151 126 111 142 153 161 146 128 144 144 138 131 123 144 158 146 159 168 143 145 150 128 129 123 162 135 141 149 133 133 147 151 140 143 154 152 144 132 119 144 124 135 148 141 131 137 138 133 144 139 138 139 155 149 137 132 126 152 142 137 138 148 148 133 149 133 155 133 154 155 169 141 157 145 153 151 137 127 155 127 138 119 118 113 149 131 146 158 161 132 141 146 146 125 148 162 153 134 148 147 142 133 159 127 143 128 136 144 169 140 132 133 128 134 146 161 128 119 146 133 125 135 140 117 151 157 121 119 143 134 143 151 138 158 149 150 127 162 163 141 135 143 129 151 117 145 138 145 147 136 160 136 127 166 124 134 133 138 117 140 151 139 142 154 133 162 158 132 165 140 147 149 133 132 143 164 163 136 139 142 136 136 148 159 132 156 147 161 153 145 137 146 141 130 153 146 147 122 141 165 137 161 133 153 139 147 157 142 137 144 146 143 140 138 139 141 148 146 136 138 136 154 171 155 146 144 135 146 123 147 143 125 173 138 142 142 156 141 139 150 140 133 166 164 129 168 157 144 148 153 146 159 177 134 142 161 161 133 141 144 164 160 163 148 132 147 141 130 158 142 157 132 180 138 160 145 159 147 153 149 157 128 154 141 136 152 145 148 137 125 145 144 155 144 142 159 143 153 152 157 153 156 138 134 153 151 146 153 153 145 157 132 156 122 139 129 141 150 150 130 143 138 163 126 140 168 142 142 149 139 121 158 140 160 126 131 116 166 128 113 172 137 144 127 135 137 142 146 152 120 134 123 163 153 144 145 143 143 144 139 144 144 136 143 139 141 127 133 156 147 154 152 141 126 148 145 141 153 140 148 160 147 152 150 147 146 163 156 160 167 138 134 131 156 121 128 149 116 154 152 137 122 102 139 133 146 158 146 125 146 150 151 157 145 153 135 134 146 151 149 144 158 125 139 136 145 136 131 127 145 134 138 139 148 150 145 151 126 151 144 128 121 153 127 135 140 138 134 131 161 154 135 140 121 141 150 156 157 153 143 129 166 154 117 127 147 138 144 127 138 138 149 153 139 137 139 121 126 127 136 130 128 137 137 137 106 142 149 150 130 143 139 137 144 132 145 158 136 148 138 151 135 157 144 130 142 121 128 158 139 166 162 151 139 136 144 126 131 152 149 130 150 158 115 145 152 151 134 139 144 145 122 129 152 152 145 147 140 133 135 138 132 136 124 142 141 145 149 134 157 169 145 144 152 150 148 135 136 149 125 127 130 140 121 154 131 133 127 130 147 162 132 137 146 142 136 150 132 133 149 134 105 139 151 147 151 147 130 153 126 137 138 157 139 140 153 119 146 127 138 130 149 139 125 131 137 146 141 145 164 140 141 144 144 147 142 132 163 124 166 147 166 162 150 151 143 139 148 168 146 136 135 152 120 139 156 165 144 142 136 139 162 154 130 151 181 145 145 145 163 143 146 119 139 127 143 140 117 152 147 150 145 128 136 134 130 163 131 150 167 168 125 142 160 139 145 130 148 142 125 132 146 159 127 145 128 141 160 152 152 151 147 156 161 138 154 134 142 151 134 147 129 144 130 146 160 134 132 139 152 124 119 130 150 137 131 139 156 148 156 136 144 149 131 128 146 130 141 152 152 120 133 122 140 144 122 138 132 126 139 144 149 143 149 142 145 134 133 159 151 131 140 166 159 149 161 145 145 142 143 140 123 164 145 130 165 128 124 131 153 145 151 125 143 148 145 153 133 130 152 136 159 152 133 151 116 132 138 134 158 148 147 144 166 138 133 157 128 139 142 164 142 158 133 131 130 151 162 153 138 135 143 151 129 129 142 133 141 141 135 118 138 134 127 160 149 147 166 126 126 130 138 140 126 141 137 143 157 142 135 134 110 145 163 148 129 149 143 159 141 141 138 143 140 133 126 130 149 121 147 144 130 150 152 133 142 130 157 126 138 135 161 143 131 120 128 148 137 153 148 131 121 140 142 132 125 143 144 138 144 147 161 132 123 119 148 121 148 127 147 136 146 132 152 142 145 142 149 131 163 130 132 131 127 152 133 161 144 150 133 128 128 147 125 164 153 130 171 130 145 145 134 145 136 134 139 141 154 139 150 139 142 140 174 141 137 128 135 130 141 138 140 137 142 151 131 142 129 126 136 148 150 136 148 151 129 138 155 143 155 153 152 151 146 124 144 130 151 140 148 150 126 145 134 131 131 134 146 146 134 156 150 127 151 150 145 120 144 144 145 134 146 123 139 139 131 130 150 140 142 138 127 166 133 176 137 133 131 144 130 124 161 136 148 141 131 129 126 136 130 144 145 159 127 145 146 138 133 142 134 128 146 146 142 169 133 134 118 115 137 124 143 128 138 144 134 133 137 140 141 145 128 157 133 134 143 150 135 156 153 164 139 156 139 122 143 141 127 154 134 168 131 158 152 136 122 142 156 146 133 160 133 137 161 140 137 116 167 162 126 129 146 151 139 135 136 127 129 142 141 129 126 128 128 148 157 133 161 150 154 136 151 150 135 161 157 131 142 150 148 128 141 133 140 148 153 152 157 127 146 134 127 145 158 120 146 141 130 124 138 123 139 139 149 139 127 140 131 132 174 137 138 156 119 139 125 145 136 142 140 142 132 125 143 143 157 183 145 155 153 139 128 147 139 147 134 150 156 120 129 121 132 165 122 154 145 136 142 156 135 147 124 152 149 156 148 139 129 131 143 133 155 143 124 154 133 130 139 144 157 134 127 135 143 142 140 149 151 147 135 153 108 128 129 132 137 142 131 123 140 139 148 119 124 132 137 118 146 139 140 141 142 146 167 148 131 140 150 141 155 158 158 142 148 140 118 128 130 149 136 146 147 148 153 153 125 134 130 146 139 139 144 160 145 146 142 162 145 146 144 140 134 139 158 133 137 157 137 125 160 158 150 133 159 133 150 168 151 136 140 139 137 142 136 138 145 146 129 138 134 150 154 147 159 130 156 131 147 149 144 147 138 118 129 128 165 147 151 132 130 134 161 146 156 138 153 134 141 150 141 141 126 126 135 143 144 142 129 134 164 148 134 107 137 154 132 147 127 112 148 133 168 134 134 157 152 154 155 141 132 149 144 149 145 139 153 124 152 132 124 162 150 143 155 140 142 145 136 135 142 127 158 132 147 152 149 138 140 142 162 147 146 135 126 148 146 146 139 137 140 137 132 143 150 116 164 135 140 154 129 152 122 118 155 147 140 148 144 139 145 128 146 144 140 134 137 146 157 145 139 157 141 134 132 129 151 148 135 141 146 130 132 141 147 155 138 130 140 128 139 171 116 132 117 137 111 134 147 145 122 129 126 148 128 131 128 158 139 146 151 163 177 136 158 144 129 135 140 137 125 142 156 164 132 137 158 148 153 144 114 138 124 154 138 138 150 178 154 133 156 141 167 149 148 145 150 148 129 156 136 148 151 130 148 148 152 160 159 150 126 155 130 137 144 140 152 136 119 147 122 139 142 145 147 159 135 144 146 166 127 149 145 144 138 131 135 141 157 135 138 132 127 129 134 147 147 132 148 132 138 148 123 150 135 139 114 126 150 122 137 141 136 112 145 152 146 118 142 143 137 145 133 146 128 154 151 142 130 137 145 139 127 142 147 148 151 145 154 134 155 144 183 150 154 129 139 142 149 149 150 157 138 136 151 152 154 135 134 155 132 137 150 153 140 136 143 149 160 132 142 152 125 142 126 148 140 146 146 153 152 145 136 166 138 159 151 149 138 146 155 154 137 144 155 157 145 141 128 151 146 134 134 151 142 156 146 154 139 154 144 154 149 138 140 123 120 152 146 131 149 143 125 139 158 124 130 157 118 149 146 133 151 154 142 128 134 125 144 147 141 145 150 160 156 144 149 144 141 120 159 138 141 147 161 116 125 161 136 141 133 126 150 147 125 161 131 122 147 161 132 139 133 140 147 138 136 159 151 138 135 135 149 147 154 140 149 148 142 152 158 153 147 144 140 139 143 152 150 140 164 129 141 148 134 151 164 112 112 145 129 177 114 147 139 149 143 148 132 150 146 145 136 144 139 149 167 142 152 144 138 151 150 149 121 153 142 130 138 145 133 125 138 130 144 136 131 136 136 162 127 111 124 136 121 157 162 163 142 132 131 160 152 162 151 160 145 146 132 137 127 151 143 151 162 139 130 142 135 137 136 156 157 161 149 152 146 150 140 147 153 133 155 135 136 147 179 127 132 146 133 123 148 129 137 145 117 162 144 156 141 144 149 157 147 129 167 129 144 148 148 144 165 147 153 139 143 147 158 145 158 139 153 141 140 176 150 142 126 137 135 134 136 160 150 156 150 140 144 149 137 145 154 137 127 166 168 141 144 144 116 162 128 136 155 147 133 167 151 148 153 170 170 127 138 144 150 196 132 166 155 138 142 150 158 181 145 165 157 157 161 163 150 161 131 145 157 151 141 153 128 142 142 143 153 141 144 139 149 166 141 142 136 149 155 153 152 145 149 140 160 181 181 151 133 159 148 147 138 149 166 163 154 168 152 177 139 173 131 140 159 152 153 150 151 146 145 153 151 136 136 150 141 147 146 153 124 148 150 163 144 154 149 151 171 157 152 149 134 156 171 154 151 139 151 157 157 153 152 143 151 159 157 154 155 151 140 131 159 149 153 166 160 167 145 146 137 170 156 167 158 155 150 135 141 151 154 137 160 153 149 150 148 152 153 156 127 141 146 167 156 146 142 173 167 137 116 141 130 155 154 158 145 140 147 142 162 125 160 141 139 134 140 132 150 134 145 135 147 150 141 134 116 148 133 138 160 147 147 133 133 145 142 134 140 156 144 150 129 159 121 139 139 155 151 175 144 131 152 129 141 139 150 116 127 150 172 159 146 149 135 141 174 157 139 129 127 156 157 134 121 149 148 139 166 144 139 147 132 161 164 139 154 155 133 150 149 144 132 168 157 141 144 162 148 137 155 132 149 160 140 174 154 156 162 153 123 147 149 142 148 144 156 131 141 142 150 125 146 145 139 155 153 151 166 136 144 131 144 152 144 144 124 133 148 162 139 135 127 133 152 150 115 146 151 142 125 156 153 142 156 137 165 151 136 147 129 126 131 151 142 131 155 135 127 147 134 153 143 151 137 148 142 153 134 172 122 154 139 147 163 134 183 132 148 140 144 136 156 142 127 128 144 140 151 144 137 155 133 125 134 149 145 130 130 145 131 147 142 131 119 141 146 147 134 133 137 119 116 178 139 140 141 156 127 132 162 150 151 146 137 119 140 154 145 147 139 151 146 139 145 165 146 128 131 150 137 133 157 135 135 146 142 141 140 167 155 141 180 132 156 159 154 139 156 135 160 162 136 148 149 126 156 144 158 133 141 137 116 127 164 144 159 131 139 145 135 119 135 159 122 136 134 135 138 135 133 140 119 147 129 143 140 141 160 152 144 149 148 129 131 179 152 150 148 143 160 147 159 156 137 146 167 131 136 141 152 163 154 161 141 149 126 158 132 141 131 150 138 153 156 146 153 165 156 137 144 146 141 131 137 164 133 142 160 146 133 151 136 150 152 126 123 148 140 153 148 128 139 147 136 144 131 138 132 151 125 141 147 132 140 141 163 155 145 149 145 119 150 124 147 146 160 149 164 159 132 155 155 131 143 146 168 149 124 135 117 119 144 137 147 141 145 123 145 126 141 147 134 168 160 142 135 149 135 157 139 134 137 131 139 134 138 156 143 136 164 125 149 130 134 132 148 141 150 148 167 151 145 116 135 156 147 157 135 138 148 153 162 152 170 118 127 142 135 178 148 143 149 150 142 141 140 145 133 142 151 171 146 171 145 172 149 128 148 156 136 141 137 157 157 140 161 128 126 142 150 145 141 140 149 144 139 135 139 141 136 155 116 125 137 154 139 139 136 164 143 139 119 145 135 146 146 125 160 135 161 140 136 151 152 156 120 154 143 171 149 161 163 144 161 153 160 129 138 130 145 149 131 156 157 141 118 140 144 145 137 139 133 139 147 127 138 158 170 135 136 147 148 130 122 157 128 129 150 140 150 141 134 137 148 125 123 156 136 136 146 149 145 134 147 148 132 126 155 150 166 152 142 145 154 147 154 157 151 152 149 150 158 147 142 131 159 153 138 165 138 149 150 153 161 160 157 149 136 129 144 124 148 129 146 121 135 123 136 128 127 151 169 145 127 145 128 138 150 153 130 146 154 160 144 163 159 153 164 126 151 139 127 149 152 139 151 130 120 160 147 132 140 152 142 149 151 134 144 165 135 183 122 142 157 135 148 148 144 143 151 149 137 181 140 147 157 158 136 138 117 141 132 128 150 135 132 168 143 143 137 162 140 155 165 124 151 140 150 152 150 131 133 149 152 163 139 165 118 113 152 126 137 105 150 134 136 139 126 135 116 155 152 124 128 139 139 136 165 149 135 141 163 145 136 146 141 139 146 156 166 157 146 140 143 136 177 115 134 159 136 127 156 141 120 131 155 131 145 125 136 158 152 153 174 153 141 143 140 144 121 151 140 137 150 157 132 151 156 159 151 160 157 127 144 142 137 136 150 144 152 150 146 138 137 144 136 153 152 136 139 157 165 143 143 142 129 157 182 146 127 141 156 132 145 157 127 153 174 154 146 141 160 132 152 165 136 140 145 157 124 141 150 145 138 136 147 128 154 119 145 142 137 153 160 124 136 161 151 161 147 142 153 152 120 140 133 173 135 148 171 146 158 138 151 143 127 156 162 135 154 124 155 151 160 149 144 156 143 124 146 136 148 150 132 139 141 131 139 142 144 142 135 135 149 134 125 155 152 136 151 125 139 149 142 144 136 160 136 135 148 153 148 143 168 138 148 138 152 128 140 152 153 178 180 134 131 150 134 145 158 141 170 151 155 138 135 123 143 144 148 137 145 145 173 150 172 142 145 150 162 141 144 145 152 152 131 152 156 137 134 142 147 169 151 173 126 137 125 149 141 135 163 148 138 139 147 142 139 133 179 150 143 148 138 144 126 144 134 152 134 161 136 139 145 144 138 154 128 163 168 135 146 130 173 125 143 166 157 135 153 162 142 138 157 127 172 161 138 155 164 154 166 156 149 130 151 151 143 140 152 151 160 159 146 144 168 163 159 154 153 146 144 151 152 155 145 150 140 137 124 143 139 135 151 158 141 135 154 137 135 135 148 149 148 146 140 150 126 133 161 150 156 138 124 133 150 128 164 165 129 172 141 141 125 149 148 144 141 155 147 150 145 158 142 138 154 174 159 146 137 161 146 146 155 135 144 142 146 149 146 147 154 142 163 151 149 156 145 157 179 141 138 135 148 113 128 137 142 138 144 152 155 153 147 154 133 166 127 158 163 147 137 151 136 147 160 157 141 169 141 144 141 165 152 153 142 145 146 130 160 159 161 153 151 152 158 132 140 145 141 128 132 142 148 144 153 145 143 150 170 173 155 156 130 146 136 171 128 145 146 136 145 162 141 153 148 138 137 153 147 142 153 146 144 158 146 142 150 163 129 149 145 149 142 154 145 142 155 145 136 167 157 138 155 146 157 151 162 136 136 145 152 142 150 150 162 151 132 148 154 133 134 145 168 140 150 147 153 145 143 146 165 131 159 144 138 163 167 136 118 145 156 134 148 137 138 161 136 146 157 155 143 128 124 136 157 154 148 144 151 152 160 157 156 138 144 138 135 143 171 133 137 146 142 154 134 143 122 169 160 162 170 131 142 153 132 166 145 149 167 157 158 142 176 151 151</counts>
			</dataPoints>
		</scan>
	</xrdMeasurement>
</xrdMeasurements>