File: data/XRD/XG-Vakuum/XG-875/W6821-1C_XG_Vakuum_875.xrdml
<xrdMeasurements xmlns="http://www.xrdml.com/XRDMeasurement/2.1" xmlns:xsi="http://www.w3.org/2001/XMLSchema-instance" xsi:schemaLocation="http://www.xrdml.com/XRDMeasurement/2.1 http://www.xrdml.com/XRDMeasurement/2.1/XRDMeasurement.xsd" status="Completed">
	<comment>
		<entry>Configuration=Factory configuration, Owner=User-1, Creation date=7/8/2013 4:01:53 PM</entry>
		<entry>Goniometer=PW3050/65 (Theta/2Theta); Minimum step size 2Theta:0.0001; Minimum step size Omega:0.0001</entry>
		<entry>Sample stage=MRD Cradle; Minimum step size Phi:0.01; Minimum step size Chi:0.01; Minimum step size X:0.01; Minimum step size Y:0.01; Minimum step size Z:0.001</entry>
		<entry>Diffractometer system=XPERT-PRO</entry>
		<entry>Measurement program=C:\PANalytical\Data Collector\Programs\Jorrit\2thom\_absolute_2th-om_10-130deg_PIXscan_56min.xrdmp, Identifier={15BCCF57-2807-42BD-B5B9-ECC0B3DC9284}</entry>
		<entry>Batch program=C:\PANalytical\Data Collector\Programs\SimonL\batch7x_2thom_10-130°_z9.1_x0,10,20,30_y10,20,30_57min.xrdmp, Identifier={089D96B1-A01D-49FF-BCB5-EEA9DFC9CC78}</entry>
	</comment>
	<sample type="To be analyzed">
		<id></id>
		<name></name>
		<preparedBy></preparedBy>
	</sample>
	<xrdMeasurement measurementType="Scan" status="Completed" sampleMode="Reflection">
		<comment>
			<entry>_absolute_2th-om_10-130deg_PIXscan_56min</entry>
			<entry>PHD Lower Level = 4.83 (keV), PHD Upper Level = 11.27 (keV)</entry>
		</comment>
		<usedWavelength intended="K-Alpha 1">
			<kAlpha1 unit="Angstrom">1.5405980</kAlpha1>
			<kAlpha2 unit="Angstrom">1.5444260</kAlpha2>
			<kBeta unit="Angstrom">1.3922500</kBeta>
			<ratioKAlpha2KAlpha1>0.5000</ratioKAlpha2KAlpha1>
		</usedWavelength>
		<incidentBeamPath>
			<radius unit="mm">320.00</radius>
			<xRayTube id="1010048" name="Empyrean Cu LFF HR (9430 033 7310x) DK442154">
				<tension unit="kV">40.0</tension>
				<current unit="mA">40.0</current>
				<anodeMaterial>Cu</anodeMaterial>
				<focus type="Line">
					<length unit="mm">12.0</length>
					<width unit="mm">0.4</width>
					<takeOffAngle unit="deg">4.2</takeOffAngle>
				</focus>
			</xRayTube>
			<xRayMirror id="27010001" name="Inc. Beam Cu W/Si (parabolic MRD)" hybrid="false">
				<crystal type="Graded" shape="Parabolic">W/Si</crystal>
				<acceptanceAngle unit="deg">0.800</acceptanceAngle>
				<length unit="mm">60.0</length>
			</xRayMirror>
			<sollerSlit id="21010002" name="Soller slits 0.04 rad.">
				<opening unit="rad">0.0400</opening>
			</sollerSlit>
			<mask id="22030008" name="Fixed mask 4 mm">
				<distanceToSample unit="mm">220.00</distanceToSample>
				<width unit="mm">4.00</width>
			</mask>
			<divergenceSlit id="22010011" name="Fixed slit 1/32°" xsi:type="fixedDivergenceSlitType">
				<distanceToSample unit="mm">220.00</distanceToSample>
				<height unit="mm">0.05</height>
			</divergenceSlit>
		</incidentBeamPath>
		<diffractedBeamPath>
			<radius unit="mm">320.00</radius>
			<sollerSlit id="21010002" name="Soller slits 0.04 rad.">
				<opening unit="rad">0.0400</opening>
			</sollerSlit>
			<receivingSlit id="22010001" name="Fixed slit 4°">
				<height unit="mm">5.88</height>
			</receivingSlit>
			<detector id="7010017" name="PIXcel3D 1x1 detector" xsi:type="areaDetectorType">
				<phd unit="%">
					<lowerLevel>30.0</lowerLevel>
					<upperLevel>70.0</upperLevel>
				</phd>
				<mode>Scanning</mode>
				<activeChannelsEquatorial>255</activeChannelsEquatorial>
				<activeChannelsAxial>255</activeChannelsAxial>
				<pitchEquatorial unit="mm">0.05500</pitchEquatorial>
				<pitchAxial unit="mm">0.05500</pitchAxial>
				<readOutPeriod unit="seconds">0.135</readOutPeriod>
			</detector>
		</diffractedBeamPath>
		<scan appendNumber="0" mode="Continuous" scanAxis="2Theta-Omega" status="Completed">
			<header>
				<startTimeStamp>2024-10-22T00:14:40+02:00</startTimeStamp>
				<endTimeStamp>2024-10-22T01:10:45+02:00</endTimeStamp>
				<author>
					<name>PRO-MRD</name>
				</author>
				<source>
					<applicationSoftware version="6.1b">Data Collector</applicationSoftware>
					<instrumentControlSoftware version="7.0E 20130304">XPERT-PRO</instrumentControlSoftware>
					<instrumentID>0000000011142674</instrumentID>
				</source>
			</header>
			<dataPoints>
				<positions axis="2Theta" unit="deg">
					<startPosition>9.99826193</startPosition>
					<endPosition>129.99755682</endPosition>
				</positions>
				<positions axis="Omega" unit="deg">
					<startPosition>4.99913096</startPosition>
					<endPosition>64.99877841</endPosition>
				</positions>
				<positions axis="Phi" unit="deg">
					<commonPosition>0.00</commonPosition>
				</positions>
				<positions axis="Chi" unit="deg">
					<commonPosition>0.00</commonPosition>
				</positions>
				<positions axis="X" unit="mm">
					<commonPosition>0.00</commonPosition>
				</positions>
				<positions axis="Y" unit="mm">
					<commonPosition>-10.00</commonPosition>
				</positions>
				<positions axis="Z" unit="mm">
					<commonPosition>9.100</commonPosition>
				</positions>
				<commonCountingTime unit="seconds">32.895</commonCountingTime>
				<counts 85 63 67 69 79 85 62 78 79 85 38 78 52 68 74 82 66 57 60 77 60 62 70 72 65 57 72 77 65 62 69 77 64 70 62 80 66 75 72 71 65 53 75 56 64 55 69 63 73 75 59 66 63 66 60 57 67 44 66 69 63 83 58 73 67 62 57 57 55 74 63 65 66 72 55 52 61 61 67 70 63 65 68 58 69 65 65 75 55 61 63 64 58 66 55 61 62 62 69 75 63 68 61 64 69 52 76 68 57 66 60 62 59 57 65 67 57 63 59 55 52 74 62 67 60 45 57 50 63 66 53 67 71 66 43 68 74 61 69 51 41 76 56 63 74 59 76 61 69 58 53 58 67 68 58 60 60 68 61 40 60 61 64 75 66 56 55 74 41 59 64 70 65 60 62 67 55 59 56 66 53 60 46 69 42 53 57 62 56 62 69 73 53 65 61 72 60 59 54 60 72 70 41 71 67 61 57 57 58 46 65 53 57 86 59 56 63 53 54 39 57 64 64 59 57 42 47 39 54 59 68 60 63 66 47 58 68 60 53 77 72 55 65 60 46 54 77 58 59 68 56 44 56 53 51 49 66 58 55 66 53 66 53 60 59 47 49 46 64 51 55 51 63 69 47 41 68 48 52 57 54 52 59 49 58 54 54 67 56 62 70 56 53 52 59 56 59 54 67 59 47 54 56 46 51 67 45 58 55 53 75 50 45 52 60 54 49 52 54 53 67 62 48 60 53 45 72 47 43 53 59 58 57 57 65 52 45 56 44 45 57 55 59 58 61 53 53 52 68 56 55 36 56 60 54 55 42 43 55 52 57 59 52 37 60 49 74 57 60 55 47 52 41 57 46 63 47 45 50 58 51 48 52 52 48 53 46 51 53 54 53 64 60 48 48 56 46 58 59 54 46 51 52 43 41 51 56 56 71 45 50 58 44 54 57 41 60 44 46 47 41 55 42 42 55 54 47 54 41 49 49 60 49 54 56 62 42 64 51 61 52 37 55 41 42 58 54 55 63 47 48 40 54 57 52 59 59 53 53 56 46 60 62 59 55 43 54 60 58 59 54 61 46 48 59 54 47 61 48 54 62 55 55 67 52 37 54 51 40 55 57 45 51 48 45 49 51 47 58 41 40 58 52 50 48 56 49 56 46 55 39 53 57 57 45 43 52 43 43 42 50 45 47 55 44 65 48 53 45 63 53 42 57 54 58 44 51 53 55 46 46 48 44 53 40 43 49 49 44 50 52 56 56 49 53 49 37 41 55 52 58 52 47 52 55 51 49 46 47 50 46 54 45 47 53 43 37 53 62 57 56 40 55 39 48 42 50 50 54 39 51 53 48 52 50 51 41 52 41 40 54 43 41 45 65 54 50 54 46 47 41 64 51 46 56 52 58 43 69 56 58 62 57 46 57 50 51 48 48 45 59 64 49 52 44 47 50 48 51 46 41 50 41 43 56 54 52 59 40 52 53 52 53 47 66 53 57 46 58 48 56 67 41 55 42 48 59 50 36 44 55 44 49 64 58 49 46 51 42 53 37 44 43 41 33 55 47 42 45 42 44 58 44 41 42 49 42 52 52 45 50 55 51 44 57 45 45 51 52 53 45 50 64 65 46 48 55 48 43 39 52 48 63 43 40 51 47 54 31 55 52 57 54 39 46 43 52 57 50 50 44 43 56 51 41 53 44 49 49 48 53 44 49 48 55 47 44 50 44 53 59 59 53 35 50 41 52 54 56 57 37 52 43 44 58 43 52 45 51 49 45 40 45 48 47 49 41 50 58 56 45 59 44 43 57 41 41 43 40 52 48 41 51 55 55 55 40 41 58 48 36 60 53 42 48 40 62 42 45 51 58 44 59 55 66 41 63 46 55 42 53 39 44 59 54 44 48 58 50 47 46 54 47 38 58 57 46 53 49 45 42 49 39 39 40 54 40 37 46 52 40 42 51 46 46 40 37 57 52 62 60 43 39 49 49 48 49 60 54 38 50 43 50 51 34 64 37 42 43 38 45 45 44 39 45 49 53 42 41 55 53 52 54 49 44 49 40 53 43 50 56 45 52 57 50 45 43 53 54 37 48 42 43 44 48 61 37 51 56 61 44 52 48 46 58 56 48 49 50 53 51 57 52 57 51 46 45 53 38 45 50 44 48 44 62 49 51 60 51 55 44 55 50 43 47 35 40 44 51 55 55 55 47 50 53 51 62 53 59 57 47 49 54 45 41 46 39 46 48 43 50 49 38 48 49 51 44 48 47 43 53 51 55 51 49 42 51 42 44 62 58 51 62 51 47 51 54 58 43 55 44 45 58 50 43 46 56 48 46 51 51 38 56 44 41 36 51 61 51 49 44 46 50 44 50 56 58 38 31 52 56 44 63 51 49 54 51 49 51 43 52 44 49 38 39 51 35 53 43 50 46 59 55 46 63 50 50 69 52 48 70 53 53 44 55 46 49 46 44 51 43 36 40 46 52 50 48 56 39 52 46 43 52 62 53 51 41 44 48 49 47 57 48 43 46 45 38 48 44 57 48 36 53 48 58 54 50 51 43 42 44 56 53 49 60 55 49 46 45 50 43 45 56 51 50 53 57 40 51 52 38 55 55 49 51 45 29 64 44 54 50 53 55 44 64 45 52 49 36 46 47 51 39 43 50 56 57 57 52 51 41 53 49 50 49 45 54 46 58 52 60 40 44 53 56 43 58 36 48 56 44 53 63 49 58 50 56 55 41 58 62 52 59 44 54 59 59 47 53 57 44 58 58 43 45 60 53 43 46 53 48 43 46 48 49 37 39 41 43 40 55 59 45 56 44 44 36 62 33 41 52 38 54 37 53 55 51 46 45 43 42 43 55 44 37 47 61 36 50 60 37 50 44 45 50 48 55 61 49 47 54 44 49 50 44 46 51 53 45 38 53 50 48 50 45 50 45 56 48 49 50 45 56 49 53 41 50 47 47 43 40 57 53 56 42 55 45 48 40 35 46 46 46 57 54 41 58 60 48 57 40 52 44 54 56 49 50 53 46 55 53 58 40 42 52 47 39 48 52 53 53 57 59 61 49 51 50 39 56 47 50 47 52 43 54 45 46 51 51 46 53 49 50 38 59 45 45 45 54 43 39 40 32 59 51 58 44 56 49 44 43 53 51 54 50 55 46 46 55 37 57 45 53 58 55 55 57 58 52 64 46 50 46 54 48 52 47 43 51 56 56 46 55 52 45 53 52 41 48 51 51 45 49 38 38 58 52 42 54 52 52 61 46 43 52 44 45 45 43 38 53 49 51 44 51 45 56 40 47 53 47 60 51 55 36 43 37 51 48 53 62 41 34 43 53 58 49 58 55 61 48 47 49 58 46 43 46 50 53 40 47 53 44 53 43 55 53 62 44 45 53 60 48 43 55 42 49 55 49 45 50 52 49 51 42 66 62 41 54 37 42 56 56 44 44 49 46 45 45 58 58 57 58 47 38 60 46 43 47 50 61 48 42 39 37 43 45 44 46 48 42 51 41 46 56 53 40 49 44 44 59 38 50 39 44 46 49 45 53 46 48 47 50 44 48 42 51 54 56 49 49 54 61 59 58 52 57 45 52 61 38 35 53 45 46 46 55 48 45 42 48 50 32 52 61 42 50 52 60 47 48 50 44 48 52 65 54 61 42 48 32 48 41 56 57 43 46 32 41 57 52 42 45 42 48 40 46 45 50 54 60 49 42 41 47 49 46 57 38 56 55 40 44 43 41 43 62 40 43 55 49 41 40 65 46 58 46 42 44 42 44 49 42 42 56 56 39 43 42 49 53 40 42 45 40 35 54 45 58 51 51 33 51 43 50 41 45 58 37 43 58 39 39 37 44 40 42 49 41 42 47 54 46 53 43 51 40 47 42 48 49 47 54 45 56 62 39 47 41 49 46 47 46 56 51 59 42 56 45 43 46 42 48 45 40 55 36 62 46 54 40 43 45 44 43 42 40 36 45 56 39 53 39 45 43 55 45 39 45 48 46 36 49 54 54 44 45 47 49 42 42 53 45 50 34 47 52 41 60 48 45 48 53 50 48 46 56 43 51 49 55 54 41 51 56 45 39 46 36 52 52 36 52 46 45 46 51 54 42 52 62 45 48 44 52 38 39 44 41 58 35 54 34 52 48 42 42 38 49 45 46 47 43 51 63 45 38 35 54 40 51 39 47 58 48 38 61 36 45 35 42 29 47 45 54 42 53 48 52 38 47 40 43 42 50 47 44 40 41 40 33 51 45 47 35 55 30 51 48 47 53 46 51 34 50 47 52 51 45 44 38 54 42 34 55 58 38 38 48 57 51 43 46 46 45 41 50 47 54 44 46 54 42 55 57 45 61 44 43 48 43 46 55 50 50 40 39 43 49 46 45 39 51 48 60 44 47 55 47 41 57 47 44 41 48 45 47 39 44 43 34 40 38 45 43 53 41 37 52 40 41 48 35 43 45 46 54 47 43 35 51 40 45 48 51 48 41 47 42 45 49 50 60 48 63 47 40 36 43 39 55 39 38 44 34 56 48 48 45 53 37 44 44 38 37 55 54 54 49 37 39 42 43 33 43 48 57 44 47 49 47 40 55 46 42 41 47 51 52 45 56 55 38 51 50 53 41 42 38 44 51 48 38 39 39 42 35 58 44 48 59 51 43 42 52 53 40 39 34 42 53 53 55 49 54 54 53 39 40 52 45 38 44 48 29 42 47 38 64 49 47 52 49 41 54 36 42 47 50 56 49 48 57 61 48 46 50 40 51 46 51 50 44 38 44 46 48 43 46 45 45 51 42 44 39 39 36 38 52 42 41 55 51 42 61 50 42 44 42 31 37 46 50 54 41 36 57 40 52 49 54 48 48 56 49 34 56 61 48 39 61 53 39 38 44 38 46 40 52 59 44 45 45 40 45 53 40 48 47 53 49 56 59 46 48 43 54 61 43 41 48 54 44 40 58 48 43 43 44 39 39 44 48 46 46 49 31 51 41 34 41 44 50 39 45 42 47 46 49 46 37 51 37 51 56 48 41 43 58 51 52 52 50 52 45 51 57 40 36 56 48 43 33 43 52 55 44 43 44 35 57 44 51 54 49 51 48 37 48 52 46 49 44 44 35 43 36 55 49 35 46 39 48 54 49 37 44 45 43 43 41 57 57 52 37 60 49 45 54 42 44 63 47 49 55 33 49 44 44 42 52 51 59 54 60 46 39 39 48 46 44 53 41 48 40 44 53 42 52 38 47 48 45 39 48 45 52 49 49 45 51 41 42 44 47 42 60 55 50 46 60 47 45 47 47 52 58 38 53 44 47 56 44 39 43 46 47 44 32 42 39 37 40 46 54 41 43 51 47 53 44 50 48 49 49 36 46 50 50 40 46 61 65 47 51 46 56 39 37 55 46 40 53 66 60 38 48 49 52 39 51 50 53 37 43 50 43 48 30 48 35 44 52 40 50 43 35 51 52 46 54 42 49 47 42 48 35 47 43 45 57 50 51 45 45 50 57 52 40 47 50 39 46 55 55 51 48 56 44 40 47 45 51 51 34 46 47 42 54 54 47 40 44 49 47 38 46 44 43 44 42 42 57 50 59 50 59 41 53 50 50 52 51 41 49 49 44 53 56 49 37 46 41 46 35 35 31 51 53 45 45 48 41 48 37 43 53 52 61 67 45 53 46 37 49 45 52 61 42 39 39 40 43 47 53 50 44 50 33 41 56 53 38 43 45 43 46 32 60 48 56 42 42 55 38 55 27 44 49 48 43 54 48 43 58 49 38 57 42 49 52 51 43 46 57 51 47 43 54 52 42 39 42 45 42 45 47 36 42 49 46 46 55 38 50 51 46 53 51 51 45 47 44 66 39 44 40 46 47 48 44 48 48 43 47 45 39 37 46 54 41 38 51 45 58 42 58 46 54 56 46 45 51 49 45 44 44 32 49 43 40 49 58 42 47 49 44 49 50 55 50 45 45 49 34 40 44 43 31 39 25 39 41 45 64 52 44 58 51 49 34 57 53 38 41 49 46 36 44 45 39 47 50 43 32 40 45 55 41 47 61 56 47 59 44 33 63 40 48 61 39 44 45 47 54 48 43 50 45 43 59 47 37 43 44 43 64 57 40 42 47 44 35 44 53 34 38 49 50 45 45 55 45 43 30 46 46 44 42 47 36 46 45 43 40 43 35 52 51 51 43 39 45 59 41 42 40 31 55 29 42 49 46 40 48 45 35 48 31 54 42 44 44 46 51 55 45 38 43 41 41 41 49 40 46 42 50 36 53 34 37 45 42 34 43 47 49 48 53 43 42 44 45 42 51 41 42 50 34 61 35 42 49 42 43 34 43 53 48 59 49 34 30 40 55 55 50 36 45 38 53 50 57 46 47 47 33 40 47 38 43 45 34 43 48 35 47 36 40 38 31 45 44 36 40 42 32 51 52 29 41 33 51 40 45 41 43 27 57 34 46 30 43 51 40 44 44 55 53 46 38 55 47 40 42 46 58 35 46 46 40 51 48 38 39 33 44 57 64 35 43 42 38 40 49 42 55 43 47 45 45 35 40 37 45 47 36 58 53 43 44 49 43 42 44 45 45 45 40 45 52 39 32 51 46 36 49 44 61 45 57 45 39 40 34 50 47 42 52 52 37 55 56 49 46 52 51 42 53 53 54 48 53 47 40 51 43 47 45 40 55 35 44 41 44 44 58 48 44 54 42 41 55 41 37 42 43 55 54 55 48 49 45 35 41 48 47 55 38 56 52 44 36 46 37 50 43 44 40 44 52 49 41 44 43 39 41 40 52 51 44 54 36 40 43 47 42 49 39 39 55 45 45 42 56 55 54 41 45 55 44 48 43 41 51 33 39 52 30 40 44 38 57 37 40 39 46 58 52 46 48 42 45 46 51 51 49 46 49 41 46 43 39 61 33 37 36 54 47 58 50 46 49 65 43 44 42 42 52 54 38 43 41 47 63 47 45 50 53 50 44 50 52 41 48 49 42 48 43 44 61 43 41 52 40 38 46 44 44 50 42 52 57 48 42 55 44 44 55 42 46 53 51 40 47 62 44 41 58 60 52 38 43 46 53 48 46 52 47 45 51 51 40 46 42 42 43 39 52 50 37 48 49 45 55 42 48 50 45 40 47 43 43 49 46 38 49 63 48 37 37 40 46 49 47 46 43 52 42 48 42 45 52 55 33 51 46 45 42 53 45 41 50 47 45 48 43 44 53 58 42 51 48 44 39 48 44 46 47 56 47 56 43 43 41 35 56 45 46 41 55 50 41 61 30 55 42 55 47 36 54 44 32 43 60 42 55 48 34 46 43 51 43 52 39 44 47 44 39 52 57 47 42 42 42 58 40 60 53 43 41 68 42 48 48 43 42 39 44 40 29 45 51 42 44 42 48 43 52 41 32 45 46 50 45 35 46 56 50 45 50 26 38 47 39 41 46 50 55 47 45 50 50 61 44 48 54 50 55 37 43 41 45 44 40 49 50 48 50 48 43 54 60 45 51 31 47 52 50 72 54 50 40 42 44 41 52 53 50 54 59 40 41 41 60 53 54 35 59 53 49 49 49 54 49 47 48 53 56 49 58 58 58 57 55 39 41 45 50 49 48 56 56 58 51 64 38 60 49 67 46 59 55 44 58 51 44 48 49 53 60 48 38 50 49 58 66 49 55 48 54 55 55 38 49 52 56 58 46 44 50 42 59 64 48 60 68 52 49 37 50 56 49 46 49 56 61 51 54 49 60 59 59 52 53 65 50 54 44 66 50 41 61 41 50 65 46 55 50 52 62 55 50 55 48 67 66 52 60 65 66 47 80 66 73 74 68 68 76 65 78 75 88 67 79 73 100 79 86 95 102 108 82 85 89 91 104 82 97 95 93 82 71 106 94 70 71 66 88 91 79 74 88 68 71 68 55 65 69 58 65 67 64 62 52 56 59 68 57 59 47 54 65 66 59 52 52 54 54 45 62 56 49 56 55 57 44 55 53 54 65 45 57 41 48 51 52 50 54 53 42 60 49 55 56 44 49 37 42 42 45 49 53 50 45 52 50 49 56 52 55 45 52 52 54 45 52 36 56 52 56 48 51 48 49 50 38 50 37 57 46 54 42 39 45 62 51 55 49 38 42 48 60 45 40 47 60 37 47 78 51 56 39 35 48 47 50 48 53 41 43 50 51 56 57 43 47 41 38 48 48 52 59 60 69 53 48 39 50 37 41 39 41 53 48 35 42 42 65 55 57 51 42 52 44 50 37 53 38 40 52 60 50 49 51 50 33 36 41 52 47 48 34 42 45 47 53 60 50 36 51 43 47 47 55 36 49 52 46 43 41 40 56 56 55 53 52 50 47 40 46 49 42 45 49 44 51 52 43 46 44 49 42 50 50 42 52 41 40 38 39 51 44 49 51 40 45 43 51 31 41 45 43 52 44 53 59 55 55 55 53 40 47 40 45 50 40 51 52 43 36 44 52 59 50 41 46 45 54 51 44 46 60 41 44 45 56 47 45 42 46 55 59 62 39 53 45 54 49 47 46 43 45 42 46 42 50 48 57 53 47 57 39 50 46 37 51 48 51 46 43 46 47 49 52 39 53 49 41 53 44 54 49 33 45 42 46 46 46 61 49 50 46 41 48 53 46 49 42 41 58 49 33 51 39 51 58 55 31 56 40 54 49 47 41 51 49 52 38 52 43 44 51 35 65 47 48 63 50 57 38 58 47 44 57 39 54 47 50 54 49 45 59 56 41 55 48 44 43 53 44 43 59 46 37 44 51 42 48 58 42 53 52 41 50 49 63 52 48 41 57 57 45 44 42 49 45 41 45 47 48 51 38 45 54 43 52 45 47 55 51 46 44 49 47 39 44 42 36 46 38 35 42 43 49 54 44 55 49 56 36 47 49 43 45 57 47 48 57 47 37 46 55 43 43 63 48 39 41 35 39 64 43 27 54 42 54 35 47 42 46 51 42 55 45 36 55 45 48 52 57 45 47 52 50 46 55 47 48 54 42 43 53 44 50 40 52 33 40 47 53 58 47 53 48 39 56 51 37 49 57 45 56 57 44 56 47 47 50 53 55 41 42 59 43 37 40 44 55 67 47 56 43 48 39 48 49 56 47 58 47 52 39 42 43 58 41 52 47 54 35 50 43 57 39 39 50 57 46 61 49 42 52 42 51 46 47 45 51 55 33 45 56 52 57 50 57 44 51 39 48 44 44 52 52 33 46 43 42 55 56 49 45 46 55 54 47 32 50 49 41 45 58 50 44 56 48 51 39 49 57 50 36 53 55 41 41 44 43 43 52 50 35 43 46 41 51 46 58 39 53 51 46 44 36 46 46 46 43 50 31 41 39 45 53 34 50 45 52 48 41 47 45 52 43 48 44 40 37 61 52 41 47 40 46 50 45 44 37 42 48 47 40 52 59 34 46 42 51 46 40 40 53 48 43 44 56 44 50 44 53 48 47 36 38 39 48 52 42 52 45 44 44 32 46 46 43 53 42 30 45 51 54 48 52 49 50 42 44 44 43 34 46 37 51 50 44 36 35 38 53 48 43 44 43 37 50 44 51 44 39 56 50 46 49 59 42 55 51 37 48 52 53 49 56 56 58 48 46 46 39 52 47 33 42 52 47 52 46 38 51 47 55 42 52 37 40 44 47 49 50 40 46 42 53 46 52 43 49 50 54 41 39 64 47 40 51 53 54 53 55 46 48 47 48 57 48 49 47 51 57 47 52 45 38 54 55 39 51 48 46 41 46 38 52 44 54 51 41 60 45 36 55 41 45 58 61 44 51 48 40 52 47 52 44 35 43 52 53 52 55 51 54 42 51 53 30 38 40 55 42 46 56 55 48 57 45 44 49 49 44 46 53 48 54 44 51 40 62 55 46 34 56 60 43 41 44 42 50 41 35 35 58 47 79 47 55 53 65 45 39 36 46 42 46 57 42 60 49 44 44 58 46 58 50 50 48 48 57 40 37 50 50 45 53 47 45 63 45 36 59 45 42 50 46 54 55 55 50 43 45 50 53 59 34 44 47 59 54 43 54 50 49 41 53 52 48 38 57 35 36 40 40 51 45 49 48 52 54 43 46 62 50 40 52 45 51 48 33 52 50 40 56 38 42 43 48 47 43 53 49 54 38 55 60 59 52 63 65 36 53 39 36 43 60 35 47 59 50 40 49 29 50 44 54 48 46 53 46 47 45 46 42 53 49 57 42 47 40 44 45 49 45 54 30 45 46 47 41 42 59 57 63 40 51 50 49 50 41 44 40 44 31 44 47 59 43 50 47 46 37 41 59 48 32 45 53 49 40 46 46 55 43 49 52 51 50 40 64 51 48 38 39 59 55 34 46 44 55 42 49 51 39 50 50 41 54 47 68 46 52 45 49 46 56 56 61 44 45 34 62 44 42 45 62 47 36 50 46 49 53 44 54 47 50 50 49 47 52 51 49 52 44 45 42 40 43 46 46 49 47 61 50 53 54 53 46 55 54 52 50 59 38 55 46 44 51 47 46 44 34 42 52 58 46 42 52 49 35 52 55 54 39 42 40 42 49 56 51 42 45 53 44 53 59 46 45 48 47 59 45 49 50 47 39 52 41 53 63 48 38 40 39 48 40 46 40 43 35 58 59 42 43 48 50 38 53 58 34 48 45 54 40 57 40 42 39 44 51 41 36 43 56 43 58 48 46 40 39 50 48 49 46 39 55 56 56 57 49 46 35 39 43 50 37 48 50 48 46 51 42 46 47 52 45 42 43 36 56 42 52 41 47 37 34 49 54 44 45 47 45 60 58 48 45 54 44 47 53 54 43 62 42 46 49 49 42 47 37 53 39 49 59 42 47 60 47 50 51 50 43 42 58 47 55 48 51 42 40 55 37 47 48 37 53 47 52 52 40 49 46 45 35 54 53 68 41 34 49 62 57 46 42 47 54 50 62 48 33 35 43 49 51 56 42 40 57 38 43 52 61 56 51 45 43 47 47 45 40 41 40 50 44 49 51 67 49 50 43 50 47 43 36 41 41 47 48 58 53 44 53 61 44 64 46 54 43 43 45 45 47 43 50 45 38 47 39 52 49 62 54 56 47 55 41 34 54 43 45 55 57 37 46 54 54 46 45 58 42 50 38 42 46 44 40 43 50 56 44 45 44 40 52 57 44 51 39 45 38 42 45 56 50 40 48 52 49 37 61 52 39 44 43 56 64 60 43 43 50 38 34 55 48 52 53 46 56 53 45 37 52 57 48 44 45 54 44 52 42 49 42 49 63 48 52 59 53 57 39 46 55 41 60 60 32 53 58 42 55 47 45 52 53 49 41 57 54 53 44 36 46 47 38 53 45 38 49 49 48 45 54 47 37 46 45 51 56 48 48 48 35 53 35 42 50 44 35 49 46 38 44 45 41 50 56 39 56 56 48 49 35 48 59 32 42 43 56 47 44 40 62 54 46 51 53 46 28 49 42 47 53 36 52 49 36 50 49 42 37 48 48 52 49 45 48 55 40 46 44 34 49 47 42 43 61 43 40 56 46 56 62 45 57 43 51 56 44 48 44 49 40 39 32 39 43 38 50 44 48 44 48 42 39 50 45 43 30 43 47 48 43 41 49 39 60 38 50 51 56 47 58 42 56 55 47 48 50 47 61 43 44 49 55 52 59 50 47 43 40 51 43 66 52 42 50 52 39 55 48 59 44 53 49 46 52 45 48 52 61 59 52 47 47 42 51 51 46 39 42 37 48 41 43 55 44 47 39 48 50 47 38 53 43 48 55 47 49 46 37 36 44 37 60 30 38 49 55 51 46 49 61 55 50 56 50 49 49 50 49 30 44 54 41 50 45 60 45 50 45 54 44 48 51 52 43 49 42 53 53 42 51 50 45 52 52 51 41 49 44 42 49 41 54 38 58 55 48 34 46 43 48 40 46 43 62 51 53 46 47 52 42 45 58 54 34 49 54 53 54 53 39 54 42 38 46 51 29 59 38 47 50 46 47 37 47 49 50 51 52 37 49 54 53 43 48 41 57 52 54 57 51 41 46 40 49 50 45 51 41 38 38 38 61 45 57 51 60 50 44 56 36 52 56 43 63 59 50 62 38 43 44 49 37 49 48 47 53 59 44 47 58 50 66 53 45 48 50 54 65 51 50 60 48 64 51 47 49 50 53 54 60 54 56 49 40 43 39 42 46 52 44 50 39 65 53 50 56 52 38 45 45 55 35 39 46 34 52 49 35 56 68 44 43 43 68 53 59 59 66 44 44 54 50 57 57 52 55 41 43 51 49 61 59 30 51 58 49 40 53 55 37 55 42 53 50 54 59 53 41 58 51 46 53 51 37 51 39 56 44 51 42 46 41 44 52 44 51 51 57 59 45 62 59 53 42 59 53 58 55 43 43 42 62 54 27 47 47 52 50 52 48 51 38 44 53 44 44 39 36 47 53 49 41 35 51 31 49 49 51 48 57 49 46 58 52 46 52 47 53 49 53 53 48 52 61 46 50 58 50 49 49 40 61 50 59 48 46 53 56 44 55 43 51 60 54 53 49 50 56 54 54 61 56 60 61 49 49 43 62 58 49 48 38 54 53 49 67 51 56 52 58 62 40 57 49 40 39 53 55 41 42 46 51 53 59 57 57 49 45 44 40 43 57 50 46 60 56 54 46 45 45 48 37 51 40 48 49 47 57 50 57 63 50 43 55 52 50 59 46 46 50 51 51 47 49 53 44 54 47 41 46 40 49 47 60 41 41 46 37 64 58 49 44 48 53 44 37 55 57 39 45 56 57 39 41 39 47 47 58 57 48 32 45 34 41 50 50 48 51 37 45 49 41 53 55 33 61 43 40 58 48 54 53 51 56 39 45 58 45 51 57 46 42 45 45 55 61 43 49 46 53 41 60 44 44 44 51 60 73 58 49 46 35 51 50 59 59 41 52 58 55 57 50 42 46 48 62 48 58 48 48 44 46 60 52 59 44 47 51 70 44 49 55 37 36 45 42 49 45 41 55 47 45 49 54 48 49 44 33 48 47 49 39 48 52 59 54 49 43 57 51 49 65 51 48 58 46 42 49 45 51 38 44 31 53 63 40 36 44 41 40 43 50 56 53 64 61 59 42 39 58 38 37 55 52 55 49 45 45 43 46 40 60 53 48 50 37 52 52 48 41 46 55 44 62 35 46 40 44 47 65 59 60 62 51 61 51 47 51 46 47 49 43 49 50 48 53 47 42 48 56 50 39 51 38 47 58 40 60 57 53 58 54 36 47 61 50 58 42 47 41 39 54 50 52 45 46 36 44 39 51 40 47 30 55 58 46 42 56 47 43 56 53 39 52 50 39 33 53 57 57 40 44 58 46 51 40 51 44 34 49 38 57 56 53 53 37 57 48 46 43 61 41 52 63 63 42 43 55 44 56 53 47 52 38 51 48 49 41 41 50 40 47 55 42 55 51 45 45 54 47 40 45 54 50 47 57 41 44 51 48 45 43 54 46 47 46 63 48 50 57 34 51 49 46 51 52 45 39 57 36 47 44 53 59 46 59 46 55 45 52 50 38 41 56 45 45 56 40 47 38 40 48 58 32 49 40 44 44 42 45 53 37 56 53 60 43 52 43 63 53 35 37 51 46 54 57 44 45 35 44 57 56 48 47 54 55 62 49 45 57 47 49 45 33 59 40 59 49 45 56 53 49 50 51 48 35 48 57 37 46 52 35 68 60 39 41 47 55 55 42 49 41 47 48 44 47 39 48 57 55 45 58 52 51 53 41 53 39 36 41 39 49 49 59 44 57 67 62 49 45 54 47 47 35 52 51 51 56 38 49 39 47 53 40 48 43 40 53 55 55 39 55 43 58 45 33 33 46 36 49 42 45 44 44 59 54 49 54 47 47 42 50 47 52 42 54 65 46 49 52 44 44 45 43 49 55 47 51 45 47 41 52 43 49 46 47 40 55 48 39 37 36 35 55 49 46 69 46 53 39 49 44 42 54 46 51 52 51 46 54 35 54 63 43 54 51 44 48 41 53 51 40 46 57 57 59 67 45 49 42 39 47 48 50 46 34 61 42 53 39 48 55 45 47 46 48 48 40 46 50 47 44 48 43 40 46 38 51 45 44 38 36 62 56 51 45 46 45 49 49 37 54 53 41 46 44 42 47 52 50 53 57 46 50 44 36 50 51 44 37 44 37 51 49 50 62 47 47 41 59 48 44 50 43 44 44 40 51 42 49 58 57 46 49 27 49 57 54 49 37 63 45 43 52 51 35 44 54 47 40 51 50 42 47 55 53 51 33 44 52 50 47 55 57 47 52 46 48 38 67 46 38 50 47 49 43 33 50 48 38 53 48 45 48 40 48 47 48 41 55 32 42 40 51 53 44 45 38 49 53 44 48 44 52 47 48 49 53 37 49 53 44 46 40 44 49 53 43 48 41 52 46 47 31 58 39 42 52 48 45 45 45 52 48 57 52 67 44 51 59 41 33 43 61 44 50 55 63 41 44 36 38 45 41 49 51 41 50 46 44 55 62 54 60 33 48 47 53 54 37 39 44 44 45 46 51 46 54 50 61 51 46 49 41 40 36 45 57 51 42 45 49 41 58 44 55 49 38 48 49 47 43 53 41 48 49 61 43 56 31 65 46 41 46 32 41 52 46 43 54 42 59 43 46 47 45 58 46 44 45 42 50 42 40 39 42 46 43 46 48 47 40 63 44 54 60 59 40 59 51 56 51 48 38 59 55 57 41 47 40 44 57 44 47 49 52 41 52 40 51 42 41 60 53 57 52 44 43 54 47 41 56 44 43 37 42 46 39 55 51 63 47 55 56 41 49 42 60 52 45 41 31 48 69 45 48 55 38 33 43 49 46 55 45 58 42 54 46 34 47 39 33 56 53 49 52 52 27 49 45 44 31 41 52 48 50 45 47 49 40 51 40 38 45 57 49 45 34 44 40 55 41 47 53 30 38 34 53 32 46 30 50 46 35 56 32 57 36 54 53 62 45 42 46 50 45 46 54 49 32 60 57 41 59 45 50 46 41 53 50 42 41 45 49 37 49 39 49 47 37 52 52 36 45 45 54 54 33 55 44 39 41 37 42 48 43 55 40 52 38 48 52 53 49 52 59 30 45 53 52 55 52 43 41 45 46 42 43 49 42 56 38 52 43 43 47 50 54 40 44 47 47 48 64 50 53 40 50 39 41 51 55 46 48 44 49 45 45 42 50 57 48 52 49 54 49 38 46 44 34 43 52 47 47 60 71 56 40 51 47 51 52 47 57 31 41 56 29 46 47 47 46 46 44 60 40 45 63 58 53 47 31 46 38 52 53 55 43 46 42 60 57 47 50 63 50 42 55 44 47 51 42 36 50 62 45 47 42 42 50 46 46 37 42 52 37 40 51 35 59 42 38 40 53 51 52 54 43 43 42 48 49 40 46 44 54 54 49 52 40 52 66 38 63 54 52 61 42 58 51 41 41 53 50 52 45 52 50 46 34 43 50 39 50 45 53 44 41 49 51 65 51 40 49 43 49 52 44 39 53 43 47 49 46 46 46 36 51 50 53 52 54 55 31 46 48 57 48 44 39 46 58 37 47 43 50 40 51 49 47 48 43 47 53 45 31 44 37 46 40 45 43 43 48 37 49 43 38 41 58 51 50 51 45 53 42 51 34 49 46 56 46 46 54 53 44 55 46 56 42 47 37 55 53 54 49 44 66 35 46 60 53 39 46 60 47 46 58 42 56 51 44 36 35 42 26 48 42 50 44 47 45 39 58 41 43 42 36 46 52 51 38 50 42 51 41 40 43 42 33 48 48 41 48 55 54 46 42 54 37 57 42 42 49 53 52 37 47 52 42 38 52 53 46 43 49 54 40 37 47 48 30 42 48 42 44 40 39 43 57 34 44 50 47 62 43 49 54 53 46 43 43 50 43 61 50 40 49 44 38 51 58 47 64 38 51 56 54 45 51 38 46 44 50 45 43 49 55 61 43 50 44 48 49 51 44 39 40 50 64 42 48 43 57 48 43 46 43 47 51 43 46 40 50 38 36 39 41 44 52 50 38 55 45 48 58 33 48 34 49 56 51 56 44 43 45 45 48 40 49 45 58 56 40 39 44 39 67 41 51 44 59 40 42 46 50 51 58 53 59 39 34 56 47 38 35 50 45 50 39 44 50 40 52 51 42 55 53 54 51 43 43 40 40 53 48 43 42 43 60 41 48 55 48 42 54 49 52 39 46 49 45 53 33 54 59 39 47 44 55 53 48 50 38 45 55 49 40 43 41 50 50 49 55 40 39 49 48 44 36 38 64 52 44 51 47 43 44 59 44 48 44 45 46 42 41 58 50 54 32 45 50 37 51 54 57 54 45 47 47 52 42 55 39 60 47 44 51 40 50 48 37 52 45 51 37 57 49 51 50 55 49 48 51 46 51 49 44 49 49 57 43 46 46 46 58 53 46 52 55 54 58 45 52 60 57 51 53 51 48 50 44 40 45 56 51 50 40 54 57 58 49 52 44 52 57 64 48 54 53 49 62 59 63 60 63 52 49 47 56 54 52 43 56 58 64 52 52 68 44 45 55 51 52 50 68 40 56 65 51 41 41 49 51 58 33 63 46 47 57 49 55 57 50 47 66 52 56 54 55 48 52 38 48 45 59 48 49 52 44 52 41 46 34 59 49 51 52 37 51 43 49 49 43 43 49 41 45 49 42 55 38 45 47 43 42 52 48 47 42 43 44 42 58 46 55 49 39 57 55 51 40 44 45 47 43 46 48 35 47 39 43 48 40 42 48 49 43 43 42 50 47 59 43 47 37 40 47 51 38 54 48 51 61 61 40 53 50 30 38 52 42 50 28 37 37 38 47 40 36 44 54 55 55 41 42 39 41 52 53 46 45 39 50 48 53 48 46 46 55 67 51 54 42 38 42 50 61 41 49 41 52 48 47 39 52 42 41 42 34 54 45 50 52 53 47 43 49 46 54 60 47 43 54 44 45 42 51 39 43 40 45 56 44 49 39 46 45 52 53 43 41 43 47 48 51 51 47 42 36 51 44 54 45 48 45 46 49 38 51 43 40 54 54 43 41 52 40 37 44 54 47 51 39 47 38 39 45 49 69 49 51 31 39 55 37 45 52 46 50 50 46 43 40 54 42 39 53 49 60 43 55 47 54 37 63 43 44 51 49 46 51 45 49 51 42 56 46 54 51 37 49 53 33 51 52 44 44 41 33 53 38 51 52 51 52 42 51 51 53 47 42 35 43 38 43 51 60 46 55 43 43 47 48 43 36 49 42 52 60 54 43 55 44 36 53 57 49 61 46 58 49 47 44 57 51 44 38 41 41 39 49 59 59 39 49 43 46 51 46 48 42 50 52 49 51 32 41 55 44 40 54 37 47 48 44 51 40 54 49 54 45 46 42 53 40 48 48 42 44 51 44 38 49 37 53 46 52 36 33 42 45 44 51 51 45 48 52 50 47 51 52 42 56 46 48 52 48 40 29 38 50 42 43 47 48 54 47 57 56 41 55 37 43 58 36 47 53 44 50 41 35 59 50 46 46 46 43 53 52 40 39 52 43 61 46 42 48 48 42 33 34 39 38 52 53 48 49 43 58 48 55 50 40 50 48 43 50 46 44 53 41 60 40 51 59 37 54 47 38 46 46 46 43 39 50 52 35 43 49 47 62 37 49 38 46 52 55 41 43 56 50 51 50 58 40 50 55 53 34 49 47 40 55 47 55 37 45 43 45 50 40 50 53 40 47 40 40 45 51 45 61 46 54 41 54 41 46 46 39 45 53 46 42 47 60 46 38 55 35 41 54 45 52 37 45 48 45 31 49 54 32 50 54 53 52 48 45 53 49 48 46 38 41 49 61 52 60 46 41 54 53 53 47 28 42 49 51 42 46 45 44 51 55 51 54 54 41 52 46 41 41 54 46 44 47 52 43 48 53 62 52 32 45 62 50 48 38 49 44 55 56 53 46 53 48 36 49 36 47 51 48 43 59 37 50 45 33 46 31 57 47 49 49 53 55 43 32 45 66 52 51 45 50 48 51 50 51 42 46 32 56 48 46 42 48 41 42 30 51 46 35 42 31 51 40 29 37 42 42 46 45 41 54 40 42 53 46 60 32 51 41 38 50 39 35 43 47 38 50 50 37 54 49 45 52 51 57 52 42 47 46 33 53 48 40 44 46 51 50 49 44 37 46 44 44 58 60 48 43 35 50 43 40 42 49 42 52 41 47 65 46 52 52 47 50 53 37 48 48 49 52 48 45 39 54 49 52 54 37 43 31 52 46 49 47 49 51 35 36 48 41 56 40 46 48 49 51 52 44 40 52 55 50 57 57 48 58 50 46 40 47 45 52 48 45 45 52 40 40 40 46 57 52 59 49 54 62 43 50 38 44 53 48 45 46 40 50 38 47 52 56 53 42 50 51 37 60 42 45 36 48 42 37 49 47 46 52 48 46 50 43 52 44 50 42 41 47 49 59 45 58 38 59 44 44 46 51 55 41 38 31 54 54 50 52 46 41 55 54 50 44 49 34 50 52 49 43 53 51 56 46 50 38 49 53 42 57 51 52 54 40 52 41 56 57 56 59 57 51 54 45 45 45 53 45 50 54 51 51 44 57 52 50 52 53 43 46 49 37 52 45 50 51 43 41 44 52 53 44 38 42 49 41 65 49 45 58 57 47 55 45 38 50 48 67 51 49 49 47 52 56 56 56 48 47 37 55 33 46 44 43 37 58 38 44 57 38 52 47 44 57 34 39 58 59 58 51 38 40 44 47 44 54 56 44 44 34 47 39 50 40 57 47 50 42 46 52 52 37 37 43 44 43 29 48 49 54 47 39 57 46 53 48 47 41 50 61 47 34 47 47 44 44 51 57 56 52 69 51 44 56 44 55 43 43 43 41 36 33 58 33 47 57 48 52 43 46 56 63 50 57 45 43 47 36 55 54 45 41 47 51 43 34 44 45 46 41 41 36 38 42 43 52 47 47 40 46 36 44 51 44 50 40 58 46 38 55 51 58 61 52 44 53 43 46 39 51 39 38 64 49 51 51 58 46 47 45 35 38 37 49 50 45 46 58 46 37 56 62 48 40 48 55 56 48 44 45 52 49 40 52 53 58 53 42 28 46 49 47 53 48 46 46 42 40 60 44 37 63 54 43 46 44 39 34 64 39 58 42 44 61 41 56 52 39 40 50 49 48 39 44 34 45 42 51 56 41 47 42 43 54 52 47 42 37 47 34 52 35 52 40 40 43 40 48 40 42 45 41 38 40 52 46 46 45 51 54 47 49 48 48 45 55 54 38 32 51 51 55 41 48 50 54 53 39 61 44 47 35 45 39 54 66 45 49 50 39 57 42 56 40 36 45 47 42 40 43 39 40 55 54 43 54 46 42 45 45 41 62 50 49 60 40 50 40 48 37 56 54 39 51 40 51 48 50 43 54 55 53 51 49 44 55 52 41 43 50 42 53 43 46 40 49 46 40 50 44 41 45 48 57 46 47 61 53 65 48 55 47 51 50 46 43 40 41 49 56 56 38 47 39 40 57 50 45 56 55 52 43 44 39 41 51 40 50 36 49 51 50 53 43 33 44 49 39 38 36 46 58 49 46 47 43 44 45 41 40 57 58 62 51 32 39 41 49 47 47 43 47 37 39 50 50 42 43 52 63 55 45 64 43 46 50 57 47 46 53 47 42 54 48 37 41 45 42 41 47 48 54 42 59 48 31 42 33 43 51 54 47 49 44 49 45 52 42 56 43 56 50 49 44 41 54 46 44 51 47 39 52 41 43 43 49 42 55 48 44 49 52 43 53 48 46 38 42 37 42 46 45 39 44 40 46 41 41 44 42 45 44 47 48 45 47 46 49 44 57 42 43 57 47 50 36 36 49 48 38 42 41 45 44 40 44 44 37 37 50 55 45 46 42 42 40 50 51 50 47 51 67 47 49 45 51 47 48 47 51 37 49 45 48 44 37 44 39 43 50 51 44 47 55 50 44 52 36 55 37 48 50 52 54 40 41 35 56 45 43 33 39 52 38 40 55 54 52 58 47 55 49 37 54 61 56 51 63 46 42 48 38 29 38 50 43 43 64 38 43 57 53 45 42 49 45 61 44 41 44 44 33 45 46 43 42 49 42 48 58 55 47 57 48 54 51 55 38 44 60 57 43 51 46 47 44 50 50 62 48 48 49 68 44 50 48 43 36 65 43 47 48 53 39 56 54 62 48 53 44 31 48 52 57 60 50 48 53 57 55 44 57 41 48 47 54 36 44 44 50 52 36 37 58 55 58 62 49 56 44 48 51 47 51 55 49 52 43 49 44 45 63 45 42 56 58 53 57 40 52 51 49 40 45 53 48 48 70 43 44 62 44 41 46 34 51 49 43 42 46 50 39 47 49 51 50 51 40 41 58 38 40 50 52 43 65 46 61 43 53 38 64 38 44 38 51 55 46 45 46 57 49 58 45 58 48 51 39 50 52 46 61 56 48 54 49 51 45 53 42 36 39 52 40 52 45 48 51 48 50 44 44 45 54 45 47 41 34 52 35 48 48 45 44 40 44 59 40 43 38 39 41 37 34 45 53 47 57 33 56 41 50 52 48 52 42 48 50 38 30 40 50 48 47 36 39 62 47 58 42 47 41 52 43 44 57 35 38 46 45 58 48 48 55 43 55 37 38 45 43 39 55 38 50 44 49 39 45 46 46 48 41 63 46 55 51 44 50 42 47 44 56 50 44 48 49 47 43 35 54 41 37 50 57 45 58 44 40 48 44 46 42 41 47 53 45 52 52 40 59 60 42 42 59 54 51 39 53 58 40 44 39 47 41 58 48 44 42 50 39 52 41 51 66 38 46 40 44 56 48 34 31 37 53 43 49 57 61 49 46 48 43 45 48 45 59 54 52 49 35 48 51 48 49 47 46 31 48 47 36 50 64 39 55 56 45 49 47 49 50 46 43 44 48 55 52 53 50 45 46 51 48 42 53 42 52 43 62 55 48 48 44 45 54 63 45 49 47 51 43 62 51 46 54 50 47 45 59 33 59 39 62 56 46 34 51 51 55 43 59 54 51 46 48 54 55 40 55 47 49 41 51 49 46 38 29 49 46 44 45 44 41 54 51 42 45 49 42 45 48 46 41 57 44 48 38 43 42 45 56 47 41 45 42 48 58 55 49 53 48 38 35 36 42 40 46 64 48 50 53 51 43 50 41 49 38 60 53 41 55 54 45 41 58 52 43 52 48 47 43 44 45 39 43 51 41 45 40 48 42 51 41 48 47 56 51 52 47 38 54 57 48 46 43 43 48 45 42 53 41 51 38 33 48 49 44 51 54 40 37 41 55 52 49 41 53 49 38 50 40 38 50 49 48 49 45 46 52 61 50 55 40 43 59 60 43 54 50 48 58 41 46 52 55 48 42 50 41 42 49 59 38 46 40 43 51 48 47 51 53 38 41 45 67 40 47 37 42 43 54 50 47 48 50 50 43 52 56 46 49 44 60 36 46 43 45 41 54 46 44 45 34 36 36 46 42 43 54 46 51 52 33 43 45 41 43 45 48 41 46 40 42 30 44 42 53 46 54 53 62 55 48 39 42 52 39 50 52 51 46 57 52 48 44 45 50 45 50 53 38 46 48 54 41 42 36 51 41 38 38 45 32 48 40 44 52 53 43 51 45 44 43 54 43 36 56 40 45 41 49 40 46 53 41 34 47 46 43 42 50 37 48 39 51 41 55 33 47 48 53 52 47 53 44 38 46 35 48 43 37 43 40 50 54 50 54 48 41 59 51 53 44 45 44 73 48 40 39 57 39 42 45 61 49 51 50 50 41 50 45 44 48 46 47 37 41 49 47 46 45 57 38 55 53 47 52 49 50 59 45 45 50 58 44 52 25 48 44 48 39 46 39 49 50 46 41 45 49 44 61 50 27 45 44 48 42 49 58 38 46 46 55 51 45 48 46 41 32 45 53 34 53 38 39 47 44 43 54 55 43 54 51 47 36 48 32 37 39 52 56 56 56 52 29 36 47 45 45 38 47 56 46 48 41 44 45 58 43 50 57 36 53 49 51 47 46 66 36 44 43 48 41 53 48 52 57 51 50 55 50 40 42 58 57 38 51 33 46 43 47 52 36 44 47 56 38 49 46 45 47 45 46 48 54 61 59 49 39 51 41 47 43 39 47 42 39 60 46 39 38 53 51 49 43 48 62 59 53 48 50 48 46 48 60 57 48 46 46 45 49 43 59 34 47 47 41 50 40 29 35 51 52 51 45 39 61 54 51 36 49 51 38 48 49 55 39 58 50 46 42 43 65 40 51 58 52 56 46 50 41 48 38 50 39 38 46 45 53 57 54 63 60 50 39 44 52 35 60 45 52 41 54 60 48 46 52 42 44 45 38 56 47 48 40 54 44 51 50 60 49 50 44 47 48 43 42 45 49 42 46 47 67 49 42 45 49 46 52 53 57 45 44 46 43 62 65 51 41 37 45 53 53 58 43 55 43 62 40 67 45 51 45 43 39 58 41 57 42 48 54 37 51 39 44 59 62 51 57 45 33 33 47 48 59 56 51 38 50 48 32 44 42 46 35 30 51 50 39 37 50 55 59 47 37 44 51 34 42 44 37 39 42 58 39 39 58 48 50 40 38 54 43 46 57 53 47 41 49 49 54 57 55 54 50 49 51 57 47 40 43 57 63 41 44 59 46 43 52 50 47 53 42 54 39 56 27 41 56 47 40 44 44 42 45 48 43 40 59 56 43 37 47 42 51 42 51 49 49 54 52 50 51 46 52 44 49 43 52 58 53 41 44 54 48 42 40 61 55 49 47 44 45 39 61 52 34 47 47 48 54 47 59 49 34 32 48 45 39 42 52 58 54 57 41 47 50 50 37 48 47 47 41 44 51 63 36 46 57 48 53 40 56 54 48 50 50 43 58 49 47 43 47 48 59 43 45 56 47 53 37 43 47 41 56 55 45 53 49 49 44 40 46 46 44 60 51 56 44 61 54 39 55 48 53 52 46 41 34 51 48 51 57 46 60 43 58 57 43 52 48 56 39 45 40 48 50 35 52 57 60 52 48 41 44 42 53 51 41 39 43 41 45 67 50 48 42 54 51 57 42 40 53 40 61 34 50 44 50 44 63 42 46 48 55 64 56 51 48 54 50 37 52 43 58 29 59 23 38 57 56 49 42 45 40 36 49 38 41 44 58 52 36 50 46 58 48 48 48 58 51 52 44 41 49 50 54 33 51 59 46 40 44 45 52 34 48 51 49 40 49 50 56 52 51 49 47 41 56 39 44 55 44 46 44 39 39 44 49 43 36 49 54 46 44 49 40 46 50 50 45 52 37 51 36 45 63 51 35 44 52 53 56 43 59 49 48 38 45 42 49 36 47 59 40 35 42 42 46 46 43 41 34 47 55 47 44 39 42 54 51 49 41 50 43 49 47 47 49 65 46 43 42 47 48 41 58 42 54 41 47 45 48 42 41 44 46 54 47 50 39 45 39 53 39 45 35 56 51 54 46 46 44 49 45 49 46 39 35 41 42 37 45 35 36 51 46 50 54 50 49 65 54 46 61 55 39 45 49 43 51 61 41 49 62 39 45 43 47 42 46 55 53 34 39 47 44 42 47 43 47 41 48 57 54 39 37 44 52 50 41 51 46 47 48 49 42 44 43 46 41 43 48 52 49 51 47 45 45 40 46 45 55 47 57 56 45 55 45 49 56 48 45 46 42 38 42 50 54 43 43 43 39 53 45 51 58 47 36 56 52 57 46 53 44 53 51 48 41 53 45 51 49 42 45 43 48 50 34 48 52 36 41 62 48 48 42 38 38 49 40 58 46 44 48 36 49 43 41 36 38 43 41 46 68 47 47 48 41 43 49 51 54 41 52 31 49 58 48 36 47 49 43 49 48 43 42 55 39 46 67 45 40 42 44 46 40 45 36 42 46 42 60 44 58 43 40 55 45 53 42 55 40 51 56 52 56 52 43 42 54 63 42 54 50 42 30 46 51 55 54 41 54 45 57 46 34 43 40 54 52 44 35 43 50 53 44 41 49 59 66 48 47 50 61 56 68 64 53 46 52 40 54 45 52 58 31 49 38 32 44 42 42 64 48 47 44 54 40 56 48 49 52 46 44 46 52 52 39 41 58 46 55 41 45 46 53 49 52 40 61 45 42 53 50 49 48 43 42 51 49 45 46 49 56 54 43 50 43 56 50 44 55 39 49 45 44 44 40 39 46 47 48 46 60 39 43 35 38 40 43 70 49 61 40 37 53 41 40 63 44 43 52 37 45 56 66 37 56 38 47 51 48 42 39 57 52 38 49 47 44 48 66 50 35 30 44 46 58 43 56 47 44 46 33 43 54 51 54 48 46 38 51 34 44 43 50 52 49 53 50 50 43 46 65 50 58 47 62 52 46 47 50 46 52 51 48 47 52 46 48 60 61 54 43 53 56 50 34 48 57 43 44 42 52 53 43 41 49 51 54 44 47 58 47 55 51 61 41 55 34 53 48 53 47 52 59 32 39 37 43 51 53 52 48 46 50 47 46 54 49 44 52 55 56 41 50 44 44 48 62 49 40 44 56 54 41 51 53 46 43 51 48 53 40 45 57 49 43 49 54 54 50 38 49 45 53 52 44 43 41 66 44 48 61 60 47 53 52 47 45 49 40 31 56 46 47 45 54 48 35 48 50 50 47 36 58 31 59 51 54 43 57 51 60 50 49 51 56 49 33 41 56 55 42 50 42 40 58 43 52 46 46 52 43 40 41 52 46 60 42 47 52 50 45 34 52 38 58 42 53 53 39 46 59 43 56 45 45 58 46 63 52 45 44 40 49 50 51 37 60 37 36 51 45 36 49 38 45 40 36 50 45 43 39 42 41 36 43 47 61 52 46 45 53 40 48 52 41 41 49 53 40 43 42 57 56 37 50 54 44 46 48 45 50 43 50 47 47 58 57 43 56 46 31 47 48 60 54 43 50 42 47 46 49 50 61 52 49 45 50 52 39 51 52 51 53 45 46 45 42 45 45 48 44 47 40 51 54 47 45 45 44 43 43 56 59 55 49 51 45 55 60 38 51 52 41 49 57 38 51 47 50 48 43 48 41 54 60 54 58 48 53 60 44 54 50 41 45 44 47 49 35 48 50 51 55 38 43 46 57 49 46 44 31 44 46 39 45 33 46 49 40 60 45 50 46 63 58 42 42 42 36 54 42 58 48 43 42 58 50 52 64 45 57 38 33 45 60 51 49 40 55 48 50 51 45 56 40 51 57 49 44 48 56 67 59 24 46 53 45 53 47 49 56 50 44 41 58 49 57 42 50 57 49 41 53 54 46 59 57 52 53 47 46 55 49 59 41 50 49 55 46 56 47 52 50 56 49 52 46 54 43 48 44 50 56 32 39 56 34 52 50 64 53 53 55 47 55 59 56 52 44 62 42 58 43 46 59 51 48 52 45 50 48 55 40 47 44 46 39 46 53 41 45 43 44 41 47 42 51 58 51 43 40 55 55 53 42 53 48 42 50 47 38 33 52 41 46 47 43 54 46 48 44 59 52 52 62 42 41 55 62 57 47 36 47 49 35 51 60 43 30 54 50 58 48 62 42 54 43 48 46 44 52 44 56 45 37 62 56 47 48 53 51 53 45 57 61 36 32 47 45 56 52 54 57 43 45 47 59 53 54 56 56 49 57 37 48 47 45 51 44 38 43 40 33 40 62 53 42 49 61 55 48 40 45 42 46 52 44 40 41 47 49 45 54 50 44 48 42 56 45 47 58 45 60 56 45 49 43 44 37 58 44 48 46 50 47 40 42 52 54 50 52 31 54 50 58 33 49 49 48 45 46 42 49 51 56 42 52 38 62 50 60 53 50 59 42 56 48 49 53 39 51 43 50 54 50 48 49 56 40 54 44 44 58 51 46 45 43 44 49 56 54 53 51 40 53 45 44 36 50 45 52 54 36 49 41 38 38 40 45 41 46 51 45 47 47 44 52 44 46 65 60 48 45 48 47 55 57 44 54 40 40 60 41 52 52 50 56 48 53 38 60 36 55 47 47 46 43 54 52 34 51 43 48 43 45 47 51 47 48 59 57 43 55 41 42 44 47 48 50 49 49 47 53 60 47 53 44 59 56 53 50 58 42 50 60 48 53 51 59 48 59 41 48 55 53 57 44 43 44 66 33 43 61 45 48 41 50 54 44 44 70 52 55 46 40 49 52 51 39 42 54 37 42 40 57 46 48 57 44 56 46 40 37 49 41 52 41 52 57 50 41 55 50 61 47 58 52 46 56 48 43 49 55 44 39 47 55 44 47 41 55 41 46 47 48 59 35 40 46 42 53 54 61 51 41 54 56 48 52 54 47 52 52 47 44 42 51 45 50 49 51 40 43 32 44 49 46 57 63 46 45 49 47 46 51 46 45 52 45 49 39 54 43 64 48 40 48 55 47 51 53 49 51 57 50 50 44 54 48 54 65 46 47 34 61 64 56 47 58 32 38 47 52 41 62 64 55 47 50 48 64 41 36 44 39 58 50 48 50 34 46 44 40 49 49 34 42 55 53 34 44 44 52 44 38 41 37 56 43 43 48 48 53 67 55 51 38 56 51 35 50 58 56 54 32 43 52 45 38 59 58 50 50 43 34 50 46 49 58 56 54 40 39 58 55 44 43 37 44 51 60 38 40 57 39 37 45 55 49 48 42 51 37 51 35 50 51 47 48 40 45 46 48 34 36 46 62 48 39 49 47 44 63 58 57 41 47 44 40 42 38 52 61 52 64 59 50 48 37 38 52 49 49 53 39 40 50 49 46 60 50 49 46 57 42 68 38 49 45 39 56 41 36 52 52 57 53 48 50 49 57 55 52 46 38 57 47 40 41 47 39 42 46 37 53 51 38 53 49 50 38 30 54 55 52 40 42 40 49 45 64 59 45 43 57 56 37 43 48 53 58 44 46 44 48 35 53 44 56 57 51 43 47 40 53 44 42 48 46 36 43 48 43 57 50 47 59 51 41 41 57 42 48 55 49 63 44 58 46 57 35 44 59 45 41 46 46 36 40 56 53 43 36 51 54 42 51 51 41 29 43 50 55 61 51 57 39 35 60 45 49 50 41 57 41 54 37 42 58 48 39 54 49 46 52 44 39 51 44 45 41 59 54 49 53 59 48 55 54 36 43 51 65 52 56 47 40 50 40 50 50 52 67 40 49 49 40 41 42 39 52 52 40 63 56 47 45 58 42 54 54 46 50 44 52 35 50 46 55 48 40 41 39 54 51 49 47 59 41 55 40 50 53 50 53 48 55 54 52 44 52 48 55 48 56 53 43 39 46 40 33 44 48 48 53 43 53 45 40 37 35 47 46 42 54 70 49 40 41 57 35 61 48 39 53 48 50 52 43 42 37 54 45 53 38 54 60 45 59 59 32 44 56 54 44 44 51 56 51 54 48 55 52 43 45 56 53 51 46 49 54 56 45 45</counts>
			</dataPoints>
		</scan>
	</xrdMeasurement>
</xrdMeasurements>