File: data/XRD/XG-Vakuum/XG-875/W6824-1C_XG_Vakuum_875.xrdml
<xrdMeasurements xmlns="http://www.xrdml.com/XRDMeasurement/2.1" xmlns:xsi="http://www.w3.org/2001/XMLSchema-instance" xsi:schemaLocation="http://www.xrdml.com/XRDMeasurement/2.1 http://www.xrdml.com/XRDMeasurement/2.1/XRDMeasurement.xsd" status="Completed">
	<comment>
		<entry>Configuration=Factory configuration, Owner=User-1, Creation date=7/8/2013 4:01:53 PM</entry>
		<entry>Goniometer=PW3050/65 (Theta/2Theta); Minimum step size 2Theta:0.0001; Minimum step size Omega:0.0001</entry>
		<entry>Sample stage=MRD Cradle; Minimum step size Phi:0.01; Minimum step size Chi:0.01; Minimum step size X:0.01; Minimum step size Y:0.01; Minimum step size Z:0.001</entry>
		<entry>Diffractometer system=XPERT-PRO</entry>
		<entry>Measurement program=C:\PANalytical\Data Collector\Programs\Jorrit\2thom\_absolute_2th-om_10-130deg_PIXscan_56min.xrdmp, Identifier={15BCCF57-2807-42BD-B5B9-ECC0B3DC9284}</entry>
		<entry>Batch program=C:\PANalytical\Data Collector\Programs\SimonL\batch7x_2thom_10-130°_z9.1_x0,10,20,30_y10,20,30_57min.xrdmp, Identifier={089D96B1-A01D-49FF-BCB5-EEA9DFC9CC78}</entry>
	</comment>
	<sample type="To be analyzed">
		<id></id>
		<name></name>
		<preparedBy></preparedBy>
	</sample>
	<xrdMeasurement measurementType="Scan" status="Completed" sampleMode="Reflection">
		<comment>
			<entry>_absolute_2th-om_10-130deg_PIXscan_56min</entry>
			<entry>PHD Lower Level = 4.83 (keV), PHD Upper Level = 11.27 (keV)</entry>
		</comment>
		<usedWavelength intended="K-Alpha 1">
			<kAlpha1 unit="Angstrom">1.5405980</kAlpha1>
			<kAlpha2 unit="Angstrom">1.5444260</kAlpha2>
			<kBeta unit="Angstrom">1.3922500</kBeta>
			<ratioKAlpha2KAlpha1>0.5000</ratioKAlpha2KAlpha1>
		</usedWavelength>
		<incidentBeamPath>
			<radius unit="mm">320.00</radius>
			<xRayTube id="1010048" name="Empyrean Cu LFF HR (9430 033 7310x) DK442154">
				<tension unit="kV">40.0</tension>
				<current unit="mA">40.0</current>
				<anodeMaterial>Cu</anodeMaterial>
				<focus type="Line">
					<length unit="mm">12.0</length>
					<width unit="mm">0.4</width>
					<takeOffAngle unit="deg">4.2</takeOffAngle>
				</focus>
			</xRayTube>
			<xRayMirror id="27010001" name="Inc. Beam Cu W/Si (parabolic MRD)" hybrid="false">
				<crystal type="Graded" shape="Parabolic">W/Si</crystal>
				<acceptanceAngle unit="deg">0.800</acceptanceAngle>
				<length unit="mm">60.0</length>
			</xRayMirror>
			<sollerSlit id="21010002" name="Soller slits 0.04 rad.">
				<opening unit="rad">0.0400</opening>
			</sollerSlit>
			<mask id="22030008" name="Fixed mask 4 mm">
				<distanceToSample unit="mm">220.00</distanceToSample>
				<width unit="mm">4.00</width>
			</mask>
			<divergenceSlit id="22010011" name="Fixed slit 1/32°" xsi:type="fixedDivergenceSlitType">
				<distanceToSample unit="mm">220.00</distanceToSample>
				<height unit="mm">0.05</height>
			</divergenceSlit>
		</incidentBeamPath>
		<diffractedBeamPath>
			<radius unit="mm">320.00</radius>
			<sollerSlit id="21010002" name="Soller slits 0.04 rad.">
				<opening unit="rad">0.0400</opening>
			</sollerSlit>
			<receivingSlit id="22010001" name="Fixed slit 4°">
				<height unit="mm">5.88</height>
			</receivingSlit>
			<detector id="7010017" name="PIXcel3D 1x1 detector" xsi:type="areaDetectorType">
				<phd unit="%">
					<lowerLevel>30.0</lowerLevel>
					<upperLevel>70.0</upperLevel>
				</phd>
				<mode>Scanning</mode>
				<activeChannelsEquatorial>255</activeChannelsEquatorial>
				<activeChannelsAxial>255</activeChannelsAxial>
				<pitchEquatorial unit="mm">0.05500</pitchEquatorial>
				<pitchAxial unit="mm">0.05500</pitchAxial>
				<readOutPeriod unit="seconds">0.135</readOutPeriod>
			</detector>
		</diffractedBeamPath>
		<scan appendNumber="0" mode="Continuous" scanAxis="2Theta-Omega" status="Completed">
			<header>
				<startTimeStamp>2024-10-22T02:07:53+02:00</startTimeStamp>
				<endTimeStamp>2024-10-22T03:03:58+02:00</endTimeStamp>
				<author>
					<name>PRO-MRD</name>
				</author>
				<source>
					<applicationSoftware version="6.1b">Data Collector</applicationSoftware>
					<instrumentControlSoftware version="7.0E 20130304">XPERT-PRO</instrumentControlSoftware>
					<instrumentID>0000000011142674</instrumentID>
				</source>
			</header>
			<dataPoints>
				<positions axis="2Theta" unit="deg">
					<startPosition>9.99826193</startPosition>
					<endPosition>129.99755682</endPosition>
				</positions>
				<positions axis="Omega" unit="deg">
					<startPosition>4.99913096</startPosition>
					<endPosition>64.99877841</endPosition>
				</positions>
				<positions axis="Phi" unit="deg">
					<commonPosition>0.00</commonPosition>
				</positions>
				<positions axis="Chi" unit="deg">
					<commonPosition>0.00</commonPosition>
				</positions>
				<positions axis="X" unit="mm">
					<commonPosition>0.00</commonPosition>
				</positions>
				<positions axis="Y" unit="mm">
					<commonPosition>-30.00</commonPosition>
				</positions>
				<positions axis="Z" unit="mm">
					<commonPosition>9.100</commonPosition>
				</positions>
				<commonCountingTime unit="seconds">32.895</commonCountingTime>
				<counts 83 85 76 84 83 70 72 85 68 72 94 86 68 88 66 91 77 78 88 75 79 80 56 84 81 72 84 82 83 88 88 79 70 77 79 71 80 91 72 91 88 93 93 91 72 84 74 68 71 82 73 80 92 77 92 69 67 87 66 74 91 67 70 83 88 66 92 75 88 75 69 69 73 83 70 84 98 64 66 86 91 88 73 69 63 86 81 77 70 80 86 101 69 70 90 88 68 69 84 84 82 67 80 82 88 84 75 76 79 75 87 89 78 87 76 60 72 74 93 53 71 74 74 82 78 88 70 88 82 90 80 80 78 75 61 73 66 73 73 64 80 80 89 67 71 72 80 72 86 76 86 76 90 68 72 66 77 79 68 90 91 75 78 79 84 80 78 93 74 78 86 85 78 76 64 84 91 80 79 76 62 76 71 81 72 79 82 79 67 59 87 72 73 83 92 84 73 78 68 90 73 95 68 78 78 87 76 68 72 78 82 77 79 65 76 87 80 61 74 74 67 84 81 76 69 60 81 69 71 84 94 68 78 69 73 74 83 79 80 83 65 90 67 83 76 80 90 78 62 60 70 85 88 73 71 84 84 92 54 77 71 74 66 74 80 76 87 94 86 68 78 77 75 82 77 92 66 66 89 74 81 68 70 69 83 77 75 73 77 75 91 64 59 71 79 72 74 94 71 91 79 68 67 84 86 74 80 68 74 78 74 72 66 76 68 77 78 75 67 89 71 73 77 66 67 61 58 79 73 102 77 58 68 77 80 65 77 69 81 81 84 76 84 68 87 100 89 85 81 59 64 64 63 81 59 70 62 73 76 87 88 74 62 75 82 76 81 79 76 68 83 76 78 65 85 68 90 71 82 70 77 61 76 78 60 68 58 66 63 75 75 52 80 91 68 84 63 84 71 65 81 72 86 71 70 92 76 80 73 64 72 66 61 82 67 70 71 72 74 87 77 84 81 69 87 58 74 68 77 75 63 84 66 67 67 60 65 71 74 62 82 60 71 87 76 64 79 69 67 66 70 72 78 71 82 66 76 73 79 69 68 83 69 67 73 72 58 82 86 71 72 69 61 70 64 67 72 69 80 86 71 77 80 66 71 78 65 71 81 77 66 88 70 65 72 77 64 76 74 88 72 60 72 85 72 76 82 64 65 63 65 80 64 69 70 67 77 80 68 80 72 79 81 67 60 71 58 62 80 70 60 77 74 61 70 79 79 69 80 65 71 79 60 80 76 67 60 61 63 59 73 63 66 62 66 63 56 70 57 71 57 65 72 68 75 76 52 83 75 70 58 70 75 66 83 69 81 70 73 68 71 59 74 71 61 68 64 66 69 71 80 64 56 78 66 64 70 64 68 62 64 60 71 75 70 68 61 54 75 69 82 75 63 67 68 61 77 58 79 81 81 71 53 90 72 79 57 77 80 69 79 69 72 55 68 76 68 83 64 68 62 55 62 75 55 60 85 69 60 68 70 76 68 74 72 77 78 71 57 73 79 65 69 61 66 65 60 77 64 76 74 77 71 70 68 78 73 59 63 69 53 78 79 71 80 63 66 70 60 58 59 72 64 76 75 77 63 72 57 86 67 59 57 87 59 61 81 74 62 80 73 55 75 70 62 75 70 66 50 76 83 86 71 82 67 61 75 61 73 61 76 67 70 69 76 68 63 62 79 73 59 61 79 69 68 76 67 61 72 53 59 73 64 74 73 77 74 77 76 71 90 72 85 74 71 67 61 69 53 67 76 70 70 70 69 65 61 66 60 81 67 64 63 69 68 56 79 73 68 84 78 61 84 78 84 70 75 67 61 85 72 73 57 90 59 60 51 63 77 66 71 71 71 76 54 66 61 76 91 73 81 62 74 71 74 84 53 73 67 84 63 58 81 72 74 64 74 74 75 62 53 85 53 66 74 69 71 68 75 66 67 65 80 65 78 70 76 74 66 77 73 86 63 70 57 69 51 77 60 77 47 81 73 83 72 59 88 79 61 80 57 68 65 72 60 63 69 55 80 69 60 73 68 65 67 86 64 63 65 69 60 78 61 74 73 60 70 64 66 71 84 75 66 62 56 49 62 80 48 68 87 74 86 72 74 65 76 80 85 76 78 68 71 72 60 66 86 83 64 65 69 62 64 73 93 57 96 100 58 55 59 79 73 74 71 71 62 92 73 69 58 58 76 76 76 86 59 56 73 74 59 60 71 82 72 71 69 78 82 75 62 58 74 66 56 48 76 63 64 69 67 73 77 75 75 72 58 80 65 69 80 63 70 71 68 63 59 70 73 79 76 58 79 82 80 74 72 69 79 68 68 70 69 62 87 63 66 87 80 69 86 79 74 64 81 69 73 83 51 82 74 65 71 62 78 71 61 81 72 78 70 75 79 68 59 57 75 57 60 74 72 71 64 58 71 61 76 71 68 66 57 83 66 86 61 76 67 73 68 75 75 78 68 70 78 70 79 71 61 81 76 64 63 74 72 68 81 66 64 68 68 68 66 94 68 77 78 69 75 64 64 62 69 65 62 75 66 71 81 57 60 67 69 61 56 78 75 74 65 71 73 74 87 67 77 58 70 69 70 59 66 90 71 85 79 75 73 51 67 60 79 71 63 64 68 69 69 74 66 66 56 66 71 68 81 69 70 69 74 76 65 94 72 76 74 56 67 67 62 77 74 61 72 66 64 79 61 72 79 58 60 77 76 73 79 81 78 67 79 61 53 57 67 82 92 73 81 76 78 72 65 71 82 68 67 72 82 76 89 80 74 71 67 69 70 86 70 84 72 75 75 69 70 75 70 83 91 78 78 72 60 70 75 52 62 64 63 76 52 80 73 62 71 76 67 64 82 82 60 53 65 67 65 61 56 77 68 78 61 73 83 73 68 66 70 70 87 60 73 81 77 63 56 73 87 71 68 68 61 65 70 68 65 50 65 63 60 70 67 78 68 65 80 93 68 71 75 73 57 65 76 54 71 81 58 69 64 78 65 75 67 66 72 85 72 72 70 70 82 74 85 70 74 64 68 67 67 74 73 63 59 56 72 70 70 55 67 69 61 60 65 82 62 71 67 69 65 74 71 72 63 89 79 59 83 76 71 58 73 61 62 60 53 61 68 73 75 82 69 69 57 81 67 61 64 67 68 76 74 84 68 65 66 61 69 69 67 60 64 58 63 90 74 65 66 88 65 73 71 72 76 55 84 70 67 89 53 70 66 64 74 59 77 75 74 62 70 62 64 61 74 75 64 62 61 62 55 64 68 83 84 59 74 53 67 74 79 66 67 74 77 74 77 58 51 78 73 70 71 73 72 75 80 58 76 63 64 88 64 78 60 69 87 61 69 68 54 80 86 62 49 71 53 80 68 76 62 66 64 65 66 70 66 62 60 82 64 63 50 74 75 80 67 86 52 75 65 69 67 66 62 69 62 88 75 84 72 56 71 70 68 60 68 75 84 76 66 86 70 69 68 69 70 68 62 82 82 72 77 80 69 61 64 60 67 76 63 62 64 67 73 63 73 75 72 55 60 82 63 56 65 66 64 76 75 71 70 70 57 63 66 53 59 66 73 71 65 65 65 70 75 86 74 63 70 67 67 62 70 73 65 59 67 61 53 75 62 72 59 83 68 74 57 61 65 77 67 73 65 55 52 81 63 61 58 79 68 64 66 70 68 75 60 53 71 62 66 72 56 62 66 61 61 55 55 64 72 64 56 68 59 63 66 64 59 52 53 63 56 66 74 71 57 72 66 64 65 69 61 66 52 64 69 66 70 60 68 73 65 67 65 61 60 54 60 70 60 52 64 60 60 60 70 60 46 63 56 57 70 63 52 60 65 83 53 75 57 71 81 65 57 63 82 59 60 54 58 59 68 53 50 49 60 66 58 83 61 67 61 71 55 65 61 64 46 50 75 72 57 65 56 63 65 54 76 49 65 71 75 73 65 58 52 57 64 55 62 55 52 63 68 66 77 56 50 59 58 68 58 68 51 69 53 60 63 68 70 45 63 64 49 60 58 71 52 63 68 63 55 45 65 64 67 70 75 67 62 75 69 45 60 61 39 55 64 83 57 60 60 55 73 65 50 64 52 51 52 59 60 56 59 70 71 76 61 58 73 81 71 72 52 67 55 64 65 56 58 69 57 61 67 55 61 62 57 69 73 68 64 61 62 81 61 61 67 72 59 62 72 45 69 59 77 61 71 54 61 59 73 71 60 55 64 60 67 73 63 67 60 71 54 52 64 68 63 66 75 47 49 58 62 70 52 69 57 56 65 51 59 81 66 71 53 61 46 60 70 77 61 62 68 57 68 58 46 61 65 75 68 74 62 65 62 62 60 51 61 59 75 64 65 64 65 54 60 51 62 70 59 80 50 56 49 74 70 48 75 44 65 66 60 58 62 73 56 77 62 53 68 70 50 66 70 57 56 75 71 73 64 51 45 76 59 56 63 54 52 46 86 69 58 58 58 59 48 67 72 73 67 63 65 80 77 59 50 60 51 49 70 57 74 57 68 58 59 64 59 60 61 64 62 61 73 72 60 56 68 68 71 52 56 63 66 53 64 52 73 53 65 70 52 64 57 52 53 58 47 63 64 62 41 68 49 49 60 50 66 68 78 64 41 59 63 68 67 55 50 60 79 58 61 63 63 64 70 49 52 63 47 60 51 59 61 49 50 55 60 48 51 51 57 78 69 52 50 46 74 59 64 56 65 61 62 54 65 57 70 72 63 58 54 59 80 47 53 54 51 61 47 60 50 54 68 67 61 55 67 73 58 43 60 70 60 50 58 52 58 44 45 60 66 58 65 53 59 58 55 56 58 55 43 56 68 53 60 47 57 58 68 61 61 51 60 60 69 65 68 58 52 64 52 52 56 57 56 52 61 54 62 64 50 73 68 47 61 62 74 53 64 59 69 50 64 57 49 57 58 73 55 56 59 64 60 52 50 65 54 64 51 59 74 56 60 48 51 69 67 65 65 66 68 64 70 64 56 76 68 62 68 60 60 62 55 47 46 53 69 57 45 54 70 62 71 71 49 59 41 47 67 66 54 52 61 52 58 45 56 52 54 50 61 63 49 48 58 52 49 75 59 62 60 57 53 59 63 51 57 64 65 61 62 46 45 51 60 57 49 61 64 60 49 57 66 60 66 62 58 65 47 50 63 65 60 64 66 58 56 62 61 52 55 65 65 50 45 54 55 62 70 60 59 58 45 57 50 49 55 53 49 64 46 64 56 61 74 52 61 47 57 47 63 61 65 53 63 61 60 68 59 44 63 57 56 52 52 52 51 63 57 58 58 52 62 47 58 53 68 50 60 65 66 73 59 50 71 56 63 56 57 62 81 63 70 45 55 65 52 60 64 57 57 65 50 60 55 68 69 56 48 54 52 68 44 61 68 54 50 51 51 58 56 42 66 56 65 59 55 58 58 49 51 60 54 59 46 60 64 57 48 67 49 48 53 53 47 40 64 59 45 71 56 48 63 50 51 42 62 57 65 59 53 57 46 48 58 57 56 59 62 63 43 59 51 48 66 43 49 67 67 61 58 62 66 71 61 62 59 68 60 49 71 60 63 58 63 54 63 61 54 56 48 50 45 48 61 57 65 67 56 57 65 59 39 61 65 52 56 51 50 56 64 51 56 59 56 50 62 60 51 48 61 46 54 54 66 51 63 61 56 60 59 51 47 62 62 58 61 50 47 61 47 54 63 53 51 53 62 55 45 55 67 46 63 50 53 54 48 46 57 60 50 56 60 56 61 69 55 50 36 62 60 48 56 60 55 72 55 43 58 54 59 54 43 59 44 48 64 59 49 57 65 55 61 51 56 56 51 56 59 62 58 60 58 53 43 52 62 59 55 56 58 59 55 54 61 61 54 66 58 48 55 55 55 53 44 65 46 59 48 51 52 78 49 64 59 55 56 59 54 58 51 41 60 61 58 57 68 67 59 56 56 57 69 46 60 57 53 53 56 50 53 53 56 47 56 56 58 47 51 51 52 50 61 55 67 44 69 51 51 58 70 47 65 51 47 51 56 61 64 72 48 54 57 71 53 56 73 48 60 46 52 48 48 58 60 51 55 57 56 44 58 49 57 60 59 53 51 59 43 60 68 50 49 53 63 51 60 63 74 62 61 65 47 53 38 63 61 61 48 56 52 62 62 57 54 58 55 46 56 42 52 57 50 46 51 63 73 58 57 47 46 57 60 50 54 61 68 46 45 56 55 38 54 42 61 62 59 52 56 50 44 66 69 48 58 59 47 56 60 52 49 49 50 54 55 54 58 49 61 56 53 43 53 60 57 50 60 60 68 66 63 61 48 54 54 64 40 51 48 68 62 64 44 45 63 50 57 50 62 61 57 53 44 51 54 53 61 60 64 60 51 65 56 50 56 50 58 53 49 56 50 60 40 60 58 61 63 57 55 62 45 42 49 47 63 68 53 52 53 35 59 50 54 41 60 48 49 52 51 66 55 61 56 68 49 63 54 55 54 64 55 61 45 57 56 48 61 56 40 58 60 48 56 53 49 57 53 58 49 65 55 66 50 70 63 49 54 50 44 45 49 50 55 51 48 48 62 72 47 50 58 53 51 55 55 71 47 50 51 49 58 52 47 60 55 44 41 54 47 48 48 63 55 52 52 43 57 53 43 62 54 66 53 64 44 51 46 65 51 41 65 45 61 53 45 60 59 36 51 53 59 62 68 46 60 55 54 48 42 62 46 61 54 55 55 49 54 62 58 46 66 50 48 50 50 42 59 50 52 43 53 49 52 48 45 55 51 48 54 43 55 47 53 62 39 60 50 57 47 55 38 56 44 60 56 53 55 53 51 52 51 52 43 47 53 59 55 70 68 74 55 67 56 65 63 51 58 47 50 58 57 62 50 56 56 43 35 61 55 52 47 51 52 51 39 61 49 50 49 60 47 50 55 52 49 56 55 47 48 57 46 60 62 52 68 54 47 45 69 53 65 50 57 48 38 63 50 47 59 54 56 51 59 46 64 45 53 61 54 61 70 57 61 45 51 45 51 48 63 45 43 39 60 63 43 62 62 45 66 49 54 45 46 39 50 49 42 53 52 55 57 54 43 36 47 70 62 51 59 49 39 55 51 48 39 47 55 47 50 68 63 57 58 56 53 49 55 47 53 49 54 50 48 52 65 58 59 55 56 40 65 61 48 50 68 59 54 40 67 46 62 50 61 43 49 46 48 55 61 64 51 63 52 65 42 53 41 62 57 53 45 40 56 51 46 59 35 63 58 54 44 50 51 56 61 55 47 60 39 56 60 54 49 49 56 47 45 58 57 46 58 34 47 58 68 51 52 47 55 53 54 50 63 60 51 57 45 57 41 57 45 58 56 42 48 65 50 48 49 57 66 56 58 57 39 56 43 53 58 57 61 54 52 67 65 58 51 58 49 53 49 50 71 52 62 52 52 54 53 73 45 57 53 42 51 49 49 42 54 59 53 47 52 53 49 67 46 54 56 48 56 45 51 64 51 44 47 46 36 59 56 47 52 53 50 61 45 52 58 46 58 54 49 52 55 45 59 59 58 54 53 45 47 50 70 54 48 49 54 45 67 45 52 58 52 62 58 57 56 46 48 63 47 44 58 67 48 61 50 57 51 65 57 62 46 53 60 52 49 44 56 45 70 56 67 50 56 47 53 57 56 45 56 64 62 52 49 57 63 54 70 68 52 35 59 43 51 50 46 65 53 49 63 57 49 66 58 38 57 64 69 65 71 57 67 65 59 68 51 67 62 74 72 70 52 70 62 76 55 58 59 51 54 64 62 65 58 75 61 68 65 74 72 66 63 65 73 72 71 82 83 81 79 70 81 96 82 87 107 90 85 82 95 83 96 119 121 120 111 104 98 107 113 113 101 122 124 111 121 111 102 108 111 113 96 90 113 88 98 80 79 88 101 80 89 81 99 75 73 69 72 63 55 72 59 75 59 64 64 59 84 71 60 56 62 47 59 46 57 65 66 50 75 63 54 58 76 49 57 62 58 51 50 51 58 46 52 62 57 68 58 53 52 53 53 62 64 69 58 58 52 56 58 56 45 57 59 53 65 61 47 54 54 53 62 61 50 62 55 64 65 64 71 61 60 46 50 49 51 37 57 50 54 65 50 64 50 58 73 44 58 45 51 55 58 56 62 53 55 60 51 64 62 58 58 56 48 60 50 58 53 66 56 54 52 61 53 54 70 56 53 60 52 55 57 54 63 53 55 62 53 65 58 42 50 53 47 48 55 68 59 48 63 45 51 59 51 63 61 45 51 44 49 50 58 46 58 58 40 67 47 51 59 57 57 43 66 57 71 58 52 60 44 60 51 60 44 44 55 57 53 40 53 56 47 62 52 59 64 62 46 64 50 55 57 53 59 47 53 48 55 56 41 59 57 37 63 48 51 58 54 68 51 38 56 65 66 52 57 52 46 48 47 59 57 48 53 72 61 54 52 69 44 57 55 55 49 53 44 37 52 53 59 49 54 43 52 48 67 51 60 47 56 48 68 51 50 57 64 53 50 58 43 41 48 43 67 50 46 48 46 51 47 55 48 53 51 56 52 62 62 49 54 62 53 49 50 65 56 49 57 46 51 48 45 41 56 59 53 54 61 46 54 53 54 60 49 49 64 64 57 49 65 56 55 47 59 56 55 56 56 37 45 64 53 44 44 54 41 47 56 48 49 39 53 62 60 39 59 41 55 50 42 57 68 61 53 55 49 48 56 46 65 54 57 56 54 56 56 49 38 53 53 56 59 53 60 69 51 51 57 46 55 63 51 67 42 57 49 58 59 54 60 51 43 55 54 53 45 44 57 51 58 38 66 66 36 56 54 56 42 53 45 50 49 59 53 51 57 48 60 47 54 52 58 53 52 54 41 70 43 60 58 54 45 62 51 57 43 57 63 53 60 62 54 63 54 48 70 59 55 57 60 42 44 51 56 58 54 48 56 52 47 59 51 52 48 58 55 53 53 52 51 51 47 64 39 62 44 53 43 52 65 51 49 75 49 48 45 58 53 50 53 47 52 58 58 57 54 57 55 54 65 48 50 63 43 56 54 50 51 53 49 50 56 46 44 47 43 48 56 47 71 37 51 57 53 47 40 42 63 43 59 48 58 46 45 56 48 57 53 63 49 54 44 50 56 54 71 50 60 68 48 46 51 48 63 59 61 62 64 48 55 37 43 40 50 69 53 49 50 53 53 47 53 53 50 51 49 39 37 50 47 59 57 59 60 56 65 46 51 42 55 46 70 60 58 39 47 41 56 54 52 70 51 48 61 58 50 53 51 44 54 52 42 60 63 66 41 54 55 45 52 44 44 57 57 69 47 57 39 65 54 54 54 51 40 47 43 57 52 66 50 59 41 63 44 55 58 65 41 54 46 56 56 46 43 56 59 49 34 51 51 56 57 53 53 49 50 61 60 54 62 46 47 52 48 56 46 62 56 39 49 58 51 74 51 48 61 69 55 45 53 51 59 70 45 48 39 44 51 45 35 47 51 61 44 42 53 54 50 56 48 50 52 47 43 51 49 39 51 57 53 61 54 56 58 52 59 65 46 59 43 60 46 44 57 67 53 59 59 67 40 55 61 56 61 48 60 41 42 45 55 45 55 48 53 54 56 49 59 54 53 47 40 51 54 35 47 66 55 47 55 32 50 51 47 61 52 52 62 62 41 57 59 48 53 61 56 42 52 55 44 58 49 42 46 51 67 53 66 41 61 49 61 45 29 51 54 59 45 62 54 68 59 51 53 55 59 54 64 57 50 42 49 55 53 54 51 54 46 57 52 40 42 50 68 54 59 43 41 42 57 52 56 65 64 51 45 40 48 54 61 53 64 53 50 49 46 58 52 51 47 41 60 58 74 68 54 55 47 58 63 51 50 38 55 59 67 53 54 55 44 57 58 48 50 39 40 60 69 53 44 42 58 43 59 57 56 46 51 50 43 50 57 48 62 48 56 51 48 50 51 44 53 48 61 36 49 51 45 68 45 45 48 50 38 54 40 53 62 40 46 39 39 40 64 42 58 60 58 45 60 56 48 69 48 45 45 57 60 43 54 37 55 59 56 50 58 45 50 47 45 62 60 55 45 50 56 60 48 68 54 55 64 54 49 53 55 36 49 59 39 50 58 47 45 44 52 56 50 48 54 42 57 40 49 61 60 43 53 56 53 58 49 57 68 67 52 70 52 56 47 48 50 41 63 47 42 50 47 60 54 60 69 47 68 58 60 50 55 61 46 41 60 55 51 54 49 65 49 56 57 58 47 62 48 54 49 51 53 48 43 51 72 59 45 56 46 52 53 43 66 49 56 43 56 52 42 65 51 58 50 54 60 50 54 50 60 50 43 62 52 41 59 51 58 58 54 52 57 60 61 58 60 50 45 65 76 53 41 48 55 54 58 44 41 63 55 48 53 48 54 35 40 58 59 46 61 48 44 46 49 53 56 50 51 54 43 45 65 49 45 43 69 58 51 51 50 50 48 57 50 64 53 55 57 48 55 47 43 47 58 50 50 48 59 65 47 53 58 64 55 49 59 50 51 48 51 60 69 49 54 48 59 37 55 45 50 56 59 45 51 47 46 55 47 55 57 47 52 45 53 54 56 70 49 48 57 60 59 57 39 48 49 55 56 66 69 49 51 46 54 40 49 71 61 56 59 46 42 46 57 67 49 60 54 50 59 53 57 58 65 51 46 54 68 43 56 48 48 44 46 52 46 49 53 52 48 47 41 57 49 57 59 45 55 44 47 47 53 70 47 50 54 52 53 56 49 59 56 51 60 40 35 65 49 44 58 56 52 61 50 57 54 49 54 55 58 42 64 45 58 43 59 38 50 45 54 47 60 54 53 53 55 57 51 56 35 49 55 55 52 51 50 58 41 40 49 54 54 51 49 41 70 51 58 51 53 60 42 53 62 49 40 53 50 61 45 64 49 55 42 60 57 50 49 51 51 63 50 52 46 59 52 55 52 61 55 51 53 60 49 46 44 42 50 57 52 54 52 47 56 54 41 55 59 51 40 53 52 42 55 49 43 53 63 50 49 54 64 55 52 40 50 53 36 51 69 50 62 50 59 60 50 53 59 48 58 56 60 60 46 46 38 45 44 67 51 57 62 42 51 47 60 57 53 50 48 54 54 54 51 39 53 49 54 58 43 54 57 51 56 47 55 60 64 51 61 72 68 42 55 45 37 57 52 60 46 52 63 49 52 49 71 42 47 55 44 65 48 67 53 44 37 47 60 48 58 49 51 46 42 53 56 60 57 56 58 49 42 67 49 53 58 61 50 51 34 52 60 65 56 45 43 59 55 54 50 61 38 47 52 62 46 55 45 47 54 67 49 57 63 52 53 55 51 53 65 51 38 62 63 49 56 46 64 60 42 58 71 54 46 49 47 58 56 55 44 55 49 49 49 53 48 52 45 60 46 67 58 69 48 50 54 54 67 55 45 60 51 46 50 56 42 47 66 48 59 68 46 54 48 53 52 72 54 57 46 46 51 53 65 42 50 41 46 57 66 53 47 50 54 63 44 44 54 59 44 54 44 49 51 52 59 47 49 46 59 47 44 54 62 56 47 43 56 47 38 54 51 52 48 67 54 53 65 55 46 40 52 54 46 50 63 43 68 44 39 55 50 56 45 51 53 55 56 60 50 46 42 61 62 49 66 47 51 47 41 64 57 56 55 54 48 59 57 58 61 71 50 44 55 55 64 50 56 65 53 56 56 49 65 55 51 39 56 51 59 55 59 47 57 53 49 47 47 56 50 59 47 52 42 56 52 52 55 52 47 52 56 55 56 58 56 52 63 48 50 40 50 53 57 58 56 44 44 69 56 66 55 63 51 55 58 62 49 58 62 48 43 50 65 46 60 44 54 65 52 60 50 50 55 55 62 45 61 65 55 60 62 50 56 64 44 63 53 62 51 63 54 54 45 53 36 50 64 54 53 47 52 52 42 47 63 50 59 55 55 52 56 52 65 46 50 62 52 55 44 69 43 54 39 41 74 55 70 51 53 50 53 60 59 54 47 47 56 54 69 56 61 61 60 56 54 41 59 63 55 61 44 69 43 56 58 51 51 60 71 37 50 60 60 53 48 56 57 42 49 46 43 55 40 50 51 60 58 56 60 61 40 52 61 66 52 64 47 63 53 42 59 48 46 53 65 71 74 52 48 47 58 61 70 55 58 63 63 52 56 47 47 54 55 55 55 63 44 54 42 59 62 47 41 53 43 53 57 52 41 48 41 53 37 57 61 48 51 60 49 53 44 46 62 49 66 58 52 48 48 72 50 57 63 55 59 56 56 59 68 41 46 56 48 57 59 61 62 51 57 61 50 50 55 48 50 57 55 58 49 54 61 60 59 67 37 55 43 57 64 58 57 44 63 44 54 56 53 59 58 37 63 62 60 62 59 53 63 66 60 49 59 57 52 66 50 40 49 58 61 51 50 42 58 44 50 68 52 61 54 55 65 56 73 54 60 54 69 50 58 59 57 64 41 65 44 59 44 58 57 59 63 58 59 42 38 64 51 62 55 59 60 50 49 42 59 59 35 51 51 59 67 57 49 57 67 71 68 53 55 49 53 61 54 56 58 52 49 62 57 62 54 69 50 53 45 45 52 42 58 63 52 53 55 53 58 56 55 62 56 79 41 73 54 59 35 56 52 61 50 50 55 58 41 63 47 53 55 60 62 47 59 47 51 41 54 52 42 57 61 56 57 46 55 47 51 56 59 52 56 54 57 51 66 41 58 51 42 44 51 56 58 43 54 60 66 55 63 56 49 51 39 50 46 58 39 54 65 58 66 56 48 58 47 49 59 68 53 50 61 42 63 53 43 59 61 53 54 36 51 49 48 48 52 37 71 46 66 41 62 54 54 51 65 49 54 58 51 53 65 57 50 56 67 56 57 55 65 52 48 46 51 43 43 61 76 54 60 41 53 40 50 68 65 52 52 53 47 50 56 64 68 63 59 72 53 52 55 62 54 56 39 47 40 60 53 50 63 53 48 57 60 48 43 60 43 35 55 55 47 60 64 49 58 51 63 34 63 56 55 49 57 52 56 52 46 61 59 55 42 55 59 58 55 58 60 59 59 55 54 31 44 64 45 47 57 58 59 42 65 54 68 60 50 54 43 66 56 54 48 53 62 54 71 66 59 52 58 50 57 45 57 53 54 63 62 44 43 55 66 51 48 48 54 58 48 56 51 50 47 47 46 55 64 46 63 61 47 42 51 58 60 66 54 75 53 65 43 55 55 52 55 39 50 55 43 39 55 58 56 54 52 51 54 63 66 56 54 51 46 50 51 60 50 52 56 48 46 48 40 45 50 57 60 48 56 39 52 42 63 58 49 45 56 54 49 46 56 42 44 49 63 58 52 42 73 58 56 57 44 51 53 53 53 41 57 68 55 50 51 50 45 59 54 52 67 43 75 52 63 53 57 54 52 59 50 54 52 57 42 52 68 53 54 54 47 58 53 56 44 46 50 57 49 57 48 59 40 46 54 60 47 70 47 58 56 49 60 45 52 44 56 44 57 49 67 63 57 47 58 43 52 57 56 59 51 58 48 57 63 66 64 41 61 57 63 49 62 49 45 57 56 44 50 43 45 48 60 49 44 53 64 55 55 45 45 42 49 50 57 44 59 66 61 42 55 50 44 55 61 60 45 67 59 51 30 47 64 50 50 48 48 49 52 55 43 46 49 74 56 49 43 60 53 62 50 58 44 57 54 61 53 54 57 70 45 62 43 56 61 51 61 49 53 64 41 52 68 56 61 60 50 56 53 54 57 54 54 64 47 53 53 65 66 50 51 50 61 61 46 46 60 70 58 69 54 49 48 57 59 55 61 47 48 58 52 57 53 49 48 66 56 52 42 51 48 44 47 50 44 63 47 48 53 45 64 58 59 58 49 58 54 58 48 52 58 59 44 51 39 51 56 67 55 52 54 58 49 43 54 42 59 52 66 45 61 51 58 45 50 51 63 73 57 59 59 49 50 52 41 40 51 60 66 61 57 51 53 52 54 60 61 43 42 60 53 50 50 51 57 63 56 62 52 59 70 53 64 55 58 46 62 57 58 60 51 47 64 50 53 56 57 53 59 58 56 50 45 47 51 55 46 42 44 45 49 47 71 52 57 51 62 59 60 52 54 57 38 60 57 56 63 46 50 52 49 49 63 51 52 44 63 57 52 59 53 48 46 60 57 58 56 43 48 51 46 57 35 58 57 53 58 45 48 53 46 62 56 58 55 45 51 59 54 61 53 50 54 53 51 54 43 57 50 54 59 42 53 69 40 51 43 51 58 57 46 51 49 54 56 49 66 44 49 50 64 53 69 55 52 60 45 56 47 55 55 40 48 45 49 58 52 49 48 57 58 50 56 59 52 50 50 45 52 53 61 51 39 44 52 55 54 57 69 39 40 52 47 65 48 56 46 53 39 66 51 57 43 52 65 60 47 61 59 50 48 51 57 65 51 48 50 55 50 48 62 62 58 54 45 55 59 50 53 43 40 68 63 52 59 65 46 62 58 39 49 53 46 53 51 53 65 61 55 46 56 46 52 52 55 45 42 38 60 58 58 47 64 57 43 66 48 58 57 46 56 55 45 47 66 54 55 52 51 53 57 50 69 54 47 67 52 49 56 56 43 45 60 51 51 43 49 54 52 60 56 42 62 53 50 59 61 55 59 63 56 41 38 54 51 48 50 60 49 46 75 45 52 40 51 58 56 38 48 59 42 53 61 41 59 64 48 59 40 63 58 54 53 50 57 57 59 63 44 47 50 43 48 45 52 58 39 44 56 62 59 44 58 56 53 48 49 61 52 42 48 63 58 57 67 55 60 73 48 60 53 53 49 51 61 52 64 56 46 63 42 56 68 53 47 55 57 53 40 57 60 54 52 70 55 53 55 54 52 55 50 56 51 59 58 50 58 57 42 61 46 45 63 47 52 48 37 48 43 55 46 56 57 47 47 58 55 53 41 51 48 51 58 48 41 50 51 44 43 48 50 59 47 42 42 56 53 52 60 60 44 48 48 55 38 54 63 54 62 42 54 56 48 57 62 42 48 56 58 48 53 61 43 52 53 38 55 53 46 56 56 45 44 39 56 57 55 53 62 49 55 47 57 54 45 60 73 44 54 48 52 55 48 61 45 63 54 43 44 55 57 54 55 50 54 41 51 48 55 44 48 62 49 54 45 54 64 50 48 47 54 53 63 52 56 58 64 59 51 51 73 43 49 60 61 48 65 64 55 45 51 44 52 49 60 66 47 48 52 54 45 47 72 41 51 52 60 51 58 56 64 58 63 57 59 66 57 57 58 49 42 55 69 45 56 40 53 55 51 57 51 46 50 50 48 42 55 45 48 55 59 47 59 52 47 45 43 51 59 53 63 45 50 49 65 52 52 60 61 58 59 63 53 58 49 45 38 42 56 42 42 58 55 61 55 63 62 46 53 60 69 47 46 65 42 72 46 56 40 47 57 46 50 48 61 43 49 68 71 57 71 52 54 61 63 62 47 56 56 56 52 62 53 51 63 54 53 56 56 55 48 53 58 60 58 54 57 55 49 69 41 58 50 61 54 50 58 51 49 52 49 50 48 40 51 51 56 48 49 42 45 54 47 58 57 47 63 45 52 54 45 46 43 52 49 54 45 59 59 45 54 50 51 54 30 45 47 47 66 51 46 56 49 50 47 48 54 54 59 54 58 60 54 47 53 45 55 48 60 60 66 44 47 42 56 45 51 63 56 58 53 42 43 61 59 65 51 51 58 42 59 44 67 40 55 53 58 47 57 46 50 47 62 55 70 55 60 56 51 55 59 54 63 46 58 51 59 51 46 58 62 51 54 52 59 59 62 48 50 62 65 43 49 56 60 49 65 57 58 45 62 59 49 44 55 62 55 44 54 55 52 53 49 55 58 39 62 55 53 55 49 48 54 49 51 56 51 59 46 43 46 55 61 52 46 55 51 55 65 64 53 41 50 53 65 68 52 55 52 60 55 63 50 64 53 52 60 49 63 48 60 48 43 52 51 51 49 66 43 47 42 56 48 51 48 38 53 52 55 62 49 57 49 51 42 73 48 57 41 66 57 50 45 69 49 71 39 54 46 60 46 52 51 52 41 50 62 54 63 69 53 44 41 53 46 50 51 59 55 50 54 59 59 64 61 66 57 61 46 47 53 47 51 49 46 52 60 50 62 61 64 54 52 59 55 50 66 49 42 63 61 41 53 48 58 45 46 60 50 52 61 64 50 66 60 63 54 53 57 59 47 49 52 59 55 64 43 57 55 48 65 38 46 52 61 54 49 49 65 41 58 54 57 66 52 58 48 53 36 74 54 55 74 52 48 69 54 56 51 57 40 60 53 65 51 72 51 56 53 51 67 65 55 70 53 62 34 76 54 49 59 62 44 56 55 55 65 61 48 45 48 71 51 57 51 58 62 47 73 68 56 69 50 52 54 81 46 55 67 58 59 56 59 55 66 63 52 52 74 65 67 61 65 64 65 65 70 48 73 55 60 59 57 65 54 66 62 43 64 63 49 52 57 52 66 63 61 54 73 68 40 64 56 52 69 62 61 58 56 68 55 58 53 56 56 43 52 45 62 55 67 52 79 59 65 63 64 59 71 44 49 46 54 60 56 49 58 61 47 57 56 63 76 53 65 48 59 63 41 53 46 46 53 46 54 43 49 52 52 48 56 53 68 42 52 56 44 42 38 48 53 75 55 57 42 56 58 52 53 63 49 53 55 55 43 54 41 62 56 54 58 61 48 50 53 56 56 67 45 51 64 54 54 49 53 52 51 56 45 42 48 63 55 49 50 66 54 50 63 50 59 57 52 50 57 48 53 41 71 48 60 57 49 42 51 54 50 46 46 53 40 54 42 47 60 50 50 52 48 65 48 65 48 59 43 51 61 66 52 57 61 59 54 44 55 54 59 52 52 45 49 43 55 58 49 48 56 38 53 54 53 59 44 41 53 55 46 50 56 47 45 45 56 47 51 47 47 45 50 45 70 46 75 60 64 54 48 63 56 64 55 46 49 58 61 55 49 57 51 48 49 63 47 46 52 61 62 47 50 60 49 61 41 61 51 52 46 51 53 63 52 43 55 60 35 57 51 56 54 59 61 47 59 42 48 49 46 56 52 67 65 50 51 59 46 38 52 47 58 62 55 52 41 43 64 68 69 40 41 60 50 59 64 85 53 51 45 48 48 50 50 67 64 45 60 57 59 66 46 42 54 60 54 38 63 50 55 47 64 45 50 55 46 49 38 55 66 72 57 55 59 41 59 52 52 60 50 42 49 51 45 57 42 51 42 42 56 59 39 43 61 42 43 60 51 41 55 39 46 49 63 52 48 58 57 54 55 42 53 63 62 54 63 51 62 56 67 59 60 49 34 59 45 52 52 46 55 52 52 50 57 52 53 51 68 46 66 56 53 53 49 46 57 49 45 61 58 61 53 54 55 41 57 42 51 45 42 54 51 53 59 52 58 46 52 58 56 52 41 39 37 54 57 64 42 41 58 61 53 65 60 45 53 59 48 56 53 41 64 55 40 58 48 40 51 68 58 52 34 45 46 59 40 53 56 57 45 56 53 43 68 55 59 56 57 49 45 51 39 52 52 58 47 47 52 36 59 58 50 47 47 35 58 61 56 44 57 60 55 47 54 41 43 50 40 49 61 41 56 61 61 52 63 53 60 44 43 48 49 57 44 64 64 68 55 40 53 52 56 45 52 58 42 49 59 66 53 58 56 51 38 52 55 37 52 44 56 54 48 52 54 44 41 55 43 51 45 43 51 56 47 57 51 56 51 47 45 50 55 45 43 60 67 57 66 52 40 55 34 44 56 59 53 49 40 49 49 51 52 42 51 56 60 50 59 65 45 53 51 59 54 52 38 60 51 58 50 52 55 52 45 49 58 52 56 47 49 54 44 50 40 55 53 42 51 55 60 44 54 51 48 58 62 52 42 41 46 54 47 54 56 63 56 52 55 53 47 48 44 57 47 55 47 53 53 47 54 54 40 56 50 40 45 47 47 60 39 55 48 49 52 58 53 48 52 47 53 50 37 44 50 64 51 49 58 44 49 56 46 42 50 51 47 51 58 58 46 54 52 60 64 68 49 48 50 50 45 55 69 49 44 54 59 57 61 43 53 56 73 60 45 49 56 51 66 53 62 66 56 50 46 58 59 62 59 56 54 54 42 61 61 56 58 45 45 38 44 55 47 55 64 61 50 45 53 53 55 66 52 50 48 42 50 65 54 61 50 52 53 48 49 47 51 48 61 66 52 42 49 47 45 45 43 62 56 46 58 63 45 60 60 49 59 52 62 57 50 51 44 50 54 53 45 45 47 46 55 49 42 52 42 57 45 53 53 53 40 56 45 46 60 60 40 50 51 42 58 53 52 45 53 49 52 51 52 53 55 51 53 42 45 59 57 55 41 47 47 63 46 61 53 54 46 51 55 50 78 54 43 50 47 46 53 47 59 53 66 40 53 53 60 58 42 47 63 54 51 52 58 48 69 55 53 44 48 55 41 57 61 44 53 59 43 54 51 44 44 63 53 35 60 45 56 44 37 51 40 52 45 48 56 51 43 54 49 48 48 55 46 48 47 65 58 51 49 65 70 56 52 46 58 43 55 61 49 50 52 64 45 44 44 46 57 60 43 43 43 53 55 52 58 52 42 50 52 51 45 56 35 45 56 65 42 65 58 39 39 53 42 48 43 63 48 54 53 44 42 47 51 49 57 55 45 54 53 51 44 53 66 54 52 56 54 43 47 56 44 47 42 57 46 49 48 52 51 43 49 44 60 42 42 52 43 58 53 43 46 57 48 56 43 35 39 53 37 37 39 57 53 54 57 56 45 53 56 53 48 59 38 57 46 48 66 51 57 44 50 44 57 56 60 51 55 46 49 55 45 46 52 55 56 46 53 59 55 59 44 45 42 45 51 55 46 56 53 66 60 42 46 44 52 59 39 51 46 52 52 46 51 58 39 50 61 52 57 53 34 64 44 41 43 64 47 61 49 54 39 58 62 50 47 44 57 45 55 50 52 60 64 55 52 38 56 44 48 56 39 47 50 44 50 49 58 49 41 54 44 59 46 61 54 44 50 48 52 58 61 60 50 55 55 47 43 44 55 51 52 53 42 51 51 53 51 43 42 53 62 54 44 52 53 55 39 56 40 46 50 48 51 51 46 46 47 59 50 45 58 49 42 57 67 56 56 63 65 51 67 49 63 54 50 51 44 53 56 48 59 52 59 60 51 49 45 58 72 48 52 46 53 45 46 43 57 58 49 44 47 54 49 44 50 53 59 44 39 63 55 44 57 41 46 45 49 51 47 65 69 44 63 48 62 56 55 56 41 42 46 50 43 52 46 61 49 53 40 47 43 51 56 60 55 35 54 71 49 64 40 50 43 55 57 42 66 44 49 41 42 45 57 60 50 55 59 55 46 42 71 52 48 42 42 60 35 44 47 47 56 66 53 55 57 47 61 51 51 57 47 49 56 54 35 47 52 42 54 59 56 43 36 51 50 52 63 49 47 53 56 51 50 58 53 57 54 43 53 57 63 42 58 45 50 61 48 37 45 51 44 53 48 58 56 54 48 46 53 43 51 68 54 56 39 56 46 53 46 54 43 64 54 48 43 44 41 60 42 61 66 51 50 72 41 59 34 46 55 52 50 46 50 47 53 55 59 67 67 58 72 50 60 62 35 53 65 52 60 54 47 55 54 40 50 57 58 50 57 61 49 52 54 65 61 51 61 47 58 53 54 56 54 53 56 51 56 42 43 60 62 47 62 47 56 57 54 57 62 49 57 48 45 58 49 56 62 38 61 57 51 62 54 65 47 62 48 66 40 51 47 68 51 57 55 73 45 55 40 46 55 36 46 51 45 47 49 52 51 60 56 43 66 48 45 50 57 47 52 66 59 48 44 35 58 47 63 36 56 49 55 47 45 52 45 59 50 55 52 42 48 45 49 52 50 44 55 49 51 51 60 57 56 49 52 51 58 46 64 60 51 64 63 52 47 48 46 52 56 49 44 40 48 61 41 54 50 70 64 60 50 56 58 54 42 48 49 58 39 52 57 53 60 60 52 37 51 55 50 52 63 44 45 45 52 46 51 44 55 48 50 44 56 60 47 49 50 39 44 55 55 60 53 43 54 58 44 57 65 55 52 54 49 54 41 48 43 64 49 46 47 56 56 42 53 58 60 51 42 43 47 46 46 69 61 57 47 60 40 38 48 58 48 53 45 50 59 44 57 50 42 52 61 51 44 60 45 51 55 63 52 60 67 61 56 60 55 44 62 47 54 43 42 58 61 53 51 52 51 63 56 48 55 50 58 56 51 53 51 65 50 47 50 49 45 44 51 54 55 50 46 56 50 51 49 39 44 53 61 64 56 54 55 60 47 51 40 53 56 39 52 64 51 46 52 46 58 65 59 49 68 53 50 58 44 47 52 58 60 60 50 39 56 56 49 54 52 44 49 59 57 46 48 54 60 48 61 46 57 53 64 66 64 46 55 46 41 52 49 52 50 42 55 52 53 45 41 48 43 58 41 62 57 40 47 55 35 55 54 59 52 53 47 57 37 52 47 45 51 49 53 47 46 59 41 46 47 51 50 46 49 56 51 49 40 60 47 40 41 49 40 58 45 51 60 51 47 59 50 71 54 58 68 61 61 58 49 53 47 57 63 57 56 70 40 59 46 65 44 63 47 50 54 49 52 56 62 46 53 62 55 48 58 59 45 53 39 62 62 56 50 51 61 56 46 54 48 52 52 59 62 40 57 53 45 39 57 56 58 48 55 55 55 58 58 50 43 46 61 49 43 34 43 53 61 56 51 52 53 45 57 45 56 40 44 46 49 62 37 53 53 52 59 50 41 63 58 45 47 63 40 40 53 66 50 66 52 44 45 43 64 45 56 51 45 61 63 60 47 67 51 53 47 51 46 57 50 54 59 54 51 53 52 49 44 54 48 47 46 53 46 43 37 59 52 51 57 49 44 63 37 64 67 45 57 59 47 57 51 56 43 49 52 58 55 54 63 54 60 53 43 51 57 69 65 55 49 42 42 55 62 50 64 63 37 40 46 51 55 61 62 59 59 62 43 58 57 67 49 55 52 46 53 57 55 57 47 54 57 53 61 45 53 49 51 45 58 59 60 72 53 66 44 45 48 62 58 48 51 44 53 58 65 51 53 45 55 52 48 59 61 48 47 47 67 44 34 41 59 58 42 56 54 41 62 51 55 41 51 54 49 50 45 66 43 50 57 59 38 58 48 40 51 46 52 58 59 55 65 50 58 41 59 57 52 49 60 60 50 57 55 52 59 52 40 46 47 55 47 56 44 40 57 49 58 55 52 54 44 59 39 48 48 52 56 51 61 47 62 50 53 60 53 47 65 60 58 47 53 46 53 55 50 54 56 50 41 47 57 35 38 55 54 53 60 41 66 40 41 45 52 58 54 53 47 47 52 53 41 45 55 60 58 48 60 40 43 53 55 48 48 41 53 56 44 55 50 47 59 48 61 47 46 49 56 58 48 52 27 45 54 56 58 60 54 61 49 42 51 51 55 51 56 51 52 59 52 50 59 65 52 40 50 52 55 51 57 44 47 53 59 48 57 48 46 44 65 53 50 64 46 59 51 53 63 61 48 49 48 57 44 37 53 67 54 52 53 54 59 66 52 57 61 52 54 54 52 47 52 45 60 57 47 49 43 45 45 53 56 40 61 50 37 48 45 47 47 55 48 36 42 60 50 43 48 50 42 73 39 54 47 34 56 54 63 51 51 51 50 53 56 53 57 49 56 59 62 53 43 54 51 40 52 61 46 58 51 48 50 51 47 46 50 53 45 49 63 46 58 47 46 65 45 58 45 59 59 52 48 52 53 52 42 39 41 58 48 50 44 55 58 44 38 44 52 54 49 71 49 49 49 47 46 47 40 54 56 38 49 62 63 56 46 49 61 61 44 60 70 60 58 52 41 59 49 40 52 51 53 52 61 43 52 60 53 48 55 64 44 68 47 55 44 55 56 35 47 44 52 55 36 48 53 60 51 50 56 37 52 55 55 50 49 51 57 43 42 51 52 58 37 41 56 56 55 61 66 53 51 46 51 58 47 47 41 44 61 46 58 52 72 45 45 61 56 57 60 51 60 55 48 66 54 57 53 55 43 62 51 45 59 62 46 47 40 50 51 49 78 46 60 41 46 63 56 45 47 55 57 47 50 57 50 50 51 66 61 51 48 35 59 65 66 59 46 52 61 57 51 60 53 65 57 49 52 47 65 44 54 46 52 48 47 57 56 42 58 46 51 60 47 52 55 51 57 53 57 37 45 49 59 56 53 54 55 35 56 46 60 35 52 45 36 52 61 41 52 47 49 48 52 59 52 51 55 56 45 56 58 34 71 59 43 55 48 51 61 51 54 58 50 64 48 41 55 58 56 56 54 61 54 64 53 51 41 62 62 57 48 54 50 50 65 51 60 52 55 55 48 59 44 60 53 52 45 54 65 48 56 51 48 70 48 58 51 54 52 56 56 52 44 73 47 51 54 55 68 56 62 52 48 52 62 46 58 33 64 53 60 41 56 59 45 59 55 53 45 50 77 53 60 63 61 51 60 61 56 53 61 46 61 66 44 63 62 31 45 46 54 55 41 62 41 58 48 55 57 55 60 53 62 36 45 51 42 53 45 56 50 47 59 45 49 59 40 59 51 67 59 51 45 40 79 42 54 62 46 47 56 48 46 56 56 53 49 52 47 45 60 54 56 54 57 66 45 55 40 50 60 62 48 66 54 60 60 53 58 54 40 49 46 46 42 51 53 51 54 58 55 45 51 54 50 60 51 49 48 48 59 74 63 50 53 59 55 41 60 55 58 49 39 49 42 48 48 57 51 54 56 53 46 51 57 53 46 48 51 64 53 55 55 51 46 67 46 44 44 59 54 59 44 61 61 54 42 50 46 60 46 59 51 59 49 53 54 58 54 42 53 46 49 42 42 48 50 45 64 48 57 50 62 50 44 50 55 51 50 55 52 40 61 62 58 65 54 57 55 58 56 52 50 61 60 49 55 69 56 45 52 44 53 40 46 56 46 52 53 50 63 43 62 57 53 46 51 65 43 52 60 41 60 53 47 53 48 62 61 51 56 58 54 57 48 55 48 45 55 65 44 46 58 59 58 68 65 55 61 64 50 36 45 45 62 59 49 58 57 42 47 48 50 62 62 50 47 46 46 39 53 47 60 61 50 46 58 54 40 60 53 57 48 57 52 51 45 57 46 40 60 69 48 43 66 56 48 54 53 63 58 53 56 57 53 50 53 55 44 51 53 49 47 57 60 50 55 43 56 57 57 48 43 57 44 55 42 58 54 49 46 53 50 44 43 42 58 43 51 46 36 42 43 45 47 45 43 53 40 59 64 41 55 44 55 54 67 46 60 60 52 57 60 52 71 46 40 38 51 50 55 58 50 68 56 56 48 47 60 81 58 49 60 65 59 55 55 55 56 42 56 46 55 62 44 49 57 65 61 42 46 62 47 60 53 52 59 48 58 57 50 53 61 68 58 58 46 62 66 63 59 60 46 47 52 51 47 43 48 58 60 56 68 61 53 47 59 58 59 50 56 57 51 50 60 48 58 53 67 62 68 63 56 54 57 46 54 47 63 56 48 61 40 53 53 53 55 53 44 61 50 55 54 64 51 53 55 54 65 51 48 74 46 64 39 56 44 65 78 56 40 53 56 54 44 48 54 43 61 62 55 53 51 46 50 55 65 59 63 46 52 49 55 47 57 49 43 59 49 57 61 55 48 61 59 62 49 34 60 45 38 59 48 56 59 54 50 55 53 56 45 49 46 54 53 53 39 52 64 59 62 59 44 60 51 58 47 57 38 83 46 52 51 50 53 45 60 45 49 53 56 50 50 52 54 63 52 53 43 55 38 72 58 57 52 60 53 51 50 57 55 54 56 48 68 51 49 49 48 58 50 53 49 50 55 52 51 66 51 48 47 54 64 44 56 68 61 55 54 59 64 46 63 47 50 47 48 47 46 58 57 64 54 57 54 54 55 61 59 56 42 42 46 46 41 46 58 50 65 50 61 44 57 62 58 59 54 61 45 49 69 54 68 54 55 50 43 70 36 46 51 58 53 60 56 50 61 56 64 52 63 65 50 46 48 39 47 53 68 48 54 47 45 52 49 59 49 59 48 52 49 68 58 52 59 59 50 55 49 55 60 49 49 60 50 61 60 59 67 66 67 46 64 50 59 67 61 56 55 55 75 46 66 48 41 48 42 57 56 59 53 56 51 55 60 74 66 56 67 54 43 49 71 54 68 68 46 70 56 56 54 45 60 61 58 59 54 64 66 55 72 54 46 69 60 55 52 44 50 60 56 75 59 55 49 47 71 60 47 73 70 66 58 53 71 58 53 68 54 46 57 67 48 53 55 49 54 54 71 44 66 55 58 57 59 50 64 65 51 56 53 64 55 53 64 43 53 58 58 55 60 51 55 52 59 60 61 45 62 55 51 52 40 54 36 52 65 45 59 64 56 53 57 45 67 64 73 58 49 55 54 54 61 61 54 54 48 49 55 63 63 51 52 68 49 63 39 46 48 44 48 54 41 76 56 49 56 66 54 46 51 54 50 48 47 54 54 52 50 57 50 53 42 58 43 47 37 52 47 63 56 52 54 53 55 63 59 62 57 50 60 56 63 45 65 55 50 41 58 50 47 48 49 38 52 52 68 50 69 42 39 73 56 47 43 65 56 58 46 51 53 47 52 41 50 51 44 50 58 58 60 55 46 41 49 54 40 58 50 68 47 44 55 51 55 57 50 56 57 44 52 53 56 55 53 58 46 35 47 55 53 44 66 47 51 44 56 50 57 60 49 51 43 38 42 56 54 47 56 59 64 41 45 50 51 43 44 54 61 52 50 42 44 50 64 59 52 58 40 55 58 53 39 66 47 51 46 58 46 58 53 57 69 49 59 53 40 41 62 49 46 54 51 69 49 43 62 52 43 40 56 58 60 50 59 58 47 48 54 55 57 44 41 60 51 59 46 61 54 53 46 50 51 58 51 54 55 47 54 53 49 50 44 46 54 60 46 43 71 46 63 43 45 56 54 59 37 54 68 28 53 47 56 49 56 63 54 64 39 61 59 51 54 63 40 46 63 77 47 44 64 50 48 53 49 62 55 51 47 50 47 58 59 31 46 64 53 57 58 45 53 54 54 58 44 50 57 43 43 47 73 58 65 48 62 48 55 50 58 54 53 47 57 49 48 48 42 53 55 51 57 49 39 53 51 54 55 49 61 62 60 50 81 58 56 62 50 54 46 45 48 48 45 46 58 54 46 67 50 39 48 57 53 42 50 58 58 55 53 54 49 57 58 50 51 56 50 63 59 62 38 61 47 55 48 40 47 64 50 53 46 50 60 69 54 48 48 52 46 50 48 52 62 46 53 46 49 55 48 55 42 69 53 43 61 38 61 54 42 45 54 69 53 58 61 50 57 58 62 45 64 45 59 43 53 56 52 69 47 51 57 39 59 47 47 57 50 56 41 50 44 58 62 41 60 52 50 41 54 58 48 52 54 46 65 44 60 53 44 57 57 43 55 51 42 52 43 60 57 73 51 75 43 54 58 58 63 62 45 67 43 62 51 57 54 49 50 45 52 55 49 60 53 49 59 66 47 56 55 44 58 73 66 54 31 63 75 47 67 50 62 52 76 42 61 60 65 55 56 55 62 47 59 61 51 40 52 57 62 59 45 52 71 60 66 64 58 42 45 69 64 54 61 63 49 63 52 44 52 56 54 63 44 49 57 59 45 59 51 58 56 47 59 53 44 75 55 62 51 56 51 65 64 64 57 55 47 58 57 41 54 58 52 38 53 58 53 57 68 54 56 58 51 51 61 57 54 50 56 57 56 57 55 51 40 56 54 59 43 65 35 50 66 45 57 55 59 63 45 54 55 55 47 62 41 54 47 43 48 53 64 60 54 60 62 55 57 54 52 64 50 55 51 55 58 54 47 54 56 56 52 54 52 52 60 59 55 73 42 60 60 54 57 45 57 48 59 58 50 48 45 43 63 48 63 68 57 56 50 49 56 46 37 62 52 61 55 60 46 50 48 55 66 51 53 48 58 54 56 48 45 55 43 54 58 56 58 61 60 55 48 47 45 58 59 57 45 53 64 43 51 57 59 45 39 42 39 58 36 42 54 56 46 51 64 74 54 49 42 50 60 48 52 74 44 56 51 61 52 60 55 43 52 43 66 38 62 49 54 53 59 47 56 51 54 54 46 66 54 60 46 52 49 63 56 37 59 52 49 54 42 66 68 68 48 44 53 43 58 53 58 54 47 68 62 57 53 45 64 56 44 59 60 41 45 47 61 43 53 65 52 57 57 52 51 61 49 55 54 43 51 50 68 42 60 46 48 59 50 44 58 54 46 51 46 48 44 60 58 56 52 62 55 54 53 65 54 47 39 48 65 46 55 47 61 55 43 56 41 54 53 34 49 55 37 46 47 48 47 50 37 56 52 61 49 35 43 55 51 60 39 54 44 68 54 54 71 50 35 48 78 39 51 44 55 43 54 58 46 50 51 56 58 56 60 58 56 76 58 55 44 39 48 38 56 54 53 67 44 45 52 50 68 77 41 44 61 55 47 51 56 76 57 52 54 54 53 66 56 46 53 35 80 64 53 52 70 45 55 52 45 53 55 57 58 57 44 50 65 48 45 57 49 51 50 50 53 47 43 45 43 59 58 51 46 37 56 52 57 45 67 56 49 47 49 46 50 56 63 53 56 56 46 52 62 55 51 63 57 46 59 49 55 66 54 41 61 52 73 34 59 56 43 57 57 49 60 48 56 59 50 45 48 55 58 63 53 50 52 78 47 59 47 61 47 54 51 50 56 44 52 56 39 58 60 61 45 46 54 50 51 48 57 53 49 50 55 54 68 63 46 53 53 46 58 49 61 60 55 57 43 61 58 54 51 53 50 57 61 49 53 46 56 48 67 40 45 58 54 53 55 55 40 59 58 44 56 75 45 62 50 41 52 75 53 65 54 57 56 55 51 53 50 48 52 62 59 52 56 49 68 46 58 70 64 54 50 44 59 54 53 68 58 50 60 50 52 40 60 53 49 61 41 54 65 48 57 55 62 56 46 59 56 40 51 57 58 56 53 54 50 48 46 48 41 50 48 54 58 52 44 59 55 55 57 53 41 41 55 52 48 40 48 57 50 51 56 56 47 52 57 57 52 65 49 56 54 53 41 67 55 51 40 57 53 42 49 47 52 55 47 64 52 41 43 38 59 45 63 50 63 64 44 45 75 52 35 56 56 52 50 67 46 52 52 61 66 57 69 45 53 58 57 65 51 60 53 50 49 54 42 43 56 62 58 49 54 67 53 55 57 51 66 53 54 66 49 59 60 46 58 63 62 57 58 47 47 52 56 59 47 56 51 53 52 59 57 59 55 62 43 42 49 49 57 43 49 53</counts>
			</dataPoints>
		</scan>
	</xrdMeasurement>
</xrdMeasurements>