File: data/XRD/XG-Vakuum/XG-875/W6822-1C_XG_Vakuum_875.xrdml
<xrdMeasurements xmlns="http://www.xrdml.com/XRDMeasurement/2.1" xmlns:xsi="http://www.w3.org/2001/XMLSchema-instance" xsi:schemaLocation="http://www.xrdml.com/XRDMeasurement/2.1 http://www.xrdml.com/XRDMeasurement/2.1/XRDMeasurement.xsd" status="Completed">
	<comment>
		<entry>Configuration=Factory configuration, Owner=User-1, Creation date=7/8/2013 4:01:53 PM</entry>
		<entry>Goniometer=PW3050/65 (Theta/2Theta); Minimum step size 2Theta:0.0001; Minimum step size Omega:0.0001</entry>
		<entry>Sample stage=MRD Cradle; Minimum step size Phi:0.01; Minimum step size Chi:0.01; Minimum step size X:0.01; Minimum step size Y:0.01; Minimum step size Z:0.001</entry>
		<entry>Diffractometer system=XPERT-PRO</entry>
		<entry>Measurement program=C:\PANalytical\Data Collector\Programs\Jorrit\2thom\_absolute_2th-om_10-130deg_PIXscan_56min.xrdmp, Identifier={15BCCF57-2807-42BD-B5B9-ECC0B3DC9284}</entry>
		<entry>Batch program=C:\PANalytical\Data Collector\Programs\SimonL\batch7x_2thom_10-130°_z9.1_x0,10,20,30_y10,20,30_57min.xrdmp, Identifier={089D96B1-A01D-49FF-BCB5-EEA9DFC9CC78}</entry>
	</comment>
	<sample type="To be analyzed">
		<id></id>
		<name></name>
		<preparedBy></preparedBy>
	</sample>
	<xrdMeasurement measurementType="Scan" status="Completed" sampleMode="Reflection">
		<comment>
			<entry>_absolute_2th-om_10-130deg_PIXscan_56min</entry>
			<entry>PHD Lower Level = 4.83 (keV), PHD Upper Level = 11.27 (keV)</entry>
		</comment>
		<usedWavelength intended="K-Alpha 1">
			<kAlpha1 unit="Angstrom">1.5405980</kAlpha1>
			<kAlpha2 unit="Angstrom">1.5444260</kAlpha2>
			<kBeta unit="Angstrom">1.3922500</kBeta>
			<ratioKAlpha2KAlpha1>0.5000</ratioKAlpha2KAlpha1>
		</usedWavelength>
		<incidentBeamPath>
			<radius unit="mm">320.00</radius>
			<xRayTube id="1010048" name="Empyrean Cu LFF HR (9430 033 7310x) DK442154">
				<tension unit="kV">40.0</tension>
				<current unit="mA">40.0</current>
				<anodeMaterial>Cu</anodeMaterial>
				<focus type="Line">
					<length unit="mm">12.0</length>
					<width unit="mm">0.4</width>
					<takeOffAngle unit="deg">4.2</takeOffAngle>
				</focus>
			</xRayTube>
			<xRayMirror id="27010001" name="Inc. Beam Cu W/Si (parabolic MRD)" hybrid="false">
				<crystal type="Graded" shape="Parabolic">W/Si</crystal>
				<acceptanceAngle unit="deg">0.800</acceptanceAngle>
				<length unit="mm">60.0</length>
			</xRayMirror>
			<sollerSlit id="21010002" name="Soller slits 0.04 rad.">
				<opening unit="rad">0.0400</opening>
			</sollerSlit>
			<mask id="22030008" name="Fixed mask 4 mm">
				<distanceToSample unit="mm">220.00</distanceToSample>
				<width unit="mm">4.00</width>
			</mask>
			<divergenceSlit id="22010011" name="Fixed slit 1/32°" xsi:type="fixedDivergenceSlitType">
				<distanceToSample unit="mm">220.00</distanceToSample>
				<height unit="mm">0.05</height>
			</divergenceSlit>
		</incidentBeamPath>
		<diffractedBeamPath>
			<radius unit="mm">320.00</radius>
			<sollerSlit id="21010002" name="Soller slits 0.04 rad.">
				<opening unit="rad">0.0400</opening>
			</sollerSlit>
			<receivingSlit id="22010001" name="Fixed slit 4°">
				<height unit="mm">5.88</height>
			</receivingSlit>
			<detector id="7010017" name="PIXcel3D 1x1 detector" xsi:type="areaDetectorType">
				<phd unit="%">
					<lowerLevel>30.0</lowerLevel>
					<upperLevel>70.0</upperLevel>
				</phd>
				<mode>Scanning</mode>
				<activeChannelsEquatorial>255</activeChannelsEquatorial>
				<activeChannelsAxial>255</activeChannelsAxial>
				<pitchEquatorial unit="mm">0.05500</pitchEquatorial>
				<pitchAxial unit="mm">0.05500</pitchAxial>
				<readOutPeriod unit="seconds">0.135</readOutPeriod>
			</detector>
		</diffractedBeamPath>
		<scan appendNumber="0" mode="Continuous" scanAxis="2Theta-Omega" status="Completed">
			<header>
				<startTimeStamp>2024-10-22T01:11:16+02:00</startTimeStamp>
				<endTimeStamp>2024-10-22T02:07:21+02:00</endTimeStamp>
				<author>
					<name>PRO-MRD</name>
				</author>
				<source>
					<applicationSoftware version="6.1b">Data Collector</applicationSoftware>
					<instrumentControlSoftware version="7.0E 20130304">XPERT-PRO</instrumentControlSoftware>
					<instrumentID>0000000011142674</instrumentID>
				</source>
			</header>
			<dataPoints>
				<positions axis="2Theta" unit="deg">
					<startPosition>9.99826193</startPosition>
					<endPosition>129.99755682</endPosition>
				</positions>
				<positions axis="Omega" unit="deg">
					<startPosition>4.99913096</startPosition>
					<endPosition>64.99877841</endPosition>
				</positions>
				<positions axis="Phi" unit="deg">
					<commonPosition>0.00</commonPosition>
				</positions>
				<positions axis="Chi" unit="deg">
					<commonPosition>0.00</commonPosition>
				</positions>
				<positions axis="X" unit="mm">
					<commonPosition>0.00</commonPosition>
				</positions>
				<positions axis="Y" unit="mm">
					<commonPosition>-20.00</commonPosition>
				</positions>
				<positions axis="Z" unit="mm">
					<commonPosition>9.100</commonPosition>
				</positions>
				<commonCountingTime unit="seconds">32.895</commonCountingTime>
				<counts 86 64 80 70 58 67 62 78 62 55 78 83 68 57 83 77 70 61 53 76 70 77 59 64 66 72 61 60 79 80 74 61 68 58 74 67 71 68 61 81 72 74 67 58 74 70 71 60 75 70 74 72 69 68 63 64 73 77 68 85 74 66 77 48 62 81 61 85 59 74 64 65 70 73 68 46 80 73 68 68 80 74 68 79 67 65 65 71 61 74 66 57 59 81 65 87 74 49 69 59 72 72 80 65 67 72 70 61 74 75 77 64 65 63 48 85 63 70 62 70 69 90 60 65 58 62 83 60 70 76 64 75 66 63 61 48 55 58 58 62 60 70 68 80 72 69 86 64 62 77 82 79 64 90 63 65 74 62 53 68 68 72 74 70 55 66 57 65 68 70 64 59 59 69 67 68 70 72 61 47 50 74 69 68 64 73 66 72 58 76 57 89 87 72 60 78 84 67 78 66 52 61 64 67 56 81 62 76 58 61 66 51 72 67 48 79 67 66 68 65 78 52 63 67 63 58 61 65 65 75 57 58 76 83 66 74 78 61 75 67 76 55 76 72 59 57 69 52 65 59 73 59 66 63 61 59 59 60 74 64 66 68 66 60 62 69 59 63 62 65 81 59 67 75 54 52 63 71 58 70 75 52 60 53 65 64 60 66 64 62 60 65 56 71 68 49 60 54 71 63 67 61 49 62 64 58 54 84 64 71 62 65 68 55 66 74 64 53 70 51 56 52 54 70 63 81 60 63 56 72 55 93 69 69 73 57 66 80 65 80 73 62 62 78 48 57 60 58 61 46 69 50 60 60 76 62 58 71 68 79 62 53 59 55 61 69 62 54 53 53 48 59 63 71 74 57 63 71 62 58 62 51 65 55 68 62 77 57 61 52 75 68 72 63 74 59 80 67 75 65 70 73 55 66 63 75 50 57 65 58 67 60 60 53 65 52 66 59 55 72 57 74 65 52 65 55 47 67 66 63 61 52 56 59 57 59 62 52 62 61 61 51 68 62 55 55 70 55 68 62 56 56 62 56 60 59 62 53 69 52 42 55 58 63 67 55 70 61 60 58 51 63 64 61 55 56 55 60 58 55 57 61 69 62 52 70 72 58 65 71 65 62 72 44 62 63 57 64 69 66 58 71 50 64 65 61 56 51 73 58 46 65 65 62 60 64 50 64 50 71 49 58 67 75 52 58 50 58 69 50 75 63 43 47 61 57 51 45 65 54 59 50 56 67 49 52 67 63 68 64 48 68 51 51 52 61 62 63 60 53 63 50 54 44 53 53 57 62 70 55 68 82 46 66 48 63 52 55 66 51 51 53 60 61 53 52 62 65 57 53 60 43 72 70 63 59 63 58 64 59 67 62 57 60 55 69 72 62 45 40 55 50 63 58 53 58 57 64 53 58 67 60 63 91 64 61 65 53 53 60 73 55 52 54 46 58 70 72 51 60 57 60 62 65 65 52 74 59 55 51 51 50 64 54 58 62 46 63 59 70 67 58 50 62 49 56 67 61 54 50 45 53 60 50 58 68 70 41 46 66 51 46 71 58 65 58 61 57 64 60 52 50 45 59 64 55 63 55 53 62 58 53 61 60 60 50 62 60 60 63 58 57 56 65 52 56 58 68 62 67 61 66 60 55 65 55 52 57 57 47 52 62 62 61 68 63 62 55 65 57 58 57 62 48 59 64 74 73 67 75 60 58 57 61 58 48 63 60 43 60 58 63 63 64 76 65 65 54 66 56 63 77 67 38 58 69 55 57 59 51 65 61 58 60 55 62 69 54 61 60 55 74 53 50 68 59 47 52 54 61 62 45 54 61 54 62 53 44 62 65 59 52 51 70 51 55 60 48 52 54 84 64 67 69 57 57 61 62 46 60 65 59 69 50 70 68 61 48 66 58 61 58 49 68 52 70 52 51 59 62 53 61 50 61 58 59 50 57 53 53 56 69 50 50 71 59 66 65 57 73 64 45 63 53 76 55 61 61 67 61 56 63 60 65 62 46 47 57 68 69 63 62 73 51 59 58 54 72 74 57 65 55 55 73 73 73 69 60 68 48 60 68 55 69 66 67 66 60 72 49 63 67 47 57 63 57 60 55 62 62 65 64 67 56 53 70 48 63 67 63 60 78 59 52 43 50 67 71 63 59 65 57 54 58 55 62 67 56 67 67 55 55 63 58 75 59 54 76 70 69 67 55 75 58 60 56 66 62 55 65 62 74 62 55 64 59 72 76 73 45 61 63 64 61 62 41 61 73 48 54 68 62 56 74 62 69 57 47 44 82 56 65 68 48 66 49 55 49 63 71 57 53 58 68 63 56 57 58 72 61 55 64 65 47 62 62 61 66 43 73 61 52 60 69 59 51 83 55 69 63 58 63 53 84 85 53 58 61 62 68 52 72 85 53 58 73 71 54 61 62 73 53 58 69 60 69 56 64 74 62 71 62 60 66 64 71 55 60 56 62 59 68 56 75 70 68 60 60 58 63 52 62 54 53 63 61 53 61 59 55 62 61 76 72 62 47 79 60 70 78 60 62 57 64 60 64 50 50 51 61 54 70 59 72 71 71 55 59 66 69 68 71 73 56 56 56 62 72 69 59 58 70 59 68 77 75 67 76 58 64 67 55 68 72 57 58 66 76 70 63 78 50 60 51 62 67 53 68 46 60 76 58 63 68 55 42 80 59 58 64 56 67 60 73 69 63 63 72 55 69 64 66 51 73 72 56 61 59 74 67 70 61 64 64 70 63 63 65 74 57 89 57 72 79 66 63 57 78 62 55 57 71 70 62 72 58 61 66 63 60 73 62 70 66 69 68 64 60 67 65 54 48 58 52 61 72 67 49 53 51 59 67 76 54 72 62 63 53 62 53 72 78 66 73 61 66 54 57 69 51 59 59 77 55 69 66 67 64 66 65 66 63 71 60 65 65 71 64 56 76 63 78 65 63 74 69 65 63 70 70 64 51 69 58 77 70 67 60 66 53 47 52 54 67 61 69 57 58 50 70 53 57 57 64 69 74 70 76 63 83 58 61 69 72 70 65 66 59 60 59 61 66 86 75 62 71 76 68 74 56 55 51 52 80 57 71 57 54 66 66 54 59 66 63 63 59 73 60 63 63 65 73 60 60 55 65 75 62 62 55 46 52 61 59 70 57 61 57 63 65 65 68 49 64 67 42 51 49 67 70 66 77 64 68 69 76 63 50 60 54 68 64 62 64 75 67 64 50 62 53 54 63 71 62 59 56 57 70 59 66 49 55 59 53 55 56 54 49 58 67 64 59 60 61 65 65 55 53 55 64 54 44 58 68 63 66 70 67 71 54 51 65 65 57 75 81 52 62 73 63 69 61 62 66 68 64 69 56 47 41 60 48 45 59 71 55 61 68 62 53 53 55 57 62 54 47 69 42 51 51 74 59 67 57 60 63 58 54 45 69 58 72 58 57 51 59 62 51 51 64 41 60 54 54 61 67 55 57 60 73 63 58 58 57 68 60 59 55 53 63 59 74 59 61 58 49 54 52 55 48 54 68 64 61 65 57 67 61 51 63 67 62 66 52 58 65 57 73 55 61 65 69 50 71 70 74 56 66 42 44 57 53 55 49 69 66 56 60 76 58 67 68 59 46 56 59 62 65 54 59 53 58 72 63 38 77 59 56 64 48 61 66 60 55 51 50 61 64 60 66 50 67 54 70 71 47 46 73 62 59 50 51 47 52 68 67 50 62 56 63 53 46 62 51 46 45 62 58 59 56 69 68 60 60 52 48 64 58 62 57 67 48 43 64 57 66 52 49 53 59 56 52 66 58 49 76 55 59 60 67 58 58 53 50 52 52 63 62 48 60 52 57 57 58 47 55 45 47 62 62 49 55 66 71 64 48 63 51 68 53 65 60 58 63 58 61 63 49 60 64 65 42 78 58 64 49 55 48 67 55 56 66 54 56 65 65 65 58 53 60 49 53 49 70 70 62 61 63 50 49 63 55 56 62 63 55 55 50 67 52 62 50 54 58 61 65 59 47 53 43 52 50 54 52 61 45 54 68 57 59 51 42 62 46 48 31 50 62 59 61 48 47 49 48 46 52 60 66 58 54 48 54 65 63 43 62 47 59 67 58 55 59 63 54 53 57 50 62 60 50 32 55 56 58 70 53 52 55 53 64 56 43 55 69 59 50 58 61 52 63 44 56 57 49 61 65 63 78 62 76 55 68 67 60 62 64 54 55 54 55 59 39 56 52 65 55 53 50 51 44 74 45 47 65 41 50 65 66 58 47 53 53 55 46 66 49 48 61 48 63 50 56 63 59 59 63 65 51 54 55 66 63 61 48 52 62 50 60 47 58 58 71 68 61 46 52 41 46 66 50 57 55 54 45 60 58 61 46 75 60 51 59 62 56 58 72 49 52 42 52 65 42 56 55 61 59 46 61 62 51 45 48 62 53 42 68 51 55 53 47 56 59 45 49 49 43 55 60 60 51 59 64 56 54 55 69 42 70 58 45 58 50 51 38 70 46 44 55 46 53 39 42 50 52 43 37 59 43 52 42 51 49 38 53 61 52 60 51 61 50 69 61 53 47 66 55 52 49 50 45 57 59 55 54 52 54 71 66 53 50 68 55 52 50 65 43 48 51 60 59 57 34 56 58 58 42 38 46 64 48 60 59 48 50 46 54 45 39 41 59 55 46 57 61 65 48 58 53 47 49 40 44 48 56 60 51 54 42 65 50 52 53 55 40 55 49 47 71 56 62 55 59 53 65 52 56 63 52 55 32 50 48 66 45 70 59 71 54 43 57 57 55 44 55 65 56 42 62 45 55 60 54 49 44 60 51 42 41 41 57 42 57 50 50 55 51 57 55 47 61 59 56 42 52 49 53 43 44 50 52 57 64 54 59 44 66 52 35 47 49 53 61 55 43 62 50 67 49 48 53 44 46 45 56 58 46 45 44 56 49 43 57 52 59 47 44 51 45 60 63 44 49 51 46 48 44 47 54 36 62 47 46 48 61 47 48 39 45 49 58 45 58 48 52 48 52 53 38 42 50 48 48 48 41 46 50 49 51 56 46 55 41 60 57 41 52 58 44 61 54 54 45 54 50 49 49 53 64 44 44 56 50 39 60 55 45 50 45 51 55 60 46 47 44 52 63 51 52 46 48 42 37 54 51 45 52 52 59 48 44 54 41 59 40 54 49 38 43 43 69 51 57 47 43 58 52 52 64 57 50 49 57 53 53 61 48 52 47 61 47 43 45 65 41 49 48 51 57 44 57 57 55 61 56 46 55 39 57 51 54 49 40 47 48 30 57 48 48 48 46 65 48 50 54 42 46 48 45 52 54 46 66 54 36 58 47 46 55 53 43 51 59 47 41 52 41 46 59 57 51 47 55 50 41 52 40 44 46 50 32 31 44 51 33 56 54 51 61 47 50 54 44 52 50 46 50 44 38 56 42 41 46 59 60 49 50 56 47 57 42 48 50 43 46 58 48 48 44 62 52 47 61 46 38 41 53 47 49 49 62 48 46 41 42 46 47 59 40 39 52 59 53 53 49 61 53 47 46 61 45 58 38 45 46 47 54 54 54 46 62 48 46 36 56 46 46 54 52 48 48 50 60 52 58 50 55 35 45 39 48 58 49 44 51 47 40 53 54 37 48 60 51 51 44 38 43 39 47 46 38 67 49 52 46 54 45 48 53 41 51 64 46 44 38 52 54 43 59 49 57 61 54 45 47 53 47 50 44 40 56 35 47 49 57 59 45 60 33 62 42 45 52 54 43 56 40 44 56 55 57 53 39 46 42 56 49 43 53 61 43 36 44 43 42 47 38 43 45 52 49 44 49 49 38 45 57 32 44 62 57 64 46 48 56 59 53 60 61 51 58 45 48 46 58 42 53 54 43 49 48 50 39 45 51 35 37 49 55 49 44 62 36 43 46 35 50 48 52 50 41 46 47 50 43 58 49 40 63 64 41 49 54 43 39 48 36 50 58 62 41 54 51 59 49 46 38 45 55 47 49 47 51 58 52 47 54 55 40 39 54 51 52 54 60 60 57 47 42 55 49 49 50 54 60 52 42 56 42 58 65 54 56 54 48 45 43 42 44 36 52 37 36 47 55 47 41 49 55 64 62 48 41 54 41 53 55 64 49 57 47 57 47 54 38 36 33 53 37 52 54 36 60 39 52 36 45 41 53 41 45 48 54 44 38 53 36 53 41 48 58 57 48 44 44 53 49 49 40 49 43 52 43 51 50 44 56 54 41 44 47 65 57 45 56 44 42 53 47 37 47 42 58 59 44 43 46 54 44 37 41 48 54 59 50 48 56 53 52 51 51 41 58 50 48 49 41 48 52 57 48 51 48 54 50 49 46 62 45 48 52 51 48 54 41 43 59 52 47 43 69 42 61 57 46 44 53 59 50 54 56 40 48 48 45 50 43 40 49 39 50 39 39 48 50 51 51 41 47 51 44 40 42 48 50 48 45 42 49 37 42 42 52 46 39 55 58 50 67 49 47 40 47 49 54 44 46 54 40 51 68 35 44 28 56 47 58 40 36 43 47 46 42 44 51 45 47 46 49 42 54 60 52 46 59 46 53 50 45 51 52 49 45 62 45 51 51 59 45 53 43 46 46 56 48 54 53 45 41 51 45 41 56 46 42 40 62 48 36 39 57 42 41 51 46 51 42 57 55 51 35 47 48 40 53 47 42 55 47 43 43 41 42 49 45 52 48 51 46 46 41 39 59 50 36 42 42 40 52 42 39 41 37 52 37 43 57 46 45 42 45 45 52 48 45 49 62 46 59 43 42 50 54 55 57 46 52 56 43 57 45 75 34 63 57 50 36 54 57 52 54 50 51 39 41 51 34 55 44 48 52 69 47 47 50 47 40 52 60 56 53 48 43 51 52 54 41 40 47 51 58 49 49 41 46 56 35 37 48 51 48 55 41 41 54 48 39 52 46 44 53 47 47 35 51 42 48 44 62 58 49 34 49 43 42 51 40 52 51 67 53 58 47 47 41 45 49 48 60 60 43 54 42 52 47 45 60 44 45 58 51 58 41 42 47 58 39 50 49 41 49 54 38 45 59 47 47 42 43 56 62 36 41 43 61 44 44 47 42 49 42 58 57 52 55 42 62 67 54 54 39 52 39 46 43 52 51 56 55 45 47 48 47 53 49 50 52 54 56 44 59 63 65 56 42 47 44 42 61 38 44 48 53 36 49 49 48 50 59 45 50 53 57 46 49 40 51 50 58 57 71 49 49 55 49 35 52 50 61 31 49 54 48 46 34 34 43 49 38 54 49 50 48 64 53 43 47 52 43 47 43 55 54 48 53 67 54 35 49 37 39 41 43 44 45 53 45 47 61 54 46 43 58 51 52 47 62 41 43 41 47 44 51 53 53 35 47 55 51 46 49 46 58 51 46 44 52 45 48 42 48 53 57 48 51 48 59 50 36 60 65 43 49 48 58 40 49 46 40 40 40 47 54 48 50 53 43 55 50 57 65 52 46 43 45 66 55 38 50 45 48 43 42 41 53 50 52 47 52 51 49 44 49 52 49 67 47 51 46 52 57 58 46 58 49 58 45 61 51 49 56 49 71 55 51 44 58 48 37 45 54 53 70 57 57 49 65 33 46 46 54 42 45 59 49 46 40 48 50 48 48 50 42 49 57 64 47 49 56 62 50 48 53 45 49 45 51 47 42 71 49 43 49 53 57 47 61 65 46 61 53 39 48 50 45 52 55 57 60 50 49 60 39 55 53 64 50 42 54 45 60 48 50 71 51 57 53 56 64 61 58 48 64 63 58 50 47 61 67 65 83 66 56 54 71 66 58 70 74 76 66 80 75 71 74 73 81 91 86 82 88 89 93 78 102 90 104 101 83 97 99 98 110 96 77 80 90 70 82 77 77 87 66 65 82 65 78 72 88 80 53 77 53 53 75 60 77 64 44 52 58 53 63 52 49 55 61 57 57 79 56 59 54 51 45 58 67 53 56 51 57 44 45 50 58 63 52 50 55 43 47 67 48 41 40 53 47 44 43 41 43 50 47 65 58 60 48 55 43 37 38 53 60 48 50 50 49 53 41 49 44 46 55 53 39 47 58 61 40 46 43 49 51 52 62 55 51 42 43 46 51 62 40 49 52 60 58 49 46 67 53 58 62 50 48 56 48 49 54 50 46 47 59 51 49 40 49 53 48 50 43 46 57 56 44 54 42 47 48 40 41 50 38 47 36 38 41 48 39 65 56 34 55 54 50 57 52 44 39 33 52 60 54 55 50 51 54 50 73 45 47 55 52 49 35 51 55 49 55 55 60 62 53 32 56 40 52 54 54 55 54 48 47 56 55 50 58 65 46 34 44 56 44 45 47 52 38 44 56 62 49 51 47 50 49 40 48 44 41 55 57 52 49 45 51 42 52 47 40 45 49 47 42 53 54 40 61 58 47 43 43 53 47 46 47 52 44 50 46 48 46 48 42 52 50 53 52 49 47 52 49 45 56 49 41 60 41 49 55 48 49 46 54 49 53 56 47 40 53 57 55 46 37 54 47 43 52 50 47 44 51 47 50 49 46 46 48 56 41 54 55 42 51 36 40 57 52 34 52 36 52 54 61 69 40 62 51 48 46 38 38 43 57 54 45 44 51 50 46 33 54 49 48 50 40 60 49 44 80 53 38 43 42 48 41 48 34 47 39 43 43 48 50 34 49 45 50 60 48 45 38 42 44 50 45 43 51 44 49 42 53 41 50 42 48 55 64 58 46 40 47 48 49 43 53 48 32 44 39 57 44 46 44 46 45 59 55 58 41 42 44 44 57 47 51 37 46 53 39 46 39 36 55 41 50 41 53 59 43 55 48 46 37 47 32 54 48 43 45 47 50 50 49 42 42 48 49 52 36 32 45 43 46 58 47 36 46 47 57 41 43 33 49 42 50 47 51 41 37 48 46 57 47 44 43 58 37 56 54 44 44 38 67 45 49 47 58 37 52 48 52 57 54 39 60 50 42 42 38 47 46 43 43 43 42 54 39 46 54 40 40 37 49 40 51 48 47 44 60 34 39 37 45 39 52 34 50 48 42 37 43 52 50 47 52 55 46 50 61 43 44 51 42 50 44 49 37 44 40 49 56 42 38 49 48 45 48 53 51 47 42 42 49 44 34 40 39 52 46 60 49 44 42 49 54 51 59 51 54 48 43 42 54 31 43 48 47 54 52 46 51 56 39 45 55 52 38 55 41 50 46 47 51 42 56 38 44 49 39 41 42 45 51 55 51 47 49 40 60 58 49 51 46 53 44 44 44 46 58 42 68 43 40 36 45 47 58 52 37 59 51 47 46 48 53 52 56 47 60 38 46 49 66 51 57 39 48 37 32 52 47 45 42 36 44 55 43 51 60 36 55 45 46 48 49 41 49 41 49 49 56 45 42 54 48 39 35 61 50 50 58 51 52 49 53 40 45 41 33 45 65 57 45 39 53 37 47 40 48 50 59 40 47 48 38 54 44 42 59 35 47 50 40 52 54 46 48 50 43 50 49 39 50 53 40 47 51 50 45 60 42 53 46 46 46 50 60 51 38 58 58 55 42 52 43 45 48 51 31 47 57 50 45 49 46 52 50 50 48 54 44 51 45 40 50 53 53 41 38 49 45 41 53 50 51 38 44 55 38 52 36 47 50 47 47 43 51 52 42 39 49 38 53 41 56 53 53 48 50 44 47 60 40 53 42 45 49 46 43 45 41 37 57 51 50 56 50 42 47 55 44 43 27 36 49 47 50 43 56 55 43 58 36 30 52 42 43 32 31 53 41 49 55 48 45 53 42 50 55 42 55 53 58 40 53 56 45 43 46 49 43 50 51 56 55 40 50 59 55 40 60 46 55 45 49 45 49 58 69 47 45 50 37 54 49 54 44 41 34 40 40 34 40 36 50 50 59 36 54 42 46 41 53 48 52 36 44 50 48 33 55 43 53 42 55 42 38 40 39 57 42 45 38 38 42 51 53 52 45 45 48 43 44 64 44 48 51 46 53 40 54 39 46 38 43 39 58 36 45 45 52 37 49 42 48 53 58 34 49 38 50 45 42 48 51 48 41 37 34 48 49 52 51 44 34 52 43 48 43 45 50 54 41 47 34 40 44 48 37 53 50 46 39 42 48 52 54 37 39 53 45 53 46 50 57 48 41 53 41 40 44 47 52 42 43 35 37 47 52 48 40 54 35 47 57 64 47 47 55 71 46 42 41 42 40 52 44 44 59 40 51 36 38 44 48 48 57 48 47 44 37 43 47 40 45 54 48 38 48 40 50 36 45 59 47 56 50 42 50 38 55 54 48 54 42 46 28 37 46 51 45 40 53 47 45 43 54 37 60 42 61 44 45 48 34 51 53 46 50 56 51 46 62 46 59 32 52 60 37 50 57 39 47 53 40 58 56 36 46 40 39 47 48 37 53 46 39 48 50 39 41 40 32 51 52 56 70 59 56 40 41 39 49 44 45 55 37 51 44 35 29 58 53 53 48 46 53 33 58 47 44 56 48 48 58 47 44 53 62 47 47 35 44 50 60 45 56 44 60 45 49 37 54 56 41 37 49 35 51 52 45 42 46 45 48 43 41 60 44 41 34 43 59 41 41 33 40 36 55 58 37 39 47 36 44 49 50 56 39 55 50 48 47 36 49 49 55 54 48 45 42 45 50 47 36 54 44 58 51 36 49 59 43 51 55 62 43 47 48 48 48 43 47 47 44 46 48 46 40 51 53 58 40 48 39 39 46 51 49 40 50 46 51 45 58 53 61 60 48 42 46 60 50 49 60 45 57 52 44 49 41 48 47 53 41 49 65 59 36 34 40 48 36 46 43 55 36 60 62 51 44 43 46 50 52 43 33 40 46 43 39 46 35 42 46 42 56 38 56 43 40 52 45 47 39 37 42 50 46 40 45 40 52 52 34 40 47 39 52 48 45 61 44 49 52 41 51 38 46 56 46 56 36 34 45 43 44 46 44 48 42 57 57 45 48 43 56 44 59 45 50 38 38 44 58 46 60 42 45 48 49 52 39 48 44 51 54 43 43 48 43 55 53 42 54 42 53 46 52 51 58 37 63 52 61 44 48 49 47 43 46 59 60 48 47 48 31 42 47 41 51 44 49 39 40 48 56 56 53 45 52 50 52 50 43 57 42 47 32 48 40 44 46 49 45 57 48 58 41 40 43 42 46 45 38 47 45 47 43 43 54 45 43 49 62 50 43 41 48 34 61 47 45 60 44 40 48 53 42 46 44 57 50 51 42 55 32 54 60 49 52 42 53 37 50 43 46 38 57 56 43 42 32 46 52 52 36 45 54 45 44 54 47 41 47 45 50 40 45 40 48 40 53 44 58 42 34 46 55 56 35 55 51 57 41 56 39 40 41 43 34 60 62 49 36 43 42 35 51 45 51 37 36 67 48 41 49 46 43 54 41 25 56 44 51 41 47 47 49 38 43 49 44 55 53 49 46 49 44 47 40 40 49 43 50 49 49 43 50 40 56 35 44 50 48 50 44 50 58 42 50 60 43 48 51 49 52 45 43 42 61 45 35 43 50 44 45 48 50 69 43 52 46 59 53 46 54 47 49 47 51 38 53 46 46 42 40 40 45 49 49 39 45 35 49 42 39 61 56 47 47 42 41 46 55 48 61 39 41 53 58 44 49 36 41 38 41 40 51 47 48 55 56 36 32 61 55 37 43 37 37 50 43 36 44 52 42 45 54 44 37 51 53 41 47 59 41 47 46 51 46 43 37 57 54 42 55 37 43 33 48 39 53 54 53 42 42 52 36 53 50 33 49 61 51 36 53 41 41 49 61 39 39 45 59 56 39 44 61 45 38 40 53 59 40 46 54 44 43 54 52 53 55 52 39 53 37 47 52 41 42 59 49 41 61 60 53 52 45 40 36 43 50 46 41 57 28 41 56 38 51 42 61 34 49 51 50 37 55 43 49 38 41 39 47 47 53 60 42 46 38 38 46 49 36 49 54 58 41 49 39 38 40 58 41 52 49 44 54 47 48 61 48 40 45 51 39 42 33 43 43 53 50 41 52 50 58 39 48 41 49 49 44 41 44 48 49 44 48 47 44 51 45 46 47 52 39 38 45 51 49 48 59 49 55 50 45 50 39 49 54 46 56 47 39 48 49 39 50 59 61 66 51 38 46 38 54 38 48 42 41 62 45 44 54 50 46 54 51 48 48 36 47 50 47 43 47 42 48 52 46 53 41 42 53 57 59 37 50 41 35 41 41 42 43 58 45 45 39 43 55 44 63 48 56 43 51 55 45 54 42 45 51 42 52 39 41 37 51 46 60 63 51 53 54 47 37 51 41 45 45 47 51 57 43 51 36 46 48 45 49 57 63 49 52 47 47 40 47 36 40 41 43 36 40 31 44 55 37 52 52 48 41 49 45 51 54 60 39 47 49 45 58 47 65 48 36 42 44 60 51 38 52 45 54 46 57 36 68 49 40 56 43 52 50 57 45 44 51 42 40 47 54 43 48 40 54 47 53 45 52 62 51 54 53 61 25 60 43 53 46 49 37 52 57 50 54 41 49 51 49 53 45 51 49 49 39 59 47 65 41 53 57 51 49 65 61 51 45 51 50 46 51 57 39 56 41 50 36 52 37 48 56 46 59 55 38 52 45 45 47 51 46 47 54 59 48 57 41 50 41 44 45 57 53 47 35 49 59 56 49 55 36 48 50 57 40 46 36 44 56 43 48 55 63 62 48 63 63 49 59 54 54 44 57 51 41 36 44 40 52 45 53 51 54 49 40 49 34 41 55 61 42 50 36 42 31 44 49 43 47 47 49 47 46 45 49 56 43 47 43 53 42 51 39 36 53 56 53 41 50 38 46 37 51 53 58 32 45 50 45 45 60 50 41 46 57 44 42 41 53 46 45 49 44 43 53 47 44 57 58 38 52 59 49 55 50 49 55 45 37 53 54 51 35 43 47 48 47 41 45 41 46 54 50 51 44 37 46 55 36 57 56 52 39 50 50 31 38 45 49 48 42 51 49 53 46 48 35 47 41 41 41 52 45 50 36 51 50 40 35 48 54 40 50 42 51 50 41 42 34 50 51 43 41 54 62 47 49 35 51 47 48 50 44 45 48 39 53 42 59 44 50 36 48 43 57 49 38 35 49 37 50 45 44 36 52 41 55 46 49 45 47 51 23 62 42 61 49 46 42 53 42 45 58 47 54 47 50 46 42 48 48 45 55 48 49 44 49 46 42 48 40 60 55 43 46 44 46 62 55 55 54 47 53 49 44 57 41 42 40 48 60 45 38 43 44 45 58 53 56 38 53 51 60 56 52 49 38 40 51 46 41 55 38 54 43 59 41 31 58 53 57 47 51 42 45 51 39 49 46 50 46 49 61 42 42 56 35 42 62 49 47 41 47 53 48 43 46 52 52 54 55 48 45 45 47 47 59 52 57 48 31 59 45 45 45 51 47 54 57 48 47 48 43 46 48 42 47 56 57 33 41 53 53 38 35 49 51 51 48 48 50 57 67 50 59 41 34 50 43 67 60 43 41 56 41 44 44 39 51 49 48 47 32 48 29 37 30 44 40 53 47 48 49 50 54 46 48 49 35 42 47 38 52 49 49 55 54 52 43 39 48 56 39 52 43 56 41 42 55 44 52 44 48 40 48 43 59 41 40 43 49 49 44 43 48 47 59 48 51 50 55 44 59 61 61 39 46 50 47 45 48 51 50 56 52 54 40 47 59 50 58 45 49 46 52 47 63 55 37 46 57 52 52 52 37 43 50 39 55 55 60 55 48 52 42 42 39 49 42 50 48 44 50 42 56 61 32 58 60 36 40 52 47 52 50 47 57 42 51 48 48 48 55 49 50 57 44 56 45 40 34 50 37 41 55 58 58 52 46 44 48 47 51 42 40 41 50 52 58 51 44 40 44 49 34 49 46 42 50 52 55 67 53 43 52 42 42 52 46 50 44 52 45 47 41 45 49 37 46 42 44 46 50 45 57 50 54 64 55 50 49 42 49 39 36 44 52 43 55 64 46 62 36 53 44 45 52 50 45 55 53 47 50 49 58 38 49 47 44 44 47 47 55 48 48 48 48 40 52 59 46 39 44 46 59 50 41 46 48 48 48 46 54 56 51 39 55 54 47 51 48 51 46 52 50 61 69 55 48 34 45 36 58 53 50 55 35 54 54 43 40 40 57 35 40 53 48 36 51 58 42 42 50 57 53 51 40 50 64 37 45 54 55 61 58 48 50 44 49 44 48 51 56 45 49 45 43 36 48 52 31 42 42 52 53 36 48 54 57 52 56 37 54 47 25 60 43 43 44 49 43 49 42 33 44 46 51 55 57 51 51 51 45 59 39 40 54 50 33 66 38 54 51 53 51 50 42 55 41 42 33 39 48 54 50 59 45 56 46 45 45 54 47 48 62 37 46 34 57 46 46 39 53 42 45 52 51 41 34 54 33 47 55 62 28 51 58 47 47 77 47 53 34 43 52 48 50 46 52 55 55 52 46 47 45 44 50 65 39 49 53 41 55 44 55 47 37 40 46 49 43 51 47 52 50 43 44 43 48 50 41 41 59 51 65 51 55 49 51 52 36 44 45 45 46 44 38 57 44 62 52 64 54 50 50 42 45 47 49 57 55 60 45 47 64 29 46 47 49 49 54 54 37 39 49 55 55 49 49 47 52 41 49 41 36 47 41 53 42 49 40 52 49 61 43 54 44 50 43 47 40 51 47 58 54 43 46 52 43 49 54 39 35 52 46 51 44 49 40 49 63 39 43 47 47 47 47 45 41 46 48 61 33 51 47 54 53 50 53 46 48 33 56 48 51 57 63 43 40 39 47 61 47 55 48 62 57 52 51 42 46 49 47 48 58 53 39 31 39 48 40 47 49 40 65 43 49 48 42 45 31 45 44 37 41 45 53 50 34 42 54 50 65 42 65 48 49 48 35 51 40 35 52 59 42 46 44 68 39 44 45 42 55 44 51 55 54 52 58 51 52 49 37 54 40 39 45 48 48 53 32 32 55 50 53 56 38 66 40 53 46 44 47 50 55 57 51 43 45 39 43 51 58 43 41 35 40 46 51 42 48 46 51 43 42 37 48 49 57 49 41 52 37 51 48 59 48 48 49 52 55 62 43 47 47 50 51 44 47 44 41 43 57 44 44 53 53 45 35 54 45 43 45 44 41 35 49 52 51 46 49 35 46 60 41 40 47 54 46 44 43 49 53 37 41 47 44 43 36 60 43 50 52 36 43 51 48 55 36 39 46 52 56 44 49 37 47 51 43 53 53 50 44 55 42 44 46 51 50 49 34 51 48 62 42 58 40 43 44 41 48 45 43 40 36 38 48 41 47 45 58 52 45 35 42 46 44 46 49 41 54 42 43 38 37 35 44 45 40 58 57 54 54 46 42 37 57 51 46 57 43 44 54 48 43 58 58 40 51 54 34 47 40 37 42 52 56 53 47 37 42 46 53 40 41 37 38 49 39 40 59 54 62 43 45 37 41 55 44 47 44 54 40 52 43 50 48 37 41 36 36 59 41 43 43 43 41 45 44 51 42 53 43 48 44 38 41 43 40 43 45 58 40 45 42 49 50 37 40 60 43 46 39 43 32 41 41 38 53 48 43 44 47 33 45 45 38 46 57 47 45 61 48 57 47 38 55 33 49 38 54 44 51 49 49 34 46 39 40 36 57 37 57 47 43 38 52 58 48 46 39 40 48 45 36 49 49 42 46 54 53 45 58 38 42 39 49 41 52 53 46 50 45 40 44 49 47 44 50 35 44 42 46 42 61 43 41 35 59 46 45 59 41 24 44 42 49 56 38 44 48 51 51 41 38 46 41 49 57 42 38 44 56 47 60 56 44 35 35 41 42 45 46 33 47 41 53 46 56 47 44 50 37 40 48 48 39 44 43 53 58 52 64 45 45 51 46 39 52 50 37 39 42 48 43 36 65 45 45 48 55 53 56 52 51 53 52 48 41 45 55 44 49 51 39 51 42 45 42 39 50 45 52 47 52 50 46 48 47 56 52 37 47 45 35 50 45 44 42 53 53 46 52 46 58 58 46 61 44 48 46 45 55 40 59 34 62 38 38 34 46 47 56 36 37 48 55 33 39 44 38 44 47 48 56 41 46 60 47 45 57 49 46 43 41 48 47 44 40 52 46 52 43 36 44 44 52 53 37 37 42 51 40 58 37 44 51 51 46 46 42 47 29 44 53 35 47 43 49 40 47 44 61 46 46 45 52 48 44 54 51 43 57 51 39 44 57 38 38 58 44 53 47 48 46 47 46 67 50 49 45 59 50 50 47 42 39 42 59 48 42 37 52 42 48 49 44 46 52 48 36 38 46 55 49 43 48 51 51 42 49 55 46 43 53 56 51 39 33 42 42 38 54 68 47 59 52 60 35 49 44 57 50 40 57 53 50 51 54 52 56 60 64 43 36 47 46 49 42 48 50 45 56 42 55 56 59 42 49 59 72 44 45 58 52 48 68 46 55 44 45 67 41 45 54 60 52 50 50 58 64 66 34 60 48 53 54 57 47 49 52 54 47 41 44 48 65 51 53 51 53 52 55 53 51 40 38 55 60 47 43 52 50 44 42 59 54 52 45 42 48 42 45 44 47 59 44 56 40 46 41 42 51 52 46 37 46 38 45 51 41 48 52 48 51 53 46 45 48 49 55 56 41 41 57 53 67 36 46 52 43 48 45 41 47 58 40 49 41 44 40 48 49 45 46 38 49 36 39 33 56 51 48 59 55 39 42 46 66 44 54 36 40 46 44 53 31 42 48 37 41 37 43 55 38 54 43 36 38 57 49 39 44 43 41 49 51 50 42 43 47 43 42 43 54 53 53 56 48 42 44 40 47 44 42 37 53 57 47 54 42 37 33 47 58 36 41 36 44 36 45 50 40 43 46 48 40 43 47 43 50 53 36 42 37 38 39 60 58 54 48 41 49 53 38 41 52 42 43 54 63 44 41 45 50 50 47 37 48 43 49 52 31 51 52 50 49 48 35 54 41 49 48 45 47 48 57 56 42 49 46 43 41 49 58 49 46 47 45 28 50 41 38 41 47 37 50 51 39 45 44 55 40 53 51 37 50 45 44 45 53 49 55 44 52 48 47 51 39 41 42 38 37 52 46 53 43 49 53 49 49 58 42 47 42 40 44 47 42 34 49 43 49 54 44 45 36 42 32 51 40 46 39 45 50 44 62 50 45 39 47 49 50 40 41 41 35 49 33 38 41 44 44 49 50 50 41 40 40 38 44 52 65 35 59 48 49 45 51 51 34 53 42 42 42 47 44 41 33 45 46 56 46 45 41 45 56 56 54 54 48 53 28 44 43 61 39 46 42 46 42 52 54 51 37 41 48 52 37 42 43 39 41 43 45 35 40 50 54 39 50 32 49 48 55 39 41 50 53 44 43 59 44 54 45 44 50 42 41 42 49 35 50 47 46 33 55 57 50 42 47 57 53 42 52 37 37 43 49 41 33 47 31 56 49 48 47 56 40 39 46 40 42 33 33 46 39 38 52 58 42 45 54 45 65 49 48 39 46 44 28 54 37 53 47 47 50 46 46 40 60 45 47 62 41 38 43 43 45 31 36 48 37 54 41 43 49 41 40 52 33 44 35 40 44 45 36 39 45 35 38 45 62 41 46 38 39 33 50 42 47 55 40 49 45 47 51 50 52 41 46 41 42 47 46 42 44 48 38 46 51 48 62 55 43 48 30 54 49 41 52 53 43 47 46 42 44 44 54 56 54 50 53 62 48 53 46 35 49 39 48 35 29 49 53 36 54 39 47 46 41 44 38 54 42 40 51 49 48 37 49 47 44 47 53 50 52 47 36 50 43 41 32 47 32 38 35 43 46 55 44 28 41 53 41 41 53 45 41 53 54 42 40 41 48 48 52 47 45 55 39 53 55 44 56 49 49 44 46 60 38 23 48 46 64 57 44 42 55 42 36 39 28 47 45 51 36 53 39 50 49 38 43 46 54 37 37 44 54 46 40 51 38 35 40 47 54 52 44 50 45 49 42 51 41 38 49 46 53 39 48 36 41 41 50 47 29 46 40 58 51 44 53 50 40 37 57 49 58 50 46 51 45 45 40 52 48 53 44 40 37 44 56 40 48 43 43 35 56 37 41 57 48 51 54 59 41 40 39 33 43 44 45 50 46 43 50 42 53 42 49 49 34 33 34 46 54 58 51 48 46 35 44 41 51 49 21 46 37 60 36 49 47 48 47 36 46 59 53 51 53 60 33 48 51 43 48 47 51 51 45 52 49 58 62 34 55 45 39 44 35 47 54 53 47 46 45 52 31 40 51 50 61 62 48 59 51 53 43 52 57 43 53 44 45 56 44 41 47 35 55 43 56 53 43 52 36 39 34 37 47 52 45 45 34 49 37 44 47 33 49 44 43 50 43 36 53 40 46 56 51 37 47 61 53 43 46 48 53 43 64 45 54 50 59 41 45 41 37 46 55 59 37 46 42 50 51 51 52 34 37 46 40 33 54 42 41 47 45 41 36 35 44 51 39 51 49 34 47 49 47 53 53 51 56 44 59 43 44 30 62 56 50 52 46 44 52 35 49 51 39 42 50 47 46 52 48 46 44 43 42 58 46 47 48 38 44 51 39 47 40 45 47 52 50 44 50 47 45 39 49 46 61 31 55 46 29 62 53 55 42 39 47 48 57 49 42 52 50 46 48 43 41 47 41 44 49 38 61 46 46 46 58 43 49 45 43 51 43 48 51 43 51 54 32 44 41 47 49 59 42 60 51 44 39 46 51 32 43 44 59 52 54 49 51 46 57 43 33 46 50 41 45 48 45 48 48 48 43 32 57 42 46 42 50 41 51 42 44 59 45 52 55 44 55 52 43 46 40 36 49 37 53 43 46 54 56 47 45 40 37 36 41 49 53 48 50 35 44 42 43 49 45 53 51 45 62 53 42 41 45 40 50 50 34 48 51 49 48 45 51 57 45 37 47 31 42 52 45 49 40 39 47 50 57 56 45 48 46 37 35 45 43 43 30 46 48 60 50 36 46 53 47 45 51 39 43 44 40 41 47 33 41 47 34 31 46 46 65 46 47 36 46 56 44 51 44 44 42 38 39 39 34 39 48 39 42 42 48 48 57 43 44 47 66 58 46 54 35 40 45 52 42 44 35 51 41 48 48 58 44 40 50 47 49 49 45 44 50 53 33 44 39 47 53 52 48 49 48 51 33 39 45 49 54 41 33 42 48 46 55 43 51 36 58 48 48 39 46 43 47 49 39 50 38 56 38 49 47 47 42 55 45 38 55 46 40 51 53 54 43 43 43 45 48 46 58 59 51 43 48 43 42 52 55 52 40 41 48 43 42 39 47 35 50 42 42 37 52 45 44 45 49 46 53 43 36 41 60 41 48 47 55 57 54 52 40 39 48 45 41 46 46 45 54 32 41 42 38 44 52 37 37 48 53 39 40 40 54 58 41 37 38 49 48 48 38 51 56 52 45 47 50 50 49 47 39 42 42 37 58 48 50 46 48 52 43 54 43 43 45 58 45 43 66 40 42 41 47 45 44 55 42 44 55 52 46 50 40 53 44 41 46 61 37 43 49 64 49 43 57 39 51 32 46 33 48 41 38 46 42 44 47 44 59 51 46 52 47 45 50 50 45 42 49 41 46 40 44 49 41 40 41 58 44 47 48 46 52 48 58 45 50 53 62 43 52 41 38 40 44 45 46 44 55 41 45 46 44 42 29 46 46 55 47 51 41 36 44 52 52 46 53 43 41 44 43 43 51 48 49 54 43 38 46 47 41 36 48 51 48 34 44 43 42 49 35 49 39 41 53 39 54 35 46 56 41 42 43 51 37 40 47 43 41 36 39 41 46 42 48 39 53 58 41 50 50 56 56 48 46 51 54 37 47 51 43 57 41 47 41 53 55 61 47 51 39 41 47 44 50 40 46 41 43 51 42 45 47 37 35 44 40 51 48 55 40 59 50 49 43 51 56 48 34 49 49 46 38 43 42 38 40 43 52 49 32 48 48 45 45 55 44 36 39 52 56 49 38 37 40 47 52 34 59 57 40 49 46 52 50 46 37 51 46 48 36 45 34 54 42 49 43 56 53 47 35 58 50 45 39 42 52 46 41 51 45 52 56 59 47 45 50 46 47 54 44 50 38 47 43 49 45 52 38 50 52 48 42 46 36 42 44 45 40 53 45 46 53 45 39 52 45 55 40 42 46 52 44 53 49 38 42 62 42 33 51 58 46 45 53 40 59 43 47 57 55 51 48 49 57 40 53 48 55 60 48 58 34 39 53 45 49 45 33 34 54 40 42 45 49 52 52 58 50 38 55 50 40 41 39 59 50 55 63 46 44 52 57 35 53 61 59 50 51 48 62 53 40 38 57 57 48 42 47 47 51 47 40 42 36 48 63 42 50 40 41 53 50 50 45 53 42 47 35 34 46 48 51 41 36 49 44 65 50 36 47 45 47 43 41 47 33 39 44 37 39 47 50 44 47 51 51 49 42 60 38 50 49 52 30 49 48 47 50 50 43 56 35 50 38 50 49 50 46 50 49 46 52 51 47 40 45 58 54 49 49 47 45 42 45 42 53 47 50 60 49 47 40 36 47 41 52 56 40 41 45 39 37 32 48 50 51 50 37 40 56 53 38 42 59 53 50 42 53 53 60 68 45 52 43 45 40 42 38 51 60 41 46 65 30 48 40 61 43 55 50 38 56 47 37 50 50 40 50 48 47 50 55 48 51 61 64 53 36 64 45 35 42 50 53 67 50 40 60 37 57 52 54 50 63 48 56 42 46 52 57 49 44 39 49 54 40 41 45 30 49 56 40 39 33 50 47 56 51 50 46 41 47 35 41 55 44 52 47 48 52 41 52 46 45 51 54 58 46 54 34 42 47 33 51 42 43 38 53 46 54 49 46 50 48 49 45 34 49 50 43 50 53 52 50 44 49 47 60 55 36 49 61 54 48 50 45 43 52 48 52 46 34 33 47 43 54 49 47 49 54 50 51 38 46 47 44 42 59 48 45 45 48 46 44 43 56 42 48 52 43 36 54 52 50 53 45 39 44 33 52 40 47 43 46 46 36 53 58 54 53 40 44 51 49 58 62 53 36 39 42 60 36 62 49 51 55 55 44 59 44 42 64 38 53 50 45 44 41 44 42 58 33 51 37 53 57 49 42 40 50 53 45 48 52 52 57 41 46 51 39 53 37 51 45 36 44 47 52 32 32 55 62 59 48 50 38 49 43 36 55 44 43 40 52 57 59 43 31 44 42 38 41 55 42 43 47 49 56 38 50 51 55 44 45 58 37 53 46 41 56 44 56 41 49 50 46 32 44 39 39 54 38 54 44 47 51 47 54 42 38 53 48 45 50 54 53 48 44 37 43 44 49 40 37 39 51 50 52 40 42 63 41 48 55 59 51 54 45 38 36 38 41 50 53 42 50 61 49 46 42 52 41 38 59 48 39 57 38 46 36 41 42 42 54 39 40 48 39 51 43 59 57 51 34 48 40 40 29 48 39 44 61 60 44 41 46 48 46 42 38 37 56 46 51 37 45 42 54 47 37 53 55 32 63 49 46 46 38 54 56 53 43 42 62 47 48 45 47 44 54 51 47 57 36 54 50 44 51 43 51 40 41 43 47 53 41 36 48 51 43 37 51 56 49 34 40 43 37 50 46 49 52 40 47 57 48 55 51 40 38 53 64 55 43 47 52 35 42 39 54 45 52 46 57 52 41 50 50 43 50 45 47 33 33 32 45 57 45 45 51 46 36 48 51 46 48 56 50 42 46 49 51 50 46 45 42 41 52 53 58 45 49 61 44 46 33 44 43 44 46 47 37 44 49 52 54 48 36 49 44 41 43 50 46 46 44 39 49 37 53 43 40 52 42 63 41 55 46 41 57 46 50 46 47 49 42 44 43 43 42 45 46 38 57 34 65 51 56 35 55 37 39 47 48 53 56 52 44 40 38 34 48 46 50 45 41 46 58 52 44 38 45 60 47 33 46 55 41 36 38 46 50 48 50 55 39 52 41 53 52 59 42 50 35 51 47 53 42 46 48 41 55 50 38 49 49 49 48 39 56 49 40 41 43 46 46 44 55 42 44 45 58 40 46 48 49 39 46 54 47 30 52 49 41 41 59 49 54 34 48 57 49 37 41 50 50 50 49 51 31 52 49 35 42 44 40 42 40 54 52 30 51 59 55 37 56 43 50 48 57 37 47 56 50 46 52 60 42 37 47 39 43 51 49 48 36 57 48 48 44 43 49 44 47 37 42 31 41 52 53 42 54 32 45 55 48 43 46 50 43 40 35 46 40 58 48 52 43 35 54 59 60 45 42 51 54 40 45 49 45 52 58 56 40 61 50 58 45 40 40 49 57 41 48 53 56 49 37 47 45 41 50 38 46 45 39 32 43 50 50 46 40 52 41 48 38 38 48 55 47 59 39 45 45 42 46 45 41 45 41 57 44 35 32 52 59 51 42 44 49 44 57 39 48 39 52 55 40 50 44 43 48 53 44 47 41 35 48 45 52 48 48 43 51 38 47 52 43 54 53 42 41 34 41 60 42 46 57 59 46 47 40 32 50 57 51 60 46 38 38 36 50 51 55 49 37 43 43 55 44 47 35 42 36 38 50 55 50 48 43 47 54 44 46 46 52 55 52 43 40 45 60 43 43 48 45 46 55 44 43 50 43 53 52 36 54 45 41 39 40 42 39 40 49 52 45 36 59 50 39 57 47 39 43 45 34 57 46 57 47 44 58 35 44 54 43 56 58 40 47 51 49 53 55 35 39 39 39 44 42 57 33 44 46 41 41 47 33 46 40 48 54 44 52 40 38 49 49 57 60 34 56 47 55 44 40 43 43 41 60 43 52 50 39 44 52 33 53 51 46 39 40 54 41 51 41 31 47 52 34 40 45 48 44 42 43 48 56 44 43 58 56 41 59 51 40 52 41 45 36 51 38 34 42 54 44 41 53 42 54 41 35 49 47 57 43 49 45 43 58 46 45 42 41 52 44 36 48 36 46 51 51 40 41 50 39 42 44 52 51 51 57 53 40 49 36 41 40 55 49 56 51 42 52 52 55 46 41 50 49 48 57 47 44 42 49 47 45 49 52 43 40 46 45 43 50 57 31 55 54 50 51 50 44 44 46 45 43 48 48 57 49 55 51 47 48 49 58 32 57 56 49 42 37 42 38 49 59 40 38 52 31 41 49 43 45 47 40 48 57 46 45 43 47 52 53 42 63 51 51 54 39 44 58 55 50 43 50 47 48 45 55 44 45 46 40 40 30 42 44 53 51 56 59 47 46 38 54 51 46 55 55 48 52 54 48 58 39 48 52 53 41 56 49 42 62 47 46 44 34 42 48 44 46 56 48 45 33 47 43 41 41 40 43 50 45 58 41 45 41 47 48 52 45 48 43 42 56 50 45 58 48 42 40 45 42 47 45 33 56 50 62 42 56 43 43 43 53 49 38 53 40 40 44 47 36 46 45 53 42 52 49 45 40 53 42 37 41 48 49 43 37 41 54 35 54 57 41 55 45 43 48 41 41 32 48 47 41 52 54 34 47 55 52 61 47 48 47 47 43 47 53 45 54 55 34 57 46 54 48 41 50 49 38 43 45 48 59 62 54 48 42 38 55 39 41 56 54 41 36 31 52 37 44 55 51 55 53 59 48 52 49 56 46 50 41 52 43 47 43 48 47 51 46 47 51 55 43 50 51 51 38 44 43 50 41 42 47 49 55 38 37 56 46 48 40 48 47 43 51 43 40 42 48 43 37 35 44 44 44 45 58 33 44 42 64 46 60 39 52 45 50 55 54 41 49 35 53 46 55 53 37 49 61 58 42 52 50 44 45 50 46 47 34 51 41 51 51 54 50 51 59 45 50 48 54 43 58 42 51 42 49 50 71 42 35 52 58 51 44 49 47 54 50 47 50 43 50 56 49 46 47 47 35 39 40 42 44 50 51 48 49 52 48 53 30 43 47 58 44 45 40 47 32 51 42 49 30 47 53 57 47 46 54 46 41 48 31 60 56 53 58 57 40 44 52 41 60 45 57 42 48 33 45 56 31 58 57 39 49 42 36 49 45 40 47 56 32 42 44 57 44 44 59 42 53 43 45 48 47 52 57 51 39 34 49 46 48 35 54 34 37 46 36 51 51 46 41 45 50 42 45 39 44 45 53 50 44 43 48 55 55 42 45 42 53 52 52 49 36 45 43 54 53 51 38 43 59 48 54 48 43 67 52 57 43 49 44 39 51 57 45 43 53 57 62 44 52 49 42 46 47 58 47 40 47 54 57 43 60 53 63 44 48 54 49 57 36 53 53 44 40 49 43 44 42 56 64 67 53 44 51 38 44 61 60 47 53 38 49 48 41 45 41 54 43 57 44 39 45 50 49 61 60 41 44 45 55 47 51 44 57 51 42 59 55 47 50 49 41 55 45 53 52 51 45 42 41 32 50 44 46 45 48 60 46 55 44 42 56 43 48 45 33 54 45 41 46 52 45 36 52 45 48 46 47 53 52 45 43 48 54 56 52 56 39 49 43 52 38 47 47 47 50 35 51 47 50 38 45 39 40 55 56 41 54 49 47 45 48 41 39 34 49 47 48 46 54 42 54 40 40 55 42 48 41 46 49 37 51 49 51 34 39 51 55 43 45 48 46 31 56 45 48 48 45 55 43 52 55 51 49 43 58 50 51 45 45 47 29 39 46 49 59 56 45 51 56 53 51 52 37 36 51 45 50 49 34 41 35 50 45 49 41 47 54 39 60 51 42 50 43 48 47 51 40 38 47 55 61 43 46 53 43 30 54 43 47 44 38 51 51 52 43 47 57 50 41 41 58 44 63 50 49 49 35 44 47 43 54 35 44 56 47 49 48 51 51 46 38 47 35 43 46 40 44 39 60 45 50 47 36 43 42 46 57 53 55 43 42 51 46 60 42 43 51 46 45 47 46 47 44 41 46 47 37 53 53 48 44 50 43 49 38 38 41 44 47 50 46 41 40 49 42 45 47 49 47 54 45 58 48 46 46 47 45 41 46 43 43 43 37 44 44 49 39 55 46 45 58 34 58 40 58 56 55 51 41 37 44 43 43 44 49 46 33 43 47 52 52 45 44 41 36 44 45 49 50 47 46 44 44 41 45 50 56 53 47 40 51 48 42 41 54 36 47 50 42 45 43 46 50 38 52 52 46 46 42 52 49 39 51 52 38 50 45 48 47 57 46 36 28 32 43 39 44 57 43 50 44 53 36 50 37 55 47 51 55 55 58 52 58 41 56 53 47 49 42 47 48 44 41 61 48 42 47 34 47 41 49 44 55 34 48 37 48 49 44 49 46 44 45 57 42 41 45 50 33 36 43 41 44 35 45 55 37 51 68 44 42 48 35 43 65 44 46 48 59 48 44 54 49 54 27 55 47 44 53 42 47 41 46 28 52 44 44 62 56 46 56 53 58 51 50 42 46 59 43 59 46 51 47 44 54 51 49 42 44 44 57 50 41 40 48 52 39 42 56 45 49 51 58 44 36 49 54 45 40 40 40 39 55 45 59 39 45 35 42 52 48 52 57 59 61 55 54 47 39 63 38 45 48 54 48 58 37 51 55 45 34 40 44 46 52 46 42 41 46 48 42 51 46 54 55 46 38 48 39 38 45 49 43 46 43 43 43 39 44 45 31 50 52 62 53 45 40 52 44 49 53 34 54 49 49 49 48 48 53 46 54 39 47 55 41 57 46 43 62 41 54 49 44 39 52 29 41 47 44 52 59 42 41 40 35 49 44 49 43 52 34 55 51 51 53 53 46 52 43 55 47 52 46 44 48 63 41 29 48 52 47 44 46 47 50 45 46 53 48 40 45 43 41 44 47 49 52 56 44 45 53 45 40 50 50 43 44 43 35 47 39 54 48 52 60 60 48 45 53 51 38 45 44 43 40 50 41 45 35 53 51 41 43 56 42 44 36 38 45 50 40 49 54 57 33 53 46 40 44 51 45 55 44 47 42 41 43 55 37 57 59 49 50 50 43 35 55 47 54 55 63 43 50 44 46 52 42 52 45 53 38 42 57 51 48 50 46 43 47 38 51 45 56 51 48 52 48 48 54 36 63 40 38 60 51 45 52 50 41 38 57 38 51 52 50 51 50 55 57 49 38 45 56 60 41 43 47 43 63 43 50 54 47 57 54 52 46 45 52 43 29 53 56 50 48 44 54 56 66 43 44 57 53 41 43 46 44 47 39 43 52 59 42 43 45 43 49 47 45 39 42 59 51 57 45 48 50 49 44 46 41 57 51 45 48 44 53 45 36 51 43 48 37 46 58 47 43 56 46 47 46 40 60 59 49 38 50 59 52 56 53 49 45 34 61 52 46 49 57 51 51 49 68 52 46 42 39 46 37 50 52 48 63 52 46 48 49 42 58 48 51 49 51 50 40 42 43 40 43 49 54 50 40 36 57 44 48 49 45 47 53 36 50 45 53 47 52 48 40 57 50 65 43 51 43 51 61 50 50 52 42 52 55 41 47 49 51 44 59 54 42 47 51 47 59 50 53 47 52 38 38 48 63 52 53 46 38 47 44 42 51 52 53 41 46 42 35 44 43 45 57 47 45 53 59 50 45 78 40 58 60 56 40 36 47 46 28 41 42 47 39 47 44 42 45 43 45 62 49 60 47 49 49 53 43 52 54 52 45 47 49 35 56 51 52 43 46 48 46 37 61 43 49 45 37 56 48 48 43 42 47 46 50 57 54 35 48 44 51 53 54 43 42 47 42 46 52 47 46 51 43 57 40 38 39 54 38 48 42 46 45 49 43 46 55 51 37 54 47 51 54 40 55 49 54 42 41 41 35 51 47 55 41 54 39 50 48 41 53 57 50 47 69 50 48 47 61 44 41 56 40 53 46 59 53 50 49 48 34 45 46 37 51 58 45 48 43 51 37 51 39 63 52 35 38 46 50 42 50 38 55 46 50 47 55 52 54 44 47 56 50 33 59 45 52 46 50 58 70 48 46 56 42 56 41 44 50 59 42 53 40 55 69 49 46 47 31 49 51 30 58 47 49 42 52 57 46 45 48 55 50 55 52 47 39 49 34 44 51 44 49 50 47 43 64 43 35 59 51 49 44 53 50 48 41 46 55 42 52 58 53 44 54 41 45 41 47 34 59 48 43 49 36 44 50 57 57 49 46 60 43 44 36 45 48 37 41 55 36 46 43 50 61 51 62 41 46 39 50 53 64 59 32 46 40 34 55 53 49 53 46 41 44 39 51 59 54 55 38 46 47 51 38 36 37 49 54 41 40 43 48 32 47 54 57 43 48 48 43 48 53 49 35 45 47 35 51 37 44 43 46 50 37 43 41 48 37 41 60 40 39 43 49 57 42 41 41 54 58 53 33 55 42 64 42 44 49 38 43 44 49 49 49 50 46 36 43 31 37</counts>
			</dataPoints>
		</scan>
	</xrdMeasurement>
</xrdMeasurements>